File: SQUID/Reference/LAO/C3/LAOsubstrate_22172_MT_F_p0.5T_00001.dat
[Header]
; MPMS3 Data File (default extension .dat)
; Copyright (c) 2007, Quantum Design, Inc. All rights reserved.
TITLE,
FILEOPENTIME,3881323170.55303,12/27/2022,5:22 pm
BYAPP,SQUID AC,0.9.1.0
INFO,MPMS3 Measurement Release 1.1.16 Build 347, MultiVu Release 2.3.3.2,APPNAME
INFO,0,MOMENT_UNITS
INFO,LAO,SAMPLE_MATERIAL
INFO,,SAMPLE_COMMENT
INFO,,SAMPLE_MASS
INFO,,SAMPLE_VOLUME
INFO,,SAMPLE_MOLECULAR_WEIGHT
INFO,,SAMPLE_SIZE
INFO,,SAMPLE_SHAPE
INFO,Quartz,SAMPLE_HOLDER
INFO,Standard,SAMPLE_HOLDER_DETAIL
INFO,65.74,SAMPLE_OFFSET
DATATYPE,COMMENT,1
DATATYPE,TIME,2
STARTUPAXIS,X,2
STARTUPAXIS,Y1,5
FIELDGROUP, VSM,2,3,4,5,6,8,9,10,11,14,15
FIELDGROUP, DC, 2,3,4,14,56,57,58,59,60,61,62,63,64,65,66,67,68,69
FIELDGROUP, AC, 2,3,4,11,16,17,18,19,20,21,22,23,24,25,26,27,28,29,30
STARTUPGROUP, All
[Data]
Comment,Time Stamp (sec),Temperature (K),Magnetic Field (Oe),Moment (emu),M. Std. Err. (emu),Transport Action,Averaging Time (sec),Frequency (Hz),Peak Amplitude (mm),Center Position (mm),Lockin Signal' (V),Lockin Signal (V),Range,M. Quad. Signal (emu),AC Moment (emu),AC M. Std Err. (emu),AC Phase (deg),AC Phase Std. Err. (deg),AC Susceptibility (emu/Oe),AC Suscept. Std Err. (emu/Oe),AC X' (emu/Oe),AC X' Std Err. (emu/Oe),AC X'' (emu/Oe),AC X'' Std Err. (emu/Oe),AC Drive (Oe),AC Frequency (Hz),AC Averaging Time (sec),AC Cycles,AC Range,AC Measure Type,AC Signal' (V),AC Signal'' (V),AC Trim Coil Ratio,AC Trim Coil Phase,Min. Temperature (K),Max. Temperature (K),Min. Field (Oe),Max. Field (Oe),Mass (grams),Motor Lag (deg),Pressure (Torr),Measure Count,Measurement Number,SQUID Status (code),Motor Status (code),Measure Status (code),Motor Current (amps),Motor Temp. (C),Temp. Status (code),Field Status (code),Chamber Status (code),Chamber Temp (K),Redirection State,Average Temp (K),Rotation Angle (deg),Rotator state,DC Moment Fixed Ctr (emu),DC Moment Err Fixed Ctr (emu),DC Moment Free Ctr (emu),DC Moment Err Free Ctr (emu),DC Fixed Fit,DC Free Fit,DC Calculated Center (mm),DC Calculated Center Err (mm),DC Scan Length (mm),DC Scan Time (s),DC Number of Points,DC Squid Drift,DC Min V (V),DC Max V (V),DC Scans per Measure,Map 01,Map 02,Map 03,Map 04,Map 05,Map 06,Map 07,Map 08,Map 09,Map 10,Map 11,Map 12,Map 13,Map 14,Map 15,Map 16
,3881323195.10534,399.987731933594,4999.6396484375,-9.22772803633431E-5,1.48975455111959E-8,1,4,14.0008964538574,4.99686564470688,33.4299989044666,-0.114578313468202,-0.0172695520105406,1,1.06158497477806E-7,,,,,,,,,,,,,,,,,,,,,399.987457275391,399.988006591797,4999.6396484375,4999.6396484375,53.5071619124672,5.86257457403168,13.6318578720093,56,1,0,0,1,0.329742431640625,31.7693061828613,1,1,3,399.988006591797,0,399.987731933594,,,,,,,,,,,,,,,,,,,,,,,,,,,,,,,,,
,3881323240.52419,397.981353759766,4999.6396484375,-9.22789102550314E-5,1.32397831606126E-8,1,4,14.0008964538574,4.99720430069796,33.4299989044666,-0.114596377531622,-0.0172374786283593,1,1.33558823687916E-7,,,,,,,,,,,,,,,,,,,,,397.825408935547,398.137298583984,4999.6396484375,4999.6396484375,53.5997848919961,5.87334994485776,13.6561412811279,56,1,0,0,1,0.329513549804687,32.2580642700195,2,1,3,397.825408935547,0,397.981353759766,,,,,,,,,,,,,,,,,,,,,,,,,,,,,,,,,
,3881323288.55027,393.685089111328,4999.6396484375,-9.22850247388011E-5,1.20709847284412E-8,1,4,14.0008964538574,4.99730568315242,33.4200002253056,-0.114609413782945,-0.0172247085377321,1,1.45167068136053E-7,,,,,,,,,,,,,,,,,,,,,393.497406005859,393.872772216797,4999.6396484375,4999.6396484375,53.4501030305633,5.87423132086037,13.6818723678589,54,1,64,0,0,0.32867431640625,32.2580642700195,2,1,3,393.497406005859,0,393.685089111328,,,,,,,,,,,,,,,,,,,,,,,,,,,,,,,,,
,3881323336.35138,389.40950012207,4999.6396484375,-9.22788936695941E-5,1.16716941354404E-8,1,4,14.0008964538574,4.99727145955305,33.4200002253056,-0.114599794922747,-0.0172293621517995,1,1.40354658511587E-7,,,,,,,,,,,,,,,,,,,,,389.227966308594,389.591033935547,4999.6396484375,4999.6396484375,53.5907961640249,5.87319516486242,13.6894941329956,56,1,0,0,1,0.328903198242188,32.7468223571777,2,1,3,389.227966308594,0,389.40950012207,,,,,,,,,,,,,,,,,,,,,,,,,,,,,,,,,
,3881323384.33579,385.460266113281,4999.6396484375,-9.22558425294876E-5,9.45823147076158E-9,1,4,14.0008964538574,4.9972130565497,33.4100015461445,-0.114568477472789,-0.0172301474439956,1,1.35993638735838E-7,,,,,,,,,,,,,,,,,,,,,385.312622070313,385.60791015625,4999.6396484375,4999.6396484375,53.5704738225249,5.87282985928409,13.7152519226074,56,1,0,0,1,0.32989501953125,32.7468223571777,2,1,3,385.312622070313,0,385.460266113281,,,,,,,,,,,,,,,,,,,,,,,,,,,,,,,,,
,3881323432.34365,381.730239868164,4999.6396484375,-9.22607752421795E-5,1.14170871815186E-8,1,4,14.0008964538574,4.99722863720484,33.390000462532,-0.114576587037773,-0.017221376369716,1,1.43867921494997E-7,,,,,,,,,,,,,,,,,,,,,381.563873291016,381.896606445313,4999.6396484375,4999.6396484375,53.5153690119191,5.87307048459427,13.7269592285156,56,1,0,0,1,0.324935913085937,32.7468223571777,2,1,3,381.563873291016,0,381.730239868164,,,,,,,,,,,,,,,,,,,,,,,,,,,,,,,,,
,3881323480.33643,377.959396362305,4999.6396484375,-9.22582820600892E-5,1.03122223760395E-8,1,4,14.0008964538574,4.99724454547303,33.390000462532,-0.114574459221236,-0.0172179742993296,1,1.46291124636199E-7,,,,,,,,,,,,,,,,,,,,,377.780242919922,378.138549804687,4999.6396484375,4999.6396484375,53.6036930345922,5.87350789168215,13.7243595123291,56,1,0,0,1,0.32501220703125,32.7468223571777,2,1,3,377.780242919922,0,377.959396362305,,,,,,,,,,,,,,,,,,,,,,,,,,,,,,,,,
,3881323528.32446,374.074279785156,4999.6396484375,-9.22583667714007E-5,1.04829557966602E-8,1,4,14.0008964538574,4.99720329173678,33.390000462532,-0.114571884314547,-0.017226716874347,1,1.39102181553246E-7,,,,,,,,,,,,,,,,,,,,,373.913330078125,374.235229492188,4999.6396484375,4999.6396484375,53.5607034660345,5.87382517033782,13.739429473877,56,1,0,0,1,0.324859619140625,33.2355842590332,2,1,3,373.913330078125,0,374.074279785156,,,,,,,,,,,,,,,,,,,,,,,,,,,,,,,,,
,3881323576.32152,370.110702514648,4999.6396484375,-9.22811142073495E-5,1.05738256909737E-8,1,4,14.0008964538574,4.99717525291023,33.3699993789196,-0.114600933967747,-0.0172196318640752,1,1.48155020150201E-7,,,,,,,,,,,,,,,,,,,,,369.948303222656,370.273101806641,4999.6396484375,4999.6396484375,53.5712554510441,5.87369198703896,13.7334508895874,56,1,0,0,1,0.330352783203125,32.7468223571777,2,1,3,369.948303222656,0,370.110702514648,,,,,,,,,,,,,,,,,,,,,,,,,,,,,,,,,
,3881323624.31793,366.15234375,4999.6396484375,-9.23019716371174E-5,9.1396144370077E-9,1,4,14.0008964538574,4.99723238727773,33.3699993789196,-0.114626947307991,-0.0172351477065822,1,1.39048464173442E-7,,,,,,,,,,,,,,,,,,,,,365.996856689453,366.307830810547,4999.6396484375,4999.6396484375,53.6376938751787,5.87322132452181,13.7427091598511,56,1,0,0,1,0.325164794921875,32.2580642700195,2,1,3,365.996856689453,0,366.15234375,,,,,,,,,,,,,,,,,,,,,,,,,,,,,,,,,
,3881323672.29775,362.098571777344,4999.6396484375,-9.23155271548829E-5,9.79478960489462E-9,1,4,14.0008964538574,4.99720652377978,33.3699993789196,-0.114644296166183,-0.0172286965721653,1,1.46202873250112E-7,,,,,,,,,,,,,,,,,,,,,361.927154541016,362.269989013672,4999.6396484375,4999.6396484375,53.684200772073,5.87370456665537,13.7334222793579,56,1,0,0,1,0.324249267578125,33.7243423461914,2,1,3,361.927154541016,0,362.098571777344,,,,,,,,,,,,,,,,,,,,,,,,,,,,,,,,,
,3881323720.30392,358.065231323242,4999.6396484375,-9.2369226181385E-5,1.13993337607493E-8,1,4,14.0008964538574,4.9972120293174,33.3499982953072,-0.114712109466745,-0.0172324980002411,1,1.51319359224121E-7,,,,,,,,,,,,,,,,,,,,,357.897827148438,358.232635498047,4999.6396484375,4999.6396484375,53.5743819651211,5.87399760776073,13.7403230667114,56,1,0,0,1,0.326309204101562,33.2355842590332,2,1,3,357.897827148438,0,358.065231323242,,,,,,,,,,,,,,,,,,,,,,,,,,,,,,,,,
,3881323768.33509,353.951614379883,4999.6396484375,-9.23853217029193E-5,1.30807598161716E-8,1,4,14.0008964538574,4.99720874120016,33.3499982953072,-0.114730476611218,-0.0172454650119143,1,1.43307484789618E-7,,,,,,,,,,,,,,,,,,,,,353.782440185547,354.120788574219,4999.6396484375,4999.6396484375,53.5864972071691,5.87384484867129,13.7339944839478,56,1,0,0,1,0.326919555664063,32.7468223571777,2,1,3,353.782440185547,0,353.951614379883,,,,,,,,,,,,,,,,,,,,,,,,,,,,,,,,,
,3881323816.29396,349.929641723633,4999.6396484375,-9.2404233054208E-5,1.25809765201852E-8,1,4,14.0008964538574,4.99719246456111,33.3499982953072,-0.114755399016994,-0.0172360112358554,1,1.53731131744114E-7,,,,,,,,,,,,,,,,,,,,,349.749725341797,350.109558105469,4999.6396484375,4999.6396484375,53.5478065954672,5.87374038627632,13.7240295410156,56,1,0,0,1,0.325088500976562,33.2355842590332,2,1,3,349.749725341797,0,349.929641723633,,,,,,,,,,,,,,,,,,,,,,,,,,,,,,,,,
,3881323864.33984,345.944763183594,4999.6396484375,-9.24040063604286E-5,1.13635080946976E-8,1,4,14.0008964538574,4.99727406159164,33.330000936985,-0.114755580034261,-0.0172505893100504,1,1.42272699526281E-7,,,,,,,,,,,,,,,,,,,,,345.776245117188,346.11328125,4999.6396484375,4999.6396484375,53.5353005391595,5.87316461607619,13.732590675354,56,1,0,0,1,0.326385498046875,33.2355842590332,2,1,3,345.776245117188,0,345.944763183594,,,,,,,,,,,,,,,,,,,,,,,,,,,,,,,,,
,3881323912.49189,341.878219604492,4999.6396484375,-9.24336813960625E-5,9.38462554978496E-9,1,4,14.0008964538574,4.99724918134759,33.330000936985,-0.114793089397589,-0.0172464208013584,1,1.50040863804184E-7,,,,,,,,,,,,,,,,,,,,,341.699127197266,342.057312011719,4999.6396484375,4999.6396484375,53.5861063929095,5.87311632904876,13.7183046340942,56,1,0,0,1,0.324783325195313,33.7243423461914,2,1,3,341.699127197266,0,341.878219604492,,,,,,,,,,,,,,,,,,,,,,,,,,,,,,,,,
,3881323960.28307,337.869110107422,4999.6396484375,-9.24468514054953E-5,1.15525102836933E-8,1,4,14.0008964538574,4.99724666939752,33.3199985325336,-0.11480875318369,-0.0172528896875447,1,1.46821441165397E-7,,,,,,,,,,,,,,,,,,,,,337.721954345703,338.016265869141,4999.6396484375,4999.6396484375,53.5708646367845,5.87310349062212,13.7269744873047,56,1,0,0,1,0.324935913085937,33.7243423461914,2,1,3,337.721954345703,0,337.869110107422,,,,,,,,,,,,,,,,,,,,,,,,,,,,,,,,,
,3881324008.27989,333.869430541992,4999.6396484375,-9.24719672702712E-5,1.02353622197061E-8,1,4,14.0008964538574,4.99725242435836,33.3199985325336,-0.114842206676122,-0.0172439299152679,1,1.57875292405157E-7,,,,,,,,,,,,,,,,,,,,,333.691864013672,334.046997070313,4999.6396484375,4999.6396484375,53.5587493947364,5.87363805990607,13.7199306488037,56,1,0,0,1,0.32470703125,33.2355842590332,2,1,3,333.691864013672,0,333.869430541992,,,,,,,,,,,,,,,,,,,,,,,,,,,,,,,,,
,3881324056.50458,329.965469360352,4999.6396484375,-9.24735211984401E-5,1.05602923672389E-8,1,4,14.0008964538574,4.99726443988719,33.3099998533726,-0.114844798370337,-0.0172424657988185,1,1.59337309584399E-7,,,,,,,,,,,,,,,,,,,,,329.834106445313,330.096832275391,4999.6396484375,4999.6396484375,53.5489790382461,5.87289360749776,13.7136859893799,55,1,64,0,0,0.329513549804687,33.7243423461914,2,1,3,329.834106445313,0,329.965469360352,,,,,,,,,,,,,,,,,,,,,,,,,,,,,,,,,
,3881324104.27536,325.957672119141,4999.6396484375,-9.24789248463121E-5,1.15712633841095E-8,1,4,14.0008964538574,4.99726954444688,33.2899987697601,-0.11484828232726,-0.0172658233256683,1,1.41365506091413E-7,,,,,,,,,,,,,,,,,,,,,325.806427001953,326.108917236328,4999.6396484375,4999.6396484375,53.4243092894287,5.87298170614012,13.7209825515747,56,1,0,0,1,0.327072143554687,33.7243423461914,2,1,3,325.806427001953,0,325.957672119141,,,,,,,,,,,,,,,,,,,,,,,,,,,,,,,,,
,3881324152.2664,321.942077636719,4999.6396484375,-9.24760668038218E-5,9.68365293588099E-9,1,4,14.0008964538574,4.99719906437056,33.2899987697601,-0.114844347827622,-0.0172525546469002,1,1.51343754480015E-7,,,,,,,,,,,,,,,,,,,,,321.764587402344,322.119567871094,4999.6396484375,4999.6396484375,53.552105552323,5.87287315436051,13.7122840881348,56,1,0,0,1,0.329132080078125,33.2355842590332,2,1,3,321.764587402344,0,321.942077636719,,,,,,,,,,,,,,,,,,,,,,,,,,,,,,,,,
,3881324200.25612,317.879791259766,4999.6396484375,-9.24900219394591E-5,1.01795480786677E-8,1,4,14.0008964538574,4.99718724122891,33.2899987697601,-0.114861874613144,-0.0172513047423827,1,1.54424214436606E-7,,,,,,,,,,,,,,,,,,,,,317.712707519531,318.046875,4999.6396484375,4999.6396484375,53.5864972071691,5.87283763354424,13.7071981430054,56,1,0,0,1,0.329971313476562,33.2355842590332,2,1,3,317.712707519531,0,317.879791259766,,,,,,,,,,,,,,,,,,,,,,,,,,,,,,,,,
,3881324248.25756,313.909042358398,4999.6396484375,-9.24792270535736E-5,1.04052700695675E-8,1,4,14.0008964538574,4.99718529236531,33.2899987697601,-0.114845558895116,-0.0172680245872201,1,1.39310177425308E-7,,,,,,,,,,,,,,,,,,,,,313.72705078125,314.091033935547,4999.6396484375,4999.6396484375,53.6298775899864,5.8727272624222,13.7011709213257,56,1,0,0,1,0.328445434570313,33.7243423461914,2,1,3,313.72705078125,0,313.909042358398,,,,,,,,,,,,,,,,,,,,,,,,,,,,,,,,,
,3881324296.30986,309.92448425293,4999.6396484375,-9.24594351885315E-5,9.9005791292548E-9,1,4,14.0008964538574,4.99717474328951,33.270001411438,-0.114822052720618,-0.0172549838239919,1,1.46766186098905E-7,,,,,,,,,,,,,,,,,,,,,309.754302978516,310.094665527344,4999.6396484375,4999.6396484375,53.6380846894384,5.87304748430749,13.6976222991943,55,1,64,0,0,0.328445434570313,33.7243423461914,2,1,3,309.754302978516,0,309.92448425293,,,,,,,,,,,,,,,,,,,,,,,,,,,,,,,,,
,3881324344.26489,305.921203613281,4999.6396484375,-9.24709148790601E-5,9.49265031943036E-9,1,4,14.0008964538574,4.99714507701817,33.270001411438,-0.114836153451586,-0.017251722474964,1,1.51021253241068E-7,,,,,,,,,,,,,,,,,,,,,305.754058837891,306.088348388672,4999.6396484375,4999.6396484375,53.6150266481211,5.87300003130288,13.69837474823,56,1,0,0,1,0.325775146484375,33.2355842590332,2,1,3,305.754058837891,0,305.921203613281,,,,,,,,,,,,,,,,,,,,,,,,,,,,,,,,,
,3881324392.24253,301.887329101562,4999.6396484375,-9.24478589308251E-5,1.15847932474551E-8,1,4,14.0008964538574,4.99712659156809,33.270001411438,-0.114807023329998,-0.0172466943229947,1,1.51497003687145E-7,,,,,,,,,,,,,,,,,,,,,301.744812011719,302.029846191406,4999.6396484375,4999.6396484375,53.6040838488518,5.8730767946309,13.6880531311035,56,1,0,0,1,0.32684326171875,33.2355842590332,2,1,3,301.744812011719,0,301.887329101562,,,,,,,,,,,,,,,,,,,,,,,,,,,,,,,,,
,3881324440.22856,297.852294921875,4999.6396484375,-9.24246090993535E-5,9.95834045180955E-9,1,4,14.0008964538574,4.99716675002242,33.2500003278255,-0.114780118995137,-0.017238092973356,1,1.55049513733683E-7,,,,,,,,,,,,,,,,,,,,,297.714752197266,297.989837646484,4999.6396484375,4999.6396484375,53.6853732148518,5.87295798188185,13.6800441741943,56,1,0,0,1,0.328140258789063,33.7243423461914,2,1,3,297.714752197266,0,297.852294921875,,,,,,,,,,,,,,,,,,,,,,,,,,,,,,,,,
,3881324488.23763,293.861602783203,4999.6396484375,-9.23671875213359E-5,1.00347560205912E-8,1,4,14.0008964538574,4.99716720666597,33.2500003278255,-0.114710064692605,-0.017219211437541,1,1.61536870009001E-7,,,,,,,,,,,,,,,,,,,,,293.694458007812,294.028747558594,4999.6396484375,4999.6396484375,53.6337857325826,5.87274172156922,13.6773853302002,56,1,0,0,1,0.324783325195313,33.2355842590332,2,1,3,293.694458007812,0,293.861602783203,,,,,,,,,,,,,,,,,,,,,,,,,,,,,,,,,
,3881324536.22876,289.851043701172,4999.6396484375,-9.23055461670871E-5,1.18949887928972E-8,1,4,14.0008964538574,4.99713646914909,33.2500003278255,-0.114633052876488,-0.0172041004402228,1,1.64225199103967E-7,,,,,,,,,,,,,,,,,,,,,289.683990478516,290.018096923828,4999.6396484375,4999.6396484375,53.5556228806595,5.87289545175865,13.6597757339478,56,1,0,0,1,0.324935913085937,33.7243423461914,2,1,3,289.683990478516,0,289.851043701172,,,,,,,,,,,,,,,,,,,,,,,,,,,,,,,,,
,3881324584.2763,285.882415771484,4999.6396484375,-9.21821701277579E-5,1.20983549992271E-8,1,4,14.0008964538574,4.99717857546016,33.2500003278255,-0.114481562232332,-0.0171788204735542,1,1.66009276222426E-7,,,,,,,,,,,,,,,,,,,,,285.741912841797,286.022918701172,4999.6396484375,4999.6396484375,53.6103368770057,5.87331433388344,13.657413482666,56,1,0,0,1,0.325164794921875,33.7243423461914,2,1,3,285.741912841797,0,285.882415771484,,,,,,,,,,,,,,,,,,,,,,,,,,,,,,,,,
,3881324632.22161,281.849456787109,4999.6396484375,-9.21995747196273E-5,1.0656170258057E-8,1,4,14.0008964538574,4.99715185662512,33.2299992442131,-0.114501999653514,-0.0171840436397904,1,1.64342492951643E-7,,,,,,,,,,,,,,,,,,,,,281.672149658203,282.026763916016,4999.6396484375,4999.6396484375,53.6326132898038,5.87364882140837,13.6568651199341,56,1,0,0,1,0.324783325195313,33.2355842590332,2,1,3,281.672149658203,0,281.849456787109,,,,,,,,,,,,,,,,,,,,,,,,,,,,,,,,,
,3881324680.19832,277.951416015625,4999.6396484375,-9.22844760013507E-5,1.15290721909714E-8,1,4,14.0008964538574,4.9971279971866,33.2299992442131,-0.114606191845177,-0.0172029121238174,1,1.61948884037892E-7,,,,,,,,,,,,,,,,,,,,,277.801300048828,278.101531982422,4999.6396484375,4999.6396484375,53.391480891621,5.87334032567336,13.6461029052734,56,1,0,0,1,0.329513549804687,33.2355842590332,2,1,3,277.793975830078,0,277.951416015625,,,,,,,,,,,,,,,,,,,,,,,,,,,,,,,,,
,3881324728.40351,273.902633666992,4999.6396484375,-9.22516407370393E-5,9.80191390656098E-9,1,4,14.0008964538574,4.99707359129968,33.2299992442131,-0.114564859096308,-0.0171886876620258,1,1.68207210315751E-7,,,,,,,,,,,,,,,,,,,,,273.721313476562,274.083953857422,4999.6396484375,4999.6396484375,53.6044746631114,5.87256563938574,13.6423501968384,56,1,0,0,1,0.326766967773438,33.7243423461914,2,1,3,273.721313476562,0,273.902633666992,,,,,,,,,,,,,,,,,,,,,,,,,,,,,,,,,
,3881324776.19904,269.932922363281,4999.6396484375,-9.22848545757254E-5,1.07651433787426E-8,1,4,14.0008964538574,4.99709521231996,33.220000565052,-0.11460550958306,-0.0172034806240181,1,1.61421207689367E-7,,,,,,,,,,,,,,,,,,,,,269.753112792969,270.112731933594,4999.6396484375,4999.6396484375,53.5736003366018,5.87310556005198,13.6316776275635,56,1,0,0,1,0.325393676757812,33.7243423461914,2,1,3,269.753112792969,0,269.932922363281,,,,,,,,,,,,,,,,,,,,,,,,,,,,,,,,,
,3881324824.37496,265.945846557617,4999.6396484375,-9.22941888763095E-5,1.19211522240158E-8,1,4,14.0008964538574,4.99715575576522,33.2099981606007,-0.114619065510494,-0.0172053832466495,1,1.61541690046243E-7,,,,,,,,,,,,,,,,,,,,,265.807189941406,266.084503173828,4999.6396484375,4999.6396484375,53.5880604642076,5.87435047359832,13.6183853149414,55,1,64,0,0,0.324859619140625,32.7468223571777,2,1,3,265.807189941406,0,265.945846557617,,,,,,,,,,,,,,,,,,,,,,,,,,,,,,,,,
,3881324872.20829,261.918380737305,4999.6396484375,-9.22847639162343E-5,1.18131479573307E-8,1,4,14.0008964538574,4.99710128578826,33.2099981606007,-0.114604985282206,-0.0172074873582809,1,1.58203785238566E-7,,,,,,,,,,,,,,,,,,,,,261.748291015625,262.088470458984,4999.6396484375,4999.6396484375,53.6263602616499,5.87303450380441,13.6117725372314,56,1,0,0,1,0.32501220703125,33.2355842590332,2,1,3,261.748291015625,0,261.918380737305,,,,,,,,,,,,,,,,,,,,,,,,,,,,,,,,,
,3881324920.39015,257.919998168945,4999.6396484375,-9.22683108143162E-5,9.44169579014761E-9,1,4,14.0008964538574,4.99704728863966,33.1900008022785,-0.11458487141404,-0.0171906487762739,1,1.69057744936181E-7,,,,,,,,,,,,,,,,,,,,,257.795593261719,258.044403076172,4999.6396484375,4999.6396484375,53.6197164192364,5.87348086505583,13.6062421798706,56,1,0,0,1,0.326614379882812,33.2355842590332,2,1,3,257.776611328125,0,257.919998168945,,,,,,,,,,,,,,,,,,,,,,,,,,,,,,,,,
,3881324968.20973,253.973236083984,4999.6396484375,-9.22763653690487E-5,9.66887782902679E-9,1,4,14.0008964538574,4.99707244338962,33.1900008022785,-0.114595079806243,-0.0171962335999701,1,1.65880476992866E-7,,,,,,,,,,,,,,,,,,,,,253.817901611328,254.128570556641,4999.6396484375,4999.6396484375,53.567347308448,5.87355974462559,13.5943336486816,56,1,0,0,1,0.326995849609375,33.7243423461914,2,1,3,253.817901611328,0,253.973236083984,,,,,,,,,,,,,,,,,,,,,,,,,,,,,,,,,
,3881325016.41657,249.936416625977,4999.6396484375,-9.22365057219332E-5,8.73667165874699E-9,1,4,14.0008964538574,4.99701679892156,33.1900008022785,-0.11454433327842,-0.0171849838449223,1,1.68671213463505E-7,,,,,,,,,,,,,,,,,,,,,249.767761230469,250.105072021484,4999.6396484375,4999.6396484375,53.5700830082653,5.87334163515669,13.5968008041382,56,1,0,0,1,0.324935913085937,33.7243423461914,2,1,3,249.767761230469,0,249.936416625977,,,,,,,,,,,,,,,,,,,,,,,,,,,,,,,,,
,3881325064.16334,245.899467468262,4999.6396484375,-9.22827484362145E-5,8.99160947678194E-9,1,4,14.0008964538574,4.99703678010022,33.1900008022785,-0.114600282931103,-0.0172076438058492,1,1.57521116647144E-7,,,,,,,,,,,,,,,,,,,,,245.715835571289,246.083099365234,4999.6396484375,4999.6396484375,53.6165899051595,5.87348501579812,13.5843534469604,56,1,0,0,1,0.324630737304687,33.7243423461914,2,1,3,245.715835571289,0,245.899467468262,,,,,,,,,,,,,,,,,,,,,,,,,,,,,,,,,
,3881325112.17662,241.941711425781,4999.6396484375,-9.22571714239626E-5,8.64046267006236E-9,1,4,14.0008964538574,4.99703513894329,33.1699997186661,-0.114569855420397,-0.0171937310212861,1,1.64835894169654E-7,,,,,,,,,,,,,,,,,,,,,241.746688842773,242.136734008789,4999.6396484375,4999.6396484375,53.4977823702364,5.87351580688785,13.5793447494507,56,1,0,0,1,0.324935913085937,33.7243423461914,2,1,3,241.746688842773,0,241.941711425781,,,,,,,,,,,,,,,,,,,,,,,,,,,,,,,,,
,3881325160.18184,237.883827209473,4999.6396484375,-9.22293687048913E-5,1.14654810326852E-8,1,4,14.0008964538574,4.99706767422382,33.1699997186661,-0.114536601631203,-0.0171871988158093,1,1.66000352250948E-7,,,,,,,,,,,,,,,,,,,,,237.721633911133,238.046020507813,4999.6396484375,4999.6396484375,53.6376938751787,5.87350903385734,13.5723276138306,56,1,0,0,1,0.325469970703125,33.2355842590332,2,1,3,237.721633911133,0,237.883827209473,,,,,,,,,,,,,,,,,,,,,,,,,,,,,,,,,
,3881325208.17964,233.885375976562,4999.6396484375,-9.22051553438785E-5,1.36337185876718E-8,1,4,14.0008964538574,4.99705485731821,33.1699997186661,-0.114507414391225,-0.0171741077405943,1,1.72817007944442E-7,,,,,,,,,,,,,,,,,,,,,233.712387084961,234.058364868164,4999.6396484375,4999.6396484375,53.5798533647557,5.87314903448243,13.5567502975464,56,1,0,0,1,0.325164794921875,33.7243423461914,2,1,3,233.712387084961,0,233.885375976562,,,,,,,,,,,,,,,,,,,,,,,,,,,,,,,,,
,3881325256.14737,229.962844848633,4999.6396484375,-9.21736263300739E-5,8.38164849667721E-9,1,4,14.0008964538574,4.99700834067494,33.1699997186661,-0.114466151574965,-0.0171720649040787,1,1.69492917768677E-7,,,,,,,,,,,,,,,,,,,,,229.807922363281,230.117767333984,4999.6396484375,4999.6396484375,53.5560136949191,5.87314687549305,13.558590888977,56,1,0,0,1,0.325393676757812,33.7243423461914,2,1,3,229.807922363281,0,229.962844848633,,,,,,,,,,,,,,,,,,,,,,,,,,,,,,,,,
,3881325304.1433,226.009468078613,4999.6396484375,-9.21418559609504E-5,1.11239079137646E-8,1,4,14.0008964538574,4.99704431170842,33.1499986350536,-0.114428183426082,-0.0171641288774744,1,1.71198613145103E-7,,,,,,,,,,,,,,,,,,,,,225.859710693359,226.159225463867,4999.6396484375,4999.6396484375,53.6392571322172,5.87336277219194,13.5398225784302,56,1,0,0,1,0.329360961914063,33.7243423461914,2,1,3,225.859710693359,0,226.009468078613,,,,,,,,,,,,,,,,,,,,,,,,,,,,,,,,,
,3881325352.15933,221.965728759766,4999.6396484375,-9.21016667414562E-5,9.99270499452021E-9,1,4,14.0008964538574,4.9969587561361,33.1499986350536,-0.114375317342313,-0.0171576425597323,1,1.69987089122728E-7,,,,,,,,,,,,,,,,,,,,,221.802856445313,222.128601074219,4999.6396484375,4999.6396484375,53.643556089073,5.87349735190279,13.5344591140747,56,1,0,0,1,0.328903198242188,33.7243423461914,2,1,3,221.802856445313,0,221.965728759766,,,,,,,,,,,,,,,,,,,,,,,,,,,,,,,,,
,3881325400.17716,217.902488708496,4999.6396484375,-9.20789357388387E-5,1.30756059159374E-8,1,4,14.0008964538574,4.99705413604471,33.1499986350536,-0.114350320593782,-0.0171527113592603,1,1.70875504428716E-7,,,,,,,,,,,,,,,,,,,,,217.734115600586,218.070861816406,4999.6396484375,4999.6396484375,53.6216704905345,5.87392347910379,13.5275421142578,56,1,0,0,1,0.329971313476562,33.2355842590332,2,1,3,217.734115600586,0,217.902488708496,,,,,,,,,,,,,,,,,,,,,,,,,,,,,,,,,
,3881325448.14118,213.984886169434,4999.6396484375,-9.19819905633871E-5,1.39012059923094E-8,1,4,14.0008964538574,4.99699541261302,33.1499986350536,-0.114227504567822,-0.0171379443769856,1,1.67816699875556E-7,,,,,,,,,,,,,,,,,,,,,213.846633911133,214.123138427734,4999.6396484375,4999.6396484375,53.5966583779191,5.87341564007338,13.5131063461304,56,1,0,0,1,0.3265380859375,34.2131004333496,2,1,3,213.846633911133,0,213.984886169434,,,,,,,,,,,,,,,,,,,,,,,,,,,,,,,,,
,3881325496.11947,209.996078491211,4999.6396484375,-9.20048809505045E-5,1.10575655358715E-8,1,4,14.0008964538574,4.99709836520869,33.1300012767315,-0.114258822312282,-0.0171453671914084,1,1.65713214687846E-7,,,,,,,,,,,,,,,,,,,,,209.827789306641,210.164367675781,4999.6396484375,4999.6396484375,53.5454617099095,5.87297611645741,13.5163688659668,56,1,0,0,1,0.324935913085937,33.7243423461914,2,1,3,209.827789306641,0,209.996078491211,,,,,,,,,,,,,,,,,,,,,,,,,,,,,,,,,
,3881325544.1426,205.947456359863,4999.6396484375,-9.20079107013683E-5,8.21867990362735E-9,1,4,14.0008964538574,4.99709514855068,33.1300012767315,-0.114263304344336,-0.0171405020111822,1,1.7007966082757E-7,,,,,,,,,,,,,,,,,,,,,205.803375244141,206.091537475586,4999.6396484375,4999.6396484375,53.6271418901691,5.87299158959538,13.4971179962158,56,1,0,0,1,0.326690673828125,33.2355842590332,2,1,3,205.803375244141,0,205.947456359863,,,,,,,,,,,,,,,,,,,,,,,,,,,,,,,,,
,3881325592.13643,202.012870788574,4999.6396484375,-9.19660408716964E-5,9.94567027306633E-9,1,4,14.0008964538574,4.99711051493376,33.1300012767315,-0.114211758935701,-0.0171330364252663,1,1.6979225161779E-7,,,,,,,,,,,,,,,,,,,,,201.855850219727,202.169891357422,4999.6396484375,4999.6396484375,53.7580646671403,5.87294117637967,13.4912176132202,56,1,0,0,1,0.325088500976562,33.2355842590332,2,1,3,201.855850219727,0,202.012870788574,,,,,,,,,,,,,,,,,,,,,,,,,,,,,,,,,
,3881325640.11296,197.98477935791,4999.6396484375,-9.19040671930581E-5,1.71648343304277E-8,1,4,14.0008964538574,4.99706120107634,33.1300012767315,-0.114132713818179,-0.0171245694333431,1,1.67007636363357E-7,,,,,,,,,,,,,,,,,,,,,197.792922973633,198.176635742187,4999.6396484375,4999.6396484375,53.4825406141114,5.87294781076143,13.489354133606,56,1,0,0,1,0.329208374023438,33.2355842590332,2,1,3,197.792922973633,0,197.98477935791,,,,,,,,,,,,,,,,,,,,,,,,,,,,,,,,,
,3881325688.12128,193.95482635498,4999.6396484375,-9.20145448422577E-5,1.05076679719139E-8,1,4,14.0008964538574,4.99704382286289,33.110000193119,-0.114269056992466,-0.0171470401800387,1,1.65622573326245E-7,,,,,,,,,,,,,,,,,,,,,193.785202026367,194.124450683594,4999.6396484375,4999.6396484375,53.6013481490345,5.87304113202316,13.4671030044556,56,1,0,0,1,0.329055786132812,33.2355842590332,2,1,3,193.785202026367,0,193.95482635498,,,,,,,,,,,,,,,,,,,,,,,,,,,,,,,,,
,3881325736.09995,189.931144714355,4999.6396484375,-9.19614150096117E-5,1.33047367523188E-8,1,4,14.0008964538574,4.99703517784989,33.110000193119,-0.114205957160553,-0.0171163173736576,1,1.82264924088838E-7,,,,,,,,,,,,,,,,,,,,,189.7626953125,190.099594116211,4999.6396484375,4999.6396484375,53.5857155786499,5.87314613848346,13.4685773849487,56,1,0,0,1,0.328903198242188,33.2355842590332,2,1,3,189.7626953125,0,189.931144714355,,,,,,,,,,,,,,,,,,,,,,,,,,,,,,,,,
,3881325784.15152,185.983245849609,4999.6396484375,-9.19628072328465E-5,1.62027384985783E-8,1,4,14.0008964538574,4.9970022175643,33.110000193119,-0.114205489364193,-0.0171239367806553,1,1.76211840668099E-7,,,,,,,,,,,,,,,,,,,,,185.833786010742,186.132705688477,4999.6396484375,4999.6396484375,53.5153690119191,5.87294523890346,13.4599628448486,56,1,0,0,1,0.330581665039063,33.2355842590332,2,1,3,185.833786010742,0,185.983245849609,,,,,,,,,,,,,,,,,,,,,,,,,,,,,,,,,
,3881325832.13098,181.929069519043,4999.6396484375,-9.19647070982784E-5,1.21623534672977E-8,1,4,14.0008964538574,4.99697577629502,33.110000193119,-0.114207789097262,-0.0171189858877622,1,1.80386085042211E-7,,,,,,,,,,,,,,,,,,,,,181.779830932617,182.078308105469,4999.6396484375,4999.6396484375,53.5310015823037,5.87320383438665,13.4367570877075,56,1,0,0,1,0.325393676757812,33.7243423461914,2,1,3,181.779830932617,0,181.929069519043,,,,,,,,,,,,,,,,,,,,,,,,,,,,,,,,,
,3881325880.09622,177.935722351074,4999.6396484375,-9.19263202323419E-5,1.73234880886563E-8,1,4,14.0008964538574,4.99692994922091,33.110000193119,-0.114157873014051,-0.0171167479201948,1,1.76180737185388E-7,,,,,,,,,,,,,,,,,,,,,177.7685546875,178.102890014648,4999.6396484375,4999.6396484375,53.6064287344095,5.87258389646034,13.4369821548462,56,1,0,0,1,0.3265380859375,33.7243423461914,2,1,3,177.7685546875,0,177.935722351074,,,,,,,,,,,,,,,,,,,,,,,,,,,,,,,,,
,3881325928.2678,173.951232910156,4999.6396484375,-9.2009250777774E-5,1.08311518784421E-8,1,4,14.0008964538574,4.99702512204987,33.110000193119,-0.114264727345077,-0.0171272437988207,1,1.80691409256001E-7,,,,,,,,,,,,,,,,,,,,,173.790374755859,174.112091064453,4999.6396484375,4999.6396484375,53.6513723742653,5.87325418339115,13.4172258377075,56,1,0,0,1,0.325546264648438,33.2355842590332,2,1,3,173.790374755859,0,173.951232910156,,,,,,,,,,,,,,,,,,,,,,,,,,,,,,,,,
,3881325976.09058,169.960494995117,4999.6396484375,-9.19926324503354E-5,8.47000789417293E-9,1,4,14.0008964538574,4.99700058248102,33.0899991095066,-0.114241779232203,-0.0171340692377253,1,1.72574519568351E-7,,,,,,,,,,,,,,,,,,,,,169.807479858398,170.113510131836,4999.6396484375,4999.6396484375,53.6529356313038,5.87297670987059,13.4194660186768,56,1,0,0,1,0.325469970703125,33.2355842590332,2,1,3,169.807479858398,0,169.960494995117,,,,,,,,,,,,,,,,,,,,,,,,,,,,,,,,,
,3881326024.09717,166.006713867187,4999.6396484375,-9.19584419773206E-5,1.34177901779005E-8,1,4,14.0008964538574,4.9970225767998,33.0899991095066,-0.114201028167621,-0.0171211913732153,1,1.77838786054156E-7,,,,,,,,,,,,,,,,,,,,,165.841720581055,166.17170715332,4999.6396484375,4999.6396484375,53.6009573347749,5.87313077154003,13.4042310714722,56,1,0,0,1,0.326004028320313,33.2355842590332,2,1,3,165.841720581055,0,166.006713867187,,,,,,,,,,,,,,,,,,,,,,,,,,,,,,,,,
,3881326072.07916,161.930999755859,4999.6396484375,-9.19064051476019E-5,1.47523505319719E-8,1,4,14.0008964538574,4.99699341994016,33.0800004303455,-0.114135580265947,-0.0171106529848349,1,1.78310174466981E-7,,,,,,,,,,,,,,,,,,,,,161.781936645508,162.080062866211,4999.6396484375,4999.6396484375,53.5810258075345,5.87255232511032,13.3869476318359,56,1,0,0,1,0.32958984375,33.2355842590332,2,1,3,161.781936645508,0,161.930999755859,,,,,,,,,,,,,,,,,,,,,,,,,,,,,,,,,
,3881326120.06784,157.895874023438,4999.6396484375,-9.17042417906322E-5,2.00066609737073E-8,1,4,14.0008964538574,4.99691443190954,33.0800004303455,-0.113882648069211,-0.0170683683379361,1,1.81356656091147E-7,,,,,,,,,,,,,,,,,,,,,157.717498779297,158.074249267578,4999.6396484375,4999.6396484375,53.6404295749961,5.87315183457522,13.379132270813,56,1,0,0,1,0.324783325195313,33.7243423461914,2,1,3,157.717498779297,0,157.895874023438,,,,,,,,,,,,,,,,,,,,,,,,,,,,,,,,,
,3881326168.07521,153.970199584961,4999.6396484375,-9.17861036209565E-5,1.72481650580893E-8,1,4,14.0008964538574,4.99691798042381,33.0700017511845,-0.113983579979575,-0.017089160346093,1,1.77057273280851E-7,,,,,,,,,,,,,,,,,,,,,153.811721801758,154.128677368164,4999.6396484375,4999.6396484375,53.5990032634768,5.8727993166348,13.3608417510986,56,1,0,0,1,0.325851440429687,33.2355842590332,2,1,3,153.811721801758,0,153.970199584961,,,,,,,,,,,,,,,,,,,,,,,,,,,,,,,,,
,3881326216.0766,149.956581115723,4999.6396484375,-9.15782901279156E-5,2.5683554347736E-8,1,4,14.0008964538574,4.99683132149891,33.0700017511845,-0.113721803352289,-0.0170562701691386,1,1.71649709481553E-7,,,,,,,,,,,,,,,,,,,,,149.777557373047,150.135604858398,4999.6396484375,4999.6396484375,53.5794625504961,5.87259715878229,13.3613328933716,56,1,0,0,1,0.3253173828125,33.2355842590332,2,1,3,149.777557373047,0,149.956581115723,,,,,,,,,,,,,,,,,,,,,,,,,,,,,,,,,
,3881326264.06338,145.880844116211,4999.6396484375,-9.15723067899542E-5,2.34043867815705E-8,1,4,14.0008964538574,4.99690787918181,33.0700017511845,-0.113719294828037,-0.0170391812632223,1,1.84800613237015E-7,,,,,,,,,,,,,,,,,,,,,145.712188720703,146.049499511719,4999.6396484375,4999.6396484375,53.633394918323,5.87231449508149,13.3352832794189,56,1,0,0,1,0.324935913085937,33.2355842590332,2,1,3,145.712188720703,0,145.880844116211,,,,,,,,,,,,,,,,,,,,,,,,,,,,,,,,,
,3881326312.05448,141.732864379883,4999.6396484375,-9.16080943562969E-5,2.43362284070232E-8,1,4,14.0008964538574,4.99690242113047,33.050000667572,-0.113761734122149,-0.0170578590777538,1,1.75170816140849E-7,,,,,,,,,,,,,,,,,,,,,141.537658691406,141.928070068359,4999.6396484375,4999.6396484375,53.5841523216114,5.87117150227212,13.3251523971558,56,1,0,0,1,0.32501220703125,33.7243423461914,2,1,3,141.537658691406,0,141.732864379883,,,,,,,,,,,,,,,,,,,,,,,,,,,,,,,,,
,3881326360.05679,137.750595092773,4999.6396484375,-9.14791791836577E-5,2.95932188903907E-8,1,4,14.0008964538574,4.99674650646654,33.050000667572,-0.113596078756434,-0.0170370695392928,1,1.71734991170442E-7,,,,,,,,,,,,,,,,,,,,,137.589279174805,137.911911010742,4999.6396484375,4999.6396484375,53.5423351958326,5.87292117583377,13.3108186721802,56,1,0,0,1,0.329208374023438,33.2355842590332,2,1,3,137.589279174805,0,137.750595092773,,,,,,,,,,,,,,,,,,,,,,,,,,,,,,,,,
,3881326408.04257,133.816581726074,4999.6396484375,-9.13237906772332E-5,2.08532708555833E-8,1,4,14.0008964538574,4.99660184116419,33.050000667572,-0.113398616603236,-0.0170068357914121,1,1.71930419282107E-7,,,,,,,,,,,,,,,,,,,,,133.614379882812,134.018783569336,4999.6396484375,4999.6396484375,53.5599218375153,5.87287881317126,13.2901525497437,56,1,0,0,1,0.329055786132812,33.7243423461914,2,1,3,133.614379882812,0,133.816581726074,,,,,,,,,,,,,,,,,,,,,,,,,,,,,,,,,
,3881326456.28128,129.732421875,4999.6396484375,-9.14317198196737E-5,2.91576429361804E-8,1,4,14.0008964538574,4.99667696851095,33.050000667572,-0.113536826463328,-0.0170154318713915,1,1.81688676866172E-7,,,,,,,,,,,,,,,,,,,,,129.607070922852,129.857772827148,4999.6396484375,4999.6396484375,53.5044262126499,5.87206258470049,13.2830877304077,55,1,64,0,0,0.324630737304687,33.2355842590332,2,1,3,129.607070922852,0,129.732421875,,,,,,,,,,,,,,,,,,,,,,,,,,,,,,,,,
,3881326504.0305,125.856502532959,4999.6396484375,-9.12921918336134E-5,2.30159418068445E-8,1,4,14.0008964538574,4.99674449159486,33.050000667572,-0.113364207035394,-0.0169996842553511,1,1.73439020583802E-7,,,,,,,,,,,,,,,,,,,,,125.704559326172,126.008445739746,4999.6396484375,4999.6396484375,53.4891844565249,5.87109320044631,13.2523899078369,56,1,0,0,1,0.329666137695313,33.2355842590332,2,1,3,125.704559326172,0,125.856502532959,,,,,,,,,,,,,,,,,,,,,,,,,,,,,,,,,
,3881326552.01767,121.778343200684,4999.6396484375,-9.13395259505307E-5,3.14528774449279E-8,1,4,14.0008964538574,4.99657141535004,33.0299995839596,-0.113420321195019,-0.0169889966044749,1,1.88574522767619E-7,,,,,,,,,,,,,,,,,,,,,121.60676574707,121.949920654297,4999.6396484375,4999.6396484375,53.4778508429961,5.87162433995377,13.2482776641846,56,1,0,0,1,0.326080322265625,33.7243423461914,2,1,3,121.60676574707,0,121.778343200684,,,,,,,,,,,,,,,,,,,,,,,,,,,,,,,,,
,3881326600.031,117.828678131104,4999.6396484375,-9.12569986185005E-5,2.53365036630336E-8,1,4,14.0008964538574,4.99667146121068,33.0299995839596,-0.113316333111676,-0.0170049807752577,1,1.63546334937143E-7,,,,,,,,,,,,,,,,,,,,,117.637832641602,118.019523620605,4999.6396484375,4999.6396484375,53.5536688093614,5.87032596253945,13.2141351699829,56,1,0,0,1,0.3253173828125,33.2355842590332,2,1,3,117.637832641602,0,117.828678131104,,,,,,,,,,,,,,,,,,,,,,,,,,,,,,,,,
,3881326648.09014,113.846996307373,4999.6396484375,-9.1317810606483E-5,3.70768805824751E-8,1,4,14.0008964538574,4.99649069523427,33.0299995839596,-0.113385270716486,-0.0170209162992472,1,1.59252199112655E-7,,,,,,,,,,,,,,,,,,,,,113.687599182129,114.006393432617,4999.6396484375,4999.6396484375,53.528656696746,5.87154981708913,13.2070274353027,54,1,64,0,0,0.326004028320313,33.2355842590332,2,1,3,113.687599182129,0,113.846996307373,,,,,,,,,,,,,,,,,,,,,,,,,,,,,,,,,
,3881326696.01103,109.767826080322,4999.6396484375,-9.12455094055052E-5,3.19218661455441E-8,1,4,14.0008964538574,4.9965884523085,33.0299995839596,-0.113302235610389,-0.0169839808633587,1,1.78399321185786E-7,,,,,,,,,,,,,,,,,,,,,109.610877990723,109.924774169922,4999.6396484375,4999.6396484375,53.5884512784672,5.87149294042207,13.1845617294312,56,1,0,0,1,0.32623291015625,33.2355842590332,2,1,3,109.610877990723,0,109.767826080322,,,,,,,,,,,,,,,,,,,,,,,,,,,,,,,,,
,3881326744.01001,105.775909423828,4999.6396484375,-9.11982663534067E-5,2.83526758411517E-8,1,4,14.0008964538574,4.99657792530372,33.0299995839596,-0.113241530756021,-0.0169863794104364,1,1.69250566895468E-7,,,,,,,,,,,,,,,,,,,,,105.605682373047,105.946136474609,4999.6396484375,4999.6396484375,53.5556228806595,5.87069321288,13.1526727676392,56,1,0,0,1,0.326080322265625,33.2355842590332,2,1,3,105.605682373047,0,105.775909423828,,,,,,,,,,,,,,,,,,,,,,,,,,,,,,,,,
,3881326792.04374,101.82413482666,4999.6396484375,-9.12832778915295E-5,3.25318264641026E-8,1,4,14.0008964538574,4.99647399720089,33.0099985003471,-0.113345563198442,-0.0169900377382049,1,1.78818097048135E-7,,,,,,,,,,,,,,,,,,,,,101.655014038086,101.993255615234,4999.6396484375,4999.6396484375,53.6048654773711,5.87161210912807,13.1389284133911,56,1,0,0,1,0.329818725585937,33.7243423461914,2,1,3,101.655014038086,0,101.82413482666,,,,,,,,,,,,,,,,,,,,,,,,,,,,,,,,,
,3881326839.99856,97.8492851257324,4999.6396484375,-9.12453277876672E-5,2.7407065088755E-8,1,4,14.0008964538574,4.99656358309018,33.0099985003471,-0.113300312595195,-0.0169898053394953,1,1.73584337674847E-7,,,,,,,,,,,,,,,,,,,,,97.6582717895508,98.0402984619141,4999.6396484375,4999.6396484375,53.6036930345922,5.87059056938157,13.0980377197266,56,1,0,0,1,0.323638916015625,33.7243423461914,2,1,3,97.6582717895508,0,97.8492851257324,,,,,,,,,,,,,,,,,,,,,,,,,,,,,,,,,
,3881326899.15023,92.896240234375,4999.6396484375,-9.1312596781181E-5,1.09878697559532E-8,1,4,14.0008964538574,4.99652883247127,33.0099985003471,-0.11336988242915,-0.0170867908949969,1,1.05539446928677E-7,,,,,,,,,,,,,,,,,,,,,92.694206237793,93.098274230957,4999.6396484375,4999.6396484375,53.5247485541499,5.87024333288033,13.0672082901001,56,1,0,0,1,0.330047607421875,33.7243423461914,2,1,3,92.694206237793,0,92.896240234375,,,,,,,,,,,,,,,,,,,,,,,,,,,,,,,,,
,3881326948.04594,88.8094673156738,4999.6396484375,-9.08946118744887E-5,2.9609052660082E-8,1,4,14.0008964538574,4.99632022185556,33.0099985003471,-0.112853539871411,-0.0169469654681873,1,1.53890285670347E-7,,,,,,,,,,,,,,,,,,,,,88.6688385009766,88.9500961303711,4999.6396484375,4999.6396484375,53.4035961336691,5.87130216361357,13.0411014556885,56,1,0,0,1,0.327377319335937,33.2355842590332,2,1,3,88.6688385009766,0,88.8094673156738,,,,,,,,,,,,,,,,,,,,,,,,,,,,,,,,,
,3881326995.9835,84.8352661132813,4999.6396484375,-9.1078228804598E-5,2.939706641881E-8,1,4,14.0008964538574,4.99649510185908,33.0099985003471,-0.113092233817297,-0.0169479628621994,1,1.81647247491351E-7,,,,,,,,,,,,,,,,,,,,,84.6927719116211,84.9777603149414,4999.6396484375,4999.6396484375,53.4903568993037,5.87065138765148,13.0028963088989,56,1,0,0,1,0.325469970703125,33.7243423461914,2,1,3,84.6927719116211,0,84.8352661132813,,,,,,,,,,,,,,,,,,,,,,,,,,,,,,,,,
,3881327043.97441,80.7977523803711,4999.6396484375,-9.09343574600705E-5,3.09116048092821E-8,1,4,14.0008964538574,4.99635966003987,33.0099985003471,-0.11290209050097,-0.0169680255007874,1,1.43112158996016E-7,,,,,,,,,,,,,,,,,,,,,80.6474914550781,80.9480133056641,4999.6396484375,4999.6396484375,53.5669564941884,5.87131681004581,12.9817867279053,56,1,0,0,1,0.326080322265625,33.7243423461914,2,1,3,80.6474914550781,0,80.7977523803711,,,,,,,,,,,,,,,,,,,,,,,,,,,,,,,,,
,3881327091.9774,76.8259925842285,4999.6396484375,-9.08837274966807E-5,3.11558123134765E-8,1,4,14.0008964538574,4.99643750122556,32.990001142025,-0.11284233491034,-0.0169547100865036,1,1.46446628045286E-7,,,,,,,,,,,,,,,,,,,,,76.6634674072266,76.9885177612305,4999.6396484375,4999.6396484375,53.6095552484864,5.87048225158529,12.9243297576904,56,1,0,0,1,0.325775146484375,33.7243423461914,2,1,3,76.6634674072266,0,76.8259925842285,,,,,,,,,,,,,,,,,,,,,,,,,,,,,,,,,
,3881327139.97807,72.7805633544922,4999.6396484375,-9.05053491057156E-5,2.73142828474833E-8,1,4,14.0008964538574,4.99620831018633,32.990001142025,-0.112369479769604,-0.0168556376382097,1,1.67911815073535E-7,,,,,,,,,,,,,,,,,,,,,72.6044998168945,72.9566268920898,4999.6396484375,4999.6396484375,53.5173230832172,5.87223947015166,12.8975095748901,56,1,0,0,1,0.325546264648438,33.7243423461914,2,1,3,72.6044998168945,0,72.7805633544922,,,,,,,,,,,,,,,,,,,,,,,,,,,,,,,,,
,3881327187.98626,68.6762962341309,4999.6396484375,-9.07160811923269E-5,3.25168730948845E-8,1,4,14.0008964538574,4.99638972848433,32.9999998211861,-0.112637388671022,-0.0168921783327719,1,1.71174729649505E-7,,,,,,,,,,,,,,,,,,,,,68.5259170532227,68.8266754150391,4999.6396484375,4999.6396484375,53.4340796459191,5.87114186734422,12.8331422805786,56,1,0,0,1,0.329132080078125,33.2355842590332,2,1,3,68.5117950439453,0,68.6762962341309,,,,,,,,,,,,,,,,,,,,,,,,,,,,,,,,,
,3881327235.97479,64.5944328308105,4999.6396484375,-9.03419824086447E-5,3.48579986185394E-8,1,4,14.0008964538574,4.9962998838478,32.990001142025,-0.112170654583945,-0.0168182150459266,1,1.73593898615349E-7,,,,,,,,,,,,,,,,,,,,,64.4110870361328,64.7777786254883,4999.6396484375,4999.6396484375,53.5188863402557,5.87095853335756,12.7943105697632,56,1,0,0,1,0.32501220703125,33.7243423461914,2,1,3,64.4110870361328,0,64.5944328308105,,,,,,,,,,,,,,,,,,,,,,,,,,,,,,,,,
,3881327296.08769,59.5474414825439,4999.6396484375,-9.03099204006581E-5,3.55330502833494E-8,1,4,14.0008964538574,4.99635914416381,32.990001142025,-0.112131258792186,-0.0168220663411971,1,1.65846053442538E-7,,,,,,,,,,,,,,,,,,,,,59.3894958496094,59.7053871154785,4999.6396484375,4999.6396484375,53.5220128543326,5.87109891390391,12.7127389907837,56,1,0,0,1,0.325546264648438,32.7468223571777,2,1,3,59.3894958496094,0,59.5474414825439,,,,,,,,,,,,,,,,,,,,,,,,,,,,,,,,,
,3881327343.94565,55.5129375457764,4999.6396484375,-9.00093621581462E-5,3.46375160922858E-8,1,4,14.0008964538574,4.99617100606965,32.990001142025,-0.111752124535031,-0.0167655927770551,1,1.64975386804426E-7,,,,,,,,,,,,,,,,,,,,,55.3669128417969,55.6589622497559,4999.6396484375,4999.6396484375,53.5364729819384,5.87144721086567,12.6491432189941,56,1,0,0,1,0.325088500976562,33.2355842590332,2,1,3,55.3669128417969,0,55.5129375457764,,,,,,,,,,,,,,,,,,,,,,,,,,,,,,,,,
,3881327391.97675,51.5196323394775,4999.6396484375,-8.98447905623439E-5,3.17574047241596E-8,1,4,14.0008964538574,4.99630454801115,32.990001142025,-0.111544918435402,-0.0167820141277907,1,1.27253043399021E-7,,,,,,,,,,,,,,,,,,,,,51.3686866760254,51.6705780029297,4999.6396484375,4999.6396484375,53.597830820698,5.87067680794363,12.561128616333,56,1,0,0,1,0.326995849609375,33.7243423461914,2,1,3,51.3686866760254,0,51.5196323394775,,,,,,,,,,,,,,,,,,,,,,,,,,,,,,,,,
,3881327439.94661,47.4377956390381,4999.6396484375,-8.96505128850155E-5,3.904003755748E-8,1,4,14.0008964538574,4.99635112343774,32.9999998211861,-0.111303065787088,-0.0167597962848922,1,1.15818017905502E-7,,,,,,,,,,,,,,,,,,,,,47.2595977783203,47.6159934997559,4999.6396484375,4999.6396484375,53.663878430573,5.87031131103889,12.4887609481812,56,1,0,0,1,0.325088500976562,33.2355842590332,2,1,3,47.2595977783203,0,47.4377956390381,,,,,,,,,,,,,,,,,,,,,,,,,,,,,,,,,
,3881327487.93518,43.4270210266113,4999.6396484375,-8.93575989001248E-5,3.65855347582598E-8,1,4,14.0008964538574,4.99626108601869,32.990001142025,-0.110941546268605,-0.0166721002963681,1,1.41635343927252E-7,,,,,,,,,,,,,,,,,,,,,43.2554168701172,43.5986251831055,4999.6396484375,4999.6396484375,53.5310015823037,5.87048068770689,12.365255355835,56,1,0,0,1,0.325698852539063,33.7243423461914,2,1,3,43.2554168701172,0,43.4270210266113,,,,,,,,,,,,,,,,,,,,,,,,,,,,,,,,,
,3881327535.94477,39.3718738555908,4999.6396484375,-8.88167445349987E-5,2.62573429322253E-8,1,4,14.0008964538574,4.99627850962416,32.9700000584126,-0.110266597498205,-0.0165975494733753,1,1.19606392216506E-7,,,,,,,,,,,,,,,,,,,,,39.1964530944824,39.5472946166992,4999.6396484375,4999.6396484375,53.5427260100922,5.87049931002123,12.2639455795288,56,1,0,0,1,0.324554443359375,33.7243423461914,2,1,3,39.1964530944824,0,39.3718738555908,,,,,,,,,,,,,,,,,,,,,,,,,,,,,,,,,
,3881327583.93024,35.3537940979004,4999.6396484375,-8.89147998134979E-5,2.56438169015527E-8,1,4,14.0008964538574,4.99633425971873,32.9700000584126,-0.110389134685047,-0.0166222157289215,1,1.14838115038813E-7,,,,,,,,,,,,,,,,,,,,,35.1854858398438,35.522102355957,4999.6396484375,4999.6396484375,53.4794141000345,5.86944618004048,12.1084012985229,56,1,0,0,1,0.327911376953125,32.7468223571777,2,1,3,35.1854858398438,0,35.3537940979004,,,,,,,,,,,,,,,,,,,,,,,,,,,,,,,,,
,3881327663.0314,28.6815633773804,4999.6396484375,-8.80039526013688E-5,3.61367103568383E-8,1,4,14.0008964538574,4.99621849766382,32.9700000584126,-0.109251735693635,-0.0164713039557834,1,9.76286663524507E-8,,,,,,,,,,,,,,,,,,,,,28.6573066711426,28.7058200836182,4999.6396484375,4999.6396484375,53.5802441790153,5.86990079762067,11.7997789382935,56,1,0,0,1,0.326385498046875,33.7243423461914,2,1,3,28.6573066711426,0,28.6815633773804,,,,,,,,,,,,,,,,,,,,,,,,,,,,,,,,,
,3881327750.13476,21.4211416244507,4999.6396484375,-9.1528625065134E-5,4.50480938571091E-6,1,4,14.0008964538574,4.99621538281949,32.9700000584126,-0.113543618318506,-0.0176819552318833,10,-3.4235046770687E-7,,,,,,,,,,,,,,,,,,,,,21.3999309539795,21.4423522949219,4999.6396484375,4999.6396484375,53.4915293420826,5.86955334199435,11.1780519485474,56,1,0,0,1,0.32501220703125,33.7243423461914,2,1,3,21.3999309539795,0,21.4211416244507,,,,,,,,,,,,,,,,,,,,,,,,,,,,,,,,,
,3881327834.15277,14.5168061256409,4999.6396484375,-8.44656789979298E-5,2.91478470622824E-8,1,4,14.0008964538574,4.99619833361956,32.9700000584126,-0.104854377816559,-0.0158366645486721,1,7.13926477644644E-8,,,,,,,,,,,,,,,,,,,,,14.4964904785156,14.5371217727661,4999.6396484375,4999.6396484375,53.4774600287364,5.87027157765277,10.0431680679321,48,1,100,0,0,0.326461791992188,33.2355842590332,2,1,3,14.4665641784668,0,14.5168061256409,,,,,,,,,,,,,,,,,,,,,,,,,,,,,,,,,
,3881327899.89788,9.56199550628662,4999.6396484375,-0.000100844292745693,2.12026064520283E-5,1,4,14.0008964538574,4.99622116422512,32.9700000584126,-0.126263322299644,-0.0118240989717382,10,5.79210240267242E-6,,,,,,,,,,,,,,,,,,,,,9.4286413192749,9.69534969329834,4999.6396484375,4999.6396484375,53.3852278634672,5.87003783000594,8.71583271026611,56,1,0,0,1,0.328521728515625,33.2355842590332,6,1,3,9.4286413192749,0,9.56199550628662,,,,,,,,,,,,,,,,,,,,,,,,,,,,,,,,,
,3881327954.43741,5.10752081871033,4999.6396484375,-7.88157711114621E-5,5.28988872326242E-6,1,4,14.0008964538574,4.99614151983895,32.9700000584126,-0.0970840176937494,-0.0197481300594475,100,-3.93837302053204E-6,,,,,,,,,,,,,,,,,,,,,5.07310771942139,5.14193391799927,4999.6396484375,4999.6396484375,53.4895752707845,5.86992284066628,7.6509108543396,56,1,0,0,1,0.326080322265625,33.7243423461914,6,1,3,5.056067943573,0,5.10752081871033,,,,,,,,,,,,,,,,,,,,,,,,,,,,,,,,,
,3881328007.89406,2.70568203926086,4999.6396484375,-4.4597952658343E-5,1.38150334136218E-5,1,4,14.0008964538574,4.99624733742872,32.9700000584126,-0.0565018799724421,-0.000870642910809745,10,6.07297623510526E-6,,,,,,,,,,,,,,,,,,,,,2.7041974067688,2.70716667175293,4999.6396484375,4999.6396484375,53.6330041040634,5.87081847828695,5.95893239974976,56,1,0,0,1,0.325851440429687,33.2355842590332,6,1,3,2.70716667175293,0,2.70568203926086,,,,,,,,,,,,,,,,,,,,,,,,,,,,,,,,,
,3881328067.87943,2.68116676807404,4999.6396484375,-5.16383601833346E-5,2.13632021066617E-5,1,4,14.0008964538574,4.99620798340437,32.9700000584126,-0.0621469968066915,-0.022560288846028,10,-1.03319362504358E-5,,,,,,,,,,,,,,,,,,,,,2.67879986763,2.68353366851807,4999.6396484375,4999.6396484375,53.4587009442749,5.87075975132204,5.765465259552,56,1,0,0,1,0.325698852539063,32.2580642700195,6,1,3,2.68353366851807,0,2.68116676807404,,,,,,,,,,,,,,,,,,,,,,,,,,,,,,,,,
,3881328151.55132,2.59889543056488,4999.6396484375,-5.74060315235112E-5,1.1198755872552E-5,1,4,14.0008964538574,4.9962148082172,32.9700000584126,-0.0709993487616816,-0.0125007916541221,10,-1.35134183320575E-6,,,,,,,,,,,,,,,,,,,,,2.59639072418213,2.60140013694763,4999.6396484375,4999.6396484375,53.5665656799287,5.87082591485992,5.71278429031372,54,1,68,0,0,0.326080322265625,33.2355842590332,6,1,3,2.59418392181396,0,2.59889543056488,,,,,,,,,,,,,,,,,,,,,,,,,,,,,,,,,
,3881328199.86448,2.58050131797791,4999.6396484375,-5.24992097041866E-5,1.11105867428456E-5,1,4,14.0008964538574,4.99618066733736,32.9700000584126,-0.0643991548864745,-0.0149269281721668,10,-4.05142210672764E-6,,,,,,,,,,,,,,,,,,,,,2.57495880126953,2.58604383468628,4999.6396484375,4999.6396484375,53.5427260100922,5.87027935187533,5.73032569885254,56,1,0,0,1,0.325241088867188,33.7243423461914,6,1,3,2.58604383468628,0,2.58050131797791,,,,,,,,,,,,,,,,,,,,,,,,,,,,,,,,,
,3881328259.86102,2.51893377304077,4999.6396484375,-7.31129514652055E-5,1.74928906470459E-5,1,4,14.0008964538574,4.99608616206381,32.9700000584126,-0.0940489848416314,0.0079550623448717,10,1.75150605077279E-5,,,,,,,,,,,,,,,,,,,,,2.51734328269958,2.52052426338196,4999.6396484375,4999.6396484375,53.4805865428134,5.87053852235274,5.69305944442749,56,1,0,0,1,0.32958984375,33.7243423461914,6,1,3,2.52052426338196,0,2.51893377304077,,,,,,,,,,,,,,,,,,,,,,,,,,,,,,,,,
,3881328307.89863,2.26265120506287,4999.6396484375,-5.75341339983693E-5,7.68172307504658E-6,1,4,14.0008964538574,4.99614311273831,32.9700000584126,-0.0729675911324104,-0.000604521783253554,10,8.2523600369518E-6,,,,,,,,,,,,,,,,,,,,,2.24460339546204,2.2806990146637,4999.6396484375,4999.6396484375,53.516541454698,5.87100940793558,5.41939735412598,54,1,68,0,0,0.326080322265625,33.2355842590332,6,1,3,2.24460339546204,0,2.26265120506287,,,,,,,,,,,,,,,,,,,,,,,,,,,,,,,,,
,3881328391.11179,1.99815380573273,4999.6396484375,-5.3907505747549E-5,9.75383939094777E-6,1,4,14.0008964538574,4.99608926645074,32.9700000584126,-0.0667475051083776,-0.0112286415067814,10,-8.58174098564972E-7,,,,,,,,,,,,,,,,,,,,,1.99804246425629,1.99826514720917,4999.6396484375,4999.6396484375,53.5888420927268,5.87093822328914,5.07180500030518,56,1,0,0,1,0.324859619140625,33.2355842590332,5,1,3,1.99804246425629,0,1.99815380573273,,,,,,,,,,,,,,,,,,,,,,,,,,,,,,,,,
,3881328411.83073,1.99694603681564,4999.6396484375,-3.77121872679817E-5,1.89964956756201E-5,1,4,14.0008964538574,4.99609706359736,32.9700000584126,-0.0446364864568342,-0.0214057259109652,10,-1.15176729227493E-5,,,,,,,,,,,,,,,,,,,,,1.99667310714722,1.99721896648407,4999.6396484375,4999.6396484375,53.5048170269095,5.87175430446942,5.03973770141602,56,1,0,0,1,0.324783325195313,33.2355842590332,1,1,3,1.99721896648407,0,1.99694603681564,,,,,,,,,,,,,,,,,,,,,,,,,,,,,,,,,