File: SQUID/Reference/LAO/C3/LAOsubs_22172_MH_300K_FC_p0d5T.csv
Comment,Time Stamp (sec),Temperature (K),Magnetic Field (Oe),Moment (emu),M. Std. Err. (emu),Transport Action,Averaging Time (sec),Frequency (Hz),Peak Amplitude (mm),Center Position (mm),Lockin Signal' (V),Lockin Signal (V),Range,M. Quad. Signal (emu),AC Moment (emu),AC M. Std Err. (emu),AC Phase (deg),AC Phase Std. Err. (deg),AC Susceptibility (emu/Oe),AC Suscept. Std Err. (emu/Oe),AC X' (emu/Oe),AC X' Std Err. (emu/Oe),AC X'' (emu/Oe),AC X'' Std Err. (emu/Oe),AC Drive (Oe),AC Frequency (Hz),AC Averaging Time (sec),AC Cycles,AC Range,AC Measure Type,AC Signal' (V),AC Signal'' (V),AC Trim Coil Ratio,AC Trim Coil Phase,Min. Temperature (K),Max. Temperature (K),Min. Field (Oe),Max. Field (Oe),Mass (grams),Motor Lag (deg),Pressure (Torr),Measure Count,Measurement Number,SQUID Status (code),Motor Status (code),Measure Status (code),Motor Current (amps),Motor Temp. (C),Temp. Status (code),Field Status (code),Chamber Status (code),Chamber Temp (K),Redirection State,Average Temp (K),Rotation Angle (deg),Rotator state,DC Moment Fixed Ctr (emu),DC Moment Err Fixed Ctr (emu),DC Moment Free Ctr (emu),DC Moment Err Free Ctr (emu),DC Fixed Fit,DC Free Fit,DC Calculated Center (mm),DC Calculated Center Err (mm),DC Scan Length (mm),DC Scan Time (s),DC Number of Points,DC Squid Drift,DC Min V (V),DC Max V (V),DC Scans per Measure,Map 01,Map 02,Map 03,Map 04,Map 05,Map 06,Map 07,Map 08,Map 09,Map 10,Map 11,Map 12,Map 13,Map 14,Map 15,Map 16
,3881352139.21459,300.037963867188,69999.7890625,-0.00129000585750806,3.44533242981374E-7,1,4,14.0008964538574,5.00498243809998,33.2500003278255,-1.60504281792147,-0.244381625026927,1,-4.52859286450037E-7,,,,,,,,,,,,,,,,,,,,,300.037872314453,300.038055419922,69999.7890625,69999.7890625,53.2101430751595,5.88146907211522,5.82574653625488,56,1,0,0,1,0.330734252929687,32.7468223571777,1,1,3,300.037841796875,0,300.037963867188,,,,,,,,,,,,,,,,,,,,,,,,,,,,,,,,,
,3881352225.27339,300.136138916016,60000.47265625,-0.00110552140108034,2.48328194017834E-7,1,4,14.0008964538574,5.00486626409565,33.2500003278255,-1.37545494711926,-0.209459610245723,1,-4.15369851509934E-7,,,,,,,,,,,,,,,,,,,,,300.112640380859,300.159637451172,60000.47265625,60000.47265625,53.2906508126403,5.88251566710008,5.85058403015137,56,1,0,0,1,0.331039428710937,33.2355842590332,1,1,3,300.159637451172,0,300.136138916016,,,,,,,,,,,,,,,,,,,,,,,,,,,,,,,,,
,3881352318.71247,300.156021118164,49999.81640625,-9.21733978110273E-4,1.61627309131205E-7,1,4,14.0008964538574,5.00468937318268,33.2500003278255,-1.14704652694003,-0.172583329721357,10,1.29816864467869E-6,,,,,,,,,,,,,,,,,,,,,300.139312744141,300.172729492188,49999.81640625,49999.81640625,53.3992971768133,5.88278125579673,5.93249082565308,56,1,0,0,1,0.33050537109375,34.2131004333496,1,1,3,300.174407958984,0,300.156021118164,,,,,,,,,,,,,,,,,,,,,,,,,,,,,,,,,
,3881352410.24513,300.064193725586,39999.66015625,-7.36946785626354E-4,9.39232332458385E-8,1,4,14.0008964538574,5.00493153510099,33.2500003278255,-0.916931224795,-0.139441897611937,1,-1.26113017251026E-7,,,,,,,,,,,,,,,,,,,,,300.042694091797,300.085693359375,39999.66015625,39999.66015625,53.4004696195922,5.88204494079284,6.03656196594238,55,1,68,0,0,0.330810546875,34.2131004333496,1,1,3,300.085693359375,0,300.064193725586,,,,,,,,,,,,,,,,,,,,,,,,,,,,,,,,,
,3881352509.11844,300.220596313477,29999.61328125,-5.5248700740095E-4,4.84456152587015E-8,1,4,14.0008964538574,5.0047788237495,33.2500003278255,-0.687401557184829,-0.104468686491795,1,-4.14481697640987E-8,,,,,,,,,,,,,,,,,,,,,300.203155517578,300.238037109375,29999.61328125,29999.61328125,53.4739427003999,5.88185462514086,6.19901752471924,56,1,0,0,1,0.331039428710937,33.7243423461914,1,1,3,300.238037109375,0,300.220596313477,,,,,,,,,,,,,,,,,,,,,,,,,,,,,,,,,
,3881352595.76159,300.206771850586,19999.716796875,-3.68292493622305E-4,3.20583611907604E-8,1,4,14.0008964538574,5.00475807458495,33.2500003278255,-0.45823898282539,-0.0695473311701797,1,4.62904517378528E-8,,,,,,,,,,,,,,,,,,,,,300.19970703125,300.213836669922,19999.716796875,19999.716796875,53.5857155786499,5.88247864444845,6.3653359413147,56,1,0,0,1,0.330886840820313,34.2131004333496,1,1,3,300.19970703125,0,300.206771850586,,,,,,,,,,,,,,,,,,,,,,,,,,,,,,,,,
,3881352659.68337,300.233551025391,14499.5927734375,-2.66755654954462E-4,2.73104398596629E-8,1,4,14.0008964538574,5.00479493701209,33.2500003278255,-0.33192272881812,-0.050274700866514,1,1.13269149033186E-7,,,,,,,,,,,,,,,,,,,,,300.225067138672,300.242034912109,14499.5927734375,14499.5927734375,53.557186137698,5.88210040810574,6.47753190994263,56,1,0,0,1,0.3302001953125,34.2131004333496,1,1,3,300.243316650391,0,300.233551025391,,,,,,,,,,,,,,,,,,,,,,,,,,,,,,,,,
,3881352699.82605,300.22331237793,13499.76953125,-2.48438279120116E-4,2.84617580067576E-8,1,4,14.0008964538574,5.00458917742739,33.2500003278255,-0.309113217087327,-0.0468166187173464,1,1.08035137490092E-7,,,,,,,,,,,,,,,,,,,,,300.206848144531,300.239776611328,13499.76953125,13499.76953125,53.5505422952845,5.88251391432971,6.53599071502686,56,1,0,0,1,0.331039428710937,33.7243423461914,1,1,3,300.239776611328,0,300.22331237793,,,,,,,,,,,,,,,,,,,,,,,,,,,,,,,,,
,3881352749.47617,300.281646728516,12499.708984375,-2.30113370857402E-4,3.01653206994222E-8,1,4,14.0008964538574,5.00461416615726,33.2599990069866,-0.286363735822935,-0.0430422083124799,10,3.58475717165433E-7,,,,,,,,,,,,,,,,,,,,,300.277709960937,300.285583496094,12499.708984375,12499.708984375,53.5036445841307,5.88252079656764,6.55656957626343,56,1,0,0,1,0.330047607421875,34.2131004333496,1,1,3,300.285583496094,0,300.281646728516,,,,,,,,,,,,,,,,,,,,,,,,,,,,,,,,,
,3881352795.26892,300.174789428711,11499.72265625,-2.11526355263776E-4,2.56029057311631E-8,1,4,14.0008964538574,5.00455668284153,33.2500003278255,-0.263180950690402,-0.039881000702333,1,7.54565544578887E-8,,,,,,,,,,,,,,,,,,,,,300.169769287109,300.179809570313,11499.72265625,11499.72265625,53.5810258075345,5.88247198116045,6.53239154815674,56,1,0,0,1,0.331344604492188,34.2131004333496,1,1,3,300.169769287109,0,300.174789428711,,,,,,,,,,,,,,,,,,,,,,,,,,,,,,,,,
,3881352836.68063,300.185806274414,10499.5986328125,-1.93126174413002E-4,2.01254221020452E-8,1,4,14.0008964538574,5.00452647122351,33.2500003278255,-0.240287449403655,-0.0363982395321643,1,7.95823786276251E-8,,,,,,,,,,,,,,,,,,,,,300.182891845703,300.188720703125,10499.5986328125,10499.5986328125,53.5595310232557,5.88279025578382,6.49899005889893,56,1,0,0,1,0.331573486328125,34.7018585205078,1,1,3,300.182891845703,0,300.185806274414,,,,,,,,,,,,,,,,,,,,,,,,,,,,,,,,,
,3881352878.67442,300.116744995117,9499.525390625,-1.74637307195139E-4,2.1475570426591E-8,1,4,14.0008964538574,5.00451437089559,33.2500003278255,-0.217282724527968,-0.0329145735331539,1,7.11452451348507E-8,,,,,,,,,,,,,,,,,,,,,300.099212646484,300.13427734375,9499.525390625,9499.525390625,53.5290475110057,5.88283059846792,6.47891235351562,56,1,0,0,1,0.33172607421875,33.7243423461914,1,1,3,300.13427734375,0,300.116744995117,,,,,,,,,,,,,,,,,,,,,,,,,,,,,,,,,
,3881352920.07785,300.303512573242,8499.52734375,-1.56229253670708E-4,1.93606550795698E-8,1,4,14.0008964538574,5.00440619404928,33.2500003278255,-0.194374893801006,-0.0294360903837253,1,7.02014363149818E-8,,,,,,,,,,,,,,,,,,,,,300.284118652344,300.322906494141,8499.52734375,8499.52734375,53.5544504378807,5.88295478223417,6.46186876296997,56,1,0,0,1,0.33172607421875,34.2131004333496,1,1,3,300.322906494141,0,300.303512573242,,,,,,,,,,,,,,,,,,,,,,,,,,,,,,,,,
,3881352960.69597,300.294982910156,7499.591796875,-1.37823161388571E-4,1.76567956452084E-8,1,4,14.0008964538574,5.00454971495029,33.2500003278255,-0.171486677308335,-0.0259354702911578,1,8.89852786617767E-8,,,,,,,,,,,,,,,,,,,,,300.282104492188,300.307861328125,7499.591796875,7499.591796875,53.6126817625634,5.88265650498388,6.44042158126831,56,1,0,0,1,0.3314208984375,34.2131004333496,1,1,3,300.307861328125,0,300.294982910156,,,,,,,,,,,,,,,,,,,,,,,,,,,,,,,,,
,3881353000.39266,300.350540161133,6499.7060546875,-1.1934802225042E-4,1.54096812278914E-8,1,4,14.0008964538574,5.00453635401061,33.2500003278255,-0.148494145688409,-0.022486774322673,1,5.45291901273478E-8,,,,,,,,,,,,,,,,,,,,,300.341766357422,300.359313964844,6499.7060546875,6499.7060546875,53.5016905128326,5.88250350668518,6.42398548126221,55,1,68,0,0,0.331954956054687,34.2131004333496,1,1,3,300.359313964844,0,300.350540161133,,,,,,,,,,,,,,,,,,,,,,,,,,,,,,,,,
,3881353041.4844,300.30647277832,5499.75830078125,-1.00895516767035E-4,1.13059662408315E-8,1,4,14.0008964538574,5.00449620950108,33.2500003278255,-0.125532811362616,-0.0190171817652677,1,4.02137097208049E-8,,,,,,,,,,,,,,,,,,,,,300.289123535156,300.323822021484,5499.75830078125,5499.75830078125,53.5743819651211,5.88262357869052,6.40247392654419,54,1,68,0,0,0.331192016601562,34.2131004333496,1,1,3,300.323822021484,0,300.30647277832,,,,,,,,,,,,,,,,,,,,,,,,,,,,,,,,,
,3881353082.70672,300.275787353516,4499.78466796875,-8.24306438473351E-5,1.1009756619805E-8,1,4,14.0008964538574,5.00443251323561,33.2500003278255,-0.102556893096314,-0.0155388930820435,1,3.09898941054206E-8,,,,,,,,,,,,,,,,,,,,,300.270690917969,300.280883789063,4499.78466796875,4499.78466796875,53.5306107680441,5.88263011408943,6.39587116241455,56,1,0,0,1,0.330352783203125,34.2131004333496,1,1,3,300.280883789063,0,300.275787353516,,,,,,,,,,,,,,,,,,,,,,,,,,,,,,,,,
,3881353123.51743,300.367492675781,3499.76147460937,-6.3974755860126E-5,1.09968179999945E-8,1,4,14.0008964538574,5.00438606347273,33.2500003278255,-0.0795913327089798,-0.0120757922264227,1,1.10689839075519E-8,,,,,,,,,,,,,,,,,,,,,300.358978271484,300.376007080078,3499.76147460937,3499.76147460937,53.5392086817557,5.88322138632589,6.38219690322876,56,1,0,0,1,0.334091186523438,34.7018585205078,1,1,3,300.376007080078,0,300.367492675781,,,,,,,,,,,,,,,,,,,,,,,,,,,,,,,,,
,3881353180.13045,300.362731933594,2709.77294921875,-4.93883177340784E-5,9.39963953272029E-9,1,4,14.0008964538574,5.0043816058694,33.2500003278255,-0.0614435021501086,-0.00932699971423222,1,4.89888021653241E-9,,,,,,,,,,,,,,,,,,,,,300.353759765625,300.371704101562,2709.77294921875,2709.77294921875,53.5786809219768,5.88277935103854,6.36540842056274,56,1,0,0,1,0.331954956054687,34.2131004333496,1,1,3,300.371704101562,0,300.362731933594,,,,,,,,,,,,,,,,,,,,,,,,,,,,,,,,,
,3881353219.13877,300.280807495117,2129.61791992187,-3.86610509495461E-5,8.55254161092754E-9,1,4,14.0008964538574,5.00434681946375,33.2500003278255,-0.0480986214388212,-0.00729272000360621,1,1.05555287959581E-8,,,,,,,,,,,,,,,,,,,,,300.272277832031,300.289337158203,2129.61791992187,2129.61791992187,53.6748212298422,5.88349476429484,6.34799098968506,56,1,0,0,1,0.329742431640625,33.7243423461914,1,1,3,300.272277832031,0,300.280807495117,,,,,,,,,,,,,,,,,,,,,,,,,,,,,,,,,
,3881353258.83959,300.202499389648,1549.57641601562,-2.79647058303512E-5,8.71215502255026E-9,1,4,14.0008964538574,5.00432060877254,33.2500003278255,-0.0347886953194324,-0.00528972258925631,1,-4.19444846633746E-9,,,,,,,,,,,,,,,,,,,,,300.182159423828,300.222839355469,1549.57641601562,1549.57641601562,53.6275327044288,5.88335211966254,6.33680629730225,56,1,0,0,1,0.331573486328125,34.2131004333496,1,1,3,300.222839355469,0,300.202499389648,,,,,,,,,,,,,,,,,,,,,,,,,,,,,,,,,
,3881353298.09358,300.220642089844,969.559936523437,-1.72508555318776E-5,8.25719170054536E-9,1,4,14.0008964538574,5.00425262585798,33.2500003278255,-0.0214614779527313,-0.00325351073004873,1,5.08844286444207E-9,,,,,,,,,,,,,,,,,,,,,300.206481933594,300.234802246094,969.559936523437,969.559936523437,53.5036445841307,5.88352151407714,6.32455062866211,56,1,0,0,1,0.331192016601562,34.7018585205078,1,1,3,300.234802246094,0,300.220642089844,,,,,,,,,,,,,,,,,,,,,,,,,,,,,,,,,
,3881353338.96982,300.350143432617,389.581298828125,-6.51367254376831E-6,7.43807040649194E-9,1,4,14.0008964538574,5.00428827464633,33.2599990069866,-0.0081032037326262,-0.00123125187308997,1,-2.98245131085111E-10,,,,,,,,,,,,,,,,,,,,,300.346221923828,300.354064941406,389.581298828125,389.581298828125,53.5384270532364,5.88322150022611,6.31814193725586,56,1,0,0,1,0.332183837890625,34.2131004333496,1,1,3,300.354064941406,0,300.350143432617,,,,,,,,,,,,,,,,,,,,,,,,,,,,,,,,,
,3881353378.42747,300.249786376953,-190.170776367187,4.18079133190917E-6,1.88186452801252E-8,1,4,14.0008964538574,5.00425744307134,33.2500003278255,0.00520452193676008,7.66984514959962E-4,1,-1.85267336414802E-8,,,,,,,,,,,,,,,,,,,,,300.231658935547,300.267913818359,-190.170776367187,-190.170776367187,53.5763360364191,5.88368391316707,6.31006956100464,56,1,0,0,1,0.329666137695313,34.2131004333496,1,1,3,300.267913818359,0,300.249786376953,,,,,,,,,,,,,,,,,,,,,,,,,,,,,,,,,
,3881353415.92982,300.295959472656,-770.401184082031,1.48220876538906E-5,3.21166265079259E-8,1,4,14.0008964538574,5.00431040688904,33.2500003278255,0.0184428038696495,0.00277827885670515,1,-1.82071160990214E-8,,,,,,,,,,,,,,,,,,,,,300.2783203125,300.313598632812,-770.401184082031,-770.401184082031,53.5380362389768,5.88312404047095,6.29750061035156,56,1,0,0,1,0.330581665039063,34.2131004333496,1,1,3,300.313598632812,0,300.295959472656,,,,,,,,,,,,,,,,,,,,,,,,,,,,,,,,,
,3881353453.45175,300.319198608398,-1350.3798828125,2.56050254398034E-5,3.36380354790659E-8,1,4,14.0008964538574,5.00450830302531,33.2500003278255,0.0318642140697195,0.00478213141076245,1,-4.55881409508759E-8,,,,,,,,,,,,,,,,,,,,,300.304351806641,300.334045410156,-1350.3798828125,-1350.3798828125,53.6705222729865,5.88226287494244,6.29918098449707,56,1,0,0,1,0.328750610351562,34.2131004333496,1,1,3,300.334045410156,0,300.319198608398,,,,,,,,,,,,,,,,,,,,,,,,,,,,,,,,,
,3881353491.97127,300.333602905273,-1930.30810546875,3.62816587435466E-5,6.26808226577023E-8,1,4,14.0008964538574,5.00439656574774,33.2500003278255,0.0451450454685456,0.00680433093412372,1,-4.17802810129444E-8,,,,,,,,,,,,,,,,,,,,,300.324951171875,300.342254638672,-1930.30810546875,-1930.30810546875,53.5700830082653,5.88247082594458,6.29160976409912,56,1,0,0,1,0.3314208984375,34.2131004333496,1,1,3,300.324951171875,0,300.333602905273,,,,,,,,,,,,,,,,,,,,,,,,,,,,,,,,,
,3881353530.10426,300.341949462891,-2510.31201171875,4.68758522457655E-5,4.82816554508978E-8,1,4,14.0008964538574,5.0044299585915,33.2500003278255,0.0583301944359074,0.00877603001711176,1,-6.62284378828716E-8,,,,,,,,,,,,,,,,,,,,,300.329681396484,300.354217529297,-2510.31201171875,-2510.31201171875,53.6064287344095,5.88335825861112,6.27588748931885,56,1,0,0,1,0.329742431640625,34.2131004333496,1,1,3,300.354217529297,0,300.341949462891,,,,,,,,,,,,,,,,,,,,,,,,,,,,,,,,,
,3881353582.00474,300.258728027344,-3000.27221679687,5.5942745429003E-5,7.06135624544207E-9,1,4,14.0008964538574,5.00441546587022,33.2500003278255,0.0696134510042393,0.0104661976757534,1,-8.48908372705795E-8,,,,,,,,,,,,,,,,,,,,,300.257659912109,300.259796142578,-3000.27221679687,-3000.27221679687,53.6060379201499,5.88260014366039,6.27406692504883,56,1,0,0,1,0.331192016601562,34.2131004333496,1,1,3,300.257659912109,0,300.258728027344,,,,,,,,,,,,,,,,,,,,,,,,,,,,,,,,,
,3881353621.30648,300.183395385742,-4000.1318359375,7.42288561107566E-5,8.15344146229368E-8,1,4,14.0008964538574,5.00419997937628,33.2500003278255,0.0923732156727662,0.0138163739101509,1,-1.68983951877142E-7,,,,,,,,,,,,,,,,,,,,,300.170654296875,300.196136474609,-4000.1318359375,-4000.1318359375,53.4985639987557,5.88395684649714,6.26324653625488,56,1,0,0,1,0.331573486328125,34.2131004333496,1,1,3,300.196136474609,0,300.183395385742,,,,,,,,,,,,,,,,,,,,,,,,,,,,,,,,,
,3881353661.0364,300.277557373047,-5000.255859375,9.26831167943382E-5,1.03935405452102E-8,1,4,14.0008964538574,5.00430901914056,33.2500003278255,0.115323177091724,0.017375190176489,1,-1.11835238593878E-7,,,,,,,,,,,,,,,,,,,,,300.271118164063,300.283996582031,-5000.255859375,-5000.255859375,53.5399903102749,5.88382201293789,6.25468254089356,56,1,0,0,1,0.331268310546875,34.2131004333496,1,1,3,300.283996582031,0,300.277557373047,,,,,,,,,,,,,,,,,,,,,,,,,,,,,,,,,
,3881353700.6381,300.310165405273,-6000.19189453125,1.11029703578542E-4,1.46813605780929E-8,1,4,14.0008964538574,5.00446650455316,33.2500003278255,0.138156066063094,0.0208245327061844,1,-1.26727328969222E-7,,,,,,,,,,,,,,,,,,,,,300.304351806641,300.315979003906,-6000.19189453125,-6000.19189453125,53.6009573347749,5.8828383571082,6.24758243560791,56,1,0,0,1,0.331344604492188,33.7243423461914,1,1,3,300.304351806641,0,300.310165405273,,,,,,,,,,,,,,,,,,,,,,,,,,,,,,,,,
,3881353740.35689,300.31005859375,-6999.7744140625,1.29510078259156E-4,1.4643979599554E-8,1,4,14.0008964538574,5.00444730070171,33.2500003278255,0.161150235798446,0.0242931568503948,1,-1.45723819911305E-7,,,,,,,,,,,,,,,,,,,,,300.293151855469,300.326965332031,-6999.7744140625,-6999.7744140625,53.547024966948,5.88256876480457,6.24236679077148,56,1,0,0,1,0.331954956054687,34.2131004333496,1,1,3,300.326965332031,0,300.31005859375,,,,,,,,,,,,,,,,,,,,,,,,,,,,,,,,,
,3881353780.19566,300.255783081055,-8000.0498046875,1.47920074518659E-4,1.60361389139621E-8,1,4,14.0008964538574,5.00435298182943,33.2500003278255,0.18405312397019,0.0277453216579109,1,-1.66761830738997E-7,,,,,,,,,,,,,,,,,,,,,300.248199462891,300.263366699219,-8000.0498046875,-8000.0498046875,53.6732579728038,5.88295444206164,6.24036550521851,56,1,0,0,1,0.330047607421875,33.7243423461914,1,1,3,300.248199462891,0,300.255783081055,,,,,,,,,,,,,,,,,,,,,,,,,,,,,,,,,
,3881353819.76374,300.157257080078,-8999.771484375,1.66330018703367E-4,2.18348439721338E-8,1,4,14.0008964538574,5.00447548898347,33.2500003278255,0.206969314609597,0.0311857943733003,1,-1.98563163254138E-7,,,,,,,,,,,,,,,,,,,,,300.139587402344,300.174926757812,-8999.771484375,-8999.771484375,53.5743819651211,5.88229197638251,6.23455667495727,56,1,0,0,1,0.331649780273438,33.7243423461914,1,1,3,300.174926757812,0,300.157257080078,,,,,,,,,,,,,,,,,,,,,,,,,,,,,,,,,
,3881353859.39705,300.162109375,-10000.0595703125,1.84781342852756E-4,1.44057804687943E-8,1,4,14.0008964538574,5.00449825260506,33.2500003278255,0.229922160270365,0.0346991067922549,1,-1.77516053992706E-7,,,,,,,,,,,,,,,,,,,,,300.158538818359,300.165679931641,-10000.0595703125,-10000.0595703125,53.5407719387941,5.8830636501384,6.22815942764282,56,1,0,0,1,0.329132080078125,34.2131004333496,1,1,3,300.158538818359,0,300.162109375,,,,,,,,,,,,,,,,,,,,,,,,,,,,,,,,,
,3881353899.24117,300.105361938477,-10999.8818359375,2.0318459030202E-4,2.0363051793405E-8,1,4,14.0008964538574,5.00443950397013,33.2500003278255,0.252815759826141,0.0381627854515531,1,-1.88397992865525E-7,,,,,,,,,,,,,,,,,,,,,300.087829589844,300.122894287109,-10999.8818359375,-10999.8818359375,53.5931410495826,5.88330034738773,6.22948551177978,56,1,0,0,1,0.330123901367188,34.2131004333496,1,1,3,300.122894287109,0,300.105361938477,,,,,,,,,,,,,,,,,,,,,,,,,,,,,,,,,
,3881353938.8315,300.182632446289,-11999.9052734375,2.21733238607077E-4,1.6082370641148E-7,1,4,14.0008964538574,5.00448668021643,33.2500003278255,0.275909492747936,0.0415771838946025,1,-2.6187615465365E-7,,,,,,,,,,,,,,,,,,,,,300.182067871094,300.183197021484,-11999.9052734375,-11999.9052734375,53.6470734174095,5.88263001746975,6.22530555725098,54,1,68,0,0,0.328826904296875,34.2131004333496,1,1,3,300.182067871094,0,300.182632446289,,,,,,,,,,,,,,,,,,,,,,,,,,,,,,,,,
,3881353991.25537,300.197418212891,-13000.0419921875,2.40090689250653E-4,1.77763540960407E-8,1,4,14.0008964538574,5.00437069072611,33.2500003278255,0.298727287459097,0.0451184058886583,1,-2.02792163670496E-7,,,,,,,,,,,,,,,,,,,,,300.191497802734,300.203338623047,-13000.0419921875,-13000.0419921875,53.6048654773711,5.88295138758785,6.21888399124146,56,1,0,0,1,0.331344604492188,34.2131004333496,1,1,3,300.191497802734,0,300.197418212891,,,,,,,,,,,,,,,,,,,,,,,,,,,,,,,,,
,3881354031.62406,300.092834472656,-13999.6748046875,2.58464231169512E-4,2.26427285069962E-8,1,4,14.0008964538574,5.00423862666705,33.2500003278255,0.321572638898469,0.0485933372257537,1,-1.99079477959215E-7,,,,,,,,,,,,,,,,,,,,,300.087677001953,300.097991943359,-13999.6748046875,-13999.6748046875,53.6287051472076,5.88367043962775,6.21482992172241,54,1,68,0,0,0.330963134765625,34.2131004333496,1,1,3,300.097991943359,0,300.092834472656,,,,,,,,,,,,,,,,,,,,,,,,,,,,,,,,,
,3881354176.93899,300.178100585937,-14999.5478515625,2.76911998327506E-4,2.65657843670706E-8,1,4,14.0008964538574,5.0042812847633,33.2500003278255,0.344526352442303,0.0520787104908695,1,-2.00085529021775E-7,,,,,,,,,,,,,,,,,,,,,300.176696777344,300.179504394531,-14999.5478515625,-14999.5478515625,53.5274842539672,5.88345682876232,6.19461154937744,56,1,0,0,1,0.331573486328125,34.2131004333496,1,1,3,300.176696777344,0,300.178100585937,,,,,,,,,,,,,,,,,,,,,,,,,,,,,,,,,
,3881354264.38266,300.088043212891,-24999.64453125,4.61342487146182E-4,4.59433065501947E-8,1,4,14.0008964538574,5.00430463610165,33.2500003278255,0.573968508910158,0.0869294258509571,1,-2.01203581539683E-7,,,,,,,,,,,,,,,,,,,,,300.064331054687,300.111755371094,-24999.64453125,-24999.64453125,53.6294867757268,5.88328177849391,6.18796396255493,56,1,0,0,1,0.329513549804687,34.2131004333496,1,1,3,300.111755371094,0,300.088043212891,,,,,,,,,,,,,,,,,,,,,,,,,,,,,,,,,
,3881354352.3006,300.074768066406,-34999.640625,6.45726796639722E-4,5.78560383010068E-8,1,4,14.0008964538574,5.00437053188531,33.2500003278255,0.803332984533425,0.121989103329975,1,-2.88696277857425E-8,,,,,,,,,,,,,,,,,,,,,300.073120117188,300.076416015625,-34999.640625,-34999.640625,53.5880604642076,5.88293373805118,6.18399620056152,56,1,0,0,1,0.331039428710937,33.7243423461914,1,1,3,300.076416015625,0,300.074768066406,,,,,,,,,,,,,,,,,,,,,,,,,,,,,,,,,
,3881354451.93948,300.078994750977,-44999.51171875,8.30037493851432E-4,1.24350452660418E-7,1,4,14.0008964538574,5.00437344748675,33.2599990069866,1.0325985019542,0.157017931497684,1,1.31032826831045E-7,,,,,,,,,,,,,,,,,,,,,300.053955078125,300.104034423828,-44999.51171875,-44999.51171875,53.4594825727941,5.88485531627348,6.17310428619385,56,1,0,0,1,0.331039428710937,33.7243423461914,1,1,3,300.104034423828,0,300.078994750977,,,,,,,,,,,,,,,,,,,,,,,,,,,,,,,,,
,3881354553.10812,300.052734375,-54999.734375,0.00101443584242133,2.0611005941586E-7,1,4,14.0008964538574,5.00472658488298,33.2500003278255,1.26211328371364,0.191974652581792,1,2.04513030833739E-7,,,,,,,,,,,,,,,,,,,,,300.031890869141,300.073577880859,-54999.734375,-54999.734375,53.4450224451884,5.88292120553096,6.16699600219727,56,1,0,0,1,0.331497192382812,34.2131004333496,1,1,3,300.073577880859,0,300.052734375,,,,,,,,,,,,,,,,,,,,,,,,,,,,,,,,,
,3881354653.53548,300.121322631836,-64999.69140625,0.00119895556996288,3.30128960943356E-7,1,4,14.0008964538574,5.0043641106557,33.2500003278255,1.49145108165536,0.227409641030679,1,6.74925498003777E-7,,,,,,,,,,,,,,,,,,,,,300.117004394531,300.125640869141,-64999.69140625,-64999.69140625,53.3500545801018,5.88339203931818,6.15914297103882,56,1,0,0,1,0.331573486328125,34.2131004333496,1,1,3,300.117004394531,0,300.121322631836,,,,,,,,,,,,,,,,,,,,,,,,,,,,,,,,,
,3881354754.01428,300.157119750977,-64999.6796875,0.00119859397837312,3.58156369031278E-7,1,4,14.0008964538574,5.0043042039985,33.2500003278255,1.49100467452838,0.227150548324152,1,5.24644968455433E-7,,,,,,,,,,,,,,,,,,,,,300.14013671875,300.174102783203,-64999.6796875,-64999.6796875,53.2824437131883,5.88312724213568,6.15150594711304,56,1,0,0,1,0.331344604492188,33.7243423461914,1,1,3,300.174102783203,0,300.157119750977,,,,,,,,,,,,,,,,,,,,,,,,,,,,,,,,,
,3881354839.76007,300.101013183594,-54999.72265625,0.00101396352499714,2.42674159199323E-7,1,4,14.0008964538574,5.00435654245988,33.2500003278255,1.26134110591942,0.192221573681222,1,4.90693743863076E-7,,,,,,,,,,,,,,,,,,,,,300.099975585937,300.10205078125,-54999.72265625,-54999.72265625,53.493092599121,5.88404241418645,6.14922189712524,56,1,0,0,1,0.330352783203125,34.7018585205078,1,1,3,300.099975585937,0,300.101013183594,,,,,,,,,,,,,,,,,,,,,,,,,,,,,,,,,
,3881354926.60315,300.140151977539,-44999.5625,8.29378908475583E-4,1.45225066120076E-7,1,4,14.0008964538574,5.004337406772,33.2500003278255,1.03173467325623,0.15711646164712,1,3.11543592754616E-7,,,,,,,,,,,,,,,,,,,,,300.12548828125,300.154815673828,-44999.5625,-44999.5625,53.4161021899768,5.88409998125439,6.14916229248047,56,1,0,0,1,0.3289794921875,34.2131004333496,1,1,3,300.154815673828,0,300.140151977539,,,,,,,,,,,,,,,,,,,,,,,,,,,,,,,,,
,3881355027.23768,300.059188842773,-34999.73046875,6.44909358738958E-4,8.13620139586559E-8,1,4,14.0008964538574,5.00456010196868,33.2500003278255,0.802350965246155,0.121890962516744,1,1.12213125350722E-8,,,,,,,,,,,,,,,,,,,,,300.051574707031,300.066802978516,-34999.73046875,-34999.73046875,53.5020813270922,5.88439632249768,6.14584064483643,56,1,0,0,1,0.33111572265625,34.2131004333496,1,1,3,300.066802978516,0,300.059188842773,,,,,,,,,,,,,,,,,,,,,,,,,,,,,,,,,
,3881355112.07555,300.2275390625,-24999.669921875,4.60652215276812E-4,4.69924471227508E-8,1,4,14.0008964538574,5.00426514459414,33.2500003278255,0.573062935391434,0.0870647793046942,1,1.32219161817972E-8,,,,,,,,,,,,,,,,,,,,,300.2060546875,300.2490234375,-24999.669921875,-24999.669921875,53.5478065954672,5.88459276305752,6.14268398284912,56,1,0,0,1,0.33172607421875,34.2131004333496,1,1,3,300.2490234375,0,300.2275390625,,,,,,,,,,,,,,,,,,,,,,,,,,,,,,,,,
,3881355195.8167,300.233703613281,-14999.75,2.7617193751802E-4,2.17640157291555E-8,1,4,14.0008964538574,5.00435678467039,33.2500003278255,0.343587114347971,0.0521099774223571,1,-6.34210537685415E-8,,,,,,,,,,,,,,,,,,,,,300.226593017578,300.240814208984,-14999.75,-14999.75,53.6224521190538,5.88444208912315,6.13961267471314,56,1,0,0,1,0.330810546875,34.2131004333496,1,1,3,300.226593017578,0,300.233703613281,,,,,,,,,,,,,,,,,,,,,,,,,,,,,,,,,
,3881355269.22471,300.445114135742,-14000.19140625,2.57756439415475E-4,2.25395539325829E-8,1,4,14.0008964538574,5.00437530159342,33.2500003278255,0.32070018440882,0.0484890634358424,1,-1.76875017798211E-7,,,,,,,,,,,,,,,,,,,,,300.440979003906,300.449249267578,-14000.19140625,-14000.19140625,53.5552320663999,5.88399626844654,6.13338088989258,56,1,0,0,1,0.331954956054687,34.7018585205078,1,1,3,300.440979003906,0,300.445114135742,,,,,,,,,,,,,,,,,,,,,,,,,,,,,,,,,
,3881355323.20302,300.378982543945,-13000.419921875,2.39222138641315E-4,2.91841538745156E-8,1,4,14.0008964538574,5.00437841185356,33.2500003278255,0.297627652309829,0.0450843379035275,1,-9.83223500947958E-8,,,,,,,,,,,,,,,,,,,,,300.375793457031,300.382171630859,-13000.419921875,-13000.419921875,53.6412112035153,5.884341790875,6.13131809234619,55,1,68,0,0,0.332183837890625,34.2131004333496,1,1,3,300.382171630859,0,300.378982543945,,,,,,,,,,,,,,,,,,,,,,,,,,,,,,,,,
,3881355374.60961,300.34504699707,-12000.3076171875,2.20793546341761E-4,2.18943571249934E-8,1,4,14.0008964538574,5.00437559877272,33.2500003278255,0.274696989388815,0.0416280508669995,1,-7.72123830625077E-8,,,,,,,,,,,,,,,,,,,,,300.324005126953,300.366088867188,-12000.3076171875,-12000.3076171875,53.521622040073,5.88440205132021,6.1346378326416,56,1,0,0,1,0.33111572265625,34.2131004333496,1,1,3,300.366088867188,0,300.34504699707,,,,,,,,,,,,,,,,,,,,,,,,,,,,,,,,,
,3881355413.40346,300.370635986328,-11000.4736328125,2.02391792294542E-4,2.53448808744511E-8,1,4,14.0008964538574,5.00432056377736,33.2500003278255,0.25180209218672,0.0381366795249627,1,-8.79373879075376E-8,,,,,,,,,,,,,,,,,,,,,300.350189208984,300.391082763672,-11000.4736328125,-11000.4736328125,53.531783210823,5.88329385910849,6.12802886962891,55,1,68,0,0,0.331497192382812,33.7243423461914,1,1,3,300.391082763672,0,300.370635986328,,,,,,,,,,,,,,,,,,,,,,,,,,,,,,,,,
,3881355465.06289,300.380157470703,-10000.3623046875,1.83887015449643E-4,1.67588784104172E-8,1,4,14.0008964538574,5.00427759121203,33.2500003278255,0.228775106239222,0.0346616181109712,1,-7.0082975435541E-8,,,,,,,,,,,,,,,,,,,,,300.376525878906,300.3837890625,-10000.3623046875,-10000.3623046875,53.5661748656691,5.88325948821051,6.1283540725708,54,1,68,0,0,0.331344604492188,34.2131004333496,1,1,3,300.3837890625,0,300.380157470703,,,,,,,,,,,,,,,,,,,,,,,,,,,,,,,,,
,3881355504.10199,300.361938476562,-9000.2119140625,1.65424247211966E-4,2.1359177651159E-8,1,4,14.0008964538574,5.00420006786757,33.2500003278255,0.20580005004007,0.0311870062309143,1,-5.80732991954979E-8,,,,,,,,,,,,,,,,,,,,,300.351379394531,300.372497558594,-9000.2119140625,-9000.2119140625,53.5345189106403,5.88316777350392,6.12499666213989,56,1,0,0,1,0.331268310546875,34.2131004333496,1,1,3,300.350646972656,0,300.361938476562,,,,,,,,,,,,,,,,,,,,,,,,,,,,,,,,,
,3881355544.50172,300.209762573242,-8000.263671875,1.47028932474902E-4,1.94156894296356E-8,1,4,14.0008964538574,5.00422811861034,33.2599990069866,0.182922700477651,0.027677370401031,1,-8.52419857158787E-8,,,,,,,,,,,,,,,,,,,,,300.200134277344,300.219390869141,-8000.263671875,-8000.263671875,53.5650024228903,5.88324856474258,6.11915445327759,55,1,68,0,0,0.3338623046875,33.7243423461914,1,1,3,300.219390869141,0,300.209762573242,,,,,,,,,,,,,,,,,,,,,,,,,,,,,,,,,
,3881355585.78074,300.23518371582,-7000.3662109375,1.28566865047867E-4,1.52289829819493E-8,1,4,14.0008964538574,5.00424493941358,33.2500003278255,0.15994996290477,0.0242305993158433,1,-5.16323607036135E-8,,,,,,,,,,,,,,,,,,,,,300.217926025391,300.25244140625,-7000.3662109375,-7000.3662109375,53.7084312561692,5.88309356710473,6.12223148345947,56,1,0,0,1,0.32958984375,34.2131004333496,1,1,3,300.25244140625,0,300.23518371582,,,,,,,,,,,,,,,,,,,,,,,,,,,,,,,,,
,3881355626.11088,300.323486328125,-6000.26708984375,1.10102680466997E-4,1.43376779465138E-8,1,4,14.0008964538574,5.00420217362709,33.2500003278255,0.136975268006824,0.0207621574327299,1,-3.48169998506157E-8,,,,,,,,,,,,,,,,,,,,,300.309753417969,300.337219238281,-6000.26708984375,-6000.26708984375,53.613072576823,5.88276257273839,6.12666893005371,56,1,0,0,1,0.330123901367188,34.2131004333496,1,1,3,300.337219238281,0,300.323486328125,,,,,,,,,,,,,,,,,,,,,,,,,,,,,,,,,
,3881355678.96907,300.37580871582,-5000.2939453125,9.16482737424829E-5,1.10720485233007E-8,1,4,14.0008964538574,5.00438257459969,33.2500003278255,0.114021225783526,0.0172912688238648,1,-2.23872603426992E-8,,,,,,,,,,,,,,,,,,,,,300.370635986328,300.380981445313,-5000.2939453125,-5000.2939453125,53.5313923965634,5.88267393114856,6.11666488647461,56,1,0,0,1,0.332489013671875,33.7243423461914,1,1,3,300.380981445313,0,300.37580871582,,,,,,,,,,,,,,,,,,,,,,,,,,,,,,,,,
,3881355718.77752,300.294906616211,-4000.37109375,7.32143428656266E-5,1.05367449452477E-8,1,4,14.0008964538574,5.00448273347202,33.2500003278255,0.0910918585827013,0.0138001655029893,1,-2.87856851573091E-8,,,,,,,,,,,,,,,,,,,,,300.281158447266,300.308654785156,-4000.37109375,-4000.37109375,53.5864972071691,5.88187181970313,6.12182664871216,56,1,0,0,1,0.331497192382812,33.7243423461914,1,1,3,300.308654785156,0,300.294906616211,,,,,,,,,,,,,,,,,,,,,,,,,,,,,,,,,
,3881355759.12914,300.390289306641,-3000.48608398438,5.47483460804093E-5,9.08499844947357E-9,1,4,14.0008964538574,5.00461557972262,33.2500003278255,0.0681183249060573,0.0103266694175689,1,-1.60799052337566E-8,,,,,,,,,,,,,,,,,,,,,300.382263183594,300.398315429687,-3000.48608398438,-3000.48608398438,53.6462917888903,5.88182558220524,6.11524677276611,56,1,0,0,1,0.330963134765625,33.7243423461914,1,1,3,300.398315429687,0,300.390289306641,,,,,,,,,,,,,,,,,,,,,,,,,,,,,,,,,
,3881355826.85522,300.428024291992,-2510.50073242187,4.57075363523817E-5,7.71295934233402E-9,1,4,14.0008964538574,5.00435430675842,33.2500003278255,0.0568718490298482,0.00857912921280494,1,-4.68852996025664E-8,,,,,,,,,,,,,,,,,,,,,300.423889160156,300.432159423828,-2510.50073242187,-2510.50073242187,53.5345189106403,5.88187648685635,6.11703634262085,56,1,0,0,1,0.330734252929687,34.2131004333496,1,1,3,300.423889160156,0,300.428024291992,,,,,,,,,,,,,,,,,,,,,,,,,,,,,,,,,
,3881355867.23312,300.263275146484,-1930.33337402344,3.49980339100836E-5,7.8112611562089E-9,1,4,14.0008964538574,5.00431841885737,33.2500003278255,0.0435388456703075,0.00661639866575705,1,2.25609453068111E-9,,,,,,,,,,,,,,,,,,,,,300.261749267578,300.264801025391,-1930.33337402344,-1930.33337402344,53.6185439764576,5.88199016518061,6.11632299423218,56,1,0,0,1,0.331802368164063,34.2131004333496,1,1,3,300.261749267578,0,300.263275146484,,,,,,,,,,,,,,,,,,,,,,,,,,,,,,,,,
,3881355906.66614,300.314880371094,-1350.31701660156,2.42808412783036E-5,5.28276443660439E-8,1,4,14.0008964538574,5.00420192058088,33.2500003278255,0.0301980267569684,0.00463790208614556,1,3.99446822389504E-8,,,,,,,,,,,,,,,,,,,,,300.299407958984,300.330352783203,-1350.31701660156,-1350.31701660156,53.5239669256307,5.88252137875863,6.12044191360474,56,1,0,0,1,0.331649780273438,34.2131004333496,1,1,3,300.330352783203,0,300.314880371094,,,,,,,,,,,,,,,,,,,,,,,,,,,,,,,,,
,3881355957.40599,300.376434326172,-770.514526367187,1.35694301673066E-5,6.75542494952302E-9,1,4,14.0008964538574,5.00408053802988,33.2500003278255,0.0168811190072196,0.00255612292093653,1,-6.37240840820936E-9,,,,,,,,,,,,,,,,,,,,,300.372344970703,300.380523681641,-770.514526367187,-770.514526367187,53.6161990908999,5.88272288927734,6.11061334609985,56,1,0,0,1,0.33203125,34.2131004333496,1,1,3,300.371917724609,0,300.376434326172,,,,,,,,,,,,,,,,,,,,,,,,,,,,,,,,,
,3881355996.63907,300.227828979492,-190.246292114258,2.84314033197988E-6,3.82861568458113E-8,1,4,14.0008964538574,5.00397566243435,33.2500003278255,0.00352984698199607,5.82118132443191E-4,1,3.6095500250721E-8,,,,,,,,,,,,,,,,,,,,,300.217956542969,300.237701416016,-190.246292114258,-190.246292114258,53.6490274887076,5.8832671901768,6.11491060256958,56,1,0,0,1,0.330352783203125,33.7243423461914,1,1,3,300.217956542969,0,300.227828979492,,,,,,,,,,,,,,,,,,,,,,,,,,,,,,,,,
,3881356035.55143,300.261154174805,389.644256591797,-7.88345036723816E-6,2.34943755602898E-8,1,4,14.0008964538574,5.00404730511916,33.2500003278255,-0.00981195101495561,-0.00145476780536514,1,2.80218993074146E-8,,,,,,,,,,,,,,,,,,,,,300.258331298828,300.263977050781,389.644256591797,389.644256591797,53.5966583779191,5.88291852168765,6.11718893051148,56,1,0,0,1,0.331573486328125,33.7243423461914,1,1,3,300.258331298828,0,300.261154174805,,,,,,,,,,,,,,,,,,,,,,,,,,,,,,,,,
,3881356075.05111,300.335647583008,969.673278808594,-1.85532210590067E-5,2.85439789681289E-8,1,4,14.0008964538574,5.00389944937315,33.2599990069866,-0.0230796694415033,-0.00349734081490995,1,6.63878321432232E-9,,,,,,,,,,,,,,,,,,,,,300.333190917969,300.338104248047,969.673278808594,969.673278808594,53.6154174623807,5.88353412690424,6.11774635314941,56,1,0,0,1,0.330963134765625,33.7243423461914,1,1,3,300.338104248047,0,300.335647583008,,,,,,,,,,,,,,,,,,,,,,,,,,,,,,,,,
,3881356114.11796,300.379318237305,1549.56384277344,-2.9221316247735E-5,1.05579428725075E-7,1,4,14.0008964538574,5.00384985520787,33.2500003278255,-0.0363381679230079,-0.00558591012000573,1,-5.19901457878552E-8,,,,,,,,,,,,,,,,,,,,,300.376708984375,300.381927490234,1549.56384277344,1549.56384277344,53.6290959614672,5.88366948969788,6.1164493560791,56,1,0,0,1,0.330810546875,33.2355842590332,1,1,3,300.376708984375,0,300.379318237305,,,,,,,,,,,,,,,,,,,,,,,,,,,,,,,,,
,3881356154.18634,300.335784912109,2129.4921875,-3.99736404727689E-5,3.49077686274773E-8,1,4,14.0008964538574,5.00392063419871,33.2500003278255,-0.0497371485970674,-0.00746407893224185,1,7.14806647104917E-8,,,,,,,,,,,,,,,,,,,,,300.316741943359,300.354827880859,2129.4921875,2129.4921875,53.5950951208807,5.88375749767297,6.11596965789795,56,1,0,0,1,0.33203125,33.7243423461914,1,1,3,300.354827880859,0,300.335784912109,,,,,,,,,,,,,,,,,,,,,,,,,,,,,,,,,
,3881356193.26516,300.330947875977,2709.69750976562,-5.0592613891129E-5,1.39468159306412E-8,1,4,14.0008964538574,5.0039766785735,33.2500003278255,-0.062947076747504,-0.00947142240039365,1,7.08803968365942E-8,,,,,,,,,,,,,,,,,,,,,300.318817138672,300.343078613281,2709.69750976562,2709.69750976562,53.6580162166788,5.8838594593421,6.11096715927124,56,1,0,0,1,0.332183837890625,34.2131004333496,1,1,3,300.343078613281,0,300.330947875977,,,,,,,,,,,,,,,,,,,,,,,,,,,,,,,,,
,3881356262.05033,300.428588867188,3499.76147460937,-6.50437348187342E-5,7.74925598384665E-9,1,4,14.0008964538574,5.00394723838404,33.2599990069866,-0.0809274011142735,-0.0121702719530261,1,9.63025493585845E-8,,,,,,,,,,,,,,,,,,,,,300.427215576172,300.429962158203,3499.76147460937,3499.76147460937,53.5196679687749,5.884423177876,6.1145133972168,56,1,0,0,1,0.327911376953125,33.7243423461914,1,1,3,300.424865722656,0,300.428588867188,,,,,,,,,,,,,,,,,,,,,,,,,,,,,,,,,
,3881356318.51943,300.465179443359,4499.78466796875,-8.34533785152486E-5,1.16758584955444E-8,1,4,14.0008964538574,5.00403551321424,33.2500003278255,-0.103835400760576,-0.0156141955582976,1,1.24421905823639E-7,,,,,,,,,,,,,,,,,,,,,300.45703125,300.473327636719,4499.78466796875,4499.78466796875,53.6920170572653,5.88379209426388,6.1062707901001,56,1,0,0,1,0.329818725585937,34.2131004333496,1,1,3,300.45703125,0,300.465179443359,,,,,,,,,,,,,,,,,,,,,,,,,,,,,,,,,
,3881356360.74163,300.326797485352,5499.4814453125,-1.01841250952814E-4,1.59007843278695E-8,1,4,14.0008964538574,5.00402513179491,33.2500003278255,-0.126711766908571,-0.0190680455242164,1,1.40968643433876E-7,,,,,,,,,,,,,,,,,,,,,300.316864013672,300.336730957031,5499.4814453125,5499.4814453125,53.5442892671307,5.88476897877207,6.1070876121521,56,1,0,0,1,0.3314208984375,33.7243423461914,1,1,3,300.316864013672,0,300.326797485352,,,,,,,,,,,,,,,,,,,,,,,,,,,,,,,,,
,3881356401.69925,300.146865844727,6499.55517578125,-1.20258367879846E-4,1.6750252918272E-8,1,4,14.0008964538574,5.0040743033495,33.2500003278255,-0.14963104846369,-0.0225002635480513,1,1.79632368706846E-7,,,,,,,,,,,,,,,,,,,,,300.140869140625,300.152862548828,6499.55517578125,6499.55517578125,53.5407719387941,5.88357480455898,6.11191606521606,56,1,0,0,1,0.331268310546875,33.7243423461914,1,1,3,300.140869140625,0,300.146865844727,,,,,,,,,,,,,,,,,,,,,,,,,,,,,,,,,
,3881356442.29187,300.189193725586,7499.50341796875,-1.3866671326018E-4,1.9602148179393E-8,1,4,14.0008964538574,5.00406622324217,33.2500003278255,-0.172529331884842,-0.0259828772655056,1,1.76193692240928E-7,,,,,,,,,,,,,,,,,,,,,300.180084228516,300.198303222656,7499.50341796875,7499.50341796875,53.6290959614672,5.88624495524011,6.10914325714111,55,1,68,0,0,0.331649780273438,33.7243423461914,1,1,3,300.198303222656,0,300.189193725586,,,,,,,,,,,,,,,,,,,,,,,,,,,,,,,,,
,3881356481.83946,300.313552856445,8499.564453125,-1.57073914852836E-4,2.13622864244942E-8,1,4,14.0008964538574,5.00378077733,33.2500003278255,-0.195407478472225,-0.0294857562945112,1,1.54439951306761E-7,,,,,,,,,,,,,,,,,,,,,300.29541015625,300.331695556641,8499.564453125,8499.564453125,53.5380362389768,5.8864330404894,6.1095757484436,56,1,0,0,1,0.33203125,34.2131004333496,1,1,3,300.331695556641,0,300.313552856445,,,,,,,,,,,,,,,,,,,,,,,,,,,,,,,,,
,3881356548.4235,300.440811157227,9499.8271484375,-1.7554984446556E-4,1.91610497166806E-8,1,4,14.0008964538574,5.00406040620252,33.2500003278255,-0.218405306978135,-0.032984155779808,1,1.50466326757841E-7,,,,,,,,,,,,,,,,,,,,,300.430450439453,300.451171875,9499.8271484375,9499.8271484375,53.6951435713422,5.88495993086982,6.10318899154663,56,1,0,0,1,0.32928466796875,33.7243423461914,1,1,3,300.430450439453,0,300.440811157227,,,,,,,,,,,,,,,,,,,,,,,,,,,,,,,,,
,3881356590.44051,300.369842529297,10499.5859375,-1.93903140872052E-4,2.35938384068176E-8,1,4,14.0008964538574,5.00422238817637,33.2500003278255,-0.241251820902148,-0.0364219403041439,1,1.76065031921173E-7,,,,,,,,,,,,,,,,,,,,,300.356750488281,300.382934570313,10499.5859375,10499.5859375,53.7049139278326,5.88463567232021,6.10642337799072,56,1,0,0,1,0.329666137695313,33.7243423461914,1,1,3,300.382934570313,0,300.369842529297,,,,,,,,,,,,,,,,,,,,,,,,,,,,,,,,,
,3881356642.64578,300.443054199219,11499.546875,-2.12373974778974E-4,2.58585431320308E-8,1,4,14.0008964538574,5.00421414379638,33.2500003278255,-0.264224628008875,-0.0399424216336646,1,1.51767567541001E-7,,,,,,,,,,,,,,,,,,,,,300.440277099609,300.445831298828,11499.546875,11499.546875,53.6099460627461,5.88340020565497,6.11084270477295,56,1,0,0,1,0.331192016601562,33.7243423461914,1,1,3,300.440277099609,0,300.443054199219,,,,,,,,,,,,,,,,,,,,,,,,,,,,,,,,,
,3881356682.8241,300.293609619141,12499.74609375,-2.30815829079158E-4,3.87222069668108E-8,1,4,14.0008964538574,5.00424297343528,33.2500003278255,-0.287178596862377,-0.0433634358154805,1,2.03373123110995E-7,,,,,,,,,,,,,,,,,,,,,300.273895263672,300.313323974609,12499.74609375,12499.74609375,53.5685197512268,5.88378056799744,6.10850477218628,56,1,0,0,1,0.3314208984375,33.7243423461914,1,1,3,300.313323974609,0,300.293609619141,,,,,,,,,,,,,,,,,,,,,,,,,,,,,,,,,
,3881356735.91236,300.276153564453,13499.6318359375,-2.4923942787249E-4,4.4140613813815E-8,1,4,14.0008964538574,5.00424210788964,33.2500003278255,-0.310093655714757,-0.0468728056143302,1,1.80913752007745E-7,,,,,,,,,,,,,,,,,,,,,300.265502929687,300.286804199219,13499.6318359375,13499.6318359375,53.5720370795634,5.88315179191899,6.10020637512207,56,1,0,0,1,0.332260131835937,33.7243423461914,1,1,3,300.286804199219,0,300.276153564453,,,,,,,,,,,,,,,,,,,,,,,,,,,,,,,,,
,3881356776.38048,300.166625976562,14499.517578125,-2.67646966461543E-4,6.72744258785465E-8,1,4,14.0008964538574,5.00435962192909,33.2599990069866,-0.333001405806357,-0.0503698452184002,1,1.67264556789615E-7,,,,,,,,,,,,,,,,,,,,,300.157165527344,300.176086425781,14499.517578125,14499.517578125,53.5200587830345,5.88278676204174,6.10094451904297,56,1,0,0,1,0.33111572265625,34.2131004333496,1,1,3,300.157165527344,0,300.166625976562,,,,,,,,,,,,,,,,,,,,,,,,,,,,,,,,,
,3881356851.88324,300.206817626953,19999.541015625,-3.69091924856533E-4,3.49244112385034E-8,1,4,14.0008964538574,5.00418420814886,33.2500003278255,-0.45918396948701,-0.0695294138105819,1,1.73161695494051E-7,,,,,,,,,,,,,,,,,,,,,300.206359863281,300.207275390625,19999.541015625,19999.541015625,53.6267510759095,5.88273711478576,6.10166120529175,56,1,0,0,1,0.330657958984375,34.2131004333496,1,1,3,300.206359863281,0,300.206817626953,,,,,,,,,,,,,,,,,,,,,,,,,,,,,,,,,
,3881356936.15046,300.188995361328,29999.9140625,-5.53271549614892E-4,6.10127006971305E-8,1,4,14.0008964538574,5.00421618848558,33.2500003278255,-0.688292185691436,-0.104450948960995,1,7.87790293114638E-8,,,,,,,,,,,,,,,,,,,,,300.166290283203,300.211700439453,29999.9140625,29999.9140625,53.5392086817557,5.88224247409459,6.10696601867676,56,1,0,0,1,0.331039428710937,33.2355842590332,1,1,3,300.211700439453,0,300.188995361328,,,,,,,,,,,,,,,,,,,,,,,,,,,,,,,,,
,3881357022.36604,300.073577880859,40000.36328125,-7.3822723366822E-4,1.36027725064827E-7,1,4,14.0008964538574,5.00416096753683,33.2500003278255,-0.918355917164946,-0.139461292013317,1,2.86614086702545E-8,,,,,,,,,,,,,,,,,,,,,300.069458007812,300.077697753906,40000.36328125,40000.36328125,53.4563560587172,5.88249833937084,6.10570526123047,55,1,68,0,0,0.331497192382812,33.7243423461914,1,1,3,300.069458007812,0,300.073577880859,,,,,,,,,,,,,,,,,,,,,,,,,,,,,,,,,
,3881357134.69779,300.159484863281,50000.30859375,-9.22309918322392E-4,1.45364451793587E-7,1,4,14.0008964538574,5.00409242534003,33.2500003278255,-1.1472930779562,-0.174497227183854,1,-1.76028233387174E-7,,,,,,,,,,,,,,,,,,,,,300.137847900391,300.181121826172,50000.30859375,50000.30859375,53.493092599121,5.88207287583195,6.09887266159058,56,1,0,0,1,0.3314208984375,33.7243423461914,1,1,3,300.181121826172,0,300.159484863281,,,,,,,,,,,,,,,,,,,,,,,,,,,,,,,,,
,3881357221.72967,300.096969604492,60000.484375,-0.00110722915798671,2.83902133044869E-7,1,4,14.0008964538574,5.00406444170198,33.2500003278255,-1.37725313515103,-0.209854045186982,1,-5.10767917278766E-7,,,,,,,,,,,,,,,,,,,,,300.073608398438,300.120330810547,60000.484375,60000.484375,53.3418474806499,5.88183968791139,6.105788230896,55,1,68,0,0,0.33203125,33.7243423461914,1,1,3,300.120330810547,0,300.096969604492,,,,,,,,,,,,,,,,,,,,,,,,,,,,,,,,,
,3881357335.21282,300.044586181641,70000.40625,-0.00129116536918324,3.508940249028E-7,1,4,14.0008964538574,5.0042385004774,33.2500003278255,-1.60609497571461,-0.244922993314452,1,-7.52740147929447E-7,,,,,,,,,,,,,,,,,,,,,300.01904296875,300.070129394531,70000.40625,70000.40625,53.308237454323,5.88237806334664,6.09800338745117,56,1,0,0,1,0.329666137695313,33.7243423461914,1,1,3,300.070129394531,0,300.044586181641,,,,,,,,,,,,,,,,,,,,,,,,,,,,,,,,,
,3881357339.06631,300.088424682617,70000.40625,-0.00129165389514217,3.92248229950617E-7,1,4,14.0008964538574,5.00422401053893,33.2500003278255,-1.6067039116773,-0.244963586368211,1,-7.11961256008465E-7,,,,,,,,,,,,,,,,,,,,,300.070129394531,300.106719970703,70000.40625,70000.40625,53.3395025950922,5.88257901886084,6.09555244445801,56,2,0,0,1,0.331192016601562,34.2131004333496,1,1,3,300.106719970703,0,300.088424682617,,,,,,,,,,,,,,,,,,,,,,,,,,,,,,,,,