File: XRD:XRR/SCO/22102_S(CT)OL/22102_S(CT)OL_XRD_notAnn_001.ras
*RAS_DATA_START
*RAS_HEADER_START
*DISP_FMT_X "%.4f"
*DISP_FMT_Y "%.0f"
*DISP_FULLSCALE "233031.8924000000"
*DISP_LINE_COLOR "255.0000000000"
*DISP_LINE_STYLE "0.0000000000"
*DISP_LINE_WIDTH "0.2500000000"
*DISP_NOTE "Collected Data-334"
*DISP_OFFSET_Y "0.0000000000"
*DISP_PEAKSEARCH_UNIT_Y "cps"
*DISP_RANGE_BOTTOM "0.0100000000"
*DISP_RANGE_LEFT "15.9952000000"
*DISP_RANGE_LOGCUTOFF "0.0100000000"
*DISP_RANGE_RIGHT "31.0050000000"
*DISP_RANGE_TOP "233031.8924000000"
*DISP_SCALE_MODE_Y "2.0000000000"
*DISP_TAB_NAME "2-Theta/Omega"
*DISP_TITLE_Y "Intensity"
*DISP_UNIT_Y "cps"
*DISP_WINDOW_NAME "MSG_MACROENGINE"
*FILE_COMMENT " "
*FILE_MD5 ""
*FILE_MEMO " "
*FILE_OPERATOR "administrator"
*FILE_PART_ID "MEAS_KHP2_00061"
*FILE_SAMPLE " "
*FILE_TYPE "RAS_RAW"
*FILE_USERGROUP "System Manager"
*FILE_VERSION "1.0000000000"
*HW_ATTACHMENT_ID "ATT0022"
*HW_ATTACHMENT_NAME "RxRy|RxRy"
*HW_COUNTER_ID-0 "CUT0041"
*HW_COUNTER_ID-1 "CUT0020"
*HW_COUNTER_ID-2 "CUT0020"
*HW_COUNTER_ID-3 "CSL0021"
*HW_COUNTER_ID-4 "CMC0021"
*HW_COUNTER_NAME-0 "D/teX Ultra 250|D/teX Ultra 250"
*HW_COUNTER_NAME-1 "None|None"
*HW_COUNTER_NAME-2 "None|None"
*HW_COUNTER_NAME-3 "BBM|BBM"
*HW_COUNTER_NAME-4 "検出器モノクロメータ|Detector monochromator"
*HW_COUNTER_SELECT_NAME "D/teX Ultra 250|D/teX Ultra 250"
*HW_GONIOMETER_ID "GON0024"
*HW_GONIOMETER_NAME "SmartLab(In-plane)|SmartLab(In-plane)"
*HW_GONIOMETER_RADIUS-0 "90.0"
*HW_GONIOMETER_RADIUS-1 "114.0"
*HW_GONIOMETER_RADIUS-2 "190.0"
*HW_GONIOMETER_RADIUS-3 "300.0"
*HW_GONIOMETER_RADIUS-4 "187.0"
*HW_GONIOMETER_RADIUS-5 "300.0"
*HW_GONIOMETER_RADIUS-6 "113.0"
*HW_GONIOMETER_RADIUS-7 "331.0"
*HW_I_OPT_ID-0 "CBO0021"
*HW_I_OPT_ID-1 "ICR0021"
*HW_I_OPT_ID-2 "ISL0021"
*HW_I_OPT_ID-3 "ISO0021"
*HW_I_OPT_ID-4 "IAD0021"
*HW_I_OPT_ID-5 "IPR0001"
*HW_I_OPT_NAME-0 "CBOユニット|CBO unit"
*HW_I_OPT_NAME-1 "標準入射光学ユニット|Standard incident optical unit"
*HW_I_OPT_NAME-2 "標準入射スリットボックス|Standard incident slit box"
*HW_I_OPT_NAME-3 "入射平行スリット|Incident parallel slit"
*HW_I_OPT_NAME-4 "長手制限スリット|Length limiting slit"
*HW_I_OPT_NAME-5 "None|None"
*HW_R_ATTENUATER_AUTOMODE "1"
*HW_R_OPT_ID-0 "RSS0021"
*HW_R_OPT_ID-1 "RCR0022"
*HW_R_OPT_ID-2 "RSO0021"
*HW_R_OPT_ID-3 "RRS0021"
*HW_R_OPT_ID-4 "ATN0021"
*HW_R_OPT_ID-5 "RFL0021"
*HW_R_OPT_ID-6 "RAD0021"
*HW_R_OPT_NAME-0 "標準受光スリットボックス1|Standard receiving slit box # 1"
*HW_R_OPT_NAME-1 "標準受光光学ユニット1|Standard receiving unit # 1"
*HW_R_OPT_NAME-2 "標準受光光学ユニット2|Standard receiving optical unit # 2"
*HW_R_OPT_NAME-3 "標準受光スリットボックス2|Standard receiving slit box # 2"
*HW_R_OPT_NAME-4 "標準アッテネータ|Standard Attenuator"
*HW_R_OPT_NAME-5 "Cu Kβ|Cu K-beta"
*HW_R_OPT_NAME-6 "調整用受光スリット|Alignment receiving slit"
*HW_SAMPLE_HOLDER_ID "SMP0026"
*HW_SAMPLE_HOLDER_NAME "Z-φステージ|Z-Phi Stage"
*HW_XG_CURRENT_MAX "50"
*HW_XG_CURRENT_MIN "2"
*HW_XG_CURRENT_RESOLUTION "1"
*HW_XG_CURRENT_UNIT "mA"
*HW_XG_FOCUS "1mm x 10mm"
*HW_XG_FOCUS_TYPE "Normal"
*HW_XG_ID "1200"
*HW_XG_NAME "3kW 封入管(ID:1200)|3kW Sealed tube(ID:1200)"
*HW_XG_TARGET_ATOMIC_NUMBER "29.0000000000"
*HW_XG_TARGET_NAME "Cu"
*HW_XG_TYPE "Hermetic"
*HW_XG_VOLTAGE_MAX "50"
*HW_XG_VOLTAGE_MIN "20"
*HW_XG_VOLTAGE_RESOLUTION "1"
*HW_XG_VOLTAGE_UNIT "kV"
*HW_XG_WATT_MAX "2"
*HW_XG_WATT_UNIT "kW"
*HW_XG_WAVE_LENGTH_ALPHA1 "1.540593"
*HW_XG_WAVE_LENGTH_ALPHA2 "1.544414"
*HW_XG_WAVE_LENGTH_BETA "1.392250"
*MEAS_COND_AXIS_NAME-0 "Theta/2-Theta"
*MEAS_COND_AXIS_NAME-1 "2-Theta"
*MEAS_COND_AXIS_NAME-2 "Omega"
*MEAS_COND_AXIS_NAME-3 "Phi"
*MEAS_COND_AXIS_NAME-4 "Z"
*MEAS_COND_AXIS_NAME-5 "Rx"
*MEAS_COND_AXIS_NAME-6 "Ry"
*MEAS_COND_AXIS_NAME-7 "2-Theta/Omega"
*MEAS_COND_AXIS_NAME-8 "2-ThetaChi"
*MEAS_COND_AXIS_NAME-9 "2-ThetaChi/Phi"
*MEAS_COND_AXIS_NAME-10 "Alpha"
*MEAS_COND_AXIS_NAME-11 "Beta"
*MEAS_COND_AXIS_NAME-12 "Theta_s"
*MEAS_COND_AXIS_NAME-13 "Theta_d"
*MEAS_COND_AXIS_NAME-14 "Ts"
*MEAS_COND_AXIS_NAME-15 "CBO selection slit"
*MEAS_COND_AXIS_NAME-16 "M"
*MEAS_COND_AXIS_NAME-17 "Incident parallel slit"
*MEAS_COND_AXIS_NAME-18 "Incident slit"
*MEAS_COND_AXIS_NAME-19 ""
*MEAS_COND_AXIS_NAME-20 "Zs"
*MEAS_COND_AXIS_NAME-21 "Incident optical device"
*MEAS_COND_AXIS_NAME-22 "Omega_m"
*MEAS_COND_AXIS_NAME-23 "Length limiting slit"
*MEAS_COND_AXIS_NAME-24 "Center slit"
*MEAS_COND_AXIS_NAME-25 "Filter"
*MEAS_COND_AXIS_NAME-26 "Receiving slit # 1"
*MEAS_COND_AXIS_NAME-27 "Receiving slit # 2"
*MEAS_COND_AXIS_NAME-28 "Receiving optical device"
*MEAS_COND_AXIS_NAME-29 "Receiving parallel slit"
*MEAS_COND_AXIS_NAME-30 "Alignment receiving slit"
*MEAS_COND_AXIS_NAME-31 ""
*MEAS_COND_AXIS_NAME-32 ""
*MEAS_COND_AXIS_NAME-33 "Zd"
*MEAS_COND_AXIS_NAME-34 "Attenuator"
*MEAS_COND_AXIS_NAME-35 "Diffracted beam monochromator"
*MEAS_COND_AXIS_NAME-36 "Monochromator slit"
*MEAS_COND_AXIS_NAME-37 "2-ThetaB"
*MEAS_COND_AXIS_NAME-38 "Primary beam"
*MEAS_COND_AXIS_NAME-39 "PHA"
*MEAS_COND_AXIS_NAME_INTERNAL-0 "TwoThetaTheta"
*MEAS_COND_AXIS_NAME_INTERNAL-1 "TwoTheta"
*MEAS_COND_AXIS_NAME_INTERNAL-2 "Omega"
*MEAS_COND_AXIS_NAME_INTERNAL-3 "Phi"
*MEAS_COND_AXIS_NAME_INTERNAL-4 "Z"
*MEAS_COND_AXIS_NAME_INTERNAL-5 "Rx"
*MEAS_COND_AXIS_NAME_INTERNAL-6 "Ry"
*MEAS_COND_AXIS_NAME_INTERNAL-7 "TwoThetaOmega"
*MEAS_COND_AXIS_NAME_INTERNAL-8 "TwoThetaChi"
*MEAS_COND_AXIS_NAME_INTERNAL-9 "TwoThetaChiPhi"
*MEAS_COND_AXIS_NAME_INTERNAL-10 "Alpha"
*MEAS_COND_AXIS_NAME_INTERNAL-11 "Beta"
*MEAS_COND_AXIS_NAME_INTERNAL-12 "ThetaS"
*MEAS_COND_AXIS_NAME_INTERNAL-13 "ThetaD"
*MEAS_COND_AXIS_NAME_INTERNAL-14 "Ts"
*MEAS_COND_AXIS_NAME_INTERNAL-15 "CBO"
*MEAS_COND_AXIS_NAME_INTERNAL-16 "CBO-M"
*MEAS_COND_AXIS_NAME_INTERNAL-17 "IncidentSollerSlit"
*MEAS_COND_AXIS_NAME_INTERNAL-18 "IncidentSlitBox"
*MEAS_COND_AXIS_NAME_INTERNAL-19 "IncidentSlitBox-_Axis"
*MEAS_COND_AXIS_NAME_INTERNAL-20 "Zs"
*MEAS_COND_AXIS_NAME_INTERNAL-21 "IncidentMonochromator"
*MEAS_COND_AXIS_NAME_INTERNAL-22 "IncidentMonochromator-OmegaM"
*MEAS_COND_AXIS_NAME_INTERNAL-23 "IncidentAxdSlit"
*MEAS_COND_AXIS_NAME_INTERNAL-24 "CenterSlit"
*MEAS_COND_AXIS_NAME_INTERNAL-25 "Filter"
*MEAS_COND_AXIS_NAME_INTERNAL-26 "ReceivingSlitBox1"
*MEAS_COND_AXIS_NAME_INTERNAL-27 "ReceivingSlitBox2"
*MEAS_COND_AXIS_NAME_INTERNAL-28 "ReceivingOptics"
*MEAS_COND_AXIS_NAME_INTERNAL-29 "ReceivingSollerSlit"
*MEAS_COND_AXIS_NAME_INTERNAL-30 "ReceivingAxdSlit"
*MEAS_COND_AXIS_NAME_INTERNAL-31 "ReceivingSlitBox1-_Axis"
*MEAS_COND_AXIS_NAME_INTERNAL-32 "ReceivingSlitBox2-_Axis"
*MEAS_COND_AXIS_NAME_INTERNAL-33 "ReceivingSlitBox2-Zd"
*MEAS_COND_AXIS_NAME_INTERNAL-34 "Attenuator"
*MEAS_COND_AXIS_NAME_INTERNAL-35 "CounterMonochromator"
*MEAS_COND_AXIS_NAME_INTERNAL-36 "CounterSlit"
*MEAS_COND_AXIS_NAME_INTERNAL-37 "TwoThetaB"
*MEAS_COND_AXIS_NAME_INTERNAL-38 "IncidentPrimary"
*MEAS_COND_AXIS_NAME_INTERNAL-39 "PHA"
*MEAS_COND_AXIS_NAME_MAGICNO-0 "83951616.0000000000"
*MEAS_COND_AXIS_NAME_MAGICNO-1 "268632064.0000000000"
*MEAS_COND_AXIS_NAME_MAGICNO-2 "268500992.0000000000"
*MEAS_COND_AXIS_NAME_MAGICNO-3 "268500992.0000000000"
*MEAS_COND_AXIS_NAME_MAGICNO-4 "285278208.0000000000"
*MEAS_COND_AXIS_NAME_MAGICNO-5 "285278208.0000000000"
*MEAS_COND_AXIS_NAME_MAGICNO-6 "285278208.0000000000"
*MEAS_COND_AXIS_NAME_MAGICNO-7 "83951616.0000000000"
*MEAS_COND_AXIS_NAME_MAGICNO-8 "268632064.0000000000"
*MEAS_COND_AXIS_NAME_MAGICNO-9 "83951616.0000000000"
*MEAS_COND_AXIS_NAME_MAGICNO-10 "17039360.0000000000"
*MEAS_COND_AXIS_NAME_MAGICNO-11 "17039360.0000000000"
*MEAS_COND_AXIS_NAME_MAGICNO-12 "131072.0000000000"
*MEAS_COND_AXIS_NAME_MAGICNO-13 "131072.0000000000"
*MEAS_COND_AXIS_NAME_MAGICNO-14 "318898176.0000000000"
*MEAS_COND_AXIS_NAME_MAGICNO-15 "20971521.0000000000"
*MEAS_COND_AXIS_NAME_MAGICNO-16 "285343744.0000000000"
*MEAS_COND_AXIS_NAME_MAGICNO-17 "20971521.0000000000"
*MEAS_COND_AXIS_NAME_MAGICNO-18 "22020097.0000000000"
*MEAS_COND_AXIS_NAME_MAGICNO-19 "25165824.0000000000"
*MEAS_COND_AXIS_NAME_MAGICNO-20 "318898176.0000000000"
*MEAS_COND_AXIS_NAME_MAGICNO-21 "20971521.0000000000"
*MEAS_COND_AXIS_NAME_MAGICNO-22 "285343744.0000000000"
*MEAS_COND_AXIS_NAME_MAGICNO-23 "20971521.0000000000"
*MEAS_COND_AXIS_NAME_MAGICNO-24 "20971521.0000000000"
*MEAS_COND_AXIS_NAME_MAGICNO-25 "20971521.0000000000"
*MEAS_COND_AXIS_NAME_MAGICNO-26 "23068673.0000000000"
*MEAS_COND_AXIS_NAME_MAGICNO-27 "23068673.0000000000"
*MEAS_COND_AXIS_NAME_MAGICNO-28 "20971521.0000000000"
*MEAS_COND_AXIS_NAME_MAGICNO-29 "20971521.0000000000"
*MEAS_COND_AXIS_NAME_MAGICNO-30 "20971521.0000000000"
*MEAS_COND_AXIS_NAME_MAGICNO-31 "25165824.0000000000"
*MEAS_COND_AXIS_NAME_MAGICNO-32 "25165824.0000000000"
*MEAS_COND_AXIS_NAME_MAGICNO-33 "285343744.0000000000"
*MEAS_COND_AXIS_NAME_MAGICNO-34 "17301505.0000000000"
*MEAS_COND_AXIS_NAME_MAGICNO-35 "20971521.0000000000"
*MEAS_COND_AXIS_NAME_MAGICNO-36 "20971521.0000000000"
*MEAS_COND_AXIS_NAME_MAGICNO-37 "17039360.0000000000"
*MEAS_COND_AXIS_NAME_MAGICNO-38 "20971521.0000000000"
*MEAS_COND_AXIS_NAME_MAGICNO-39 "0.0000000000"
*MEAS_COND_AXIS_OFFSET-0 "-"
*MEAS_COND_AXIS_OFFSET-1 "0.5969000000"
*MEAS_COND_AXIS_OFFSET-2 "0.3973000000"
*MEAS_COND_AXIS_OFFSET-3 "0.0000000000"
*MEAS_COND_AXIS_OFFSET-4 "-"
*MEAS_COND_AXIS_OFFSET-5 "-"
*MEAS_COND_AXIS_OFFSET-6 "-"
*MEAS_COND_AXIS_OFFSET-7 "-"
*MEAS_COND_AXIS_OFFSET-8 "0.0000000000"
*MEAS_COND_AXIS_OFFSET-9 "-"
*MEAS_COND_AXIS_OFFSET-10 "-"
*MEAS_COND_AXIS_OFFSET-11 "-"
*MEAS_COND_AXIS_OFFSET-12 "0.3973000000"
*MEAS_COND_AXIS_OFFSET-13 "0.1996000000"
*MEAS_COND_AXIS_OFFSET-14 "-"
*MEAS_COND_AXIS_OFFSET-15 "-"
*MEAS_COND_AXIS_OFFSET-16 "-"
*MEAS_COND_AXIS_OFFSET-17 "-"
*MEAS_COND_AXIS_OFFSET-18 "-"
*MEAS_COND_AXIS_OFFSET-19 "-"
*MEAS_COND_AXIS_OFFSET-20 "-"
*MEAS_COND_AXIS_OFFSET-21 "-"
*MEAS_COND_AXIS_OFFSET-22 "-"
*MEAS_COND_AXIS_OFFSET-23 "-"
*MEAS_COND_AXIS_OFFSET-24 "-"
*MEAS_COND_AXIS_OFFSET-25 "-"
*MEAS_COND_AXIS_OFFSET-26 "-"
*MEAS_COND_AXIS_OFFSET-27 "-"
*MEAS_COND_AXIS_OFFSET-28 "-"
*MEAS_COND_AXIS_OFFSET-29 "-"
*MEAS_COND_AXIS_OFFSET-30 "-"
*MEAS_COND_AXIS_OFFSET-31 "-"
*MEAS_COND_AXIS_OFFSET-32 "-"
*MEAS_COND_AXIS_OFFSET-33 "-"
*MEAS_COND_AXIS_OFFSET-34 "-"
*MEAS_COND_AXIS_OFFSET-35 "-"
*MEAS_COND_AXIS_OFFSET-36 "-"
*MEAS_COND_AXIS_OFFSET-37 "-"
*MEAS_COND_AXIS_OFFSET-38 "-"
*MEAS_COND_AXIS_OFFSET-39 "-"
*MEAS_COND_AXIS_POSITION-0 "15.9952000000"
*MEAS_COND_AXIS_POSITION-1 "15.9951000000"
*MEAS_COND_AXIS_POSITION-2 "8.0816000000"
*MEAS_COND_AXIS_POSITION-3 "-0.6280000000"
*MEAS_COND_AXIS_POSITION-4 "-1.7156000000"
*MEAS_COND_AXIS_POSITION-5 "0.2356000000"
*MEAS_COND_AXIS_POSITION-6 "0.0040000000"
*MEAS_COND_AXIS_POSITION-7 "15.9952000000"
*MEAS_COND_AXIS_POSITION-8 "0.0000000000"
*MEAS_COND_AXIS_POSITION-9 "0.0000000000"
*MEAS_COND_AXIS_POSITION-10 "90.0000000000"
*MEAS_COND_AXIS_POSITION-11 "-0.6280000000"
*MEAS_COND_AXIS_POSITION-12 "8.0816000000"
*MEAS_COND_AXIS_POSITION-13 "7.9135000000"
*MEAS_COND_AXIS_POSITION-14 "-5.8766900000"
*MEAS_COND_AXIS_POSITION-15 "PB"
*MEAS_COND_AXIS_POSITION-16 "0.0000000000"
*MEAS_COND_AXIS_POSITION-17 "None"
*MEAS_COND_AXIS_POSITION-18 "0.400mm"
*MEAS_COND_AXIS_POSITION-19 "0.4000000000"
*MEAS_COND_AXIS_POSITION-20 "-1.4671900000"
*MEAS_COND_AXIS_POSITION-21 "Ge(220)x2"
*MEAS_COND_AXIS_POSITION-22 "0.0000000000"
*MEAS_COND_AXIS_POSITION-23 "2.0mm"
*MEAS_COND_AXIS_POSITION-24 "None"
*MEAS_COND_AXIS_POSITION-25 "None"
*MEAS_COND_AXIS_POSITION-26 "0.400mm"
*MEAS_COND_AXIS_POSITION-27 "0.400mm"
*MEAS_COND_AXIS_POSITION-28 "PSA_open"
*MEAS_COND_AXIS_POSITION-29 "Soller_slit_5.0deg"
*MEAS_COND_AXIS_POSITION-30 "None"
*MEAS_COND_AXIS_POSITION-31 "0.4000000000"
*MEAS_COND_AXIS_POSITION-32 "0.4000000000"
*MEAS_COND_AXIS_POSITION-33 "0.3465600000"
*MEAS_COND_AXIS_POSITION-34 "1/10000"
*MEAS_COND_AXIS_POSITION-35 "None"
*MEAS_COND_AXIS_POSITION-36 "None"
*MEAS_COND_AXIS_POSITION-37 "15.9951000000"
*MEAS_COND_AXIS_POSITION-38 "None"
*MEAS_COND_AXIS_POSITION-39 "30.0000000000"
*MEAS_COND_AXIS_UNIT-0 "deg"
*MEAS_COND_AXIS_UNIT-1 "deg"
*MEAS_COND_AXIS_UNIT-2 "deg"
*MEAS_COND_AXIS_UNIT-3 "deg"
*MEAS_COND_AXIS_UNIT-4 "mm"
*MEAS_COND_AXIS_UNIT-5 "deg"
*MEAS_COND_AXIS_UNIT-6 "deg"
*MEAS_COND_AXIS_UNIT-7 "deg"
*MEAS_COND_AXIS_UNIT-8 "deg"
*MEAS_COND_AXIS_UNIT-9 "deg"
*MEAS_COND_AXIS_UNIT-10 "deg"
*MEAS_COND_AXIS_UNIT-11 "deg"
*MEAS_COND_AXIS_UNIT-12 "deg"
*MEAS_COND_AXIS_UNIT-13 "deg"
*MEAS_COND_AXIS_UNIT-14 "mm"
*MEAS_COND_AXIS_UNIT-15 ""
*MEAS_COND_AXIS_UNIT-16 "pulse"
*MEAS_COND_AXIS_UNIT-17 ""
*MEAS_COND_AXIS_UNIT-18 ""
*MEAS_COND_AXIS_UNIT-19 "mm"
*MEAS_COND_AXIS_UNIT-20 "mm"
*MEAS_COND_AXIS_UNIT-21 ""
*MEAS_COND_AXIS_UNIT-22 "pulse"
*MEAS_COND_AXIS_UNIT-23 ""
*MEAS_COND_AXIS_UNIT-24 ""
*MEAS_COND_AXIS_UNIT-25 ""
*MEAS_COND_AXIS_UNIT-26 ""
*MEAS_COND_AXIS_UNIT-27 ""
*MEAS_COND_AXIS_UNIT-28 ""
*MEAS_COND_AXIS_UNIT-29 ""
*MEAS_COND_AXIS_UNIT-30 ""
*MEAS_COND_AXIS_UNIT-31 "mm"
*MEAS_COND_AXIS_UNIT-32 "mm"
*MEAS_COND_AXIS_UNIT-33 "mm"
*MEAS_COND_AXIS_UNIT-34 ""
*MEAS_COND_AXIS_UNIT-35 ""
*MEAS_COND_AXIS_UNIT-36 ""
*MEAS_COND_AXIS_UNIT-37 "deg"
*MEAS_COND_AXIS_UNIT-38 ""
*MEAS_COND_AXIS_UNIT-39 "div"
*MEAS_COND_COUNTER_CNTLOSS_CORR "0.0000000000"
*MEAS_COND_COUNTER_PHABASE "30.0000000000"
*MEAS_COND_COUNTER_PHAWINDOW "20.0000000000"
*MEAS_COND_COUNTER_PHA_UNIT "div"
*MEAS_COND_COUNTER_TAUDIFF "0.2500000000"
*MEAS_COND_COUNTER_TAUINT "0.7500000000"
*MEAS_COND_IRRADIATION_MODE "OFF"
*MEAS_COND_IRRADIATION_WIDTH ""
*MEAS_COND_OPT_ATTR "High resolution parallel beam Ge(220)x2/RS"
*MEAS_COND_OPT_NAME "@High resolution PB-Ge(220)x2"
*MEAS_COND_UNSYMMETRIC_MODE "OFF"
*MEAS_COND_XG_CURRENT "30.0000000000"
*MEAS_COND_XG_VOLTAGE "40.0000000000"
*MEAS_COND_XG_WAVE_TYPE "Ka1"
*MEAS_DATA_COUNT "1501.0000000000"
*MEAS_SCAN_AXIS_X "2-Theta/Omega"
*MEAS_SCAN_AXIS_X_INTERNAL "TwoThetaOmega"
*MEAS_SCAN_END_TIME "06/28/22 03:41:23"
*MEAS_SCAN_MODE "CONTINUOUS"
*MEAS_SCAN_MONITOR "0"
*MEAS_SCAN_RESOLUTION_X "0.0002"
*MEAS_SCAN_SPEED "0.021031"
*MEAS_SCAN_SPEED_UNIT "deg/min"
*MEAS_SCAN_SPEED_USER "0.021000"
*MEAS_SCAN_START "16.0000000000"
*MEAS_SCAN_START_TIME "06/27/22 15:46:27"
*MEAS_SCAN_STEP "0.0100000000"
*MEAS_SCAN_STOP "31.0000000000"
*MEAS_SCAN_UNIT_X "deg"
*MEAS_SCAN_UNIT_Y "counts"
*RAS_HEADER_END
*RAS_INT_START
16.0000 0.0000 1.0000
16.0200 1.0000 1.0000
16.0400 0.0000 1.0000
16.0600 5.0000 1.0000
16.0800 3.0000 1.0000
16.1000 0.0000 1.0000
16.1200 0.0000 1.0000
16.1400 0.0000 1.0000
16.1600 13.0000 1.0000
16.1800 0.0000 1.0000
16.2000 2.0000 1.0000
16.2200 2.0000 1.0000
16.2400 1.0000 1.0000
16.2600 2.0000 1.0000
16.2800 2.0000 1.0000
16.3000 0.0000 1.0000
16.3200 0.0000 1.0000
16.3400 0.0000 1.0000
16.3600 0.0000 1.0000
16.3800 0.0000 1.0000
16.4000 0.0000 1.0000
16.4200 4.0000 1.0000
16.4400 2.0000 1.0000
16.4600 0.0000 1.0000
16.4800 0.0000 1.0000
16.5000 51.0000 1.0000
16.5200 2.0000 1.0000
16.5400 0.0000 1.0000
16.5600 4.0000 1.0000
16.5800 0.0000 1.0000
16.6000 4.0000 1.0000
16.6200 1.5008 1.0000
16.6400 0.0000 1.0000
16.6600 0.0000 1.0000
16.6800 2.0000 1.0000
16.7000 2.0000 1.0000
16.7200 2.0000 1.0000
16.7400 0.0000 1.0000
16.7600 0.0000 1.0000
16.7800 3.0000 1.0000
16.8000 0.0000 1.0000
16.8200 0.0000 1.0000
16.8400 2.0000 1.0000
16.8600 0.0000 1.0000
16.8800 2.0000 1.0000
16.9000 0.0000 1.0000
16.9200 0.0000 1.0000
16.9400 2.0000 1.0000
16.9600 2.0000 1.0000
16.9800 2.0000 1.0000
17.0000 6.0000 1.0000
17.0200 5.0000 1.0000
17.0400 0.0000 1.0000
17.0600 0.0000 1.0000
17.0800 0.0000 1.0000
17.1000 2.0000 1.0000
17.1200 2.0000 1.0000
17.1400 1.0000 1.0000
17.1600 2.0000 1.0000
17.1800 4.0000 1.0000
17.2000 3.0000 1.0000
17.2200 0.0000 1.0000
17.2400 0.0000 1.0000
17.2600 2.0000 1.0000
17.2800 2.0000 1.0000
17.3000 0.0000 1.0000
17.3200 0.0000 1.0000
17.3400 2.0000 1.0000
17.3600 0.0000 1.0000
17.3800 2.0000 1.0000
17.4000 0.0000 1.0000
17.4200 2.0000 1.0000
17.4400 0.0000 1.0000
17.4600 2.4992 1.0000
17.4800 4.0000 1.0000
17.5000 2.0000 1.0000
17.5200 4.0000 1.0000
17.5400 4.0000 1.0000
17.5600 5.5024 1.0000
17.5800 11.0000 1.0000
17.6000 4.4992 1.0000
17.6200 3.0000 1.0000
17.6400 0.0000 1.0000
17.6600 2.0000 1.0000
17.6800 2.0000 1.0000
17.7000 4.0000 1.0000
17.7200 5.0000 1.0000
17.7400 2.0000 1.0000
17.7600 2.0000 1.0000
17.7800 0.0000 1.0000
17.8000 4.0000 1.0000
17.8200 2.0000 1.0000
17.8400 1.0000 1.0000
17.8600 4.0000 1.0000
17.8800 0.0000 1.0000
17.9000 0.0000 1.0000
17.9200 2.0000 1.0000
17.9400 0.0000 1.0000
17.9600 2.5008 1.0000
17.9800 0.0000 1.0000
18.0000 2.0000 1.0000
18.0200 0.0000 1.0000
18.0400 3.0000 1.0000
18.0600 0.0000 1.0000
18.0800 2.0000 1.0000
18.1000 0.0000 1.0000
18.1200 6.0000 1.0000
18.1400 0.0000 1.0000
18.1600 0.0000 1.0000
18.1800 0.0000 1.0000
18.2000 3.0000 1.0000
18.2200 0.0000 1.0000
18.2400 0.0000 1.0000
18.2600 2.0000 1.0000
18.2800 3.0000 1.0000
18.3000 0.0000 1.0000
18.3200 3.0000 1.0000
18.3400 0.0000 1.0000
18.3600 4.0000 1.0000
18.3800 0.0000 1.0000
18.4000 0.0000 1.0000
18.4200 0.0000 1.0000
18.4400 0.0000 1.0000
18.4600 1.0000 1.0000
18.4800 2.0000 1.0000
18.5000 2.0000 1.0000
18.5200 0.0000 1.0000
18.5400 0.0000 1.0000
18.5600 0.0000 1.0000
18.5800 2.0000 1.0000
18.6000 0.0000 1.0000
18.6200 0.0000 1.0000
18.6400 0.0000 1.0000
18.6600 1.4992 1.0000
18.6800 7.0000 1.0000
18.7000 0.0000 1.0000
18.7200 0.0000 1.0000
18.7400 0.0000 1.0000
18.7600 4.0000 1.0000
18.7800 0.0000 1.0000
18.8000 7.0000 1.0000
18.8200 4.0000 1.0000
18.8400 2.0000 1.0000
18.8600 3.0000 1.0000
18.8800 2.0000 1.0000
18.9000 2.0000 1.0000
18.9200 9.0000 1.0000
18.9400 0.0000 1.0000
18.9600 5.5008 1.0000
18.9800 6.0000 1.0000
19.0000 2.0000 1.0000
19.0200 4.0000 1.0000
19.0400 1.4992 1.0000
19.0600 0.0000 1.0000
19.0800 2.0000 1.0000
19.1000 2.0000 1.0000
19.1200 0.0000 1.0000
19.1400 0.0000 1.0000
19.1600 0.0000 1.0000
19.1800 2.0000 1.0000
19.2000 0.0000 1.0000
19.2200 0.0000 1.0000
19.2400 0.0000 1.0000
19.2600 2.0000 1.0000
19.2800 0.0000 1.0000
19.3000 2.5008 1.0000
19.3200 0.0000 1.0000
19.3400 2.0000 1.0000
19.3600 2.0000 1.0000
19.3800 0.0000 1.0000
19.4000 1.0000 1.0000
19.4200 2.0000 1.0000
19.4400 0.0000 1.0000
19.4600 5.0000 1.0000
19.4800 5.0000 1.0000
19.5000 5.0000 1.0000
19.5200 0.0000 1.0000
19.5400 0.0000 1.0000
19.5600 9.0000 1.0000
19.5800 5.0000 1.0000
19.6000 2.0000 1.0000
19.6200 4.0000 1.0000
19.6400 0.0000 1.0000
19.6600 0.0000 1.0000
19.6800 0.0000 1.0000
19.7000 0.0000 1.0000
19.7200 3.0000 1.0000
19.7400 5.0000 1.0000
19.7600 0.0000 1.0000
19.7800 1.4992 1.0000
19.8000 6.0000 1.0000
19.8200 4.0000 1.0000
19.8400 4.0000 1.0000
19.8600 0.0000 1.0000
19.8800 2.4992 1.0000
19.9000 0.0000 1.0000
19.9200 0.0000 1.0000
19.9400 2.0000 1.0000
19.9600 0.0000 1.0000
19.9800 2.0000 1.0000
20.0000 2.0000 1.0000
20.0200 5.0000 1.0000
20.0400 3.0000 1.0000
20.0600 0.0000 1.0000
20.0800 7.4992 1.0000
20.1000 0.0000 1.0000
20.1200 2.0000 1.0000
20.1400 3.0000 1.0000
20.1600 0.0000 1.0000
20.1800 2.0000 1.0000
20.2000 0.0000 1.0000
20.2200 9.0000 1.0000
20.2400 3.0000 1.0000
20.2600 1.5008 1.0000
20.2800 0.0000 1.0000
20.3000 0.0000 1.0000
20.3200 3.0000 1.0000
20.3400 0.0000 1.0000
20.3600 0.0000 1.0000
20.3800 4.0000 1.0000
20.4000 0.0000 1.0000
20.4200 2.0000 1.0000
20.4400 0.0000 1.0000
20.4600 0.0000 1.0000
20.4800 1.0000 1.0000
20.5000 0.4992 1.0000
20.5200 2.0000 1.0000
20.5400 4.0000 1.0000
20.5600 3.0000 1.0000
20.5800 6.0000 1.0000
20.6000 2.0000 1.0000
20.6200 1.4992 1.0000
20.6400 2.0000 1.0000
20.6600 2.0000 1.0000
20.6800 2.0000 1.0000
20.7000 3.0000 1.0000
20.7200 6.0000 1.0000
20.7400 0.0000 1.0000
20.7600 4.0000 1.0000
20.7800 0.0000 1.0000
20.8000 0.0000 1.0000
20.8200 0.0000 1.0000
20.8400 0.0000 1.0000
20.8600 5.0000 1.0000
20.8800 5.0000 1.0000
20.9000 5.0000 1.0000
20.9200 0.0000 1.0000
20.9400 3.0000 1.0000
20.9600 0.0000 1.0000
20.9800 0.0000 1.0000
21.0000 3.5008 1.0000
21.0200 2.0000 1.0000
21.0400 4.0000 1.0000
21.0600 2.0000 1.0000
21.0800 7.0000 1.0000
21.1000 7.0000 1.0000
21.1200 2.0000 1.0000
21.1400 0.0000 1.0000
21.1600 3.0000 1.0000
21.1800 0.0000 1.0000
21.2000 1.0000 1.0000
21.2200 0.0000 1.0000
21.2400 2.4992 1.0000
21.2600 0.0000 1.0000
21.2800 0.0000 1.0000
21.3000 2.0000 1.0000
21.3200 1.4992 1.0000
21.3400 2.0000 1.0000
21.3600 0.0000 1.0000
21.3800 0.0000 1.0000
21.4000 2.4992 1.0000
21.4200 7.0000 1.0000
21.4400 4.0000 1.0000
21.4600 4.0000 1.0000
21.4800 2.0000 1.0000
21.5000 10.0000 1.0000
21.5200 8.0000 1.0000
21.5400 7.0000 1.0000
21.5600 5.0000 1.0000
21.5800 9.0016 1.0000
21.6000 11.0000 1.0000
21.6200 2.9984 1.0000
21.6400 8.0000 1.0000
21.6600 15.0000 1.0000
21.6800 12.0000 1.0000
21.7000 6.0000 1.0000
21.7200 10.9984 1.0000
21.7400 14.0000 1.0000
21.7600 5.0000 1.0000
21.7800 12.0000 1.0000
21.8000 13.0000 1.0000
21.8200 4.0000 1.0000
21.8400 13.0000 1.0000
21.8600 13.0000 1.0000
21.8800 3.0000 1.0000
21.9000 10.9984 1.0000
21.9200 6.0000 1.0000
21.9400 8.5008 1.0000
21.9600 9.4992 1.0000
21.9800 2.0000 1.0000
22.0000 8.4992 1.0000
22.0200 12.0000 1.0000
22.0400 9.0000 1.0000
22.0600 3.0000 1.0000
22.0800 2.0000 1.0000
22.1000 11.0000 1.0000
22.1200 16.0000 1.0000
22.1400 30.0000 1.0000
22.1600 18.5024 1.0000
22.1800 24.0000 1.0000
22.2000 8.0000 1.0000
22.2200 13.5008 1.0000
22.2400 5.0000 1.0000
22.2600 13.0000 1.0000
22.2800 16.0000 1.0000
22.3000 15.5008 1.0000
22.3200 15.0000 1.0000
22.3400 23.4992 1.0000
22.3600 33.0016 1.0000
22.3800 35.0000 1.0000
22.4000 42.4992 1.0000
22.4200 70.0000 1.0000
22.4400 87.4992 1.0000
22.4600 67.0000 1.0000
22.4800 151.4976 1.0000
22.5000 139.0016 1.0000
22.5200 197.4961 1.0000
22.5400 187.0016 1.0000
22.5600 239.9984 1.0000
22.5800 282.9937 1.0000
22.6000 259.9984 1.0000
22.6200 277.9984 1.0000
22.6400 280.0016 1.0000
22.6600 335.5008 1.0000
22.6800 329.9969 1.0000
22.7000 308.0016 1.0000
22.7200 286.9969 1.0000
22.7400 330.9984 1.0000
22.7600 278.0000 1.0000
22.7800 277.9984 1.0000
22.8000 223.0047 1.0000
22.8200 208.9969 1.0000
22.8400 166.5039 1.0000
22.8600 167.9984 1.0000
22.8800 185.4992 1.0000
22.9000 145.4976 1.0000
22.9200 140.9969 1.0000
22.9400 135.4992 1.0000
22.9600 159.0000 1.0000
22.9800 129.4992 1.0000
23.0000 178.4976 1.0000
23.0200 165.9984 1.0000
23.0400 185.9969 1.0000
23.0600 206.5024 1.0000
23.0800 271.0000 1.0000
23.1000 243.4992 1.0000
23.1200 331.4992 1.0000
23.1400 399.9937 1.0000
23.1600 415.0000 1.0000
23.1800 429.0094 1.0000
23.2000 519.5039 1.0000
23.2200 489.5023 1.0000
23.2400 623.4976 1.0000
23.2600 743.9984 1.0000
23.2800 1032.5055 1.0000
23.3000 1361.9937 1.0000
23.3200 1948.9906 1.0000
23.3400 3350.9827 1.0000
23.3600 6061.9639 1.0000
23.3800 13858.8965 1.0000
23.4000 43666.4453 1.0000
23.4200 1094773.8750 1.0000
23.4400 1911988.1250 1.0000
23.4600 4014274.7500 1.0000
23.4800 5233420.0000 1.0000
23.5000 1640876.8750 1.0000
23.5200 168229.5469 1.0000
23.5400 55145.8555 1.0000
23.5600 21815.6582 1.0000
23.5800 9699.0459 1.0000
23.6000 4839.0254 1.0000
23.6200 2886.5056 1.0000
23.6400 1740.0048 1.0000
23.6600 1299.0016 1.0000
23.6800 945.9968 1.0000
23.7000 682.0047 1.0000
23.7200 615.0016 1.0000
23.7400 432.9953 1.0000
23.7600 364.4977 1.0000
23.7800 307.0063 1.0000
23.8000 260.9984 1.0000
23.8200 252.0031 1.0000
23.8400 211.0000 1.0000
23.8600 161.5024 1.0000
23.8800 136.0016 1.0000
23.9000 142.4976 1.0000
23.9200 100.9984 1.0000
23.9400 119.0000 1.0000
23.9600 97.4976 1.0000
23.9800 87.4992 1.0000
24.0000 70.0016 1.0000
24.0200 92.0016 1.0000
24.0400 68.0000 1.0000
24.0600 68.4992 1.0000
24.0800 82.0000 1.0000
24.1000 69.0000 1.0000
24.1200 42.0000 1.0000
24.1400 46.4992 1.0000
24.1600 49.0000 1.0000
24.1800 56.4992 1.0000
24.2000 22.4992 1.0000
24.2200 7.0000 1.0000
24.2400 26.0000 1.0000
24.2600 21.0000 1.0000
24.2800 32.5008 1.0000
24.3000 26.5008 1.0000
24.3200 27.0000 1.0000
24.3400 13.9984 1.0000
24.3600 28.4992 1.0000
24.3800 28.0000 1.0000
24.4000 24.9984 1.0000
24.4200 18.0000 1.0000
24.4400 17.5008 1.0000
24.4600 16.0000 1.0000
24.4800 23.4992 1.0000
24.5000 13.0000 1.0000
24.5200 23.0000 1.0000
24.5400 10.4992 1.0000
24.5600 11.9984 1.0000
24.5800 6.0000 1.0000
24.6000 17.0000 1.0000
24.6200 6.5008 1.0000
24.6400 5.4992 1.0000
24.6600 12.0000 1.0000
24.6800 8.0000 1.0000
24.7000 7.0000 1.0000
24.7200 17.4992 1.0000
24.7400 19.0000 1.0000
24.7600 2.0000 1.0000
24.7800 10.0000 1.0000
24.8000 2.0000 1.0000
24.8200 5.0000 1.0000
24.8400 16.0000 1.0000
24.8600 0.0000 1.0000
24.8800 2.0000 1.0000
24.9000 2.0000 1.0000
24.9200 4.0000 1.0000
24.9400 11.0000 1.0000
24.9600 4.0000 1.0000
24.9800 6.0000 1.0000
25.0000 6.0000 1.0000
25.0200 9.0000 1.0000
25.0400 5.0000 1.0000
25.0600 5.4992 1.0000
25.0800 3.0000 1.0000
25.1000 9.0000 1.0000
25.1200 0.0000 1.0000
25.1400 0.0000 1.0000
25.1600 2.0000 1.0000
25.1800 6.0000 1.0000
25.2000 0.0000 1.0000
25.2200 3.0000 1.0000
25.2400 21.0000 1.0000
25.2600 6.0000 1.0000
25.2800 3.0000 1.0000
25.3000 7.0000 1.0000
25.3200 10.0000 1.0000
25.3400 0.0000 1.0000
25.3600 0.0000 1.0000
25.3800 6.0000 1.0000
25.4000 11.0000 1.0000
25.4200 2.0000 1.0000
25.4400 0.0000 1.0000
25.4600 4.0000 1.0000
25.4800 5.0000 1.0000
25.5000 4.0000 1.0000
25.5200 5.0000 1.0000
25.5400 2.0000 1.0000
25.5600 2.0000 1.0000
25.5800 2.0000 1.0000
25.6000 3.5008 1.0000
25.6200 0.0000 1.0000
25.6400 0.0000 1.0000
25.6600 2.0000 1.0000
25.6800 0.0000 1.0000
25.7000 3.0000 1.0000
25.7200 2.0000 1.0000
25.7400 5.0016 1.0000
25.7600 6.0000 1.0000
25.7800 0.0000 1.0000
25.8000 5.0000 1.0000
25.8200 1.0000 1.0000
25.8400 2.0000 1.0000
25.8600 3.0000 1.0000
25.8800 8.0000 1.0000
25.9000 0.0000 1.0000
25.9200 1.0000 1.0000
25.9400 2.0000 1.0000
25.9600 12.0016 1.0000
25.9800 3.0000 1.0000
26.0000 2.0000 1.0000
26.0200 2.0000 1.0000
26.0400 6.0000 1.0000
26.0600 0.0000 1.0000
26.0800 3.0000 1.0000
26.1000 2.0000 1.0000
26.1200 0.0000 1.0000
26.1400 0.0000 1.0000
26.1600 0.0000 1.0000
26.1800 5.0000 1.0000
26.2000 6.4992 1.0000
26.2200 0.0000 1.0000
26.2400 0.0000 1.0000
26.2600 2.0000 1.0000
26.2800 4.0000 1.0000
26.3000 5.0000 1.0000
26.3200 0.0000 1.0000
26.3400 1.0000 1.0000
26.3600 1.0000 1.0000
26.3800 0.0000 1.0000
26.4000 0.0000 1.0000
26.4200 0.0000 1.0000
26.4400 1.0000 1.0000
26.4600 2.0000 1.0000
26.4800 0.0000 1.0000
26.5000 0.0000 1.0000
26.5200 0.0000 1.0000
26.5400 4.0000 1.0000
26.5600 0.0000 1.0000
26.5800 5.0000 1.0000
26.6000 3.0000 1.0000
26.6200 2.0000 1.0000
26.6400 0.0000 1.0000
26.6600 5.0000 1.0000
26.6800 8.0000 1.0000
26.7000 4.0000 1.0000
26.7200 2.0000 1.0000
26.7400 0.0000 1.0000
26.7600 1.0000 1.0000
26.7800 1.0000 1.0000
26.8000 0.0000 1.0000
26.8200 2.5008 1.0000
26.8400 2.0000 1.0000
26.8600 2.0000 1.0000
26.8800 0.0000 1.0000
26.9000 7.0000 1.0000
26.9200 0.5008 1.0000
26.9400 0.0000 1.0000
26.9600 0.0000 1.0000
26.9800 2.0000 1.0000
27.0000 0.0000 1.0000
27.0200 0.0000 1.0000
27.0400 0.0000 1.0000
27.0600 2.0000 1.0000
27.0800 0.0000 1.0000
27.1000 2.0000 1.0000
27.1200 0.0000 1.0000
27.1400 0.5008 1.0000
27.1600 7.0000 1.0000
27.1800 3.0000 1.0000
27.2000 0.0000 1.0000
27.2200 6.0000 1.0000
27.2400 5.0000 1.0000
27.2600 5.0000 1.0000
27.2800 6.0000 1.0000
27.3000 0.0000 1.0000
27.3200 2.0000 1.0000
27.3400 8.0000 1.0000
27.3600 2.0000 1.0000
27.3800 4.0000 1.0000
27.4000 6.0000 1.0000
27.4200 2.0000 1.0000
27.4400 0.0000 1.0000
27.4600 3.0000 1.0000
27.4800 2.0000 1.0000
27.5000 2.0000 1.0000
27.5200 3.0000 1.0000
27.5400 0.0000 1.0000
27.5600 6.0000 1.0000
27.5800 1.0000 1.0000
27.6000 2.0000 1.0000
27.6200 0.0000 1.0000
27.6400 2.0000 1.0000
27.6600 2.0000 1.0000
27.6800 2.0000 1.0000
27.7000 0.0000 1.0000
27.7200 0.0000 1.0000
27.7400 2.0000 1.0000
27.7600 5.0000 1.0000
27.7800 6.0000 1.0000
27.8000 3.0000 1.0000
27.8200 0.0000 1.0000
27.8400 2.0000 1.0000
27.8600 0.0000 1.0000
27.8800 3.0000 1.0000
27.9000 4.0000 1.0000
27.9200 0.5008 1.0000
27.9400 0.0000 1.0000
27.9600 0.5008 1.0000
27.9800 0.0000 1.0000
28.0000 0.0000 1.0000
28.0200 2.0000 1.0000
28.0400 4.0000 1.0000
28.0600 0.0000 1.0000
28.0800 0.0000 1.0000
28.1000 0.0000 1.0000
28.1200 0.0000 1.0000
28.1400 2.0000 1.0000
28.1600 0.0000 1.0000
28.1800 2.0000 1.0000
28.2000 0.0000 1.0000
28.2200 0.0000 1.0000
28.2400 2.0000 1.0000
28.2600 0.0000 1.0000
28.2800 0.0000 1.0000
28.3000 4.5008 1.0000
28.3200 6.0000 1.0000
28.3400 2.0000 1.0000
28.3600 2.0000 1.0000
28.3800 0.0000 1.0000
28.4000 0.0000 1.0000
28.4200 0.0000 1.0000
28.4400 1.0000 1.0000
28.4600 2.0000 1.0000
28.4800 0.0000 1.0000
28.5000 0.0000 1.0000
28.5200 2.4992 1.0000
28.5400 0.0000 1.0000
28.5600 2.0000 1.0000
28.5800 2.0000 1.0000
28.6000 2.0000 1.0000
28.6200 6.0000 1.0000
28.6400 2.5008 1.0000
28.6600 2.4992 1.0000
28.6800 0.0000 1.0000
28.7000 0.0000 1.0000
28.7200 0.0000 1.0000
28.7400 0.0000 1.0000
28.7600 6.0000 1.0000
28.7800 2.0000 1.0000
28.8000 1.0000 1.0000
28.8200 5.0000 1.0000
28.8400 5.0000 1.0000
28.8600 2.0000 1.0000
28.8800 0.0000 1.0000
28.9000 0.0000 1.0000
28.9200 2.0000 1.0000
28.9400 2.0000 1.0000
28.9600 0.0000 1.0000
28.9800 2.0000 1.0000
29.0000 0.0000 1.0000
29.0200 2.0000 1.0000
29.0400 0.0000 1.0000
29.0600 2.0000 1.0000
29.0800 0.0000 1.0000
29.1000 2.0000 1.0000
29.1200 0.0000 1.0000
29.1400 0.0000 1.0000
29.1600 5.0000 1.0000
29.1800 3.0000 1.0000
29.2000 2.0000 1.0000
29.2200 0.0000 1.0000
29.2400 0.0000 1.0000
29.2600 0.0000 1.0000
29.2800 0.0000 1.0000
29.3000 9.0000 1.0000
29.3200 6.0000 1.0000
29.3400 2.0000 1.0000
29.3600 2.0000 1.0000
29.3800 0.5008 1.0000
29.4000 0.0000 1.0000
29.4200 2.0000 1.0000
29.4400 5.0000 1.0000
29.4600 2.0000 1.0000
29.4800 1.0000 1.0000
29.5000 2.0000 1.0000
29.5200 0.0000 1.0000
29.5400 0.0000 1.0000
29.5600 1.4976 1.0000
29.5800 0.0000 1.0000
29.6000 0.0000 1.0000
29.6200 4.0000 1.0000
29.6400 7.0000 1.0000
29.6600 0.0000 1.0000
29.6800 5.0000 1.0000
29.7000 4.0000 1.0000
29.7200 4.0000 1.0000
29.7400 0.0000 1.0000
29.7600 0.0000 1.0000
29.7800 0.0000 1.0000
29.8000 4.0000 1.0000
29.8200 2.0000 1.0000
29.8400 1.0000 1.0000
29.8600 0.4992 1.0000
29.8800 0.0000 1.0000
29.9000 2.0000 1.0000
29.9200 0.0000 1.0000
29.9400 0.0000 1.0000
29.9600 3.0000 1.0000
29.9800 2.0000 1.0000
30.0000 3.0000 1.0000
30.0200 3.0000 1.0000
30.0400 4.0000 1.0000
30.0600 0.0000 1.0000
30.0800 2.0000 1.0000
30.1000 0.0000 1.0000
30.1200 2.0000 1.0000
30.1400 2.0000 1.0000
30.1600 0.0000 1.0000
30.1800 0.0000 1.0000
30.2000 2.4992 1.0000
30.2200 0.0000 1.0000
30.2400 0.0000 1.0000
30.2600 0.0000 1.0000
30.2800 0.0000 1.0000
30.3000 0.0000 1.0000
30.3200 0.0000 1.0000
30.3400 0.0000 1.0000
30.3600 0.0000 1.0000
30.3800 0.4992 1.0000
30.4000 0.0000 1.0000
30.4200 0.0000 1.0000
30.4400 0.0000 1.0000
30.4600 0.0000 1.0000
30.4800 0.0000 1.0000
30.5000 3.0000 1.0000
30.5200 0.0000 1.0000
30.5400 0.0000 1.0000
30.5600 0.0000 1.0000
30.5800 0.0000 1.0000
30.6000 3.0000 1.0000
30.6200 0.0000 1.0000
30.6400 0.0000 1.0000
30.6600 0.0000 1.0000
30.6800 1.0000 1.0000
30.7000 0.0000 1.0000
30.7200 0.0000 1.0000
30.7400 4.0000 1.0000
30.7600 0.0000 1.0000
30.7800 0.0000 1.0000
30.8000 0.0000 1.0000
30.8200 4.0000 1.0000
30.8400 0.0000 1.0000
30.8600 2.0000 1.0000
30.8800 0.0000 1.0000
30.9000 0.0000 1.0000
30.9200 2.0000 1.0000
30.9400 0.0000 1.0000
30.9600 0.0000 1.0000
30.9800 0.0000 1.0000
31.0000 0.0000 1.0000
*RAS_INT_END
*RAS_DATA_END