File: SQUID/23006_LCOS/transfer_119973_files_84937504/23006_LCOS_A1_MH_30K_FC_p0d5T.dat
[Header]
; MPMS3 Data File (default extension .dat)
; Copyright (c) 2007, Quantum Design, Inc. All rights reserved.
TITLE,
FILEOPENTIME,3883375494.97822,01/20/2023,11:29 am
BYAPP,SQUID AC,0.9.1.0
INFO,MPMS3 Measurement Release 1.1.16 Build 347, MultiVu Release 2.3.3.2,APPNAME
INFO,0,MOMENT_UNITS
INFO,LSAT//LCO,SAMPLE_MATERIAL
INFO,,SAMPLE_COMMENT
INFO,,SAMPLE_MASS
INFO,,SAMPLE_VOLUME
INFO,,SAMPLE_MOLECULAR_WEIGHT
INFO,,SAMPLE_SIZE
INFO,,SAMPLE_SHAPE
INFO,Quartz,SAMPLE_HOLDER
INFO,Standard,SAMPLE_HOLDER_DETAIL
INFO,65.59,SAMPLE_OFFSET
DATATYPE,COMMENT,1
DATATYPE,TIME,2
STARTUPAXIS,X,2
STARTUPAXIS,Y1,5
FIELDGROUP, VSM,2,3,4,5,6,8,9,10,11,14,15
FIELDGROUP, DC, 2,3,4,14,56,57,58,59,60,61,62,63,64,65,66,67,68,69
FIELDGROUP, AC, 2,3,4,11,16,17,18,19,20,21,22,23,24,25,26,27,28,29,30
STARTUPGROUP, All
[Data]
Comment,Time Stamp (sec),Temperature (K),Magnetic Field (Oe),Moment (emu),M. Std. Err. (emu),Transport Action,Averaging Time (sec),Frequency (Hz),Peak Amplitude (mm),Center Position (mm),Lockin Signal' (V),Lockin Signal (V),Range,M. Quad. Signal (emu),AC Moment (emu),AC M. Std Err. (emu),AC Phase (deg),AC Phase Std. Err. (deg),AC Susceptibility (emu/Oe),AC Suscept. Std Err. (emu/Oe),AC X' (emu/Oe),AC X' Std Err. (emu/Oe),AC X'' (emu/Oe),AC X'' Std Err. (emu/Oe),AC Drive (Oe),AC Frequency (Hz),AC Averaging Time (sec),AC Cycles,AC Range,AC Measure Type,AC Signal' (V),AC Signal'' (V),AC Trim Coil Ratio,AC Trim Coil Phase,Min. Temperature (K),Max. Temperature (K),Min. Field (Oe),Max. Field (Oe),Mass (grams),Motor Lag (deg),Pressure (Torr),Measure Count,Measurement Number,SQUID Status (code),Motor Status (code),Measure Status (code),Motor Current (amps),Motor Temp. (C),Temp. Status (code),Field Status (code),Chamber Status (code),Chamber Temp (K),Redirection State,Average Temp (K),Rotation Angle (deg),Rotator state,DC Moment Fixed Ctr (emu),DC Moment Err Fixed Ctr (emu),DC Moment Free Ctr (emu),DC Moment Err Free Ctr (emu),DC Fixed Fit,DC Free Fit,DC Calculated Center (mm),DC Calculated Center Err (mm),DC Scan Length (mm),DC Scan Time (s),DC Number of Points,DC Squid Drift,DC Min V (V),DC Max V (V),DC Scans per Measure,Map 01,Map 02,Map 03,Map 04,Map 05,Map 06,Map 07,Map 08,Map 09,Map 10,Map 11,Map 12,Map 13,Map 14,Map 15,Map 16
,3883375633.90505,29.89430809021,70000.2265625,-0.000928984772485701,1.47881444258306E-7,1,4,13.4005146026611,4.97486228018072,30.4300002753735,-1.14637562376431,-0.172694131774407,1,-9.53702057970028E-7,,,,,,,,,,,,,,,,,,,,,29.8939647674561,29.8946514129639,70000.2265625,70000.2265625,53.3512270228807,5.64236622613582,4.42446041107178,46,1,100,0,0,0.299453735351562,31.2805480957031,1,1,3,29.8939647674561,0,29.89430809021,,,,,,,,,,,,,,,,,,,,,,,,,,,,,,,,,
,3883375732.67851,29.9466381072998,60000.4453125,-0.000767153160795538,1.22852893928142E-7,1,4,13.4005146026611,4.98502425011912,30.4300002753735,-0.949456696582322,-0.142572518426394,1,-4.26448247734345E-7,,,,,,,,,,,,,,,,,,,,,29.9442272186279,29.9490489959717,60000.4453125,60000.4453125,53.4567468729768,5.64403504552451,4.33591222763062,51,1,100,0,0,0.298614501953125,32.2580642700195,1,1,3,29.9490489959717,0,29.9466381072998,,,,,,,,,,,,,,,,,,,,,,,,,,,,,,,,,
,3883375847.61915,30.0195970535278,50000.4609375,-0.000605725929928364,1.18638870097246E-7,1,4,13.4005146026611,4.98474636489433,30.4300002753735,-0.749588274991323,-0.112707318062646,1,-4.53260694636154E-7,,,,,,,,,,,,,,,,,,,,,30.0194110870361,30.0197830200195,50000.4609375,50000.4609375,53.521622040073,5.64420544367968,4.34948778152466,47,1,68,0,0,0.300369262695313,32.2580642700195,1,1,3,30.0194110870361,0,30.0195970535278,,,,,,,,,,,,,,,,,,,,,,,,,,,,,,,,,
,3883375961.7959,30.016058921814,40000.44140625,-0.000451029380830702,0.000101517779633164,1,4,13.4005146026611,4.98463169977607,30.4300002753735,-0.541473279439403,-0.195284340621632,100,-9.03212243236328E-5,,,,,,,,,,,,,,,,,,,,,30.01584815979,30.0162696838379,40000.44140625,40000.44140625,53.3633422649287,5.64435566851512,4.37940740585327,53,1,68,0,0,0.298919677734375,32.7468223571777,1,1,3,30.01584815979,0,30.016058921814,,,,,,,,,,,,,,,,,,,,,,,,,,,,,,,,,
,3883376061.82538,30.0000047683716,30000.041015625,-0.000281521776778948,6.99083016503321E-5,1,4,13.4005146026611,4.98460698833839,30.4300002753735,-0.343716157666999,-0.0834949576144397,10,-2.53516230803661E-5,,,,,,,,,,,,,,,,,,,,,29.9999942779541,30.0000152587891,30000.041015625,30000.041015625,53.5333464678614,5.64421231351061,4.39248943328857,50,1,68,0,0,0.299606323242188,33.2355842590332,1,1,3,30.0000152587891,0,30.0000047683716,,,,,,,,,,,,,,,,,,,,,,,,,,,,,,,,,
,3883376167.6176,29.9997930526733,19999.654296875,-0.000134509292284765,1.26540337432439E-5,1,4,13.4005146026611,4.98446549940572,30.4300002753735,-0.166388900777462,-0.0253853290985437,100,-3.9089395060578E-7,,,,,,,,,,,,,,,,,,,,,29.9996223449707,29.999963760376,19999.654296875,19999.654296875,53.5149781976595,5.64414068642485,4.40786123275757,54,1,0,0,1,0.29937744140625,33.2355842590332,1,1,3,29.999963760376,0,29.9997930526733,,,,,,,,,,,,,,,,,,,,,,,,,,,,,,,,,
,3883376249.07962,30.0094137191772,14499.7939453125,-3.42221980903343E-5,2.38222040889458E-6,1,4,13.4005146026611,4.98450939916527,30.4300002753735,-0.042730826147653,-0.0038034004764989,10,2.04612422496328E-6,,,,,,,,,,,,,,,,,,,,,30.0092239379883,30.0096035003662,14499.7939453125,14499.7939453125,53.4012512481114,5.64356206385169,4.4111385345459,54,1,0,0,1,0.300827026367188,33.2355842590332,1,1,3,30.0092239379883,0,30.0094137191772,,,,,,,,,,,,,,,,,,,,,,,,,,,,,,,,,
,3883376290.3466,30.0004653930664,13499.5556640625,-1.42866328912061E-5,9.51048507772208E-6,1,4,13.4005146026611,4.98438954145356,30.4300002753735,-0.019252276770522,0.00786569452614753,10,8.49321520385682E-6,,,,,,,,,,,,,,,,,,,,,30.0002861022949,30.0006446838379,13499.5556640625,13499.5556640625,53.4813681713326,5.64444591952353,4.41673421859741,54,1,0,0,1,0.2996826171875,33.2355842590332,1,1,3,30.0006446838379,0,30.0004653930664,,,,,,,,,,,,,,,,,,,,,,,,,,,,,,,,,
,3883376329.03166,30.0137968063354,12499.708984375,-4.23397616414122E-6,3.19646599549124E-8,1,4,13.4005146026611,4.98448671147981,30.4300002753735,-0.00522987736224185,-0.000849941311926858,10,-5.34155743478023E-8,,,,,,,,,,,,,,,,,,,,,30.0129795074463,30.0146141052246,12499.708984375,12499.708984375,53.5005180700537,5.64393276432769,4.42838621139526,54,1,0,0,1,0.299758911132812,33.2355842590332,1,1,3,30.0129795074463,0,30.0137968063354,,,,,,,,,,,,,,,,,,,,,,,,,,,,,,,,,
,3883376367.65454,30.0120010375977,11499.82421875,1.35750696376622E-5,2.47833278673113E-6,1,4,13.4005146026611,4.98440605313273,30.4300002753735,0.0165296545158592,0.00431678432691613,10,1.45749601512842E-6,,,,,,,,,,,,,,,,,,,,,30.0115451812744,30.0124568939209,11499.82421875,11499.82421875,53.2941681409768,5.64324536191306,4.42168188095093,54,1,0,0,1,0.30059814453125,33.2355842590332,1,1,3,30.0115451812744,0,30.0120010375977,,,,,,,,,,,,,,,,,,,,,,,,,,,,,,,,,
,3883376409.12868,30.0002431869507,10499.8505859375,2.69771789660489E-5,2.27317318264E-8,1,4,13.4005146026611,4.98442097431848,30.4300002753735,0.0333996220616684,0.00489676953821359,10,-7.87278050071773E-8,,,,,,,,,,,,,,,,,,,,,30.0001010894775,30.0003852844238,10499.8505859375,10499.8505859375,53.4215735896114,5.64386630045041,4.43640184402466,54,1,0,0,1,0.300979614257812,33.2355842590332,1,1,3,30.0001010894775,0,30.0002431869507,,,,,,,,,,,,,,,,,,,,,,,,,,,,,,,,,
,3883376455.06656,30.0163373947144,9499.814453125,4.23277710804199E-5,4.03409489622762E-8,1,4,13.4005146026611,4.98434840249703,30.4300002753735,0.0523898155727609,0.0077754678868817,1,-4.87875600327656E-8,,,,,,,,,,,,,,,,,,,,,30.0157241821289,30.0169506072998,9499.814453125,9499.814453125,53.3754575069768,5.64361791681894,4.43159866333008,54,1,0,0,1,0.298995971679687,33.7243423461914,1,1,3,30.0157241821289,0,30.0163373947144,,,,,,,,,,,,,,,,,,,,,,,,,,,,,,,,,
,3883376495.87157,30.0004281997681,8499.615234375,5.76068105361737E-5,2.12595890228482E-8,1,4,13.4005146026611,4.98426585875007,30.4300002753735,0.0713002908743234,0.0105752447061489,1,-7.18005241408214E-8,,,,,,,,,,,,,,,,,,,,,30.0001792907715,30.0006771087646,8499.615234375,8499.615234375,53.5302199537845,5.6459992707421,4.44617414474487,50,1,100,0,0,0.298690795898438,33.2355842590332,1,1,3,30.0001811981201,0,30.0004281997681,,,,,,,,,,,,,,,,,,,,,,,,,,,,,,,,,
,3883376557.56333,30.0004997253418,7499.5791015625,7.26510704081192E-5,1.95669900971831E-8,1,4,13.4005146026611,4.98418508048396,30.4300002753735,0.0899254632705498,0.0132909381509957,10,-1.27541203298298E-7,,,,,,,,,,,,,,,,,,,,,30.0003395080566,30.000659942627,7499.5791015625,7499.5791015625,53.4340796459191,5.64479664397657,4.44781732559204,54,1,0,0,1,0.3009033203125,33.7243423461914,1,1,3,30.0003395080566,0,30.0004997253418,,,,,,,,,,,,,,,,,,,,,,,,,,,,,,,,,
,3883376604.40694,30.0023555755615,6499.52978515625,8.72225385948735E-5,1.76992144236152E-8,1,4,13.4005146026611,4.98416495080596,30.4300002753735,0.107951004718047,0.0160234478833685,1,-9.90865994797464E-8,,,,,,,,,,,,,,,,,,,,,30.0018405914307,30.0028705596924,6499.52978515625,6499.52978515625,53.4391602312941,5.64518615695751,4.45657014846802,54,1,0,0,1,0.300827026367188,33.7243423461914,1,1,3,30.0018405914307,0,30.0023555755615,,,,,,,,,,,,,,,,,,,,,,,,,,,,,,,,,
,3883376645.28681,30.0030918121338,5499.54443359375,0.000101229881272096,2.11615711388685E-8,1,4,13.4005146026611,4.98420140559931,30.4300002753735,0.125285444797373,0.0186172031673029,1,-9.85877735261301E-8,,,,,,,,,,,,,,,,,,,,,30.0026531219482,30.0035305023193,5499.54443359375,5499.54443359375,53.5052078411691,5.64491201278824,4.4587836265564,53,1,68,0,0,0.300445556640625,33.2355842590332,1,1,3,30.0026531219482,0,30.0030918121338,,,,,,,,,,,,,,,,,,,,,,,,,,,,,,,,,
,3883376686.89949,30.0029001235962,4499.6591796875,0.00011417285711056,1.68966972683682E-8,1,4,13.4005146026611,4.98415235175691,30.4300002753735,0.141296173918191,0.0210371940231289,1,-7.89196689120556E-8,,,,,,,,,,,,,,,,,,,,,30.0020561218262,30.0037441253662,4499.6591796875,4499.6591796875,53.3359852667556,5.64550411512368,4.4597954750061,53,1,68,0,0,0.299301147460937,33.7243423461914,1,1,3,30.0020561218262,0,30.0029001235962,,,,,,,,,,,,,,,,,,,,,,,,,,,,,,,,,
,3883376726.5752,29.9999523162842,3499.64819335937,0.000124954147198806,1.90226462310166E-8,1,4,13.4005146026611,4.9841969015138,30.4300002753735,0.15464466424903,0.0229971506156672,1,-1.0808166559281E-7,,,,,,,,,,,,,,,,,,,,,29.9999179840088,29.9999866485596,3499.64819335937,3499.64819335937,53.5227944828518,5.64461108191896,4.46740770339966,52,1,68,0,0,0.299224853515625,33.7243423461914,1,1,3,29.9999179840088,0,29.9999523162842,,,,,,,,,,,,,,,,,,,,,,,,,,,,,,,,,
,3883376787.48502,30.0147409439087,2709.64721679687,0.000130391172969916,1.31322149458743E-8,1,4,13.4005146026611,4.98425207355728,30.4300002753735,0.161374517503683,0.024008723669991,1,-1.04263519963562E-7,,,,,,,,,,,,,,,,,,,,,30.0142765045166,30.0152053833008,2709.64721679687,2709.64721679687,53.4317347603614,5.6451763236367,4.46517848968506,54,1,0,0,1,0.300369262695313,33.7243423461914,1,1,3,30.0142765045166,0,30.0147409439087,,,,,,,,,,,,,,,,,,,,,,,,,,,,,,,,,
,3883376826.75819,30.0170516967773,2129.74389648438,0.00013110219378779,1.21180745760671E-8,1,4,13.4005146026611,4.98420627066873,30.4300002753735,0.162250660895931,0.0241509443874196,1,-9.54476554367092E-8,,,,,,,,,,,,,,,,,,,,,30.0165596008301,30.0175437927246,2129.74389648438,2129.74389648438,53.3860094919864,5.64486482932013,4.47277688980103,54,1,0,0,1,0.300140380859375,33.7243423461914,1,1,3,30.0165596008301,0,30.0170516967773,,,,,,,,,,,,,,,,,,,,,,,,,,,,,,,,,
,3883376865.56643,30.0080442428589,1549.55126953125,0.000126780562947937,1.37474577015319E-8,1,4,13.4005146026611,4.98433014829722,30.4300002753735,0.156903491738471,0.0233839710787988,1,-6.94164193829E-8,,,,,,,,,,,,,,,,,,,,,30.0071773529053,30.0089111328125,1549.55126953125,1549.55126953125,53.2488336868614,5.64428137104605,4.47292137145996,54,1,0,0,1,0.300750732421875,33.7243423461914,1,1,3,30.0071773529053,0,30.0080442428589,,,,,,,,,,,,,,,,,,,,,,,,,,,,,,,,,
,3883376906.23144,30.0067758560181,969.534790039063,0.000113103879317622,1.35527238832713E-8,1,4,13.4005146026611,4.98421830276892,30.4300002753735,0.139975097266917,0.0208456083025057,1,-7.41446935964698E-8,,,,,,,,,,,,,,,,,,,,,30.0063495635986,30.0072021484375,969.534790039063,969.534790039063,53.5141965691403,5.64514963181038,4.47378063201904,54,1,0,0,1,0.302352905273438,33.2355842590332,1,1,3,30.0063495635986,0,30.0067758560181,,,,,,,,,,,,,,,,,,,,,,,,,,,,,,,,,
,3883376945.72123,30.0174036026001,389.66943359375,7.88248224689336E-5,1.18666596824449E-8,1,4,13.4005146026611,4.98412652180444,30.4300002753735,0.0975525719047649,0.014506913010213,1,-6.82552651997295E-8,,,,,,,,,,,,,,,,,,,,,30.0165214538574,30.0182857513428,389.66943359375,389.66943359375,53.5181047117364,5.6454535977538,4.47390794754028,54,1,0,0,1,0.30059814453125,33.2355842590332,1,1,3,30.0165214538574,0,30.0174036026001,,,,,,,,,,,,,,,,,,,,,,,,,,,,,,,,,
,3883376984.01338,30.0163650512695,-190.321823120117,-1.97755745144117E-5,2.05649527965528E-8,1,4,13.4005146026611,4.98422792670495,30.4300002753735,-0.0244738414077717,-0.00364528221250473,1,1.25310738889844E-8,,,,,,,,,,,,,,,,,,,,,30.0158309936523,30.0168991088867,-190.321823120117,-190.321823120117,53.5098976122845,5.64448563599375,4.47844648361206,54,1,0,0,1,0.300064086914063,33.7243423461914,1,1,3,30.0158309936523,0,30.0163650512695,,,,,,,,,,,,,,,,,,,,,,,,,,,,,,,,,
,3883377020.99142,30.0072441101074,-770.313110351562,-8.98207973447768E-5,2.3512188343209E-8,1,4,13.4005146026611,4.98424022177888,30.4300002753735,-0.111161896426335,-0.0165492444261181,1,6.31467810827043E-8,,,,,,,,,,,,,,,,,,,,,30.0064067840576,30.0080814361572,-770.313110351562,-770.313110351562,53.4477581450057,5.64513539772476,4.48061943054199,54,1,0,0,1,0.299301147460937,33.2355842590332,1,1,3,30.0064067840576,0,30.0072441101074,,,,,,,,,,,,,,,,,,,,,,,,,,,,,,,,,
,3883377059.27063,30.000412940979,-1349.93933105469,-0.000116129716985547,2.58048664781162E-8,1,4,13.4005146026611,4.9842154617136,30.4300002753735,-0.143717465082466,-0.0214181978103795,1,6.40634731234568E-8,,,,,,,,,,,,,,,,,,,,,30.0003566741943,30.0004692077637,-1349.93933105469,-1349.93933105469,53.4723794433614,5.64426191434781,4.48040008544922,54,1,0,0,1,0.299530029296875,33.2355842590332,1,1,3,30.0003566741943,0,30.000412940979,,,,,,,,,,,,,,,,,,,,,,,,,,,,,,,,,
,3883377097.81219,30.012806892395,-1930.28295898438,-0.000126102044884911,3.25750681692939E-8,1,4,13.4005146026611,4.98426204413534,30.4300002753735,-0.156057692899572,-0.0232789250363129,1,5.24395453493722E-8,,,,,,,,,,,,,,,,,,,,,30.0126552581787,30.0129585266113,-1930.28295898438,-1930.28295898438,53.4915293420826,5.64360516620593,4.48899841308594,54,1,0,0,1,0.299606323242188,33.2355842590332,1,1,3,30.0126552581787,0,30.012806892395,,,,,,,,,,,,,,,,,,,,,,,,,,,,,,,,,
,3883377136.47471,30.000412940979,-2509.99731445313,-0.000128278196841924,2.86706638996721E-8,1,4,13.4005146026611,4.98435869540625,30.4300002753735,-0.158753233041154,-0.0236938451588286,1,4.32032866928299E-8,,,,,,,,,,,,,,,,,,,,,29.9999656677246,30.0008602142334,-2509.99731445313,-2509.99731445313,53.4997364415345,5.64414635282135,4.48221921920776,54,1,0,0,1,0.299758911132812,33.7243423461914,1,1,3,29.9999656677246,0,30.000412940979,,,,,,,,,,,,,,,,,,,,,,,,,,,,,,,,,
,3883377191.26013,30.0041179656982,-3000.08325195313,-0.000126721890986159,1.55570064051616E-8,1,4,13.4005146026611,4.98424676548221,30.4300002753735,-0.156820410906387,-0.0234179748597533,1,3.27174536834364E-8,,,,,,,,,,,,,,,,,,,,,30.0039710998535,30.004264831543,-3000.08325195313,-3000.08325195313,53.5700830082653,5.64288684437398,4.49508857727051,54,1,0,0,1,0.298843383789063,33.2355842590332,1,1,3,30.0039710998535,0,30.0041179656982,,,,,,,,,,,,,,,,,,,,,,,,,,,,,,,,,
,3883377230.85252,30.0076742172241,-3999.94311523438,-0.000118360371929801,1.89327094160654E-8,1,4,13.4005146026611,4.98422342162077,30.4300002753735,-0.146479661924213,-0.0218209648346147,1,7.23157820794236E-8,,,,,,,,,,,,,,,,,,,,,30.0072078704834,30.0081405639648,-3999.94311523438,-3999.94311523438,53.472770257621,5.64396162760879,4.48770713806152,54,1,0,0,1,0.298995971679687,33.2355842590332,1,1,3,30.0072078704834,0,30.0076742172241,,,,,,,,,,,,,,,,,,,,,,,,,,,,,,,,,
,3883377270.83056,30.0181074142456,-5000.080078125,-0.000106523167142636,1.82692907578516E-8,1,4,13.4005146026611,4.98423156564809,30.4300002753735,-0.131830161742232,-0.0196413132708893,1,6.29701683414485E-8,,,,,,,,,,,,,,,,,,,,,30.0180969238281,30.0181179046631,-5000.080078125,-5000.080078125,53.5392086817557,5.64412863617761,4.49052953720093,54,1,0,0,1,0.29937744140625,33.2355842590332,1,1,3,30.0180969238281,0,30.0181074142456,,,,,,,,,,,,,,,,,,,,,,,,,,,,,,,,,
,3883377312.04158,30.0004825592041,-5999.990234375,-9.30869982162241E-5,1.49155287482205E-8,1,4,13.4005146026611,4.98413341125328,30.4300002753735,-0.11519061875006,-0.0172177165202797,1,1.1137794048571E-8,,,,,,,,,,,,,,,,,,,,,30.000301361084,30.0006637573242,-5999.990234375,-5999.990234375,53.239063330371,5.64408144258259,4.50127172470093,53,1,68,0,0,0.299530029296875,33.2355842590332,1,1,3,30.000301361084,0,30.0004825592041,,,,,,,,,,,,,,,,,,,,,,,,,,,,,,,,,
,3883377353.20719,30.0131731033325,-6999.64892578125,-7.87785139725306E-5,2.44993550204732E-8,1,4,13.4005146026611,4.98421391323654,30.4300002753735,-0.0974828692486107,-0.0145976162684796,1,-1.16819166272614E-8,,,,,,,,,,,,,,,,,,,,,30.0122470855713,30.0140991210937,-6999.64892578125,-6999.64892578125,53.3430199234287,5.64391459387918,4.49963045120239,48,1,100,0,0,0.300369262695313,33.7243423461914,1,1,3,30.0122470855713,0,30.0131731033325,,,,,,,,,,,,,,,,,,,,,,,,,,,,,,,,,
,3883377407.67707,30.0223073959351,-8000.01220703125,-6.39457372461479E-5,5.84812364687809E-8,1,4,13.4005146026611,4.98428375141916,30.4300002753735,-0.0791418165625152,-0.0117697309796512,1,5.48520440710326E-8,,,,,,,,,,,,,,,,,,,,,30.0215702056885,30.0230445861816,-8000.01220703125,-8000.01220703125,53.4567468729768,5.64339908536073,4.49828195571899,46,1,100,0,0,0.299072265625,33.2355842590332,1,1,3,30.0215702056885,0,30.0223073959351,,,,,,,,,,,,,,,,,,,,,,,,,,,,,,,,,
,3883377475.35238,30.0021772384644,-8999.6826171875,-4.88916510479114E-5,4.34109186683849E-8,1,4,13.4005146026611,4.98431056654924,30.4300002753735,-0.0605042874910397,-0.0090420435119876,1,7.13357750178741E-9,,,,,,,,,,,,,,,,,,,,,30.0020847320557,30.002269744873,-8999.6826171875,-8999.6826171875,53.5020813270922,5.64300681608696,4.50724792480469,44,1,100,0,0,0.299453735351562,33.2355842590332,1,1,3,30.0020847320557,0,30.0021772384644,,,,,,,,,,,,,,,,,,,,,,,,,,,,,,,,,
,3883377542.91165,30.0137910842895,-9999.9970703125,-3.35220802092743E-5,2.96470562762819E-8,1,4,13.4005146026611,4.98428333087309,30.4300002753735,-0.0414771930046869,-0.00624405646644424,1,-3.10817529200022E-8,,,,,,,,,,,,,,,,,,,,,30.0136814117432,30.0139007568359,-9999.9970703125,-9999.9970703125,53.4344704601787,5.64424195531098,4.50913953781128,45,1,100,0,0,0.300750732421875,33.7243423461914,1,1,3,30.0136814117432,0,30.0137910842895,,,,,,,,,,,,,,,,,,,,,,,,,,,,,,,,,
,3883377602.00534,30.0243768692017,-10999.73046875,7.80123205496568E-7,1.56747115614407E-5,1,4,13.4005146026611,4.98419305859419,30.4300002753735,-0.00113591802406559,0.0141909890438064,10,1.13512291013646E-5,,,,,,,,,,,,,,,,,,,,,30.0241203308105,30.0246334075928,-10999.73046875,-10999.73046875,53.4641723439095,5.64355099161961,4.50613451004028,54,1,0,0,1,0.301666259765625,33.2355842590332,1,1,3,30.0246334075928,0,30.0243768692017,,,,,,,,,,,,,,,,,,,,,,,,,,,,,,,,,
,3883377655.59898,30.0031681060791,-11999.8544921875,-1.07701208412007E-5,9.61764667473798E-6,1,4,13.4005146026611,4.9841750446765,30.4300002753735,-0.0121728881879269,-0.00971145396533046,10,-6.23685371589652E-6,,,,,,,,,,,,,,,,,,,,,30.0024375915527,30.0038986206055,-11999.8544921875,-11999.8544921875,53.4094583475633,5.64424242276951,4.51138401031494,54,1,0,0,1,0.300369262695313,33.2355842590332,1,1,3,30.0024375915527,0,30.0031681060791,,,,,,,,,,,,,,,,,,,,,,,,,,,,,,,,,
,3883377696.90087,30.0244607925415,-12999.9287109375,1.47669526423743E-5,5.57009031741774E-6,1,4,13.4005146026611,4.98410267061047,30.4300002753735,0.0188724249746349,-0.00127418346955074,10,-3.23875631743075E-6,,,,,,,,,,,,,,,,,,,,,30.0232391357422,30.0256824493408,-12999.9287109375,-12999.9287109375,53.3770207640153,5.64373836096432,4.51479482650757,54,1,0,0,1,0.30029296875,33.7243423461914,1,1,3,30.0232391357422,0,30.0244607925415,,,,,,,,,,,,,,,,,,,,,,,,,,,,,,,,,
,3883377738.241,30.0137605667114,-13999.5869140625,3.52675088518226E-5,4.20616470452384E-6,1,4,13.4005146026611,4.98409769444433,30.4300002753735,0.0433128612768826,0.00871923355061485,10,1.77051791320038E-6,,,,,,,,,,,,,,,,,,,,,30.0135650634766,30.0139560699463,-13999.5869140625,-13999.5869140625,53.5392086817557,5.64438572970554,4.51844596862793,54,1,0,0,1,0.302658081054687,33.7243423461914,1,1,3,30.0135650634766,0,30.0137605667114,,,,,,,,,,,,,,,,,,,,,,,,,,,,,,,,,
,3883377795.97583,30.0088996887207,-14999.63671875,4.0570793424454E-5,3.25250450048097E-5,1,4,13.4005146026611,4.98419989292872,30.4300002753735,0.045271614577491,0.0404849168777325,10,2.66472066713557E-5,,,,,,,,,,,,,,,,,,,,,30.0086002349854,30.0091991424561,-14999.63671875,-14999.63671875,53.5098976122845,5.6442345039668,4.51941633224487,52,1,68,0,0,0.300216674804687,33.2355842590332,1,1,3,30.0086002349854,0,30.0088996887207,,,,,,,,,,,,,,,,,,,,,,,,,,,,,,,,,
,3883377895.49574,30.0001764297485,-24999.630859375,0.000206187487655242,2.39139502114093E-6,1,4,13.4005146026611,4.98423794937979,30.4400008171797,0.254855517886166,0.0401367133238931,10,1.59023423023945E-6,,,,,,,,,,,,,,,,,,,,,30.0001640319824,30.0001888275146,-24999.630859375,-24999.630859375,53.5567953234384,5.64431382428294,4.5160346031189,54,1,0,0,1,0.298995971679687,33.2355842590332,1,1,3,30.0001697540283,0,30.0001764297485,,,,,,,,,,,,,,,,,,,,,,,,,,,,,,,,,
,3883377993.88499,30.0190210342407,-34999.65625,0.00035168305888226,2.51679720464448E-5,1,4,13.4005146026611,4.98424821477322,30.4400008171797,0.432065330769407,0.0860365972498408,10,1.69166419810926E-5,,,,,,,,,,,,,,,,,,,,,30.018913269043,30.0191287994385,-34999.65625,-34999.65625,53.6498091172268,5.64405877146278,4.52144861221313,51,1,68,0,0,0.299224853515625,33.2355842590332,1,1,3,30.018913269043,0,30.0190210342407,,,,,,,,,,,,,,,,,,,,,,,,,,,,,,,,,
,3883378108.38549,30.0279216766357,-44999.82421875,0.000514719393176779,1.64097431483873E-5,1,4,13.4005146026611,4.98403200831158,30.4400008171797,0.639284439871709,0.0794090365900797,10,-1.28244225771769E-5,,,,,,,,,,,,,,,,,,,,,30.0262908935547,30.0295524597168,-44999.82421875,-44999.82421875,53.5059894696884,5.64499398359246,4.53006458282471,51,1,68,0,0,0.300064086914063,33.2355842590332,1,1,3,30.0295524597168,0,30.0279216766357,,,,,,,,,,,,,,,,,,,,,,,,,,,,,,,,,
,3883378215.16143,30.0056457519531,-54999.734375,0.000644663850157169,4.15591237438938E-5,1,4,13.4005146026611,4.98421154043513,30.4400008171797,0.800459223687372,0.101182360473896,10,-1.46713293465961E-5,,,,,,,,,,,,,,,,,,,,,30.0053119659424,30.0059795379639,-54999.734375,-54999.734375,53.503253769871,5.64441887668078,4.52045631408691,51,1,68,0,0,0.301589965820313,33.2355842590332,1,1,3,30.0053119659424,0,30.0056457519531,,,,,,,,,,,,,,,,,,,,,,,,,,,,,,,,,
,3883378317.25268,30.0311279296875,-64999.640625,0.000826656304525474,4.6895368610536E-5,1,4,13.4005146026611,4.98394806078479,30.4400008171797,1.01772502406761,0.18744332347073,10,2.78232468579082E-5,,,,,,,,,,,,,,,,,,,,,30.0287265777588,30.0335292816162,-64999.640625,-64999.640625,53.0596795852075,5.64615319749908,4.52367877960205,52,1,68,0,0,0.302963256835937,32.7468223571777,1,1,3,30.0335292816162,0,30.0311279296875,,,,,,,,,,,,,,,,,,,,,,,,,,,,,,,,,
,3883378426.31208,30.0575685501099,-64999.62890625,0.000849343934945464,1.46785948413303E-7,1,4,13.4005146026611,4.98395765294352,30.4400008171797,1.05113447583499,0.155988429930994,10,-9.91902569044605E-7,,,,,,,,,,,,,,,,,,,,,30.0519905090332,30.0631465911865,-64999.62890625,-64999.62890625,53.4919201563422,5.64604279894536,4.53848171234131,54,1,0,0,1,0.302581787109375,33.2355842590332,1,1,3,30.0631465911865,0,30.0575685501099,,,,,,,,,,,,,,,,,,,,,,,,,,,,,,,,,
,3883378522.85539,30.0212383270264,-54999.55859375,0.000709835791729324,0.000134836443734182,1,4,13.4005146026611,4.98382689300119,30.4400008171797,0.886903217164787,0.073848042378175,100,-4.65033066149764E-5,,,,,,,,,,,,,,,,,,,,,30.0204124450684,30.0220642089844,-54999.55859375,-54999.55859375,53.5462433384287,5.64554725215691,4.5311918258667,53,1,68,0,0,0.302047729492188,33.7243423461914,1,1,3,30.0204124450684,0,30.0212383270264,,,,,,,,,,,,,,,,,,,,,,,,,,,,,,,,,
,3883378630.98395,30.082649230957,-44999.53515625,0.00053032981564664,8.63279111502577E-6,1,4,13.4005146026611,4.98407286454484,30.4400008171797,0.657616903084939,0.0889265203359052,100,-7.46891577381254E-6,,,,,,,,,,,,,,,,,,,,,30.0811500549316,30.0841484069824,-44999.53515625,-44999.53515625,53.455574430198,5.64539889779959,4.53547620773315,52,1,68,0,0,0.30242919921875,33.7243423461914,1,1,3,30.0841484069824,0,30.082649230957,,,,,,,,,,,,,,,,,,,,,,,,,,,,,,,,,
,3883378730.75958,30.1302976608276,-34999.6796875,0.000356619265044218,5.45919330616366E-5,1,4,13.4005146026611,4.98407927949249,30.4400008171797,0.433022330080872,0.121242888188442,100,4.46331146571984E-5,,,,,,,,,,,,,,,,,,,,,30.1302051544189,30.1303901672363,-34999.6796875,-34999.6796875,53.4966099274576,5.6445288677574,4.54223537445068,51,1,68,0,0,0.301437377929687,33.7243423461914,1,1,3,30.1303901672363,0,30.1302976608276,,,,,,,,,,,,,,,,,,,,,,,,,,,,,,,,,
,3883385991.12204,299.907989501953,-24999.669921875,0.00022594228962488,3.35440950668089E-8,1,4,13.4005146026611,4.98310332812764,30.7100005447865,0.279550132628537,0.0415206687200672,10,-2.35863719930802E-7,,,,,,,,,,,,,,,,,,,,,299.898559570313,299.917419433594,-24999.669921875,-24999.669921875,53.4899660850441,5.64899800918358,5.28023719787598,54,1,0,0,1,0.303878784179687,33.7243423461914,1,1,3,299.917419433594,0,299.907989501953,,,,,,,,,,,,,,,,,,,,,,,,,,,,,,,,,
,3883386077.86141,299.989471435547,-15000.0263671875,6.04766320979011E-5,2.51498559144061E-8,1,4,13.4005146026611,4.98342324617261,30.7100005447865,0.0748248402806607,0.0111642318798813,10,-2.30090648627475E-8,,,,,,,,,,,,,,,,,,,,,299.98876953125,299.990173339844,-15000.0263671875,-15000.0263671875,53.5567953234384,5.64758642723421,5.2457914352417,54,1,0,0,1,0.303115844726562,33.7243423461914,1,1,3,299.990173339844,0,299.989471435547,,,,,,,,,,,,,,,,,,,,,,,,,,,,,,,,,
,3883386129.87308,299.939346313477,-14000.1279296875,4.40979522021087E-5,1.99682040268402E-8,1,4,13.4005146026611,4.98332152591338,30.7100005447865,0.0545582909075902,0.00814330624236562,10,-1.44510037422167E-8,,,,,,,,,,,,,,,,,,,,,299.937835693359,299.940856933594,-14000.1279296875,-14000.1279296875,53.4516662876018,5.64773754673364,5.23748064041138,54,1,0,0,1,0.301895141601562,33.7243423461914,1,1,3,299.940856933594,0,299.939346313477,,,,,,,,,,,,,,,,,,,,,,,,,,,,,,,,,
,3883386178.24309,299.975311279297,-13000.28125,2.77240850043334E-5,2.39056022167312E-8,1,4,13.4005146026611,4.98319778290073,30.7100005447865,0.0342946974479195,0.00514979078787807,1,1.54296682924411E-8,,,,,,,,,,,,,,,,,,,,,299.974365234375,299.976257324219,-13000.28125,-13000.28125,53.5306107680441,5.64878212118796,5.23460388183594,54,1,0,0,1,0.303192138671875,33.7243423461914,1,1,3,299.976257324219,0,299.975311279297,,,,,,,,,,,,,,,,,,,,,,,,,,,,,,,,,
,3883386217.2087,300.061767578125,-12000.20703125,1.14355271944472E-5,2.0182525680334E-8,1,4,13.4005146026611,4.98315061682335,30.7100005447865,0.0141369812094468,0.00218149245448936,1,5.27266563952504E-8,,,,,,,,,,,,,,,,,,,,,300.047180175781,300.076354980469,-12000.20703125,-12000.20703125,53.5306107680441,5.6487579414435,5.2352180480957,54,1,0,0,1,0.302352905273438,33.7243423461914,1,1,3,300.076354980469,0,300.061767578125,,,,,,,,,,,,,,,,,,,,,,,,,,,,,,,,,
,3883386257.48249,300.048645019531,-11000.1708984375,-4.7821507280108E-6,1.7728305257922E-8,1,4,13.4005146026611,4.9830179039977,30.7199992239475,-0.00592937764284842,-0.00079361665282985,1,7.38356931245985E-8,,,,,,,,,,,,,,,,,,,,,300.048492431641,300.048797607422,-11000.1708984375,-11000.1708984375,53.5618759088134,5.64920535588794,5.22927522659302,54,1,0,0,1,0.302200317382812,33.7243423461914,1,1,3,300.048492431641,0,300.048645019531,,,,,,,,,,,,,,,,,,,,,,,,,,,,,,,,,
,3883386297.2044,300.092254638672,-10000.349609375,-2.08991737936892E-5,2.42785728421819E-8,1,4,13.4005146026611,4.98320603836917,30.7100005447865,-0.0258690937255498,-0.00377007627660559,1,7.88912011739339E-8,,,,,,,,,,,,,,,,,,,,,300.079620361328,300.104888916016,-10000.349609375,-10000.349609375,53.4989548130153,5.64862776869677,5.23139047622681,52,1,68,0,0,0.303497314453125,33.7243423461914,1,1,3,300.104888916016,0,300.092254638672,,,,,,,,,,,,,,,,,,,,,,,,,,,,,,,,,
,3883386337.94863,299.978225708008,-9000.375,-3.68730151357803E-5,1.66583994884996E-8,1,4,13.4005146026611,4.98316248367061,30.7100005447865,-0.0456333795961515,-0.00670270363022969,1,9.78584658934539E-8,,,,,,,,,,,,,,,,,,,,,299.977264404297,299.979187011719,-9000.375,-9000.375,53.5392086817557,5.64857778746041,5.22952508926392,52,1,68,0,0,0.303573608398438,34.2131004333496,1,1,3,299.977264404297,0,299.978225708008,,,,,,,,,,,,,,,,,,,,,,,,,,,,,,,,,
,3883386379.16186,299.993759155273,-8000.376953125,-5.26443899140759E-5,1.46683494266588E-8,1,4,13.4005146026611,4.98324578960882,30.7100005447865,-0.0651502063580394,-0.00959034629273386,1,1.23120491875214E-7,,,,,,,,,,,,,,,,,,,,,299.993072509766,299.994445800781,-8000.376953125,-8000.376953125,53.4665172294672,5.64806847928729,5.24220323562622,53,1,68,0,0,0.30181884765625,33.7243423461914,1,1,3,299.994445800781,0,299.993759155273,,,,,,,,,,,,,,,,,,,,,,,,,,,,,,,,,
,3883386420.30399,299.924285888672,-7000.07666015625,-6.81707379047706E-5,1.38883779140884E-8,1,4,13.4005146026611,4.98345811871899,30.7100005447865,-0.0843645510955226,-0.0124554748972058,1,1.30401599197917E-7,,,,,,,,,,,,,,,,,,,,,299.913452148438,299.935119628906,-7000.07666015625,-7000.07666015625,53.5399903102749,5.64707265822382,5.24796867370605,52,1,68,0,0,0.30181884765625,33.7243423461914,1,1,3,299.935119628906,0,299.924285888672,,,,,,,,,,,,,,,,,,,,,,,,,,,,,,,,,
,3883386461.38801,300.123764038086,-6000.2548828125,-8.32155962758712E-5,1.14083370486829E-8,1,4,13.4005146026611,4.98339981566282,30.7100005447865,-0.102977899254235,-0.0152287623944585,1,1.39222711105497E-7,,,,,,,,,,,,,,,,,,,,,300.107299804687,300.140228271484,-6000.2548828125,-6000.2548828125,53.5126333121018,5.64759206346855,5.26671934127808,54,1,0,0,1,0.302352905273438,33.7243423461914,1,1,3,300.140228271484,0,300.123764038086,,,,,,,,,,,,,,,,,,,,,,,,,,,,,,,,,
,3883386501.20301,300.262252807617,-5000.24365234375,-9.75522180424E-5,1.37010075592253E-8,1,4,13.4005146026611,4.98322229781699,30.7100005447865,-0.12071135543495,-0.0178638114161483,1,1.53276845083824E-7,,,,,,,,,,,,,,,,,,,,,300.251098632812,300.273406982422,-5000.24365234375,-5000.24365234375,53.5864972071691,5.64834552051623,5.28877639770508,52,1,68,0,0,0.304031372070313,34.2131004333496,1,1,3,300.273406982422,0,300.262252807617,,,,,,,,,,,,,,,,,,,,,,,,,,,,,,,,,
,3883386542.49012,300.20768737793,-4000.4970703125,-0.000110441710257665,1.06069274194804E-8,1,4,13.4005146026611,4.98319355011782,30.7100005447865,-0.136658181753275,-0.0202343857101537,1,1.65116228324785E-7,,,,,,,,,,,,,,,,,,,,,300.197021484375,300.218353271484,-4000.4970703125,-4000.4970703125,53.5274842539672,5.6482900621355,5.31936025619507,53,1,68,0,0,0.30364990234375,32.7468223571777,1,1,3,300.218353271484,0,300.20768737793,,,,,,,,,,,,,,,,,,,,,,,,,,,,,,,,,
,3883386582.78661,300.172088623047,-3000.4482421875,-0.000120407593297596,1.31912806713255E-8,1,4,13.4005146026611,4.98315203521861,30.7199992239475,-0.148982550748687,-0.0220964904147819,1,1.5052658476002E-7,,,,,,,,,,,,,,,,,,,,,300.166839599609,300.177337646484,-3000.4482421875,-3000.4482421875,53.4286082462845,5.64881142215526,5.35424327850342,54,1,0,0,1,0.304107666015625,33.7243423461914,1,1,3,300.177337646484,0,300.172088623047,,,,,,,,,,,,,,,,,,,,,,,,,,,,,,,,,
,3883386640.16029,300.313583374023,-2510.33715820313,-0.000123216834194827,1.24638297638427E-8,1,4,13.4005146026611,4.98318549368111,30.7100005447865,-0.152458091336393,-0.0226244165173441,1,1.44194725655937E-7,,,,,,,,,,,,,,,,,,,,,300.313018798828,300.314147949219,-2510.33715820313,-2510.33715820313,53.399687991073,5.64891317071131,5.41696691513062,54,1,0,0,1,0.302352905273438,33.7243423461914,1,1,3,300.314147949219,0,300.313583374023,,,,,,,,,,,,,,,,,,,,,,,,,,,,,,,,,
,3883386693.5056,300.252899169922,-1930.27038574219,-0.000123290031298837,1.44449764184966E-8,1,4,13.4005146026611,4.98324170670157,30.7100005447865,-0.152552724859381,-0.0226271785534118,1,1.53201399969903E-7,,,,,,,,,,,,,,,,,,,,,300.244720458984,300.261077880859,-1930.27038574219,-1930.27038574219,53.4989548130153,5.64859650316843,5.48291826248169,54,1,0,0,1,0.303726196289063,33.7243423461914,1,1,3,300.244720458984,0,300.252899169922,,,,,,,,,,,,,,,,,,,,,,,,,,,,,,,,,
,3883386732.17176,300.163879394531,-1350.40502929688,-0.000117327122739878,1.25564692065627E-8,1,4,13.4005146026611,4.98318992380172,30.7100005447865,-0.145170830267612,-0.0215430812303924,1,1.37241511487885E-7,,,,,,,,,,,,,,,,,,,,,300.145202636719,300.182556152344,-1350.40502929688,-1350.40502929688,53.5544504378807,5.64853694084628,5.53460264205933,54,1,0,0,1,0.302505493164063,34.2131004333496,1,1,3,300.182556152344,0,300.163879394531,,,,,,,,,,,,,,,,,,,,,,,,,,,,,,,,,
,3883386771.94347,300.120819091797,-770.287902832031,-9.92223086341207E-5,2.79484129229327E-8,1,4,13.4005146026611,4.98334055097057,30.7100005447865,-0.122776236675976,-0.0182088902438371,1,1.24663095701146E-7,,,,,,,,,,,,,,,,,,,,,300.113555908203,300.128082275391,-770.287902832031,-770.287902832031,53.5071619124672,5.6485009710253,5.59379196166992,54,1,0,0,1,0.30242919921875,33.7243423461914,1,1,3,300.113555908203,0,300.120819091797,,,,,,,,,,,,,,,,,,,,,,,,,,,,,,,,,
,3883386809.79024,300.108489990234,-190.472885131836,-5.05300640291903E-5,1.18711042425699E-7,1,4,13.4005146026611,4.98309260703449,30.7100005447865,-0.0625064835481481,-0.00936812572972852,1,-1.38689322206588E-8,,,,,,,,,,,,,,,,,,,,,300.097320556641,300.119659423828,-190.472885131836,-190.472885131836,53.5231852971114,5.64897714582074,5.65670299530029,54,1,0,0,1,0.302047729492188,33.7243423461914,1,1,3,300.119659423828,0,300.108489990234,,,,,,,,,,,,,,,,,,,,,,,,,,,,,,,,,
,3883386849.11623,300.265823364258,389.744964599609,6.07649628278921E-5,1.53785247759019E-8,1,4,13.4005146026611,4.98337563320954,30.7100005447865,0.0751852253508085,0.0111861899297269,1,-4.8271908493791E-8,,,,,,,,,,,,,,,,,,,,,300.263793945313,300.267852783203,389.744964599609,389.744964599609,53.552105552323,5.64767740399283,5.72452926635742,54,1,0,0,1,0.30242919921875,33.7243423461914,1,1,3,300.267852783203,0,300.265823364258,,,,,,,,,,,,,,,,,,,,,,,,,,,,,,,,,
,3883386889.84487,300.343368530273,969.622924804687,0.000103314746874545,2.69035940572813E-8,1,4,13.4005146026611,4.98329804842683,30.7100005447865,0.127838546265543,0.0189602521147373,1,-1.29351778797331E-7,,,,,,,,,,,,,,,,,,,,,300.329742431641,300.356994628906,969.622924804687,969.622924804687,53.533737282121,5.64745916873903,5.80110311508179,54,1,0,0,1,0.302276611328125,33.7243423461914,1,1,3,300.356994628906,0,300.343368530273,,,,,,,,,,,,,,,,,,,,,,,,,,,,,,,,,
,3883386929.6985,300.29345703125,1549.53869628906,0.00011844641451049,1.62664680962362E-8,1,4,13.4005146026611,4.98321641293214,30.7100005447865,0.146556196331334,0.0217530790996286,1,-1.35061763379742E-7,,,,,,,,,,,,,,,,,,,,,300.281921386719,300.304992675781,1549.53869628906,1549.53869628906,53.4579193157556,5.64754992072183,5.87916326522827,54,1,0,0,1,0.302658081054687,33.7243423461914,1,1,3,300.281921386719,0,300.29345703125,,,,,,,,,,,,,,,,,,,,,,,,,,,,,,,,,
,3883386968.97887,300.349090576172,2129.63061523438,0.000122664698218545,1.38458029721915E-8,1,4,13.4005146026611,4.98329298650028,30.7100005447865,0.151776690784263,0.0225426234444041,1,-1.28266963542934E-7,,,,,,,,,,,,,,,,,,,,,300.330322265625,300.367858886719,2129.63061523438,2129.63061523438,53.5102884265441,5.64770629631856,5.95313882827759,54,1,0,0,1,0.303421020507812,33.7243423461914,1,1,3,300.367858886719,0,300.349090576172,,,,,,,,,,,,,,,,,,,,,,,,,,,,,,,,,
,3883387008.49155,300.331726074219,2709.72265625,0.000121449482663204,2.32935466374609E-8,1,4,13.4005146026611,4.98336826327946,30.7100005447865,0.150275931077061,0.0223219263948211,1,-1.25254112536967E-7,,,,,,,,,,,,,,,,,,,,,300.322662353516,300.340789794922,2709.72265625,2709.72265625,53.5712554510441,5.647934727389,6.01104307174683,54,1,0,0,1,0.303192138671875,33.7243423461914,1,1,3,300.322662353516,0,300.331726074219,,,,,,,,,,,,,,,,,,,,,,,,,,,,,,,,,
,3883387134.02707,300.186538696289,3499.77392578125,0.000115266393394134,7.91079012196163E-9,1,4,13.4005146026611,4.98323010964694,30.7100005447865,0.142628019722288,0.0211291698437428,1,-1.63744241068684E-7,,,,,,,,,,,,,,,,,,,,,300.185424804687,300.187652587891,3499.77392578125,3499.77392578125,53.557186137698,5.6478053354462,5.96327447891235,54,1,0,0,1,0.301361083984375,33.7243423461914,1,1,3,300.185424804687,0,300.186538696289,,,,,,,,,,,,,,,,,,,,,,,,,,,,,,,,,
,3883387174.4564,300.278427124023,4499.78466796875,0.000103541051584811,1.00149875571373E-8,1,4,13.4005146026611,4.98328723002166,30.7100005447865,0.128108054842019,0.0190694005155425,1,-7.49320846298534E-8,,,,,,,,,,,,,,,,,,,,,300.255462646484,300.301391601562,4499.78466796875,4499.78466796875,53.5943134923614,5.6473712699966,5.94100046157837,54,1,0,0,1,0.301971435546875,33.7243423461914,1,1,3,300.301391601562,0,300.278427124023,,,,,,,,,,,,,,,,,,,,,,,,,,,,,,,,,
,3883387226.99358,300.404525756836,5499.87158203125,8.98086514311958E-5,7.6841270521518E-9,1,4,13.4005146026611,4.9832931542154,30.7100005447865,0.111125339129629,0.0164884154799417,1,-1.06932803009102E-7,,,,,,,,,,,,,,,,,,,,,300.399749755859,300.409301757812,5499.87158203125,5499.87158203125,53.6068195486691,5.64750295342723,5.91289186477661,54,1,0,0,1,0.302047729492188,33.2355842590332,1,1,3,300.399749755859,0,300.404525756836,,,,,,,,,,,,,,,,,,,,,,,,,,,,,,,,,
,3883387281.57354,300.436630249023,6499.5927734375,7.50615181325283E-5,1.23673033682187E-8,1,4,13.4005146026611,4.98341927829935,30.7100005447865,0.0928808275326153,0.0137837142503622,1,-8.75077057966663E-8,,,,,,,,,,,,,,,,,,,,,300.430908203125,300.442352294922,6499.5927734375,6499.5927734375,53.5055986554287,5.64796073516103,5.88643217086792,54,1,0,0,1,0.302963256835937,33.2355842590332,1,1,3,300.430480957031,0,300.436630249023,,,,,,,,,,,,,,,,,,,,,,,,,,,,,,,,,
,3883387334.69026,300.337905883789,7500.01953125,5.97462091120265E-5,1.18303931282769E-8,1,4,13.4005146026611,4.98343150611639,30.7100005447865,0.0739189811644671,0.0110448847395219,1,-1.02299936419316E-8,,,,,,,,,,,,,,,,,,,,,300.327392578125,300.348419189453,7500.01953125,7500.01953125,53.4536203588999,5.64782253352187,5.86325407028198,54,1,0,0,1,0.303497314453125,33.7243423461914,1,1,3,300.327392578125,0,300.337905883789,,,,,,,,,,,,,,,,,,,,,,,,,,,,,,,,,
,3883387387.63463,300.416091918945,8499.564453125,4.41095997398264E-5,1.31498258120716E-8,1,4,13.4005146026611,4.98354498708436,30.7100005447865,0.0545788203713425,0.00812801867075253,1,-2.89638837764087E-8,,,,,,,,,,,,,,,,,,,,,300.412322998047,300.419860839844,8499.564453125,8499.564453125,53.498173184496,5.64681035764518,5.85161447525024,54,1,0,0,1,0.302047729492188,33.2355842590332,1,1,3,300.412322998047,0,300.416091918945,,,,,,,,,,,,,,,,,,,,,,,,,,,,,,,,,
,3883387452.20401,300.43115234375,9499.83984375,2.8241689956746E-5,1.58743630772939E-8,1,4,13.4005146026611,4.98322073705102,30.7100005447865,0.0349393052253482,0.00521853251266694,1,-6.46142210390239E-9,,,,,,,,,,,,,,,,,,,,,300.424194335937,300.438110351562,9499.83984375,9499.83984375,53.5618759088134,5.64838689344511,5.83353805541992,54,1,0,0,1,0.30242919921875,33.7243423461914,1,1,3,300.424194335937,0,300.43115234375,,,,,,,,,,,,,,,,,,,,,,,,,,,,,,,,,
,3883387505.72519,300.310989379883,10499.69921875,1.21896118686889E-5,1.59416402914756E-8,1,4,13.4005146026611,4.98326306434146,30.7100005447865,0.0150721904894113,0.00230865703487161,1,4.26547300679712E-8,,,,,,,,,,,,,,,,,,,,,300.298431396484,300.323547363281,10499.69921875,10499.69921875,53.5958767493999,5.64818277995206,5.81858205795288,54,1,0,0,1,0.302276611328125,33.7243423461914,1,1,3,300.298431396484,0,300.310989379883,,,,,,,,,,,,,,,,,,,,,,,,,,,,,,,,,
,3883387546.87366,300.287811279297,11500.025390625,-3.97271996538686E-6,1.43759471488651E-8,1,4,13.4005146026611,4.98376371531559,30.7100005447865,-0.00492812245825207,-0.000650591916679571,1,6.84787413840208E-8,,,,,,,,,,,,,,,,,,,,,300.285034179687,300.290588378906,11500.025390625,11500.025390625,53.4798049142941,5.64739422421031,5.80517292022705,54,1,0,0,1,0.3009033203125,33.7243423461914,1,1,3,300.290588378906,0,300.287811279297,,,,,,,,,,,,,,,,,,,,,,,,,,,,,,,,,
,3883387588.03076,300.270690917969,12499.97265625,-2.02220692298054E-5,1.67934500870438E-8,1,4,13.4005146026611,4.98375961177689,30.7100005447865,-0.0250369493959198,-0.0036346142631027,1,8.75575264003985E-8,,,,,,,,,,,,,,,,,,,,,300.261932373047,300.279449462891,12499.97265625,12499.97265625,53.470816186323,5.64741851401568,5.79561996459961,53,1,68,0,0,0.300750732421875,33.2355842590332,1,1,3,300.261932373047,0,300.270690917969,,,,,,,,,,,,,,,,,,,,,,,,,,,,,,,,,
,3883387629.26134,300.29736328125,13499.8076171875,-3.65661352117523E-5,1.72251511022067E-8,1,4,13.4005146026611,4.98369225242953,30.7100005447865,-0.0452628017422153,-0.00663146261686933,1,1.10338181823654E-7,,,,,,,,,,,,,,,,,,,,,300.29296875,300.3017578125,13499.8076171875,13499.8076171875,53.5192771545153,5.64744207050672,5.78745746612549,54,1,0,0,1,0.302276611328125,33.2355842590332,1,1,3,300.3017578125,0,300.29736328125,,,,,,,,,,,,,,,,,,,,,,,,,,,,,,,,,
,3883387670.43405,300.243041992188,14499.6552734375,-5.29306535278349E-5,2.25403548797382E-8,1,4,13.4005146026611,4.98371409341479,30.7100005447865,-0.0655155150885823,-0.00962769104594323,1,1.36782974935557E-7,,,,,,,,,,,,,,,,,,,,,300.223968505859,300.262115478516,14499.6552734375,14499.6552734375,53.5423351958326,5.64725163366604,5.77737283706665,54,1,0,0,1,0.301284790039063,33.2355842590332,1,1,3,300.262115478516,0,300.243041992188,,,,,,,,,,,,,,,,,,,,,,,,,,,,,,,,,
,3883387739.13797,300.240173339844,19999.615234375,-0.000143644592611069,2.84299232031528E-8,1,4,13.4005146026611,4.98330309827578,30.7100005447865,-0.177735313314784,-0.026404500205365,1,1.45164830573895E-7,,,,,,,,,,,,,,,,,,,,,300.239898681641,300.240447998047,19999.615234375,19999.615234375,53.5091159837653,5.6479905744785,5.76743984222412,54,1,0,0,1,0.302810668945313,33.7243423461914,1,1,3,300.239898681641,0,300.240173339844,,,,,,,,,,,,,,,,,,,,,,,,,,,,,,,,,
,3883387824.3995,300.050872802734,30000.1796875,-0.000309853230885126,3.46149771520595E-8,1,4,13.4005146026611,4.98342293298385,30.7100005447865,-0.383378658107778,-0.0571190721269658,1,1.83429567796123E-7,,,,,,,,,,,,,,,,,,,,,300.04833984375,300.053405761719,30000.1796875,30000.1796875,53.470816186323,5.64838559879782,5.7469220161438,54,1,0,0,1,0.302047729492188,33.7243423461914,1,1,3,300.04833984375,0,300.050872802734,,,,,,,,,,,,,,,,,,,,,,,,,,,,,,,,,
,3883387909.85396,300.17805480957,40000.44140625,-0.000476543608659235,6.03927863082138E-8,1,4,13.4005146026611,4.98323880995034,30.7100005447865,-0.589566457977909,-0.0880174921640086,1,1.40748629480279E-7,,,,,,,,,,,,,,,,,,,,,300.155944824219,300.200164794922,40000.44140625,40000.44140625,53.437206159996,5.64837116222663,5.73894548416138,53,1,68,0,0,0.303268432617188,33.2355842590332,1,1,3,300.200164794922,0,300.17805480957,,,,,,,,,,,,,,,,,,,,,,,,,,,,,,,,,
,3883387996.30086,300.059295654297,50000.20703125,-0.000643406059646749,9.85379476638277E-8,1,4,13.4005146026611,4.9831031440068,30.7100005447865,-0.795956032816862,-0.11894996812701,1,9.50007517589258E-8,,,,,,,,,,,,,,,,,,,,,300.056945800781,300.061645507812,50000.20703125,50000.20703125,53.386400306246,5.64925509607232,5.72330236434937,54,1,0,0,1,0.303192138671875,33.2355842590332,1,1,3,300.056945800781,0,300.059295654297,,,,,,,,,,,,,,,,,,,,,,,,,,,,,,,,,
,3883388083.90256,300.031051635742,60000.1953125,-0.000810419274599796,1.28045210178501E-7,1,4,13.4005146026611,4.98322393061041,30.7100005447865,-1.0025727311231,-0.150025785200849,1,-3.72224889634348E-8,,,,,,,,,,,,,,,,,,,,,300.007751464844,300.054351806641,60000.1953125,60000.1953125,53.2793171991114,5.64820111076333,5.71791362762451,54,1,0,0,1,0.303573608398438,33.2355842590332,1,1,3,300.054351806641,0,300.031051635742,,,,,,,,,,,,,,,,,,,,,,,,,,,,,,,,,
,3883388171.44188,300.043823242188,70000.1875,-0.000977471804637049,1.36316243272326E-7,1,4,13.4005146026611,4.98320076064894,30.7100005447865,-1.20918639285016,-0.181215367477231,1,-2.59750763131625E-7,,,,,,,,,,,,,,,,,,,,,300.032531738281,300.055114746094,70000.1875,70000.1875,53.2015451614479,5.64868266588323,5.70794343948364,52,1,68,0,0,0.302886962890625,33.2355842590332,1,1,3,300.055114746094,0,300.043823242188,,,,,,,,,,,,,,,,,,,,,,,,,,,,,,,,,
,3883388175.28979,300.063049316406,70000.1875,-0.000977517193383599,1.36122949486005E-7,1,4,13.4005146026611,4.9832322249002,30.7199992239475,-1.20926686513912,-0.181134406269994,1,-1.86219534039077E-7,,,,,,,,,,,,,,,,,,,,,300.055114746094,300.070983886719,70000.1875,70000.1875,53.2234307599864,5.64883110085201,5.70662450790405,54,2,0,0,1,0.303573608398438,33.7243423461914,1,1,3,300.070983886719,0,300.063049316406,,,,,,,,,,,,,,,,,,,,,,,,,,,,,,,,,