File: SQUID/23006_LCOS/transfer_119973_files_84937504/23006_LCOS_A1_MH_300K_FC_p0d5T.dat
[Header]
; MPMS3 Data File (default extension .dat)
; Copyright (c) 2007, Quantum Design, Inc. All rights reserved.
TITLE,
FILEOPENTIME,3883336808.41622,01/20/2023,12:44 am
BYAPP,SQUID AC,0.9.1.0
INFO,MPMS3 Measurement Release 1.1.16 Build 347, MultiVu Release 2.3.3.2,APPNAME
INFO,0,MOMENT_UNITS
INFO,LSAT//LCO,SAMPLE_MATERIAL
INFO,,SAMPLE_COMMENT
INFO,,SAMPLE_MASS
INFO,,SAMPLE_VOLUME
INFO,,SAMPLE_MOLECULAR_WEIGHT
INFO,,SAMPLE_SIZE
INFO,,SAMPLE_SHAPE
INFO,Quartz,SAMPLE_HOLDER
INFO,Standard,SAMPLE_HOLDER_DETAIL
INFO,65.59,SAMPLE_OFFSET
DATATYPE,COMMENT,1
DATATYPE,TIME,2
STARTUPAXIS,X,2
STARTUPAXIS,Y1,5
FIELDGROUP, VSM,2,3,4,5,6,8,9,10,11,14,15
FIELDGROUP, DC, 2,3,4,14,56,57,58,59,60,61,62,63,64,65,66,67,68,69
FIELDGROUP, AC, 2,3,4,11,16,17,18,19,20,21,22,23,24,25,26,27,28,29,30
STARTUPGROUP, All
[Data]
Comment,Time Stamp (sec),Temperature (K),Magnetic Field (Oe),Moment (emu),M. Std. Err. (emu),Transport Action,Averaging Time (sec),Frequency (Hz),Peak Amplitude (mm),Center Position (mm),Lockin Signal' (V),Lockin Signal (V),Range,M. Quad. Signal (emu),AC Moment (emu),AC M. Std Err. (emu),AC Phase (deg),AC Phase Std. Err. (deg),AC Susceptibility (emu/Oe),AC Suscept. Std Err. (emu/Oe),AC X' (emu/Oe),AC X' Std Err. (emu/Oe),AC X'' (emu/Oe),AC X'' Std Err. (emu/Oe),AC Drive (Oe),AC Frequency (Hz),AC Averaging Time (sec),AC Cycles,AC Range,AC Measure Type,AC Signal' (V),AC Signal'' (V),AC Trim Coil Ratio,AC Trim Coil Phase,Min. Temperature (K),Max. Temperature (K),Min. Field (Oe),Max. Field (Oe),Mass (grams),Motor Lag (deg),Pressure (Torr),Measure Count,Measurement Number,SQUID Status (code),Motor Status (code),Measure Status (code),Motor Current (amps),Motor Temp. (C),Temp. Status (code),Field Status (code),Chamber Status (code),Chamber Temp (K),Redirection State,Average Temp (K),Rotation Angle (deg),Rotator state,DC Moment Fixed Ctr (emu),DC Moment Err Fixed Ctr (emu),DC Moment Free Ctr (emu),DC Moment Err Free Ctr (emu),DC Fixed Fit,DC Free Fit,DC Calculated Center (mm),DC Calculated Center Err (mm),DC Scan Length (mm),DC Scan Time (s),DC Number of Points,DC Squid Drift,DC Min V (V),DC Max V (V),DC Scans per Measure,Map 01,Map 02,Map 03,Map 04,Map 05,Map 06,Map 07,Map 08,Map 09,Map 10,Map 11,Map 12,Map 13,Map 14,Map 15,Map 16
,3883336848.10681,299.98503112793,70000.1015625,-0.000975777023697686,1.82916635162339E-7,1,4,13.4005146026611,4.99413934078569,30.7100005447865,-1.2108383335767,-0.181244083099675,1,-8.68028304542075E-8,,,,,,,,,,,,,,,,,,,,,299.984893798828,299.985168457031,70000.1015625,70000.1015625,53.1104854389575,5.6463185140151,5.43055629730225,54,1,0,0,1,0.300750732421875,32.7468223571777,1,1,3,299.985168457031,0,299.98503112793,,,,,,,,,,,,,,,,,,,,,,,,,,,,,,,,,
,3883336942.76173,299.917419433594,60000.21875,-0.000809269697446582,2.0346163339077E-7,1,4,13.4005146026611,4.99413786451683,30.7199992239475,-1.00444449446601,-0.148812709630791,10,1.13976620616481E-6,,,,,,,,,,,,,,,,,,,,,299.915313720703,299.919525146484,60000.21875,60000.21875,53.0932896115345,5.64664761774936,5.45431995391846,54,1,0,0,1,0.300674438476562,33.2355842590332,1,1,3,299.919525146484,0,299.917419433594,,,,,,,,,,,,,,,,,,,,,,,,,,,,,,,,,
,3883337046.1774,300.058929443359,49999.73046875,-0.000641989591542207,1.43566356417304E-7,1,4,13.4005146026611,4.99408392211421,30.7100005447865,-0.796642949910986,-0.119158743754387,1,1.11420419025378E-8,,,,,,,,,,,,,,,,,,,,,300.058013916016,300.059844970703,49999.73046875,49999.73046875,53.4743335146595,5.64767186590804,5.53255414962769,53,1,68,0,0,0.302276611328125,34.7018585205078,1,1,3,300.058013916016,0,300.058929443359,,,,,,,,,,,,,,,,,,,,,,,,,,,,,,,,,
,3883337133.05391,300.090560913086,39999.78515625,-0.000475431516463424,5.5126721330317E-8,1,4,13.4005146026611,4.99405710849938,30.7100005447865,-0.589971081833947,-0.0881500103110149,1,8.35770038969993E-8,,,,,,,,,,,,,,,,,,,,,300.088775634766,300.092346191406,39999.78515625,39999.78515625,53.4520571018614,5.6479520728237,5.63864707946777,54,1,0,0,1,0.302047729492188,33.7243423461914,1,1,3,300.088775634766,0,300.090560913086,,,,,,,,,,,,,,,,,,,,,,,,,,,,,,,,,
,3883337219.94454,300.071640014648,29999.751953125,-0.000308973919908446,3.90153270128659E-8,1,4,13.4005146026611,4.99422905185121,30.7100005447865,-0.383435268899395,-0.0572512267810678,1,8.5384135641794E-8,,,,,,,,,,,,,,,,,,,,,300.048370361328,300.094909667969,29999.751953125,29999.751953125,53.5943134923614,5.64683140868074,5.78406238555908,54,1,0,0,1,0.302505493164063,33.7243423461914,1,1,3,300.094909667969,0,300.071640014648,,,,,,,,,,,,,,,,,,,,,,,,,,,,,,,,,
,3883337307.62796,300.201583862305,19999.75390625,-0.00014298047243773,2.77000537702028E-8,1,4,13.4005146026611,4.9941418459618,30.7100005447865,-0.177438568445961,-0.0264609599659353,1,6.52307166198292E-8,,,,,,,,,,,,,,,,,,,,,300.183898925781,300.219268798828,19999.75390625,19999.75390625,53.5384270532364,5.64672040635912,5.95436716079712,54,1,0,0,1,0.301055908203125,34.2131004333496,1,1,3,300.219268798828,0,300.201583862305,,,,,,,,,,,,,,,,,,,,,,,,,,,,,,,,,
,3883337379.90319,300.108947753906,14499.71875,-5.22840472630058E-5,2.21134259365198E-8,1,4,13.4005146026611,4.99422452895298,30.7100005447865,-0.0648865359038345,-0.00967225715052943,1,2.70896765608445E-8,,,,,,,,,,,,,,,,,,,,,300.107971191406,300.109924316406,14499.71875,14499.71875,53.3906992631018,5.64680699205836,6.09419918060303,54,1,0,0,1,0.303192138671875,34.2131004333496,1,1,3,300.109924316406,0,300.108947753906,,,,,,,,,,,,,,,,,,,,,,,,,,,,,,,,,
,3883337421.61309,300.168182373047,13499.794921875,-3.59153350055619E-5,2.13396132398116E-8,1,4,13.4005146026611,4.99430171255605,30.7100005447865,-0.0445707557490536,-0.00666123712379648,1,4.94462947605234E-9,,,,,,,,,,,,,,,,,,,,,300.152648925781,300.183715820313,13499.794921875,13499.794921875,53.6150266481211,5.64675585880243,6.17795991897583,53,1,68,0,0,0.300140380859375,34.2131004333496,1,1,3,300.183715820313,0,300.168182373047,,,,,,,,,,,,,,,,,,,,,,,,,,,,,,,,,
,3883337462.26546,300.248504638672,12499.6962890625,-1.95981441519181E-5,1.94733412417382E-8,1,4,13.4005146026611,4.99426202178799,30.7100005447865,-0.0243170569909286,-0.00366073275970452,1,-1.8168449065951E-8,,,,,,,,,,,,,,,,,,,,,300.229583740234,300.267425537109,12499.6962890625,12499.6962890625,53.5939226781018,5.6473210447415,6.25777959823608,54,1,0,0,1,0.300216674804687,34.2131004333496,1,1,3,300.267425537109,0,300.248504638672,,,,,,,,,,,,,,,,,,,,,,,,,,,,,,,,,
,3883337504.62082,300.28010559082,11499.861328125,-3.36036715642887E-6,2.23932513907174E-8,1,4,13.4005146026611,4.99414483604821,30.7100005447865,-0.00416237544535019,-0.000674295602204017,1,-4.06955921042804E-8,,,,,,,,,,,,,,,,,,,,,300.268432617188,300.291778564453,11499.861328125,11499.861328125,53.3883543775441,5.64806796112103,6.29912185668945,54,1,0,0,1,0.30029296875,34.2131004333496,1,1,3,300.268432617188,0,300.28010559082,,,,,,,,,,,,,,,,,,,,,,,,,,,,,,,,,
,3883337544.74331,300.267196655273,10499.7119140625,1.28172076840364E-5,1.70614712507537E-8,1,4,13.4005146026611,4.99401307902213,30.7100005447865,0.0159166094087271,0.00229810989433547,1,-6.53589705520384E-8,,,,,,,,,,,,,,,,,,,,,300.253601074219,300.280792236328,10499.7119140625,10499.7119140625,53.592750235323,5.64862529657582,6.28748416900635,54,1,0,0,1,0.301437377929687,34.2131004333496,1,1,3,300.280792236328,0,300.267196655273,,,,,,,,,,,,,,,,,,,,,,,,,,,,,,,,,
,3883337587.08002,300.385696411133,9499.6513671875,2.88598767474818E-5,1.55271472783485E-8,1,4,13.4005146026611,4.99422081397288,30.7100005447865,0.0358278489285141,0.00526098711247005,1,-7.77469403175737E-8,,,,,,,,,,,,,,,,,,,,,300.369049072266,300.40234375,9499.6513671875,9499.6513671875,53.5325648393422,5.64759901698127,6.25671005249023,54,1,0,0,1,0.300979614257812,34.2131004333496,1,1,3,300.40234375,0,300.385696411133,,,,,,,,,,,,,,,,,,,,,,,,,,,,,,,,,
,3883337630.1444,300.361785888672,8499.765625,4.47365372558372E-5,1.41796324849624E-8,1,4,13.4005146026611,4.99384583534582,30.7199992239475,0.0555276220304465,0.00818330406829308,1,-9.71845722000232E-8,,,,,,,,,,,,,,,,,,,,,300.345794677734,300.377777099609,8499.765625,8499.765625,53.5505422952845,5.64940160765676,6.2258472442627,54,1,0,0,1,0.302352905273438,34.2131004333496,1,1,3,300.377777099609,0,300.361785888672,,,,,,,,,,,,,,,,,,,,,,,,,,,,,,,,,
,3883337671.76281,300.299224853516,7499.62939453125,6.03149784524564E-5,1.39957190786403E-8,1,4,13.4005146026611,4.99423152173804,30.7100005447865,0.0748685480310312,0.0110565659928409,1,-1.1295497847026E-7,,,,,,,,,,,,,,,,,,,,,300.289855957031,300.30859375,7499.62939453125,7499.62939453125,53.6693498302076,5.64850764164341,6.20006704330444,54,1,0,0,1,0.30242919921875,33.7243423461914,1,1,3,300.289855957031,0,300.299224853516,,,,,,,,,,,,,,,,,,,,,,,,,,,,,,,,,
,3883337713.1548,300.217102050781,6499.8193359375,7.57057401952316E-5,1.33835353058343E-8,1,4,13.4005146026611,4.99431327910751,30.7100005447865,0.0939728279050683,0.0138937090640562,1,-1.29298899346903E-7,,,,,,,,,,,,,,,,,,,,,300.21142578125,300.222778320313,6499.8193359375,6499.8193359375,53.5630483515922,5.64781981750554,6.17442178726196,52,1,68,0,0,0.303573608398438,34.2131004333496,1,1,3,300.21142578125,0,300.217102050781,,,,,,,,,,,,,,,,,,,,,,,,,,,,,,,,,
,3883337754.91624,300.183731079102,5499.67041015625,9.04285970409065E-5,1.14637368930154E-8,1,4,13.4005146026611,4.99441795982513,30.7199992239475,0.112248288022062,0.0166174304393477,1,-1.37314536392898E-7,,,,,,,,,,,,,,,,,,,,,300.179779052734,300.187683105469,5499.67041015625,5499.67041015625,53.6513723742653,5.64701187825696,6.15196704864502,52,1,68,0,0,0.300445556640625,34.2131004333496,1,1,3,300.179779052734,0,300.183731079102,,,,,,,,,,,,,,,,,,,,,,,,,,,,,,,,,
,3883337796.23252,300.20378112793,4499.5205078125,0.000104160202067413,1.18664383663652E-8,1,4,13.4005146026611,4.99426920179238,30.7100005447865,0.12928792318163,0.0191393320609956,1,-1.58698247043786E-7,,,,,,,,,,,,,,,,,,,,,300.199951171875,300.207611083984,4499.5205078125,4499.5205078125,53.562266723073,5.6473757725871,6.13376998901367,52,1,68,0,0,0.30120849609375,34.2131004333496,1,1,3,300.199951171875,0,300.20378112793,,,,,,,,,,,,,,,,,,,,,,,,,,,,,,,,,
,3883337838.61392,300.249130249023,3499.484375,0.000115826761928506,1.14874516782755E-8,1,4,13.4005146026611,4.99443361453822,30.7100005447865,0.143773187103041,0.0212999370131828,1,-1.63657344140089E-7,,,,,,,,,,,,,,,,,,,,,300.230926513672,300.267333984375,3499.484375,3499.484375,53.6060379201499,5.64682680814002,6.11645984649658,54,1,0,0,1,0.302505493164063,34.2131004333496,1,1,3,300.267333984375,0,300.249130249023,,,,,,,,,,,,,,,,,,,,,,,,,,,,,,,,,
,3883337900.31626,300.306838989258,2709.53369140625,0.000122209604712593,8.47061404300636E-9,1,4,13.4005146026611,4.99438071774247,30.7100005447865,0.151690345888387,0.0224965827970595,1,-1.53975115841052E-7,,,,,,,,,,,,,,,,,,,,,300.296539306641,300.317138671875,2709.53369140625,2709.53369140625,53.5153690119191,5.64697166911663,6.09096097946167,54,1,0,0,1,0.30029296875,33.7243423461914,1,1,3,300.296539306641,0,300.306838989258,,,,,,,,,,,,,,,,,,,,,,,,,,,,,,,,,
,3883337939.66916,300.272506713867,2129.66821289062,0.000123700148038568,9.86701518603472E-9,1,4,13.4005146026611,4.99446226464378,30.7100005447865,0.153541111305755,0.0227905688799936,1,-1.40476159432645E-7,,,,,,,,,,,,,,,,,,,,,300.254486083984,300.29052734375,2129.66821289062,2129.66821289062,53.6146358338614,5.6464816753369,6.07426404953003,54,1,0,0,1,0.301055908203125,33.7243423461914,1,1,3,300.29052734375,0,300.272506713867,,,,,,,,,,,,,,,,,,,,,,,,,,,,,,,,,
,3883337991.33997,300.358291625977,1549.62670898438,0.000120211806609667,1.01337775430125E-8,1,4,13.4005146026611,4.99424264611449,30.7100005447865,0.149199743358651,0.0221620300634376,1,-1.24009070808887E-7,,,,,,,,,,,,,,,,,,,,,300.348693847656,300.367889404297,1549.62670898438,1549.62670898438,53.5614850945537,5.64740796019073,6.05840873718262,54,1,0,0,1,0.303192138671875,33.2355842590332,1,1,3,300.367889404297,0,300.358291625977,,,,,,,,,,,,,,,,,,,,,,,,,,,,,,,,,
,3883338031.33314,300.398880004883,969.824340820312,0.000107378449002996,1.24861645844027E-8,1,4,13.4005146026611,4.99420061071115,30.7100005447865,0.133273267172798,0.0197751719291044,1,-1.27443467118858E-7,,,,,,,,,,,,,,,,,,,,,300.378265380859,300.419494628906,969.824340820312,969.824340820312,53.5403811245345,5.64725637538807,6.04237985610962,54,1,0,0,1,0.3021240234375,34.2131004333496,1,1,3,300.420471191406,0,300.398880004883,,,,,,,,,,,,,,,,,,,,,,,,,,,,,,,,,
,3883338071.52014,300.33122253418,389.694610595703,7.33895182827839E-5,1.02063198612154E-8,1,4,13.4005146026611,4.99404438890624,30.7199992239475,0.0910829249707081,0.0135206114989133,1,-8.26337039243678E-8,,,,,,,,,,,,,,,,,,,,,300.324645996094,300.337799072266,389.694610595703,389.694610595703,53.5763360364191,5.64836643739781,6.03544521331787,54,1,0,0,1,0.300369262695313,34.2131004333496,1,1,3,300.324645996094,0,300.33122253418,,,,,,,,,,,,,,,,,,,,,,,,,,,,,,,,,
,3883338111.81941,300.186416625977,-190.472885131836,-3.00866175155153E-5,1.20045313217929E-8,1,4,13.4005146026611,4.9942113270331,30.7100005447865,-0.03734065427433,-0.0055515961240539,1,2.70635877542735E-8,,,,,,,,,,,,,,,,,,,,,300.180694580078,300.192138671875,-190.472885131836,-190.472885131836,53.5177138974768,5.64738783184746,6.02660417556763,54,1,0,0,1,0.301895141601562,33.7243423461914,1,1,3,300.192138671875,0,300.186416625977,,,,,,,,,,,,,,,,,,,,,,,,,,,,,,,,,
,3883338149.56558,300.31787109375,-770.111694335938,-9.32188687108313E-5,2.30396938579157E-8,1,4,13.4005146026611,4.99433175920922,30.7100005447865,-0.115709635824962,-0.0171257305585003,1,1.44802536154573E-7,,,,,,,,,,,,,,,,,,,,,300.306182861328,300.329559326172,-770.111694335938,-770.111694335938,53.5892329069864,5.64696192807348,6.00951671600342,54,1,0,0,1,0.302734375,33.7243423461914,1,1,3,300.329559326172,0,300.31787109375,,,,,,,,,,,,,,,,,,,,,,,,,,,,,,,,,
,3883338188.20949,300.264419555664,-1350.10290527344,-0.000114758567507832,6.29199898618579E-8,1,4,13.4005146026611,4.99423494438348,30.7199992239475,-0.142428643399324,-0.0211737234275195,1,1.04613188007365E-7,,,,,,,,,,,,,,,,,,,,,300.253814697266,300.275024414063,-1350.10290527344,-1350.10290527344,53.628314332948,5.64812651618466,6.00083017349243,54,1,0,0,1,0.301055908203125,33.7243423461914,1,1,3,300.275024414063,0,300.264419555664,,,,,,,,,,,,,,,,,,,,,,,,,,,,,,,,,
,3883338226.78459,300.392486572266,-1930.2578125,-0.000121879977325622,2.80248045069172E-8,1,4,13.4005146026611,4.99425543013846,30.7199992239475,-0.1512766029928,-0.0224303252232426,1,1.57420348704267E-7,,,,,,,,,,,,,,,,,,,,,300.384704589844,300.400268554687,-1930.2578125,-1930.2578125,53.4825406141114,5.64777928633057,5.99058198928833,54,1,0,0,1,0.301437377929687,34.2131004333496,1,1,3,300.400268554687,0,300.392486572266,,,,,,,,,,,,,,,,,,,,,,,,,,,,,,,,,
,3883338277.10787,300.36506652832,-2510.37475585938,-0.000122189381651816,1.31497295855315E-8,1,4,13.4005146026611,4.99415002774279,30.7100005447865,-0.151654383456574,-0.0224984109868154,1,1.48303652666263E-7,,,,,,,,,,,,,,,,,,,,,300.362213134766,300.367919921875,-2510.37475585938,-2510.37475585938,53.5818074360538,5.64816995389264,5.98808431625366,54,1,0,0,1,0.301513671875,33.7243423461914,1,1,3,300.362213134766,0,300.36506652832,,,,,,,,,,,,,,,,,,,,,,,,,,,,,,,,,
,3883338388.44747,300.19287109375,-3000.19653320313,-0.000119502724915038,1.08524998423816E-8,1,4,13.4005146026611,4.99410797419896,30.7100005447865,-0.148320497963721,-0.0219875095269258,1,1.57900259449929E-7,,,,,,,,,,,,,,,,,,,,,300.191253662109,300.194488525391,-3000.19653320313,-3000.19653320313,53.5395994960153,5.64823862812835,5.96360492706299,54,1,0,0,1,0.300827026367188,33.7243423461914,1,1,3,300.191253662109,0,300.19287109375,,,,,,,,,,,,,,,,,,,,,,,,,,,,,,,,,
,3883338430.42807,300.242034912109,-4000.14453125,-0.000109606137212258,9.64862453544149E-9,1,4,13.4005146026611,4.99397343808119,30.7100005447865,-0.136024870873846,-0.0202151205677347,1,1.05123711459376E-7,,,,,,,,,,,,,,,,,,,,,300.241851806641,300.242218017578,-4000.14453125,-4000.14453125,53.5395994960153,5.64836242325575,5.952232837677,54,1,0,0,1,0.301055908203125,33.7243423461914,1,1,3,300.241851806641,0,300.242034912109,,,,,,,,,,,,,,,,,,,,,,,,,,,,,,,,,
,3883338470.35117,300.200225830078,-5000.1181640625,-9.67063824642805E-5,1.14079579726791E-8,1,4,13.4005146026611,4.99415173747037,30.7100005447865,-0.120020385175223,-0.0178466320714783,1,8.48739006919288E-8,,,,,,,,,,,,,,,,,,,,,300.192993164063,300.207458496094,-5000.1181640625,-5000.1181640625,53.6087736199672,5.64809036548073,5.94700336456299,54,1,0,0,1,0.301132202148438,33.7243423461914,1,1,3,300.192993164063,0,300.200225830078,,,,,,,,,,,,,,,,,,,,,,,,,,,,,,,,,
,3883338510.52836,300.309524536133,-6000.04052734375,-8.23778298964276E-5,1.33564235143345E-8,1,4,13.4005146026611,4.99423232873813,30.7100005447865,-0.102239190360846,-0.0152068758436614,1,6.89495713554854E-8,,,,,,,,,,,,,,,,,,,,,300.283477783203,300.335571289063,-6000.04052734375,-6000.04052734375,53.5864972071691,5.6478786765039,5.94064617156982,53,1,68,0,0,0.302352905273438,33.7243423461914,1,1,3,300.335571289063,0,300.309524536133,,,,,,,,,,,,,,,,,,,,,,,,,,,,,,,,,
,3883338562.9112,300.450927734375,-6999.63623046875,-6.73729395970633E-5,1.60401485804618E-8,1,4,13.4005146026611,4.99411249814525,30.7100005447865,-0.0836187212083044,-0.0124036622080332,1,8.29083002101354E-8,,,,,,,,,,,,,,,,,,,,,300.4462890625,300.45556640625,-6999.63623046875,-6999.63623046875,53.6584070309384,5.64809640652498,5.93441390991211,54,1,0,0,1,0.30059814453125,33.7243423461914,1,1,3,300.4462890625,0,300.450927734375,,,,,,,,,,,,,,,,,,,,,,,,,,,,,,,,,
,3883338615.40198,300.325180053711,-8000.1376953125,-5.1833862340232E-5,1.94165215118333E-8,1,4,13.4005146026611,4.99407595507909,30.7100005447865,-0.06432460945326,-0.00959224428763672,1,2.39001370760795E-8,,,,,,,,,,,,,,,,,,,,,300.311462402344,300.338897705078,-8000.1376953125,-8000.1376953125,53.5020813270922,5.64847080130759,5.92461585998535,53,1,68,0,0,0.300369262695313,33.7243423461914,1,1,3,300.311462402344,0,300.325180053711,,,,,,,,,,,,,,,,,,,,,,,,,,,,,,,,,
,3883338655.26874,300.170837402344,-8999.8466796875,-3.60900253302101E-5,1.57521416943096E-8,1,4,13.4005146026611,4.99410358259266,30.7199992239475,-0.0447822040216408,-0.00671233478911483,1,-1.03989659483416E-8,,,,,,,,,,,,,,,,,,,,,300.166015625,300.175659179687,-8999.8466796875,-8999.8466796875,53.6095552484864,5.6481738642085,5.9125828742981,52,1,68,0,0,0.300674438476562,33.2355842590332,1,1,3,300.166015625,0,300.170837402344,,,,,,,,,,,,,,,,,,,,,,,,,,,,,,,,,
,3883338695.7116,300.072235107422,-9999.984375,-2.01675624802673E-5,1.61913937958677E-8,1,4,13.4005146026611,4.99418530811201,30.7100005447865,-0.0250208562388684,-0.00378163475535613,1,-3.04790593294326E-8,,,,,,,,,,,,,,,,,,,,,300.052001953125,300.092468261719,-9999.984375,-9999.984375,53.613072576823,5.64776023713908,5.91162919998169,52,1,68,0,0,0.300369262695313,34.2131004333496,1,1,3,300.092468261719,0,300.072235107422,,,,,,,,,,,,,,,,,,,,,,,,,,,,,,,,,
,3883338735.67956,300.31803894043,-10999.78125,-4.05009924005126E-6,1.94411424900384E-8,1,4,13.4005146026611,4.99407679136743,30.7100005447865,-0.00501766412273001,-0.000805756207291584,1,-4.34667605954177E-8,,,,,,,,,,,,,,,,,,,,,300.293609619141,300.342468261719,-10999.78125,-10999.78125,53.5857155786499,5.64728930315448,5.90481281280518,52,1,68,0,0,0.301284790039063,34.2131004333496,1,1,3,300.342468261719,0,300.31803894043,,,,,,,,,,,,,,,,,,,,,,,,,,,,,,,,,
,3883338792.91012,300.342742919922,-11999.830078125,1.21307138060654E-5,2.25149196332501E-8,1,4,13.4005146026611,4.9939232015078,30.7199992239475,0.015066298347233,0.00215780389526103,1,-7.56906215734653E-8,,,,,,,,,,,,,,,,,,,,,300.336151123047,300.349334716797,-11999.830078125,-11999.830078125,53.5341280963807,5.64876027264089,5.90186786651611,54,1,0,0,1,0.302276611328125,33.7243423461914,1,1,3,300.336151123047,0,300.342742919922,,,,,,,,,,,,,,,,,,,,,,,,,,,,,,,,,
,3883338832.50569,300.201568603516,-12999.94140625,2.84125466320806E-5,2.05403284307001E-8,1,4,13.4005146026611,4.99399146294304,30.7100005447865,0.0352723590276532,0.00516498123935366,1,-8.79267014848999E-8,,,,,,,,,,,,,,,,,,,,,300.195068359375,300.208068847656,-12999.94140625,-12999.94140625,53.5325648393422,5.64772969576163,5.89872312545776,52,1,68,0,0,0.301971435546875,33.7243423461914,1,1,3,300.195068359375,0,300.201568603516,,,,,,,,,,,,,,,,,,,,,,,,,,,,,,,,,
,3883338873.69028,300.286911010742,-13999.775390625,4.47381352092564E-5,2.06146144750746E-8,1,4,13.4005146026611,4.99388452026969,30.7199992239475,0.0555329785189513,0.00816516508643152,1,-1.12113676943366E-7,,,,,,,,,,,,,,,,,,,,,300.266265869141,300.307556152344,-13999.775390625,-13999.775390625,53.6048654773711,5.64816404931253,5.89069366455078,54,1,0,0,1,0.302047729492188,33.2355842590332,1,1,3,300.307556152344,0,300.286911010742,,,,,,,,,,,,,,,,,,,,,,,,,,,,,,,,,
,3883338935.90086,300.305480957031,-14999.6240234375,6.11274056461199E-5,1.66442999605056E-8,1,4,13.4005146026611,4.993968950443,30.7199992239475,0.0758676236129207,0.0112300476808826,1,-9.4024532491391E-8,,,,,,,,,,,,,,,,,,,,,300.302337646484,300.308624267578,-14999.6240234375,-14999.6240234375,53.5767268506787,5.64784182278286,5.87953186035156,54,1,0,0,1,0.301284790039063,33.7243423461914,1,1,3,300.302337646484,0,300.305480957031,,,,,,,,,,,,,,,,,,,,,,,,,,,,,,,,,
,3883339023.48064,300.162002563477,-24999.64453125,0.000226520255945676,2.99849499131924E-8,1,4,13.4005146026611,4.99386910286449,30.7100005447865,0.281114152779538,0.0417555377573346,1,-2.34440691405559E-7,,,,,,,,,,,,,,,,,,,,,300.160247802734,300.163757324219,-24999.64453125,-24999.64453125,53.4801957285537,5.64832104376062,5.86863422393799,54,1,0,0,1,0.302734375,33.7243423461914,1,1,3,300.160034179687,0,300.162002563477,,,,,,,,,,,,,,,,,,,,,,,,,,,,,,,,,
,3883339123.98455,300.160949707031,-34999.640625,0.000392885435951482,4.25902549206711E-8,1,4,13.4005146026611,4.99383371120723,30.7100005447865,0.487533334732613,0.0726691138141476,1,-2.07217444550788E-7,,,,,,,,,,,,,,,,,,,,,300.14892578125,300.172973632812,-34999.640625,-34999.640625,53.447367330746,5.64821757945437,5.86152410507202,54,1,0,0,1,0.3021240234375,33.7243423461914,1,1,3,300.172973632812,0,300.160949707031,,,,,,,,,,,,,,,,,,,,,,,,,,,,,,,,,
,3883339211.61533,300.156768798828,-44999.5625,0.000559536545524836,5.62655732069587E-8,1,4,13.4005146026611,4.99403665399786,30.7199992239475,0.694344187859741,0.103678370905525,1,-1.50746173594851E-7,,,,,,,,,,,,,,,,,,,,,300.154663085937,300.158874511719,-44999.5625,-44999.5625,53.4254817322076,5.64741351924575,5.85735321044922,54,1,0,0,1,0.3021240234375,33.2355842590332,1,1,3,300.154663085937,0,300.156768798828,,,,,,,,,,,,,,,,,,,,,,,,,,,,,,,,,
,3883339299.15922,300.123199462891,-54999.64453125,0.000726334262725854,7.88750164726035E-8,1,4,13.4005146026611,4.99401895652933,30.7100005447865,0.901298873052034,0.134749217075497,1,-6.2700037961907E-8,,,,,,,,,,,,,,,,,,,,,300.101776123047,300.144622802734,-54999.64453125,-54999.64453125,53.3156629252556,5.64719480491684,5.84812068939209,53,1,68,0,0,0.29998779296875,33.7243423461914,1,1,3,300.144622802734,0,300.123199462891,,,,,,,,,,,,,,,,,,,,,,,,,,,,,,,,,
,3883339412.98833,300.064453125,-64999.6171875,0.000893319205620134,1.2584154596548E-7,1,4,13.4005146026611,4.99375574626794,30.7100005447865,1.10841687759016,0.165780312045118,1,-2.52468176886499E-8,,,,,,,,,,,,,,,,,,,,,300.057922363281,300.070983886719,-64999.6171875,-64999.6171875,53.2969038407941,5.6485671886249,5.8393087387085,53,1,68,0,0,0.302047729492188,33.7243423461914,1,1,3,300.070983886719,0,300.064453125,,,,,,,,,,,,,,,,,,,,,,,,,,,,,,,,,
,3883339513.69602,300.155776977539,-64999.6171875,0.000893019546851321,2.069641996116E-7,1,4,13.4005146026611,4.99390274658209,30.7199992239475,1.10805331345503,0.165981845811085,1,1.76489240543635E-7,,,,,,,,,,,,,,,,,,,,,300.151062011719,300.160491943359,-64999.6171875,-64999.6171875,53.2640754429864,5.64716549882324,5.82755327224731,54,1,0,0,1,0.301742553710937,33.7243423461914,1,1,3,300.151062011719,0,300.155776977539,,,,,,,,,,,,,,,,,,,,,,,,,,,,,,,,,
,3883339601.68777,299.998489379883,-54999.58203125,0.000725996085359575,1.40783042434759E-7,1,4,13.4005146026611,4.99383405042646,30.7100005447865,0.900822541268394,0.134746115545803,1,-8.97778913869061E-9,,,,,,,,,,,,,,,,,,,,,299.9912109375,300.005767822266,-54999.58203125,-54999.58203125,53.355916793996,5.64764544554309,5.82703161239624,54,1,0,0,1,0.303955078125,33.7243423461914,1,1,3,300.005767822266,0,299.998489379883,,,,,,,,,,,,,,,,,,,,,,,,,,,,,,,,,
,3883339689.47597,300.079971313477,-44999.63671875,0.000559122125690538,6.49887701627043E-8,1,4,13.4005146026611,4.99390181096912,30.7100005447865,0.693781150145917,0.103748269537957,1,-2.92590165902321E-8,,,,,,,,,,,,,,,,,,,,,300.055450439453,300.1044921875,-44999.63671875,-44999.63671875,53.3105823398806,5.64733492136884,5.81864976882935,54,1,0,0,1,0.301284790039063,33.7243423461914,1,1,3,300.1044921875,0,300.079971313477,,,,,,,,,,,,,,,,,,,,,,,,,,,,,,,,,
,3883339777.50447,300.1123046875,-34999.75390625,0.000392432938969767,3.22317987296565E-8,1,4,13.4005146026611,4.9939108697708,30.7100005447865,0.486968820530405,0.0726775605208453,1,-1.33986994134521E-7,,,,,,,,,,,,,,,,,,,,,300.085754394531,300.138854980469,-34999.75390625,-34999.75390625,53.3652963362268,5.6477744080515,5.81434154510498,54,1,0,0,1,0.302963256835937,33.7243423461914,1,1,3,300.138854980469,0,300.1123046875,,,,,,,,,,,,,,,,,,,,,,,,,,,,,,,,,
,3883339877.73208,300.140365600586,-24999.744140625,0.000226026948165333,3.17863311364794E-8,1,4,13.4005146026611,4.99393040316813,30.7100005447865,0.280478574552839,0.0418538389147012,1,-8.20020957335741E-8,,,,,,,,,,,,,,,,,,,,,300.134796142578,300.145935058594,-24999.744140625,-24999.744140625,53.6185439764576,5.64765019842383,5.80866289138794,54,1,0,0,1,0.302658081054687,33.7243423461914,1,1,3,300.134796142578,0,300.140365600586,,,,,,,,,,,,,,,,,,,,,,,,,,,,,,,,,
,3883339964.00471,300.169082641602,-14999.673828125,6.05122446632026E-5,2.55515269477748E-8,1,4,13.4005146026611,4.99380211313683,30.7100005447865,0.0750838001254374,0.0112288719977123,1,-2.52419858009996E-9,,,,,,,,,,,,,,,,,,,,,300.163818359375,300.174346923828,-14999.673828125,-14999.673828125,53.5493698525057,5.64838743915134,5.79943943023682,54,1,0,0,1,0.302810668945313,33.7243423461914,1,1,3,300.174346923828,0,300.169082641602,,,,,,,,,,,,,,,,,,,,,,,,,,,,,,,,,
,3883340028.53937,300.407257080078,-14000.1279296875,4.41252962578182E-5,1.82122804196319E-8,1,4,13.4005146026611,4.99375467041559,30.7100005447865,0.0547494751070169,0.00819205066654765,1,1.47125993771273E-9,,,,,,,,,,,,,,,,,,,,,300.405822753906,300.40869140625,-14000.1279296875,-14000.1279296875,53.5329556536018,5.64849797048809,5.80607414245606,53,1,68,0,0,0.304183959960937,33.7243423461914,1,1,3,300.40869140625,0,300.407257080078,,,,,,,,,,,,,,,,,,,,,,,,,,,,,,,,,
,3883340070.24532,300.281478881836,-13000.3310546875,2.77621399922851E-5,2.03862205440058E-8,1,4,13.4005146026611,4.99372300905746,30.7199992239475,0.0344433219891499,0.00517340084121952,1,1.64693894934993E-8,,,,,,,,,,,,,,,,,,,,,300.261016845703,300.301940917969,-13000.3310546875,-13000.3310546875,53.450493844823,5.64827138394091,5.8024582862854,54,1,0,0,1,0.301895141601562,33.7243423461914,1,1,3,300.301940917969,0,300.281478881836,,,,,,,,,,,,,,,,,,,,,,,,,,,,,,,,,
,3883340111.40636,300.358703613281,-12000.294921875,1.14873735474227E-5,1.86748023911795E-8,1,4,13.4005146026611,4.99380934132642,30.7100005447865,0.0142476787375918,0.00217123394909981,1,3.14283838466939E-8,,,,,,,,,,,,,,,,,,,,,300.342956542969,300.374450683594,-12000.294921875,-12000.294921875,53.6033022203326,5.64878125036778,5.79704427719116,54,1,0,0,1,0.300979614257812,34.2131004333496,1,1,3,300.374450683594,0,300.358703613281,,,,,,,,,,,,,,,,,,,,,,,,,,,,,,,,,
,3883340169.33511,300.396865844727,-11000.435546875,-4.76434150481046E-6,1.26075935610422E-8,1,4,13.4005146026611,4.99393651900232,30.7100005447865,-0.00592249894351389,-0.000812830004053657,1,5.76531322703028E-8,,,,,,,,,,,,,,,,,,,,,300.384338378906,300.409393310547,-11000.435546875,-11000.435546875,53.4985639987557,5.64863761544029,5.79661703109741,54,1,0,0,1,0.302200317382812,34.2131004333496,1,1,3,300.409393310547,0,300.396865844727,,,,,,,,,,,,,,,,,,,,,,,,,,,,,,,,,
,3883340286.44056,300.180358886719,-10000.2861328125,-2.08821716677709E-5,1.4657723436432E-8,1,4,13.4005146026611,4.9939562380598,30.7100005447865,-0.0259236705211508,-0.00379572248837933,1,6.48729633369781E-8,,,,,,,,,,,,,,,,,,,,,300.158874511719,300.201843261719,-10000.2861328125,-10000.2861328125,53.5857155786499,5.64786792849817,5.78630828857422,54,1,0,0,1,0.301589965820313,33.7243423461914,1,1,3,300.201843261719,0,300.180358886719,,,,,,,,,,,,,,,,,,,,,,,,,,,,,,,,,
,3883340325.94848,300.190048217773,-9000.3505859375,-3.6822522308661E-5,1.45892281017517E-8,1,4,13.4005146026611,4.99403784479548,30.7100005447865,-0.0457104444183247,-0.00671363877022802,1,9.8027474585424E-8,,,,,,,,,,,,,,,,,,,,,300.186737060547,300.193359375,-9000.3505859375,-9000.3505859375,53.6388663179576,5.6478296239903,5.79498147964478,54,1,0,0,1,0.301513671875,33.7243423461914,1,1,3,300.186737060547,0,300.190048217773,,,,,,,,,,,,,,,,,,,,,,,,,,,,,,,,,
,3883340367.88608,300.245574951172,-8000.32666015625,-5.25801409590665E-5,1.75653251341595E-8,1,4,13.4005146026611,4.9940963637084,30.7100005447865,-0.0652676166908541,-0.00961997596986004,1,1.13234999619546E-7,,,,,,,,,,,,,,,,,,,,,300.239562988281,300.251586914063,-8000.32666015625,-8000.32666015625,53.6161990908999,5.64694722538244,5.78777599334717,54,1,0,0,1,0.302047729492188,33.7243423461914,1,1,3,300.251586914063,0,300.245574951172,,,,,,,,,,,,,,,,,,,,,,,,,,,,,,,,,
,3883340409.857,300.169815063477,-7000.31591796875,-6.81128692670566E-5,1.22832258402604E-8,1,4,13.4005146026611,4.99409595984427,30.7100005447865,-0.0845430008109972,-0.0124975723010887,1,1.17871711111602E-7,,,,,,,,,,,,,,,,,,,,,300.168212890625,300.171417236328,-7000.31591796875,-7000.31591796875,53.597830820698,5.64667797285545,5.78512191772461,54,1,0,0,1,0.30120849609375,33.7243423461914,1,1,3,300.168212890625,0,300.169815063477,,,,,,,,,,,,,,,,,,,,,,,,,,,,,,,,,
,3883340451.0738,300.21354675293,-6000.50634765625,-8.32065121209284E-5,1.24994062678303E-8,1,4,13.4005146026611,4.99389037670761,30.7100005447865,-0.10327068775285,-0.015271984217522,1,1.39268107671317E-7,,,,,,,,,,,,,,,,,,,,,300.206604003906,300.220489501953,-6000.50634765625,-6000.50634765625,53.6189347907172,5.64773168949382,5.78936767578125,54,1,0,0,1,0.301055908203125,34.2131004333496,1,1,3,300.220489501953,0,300.21354675293,,,,,,,,,,,,,,,,,,,,,,,,,,,,,,,,,
,3883340490.9677,300.199447631836,-5000.2685546875,-9.74909400881489E-5,1.09600681628142E-8,1,4,13.4005146026611,4.99426649732326,30.7100005447865,-0.121006994706442,-0.017931727714341,1,1.34129224510175E-7,,,,,,,,,,,,,,,,,,,,,300.185394287109,300.213500976562,-5000.2685546875,-5000.2685546875,53.4243092894287,5.64528272952842,5.78282356262207,54,1,0,0,1,0.301971435546875,34.2131004333496,1,1,3,300.213500976562,0,300.199447631836,,,,,,,,,,,,,,,,,,,,,,,,,,,,,,,,,
,3883340532.40862,300.194030761719,-4000.28295898438,-0.000110379580406962,1.58302078244815E-8,1,4,13.4005146026611,4.99419152302904,30.7199992239475,-0.136999710609748,-0.0203149551215296,1,1.41371261395397E-7,,,,,,,,,,,,,,,,,,,,,300.173553466797,300.214508056641,-4000.28295898438,-4000.28295898438,53.5345189106403,5.6450341441913,5.78520393371582,53,1,68,0,0,0.302276611328125,33.7243423461914,1,1,3,300.216156005859,0,300.194030761719,,,,,,,,,,,,,,,,,,,,,,,,,,,,,,,,,
,3883340572.89768,300.342666625977,-3000.2216796875,-0.000120416737766966,5.59041073071637E-8,1,4,13.4005146026611,4.99423396581115,30.7100005447865,-0.149460288664267,-0.0221558992661886,1,1.59562452151568E-7,,,,,,,,,,,,,,,,,,,,,300.333831787109,300.351501464844,-3000.2216796875,-3000.2216796875,53.6412112035153,5.64528870000302,5.78435945510864,52,1,68,0,0,0.301513671875,34.2131004333496,1,1,3,300.351501464844,0,300.342666625977,,,,,,,,,,,,,,,,,,,,,,,,,,,,,,,,,
,3883340698.3586,300.163848876953,-2510.37475585938,-0.000123147374171656,1.4692321910365E-8,1,4,13.4005146026611,4.99385420535263,30.7100005447865,-0.152830001597023,-0.0226776314282423,1,1.45671108630322E-7,,,,,,,,,,,,,,,,,,,,,300.153503417969,300.174194335937,-2510.37475585938,-2510.37475585938,53.6560621453807,5.64637016599819,5.77133369445801,54,1,0,0,1,0.30120849609375,33.7243423461914,1,1,3,300.174194335937,0,300.163848876953,,,,,,,,,,,,,,,,,,,,,,,,,,,,,,,,,
,3883340738.43859,300.182281494141,-1930.18225097656,-0.000123228698130871,1.31433981047414E-8,1,4,13.4005146026611,4.99381972267026,30.7100005447865,-0.152931006034017,-0.0226819729839604,1,1.54160890986052E-7,,,,,,,,,,,,,,,,,,,,,300.167144775391,300.197418212891,-1930.18225097656,-1930.18225097656,53.5935318638422,5.64726175163298,5.77569007873535,54,1,0,0,1,0.30242919921875,33.7243423461914,1,1,3,300.197418212891,0,300.182281494141,,,,,,,,,,,,,,,,,,,,,,,,,,,,,,,,,
,3883340778.69627,300.35205078125,-1350.20361328125,-0.000117256342092911,1.38268399233931E-8,1,4,13.4005146026611,4.9938697557185,30.7199992239475,-0.145521470872231,-0.0215808445148375,1,1.48410314331506E-7,,,,,,,,,,,,,,,,,,,,,300.348571777344,300.355529785156,-1350.20361328125,-1350.20361328125,53.6036930345922,5.64661778266705,5.77626085281372,54,1,0,0,1,0.30120849609375,33.7243423461914,1,1,3,300.355529785156,0,300.35205078125,,,,,,,,,,,,,,,,,,,,,,,,,,,,,,,,,
,3883340817.73868,300.253875732422,-770.388610839844,-9.91845265202065E-5,1.34245685329964E-8,1,4,13.4005146026611,4.99374716661834,30.7100005447865,-0.123089182295274,-0.0182538185543185,1,1.2578610059586E-7,,,,,,,,,,,,,,,,,,,,,300.24853515625,300.259216308594,-770.388610839844,-770.388610839844,53.4751151431787,5.64696026317361,5.7791862487793,54,1,0,0,1,0.302581787109375,33.2355842590332,1,1,3,300.259216308594,0,300.253875732422,,,,,,,,,,,,,,,,,,,,,,,,,,,,,,,,,
,3883340867.93368,300.399215698242,-190.460296630859,-5.03761072185213E-5,6.83896639131347E-9,1,4,13.4005146026611,4.99410224344491,30.7100005447865,-0.0625269492650474,-0.00924955482106638,1,8.20479489393861E-8,,,,,,,,,,,,,,,,,,,,,300.396453857422,300.401977539063,-190.460296630859,-190.460296630859,53.6017389632941,5.64607267269594,5.77626180648804,54,1,0,0,1,0.301132202148438,33.7243423461914,1,1,3,300.396453857422,0,300.399215698242,,,,,,,,,,,,,,,,,,,,,,,,,,,,,,,,,
,3883340907.50295,300.206665039063,389.719787597656,6.0692387619292E-5,2.00795343896945E-8,1,4,13.4005146026611,4.99382022238127,30.7199992239475,0.0753113132420473,0.0112382348288865,1,-2.19726581317532E-8,,,,,,,,,,,,,,,,,,,,,300.199249267578,300.214080810547,389.719787597656,389.719787597656,53.6455101603711,5.64743092297876,5.77211904525757,54,1,0,0,1,0.300521850585937,33.7243423461914,1,1,3,300.199249267578,0,300.206665039063,,,,,,,,,,,,,,,,,,,,,,,,,,,,,,,,,
,3883340946.94767,300.11360168457,969.572570800781,0.000103205979811408,2.18163026744584E-8,1,4,13.4005146026611,4.99397423581568,30.7199992239475,0.128091582248257,0.0189712687748465,1,-1.50117853130922E-7,,,,,,,,,,,,,,,,,,,,,300.098022460937,300.129180908203,969.572570800781,969.572570800781,53.4907477135634,5.64767674405875,5.77322673797607,54,1,0,0,1,0.30120849609375,33.7243423461914,1,1,3,300.129180908203,0,300.11360168457,,,,,,,,,,,,,,,,,,,,,,,,,,,,,,,,,
,3883340986.52898,300.185653686523,1549.67712402344,0.00011832131148216,2.41262924015855E-8,1,4,13.4005146026611,4.9938568404476,30.7100005447865,0.146838675791746,0.0218031614533068,1,-1.28490032570251E-7,,,,,,,,,,,,,,,,,,,,,300.160736083984,300.210571289063,1549.67712402344,1549.67712402344,53.5255301826691,5.64773228804592,5.77450799942017,54,1,0,0,1,0.301513671875,33.7243423461914,1,1,3,300.210571289063,0,300.185653686523,,,,,,,,,,,,,,,,,,,,,,,,,,,,,,,,,
,3883341025.99472,300.215393066406,2129.78149414062,0.000122614015247552,6.3470049348008E-8,1,4,13.4005146026611,4.99406630325641,30.7100005447865,0.152184641793533,0.0225306010701314,1,-1.85459267855189E-7,,,,,,,,,,,,,,,,,,,,,300.21533203125,300.215454101562,2129.78149414062,2129.78149414062,53.6259694473903,5.64618352788786,5.76895999908447,54,1,0,0,1,0.3009033203125,33.7243423461914,1,1,3,300.21533203125,0,300.215393066406,,,,,,,,,,,,,,,,,,,,,,,,,,,,,,,,,
,3883341066.55054,300.130462646484,2709.54638671875,0.000121315507395633,1.1946045641321E-8,1,4,13.4005146026611,4.99385851241215,30.7100005447865,0.150552225612462,0.0223707357233082,1,-1.18991114475061E-7,,,,,,,,,,,,,,,,,,,,,300.125671386719,300.13525390625,2709.54638671875,2709.54638671875,53.6552805168614,5.64681436119578,5.76641416549683,54,1,0,0,1,0.302276611328125,33.7243423461914,1,1,3,300.125671386719,0,300.130462646484,,,,,,,,,,,,,,,,,,,,,,,,,,,,,,,,,
,3883341128.68173,300.316421508789,3499.7236328125,0.000115116343181374,8.32754053524719E-9,1,4,13.4005146026611,4.9939743732331,30.7100005447865,0.142866460619073,0.0212099857030695,1,-1.27663506191697E-7,,,,,,,,,,,,,,,,,,,,,300.315490722656,300.317352294922,3499.7236328125,3499.7236328125,53.6072103629288,5.64613593555486,5.76217889785767,54,1,0,0,1,0.300674438476562,34.2131004333496,1,1,3,300.315490722656,0,300.316421508789,,,,,,,,,,,,,,,,,,,,,,,,,,,,,,,,,
,3883341169.26045,300.336334228516,4499.873046875,0.000103426576037832,7.91413865998379E-9,1,4,13.4005146026611,4.99386296819632,30.7199992239475,0.128348708290688,0.0190958219492872,1,-8.22605091247195E-8,,,,,,,,,,,,,,,,,,,,,300.332489013672,300.340179443359,4499.873046875,4499.873046875,53.5278750682268,5.64655298350575,5.76672029495239,54,1,0,0,1,0.301361083984375,33.7243423461914,1,1,3,300.332489013672,0,300.336334228516,,,,,,,,,,,,,,,,,,,,,,,,,,,,,,,,,
,3883341210.83176,300.180282592773,5499.75830078125,8.96503058388257E-5,1.39932829254213E-8,1,4,13.4005146026611,4.99390735342303,30.7100005447865,0.111252262981894,0.0165656501737587,1,-6.06993756375744E-8,,,,,,,,,,,,,,,,,,,,,300.162048339844,300.198516845703,5499.75830078125,5499.75830078125,53.5028629556114,5.64708846135273,5.76671552658081,54,1,0,0,1,0.301437377929687,33.7243423461914,1,1,3,300.198516845703,0,300.180282592773,,,,,,,,,,,,,,,,,,,,,,,,,,,,,,,,,
,3883341252.40682,300.16845703125,6499.78173828125,7.49669925827834E-5,1.07990832440383E-8,1,4,13.4005146026611,4.9940314607081,30.7100005447865,0.0930327033495005,0.0138624546450285,1,-4.30891826340521E-8,,,,,,,,,,,,,,,,,,,,,300.163269042969,300.173645019531,6499.78173828125,6499.78173828125,53.6572345881595,5.64619934107372,5.76294946670532,54,1,0,0,1,0.300979614257812,33.7243423461914,1,1,3,300.163269042969,0,300.16845703125,,,,,,,,,,,,,,,,,,,,,,,,,,,,,,,,,
,3883341293.60109,300.049911499023,7499.591796875,5.96443383070566E-5,1.37688445062839E-8,1,4,13.4005146026611,4.99399734438434,30.7100005447865,0.0740155935120215,0.0110373990353308,1,-2.74925537307382E-8,,,,,,,,,,,,,,,,,,,,,300.046936035156,300.052886962891,7499.591796875,7499.591796875,53.5345189106403,5.64652184110136,5.76615047454834,54,1,0,0,1,0.302200317382812,33.7243423461914,1,1,3,300.046936035156,0,300.049911499023,,,,,,,,,,,,,,,,,,,,,,,,,,,,,,,,,
,3883341334.80227,300.095626831055,8499.6650390625,4.40349989774732E-5,1.41753927634433E-8,1,4,13.4005146026611,4.9938431477397,30.7100005447865,0.054639987110853,0.00816750575037387,1,-4.96605625259772E-9,,,,,,,,,,,,,,,,,,,,,300.091064453125,300.100189208984,8499.6650390625,8499.6650390625,53.6134633910826,5.6466995061833,5.76399803161621,54,1,0,0,1,0.30242919921875,33.2355842590332,1,1,3,300.100189208984,0,300.095626831055,,,,,,,,,,,,,,,,,,,,,,,,,,,,,,,,,
,3883341376.00608,300.289459228516,9499.90234375,2.81636075017438E-5,1.74769420375021E-8,1,4,13.4005146026611,4.99413456015804,30.7100005447865,0.0349463154738107,0.00524296601854989,1,1.19907516231974E-8,,,,,,,,,,,,,,,,,,,,,300.267364501953,300.311553955078,9499.90234375,9499.90234375,53.5892329069864,5.64693138189497,5.75886201858521,54,1,0,0,1,0.3021240234375,33.7243423461914,1,1,3,300.311553955078,0,300.289459228516,,,,,,,,,,,,,,,,,,,,,,,,,,,,,,,,,
,3883341433.12048,300.392669677734,10499.6875,1.21239938530385E-5,1.37388140917352E-8,1,4,13.4005146026611,4.99388681011144,30.7100005447865,0.0150341582840291,0.00231461573451131,1,5.17094571728354E-8,,,,,,,,,,,,,,,,,,,,,300.3857421875,300.399597167969,10499.6875,10499.6875,53.5599218375153,5.64809616787179,5.75738668441772,54,1,0,0,1,0.303802490234375,33.7243423461914,1,1,3,300.399597167969,0,300.392669677734,,,,,,,,,,,,,,,,,,,,,,,,,,,,,,,,,
,3883341484.49986,300.450134277344,11500.025390625,-3.99387567321593E-6,1.44835895041609E-8,1,4,13.4005146026611,4.99402904004368,30.7199992239475,-0.00496248494016312,-0.000697347381919813,1,3.54786899619449E-8,,,,,,,,,,,,,,,,,,,,,300.442230224609,300.458038330078,11500.025390625,11500.025390625,53.7088220704288,5.64786435197584,5.75549030303955,54,1,0,0,1,0.300750732421875,33.7243423461914,1,1,3,300.442230224609,0,300.450134277344,,,,,,,,,,,,,,,,,,,,,,,,,,,,,,,,,
,3883341534.54654,300.339797973633,12499.8720703125,-2.02958501143076E-5,1.67199653914139E-8,1,4,13.4005146026611,4.99378460051473,30.7100005447865,-0.0251996011118865,-0.00365542272227093,1,9.00885586669127E-8,,,,,,,,,,,,,,,,,,,,,300.330322265625,300.349273681641,12499.8720703125,12499.8720703125,53.5341280963807,5.64796784394461,5.75941562652588,52,1,68,0,0,0.302734375,33.7243423461914,1,1,3,300.330322265625,0,300.339797973633,,,,,,,,,,,,,,,,,,,,,,,,,,,,,,,,,
,3883341575.00576,300.334167480469,13499.70703125,-3.65904653142829E-5,1.89717409437955E-8,1,4,13.4005146026611,4.99383169662282,30.7100005447865,-0.0454207098375437,-0.00666451943882442,1,1.02586938689157E-7,,,,,,,,,,,,,,,,,,,,,300.327697753906,300.340637207031,13499.70703125,13499.70703125,53.594704306621,5.64776150390188,5.75556755065918,54,1,0,0,1,0.301666259765625,33.7243423461914,1,1,3,300.340789794922,0,300.334167480469,,,,,,,,,,,,,,,,,,,,,,,,,,,,,,,,,
,3883341630.73799,300.457778930664,14499.6181640625,-5.29602251317368E-5,1.71338388644295E-8,1,4,13.4005146026611,4.99375135923883,30.7100005447865,-0.0657294482137397,-0.00971267238049705,1,9.46346618113653E-8,,,,,,,,,,,,,,,,,,,,,300.451568603516,300.463989257812,14499.6181640625,14499.6181640625,53.5161506404384,5.64789148550145,5.75460958480835,54,1,0,0,1,0.30120849609375,33.7243423461914,1,1,3,300.451568603516,0,300.457778930664,,,,,,,,,,,,,,,,,,,,,,,,,,,,,,,,,
,3883341699.71893,300.369338989258,19999.81640625,-0.000143613301669869,2.27090909092752E-8,1,4,13.4005146026611,4.99367963782583,30.7199992239475,-0.178221209458415,-0.0264382151235908,1,1.75464655352063E-7,,,,,,,,,,,,,,,,,,,,,300.367828369141,300.370849609375,19999.81640625,19999.81640625,53.491138527823,5.64885422657699,5.75490522384644,54,1,0,0,1,0.302505493164063,33.7243423461914,1,1,3,300.367828369141,0,300.369338989258,,,,,,,,,,,,,,,,,,,,,,,,,,,,,,,,,
,3883341784.83578,300.257888793945,30000.015625,-0.000309706035965161,4.08344839516508E-8,1,4,13.4005146026611,4.99362432932081,30.7100005447865,-0.384310500140612,-0.0571641116635538,1,2.57290174630079E-7,,,,,,,,,,,,,,,,,,,,,300.237030029297,300.278747558594,30000.015625,30000.015625,53.3723309928999,5.64955302598272,5.74731349945068,54,1,0,0,1,0.302886962890625,33.7243423461914,1,1,3,300.278747558594,0,300.257888793945,,,,,,,,,,,,,,,,,,,,,,,,,,,,,,,,,
,3883341871.16287,300.108734130859,40000.4921875,-0.000476270276557025,5.53486704623206E-8,1,4,13.4005146026611,4.99373325057936,30.7100005447865,-0.590979527168404,-0.0881551021926906,1,1.98492719033231E-7,,,,,,,,,,,,,,,,,,,,,300.088165283203,300.129302978516,40000.4921875,40000.4921875,53.467689672246,5.64907033016607,5.74844217300415,53,1,68,0,0,0.30120849609375,33.2355842590332,1,1,3,300.129302978516,0,300.108734130859,,,,,,,,,,,,,,,,,,,,,,,,,,,,,,,,,
,3883341957.91772,300.180053710937,50000.26953125,-0.000643005012478454,7.50756804988827E-8,1,4,13.4005146026611,4.9936607280427,30.7100005447865,-0.797830356040428,-0.119185390907049,1,1.30165855634298E-7,,,,,,,,,,,,,,,,,,,,,300.171630859375,300.1884765625,50000.26953125,50000.26953125,53.4598733870537,5.64938423244947,5.747642993927,52,1,68,0,0,0.303497314453125,33.2355842590332,1,1,3,300.189239501953,0,300.180053710937,,,,,,,,,,,,,,,,,,,,,,,,,,,,,,,,,
,3883342044.46714,300.099487304687,60000.421875,-0.000809898288449262,1.34973687717954E-7,1,4,13.4005146026611,4.99357899905459,30.7100005447865,-1.00486471625258,-0.150257892790235,1,5.02019955655112E-8,,,,,,,,,,,,,,,,,,,,,300.069885253906,300.129089355469,60000.421875,60000.421875,53.3395025950922,5.64968625886841,5.74951457977295,54,1,0,0,1,0.302505493164063,33.7243423461914,1,1,3,300.129089355469,0,300.099487304687,,,,,,,,,,,,,,,,,,,,,,,,,,,,,,,,,
,3883342132.23674,300.07307434082,70000.2421875,-0.00097685001675052,9.63625166450697E-8,1,4,13.4005146026611,4.99354180045888,30.7100005447865,-1.21195234425315,-0.181508531582196,1,-1.63917627483009E-7,,,,,,,,,,,,,,,,,,,,,300.050018310547,300.096130371094,70000.2421875,70000.2421875,53.2894783698614,5.65004014596861,5.7465763092041,54,1,0,0,1,0.303268432617188,32.7468223571777,1,1,3,300.096130371094,0,300.07307434082,,,,,,,,,,,,,,,,,,,,,,,,,,,,,,,,,
,3883342136.1126,300.113952636719,70000.2421875,-0.000976848483407725,1.56821062533634E-7,1,4,13.4005146026611,4.99350298904464,30.7100005447865,-1.21194253021983,-0.181470943797731,1,-1.35444115368155E-7,,,,,,,,,,,,,,,,,,,,,300.097961425781,300.129943847656,70000.2421875,70000.2421875,53.0616336565056,5.6502625436177,5.74700212478638,53,2,68,0,0,0.304641723632812,33.7243423461914,1,1,3,300.129943847656,0,300.113952636719,,,,,,,,,,,,,,,,,,,,,,,,,,,,,,,,,