File: SQUID/23006_LCOS/transfer_119973_files_84937504/23006_LCOS_A1_MH_200K_FC_p0d5T.dat
[Header]
; MPMS3 Data File (default extension .dat)
; Copyright (c) 2007, Quantum Design, Inc. All rights reserved.
TITLE,
FILEOPENTIME,3883330548.82692,01/19/2023,11:00 pm
BYAPP,SQUID AC,0.9.1.0
INFO,MPMS3 Measurement Release 1.1.16 Build 347, MultiVu Release 2.3.3.2,APPNAME
INFO,0,MOMENT_UNITS
INFO,LSAT//LCO,SAMPLE_MATERIAL
INFO,,SAMPLE_COMMENT
INFO,,SAMPLE_MASS
INFO,,SAMPLE_VOLUME
INFO,,SAMPLE_MOLECULAR_WEIGHT
INFO,,SAMPLE_SIZE
INFO,,SAMPLE_SHAPE
INFO,Quartz,SAMPLE_HOLDER
INFO,Standard,SAMPLE_HOLDER_DETAIL
INFO,65.59,SAMPLE_OFFSET
DATATYPE,COMMENT,1
DATATYPE,TIME,2
STARTUPAXIS,X,2
STARTUPAXIS,Y1,5
FIELDGROUP, VSM,2,3,4,5,6,8,9,10,11,14,15
FIELDGROUP, DC, 2,3,4,14,56,57,58,59,60,61,62,63,64,65,66,67,68,69
FIELDGROUP, AC, 2,3,4,11,16,17,18,19,20,21,22,23,24,25,26,27,28,29,30
STARTUPGROUP, All
[Data]
Comment,Time Stamp (sec),Temperature (K),Magnetic Field (Oe),Moment (emu),M. Std. Err. (emu),Transport Action,Averaging Time (sec),Frequency (Hz),Peak Amplitude (mm),Center Position (mm),Lockin Signal' (V),Lockin Signal (V),Range,M. Quad. Signal (emu),AC Moment (emu),AC M. Std Err. (emu),AC Phase (deg),AC Phase Std. Err. (deg),AC Susceptibility (emu/Oe),AC Suscept. Std Err. (emu/Oe),AC X' (emu/Oe),AC X' Std Err. (emu/Oe),AC X'' (emu/Oe),AC X'' Std Err. (emu/Oe),AC Drive (Oe),AC Frequency (Hz),AC Averaging Time (sec),AC Cycles,AC Range,AC Measure Type,AC Signal' (V),AC Signal'' (V),AC Trim Coil Ratio,AC Trim Coil Phase,Min. Temperature (K),Max. Temperature (K),Min. Field (Oe),Max. Field (Oe),Mass (grams),Motor Lag (deg),Pressure (Torr),Measure Count,Measurement Number,SQUID Status (code),Motor Status (code),Measure Status (code),Motor Current (amps),Motor Temp. (C),Temp. Status (code),Field Status (code),Chamber Status (code),Chamber Temp (K),Redirection State,Average Temp (K),Rotation Angle (deg),Rotator state,DC Moment Fixed Ctr (emu),DC Moment Err Fixed Ctr (emu),DC Moment Free Ctr (emu),DC Moment Err Free Ctr (emu),DC Fixed Fit,DC Free Fit,DC Calculated Center (mm),DC Calculated Center Err (mm),DC Scan Length (mm),DC Scan Time (s),DC Number of Points,DC Squid Drift,DC Min V (V),DC Max V (V),DC Scans per Measure,Map 01,Map 02,Map 03,Map 04,Map 05,Map 06,Map 07,Map 08,Map 09,Map 10,Map 11,Map 12,Map 13,Map 14,Map 15,Map 16
,3883330590.32721,200.100364685059,69999.7109375,-0.000968054593764544,1.81622562924812E-7,1,4,13.4005146026611,5.00486105699928,30.5499993264675,-1.20514899775728,-0.178462925674266,10,1.43021436636923E-6,,,,,,,,,,,,,,,,,,,,,200.100250244141,200.100479125977,69999.7109375,69999.7109375,53.0495184144575,5.64476340015545,5.08689832687378,54,1,0,0,1,0.305023193359375,32.2580642700195,1,1,3,200.100250244141,0,200.100364685059,,,,,,,,,,,,,,,,,,,,,,,,,,,,,,,,,
,3883330677.25341,200.129432678223,60000.47265625,-0.000801204546601134,1.2219872037828E-7,1,4,13.4005146026611,5.00479422377041,30.5499993264675,-0.997370813099485,-0.148000888626857,10,9.42765123394469E-7,,,,,,,,,,,,,,,,,,,,,200.125778198242,200.133087158203,60000.47265625,60000.47265625,53.4133664901595,5.64506975890772,5.08544635772705,54,1,0,0,1,0.304107666015625,33.2355842590332,1,1,3,200.133087158203,0,200.129432678223,,,,,,,,,,,,,,,,,,,,,,,,,,,,,,,,,
,3883330764.07046,200.202018737793,49999.62890625,-0.000634982532691592,1.63335685169283E-7,1,4,13.4005146026611,5.00480959835176,30.5499993264675,-0.790469308221903,-0.117197598016976,10,8.26530909292178E-7,,,,,,,,,,,,,,,,,,,,,200.176788330078,200.227249145508,49999.62890625,49999.62890625,53.3453648089864,5.64496356456797,5.08201503753662,54,1,0,0,1,0.302658081054687,33.7243423461914,1,1,3,200.227249145508,0,200.202018737793,,,,,,,,,,,,,,,,,,,,,,,,,,,,,,,,,
,3883330855.77224,200.25008392334,39999.734375,-0.000468440091724547,5.08296445462047E-8,1,4,13.4005146026611,5.00485568370061,30.5499993264675,-0.583034588366481,-0.0872551357051037,1,-2.88817400097622E-8,,,,,,,,,,,,,,,,,,,,,200.22998046875,200.27018737793,39999.734375,39999.734375,53.4082859047845,5.64502901055702,5.08788299560547,54,1,0,0,1,0.304489135742188,33.7243423461914,1,1,3,200.27018737793,0,200.25008392334,,,,,,,,,,,,,,,,,,,,,,,,,,,,,,,,,
,3883330941.73603,200.175163269043,29999.712890625,-0.00030264779510699,4.30486344711793E-8,1,4,13.4005146026611,5.00484112238578,30.5499993264675,-0.3766913758185,-0.0563171472566289,1,2.63756597813888E-8,,,,,,,,,,,,,,,,,,,,,200.165100097656,200.18522644043,29999.712890625,29999.712890625,53.4430683738903,5.64339779258443,5.08321571350098,54,1,0,0,1,0.302886962890625,33.7243423461914,1,1,3,200.186096191406,0,200.175163269043,,,,,,,,,,,,,,,,,,,,,,,,,,,,,,,,,
,3883331028.2206,200.022613525391,19999.578125,-0.000137268732868888,2.39630858609129E-8,1,4,13.4005146026611,5.00480218805478,30.5499993264675,-0.170856062472474,-0.0255025739323252,1,4.43551282935484E-8,,,,,,,,,,,,,,,,,,,,,200.020874023438,200.024353027344,19999.578125,19999.578125,53.4712070005826,5.64349463522937,5.080894947052,54,1,0,0,1,0.304031372070313,33.7243423461914,1,1,3,200.020874023438,0,200.022613525391,,,,,,,,,,,,,,,,,,,,,,,,,,,,,,,,,
,3883331099.98156,200.020309448242,14499.7685546875,-4.69486332119316E-5,2.62911726923746E-8,1,4,13.4005146026611,5.00471245994047,30.5499993264675,-0.0584337894022798,-0.00872826835494038,1,1.0268966632983E-8,,,,,,,,,,,,,,,,,,,,,200.013000488281,200.027618408203,14499.7685546875,14499.7685546875,53.3023752404287,5.64320255302943,5.08254766464233,54,1,0,0,1,0.3033447265625,34.2131004333496,1,1,3,200.027618408203,0,200.020309448242,,,,,,,,,,,,,,,,,,,,,,,,,,,,,,,,,
,3883331142.78449,200.061592102051,13499.8203125,-3.06647125733182E-5,2.00570333481565E-8,1,4,13.4005146026611,5.00470032085343,30.5499993264675,-0.0381666218672237,-0.00569783419419548,1,9.16145238278774E-9,,,,,,,,,,,,,,,,,,,,,200.04524230957,200.077941894531,13499.8203125,13499.8203125,53.5294383252653,5.64429420772785,5.08836030960083,54,1,0,0,1,0.303192138671875,34.2131004333496,1,1,3,200.077941894531,0,200.061592102051,,,,,,,,,,,,,,,,,,,,,,,,,,,,,,,,,
,3883331183.27051,200.123481750488,12499.708984375,-1.44098524726728E-5,2.09761872641788E-8,1,4,13.4005146026611,5.0047597613424,30.5499993264675,-0.0179314038737835,-0.00270440299718052,1,-1.72700129261795E-8,,,,,,,,,,,,,,,,,,,,,200.098327636719,200.148635864258,12499.708984375,12499.708984375,53.4383786027749,5.64401953161337,5.08370494842529,54,1,0,0,1,0.304718017578125,33.7243423461914,1,1,3,200.148635864258,0,200.123481750488,,,,,,,,,,,,,,,,,,,,,,,,,,,,,,,,,
,3883331225.79962,200.131568908691,11499.6728515625,1.75464023699991E-6,1.80188664128304E-8,1,4,13.4005146026611,5.00469753354661,30.5499993264675,0.00219219520756785,0.000270573290749085,1,-4.50832196092993E-8,,,,,,,,,,,,,,,,,,,,,200.127792358398,200.135345458984,11499.6728515625,11499.6728515625,53.6009573347749,5.64497037869432,5.07948780059814,54,1,0,0,1,0.303573608398438,34.2131004333496,1,1,3,200.127792358398,0,200.131568908691,,,,,,,,,,,,,,,,,,,,,,,,,,,,,,,,,
,3883331267.48343,200.077415466309,10499.7880859375,1.78303507204692E-5,1.85654777704073E-8,1,4,13.4005146026611,5.00466009957519,30.5499993264675,0.0222008033099263,0.00325534226837278,1,-5.16817804903618E-8,,,,,,,,,,,,,,,,,,,,,200.075637817383,200.079193115234,10499.7880859375,10499.7880859375,53.3719401786402,5.64418646129745,5.0870189666748,54,1,0,0,1,0.303115844726562,33.7243423461914,1,1,3,200.075561523438,0,200.077415466309,,,,,,,,,,,,,,,,,,,,,,,,,,,,,,,,,
,3883331308.73088,200.229560852051,9499.525390625,3.37922444621235E-5,1.84421196676782E-8,1,4,13.4005146026611,5.00472160938963,30.5499993264675,0.0420735898812137,0.00618503334411238,1,-8.55961891028237E-8,,,,,,,,,,,,,,,,,,,,,200.206253051758,200.252868652344,9499.525390625,9499.525390625,53.4262633607268,5.64509501717265,5.08489608764648,54,1,0,0,1,0.305252075195313,33.7243423461914,1,1,3,200.252868652344,0,200.229560852051,,,,,,,,,,,,,,,,,,,,,,,,,,,,,,,,,
,3883331365.81237,200.355728149414,8499.451171875,4.95681277883665E-5,1.47626785425105E-8,1,4,13.4005146026611,5.00468273166372,30.5499993264675,0.0617086603637106,0.00911440735846156,1,-9.18148209817265E-8,,,,,,,,,,,,,,,,,,,,,200.350830078125,200.360626220703,8499.451171875,8499.451171875,53.594704306621,5.64486541587055,5.08645296096802,54,1,0,0,1,0.304031372070313,33.7243423461914,1,1,3,200.350830078125,0,200.355728149414,,,,,,,,,,,,,,,,,,,,,,,,,,,,,,,,,
,3883331406.46838,200.29320526123,7499.60400390625,6.51021426023124E-5,1.43875342398876E-8,1,4,13.4005146026611,5.0046844579817,30.5499993264675,0.081043482092799,0.0119969503884212,1,-9.95379530278625E-8,,,,,,,,,,,,,,,,,,,,,200.269775390625,200.316635131836,7499.60400390625,7499.60400390625,53.6158082766403,5.6445658665973,5.08031558990479,54,1,0,0,1,0.305328369140625,34.2131004333496,1,1,3,200.316635131836,0,200.29320526123,,,,,,,,,,,,,,,,,,,,,,,,,,,,,,,,,
,3883331463.64077,200.441886901855,6499.56787109375,8.0293997760582E-5,1.45984244166353E-8,1,4,13.4005146026611,5.00460442566964,30.5499993264675,0.0999456116123322,0.0148460792969834,1,-8.26534664948404E-8,,,,,,,,,,,,,,,,,,,,,200.432342529297,200.451431274414,6499.56787109375,6499.56787109375,53.4544019874191,5.64528591336342,5.08863830566406,54,1,0,0,1,0.304489135742188,33.7243423461914,1,1,3,200.432342529297,0,200.441886901855,,,,,,,,,,,,,,,,,,,,,,,,,,,,,,,,,
,3883331506.15358,200.374412536621,5499.74560546875,9.48542396962843E-5,1.57141793374059E-8,1,4,13.4005146026611,5.00465435717895,30.5499993264675,0.11807481279467,0.0175133628844473,1,-1.17808284811652E-7,,,,,,,,,,,,,,,,,,,,,200.355926513672,200.39289855957,5499.74560546875,5499.74560546875,53.5993940777364,5.64396530347576,5.0825138092041,54,1,0,0,1,0.30364990234375,34.2131004333496,1,1,3,200.39289855957,0,200.374412536621,,,,,,,,,,,,,,,,,,,,,,,,,,,,,,,,,
,3883331547.89201,200.315971374512,4499.79736328125,0.00010844672325802,1.46172723839065E-8,1,4,13.4005146026611,5.00465912152385,30.5499993264675,0.134991420850291,0.0200466397479619,1,-1.1572039880442E-7,,,,,,,,,,,,,,,,,,,,,200.305999755859,200.325942993164,4499.79736328125,4499.79736328125,53.4426775596307,5.6442396816825,5.0832724571228,53,1,68,0,0,0.302581787109375,34.2131004333496,1,1,3,200.305999755859,0,200.315971374512,,,,,,,,,,,,,,,,,,,,,,,,,,,,,,,,,
,3883331588.99887,200.309112548828,3499.54736328125,0.000119866731851518,5.32101530179383E-8,1,4,13.4005146026611,5.0046591522608,30.5499993264675,0.149214018320054,0.0221089125489239,1,-1.67071332936184E-7,,,,,,,,,,,,,,,,,,,,,200.304458618164,200.313766479492,3499.54736328125,3499.54736328125,53.4688621150249,5.64396570681197,5.08949089050293,54,1,0,0,1,0.303421020507812,34.2131004333496,1,1,3,200.304458618164,0,200.309112548828,,,,,,,,,,,,,,,,,,,,,,,,,,,,,,,,,
,3883331650.15654,200.242942810059,2709.58422851562,0.000125892839854311,1.50518150370293E-8,1,4,13.4005146026611,5.00467630036432,30.5499993264675,0.156707549165607,0.0232787780573477,1,-1.28656304212319E-7,,,,,,,,,,,,,,,,,,,,,200.232116699219,200.253768920898,2709.58422851562,2709.58422851562,53.526702625448,5.64545245806372,5.09010124206543,52,1,68,0,0,0.302276611328125,33.7243423461914,1,1,3,200.253768920898,0,200.242942810059,,,,,,,,,,,,,,,,,,,,,,,,,,,,,,,,,
,3883331689.51217,200.285911560059,2129.71875,0.000127018937383689,1.00581946815557E-8,1,4,13.4005146026611,5.00461111169622,30.5499993264675,0.158104048214948,0.0235023022722081,1,-1.17171323760088E-7,,,,,,,,,,,,,,,,,,,,,200.281509399414,200.290313720703,2129.71875,2129.71875,53.4223552181307,5.64550531873358,5.08776378631592,54,1,0,0,1,0.303192138671875,32.7468223571777,1,1,3,200.281509399414,0,200.285911560059,,,,,,,,,,,,,,,,,,,,,,,,,,,,,,,,,
,3883331728.60949,200.309501647949,1549.70227050781,0.000123112051603343,2.00364696974595E-8,1,4,13.4005146026611,5.00462119467333,30.5499993264675,0.153242011804306,0.0227758488277467,1,-1.16481546511702E-7,,,,,,,,,,,,,,,,,,,,,200.309356689453,200.309646606445,1549.70227050781,1549.70227050781,53.498173184496,5.6437316247445,5.08997344970703,54,1,0,0,1,0.3033447265625,33.7243423461914,1,1,3,200.309356689453,0,200.309501647949,,,,,,,,,,,,,,,,,,,,,,,,,,,,,,,,,
,3883331768.89149,200.202392578125,969.635498046875,0.000109686309067786,1.52273390679235E-8,1,4,13.4005146026611,5.00458671532933,30.5499993264675,0.136527244253612,0.020304886651877,1,-9.33263181679585E-8,,,,,,,,,,,,,,,,,,,,,200.198287963867,200.206497192383,969.635498046875,969.635498046875,53.4571376872364,5.64478858138413,5.0878701210022,54,1,0,0,1,0.303421020507812,34.2131004333496,1,1,3,200.206497192383,0,200.202392578125,,,,,,,,,,,,,,,,,,,,,,,,,,,,,,,,,
,3883331808.09001,200.153587341309,389.694610595703,7.49055924307522E-5,7.94744628390291E-9,1,4,13.4005146026611,5.00463132102762,30.5499993264675,0.0932383362649905,0.0138551104077791,1,-7.29090119648575E-8,,,,,,,,,,,,,,,,,,,,,200.146286010742,200.160888671875,389.694610595703,389.694610595703,53.4180562612749,5.64479364929764,5.08443641662598,54,1,0,0,1,0.3045654296875,33.7243423461914,1,1,3,200.160888671875,0,200.153587341309,,,,,,,,,,,,,,,,,,,,,,,,,,,,,,,,,
,3883331846.67166,200.138092041016,-190.233703613281,-2.85763693719492E-5,1.61062758296624E-8,1,4,13.4005146026611,5.004619332584,30.5499993264675,-0.0355696835542376,-0.00528889778156371,1,2.52338591810598E-8,,,,,,,,,,,,,,,,,,,,,200.133605957031,200.142578125,-190.233703613281,-190.233703613281,53.4985639987557,5.64490355795969,5.08915567398071,54,1,0,0,1,0.304183959960937,33.7243423461914,1,1,3,200.142913818359,0,200.138092041016,,,,,,,,,,,,,,,,,,,,,,,,,,,,,,,,,
,3883331883.85861,200.138282775879,-770.413818359375,-9.39357309463799E-5,2.37548513653381E-8,1,4,13.4005146026611,5.00459700466901,30.5499993264675,-0.116930808722974,-0.017335260251723,1,1.23285381387463E-7,,,,,,,,,,,,,,,,,,,,,200.133392333984,200.143173217773,-770.413818359375,-770.413818359375,53.4360337172172,5.6450923678882,5.08271884918213,54,1,0,0,1,0.303955078125,33.7243423461914,1,1,3,200.133392333984,0,200.138282775879,,,,,,,,,,,,,,,,,,,,,,,,,,,,,,,,,
,3883331922.36309,200.228164672852,-1349.90148925781,-0.000116738352727359,1.92524511160917E-8,1,4,13.4005146026611,5.00455368656471,30.5499993264675,-0.145307199588699,-0.0215862611370064,1,1.18518226362481E-7,,,,,,,,,,,,,,,,,,,,,200.215270996094,200.241058349609,-1349.90148925781,-1349.90148925781,53.4766784002172,5.64490344320458,5.09070587158203,54,1,0,0,1,0.30548095703125,34.2131004333496,1,1,3,200.241058349609,0,200.228164672852,,,,,,,,,,,,,,,,,,,,,,,,,,,,,,,,,
,3883331960.51486,200.263328552246,-1930.35852050781,-0.000124626025262389,1.15957636063535E-8,1,4,13.4005146026611,5.00470384490628,30.5499993264675,-0.155130308114993,-0.023055024671236,1,1.19073599082568E-7,,,,,,,,,,,,,,,,,,,,,200.244659423828,200.281997680664,-1930.35852050781,-1930.35852050781,53.5208404115537,5.64481341085573,5.09009885787964,54,1,0,0,1,0.303802490234375,33.7243423461914,1,1,3,200.281997680664,0,200.263328552246,,,,,,,,,,,,,,,,,,,,,,,,,,,,,,,,,
,3883331998.52216,200.29598236084,-2509.87158203125,-0.000125374237117513,3.12042107759136E-8,1,4,13.4005146026611,5.00458207420633,30.5499993264675,-0.156060054178083,-0.0231678676222692,1,1.39701191182832E-7,,,,,,,,,,,,,,,,,,,,,200.277328491211,200.314636230469,-2509.87158203125,-2509.87158203125,53.3250424674864,5.64458400332336,5.09210777282715,54,1,0,0,1,0.301437377929687,33.7243423461914,1,1,3,200.314636230469,0,200.29598236084,,,,,,,,,,,,,,,,,,,,,,,,,,,,,,,,,
,3883332058.22774,200.428695678711,-3000.14624023438,-0.000123003826805054,1.13415587222375E-8,1,4,13.4005146026611,5.00449618467417,30.5499993264675,-0.153096722214219,-0.0227899918717678,1,8.828818341062E-8,,,,,,,,,,,,,,,,,,,,,200.427886962891,200.429504394531,-3000.14624023438,-3000.14624023438,53.4637815296499,5.64545812602421,5.08437061309814,54,1,0,0,1,0.30364990234375,33.7243423461914,1,1,3,200.427886962891,0,200.428695678711,,,,,,,,,,,,,,,,,,,,,,,,,,,,,,,,,
,3883332097.69423,200.351432800293,-4000.14453125,-0.00011346485872056,1.55015606421111E-8,1,4,13.4005146026611,5.00456643836139,30.5499993264675,-0.141225301642669,-0.0210331697858854,1,7.32994584210153E-8,,,,,,,,,,,,,,,,,,,,,200.346130371094,200.356735229492,-4000.14453125,-4000.14453125,53.4254817322076,5.64410489165619,5.08474779129028,54,1,0,0,1,0.30029296875,33.7243423461914,1,1,3,200.346130371094,0,200.351432800293,,,,,,,,,,,,,,,,,,,,,,,,,,,,,,,,,
,3883332137.64949,200.208168029785,-5000.0673828125,-0.000100887490722487,1.24987786065583E-8,1,4,13.4005146026611,5.00460444912276,30.5499993264675,-0.125571863983218,-0.018703285543741,1,6.40456274016464E-8,,,,,,,,,,,,,,,,,,,,,200.201568603516,200.214767456055,-5000.0673828125,-5000.0673828125,53.4590917585345,5.64528862968698,5.09245109558105,54,1,0,0,1,0.304336547851562,33.7243423461914,1,1,3,200.201568603516,0,200.208168029785,,,,,,,,,,,,,,,,,,,,,,,,,,,,,,,,,
,3883332178.75573,200.167510986328,-5999.990234375,-8.6721587391644E-5,1.53481604750707E-8,1,4,13.4005146026611,5.00461696628663,30.5499993264675,-0.107937224231441,-0.0160979490948184,1,3.83484445305748E-8,,,,,,,,,,,,,,,,,,,,,200.148635864258,200.186386108398,-5999.990234375,-5999.990234375,53.4856671281884,5.64451846447644,5.09129524230957,54,1,0,0,1,0.303955078125,33.7243423461914,1,1,3,200.186386108398,0,200.167510986328,,,,,,,,,,,,,,,,,,,,,,,,,,,,,,,,,
,3883332219.96037,200.234924316406,-6999.673828125,-7.18098340643054E-5,1.65284321382042E-8,1,4,13.4005146026611,5.0047767546541,30.5499993264675,-0.0893786018445647,-0.0133494704078231,1,1.65175267574044E-8,,,,,,,,,,,,,,,,,,,,,200.221084594727,200.248764038086,-6999.673828125,-6999.673828125,53.5650024228903,5.64471136771848,5.08919334411621,53,1,68,0,0,0.30426025390625,33.7243423461914,1,1,3,200.248764038086,0,200.234924316406,,,,,,,,,,,,,,,,,,,,,,,,,,,,,,,,,
,3883332261.28623,200.349662780762,-8000.0625,-5.64389871863294E-5,1.46857383936311E-8,1,4,13.4005146026611,5.00460096975879,30.5499993264675,-0.0702436705764414,-0.0104918502737372,1,1.27084293113918E-8,,,,,,,,,,,,,,,,,,,,,200.349349975586,200.349975585938,-8000.0625,-8000.0625,53.4297806890633,5.6449411375025,5.09009504318237,54,1,0,0,1,0.306396484375,33.7243423461914,1,1,3,200.349349975586,0,200.349662780762,,,,,,,,,,,,,,,,,,,,,,,,,,,,,,,,,
,3883332301.27767,200.451324462891,-8999.8212890625,-4.07862306604274E-5,1.30070437554844E-8,1,4,13.4005146026611,5.00465467036715,30.5499993264675,-0.0507591045771773,-0.00760882051272934,1,-1.22373328610486E-8,,,,,,,,,,,,,,,,,,,,,200.449203491211,200.45344543457,-8999.8212890625,-8999.8212890625,53.6357398038807,5.64533362355281,5.09398031234741,54,1,0,0,1,0.303955078125,33.7243423461914,1,1,3,200.449203491211,0,200.451324462891,,,,,,,,,,,,,,,,,,,,,,,,,,,,,,,,,
,3883332341.69548,200.256256103516,-9999.8837890625,-2.49146750226205E-5,1.6968149375623E-8,1,4,13.4005146026611,5.00450344577997,30.5499993264675,-0.0310015650163819,-0.00467332350993739,1,-2.80424138078878E-8,,,,,,,,,,,,,,,,,,,,,200.247009277344,200.265502929687,-9999.8837890625,-9999.8837890625,53.5145873833999,5.64541116457668,5.08976030349731,54,1,0,0,1,0.303878784179687,33.7243423461914,1,1,3,200.247009277344,0,200.256256103516,,,,,,,,,,,,,,,,,,,,,,,,,,,,,,,,,
,3883332381.68789,200.38191986084,-10999.693359375,-8.85514162949673E-6,1.65052991323006E-8,1,4,13.4005146026611,5.00464225551449,30.5499993264675,-0.0110094288753442,-0.00172478864622969,1,-6.11794648693768E-8,,,,,,,,,,,,,,,,,,,,,200.364715576172,200.399124145508,-10999.693359375,-10999.693359375,53.5595310232557,5.64428413621784,5.08596467971802,53,1,68,0,0,0.30670166015625,33.7243423461914,1,1,3,200.399124145508,0,200.38191986084,,,,,,,,,,,,,,,,,,,,,,,,,,,,,,,,,
,3883332437.5012,200.40259552002,-11999.7666015625,7.24369643410858E-6,2.24991894869153E-8,1,4,13.4005146026611,5.00466003370701,30.5499993264675,0.00903105036293802,0.0012434286794679,1,-8.4532170623834E-8,,,,,,,,,,,,,,,,,,,,,200.393157958984,200.412033081055,-11999.7666015625,-11999.7666015625,53.3684228503037,5.64329065986995,5.08973741531372,52,1,68,0,0,0.302810668945313,33.7243423461914,1,1,3,200.412033081055,0,200.40259552002,,,,,,,,,,,,,,,,,,,,,,,,,,,,,,,,,
,3883332477.56512,200.387825012207,-12999.8779296875,2.34277091666057E-5,1.83787239028589E-8,1,4,13.4005146026611,5.00458107106611,30.5499993264675,0.0291746930775724,0.00424248352878377,1,-9.57805650724713E-8,,,,,,,,,,,,,,,,,,,,,200.369293212891,200.406356811523,-12999.8779296875,-12999.8779296875,53.5306107680441,5.64435679416254,5.09457969665527,53,1,68,0,0,0.303497314453125,33.7243423461914,1,1,3,200.406356811523,0,200.387825012207,,,,,,,,,,,,,,,,,,,,,,,,,,,,,,,,,
,3883332518.38735,200.41820526123,-13999.7001953125,3.96947347899818E-5,2.54793437926063E-8,1,4,13.4005146026611,5.00459331866089,30.5499993264675,0.049422871370223,0.00725133824728251,1,-1.11614911038276E-7,,,,,,,,,,,,,,,,,,,,,200.416381835938,200.420028686523,-13999.7001953125,-13999.7001953125,53.4817589855922,5.64394384906954,5.09010124206543,54,1,0,0,1,0.302047729492188,34.2131004333496,1,1,3,200.416381835938,0,200.41820526123,,,,,,,,,,,,,,,,,,,,,,,,,,,,,,,,,
,3883332654.12599,200.153297424316,-14999.5859375,5.59740809425238E-5,1.72205564344292E-8,1,4,13.4005146026611,5.00457009523301,30.5499993264675,0.0696790525449204,0.0103077186263438,1,-9.10398988649479E-8,,,,,,,,,,,,,,,,,,,,,200.152099609375,200.154495239258,-14999.5859375,-14999.5859375,53.6056471058903,5.64480601708334,5.09346342086792,53,1,68,0,0,0.304946899414063,33.7243423461914,1,1,3,200.152099609375,0,200.153297424316,,,,,,,,,,,,,,,,,,,,,,,,,,,,,,,,,
,3883332753.42189,200.115539550781,-24999.70703125,0.000220681496756874,3.12151939451715E-8,1,4,13.4005146026611,5.00444936843319,30.5499993264675,0.274670098140879,0.0408706714002751,1,-1.71559517487463E-7,,,,,,,,,,,,,,,,,,,,,200.100021362305,200.131057739258,-24999.70703125,-24999.70703125,53.4743335146595,5.64475302781649,5.09375762939453,54,1,0,0,1,0.304412841796875,33.7243423461914,1,1,3,200.131057739258,0,200.115539550781,,,,,,,,,,,,,,,,,,,,,,,,,,,,,,,,,
,3883332841.01545,200.220970153809,-34999.59375,0.000386332009354746,5.12491298720265E-8,1,4,13.4005146026611,5.0046685388101,30.5499993264675,0.480847594545689,0.071741176118851,1,-1.49841703741829E-7,,,,,,,,,,,,,,,,,,,,,200.192459106445,200.249481201172,-34999.59375,-34999.59375,53.5513239238037,5.64471999229392,5.09402990341186,54,1,0,0,1,0.302810668945313,33.7243423461914,1,1,3,200.249481201172,0,200.220970153809,,,,,,,,,,,,,,,,,,,,,,,,,,,,,,,,,
,3883332937.99932,200.294189453125,-44999.8359375,0.000552328789591134,7.37904091886556E-8,1,4,13.4005146026611,5.0043923157536,30.5599998682737,0.6873791976684,0.102712278320428,1,-9.07127178494047E-8,,,,,,,,,,,,,,,,,,,,,200.278045654297,200.310333251953,-44999.8359375,-44999.8359375,53.420010332573,5.64652509696617,5.08870983123779,52,1,68,0,0,0.305099487304687,33.2355842590332,1,1,3,200.310333251953,0,200.294189453125,,,,,,,,,,,,,,,,,,,,,,,,,,,,,,,,,
,3883333025.31369,200.126777648926,-54999.609375,0.000718480678804223,9.78015181809508E-8,1,4,13.4005146026611,5.00447828639032,30.5599998682737,0.894142336983208,0.133855315826169,1,7.6337429729228E-8,,,,,,,,,,,,,,,,,,,,,200.118347167969,200.135208129883,-54999.609375,-54999.609375,53.3191802535922,5.64571598914047,5.09287309646606,54,1,0,0,1,0.30364990234375,33.2355842590332,1,1,3,200.135208129883,0,200.126777648926,,,,,,,,,,,,,,,,,,,,,,,,,,,,,,,,,
,3883333126.72208,200.03450012207,-64999.69140625,0.000884725523790526,1.30888965751839E-7,1,4,13.4005146026611,5.0045239231857,30.5599998682737,1.10104291303267,0.164853354218629,1,1.13264515729039E-7,,,,,,,,,,,,,,,,,,,,,200.032440185547,200.036560058594,-64999.69140625,-64999.69140625,53.310191525621,5.64445300118019,5.09771156311035,53,1,64,0,0,0.302963256835937,33.7243423461914,1,1,3,200.036560058594,0,200.03450012207,,,,,,,,,,,,,,,,,,,,,,,,,,,,,,,,,
,3883333213.7679,200.054046630859,-64999.60546875,0.000884335205853827,2.19351228801204E-7,1,4,13.4005146026611,5.00461495339683,30.5599998682737,1.10053509549516,0.165119472787726,1,3.82109923727916E-7,,,,,,,,,,,,,,,,,,,,,200.052200317383,200.055892944336,-64999.60546875,-64999.60546875,53.1538658217749,5.64389674278433,5.10093259811401,54,1,0,0,1,0.303878784179687,33.7243423461914,1,1,3,200.052200317383,0,200.054046630859,,,,,,,,,,,,,,,,,,,,,,,,,,,,,,,,,
,3883333301.57911,200.207015991211,-54999.7578125,0.000718089669260152,1.69692713853284E-7,1,4,13.4005146026611,5.00457561107768,30.5599998682737,0.893655472559468,0.133950301485315,1,2.08226468764163E-7,,,,,,,,,,,,,,,,,,,,,200.201553344727,200.212478637695,-54999.7578125,-54999.7578125,53.274627427996,5.64483440423728,5.0943489074707,54,1,0,0,1,0.301132202148438,33.7243423461914,1,1,3,200.201553344727,0,200.207015991211,,,,,,,,,,,,,,,,,,,,,,,,,,,,,,,,,
,3883333387.04848,200.107269287109,-44999.5625,0.000551800516531854,6.10895697728191E-8,1,4,13.4005146026611,5.00443033869654,30.5599998682737,0.686707713884024,0.102757778458119,1,2.39978421259566E-8,,,,,,,,,,,,,,,,,,,,,200.079620361328,200.134918212891,-44999.5625,-44999.5625,53.4383786027749,5.64493536808523,5.09675216674805,54,1,0,0,1,0.30364990234375,34.2131004333496,1,1,3,200.134918212891,0,200.107269287109,,,,,,,,,,,,,,,,,,,,,,,,,,,,,,,,,
,3883333474.75598,200.150230407715,-34999.69140625,0.000385799245093288,4.43781095298744E-8,1,4,13.4005146026611,5.00441553942317,30.5599998682737,0.48011948710655,0.0718447732194711,1,1.71768223589074E-8,,,,,,,,,,,,,,,,,,,,,200.126251220703,200.174209594727,-34999.69140625,-34999.69140625,53.4567468729768,5.64560768524004,5.10210704803467,54,1,0,0,1,0.303268432617188,33.7243423461914,1,1,3,200.174209594727,0,200.150230407715,,,,,,,,,,,,,,,,,,,,,,,,,,,,,,,,,
,3883333561.16202,200.092353820801,-24999.80859375,0.000219966869391802,3.16485531493969E-8,1,4,13.4005146026611,5.00449967538169,30.5599998682737,0.27375886611616,0.0409101822891869,1,-3.33694069324804E-8,,,,,,,,,,,,,,,,,,,,,200.088134765625,200.096572875977,-24999.80859375,-24999.80859375,53.4215735896114,5.64491896279115,5.10112476348877,54,1,0,0,1,0.302963256835937,33.7243423461914,1,1,3,200.088134765625,0,200.092353820801,,,,,,,,,,,,,,,,,,,,,,,,,,,,,,,,,
,3883333645.61726,200.075622558594,-14999.7626953125,5.51691798285056E-5,2.21239354512421E-8,1,4,13.4005146026611,5.00447082379982,30.5599998682737,0.068656274233161,0.0102855285034044,1,1.17676758102758E-8,,,,,,,,,,,,,,,,,,,,,200.073654174805,200.077590942383,-14999.7626953125,-14999.7626953125,53.6427744605538,5.64546214168708,5.09792709350586,54,1,0,0,1,0.302505493164063,33.7243423461914,1,1,3,200.073654174805,0,200.075622558594,,,,,,,,,,,,,,,,,,,,,,,,,,,,,,,,,
,3883333700.34024,200.244857788086,-14000.0400390625,3.88510650476467E-5,2.2063224524502E-8,1,4,13.4005146026611,5.00437958967535,30.5599998682737,0.0483470172317452,0.00724742948488668,1,1.18000085987769E-8,,,,,,,,,,,,,,,,,,,,,200.244644165039,200.245071411133,-14000.0400390625,-14000.0400390625,53.5661748656691,5.64599467570901,5.10575723648071,54,1,0,0,1,0.303878784179687,34.2131004333496,1,1,3,200.244644165039,0,200.244857788086,,,,,,,,,,,,,,,,,,,,,,,,,,,,,,,,,
,3883333841.97749,200.142082214355,-13000.3564453125,2.25943330132906E-5,1.78597413862518E-8,1,4,13.4005146026611,5.00429724631197,30.5599998682737,0.0281245191091207,0.00415898140516266,1,-3.79420002523928E-8,,,,,,,,,,,,,,,,,,,,,200.134658813477,200.149505615234,-13000.3564453125,-13000.3564453125,53.3449739947268,5.64622503166463,5.09789228439331,54,1,0,0,1,0.304183959960937,33.7243423461914,1,1,3,200.134658813477,0,200.142082214355,,,,,,,,,,,,,,,,,,,,,,,,,,,,,,,,,
,3883333883.64831,200.313179016113,-12000.2705078125,6.35503813420114E-6,1.87828911015131E-8,1,4,13.4005146026611,5.00432461930833,30.5599998682737,0.00789973800251819,0.00124211513330839,1,4.74437719342937E-8,,,,,,,,,,,,,,,,,,,,,200.308029174805,200.318328857422,-12000.2705078125,-12000.2705078125,53.4360337172172,5.64584362614879,5.09975910186768,54,1,0,0,1,0.303802490234375,34.2131004333496,1,1,3,200.318328857422,0,200.313179016113,,,,,,,,,,,,,,,,,,,,,,,,,,,,,,,,,
,3883333924.05939,200.314788818359,-11000.3974609375,-9.7665505540307E-6,2.01672151505437E-8,1,4,13.4005146026611,5.00432490015612,30.5599998682737,-0.0121636463612835,-0.0017540283481385,1,5.15428307513235E-8,,,,,,,,,,,,,,,,,,,,,200.306289672852,200.323287963867,-11000.3974609375,-11000.3974609375,53.4782416572557,5.6461536125916,5.10580110549927,52,1,68,0,0,0.302505493164063,33.2355842590332,1,1,3,200.323287963867,0,200.314788818359,,,,,,,,,,,,,,,,,,,,,,,,,,,,,,,,,
,3883334049.19226,200.15486907959,-10000.248046875,-2.58394699822807E-5,1.72070858994073E-8,1,4,13.4005146026611,5.00432994330066,30.5599998682737,-0.0321709404396962,-0.00471150096843978,1,7.94411710824338E-8,,,,,,,,,,,,,,,,,,,,,200.138687133789,200.171051025391,-10000.248046875,-10000.248046875,53.4680804865057,5.64529482569342,5.10724687576294,53,1,68,0,0,0.30426025390625,33.7243423461914,1,1,3,200.173187255859,0,200.15486907959,,,,,,,,,,,,,,,,,,,,,,,,,,,,,,,,,
,3883334193.89407,200.139221191406,-9000.337890625,-4.16718834896422E-5,2.05658362291501E-8,1,4,13.4005146026611,5.00432724407477,30.5599998682737,-0.05186737975961,-0.00770105885225219,1,4.55721449443623E-8,,,,,,,,,,,,,,,,,,,,,200.133728027344,200.144714355469,-9000.337890625,-9000.337890625,53.5943134923614,5.64587014274717,5.10666179656982,54,1,0,0,1,0.304794311523438,34.2131004333496,1,1,3,200.133728027344,0,200.139221191406,,,,,,,,,,,,,,,,,,,,,,,,,,,,,,,,,
,3883334235.30193,200.171005249023,-8000.150390625,-5.74070193541437E-5,1.74875012296463E-8,1,4,13.4005146026611,5.00421648061847,30.5599998682737,-0.071456419848311,-0.0105662539407066,1,9.68243249041216E-8,,,,,,,,,,,,,,,,,,,,,200.169692993164,200.172317504883,-8000.150390625,-8000.150390625,53.3481005088037,5.64597219845458,5.10009288787842,53,1,68,0,0,0.303955078125,33.7243423461914,1,1,3,200.172348022461,0,200.171005249023,,,,,,,,,,,,,,,,,,,,,,,,,,,,,,,,,
,3883334275.94635,200.380294799805,-7000.21533203125,-7.27781798562227E-5,1.57302871272531E-8,1,4,13.4005146026611,5.00422885838094,30.5599998682737,-0.0905890596867006,-0.013399949678237,1,1.19169341442877E-7,,,,,,,,,,,,,,,,,,,,,200.364028930664,200.396560668945,-7000.21533203125,-7000.21533203125,53.5618759088134,5.64585189387621,5.1082501411438,52,1,68,0,0,0.303573608398438,33.7243423461914,1,1,3,200.396560668945,0,200.380294799805,,,,,,,,,,,,,,,,,,,,,,,,,,,,,,,,,
,3883334334.47168,200.370704650879,-6000.26708984375,-8.77234180090834E-5,1.49207854713668E-8,1,4,13.4005146026611,5.00425222058499,30.5599998682737,-0.109190031591776,-0.0161685029844673,1,1.30201936168602E-7,,,,,,,,,,,,,,,,,,,,,200.367111206055,200.374298095703,-6000.26708984375,-6000.26708984375,53.4887936422653,5.6457273863314,5.10825300216675,52,1,68,0,0,0.30364990234375,33.7243423461914,1,1,3,200.374298095703,0,200.370704650879,,,,,,,,,,,,,,,,,,,,,,,,,,,,,,,,,
,3883334373.34945,200.441352844238,-5000.369140625,-0.000101894448282931,1.2718961134944E-8,1,4,13.4005146026611,5.00423030824361,30.5599998682737,-0.126825245678362,-0.0187990173760457,1,1.36180252704661E-7,,,,,,,,,,,,,,,,,,,,,200.43376159668,200.448944091797,-5000.369140625,-5000.369140625,53.6201072334961,5.64546485120488,5.10490274429321,52,1,68,0,0,0.302810668945313,33.7243423461914,1,1,3,200.432647705078,0,200.441352844238,,,,,,,,,,,,,,,,,,,,,,,,,,,,,,,,,
,3883334414.3748,200.333473205566,-4000.3837890625,-0.000114561195389169,1.38350544367304E-8,1,4,13.4005146026611,5.00422269660357,30.5599998682737,-0.142588858583236,-0.0211495544882001,1,1.42155927522361E-7,,,,,,,,,,,,,,,,,,,,,200.323806762695,200.343139648438,-4000.3837890625,-4000.3837890625,53.5665656799287,5.64563770774897,5.1085901260376,54,1,0,0,1,0.304031372070313,33.7243423461914,1,1,3,200.343139648438,0,200.333473205566,,,,,,,,,,,,,,,,,,,,,,,,,,,,,,,,,
,3883334454.31342,200.434638977051,-3000.53637695313,-0.00012412387802201,1.55085864661114E-8,1,4,13.4005146026611,5.00408296003651,30.5599998682737,-0.154482624292565,-0.0229302112061863,1,1.41043264925183E-7,,,,,,,,,,,,,,,,,,,,,200.433837890625,200.435440063477,-3000.53637695313,-3000.53637695313,53.4985639987557,5.64637982070288,5.10346078872681,53,1,68,0,0,0.304107666015625,33.7243423461914,1,1,3,200.435440063477,0,200.434638977051,,,,,,,,,,,,,,,,,,,,,,,,,,,,,,,,,
,3883334511.16521,200.355651855469,-2510.40014648438,-0.000126696169182447,1.62943191349443E-8,1,4,13.4005146026611,5.0041655212824,30.5599998682737,-0.157685616628374,-0.0234198474711333,1,1.32796076666714E-7,,,,,,,,,,,,,,,,,,,,,200.348205566406,200.363098144531,-2510.40014648438,-2510.40014648438,53.5564045091787,5.64628567536536,5.1028904914856,54,1,0,0,1,0.3057861328125,33.7243423461914,1,1,3,200.348205566406,0,200.355651855469,,,,,,,,,,,,,,,,,,,,,,,,,,,,,,,,,
,3883334550.0426,200.408447265625,-1930.50952148438,-0.000126417212640034,1.66673830893872E-8,1,4,13.4005146026611,5.00419136557601,30.5599998682737,-0.157337832192086,-0.0233800327791945,1,1.2319665899836E-7,,,,,,,,,,,,,,,,,,,,,200.396423339844,200.420471191406,-1930.50952148438,-1930.50952148438,53.511460869323,5.64594919351681,5.10670185089111,54,1,0,0,1,0.303955078125,34.2131004333496,1,1,3,200.421630859375,0,200.408447265625,,,,,,,,,,,,,,,,,,,,,,,,,,,,,,,,,
,3883334589.078,200.351707458496,-1350.46801757812,-0.00011984942951989,9.41540494371646E-8,1,4,13.4005146026611,5.00406806466935,30.5599998682737,-0.149165374099417,-0.0221185322493854,1,1.53817700385655E-7,,,,,,,,,,,,,,,,,,,,,200.35009765625,200.353317260742,-1350.46801757812,-1350.46801757812,53.5282658824864,5.64665248275823,5.11076831817627,54,1,0,0,1,0.30517578125,33.7243423461914,1,1,3,200.35009765625,0,200.351707458496,,,,,,,,,,,,,,,,,,,,,,,,,,,,,,,,,
,3883334627.80034,200.365585327148,-770.464172363281,-0.000101247042848162,1.47104292716322E-7,1,4,13.4005146026611,5.00404658935585,30.5599998682737,-0.126032663289247,-0.0185469509419164,1,2.41123796101944E-7,,,,,,,,,,,,,,,,,,,,,200.363540649414,200.367630004883,-770.464172363281,-770.464172363281,53.5294383252653,5.64616313489268,5.11021566390991,54,1,0,0,1,0.305328369140625,33.7243423461914,1,1,3,200.363540649414,0,200.365585327148,,,,,,,,,,,,,,,,,,,,,,,,,,,,,,,,,
,3883334685.82631,200.468780517578,-190.233703613281,-5.17346075704014E-5,8.24034358216883E-9,1,4,13.4005146026611,5.0040333320255,30.5599998682737,-0.0643881398799027,-0.00955075425007261,1,6.39166923268065E-8,,,,,,,,,,,,,,,,,,,,,200.456832885742,200.480728149414,-190.233703613281,-190.233703613281,53.4133664901595,5.64651452487469,5.10735464096069,54,1,0,0,1,0.307159423828125,33.7243423461914,1,1,3,200.456832885742,0,200.468780517578,,,,,,,,,,,,,,,,,,,,,,,,,,,,,,,,,
,3883334725.25358,200.319625854492,389.619079589844,6.00894636646553E-5,1.94240761903773E-8,1,4,13.4005146026611,5.00401804169244,30.5599998682737,0.0747787616489646,0.0111425082280518,1,-3.4533967098804E-8,,,,,,,,,,,,,,,,,,,,,200.314239501953,200.325012207031,389.619079589844,389.619079589844,53.4465857022268,5.64712985074716,5.10589981079102,52,1,32,0,0,0.3045654296875,33.2355842590332,1,1,3,200.314239501953,0,200.319625854492,,,,,,,,,,,,,,,,,,,,,,,,,,,,,,,,,
,3883334764.96646,200.197235107422,969.622924804687,0.000104422453943282,2.41454566035305E-8,1,4,13.4005146026611,5.00404239835016,30.5599998682737,0.129953236702796,0.0193427754893316,1,-7.65823074366969E-8,,,,,,,,,,,,,,,,,,,,,200.189712524414,200.20475769043,969.622924804687,969.622924804687,53.5778992934576,5.64717599758996,5.11268997192383,54,1,0,0,1,0.30548095703125,33.7243423461914,1,1,3,200.20475769043,0,200.197235107422,,,,,,,,,,,,,,,,,,,,,,,,,,,,,,,,,
,3883334804.43242,200.149749755859,1549.57641601562,0.000120660924997233,2.01831950010849E-8,1,4,13.4005146026611,5.00405620591745,30.5599998682737,0.150164108647526,0.0223401515981677,1,-9.70549396148185E-8,,,,,,,,,,,,,,,,,,,,,200.144912719727,200.154586791992,1549.57641601562,1549.57641601562,53.4927017848614,5.64649994595796,5.10292387008667,54,1,0,0,1,0.305252075195313,33.7243423461914,1,1,3,200.144912719727,0,200.149749755859,,,,,,,,,,,,,,,,,,,,,,,,,,,,,,,,,
,3883334843.97652,200.273696899414,2129.60546875,0.000125530444859492,9.29544100349349E-9,1,4,13.4005146026611,5.00402189567389,30.5599998682737,0.156220440835952,0.0232572287736553,1,-8.83408923094498E-8,,,,,,,,,,,,,,,,,,,,,200.257705688477,200.289688110352,2129.60546875,2129.60546875,53.5126333121018,5.64674384071055,5.10437107086182,54,1,0,0,1,0.30517578125,33.7243423461914,1,1,3,200.289688110352,0,200.273696899414,,,,,,,,,,,,,,,,,,,,,,,,,,,,,,,,,
,3883334883.29863,200.388885498047,2709.7099609375,0.000124748130511134,7.44154631889946E-9,1,4,13.4005146026611,5.00399354720739,30.5599998682737,0.155245240398644,0.0231147377045526,1,-8.56746036871438E-8,,,,,,,,,,,,,,,,,,,,,200.372619628906,200.405151367187,2709.7099609375,2709.7099609375,53.4852763139287,5.64706774315549,5.10975790023804,54,1,0,0,1,0.3045654296875,33.2355842590332,1,1,3,200.405151367187,0,200.388885498047,,,,,,,,,,,,,,,,,,,,,,,,,,,,,,,,,
,3883335026.05791,200.23267364502,3499.77392578125,0.000118931271859596,1.21872735798399E-8,1,4,13.4005146026611,5.00392674673895,30.5599998682737,0.148007894559706,0.0220076308245443,1,-1.04891108160864E-7,,,,,,,,,,,,,,,,,,,,,200.231063842773,200.234283447266,3499.77392578125,3499.77392578125,53.6095552484864,5.64732237114859,5.09639310836792,54,1,0,0,1,0.306015014648438,33.7243423461914,1,1,3,200.234283447266,0,200.23267364502,,,,,,,,,,,,,,,,,,,,,,,,,,,,,,,,,
,3883335068.59447,200.340347290039,4499.78466796875,0.000107505796737945,1.26671792817826E-8,1,4,13.4005146026611,5.00385734325901,30.5599998682737,0.133780959995232,0.0199300157430049,1,-6.50809093336021E-8,,,,,,,,,,,,,,,,,,,,,200.334945678711,200.345748901367,4499.78466796875,4499.78466796875,53.5231852971114,5.64766396660131,5.08758449554443,54,1,0,0,1,0.30364990234375,33.7243423461914,1,1,3,200.345748901367,0,200.340347290039,,,,,,,,,,,,,,,,,,,,,,,,,,,,,,,,,
,3883335109.86606,200.323486328125,5499.53173828125,9.39998499788683E-5,1.05277626383101E-8,1,4,13.4005146026611,5.00394259015145,30.5599998682737,0.116975250839072,0.0174373364778274,1,-4.82959635883141E-8,,,,,,,,,,,,,,,,,,,,,200.316070556641,200.330902099609,5499.53173828125,5499.53173828125,53.6095552484864,5.64754789491762,5.09020042419434,54,1,0,0,1,0.303573608398438,33.7243423461914,1,1,3,200.316070556641,0,200.323486328125,,,,,,,,,,,,,,,,,,,,,,,,,,,,,,,,,
,3883335151.09634,200.343200683594,6499.54248046875,7.94109715921792E-5,1.46024832678147E-8,1,4,13.4005146026611,5.00387271044903,30.5599998682737,0.098817445922743,0.0147387054167875,1,-3.44111218748171E-8,,,,,,,,,,,,,,,,,,,,,200.332763671875,200.353637695313,6499.54248046875,6499.54248046875,53.465735600948,5.64716855002207,5.09130477905273,54,1,0,0,1,0.306243896484375,33.7243423461914,1,1,3,200.353637695313,0,200.343200683594,,,,,,,,,,,,,,,,,,,,,,,,,,,,,,,,,
,3883335276.46688,200.10277557373,7499.5791015625,6.419133606331E-5,1.31347250826703E-8,1,4,13.4005146026611,5.00390557937036,30.5599998682737,0.0798747044585836,0.0119438672747407,1,-3.8490628004241E-9,,,,,,,,,,,,,,,,,,,,,200.097183227539,200.108367919922,7499.5791015625,7499.5791015625,53.5270934397076,5.64692421928942,5.09163475036621,54,1,0,0,1,0.303955078125,33.2355842590332,1,1,3,200.097183227539,0,200.10277557373,,,,,,,,,,,,,,,,,,,,,,,,,,,,,,,,,
,3883335317.0654,200.065002441406,8499.7158203125,4.86601389851742E-5,1.54284604221191E-8,1,4,13.4005146026611,5.003933006449,30.5599998682737,0.0605497694388192,0.00905133059111322,1,-5.1424298607217E-9,,,,,,,,,,,,,,,,,,,,,200.063385009766,200.066619873047,8499.7158203125,8499.7158203125,53.5853247643903,5.64732591368455,5.09356784820557,54,1,0,0,1,0.306167602539063,33.7243423461914,1,1,3,200.063385009766,0,200.065002441406,,,,,,,,,,,,,,,,,,,,,,,,,,,,,,,,,
,3883335358.041,200.226058959961,9499.890625,3.28759484225969E-5,1.85741554757886E-8,1,4,13.4005146026611,5.00398889657621,30.5599998682737,0.0409070035175188,0.00613211115791979,1,9.96344203592526E-9,,,,,,,,,,,,,,,,,,,,,200.210815429687,200.241302490234,9499.890625,9499.890625,53.4161021899768,5.64686212421439,5.10273933410645,54,1,0,0,1,0.304031372070313,33.2355842590332,1,1,3,200.241302490234,0,200.226058959961,,,,,,,,,,,,,,,,,,,,,,,,,,,,,,,,,
,3883335398.33383,200.313873291016,10499.8125,1.69266021030862E-5,1.85354686591365E-8,1,4,13.4005146026611,5.00411562096262,30.5599998682737,0.0210558694328679,0.00319988954355257,1,3.93490921722972E-8,,,,,,,,,,,,,,,,,,,,,200.28450012207,200.343246459961,10499.8125,10499.8125,53.4813681713326,5.64705469281756,5.10041522979736,54,1,0,0,1,0.305023193359375,33.2355842590332,1,1,3,200.343246459961,0,200.313873291016,,,,,,,,,,,,,,,,,,,,,,,,,,,,,,,,,
,3883335542.86448,200.08544921875,11500.11328125,8.65115453962592E-7,2.089667210858E-8,1,4,13.4005146026611,5.00406082097752,30.5599998682737,0.00106599659130284,0.000231383324206577,1,5.65289502183217E-8,,,,,,,,,,,,,,,,,,,,,200.081085205078,200.089813232422,11500.11328125,11500.11328125,53.5263118111883,5.64697889096121,5.1020655632019,54,1,0,0,1,0.304031372070313,33.7243423461914,1,1,3,200.081085205078,0,200.08544921875,,,,,,,,,,,,,,,,,,,,,,,,,,,,,,,,,
,3883335583.44611,200.092529296875,12499.8349609375,-1.52863269843352E-5,1.86660449994029E-8,1,4,13.4005146026611,5.00409032421511,30.5599998682737,-0.0190357271749352,-0.00275331628697307,1,7.41311225546197E-8,,,,,,,,,,,,,,,,,,,,,200.065628051758,200.119430541992,12499.8349609375,12499.8349609375,53.493092599121,5.6481202463374,5.09840106964111,54,1,0,0,1,0.304718017578125,33.7243423461914,1,1,3,200.119430541992,0,200.092529296875,,,,,,,,,,,,,,,,,,,,,,,,,,,,,,,,,
,3883335639.74577,200.465927124023,13500.16015625,-3.15204344140666E-5,1.43251611717048E-8,1,4,13.4005146026611,5.00397835074069,30.5599998682737,-0.0392324617368626,-0.00579758733746559,1,5.60826206433636E-8,,,,,,,,,,,,,,,,,,,,,200.454833984375,200.477020263672,13500.16015625,13500.16015625,53.4700345578037,5.64708357674433,5.09930896759033,54,1,0,0,1,0.303421020507812,33.7243423461914,1,1,3,200.454833984375,0,200.465927124023,,,,,,,,,,,,,,,,,,,,,,,,,,,,,,,,,
,3883335768.05177,200.149208068848,14500.109375,-4.78136579854269E-5,2.28322744125971E-8,1,4,13.4005146026611,5.00387184344927,30.5599998682737,-0.0595076244630185,-0.00881228617282532,1,7.05013975489281E-8,,,,,,,,,,,,,,,,,,,,,200.139038085938,200.159378051758,14500.109375,14500.109375,53.6240153760922,5.64745654693816,5.09979629516602,54,1,0,0,1,0.306549072265625,33.2355842590332,1,1,3,200.139038085938,0,200.149208068848,,,,,,,,,,,,,,,,,,,,,,,,,,,,,,,,,
,3883335832.90195,200.146545410156,19999.552734375,-0.00013807649193074,3.46441085913948E-8,1,4,13.4005146026611,5.00382385699832,30.5599998682737,-0.171831887814448,-0.0255292846240376,1,1.38121038938014E-7,,,,,,,,,,,,,,,,,,,,,200.145935058594,200.147155761719,19999.552734375,19999.552734375,53.5294383252653,5.64794775311785,5.10260677337646,54,1,0,0,1,0.304107666015625,33.7243423461914,1,1,3,200.145935058594,0,200.146545410156,,,,,,,,,,,,,,,,,,,,,,,,,,,,,,,,,
,3883335917.50841,200.235000610352,29999.990234375,-0.000303573906902762,4.11612382256593E-8,1,4,13.4005146026611,5.00382929070558,30.5599998682737,-0.377756514190698,-0.0563446162003457,1,1.30043318493231E-7,,,,,,,,,,,,,,,,,,,,,200.213226318359,200.256774902344,29999.990234375,29999.990234375,53.3801472780922,5.64768921623594,5.10307788848877,54,1,0,0,1,0.304183959960937,33.2355842590332,1,1,3,200.256774902344,0,200.235000610352,,,,,,,,,,,,,,,,,,,,,,,,,,,,,,,,,
,3883336016.82799,200.315811157227,40000.2265625,-0.000469454406926352,7.36105246100919E-8,1,4,13.4005146026611,5.00396317298881,30.5599998682737,-0.584179059127681,-0.0872368061237642,1,1.20096097103368E-7,,,,,,,,,,,,,,,,,,,,,200.286529541016,200.345092773438,40000.2265625,40000.2265625,53.3852278634672,5.64721254728892,5.10100173950195,53,1,68,0,0,0.303573608398438,33.2355842590332,1,1,3,200.345092773438,0,200.315811157227,,,,,,,,,,,,,,,,,,,,,,,,,,,,,,,,,
,3883336104.35872,200.202392578125,50000.20703125,-0.000635474191400625,1.4122051598286E-7,1,4,13.4005146026611,5.00408756778928,30.5599998682737,-0.790791498552765,-0.118135390008547,1,1.27452785591481E-7,,,,,,,,,,,,,,,,,,,,,200.197845458984,200.206939697266,50000.20703125,50000.20703125,53.3019844261691,5.64785659521311,5.10837316513062,52,1,68,0,0,0.305328369140625,33.7243423461914,1,1,3,200.206939697266,0,200.202392578125,,,,,,,,,,,,,,,,,,,,,,,,,,,,,,,,,
,3883336191.42744,200.235939025879,60000.47265625,-0.000801817465358117,1.59649970249357E-7,1,4,13.4005146026611,5.00397317085212,30.5599998682737,-0.99770989496586,-0.149383000697381,1,-1.03558185997765E-7,,,,,,,,,,,,,,,,,,,,,200.230758666992,200.241119384766,60000.47265625,60000.47265625,53.3191802535922,5.64903575893615,5.10165500640869,54,1,0,0,1,0.304031372070313,33.7243423461914,1,1,3,200.241119384766,0,200.235939025879,,,,,,,,,,,,,,,,,,,,,,,,,,,,,,,,,
,3883336360.37573,200.172218322754,70000.46875,-0.000968159378938505,1.39806044371035E-7,1,4,13.4005146026611,5.00410444874115,30.5599998682737,-1.20470539391002,-0.180578536104055,1,-2.84562545389857E-7,,,,,,,,,,,,,,,,,,,,,200.16552734375,200.178909301758,70000.46875,70000.46875,53.1210374239672,5.647314567705,5.10917091369629,54,1,0,0,1,0.30548095703125,33.7243423461914,1,1,3,200.16552734375,0,200.172218322754,,,,,,,,,,,,,,,,,,,,,,,,,,,,,,,,,
,3883336364.27023,200.158729553223,70000.46875,-0.00096817048269229,1.90271700128375E-7,1,4,13.4005146026611,5.00410919175105,30.5599998682737,-1.20473164207088,-0.180508420733933,1,-2.26363579837212E-7,,,,,,,,,,,,,,,,,,,,,200.151931762695,200.16552734375,70000.46875,70000.46875,53.2488336868614,5.64791920508068,5.11194944381714,54,2,0,0,1,0.305404663085937,33.7243423461914,1,1,3,200.151931762695,0,200.158729553223,,,,,,,,,,,,,,,,,,,,,,,,,,,,,,,,,