File: SQUID/23006_LCOS/transfer_119973_files_84937504/23006_LCOS_MT_FC_p0.5T.dat
[Header]
; MPMS3 Data File (default extension .dat)
; Copyright (c) 2007, Quantum Design, Inc. All rights reserved.
TITLE,
FILEOPENTIME,3883315512.21822,01/19/2023,6:49 pm
BYAPP,SQUID AC,0.9.1.0
INFO,MPMS3 Measurement Release 1.1.16 Build 347, MultiVu Release 2.3.3.2,APPNAME
INFO,0,MOMENT_UNITS
INFO,LSAT//LCO,SAMPLE_MATERIAL
INFO,,SAMPLE_COMMENT
INFO,,SAMPLE_MASS
INFO,,SAMPLE_VOLUME
INFO,,SAMPLE_MOLECULAR_WEIGHT
INFO,,SAMPLE_SIZE
INFO,,SAMPLE_SHAPE
INFO,Quartz,SAMPLE_HOLDER
INFO,Standard,SAMPLE_HOLDER_DETAIL
INFO,65.59,SAMPLE_OFFSET
DATATYPE,COMMENT,1
DATATYPE,TIME,2
STARTUPAXIS,X,2
STARTUPAXIS,Y1,5
FIELDGROUP, VSM,2,3,4,5,6,8,9,10,11,14,15
FIELDGROUP, DC, 2,3,4,14,56,57,58,59,60,61,62,63,64,65,66,67,68,69
FIELDGROUP, AC, 2,3,4,11,16,17,18,19,20,21,22,23,24,25,26,27,28,29,30
STARTUPGROUP, All
[Data]
Comment,Time Stamp (sec),Temperature (K),Magnetic Field (Oe),Moment (emu),M. Std. Err. (emu),Transport Action,Averaging Time (sec),Frequency (Hz),Peak Amplitude (mm),Center Position (mm),Lockin Signal' (V),Lockin Signal (V),Range,M. Quad. Signal (emu),AC Moment (emu),AC M. Std Err. (emu),AC Phase (deg),AC Phase Std. Err. (deg),AC Susceptibility (emu/Oe),AC Suscept. Std Err. (emu/Oe),AC X' (emu/Oe),AC X' Std Err. (emu/Oe),AC X'' (emu/Oe),AC X'' Std Err. (emu/Oe),AC Drive (Oe),AC Frequency (Hz),AC Averaging Time (sec),AC Cycles,AC Range,AC Measure Type,AC Signal' (V),AC Signal'' (V),AC Trim Coil Ratio,AC Trim Coil Phase,Min. Temperature (K),Max. Temperature (K),Min. Field (Oe),Max. Field (Oe),Mass (grams),Motor Lag (deg),Pressure (Torr),Measure Count,Measurement Number,SQUID Status (code),Motor Status (code),Measure Status (code),Motor Current (amps),Motor Temp. (C),Temp. Status (code),Field Status (code),Chamber Status (code),Chamber Temp (K),Redirection State,Average Temp (K),Rotation Angle (deg),Rotator state,DC Moment Fixed Ctr (emu),DC Moment Err Fixed Ctr (emu),DC Moment Free Ctr (emu),DC Moment Err Free Ctr (emu),DC Fixed Fit,DC Free Fit,DC Calculated Center (mm),DC Calculated Center Err (mm),DC Scan Length (mm),DC Scan Time (s),DC Number of Points,DC Squid Drift,DC Min V (V),DC Max V (V),DC Scans per Measure,Map 01,Map 02,Map 03,Map 04,Map 05,Map 06,Map 07,Map 08,Map 09,Map 10,Map 11,Map 12,Map 13,Map 14,Map 15,Map 16
,3883315538.86489,399.993789672852,4999.71533203125,9.21396470803803E-5,2.08167585262094E-8,1,4,13.4005146026611,4.97787524512618,30.8999996632338,0.113829702221994,0.0169303277759798,1,-7.75162931630658E-8,,,,,,,,,,,,,,,,,,,,,399.993194580078,399.994384765625,4999.71533203125,4999.71533203125,53.4903568993037,5.6287867329925,5.25123643875122,54,1,0,0,1,0.29541015625,31.7693061828613,1,1,3,399.994384765625,0,399.993789672852,,,,,,,,,,,,,,,,,,,,,,,,,,,,,,,,,
,3883315598.07495,398.437515258789,4999.71533203125,9.18318820564882E-5,1.17968746516366E-8,1,4,13.4005146026611,4.98691695830009,30.8999996632338,0.113748777274246,0.0168499809606595,1,-1.31217168817128E-7,,,,,,,,,,,,,,,,,,,,,398.350555419922,398.524475097656,4999.71533203125,4999.71533203125,53.6666141303903,5.6387435839734,5.26831245422363,54,1,0,0,1,0.295486450195313,32.7468223571777,2,1,3,398.350555419922,0,398.437515258789,,,,,,,,,,,,,,,,,,,,,,,,,,,,,,,,,
,3883315658.59761,393.865859985352,4999.71533203125,9.2188194186506E-5,8.47371640680973E-9,1,4,13.4005146026611,4.98667187575195,30.8800004422665,0.114185346851653,0.016893545483065,1,-1.48400917672461E-7,,,,,,,,,,,,,,,,,,,,,393.673400878906,394.058319091797,4999.71533203125,4999.71533203125,53.3848370492076,5.63888363346652,5.27774667739868,54,1,0,0,1,0.297088623046875,34.2131004333496,2,1,3,393.673400878906,0,393.865859985352,,,,,,,,,,,,,,,,,,,,,,,,,,,,,,,,,
,3883315719.06363,387.291534423828,4999.71533203125,9.2638500327943E-5,1.16723621432918E-8,1,4,13.4005146026611,4.98642075156554,30.8800004422665,0.114735154425894,0.0169738154827379,1,-1.49973744367081E-7,,,,,,,,,,,,,,,,,,,,,387.025299072266,387.557769775391,4999.71533203125,4999.71533203125,53.6482458601884,5.6402163372596,5.29570960998535,53,1,64,0,0,0.296859741210937,32.7468223571777,2,1,3,387.025299072266,0,387.291534423828,,,,,,,,,,,,,,,,,,,,,,,,,,,,,,,,,
,3883315779.43203,380.092361450195,4999.71533203125,9.31420241801631E-5,1.13487082520565E-8,1,4,13.4005146026611,4.98604286770595,30.859999358654,0.115346127546182,0.0170668883927862,1,-1.48666338690453E-7,,,,,,,,,,,,,,,,,,,,,379.883697509766,380.301025390625,4999.71533203125,4999.71533203125,53.5306107680441,5.64213149301827,5.30429315567017,54,1,0,0,1,0.297470092773438,33.2355842590332,2,1,3,379.883697509766,0,380.092361450195,,,,,,,,,,,,,,,,,,,,,,,,,,,,,,,,,
,3883315839.85186,374.910003662109,4999.71533203125,9.3410913544576E-5,1.1072715192385E-8,1,4,13.4005146026611,4.98602076039566,30.859999358654,0.115679142040374,0.0171110781699419,1,-1.53112809680686E-7,,,,,,,,,,,,,,,,,,,,,374.732360839844,375.087646484375,4999.71533203125,4999.71533203125,53.5614850945537,5.64178939957594,5.31210231781006,54,1,0,0,1,0.297393798828125,33.2355842590332,2,1,3,374.732360839844,0,374.910003662109,,,,,,,,,,,,,,,,,,,,,,,,,,,,,,,,,
,3883315900.3245,370.09797668457,4999.71533203125,9.36841452516111E-5,9.82408197941651E-9,1,4,13.4005146026611,4.98590058902627,30.850000679493,0.116012135611334,0.0171702547168747,1,-1.45720980038266E-7,,,,,,,,,,,,,,,,,,,,,369.925262451172,370.270690917969,4999.71533203125,4999.71533203125,53.577508479198,5.64241381455522,5.31811809539795,54,1,0,0,1,0.297698974609375,33.2355842590332,2,1,3,369.925262451172,0,370.09797668457,,,,,,,,,,,,,,,,,,,,,,,,,,,,,,,,,
,3883315960.76945,365.235412597656,4999.71533203125,9.39463183539501E-5,8.46271886373773E-9,1,4,13.4005146026611,4.98595638200294,30.8299995958805,0.116339374112304,0.0172135281809687,1,-1.50205607089515E-7,,,,,,,,,,,,,,,,,,,,,365.051483154297,365.419342041016,4999.71533203125,4999.71533203125,53.6357398038807,5.64132356187816,5.32139539718628,54,1,0,0,1,0.297622680664063,33.2355842590332,2,1,3,365.051483154297,0,365.235412597656,,,,,,,,,,,,,,,,,,,,,,,,,,,,,,,,,
,3883316021.21378,360.232528686523,4999.71533203125,9.41549018594823E-5,8.92619118249964E-9,1,4,13.4005146026611,4.98598140594181,30.8299995958805,0.116597570800399,0.0172580551288396,1,-1.45541559755989E-7,,,,,,,,,,,,,,,,,,,,,360.097137451172,360.367919921875,4999.71533203125,4999.71533203125,53.4614366440922,5.64122460907159,5.3138747215271,54,1,0,0,1,0.297317504882812,33.2355842590332,2,1,3,360.097137451172,0,360.232528686523,,,,,,,,,,,,,,,,,,,,,,,,,,,,,,,,,
,3883316081.67897,355.153228759766,4999.71533203125,9.4450588164028E-5,1.19945580756145E-8,1,4,13.4005146026611,4.98599747319406,30.8100003749132,0.116964777326572,0.0173089078730731,1,-1.48763481233081E-7,,,,,,,,,,,,,,,,,,,,,354.982971191406,355.323486328125,4999.71533203125,4999.71533203125,53.430171503323,5.64170020562354,5.31660079956055,54,1,0,0,1,0.297393798828125,33.2355842590332,2,1,3,354.982971191406,0,355.153228759766,,,,,,,,,,,,,,,,,,,,,,,,,,,,,,,,,
,3883316142.09,350.146957397461,4999.71533203125,9.46841386727408E-5,1.11033948843564E-8,1,4,13.4005146026611,4.98594444038937,30.8100003749132,0.117252656369488,0.0173487330329281,1,-1.51325236263262E-7,,,,,,,,,,,,,,,,,,,,,349.988708496094,350.305206298828,4999.71533203125,4999.71533203125,53.6439469033326,5.64177382947287,5.31436777114868,54,1,0,0,1,0.29815673828125,33.2355842590332,2,1,3,349.988708496094,0,350.146957397461,,,,,,,,,,,,,,,,,,,,,,,,,,,,,,,,,
,3883316202.51517,345.169723510742,4999.71533203125,9.493954032827E-5,8.84336566105353E-9,1,4,13.4005146026611,4.98595871147295,30.8100003749132,0.117569609158197,0.0173942446760914,1,-1.52827698958924E-7,,,,,,,,,,,,,,,,,,,,,344.985626220703,345.353820800781,4999.71533203125,4999.71533203125,53.5130241263614,5.64181750893713,5.31773567199707,54,1,0,0,1,0.296783447265625,33.2355842590332,2,1,3,344.985626220703,0,345.169723510742,,,,,,,,,,,,,,,,,,,,,,,,,,,,,,,,,
,3883316262.9616,340.160552978516,4999.71533203125,9.52056026957933E-5,1.29484071631884E-8,1,4,13.4005146026611,4.98592570476231,30.7899992913008,0.117897593426295,0.0174455217671034,1,-1.51081024863474E-7,,,,,,,,,,,,,,,,,,,,,339.992889404297,340.328216552734,4999.71533203125,4999.71533203125,53.6670049446499,5.64143375094831,5.31338453292847,54,1,0,0,1,0.297622680664063,33.7243423461914,2,1,3,339.992889404297,0,340.160552978516,,,,,,,,,,,,,,,,,,,,,,,,,,,,,,,,,
,3883316323.93346,335.112411499023,4999.71533203125,9.54650919897953E-5,1.48376722289975E-8,1,4,13.4005146026611,4.98614992241192,30.7800006121397,0.118217918091308,0.0175507922981539,1,-1.05764038286304E-7,,,,,,,,,,,,,,,,,,,,,335.013793945313,335.211029052734,4999.71533203125,4999.71533203125,53.6095552484864,5.64148620278487,5.31101703643799,52,1,64,0,0,0.297164916992188,33.2355842590332,2,1,3,335.013793945313,0,335.112411499023,,,,,,,,,,,,,,,,,,,,,,,,,,,,,,,,,
,3883316383.83887,330.105224609375,4999.71533203125,9.5722861587698E-5,1.33618270737219E-8,1,4,13.4005146026611,4.98590426044937,30.7800006121397,0.118535703981825,0.0175516996949461,1,-1.42612247911959E-7,,,,,,,,,,,,,,,,,,,,,329.931243896484,330.279205322266,4999.71533203125,4999.71533203125,53.4837130568903,5.64161467793497,5.30970525741577,54,1,0,0,1,0.2972412109375,33.2355842590332,2,1,3,329.931243896484,0,330.105224609375,,,,,,,,,,,,,,,,,,,,,,,,,,,,,,,,,
,3883316444.34419,325.071823120117,4999.71533203125,9.5979307166748E-5,7.47729237406708E-9,1,4,13.4005146026611,4.98623961938033,30.7599995285273,0.118863455836087,0.0176072190761896,1,-1.37472108468455E-7,,,,,,,,,,,,,,,,,,,,,324.920837402344,325.222808837891,4999.71533203125,4999.71533203125,53.4837130568903,5.64027082271464,5.30496168136597,53,1,64,0,0,0.298080444335937,33.2355842590332,2,1,3,324.920837402344,0,325.071823120117,,,,,,,,,,,,,,,,,,,,,,,,,,,,,,,,,
,3883316504.75148,320.045639038086,4999.71533203125,9.61943926308576E-5,1.13191227720966E-8,1,4,13.4005146026611,4.986074788127,30.7599995285273,0.119125600322464,0.0176371680831599,1,-1.4479883822876E-7,,,,,,,,,,,,,,,,,,,,,319.862457275391,320.228820800781,4999.71533203125,4999.71533203125,53.6564529596403,5.64077241964319,5.30394172668457,54,1,0,0,1,0.297164916992188,33.2355842590332,2,1,3,319.862457275391,0,320.045639038086,,,,,,,,,,,,,,,,,,,,,,,,,,,,,,,,,
,3883316565.53518,314.967147827148,4999.71533203125,9.64459280284866E-5,1.24148116521477E-8,1,4,13.4005146026611,4.98595805084583,30.74000030756,0.119432426957629,0.0176877113716255,1,-1.41134749791712E-7,,,,,,,,,,,,,,,,,,,,,314.809020996094,315.125274658203,4999.71533203125,4999.71533203125,53.4942650418999,5.64324540212276,5.30238437652588,52,1,64,0,0,0.2972412109375,33.2355842590332,2,1,3,314.809020996094,0,314.967147827148,,,,,,,,,,,,,,,,,,,,,,,,,,,,,,,,,
,3883316625.61476,309.972671508789,4999.71533203125,9.66691828589056E-5,8.84767431931088E-9,1,4,13.4005146026611,4.98602135129131,30.74000030756,0.119713611051876,0.0177116703562395,1,-1.55435069203114E-7,,,,,,,,,,,,,,,,,,,,,309.772766113281,310.172576904297,4999.71533203125,4999.71533203125,53.6044746631114,5.6412449974873,5.2942910194397,54,1,0,0,1,0.297470092773438,33.7243423461914,2,1,3,309.772766113281,0,309.972671508789,,,,,,,,,,,,,,,,,,,,,,,,,,,,,,,,,
,3883316686.17234,304.947738647461,4999.71533203125,9.68644781500253E-5,1.30453385855196E-8,1,4,13.4005146026611,4.98616043854439,30.74000030756,0.119957384849405,0.0177666642188029,1,-1.40793040479796E-7,,,,,,,,,,,,,,,,,,,,,304.817749023438,305.077728271484,4999.71533203125,4999.71533203125,53.6275327044288,5.6417062056277,5.29040050506592,53,1,64,0,0,0.296707153320313,33.7243423461914,2,1,3,304.817749023438,0,304.947738647461,,,,,,,,,,,,,,,,,,,,,,,,,,,,,,,,,
,3883316746.51317,299.870361328125,4999.71533203125,9.70841159750577E-5,1.02197272708982E-8,1,4,13.4005146026611,4.98615867709673,30.7199992239475,0.120225288561879,0.0178339282187575,1,-1.19315502273203E-7,,,,,,,,,,,,,,,,,,,,,299.707336425781,300.033386230469,4999.71533203125,4999.71533203125,53.5767268506787,5.64066516508244,5.28607130050659,54,1,0,0,1,0.29693603515625,33.2355842590332,2,1,3,299.695220947266,0,299.870361328125,,,,,,,,,,,,,,,,,,,,,,,,,,,,,,,,,
,3883316807.02307,294.883316040039,4999.71533203125,9.73034321698618E-5,1.22403659187602E-8,1,4,13.4005146026611,4.98606354307276,30.7199992239475,0.12050005107473,0.017830993917081,1,-1.54108397359509E-7,,,,,,,,,,,,,,,,,,,,,294.732147216797,295.034484863281,4999.71533203125,4999.71533203125,53.6001757062557,5.6409692923112,5.28242588043213,53,1,64,0,0,0.298385620117188,33.7243423461914,2,1,3,294.717346191406,0,294.883316040039,,,,,,,,,,,,,,,,,,,,,,,,,,,,,,,,,
,3883316867.39863,290.025177001953,4999.71533203125,9.75778402854104E-5,7.02036053353252E-9,1,4,13.4005146026611,4.98600355348452,30.7199992239475,0.120834332805595,0.0179044056671242,1,-1.35620312447222E-7,,,,,,,,,,,,,,,,,,,,,289.861206054687,290.189147949219,4999.71533203125,4999.71533203125,53.5435076386114,5.64118123064626,5.26809215545654,54,1,0,0,1,0.29754638671875,33.2355842590332,2,1,3,289.861206054687,0,290.025177001953,,,,,,,,,,,,,,,,,,,,,,,,,,,,,,,,,
,3883316927.84523,284.980239868164,4999.71533203125,9.80283176008475E-5,9.357992513175E-9,1,4,13.4005146026611,4.98603426906631,30.7000000029802,0.121394877768983,0.0179761686560643,1,-1.45171288815044E-7,,,,,,,,,,,,,,,,,,,,,284.8388671875,285.121612548828,4999.71533203125,4999.71533203125,53.5536688093614,5.64129847306143,5.24682712554932,54,1,0,0,1,0.297088623046875,33.2355842590332,2,1,3,284.8388671875,0,284.980239868164,,,,,,,,,,,,,,,,,,,,,,,,,,,,,,,,,
,3883316988.28265,279.898391723633,4999.71533203125,9.826358058332E-5,7.2541500385077E-9,1,4,13.4005146026611,4.9860645510181,30.7000000029802,0.121689362664668,0.0180053805806318,1,-1.5689473609505E-7,,,,,,,,,,,,,,,,,,,,,279.722534179687,280.074249267578,4999.71533203125,4999.71533203125,53.5145873833999,5.6413095257657,5.2252984046936,54,1,0,0,1,0.2972412109375,32.7468223571777,2,1,3,279.722534179687,0,279.898391723633,,,,,,,,,,,,,,,,,,,,,,,,,,,,,,,,,
,3883317048.74207,274.88069152832,4999.71533203125,9.85086211695097E-5,8.05749899892739E-9,1,4,13.4005146026611,4.98604903515326,30.7000000029802,0.121991478911202,0.0180556094788033,1,-1.52918365117657E-7,,,,,,,,,,,,,,,,,,,,,274.715942382813,275.045440673828,4999.71533203125,4999.71533203125,53.5849339501307,5.64134400010942,5.20942211151123,54,1,0,0,1,0.297088623046875,33.7243423461914,2,1,3,274.715942382813,0,274.88069152832,,,,,,,,,,,,,,,,,,,,,,,,,,,,,,,,,
,3883317109.16885,269.865768432617,4999.71533203125,9.87652920666588E-5,9.40944661255662E-9,1,4,13.4005146026611,4.98606499017277,30.6800007820129,0.122306367250752,0.018126250674788,1,-1.34324155176511E-7,,,,,,,,,,,,,,,,,,,,,269.681182861328,270.050354003906,4999.71533203125,4999.71533203125,53.6924078715249,5.64108190113332,5.18699836730957,54,1,0,0,1,0.297775268554687,33.7243423461914,2,1,3,269.681182861328,0,269.865768432617,,,,,,,,,,,,,,,,,,,,,,,,,,,,,,,,,
,3883317169.62615,264.84992980957,4999.71533203125,9.90122388389562E-5,1.12619524134697E-8,1,4,13.4005146026611,4.98611893997347,30.6800007820129,0.122616998957821,0.0181520378526201,1,-1.50660369526463E-7,,,,,,,,,,,,,,,,,,,,,264.678192138672,265.021667480469,4999.71533203125,4999.71533203125,53.4966099274576,5.64111495737721,5.17202520370483,54,1,0,0,1,0.297927856445313,33.2355842590332,2,1,3,264.678192138672,0,264.84992980957,,,,,,,,,,,,,,,,,,,,,,,,,,,,,,,,,
,3883317230.05894,259.788879394531,4999.71533203125,9.92359235705894E-5,8.7567548748602E-9,1,4,13.4005146026611,4.98608147260884,30.6700002402067,0.122889560454722,0.0182139450459629,1,-1.33966245076965E-7,,,,,,,,,,,,,,,,,,,,,259.612854003906,259.964904785156,4999.71533203125,4999.71533203125,53.3348128239768,5.64093689753457,5.15483045578003,54,1,0,0,1,0.297927856445313,33.2355842590332,2,1,3,259.612854003906,0,259.788879394531,,,,,,,,,,,,,,,,,,,,,,,,,,,,,,,,,
,3883317290.77763,254.756233215332,4999.71533203125,9.94703855235642E-5,8.22893146556607E-9,1,4,13.4005146026611,4.98608523874046,30.6599996984005,0.12317549506999,0.0182873710270274,1,-1.0975094755222E-7,,,,,,,,,,,,,,,,,,,,,254.594085693359,254.918380737305,4999.71533203125,4999.71533203125,53.5845431358711,5.64226681255782,5.13334846496582,53,1,64,0,0,0.297088623046875,33.2355842590332,2,1,3,254.594085693359,0,254.756233215332,,,,,,,,,,,,,,,,,,,,,,,,,,,,,,,,,
,3883317350.9423,249.772590637207,4999.71533203125,9.96725321836457E-5,7.93799518653767E-9,1,4,13.4005146026611,4.98610629160694,30.6599996984005,0.123432889271283,0.0182822463240708,1,-1.44217426456627E-7,,,,,,,,,,,,,,,,,,,,,249.609268188477,249.935913085938,4999.71533203125,4999.71533203125,53.6681773874288,5.64092559020589,5.11803340911865,54,1,0,0,1,0.297470092773438,33.2355842590332,2,1,3,249.609268188477,0,249.772590637207,,,,,,,,,,,,,,,,,,,,,,,,,,,,,,,,,
,3883317411.44588,244.71167755127,4999.71533203125,9.98885624710168E-5,1.01168092321463E-8,1,4,13.4005146026611,4.9861284889206,30.6499991565943,0.123703873314456,0.0183040492882613,1,-1.59016747126257E-7,,,,,,,,,,,,,,,,,,,,,244.579895019531,244.843460083008,4999.71533203125,4999.71533203125,53.5681289369672,5.64077651106567,5.10677766799927,54,1,0,0,1,0.2972412109375,33.2355842590332,2,1,3,244.579895019531,0,244.71167755127,,,,,,,,,,,,,,,,,,,,,,,,,,,,,,,,,
,3883317472.43846,239.555725097656,4999.71533203125,0.000100105974638546,1.38185263929363E-8,1,4,13.4005146026611,4.98627085569157,30.629999935627,0.123978230475847,0.0183436528342449,1,-1.60146817076802E-7,,,,,,,,,,,,,,,,,,,,,239.443237304687,239.668212890625,4999.71533203125,4999.71533203125,53.6603611022364,5.64234377595614,5.09156560897827,52,1,64,0,0,0.298004150390625,33.2355842590332,2,1,3,239.443237304687,0,239.555725097656,,,,,,,,,,,,,,,,,,,,,,,,,,,,,,,,,
,3883317532.30883,234.592094421387,4999.71533203125,0.000100302649109,8.87653551900163E-9,1,4,13.4005146026611,4.98612081150328,30.629999935627,0.12421727954228,0.0183741277916794,1,-1.64328953352958E-7,,,,,,,,,,,,,,,,,,,,,234.428939819336,234.755249023438,4999.71533203125,4999.71533203125,53.5251393684095,5.64071949651783,5.07017230987549,54,1,0,0,1,0.297698974609375,33.2355842590332,2,1,3,234.428939819336,0,234.592094421387,,,,,,,,,,,,,,,,,,,,,,,,,,,,,,,,,
,3883317592.77464,229.611137390137,4999.71533203125,0.000100479271381427,1.1121153509526E-8,1,4,13.4005146026611,4.98613468704193,30.629999935627,0.124435229374968,0.0184150390543027,1,-1.57765591586954E-7,,,,,,,,,,,,,,,,,,,,,229.454467773438,229.767807006836,4999.71533203125,4999.71533203125,53.4872303852268,5.64054992442488,5.06477451324463,54,1,0,0,1,0.297012329101562,33.2355842590332,2,1,3,229.454467773438,0,229.611137390137,,,,,,,,,,,,,,,,,,,,,,,,,,,,,,,,,
,3883317653.16717,224.586975097656,4999.71533203125,0.000100675760884757,9.56566748623221E-9,1,4,13.4005146026611,4.98621851749397,30.629999935627,0.124682150216588,0.0184471739459346,1,-1.61556077598447E-7,,,,,,,,,,,,,,,,,,,,,224.419357299805,224.754592895508,4999.71533203125,4999.71533203125,53.5329556536018,5.64032436425326,5.04704475402832,54,1,0,0,1,0.297393798828125,33.2355842590332,2,1,3,224.419357299805,0,224.586975097656,,,,,,,,,,,,,,,,,,,,,,,,,,,,,,,,,
,3883317713.72611,219.599395751953,4999.71533203125,0.000100853402365311,1.12517405422258E-8,1,4,13.4005146026611,4.9862586297541,30.6100007146597,0.124890447459262,0.0185675866094963,1,-9.10476813297237E-8,,,,,,,,,,,,,,,,,,,,,219.414245605469,219.784545898438,4999.71533203125,4999.71533203125,53.4192287040537,5.64064291868964,5.02874183654785,53,1,64,0,0,0.2972412109375,33.2355842590332,2,1,3,219.414245605469,0,219.599395751953,,,,,,,,,,,,,,,,,,,,,,,,,,,,,,,,,
,3883317774.05553,214.41975402832,4999.71533203125,0.000101019878808648,1.07209048368223E-8,1,4,13.4005146026611,4.98627708954064,30.6100007146597,0.125107033826001,0.0185329353705292,1,-1.4401511588037E-7,,,,,,,,,,,,,,,,,,,,,214.251998901367,214.587509155273,4999.71533203125,4999.71533203125,53.409849161823,5.6402819825656,5.02004814147949,54,1,0,0,1,0.297012329101562,33.2355842590332,2,1,3,214.251998901367,0,214.41975402832,,,,,,,,,,,,,,,,,,,,,,,,,,,,,,,,,
,3883317834.54428,209.381401062012,4999.71533203125,0.000101103524094542,1.3741851926718E-8,1,4,13.4005146026611,4.98628664794521,30.6100007146597,0.125212473754311,0.0185382122783233,1,-1.52306347858102E-7,,,,,,,,,,,,,,,,,,,,,209.223785400391,209.539016723633,4999.71533203125,4999.71533203125,53.3969522912557,5.63972158453001,4.99818801879883,54,1,0,0,1,0.297317504882812,32.7468223571777,2,1,3,209.223785400391,0,209.381401062012,,,,,,,,,,,,,,,,,,,,,,,,,,,,,,,,,
,3883317894.95105,204.403923034668,4999.71533203125,0.000101270846758642,1.39525155361101E-8,1,4,13.4005146026611,4.98623147657887,30.5899996310473,0.125418541116521,0.018563312790071,1,-1.56832009076198E-7,,,,,,,,,,,,,,,,,,,,,204.234634399414,204.573211669922,4999.71533203125,4999.71533203125,53.5200587830345,5.63982513898561,4.98188495635986,54,1,0,0,1,0.297012329101562,33.2355842590332,2,1,3,204.234634399414,0,204.403923034668,,,,,,,,,,,,,,,,,,,,,,,,,,,,,,,,,
,3883317955.37296,199.41911315918,4999.71533203125,0.000101435377815715,1.20708446405774E-8,1,4,13.4005146026611,4.98620424411662,30.5899996310473,0.125618940888512,0.0186093790001316,1,-1.44124330184518E-7,,,,,,,,,,,,,,,,,,,,,199.225219726562,199.613006591797,4999.71533203125,4999.71533203125,53.6294867757268,5.63966711918783,4.97296905517578,54,1,0,0,1,0.29754638671875,33.7243423461914,2,1,3,199.225219726562,0,199.41911315918,,,,,,,,,,,,,,,,,,,,,,,,,,,,,,,,,
,3883318015.8155,194.377807617187,4999.71533203125,0.000101602667130542,1.26973074143911E-8,1,4,13.4005146026611,4.98617123216712,30.5899996310473,0.125827387439007,0.0186235754488759,1,-1.57544257770017E-7,,,,,,,,,,,,,,,,,,,,,194.215072631836,194.540542602539,4999.71533203125,4999.71533203125,53.4848854996691,5.63967291954237,4.95147228240967,54,1,0,0,1,0.29754638671875,32.7468223571777,2,1,3,194.215072631836,0,194.377807617187,,,,,,,,,,,,,,,,,,,,,,,,,,,,,,,,,
,3883318076.25583,189.304054260254,4999.71533203125,0.00010180124977795,1.2834484366078E-8,1,4,13.4005146026611,4.98615810057681,30.57000041008,0.126072803206347,0.0186602303658965,1,-1.5759047763566E-7,,,,,,,,,,,,,,,,,,,,,189.15625,189.451858520508,4999.71533203125,4999.71533203125,53.5239669256307,5.63970605892012,4.93478631973267,54,1,0,0,1,0.296630859375,33.2355842590332,2,1,3,189.15625,0,189.304054260254,,,,,,,,,,,,,,,,,,,,,,,,,,,,,,,,,
,3883318136.71722,184.40892791748,4999.71533203125,0.000101951887934983,1.28809087065914E-8,1,4,13.4005146026611,4.98613756396575,30.57000041008,0.126260462759225,0.018675464859787,1,-1.67733489113894E-7,,,,,,,,,,,,,,,,,,,,,184.249496459961,184.568359375,4999.71533203125,4999.71533203125,53.5966583779191,5.63976962530788,4.92964458465576,54,1,0,0,1,0.297317504882812,33.7243423461914,2,1,3,184.249496459961,0,184.40892791748,,,,,,,,,,,,,,,,,,,,,,,,,,,,,,,,,
,3883318197.14211,179.385894775391,4999.71533203125,0.000102079429825223,1.35021258731904E-8,1,4,13.4005146026611,4.98612528461637,30.57000041008,0.126418220925897,0.0186971396613467,1,-1.6925469030816E-7,,,,,,,,,,,,,,,,,,,,,179.212493896484,179.559295654297,4999.71533203125,4999.71533203125,53.4801957285537,5.63995768696957,4.9097728729248,54,1,0,0,1,0.297088623046875,33.7243423461914,2,1,3,179.212493896484,0,179.385894775391,,,,,,,,,,,,,,,,,,,,,,,,,,,,,,,,,
,3883318257.62485,174.326972961426,4999.71533203125,0.000102235661586898,1.09471756414487E-8,1,4,13.4005146026611,4.98613710362152,30.57000041008,0.126611572265162,0.0187295055874097,1,-1.6653516441356E-7,,,,,,,,,,,,,,,,,,,,,174.172500610352,174.4814453125,4999.71533203125,4999.71533203125,53.4887936422653,5.64055234368956,4.9001636505127,54,1,0,0,1,0.297698974609375,33.7243423461914,2,1,3,174.172500610352,0,174.326972961426,,,,,,,,,,,,,,,,,,,,,,,,,,,,,,,,,
,3883318318.03489,169.339210510254,4999.71533203125,0.000102420092547898,1.21485579390137E-8,1,4,13.4005146026611,4.98591916916307,30.5499993264675,0.126832755497303,0.0187584374679362,1,-1.69828603367327E-7,,,,,,,,,,,,,,,,,,,,,169.185104370117,169.493316650391,4999.71533203125,4999.71533203125,53.4610458298326,5.64067339229454,4.88157606124878,54,1,0,0,1,0.297393798828125,33.7243423461914,2,1,3,169.185104370117,0,169.339210510254,,,,,,,,,,,,,,,,,,,,,,,,,,,,,,,,,
,3883318378.49,164.28662109375,4999.71533203125,0.000102546197266155,1.13456579612144E-8,1,4,13.4005146026611,4.9860655847415,30.5499993264675,0.126994739954775,0.0187783551371098,1,-1.73229871132588E-7,,,,,,,,,,,,,,,,,,,,,164.118850708008,164.454391479492,4999.71533203125,4999.71533203125,53.6197164192364,5.64009185213767,4.86531925201416,54,1,0,0,1,0.298004150390625,32.7468223571777,2,1,3,164.118850708008,0,164.28662109375,,,,,,,,,,,,,,,,,,,,,,,,,,,,,,,,,
,3883318438.92749,159.286651611328,4999.71533203125,0.000102804630735622,6.13022618606973E-9,1,4,13.4005146026611,4.98608211992189,30.5499993264675,0.127315324454791,0.0188261385426092,1,-1.73366574803801E-7,,,,,,,,,,,,,,,,,,,,,159.09814453125,159.475158691406,4999.71533203125,4999.71533203125,53.4458040737076,5.64023173078414,4.85579776763916,54,1,0,0,1,0.297470092773438,32.2580642700195,2,1,3,159.09814453125,0,159.286651611328,,,,,,,,,,,,,,,,,,,,,,,,,,,,,,,,,
,3883318499.3545,154.213134765625,4999.71533203125,0.00010297016154237,9.50471822178331E-9,1,4,13.4005146026611,4.98617816810117,30.5400006473064,0.127524710151264,0.018850652441642,1,-1.7874082079369E-7,,,,,,,,,,,,,,,,,,,,,154.044891357422,154.381378173828,4999.71533203125,4999.71533203125,53.4262633607268,5.6400339478479,4.84390020370483,54,1,0,0,1,0.297012329101562,33.2355842590332,2,1,3,154.044891357422,0,154.213134765625,,,,,,,,,,,,,,,,,,,,,,,,,,,,,,,,,
,3883318559.81093,149.181716918945,4999.71533203125,0.000103080690306003,1.20864909292568E-8,1,4,13.4005146026611,4.98613357436912,30.5400006473064,0.127658978711633,0.0188774409647272,1,-1.73447914184109E-7,,,,,,,,,,,,,,,,,,,,,149.001754760742,149.361679077148,4999.71533203125,4999.71533203125,53.4501030305633,5.63980718853174,4.83177614212036,54,1,0,0,1,0.29754638671875,33.2355842590332,2,1,3,149.001754760742,0,149.181716918945,,,,,,,,,,,,,,,,,,,,,,,,,,,,,,,,,
,3883318620.23839,144.110855102539,4999.71533203125,0.000103245957889199,9.50159909084074E-9,1,4,13.4005146026611,4.98605992292753,30.519999563694,0.127861604546471,0.0189032956688651,1,-1.76972482091907E-7,,,,,,,,,,,,,,,,,,,,,143.936492919922,144.285217285156,4999.71533203125,4999.71533203125,53.3695952930826,5.63976756832858,4.81383800506592,54,1,0,0,1,0.297470092773438,33.2355842590332,2,1,3,143.936492919922,0,144.110855102539,,,,,,,,,,,,,,,,,,,,,,,,,,,,,,,,,
,3883318680.70218,139.11156463623,4999.71533203125,0.000103359910862728,1.18687064649505E-8,1,4,13.4005146026611,4.98608063485632,30.519999563694,0.128004118331345,0.0189199468202471,1,-1.80659222722166E-7,,,,,,,,,,,,,,,,,,,,,138.976806640625,139.246322631836,4999.71533203125,4999.71533203125,53.5118516835826,5.64017044054829,4.79684591293335,54,1,0,0,1,0.29754638671875,33.2355842590332,2,1,3,138.976806640625,0,139.11156463623,,,,,,,,,,,,,,,,,,,,,,,,,,,,,,,,,
,3883318741.17286,134.035934448242,4999.71533203125,0.000103502269934272,1.27220064797702E-8,1,4,13.4005146026611,4.9859646096352,30.519999563694,0.128175494474954,0.0189503490825108,1,-1.7690026746155E-7,,,,,,,,,,,,,,,,,,,,,133.862808227539,134.209060668945,4999.71533203125,4999.71533203125,53.4989548130153,5.64055264673481,4.78895568847656,54,1,0,0,1,0.296783447265625,33.7243423461914,2,1,3,133.862808227539,0,134.035934448242,,,,,,,,,,,,,,,,,,,,,,,,,,,,,,,,,
,3883318801.63227,129.036193847656,4999.71533203125,0.000103616360899702,1.41403215498542E-8,1,4,13.4005146026611,4.98591549302196,30.519999563694,0.12831582569858,0.0189655226049274,1,-1.81500096929683E-7,,,,,,,,,,,,,,,,,,,,,128.900100708008,129.172286987305,4999.71533203125,4999.71533203125,53.5313923965634,5.64058017291355,4.76875066757202,54,1,0,0,1,0.296630859375,33.2355842590332,2,1,3,128.900100708008,0,129.036193847656,,,,,,,,,,,,,,,,,,,,,,,,,,,,,,,,,
,3883318862.03559,123.92818069458,4999.71533203125,0.000103784831214976,8.99133468731727E-9,1,4,13.4005146026611,4.98595947477397,30.5000003427267,0.128527164529139,0.0189891110422355,1,-1.87839085975311E-7,,,,,,,,,,,,,,,,,,,,,123.737228393555,124.119132995605,4999.71533203125,4999.71533203125,53.3676412217845,5.64062420483255,4.75383758544922,54,1,0,0,1,0.296630859375,33.2355842590332,2,1,3,123.737228393555,0,123.92818069458,,,,,,,,,,,,,,,,,,,,,,,,,,,,,,,,,
,3883318934.86547,117.92626953125,4999.71533203125,0.000103936838396523,1.26428302394355E-8,1,4,13.4005146026611,4.98587666150773,30.5000003427267,0.128700911998699,0.0190933531056628,1,-1.26021583053491E-7,,,,,,,,,,,,,,,,,,,,,117.814659118652,118.037879943848,4999.71533203125,4999.71533203125,53.5575769519576,5.64152555766396,4.74263381958008,54,1,0,0,1,0.297470092773438,32.7468223571777,2,1,3,117.814659118652,0,117.92626953125,,,,,,,,,,,,,,,,,,,,,,,,,,,,,,,,,
,3883318995.01902,112.935501098633,4999.71533203125,0.000104077572731214,7.21366808257446E-9,1,4,13.4005146026611,4.98580884537788,30.5000003427267,0.128876989516474,0.0190902951307607,1,-1.49250412472444E-7,,,,,,,,,,,,,,,,,,,,,112.761192321777,113.109809875488,4999.71533203125,4999.71533203125,53.3942165914383,5.64177461594909,4.72684240341186,54,1,0,0,1,0.296783447265625,33.2355842590332,2,1,3,112.761192321777,0,112.935501098633,,,,,,,,,,,,,,,,,,,,,,,,,,,,,,,,,
,3883319055.5044,107.899074554443,4999.71533203125,0.000104208075155644,8.39337564927669E-9,1,4,13.4005146026611,4.98573623673001,30.5000003427267,0.129037516417251,0.0191033843324448,1,-1.57884817962085E-7,,,,,,,,,,,,,,,,,,,,,107.744003295898,108.054145812988,4999.71533203125,4999.71533203125,53.4915293420826,5.64180060405898,4.71272087097168,54,1,0,0,1,0.297470092773438,33.7243423461914,2,1,3,107.744003295898,0,107.899074554443,,,,,,,,,,,,,,,,,,,,,,,,,,,,,,,,,
,3883319116.45637,102.814712524414,4999.71533203125,0.000104337299901589,1.41438320684617E-8,1,4,13.4005146026611,4.98566311850788,30.4799992591143,0.129195378340796,0.019123306496494,1,-1.60805904580643E-7,,,,,,,,,,,,,,,,,,,,,102.690635681152,102.938789367676,4999.71533203125,4999.71533203125,53.2937773267172,5.64187879523717,4.68911170959473,52,1,64,0,0,0.299072265625,33.2355842590332,2,1,3,102.690635681152,0,102.814712524414,,,,,,,,,,,,,,,,,,,,,,,,,,,,,,,,,
,3883319176.38919,98.0695304870605,4999.71533203125,0.000104400116038595,1.27382486496897E-8,1,4,13.4005146026611,4.98566077360699,30.4799992591143,0.129273721529444,0.0191304849335175,1,-1.6439402423837E-7,,,,,,,,,,,,,,,,,,,,,97.8805999755859,98.2584609985352,4999.71533203125,4999.71533203125,53.4282174320249,5.64244209241496,4.67918252944946,54,1,0,0,1,0.298309326171875,33.7243423461914,2,1,3,97.8805999755859,0,98.0695304870605,,,,,,,,,,,,,,,,,,,,,,,,,,,,,,,,,
,3883319248.90832,92.0781326293945,4999.71533203125,0.000104509765070027,1.25980774208022E-8,1,4,13.4005146026611,4.98570681017658,30.4799992591143,0.129406981011613,0.0191788331231277,1,-1.41942799780145E-7,,,,,,,,,,,,,,,,,,,,,91.9433670043945,92.2128982543945,4999.71533203125,4999.71533203125,53.4114124188614,5.64183332272827,4.64955615997314,54,1,0,0,1,0.298233032226562,33.2355842590332,2,1,3,91.9433670043945,0,92.0781326293945,,,,,,,,,,,,,,,,,,,,,,,,,,,,,,,,,
,3883319309.3128,87.0046920776367,4999.71533203125,0.000104641341635833,1.26254549780654E-8,1,4,13.4005146026611,4.98572492707451,30.4799992591143,0.129572085882998,0.0191928986707669,1,-1.50343143220453E-7,,,,,,,,,,,,,,,,,,,,,86.82373046875,87.1856536865234,4999.71533203125,4999.71533203125,53.5669564941884,5.64176698264634,4.63716220855713,54,1,0,0,1,0.29815673828125,32.7468223571777,2,1,3,86.82373046875,0,87.0046920776367,,,,,,,,,,,,,,,,,,,,,,,,,,,,,,,,,
,3883319369.78592,81.9801445007324,4999.71533203125,0.000104720462522733,1.74146996264343E-8,1,4,13.4005146026611,4.98571154373026,30.4799992591143,0.129671715964258,0.0191929867917083,1,-1.62049586813737E-7,,,,,,,,,,,,,,,,,,,,,81.8500366210937,82.1102523803711,4999.71533203125,4999.71533203125,53.4082859047845,5.641826572236,4.60927963256836,54,1,0,0,1,0.298004150390625,33.2355842590332,2,1,3,81.8500366210937,0,81.9801445007324,,,,,,,,,,,,,,,,,,,,,,,,,,,,,,,,,
,3883319430.19968,76.9408340454102,4999.71533203125,0.000104940335951394,1.01461923879409E-8,1,4,13.4005146026611,4.98572178231,30.460000038147,0.129945215443307,0.0192275676207268,1,-1.67052736604162E-7,,,,,,,,,,,,,,,,,,,,,76.7755661010742,77.1061019897461,4999.71533203125,4999.71533203125,53.562266723073,5.64229297962847,4.58711385726929,54,1,0,0,1,0.297470092773438,33.2355842590332,2,1,3,76.7755661010742,0,76.9408340454102,,,,,,,,,,,,,,,,,,,,,,,,,,,,,,,,,
,3883319490.65028,71.7984580993652,4999.71533203125,0.000105075916799551,1.10002472477627E-8,1,4,13.4005146026611,4.98573249162264,30.460000038147,0.130112017086016,0.0192623408612839,1,-1.59293033586045E-7,,,,,,,,,,,,,,,,,,,,,71.6335372924805,71.96337890625,4999.71533203125,4999.71533203125,53.396561476996,5.6423682358555,4.56740045547485,54,1,0,0,1,0.297622680664063,33.2355842590332,2,1,3,71.6335372924805,0,71.7984580993652,,,,,,,,,,,,,,,,,,,,,,,,,,,,,,,,,
,3883319551.10935,66.7095413208008,4999.71533203125,0.000105213150518991,1.51101134379606E-8,1,4,13.4005146026611,4.98567550494771,30.460000038147,0.130277694989778,0.0193016640539595,1,-1.47808548056626E-7,,,,,,,,,,,,,,,,,,,,,66.5322570800781,66.8868255615234,4999.71533203125,4999.71533203125,53.2886967413422,5.64259503639196,4.53917503356934,54,1,0,0,1,0.297393798828125,33.2355842590332,2,1,3,66.5322570800781,0,66.7095413208008,,,,,,,,,,,,,,,,,,,,,,,,,,,,,,,,,
,3883319611.5824,61.6570091247559,4999.71533203125,0.000105355635312903,1.38719369707815E-8,1,4,13.4005146026611,4.98575365405944,30.460000038147,0.130459073645557,0.0193143101471408,1,-1.59251189303454E-7,,,,,,,,,,,,,,,,,,,,,61.4817695617676,61.8322486877441,4999.71533203125,4999.71533203125,53.4039869479287,5.6419873223957,4.51012516021729,54,1,0,0,1,0.296707153320313,33.2355842590332,2,1,3,61.4817695617676,0,61.6570091247559,,,,,,,,,,,,,,,,,,,,,,,,,,,,,,,,,
,3883319671.96901,56.4817371368408,4999.71533203125,0.000105527449707882,1.3648710602723E-8,1,4,13.4005146026611,4.98570793830485,30.460000038147,0.130668761103691,0.0193548185370612,1,-1.52031484798051E-7,,,,,,,,,,,,,,,,,,,,,56.2916450500488,56.6718292236328,4999.71533203125,4999.71533203125,53.396561476996,5.64202029511647,4.46985578536987,54,1,0,0,1,0.297622680664063,33.2355842590332,2,1,3,56.2916450500488,0,56.4817371368408,,,,,,,,,,,,,,,,,,,,,,,,,,,,,,,,,
,3883319732.40073,51.4353656768799,4999.71533203125,0.000105786606082573,1.16279131658362E-8,1,4,13.4005146026611,4.9857892138656,30.460000038147,0.130991887749177,0.0194079238454961,1,-1.4826130756229E-7,,,,,,,,,,,,,,,,,,,,,51.2778244018555,51.5929069519043,4999.71533203125,4999.71533203125,53.3617790078903,5.64172050119654,4.42680358886719,54,1,0,0,1,0.2996826171875,33.2355842590332,2,1,3,51.2778244018555,0,51.4353656768799,,,,,,,,,,,,,,,,,,,,,,,,,,,,,,,,,
,3883319804.28458,45.3972282409668,4999.71533203125,0.000106009486496778,1.63070923921044E-8,1,4,13.4005146026611,4.98577196623222,30.460000038147,0.131258896075877,0.0195044696058401,1,-1.03541497260716E-7,,,,,,,,,,,,,,,,,,,,,45.1324653625488,45.6619911193848,4999.71533203125,4999.71533203125,53.2668111428037,5.64133054167432,4.3719310760498,54,1,0,0,1,0.297470092773438,33.2355842590332,2,1,3,45.1324653625488,0,45.3972282409668,,,,,,,,,,,,,,,,,,,,,,,,,,,,,,,,,
,3883319877.56032,39.2143878936768,4999.71533203125,0.000106435776943596,2.02220520900718E-8,1,4,13.4005146026611,4.98597894536256,30.4400008171797,0.131795395612884,0.0195773489472226,1,-1.09364047046155E-7,,,,,,,,,,,,,,,,,,,,,39.0496826171875,39.379093170166,4999.71533203125,4999.71533203125,53.3672504075249,5.64116132784205,4.31236171722412,54,1,0,0,1,0.2984619140625,33.7243423461914,2,1,3,39.0496826171875,0,39.2143878936768,,,,,,,,,,,,,,,,,,,,,,,,,,,,,,,,,
,3883319937.93386,34.1515598297119,4999.71533203125,0.00010682703218759,1.79933692782033E-8,1,4,13.4005146026611,4.98583919371159,30.4400008171797,0.132276904717561,0.0196336161871086,1,-1.2182248847016E-7,,,,,,,,,,,,,,,,,,,,,33.9647903442383,34.3383293151855,4999.71533203125,4999.71533203125,53.4196195183133,5.6410129825967,4.24275064468384,54,1,0,0,1,0.297775268554687,33.7243423461914,2,1,3,33.9647903442383,0,34.1515598297119,,,,,,,,,,,,,,,,,,,,,,,,,,,,,,,,,
,3883320010.45998,28.0867948532104,4999.71533203125,0.000107466966375539,2.05572704971403E-8,1,4,13.4005146026611,4.98577980135832,30.4400008171797,0.133063945163188,0.0197717869733559,1,-1.05679883959414E-7,,,,,,,,,,,,,,,,,,,,,27.9477863311768,28.2258033752441,4999.71533203125,4999.71533203125,53.4665172294672,5.64068118424706,4.13356781005859,54,1,0,0,1,0.298995971679687,32.7468223571777,2,1,3,27.9477863311768,0,28.0867948532104,,,,,,,,,,,,,,,,,,,,,,,,,,,,,,,,,
,3883320070.9915,23.0372982025146,4999.71533203125,0.000108181867198504,2.55289604287881E-8,1,4,13.4005146026611,4.98577363612815,30.4400008171797,0.133947305521736,0.0199138855277765,1,-9.7816238742692E-8,,,,,,,,,,,,,,,,,,,,,22.8619289398193,23.21266746521,4999.71533203125,4999.71533203125,53.5079435409864,5.64152481202873,3.99203896522522,53,1,64,0,0,0.299301147460937,33.2355842590332,2,1,3,22.8619289398193,0,23.0372982025146,,,,,,,,,,,,,,,,,,,,,,,,,,,,,,,,,
,3883320131.36724,18.0048780441284,4999.71533203125,0.000109308364976719,2.23958241764184E-8,1,4,13.4005146026611,4.9858030678805,30.4400008171797,0.135341644993518,0.0201319401269554,1,-9.03334920639269E-8,,,,,,,,,,,,,,,,,,,,,17.8456478118896,18.1641082763672,4999.71533203125,4999.71533203125,53.5595310232557,5.64054499303423,3.75711607933044,54,1,0,0,1,0.298004150390625,33.2355842590332,2,1,3,17.8456478118896,0,18.0048780441284,,,,,,,,,,,,,,,,,,,,,,,,,,,,,,,,,
,3883320211.9266,11.4938712120056,4999.71533203125,0.000112325686341064,1.63161231640319E-8,1,4,13.4005146026611,4.98579691901652,30.4400008171797,0.139071871831671,0.0207241887752306,1,-6.32898514836091E-8,,,,,,,,,,,,,,,,,,,,,11.3328380584717,11.6549043655396,4999.71533203125,4999.71533203125,53.4684713007653,5.64233810622811,3.26415991783142,52,1,68,0,0,0.298614501953125,33.2355842590332,2,1,3,11.3328380584717,0,11.4938712120056,,,,,,,,,,,,,,,,,,,,,,,,,,,,,,,,,
,3883320272.38816,8.48530054092407,4999.71533203125,0.000114973035714934,1.86180714200904E-8,1,4,13.4005146026611,4.98575848099686,30.4400008171797,0.142342335907444,0.0212505932153529,1,-3.39287794912041E-8,,,,,,,,,,,,,,,,,,,,,8.44092273712158,8.52967834472656,4999.71533203125,4999.71533203125,53.4790232857749,5.64288317761592,3.08947730064392,52,1,32,0,0,0.299224853515625,33.2355842590332,6,1,3,8.52967834472656,0,8.48530054092407,,,,,,,,,,,,,,,,,,,,,,,,,,,,,,,,,
,3883320332.80416,9.9443473815918,4999.71533203125,0.00011345614124841,1.93470122857359E-8,1,4,13.4005146026611,4.98577358856595,30.4400008171797,0.140473170804615,0.0209153062058495,1,-7.7913161052504E-8,,,,,,,,,,,,,,,,,,,,,9.89495849609375,9.99373626708984,4999.71533203125,4999.71533203125,53.455574430198,5.64252256018041,3.28144669532776,54,1,0,0,1,0.298004150390625,33.2355842590332,6,1,3,9.99373626708984,0,9.9443473815918,,,,,,,,,,,,,,,,,,,,,,,,,,,,,,,,,
,3883320405.36994,11.5491366386414,4999.71533203125,0.000112287261496304,1.21739103908202E-8,1,4,13.4005146026611,4.98561888777654,30.4400008171797,0.139021073284039,0.0206910692699152,1,-8.34568606975852E-8,,,,,,,,,,,,,,,,,,,,,11.5071496963501,11.5911235809326,4999.71533203125,4999.71533203125,53.420010332573,5.6429205413819,3.45212864875793,54,1,0,0,1,0.2984619140625,33.2355842590332,6,1,3,11.5911235809326,0,11.5491366386414,,,,,,,,,,,,,,,,,,,,,,,,,,,,,,,,,
,3883320465.7863,12.8688583374023,4999.71533203125,0.0001113879749312,1.4736748024245E-8,1,4,13.4005146026611,4.98562107389257,30.4400008171797,0.137908543997742,0.0205201684829958,1,-8.69911638088878E-8,,,,,,,,,,,,,,,,,,,,,12.8208780288696,12.9168386459351,4999.71533203125,4999.71533203125,53.3164445537749,5.64228308010742,3.55413794517517,54,1,0,0,1,0.29815673828125,32.7468223571777,6,1,3,12.9168386459351,0,12.8688583374023,,,,,,,,,,,,,,,,,,,,,,,,,,,,,,,,,
,3883320526.26281,14.1861729621887,4999.71533203125,0.000110775196558304,1.5333365351733E-8,1,4,13.4005146026611,4.98551700029486,30.4400008171797,0.137146590893286,0.0204017461334799,1,-9.05009887594822E-8,,,,,,,,,,,,,,,,,,,,,14.1429986953735,14.2293472290039,4999.71533203125,4999.71533203125,53.5427260100922,5.64327509200153,3.64727997779846,54,1,0,0,1,0.298690795898438,32.7468223571777,6,1,3,14.2293472290039,0,14.1861729621887,,,,,,,,,,,,,,,,,,,,,,,,,,,,,,,,,
,3883320586.6853,15.4771738052368,4999.71533203125,0.000110193350469041,1.40538465132663E-8,1,4,13.4005146026611,4.98552809609289,30.4400008171797,0.136428282760457,0.0202837689191166,1,-9.88150216337146E-8,,,,,,,,,,,,,,,,,,,,,15.4318037033081,15.5225439071655,4999.71533203125,4999.71533203125,53.4329072031403,5.64328383001636,3.7139139175415,54,1,0,0,1,0.29815673828125,33.2355842590332,6,1,3,15.5225439071655,0,15.4771738052368,,,,,,,,,,,,,,,,,,,,,,,,,,,,,,,,,
,3883320647.1638,16.7432441711426,4999.71533203125,0.000109776967176856,1.05599259753545E-8,1,4,13.4005146026611,4.98556932717204,30.4400008171797,0.13590822733628,0.0202482409221036,1,-6.54162584752108E-8,,,,,,,,,,,,,,,,,,,,,16.7003631591797,16.7861251831055,4999.71533203125,4999.71533203125,53.4348612744383,5.64239483458279,3.77284049987793,54,1,0,0,1,0.29815673828125,32.2580642700195,6,1,3,16.7861251831055,0,16.7432441711426,,,,,,,,,,,,,,,,,,,,,,,,,,,,,,,,,
,3883320707.57222,17.9700803756714,4999.71533203125,0.000109329755603562,2.20654136983516E-8,1,4,13.4005146026611,4.98559828938733,30.4400008171797,0.135355300038276,0.0201683548438915,1,-6.31809388468392E-8,,,,,,,,,,,,,,,,,,,,,17.930757522583,18.0094032287598,4999.71533203125,4999.71533203125,53.343801551948,5.64169496218131,3.82088541984558,54,1,0,0,1,0.299911499023438,33.2355842590332,6,1,3,18.0094032287598,0,17.9700803756714,,,,,,,,,,,,,,,,,,,,,,,,,,,,,,,,,
,3883320768.09195,19.1495418548584,4999.71533203125,0.000108996144446906,1.96940818382182E-8,1,4,13.4005146026611,4.98555009380425,30.4400008171797,0.134944281877626,0.0200808862603706,1,-8.37114116545441E-8,,,,,,,,,,,,,,,,,,,,,19.1126194000244,19.1864643096924,4999.71533203125,4999.71533203125,53.4434591881499,5.64227556421019,3.8668704032898,54,1,0,0,1,0.2984619140625,32.2580642700195,6,1,3,19.1864643096924,0,19.1495418548584,,,,,,,,,,,,,,,,,,,,,,,,,,,,,,,,,
,3883320840.5653,20.4963026046753,4999.71533203125,0.00010867655670338,1.54869859042015E-8,1,4,13.4005146026611,4.98549327602512,30.4400008171797,0.134544679191277,0.0200335961561278,1,-7.38455339487645E-8,,,,,,,,,,,,,,,,,,,,,20.456075668335,20.5365295410156,4999.71533203125,4999.71533203125,53.4434591881499,5.64307935485272,3.91428208351135,54,1,0,0,1,0.297927856445313,33.7243423461914,6,1,3,20.5365295410156,0,20.4963026046753,,,,,,,,,,,,,,,,,,,,,,,,,,,,,,,,,
,3883320900.97851,21.5507411956787,4999.71533203125,0.000108504645807499,1.52059267259295E-8,1,4,13.4005146026611,4.98538258083049,30.4400008171797,0.134318599159464,0.0200618851620269,1,-2.47716007296604E-8,,,,,,,,,,,,,,,,,,,,,21.5183620452881,21.5831203460693,4999.71533203125,4999.71533203125,53.3121455969191,5.64274386079819,3.95068907737732,53,1,0,0,1,0.2996826171875,33.2355842590332,6,1,3,21.5831203460693,0,21.5507411956787,,,,,,,,,,,,,,,,,,,,,,,,,,,,,,,,,
,3883320961.45303,22.4764490127563,4999.71533203125,0.000108300891275578,1.77692766209627E-8,1,4,13.4005146026611,4.98539824957257,30.4400008171797,0.134078062278861,0.0199500920159518,1,-8.46735490064264E-8,,,,,,,,,,,,,,,,,,,,,22.4470462799072,22.5058517456055,4999.71533203125,4999.71533203125,53.506380283948,5.64289437131299,3.97820830345154,54,1,0,0,1,0.298233032226562,33.2355842590332,6,1,3,22.5058517456055,0,22.4764490127563,,,,,,,,,,,,,,,,,,,,,,,,,,,,,,,,,
,3883321021.86067,23.3614826202393,4999.71533203125,0.00010814158255555,1.64736613126033E-8,1,4,13.4005146026611,4.98538803919005,30.4400008171797,0.13388240351716,0.0199076375933157,1,-9.50921047389806E-8,,,,,,,,,,,,,,,,,,,,,23.3303565979004,23.3926086425781,4999.71533203125,4999.71533203125,53.496219113198,5.64310008240385,3.99484729766846,54,1,0,0,1,0.29876708984375,33.2355842590332,6,1,3,23.3926086425781,0,23.3614826202393,,,,,,,,,,,,,,,,,,,,,,,,,,,,,,,,,
,3883321082.37547,24.2289609909058,4999.71533203125,0.00010798378525102,2.33122924002933E-8,1,4,13.4005146026611,4.98549042956358,30.4400008171797,0.133684131814667,0.0199243870343583,1,-5.84193870712132E-8,,,,,,,,,,,,,,,,,,,,,24.2007923126221,24.2571296691895,4999.71533203125,4999.71533203125,53.4204011468326,5.64241386274006,4.01784229278564,53,1,68,0,0,0.299530029296875,33.2355842590332,6,1,3,24.2571296691895,0,24.2289609909058,,,,,,,,,,,,,,,,,,,,,,,,,,,,,,,,,
,3883321154.41135,25.2306957244873,4999.71533203125,0.00010784516794263,1.71244170724617E-8,1,4,13.4005146026611,4.98546309437934,30.4400008171797,0.133514219172805,0.019880456876177,1,-7.3047174389669E-8,,,,,,,,,,,,,,,,,,,,,25.2208824157715,25.2405090332031,4999.71533203125,4999.71533203125,53.2910416268999,5.64241117143564,4.04630756378174,54,1,0,0,1,0.29876708984375,32.7468223571777,6,1,3,25.2405090332031,0,25.2306957244873,,,,,,,,,,,,,,,,,,,,,,,,,,,,,,,,,
,3883321227.38828,26.219895362854,4999.71533203125,0.000107673541668909,2.87469805639913E-8,1,4,13.4005146026611,4.98530200091769,30.4400008171797,0.133291953851616,0.0198729675230948,1,-5.26953518801883E-8,,,,,,,,,,,,,,,,,,,,,26.1923084259033,26.2474822998047,4999.71533203125,4999.71533203125,53.3848370492076,5.64245572827786,4.06592559814453,54,1,0,0,1,0.300827026367188,32.7468223571777,6,1,3,26.2474822998047,0,26.219895362854,,,,,,,,,,,,,,,,,,,,,,,,,,,,,,,,,
,3883321287.82556,27.0300207138062,4999.71533203125,0.000107609890387488,1.98168098977803E-8,1,4,13.4005146026611,4.98524777113846,30.4400008171797,0.133219243548544,0.0198066496644872,1,-9.65049901400833E-8,,,,,,,,,,,,,,,,,,,,,27.0021381378174,27.0579032897949,4999.71533203125,4999.71533203125,53.5736003366018,5.64356054035566,4.08083438873291,50,1,100,0,0,0.299606323242188,33.2355842590332,6,1,3,27.0579032897949,0,27.0300207138062,,,,,,,,,,,,,,,,,,,,,,,,,,,,,,,,,
,3883321360.34415,27.9821548461914,4999.71533203125,0.000107475487180975,1.85360940344251E-8,1,4,13.4005146026611,4.98529198123761,30.4400008171797,0.13305077351211,0.0198071335323936,1,-7.6207247801558E-8,,,,,,,,,,,,,,,,,,,,,27.9537467956543,28.0105628967285,4999.71533203125,4999.71533203125,53.3797564638326,5.64279511362668,4.09939289093018,54,1,0,0,1,0.298614501953125,32.7468223571777,6,1,3,28.0105628967285,0,27.9821548461914,,,,,,,,,,,,,,,,,,,,,,,,,,,,,,,,,
,3883321420.81605,28.7608499526978,4999.71533203125,0.000107367691410643,1.62926900218054E-8,1,4,13.4005146026611,4.98531338867956,30.4400008171797,0.132914071288332,0.0198144971446298,1,-5.42292893219191E-8,,,,,,,,,,,,,,,,,,,,,28.733715057373,28.7879848480225,4999.71533203125,4999.71533203125,53.4536203588999,5.64305578813294,4.12038993835449,54,1,0,0,1,0.299530029296875,32.7468223571777,6,1,3,28.7879848480225,0,28.7608499526978,,,,,,,,,,,,,,,,,,,,,,,,,,,,,,,,,
,3883321481.2457,29.5252485275269,4999.71533203125,0.000107322669555563,1.84737753412023E-8,1,4,13.4005146026611,4.98524935761495,30.4400008171797,0.132862554705059,0.0197616377312143,1,-8.99096075737414E-8,,,,,,,,,,,,,,,,,,,,,29.4995803833008,29.5509166717529,4999.71533203125,4999.71533203125,53.4544019874191,5.64329922067464,4.13592481613159,54,1,0,0,1,0.298919677734375,32.7468223571777,6,1,3,29.5509166717529,0,29.5252485275269,,,,,,,,,,,,,,,,,,,,,,,,,,,,,,,,,
,3883321541.6906,30.2794418334961,4999.71533203125,0.000107203728551441,1.81806880124714E-8,1,4,13.4005146026611,4.98521381729005,30.4400008171797,0.132718093716423,0.0197120520232948,1,-1.12016484361343E-7,,,,,,,,,,,,,,,,,,,,,30.2523422241211,30.3065414428711,4999.71533203125,4999.71533203125,53.4164930042364,5.64317815784065,4.14001369476318,54,1,0,0,1,0.29876708984375,33.2355842590332,6,1,3,30.3065414428711,0,30.2794418334961,,,,,,,,,,,,,,,,,,,,,,,,,,,,,,,,,
,3883321602.13296,31.0246448516846,4999.71533203125,0.000107129967950631,2.04829043875562E-8,1,4,13.4005146026611,4.98539252291926,30.4400008171797,0.132624992880847,0.0197559949495497,1,-6.62841968730079E-8,,,,,,,,,,,,,,,,,,,,,31.0009937286377,31.0482959747314,4999.71533203125,4999.71533203125,53.269546842621,5.6417822969525,4.15134716033936,54,1,0,0,1,0.300979614257812,33.2355842590332,6,1,3,31.0482959747314,0,31.0246448516846,,,,,,,,,,,,,,,,,,,,,,,,,,,,,,,,,
,3883321662.58064,31.760500907898,4999.71533203125,0.000107082647662662,2.3379914524618E-8,1,4,13.4005146026611,4.9850590593425,30.4400008171797,0.132555563711385,0.0197347827515533,1,-7.48454914763779E-8,,,,,,,,,,,,,,,,,,,,,31.7369613647461,31.7840404510498,4999.71533203125,4999.71533203125,53.4547928016787,5.64379242795948,4.17239379882812,54,1,0,0,1,0.298538208007812,32.7468223571777,6,1,3,31.7840404510498,0,31.760500907898,,,,,,,,,,,,,,,,,,,,,,,,,,,,,,,,,
,3883321723.0229,32.4811191558838,4999.71533203125,0.000107050563405832,1.77541648208981E-8,1,4,13.4005146026611,4.9849454309624,30.4400008171797,0.13251608693731,0.0196983120434253,1,-9.90022935135481E-8,,,,,,,,,,,,,,,,,,,,,32.4552688598633,32.5069694519043,4999.71533203125,4999.71533203125,53.5255301826691,5.64445329584517,4.1778621673584,54,1,0,0,1,0.300140380859375,32.7468223571777,6,1,3,32.5069694519043,0,32.4811191558838,,,,,,,,,,,,,,,,,,,,,,,,,,,,,,,,,
,3883321795.90214,33.3461265563965,4999.71533203125,0.000106945243178124,2.1888781407591E-8,1,4,13.4005146026611,4.98503284165794,30.4400008171797,0.132389273552908,0.0196773818550359,1,-1.00548478242243E-7,,,,,,,,,,,,,,,,,,,,,33.3272285461426,33.3650245666504,4999.71533203125,4999.71533203125,53.6478550459288,5.64458840377928,4.19327068328857,54,1,0,0,1,0.299453735351562,33.2355842590332,6,1,3,33.3650245666504,0,33.3461265563965,,,,,,,,,,,,,,,,,,,,,,,,,,,,,,,,,
,3883321855.9966,34.0471000671387,4999.71533203125,0.000106932101916185,1.79562291342606E-8,1,4,13.4005146026611,4.98500519643736,30.4400008171797,0.132371274857939,0.0196794977876189,1,-9.67494277013888E-8,,,,,,,,,,,,,,,,,,,,,34.0233612060547,34.0708389282227,4999.71533203125,4999.71533203125,53.5904053497653,5.64466111318981,4.20296287536621,54,1,0,0,1,0.300064086914063,32.7468223571777,6,1,3,34.0708389282227,0,34.0471000671387,,,,,,,,,,,,,,,,,,,,,,,,,,,,,,,,,
,3883321916.46289,34.7444591522217,4999.71533203125,0.00010693145859642,1.38244506123628E-8,1,4,13.4005146026611,4.98504811405889,30.4400008171797,0.132375327943949,0.0196578862159437,1,-1.143056120044E-7,,,,,,,,,,,,,,,,,,,,,34.7229080200195,34.7660102844238,4999.71533203125,4999.71533203125,53.4348612744383,5.64452561985991,4.20474720001221,54,1,0,0,1,0.299224853515625,33.2355842590332,6,1,3,34.7660102844238,0,34.7444591522217,,,,,,,,,,,,,,,,,,,,,,,,,,,,,,,,,
,3883321976.8852,35.4324836730957,4999.71533203125,0.000106831564967786,1.61115442880509E-8,1,4,13.4005146026611,4.9849693568752,30.4400008171797,0.132249665406835,0.0196328611954424,1,-1.19228793839974E-7,,,,,,,,,,,,,,,,,,,,,35.4109001159668,35.4540672302246,4999.71533203125,4999.71533203125,53.3637330791883,5.64450528455074,4.2209267616272,54,1,0,0,1,0.300064086914063,32.7468223571777,6,1,3,35.4540672302246,0,35.4324836730957,,,,,,,,,,,,,,,,,,,,,,,,,,,,,,,,,
,3883322037.32026,36.1154499053955,4999.71533203125,0.00010684713639304,1.31614446378896E-8,1,4,13.4005146026611,4.98491456289536,30.4400008171797,0.132267744583578,0.0196297888291202,1,-1.23795912229278E-7,,,,,,,,,,,,,,,,,,,,,36.0937576293945,36.1371421813965,4999.71533203125,4999.71533203125,53.3250424674864,5.6448756000126,4.22819900512695,54,1,0,0,1,0.299453735351562,33.2355842590332,6,1,3,36.1371421813965,0,36.1154499053955,,,,,,,,,,,,,,,,,,,,,,,,,,,,,,,,,
,3883322089.69602,36.6958789825439,4999.71533203125,0.000106827992069408,1.58715481344269E-8,1,4,13.4005146026611,4.98484114494608,30.4400008171797,0.132243644581095,0.019610281905921,1,-1.36365290480652E-7,,,,,,,,,,,,,,,,,,,,,36.6726455688477,36.7191123962402,4999.71533203125,4999.71533203125,53.462609086871,5.64558755021778,4.23415899276733,54,1,0,0,1,0.301437377929687,33.2355842590332,6,1,3,36.721004486084,0,36.6958789825439,,,,,,,,,,,,,,,,,,,,,,,,,,,,,,,,,