File: SQUID/23006_LCOS/transfer_119973_files_84937504/LSAT_subs_A1_MH_20K_FC_p0d5T_2.dat
[Header]
; MPMS3 Data File (default extension .dat)
; Copyright (c) 2007, Quantum Design, Inc. All rights reserved.
TITLE,
FILEOPENTIME,3883223879.63155,01/18/2023,5:22 pm
BYAPP,SQUID AC,0.9.1.0
INFO,MPMS3 Measurement Release 1.1.16 Build 347, MultiVu Release 2.3.3.2,APPNAME
INFO,0,MOMENT_UNITS
INFO,LSAT,SAMPLE_MATERIAL
INFO,,SAMPLE_COMMENT
INFO,,SAMPLE_MASS
INFO,,SAMPLE_VOLUME
INFO,,SAMPLE_MOLECULAR_WEIGHT
INFO,,SAMPLE_SIZE
INFO,,SAMPLE_SHAPE
INFO,Quartz,SAMPLE_HOLDER
INFO,Standard,SAMPLE_HOLDER_DETAIL
INFO,65.8,SAMPLE_OFFSET
DATATYPE,COMMENT,1
DATATYPE,TIME,2
STARTUPAXIS,X,2
STARTUPAXIS,Y1,5
FIELDGROUP, VSM,2,3,4,5,6,8,9,10,11,14,15
FIELDGROUP, DC, 2,3,4,14,56,57,58,59,60,61,62,63,64,65,66,67,68,69
FIELDGROUP, AC, 2,3,4,11,16,17,18,19,20,21,22,23,24,25,26,27,28,29,30
STARTUPGROUP, All
[Data]
Comment,Time Stamp (sec),Temperature (K),Magnetic Field (Oe),Moment (emu),M. Std. Err. (emu),Transport Action,Averaging Time (sec),Frequency (Hz),Peak Amplitude (mm),Center Position (mm),Lockin Signal' (V),Lockin Signal (V),Range,M. Quad. Signal (emu),AC Moment (emu),AC M. Std Err. (emu),AC Phase (deg),AC Phase Std. Err. (deg),AC Susceptibility (emu/Oe),AC Suscept. Std Err. (emu/Oe),AC X' (emu/Oe),AC X' Std Err. (emu/Oe),AC X'' (emu/Oe),AC X'' Std Err. (emu/Oe),AC Drive (Oe),AC Frequency (Hz),AC Averaging Time (sec),AC Cycles,AC Range,AC Measure Type,AC Signal' (V),AC Signal'' (V),AC Trim Coil Ratio,AC Trim Coil Phase,Min. Temperature (K),Max. Temperature (K),Min. Field (Oe),Max. Field (Oe),Mass (grams),Motor Lag (deg),Pressure (Torr),Measure Count,Measurement Number,SQUID Status (code),Motor Status (code),Measure Status (code),Motor Current (amps),Motor Temp. (C),Temp. Status (code),Field Status (code),Chamber Status (code),Chamber Temp (K),Redirection State,Average Temp (K),Rotation Angle (deg),Rotator state,DC Moment Fixed Ctr (emu),DC Moment Err Fixed Ctr (emu),DC Moment Free Ctr (emu),DC Moment Err Free Ctr (emu),DC Fixed Fit,DC Free Fit,DC Calculated Center (mm),DC Calculated Center Err (mm),DC Scan Length (mm),DC Scan Time (s),DC Number of Points,DC Squid Drift,DC Min V (V),DC Max V (V),DC Scans per Measure,Map 01,Map 02,Map 03,Map 04,Map 05,Map 06,Map 07,Map 08,Map 09,Map 10,Map 11,Map 12,Map 13,Map 14,Map 15,Map 16
,3883224005.34303,19.9415674209595,70000.4921875,-0.00112641973521207,2.46384168830321E-7,1,4,13.4005146026611,5.00707175362921,30.1099997013807,-1.40266850695984,-0.211117236668723,1,-1.01051134585536E-6,,,,,,,,,,,,,,,,,,,,,19.9402751922607,19.9428596496582,70000.4921875,70000.4921875,53.5810258075345,5.64241555969541,3.57666563987732,52,1,68,0,0,0.299606323242188,31.7693061828613,1,1,3,19.9402751922607,0,19.9415674209595,,,,,,,,,,,,,,,,,,,,,,,,,,,,,,,,,
,3883224056.93895,19.9556264877319,65000.28515625,-0.00104317221567302,6.20998239317602E-6,1,4,13.4005146026611,5.00706195040472,30.1099997013807,-1.30044335122352,-0.185875051695931,10,6.80390238941251E-6,,,,,,,,,,,,,,,,,,,,,19.9550876617432,19.9561653137207,65000.28515625,65000.28515625,53.6064287344095,5.64266755254594,3.53173279762268,53,1,68,0,0,0.299606323242188,33.2355842590332,1,1,3,19.9561653137207,0,19.9556264877319,,,,,,,,,,,,,,,,,,,,,,,,,,,,,,,,,
,3883224113.88238,19.988579750061,60000.47265625,-0.000963731805017412,2.02920322993353E-7,1,4,13.4005146026611,5.00690380875045,30.1099997013807,-1.19996924226239,-0.180996068836753,1,-1.16873520127748E-6,,,,,,,,,,,,,,,,,,,,,19.9879398345947,19.9892196655273,60000.47265625,60000.47265625,53.5345189106403,5.64244333891877,3.52002334594727,53,1,68,0,0,0.299758911132812,33.2355842590332,1,1,3,19.9879398345947,0,19.988579750061,,,,,,,,,,,,,,,,,,,,,,,,,,,,,,,,,
,3883224157.92165,20.0022640228271,55000.5,-0.000882730556059877,1.76502588405404E-7,1,4,13.4005146026611,5.00681600021808,30.1099997013807,-1.09913928761209,-0.165419065420374,1,-7.81184149612623E-7,,,,,,,,,,,,,,,,,,,,,20.001392364502,20.0031356811523,55000.5,55000.5,53.6431652748134,5.64320609349406,3.541095495224,54,1,0,0,1,0.299224853515625,33.2355842590332,1,1,3,20.0031299591064,0,20.0022640228271,,,,,,,,,,,,,,,,,,,,,,,,,,,,,,,,,
,3883224201.8378,20.0026874542236,50000.47265625,-0.000801890579239369,1.31624419392003E-7,1,4,13.4005146026611,5.00669666072456,30.1099997013807,-0.998461607245426,-0.150170411965916,1,-6.33629270813495E-7,,,,,,,,,,,,,,,,,,,,,20.0020332336426,20.0033416748047,50000.47265625,50000.47265625,53.503253769871,5.64281429074748,3.56877946853638,54,1,0,0,1,0.300521850585937,33.7243423461914,1,1,3,20.0020332336426,0,20.0026874542236,,,,,,,,,,,,,,,,,,,,,,,,,,,,,,,,,
,3883224244.81233,20.0003042221069,45000.2265625,-0.000721165600619826,8.92918937319684E-8,1,4,13.4005146026611,5.00674758509616,30.1099997013807,-0.897954739204226,-0.135096258780928,1,-6.03031432913391E-7,,,,,,,,,,,,,,,,,,,,,20.0001220703125,20.0004863739014,45000.2265625,45000.2265625,53.5067710982076,5.64294074579676,3.58616900444031,54,1,0,0,1,0.298309326171875,33.2355842590332,1,1,3,20.0004863739014,0,20.0003042221069,,,,,,,,,,,,,,,,,,,,,,,,,,,,,,,,,
,3883224287.16349,20.0003089904785,39999.98828125,-0.000640586734931346,5.81861544241687E-8,1,4,13.4005146026611,5.00665013994864,30.1099997013807,-0.797612905747231,-0.119917038686353,1,-4.70540217179481E-7,,,,,,,,,,,,,,,,,,,,,20.0002498626709,20.0003681182861,39999.98828125,39999.98828125,53.5915777925441,5.64297587670636,3.59722495079041,53,1,68,0,0,0.29937744140625,33.7243423461914,1,1,3,20.0003681182861,0,20.0003089904785,,,,,,,,,,,,,,,,,,,,,,,,,,,,,,,,,
,3883224330.15392,20.0040512084961,34999.93359375,-0.000560100046803915,6.03110564876185E-8,1,4,13.4005146026611,5.00659330317005,30.1099997013807,-0.697395500362128,-0.104781882967177,1,-3.58028891234681E-7,,,,,,,,,,,,,,,,,,,,,20.0035972595215,20.0045051574707,34999.93359375,34999.93359375,53.4461948879672,5.64327456682717,3.61217737197876,54,1,0,0,1,0.299072265625,33.7243423461914,1,1,3,20.0035972595215,0,20.0040512084961,,,,,,,,,,,,,,,,,,,,,,,,,,,,,,,,,
,3883224373.64696,20.0000600814819,29999.638671875,-0.000479736336916827,6.09393375543333E-8,1,4,13.4005146026611,5.006573743134,30.1099997013807,-0.597338939797506,-0.0896823437649658,1,-2.54587767124212E-7,,,,,,,,,,,,,,,,,,,,,20.0000438690186,20.0000762939453,29999.638671875,29999.638671875,53.5059894696884,5.64278500208265,3.61722350120544,54,1,0,0,1,0.301589965820313,33.7243423461914,1,1,3,20.0000438690186,0,20.0000600814819,,,,,,,,,,,,,,,,,,,,,,,,,,,,,,,,,
,3883224416.74379,20.0002098083496,24999.53125,-0.000399480881723857,4.51725216751131E-8,1,4,13.4005146026611,5.00660459871693,30.1099997013807,-0.497422042496243,-0.0746258096297985,1,-1.685120290874E-7,,,,,,,,,,,,,,,,,,,,,20.0001335144043,20.0002861022949,24999.53125,24999.53125,53.4043777621883,5.64264044258212,3.63596844673157,54,1,0,0,1,0.300750732421875,33.7243423461914,1,1,3,20.0001335144043,0,20.0002098083496,,,,,,,,,,,,,,,,,,,,,,,,,,,,,,,,,
,3883224468.49082,20.0064611434937,19999.578125,-0.000319496267753438,4.87407402351291E-8,1,4,13.4005146026611,5.00661703799248,30.1099997013807,-0.397893434435653,-0.059252909272527,10,2.11683095926783E-7,,,,,,,,,,,,,,,,,,,,,20.0053539276123,20.007568359375,19999.578125,19999.578125,53.5384270532364,5.64230525019787,3.63790035247803,54,1,0,0,1,0.302047729492188,33.7243423461914,1,1,3,20.0053539276123,0,20.0064611434937,,,,,,,,,,,,,,,,,,,,,,,,,,,,,,,,,
,3883224519.62352,19.9991693496704,14999.4853515625,-0.000239300297777366,2.92264238559117E-8,1,4,13.4005146026611,5.00658995889939,30.1099997013807,-0.297979052931866,-0.044632856757033,1,-4.47922566309017E-8,,,,,,,,,,,,,,,,,,,,,19.9990081787109,19.9993305206299,14999.4853515625,14999.4853515625,53.4114124188614,5.64272074186781,3.6523380279541,54,1,0,0,1,0.30059814453125,33.7243423461914,1,1,3,19.9993305206299,0,19.9991693496704,,,,,,,,,,,,,,,,,,,,,,,,,,,,,,,,,
,3883224538.93065,20.0019760131836,14499.60546875,-0.000231266476865091,2.52907843795301E-8,1,4,13.4005146026611,5.00657667942746,30.1099997013807,-0.287965164895558,-0.0431946294229633,1,-9.17552294636269E-8,,,,,,,,,,,,,,,,,,,,,20.0017147064209,20.0022373199463,14499.60546875,14499.60546875,53.4899660850441,5.64312508905348,3.65908622741699,54,1,0,0,1,0.299911499023438,34.2131004333496,1,1,3,20.0017147064209,0,20.0019760131836,,,,,,,,,,,,,,,,,,,,,,,,,,,,,,,,,
,3883224559.57232,20.0069961547852,13999.5869140625,-0.000223285196339972,3.47029621403001E-8,1,4,13.4005146026611,5.00659755775603,30.1099997013807,-0.278033797631133,-0.0416705415552394,1,-6.15794753819458E-8,,,,,,,,,,,,,,,,,,,,,20.0052852630615,20.0087070465088,13999.5869140625,13999.5869140625,53.5681289369672,5.64287939716874,3.65904116630554,54,1,0,0,1,0.298614501953125,34.2131004333496,1,1,3,20.0052852630615,0,20.0069961547852,,,,,,,,,,,,,,,,,,,,,,,,,,,,,,,,,
,3883224580.28712,20.0059671401978,13499.54296875,-0.000215265847159574,2.46158465293465E-8,1,4,13.4005146026611,5.00664060588588,30.1099997013807,-0.268048930969944,-0.0401906502714271,1,-7.24050356644988E-8,,,,,,,,,,,,,,,,,,,,,20.0048332214355,20.00710105896,13499.54296875,13499.54296875,53.4207919610922,5.64309255707795,3.6632924079895,54,1,0,0,1,0.300369262695313,33.7243423461914,1,1,3,20.0048332214355,0,20.0059671401978,,,,,,,,,,,,,,,,,,,,,,,,,,,,,,,,,
,3883224600.21078,20.000171661377,12999.740234375,-0.000207274616833904,1.89628079695482E-8,1,4,13.4005146026611,5.00660796217338,30.1099997013807,-0.25810005725428,-0.0386705391678355,1,-4.7411249956751E-8,,,,,,,,,,,,,,,,,,,,,20.0001697540283,20.0001735687256,12999.740234375,12999.740234375,53.5126333121018,5.64286351979573,3.66686058044434,54,1,0,0,1,0.300750732421875,33.7243423461914,1,1,3,20.0001697540283,0,20.000171661377,,,,,,,,,,,,,,,,,,,,,,,,,,,,,,,,,
,3883224621.16159,20.0006170272827,12499.5576171875,-0.000199276707897251,3.14526415177887E-8,1,4,13.4005146026611,5.00661854132073,30.1099997013807,-0.248141076313923,-0.0371828641785221,1,-4.90819860189431E-8,,,,,,,,,,,,,,,,,,,,,20.0004749298096,20.0007591247559,12499.5576171875,12499.5576171875,53.3985155482941,5.64253488548881,3.66645216941833,54,1,0,0,1,0.300064086914063,34.2131004333496,1,1,3,20.0007591247559,0,20.0006170272827,,,,,,,,,,,,,,,,,,,,,,,,,,,,,,,,,
,3883224642.13959,19.9993028640747,11999.4775390625,-0.000191273778389515,2.93143254335298E-8,1,4,13.4005146026611,5.0065963566899,30.1099997013807,-0.238171708518076,-0.035706599753341,1,-6.09363813741162E-8,,,,,,,,,,,,,,,,,,,,,19.9991836547852,19.9994220733643,11999.4775390625,11999.4775390625,53.4438500024095,5.64285128132589,3.67200970649719,54,1,0,0,1,0.301132202148438,34.2131004333496,1,1,3,19.9991836547852,0,19.9993028640747,,,,,,,,,,,,,,,,,,,,,,,,,,,,,,,,,
,3883224663.12432,20.0030555725098,11499.546875,-0.000183285191958647,2.92724431952264E-8,1,4,13.4005146026611,5.00663750042768,30.1099997013807,-0.228231502909948,-0.0341858867011225,1,-3.44501193946015E-8,,,,,,,,,,,,,,,,,,,,,20.0027847290039,20.0033264160156,11499.546875,11499.546875,53.442286745371,5.6429548690323,3.67257118225098,54,1,0,0,1,0.298843383789063,33.7243423461914,1,1,3,20.0027847290039,0,20.0030555725098,,,,,,,,,,,,,,,,,,,,,,,,,,,,,,,,,
,3883224684.90057,19.9998416900635,10999.7177734375,-0.000175270873055927,1.53534535607181E-8,1,4,13.4005146026611,5.00662818475383,30.1099997013807,-0.218252472036536,-0.0326831309859624,1,-2.66315310968164E-8,,,,,,,,,,,,,,,,,,,,,19.9995346069336,20.0001487731934,10999.7177734375,10999.7177734375,53.4618274583518,5.64270836420808,3.6867139339447,54,1,0,0,1,0.299835205078125,34.2131004333496,1,1,3,20.0001487731934,0,19.9998416900635,,,,,,,,,,,,,,,,,,,,,,,,,,,,,,,,,
,3883224705.49954,20.0026731491089,10499.611328125,-0.000167261652620546,2.10697675741929E-8,1,4,13.4005146026611,5.00662355475077,30.1099997013807,-0.208279512835214,-0.0311853955565585,1,-2.20427311988762E-8,,,,,,,,,,,,,,,,,,,,,20.0023536682129,20.0029926300049,10499.611328125,10499.611328125,53.3496637658422,5.64300456732679,3.68682503700256,54,1,0,0,1,0.298690795898438,33.7243423461914,1,1,3,20.0023536682129,0,20.0026731491089,,,,,,,,,,,,,,,,,,,,,,,,,,,,,,,,,
,3883224727.09835,20.0052394866943,9999.7451171875,-0.0001592631836433,2.17199239975806E-8,1,4,13.4005146026611,5.00657965323744,30.1099997013807,-0.198318441093461,-0.0296850081087412,1,-1.39741929626711E-8,,,,,,,,,,,,,,,,,,,,,20.0034770965576,20.0070018768311,9999.7451171875,9999.7451171875,53.4399418598133,5.64247055561904,3.6821711063385,54,1,0,0,1,0.300521850585937,34.2131004333496,1,1,3,20.0034770965576,0,20.0052394866943,,,,,,,,,,,,,,,,,,,,,,,,,,,,,,,,,
,3883224746.87994,19.9997549057007,9499.5751953125,-0.000151261286310662,2.06411412165809E-8,1,4,13.4005146026611,5.00665182218177,30.1099997013807,-0.188356880730153,-0.0282021037680465,1,-1.96950276750016E-8,,,,,,,,,,,,,,,,,,,,,19.9995460510254,19.999963760376,9499.5751953125,9499.5751953125,53.577508479198,5.64233823564613,3.69467258453369,53,1,68,0,0,0.298843383789063,34.2131004333496,1,1,3,19.9995460510254,0,19.9997549057007,,,,,,,,,,,,,,,,,,,,,,,,,,,,,,,,,
,3883224767.51197,20.004337310791,8999.5693359375,-0.000143264141719315,2.85954660420137E-8,1,4,13.4005146026611,5.00667450324604,30.1099997013807,-0.178400642627454,-0.0267044769835622,1,-1.32267440542565E-8,,,,,,,,,,,,,,,,,,,,,20.0035724639893,20.0051021575928,8999.5693359375,8999.5693359375,53.472770257621,5.64246784171269,3.68829488754272,54,1,0,0,1,0.298690795898438,34.2131004333496,1,1,3,20.0035724639893,0,20.004337310791,,,,,,,,,,,,,,,,,,,,,,,,,,,,,,,,,
,3883224788.48183,20.0044221878052,8499.52734375,-0.000135268005723173,2.26762358921207E-8,1,4,13.4005146026611,5.00663256582846,30.1099997013807,-0.168442943595634,-0.0252035654109184,1,-4.35022895092187E-9,,,,,,,,,,,,,,,,,,,,,20.0037364959717,20.0051078796387,8499.52734375,8499.52734375,53.4841038711499,5.64238331224756,3.69002842903137,54,1,0,0,1,0.301284790039063,34.2131004333496,1,1,3,20.0035858154297,0,20.0044221878052,,,,,,,,,,,,,,,,,,,,,,,,,,,,,,,,,
,3883224808.6213,19.9998865127563,7999.55908203125,-0.000127264841759696,1.79996890026886E-8,1,4,13.4005146026611,5.00666414932704,30.1099997013807,-0.158476268639409,-0.0237266744674687,1,-1.53955426451513E-8,,,,,,,,,,,,,,,,,,,,,19.9998817443848,19.9998912811279,7999.55908203125,7999.55908203125,53.3387209665729,5.64271156674805,3.69488644599915,54,1,0,0,1,0.299148559570313,34.2131004333496,1,1,3,19.9998912811279,0,19.9998865127563,,,,,,,,,,,,,,,,,,,,,,,,,,,,,,,,,
,3883224829.74297,20.0017347335815,7499.818359375,-0.000119274400786621,2.12231569884434E-8,1,4,13.4005146026611,5.00662102530264,30.1099997013807,-0.148523571234433,-0.0222422507836602,1,-1.88820826945704E-8,,,,,,,,,,,,,,,,,,,,,20.0017318725586,20.0017375946045,7499.818359375,7499.818359375,53.4907477135634,5.64254510021908,3.69651794433594,54,1,0,0,1,0.298995971679687,33.7243423461914,1,1,3,20.0016574859619,0,20.0017347335815,,,,,,,,,,,,,,,,,,,,,,,,,,,,,,,,,
,3883224850.74154,20.0001640319824,6999.560546875,-0.000111275209863512,1.41189470015271E-8,1,4,13.4005146026611,5.00660845428216,30.1099997013807,-0.138560186532207,-0.0207645208022481,1,-2.88820194802591E-8,,,,,,,,,,,,,,,,,,,,,20.0001449584961,20.0001831054687,6999.560546875,6999.560546875,53.5188863402557,5.64286501966478,3.7026891708374,54,1,0,0,1,0.299835205078125,33.7243423461914,1,1,3,20.0001831054687,0,20.0001640319824,,,,,,,,,,,,,,,,,,,,,,,,,,,,,,,,,
,3883224872.79118,20.0042266845703,6499.4921875,-0.000103279556091687,1.82286466765251E-8,1,4,13.4005146026611,5.00667383208583,30.1099997013807,-0.128606821162854,-0.0192695267209247,1,-2.41436669101371E-8,,,,,,,,,,,,,,,,,,,,,20.0036144256592,20.0048389434814,6499.4921875,6499.4921875,53.4110216046018,5.64233459910468,3.70994591712952,54,1,0,0,1,0.299301147460937,33.7243423461914,1,1,3,20.0036144256592,0,20.0042266845703,,,,,,,,,,,,,,,,,,,,,,,,,,,,,,,,,
,3883224893.4529,20.0026302337646,5999.6376953125,-9.52873914304448E-5,1.25146851242107E-8,1,4,13.4005146026611,5.00664351025932,30.1099997013807,-0.118653229557637,-0.0177815843405745,1,-2.49714579742273E-8,,,,,,,,,,,,,,,,,,,,,20.0017757415771,20.0034847259521,5999.6376953125,5999.6376953125,53.4247001036883,5.64270748604117,3.70477294921875,52,1,68,0,0,0.29998779296875,34.7018585205078,1,1,3,20.0017757415771,0,20.0026302337646,,,,,,,,,,,,,,,,,,,,,,,,,,,,,,,,,
,3883224913.25775,19.9997081756592,5499.51904296875,-8.72542808910251E-5,1.39795963173429E-8,1,4,13.4005146026611,5.00663101433156,30.1099997013807,-0.108649123360397,-0.0162876982863563,1,-2.70660936457324E-8,,,,,,,,,,,,,,,,,,,,,19.9995861053467,19.9998302459717,5499.51904296875,5499.51904296875,53.4391602312941,5.64270310848363,3.71322703361511,53,1,68,0,0,0.299758911132812,33.7243423461914,1,1,3,19.9995861053467,0,19.9997081756592,,,,,,,,,,,,,,,,,,,,,,,,,,,,,,,,,
,3883224935.1245,20.0043172836304,4999.7783203125,-7.92640908497252E-5,1.14060388316571E-8,1,4,13.4005146026611,5.00662468414031,30.1099997013807,-0.0986997739917286,-0.0147946898460839,1,-2.34160263853214E-8,,,,,,,,,,,,,,,,,,,,,20.0037631988525,20.0048713684082,4999.7783203125,4999.7783203125,53.4688621150249,5.64263589620675,3.71221733093262,54,1,0,0,1,0.300674438476562,34.2131004333496,1,1,3,20.0037631988525,0,20.0043172836304,,,,,,,,,,,,,,,,,,,,,,,,,,,,,,,,,
,3883224955.67694,20.0000953674316,4499.58349609375,-7.12732658722171E-5,9.54636582957686E-9,1,4,13.4005146026611,5.00662617879321,30.1099997013807,-0.0887478579407666,-0.0133150012268055,1,-3.05298047773722E-8,,,,,,,,,,,,,,,,,,,,,19.9999752044678,20.0002155303955,4499.58349609375,4499.58349609375,53.430171503323,5.64286451283345,3.71948766708374,53,1,68,0,0,0.30029296875,33.7243423461914,1,1,3,19.9999752044678,0,20.0000953674316,,,,,,,,,,,,,,,,,,,,,,,,,,,,,,,,,
,3883224975.56263,19.9999952316284,3999.69140625,-6.32657681796913E-5,9.82487979198693E-9,1,4,13.4005146026611,5.00665589089801,30.1099997013807,-0.0787776074597938,-0.0118201659394947,1,-2.7900437022733E-8,,,,,,,,,,,,,,,,,,,,,19.9997081756592,20.0002822875977,3999.69140625,3999.69140625,53.4133664901595,5.64236550803493,3.71769714355469,54,1,0,0,1,0.299148559570313,34.2131004333496,1,1,3,20.0002822875977,0,19.9999952316284,,,,,,,,,,,,,,,,,,,,,,,,,,,,,,,,,
,3883224997.46225,20.0029039382935,3499.66064453125,-5.52682037717994E-5,8.93453705256678E-9,1,4,13.4005146026611,5.00667598760444,30.1099997013807,-0.0688194758938392,-0.0103264637478215,1,-2.47372107690079E-8,,,,,,,,,,,,,,,,,,,,,20.0023555755615,20.0034523010254,3499.66064453125,3499.66064453125,53.3860094919864,5.64219576166849,3.72617530822754,53,1,68,0,0,0.301589965820313,33.2355842590332,1,1,3,20.0023555755615,0,20.0029039382935,,,,,,,,,,,,,,,,,,,,,,,,,,,,,,,,,
,3883225035.5444,20.0001745223999,2999.60498046875,-4.72945980481959E-5,7.25071264687252E-9,1,4,13.4005146026611,5.00667046322315,30.1099997013807,-0.0588974508705623,-0.00879165936289794,1,1.49524619162725E-8,,,,,,,,,,,,,,,,,,,,,20.0001602172852,20.0001888275146,2999.60498046875,2999.60498046875,53.4411143025922,5.64222188495366,3.7213134765625,54,1,0,0,1,0.30120849609375,33.7243423461914,1,1,3,20.0001602172852,0,20.0001745223999,,,,,,,,,,,,,,,,,,,,,,,,,,,,,,,,,
,3883225054.76975,20.0034065246582,2709.54638671875,-4.26144422830019E-5,9.22713776282365E-9,1,4,13.4005146026611,5.00663964980061,30.1099997013807,-0.0530601433856849,-0.0079784487399416,1,-3.21868914561651E-8,,,,,,,,,,,,,,,,,,,,,20.0030498504639,20.0037631988525,2709.54638671875,2709.54638671875,53.3735034356787,5.64159425123941,3.72554564476013,54,1,0,0,1,0.301589965820313,33.7243423461914,1,1,3,20.0030498504639,0,20.0034065246582,,,,,,,,,,,,,,,,,,,,,,,,,,,,,,,,,
,3883225075.39613,19.9999513626099,2419.68896484375,-3.79779065064346E-5,9.38578052335828E-9,1,4,13.4005146026611,5.00663192027511,30.1099997013807,-0.0472869612785309,-0.00711057148510456,1,-2.88528326798067E-8,,,,,,,,,,,,,,,,,,,,,19.9998645782471,20.0000381469727,2419.68896484375,2419.68896484375,53.4688621150249,5.64192000272799,3.72874426841736,54,1,0,0,1,0.300369262695313,33.2355842590332,1,1,3,19.9998321533203,0,19.9999513626099,,,,,,,,,,,,,,,,,,,,,,,,,,,,,,,,,
,3883225095.34265,20.0004796981812,2129.80688476562,-3.33410233929568E-5,8.3558684442606E-9,1,4,13.4005146026611,5.00671423411993,30.1099997013807,-0.0415143500698586,-0.00624322678380183,1,-2.58693324341115E-8,,,,,,,,,,,,,,,,,,,,,20.0004043579102,20.0005550384521,2129.80688476562,2129.80688476562,53.3328587526787,5.64224128318221,3.73456931114197,54,1,0,0,1,0.298233032226562,33.2355842590332,1,1,3,20.0005550384521,0,20.0004796981812,,,,,,,,,,,,,,,,,,,,,,,,,,,,,,,,,
,3883225114.58037,20.0030212402344,1839.71044921875,-2.87056757920559E-5,8.12569391499892E-9,1,4,13.4005146026611,5.00664767343056,30.1099997013807,-0.0357407006101171,-0.00538392104784639,1,-2.93232400653393E-8,,,,,,,,,,,,,,,,,,,,,20.0028305053711,20.0032119750977,1839.71044921875,1839.71044921875,53.4567468729768,5.64191316004039,3.73746514320374,54,1,0,0,1,0.299835205078125,33.7243423461914,1,1,3,20.0028305053711,0,20.0030212402344,,,,,,,,,,,,,,,,,,,,,,,,,,,,,,,,,
,3883225134.2477,20.0044708251953,1549.48828125,-2.40565145286175E-5,9.57789943861738E-9,1,4,13.4005146026611,5.00662752725054,30.1099997013807,-0.0299559472205124,-0.00448540225495545,1,-3.28092987601951E-9,,,,,,,,,,,,,,,,,,,,,20.0034027099609,20.0055389404297,1549.48828125,1549.48828125,53.4309531318422,5.6422436967049,3.73963046073914,54,1,0,0,1,0.301055908203125,33.7243423461914,1,1,3,20.0034027099609,0,20.0044708251953,,,,,,,,,,,,,,,,,,,,,,,,,,,,,,,,,
,3883225153.59898,20.0000200271606,1259.64379882812,-1.94174483644703E-5,7.83950755479583E-9,1,4,13.4005146026611,5.00668503351094,30.1099997013807,-0.0241761402530832,-0.00364376053629934,1,-2.13320904696324E-8,,,,,,,,,,,,,,,,,,,,,19.9998664855957,20.0001735687256,1259.64379882812,1259.64379882812,53.5169322689576,5.6424110402,3.73346519470215,54,1,0,0,1,0.29998779296875,33.2355842590332,1,1,3,19.9998664855957,0,20.0000200271606,,,,,,,,,,,,,,,,,,,,,,,,,,,,,,,,,
,3883225173.46249,20.0026350021362,969.748779296875,-1.47777622451666E-5,6.89215315122849E-9,1,4,13.4005146026611,5.00663256631546,30.1099997013807,-0.0183983254944121,-0.00277839487374734,1,-2.05153930082308E-8,,,,,,,,,,,,,,,,,,,,,20.0020790100098,20.0031909942627,969.748779296875,969.748779296875,53.5020813270922,5.64254987243937,3.74460625648499,54,1,0,0,1,0.299453735351562,33.7243423461914,1,1,3,20.0020790100098,0,20.0026350021362,,,,,,,,,,,,,,,,,,,,,,,,,,,,,,,,,
,3883225192.72425,20.0001583099365,679.72802734375,-1.01503560486292E-5,7.09866588771143E-9,1,4,13.4005146026611,5.00663283589671,30.1099997013807,-0.012639195475418,-0.00189506262688408,1,-3.3907250094887E-9,,,,,,,,,,,,,,,,,,,,,20.000036239624,20.000280380249,679.72802734375,679.72802734375,53.513414940621,5.64258109765201,3.74607157707214,54,1,0,0,1,0.301437377929687,33.2355842590332,1,1,3,20.0002136230469,0,20.0001583099365,,,,,,,,,,,,,,,,,,,,,,,,,,,,,,,,,
,3883225212.53744,20.0041341781616,389.505767822266,-5.49643517590361E-6,8.29945466848329E-9,1,4,13.4005146026611,5.00652564905186,30.1099997013807,-0.00684021008582536,-0.00105109012235625,1,-2.18655853070565E-8,,,,,,,,,,,,,,,,,,,,,20.0034637451172,20.0048046112061,389.505767822266,389.505767822266,53.4344704601787,5.64176528466957,3.75039219856262,54,1,0,0,1,0.2996826171875,32.7468223571777,1,1,3,20.0034637451172,0,20.0041341781616,,,,,,,,,,,,,,,,,,,,,,,,,,,,,,,,,
,3883225231.79134,20.0050935745239,99.7619247436523,-9.00302134184217E-7,7.40589360417393E-9,1,4,13.4005146026611,5.00654993221878,30.1099997013807,-0.00112276847014862,-0.000156445706409997,1,9.0437286991431E-9,,,,,,,,,,,,,,,,,,,,,20.0043029785156,20.0058841705322,99.7619247436523,99.7619247436523,53.3504453943614,5.64291302942975,3.74460911750793,54,1,0,0,1,0.299758911132812,33.2355842590332,1,1,3,20.0043029785156,0,20.0050935745239,,,,,,,,,,,,,,,,,,,,,,,,,,,,,,,,,
,3883225250.32559,20.0048990249634,-190.120422363281,3.72472844654333E-6,1.31568354288047E-8,1,4,13.4005146026611,5.00651834660943,30.1099997013807,0.00464069056845654,0.000676548894734463,1,-1.38795342063921E-8,,,,,,,,,,,,,,,,,,,,,20.003942489624,20.0058555603027,-190.120422363281,-190.120422363281,53.3703769216018,5.64286203595215,3.74819397926331,54,1,0,0,1,0.299148559570313,33.7243423461914,1,1,3,20.003942489624,0,20.0048990249634,,,,,,,,,,,,,,,,,,,,,,,,,,,,,,,,,
,3883225268.49118,20.0039987564087,-480.405578613281,8.28919159579629E-6,1.7303021425879E-8,1,4,13.4005146026611,5.00653715230147,30.1099997013807,0.010325390231607,0.00152088861736048,1,-1.86366484875743E-8,,,,,,,,,,,,,,,,,,,,,20.0031814575195,20.0048160552979,-480.405578613281,-480.405578613281,53.503253769871,5.64193220979598,3.74951863288879,54,1,0,0,1,0.298614501953125,34.2131004333496,1,1,3,20.0031814575195,0,20.0039987564087,,,,,,,,,,,,,,,,,,,,,,,,,,,,,,,,,
,3883225287.47113,20.0070190429687,-770.174621582031,1.27888848101832E-5,1.1599248783391E-7,1,4,13.4005146026611,5.00653806829091,30.1099997013807,0.0158950826785571,0.00258267295116828,1,1.60920321544506E-7,,,,,,,,,,,,,,,,,,,,,20.0054588317871,20.0085792541504,-770.174621582031,-770.174621582031,53.4559652444576,5.64270435945527,3.75670266151428,54,1,0,0,1,0.300369262695313,33.2355842590332,1,1,3,20.0054588317871,0,20.0070190429687,,,,,,,,,,,,,,,,,,,,,,,,,,,,,,,,,
,3883225306.45513,20.0007572174072,-1059.88073730469,1.75062031252758E-5,6.85693995044451E-8,1,4,13.4005146026611,5.00657363027761,30.1099997013807,0.0217975958032236,0.00327315092087182,1,9.71233712295064E-9,,,,,,,,,,,,,,,,,,,,,20.0006694793701,20.0008449554443,-1059.88073730469,-1059.88073730469,53.3492729515826,5.64227241810748,3.75863409042358,54,1,0,0,1,0.30059814453125,33.2355842590332,1,1,3,20.0008449554443,0,20.0007572174072,,,,,,,,,,,,,,,,,,,,,,,,,,,,,,,,,
,3883225325.66455,19.9998483657837,-1349.83862304688,2.20464489602913E-5,1.78661986726833E-8,1,4,13.4005146026611,5.00658574402336,30.1099997013807,0.0274470989187891,0.00414753595602958,1,3.26908146472563E-8,,,,,,,,,,,,,,,,,,,,,19.9997482299805,19.9999485015869,-1349.83862304688,-1349.83862304688,53.4551836159384,5.64278754019519,3.75229835510254,54,1,0,0,1,0.300521850585937,33.2355842590332,1,1,3,19.9999485015869,0,19.9998483657837,,,,,,,,,,,,,,,,,,,,,,,,,,,,,,,,,
,3883225344.61226,20.0044221878052,-1640.06079101562,2.66510028795962E-5,1.60092239903391E-8,1,4,13.4005146026611,5.00661491092054,30.1099997013807,0.0331866332324821,0.00496871689283296,1,3.29971923363873E-9,,,,,,,,,,,,,,,,,,,,,20.0029621124268,20.0058822631836,-1640.06079101562,-1640.06079101562,53.3809289066114,5.64305786682475,3.76056098937988,54,1,0,0,1,0.299606323242188,33.2355842590332,1,1,3,20.0029621124268,0,20.0044221878052,,,,,,,,,,,,,,,,,,,,,,,,,,,,,,,,,
,3883225363.50931,20.0012102127075,-1930.11938476562,3.12306806899034E-5,5.26520646035345E-8,1,4,13.4005146026611,5.00657602049281,30.1099997013807,0.0389049977986273,0.0057152896819336,1,-8.22071279495506E-8,,,,,,,,,,,,,,,,,,,,,20.001091003418,20.0013294219971,-1930.11938476562,-1930.11938476562,53.4907477135634,5.64227177198782,3.75648427009583,54,1,0,0,1,0.299835205078125,33.2355842590332,1,1,3,20.001091003418,0,20.0012102127075,,,,,,,,,,,,,,,,,,,,,,,,,,,,,,,,,
,3883225382.73682,20.0013847351074,-2219.8505859375,3.59565220945762E-5,8.10031665487951E-8,1,4,13.4005146026611,5.00655639333184,30.1099997013807,0.0447787266512895,0.0066679876607754,1,-2.4062604309598E-8,,,,,,,,,,,,,,,,,,,,,20.0012817382813,20.0014877319336,-2219.8505859375,-2219.8505859375,53.4770692144768,5.64271791124028,3.76393175125122,54,1,0,0,1,0.299911499023438,33.7243423461914,1,1,3,20.0012817382813,0,20.0013847351074,,,,,,,,,,,,,,,,,,,,,,,,,,,,,,,,,
,3883225401.73064,19.999828338623,-2509.77075195313,4.04876466187392E-5,7.97929480574785E-9,1,4,13.4005146026611,5.00652676947044,30.1099997013807,0.0504224572071823,0.00749966410893852,1,-3.39528351449565E-8,,,,,,,,,,,,,,,,,,,,,19.9994201660156,20.0002365112305,-2509.77075195313,-2509.77075195313,53.4133664901595,5.64239463123983,3.7558581829071,54,1,0,0,1,0.299148559570313,32.7468223571777,1,1,3,19.9994163513184,0,19.999828338623,,,,,,,,,,,,,,,,,,,,,,,,,,,,,,,,,
,3883225420.66543,19.9997272491455,-2800.03076171875,4.51188704387686E-5,9.81120878914575E-9,1,4,13.4005146026611,5.00651282945324,30.1099997013807,0.0561903581616994,0.0083542021341122,1,-4.04760552768515E-8,,,,,,,,,,,,,,,,,,,,,19.999340057373,20.000114440918,-2800.03076171875,-2800.03076171875,53.4309531318422,5.64238948650657,3.76197004318237,54,1,0,0,1,0.30120849609375,32.7468223571777,1,1,3,19.999340057373,0,19.9997272491455,,,,,,,,,,,,,,,,,,,,,,,,,,,,,,,,,
,3883225454.76301,20.0012178421021,-3000.05810546875,4.83294341529983E-5,9.1663866491449E-9,1,4,13.4005146026611,5.00652111080263,30.1099997013807,0.0601888863696403,0.00894867972907347,1,-4.33646892959377E-8,,,,,,,,,,,,,,,,,,,,,20.0011901855469,20.0012454986572,-3000.05810546875,-3000.05810546875,53.447367330746,5.64257170646463,3.76420545578003,54,1,0,0,1,0.300521850585937,33.7243423461914,1,1,3,20.0012454986572,0,20.0012178421021,,,,,,,,,,,,,,,,,,,,,,,,,,,,,,,,,
,3883225474.25159,20.0003709793091,-3499.82446289063,5.62129821961714E-5,8.4469866573728E-9,1,4,13.4005146026611,5.00651101479463,30.1099997013807,0.0700040111045493,0.0104267664512104,1,-3.56634224739261E-8,,,,,,,,,,,,,,,,,,,,,19.9999485015869,20.0007934570313,-3499.82446289063,-3499.82446289063,53.4661264152076,5.64284530748995,3.76959300041199,54,1,0,0,1,0.30029296875,33.2355842590332,1,1,3,20.0007934570313,0,20.0003709793091,,,,,,,,,,,,,,,,,,,,,,,,,,,,,,,,,
,3883225494.95851,20.0001974105835,-3999.93041992188,6.42035598477538E-5,7.11972524394653E-9,1,4,13.4005146026611,5.00652269797911,30.1099997013807,0.0799574027486144,0.0118943634507699,1,-5.24485619296716E-8,,,,,,,,,,,,,,,,,,,,,20.0000896453857,20.0003051757813,-3999.93041992188,-3999.93041992188,53.5009088843133,5.6424225400416,3.76848578453064,54,1,0,0,1,0.29998779296875,33.2355842590332,1,1,3,20.0000896453857,0,20.0001974105835,,,,,,,,,,,,,,,,,,,,,,,,,,,,,,,,,
,3883225515.45917,20.0081577301025,-4499.873046875,7.21825774837918E-5,8.74687095774556E-9,1,4,13.4005146026611,5.00650294366337,30.1099997013807,0.0898918347360446,0.0133853727470016,1,-4.8616059277675E-8,,,,,,,,,,,,,,,,,,,,,20.0068912506104,20.0094242095947,-4499.873046875,-4499.873046875,53.508334355246,5.64246543936362,3.76405715942383,54,1,0,0,1,0.30120849609375,33.7243423461914,1,1,3,20.0066337585449,0,20.0081577301025,,,,,,,,,,,,,,,,,,,,,,,,,,,,,,,,,
,3883225535.30654,20.0000820159912,-4999.9921875,8.0168179298149E-5,1.29353603127166E-8,1,4,13.4005146026611,5.0065037324368,30.1099997013807,0.0998368995438468,0.0148645014945287,1,-5.53647990169694E-8,,,,,,,,,,,,,,,,,,,,,20.0000076293945,20.0001564025879,-4999.9921875,-4999.9921875,53.506380283948,5.64150217259068,3.77693057060242,54,1,0,0,1,0.299758911132812,33.2355842590332,1,1,3,20.0001564025879,0,20.0000820159912,,,,,,,,,,,,,,,,,,,,,,,,,,,,,,,,,
,3883225555.44957,20.0034971237183,-5499.78369140625,8.81476299321163E-5,1.10544665454337E-8,1,4,13.4005146026611,5.0065010190248,30.1099997013807,0.109773668648086,0.0163460333024031,1,-5.92512091387509E-8,,,,,,,,,,,,,,,,,,,,,20.0027160644531,20.0042781829834,-5499.78369140625,-5499.78369140625,53.4622182726114,5.6424090092815,3.7672119140625,52,1,68,0,0,0.299453735351562,33.2355842590332,1,1,3,20.0027160644531,0,20.0034971237183,,,,,,,,,,,,,,,,,,,,,,,,,,,,,,,,,
,3883225575.2252,20.0034408569336,-6000.0283203125,9.6128675239778E-5,1.43890502377709E-8,1,4,13.4005146026611,5.00653757069586,30.1099997013807,0.11971336710113,0.0178304214085118,1,-6.12375533267678E-8,,,,,,,,,,,,,,,,,,,,,20.0032920837402,20.003589630127,-6000.0283203125,-6000.0283203125,53.4102399760826,5.6428132229624,3.77769708633423,54,1,0,0,1,0.29937744140625,33.2355842590332,1,1,3,20.0032920837402,0,20.0034408569336,,,,,,,,,,,,,,,,,,,,,,,,,,,,,,,,,
,3883225595.71161,20.0002689361572,-6499.744140625,0.000104115649351019,1.21465049923266E-8,1,4,13.4005146026611,5.0064845493506,30.1099997013807,0.129657362311011,0.0193157664970396,1,-6.29786231163456E-8,,,,,,,,,,,,,,,,,,,,,20.0001850128174,20.0003528594971,-6499.744140625,-6499.744140625,53.4876211994864,5.64277687079186,3.77333807945251,54,1,0,0,1,0.298843383789063,33.2355842590332,1,1,3,20.0003528594971,0,20.0002689361572,,,,,,,,,,,,,,,,,,,,,,,,,,,,,,,,,
,3883225616.2986,20.0032081604004,-6999.5859375,0.000112109099153929,1.55648238380437E-8,1,4,13.4005146026611,5.00652240891361,30.1099997013807,0.139612458650743,0.0208042122995504,1,-6.3586951233882E-8,,,,,,,,,,,,,,,,,,,,,20.0027313232422,20.0036849975586,-6999.5859375,-6999.5859375,53.4207919610922,5.64272206596226,3.77445864677429,54,1,0,0,1,0.299530029296875,33.7243423461914,1,1,3,20.0027313232422,0,20.0032081604004,,,,,,,,,,,,,,,,,,,,,,,,,,,,,,,,,
,3883225636.91908,20.0093793869019,-7500.08251953125,0.000120111201177035,1.36491006327685E-8,1,4,13.4005146026611,5.00650005305735,30.1099997013807,0.149577759049756,0.0222823301216866,1,-7.35079786126895E-8,,,,,,,,,,,,,,,,,,,,,20.0076217651367,20.011137008667,-7500.08251953125,-7500.08251953125,53.5169322689576,5.64263013200435,3.77886939048767,53,1,68,0,0,0.301437377929687,33.7243423461914,1,1,3,20.0076217651367,0,20.0093793869019,,,,,,,,,,,,,,,,,,,,,,,,,,,,,,,,,
,3883225657.59838,20.0107727050781,-7999.99951171875,0.000128100551602338,1.53293000790544E-8,1,4,13.4005146026611,5.00649824718156,30.1099997013807,0.159526789162403,0.0237660983918993,1,-7.70783882750393E-8,,,,,,,,,,,,,,,,,,,,,20.0085391998291,20.0130062103271,-7999.99951171875,-7999.99951171875,53.4000788053326,5.64208792392907,3.78177690505981,53,1,68,0,0,0.2996826171875,33.7243423461914,1,1,3,20.0085391998291,0,20.0107727050781,,,,,,,,,,,,,,,,,,,,,,,,,,,,,,,,,
,3883225678.2099,20.0055646896362,-8499.8291015625,0.00013609171654869,2.23656036129842E-8,1,4,13.4005146026611,5.00653078471483,30.1099997013807,0.169480210673266,0.0252469921146079,1,-8.34219667606398E-8,,,,,,,,,,,,,,,,,,,,,20.0042629241943,20.0068664550781,-8499.8291015625,-8499.8291015625,53.3402842236114,5.64213818889416,3.78246569633484,54,1,0,0,1,0.299835205078125,33.2355842590332,1,1,3,20.0042629241943,0,20.0055646896362,,,,,,,,,,,,,,,,,,,,,,,,,,,,,,,,,
,3883225698.06652,20.002121925354,-8999.6826171875,0.000144081117272114,1.94465077113962E-8,1,4,13.4005146026611,5.00653767270163,30.1099997013807,0.179426777030279,0.026751149862896,1,-7.06869289523245E-8,,,,,,,,,,,,,,,,,,,,,20.0016746520996,20.0025691986084,-8999.6826171875,-8999.6826171875,53.4145389329383,5.64265853899104,3.78540539741516,52,1,68,0,0,0.29876708984375,33.7243423461914,1,1,3,20.0016746520996,0,20.002121925354,,,,,,,,,,,,,,,,,,,,,,,,,,,,,,,,,
,3883225718.35024,20.0019283294678,-9499.890625,0.000152076859876333,1.87257555772943E-8,1,4,13.4005146026611,5.00649100303582,30.1099997013807,0.189376924040546,0.0282662484450113,1,-4.97795389730796E-8,,,,,,,,,,,,,,,,,,,,,20.0019092559814,20.0019474029541,-9499.890625,-9499.890625,53.4516662876018,5.64197033342981,3.77922940254211,54,1,0,0,1,0.3009033203125,32.7468223571777,1,1,3,20.0019474029541,0,20.0019283294678,,,,,,,,,,,,,,,,,,,,,,,,,,,,,,,,,
,3883225738.06866,20.0041522979736,-9999.8076171875,0.00016007389839228,2.14737720362898E-8,1,4,13.4005146026611,5.00651210309072,30.1099997013807,0.199339299496193,0.0297346383242326,1,-6.69973925585087E-8,,,,,,,,,,,,,,,,,,,,,20.0034923553467,20.0048122406006,-9999.8076171875,-9999.8076171875,53.4801957285537,5.64241635494078,3.78166151046753,52,1,68,0,0,0.300750732421875,33.2355842590332,1,1,3,20.0034923553467,0,20.0041522979736,,,,,,,,,,,,,,,,,,,,,,,,,,,,,,,,,
,3883225758.61321,20.0038719177246,-10499.8125,0.000168038708139224,2.85075369923533E-8,1,4,13.4005146026611,5.0065293614124,30.1099997013807,0.209258706042392,0.0312152561686599,1,-6.95611368864437E-8,,,,,,,,,,,,,,,,,,,,,20.0030422210693,20.0047016143799,-10499.8125,-10499.8125,53.4891844565249,5.64225084083026,3.78400182723999,54,1,0,0,1,0.301132202148438,33.7243423461914,1,1,3,20.0030422210693,0,20.0038719177246,,,,,,,,,,,,,,,,,,,,,,,,,,,,,,,,,
,3883225779.16235,20.0045537948608,-10999.7177734375,0.000176046781083299,2.02360740649644E-8,1,4,13.4005146026611,5.00647499509876,30.1099997013807,0.219229689559611,0.0326899659227454,1,-8.28277418174917E-8,,,,,,,,,,,,,,,,,,,,,20.0038681030273,20.0052394866943,-10999.7177734375,-10999.7177734375,53.4141481186787,5.64200316917249,3.79159069061279,54,1,0,0,1,0.29998779296875,33.2355842590332,1,1,3,20.0038681030273,0,20.0045537948608,,,,,,,,,,,,,,,,,,,,,,,,,,,,,,,,,
,3883225799.78054,20.0010166168213,-11499.88671875,0.00018404879409377,1.82124103907394E-8,1,4,13.4005146026611,5.00653343320384,30.1099997013807,0.229196237918191,0.0341900242538509,1,-7.56595221774687E-8,,,,,,,,,,,,,,,,,,,,,20.0005588531494,20.0014743804932,-11499.88671875,-11499.88671875,53.4434591881499,5.64233397453184,3.78421640396118,54,1,0,0,1,0.301284790039063,33.7243423461914,1,1,3,20.0005588531494,0,20.0010166168213,,,,,,,,,,,,,,,,,,,,,,,,,,,,,,,,,
,3883225820.33127,19.9999895095825,-11999.841796875,0.000192048384507438,2.66091067493188E-8,1,4,13.4005146026611,5.00653033405343,30.1099997013807,0.239154521417556,0.0356988504133552,1,-6.06345089548802E-8,,,,,,,,,,,,,,,,,,,,,19.9999160766602,20.0000629425049,-11999.841796875,-11999.841796875,53.4442408166691,5.64230800428682,3.78413844108582,54,1,0,0,1,0.299148559570313,33.2355842590332,1,1,3,20.0000629425049,0,19.9999895095825,,,,,,,,,,,,,,,,,,,,,,,,,,,,,,,,,
,3883225840.96937,20.0100440979004,-12499.734375,0.00020004802303476,2.42102405716489E-8,1,4,13.4005146026611,5.00657686143269,30.1099997013807,0.249117138625224,0.0372025916642775,1,-5.01121570129141E-8,,,,,,,,,,,,,,,,,,,,,20.0083179473877,20.0117702484131,-12499.734375,-12499.734375,53.4770692144768,5.64236918221083,3.79219055175781,54,1,0,0,1,0.30029296875,33.2355842590332,1,1,3,20.0083179473877,0,20.0100440979004,,,,,,,,,,,,,,,,,,,,,,,,,,,,,,,,,
,3883225861.49483,20.0164108276367,-12999.9912109375,0.000208046827509584,2.59083969797617E-8,1,4,13.4005146026611,5.00652980400544,30.1099997013807,0.259079165030081,0.0386586823668021,1,-7.69507502864609E-8,,,,,,,,,,,,,,,,,,,,,20.0133819580078,20.0194396972656,-12999.9912109375,-12999.9912109375,53.5141965691403,5.64235761319219,3.7934775352478,54,1,0,0,1,0.2996826171875,33.2355842590332,1,1,3,20.0133819580078,0,20.0164108276367,,,,,,,,,,,,,,,,,,,,,,,,,,,,,,,,,
,3883225882.11906,20.0015449523926,-13499.5185546875,0.000216021934982376,2.25077529244413E-8,1,4,13.4005146026611,5.00658223608102,30.1099997013807,0.269010809514883,0.0401654897787512,1,-6.03802868742444E-8,,,,,,,,,,,,,,,,,,,,,20.0012073516846,20.0018825531006,-13499.5185546875,-13499.5185546875,53.4172746327557,5.64221470722072,3.7895622253418,54,1,0,0,1,0.299148559570313,33.7243423461914,1,1,3,20.0012073516846,0,20.0015449523926,,,,,,,,,,,,,,,,,,,,,,,,,,,,,,,,,
,3883225902.68962,20.0061569213867,-13999.5615234375,0.00022404618810491,1.70784788447541E-8,1,4,13.4005146026611,5.00654535497848,30.1099997013807,0.278996778466435,0.0416818404388258,1,-4.26986468107412E-8,,,,,,,,,,,,,,,,,,,,,20.0055828094482,20.0067310333252,-13999.5615234375,-13999.5615234375,53.442286745371,5.64232734966135,3.79827666282654,54,1,0,0,1,0.300369262695313,33.2355842590332,1,1,3,20.0055828094482,0,20.0061569213867,,,,,,,,,,,,,,,,,,,,,,,,,,,,,,,,,
,3883225923.35258,20.0184211730957,-14499.6435546875,0.000232062649177221,2.48023511306072E-8,1,4,13.4005146026611,5.0065355108706,30.1099997013807,0.288978114357824,0.0431763539357046,1,-4.16249085220847E-8,,,,,,,,,,,,,,,,,,,,,20.0163097381592,20.0205326080322,-14499.6435546875,-14499.6435546875,53.340675037871,5.64263013821957,3.79898071289063,54,1,0,0,1,0.30120849609375,33.2355842590332,1,1,3,20.0163097381592,0,20.0184211730957,,,,,,,,,,,,,,,,,,,,,,,,,,,,,,,,,
,3883225960.55694,20.0028400421143,-14999.6240234375,0.000240028251844609,3.1750905451858E-8,1,4,13.4005146026611,5.00660759757549,30.1099997013807,0.298904344513623,0.0446527769585771,1,-4.82847910867608E-8,,,,,,,,,,,,,,,,,,,,,20.0026454925537,20.0030345916748,-14999.6240234375,-14999.6240234375,53.5415535673134,5.64243279106451,3.79637336730957,54,1,0,0,1,0.299301147460937,33.2355842590332,1,1,3,20.0026454925537,0,20.0028400421143,,,,,,,,,,,,,,,,,,,,,,,,,,,,,,,,,
,3883226003.27469,20.0056324005127,-19999.703125,0.000320138854037554,3.57545551531398E-8,1,4,13.4005146026611,5.00658233543093,30.1099997013807,0.398647633018387,0.0596536056331018,1,1.44329985541383E-8,,,,,,,,,,,,,,,,,,,,,20.0046443939209,20.0066204071045,-19999.703125,-19999.703125,53.4501030305633,5.64305871700283,3.79533171653748,54,1,0,0,1,0.29998779296875,33.7243423461914,1,1,3,20.0046443939209,0,20.0056324005127,,,,,,,,,,,,,,,,,,,,,,,,,,,,,,,,,
,3883226046.99471,20.0190315246582,-24999.59375,0.00040030878932911,4.2579455774137E-8,1,4,13.4005146026611,5.00654207332963,30.1099997013807,0.49846695399216,0.0746272326548062,1,4.68512948415025E-8,,,,,,,,,,,,,,,,,,,,,20.0178337097168,20.0202293395996,-24999.59375,-24999.59375,53.4286082462845,5.64294624940428,3.80179214477539,53,1,68,0,0,0.300521850585937,33.2355842590332,1,1,3,20.0178337097168,0,20.0190315246582,,,,,,,,,,,,,,,,,,,,,,,,,,,,,,,,,
,3883226104.03038,20.009934425354,-29999.548828125,0.000480550450271395,5.19835437020389E-8,1,4,13.4005146026611,5.00652016778343,30.1099997013807,0.59836538751284,0.0896880352186074,1,1.38449559252944E-7,,,,,,,,,,,,,,,,,,,,,20.0098075866699,20.0100612640381,-29999.548828125,-29999.548828125,53.506380283948,5.6426289796962,3.80161380767822,52,1,68,0,0,0.301055908203125,33.7243423461914,1,1,3,20.0100612640381,0,20.009934425354,,,,,,,,,,,,,,,,,,,,,,,,,,,,,,,,,
,3883226147.7732,20.0421295166016,-34999.6796875,0.00056100510104756,7.0292170352036E-8,1,4,13.4005146026611,5.00654711295383,30.1099997013807,0.698538284067987,0.104783484501338,1,2.2500984517929E-7,,,,,,,,,,,,,,,,,,,,,20.0414905548096,20.0427684783936,-34999.6796875,-34999.6796875,53.6802926294768,5.64330795066908,3.80922770500183,54,1,0,0,1,0.29876708984375,33.2355842590332,1,1,3,20.0427684783936,0,20.0421295166016,,,,,,,,,,,,,,,,,,,,,,,,,,,,,,,,,
,3883226191.45099,20.0260829925537,-39999.66015625,0.000641438948121012,7.18151798334248E-8,1,4,13.4005146026611,5.00653828206938,30.1099997013807,0.798682686350681,0.119848130499327,1,2.90724506052451E-7,,,,,,,,,,,,,,,,,,,,,20.0258140563965,20.0263519287109,-39999.66015625,-39999.66015625,53.5177138974768,5.64345057145665,3.80841135978699,54,1,0,0,1,0.301055908203125,33.2355842590332,1,1,3,20.0258140563965,0,20.0260829925537,,,,,,,,,,,,,,,,,,,,,,,,,,,,,,,,,
,3883226235.25626,20.0484676361084,-44999.7890625,0.000722138155231419,1.01244794014877E-7,1,4,13.4005146026611,5.00650442436876,30.1099997013807,0.899133456377455,0.135076748347638,1,4.49241384368232E-7,,,,,,,,,,,,,,,,,,,,,20.0471897125244,20.0497455596924,-44999.7890625,-44999.7890625,53.6806834437364,5.6429144504747,3.81526494026184,54,1,0,0,1,0.298995971679687,33.2355842590332,1,1,3,20.0497455596924,0,20.0484676361084,,,,,,,,,,,,,,,,,,,,,,,,,,,,,,,,,
,3883226239.14311,20.0506229400635,-44999.7890625,0.000722106115229969,1.05358382223469E-7,1,4,13.4005146026611,5.00652401900422,30.1099997013807,0.899090250565143,0.135126527163597,1,4.93416670948796E-7,,,,,,,,,,,,,,,,,,,,,20.0497856140137,20.0514602661133,-44999.7890625,-44999.7890625,53.5528871808422,5.64240905102201,3.80851912498474,54,2,0,0,1,0.301284790039063,33.7243423461914,1,1,3,20.0514602661133,0,20.0506229400635,,,,,,,,,,,,,,,,,,,,,,,,,,,,,,,,,