File: SQUID/23006_LCOS/transfer_119973_files_84937504/LSAT_subs_A1_MH_50K_FC_p0d5T_00001.dat
[Header]
; MPMS3 Data File (default extension .dat)
; Copyright (c) 2007, Quantum Design, Inc. All rights reserved.
TITLE,
FILEOPENTIME,3883232181.61591,01/18/2023,7:40 pm
BYAPP,SQUID AC,0.9.1.0
INFO,MPMS3 Measurement Release 1.1.16 Build 347, MultiVu Release 2.3.3.2,APPNAME
INFO,0,MOMENT_UNITS
INFO,LSAT,SAMPLE_MATERIAL
INFO,,SAMPLE_COMMENT
INFO,,SAMPLE_MASS
INFO,,SAMPLE_VOLUME
INFO,,SAMPLE_MOLECULAR_WEIGHT
INFO,,SAMPLE_SIZE
INFO,,SAMPLE_SHAPE
INFO,Quartz,SAMPLE_HOLDER
INFO,Standard,SAMPLE_HOLDER_DETAIL
INFO,65.8,SAMPLE_OFFSET
DATATYPE,COMMENT,1
DATATYPE,TIME,2
STARTUPAXIS,X,2
STARTUPAXIS,Y1,5
FIELDGROUP, VSM,2,3,4,5,6,8,9,10,11,14,15
FIELDGROUP, DC, 2,3,4,14,56,57,58,59,60,61,62,63,64,65,66,67,68,69
FIELDGROUP, AC, 2,3,4,11,16,17,18,19,20,21,22,23,24,25,26,27,28,29,30
STARTUPGROUP, All
[Data]
Comment,Time Stamp (sec),Temperature (K),Magnetic Field (Oe),Moment (emu),M. Std. Err. (emu),Transport Action,Averaging Time (sec),Frequency (Hz),Peak Amplitude (mm),Center Position (mm),Lockin Signal' (V),Lockin Signal (V),Range,M. Quad. Signal (emu),AC Moment (emu),AC M. Std Err. (emu),AC Phase (deg),AC Phase Std. Err. (deg),AC Susceptibility (emu/Oe),AC Suscept. Std Err. (emu/Oe),AC X' (emu/Oe),AC X' Std Err. (emu/Oe),AC X'' (emu/Oe),AC X'' Std Err. (emu/Oe),AC Drive (Oe),AC Frequency (Hz),AC Averaging Time (sec),AC Cycles,AC Range,AC Measure Type,AC Signal' (V),AC Signal'' (V),AC Trim Coil Ratio,AC Trim Coil Phase,Min. Temperature (K),Max. Temperature (K),Min. Field (Oe),Max. Field (Oe),Mass (grams),Motor Lag (deg),Pressure (Torr),Measure Count,Measurement Number,SQUID Status (code),Motor Status (code),Measure Status (code),Motor Current (amps),Motor Temp. (C),Temp. Status (code),Field Status (code),Chamber Status (code),Chamber Temp (K),Redirection State,Average Temp (K),Rotation Angle (deg),Rotator state,DC Moment Fixed Ctr (emu),DC Moment Err Fixed Ctr (emu),DC Moment Free Ctr (emu),DC Moment Err Free Ctr (emu),DC Fixed Fit,DC Free Fit,DC Calculated Center (mm),DC Calculated Center Err (mm),DC Scan Length (mm),DC Scan Time (s),DC Number of Points,DC Squid Drift,DC Min V (V),DC Max V (V),DC Scans per Measure,Map 01,Map 02,Map 03,Map 04,Map 05,Map 06,Map 07,Map 08,Map 09,Map 10,Map 11,Map 12,Map 13,Map 14,Map 15,Map 16
,3883232318.505,49.9994602203369,70000.4296875,-0.00115509253939932,3.07434607834667E-7,1,4,13.4005146026611,5.00586982602359,30.120000243187,-1.43794941751848,-0.216024461881213,1,-7.19708441649565E-7,,,,,,,,,,,,,,,,,,,,,49.9994430541992,49.9994773864746,70000.4296875,70000.4296875,53.2539142722364,5.64489009893945,5.12984275817871,52,1,68,0,0,0.302505493164063,32.2580642700195,1,1,3,49.9994773864746,0,49.9994602203369,,,,,,,,,,,,,,,,,,,,,,,,,,,,,,,,,
,3883232444.53986,49.8243865966797,60000.296875,-0.000988919828621947,1.59686639576689E-7,1,4,13.4005146026611,5.00586767132861,30.120000243187,-1.23105483184298,-0.185141223060091,1,-7.7228131404964E-7,,,,,,,,,,,,,,,,,,,,,49.8224678039551,49.8263053894043,60000.296875,60000.296875,53.5149781976595,5.64547284881755,5.0484881401062,51,1,68,0,0,0.300750732421875,33.7243423461914,1,1,3,49.8224678039551,0,49.8243865966797,,,,,,,,,,,,,,,,,,,,,,,,,,,,,,,,,
,3883232544.20452,49.9519901275635,50000.26953125,-0.000823911929380448,1.07155201215498E-7,1,4,13.4005146026611,5.00567032955069,30.120000243187,-1.02561344846035,-0.154074226140826,1,-5.09725414919418E-7,,,,,,,,,,,,,,,,,,,,,49.9513053894043,49.9526748657227,50000.26953125,50000.26953125,53.4590917585345,5.6462579625469,5.0405912399292,54,1,0,0,1,0.300140380859375,33.7243423461914,1,1,3,49.9526748657227,0,49.9519901275635,,,,,,,,,,,,,,,,,,,,,,,,,,,,,,,,,
,3883232642.58957,50.0033149719238,39999.66015625,-0.000658908916771518,4.34890529042736E-8,1,4,13.4005146026611,5.00538581082334,30.120000243187,-0.820169938406513,-0.123081274506647,1,-3.05577024953573E-7,,,,,,,,,,,,,,,,,,,,,50.0032424926758,50.0033874511719,39999.66015625,39999.66015625,53.3758483212364,5.64710204595831,5.03258562088013,54,1,0,0,1,0.301055908203125,33.7243423461914,1,1,3,50.0032424926758,0,50.0033149719238,,,,,,,,,,,,,,,,,,,,,,,,,,,,,,,,,
,3883232741.80961,50.0316143035889,29999.662109375,-0.000493954612497317,6.43097266410458E-8,1,4,13.4005146026611,5.00555818021232,30.120000243187,-0.614888347761804,-0.0921798222641486,1,-1.5424322656133E-7,,,,,,,,,,,,,,,,,,,,,50.0249176025391,50.0383110046387,29999.662109375,29999.662109375,53.5188863402557,5.64631049168089,5.03911638259888,53,1,68,0,0,0.303726196289063,33.2355842590332,1,1,3,50.0383110046387,0,50.0316143035889,,,,,,,,,,,,,,,,,,,,,,,,,,,,,,,,,
,3883232826.35603,50.0033836364746,19999.654296875,-0.000329077114036386,2.09000135873079E-8,1,4,13.4005146026611,5.00567505010863,30.120000243187,-0.409674406509387,-0.0613010819240008,1,-1.28172825221657E-8,,,,,,,,,,,,,,,,,,,,,50.0032539367676,50.0035133361816,19999.654296875,19999.654296875,53.5079435409864,5.64575044023572,5.04957628250122,54,1,0,0,1,0.301513671875,33.2355842590332,1,1,3,50.0032539367676,0,50.0033836364746,,,,,,,,,,,,,,,,,,,,,,,,,,,,,,,,,
,3883232903.40291,50.0079708099365,14499.580078125,-0.000238416955963849,2.2686603950545E-8,1,4,13.4005146026611,5.00575224005712,30.120000243187,-0.296822657896817,-0.044370784514758,1,2.51860596215778E-8,,,,,,,,,,,,,,,,,,,,,50.0073623657227,50.0085792541504,14499.580078125,14499.580078125,53.491138527823,5.64536727965774,5.05516958236694,54,1,0,0,1,0.303497314453125,33.7243423461914,1,1,3,50.0073623657227,0,50.0079708099365,,,,,,,,,,,,,,,,,,,,,,,,,,,,,,,,,
,3883232945.80779,50.0012226104736,13499.5810546875,-0.000221917119437313,2.00863378044446E-8,1,4,13.4005146026611,5.0058353684944,30.120000243187,-0.276291929015659,-0.0412695707339875,1,4.87101217017013E-8,,,,,,,,,,,,,,,,,,,,,50.0009422302246,50.0015029907227,13499.5810546875,13499.5810546875,53.467689672246,5.64550528432444,5.05965709686279,54,1,0,0,1,0.302734375,33.7243423461914,1,1,3,50.0009422302246,0,50.0012226104736,,,,,,,,,,,,,,,,,,,,,,,,,,,,,,,,,
,3883232986.75012,50.0219593048096,12499.6708984375,-0.000205421216728705,2.24724909001015E-8,1,4,13.4005146026611,5.00600152921725,30.120000243187,-0.255764638738878,-0.0382128601442702,1,3.76735302656345E-8,,,,,,,,,,,,,,,,,,,,,50.0185890197754,50.0253295898438,12499.6708984375,12499.6708984375,53.5528871808422,5.64504890528961,5.05108833312988,54,1,0,0,1,0.30120849609375,34.2131004333496,1,1,3,50.0253295898438,0,50.0219593048096,,,,,,,,,,,,,,,,,,,,,,,,,,,,,,,,,
,3883233026.70247,50.040943145752,11499.798828125,-0.000188942601965751,2.28050361965623E-8,1,4,13.4005146026611,5.00598087254592,30.120000243187,-0.235248006008377,-0.0351350989392623,1,4.44294515675316E-8,,,,,,,,,,,,,,,,,,,,,50.0356864929199,50.046199798584,11499.798828125,11499.798828125,53.5059894696884,5.64504279699579,5.06197690963745,53,1,68,0,0,0.303497314453125,34.2131004333496,1,1,3,50.046199798584,0,50.040943145752,,,,,,,,,,,,,,,,,,,,,,,,,,,,,,,,,
,3883233067.66278,50.0719718933105,10499.5361328125,-0.000172442804584647,2.07937558253702E-8,1,4,13.4005146026611,5.00585900727506,30.120000243187,-0.21469349448732,-0.0320904460112625,1,2.0724019379634E-8,,,,,,,,,,,,,,,,,,,,,50.0681266784668,50.0758171081543,10499.5361328125,10499.5361328125,53.4739427003999,5.6451354233913,5.06296253204346,54,1,0,0,1,0.302734375,34.2131004333496,1,1,3,50.0758171081543,0,50.0719718933105,,,,,,,,,,,,,,,,,,,,,,,,,,,,,,,,,
,3883233109.80137,50.0261402130127,9499.6884765625,-0.000155940954398242,1.65330732364631E-8,1,4,13.4005146026611,5.00567015320377,30.120000243187,-0.194138658099414,-0.0290152284034764,1,2.09927694865386E-8,,,,,,,,,,,,,,,,,,,,,50.0238990783691,50.0283813476562,9499.6884765625,9499.6884765625,53.4348612744383,5.64546084309152,5.06198501586914,54,1,0,0,1,0.301361083984375,34.2131004333496,1,1,3,50.0238990783691,0,50.0261402130127,,,,,,,,,,,,,,,,,,,,,,,,,,,,,,,,,
,3883233151.83843,50.0039520263672,8499.52734375,-0.000139460327248566,1.92230894762725E-8,1,4,13.4005146026611,5.00529007575164,30.120000243187,-0.17360396952821,-0.0259373187680171,1,2.57462589426226E-8,,,,,,,,,,,,,,,,,,,,,50.0034484863281,50.0044555664063,8499.52734375,8499.52734375,53.4551836159384,5.64705785648979,5.05738306045532,53,1,68,0,0,0.303573608398438,34.2131004333496,1,1,3,50.0034484863281,0,50.0039520263672,,,,,,,,,,,,,,,,,,,,,,,,,,,,,,,,,
,3883233193.91654,50.0206871032715,7499.541015625,-0.000122958880234789,1.68204437125685E-8,1,4,13.4005146026611,5.00527627168276,30.120000243187,-0.153056524728539,-0.0229043921430909,1,-6.3479097166117E-9,,,,,,,,,,,,,,,,,,,,,50.0191116333008,50.0222625732422,7499.541015625,7499.541015625,53.4375969742557,5.64656920320448,5.06470632553101,54,1,0,0,1,0.300827026367188,34.2131004333496,1,1,3,50.0191116333008,0,50.0206871032715,,,,,,,,,,,,,,,,,,,,,,,,,,,,,,,,,
,3883233236.82123,50.0497703552246,6499.517578125,-0.000106475669758475,1.32125990497435E-8,1,4,13.4005146026611,5.00540751594732,30.120000243187,-0.13254693990042,-0.0198113134524933,1,1.32730428340442E-8,,,,,,,,,,,,,,,,,,,,,50.0487251281738,50.0508155822754,6499.517578125,6499.517578125,53.4188378897941,5.64678575234467,5.0701413154602,53,1,68,0,0,0.301284790039063,34.2131004333496,1,1,3,50.0508155822754,0,50.0497703552246,,,,,,,,,,,,,,,,,,,,,,,,,,,,,,,,,
,3883233277.56439,50.0402431488037,5499.54443359375,-8.99903211690707E-5,1.14548154437955E-8,1,4,13.4005146026611,5.00529078940042,30.120000243187,-0.112017569292955,-0.0167689870020135,1,-9.31009643231267E-9,,,,,,,,,,,,,,,,,,,,,50.036994934082,50.0434913635254,5499.54443359375,5499.54443359375,53.5274842539672,5.64664121771486,5.06794214248657,54,1,0,0,1,0.3033447265625,34.2131004333496,1,1,3,50.036994934082,0,50.0402431488037,,,,,,,,,,,,,,,,,,,,,,,,,,,,,,,,,
,3883233319.69966,50.0082721710205,4499.5205078125,-7.34976063924801E-5,1.0202138499898E-8,1,4,13.4005146026611,5.00539804894176,30.120000243187,-0.0914896586879043,-0.0137025098640775,1,-1.27449654506186E-8,,,,,,,,,,,,,,,,,,,,,50.007942199707,50.008602142334,4499.5205078125,4499.5205078125,53.5141965691403,5.64679920959597,5.07275676727295,54,1,0,0,1,0.301055908203125,34.7018585205078,1,1,3,50.007942199707,0,50.0082721710205,,,,,,,,,,,,,,,,,,,,,,,,,,,,,,,,,
,3883233361.23925,50.0021743774414,3499.6103515625,-5.70013214563281E-5,8.13335762395504E-9,1,4,13.4005146026611,5.00534785091923,30.120000243187,-0.0709538598464867,-0.0106286485046473,1,-1.13053982092384E-8,,,,,,,,,,,,,,,,,,,,,50.0019264221191,50.0024223327637,3499.6103515625,3499.6103515625,53.5087251695057,5.64642408663652,5.07338285446167,54,1,0,0,1,0.301666259765625,33.7243423461914,1,1,3,50.0019149780273,0,50.0021743774414,,,,,,,,,,,,,,,,,,,,,,,,,,,,,,,,,
,3883233421.46128,50.036979675293,2709.69750976562,-4.39600555886083E-5,7.85744706416462E-9,1,4,13.4005146026611,5.00562556795889,30.120000243187,-0.0547236315395464,-0.00820440638022849,1,-1.42116317062605E-8,,,,,,,,,,,,,,,,,,,,,50.0361671447754,50.0377922058105,2709.69750976562,2709.69750976562,53.4364245314768,5.64617938555859,5.07443809509277,54,1,0,0,1,0.301132202148438,34.2131004333496,1,1,3,50.0377922058105,0,50.036979675293,,,,,,,,,,,,,,,,,,,,,,,,,,,,,,,,,
,3883233460.54187,50.0185604095459,2129.78149414062,-3.44005070748593E-5,7.37956557476107E-9,1,4,13.4005146026611,5.00576898200544,30.120000243187,-0.0428255871772866,-0.00641762949190256,1,-8.78788449313353E-9,,,,,,,,,,,,,,,,,,,,,50.0168495178223,50.0202713012695,2129.78149414062,2129.78149414062,53.5200587830345,5.64558588269859,5.07524490356445,54,1,0,0,1,0.301132202148438,34.2131004333496,1,1,3,50.0168495178223,0,50.0185604095459,,,,,,,,,,,,,,,,,,,,,,,,,,,,,,,,,
,3883233499.71968,50.0373477935791,1549.71484375,-2.4825052316064E-5,7.16856230197897E-9,1,4,13.4005146026611,5.00581909522464,30.120000243187,-0.0309039930705508,-0.00464091188544757,1,-1.403545135999E-8,,,,,,,,,,,,,,,,,,,,,50.0359802246094,50.0387153625488,1549.71484375,1549.71484375,53.4993456272749,5.64567383226044,5.0748553276062,54,1,0,0,1,0.301895141601562,33.7243423461914,1,1,3,50.0387153625488,0,50.0373477935791,,,,,,,,,,,,,,,,,,,,,,,,,,,,,,,,,
,3883233539.06957,50.0118522644043,969.748779296875,-1.52551783188634E-5,7.79480212261121E-9,1,4,13.4005146026611,5.00572521147714,30.120000243187,-0.0189890530493235,-0.00285969679782368,1,-1.49680625573747E-8,,,,,,,,,,,,,,,,,,,,,50.0105209350586,50.01318359375,969.748779296875,969.748779296875,53.4618274583518,5.64523366875196,5.08504819869995,54,1,0,0,1,0.303573608398438,33.7243423461914,1,1,3,50.0105209350586,0,50.0118522644043,,,,,,,,,,,,,,,,,,,,,,,,,,,,,,,,,
,3883233579.2662,50.0070323944092,389.757537841797,-5.71340131833165E-6,5.96223660511721E-9,1,4,13.4005146026611,5.00563527379716,30.120000243187,-0.00711234145668939,-0.00106631188266576,1,-1.8458939706015E-9,,,,,,,,,,,,,,,,,,,,,50.0064430236816,50.0076217651367,389.757537841797,389.757537841797,53.5208404115537,5.64563879484996,5.08103799819946,54,1,0,0,1,0.303421020507812,33.7243423461914,1,1,3,50.0064430236816,0,50.0070323944092,,,,,,,,,,,,,,,,,,,,,,,,,,,,,,,,,
,3883233616.95806,50.0185680389404,-190.221115112305,3.78524225316281E-6,2.40893742894765E-8,1,4,13.4005146026611,5.00561056219532,30.120000243187,0.00471654269743358,0.000676318108547302,1,-2.29796403505008E-8,,,,,,,,,,,,,,,,,,,,,50.0153617858887,50.0217742919922,-190.221115112305,-190.221115112305,53.4161021899768,5.64588442802211,5.08146047592163,54,1,0,0,1,0.303421020507812,34.2131004333496,1,1,3,50.0217742919922,0,50.0185680389404,,,,,,,,,,,,,,,,,,,,,,,,,,,,,,,,,
,3883233653.77137,50.0228004455566,-770.350830078125,1.31697674703028E-5,1.75805376351995E-8,1,4,13.4005146026611,5.00560477886023,30.120000243187,0.0163898643013942,0.0024873979172292,1,2.79511699791454E-8,,,,,,,,,,,,,,,,,,,,,50.0204849243164,50.0251159667969,-770.350830078125,-770.350830078125,53.416883818496,5.64610247376449,5.0863151550293,54,1,0,0,1,0.300979614257812,33.2355842590332,1,1,3,50.0251159667969,0,50.0228004455566,,,,,,,,,,,,,,,,,,,,,,,,,,,,,,,,,
,3883233692.02191,50.0269393920898,-1349.86376953125,2.26941359023727E-5,5.35168534599481E-8,1,4,13.4005146026611,5.00556801230928,30.120000243187,0.0282616913188998,0.00415938560299393,1,-5.37336424858428E-8,,,,,,,,,,,,,,,,,,,,,50.0233612060547,50.030517578125,-1349.86376953125,-1349.86376953125,53.5474157812076,5.64650572623546,5.08630466461182,54,1,0,0,1,0.302200317382812,34.2131004333496,1,1,3,50.030517578125,0,50.0269393920898,,,,,,,,,,,,,,,,,,,,,,,,,,,,,,,,,
,3883233730.18466,50.0246639251709,-1930.34594726562,3.22463132057793E-5,3.79582999081632E-8,1,4,13.4005146026611,5.00556396254896,30.120000243187,0.0401431972658718,0.00600411083154432,1,-8.36192574019489E-10,,,,,,,,,,,,,,,,,,,,,50.0237350463867,50.0255928039551,-1930.34594726562,-1930.34594726562,53.4266541749864,5.64598137983569,5.07985305786133,54,1,0,0,1,0.30181884765625,33.7243423461914,1,1,3,50.0255928039551,0,50.0246639251709,,,,,,,,,,,,,,,,,,,,,,,,,,,,,,,,,
,3883233768.03936,50.0072765350342,-2509.88403320313,4.17526141395936E-5,6.58715433016864E-8,1,4,13.4005146026611,5.00545872817265,30.120000243187,0.0519744607470949,0.00778415415442827,1,7.14610163767892E-9,,,,,,,,,,,,,,,,,,,,,50.0070495605469,50.0075035095215,-2509.88403320313,-2509.88403320313,53.480977357073,5.64627975070674,5.09224605560303,54,1,0,0,1,0.302963256835937,33.7243423461914,1,1,3,50.0070495605469,0,50.0072765350342,,,,,,,,,,,,,,,,,,,,,,,,,,,,,,,,,
,3883233822.41143,50.0589408874512,-2999.9951171875,4.98103467752014E-5,6.23827764476002E-9,1,4,13.4005146026611,5.00539822918052,30.120000243187,0.0620166680593644,0.00920044940920516,1,-6.03936290142119E-8,,,,,,,,,,,,,,,,,,,,,50.0584449768066,50.0594367980957,-2999.9951171875,-2999.9951171875,53.5243577398903,5.6466536564453,5.09020185470581,54,1,0,0,1,0.302886962890625,34.2131004333496,1,1,3,50.0584449768066,0,50.0589408874512,,,,,,,,,,,,,,,,,,,,,,,,,,,,,,,,,
,3883233862.55927,50.0509948730469,-3999.94311523438,6.6182174467942E-5,7.90786276595919E-9,1,4,13.4005146026611,5.00537115870811,30.120000243187,0.0823974254494453,0.0122408402967535,1,-6.70296264185528E-8,,,,,,,,,,,,,,,,,,,,,50.0501327514648,50.0518569946289,-3999.94311523438,-3999.94311523438,53.457528501496,5.64706995178591,5.08606910705566,54,1,0,0,1,0.301437377929687,33.7243423461914,1,1,3,50.0518569946289,0,50.0509948730469,,,,,,,,,,,,,,,,,,,,,,,,,,,,,,,,,
,3883233902.29397,50.02028465271,-5000.0927734375,8.26168300550175E-5,9.75174063524325E-9,1,4,13.4005146026611,5.00532145530946,30.120000243187,0.102857724217411,0.0152774723940036,1,-8.59693108702651E-8,,,,,,,,,,,,,,,,,,,,,50.0184135437012,50.0221557617188,-5000.0927734375,-5000.0927734375,53.4950466704191,5.64697400243825,5.08487462997437,54,1,0,0,1,0.300979614257812,33.7243423461914,1,1,3,50.0177383422852,0,50.02028465271,,,,,,,,,,,,,,,,,,,,,,,,,,,,,,,,,
,3883233943.013,50.0135116577148,-5999.9775390625,9.90708523147687E-5,1.13623213981636E-8,1,4,13.4005146026611,5.00531226181168,30.120000243187,0.123338903303531,0.0183449386271471,1,-8.31345384019787E-8,,,,,,,,,,,,,,,,,,,,,50.0121879577637,50.014835357666,-5999.9775390625,-5999.9775390625,53.4665172294672,5.64679723363674,5.08684778213501,54,1,0,0,1,0.301895141601562,33.7243423461914,1,1,3,50.0148506164551,0,50.0135116577148,,,,,,,,,,,,,,,,,,,,,,,,,,,,,,,,,
,3883233982.60534,50.0609703063965,-6999.63623046875,0.000115531532617312,7.38541264047458E-9,1,4,13.4005146026611,5.005343738051,30.120000243187,0.143835613834809,0.0213756717276765,1,-1.10987550960384E-7,,,,,,,,,,,,,,,,,,,,,50.0565567016602,50.0653839111328,-6999.63623046875,-6999.63623046875,53.4008604338518,5.64639171807518,5.09029197692871,54,1,0,0,1,0.303268432617188,33.7243423461914,1,1,3,50.0653839111328,0,50.0609703063965,,,,,,,,,,,,,,,,,,,,,,,,,,,,,,,,,
,3883234022.81562,50.0460147857666,-7999.98681640625,0.000131990349010596,1.43050124185969E-8,1,4,13.4005146026611,5.00538827637071,30.120000243187,0.164323810001645,0.0244540245394933,1,-1.00422006413686E-7,,,,,,,,,,,,,,,,,,,,,50.042537689209,50.0494918823242,-7999.98681640625,-7999.98681640625,53.480977357073,5.64605609903759,5.09154748916626,52,1,68,0,0,0.302276611328125,33.7243423461914,1,1,3,50.042537689209,0,50.0460147857666,,,,,,,,,,,,,,,,,,,,,,,,,,,,,,,,,
,3883234063.06897,50.0744380950928,-8999.6826171875,0.000148478464131199,1.33471313697545E-8,1,4,13.4005146026611,5.00542897212828,30.120000243187,0.184855033528536,0.0274961427305868,1,-1.23384994578996E-7,,,,,,,,,,,,,,,,,,,,,50.0718383789063,50.0770378112793,-8999.6826171875,-8999.6826171875,53.4794141000345,5.64677346634896,5.09951210021973,54,1,0,0,1,0.304336547851562,33.7243423461914,1,1,3,50.0770378112793,0,50.0744380950928,,,,,,,,,,,,,,,,,,,,,,,,,,,,,,,,,
,3883234104.29587,50.0452060699463,-9999.7578125,0.000164932985677598,1.61236647179E-8,1,4,13.4005146026611,5.00545539918802,30.120000243187,0.205339730101729,0.0305610719378694,1,-1.2295605672789E-7,,,,,,,,,,,,,,,,,,,,,50.0438003540039,50.0466117858887,-9999.7578125,-9999.7578125,53.5024721413518,5.64644909072153,5.10007476806641,54,1,0,0,1,0.302276611328125,33.7243423461914,1,1,3,50.0438003540039,0,50.0452060699463,,,,,,,,,,,,,,,,,,,,,,,,,,,,,,,,,
,3883234144.79334,50.0311260223389,-10999.73046875,0.000181419866988419,1.77956706570615E-8,1,4,13.4005146026611,5.00544301904518,30.120000243187,0.225860883043617,0.0336429437403077,1,-1.13501253674489E-7,,,,,,,,,,,,,,,,,,,,,50.0283241271973,50.0339279174805,-10999.73046875,-10999.73046875,53.462609086871,5.64629170100685,5.10190534591675,52,1,68,0,0,0.303115844726562,33.7243423461914,1,1,3,50.0283241271973,0,50.0311260223389,,,,,,,,,,,,,,,,,,,,,,,,,,,,,,,,,
,3883234184.71876,50.0201930999756,-11999.830078125,0.00019789461520826,1.97052202426363E-8,1,4,13.4005146026611,5.00547133116298,30.120000243187,0.246373588052478,0.0366962323097603,1,-1.25510738475035E-7,,,,,,,,,,,,,,,,,,,,,50.0195159912109,50.0208702087402,-11999.830078125,-11999.830078125,53.3570892367749,5.64646294051049,5.09924221038818,53,1,68,0,0,0.300521850585937,33.7243423461914,1,1,3,50.0195159912109,0,50.0201930999756,,,,,,,,,,,,,,,,,,,,,,,,,,,,,,,,,
,3883234225.33146,50.0588092803955,-12999.94140625,0.000214362528119493,1.46679319287827E-8,1,4,13.4005146026611,5.00550520220786,30.120000243187,0.266876343461287,0.0397629270732233,1,-1.25816908027507E-7,,,,,,,,,,,,,,,,,,,,,50.0569725036621,50.0606460571289,-12999.94140625,-12999.94140625,53.404768576448,5.6465565849865,5.10705661773682,54,1,0,0,1,0.301742553710937,33.7243423461914,1,1,3,50.0606460571289,0,50.0588092803955,,,,,,,,,,,,,,,,,,,,,,,,,,,,,,,,,
,3883234267.40095,50.0369300842285,-13999.73828125,0.000230825377512444,2.25993221378577E-8,1,4,13.4005146026611,5.00566653439597,30.120000243187,0.287378580215507,0.0428625852844053,1,-1.00158899365551E-7,,,,,,,,,,,,,,,,,,,,,50.0350570678711,50.0388031005859,-13999.73828125,-13999.73828125,53.4923109706018,5.64604047481668,5.09930324554443,54,1,0,0,1,0.304031372070313,33.7243423461914,1,1,3,50.0350570678711,0,50.0369300842285,,,,,,,,,,,,,,,,,,,,,,,,,,,,,,,,,
,3883234334.51163,50.0431251525879,-14999.5732421875,0.000247481486783473,2.226761726819E-8,1,4,13.4005146026611,5.00565518195005,30.120000243187,0.308169464387313,0.0455881354625496,10,-4.02362616986488E-7,,,,,,,,,,,,,,,,,,,,,50.0427513122559,50.0434989929199,-14999.5732421875,-14999.5732421875,53.4817589855922,5.64616849753092,5.09911060333252,54,1,0,0,1,0.302200317382812,33.7243423461914,1,1,3,50.0427513122559,0,50.0431251525879,,,,,,,,,,,,,,,,,,,,,,,,,,,,,,,,,
,3883234437.82079,50.0137710571289,-24999.64453125,0.000412184359000293,3.31115287068131E-8,1,4,13.4005146026611,5.00567796543105,30.120000243187,0.513147333706816,0.0767109377493569,1,-4.14391465081313E-8,,,,,,,,,,,,,,,,,,,,,50.0111389160156,50.0164031982422,-24999.64453125,-24999.64453125,53.4751151431787,5.64619893208989,5.10539722442627,54,1,0,0,1,0.301666259765625,33.7243423461914,1,1,3,50.0164031982422,0,50.0137710571289,,,,,,,,,,,,,,,,,,,,,,,,,,,,,,,,,
,3883234524.95694,50.0003032684326,-34999.66796875,0.000577162456056302,5.51324557470337E-8,1,4,13.4005146026611,5.0055639855362,30.120000243187,0.718490164449252,0.107565997923405,1,6.62300746686592E-8,,,,,,,,,,,,,,,,,,,,,50.0000648498535,50.0005416870117,-34999.66796875,-34999.66796875,53.3723309928999,5.64720443988896,5.10111951828003,54,1,0,0,1,0.302352905273438,33.7243423461914,1,1,3,50.0000648498535,0,50.0003032684326,,,,,,,,,,,,,,,,,,,,,,,,,,,,,,,,,
,3883234611.88809,50.00026512146,-44999.51171875,0.000742149844176605,5.64352826276232E-8,1,4,13.4005146026611,5.00545425488087,30.120000243187,0.923825066470736,0.138471215824998,1,2.14248149053811E-7,,,,,,,,,,,,,,,,,,,,,49.9999885559082,50.0005416870117,-44999.51171875,-44999.51171875,53.5345189106403,5.64687134506538,5.11059474945068,52,1,68,0,0,0.300827026367188,33.7243423461914,1,1,3,49.9999885559082,0,50.00026512146,,,,,,,,,,,,,,,,,,,,,,,,,,,,,,,,,
,3883234726.26469,50.0142707824707,-54999.58203125,0.000907261473826669,1.08785257415115E-7,1,4,13.4005146026611,5.0053294258351,30.120000243187,1.12928031808196,0.169510292826918,1,4.53310786451583E-7,,,,,,,,,,,,,,,,,,,,,50.0116424560547,50.0168991088867,-54999.58203125,-54999.58203125,53.2582132290922,5.64728653628944,5.11118745803833,54,1,0,0,1,0.303726196289063,33.7243423461914,1,1,3,50.0168991088867,0,50.0142707824707,,,,,,,,,,,,,,,,,,,,,,,,,,,,,,,,,
,3883234814.68821,50.0339126586914,-64999.69140625,0.00107249410413341,1.29550606632167E-7,1,4,13.4005146026611,5.00521366515748,30.120000243187,1.33486669167241,0.200627362282044,1,7.38260115150528E-7,,,,,,,,,,,,,,,,,,,,,50.0310401916504,50.0367851257324,-64999.69140625,-64999.69140625,53.3598249365922,5.64736477754064,5.09269952774048,53,1,68,0,0,0.30242919921875,33.2355842590332,1,1,3,50.0367851257324,0,50.0339126586914,,,,,,,,,,,,,,,,,,,,,,,,,,,,,,,,,
,3883234901.47668,50.0551605224609,-64999.7421875,0.00107227652592232,9.85519938976431E-8,1,4,13.4005146026611,5.005160060211,30.120000243187,1.33460473570882,0.200390885030658,1,5.8324222521163E-7,,,,,,,,,,,,,,,,,,,,,50.0427436828613,50.0675773620605,-64999.7421875,-64999.7421875,53.335594452496,5.64809293061821,5.09555959701538,54,1,0,0,1,0.30487060546875,33.7243423461914,1,1,3,50.0675773620605,0,50.0551605224609,,,,,,,,,,,,,,,,,,,,,,,,,,,,,,,,,
,3883234987.75856,50.0173168182373,-54999.59375,0.000906905773153207,1.26518610418951E-7,1,4,13.4005146026611,5.00508649789962,30.120000243187,1.12876446967315,0.16940888096168,1,4.34290345668003E-7,,,,,,,,,,,,,,,,,,,,,50.0156555175781,50.0189781188965,-54999.59375,-54999.59375,53.228902159621,5.64845218912901,5.10451936721802,54,1,0,0,1,0.304107666015625,33.7243423461914,1,1,3,50.0156555175781,0,50.0173168182373,,,,,,,,,,,,,,,,,,,,,,,,,,,,,,,,,
,3883235074.02345,50.0248489379883,-44999.75,0.000741747261829283,1.30781073516876E-7,1,4,13.4005146026611,5.00518447234492,30.120000243187,0.923240434914743,0.138478660222002,1,2.88836692935428E-7,,,,,,,,,,,,,,,,,,,,,50.0205421447754,50.0291557312012,-44999.75,-44999.75,53.3688136645633,5.64731348933535,5.10635232925415,54,1,0,0,1,0.304718017578125,33.7243423461914,1,1,3,50.0291557312012,0,50.0248489379883,,,,,,,,,,,,,,,,,,,,,,,,,,,,,,,,,
,3883235174.67952,50.0068626403809,-34999.6171875,0.000576622848522375,5.59749675892145E-8,1,4,13.4005146026611,5.00513489103564,30.120000243187,0.717716225410129,0.10756054706255,1,1.52931552833323E-7,,,,,,,,,,,,,,,,,,,,,50.0060386657715,50.0076866149902,-34999.6171875,-34999.6171875,53.406722647746,5.64795275625473,5.10462522506714,54,1,0,0,1,0.302047729492188,34.7018585205078,1,1,3,50.0060386657715,0,50.0068626403809,,,,,,,,,,,,,,,,,,,,,,,,,,,,,,,,,
,3883235261.08385,50.0261993408203,-24999.80859375,0.000411643823404612,4.37818743918557E-8,1,4,13.4005146026611,5.00520634556511,30.120000243187,0.512385954440093,0.0767401360631281,1,7.09974896937078E-8,,,,,,,,,,,,,,,,,,,,,50.0212707519531,50.0311279296875,-24999.80859375,-24999.80859375,53.3918717058807,5.64768228511224,5.11598539352417,54,1,0,0,1,0.3033447265625,33.7243423461914,1,1,3,50.0311279296875,0,50.0261993408203,,,,,,,,,,,,,,,,,,,,,,,,,,,,,,,,,
,3883235346.67623,50.0106639862061,-14999.7998046875,0.000246671233212523,2.30795193467053E-8,1,4,13.4005146026611,5.00518441434194,30.120000243187,0.307038427237122,0.0459790357451231,1,3.77003558775171E-8,,,,,,,,,,,,,,,,,,,,,50.0095443725586,50.0117835998535,-14999.7998046875,-14999.7998046875,53.445413259448,5.64841606388193,5.11454439163208,54,1,0,0,1,0.305023193359375,34.2131004333496,1,1,3,50.0095443725586,0,50.0106639862061,,,,,,,,,,,,,,,,,,,,,,,,,,,,,,,,,
,3883235401.5858,50.0673828125,-14000.078125,0.000230203410608257,1.94912156616343E-8,1,4,13.4005146026611,5.00519241341833,30.120000243187,0.286546657319532,0.0428725368364632,1,5.43886324321138E-9,,,,,,,,,,,,,,,,,,,,,50.0652809143066,50.0694847106934,-14000.078125,-14000.078125,53.4614366440922,5.64812178155502,5.12148141860962,54,1,0,0,1,0.302658081054687,34.2131004333496,1,1,3,50.0694847106934,0,50.0673828125,,,,,,,,,,,,,,,,,,,,,,,,,,,,,,,,,
,3883235441.74661,50.0613269805908,-13000.2939453125,0.000213702594575709,2.44578221445397E-8,1,4,13.4005146026611,5.00517544565895,30.120000243187,0.266003722111132,0.0398140786400959,1,1.69415647933718E-8,,,,,,,,,,,,,,,,,,,,,50.054515838623,50.0681381225586,-13000.2939453125,-13000.2939453125,53.4602642013134,5.64820989816114,5.12027883529663,54,1,0,0,1,0.306015014648438,34.2131004333496,1,1,3,50.0681381225586,0,50.0613269805908,,,,,,,,,,,,,,,,,,,,,,,,,,,,,,,,,
,3883235480.73653,50.0651912689209,-12000.2451171875,0.000197210950766717,2.33280038740415E-8,1,4,13.4005146026611,5.00511598052523,30.120000243187,0.245475776212074,0.0367148602246817,1,-5.34671113987251E-9,,,,,,,,,,,,,,,,,,,,,50.057804107666,50.0725784301758,-12000.2451171875,-12000.2451171875,53.3074558258037,5.64848154569222,5.11592435836792,54,1,0,0,1,0.306015014648438,34.2131004333496,1,1,3,50.0725784301758,0,50.0651912689209,,,,,,,,,,,,,,,,,,,,,,,,,,,,,,,,,
,3883235520.9173,50.0487480163574,-11000.146484375,0.000180717902804272,1.98941279671392E-8,1,4,13.4005146026611,5.00514969958331,30.120000243187,0.224948260441677,0.0336455083273815,1,-4.21665437220117E-9,,,,,,,,,,,,,,,,,,,,,50.0478820800781,50.0496139526367,-11000.146484375,-11000.146484375,53.3887451918037,5.64833572252928,5.11632442474365,54,1,0,0,1,0.302047729492188,34.2131004333496,1,1,3,50.0496139526367,0,50.0487480163574,,,,,,,,,,,,,,,,,,,,,,,,,,,,,,,,,
,3883235560.54946,50.0615215301514,-10000.3994140625,0.000164232162977229,1.86798352070561E-8,1,4,13.4005146026611,5.0052447279089,30.120000243187,0.204432621547718,0.0305802212376434,1,-1.28863969366324E-9,,,,,,,,,,,,,,,,,,,,,50.0544967651367,50.068546295166,-10000.3994140625,-10000.3994140625,53.4297806890633,5.64752159252811,5.11247205734253,54,1,0,0,1,0.303115844726562,33.7243423461914,1,1,3,50.068546295166,0,50.0615215301514,,,,,,,,,,,,,,,,,,,,,,,,,,,,,,,,,
,3883235601.05331,50.0231971740723,-9000.2998046875,0.000147730346412295,1.32038651047533E-8,1,4,13.4005146026611,5.00528181947449,30.120000243187,0.18388805650056,0.0275437364658143,1,2.76712243824499E-8,,,,,,,,,,,,,,,,,,,,,50.0212211608887,50.0251731872559,-9000.2998046875,-9000.2998046875,53.5321740250826,5.64798799753633,5.12278985977173,54,1,0,0,1,0.303878784179687,33.7243423461914,1,1,3,50.0212211608887,0,50.0231971740723,,,,,,,,,,,,,,,,,,,,,,,,,,,,,,,,,
,3883235643.1271,50.0344486236572,-8000.1376953125,0.000131240739521472,1.44054683357256E-8,1,4,13.4005146026611,5.0054005809794,30.120000243187,0.163374740179936,0.0244247994707854,1,-1.18297088550396E-8,,,,,,,,,,,,,,,,,,,,,50.0329818725586,50.0359153747559,-8000.1376953125,-8000.1376953125,53.5118516835826,5.64692592392717,5.12433815002441,54,1,0,0,1,0.30242919921875,33.7243423461914,1,1,3,50.0359153747559,0,50.0344486236572,,,,,,,,,,,,,,,,,,,,,,,,,,,,,,,,,
,3883235683.57008,50.0258827209473,-7000.32861328125,0.000114745695547776,1.05245795881166E-8,1,4,13.4005146026611,5.00540358571172,30.120000243187,0.14283312465434,0.0214078997752128,1,3.21712091800866E-8,,,,,,,,,,,,,,,,,,,,,50.0246315002441,50.0271339416504,-7000.32861328125,-7000.32861328125,53.6287051472076,5.64771748692751,5.12184381484985,54,1,0,0,1,0.30364990234375,33.7243423461914,1,1,3,50.0246315002441,0,50.0258827209473,,,,,,,,,,,,,,,,,,,,,,,,,,,,,,,,,
,3883235724.88929,50.0746536254883,-6000.35546875,9.82459507555153E-5,1.07697379146765E-8,1,4,13.4005146026611,5.00536898715986,30.120000243187,0.122295134242729,0.018317758059848,1,1.81971717470168E-8,,,,,,,,,,,,,,,,,,,,,50.0698699951172,50.0794372558594,-6000.35546875,-6000.35546875,53.493092599121,5.64753965557742,5.12708187103271,53,1,68,0,0,0.302047729492188,34.7018585205078,1,1,3,50.0794372558594,0,50.0746536254883,,,,,,,,,,,,,,,,,,,,,,,,,,,,,,,,,
,3883235765.95738,50.044189453125,-5000.24365234375,8.17546089812949E-5,8.6652471872212E-9,1,4,13.4005146026611,5.00540444974283,30.120000243187,0.101768245064454,0.0152412226516352,1,1.36089125127372E-8,,,,,,,,,,,,,,,,,,,,,50.0439338684082,50.0444450378418,-5000.24365234375,-5000.24365234375,53.4801957285537,5.64715190966905,5.12038946151733,52,1,68,0,0,0.30303955078125,34.2131004333496,1,1,3,50.0439338684082,0,50.044189453125,,,,,,,,,,,,,,,,,,,,,,,,,,,,,,,,,
,3883235807.16874,50.0280017852783,-4000.28295898438,6.5252626813857E-5,8.41652968379363E-9,1,4,13.4005146026611,5.00548733368013,30.120000243187,0.0812278697770536,0.0121688877516715,1,1.39061861778307E-8,,,,,,,,,,,,,,,,,,,,,50.0251159667969,50.0308876037598,-4000.28295898438,-4000.28295898438,53.518495525996,5.64681779484646,5.12942361831665,53,1,68,0,0,0.304412841796875,33.7243423461914,1,1,3,50.0308876037598,0,50.0280017852783,,,,,,,,,,,,,,,,,,,,,,,,,,,,,,,,,
,3883235848.47693,50.0264167785645,-3000.42309570313,4.87673772940766E-5,6.67320819054265E-9,1,4,13.4005146026611,5.00541808299687,30.120000243187,0.0607031687573709,0.00911000098290935,1,2.29283413872077E-8,,,,,,,,,,,,,,,,,,,,,50.0258255004883,50.0270080566406,-3000.42309570313,-3000.42309570313,53.5837615073518,5.64723246351111,5.12690877914429,52,1,68,0,0,0.303497314453125,34.2131004333496,1,1,3,50.0270080566406,0,50.0264167785645,,,,,,,,,,,,,,,,,,,,,,,,,,,,,,,,,
,3883235905.30853,50.0612926483154,-2510.29931640625,4.06732513303827E-5,8.28373748891181E-9,1,4,13.4005146026611,5.00537438640789,30.120000243187,0.0506316288169397,0.007569557331792,1,-3.63212491841563E-9,,,,,,,,,,,,,,,,,,,,,50.0566635131836,50.0659217834473,-2510.29931640625,-2510.29931640625,53.445413259448,5.64733265912225,5.12643623352051,54,1,0,0,1,0.300445556640625,33.7243423461914,1,1,3,50.0659217834473,0,50.0612926483154,,,,,,,,,,,,,,,,,,,,,,,,,,,,,,,,,
,3883235945.59164,50.0451831817627,-1930.2578125,3.10917477454962E-5,7.01533928428648E-9,1,4,13.4005146026611,5.00531838284367,30.120000243187,0.0387007112972804,0.00580558879057892,1,1.27298167970892E-8,,,,,,,,,,,,,,,,,,,,,50.0439949035645,50.0463714599609,-1930.2578125,-1930.2578125,53.5478065954672,5.64783861997739,5.13127994537354,54,1,0,0,1,0.304031372070313,33.7243423461914,1,1,3,50.0463714599609,0,50.0451831817627,,,,,,,,,,,,,,,,,,,,,,,,,,,,,,,,,
,3883235983.55111,50.0222015380859,-1350.44287109375,2.15491030855793E-5,6.46328435945236E-9,1,4,13.4005146026611,5.00532294967834,30.120000243187,0.0268246641618778,0.00401106178631723,1,-1.36939488396975E-9,,,,,,,,,,,,,,,,,,,,,50.0215682983398,50.022834777832,-1350.44287109375,-1350.44287109375,53.360997379371,5.6473134069831,5.12470102310181,54,1,0,0,1,0.300064086914063,33.7243423461914,1,1,3,50.0215072631836,0,50.0222015380859,,,,,,,,,,,,,,,,,,,,,,,,,,,,,,,,,
,3883236022.97012,50.035400390625,-770.250122070312,1.19732661044512E-5,6.97139445807302E-9,1,4,13.4005146026611,5.00524899468378,30.120000243187,0.0149037075181931,0.00223192067152175,1,1.89984664794803E-9,,,,,,,,,,,,,,,,,,,,,50.0333137512207,50.0374870300293,-770.250122070312,-770.250122070312,53.5360821676787,5.64796002294076,5.12196445465088,54,1,0,0,1,0.303192138671875,33.7243423461914,1,1,3,50.0333137512207,0,50.035400390625,,,,,,,,,,,,,,,,,,,,,,,,,,,,,,,,,
,3883236061.87485,50.0333919525146,-190.372177124023,2.40475212066374E-6,7.58265019318159E-9,1,4,13.4005146026611,5.00528007224305,30.120000243187,0.00299223806243855,0.00045562394540288,1,6.2889152253936E-9,,,,,,,,,,,,,,,,,,,,,50.0314712524414,50.0353126525879,-190.372177124023,-190.372177124023,53.5431168243518,5.64811853059203,5.12336254119873,54,1,0,0,1,0.300521850585937,33.7243423461914,1,1,3,50.0312004089355,0,50.0333919525146,,,,,,,,,,,,,,,,,,,,,,,,,,,,,,,,,
,3883236102.26701,50.0374202728271,389.682006835937,-7.03959320953544E-6,9.95098695506792E-9,1,4,13.4005146026611,5.00534711805973,30.120000243187,-0.00877092171021526,-0.00125774994854715,1,4.26866030443116E-8,,,,,,,,,,,,,,,,,,,,,50.035758972168,50.0390815734863,389.682006835937,389.682006835937,53.4231368466499,5.64755961141462,5.12752342224121,54,1,0,0,1,0.302352905273438,33.7243423461914,1,1,3,50.0390815734863,0,50.0374202728271,,,,,,,,,,,,,,,,,,,,,,,,,,,,,,,,,
,3883236142.13344,50.022331237793,969.622924804687,-1.64849615997749E-5,2.59442893901523E-8,1,4,13.4005146026611,5.00524327267273,30.120000243187,-0.0205144393217703,-0.00310744527497378,1,-3.03398632536055E-8,,,,,,,,,,,,,,,,,,,,,50.0211296081543,50.0235328674316,969.622924804687,969.622924804687,53.5157598261787,5.64757500501237,5.12157917022705,54,1,0,0,1,0.302276611328125,33.7243423461914,1,1,3,50.0235328674316,0,50.022331237793,,,,,,,,,,,,,,,,,,,,,,,,,,,,,,,,,
,3883236181.49646,50.0341358184814,1549.56384277344,-2.59986793274022E-5,3.50860830471937E-8,1,4,13.4005146026611,5.00525694742875,30.120000243187,-0.0323767102612394,-0.0047473496473678,1,7.54392721824799E-8,,,,,,,,,,,,,,,,,,,,,50.0275726318359,50.040699005127,1549.56384277344,1549.56384277344,53.4207919610922,5.64821498745735,5.1291618347168,54,1,0,0,1,0.302505493164063,34.2131004333496,1,1,3,50.040699005127,0,50.0341358184814,,,,,,,,,,,,,,,,,,,,,,,,,,,,,,,,,
,3883236220.92886,50.0609302520752,2129.65576171875,-3.54879653528446E-5,3.63228714308506E-8,1,4,13.4005146026611,5.00528722787262,30.120000243187,-0.044186937445553,-0.00652932525204128,1,6.34648977635899E-8,,,,,,,,,,,,,,,,,,,,,50.0592727661133,50.0625877380371,2129.65576171875,2129.65576171875,53.4356429029576,5.64833668634933,5.13224649429321,54,1,0,0,1,0.303115844726562,34.2131004333496,1,1,3,50.0625877380371,0,50.0609302520752,,,,,,,,,,,,,,,,,,,,,,,,,,,,,,,,,
,3883236260.4212,50.0328922271729,2709.68481445313,-4.50382132494356E-5,1.09169734761878E-8,1,4,13.4005146026611,5.00524918114839,30.120000243187,-0.056071175804381,-0.0083292338610795,1,4.61002243565914E-8,,,,,,,,,,,,,,,,,,,,,50.0299110412598,50.0358734130859,2709.68481445313,2709.68481445313,53.5059894696884,5.64787067981279,5.12769412994385,54,1,0,0,1,0.302734375,33.7243423461914,1,1,3,50.0358734130859,0,50.0328922271729,,,,,,,,,,,,,,,,,,,,,,,,,,,,,,,,,
,3883236314.93276,50.0498104095459,3499.623046875,-5.79592262210632E-5,7.67750206350842E-9,1,4,13.4005146026611,5.00526145838331,30.120000243187,-0.0721589838406597,-0.0107101480182479,1,6.63122828455284E-8,,,,,,,,,,,,,,,,,,,,,50.0495948791504,50.0500259399414,3499.623046875,3499.623046875,53.4622182726114,5.64796065414542,5.13380193710327,54,1,0,0,1,0.302047729492188,34.2131004333496,1,1,3,50.0495948791504,0,50.0498104095459,,,,,,,,,,,,,,,,,,,,,,,,,,,,,,,,,
,3883236356.54638,50.0577144622803,4499.7724609375,-7.44194446383279E-5,9.67137360032875E-9,1,4,13.4005146026611,5.00526422501157,30.120000243187,-0.0926532803636865,-0.0137429475750871,1,9.22590807204178E-8,,,,,,,,,,,,,,,,,,,,,50.0560188293457,50.0594100952148,4499.7724609375,4499.7724609375,53.4739427003999,5.64728252072906,5.13439989089966,54,1,0,0,1,0.304031372070313,33.7243423461914,1,1,3,50.0594100952148,0,50.0577144622803,,,,,,,,,,,,,,,,,,,,,,,,,,,,,,,,,
,3883236398.67393,50.0475692749023,5499.80859375,-9.08770362917341E-5,1.09552563231851E-8,1,4,13.4005146026611,5.00518797910741,30.120000243187,-0.113141662351374,-0.0167760880774958,1,1.172452925199E-7,,,,,,,,,,,,,,,,,,,,,50.0456008911133,50.0495376586914,5499.80859375,5499.80859375,53.4547928016787,5.64816314064479,5.13449192047119,54,1,0,0,1,0.304107666015625,33.7243423461914,1,1,3,50.0456008911133,0,50.0475692749023,,,,,,,,,,,,,,,,,,,,,,,,,,,,,,,,,
,3883236440.75749,50.0345325469971,6499.55517578125,-0.000107346581161049,1.14911967026536E-8,1,4,13.4005146026611,5.0052403492837,30.120000243187,-0.133645371031395,-0.0198353083629444,1,1.23536258412009E-7,,,,,,,,,,,,,,,,,,,,,50.0341758728027,50.0348892211914,6499.55517578125,6499.55517578125,53.4520571018614,5.64756940107736,5.12567090988159,54,1,0,0,1,0.302658081054687,33.7243423461914,1,1,3,50.0341758728027,0,50.0345325469971,,,,,,,,,,,,,,,,,,,,,,,,,,,,,,,,,
,3883236481.97611,50.0199031829834,7499.654296875,-0.000123807599987186,1.4989156868399E-8,1,4,13.4005146026611,5.00514881643131,30.120000243187,-0.154133708236673,-0.0228865040764244,1,1.34331002580843E-7,,,,,,,,,,,,,,,,,,,,,50.018238067627,50.0215682983398,7499.654296875,7499.654296875,53.4207919610922,5.64795618940012,5.13701677322388,54,1,0,0,1,0.30364990234375,33.7243423461914,1,1,3,50.018238067627,0,50.0199031829834,,,,,,,,,,,,,,,,,,,,,,,,,,,,,,,,,
,3883236522.21666,50.0135879516602,8499.52734375,-0.000140268763593161,1.63366122696576E-8,1,4,13.4005146026611,5.00522805348323,30.120000243187,-0.174631078212923,-0.0259283194419948,1,1.53552007595737E-7,,,,,,,,,,,,,,,,,,,,,50.0135345458984,50.0136413574219,8499.52734375,8499.52734375,53.5497606667653,5.64792099457472,5.13642835617065,54,1,0,0,1,0.302047729492188,33.7243423461914,1,1,3,50.0136413574219,0,50.0135879516602,,,,,,,,,,,,,,,,,,,,,,,,,,,,,,,,,
,3883236563.47173,50.0223178863525,9499.638671875,-0.000156757577133839,2.13610178372222E-8,1,4,13.4005146026611,5.00515042570328,30.120000243187,-0.19515161478774,-0.0289982567465979,1,1.53404931552565E-7,,,,,,,,,,,,,,,,,,,,,50.0214767456055,50.0231590270996,9499.638671875,9499.638671875,53.5227944828518,5.64830884592258,5.12943172454834,52,1,68,0,0,0.302886962890625,33.7243423461914,1,1,3,50.0231590270996,0,50.0223178863525,,,,,,,,,,,,,,,,,,,,,,,,,,,,,,,,,
,3883236603.90952,50.009578704834,10499.6875,-0.000173241914543801,1.96076331532518E-8,1,4,13.4005146026611,5.00516934075385,30.120000243187,-0.215673209850102,-0.0320567081269469,1,1.62403654656013E-7,,,,,,,,,,,,,,,,,,,,,50.0082855224609,50.010871887207,10499.6875,10499.6875,53.4942650418999,5.64816881483762,5.13616132736206,53,1,68,0,0,0.303497314453125,33.7243423461914,1,1,3,50.0082855224609,0,50.009578704834,,,,,,,,,,,,,,,,,,,,,,,,,,,,,,,,,
,3883236644.18352,50.090747833252,11499.82421875,-0.000189718538960337,1.72590029874923E-8,1,4,13.4005146026611,5.00502220958609,30.120000243187,-0.236171825218011,-0.0351297667649424,1,1.57230181568153E-7,,,,,,,,,,,,,,,,,,,,,50.0839729309082,50.0975227355957,11499.82421875,11499.82421875,53.4973915559768,5.64833196404949,5.1301474571228,54,1,0,0,1,0.303268432617188,33.7243423461914,1,1,3,50.0975227355957,0,50.090747833252,,,,,,,,,,,,,,,,,,,,,,,,,,,,,,,,,
,3883236683.97689,50.1594581604004,12499.734375,-0.000206200229182888,2.61401153016668E-8,1,4,13.4005146026611,5.0050712297373,30.120000243187,-0.25669085908378,-0.038194032917369,1,1.61357423494561E-7,,,,,,,,,,,,,,,,,,,,,50.1549835205078,50.163932800293,12499.734375,12499.734375,53.5040353983903,5.64834880053187,5.13694190979004,53,1,68,0,0,0.30242919921875,33.7243423461914,1,1,3,50.163932800293,0,50.1594581604004,,,,,,,,,,,,,,,,,,,,,,,,,,,,,,,,,
,3883236724.72821,50.1578788757324,13499.6064453125,-0.000222660182711875,2.60272244597369E-8,1,4,13.4005146026611,5.00500051021972,30.120000243187,-0.277180312558392,-0.0412115962762581,1,1.9871305349237E-7,,,,,,,,,,,,,,,,,,,,,50.1556091308594,50.1601486206055,13499.6064453125,13499.6064453125,53.5181047117364,5.64881524273271,5.13939571380615,54,1,0,0,1,0.302505493164063,33.7243423461914,1,1,3,50.1556091308594,0,50.1578788757324,,,,,,,,,,,,,,,,,,,,,,,,,,,,,,,,,
,3883236765.95634,50.0539703369141,14500.0078125,-0.000239144527183847,2.29465798359058E-8,1,4,13.4005146026611,5.00512669692732,30.120000243187,-0.297703568225681,-0.0443170689328566,1,1.70951643832942E-7,,,,,,,,,,,,,,,,,,,,,50.0500183105469,50.0579223632812,14500.0078125,14500.0078125,53.4028145051499,5.64883452041004,5.13825368881226,54,1,0,0,1,0.302810668945313,33.7243423461914,1,1,3,50.0500183105469,0,50.0539703369141,,,,,,,,,,,,,,,,,,,,,,,,,,,,,,,,,
,3883236843.03893,50.0049476623535,19999.490234375,-0.000329771725674484,3.06000451112672E-8,1,4,13.4005146026611,5.00507107448096,30.120000243187,-0.410496642232204,-0.0612411922397575,1,1.30898334740938E-7,,,,,,,,,,,,,,,,,,,,,50.0049018859863,50.0049934387207,19999.490234375,19999.490234375,53.648636674448,5.64949539420516,5.13982439041138,54,1,0,0,1,0.303497314453125,33.7243423461914,1,1,3,50.0047492980957,0,50.0049476623535,,,,,,,,,,,,,,,,,,,,,,,,,,,,,,,,,
,3883236928.24793,50.0028553009033,29999.865234375,-0.000494720682745926,4.59245973879388E-8,1,4,13.4005146026611,5.00504058593868,30.120000243187,-0.615789506774237,-0.0920649086957491,1,4.19699051167151E-8,,,,,,,,,,,,,,,,,,,,,50.0026435852051,50.0030670166016,29999.865234375,29999.865234375,53.4344704601787,5.64846234643452,5.13874244689941,54,1,0,0,1,0.303878784179687,33.7243423461914,1,1,3,50.0026435852051,0,50.0028553009033,,,,,,,,,,,,,,,,,,,,,,,,,,,,,,,,,
,3883237013.65465,50.0315952301025,40000.27734375,-0.000659573646718015,2.04094276783024E-7,1,4,13.4005146026611,5.00509293541319,30.120000243187,-0.820956891737149,-0.123016799200734,1,-1.62429224558647E-7,,,,,,,,,,,,,,,,,,,,,50.0270080566406,50.0361824035645,40000.27734375,40000.27734375,53.4075042762653,5.6490863293105,5.12946081161499,54,1,0,0,1,0.305557250976562,33.7243423461914,1,1,3,50.0361824035645,0,50.0315952301025,,,,,,,,,,,,,,,,,,,,,,,,,,,,,,,,,
,3883237107.74086,50.0487670898438,50000.3203125,-0.000825373916121755,1.3978450431303E-7,1,4,13.4005146026611,5.00505493129601,30.120000243187,-1.02751553043238,-0.152590999428278,10,8.7932309571404E-7,,,,,,,,,,,,,,,,,,,,,50.0383110046387,50.0592231750488,50000.3203125,50000.3203125,53.5243577398903,5.64879167618492,5.13711309432983,54,1,0,0,1,0.305633544921875,33.7243423461914,1,1,3,50.0592231750488,0,50.0487670898438,,,,,,,,,,,,,,,,,,,,,,,,,,,,,,,,,
,3883237200.2436,50.0340347290039,60000.41015625,-0.000989959691513287,1.5593413620274E-7,1,4,13.4005146026611,5.00513435958592,30.120000243187,-1.23216126836677,-0.184867500923948,1,-4.27287518650917E-7,,,,,,,,,,,,,,,,,,,,,50.0293235778809,50.038745880127,60000.41015625,60000.41015625,53.328559795823,5.64905587904247,5.14040184020996,53,1,68,0,0,0.302276611328125,33.7243423461914,1,1,3,50.038745880127,0,50.0340347290039,,,,,,,,,,,,,,,,,,,,,,,,,,,,,,,,,
,3883237287.87402,50.0287590026855,70000.3515625,-0.00115513547393819,1.72192518921426E-7,1,4,13.4005146026611,5.00510557072183,30.120000243187,-1.43769793036831,-0.21597271027791,1,-7.08758186272064E-7,,,,,,,,,,,,,,,,,,,,,50.0257301330566,50.0317878723145,70000.3515625,70000.3515625,53.3441923662076,5.64921772297867,5.13234996795654,54,1,0,0,1,0.30242919921875,33.7243423461914,1,1,3,50.0317878723145,0,50.0287590026855,,,,,,,,,,,,,,,,,,,,,,,,,,,,,,,,,
,3883237291.72842,50.0329036712646,70000.3515625,-0.00115511118538834,2.33106051717E-7,1,4,13.4005146026611,5.00510522388884,30.120000243187,-1.43766649197474,-0.2159752955825,1,-7.14485420586242E-7,,,,,,,,,,,,,,,,,,,,,50.0317878723145,50.0340194702148,70000.3515625,70000.3515625,53.3555259797364,5.64890031596257,5.14033031463623,54,2,0,0,1,0.301895141601562,34.2131004333496,1,1,3,50.0340194702148,0,50.0329036712646,,,,,,,,,,,,,,,,,,,,,,,,,,,,,,,,,