File: SQUID/23006_LCOS/transfer_119973_files_84937504/LSAT_subs_A1_MH_300K_FC_p0d5T.dat
[Header]
; MPMS3 Data File (default extension .dat)
; Copyright (c) 2007, Quantum Design, Inc. All rights reserved.
TITLE,
FILEOPENTIME,3883243768.89598,01/18/2023,10:53 pm
BYAPP,SQUID AC,0.9.1.0
INFO,MPMS3 Measurement Release 1.1.16 Build 347, MultiVu Release 2.3.3.2,APPNAME
INFO,0,MOMENT_UNITS
INFO,LSAT,SAMPLE_MATERIAL
INFO,,SAMPLE_COMMENT
INFO,,SAMPLE_MASS
INFO,,SAMPLE_VOLUME
INFO,,SAMPLE_MOLECULAR_WEIGHT
INFO,,SAMPLE_SIZE
INFO,,SAMPLE_SHAPE
INFO,Quartz,SAMPLE_HOLDER
INFO,Standard,SAMPLE_HOLDER_DETAIL
INFO,65.8,SAMPLE_OFFSET
DATATYPE,COMMENT,1
DATATYPE,TIME,2
STARTUPAXIS,X,2
STARTUPAXIS,Y1,5
FIELDGROUP, VSM,2,3,4,5,6,8,9,10,11,14,15
FIELDGROUP, DC, 2,3,4,14,56,57,58,59,60,61,62,63,64,65,66,67,68,69
FIELDGROUP, AC, 2,3,4,11,16,17,18,19,20,21,22,23,24,25,26,27,28,29,30
STARTUPGROUP, All
[Data]
Comment,Time Stamp (sec),Temperature (K),Magnetic Field (Oe),Moment (emu),M. Std. Err. (emu),Transport Action,Averaging Time (sec),Frequency (Hz),Peak Amplitude (mm),Center Position (mm),Lockin Signal' (V),Lockin Signal (V),Range,M. Quad. Signal (emu),AC Moment (emu),AC M. Std Err. (emu),AC Phase (deg),AC Phase Std. Err. (deg),AC Susceptibility (emu/Oe),AC Suscept. Std Err. (emu/Oe),AC X' (emu/Oe),AC X' Std Err. (emu/Oe),AC X'' (emu/Oe),AC X'' Std Err. (emu/Oe),AC Drive (Oe),AC Frequency (Hz),AC Averaging Time (sec),AC Cycles,AC Range,AC Measure Type,AC Signal' (V),AC Signal'' (V),AC Trim Coil Ratio,AC Trim Coil Phase,Min. Temperature (K),Max. Temperature (K),Min. Field (Oe),Max. Field (Oe),Mass (grams),Motor Lag (deg),Pressure (Torr),Measure Count,Measurement Number,SQUID Status (code),Motor Status (code),Measure Status (code),Motor Current (amps),Motor Temp. (C),Temp. Status (code),Field Status (code),Chamber Status (code),Chamber Temp (K),Redirection State,Average Temp (K),Rotation Angle (deg),Rotator state,DC Moment Fixed Ctr (emu),DC Moment Err Fixed Ctr (emu),DC Moment Free Ctr (emu),DC Moment Err Free Ctr (emu),DC Fixed Fit,DC Free Fit,DC Calculated Center (mm),DC Calculated Center Err (mm),DC Scan Length (mm),DC Scan Time (s),DC Number of Points,DC Squid Drift,DC Min V (V),DC Max V (V),DC Scans per Measure,Map 01,Map 02,Map 03,Map 04,Map 05,Map 06,Map 07,Map 08,Map 09,Map 10,Map 11,Map 12,Map 13,Map 14,Map 15,Map 16
,3883243811.08159,300.083251953125,69999.640625,-0.00117539132678691,2.25283863084172E-7,1,4,13.4005146026611,4.99475909350907,30.3899999707937,-1.45873605890085,-0.218736813576991,1,-4.08922203907868E-7,,,,,,,,,,,,,,,,,,,,,300.082672119141,300.083831787109,69999.640625,69999.640625,53.1601188499287,5.64789774086543,5.6488995552063,54,1,0,0,1,0.300521850585937,32.2580642700195,1,1,3,300.082672119141,0,300.083251953125,,,,,,,,,,,,,,,,,,,,,,,,,,,,,,,,,
,3883243905.22158,299.957107543945,60000.484375,-0.001007798835229,2.05349970939841E-7,1,4,13.4005146026611,4.99495791522793,30.4000005125999,-1.25110561814332,-0.185601101194296,10,1.22665602162791E-6,,,,,,,,,,,,,,,,,,,,,299.943634033203,299.970581054687,60000.484375,60000.484375,53.2496153153806,5.64817202253485,5.68995380401611,54,1,0,0,1,0.300369262695313,33.2355842590332,1,1,3,299.970581054687,0,299.957107543945,,,,,,,,,,,,,,,,,,,,,,,,,,,,,,,,,
,3883243995.61691,300.13249206543,49999.515625,-0.00083909433614564,1.09348212273733E-7,1,4,13.4005146026611,4.99479408822074,30.3899999707937,-1.04140229756298,-0.156006319003921,1,-1.7254786490679E-7,,,,,,,,,,,,,,,,,,,,,300.131927490234,300.133056640625,49999.515625,49999.515625,53.3938257771787,5.64862205973741,5.76712417602539,54,1,0,0,1,0.299606323242188,34.2131004333496,1,1,3,300.133056640625,0,300.13249206543,,,,,,,,,,,,,,,,,,,,,,,,,,,,,,,,,
,3883244082.36236,300.082244873047,39999.66015625,-0.000671113914890225,9.04208838309599E-8,1,4,13.4005146026611,4.99485081376746,30.3899999707937,-0.832938823303088,-0.12474865310299,1,-1.15163211920897E-7,,,,,,,,,,,,,,,,,,,,,300.078521728516,300.085968017578,39999.66015625,39999.66015625,53.2836161559672,5.64853227960767,5.86814451217651,54,1,0,0,1,0.30059814453125,33.7243423461914,1,1,3,300.078521728516,0,300.082244873047,,,,,,,,,,,,,,,,,,,,,,,,,,,,,,,,,
,3883244169.11673,300.007308959961,29999.57421875,-0.000503191654103671,4.94669455488782E-8,1,4,13.4005146026611,4.99487535669757,30.3899999707937,-0.624547756809426,-0.093416463137816,1,9.48430526050365E-9,,,,,,,,,,,,,,,,,,,,,300.006591796875,300.008026123047,29999.57421875,29999.57421875,53.5806349932749,5.64871123839746,6.00641059875488,54,1,0,0,1,0.29998779296875,34.2131004333496,1,1,3,300.006591796875,0,300.007308959961,,,,,,,,,,,,,,,,,,,,,,,,,,,,,,,,,
,3883244255.31174,300.059692382812,19999.603515625,-0.000335248929637483,2.32079545848473E-8,1,4,13.4005146026611,4.99479491380459,30.3899999707937,-0.416101015795679,-0.0621795319114394,1,5.24995629414627E-8,,,,,,,,,,,,,,,,,,,,,300.048461914063,300.070922851562,19999.603515625,19999.603515625,53.4579193157556,5.64905122710405,6.07507085800171,54,1,0,0,1,0.299530029296875,34.2131004333496,1,1,3,300.070922851562,0,300.059692382812,,,,,,,,,,,,,,,,,,,,,,,,,,,,,,,,,
,3883244321.66873,300.102920532227,14499.7939453125,-0.000242907950783317,2.1979353865428E-8,1,4,13.4005146026611,4.99465375703536,30.3899999707937,-0.301486094081276,-0.0449982518322809,1,8.05531821407144E-8,,,,,,,,,,,,,,,,,,,,,300.100891113281,300.104949951172,14499.7939453125,14499.7939453125,53.4833222426306,5.64840716270254,6.03030061721802,54,1,0,0,1,0.300445556640625,33.7243423461914,1,1,3,300.104949951172,0,300.102920532227,,,,,,,,,,,,,,,,,,,,,,,,,,,,,,,,,
,3883244363.92848,300.215270996094,13499.7197265625,-0.000226117548104453,1.99746016246793E-8,1,4,13.4005146026611,4.99444217287477,30.3899999707937,-0.280630381434822,-0.0418826357527213,1,7.71924777144407E-8,,,,,,,,,,,,,,,,,,,,,300.212554931641,300.217987060547,13499.7197265625,13499.7197265625,53.4446316309287,5.6493202596586,6.00982666015625,54,1,0,0,1,0.302810668945313,33.7243423461914,1,1,3,300.212554931641,0,300.215270996094,,,,,,,,,,,,,,,,,,,,,,,,,,,,,,,,,
,3883244404.83027,300.244537353516,12499.6708984375,-0.000209327905445601,1.83324524728779E-8,1,4,13.4005146026611,4.99461981022517,30.3899999707937,-0.259807634322736,-0.0387638042959186,1,8.02439287663438E-8,,,,,,,,,,,,,,,,,,,,,300.219451904297,300.269622802734,12499.6708984375,12499.6708984375,53.5700830082653,5.65013832862831,6.00295400619507,54,1,0,0,1,0.300521850585937,33.7243423461914,1,1,3,300.269622802734,0,300.244537353516,,,,,,,,,,,,,,,,,,,,,,,,,,,,,,,,,
,3883244446.03857,300.310592651367,11499.546875,-0.000192524418488895,2.01097519254591E-8,1,4,13.4005146026611,4.99459317125299,30.3899999707937,-0.238951039128297,-0.0356460674327207,1,7.84465655571507E-8,,,,,,,,,,,,,,,,,,,,,300.306854248047,300.314331054687,11499.546875,11499.546875,53.6048654773711,5.6487716965235,5.98424434661865,54,1,0,0,1,0.3009033203125,34.2131004333496,1,1,3,300.306854248047,0,300.310592651367,,,,,,,,,,,,,,,,,,,,,,,,,,,,,,,,,
,3883244488.91547,300.215316772461,10499.6494140625,-0.000175739385684726,2.02051646408935E-8,1,4,13.4005146026611,4.99464602935674,30.3899999707937,-0.21812154439908,-0.0325390575416564,1,7.13884986513398E-8,,,,,,,,,,,,,,,,,,,,,300.206848144531,300.223785400391,10499.6494140625,10499.6494140625,53.4766784002172,5.64884467284771,5.96363973617554,54,1,0,0,1,0.29998779296875,34.2131004333496,1,1,3,300.206848144531,0,300.215316772461,,,,,,,,,,,,,,,,,,,,,,,,,,,,,,,,,
,3883244531.02035,300.244171142578,9499.5,-0.000158933696349457,1.3395299858789E-8,1,4,13.4005146026611,4.99467683358618,30.3899999707937,-0.197264504330198,-0.0294284109879021,1,6.39496372849092E-8,,,,,,,,,,,,,,,,,,,,,300.240570068359,300.247772216797,9499.5,9499.5,53.6244061903518,5.64819375083941,5.95071601867676,54,1,0,0,1,0.30029296875,34.2131004333496,1,1,3,300.240570068359,0,300.244171142578,,,,,,,,,,,,,,,,,,,,,,,,,,,,,,,,,
,3883244573.60678,300.231369018555,8499.81640625,-0.000142156736922055,1.42447085367302E-8,1,4,13.4005146026611,4.99461948115029,30.3899999707937,-0.176436875790291,-0.026332575392456,1,4.8307118616686E-8,,,,,,,,,,,,,,,,,,,,,300.23095703125,300.231781005859,8499.81640625,8499.81640625,53.6204980477557,5.64876657928313,5.94004535675049,54,1,0,0,1,0.301055908203125,34.2131004333496,1,1,3,300.231781005859,0,300.231369018555,,,,,,,,,,,,,,,,,,,,,,,,,,,,,,,,,
,3883244616.43577,300.235946655273,7499.85595703125,-0.000125355638392339,1.55042432544102E-8,1,4,13.4005146026611,4.99466943206061,30.3899999707937,-0.155588233011821,-0.023209044169321,1,5.20126163187009E-8,,,,,,,,,,,,,,,,,,,,,300.231781005859,300.240112304687,7499.85595703125,7499.85595703125,53.5720370795634,5.64872467541642,5.93641519546509,54,1,0,0,1,0.301055908203125,33.7243423461914,1,1,3,300.240112304687,0,300.235946655273,,,,,,,,,,,,,,,,,,,,,,,,,,,,,,,,,
,3883244656.81122,300.241119384766,6499.5048828125,-0.000108542273566627,1.46778922122706E-8,1,4,13.4005146026611,4.99460119950286,30.3899999707937,-0.1347167263931,-0.0200998008053402,1,4.17637616857317E-8,,,,,,,,,,,,,,,,,,,,,300.232757568359,300.249481201172,6499.5048828125,6499.5048828125,53.5716462653038,5.64848019177615,5.92611122131348,54,1,0,0,1,0.300979614257812,34.2131004333496,1,1,3,300.232757568359,0,300.241119384766,,,,,,,,,,,,,,,,,,,,,,,,,,,,,,,,,
,3883244696.73793,300.179992675781,5499.88427734375,-9.17437643091668E-5,1.30666271610083E-8,1,4,13.4005146026611,4.99456544133368,30.4000005125999,-0.113864030564647,-0.0170033580025176,1,2.36435520558265E-8,,,,,,,,,,,,,,,,,,,,,300.165924072266,300.194061279297,5499.88427734375,5499.88427734375,53.5395994960153,5.6490567000981,5.91981744766235,54,1,0,0,1,0.303115844726562,34.2131004333496,1,1,3,300.194061279297,0,300.179992675781,,,,,,,,,,,,,,,,,,,,,,,,,,,,,,,,,
,3883244739.25418,300.274719238281,4499.734375,-7.49352224057507E-5,9.61619324792221E-9,1,4,13.4005146026611,4.99454102151659,30.3899999707937,-0.093003535721423,-0.0138788338571166,1,2.67352220780213E-8,,,,,,,,,,,,,,,,,,,,,300.258270263672,300.291168212891,4499.734375,4499.734375,53.4993456272749,5.64889202124512,5.91329574584961,54,1,0,0,1,0.30364990234375,33.7243423461914,1,1,3,300.291168212891,0,300.274719238281,,,,,,,,,,,,,,,,,,,,,,,,,,,,,,,,,
,3883244780.76084,300.334365844727,3499.4970703125,-5.81245799340106E-5,7.82942414623579E-9,1,4,13.4005146026611,4.99454116298924,30.4000005125999,-0.0721358100010898,-0.0107901785556064,1,7.04886757122194E-10,,,,,,,,,,,,,,,,,,,,,300.326141357422,300.342590332031,3499.4970703125,3499.4970703125,53.4434591881499,5.64918628406651,5.89946889877319,54,1,0,0,1,0.300979614257812,33.7243423461914,1,1,3,300.326141357422,0,300.334365844727,,,,,,,,,,,,,,,,,,,,,,,,,,,,,,,,,
,3883244837.55235,300.240203857422,2709.52124023438,-4.48350218916342E-5,8.79566961792871E-9,1,4,13.4005146026611,4.99454835856388,30.3899999707937,-0.0556392285240484,-0.00834733059793669,1,-1.89502890554948E-8,,,,,,,,,,,,,,,,,,,,,300.233825683594,300.24658203125,2709.52124023438,2709.52124023438,53.5227944828518,5.64907608432356,5.89170598983765,54,1,0,0,1,0.300979614257812,34.7018585205078,1,1,3,300.233489990234,0,300.240203857422,,,,,,,,,,,,,,,,,,,,,,,,,,,,,,,,,
,3883244878.42291,300.198715209961,2129.7060546875,-3.50871936868301E-5,8.81442934231361E-9,1,4,13.4005146026611,4.99458800786228,30.4000005125999,-0.0435454956759687,-0.00651509661773282,1,-7.55520086083956E-10,,,,,,,,,,,,,,,,,,,,,300.197906494141,300.199523925781,2129.7060546875,2129.7060546875,53.533737282121,5.64906201284062,5.8965220451355,54,1,0,0,1,0.300750732421875,34.2131004333496,1,1,3,300.199523925781,0,300.198715209961,,,,,,,,,,,,,,,,,,,,,,,,,,,,,,,,,
,3883244917.89393,300.241165161133,1549.52600097656,-2.53415577046442E-5,7.65955801458701E-9,1,4,13.4005146026611,4.99465571873993,30.3899999707937,-0.0314498367432062,-0.00471418534320186,1,-7.47395305984806E-9,,,,,,,,,,,,,,,,,,,,,300.238006591797,300.244323730469,1549.52600097656,1549.52600097656,53.5837615073518,5.64857911329691,5.88423871994019,54,1,0,0,1,0.300750732421875,34.2131004333496,1,1,3,300.238006591797,0,300.241165161133,,,,,,,,,,,,,,,,,,,,,,,,,,,,,,,,,
,3883244957.00297,300.292831420898,969.622924804687,-1.55989172998633E-5,8.44838257392982E-9,1,4,13.4005146026611,4.99457465010889,30.3899999707937,-0.019357126400825,-0.00291031284098539,1,-1.15112775192453E-8,,,,,,,,,,,,,,,,,,,,,300.280548095703,300.305114746094,969.622924804687,969.622924804687,53.6158082766403,5.64923554619354,5.88505840301514,54,1,0,0,1,0.302352905273438,33.7243423461914,1,1,3,300.305114746094,0,300.292831420898,,,,,,,,,,,,,,,,,,,,,,,,,,,,,,,,,
,3883244996.55627,300.292068481445,389.694610595703,-5.86832742109273E-6,7.01626435687053E-9,1,4,13.4005146026611,4.99452165202135,30.3899999707937,-0.00728206596441953,-0.00109481297504811,1,-4.3038087233831E-9,,,,,,,,,,,,,,,,,,,,,300.274993896484,300.309143066406,389.694610595703,389.694610595703,53.6580162166788,5.64964645399725,5.8778772354126,54,1,0,0,1,0.300750732421875,34.7018585205078,1,1,3,300.309143066406,0,300.292068481445,,,,,,,,,,,,,,,,,,,,,,,,,,,,,,,,,
,3883245034.25115,300.302947998047,-190.271469116211,3.70703889331316E-6,1.21894604395428E-7,1,4,13.4005146026611,4.99453864663372,30.3899999707937,0.00460714467533639,0.000644664276859748,1,-3.5100352440486E-8,,,,,,,,,,,,,,,,,,,,,300.284698486328,300.321197509766,-190.271469116211,-190.271469116211,53.4610458298326,5.64917230548671,5.86684608459473,54,1,0,0,1,0.302963256835937,34.2131004333496,1,1,3,300.321197509766,0,300.302947998047,,,,,,,,,,,,,,,,,,,,,,,,,,,,,,,,,
,3883245071.38547,300.329208374023,-770.464172363281,1.34311676587936E-5,2.0131145222549E-8,1,4,13.4005146026611,4.99448974061482,30.3899999707937,0.0166666192642468,0.00250641441621262,1,1.03962314386287E-8,,,,,,,,,,,,,,,,,,,,,300.306793212891,300.351623535156,-770.464172363281,-770.464172363281,53.5513239238037,5.65000217517736,5.87113428115845,54,1,0,0,1,0.302200317382812,33.7243423461914,1,1,3,300.351623535156,0,300.329208374023,,,,,,,,,,,,,,,,,,,,,,,,,,,,,,,,,
,3883245110.01531,300.334564208984,-1349.90148925781,2.31717514129789E-5,2.07922246927293E-8,1,4,13.4005146026611,4.99446272655229,30.3899999707937,0.028760817176868,0.00427455545498576,1,-2.19780301991333E-8,,,,,,,,,,,,,,,,,,,,,300.324432373047,300.344696044922,-1349.90148925781,-1349.90148925781,53.5661748656691,5.64992564454571,5.86096572875977,54,1,0,0,1,0.3009033203125,33.7243423461914,1,1,3,300.344696044922,0,300.334564208984,,,,,,,,,,,,,,,,,,,,,,,,,,,,,,,,,
,3883245148.14655,300.313720703125,-1930.22009277344,3.29123093220342E-5,3.92034497893361E-8,1,4,13.4005146026611,4.99438069801201,30.3899999707937,0.0408460980514083,0.00609652671919634,1,-1.08751141293895E-8,,,,,,,,,,,,,,,,,,,,,300.307312011719,300.320129394531,-1930.22009277344,-1930.22009277344,53.5259209969287,5.64974835797586,5.86289501190186,54,1,0,0,1,0.303192138671875,34.2131004333496,1,1,3,300.307312011719,0,300.313720703125,,,,,,,,,,,,,,,,,,,,,,,,,,,,,,,,,
,3883245186.03111,300.328475952148,-2509.9091796875,4.25882251876716E-5,2.94464634653764E-8,1,4,13.4005146026611,4.99430809039703,30.3899999707937,0.0528684952883885,0.00778776975777505,1,-9.53948787565348E-8,,,,,,,,,,,,,,,,,,,,,300.322235107422,300.334716796875,-2509.9091796875,-2509.9091796875,53.541944381573,5.65099683152688,5.85610151290894,54,1,0,0,1,0.300369262695313,33.7243423461914,1,1,3,300.322235107422,0,300.328475952148,,,,,,,,,,,,,,,,,,,,,,,,,,,,,,,,,
,3883245237.94061,300.190017700195,-3000.1083984375,5.08180847486783E-5,5.96514950750862E-9,1,4,13.4005146026611,4.99454675350917,30.3899999707937,0.0630836581215135,0.0093301246665341,1,-8.41738429418518E-8,,,,,,,,,,,,,,,,,,,,,300.188903808594,300.191131591797,-3000.1083984375,-3000.1083984375,53.6912354287461,5.64994571560648,5.85135126113892,54,1,0,0,1,0.300979614257812,34.2131004333496,1,1,3,300.188903808594,0,300.190017700195,,,,,,,,,,,,,,,,,,,,,,,,,,,,,,,,,
,3883245277.59355,300.150833129883,-3999.99340820313,6.74932494963925E-5,1.46224405792649E-8,1,4,13.4005146026611,4.99444862939786,30.3899999707937,0.0837745097948319,0.0124365397792422,1,-7.53558646303233E-8,,,,,,,,,,,,,,,,,,,,,300.132293701172,300.169372558594,-3999.99340820313,-3999.99340820313,53.5864972071691,5.64979116530483,5.84850406646729,54,1,0,0,1,0.301742553710937,34.2131004333496,1,1,3,300.169372558594,0,300.150833129883,,,,,,,,,,,,,,,,,,,,,,,,,,,,,,,,,
,3883245317.49437,300.188079833984,-5000.080078125,8.42370689655273E-5,1.09651290184355E-8,1,4,13.4005146026611,4.99440827087657,30.3899999707937,0.104558789990934,0.0155044822104731,1,-1.07874524625898E-7,,,,,,,,,,,,,,,,,,,,,300.183471679687,300.192687988281,-5000.080078125,-5000.080078125,53.3805380923518,5.6497785630284,5.84867572784424,54,1,0,0,1,0.302200317382812,33.7243423461914,1,1,3,300.193695068359,0,300.188079833984,,,,,,,,,,,,,,,,,,,,,,,,,,,,,,,,,
,3883245357.42138,300.213623046875,-6000.0029296875,0.000100996860351153,1.33499035576945E-8,1,4,13.4005146026611,4.99446644003007,30.3899999707937,0.125363343313511,0.0185928233524338,1,-1.26703101242564E-7,,,,,,,,,,,,,,,,,,,,,300.205993652344,300.221252441406,-6000.0029296875,-6000.0029296875,53.533737282121,5.65007843554495,5.84240531921387,54,1,0,0,1,0.30059814453125,33.7243423461914,1,1,3,300.205993652344,0,300.213623046875,,,,,,,,,,,,,,,,,,,,,,,,,,,,,,,,,
,3883245397.37235,300.067443847656,-6999.63623046875,0.00011775697760753,1.24398215605982E-8,1,4,13.4005146026611,4.99443043060562,30.3899999707937,0.146166698896242,0.0216701926520998,1,-1.54041201069828E-7,,,,,,,,,,,,,,,,,,,,,300.063659667969,300.071228027344,-6999.63623046875,-6999.63623046875,53.5829798788326,5.65001451908543,5.83828115463257,54,1,0,0,1,0.303421020507812,33.7243423461914,1,1,3,300.063659667969,0,300.067443847656,,,,,,,,,,,,,,,,,,,,,,,,,,,,,,,,,
,3883245437.72307,300.213729858398,-7999.98681640625,0.000134546820488673,1.42806413944341E-8,1,4,13.4005146026611,4.99438714897341,30.3899999707937,0.167001432058127,0.0247847279499345,1,-1.55786864475084E-7,,,,,,,,,,,,,,,,,,,,,300.188171386719,300.239288330078,-7999.98681640625,-7999.98681640625,53.5442892671307,5.65021858840058,5.83989572525024,54,1,0,0,1,0.301284790039063,34.2131004333496,1,1,3,300.239288330078,0,300.213729858398,,,,,,,,,,,,,,,,,,,,,,,,,,,,,,,,,
,3883245477.69231,300.296737670898,-8999.6953125,0.000151323232586905,1.2345716658003E-8,1,4,13.4005146026611,4.99433192904073,30.3899999707937,0.187817308756242,0.0279036488088499,1,-1.51853203747002E-7,,,,,,,,,,,,,,,,,,,,,300.291381835937,300.302093505859,-8999.6953125,-8999.6953125,53.5579677662172,5.65009401986142,5.83516502380371,54,1,0,0,1,0.30059814453125,34.2131004333496,1,1,3,300.302093505859,0,300.296737670898,,,,,,,,,,,,,,,,,,,,,,,,,,,,,,,,,
,3883245530.35082,300.330139160156,-9999.93359375,0.000168101161129122,1.28595936857803E-8,1,4,13.4005146026611,4.99427310875174,30.3899999707937,0.208637110371989,0.0310033466772277,1,-1.6353371295543E-7,,,,,,,,,,,,,,,,,,,,,300.328674316406,300.331604003906,-9999.93359375,-9999.93359375,53.4032053194095,5.64994089572972,5.83463048934937,54,1,0,0,1,0.302658081054687,36.1681327819824,1,1,3,300.331604003906,0,300.330139160156,,,,,,,,,,,,,,,,,,,,,,,,,,,,,,,,,
,3883245570.84708,300.292617797852,-10999.755859375,0.000184876827353286,2.19609855703316E-8,1,4,13.4005146026611,4.9943627744967,30.3899999707937,0.229467625520141,0.034072845625011,1,-2.00272371220204E-7,,,,,,,,,,,,,,,,,,,,,300.289733886719,300.295501708984,-10999.755859375,-10999.755859375,53.3977339197749,5.6501703257805,5.82547616958618,53,1,68,0,0,0.304031372070313,33.7243423461914,1,1,3,300.295501708984,0,300.292617797852,,,,,,,,,,,,,,,,,,,,,,,,,,,,,,,,,
,3883245612.02012,300.234817504883,-11999.7919921875,0.000201659462556322,1.93408507724068E-8,1,4,13.4005146026611,4.99432283592912,30.4000005125999,0.250291799452909,0.037188827728844,1,-1.99633094397474E-7,,,,,,,,,,,,,,,,,,,,,300.217681884766,300.251953125,-11999.7919921875,-11999.7919921875,53.6349581753614,5.65042866756992,5.82614278793335,53,1,68,0,0,0.302047729492188,33.7243423461914,1,1,3,300.251953125,0,300.234817504883,,,,,,,,,,,,,,,,,,,,,,,,,,,,,,,,,
,3883245653.17895,300.229614257812,-12999.9033203125,0.000218442505109492,2.16161333517965E-8,1,4,13.4005146026611,4.99432818340946,30.3899999707937,0.271119064493362,0.0403079439330599,1,-1.96885510147569E-7,,,,,,,,,,,,,,,,,,,,,300.212524414063,300.246704101562,-12999.9033203125,-12999.9033203125,53.5997848919961,5.65110423451543,5.82818031311035,54,1,0,0,1,0.302352905273438,33.7243423461914,1,1,3,300.246704101562,0,300.229614257812,,,,,,,,,,,,,,,,,,,,,,,,,,,,,,,,,
,3883245702.20502,300.315124511719,-13999.6875,0.000235371009698579,1.95544667447012E-8,1,4,13.4005146026611,4.99426005045012,30.3899999707937,0.292161211067543,0.043183621833403,10,-4.11354599421933E-7,,,,,,,,,,,,,,,,,,,,,300.305389404297,300.324859619141,-13999.6875,-13999.6875,53.6040838488518,5.6505380697031,5.82528829574585,54,1,0,0,1,0.302352905273438,33.7243423461914,1,1,3,300.324859619141,0,300.315124511719,,,,,,,,,,,,,,,,,,,,,,,,,,,,,,,,,
,3883245853.33665,300.164199829102,-14999.611328125,0.000252159808544048,2.61601241348018E-8,1,4,13.4005146026611,4.99424349547464,30.3899999707937,0.313010462633179,0.0461893678024195,10,-5.00559562015836E-7,,,,,,,,,,,,,,,,,,,,,300.163269042969,300.165130615234,-14999.611328125,-14999.611328125,53.5243577398903,5.65039641277777,5.81824827194214,54,1,0,0,1,0.300369262695313,33.7243423461914,1,1,3,300.163269042969,0,300.164199829102,,,,,,,,,,,,,,,,,,,,,,,,,,,,,,,,,
,3883245956.17801,300.090423583984,-24999.630859375,0.000419900623253852,2.98121431928338E-8,1,4,13.4005146026611,4.99440414499522,30.3899999707937,0.521135133141446,0.0777107441844248,1,-1.95355370247979E-7,,,,,,,,,,,,,,,,,,,,,300.085998535156,300.094848632812,-24999.630859375,-24999.630859375,53.4579193157556,5.65007802094237,5.81394910812378,54,1,0,0,1,0.30242919921875,33.7243423461914,1,1,3,300.085998535156,0,300.090423583984,,,,,,,,,,,,,,,,,,,,,,,,,,,,,,,,,
,3883246043.79192,300.171737670898,-34999.60546875,0.000587878222988305,5.84729120850789E-8,1,4,13.4005146026611,4.99424523638432,30.3899999707937,0.729542933199848,0.109029171495119,1,-8.35160321155228E-8,,,,,,,,,,,,,,,,,,,,,300.151092529297,300.1923828125,-34999.60546875,-34999.60546875,53.5845431358711,5.65026490998202,5.807373046875,54,1,0,0,1,0.301513671875,33.7243423461914,1,1,3,300.1923828125,0,300.171737670898,,,,,,,,,,,,,,,,,,,,,,,,,,,,,,,,,
,3883246131.38216,300.255218505859,-44999.484375,0.000755874141624089,7.09149220651008E-8,1,4,13.4005146026611,4.99433292397802,30.3899999707937,0.93802556672425,0.14031910783488,1,-2.94793507703326E-9,,,,,,,,,,,,,,,,,,,,,300.237365722656,300.273071289063,-44999.484375,-44999.484375,53.386400306246,5.64982044275952,5.80621957778931,54,1,0,0,1,0.300674438476562,33.7243423461914,1,1,3,300.273071289063,0,300.255218505859,,,,,,,,,,,,,,,,,,,,,,,,,,,,,,,,,
,3883246227.15399,300.07275390625,-54999.921875,0.000924697211298849,1.06910802536839E-7,1,4,13.4005146026611,4.99417231997919,30.4000005125999,1.14769804134164,0.170194663700223,10,-1.17750607183461E-6,,,,,,,,,,,,,,,,,,,,,300.069915771484,300.075592041016,-54999.921875,-54999.921875,53.2546959007556,5.65025525171929,5.80194091796875,54,1,0,0,1,0.300369262695313,33.7243423461914,1,1,3,300.069915771484,0,300.07275390625,,,,,,,,,,,,,,,,,,,,,,,,,,,,,,,,,
,3883246319.55556,300.005310058594,-64999.69140625,0.00109204957692345,1.28591886358209E-7,1,4,13.4005146026611,4.99409271627527,30.4000005125999,1.35505630433087,0.203149235338109,1,3.47733134677312E-7,,,,,,,,,,,,,,,,,,,,,300.004913330078,300.005706787109,-64999.69140625,-64999.69140625,53.1054048535825,5.65024802997059,5.79703760147095,54,1,0,0,1,0.302734375,33.7243423461914,1,1,3,300.004913330078,0,300.005310058594,,,,,,,,,,,,,,,,,,,,,,,,,,,,,,,,,
,3883246420.47923,300.096099853516,-64999.578125,0.00109180887818826,2.89174469497602E-7,1,4,13.4005146026611,4.99416431855293,30.3899999707937,1.35479363279484,0.203049794101799,1,3.00317310726238E-7,,,,,,,,,,,,,,,,,,,,,300.079803466797,300.112396240234,-64999.578125,-64999.578125,53.4387694170345,5.65071648234789,5.79967451095581,54,1,0,0,1,0.302200317382812,34.2131004333496,1,1,3,300.112396240234,0,300.096099853516,,,,,,,,,,,,,,,,,,,,,,,,,,,,,,,,,
,3883246508.04326,300.222122192383,-54999.59375,0.000923645739177818,8.85993264851449E-8,1,4,13.4005146026611,4.99421162005046,30.3899999707937,1.14615523349785,0.171676865070584,1,1.72695831178307E-7,,,,,,,,,,,,,,,,,,,,,300.208526611328,300.235717773438,-54999.59375,-54999.59375,53.4141481186787,5.65058960729567,5.79184103012085,54,1,0,0,1,0.300827026367188,33.7243423461914,1,1,3,300.235717773438,0,300.222122192383,,,,,,,,,,,,,,,,,,,,,,,,,,,,,,,,,
,3883246595.68594,300.187805175781,-44999.7734375,0.000755489914787102,1.1959361783308E-7,1,4,13.4005146026611,4.99421511297942,30.3899999707937,0.937505043512353,0.140328217217698,1,6.56070191722055E-8,,,,,,,,,,,,,,,,,,,,,300.185821533203,300.189788818359,-44999.7734375,-44999.7734375,53.488012013746,5.65105015536614,5.79489231109619,54,1,0,0,1,0.301666259765625,33.7243423461914,1,1,3,300.185821533203,0,300.187805175781,,,,,,,,,,,,,,,,,,,,,,,,,,,,,,,,,
,3883246682.78185,300.185302734375,-34999.640625,0.000587405177024341,3.93844157804202E-8,1,4,13.4005146026611,4.99424093759695,30.3899999707937,0.728945631825268,0.109004035460444,1,-3.29008389689776E-8,,,,,,,,,,,,,,,,,,,,,300.165008544922,300.205596923828,-34999.640625,-34999.640625,53.5341280963807,5.65054430379996,5.78928804397583,54,1,0,0,1,0.300979614257812,33.7243423461914,1,1,3,300.205596923828,0,300.185302734375,,,,,,,,,,,,,,,,,,,,,,,,,,,,,,,,,
,3883246768.65157,300.194564819336,-24999.8203125,0.000419384561027898,3.97481634656978E-8,1,4,13.4005146026611,4.99423227677337,30.4000005125999,0.520440839776124,0.0778035062418532,1,-4.03859583997585E-8,,,,,,,,,,,,,,,,,,,,,300.191223144531,300.197906494141,-24999.8203125,-24999.8203125,53.4715978148422,5.65059570704188,5.78801822662354,54,1,0,0,1,0.30120849609375,34.2131004333496,1,1,3,300.197906494141,0,300.194564819336,,,,,,,,,,,,,,,,,,,,,,,,,,,,,,,,,
,3883246855.65522,300.01887512207,-14999.8251953125,0.000251391831363754,2.40789628104668E-8,1,4,13.4005146026611,4.9941495972462,30.3899999707937,0.311971038934681,0.0465682340133281,1,-7.93830344977955E-8,,,,,,,,,,,,,,,,,,,,,300.014404296875,300.023345947266,-14999.8251953125,-14999.8251953125,53.5696921940057,5.65095411464723,5.78593921661377,54,1,0,0,1,0.301132202148438,33.7243423461914,1,1,3,300.023345947266,0,300.01887512207,,,,,,,,,,,,,,,,,,,,,,,,,,,,,,,,,
,3883246911.44083,300.216262817383,-14000.115234375,0.000234589829446071,1.78216323108578E-8,1,4,13.4005146026611,4.9941381533243,30.3899999707937,0.291123186833712,0.0434292542658746,1,-9.53600746734007E-8,,,,,,,,,,,,,,,,,,,,,300.189575195313,300.242950439453,-14000.115234375,-14000.115234375,53.5016905128326,5.65079394148389,5.79158020019531,54,1,0,0,1,0.303115844726562,33.7243423461914,1,1,3,300.242950439453,0,300.216262817383,,,,,,,,,,,,,,,,,,,,,,,,,,,,,,,,,
,3883246963.10579,300.425186157227,-13000.318359375,0.000217826155558014,2.01324938090148E-8,1,4,13.4005146026611,4.99437165704893,30.3899999707937,0.27034795710921,0.0402576995754917,1,-1.45566636878437E-7,,,,,,,,,,,,,,,,,,,,,300.422668457031,300.427703857422,-13000.318359375,-13000.318359375,53.6357398038807,5.65025575483912,5.78984355926514,54,1,0,0,1,0.302200317382812,34.2131004333496,1,1,3,300.422668457031,0,300.425186157227,,,,,,,,,,,,,,,,,,,,,,,,,,,,,,,,,
,3883247002.19561,300.324371337891,-12000.1943359375,0.000200994030135374,2.20321789040847E-8,1,4,13.4005146026611,4.99433181073415,30.3899999707937,0.249443016505381,0.0372233135436036,1,-7.23747572168184E-8,,,,,,,,,,,,,,,,,,,,,300.314514160156,300.334228515625,-12000.1943359375,-12000.1943359375,53.653717259823,5.65041367078482,5.79167461395264,53,1,68,0,0,0.301513671875,34.2131004333496,1,1,3,300.313598632812,0,300.324371337891,,,,,,,,,,,,,,,,,,,,,,,,,,,,,,,,,
,3883247042.30874,300.197006225586,-10999.9951171875,0.000184204480308505,1.7417447957312E-8,1,4,13.4005146026611,4.99432039465154,30.3899999707937,0.228608556531661,0.0340945217267073,1,-8.19000651034807E-8,,,,,,,,,,,,,,,,,,,,,300.180450439453,300.213562011719,-10999.9951171875,-10999.9951171875,53.5349097248999,5.65014559072752,5.7842173576355,53,1,68,0,0,0.302276611328125,33.7243423461914,1,1,3,300.213562011719,0,300.197006225586,,,,,,,,,,,,,,,,,,,,,,,,,,,,,,,,,
,3883247083.05643,300.214721679687,-10000.248046875,0.000167393049043593,1.4988260792729E-8,1,4,13.4005146026611,4.99437296362759,30.3899999707937,0.207747274238822,0.0309858386162281,1,-7.24122772206101E-8,,,,,,,,,,,,,,,,,,,,,300.205718994141,300.223724365234,-10000.248046875,-10000.248046875,53.4919201563422,5.65046281492031,5.78423881530762,53,1,68,0,0,0.300750732421875,34.2131004333496,1,1,3,300.223724365234,0,300.214721679687,,,,,,,,,,,,,,,,,,,,,,,,,,,,,,,,,
,3883247122.93817,300.314178466797,-9000.3251953125,0.000150585995763325,1.48716604491655E-8,1,4,13.4005146026611,4.99433441474387,30.3899999707937,0.186887962342182,0.0278642725623684,1,-7.33127271901052E-8,,,,,,,,,,,,,,,,,,,,,300.309204101562,300.319152832031,-9000.3251953125,-9000.3251953125,53.6294867757268,5.65060448648214,5.78699064254761,53,1,68,0,0,0.301742553710937,33.7243423461914,1,1,3,300.309204101562,0,300.314178466797,,,,,,,,,,,,,,,,,,,,,,,,,,,,,,,,,
,3883247164.20308,300.156646728516,-8000.33935546875,0.000133782116090156,1.71643089793125E-8,1,4,13.4005146026611,4.99431976917712,30.3899999707937,0.166032333600332,0.0247556906747365,1,-6.44131166284406E-8,,,,,,,,,,,,,,,,,,,,,300.154632568359,300.158660888672,-8000.33935546875,-8000.33935546875,53.6154174623807,5.6506286689805,5.78066778182983,53,1,68,0,0,0.301437377929687,33.7243423461914,1,1,3,300.154632568359,0,300.156646728516,,,,,,,,,,,,,,,,,,,,,,,,,,,,,,,,,
,3883247205.15988,300.159210205078,-7000.30322265625,0.000116981704372672,1.22055702736463E-8,1,4,13.4005146026611,4.99423267110057,30.3899999707937,0.145178114223958,0.0216481095043381,1,-5.4891974954027E-8,,,,,,,,,,,,,,,,,,,,,300.151733398438,300.166687011719,-7000.30322265625,-7000.30322265625,53.5904053497653,5.65108588233327,5.78101539611816,54,1,0,0,1,0.301589965820313,34.2131004333496,1,1,3,300.166687011719,0,300.159210205078,,,,,,,,,,,,,,,,,,,,,,,,,,,,,,,,,
,3883247247.99424,300.306762695313,-6000.31787109375,0.00010016920231219,1.07594142629913E-8,1,4,13.4005146026611,4.99430603923421,30.3899999707937,0.124314747469582,0.0185443369776738,1,-4.128787835243E-8,,,,,,,,,,,,,,,,,,,,,300.287200927734,300.326324462891,-6000.31787109375,-6000.31787109375,53.5513239238037,5.65131455591897,5.78263092041016,54,1,0,0,1,0.301284790039063,34.2131004333496,1,1,3,300.328155517578,0,300.306762695313,,,,,,,,,,,,,,,,,,,,,,,,,,,,,,,,,
,3883247304.54619,300.350921630859,-5000.2060546875,8.33625253387337E-5,8.75658670444909E-9,1,4,13.4005146026611,4.99419421473017,30.3899999707937,0.103451950683479,0.015443567444901,1,-2.53860040694552E-8,,,,,,,,,,,,,,,,,,,,,300.350799560547,300.351043701172,-5000.2060546875,-5000.2060546875,53.6478550459288,5.65096049906385,5.78204202651978,54,1,0,0,1,0.301361083984375,34.2131004333496,1,1,3,300.350799560547,0,300.350921630859,,,,,,,,,,,,,,,,,,,,,,,,,,,,,,,,,
,3883247345.74721,300.340255737305,-4000.2451171875,6.65388173269192E-5,7.6931779402736E-9,1,4,13.4005146026611,4.99423506087491,30.3899999707937,0.0825741688969126,0.0123316397417579,1,-1.65106992714457E-8,,,,,,,,,,,,,,,,,,,,,300.332305908203,300.348205566406,-4000.2451171875,-4000.2451171875,53.4645631581691,5.65141849721885,5.78488159179688,53,1,68,0,0,0.303268432617188,33.7243423461914,1,1,3,300.332305908203,0,300.340255737305,,,,,,,,,,,,,,,,,,,,,,,,,,,,,,,,,
,3883247384.3978,300.219604492188,-3000.24682617188,4.97409955128041E-5,8.34203016451214E-9,1,4,13.4005146026611,4.99414627420346,30.3899999707937,0.0617249440444947,0.00922975316779912,1,-3.08849972182421E-9,,,,,,,,,,,,,,,,,,,,,300.209259033203,300.229949951172,-3000.24682617188,-3000.24682617188,53.5376454247172,5.65123549923888,5.78479862213135,52,1,68,0,0,0.30303955078125,33.7243423461914,1,1,3,300.229949951172,0,300.219604492188,,,,,,,,,,,,,,,,,,,,,,,,,,,,,,,,,
,3883247441.1838,300.404876708984,-2510.42529296875,4.15081543865867E-5,7.08031052674517E-9,1,4,13.4005146026611,4.99409614994162,30.3899999707937,0.0515089459384759,0.00769476438156263,1,-8.3999311573623E-9,,,,,,,,,,,,,,,,,,,,,300.393890380859,300.415863037109,-2510.42529296875,-2510.42529296875,53.6830283292941,5.6508684222559,5.78036689758301,54,1,0,0,1,0.302963256835937,33.7243423461914,1,1,3,300.415863037109,0,300.404876708984,,,,,,,,,,,,,,,,,,,,,,,,,,,,,,,,,
,3883247480.32786,300.346618652344,-1930.42150878906,3.17503042421471E-5,7.66045165488534E-9,1,4,13.4005146026611,4.99414677448766,30.4000005125999,0.0393994674037047,0.0058937930722828,1,-9.82222097272087E-11,,,,,,,,,,,,,,,,,,,,,300.333679199219,300.359558105469,-1930.42150878906,-1930.42150878906,53.5646116086307,5.65101572754576,5.77922916412354,54,1,0,0,1,0.3009033203125,34.2131004333496,1,1,3,300.359558105469,0,300.346618652344,,,,,,,,,,,,,,,,,,,,,,,,,,,,,,,,,
,3883247519.21716,300.34846496582,-1350.14074707031,2.19908670850249E-5,7.09492161858396E-9,1,4,13.4005146026611,4.99414077862475,30.3899999707937,0.0272866413765531,0.00409642747402364,1,1.14401826515367E-8,,,,,,,,,,,,,,,,,,,,,300.340484619141,300.3564453125,-1350.14074707031,-1350.14074707031,53.5771176649383,5.65120944161216,5.78238582611084,54,1,0,0,1,0.30120849609375,34.2131004333496,1,1,3,300.340484619141,0,300.34846496582,,,,,,,,,,,,,,,,,,,,,,,,,,,,,,,,,
,3883247558.03112,300.189849853516,-770.350830078125,1.22425252974147E-5,7.29894115614755E-9,1,4,13.4005146026611,4.99413750125369,30.3899999707937,0.0151904608864175,0.00228224591867195,1,7.76121962224546E-9,,,,,,,,,,,,,,,,,,,,,300.176940917969,300.202758789063,-770.350830078125,-770.350830078125,53.5509331095441,5.65105167957275,5.78111362457275,54,1,0,0,1,0.302581787109375,33.7243423461914,1,1,3,300.202758789063,0,300.189849853516,,,,,,,,,,,,,,,,,,,,,,,,,,,,,,,,,
,3883247597.5595,300.158843994141,-190.485473632813,2.5343789044568E-6,8.64452241802505E-9,1,4,13.4005146026611,4.99423330730048,30.4000005125999,0.00314571195632979,0.000465896237050983,1,-3.69105369181788E-9,,,,,,,,,,,,,,,,,,,,,300.156127929687,300.161560058594,-190.485473632813,-190.485473632813,53.6009573347749,5.65093742350482,5.77756690979004,54,1,0,0,1,0.3021240234375,34.2131004333496,1,1,3,300.156127929687,0,300.158843994141,,,,,,,,,,,,,,,,,,,,,,,,,,,,,,,,,
,3883247636.83211,300.125442504883,389.530944824219,-7.12787882489832E-6,1.35784294454549E-8,1,4,13.4005146026611,4.99418186049212,30.3899999707937,-0.00885322523427366,-0.00126942699490369,1,4.33207823686378E-8,,,,,,,,,,,,,,,,,,,,,300.122985839844,300.127899169922,389.530944824219,389.530944824219,53.5704738225249,5.65102812151534,5.78260993957519,54,1,0,0,1,0.300064086914063,33.7243423461914,1,1,3,300.127899169922,0,300.125442504883,,,,,,,,,,,,,,,,,,,,,,,,,,,,,,,,,
,3883247676.06034,300.208618164063,969.572570800781,-1.68345498973112E-5,2.35928316239579E-8,1,4,13.4005146026611,4.9941612123454,30.3899999707937,-0.0208948616288149,-0.00309484626235318,1,2.43529536422628E-8,,,,,,,,,,,,,,,,,,,,,300.196868896484,300.220367431641,969.572570800781,969.572570800781,53.6204980477557,5.65063411378243,5.78515195846558,54,1,0,0,1,0.300140380859375,34.2131004333496,1,1,3,300.220367431641,0,300.208618164063,,,,,,,,,,,,,,,,,,,,,,,,,,,,,,,,,
,3883247715.54609,300.251388549805,1549.6015625,-2.65307505795721E-5,1.06353160043389E-8,1,4,13.4005146026611,4.99410863976348,30.3899999707937,-0.03292971298376,-0.00487385581704558,1,4.11662461651437E-8,,,,,,,,,,,,,,,,,,,,,300.244903564453,300.257873535156,1549.6015625,1549.6015625,53.5642207943711,5.65103874749664,5.78250026702881,54,1,0,0,1,0.300216674804687,33.7243423461914,1,1,3,300.244903564453,0,300.251388549805,,,,,,,,,,,,,,,,,,,,,,,,,,,,,,,,,
,3883247755.0195,300.156845092773,2129.74389648438,-3.6371318980387E-5,1.34689652491343E-7,1,4,13.4005146026611,4.99403971995038,30.3899999707937,-0.0451427780929256,-0.00668204040771746,1,5.59975932017448E-8,,,,,,,,,,,,,,,,,,,,,300.134796142578,300.178894042969,2129.74389648438,2129.74389648438,53.5904053497653,5.65110358815006,5.77671337127686,54,1,0,0,1,0.30364990234375,34.2131004333496,1,1,3,300.178894042969,0,300.156845092773,,,,,,,,,,,,,,,,,,,,,,,,,,,,,,,,,
,3883247796.29549,300.208312988281,2709.8359375,-4.5943110031985E-5,8.56743679338445E-9,1,4,13.4005146026611,4.99411492566834,30.3899999707937,-0.0570245145588801,-0.0084382524869441,1,7.27245272069558E-8,,,,,,,,,,,,,,,,,,,,,300.190643310547,300.225982666016,2709.8359375,2709.8359375,53.5005180700537,5.65065642053123,5.77585124969482,54,1,0,0,1,0.301132202148438,34.2131004333496,1,1,3,300.225982666016,0,300.208312988281,,,,,,,,,,,,,,,,,,,,,,,,,,,,,,,,,
,3883247853.43725,300.266403198242,3499.64819335937,-5.90975281310504E-5,8.82106902738598E-9,1,4,13.4005146026611,4.99412295028375,30.3899999707937,-0.0733503472558374,-0.0108648439478758,1,8.50620760719849E-8,,,,,,,,,,,,,,,,,,,,,300.265197753906,300.267608642578,3499.64819335937,3499.64819335937,53.5943134923614,5.65130904860921,5.77785444259644,54,1,0,0,1,0.30120849609375,33.7243423461914,1,1,3,300.265197753906,0,300.266403198242,,,,,,,,,,,,,,,,,,,,,,,,,,,,,,,,,
,3883247894.75971,300.143188476562,4499.5078125,-7.58600272925862E-5,1.02003420143895E-8,1,4,13.4005146026611,4.99424150944319,30.4000005125999,-0.0941574400624049,-0.0139552180150699,1,1.0258785602722E-7,,,,,,,,,,,,,,,,,,,,,300.139343261719,300.147033691406,4499.5078125,4499.5078125,53.5395994960153,5.65077728416437,5.77846574783325,54,1,0,0,1,0.301589965820313,33.7243423461914,1,1,3,300.139343261719,0,300.143188476562,,,,,,,,,,,,,,,,,,,,,,,,,,,,,,,,,
,3883247936.05296,300.117874145508,5499.720703125,-9.26205313243824E-5,1.06944506354976E-8,1,4,13.4005146026611,4.99426809466551,30.3899999707937,-0.114963176670227,-0.0170269274102269,1,1.34666983404837E-7,,,,,,,,,,,,,,,,,,,,,300.114349365234,300.121398925781,5499.720703125,5499.720703125,53.5098976122845,5.6505818487299,5.77659559249878,54,1,0,0,1,0.300216674804687,33.7243423461914,1,1,3,300.121398925781,0,300.117874145508,,,,,,,,,,,,,,,,,,,,,,,,,,,,,,,,,
,3883247977.46962,300.230514526367,6499.78173828125,-0.000109390541737229,1.29528329573434E-8,1,4,13.4005146026611,4.99432955563198,30.3899999707937,-0.135780034545031,-0.0201161143474398,1,1.54279870983603E-7,,,,,,,,,,,,,,,,,,,,,300.221130371094,300.239898681641,6499.78173828125,6499.78173828125,53.7314892974864,5.6500410558946,5.77148485183716,54,1,0,0,1,0.301437377929687,34.2131004333496,1,1,3,300.239898681641,0,300.230514526367,,,,,,,,,,,,,,,,,,,,,,,,,,,,,,,,,
,3883248018.80254,300.287872314453,7499.818359375,-0.000126170797832186,1.51619542924151E-8,1,4,13.4005146026611,4.99437846014434,30.3899999707937,-0.156612817329066,-0.0231868801227529,1,1.90289258490862E-7,,,,,,,,,,,,,,,,,,,,,300.275085449219,300.300659179687,7499.818359375,7499.818359375,53.4157113757172,5.64932213154589,5.77680826187134,54,1,0,0,1,0.29998779296875,33.7243423461914,1,1,3,300.300659179687,0,300.287872314453,,,,,,,,,,,,,,,,,,,,,,,,,,,,,,,,,
,3883248060.07601,300.222061157227,8499.615234375,-0.000143000644266603,6.32983518139027E-8,1,4,13.4005146026611,4.99430861086163,30.3899999707937,-0.177500273801023,-0.0262762758261726,1,2.18067843662518E-7,,,,,,,,,,,,,,,,,,,,,300.213134765625,300.230987548828,8499.615234375,8499.615234375,53.5599218375153,5.65016824164193,5.77566194534302,54,1,0,0,1,0.300216674804687,33.7243423461914,1,1,3,300.213134765625,0,300.222061157227,,,,,,,,,,,,,,,,,,,,,,,,,,,,,,,,,
,3883248101.25899,300.140960693359,9499.701171875,-0.000159715789328709,4.36713706138444E-8,1,4,13.4005146026611,4.99423383068713,30.3899999707937,-0.198224900845594,-0.0294738901548123,1,1.41350963360559E-7,,,,,,,,,,,,,,,,,,,,,300.122589111328,300.159332275391,9499.701171875,9499.701171875,53.5556228806595,5.65049808626126,5.77663373947144,54,1,0,0,1,0.29998779296875,33.7243423461914,1,1,3,300.159332275391,0,300.140960693359,,,,,,,,,,,,,,,,,,,,,,,,,,,,,,,,,
,3883248142.42417,300.188781738281,10499.775390625,-0.000176505175637902,1.34360929460584E-8,1,4,13.4005146026611,4.99429589320792,30.3899999707937,-0.219071733528431,-0.0325357288145538,1,1.86053644791786E-7,,,,,,,,,,,,,,,,,,,,,300.168060302734,300.209503173828,10499.775390625,10499.775390625,53.4856671281884,5.65002703964637,5.77767896652222,53,1,68,0,0,0.303726196289063,33.7243423461914,1,1,3,300.209503173828,0,300.188781738281,,,,,,,,,,,,,,,,,,,,,,,,,,,,,,,,,
,3883248198.19903,300.469665527344,11500.087890625,-0.000193274697091087,2.21213732656507E-8,1,4,13.4005146026611,4.99432291983025,30.3899999707937,-0.23988158959807,-0.0356651157604288,1,1.73157132759289E-7,,,,,,,,,,,,,,,,,,,,,300.463897705078,300.475433349609,11500.087890625,11500.087890625,53.4184470755345,5.65016059013752,5.77741289138794,54,1,0,0,1,0.302658081054687,33.7243423461914,1,1,3,300.463897705078,0,300.469665527344,,,,,,,,,,,,,,,,,,,,,,,,,,,,,,,,,
,3883248250.20952,300.343276977539,12499.9853515625,-0.000210082869212076,1.47328976513727E-8,1,4,13.4005146026611,4.99426914556116,30.3899999707937,-0.260740213482531,-0.0387580882700918,1,1.94716098717135E-7,,,,,,,,,,,,,,,,,,,,,300.329315185547,300.357238769531,12499.9853515625,12499.9853515625,53.5181047117364,5.65053702237391,5.77780294418335,54,1,0,0,1,0.302963256835937,33.7243423461914,1,1,3,300.329315185547,0,300.343276977539,,,,,,,,,,,,,,,,,,,,,,,,,,,,,,,,,
,3883248290.13423,300.317245483398,13499.681640625,-0.000226855853651851,2.14023143454374E-8,1,4,13.4005146026611,4.99415070946206,30.3899999707937,-0.281550487476094,-0.0418366466978207,1,2.21940007697869E-7,,,,,,,,,,,,,,,,,,,,,300.304962158203,300.329528808594,13499.681640625,13499.681640625,53.4723794433614,5.6510830685789,5.77054119110107,54,1,0,0,1,0.301437377929687,33.2355842590332,1,1,3,300.329528808594,0,300.317245483398,,,,,,,,,,,,,,,,,,,,,,,,,,,,,,,,,
,3883248354.75012,300.455322265625,14499.5927734375,-0.000243622375067596,2.39269305794001E-8,1,4,13.4005146026611,4.9943029302593,30.3899999707937,-0.302366866196678,-0.0449669861705879,1,2.09053661016389E-7,,,,,,,,,,,,,,,,,,,,,300.450805664063,300.459838867188,14499.5927734375,14499.5927734375,53.5700830082653,5.65106521867999,5.77480602264404,54,1,0,0,1,0.303115844726562,33.7243423461914,1,1,3,300.450805664063,0,300.455322265625,,,,,,,,,,,,,,,,,,,,,,,,,,,,,,,,,
,3883248434.18337,300.231338500977,19999.615234375,-0.000335915594171765,3.03954125564439E-8,1,4,13.4005146026611,4.99421588212237,30.3899999707937,-0.416886909064473,-0.0621182656558993,1,1.93463131206012E-7,,,,,,,,,,,,,,,,,,,,,300.230163574219,300.232513427734,19999.615234375,19999.615234375,53.5986124492172,5.65097266507249,5.77443075180054,54,1,0,0,1,0.301132202148438,33.7243423461914,1,1,3,300.230163574219,0,300.231338500977,,,,,,,,,,,,,,,,,,,,,,,,,,,,,,,,,
,3883248519.30048,300.17578125,30000.091796875,-0.000503900665263763,3.79493984008867E-8,1,4,13.4005146026611,4.99412173802812,30.3899999707937,-0.625331012768848,-0.0932915234342746,1,2.0032298318833E-7,,,,,,,,,,,,,,,,,,,,,300.170104980469,300.181457519531,30000.091796875,30000.091796875,53.5044262126499,5.65133516271299,5.77347421646118,54,1,0,0,1,0.302047729492188,33.7243423461914,1,1,3,300.169799804687,0,300.17578125,,,,,,,,,,,,,,,,,,,,,,,,,,,,,,,,,
,3883248604.72344,300.20637512207,40000.328125,-0.000671909591803554,6.06246002996745E-8,1,4,13.4005146026611,4.99410002367301,30.3899999707937,-0.833790344795442,-0.124605817591089,1,9.78058123119227E-8,,,,,,,,,,,,,,,,,,,,,300.185607910156,300.227142333984,40000.328125,40000.328125,53.496219113198,5.65131755403051,5.77828741073608,54,1,0,0,1,0.301742553710937,33.7243423461914,1,1,3,300.227142333984,0,300.20637512207,,,,,,,,,,,,,,,,,,,,,,,,,,,,,,,,,
,3883248691.0295,300.281280517578,50000.26953125,-0.000839984031179361,1.27797432484736E-7,1,4,13.4005146026611,4.99410740743179,30.3899999707937,-1.04233458445285,-0.155948904378918,1,-1.73958960549508E-8,,,,,,,,,,,,,,,,,,,,,300.26318359375,300.299377441406,50000.26953125,50000.26953125,53.2781447563326,5.65145141449969,5.77208662033081,52,1,68,0,0,0.302886962890625,33.7243423461914,1,1,3,300.299377441406,0,300.281280517578,,,,,,,,,,,,,,,,,,,,,,,,,,,,,,,,,
,3883248791.67572,300.14372253418,60000.1953125,-0.00100808921160143,1.35540443565084E-7,1,4,13.4005146026611,4.99460884337284,30.3899999707937,-1.25107129816539,-0.187456685687057,1,-2.39684892515364E-7,,,,,,,,,,,,,,,,,,,,,300.121948242188,300.165496826172,60000.1953125,60000.1953125,53.2281205311018,5.65053348689803,5.77639055252075,53,1,68,0,0,0.3021240234375,33.7243423461914,1,1,3,300.165496826172,0,300.14372253418,,,,,,,,,,,,,,,,,,,,,,,,,,,,,,,,,
,3883248879.43075,300.235977172852,70000.4296875,-0.00117633951576195,3.63822563994704E-7,1,4,13.4005146026611,4.99368409319587,30.3899999707937,-1.45947176492482,-0.218853535497414,1,-4.14299536989789E-7,,,,,,,,,,,,,,,,,,,,,300.214660644531,300.257293701172,70000.4296875,70000.4296875,53.0975885683902,5.65370440016826,5.77735185623169,53,1,68,0,0,0.302886962890625,33.7243423461914,1,1,3,300.257293701172,0,300.235977172852,,,,,,,,,,,,,,,,,,,,,,,,,,,,,,,,,
,3883248890.07691,300.293304443359,70000.4296875,-0.00117727339004628,2.1980360015758E-7,1,4,13.4005146026611,4.99356517426177,30.3899999707937,-1.46095606651693,-0.216517317414747,10,1.60248149062511E-6,,,,,,,,,,,,,,,,,,,,,300.292785644531,300.293823242188,70000.4296875,70000.4296875,53.1878666623614,5.65497171149685,5.77212142944336,54,2,0,0,1,0.30364990234375,33.7243423461914,1,1,3,300.294281005859,0,300.293304443359,,,,,,,,,,,,,,,,,,,,,,,,,,,,,,,,,