File: SQUID/23006_LCOS/transfer_119973_files_84937504/LSAT_subs_A1_MH_200K_FC_p0d5T.dat
[Header]
; MPMS3 Data File (default extension .dat)
; Copyright (c) 2007, Quantum Design, Inc. All rights reserved.
TITLE,
FILEOPENTIME,3883237885.10658,01/18/2023,9:15 pm
BYAPP,SQUID AC,0.9.1.0
INFO,MPMS3 Measurement Release 1.1.16 Build 347, MultiVu Release 2.3.3.2,APPNAME
INFO,0,MOMENT_UNITS
INFO,LSAT,SAMPLE_MATERIAL
INFO,,SAMPLE_COMMENT
INFO,,SAMPLE_MASS
INFO,,SAMPLE_VOLUME
INFO,,SAMPLE_MOLECULAR_WEIGHT
INFO,,SAMPLE_SIZE
INFO,,SAMPLE_SHAPE
INFO,Quartz,SAMPLE_HOLDER
INFO,Standard,SAMPLE_HOLDER_DETAIL
INFO,65.8,SAMPLE_OFFSET
DATATYPE,COMMENT,1
DATATYPE,TIME,2
STARTUPAXIS,X,2
STARTUPAXIS,Y1,5
FIELDGROUP, VSM,2,3,4,5,6,8,9,10,11,14,15
FIELDGROUP, DC, 2,3,4,14,56,57,58,59,60,61,62,63,64,65,66,67,68,69
FIELDGROUP, AC, 2,3,4,11,16,17,18,19,20,21,22,23,24,25,26,27,28,29,30
STARTUPGROUP, All
[Data]
Comment,Time Stamp (sec),Temperature (K),Magnetic Field (Oe),Moment (emu),M. Std. Err. (emu),Transport Action,Averaging Time (sec),Frequency (Hz),Peak Amplitude (mm),Center Position (mm),Lockin Signal' (V),Lockin Signal (V),Range,M. Quad. Signal (emu),AC Moment (emu),AC M. Std Err. (emu),AC Phase (deg),AC Phase Std. Err. (deg),AC Susceptibility (emu/Oe),AC Suscept. Std Err. (emu/Oe),AC X' (emu/Oe),AC X' Std Err. (emu/Oe),AC X'' (emu/Oe),AC X'' Std Err. (emu/Oe),AC Drive (Oe),AC Frequency (Hz),AC Averaging Time (sec),AC Cycles,AC Range,AC Measure Type,AC Signal' (V),AC Signal'' (V),AC Trim Coil Ratio,AC Trim Coil Phase,Min. Temperature (K),Max. Temperature (K),Min. Field (Oe),Max. Field (Oe),Mass (grams),Motor Lag (deg),Pressure (Torr),Measure Count,Measurement Number,SQUID Status (code),Motor Status (code),Measure Status (code),Motor Current (amps),Motor Temp. (C),Temp. Status (code),Field Status (code),Chamber Status (code),Chamber Temp (K),Redirection State,Average Temp (K),Rotation Angle (deg),Rotator state,DC Moment Fixed Ctr (emu),DC Moment Err Fixed Ctr (emu),DC Moment Free Ctr (emu),DC Moment Err Free Ctr (emu),DC Fixed Fit,DC Free Fit,DC Calculated Center (mm),DC Calculated Center Err (mm),DC Scan Length (mm),DC Scan Time (s),DC Number of Points,DC Squid Drift,DC Min V (V),DC Max V (V),DC Scans per Measure,Map 01,Map 02,Map 03,Map 04,Map 05,Map 06,Map 07,Map 08,Map 09,Map 10,Map 11,Map 12,Map 13,Map 14,Map 15,Map 16
,3883237927.39026,200.050788879395,69999.5234375,-0.00117135686363252,2.84586856693634E-7,1,4,13.4005146026611,5.00506226237075,30.2300006151199,-1.45789274693319,-0.218848604889665,1,-5.94725242368147E-7,,,,,,,,,,,,,,,,,,,,,200.050674438477,200.050903320313,69999.5234375,69999.5234375,53.1515209362172,5.64825370499335,5.41696453094482,54,1,0,0,1,0.301666259765625,32.7468223571777,1,1,3,200.050674438477,0,200.050788879395,,,,,,,,,,,,,,,,,,,,,,,,,,,,,,,,,
,3883238014.3838,200.027778625488,60000.1171875,-0.00100365596282582,1.38885078262889E-7,1,4,13.4005146026611,5.00503556953209,30.2300006151199,-1.24914767698209,-0.187595717064388,1,-5.74368412739309E-7,,,,,,,,,,,,,,,,,,,,,200.022750854492,200.032806396484,60000.1171875,60000.1171875,53.2523510151979,5.64832540867945,5.41897392272949,54,1,0,0,1,0.304107666015625,33.2355842590332,1,1,3,200.032806396484,0,200.027778625488,,,,,,,,,,,,,,,,,,,,,,,,,,,,,,,,,
,3883238112.30935,200.033027648926,49999.77734375,-0.000836202245580322,9.22236151483004E-8,1,4,13.4005146026611,5.00510349403257,30.2300006151199,-1.04078838111938,-0.156076062644051,1,-2.99022197038527E-7,,,,,,,,,,,,,,,,,,,,,200.031875610352,200.0341796875,49999.77734375,49999.77734375,53.3070650115441,5.64853373675355,5.42047119140625,53,1,68,0,0,0.303115844726562,33.7243423461914,1,1,3,200.031875610352,0,200.033027648926,,,,,,,,,,,,,,,,,,,,,,,,,,,,,,,,,
,3883238213.20219,200.072341918945,39999.74609375,-0.000668816953507963,7.83242167398247E-8,1,4,13.4005146026611,5.00507422712768,30.2300006151199,-0.832449465907188,-0.124793699742391,1,-2.07757343567654E-7,,,,,,,,,,,,,,,,,,,,,200.038604736328,200.106079101562,39999.74609375,39999.74609375,53.3512270228807,5.64841842922017,5.41703176498413,53,1,68,0,0,0.303573608398438,33.7243423461914,1,1,3,200.108001708984,0,200.072341918945,,,,,,,,,,,,,,,,,,,,,,,,,,,,,,,,,
,3883238312.88724,200.132995605469,29999.701171875,-0.000501437636239867,4.59197700229221E-8,1,4,13.4005146026611,5.00493031694079,30.2300006151199,-0.624114448416845,-0.0934227608271472,1,-4.64298032917825E-8,,,,,,,,,,,,,,,,,,,,,200.131118774414,200.134872436523,29999.701171875,29999.701171875,53.3672504075249,5.64895437788497,5.42342758178711,53,1,68,0,0,0.303802490234375,34.2131004333496,1,1,3,200.131118774414,0,200.132995605469,,,,,,,,,,,,,,,,,,,,,,,,,,,,,,,,,
,3883238399.21521,200.025489807129,19999.552734375,-0.000334089995446741,3.24665169125298E-8,1,4,13.4005146026611,5.00491867757133,30.2300006151199,-0.415829387073885,-0.0622068562792917,1,-1.05367773719807E-9,,,,,,,,,,,,,,,,,,,,,200.023666381836,200.027313232422,19999.552734375,19999.552734375,53.4415051168518,5.64904915338405,5.42387008666992,54,1,0,0,1,0.303421020507812,34.2131004333496,1,1,3,200.023666381836,0,200.025489807129,,,,,,,,,,,,,,,,,,,,,,,,,,,,,,,,,
,3883238464.96896,200.207794189453,14499.66796875,-0.000242048571860396,2.34938519876553E-8,1,4,13.4005146026611,5.00499184707798,30.2300006151199,-0.301289556735099,-0.0449726223132752,1,7.73568504304517E-8,,,,,,,,,,,,,,,,,,,,,200.197448730469,200.218139648438,14499.66796875,14499.66796875,53.3250424674864,5.64958717185839,5.42357206344604,54,1,0,0,1,0.303421020507812,34.2131004333496,1,1,3,200.218856811523,0,200.207794189453,,,,,,,,,,,,,,,,,,,,,,,,,,,,,,,,,
,3883238515.34231,200.18286895752,13499.505859375,-0.000225453053177855,3.43215205940407E-8,1,4,13.4005146026611,5.00492146454153,30.2300006151199,-0.280666201601286,-0.0416249192141099,10,2.83702180188482E-7,,,,,,,,,,,,,,,,,,,,,200.178894042969,200.18684387207,13499.505859375,13499.505859375,53.4790232857749,5.64914987761814,5.425377368927,54,1,0,0,1,0.303726196289063,33.7243423461914,1,1,3,200.18684387207,0,200.18286895752,,,,,,,,,,,,,,,,,,,,,,,,,,,,,,,,,
,3883238562.51133,200.24568939209,12499.7587890625,-0.000208584498136181,2.27021387088104E-8,1,4,13.4005146026611,5.00480955699529,30.2300006151199,-0.259618128009153,-0.0387787913059326,1,4.59589916253609E-8,,,,,,,,,,,,,,,,,,,,,200.244964599609,200.24641418457,12499.7587890625,12499.7587890625,53.4805865428134,5.64862039582225,5.42605400085449,54,1,0,0,1,0.30548095703125,34.7018585205078,1,1,3,200.244964599609,0,200.24568939209,,,,,,,,,,,,,,,,,,,,,,,,,,,,,,,,,
,3883238603.89618,200.364288330078,11499.8115234375,-0.000191848391815191,2.2181163553712E-8,1,4,13.4005146026611,5.00490878521358,30.2300006151199,-0.23879482589704,-0.0356619704055193,1,4.73589938204967E-8,,,,,,,,,,,,,,,,,,,,,200.355026245117,200.373550415039,11499.8115234375,11499.8115234375,53.4989548130153,5.64923520340547,5.42547178268433,53,1,68,0,0,0.304336547851562,33.7243423461914,1,1,3,200.373550415039,0,200.364288330078,,,,,,,,,,,,,,,,,,,,,,,,,,,,,,,,,
,3883238644.48687,200.259956359863,10499.8759765625,-0.000175109762204329,1.79130197367636E-8,1,4,13.4005146026611,5.00493480863766,30.2300006151199,-0.217961589114639,-0.0325517329766577,1,4.24184667587266E-8,,,,,,,,,,,,,,,,,,,,,200.253601074219,200.266311645508,10499.8759765625,10499.8759765625,53.5759452221595,5.64858691241874,5.4234094619751,54,1,0,0,1,0.304183959960937,34.2131004333496,1,1,3,200.253601074219,0,200.259956359863,,,,,,,,,,,,,,,,,,,,,,,,,,,,,,,,,
,3883238686.56514,200.18236541748,9499.7392578125,-0.000158361344501908,1.54127853564356E-8,1,4,13.4005146026611,5.0049653925988,30.2300006151199,-0.197117527455994,-0.0294302400270868,1,4.50504058242141E-8,,,,,,,,,,,,,,,,,,,,,200.158050537109,200.206680297852,9499.7392578125,9499.7392578125,53.5485882239864,5.64929829337635,5.42286825180054,53,1,68,0,0,0.303726196289063,34.2131004333496,1,1,3,200.208068847656,0,200.18236541748,,,,,,,,,,,,,,,,,,,,,,,,,,,,,,,,,
,3883238728.65579,200.24040222168,8499.728515625,-0.000141628929729504,1.41577352220815E-8,1,4,13.4005146026611,5.00486448239151,30.2300006151199,-0.176283372600693,-0.0263319546690476,1,3.06108604648018E-8,,,,,,,,,,,,,,,,,,,,,200.228179931641,200.252624511719,8499.728515625,8499.728515625,53.5173230832172,5.64932068564596,5.42612886428833,54,1,0,0,1,0.302505493164063,34.2131004333496,1,1,3,200.252624511719,0,200.24040222168,,,,,,,,,,,,,,,,,,,,,,,,,,,,,,,,,
,3883238771.36271,200.188499450684,7499.61669921875,-0.000124880601344796,1.20749493396876E-8,1,4,13.4005146026611,5.0048928349643,30.2300006151199,-0.155439292126526,-0.0232110507495818,1,3.27778717156633E-8,,,,,,,,,,,,,,,,,,,,,200.18733215332,200.189666748047,7499.61669921875,7499.61669921875,53.6720855300249,5.64960742027323,5.42295408248901,54,1,0,0,1,0.3021240234375,34.2131004333496,1,1,3,200.18733215332,0,200.188499450684,,,,,,,,,,,,,,,,,,,,,,,,,,,,,,,,,
,3883238811.04717,200.158836364746,6499.75634765625,-0.000108152871116366,1.5682691844407E-8,1,4,13.4005146026611,5.00490456366107,30.2300006151199,-0.134618388901036,-0.0201038995765272,1,2.6862121295438E-8,,,,,,,,,,,,,,,,,,,,,200.133972167969,200.183700561523,6499.75634765625,6499.75634765625,53.5896237212461,5.64919027215645,5.42520666122437,52,1,68,0,0,0.303726196289063,34.2131004333496,1,1,3,200.183700561523,0,200.158836364746,,,,,,,,,,,,,,,,,,,,,,,,,,,,,,,,,
,3883238864.46307,200.455123901367,5499.61962890625,-9.14354260590826E-5,1.05758254294903E-8,1,4,13.4005146026611,5.004862314609,30.2300006151199,-0.1138156478702,-0.0169501655106876,1,5.968933361027E-8,,,,,,,,,,,,,,,,,,,,,200.448928833008,200.461318969727,5499.61962890625,5499.61962890625,53.5603126517749,5.64973523778418,5.42380094528198,54,1,0,0,1,0.304336547851562,33.7243423461914,1,1,3,200.448928833008,0,200.455123901367,,,,,,,,,,,,,,,,,,,,,,,,,,,,,,,,,
,3883238906.70933,200.265983581543,4499.5078125,-7.46551355146025E-5,1.06271808636046E-8,1,4,13.4005146026611,5.00482537964742,30.2300006151199,-0.0929213493909445,-0.0138781929918906,1,1.75001292142077E-8,,,,,,,,,,,,,,,,,,,,,200.260833740234,200.271133422852,4499.5078125,4499.5078125,53.4938742276403,5.64967524261047,5.43335342407227,52,1,68,0,0,0.302963256835937,34.7018585205078,1,1,3,200.271133422852,0,200.265983581543,,,,,,,,,,,,,,,,,,,,,,,,,,,,,,,,,
,3883238949.61805,200.197113037109,3499.623046875,-5.79043404524107E-5,1.09099658586049E-8,1,4,13.4005146026611,5.00478389082987,30.2300006151199,-0.0720684023420975,-0.0107830088157828,1,-1.58719198449837E-9,,,,,,,,,,,,,,,,,,,,,200.17936706543,200.214859008789,3499.623046875,3499.623046875,53.6017389632941,5.64947640756011,5.42838525772095,52,1,68,0,0,0.3033447265625,33.7243423461914,1,1,3,200.214859008789,0,200.197113037109,,,,,,,,,,,,,,,,,,,,,,,,,,,,,,,,,
,3883239008.66546,200.310935974121,2709.50854492187,-4.46593871453022E-5,9.5078938337769E-9,1,4,13.4005146026611,5.00495414053419,30.2300006151199,-0.0555851298259006,-0.0083242469667477,1,-7.11485377706144E-9,,,,,,,,,,,,,,,,,,,,,200.299819946289,200.322052001953,2709.50854492187,2709.50854492187,53.5009088843133,5.64899425447226,5.4284930229187,54,1,0,0,1,0.302505493164063,33.7243423461914,1,1,3,200.299819946289,0,200.310935974121,,,,,,,,,,,,,,,,,,,,,,,,,,,,,,,,,
,3883239048.00054,200.161750793457,2129.64306640625,-3.49547528131064E-5,7.39587194663886E-9,1,4,13.4005146026611,5.00492370882694,30.2300006151199,-0.0435043991313442,-0.00652550560524134,1,-1.37643667657871E-8,,,,,,,,,,,,,,,,,,,,,200.160110473633,200.163391113281,2129.64306640625,2129.64306640625,53.4332980173999,5.64940960775731,5.42610359191895,54,1,0,0,1,0.302276611328125,34.2131004333496,1,1,3,200.163391113281,0,200.161750793457,,,,,,,,,,,,,,,,,,,,,,,,,,,,,,,,,
,3883239087.2988,200.129318237305,1549.6015625,-2.5244290005442E-5,7.67699511151895E-9,1,4,13.4005146026611,5.00492034387713,30.2300006151199,-0.0314188053147611,-0.00471272154059053,1,-9.95016262090418E-9,,,,,,,,,,,,,,,,,,,,,200.115768432617,200.142868041992,1549.6015625,1549.6015625,53.4864487567076,5.64924199893162,5.43150520324707,54,1,0,0,1,0.306243896484375,34.2131004333496,1,1,3,200.142868041992,0,200.129318237305,,,,,,,,,,,,,,,,,,,,,,,,,,,,,,,,,
,3883239126.99851,200.293815612793,969.685852050781,-1.55210343335078E-5,7.83000603002264E-9,1,4,13.4005146026611,5.00490708075216,30.2300006151199,-0.0193159218127087,-0.0029064829954152,1,-1.33122815087188E-8,,,,,,,,,,,,,,,,,,,,,200.285705566406,200.30192565918,969.685852050781,969.685852050781,53.5345189106403,5.64925976097983,5.43167448043823,54,1,0,0,1,0.302886962890625,34.2131004333496,1,1,3,200.30192565918,0,200.293815612793,,,,,,,,,,,,,,,,,,,,,,,,,,,,,,,,,
,3883239166.4155,200.325080871582,389.78271484375,-5.8358486229774E-6,7.27220519727652E-9,1,4,13.4005146026611,5.0049172063154,30.2300006151199,-0.00726584014839535,-0.00107205298229874,1,1.16870467563181E-8,,,,,,,,,,,,,,,,,,,,,200.309478759766,200.340682983398,389.78271484375,389.78271484375,53.5564045091787,5.64921161087414,5.42857217788696,54,1,0,0,1,0.302734375,33.7243423461914,1,1,3,200.340682983398,0,200.325080871582,,,,,,,,,,,,,,,,,,,,,,,,,,,,,,,,,
,3883239205.1048,200.428153991699,-190.321823120117,3.83313946116347E-6,2.52681585101629E-8,1,4,13.4005146026611,5.00489147223052,30.2300006151199,0.00477457423507417,0.00068935492600086,1,-1.95613636993389E-8,,,,,,,,,,,,,,,,,,,,,200.420867919922,200.435440063477,-190.321823120117,-190.321823120117,53.5247485541499,5.64889516897865,5.42531299591064,54,1,0,0,1,0.302734375,33.7243423461914,1,1,3,200.420867919922,0,200.428153991699,,,,,,,,,,,,,,,,,,,,,,,,,,,,,,,,,
,3883239244.09028,200.25422668457,-769.973205566406,1.33808344810274E-5,3.3804973272081E-8,1,4,13.4005146026611,5.00486427269698,30.2300006151199,0.0166570738693287,0.00247339511744056,1,-1.44601872441821E-8,,,,,,,,,,,,,,,,,,,,,200.250640869141,200.2578125,-769.973205566406,-769.973205566406,53.4751151431787,5.65023905664111,5.4295654296875,54,1,0,0,1,0.302200317382812,34.7018585205078,1,1,3,200.2578125,0,200.25422668457,,,,,,,,,,,,,,,,,,,,,,,,,,,,,,,,,
,3883239281.96682,200.161636352539,-1350.09033203125,2.30915044200911E-5,2.06267685698395E-8,1,4,13.4005146026611,5.0048616525238,30.2300006151199,0.0287382424499153,0.00431580529271187,1,1.31561880039126E-8,,,,,,,,,,,,,,,,,,,,,200.155349731445,200.167922973633,-1350.09033203125,-1350.09033203125,53.5302199537845,5.64993586519802,5.43124437332153,54,1,0,0,1,0.303726196289063,33.7243423461914,1,1,3,200.155349731445,0,200.161636352539,,,,,,,,,,,,,,,,,,,,,,,,,,,,,,,,,
,3883239320.24985,200.194488525391,-1930.42150878906,3.27528162935951E-5,1.2850179337404E-8,1,4,13.4005146026611,5.00485556060721,30.2300006151199,0.0407695414082006,0.00607133471935773,1,-2.16406448115876E-8,,,,,,,,,,,,,,,,,,,,,200.193511962891,200.195465087891,-1930.42150878906,-1930.42150878906,53.536863796198,5.6497853994556,5.43316459655762,54,1,0,0,1,0.301361083984375,33.7243423461914,1,1,3,200.195465087891,0,200.194488525391,,,,,,,,,,,,,,,,,,,,,,,,,,,,,,,,,
,3883239358.77069,200.292503356934,-2510.08544921875,4.24266573192687E-5,7.39837884438972E-9,1,4,13.4005146026611,5.00479563921013,30.2300006151199,0.0528153592151928,0.00783067792838976,1,-5.51481607108364E-8,,,,,,,,,,,,,,,,,,,,,200.279388427734,200.305618286133,-2510.08544921875,-2510.08544921875,53.6646600590922,5.65005965765977,5.43141412734985,54,1,0,0,1,0.303573608398438,33.2355842590332,1,1,3,200.305618286133,0,200.292503356934,,,,,,,,,,,,,,,,,,,,,,,,,,,,,,,,,
,3883239480.54315,200.176116943359,-3000.03295898438,5.06012414284447E-5,6.34952793820466E-9,1,4,13.4005146026611,5.00478870276419,30.2300006151199,0.0629918962155901,0.00933659975199414,1,-6.80565735477207E-8,,,,,,,,,,,,,,,,,,,,,200.175064086914,200.177169799805,-3000.03295898438,-3000.03295898438,53.4848854996691,5.64942330224065,5.4306263923645,54,1,0,0,1,0.304336547851562,33.7243423461914,1,1,3,200.175064086914,0,200.176116943359,,,,,,,,,,,,,,,,,,,,,,,,,,,,,,,,,
,3883239518.09866,200.199638366699,-4000.00610351562,6.72303303967769E-5,6.46624798532482E-9,1,4,13.4005146026611,5.00478042542606,30.2300006151199,0.0836910321978615,0.0124162293773301,1,-8.12858634553981E-8,,,,,,,,,,,,,,,,,,,,,200.19709777832,200.202178955078,-4000.00610351562,-4000.00610351562,53.4493214020441,5.64946353251127,5.43459987640381,54,1,0,0,1,0.303955078125,34.2131004333496,1,1,3,200.19709777832,0,200.199638366699,,,,,,,,,,,,,,,,,,,,,,,,,,,,,,,,,
,3883239558.38804,200.25447845459,-5000.080078125,8.39317092169853E-5,8.87888419295303E-9,1,4,13.4005146026611,5.00472154466955,30.2300006151199,0.104481142956396,0.0154918713922858,1,-1.08345716369006E-7,,,,,,,,,,,,,,,,,,,,,200.248321533203,200.260635375977,-5000.080078125,-5000.080078125,53.4629999011307,5.64980278282749,5.43329334259033,54,1,0,0,1,0.3045654296875,34.2131004333496,1,1,3,200.260635375977,0,200.25447845459,,,,,,,,,,,,,,,,,,,,,,,,,,,,,,,,,
,3883239597.97545,200.209281921387,-5999.990234375,0.000100625993171623,9.89023068866082E-9,1,4,13.4005146026611,5.00470720557544,30.2300006151199,0.125256877279492,0.0186092469204516,1,-1.00916639739542E-7,,,,,,,,,,,,,,,,,,,,,200.203659057617,200.214904785156,-5999.990234375,-5999.990234375,53.5091159837653,5.64975148068025,5.43476247787476,54,1,0,0,1,0.303268432617188,33.7243423461914,1,1,3,200.214904785156,0,200.209281921387,,,,,,,,,,,,,,,,,,,,,,,,,,,,,,,,,
,3883239637.91271,200.131019592285,-6999.71142578125,0.000117336425262523,1.01011699164962E-8,1,4,13.4005146026611,5.00467848373342,30.2300006151199,0.146057140796343,0.0216948564298444,1,-1.21336479798938E-7,,,,,,,,,,,,,,,,,,,,,200.12646484375,200.13557434082,-6999.71142578125,-6999.71142578125,53.5591402089961,5.65047555049655,5.43133974075317,52,1,68,0,0,0.304489135742188,33.7243423461914,1,1,3,200.12646484375,0,200.131019592285,,,,,,,,,,,,,,,,,,,,,,,,,,,,,,,,,
,3883239694.52571,200.431549072266,-7999.98681640625,0.000134048099357238,9.13303259200962E-9,1,4,13.4005146026611,5.00479086053872,30.2300006151199,0.166859632474157,0.024818809673745,1,-1.11879727035318E-7,,,,,,,,,,,,,,,,,,,,,200.427307128906,200.435791015625,-7999.98681640625,-7999.98681640625,53.5767268506787,5.64956211192761,5.4347653388977,54,1,0,0,1,0.302352905273438,34.2131004333496,1,1,3,200.427307128906,0,200.431549072266,,,,,,,,,,,,,,,,,,,,,,,,,,,,,,,,,
,3883239735.1522,200.281509399414,-8999.7080078125,0.000150778061360177,1.17533201645455E-8,1,4,13.4005146026611,5.00457872729218,30.2300006151199,0.18767683047461,0.0278926499780747,1,-1.43546562652393E-7,,,,,,,,,,,,,,,,,,,,,200.274459838867,200.288558959961,-8999.7080078125,-8999.7080078125,53.4977823702364,5.65085323852117,5.43761682510376,53,1,68,0,0,0.303497314453125,33.7243423461914,1,1,3,200.288558959961,0,200.281509399414,,,,,,,,,,,,,,,,,,,,,,,,,,,,,,,,,
,3883239775.71681,200.350746154785,-9999.8203125,0.000167504079578621,1.24155405353596E-8,1,4,13.4005146026611,5.00471609874456,30.2300006151199,0.208501812489278,0.0310031921941461,1,-1.47271543824725E-7,,,,,,,,,,,,,,,,,,,,,200.344955444336,200.356536865234,-9999.8203125,-9999.8203125,53.5298291395249,5.6501706609082,5.4347243309021,54,1,0,0,1,0.303726196289063,33.7243423461914,1,1,3,200.344955444336,0,200.350746154785,,,,,,,,,,,,,,,,,,,,,,,,,,,,,,,,,
,3883239832.83777,200.364738464355,-10999.755859375,0.000184224799441704,1.65566726448887E-8,1,4,13.4005146026611,5.00472744147969,30.2300006151199,0.229314663962225,0.0341054921161809,1,-1.56052949960036E-7,,,,,,,,,,,,,,,,,,,,,200.360137939453,200.369338989258,-10999.755859375,-10999.755859375,53.6150266481211,5.6504296958316,5.43219232559204,54,1,0,0,1,0.303955078125,34.2131004333496,1,1,3,200.360137939453,0,200.364738464355,,,,,,,,,,,,,,,,,,,,,,,,,,,,,,,,,
,3883239872.9518,200.308029174805,-11999.8046875,0.000200938357542127,1.90280909220018E-8,1,4,13.4005146026611,5.00469326813289,30.2300006151199,0.250116934744297,0.037196766236933,1,-1.72257587329731E-7,,,,,,,,,,,,,,,,,,,,,200.307495117187,200.308563232422,-11999.8046875,-11999.8046875,53.5415535673134,5.65013480607579,5.4363055229187,52,1,68,0,0,0.30364990234375,33.7243423461914,1,1,3,200.308563232422,0,200.308029174805,,,,,,,,,,,,,,,,,,,,,,,,,,,,,,,,,
,3883239913.39422,200.229621887207,-12999.9287109375,0.000217664694656207,1.88861929040685E-8,1,4,13.4005146026611,5.00466568514276,30.2300006151199,0.27093039462614,0.0403226347709166,1,-1.62589900988939E-7,,,,,,,,,,,,,,,,,,,,,200.228500366211,200.230743408203,-12999.9287109375,-12999.9287109375,53.4669080437268,5.65021439069215,5.44281578063965,53,1,68,0,0,0.303192138671875,34.2131004333496,1,1,3,200.230743408203,0,200.229621887207,,,,,,,,,,,,,,,,,,,,,,,,,,,,,,,,,
,3883239954.57692,200.128921508789,-13999.7001953125,0.000234398457852108,2.63175501296821E-8,1,4,13.4005146026611,5.00464683298167,30.2300006151199,0.291756567688942,0.0434293545249005,1,-1.69465436210665E-7,,,,,,,,,,,,,,,,,,,,,200.123306274414,200.134536743164,-13999.7001953125,-13999.7001953125,53.4587009442749,5.65041711591952,5.4340181350708,53,1,68,0,0,0.303421020507812,33.2355842590332,1,1,3,200.123306274414,0,200.128921508789,,,,,,,,,,,,,,,,,,,,,,,,,,,,,,,,,
,3883240025.62112,200.285133361816,-14999.5478515625,0.000251153353668428,1.78019010382435E-8,1,4,13.4005146026611,5.00461730459943,30.2300006151199,0.312601670676667,0.0465814088016291,1,-1.42938238742102E-7,,,,,,,,,,,,,,,,,,,,,200.284393310547,200.285873413086,-14999.5478515625,-14999.5478515625,53.411803233121,5.65027159011823,5.43546867370605,54,1,0,0,1,0.305252075195313,33.7243423461914,1,1,3,200.285873413086,0,200.285133361816,,,,,,,,,,,,,,,,,,,,,,,,,,,,,,,,,
,3883240125.11894,200.224739074707,-24999.65625,0.000418474745993391,3.15192667475758E-8,1,4,13.4005146026611,5.0047283323276,30.2300006151199,0.520857300954777,0.0777474784257664,1,-1.33259658202814E-7,,,,,,,,,,,,,,,,,,,,,200.222854614258,200.226623535156,-24999.65625,-24999.65625,53.6099460627461,5.64964561176664,5.43668174743652,54,1,0,0,1,0.304031372070313,33.7243423461914,1,1,3,200.222854614258,0,200.224739074707,,,,,,,,,,,,,,,,,,,,,,,,,,,,,,,,,
,3883240212.85576,200.289962768555,-34999.640625,0.000585861698828406,4.52057852123627E-8,1,4,13.4005146026611,5.00468889929318,30.2300006151199,0.729150163734787,0.109101127394718,1,1.94534933427377E-8,,,,,,,,,,,,,,,,,,,,,200.25862121582,200.321304321289,-34999.640625,-34999.640625,53.379365649573,5.64896376220556,5.43649005889893,54,1,0,0,1,0.303115844726562,33.7243423461914,1,1,3,200.321304321289,0,200.289962768555,,,,,,,,,,,,,,,,,,,,,,,,,,,,,,,,,
,3883240324.28015,200.453948974609,-44999.5625,0.000753285996348037,6.29925071872036E-8,1,4,13.4005146026611,5.00461625716388,30.2300006151199,0.937474724926439,0.140469690750384,1,1.80166283569056E-7,,,,,,,,,,,,,,,,,,,,,200.450622558594,200.457275390625,-44999.5625,-44999.5625,53.2840069702268,5.64931859718077,5.44421720504761,54,1,0,0,1,0.303955078125,33.7243423461914,1,1,3,200.450622558594,0,200.453948974609,,,,,,,,,,,,,,,,,,,,,,,,,,,,,,,,,
,3883240425.02933,200.200500488281,-54999.7578125,0.000920781033636064,1.10454463454553E-7,1,4,13.4005146026611,5.00461726961197,30.2300006151199,1.14590678703002,0.171824701981622,1,3.17589229054109E-7,,,,,,,,,,,,,,,,,,,,,200.186721801758,200.214279174805,-54999.7578125,-54999.7578125,53.3383301523133,5.64987939780888,5.44076776504517,54,1,0,0,1,0.303115844726562,33.2355842590332,1,1,3,200.214279174805,0,200.200500488281,,,,,,,,,,,,,,,,,,,,,,,,,,,,,,,,,
,3883240513.01704,200.119102478027,-64999.65625,0.00108835763297278,2.79176549992098E-7,1,4,13.4005146026611,5.00467369183164,30.2300006151199,1.35443508525837,0.203374289231763,1,5.9660790852447E-7,,,,,,,,,,,,,,,,,,,,,200.091690063477,200.146514892578,-64999.65625,-64999.65625,53.2003727186691,5.64925561065583,5.44159269332886,54,1,0,0,1,0.3021240234375,33.7243423461914,1,1,3,200.146514892578,0,200.119102478027,,,,,,,,,,,,,,,,,,,,,,,,,,,,,,,,,
,3883240614.36109,200.083801269531,-64999.69140625,0.00108810952620382,2.0776372050105E-7,1,4,13.4005146026611,5.00465650787322,30.2300006151199,1.35410210840928,0.203445348803586,1,6.91603395630829E-7,,,,,,,,,,,,,,,,,,,,,200.074584960938,200.093017578125,-64999.69140625,-64999.69140625,53.1112670674768,5.64937415666863,5.44351959228516,54,1,0,0,1,0.304794311523438,34.2131004333496,1,1,3,200.093017578125,0,200.083801269531,,,,,,,,,,,,,,,,,,,,,,,,,,,,,,,,,
,3883240702.04288,200.140922546387,-54999.8828125,0.00092044891849385,1.36547131350096E-7,1,4,13.4005146026611,5.00476666839787,30.2300006151199,1.14553245784224,0.171828963807051,1,3.64932299401466E-7,,,,,,,,,,,,,,,,,,,,,200.121139526367,200.160705566406,-54999.8828125,-54999.8828125,53.3168353680345,5.64842587949297,5.44106388092041,54,1,0,0,1,0.304489135742188,33.7243423461914,1,1,3,200.160705566406,0,200.140922546387,,,,,,,,,,,,,,,,,,,,,,,,,,,,,,,,,
,3883240790.12545,200.166191101074,-44999.76171875,0.00075295078993581,5.40213725907077E-8,1,4,13.4005146026611,5.00478609716068,30.2300006151199,0.93708727467257,0.140512475071125,1,2.59330142312243E-7,,,,,,,,,,,,,,,,,,,,,200.162307739258,200.170074462891,-44999.76171875,-44999.76171875,53.3602157508518,5.648622617551,5.45026683807373,54,1,0,0,1,0.303497314453125,33.7243423461914,1,1,3,200.162307739258,0,200.166191101074,,,,,,,,,,,,,,,,,,,,,,,,,,,,,,,,,
,3883240876.50241,200.062828063965,-34999.59375,0.000585437333110943,6.69747334045552E-8,1,4,13.4005146026611,5.00477411888354,30.2300006151199,0.728627772874398,0.109102145144112,1,8.16662750732634E-8,,,,,,,,,,,,,,,,,,,,,200.052154541016,200.073501586914,-34999.59375,-34999.59375,53.442286745371,5.64967638401781,5.43933057785034,54,1,0,0,1,0.304183959960937,33.7243423461914,1,1,3,200.074356079102,0,200.062828063965,,,,,,,,,,,,,,,,,,,,,,,,,,,,,,,,,
,3883240965.2768,200.172760009766,-24999.630859375,0.000417971079459224,2.73612556143801E-8,1,4,13.4005146026611,5.00484389534936,30.2300006151199,0.520218956750214,0.0778452660117117,1,1.86357463098936E-8,,,,,,,,,,,,,,,,,,,,,200.145904541016,200.199615478516,-24999.630859375,-24999.630859375,53.6005665205153,5.64926720221412,5.44858026504517,54,1,0,0,1,0.303726196289063,34.7018585205078,1,1,3,200.199615478516,0,200.172760009766,,,,,,,,,,,,,,,,,,,,,,,,,,,,,,,,,
,3883241051.1874,200.167388916016,-14999.7998046875,0.00025053107714009,1.98957552228006E-8,1,4,13.4005146026611,5.00479603181298,30.2300006151199,0.311821482216192,0.0466102783112615,1,-2.85232735063341E-8,,,,,,,,,,,,,,,,,,,,,200.148025512695,200.186752319336,-14999.7998046875,-14999.7998046875,53.4864487567076,5.64943968729804,5.44205188751221,54,1,0,0,1,0.302963256835937,33.7243423461914,1,1,3,200.186752319336,0,200.167388916016,,,,,,,,,,,,,,,,,,,,,,,,,,,,,,,,,
,3883241109.19637,200.451545715332,-14000.216796875,0.000233792682562415,2.3359198848637E-8,1,4,13.4005146026611,5.00479039775316,30.2300006151199,0.290995490678372,0.0434441314087527,1,-6.83724103620818E-8,,,,,,,,,,,,,,,,,,,,,200.441055297852,200.462036132813,-14000.216796875,-14000.216796875,53.4801957285537,5.64956400742562,5.44433164596558,53,1,68,0,0,0.303421020507812,34.2131004333496,1,1,3,200.462036132813,0,200.451545715332,,,,,,,,,,,,,,,,,,,,,,,,,,,,,,,,,
,3883241245.38475,200.16529083252,-13000.306640625,0.000217114118676683,2.09700653438066E-8,1,4,13.4005146026611,5.00475652916242,30.2300006151199,0.270253145385174,0.040213636291386,1,-1.68626174758929E-7,,,,,,,,,,,,,,,,,,,,,200.153717041016,200.176864624023,-13000.306640625,-13000.306640625,53.4587009442749,5.64924888548372,5.44900751113892,54,1,0,0,1,0.303955078125,33.7243423461914,1,1,3,200.152954101562,0,200.16529083252,,,,,,,,,,,,,,,,,,,,,,,,,,,,,,,,,
,3883241286.98068,200.115791320801,-12000.232421875,0.000200287364707857,1.78174826925548E-8,1,4,13.4005146026611,5.00473646882877,30.2300006151199,0.249283708786956,0.0372499455790404,1,-3.25057927143711E-8,,,,,,,,,,,,,,,,,,,,,200.093383789062,200.138198852539,-12000.232421875,-12000.232421875,53.4661264152076,5.6495890833862,5.44146060943604,53,1,68,0,0,0.303878784179687,34.2131004333496,1,1,3,200.13981628418,0,200.115791320801,,,,,,,,,,,,,,,,,,,,,,,,,,,,,,,,,
,3883241326.22916,200.23934173584,-11000.18359375,0.000183551831391737,1.72157704937158E-8,1,4,13.4005146026611,5.00471134258896,30.2300006151199,0.228455523105112,0.0341173425447442,1,-4.57362584651229E-8,,,,,,,,,,,,,,,,,,,,,200.21842956543,200.26025390625,-11000.18359375,-11000.18359375,53.5493698525057,5.64939845626771,5.44707298278809,53,1,68,0,0,0.303192138671875,33.7243423461914,1,1,3,200.261489868164,0,200.23934173584,,,,,,,,,,,,,,,,,,,,,,,,,,,,,,,,,
,3883241366.3918,200.327163696289,-10000.4619140625,0.000166817334354314,1.51417543131529E-8,1,4,13.4005146026611,5.00477220397171,30.2300006151199,0.207629212080293,0.0310171153551259,1,-3.3742470741922E-8,,,,,,,,,,,,,,,,,,,,,200.307220458984,200.347106933594,-10000.4619140625,-10000.4619140625,53.5778992934576,5.64973203719793,5.45293092727661,53,1,68,0,0,0.304031372070313,33.7243423461914,1,1,3,200.347106933594,0,200.327163696289,,,,,,,,,,,,,,,,,,,,,,,,,,,,,,,,,
,3883241494.75689,200.152702331543,-9000.4384765625,0.000150122639799605,1.35201974210356E-8,1,4,13.4005146026611,5.00471050360657,30.2300006151199,0.186869806678453,0.0277596366635987,1,-1.53197918574118E-7,,,,,,,,,,,,,,,,,,,,,200.144256591797,200.161148071289,-9000.4384765625,-9000.4384765625,53.4446316309287,5.64952317645999,5.45089292526245,54,1,0,0,1,0.303115844726562,33.7243423461914,1,1,3,200.144256591797,0,200.152702331543,,,,,,,,,,,,,,,,,,,,,,,,,,,,,,,,,
,3883241535.86747,200.129417419434,-8000.31396484375,0.000133310652560289,1.39249116264603E-8,1,4,13.4005146026611,5.00468516207297,30.2300006151199,0.165921139311014,0.0247860748673171,1,-2.72751021153576E-8,,,,,,,,,,,,,,,,,,,,,200.098846435547,200.15998840332,-8000.31396484375,-8000.31396484375,53.447367330746,5.6498621602149,5.44604778289795,52,1,68,0,0,0.304794311523438,33.2355842590332,1,1,3,200.15998840332,0,200.129417419434,,,,,,,,,,,,,,,,,,,,,,,,,,,,,,,,,
,3883241577.80701,200.175559997559,-7000.2529296875,0.000116568936797655,1.04080974718151E-8,1,4,13.4005146026611,5.00470046624478,30.2300006151199,0.1450848587768,0.0216722397375255,1,-2.48040465741722E-8,,,,,,,,,,,,,,,,,,,,,200.16828918457,200.182830810547,-7000.2529296875,-7000.2529296875,53.462609086871,5.64980334158466,5.44505405426025,54,1,0,0,1,0.303192138671875,33.7243423461914,1,1,3,200.16828918457,0,200.175559997559,,,,,,,,,,,,,,,,,,,,,,,,,,,,,,,,,
,3883241619.7883,200.155387878418,-6000.330078125,9.98283020198049E-5,1.01664891092415E-8,1,4,13.4005146026611,5.00465007823932,30.2300006151199,0.12424933216705,0.0185457543726064,1,-3.23639183879287E-8,,,,,,,,,,,,,,,,,,,,,200.120040893555,200.190734863281,-6000.330078125,-6000.330078125,53.5524963665826,5.64979458156079,5.44318103790283,53,1,68,0,0,0.304107666015625,33.7243423461914,1,1,3,200.190734863281,0,200.155387878418,,,,,,,,,,,,,,,,,,,,,,,,,,,,,,,,,
,3883241660.74311,200.247978210449,-5000.3818359375,8.30720994149097E-5,1.04375464053375E-8,1,4,13.4005146026611,5.00467955991515,30.2300006151199,0.103392609346508,0.0154483253714919,1,-1.45958720529942E-8,,,,,,,,,,,,,,,,,,,,,200.236770629883,200.259185791016,-5000.3818359375,-5000.3818359375,53.5939226781018,5.64932473627875,5.44543027877808,52,1,68,0,0,0.3033447265625,34.2131004333496,1,1,3,200.259185791016,0,200.247978210449,,,,,,,,,,,,,,,,,,,,,,,,,,,,,,,,,
,3883241701.79606,200.318687438965,-4000.45922851562,6.63123171153363E-5,8.87011558199989E-9,1,4,13.4005146026611,5.00469340068623,30.2300006151199,0.0825320630197485,0.0123411932150114,1,-4.00424311208563E-9,,,,,,,,,,,,,,,,,,,,,200.305740356445,200.331634521484,-4000.45922851562,-4000.45922851562,53.5388178674961,5.64998379980139,5.45293378829956,53,1,68,0,0,0.303192138671875,33.7243423461914,1,1,3,200.331634521484,0,200.318687438965,,,,,,,,,,,,,,,,,,,,,,,,,,,,,,,,,
,3883241741.29637,200.360313415527,-3000.51123046875,4.95646828913457E-5,7.66180860428196E-9,1,4,13.4005146026611,5.00469421809522,30.2300006151199,0.0616871607464443,0.00923017847743097,1,1.6968421854332E-9,,,,,,,,,,,,,,,,,,,,,200.348083496094,200.372543334961,-3000.51123046875,-3000.51123046875,53.5294383252653,5.64957933408318,5.45388889312744,53,1,68,0,0,0.30303955078125,33.7243423461914,1,1,3,200.372543334961,0,200.360313415527,,,,,,,,,,,,,,,,,,,,,,,,,,,,,,,,,
,3883241798.34042,200.241645812988,-2510.40014648438,4.13430701719699E-5,6.99541542348991E-9,1,4,13.4005146026611,5.00476570715858,30.2300006151199,0.0514550421555669,0.00770394514916434,1,5.17714616279121E-9,,,,,,,,,,,,,,,,,,,,,200.223236083984,200.260055541992,-2510.40014648438,-2510.40014648438,53.592750235323,5.64931289022825,5.45384073257446,54,1,0,0,1,0.303955078125,33.7243423461914,1,1,3,200.260055541992,0,200.241645812988,,,,,,,,,,,,,,,,,,,,,,,,,,,,,,,,,
,3883241837.3158,200.373680114746,-1930.37109375,3.16182281571323E-5,6.89465435829265E-9,1,4,13.4005146026611,5.00469191883704,30.2300006151199,0.0393469621377859,0.00591746818201078,1,2.46809705897493E-8,,,,,,,,,,,,,,,,,,,,,200.359970092773,200.387390136719,-1930.37109375,-1930.37109375,53.5904053497653,5.64959050942767,5.45256614685059,54,1,0,0,1,0.305862426757812,33.7243423461914,1,1,3,200.387390136719,0,200.373680114746,,,,,,,,,,,,,,,,,,,,,,,,,,,,,,,,,
,3883241887.68717,200.466461181641,-1350.50573730469,2.19125794907216E-5,6.16133894229971E-9,1,4,13.4005146026611,5.00467947218226,30.2300006151199,0.0272741493054896,0.00406509840135243,1,-1.17463028062474E-8,,,,,,,,,,,,,,,,,,,,,200.459075927734,200.473846435547,-1350.50573730469,-1350.50573730469,53.5188863402557,5.65036814549839,5.44733047485352,54,1,0,0,1,0.303726196289063,33.2355842590332,1,1,3,200.459075927734,0,200.466461181641,,,,,,,,,,,,,,,,,,,,,,,,,,,,,,,,,
,3883241927.45939,200.30313873291,-770.32568359375,1.21949814253155E-5,7.69123256912007E-9,1,4,13.4005146026611,5.00467798160817,30.2300006151199,0.0151745648725838,0.00229094220688389,1,1.64415585146671E-8,,,,,,,,,,,,,,,,,,,,,200.288681030273,200.317596435547,-770.32568359375,-770.32568359375,53.5036445841307,5.64936389493062,5.45258665084839,54,1,0,0,1,0.305023193359375,33.7243423461914,1,1,3,200.317596435547,0,200.30313873291,,,,,,,,,,,,,,,,,,,,,,,,,,,,,,,,,
,3883241967.51293,200.441673278809,-190.460296630859,2.4995724214795E-6,6.61540608458542E-9,1,4,13.4005146026611,5.00467569265177,30.2300006151199,0.00311182384293903,0.000459298564092799,1,-4.88130323690096E-9,,,,,,,,,,,,,,,,,,,,,200.435394287109,200.447952270508,-190.460296630859,-190.460296630859,53.6189347907172,5.64948717235634,5.45049524307251,54,1,0,0,1,0.306854248046875,33.7243423461914,1,1,3,200.434494018555,0,200.441673278809,,,,,,,,,,,,,,,,,,,,,,,,,,,,,,,,,
,3883242006.61765,200.443801879883,389.719787597656,-7.10470562396737E-6,1.93066137842404E-8,1,4,13.4005146026611,5.00464959863575,30.2300006151199,-0.00884971064620138,-0.00127322930217991,1,3.97925711473628E-8,,,,,,,,,,,,,,,,,,,,,200.435943603516,200.45166015625,389.719787597656,389.719787597656,53.4989548130153,5.64984998198687,5.45318984985352,54,1,0,0,1,0.304718017578125,33.7243423461914,6,1,3,200.45166015625,0,200.443801879883,,,,,,,,,,,,,,,,,,,,,,,,,,,,,,,,,
,3883242047.08732,200.369468688965,969.698425292969,-1.67691680579474E-5,2.25850330375972E-8,1,4,13.4005146026611,5.00468604410057,30.2300006151199,-0.0208671591272565,-0.00314520150385807,1,-1.85494921321261E-8,,,,,,,,,,,,,,,,,,,,,200.353164672852,200.385772705078,969.698425292969,969.698425292969,53.5177138974768,5.64946516356497,5.44987964630127,54,1,0,0,1,0.30303955078125,34.2131004333496,1,1,3,200.385772705078,0,200.369468688965,,,,,,,,,,,,,,,,,,,,,,,,,,,,,,,,,
,3883242086.9461,200.363357543945,1549.68969726562,-2.64419412572066E-5,1.58412070383649E-8,1,4,13.4005146026611,5.00459395275948,30.2300006151199,-0.0329152318408707,-0.00487674530124224,1,3.70721666570562E-8,,,,,,,,,,,,,,,,,,,,,200.350067138672,200.376647949219,1549.68969726562,1549.68969726562,53.4958282989384,5.64984272023025,5.45148944854736,54,1,0,0,1,0.3045654296875,33.7243423461914,1,1,3,200.376647949219,0,200.363357543945,,,,,,,,,,,,,,,,,,,,,,,,,,,,,,,,,
,3883242126.11943,200.317390441895,2129.5927734375,-3.59986766021153E-5,1.51711808066768E-7,1,4,13.4005146026611,5.00457938158796,30.2300006151199,-0.0448035984988901,-0.0066913267075692,1,8.65745169200847E-9,,,,,,,,,,,,,,,,,,,,,200.313995361328,200.320785522461,2129.5927734375,2129.5927734375,53.5888420927268,5.65015271407638,5.45412683486938,54,1,0,0,1,0.302810668945313,33.7243423461914,1,1,3,200.313995361328,0,200.317390441895,,,,,,,,,,,,,,,,,,,,,,,,,,,,,,,,,
,3883242166.67467,200.22038269043,2709.54638671875,-4.57704248003421E-5,3.21058202275516E-8,1,4,13.4005146026611,5.00462086039713,30.2300006151199,-0.0569769506541516,-0.00843510360272147,1,6.93937180500535E-8,,,,,,,,,,,,,,,,,,,,,200.213851928711,200.226913452148,2709.54638671875,2709.54638671875,53.5552320663999,5.64985133068407,5.44830560684204,54,1,0,0,1,0.304412841796875,33.2355842590332,1,1,3,200.213851928711,0,200.22038269043,,,,,,,,,,,,,,,,,,,,,,,,,,,,,,,,,
,3883242223.50214,200.128623962402,3499.74877929687,-5.88966242503123E-5,7.43476648646013E-9,1,4,13.4005146026611,5.00463956603843,30.2300006151199,-0.0733146947039474,-0.0108721540073597,1,7.48754317628312E-8,,,,,,,,,,,,,,,,,,,,,200.127960205078,200.129287719727,3499.74877929687,3499.74877929687,53.4286082462845,5.64963162976062,5.450852394104,54,1,0,0,1,0.304946899414063,34.2131004333496,1,1,3,200.127960205078,0,200.128623962402,,,,,,,,,,,,,,,,,,,,,,,,,,,,,,,,,
,3883242264.6885,200.239715576172,4499.55810546875,-7.55971042395509E-5,9.0150083304627E-9,1,4,13.4005146026611,5.00455187360567,30.2300006151199,-0.0941020394647032,-0.0139490384129212,1,1.00635442557022E-7,,,,,,,,,,,,,,,,,,,,,200.237655639648,200.241775512695,4499.55810546875,4499.55810546875,53.6388663179576,5.65035187542273,5.4512300491333,54,1,0,0,1,0.30364990234375,33.2355842590332,1,1,3,200.237426757813,0,200.239715576172,,,,,,,,,,,,,,,,,,,,,,,,,,,,,,,,,
,3883242306.54793,200.253601074219,5499.80859375,-9.23058431992957E-5,1.31510393260418E-8,1,4,13.4005146026611,5.00451655013674,30.2300006151199,-0.114899502020338,-0.017033061340479,1,1.21974025456922E-7,,,,,,,,,,,,,,,,,,,,,200.24870300293,200.258499145508,5499.80859375,5499.80859375,53.4723794433614,5.64992387369415,5.44919013977051,54,1,0,0,1,0.304946899414063,33.7243423461914,1,1,3,200.24870300293,0,200.253601074219,,,,,,,,,,,,,,,,,,,,,,,,,,,,,,,,,
,3883242349.42209,200.161338806152,6499.52978515625,-0.000109038701605525,1.53919362886474E-8,1,4,13.4005146026611,5.00458414160854,30.2300006151199,-0.135730465189413,-0.0201221539219355,1,1.43263192462291E-7,,,,,,,,,,,,,,,,,,,,,200.151062011719,200.171615600586,6499.52978515625,6499.52978515625,53.5997848919961,5.64953908497055,5.44895935058594,54,1,0,0,1,0.303726196289063,33.7243423461914,1,1,3,200.171615600586,0,200.161338806152,,,,,,,,,,,,,,,,,,,,,,,,,,,,,,,,,
,3883242405.32515,200.429298400879,7499.62939453125,-0.000125726354219551,1.81176124814225E-8,1,4,13.4005146026611,5.00464895287489,30.2300006151199,-0.156496130691578,-0.023267778342836,1,1.12446310043482E-7,,,,,,,,,,,,,,,,,,,,,200.425796508789,200.432800292969,7499.62939453125,7499.62939453125,53.4907477135634,5.65016339975408,5.45268440246582,54,1,0,0,1,0.303878784179687,33.2355842590332,1,1,3,200.425796508789,0,200.429298400879,,,,,,,,,,,,,,,,,,,,,,,,,,,,,,,,,
,3883242447.94848,200.407417297363,8499.8291015625,-0.000142465765214261,1.68862552716488E-8,1,4,13.4005146026611,5.00487023444577,30.2300006151199,-0.177350434611639,-0.0263192568930613,1,1.66032211405081E-7,,,,,,,,,,,,,,,,,,,,,200.402450561523,200.412384033203,8499.8291015625,8499.8291015625,53.467689672246,5.64832267270592,5.45443487167358,54,1,0,0,1,0.303802490234375,33.7243423461914,1,1,3,200.402450561523,0,200.407417297363,,,,,,,,,,,,,,,,,,,,,,,,,,,,,,,,,
,3883242488.0504,200.259590148926,9499.953125,-0.000159210238882204,2.54191216224749E-8,1,4,13.4005146026611,5.00490059183743,30.2300006151199,-0.198192081541862,-0.0294437710894582,1,1.6074034178153E-7,,,,,,,,,,,,,,,,,,,,,200.249954223633,200.269226074219,9499.953125,9499.953125,53.521622040073,5.64800957265597,5.44905662536621,52,1,68,0,0,0.302352905273438,33.7243423461914,1,1,3,200.26969909668,0,200.259590148926,,,,,,,,,,,,,,,,,,,,,,,,,,,,,,,,,
,3883242620.42604,200.147117614746,10499.498046875,-0.000175906799359653,1.65661958853112E-8,1,4,13.4005146026611,5.00491245293274,30.2300006151199,-0.218973621750995,-0.0325571938555604,1,1.57099511338895E-7,,,,,,,,,,,,,,,,,,,,,200.137435913086,200.156799316406,10499.498046875,10499.498046875,53.3723309928999,5.64755216810432,5.45717716217041,54,1,0,0,1,0.3033447265625,33.7243423461914,1,1,3,200.137435913086,0,200.147117614746,,,,,,,,,,,,,,,,,,,,,,,,,,,,,,,,,
,3883242663.04848,200.117240905762,11500.0126953125,-0.000192663256571977,2.12348304678682E-8,1,4,13.4005146026611,5.00479558193502,30.2300006151199,-0.239823350144446,-0.0356662971115628,1,1.64875108870355E-7,,,,,,,,,,,,,,,,,,,,,200.112762451172,200.121719360352,11500.0126953125,11500.0126953125,53.5454617099095,5.6476128225085,5.45871543884277,53,1,68,0,0,0.302658081054687,33.7243423461914,1,1,3,200.121719360352,0,200.117240905762,,,,,,,,,,,,,,,,,,,,,,,,,,,,,,,,,
,3883242703.09241,200.136695861816,12499.9228515625,-0.000209380100782557,2.05990986281074E-8,1,4,13.4005146026611,5.00491890462534,30.2300006151199,-0.260640354026566,-0.0387674370629242,1,1.75050533503137E-7,,,,,,,,,,,,,,,,,,,,,200.111968994141,200.161422729492,12499.9228515625,12499.9228515625,53.4786324715153,5.64796621230682,5.45632171630859,54,1,0,0,1,0.30242919921875,33.7243423461914,1,1,3,200.162857055664,0,200.136695861816,,,,,,,,,,,,,,,,,,,,,,,,,,,,,,,,,
,3883242743.31717,200.266326904297,13499.6689453125,-0.000226096909565953,2.2260576050936E-8,1,4,13.4005146026611,5.00489341224256,30.2300006151199,-0.281450390721595,-0.0418446775116115,1,2.03195326605818E-7,,,,,,,,,,,,,,,,,,,,,200.256042480469,200.276611328125,13499.6689453125,13499.6689453125,53.4528387303807,5.64773314406689,5.45406055450439,54,1,0,0,1,0.303878784179687,33.7243423461914,1,1,3,200.276611328125,0,200.266326904297,,,,,,,,,,,,,,,,,,,,,,,,,,,,,,,,,
,3883242783.36416,200.284591674805,14499.5927734375,-0.000242846371187967,2.09261301409235E-8,1,4,13.4005146026611,5.00493592227816,30.2300006151199,-0.302293343251988,-0.045016865311703,1,1.6059214145294E-7,,,,,,,,,,,,,,,,,,,,,200.282516479492,200.286666870117,14499.5927734375,14499.5927734375,53.4997364415345,5.64788386378966,5.45722436904907,54,1,0,0,1,0.303878784179687,33.7243423461914,1,1,3,200.282516479492,0,200.284591674805,,,,,,,,,,,,,,,,,,,,,,,,,,,,,,,,,
,3883242858.3019,200.392433166504,19999.90625,-0.000335099705077707,5.86610132953927E-8,1,4,13.4005146026611,5.00480330701774,30.2300006151199,-0.417166641654088,-0.0617648048409102,10,5.03550361684696E-7,,,,,,,,,,,,,,,,,,,,,200.391632080078,200.39323425293,19999.90625,19999.90625,53.4884028280057,5.64795240840331,5.45801401138306,54,1,0,0,1,0.302963256835937,33.7243423461914,1,1,3,200.39323425293,0,200.392433166504,,,,,,,,,,,,,,,,,,,,,,,,,,,,,,,,,
,3883242946.69708,200.240447998047,29999.90234375,-0.00050232150121434,3.88222362563122E-8,1,4,13.4005146026611,5.0047400782437,30.2300006151199,-0.625204815474495,-0.0934253818998034,1,7.96950433349963E-8,,,,,,,,,,,,,,,,,,,,,200.217193603516,200.263702392578,29999.90234375,29999.90234375,53.3899176345826,5.64850947186004,5.45303678512573,54,1,0,0,1,0.30242919921875,33.7243423461914,1,1,3,200.263702392578,0,200.240447998047,,,,,,,,,,,,,,,,,,,,,,,,,,,,,,,,,
,3883243032.16643,200.27278137207,40000.390625,-0.000669753032040601,4.70027117606967E-8,1,4,13.4005146026611,5.00494331605528,30.2300006151199,-0.833615884698876,-0.124751146940419,1,-3.72050204264998E-8,,,,,,,,,,,,,,,,,,,,,200.263641357422,200.281921386719,40000.390625,40000.390625,53.4051593907076,5.64818507446599,5.45397472381592,54,1,0,0,1,0.302963256835937,33.7243423461914,1,1,3,200.263641357422,0,200.27278137207,,,,,,,,,,,,,,,,,,,,,,,,,,,,,,,,,
,3883243132.08517,200.023094177246,50000.296875,-0.000837266948923713,1.60040001372144E-7,1,4,13.4005146026611,5.00478691085066,30.2300006151199,-1.04204940283352,-0.156073762098385,1,-1.48992751162219E-7,,,,,,,,,,,,,,,,,,,,,200.021896362305,200.024291992187,50000.296875,50000.296875,53.3637330791883,5.64832856157,5.45631837844849,54,1,0,0,1,0.303268432617188,33.7243423461914,1,1,3,200.021896362305,0,200.023094177246,,,,,,,,,,,,,,,,,,,,,,,,,,,,,,,,,
,3883243232.6226,200.219970703125,60000.53515625,-0.00100476665741869,2.00964218965846E-7,1,4,13.4005146026611,5.00478790323618,30.2300006151199,-1.25047427760468,-0.187584646359788,1,-4.09750503539911E-7,,,,,,,,,,,,,,,,,,,,,200.189636230469,200.250305175781,60000.53515625,60000.53515625,53.2402357731499,5.64827703937616,5.45443058013916,54,1,0,0,1,0.30364990234375,33.7243423461914,1,1,3,200.250305175781,0,200.219970703125,,,,,,,,,,,,,,,,,,,,,,,,,,,,,,,,,
,3883243320.12533,200.135765075684,70000.484375,-0.00117239180492181,2.46741559691256E-7,1,4,13.4005146026611,5.0047271080315,30.2300006151199,-1.45905084341952,-0.218977130236071,1,-5.59637082706615E-7,,,,,,,,,,,,,,,,,,,,,200.130966186523,200.140563964844,70000.484375,70000.484375,53.1304169661979,5.64828381915098,5.45618200302124,54,1,0,0,1,0.3045654296875,33.7243423461914,1,1,3,200.140563964844,0,200.135765075684,,,,,,,,,,,,,,,,,,,,,,,,,,,,,,,,,
,3883243323.97373,200.14289855957,70000.484375,-0.00117240990977174,3.36237929713122E-7,1,4,13.4005146026611,5.00466041698914,30.2300006151199,-1.45903720591341,-0.219036449522865,1,-6.07869900413765E-7,,,,,,,,,,,,,,,,,,,,,200.140563964844,200.145233154297,70000.484375,70000.484375,53.2535234579768,5.64905018724577,5.45358657836914,54,2,0,0,1,0.303573608398438,33.7243423461914,1,1,3,200.145233154297,0,200.14289855957,,,,,,,,,,,,,,,,,,,,,,,,,,,,,,,,,