File: SQUID/23006_LCOS/transfer_119973_files_84937504/LSAT_subs_A1_MH_20K_FC_p0d5T.dat
[Header]
; MPMS3 Data File (default extension .dat)
; Copyright (c) 2007, Quantum Design, Inc. All rights reserved.
TITLE,
FILEOPENTIME,3883216191.91667,01/18/2023,3:14 pm
BYAPP,SQUID AC,0.9.1.0
INFO,MPMS3 Measurement Release 1.1.16 Build 347, MultiVu Release 2.3.3.2,APPNAME
INFO,0,MOMENT_UNITS
INFO,LSAT,SAMPLE_MATERIAL
INFO,,SAMPLE_COMMENT
INFO,,SAMPLE_MASS
INFO,,SAMPLE_VOLUME
INFO,,SAMPLE_MOLECULAR_WEIGHT
INFO,,SAMPLE_SIZE
INFO,,SAMPLE_SHAPE
INFO,Quartz,SAMPLE_HOLDER
INFO,Standard,SAMPLE_HOLDER_DETAIL
INFO,65.8,SAMPLE_OFFSET
DATATYPE,COMMENT,1
DATATYPE,TIME,2
STARTUPAXIS,X,2
STARTUPAXIS,Y1,5
FIELDGROUP, VSM,2,3,4,5,6,8,9,10,11,14,15
FIELDGROUP, DC, 2,3,4,14,56,57,58,59,60,61,62,63,64,65,66,67,68,69
FIELDGROUP, AC, 2,3,4,11,16,17,18,19,20,21,22,23,24,25,26,27,28,29,30
STARTUPGROUP, All
[Data]
Comment,Time Stamp (sec),Temperature (K),Magnetic Field (Oe),Moment (emu),M. Std. Err. (emu),Transport Action,Averaging Time (sec),Frequency (Hz),Peak Amplitude (mm),Center Position (mm),Lockin Signal' (V),Lockin Signal (V),Range,M. Quad. Signal (emu),AC Moment (emu),AC M. Std Err. (emu),AC Phase (deg),AC Phase Std. Err. (deg),AC Susceptibility (emu/Oe),AC Suscept. Std Err. (emu/Oe),AC X' (emu/Oe),AC X' Std Err. (emu/Oe),AC X'' (emu/Oe),AC X'' Std Err. (emu/Oe),AC Drive (Oe),AC Frequency (Hz),AC Averaging Time (sec),AC Cycles,AC Range,AC Measure Type,AC Signal' (V),AC Signal'' (V),AC Trim Coil Ratio,AC Trim Coil Phase,Min. Temperature (K),Max. Temperature (K),Min. Field (Oe),Max. Field (Oe),Mass (grams),Motor Lag (deg),Pressure (Torr),Measure Count,Measurement Number,SQUID Status (code),Motor Status (code),Measure Status (code),Motor Current (amps),Motor Temp. (C),Temp. Status (code),Field Status (code),Chamber Status (code),Chamber Temp (K),Redirection State,Average Temp (K),Rotation Angle (deg),Rotator state,DC Moment Fixed Ctr (emu),DC Moment Err Fixed Ctr (emu),DC Moment Free Ctr (emu),DC Moment Err Free Ctr (emu),DC Fixed Fit,DC Free Fit,DC Calculated Center (mm),DC Calculated Center Err (mm),DC Scan Length (mm),DC Scan Time (s),DC Number of Points,DC Squid Drift,DC Min V (V),DC Max V (V),DC Scans per Measure,Map 01,Map 02,Map 03,Map 04,Map 05,Map 06,Map 07,Map 08,Map 09,Map 10,Map 11,Map 12,Map 13,Map 14,Map 15,Map 16
,3883216223.36639,20.0001420974731,70000.0546875,-0.00112659678924585,3.40927783365287E-7,1,4,13.4005146026611,4.99727264147721,30.1099997013807,-1.39898896929837,-0.210976366729057,1,-1.3358291675266E-6,,,,,,,,,,,,,,,,,,,,,20.0001010894775,20.0001831054687,70000.0546875,70000.0546875,53.6275327044288,5.6427125151583,4.799232006073,54,1,0,0,1,0.297470092773438,31.7693061828613,1,1,3,20.0001010894775,0,20.0001420974731,,,,,,,,,,,,,,,,,,,,,,,,,,,,,,,,,
,3883216226.34053,20.0001993179321,70000.0546875,-0.00112678538699298,2.52582192975255E-7,1,4,13.4005146026611,4.99727990257617,30.1099997013807,-1.39924824039713,-0.210863531907955,1,-1.21642168042059E-6,,,,,,,,,,,,,,,,,,,,,20.0001010894775,20.0002975463867,70000.0546875,70000.0546875,53.5294383252653,5.64338826142127,4.79977989196777,54,2,0,0,1,0.297393798828125,31.2805480957031,1,1,3,20.0002975463867,0,20.0001993179321,,,,,,,,,,,,,,,,,,,,,,,,,,,,,,,,,
,3883216266.51313,20.0126581192017,65000.44921875,-0.00104520281561459,1.37851865363735E-7,1,4,13.4005146026611,4.997245118574,30.1099997013807,-1.29788633270496,-0.195859045203374,1,-1.34136029452367E-6,,,,,,,,,,,,,,,,,,,,,20.0097522735596,20.0155639648438,65000.44921875,65000.44921875,53.6056471058903,5.64341084578013,4.81120872497559,54,1,0,0,1,0.297775268554687,32.2580642700195,1,1,3,20.0097522735596,0,20.0126581192017,,,,,,,,,,,,,,,,,,,,,,,,,,,,,,,,,
,3883216270.58037,20.0080852508545,65000.44921875,-0.0010450988358948,2.06175496162408E-7,1,4,13.4005146026611,4.99720769161653,30.1099997013807,-1.2977688225107,-0.195668945542227,1,-1.2055070229392E-6,,,,,,,,,,,,,,,,,,,,,20.0064182281494,20.0097522735596,65000.44921875,65000.44921875,53.6005665205153,5.64323796021715,4.81996202468872,54,2,0,0,1,0.296859741210937,32.7468223571777,1,1,3,20.0064182281494,0,20.0080852508545,,,,,,,,,,,,,,,,,,,,,,,,,,,,,,,,,
,3883216311.13657,20.0001201629639,60000.296875,-0.000963857751120513,1.92111602469526E-7,1,4,13.4005146026611,4.99715717498196,30.1099997013807,-1.19685787857024,-0.180533134913757,1,-1.17390001424882E-6,,,,,,,,,,,,,,,,,,,,,20.0000629425049,20.0001773834229,60000.296875,60000.296875,53.5806349932749,5.64326978409875,4.83094835281372,54,1,0,0,1,0.297698974609375,32.7468223571777,1,1,3,20.0000629425049,0,20.0001201629639,,,,,,,,,,,,,,,,,,,,,,,,,,,,,,,,,
,3883216315.18014,20.0001382827759,60000.296875,-0.000963871433876452,1.45819112677503E-7,1,4,13.4005146026611,4.99716842587172,30.1099997013807,-1.19688618601015,-0.180485836346496,1,-1.13331134441503E-6,,,,,,,,,,,,,,,,,,,,,20.0000629425049,20.0002136230469,60000.296875,60000.296875,53.4317347603614,5.6432408990424,4.83159160614014,53,2,68,0,0,0.297927856445313,32.7468223571777,1,1,3,20.0002136230469,0,20.0001382827759,,,,,,,,,,,,,,,,,,,,,,,,,,,,,,,,,
,3883216355.43305,20.0116348266602,55000.40234375,-0.000882983135435514,2.48085771642574E-7,1,4,13.4005146026611,4.9971428560458,30.1099997013807,-1.09648969026596,-0.16497521752259,1,-7.45903950777527E-7,,,,,,,,,,,,,,,,,,,,,20.009162902832,20.0141067504883,55000.40234375,55000.40234375,53.4876211994864,5.6429982638961,4.83648490905762,53,1,64,0,0,0.298080444335937,33.2355842590332,1,1,3,20.009162902832,0,20.0116348266602,,,,,,,,,,,,,,,,,,,,,,,,,,,,,,,,,
,3883216359.50524,20.0072479248047,55000.40234375,-0.000882840675089075,1.83341315944415E-7,1,4,13.4005146026611,4.99707160594984,30.1099997013807,-1.09625770586726,-0.165167179838133,1,-9.2443433667157E-7,,,,,,,,,,,,,,,,,,,,,20.0053329467773,20.009162902832,55000.40234375,55000.40234375,53.5087251695057,5.64284823797059,4.83112525939941,54,2,0,0,1,0.2984619140625,32.7468223571777,1,1,3,20.0053329467773,0,20.0072479248047,,,,,,,,,,,,,,,,,,,,,,,,,,,,,,,,,
,3883216398.80512,20.005687713623,50000.33203125,-0.000801961416269515,1.38069431041178E-7,1,4,13.4005146026611,4.99710506119155,30.1099997013807,-0.99581121369292,-0.150203630434835,1,-9.73748636214973E-7,,,,,,,,,,,,,,,,,,,,,20.0044994354248,20.0068759918213,50000.33203125,50000.33203125,53.7811227084576,5.64311628073453,4.83978414535522,54,1,0,0,1,0.2978515625,33.2355842590332,1,1,3,20.0044994354248,0,20.005687713623,,,,,,,,,,,,,,,,,,,,,,,,,,,,,,,,,
,3883216402.90224,20.0038585662842,50000.33203125,-0.000802005905246589,1.21510742536291E-7,1,4,13.4005146026611,4.9970971098628,30.1099997013807,-0.995900675986083,-0.149968047835227,1,-7.77673981197416E-7,,,,,,,,,,,,,,,,,,,,,20.0032176971436,20.0044994354248,50000.33203125,50000.33203125,53.4891844565249,5.64269401415294,4.8511176109314,54,2,0,0,1,0.2978515625,32.7468223571777,1,1,3,20.0032176971436,0,20.0038585662842,,,,,,,,,,,,,,,,,,,,,,,,,,,,,,,,,
,3883216441.70334,20.0000782012939,45000.3046875,-0.000721231734952793,8.27113947893914E-8,1,4,13.4005146026611,4.99704491106527,30.1099997013807,-0.895580483081659,-0.134893947989853,1,-7.25061951985078E-7,,,,,,,,,,,,,,,,,,,,,20.0000152587891,20.0001411437988,45000.3046875,45000.3046875,53.597830820698,5.64247501473494,4.84421110153198,54,1,0,0,1,0.297927856445313,33.2355842590332,1,1,3,20.0000152587891,0,20.0000782012939,,,,,,,,,,,,,,,,,,,,,,,,,,,,,,,,,
,3883216445.59034,20.0000009536743,45000.3046875,-0.000721198804297914,1.10261615248452E-7,1,4,13.4005146026611,4.99710100161562,30.1099997013807,-0.89557162290865,-0.134769874549499,1,-6.28378512098908E-7,,,,,,,,,,,,,,,,,,,,,19.9999866485596,20.0000152587891,45000.3046875,45000.3046875,53.4856671281884,5.64231155354328,4.85220670700073,54,2,0,0,1,0.297775268554687,33.2355842590332,1,1,3,19.9999866485596,0,20.0000009536743,,,,,,,,,,,,,,,,,,,,,,,,,,,,,,,,,
,3883216484.66981,20.0111227035522,40000.19921875,-0.000640535486708285,1.25798222308428E-7,1,4,13.4005146026611,4.99700113480646,30.1099997013807,-0.79538812071551,-0.119659589740274,1,-5.31168586217933E-7,,,,,,,,,,,,,,,,,,,,,20.0090370178223,20.0132083892822,40000.19921875,40000.19921875,53.4950466704191,5.64262178212718,4.85730028152466,54,1,0,0,1,0.2978515625,33.7243423461914,1,1,3,20.0090370178223,0,20.0111227035522,,,,,,,,,,,,,,,,,,,,,,,,,,,,,,,,,
,3883216488.73792,20.0071325302124,40000.19921875,-0.000640662085359262,5.78348910984814E-8,1,4,13.4005146026611,4.99703264714003,30.1099997013807,-0.795556539696001,-0.119656287716365,1,-5.08720645550046E-7,,,,,,,,,,,,,,,,,,,,,20.0052280426025,20.0090370178223,40000.19921875,40000.19921875,53.5052078411691,5.64266437283244,4.85698795318604,54,2,0,0,1,0.2984619140625,33.2355842590332,1,1,3,20.0052280426025,0,20.0071325302124,,,,,,,,,,,,,,,,,,,,,,,,,,,,,,,,,
,3883216527.67002,20.0000772476196,34999.95703125,-0.000560149760193014,6.41883941692386E-8,1,4,13.4005146026611,4.99699614159385,30.1099997013807,-0.695573251386997,-0.104605815966728,1,-4.35017394733563E-7,,,,,,,,,,,,,,,,,,,,,20.0000591278076,20.0000953674316,34999.95703125,34999.95703125,53.491138527823,5.64293201565974,4.85482501983643,54,1,0,0,1,0.298385620117188,33.7243423461914,1,1,3,20.0001010894775,0,20.0000772476196,,,,,,,,,,,,,,,,,,,,,,,,,,,,,,,,,
,3883216532.08843,20.0000953674316,34999.95703125,-0.000560167202834827,6.04344523435737E-8,1,4,13.4005146026611,4.99695722584134,30.1099997013807,-0.695595125810614,-0.104555792920271,1,-3.93046911811397E-7,,,,,,,,,,,,,,,,,,,,,20.0000896453857,20.0001010894775,34999.95703125,34999.95703125,53.5755544078999,5.64247511149913,4.85746908187866,54,2,0,0,1,0.297393798828125,33.7243423461914,1,1,3,20.0000896453857,0,20.0000953674316,,,,,,,,,,,,,,,,,,,,,,,,,,,,,,,,,
,3883216570.88488,20.0120143890381,29999.80078125,-0.000479774596477034,7.12638876393363E-8,1,4,13.4005146026611,4.9969969828442,30.1099997013807,-0.595773882390604,-0.0895466456952042,1,-3.32788940139542E-7,,,,,,,,,,,,,,,,,,,,,20.0100784301758,20.0139503479004,29999.80078125,29999.80078125,53.516541454698,5.64308523964128,4.87309408187866,54,1,0,0,1,0.29815673828125,33.2355842590332,1,1,3,20.0100784301758,0,20.0120143890381,,,,,,,,,,,,,,,,,,,,,,,,,,,,,,,,,
,3883216574.78134,20.0078029632568,29999.80078125,-0.000479788952645924,4.92735058698674E-8,1,4,13.4005146026611,4.99695285287825,30.1099997013807,-0.595792219988968,-0.089495558050782,1,-2.90396010260691E-7,,,,,,,,,,,,,,,,,,,,,20.0059356689453,20.0096702575684,29999.80078125,29999.80078125,53.4528387303807,5.6425793026543,4.87363815307617,54,2,0,0,1,0.297622680664063,33.2355842590332,1,1,3,20.0059356689453,0,20.0078029632568,,,,,,,,,,,,,,,,,,,,,,,,,,,,,,,,,
,3883216613.94647,19.9999160766602,24999.630859375,-0.000399524551536898,3.5342945915022E-8,1,4,13.4005146026611,4.99696606343994,30.1099997013807,-0.496131668581565,-0.0744683937957,1,-1.9701807440779E-7,,,,,,,,,,,,,,,,,,,,,19.9996013641357,20.0002307891846,24999.630859375,24999.630859375,53.4665172294672,5.6425554089647,4.86730241775513,53,1,68,0,0,0.297622680664063,33.2355842590332,1,1,3,20.0002307891846,0,19.9999160766602,,,,,,,,,,,,,,,,,,,,,,,,,,,,,,,,,
,3883216624.3964,20.0006465911865,24999.630859375,-0.000399783064632105,6.1516838547187E-8,1,4,13.4005146026611,4.99697707185197,30.1099997013807,-0.496555758011288,-0.073838069688409,10,3.49386787874029E-7,,,,,,,,,,,,,,,,,,,,,20.0005550384521,20.0007381439209,24999.630859375,24999.630859375,53.4559652444576,5.64272080877819,4.87639141082764,54,2,0,0,1,0.2978515625,33.7243423461914,1,1,3,20.0005550384521,0,20.0006465911865,,,,,,,,,,,,,,,,,,,,,,,,,,,,,,,,,
,3883216671.03404,19.999906539917,19999.501953125,-0.000319352212830242,4.80031836292899E-8,1,4,13.4005146026611,4.99691908448448,30.1099997013807,-0.396576592053209,-0.0594667858374298,1,-1.11343706170273E-7,,,,,,,,,,,,,,,,,,,,,19.9998340606689,19.999979019165,19999.501953125,19999.501953125,53.4571376872364,5.64233048922773,4.87239027023315,54,1,0,0,1,0.297164916992188,33.7243423461914,1,1,3,19.999979019165,0,19.999906539917,,,,,,,,,,,,,,,,,,,,,,,,,,,,,,,,,
,3883216675.07164,20.0002164840698,19999.501953125,-0.000319273502911328,2.13185319386661E-7,1,4,13.4005146026611,4.99693818668073,30.1099997013807,-0.396511221456862,-0.0592502304675182,1,5.15141304399701E-8,,,,,,,,,,,,,,,,,,,,,19.999979019165,20.0004539489746,19999.501953125,19999.501953125,53.355916793996,5.64265669629535,4.88134717941284,48,2,100,0,0,0.2978515625,33.7243423461914,1,1,3,20.0004539489746,0,20.0002164840698,,,,,,,,,,,,,,,,,,,,,,,,,,,,,,,,,
,3883216722.35995,20.0024967193604,15000.0517578125,-0.00023947104874743,3.02579611991085E-8,1,4,13.4005146026611,4.99695105902616,30.1099997013807,-0.297432055402393,-0.04425499588343,10,1.88242172706511E-7,,,,,,,,,,,,,,,,,,,,,20.002269744873,20.0027236938477,15000.0517578125,15000.0517578125,53.4567468729768,5.64214867413097,4.88854646682739,54,1,0,0,1,0.298004150390625,33.7243423461914,1,1,3,20.002269744873,0,20.0024967193604,,,,,,,,,,,,,,,,,,,,,,,,,,,,,,,,,
,3883216731.16104,20.0004997253418,15000.0517578125,-0.000239339557020115,2.77662661176718E-8,1,4,13.4005146026611,4.99697560724789,30.1099997013807,-0.297233894140536,-0.0444775902382176,1,-1.0419981040053E-8,,,,,,,,,,,,,,,,,,,,,20.0004081726074,20.0005912780762,15000.0517578125,15000.0517578125,53.6623151735345,5.64271766069613,4.88139152526855,54,2,0,0,1,0.297164916992188,33.7243423461914,1,1,3,20.0004081726074,0,20.0004997253418,,,,,,,,,,,,,,,,,,,,,,,,,,,,,,,,,
,3883216747.03599,20.0023384094238,14499.693359375,-0.000231278544591393,3.02566117260701E-8,1,4,13.4005146026611,4.9968994089753,30.1099997013807,-0.28720762146709,-0.0430403763003059,1,-5.97676490644881E-8,,,,,,,,,,,,,,,,,,,,,20.0020046234131,20.0026721954346,14499.693359375,14499.693359375,53.5212312258134,5.6422713959927,4.87953853607178,54,1,0,0,1,0.29815673828125,33.7243423461914,1,1,3,20.0020046234131,0,20.0023384094238,,,,,,,,,,,,,,,,,,,,,,,,,,,,,,,,,
,3883216750.87114,20.0017509460449,14499.693359375,-0.000231302256700921,2.98947123436775E-8,1,4,13.4005146026611,4.99696413570075,30.1099997013807,-0.287250669350386,-0.0429894718169413,1,-1.4602559981218E-8,,,,,,,,,,,,,,,,,,,,,20.0015144348145,20.0019874572754,14499.693359375,14499.693359375,53.5736003366018,5.64244290366969,4.88728618621826,53,2,68,0,0,0.29693603515625,33.7243423461914,1,1,3,20.0015144348145,0,20.0017509460449,,,,,,,,,,,,,,,,,,,,,,,,,,,,,,,,,
,3883216775.52528,20.0040483474731,13999.6875,-0.000223419104087949,3.37452538313166E-8,1,4,13.4005146026611,4.996952596878,30.1099997013807,-0.277493642366433,-0.0412980112502272,10,1.68017235461806E-7,,,,,,,,,,,,,,,,,,,,,20.0035457611084,20.0045509338379,13999.6875,13999.6875,53.4833222426306,5.64216032395082,4.88581418991089,54,1,0,0,1,0.298004150390625,33.2355842590332,1,1,3,20.0035457611084,0,20.0040483474731,,,,,,,,,,,,,,,,,,,,,,,,,,,,,,,,,
,3883216786.26454,20.0009937286377,13999.6875,-0.000223305981621686,3.34552774200739E-8,1,4,13.4005146026611,4.99694545303393,30.1099997013807,-0.277323194511434,-0.0414734901468854,1,9.72833366339625E-9,,,,,,,,,,,,,,,,,,,,,20.0009803771973,20.0010070800781,13999.6875,13999.6875,53.493092599121,5.64233220953567,4.89140939712524,54,2,0,0,1,0.297775268554687,33.2355842590332,1,1,3,20.0009803771973,0,20.0009937286377,,,,,,,,,,,,,,,,,,,,,,,,,,,,,,,,,
,3883216801.67979,20.0051546096802,13499.7822265625,-0.000215282887612193,3.09945658623977E-8,1,4,13.4005146026611,4.99695514853001,30.1099997013807,-0.267349373000741,-0.0400549403235177,1,-4.81383925160728E-8,,,,,,,,,,,,,,,,,,,,,20.0041942596436,20.0061149597168,13499.7822265625,13499.7822265625,53.506380283948,5.64228963522838,4.89796829223633,53,1,68,0,0,0.298385620117188,33.2355842590332,1,1,3,20.0041942596436,0,20.0051546096802,,,,,,,,,,,,,,,,,,,,,,,,,,,,,,,,,
,3883216805.54632,20.0035390853882,13499.7822265625,-0.000215320185874479,3.38806768366833E-8,1,4,13.4005146026611,4.99695418204524,30.1099997013807,-0.26740302309647,-0.0400123776881167,1,-8.29514288034514E-9,,,,,,,,,,,,,,,,,,,,,20.0028839111328,20.0041942596436,13499.7822265625,13499.7822265625,53.5122424978422,5.64234429755222,4.88633155822754,54,2,0,0,1,0.297927856445313,33.7243423461914,1,1,3,20.0028839111328,0,20.0035390853882,,,,,,,,,,,,,,,,,,,,,,,,,,,,,,,,,
,3883216822.35277,20.0006437301636,12999.689453125,-0.00020728150707875,2.60317434173037E-8,1,4,13.4005146026611,4.99696184968498,30.1099997013807,-0.257412564737194,-0.03857141404644,1,-5.0468832751994E-8,,,,,,,,,,,,,,,,,,,,,20.0005149841309,20.0007724761963,12999.689453125,12999.689453125,53.3656871504864,5.64295610088071,4.89353322982788,53,1,68,0,0,0.298614501953125,33.7243423461914,1,1,3,20.0005149841309,0,20.0006437301636,,,,,,,,,,,,,,,,,,,,,,,,,,,,,,,,,
,3883216826.18456,20.0005531311035,12999.689453125,-0.000207297590015091,2.53771337379692E-8,1,4,13.4005146026611,4.99694172364116,30.1099997013807,-0.257436171640526,-0.038540189978364,1,-2.30956665711313E-8,,,,,,,,,,,,,,,,,,,,,20.0005149841309,20.0005912780762,12999.689453125,12999.689453125,53.4383786027749,5.64212182046707,4.89800357818604,54,2,0,0,1,0.297775268554687,33.2355842590332,1,1,3,20.0005912780762,0,20.0005531311035,,,,,,,,,,,,,,,,,,,,,,,,,,,,,,,,,
,3883216842.91049,20.0051183700562,12499.68359375,-0.000199285153315684,2.79249858482098E-8,1,4,13.4005146026611,4.9969338192419,30.1099997013807,-0.247478523578787,-0.0370953392192561,1,-5.83425330505998E-8,,,,,,,,,,,,,,,,,,,,,20.0042057037354,20.006031036377,12499.68359375,12499.68359375,53.4204011468326,5.64265031248266,4.88926982879639,54,1,0,0,1,0.2984619140625,33.7243423461914,1,1,3,20.0042057037354,0,20.0051183700562,,,,,,,,,,,,,,,,,,,,,,,,,,,,,,,,,
,3883216846.8507,20.003303527832,12499.68359375,-0.000199297658242877,2.6343541920529E-8,1,4,13.4005146026611,4.99696543783593,30.1099997013807,-0.247506477378854,-0.0370295967569935,1,-3.27008526549185E-9,,,,,,,,,,,,,,,,,,,,,20.0024013519287,20.0042057037354,12499.68359375,12499.68359375,53.5943134923614,5.64292765567102,4.89264440536499,54,2,0,0,1,0.296859741210937,33.7243423461914,1,1,3,20.0024013519287,0,20.003303527832,,,,,,,,,,,,,,,,,,,,,,,,,,,,,,,,,
,3883216863.49952,20.0101413726807,11999.779296875,-0.00019128288612258,2.29805492644258E-8,1,4,13.4005146026611,4.99688091908639,30.1099997013807,-0.237537251655906,-0.035607162841942,1,-5.7537417019726E-8,,,,,,,,,,,,,,,,,,,,,20.0086040496826,20.0116786956787,11999.779296875,11999.779296875,53.4043777621883,5.64190500214212,4.90061473846436,53,1,68,0,0,0.2978515625,33.7243423461914,1,1,3,20.0086040496826,0,20.0101413726807,,,,,,,,,,,,,,,,,,,,,,,,,,,,,,,,,
,3883216867.41991,20.0068368911743,11999.779296875,-0.000191314706711126,2.69698625144383E-8,1,4,13.4005146026611,4.99689473374338,30.1099997013807,-0.237583355635928,-0.0355753272028467,1,-2.70310596581681E-8,,,,,,,,,,,,,,,,,,,,,20.005069732666,20.0086040496826,11999.779296875,11999.779296875,53.5251393684095,5.64217367659367,4.89944505691528,54,2,0,0,1,0.298309326171875,33.7243423461914,1,1,3,20.005069732666,0,20.0068368911743,,,,,,,,,,,,,,,,,,,,,,,,,,,,,,,,,
,3883216884.64975,20.0007209777832,11499.798828125,-0.000183290871903727,2.61219804353944E-8,1,4,13.4005146026611,4.99693044756541,30.1099997013807,-0.227617075566028,-0.0341116490634761,1,-4.84661701352858E-8,,,,,,,,,,,,,,,,,,,,,20.0006065368652,20.0008354187012,11499.798828125,11499.798828125,53.460655015573,5.64259266664123,4.8928279876709,53,1,68,0,0,0.297622680664063,33.7243423461914,1,1,3,20.0006065368652,0,20.0007209777832,,,,,,,,,,,,,,,,,,,,,,,,,,,,,,,,,
,3883216888.64294,20.0005378723145,11499.798828125,-0.000183296720399528,2.65049825824489E-8,1,4,13.4005146026611,4.99687793266061,30.1099997013807,-0.227625948349317,-0.0340790827710275,1,-2.17717952596408E-8,,,,,,,,,,,,,,,,,,,,,20.0004692077637,20.0006065368652,11499.798828125,11499.798828125,53.4864487567076,5.64244818849978,4.90558338165283,54,2,0,0,1,0.297393798828125,33.7243423461914,1,1,3,20.0004692077637,0,20.0005378723145,,,,,,,,,,,,,,,,,,,,,,,,,,,,,,,,,
,3883216905.32589,20.0022773742676,10999.6044921875,-0.000175302566398808,3.64007154715611E-8,1,4,13.4005146026611,4.9968824461393,30.1099997013807,-0.21768802054452,-0.032664422221356,1,-7.84738182874599E-8,,,,,,,,,,,,,,,,,,,,,20.0020408630371,20.002513885498,10999.6044921875,10999.6044921875,53.5071619124672,5.64230469071067,4.9037127494812,53,1,68,0,0,0.29754638671875,33.7243423461914,1,1,3,20.0020408630371,0,20.0022773742676,,,,,,,,,,,,,,,,,,,,,,,,,,,,,,,,,
,3883216909.15847,20.0015592575073,10999.6044921875,-0.000175298929057977,3.26524468066949E-8,1,4,13.4005146026611,4.99690875286978,30.1099997013807,-0.217697325752995,-0.0325823151288215,1,-1.2708729040744E-8,,,,,,,,,,,,,,,,,,,,,20.0010776519775,20.0020408630371,10999.6044921875,10999.6044921875,53.4700345578037,5.64218801359175,4.8938250541687,54,2,0,0,1,0.298309326171875,33.7243423461914,1,1,3,20.0010776519775,0,20.0015592575073,,,,,,,,,,,,,,,,,,,,,,,,,,,,,,,,,
,3883216925.95487,20.005446434021,10499.5361328125,-0.000167284589925489,2.21501382899062E-8,1,4,13.4005146026611,4.99687700186987,30.1099997013807,-0.207733623071712,-0.0311535338067174,1,-6.13261089375673E-8,,,,,,,,,,,,,,,,,,,,,20.0042037963867,20.0066890716553,10499.5361328125,10499.5361328125,53.5493698525057,5.64267381787756,4.89884614944458,53,1,68,0,0,0.297775268554687,33.7243423461914,1,1,3,20.0040969848633,0,20.005446434021,,,,,,,,,,,,,,,,,,,,,,,,,,,,,,,,,
,3883216929.85445,20.0031766891479,10499.5361328125,-0.000167305640145812,2.2937764915854E-8,1,4,13.4005146026611,4.99686337228148,30.1099997013807,-0.207764748954798,-0.0311187020975789,1,-3.02249434825818E-8,,,,,,,,,,,,,,,,,,,,,20.0022563934326,20.0040969848633,10499.5361328125,10499.5361328125,53.4665172294672,5.64264908258569,4.90707111358643,54,2,0,0,1,0.298233032226562,33.7243423461914,1,1,3,20.0022563934326,0,20.0031766891479,,,,,,,,,,,,,,,,,,,,,,,,,,,,,,,,,
,3883216946.64177,20.0133762359619,9999.7451171875,-0.000159295599854598,2.56330355541903E-8,1,4,13.4005146026611,4.99691164680779,30.1099997013807,-0.197815950961345,-0.029658557933443,1,-5.23836535498935E-8,,,,,,,,,,,,,,,,,,,,,20.0109920501709,20.0157604217529,9999.7451171875,9999.7451171875,53.3883543775441,5.64307993845393,4.89742183685303,53,1,68,0,0,0.297927856445313,34.2131004333496,1,1,3,20.0109920501709,0,20.0133762359619,,,,,,,,,,,,,,,,,,,,,,,,,,,,,,,,,
,3883216950.49449,20.0079040527344,9999.7451171875,-0.000159305641854488,1.52675340367864E-8,1,4,13.4005146026611,4.99688581861693,30.1099997013807,-0.19783292358587,-0.0296205451777356,1,-2.04449614820291E-8,,,,,,,,,,,,,,,,,,,,,20.0048160552979,20.0109920501709,9999.7451171875,9999.7451171875,53.5587493947364,5.64264047909718,4.903244972229,54,2,0,0,1,0.297927856445313,33.2355842590332,1,1,3,20.0048160552979,0,20.0079040527344,,,,,,,,,,,,,,,,,,,,,,,,,,,,,,,,,
,3883216966.31473,20.0113248825073,9499.55078125,-0.000151275005556536,2.47832839464362E-8,1,4,13.4005146026611,4.99687438895374,30.1099997013807,-0.187858555258496,-0.0281336981201248,1,-2.45855333953235E-8,,,,,,,,,,,,,,,,,,,,,20.0088119506836,20.0138378143311,9499.55078125,9499.55078125,53.5333464678614,5.64264862033354,4.90756893157959,54,1,0,0,1,0.2978515625,33.7243423461914,1,1,3,20.0088119506836,0,20.0113248825073,,,,,,,,,,,,,,,,,,,,,,,,,,,,,,,,,
,3883216970.35328,20.006854057312,9499.55078125,-0.000151300468111476,2.63367301821375E-8,1,4,13.4005146026611,4.9968556340876,30.1099997013807,-0.187893547437273,-0.0281091445857536,1,-1.12394475864756E-9,,,,,,,,,,,,,,,,,,,,,20.0048961639404,20.0088119506836,9499.55078125,9499.55078125,53.4641723439095,5.64286319543824,4.90518999099731,53,2,68,0,0,0.29815673828125,33.7243423461914,1,1,3,20.0048961639404,0,20.006854057312,,,,,,,,,,,,,,,,,,,,,,,,,,,,,,,,,
,3883216988.15019,20.0041055679321,8999.494140625,-0.000143267661641642,1.78933394784085E-8,1,4,13.4005146026611,4.99684494036284,30.1099997013807,-0.177908528579711,-0.0266761198337245,1,-4.89109778216765E-8,,,,,,,,,,,,,,,,,,,,,20.0030536651611,20.0051574707031,8999.494140625,8999.494140625,53.6060379201499,5.64212260243626,4.91087818145752,54,1,0,0,1,0.2978515625,34.2131004333496,1,1,3,20.0030536651611,0,20.0041055679321,,,,,,,,,,,,,,,,,,,,,,,,,,,,,,,,,
,3883216992.01327,20.0024757385254,8999.494140625,-0.000143292779079433,2.11272877800351E-8,1,4,13.4005146026611,4.99685851668973,30.1099997013807,-0.177947918517815,-0.0266306127669762,1,-8.42754515203399E-9,,,,,,,,,,,,,,,,,,,,,20.0019226074219,20.0030288696289,8999.494140625,8999.494140625,53.4950466704191,5.64191870336671,4.90034866333008,54,2,0,0,1,0.298309326171875,33.7243423461914,1,1,3,20.0019226074219,0,20.0024757385254,,,,,,,,,,,,,,,,,,,,,,,,,,,,,,,,,
,3883217008.7693,20.0186147689819,8499.615234375,-0.000135276867788709,2.03762900060184E-8,1,4,13.4005146026611,4.99685815248849,30.1099997013807,-0.167984939163659,-0.0251971252253265,1,-5.3253138889455E-8,,,,,,,,,,,,,,,,,,,,,20.0157337188721,20.0214958190918,8499.615234375,8499.615234375,53.4481489592653,5.64265499611213,4.90594339370728,54,1,0,0,1,0.2984619140625,33.7243423461914,1,1,3,20.0157337188721,0,20.0186147689819,,,,,,,,,,,,,,,,,,,,,,,,,,,,,,,,,
,3883217012.64109,20.0125036239624,8499.615234375,-0.000135287764376192,1.70719136864105E-8,1,4,13.4005146026611,4.99687774545736,30.1099997013807,-0.168010268015052,-0.0251265946039259,1,5.28238295418414E-9,,,,,,,,,,,,,,,,,,,,,20.0092735290527,20.0157337188721,8499.615234375,8499.615234375,53.5192771545153,5.64253768110118,4.90322685241699,54,2,0,0,1,0.298538208007812,33.7243423461914,1,1,3,20.0092735290527,0,20.0125036239624,,,,,,,,,,,,,,,,,,,,,,,,,,,,,,,,,
,3883217029.36877,20.0121574401855,7999.7099609375,-0.000127281528757952,1.88635073077814E-8,1,4,13.4005146026611,4.99685516157045,30.1099997013807,-0.158057525313257,-0.0236997125443581,1,-4.353970618287E-8,,,,,,,,,,,,,,,,,,,,,20.0102519989014,20.0140628814697,7999.7099609375,7999.7099609375,53.3797564638326,5.64258592961725,4.90255403518677,54,1,0,0,1,0.2972412109375,33.7243423461914,1,1,3,20.0102519989014,0,20.0121574401855,,,,,,,,,,,,,,,,,,,,,,,,,,,,,,,,,
,3883217033.23831,20.008111000061,7999.7099609375,-0.000127300999584346,1.99179200133605E-8,1,4,13.4005146026611,4.99681031203925,30.1099997013807,-0.158086974963254,-0.0236545248022847,1,-4.47917863003401E-9,,,,,,,,,,,,,,,,,,,,,20.0059700012207,20.0102519989014,7999.7099609375,7999.7099609375,53.5169322689576,5.64233009136171,4.90770578384399,53,2,68,0,0,0.298919677734375,34.2131004333496,1,1,3,20.0059700012207,0,20.008111000061,,,,,,,,,,,,,,,,,,,,,,,,,,,,,,,,,
,3883217049.95618,20.0015687942505,7499.62939453125,-0.000119270040093958,1.35991107051334E-8,1,4,13.4005146026611,4.99683273833888,30.1099997013807,-0.148106696668219,-0.0222163571327864,1,-4.76571062641537E-8,,,,,,,,,,,,,,,,,,,,,20.0012626647949,20.0018749237061,7499.62939453125,7499.62939453125,53.3258240960056,5.64248599557382,4.91502141952515,53,1,68,0,0,0.298004150390625,33.7243423461914,1,1,3,20.0012626647949,0,20.0015687942505,,,,,,,,,,,,,,,,,,,,,,,,,,,,,,,,,
,3883217053.78924,20.0010442733765,7499.62939453125,-0.000119301186162363,1.33709023509151E-8,1,4,13.4005146026611,4.99678692235688,30.1099997013807,-0.148150244319714,-0.0221765963056217,1,-1.12097114610744E-8,,,,,,,,,,,,,,,,,,,,,20.000825881958,20.0012626647949,7499.62939453125,7499.62939453125,53.4387694170345,5.6422848194153,4.90941619873047,54,2,0,0,1,0.297775268554687,33.7243423461914,1,1,3,20.000825881958,0,20.0010442733765,,,,,,,,,,,,,,,,,,,,,,,,,,,,,,,,,
,3883217070.73275,20.0146312713623,6999.49755859375,-0.00011127717338412,1.74795731470444E-8,1,4,13.4005146026611,4.99679145695899,30.1099997013807,-0.138179192633259,-0.0207309940679414,1,-4.74453124744297E-8,,,,,,,,,,,,,,,,,,,,,20.0132312774658,20.0160312652588,6999.49755859375,6999.49755859375,53.437206159996,5.64236621731216,4.91065406799316,53,1,68,0,0,0.298385620117188,34.2131004333496,1,1,3,20.0132312774658,0,20.0146312713623,,,,,,,,,,,,,,,,,,,,,,,,,,,,,,,,,
,3883217074.74157,20.0107469558716,6999.49755859375,-0.000111289571100524,1.36611053416868E-8,1,4,13.4005146026611,4.99678711252461,30.1099997013807,-0.138201567912093,-0.0206854920079728,1,-8.97001349218879E-9,,,,,,,,,,,,,,,,,,,,,20.0082626342773,20.0132312774658,6999.49755859375,6999.49755859375,53.5102884265441,5.64219566527019,4.91827821731567,54,2,0,0,1,0.297622680664063,33.7243423461914,1,1,3,20.0082626342773,0,20.0107469558716,,,,,,,,,,,,,,,,,,,,,,,,,,,,,,,,,
,3883217091.47143,20.0152454376221,6499.60546875,-0.000103281545244722,1.39072534461164E-8,1,4,13.4005146026611,4.99678058452184,30.1099997013807,-0.128250248831269,-0.0192408580215257,1,-4.36433815346617E-8,,,,,,,,,,,,,,,,,,,,,20.0136051177979,20.0168857574463,6499.60546875,6499.60546875,53.5501514810249,5.64260586068953,4.90666675567627,52,1,68,0,0,0.297927856445313,33.7243423461914,1,1,3,20.0136051177979,0,20.0152454376221,,,,,,,,,,,,,,,,,,,,,,,,,,,,,,,,,
,3883217095.33568,20.0118360519409,6499.60546875,-0.000103289172118429,1.87806355216137E-8,1,4,13.4005146026611,4.99678965293503,30.1099997013807,-0.128265639195125,-0.0192049349691383,1,-1.35356897512234E-8,,,,,,,,,,,,,,,,,,,,,20.010066986084,20.0136051177979,6499.60546875,6499.60546875,53.4841038711499,5.64249050880939,4.91474199295044,54,2,0,0,1,0.297698974609375,33.2355842590332,1,1,3,20.009916305542,0,20.0118360519409,,,,,,,,,,,,,,,,,,,,,,,,,,,,,,,,,
,3883217111.35735,20.0179319381714,5999.5244140625,-9.52827855305822E-5,1.38186318396737E-8,1,4,13.4005146026611,4.99680014743694,30.1099997013807,-0.118319332246694,-0.017744642043988,1,-3.52847854505717E-8,,,,,,,,,,,,,,,,,,,,,20.0167140960693,20.0191497802734,5999.5244140625,5999.5244140625,53.5481974097268,5.64220699676032,4.91879177093506,53,1,68,0,0,0.297622680664063,33.7243423461914,1,1,3,20.0167140960693,0,20.0179319381714,,,,,,,,,,,,,,,,,,,,,,,,,,,,,,,,,
,3883217115.39036,20.0151453018188,5999.5244140625,-9.53025621267217E-5,1.18690727135818E-8,1,4,13.4005146026611,4.99674101323079,30.1099997013807,-0.118346966768683,-0.0177143559167626,1,-8.1745824252009E-9,,,,,,,,,,,,,,,,,,,,,20.0135765075684,20.0167140960693,5999.5244140625,5999.5244140625,53.5091159837653,5.64229527700041,4.9136528968811,54,2,0,0,1,0.298690795898438,34.2131004333496,1,1,3,20.0135765075684,0,20.0151453018188,,,,,,,,,,,,,,,,,,,,,,,,,,,,,,,,,
,3883217132.40687,20.014461517334,5499.58203125,-8.72671923223782E-5,1.30122392389985E-8,1,4,13.4005146026611,4.99682569146116,30.1099997013807,-0.108368499624975,-0.0162391875637248,1,-2.19963392936641E-8,,,,,,,,,,,,,,,,,,,,,20.0135746002197,20.0153484344482,5499.58203125,5499.58203125,53.3606065651114,5.64272473710461,4.91656970977783,54,1,0,0,1,0.298004150390625,35.190616607666,1,1,3,20.0135746002197,0,20.014461517334,,,,,,,,,,,,,,,,,,,,,,,,,,,,,,,,,
,3883217136.44103,20.0123729705811,5499.58203125,-8.73045032280786E-5,1.28213416425095E-8,1,4,13.4005146026611,4.99678494458916,30.1099997013807,-0.108415552515878,-0.0162328559489991,1,-1.14655686591113E-8,,,,,,,,,,,,,,,,,,,,,20.0112915039062,20.0134544372559,5499.58203125,5499.58203125,53.5087251695057,5.64205526976605,4.91976022720337,52,2,68,0,0,0.297470092773438,33.7243423461914,1,1,3,20.0112915039062,0,20.0123729705811,,,,,,,,,,,,,,,,,,,,,,,,,,,,,,,,,
,3883217154.24066,20.0301723480225,4999.513671875,-7.92685075389544E-5,1.23412745823989E-8,1,4,13.4005146026611,4.99678583913975,30.1099997013807,-0.0984329757010049,-0.0147616021675712,1,-2.88551462095402E-8,,,,,,,,,,,,,,,,,,,,,20.0297317504883,20.0306129455566,4999.513671875,4999.513671875,53.4958282989384,5.64249276905742,4.91441440582275,54,1,0,0,1,0.29754638671875,34.7018585205078,1,1,3,20.0297317504883,0,20.0301723480225,,,,,,,,,,,,,,,,,,,,,,,,,,,,,,,,,
,3883217158.09226,20.028341293335,4999.513671875,-7.92840257480631E-5,1.37939681689191E-8,1,4,13.4005146026611,4.99674410622996,30.1099997013807,-0.0984548175642754,-0.0147394304394256,1,-8.81850530483399E-9,,,,,,,,,,,,,,,,,,,,,20.0270595550537,20.0296230316162,4999.513671875,4999.513671875,53.4008604338518,5.64220935810589,4.91561937332153,53,2,68,0,0,0.298004150390625,33.7243423461914,1,1,3,20.0270595550537,0,20.028341293335,,,,,,,,,,,,,,,,,,,,,,,,,,,,,,,,,
,3883217175.01516,20.0520305633545,4499.6083984375,-7.12859106449093E-5,1.1883164729033E-8,1,4,13.4005146026611,4.99676316016399,30.1099997013807,-0.0885177512247776,-0.0132892861548373,1,-3.74725061020264E-8,,,,,,,,,,,,,,,,,,,,,20.0511016845703,20.0529594421387,4499.6083984375,4499.6083984375,53.491138527823,5.64202946833714,4.92118453979492,52,1,68,0,0,0.298080444335937,33.7243423461914,1,1,3,20.0529594421387,0,20.0520305633545,,,,,,,,,,,,,,,,,,,,,,,,,,,,,,,,,
,3883217179.05425,20.052303314209,4499.6083984375,-7.13043841356159E-5,1.20268011037194E-8,1,4,13.4005146026611,4.99679051261045,30.1099997013807,-0.0885489198457757,-0.013242355847724,1,3.16411329406445E-9,,,,,,,,,,,,,,,,,,,,,20.0516471862793,20.0529594421387,4499.6083984375,4499.6083984375,53.421964403871,5.642923926737,4.92330121994019,54,2,0,0,1,0.29815673828125,34.2131004333496,1,1,3,20.0516471862793,0,20.052303314209,,,,,,,,,,,,,,,,,,,,,,,,,,,,,,,,,
,3883217195.72849,20.0770349502563,3999.54028320313,-6.32795119095255E-5,1.2210714137584E-8,1,4,13.4005146026611,4.99672206502274,30.1099997013807,-0.0785745227571659,-0.0118002527673415,1,-3.62224325234427E-8,,,,,,,,,,,,,,,,,,,,,20.0762023925781,20.0778675079346,3999.54028320313,3999.54028320313,53.3238700247076,5.64254304156056,4.91365146636963,53,1,68,0,0,0.297317504882812,33.7243423461914,1,1,3,20.0778675079346,0,20.0770349502563,,,,,,,,,,,,,,,,,,,,,,,,,,,,,,,,,
,3883217199.57843,20.0778255462646,3999.54028320313,-6.33023983314621E-5,1.02610089362674E-8,1,4,13.4005146026611,4.9967609112792,30.1099997013807,-0.0786076078197337,-0.0117791720808589,1,-1.57197599608808E-8,,,,,,,,,,,,,,,,,,,,,20.0777740478516,20.0778770446777,3999.54028320313,3999.54028320313,53.4790232857749,5.64232458797601,4.92417097091675,54,2,0,0,1,0.2978515625,34.2131004333496,1,1,3,20.0777740478516,0,20.0778255462646,,,,,,,,,,,,,,,,,,,,,,,,,,,,,,,,,
,3883217216.5437,20.0768203735352,3499.53491210937,-5.52816755644817E-5,1.12042118757556E-8,1,4,13.4005146026611,4.99675435190002,30.1099997013807,-0.0686430795154923,-0.0103163190465776,1,-3.75997105420605E-8,,,,,,,,,,,,,,,,,,,,,20.0765514373779,20.0770893096924,3499.53491210937,3499.53491210937,53.4090675333037,5.64295356417758,4.91888523101807,54,1,0,0,1,0.298233032226562,33.7243423461914,1,1,3,20.0770893096924,0,20.0768203735352,,,,,,,,,,,,,,,,,,,,,,,,,,,,,,,,,
,3883217220.55633,20.0776453018188,3499.53491210937,-5.52962675436653E-5,1.14591797065478E-8,1,4,13.4005146026611,4.99669644334157,30.1099997013807,-0.0686665969741982,-0.0102753377805705,1,-2.55022827387546E-9,,,,,,,,,,,,,,,,,,,,,20.0770893096924,20.0782012939453,3499.53491210937,3499.53491210937,53.3649055219672,5.64251678160687,4.92999315261841,53,2,68,0,0,0.2984619140625,33.7243423461914,1,1,3,20.0782012939453,0,20.0776453018188,,,,,,,,,,,,,,,,,,,,,,,,,,,,,,,,,