File: SQUID/Reference/STO/A6/STO_MH_2K_FC_1T.csv
Comment,Time Stamp (sec),Temperature (K),Magnetic Field (Oe),Moment (emu),M. Std. Err. (emu),Transport Action,Averaging Time (sec),Frequency (Hz),Peak Amplitude (mm),Center Position (mm),Lockin Signal' (V),Lockin Signal (V),Range,M. Quad. Signal (emu),AC Moment (emu),AC M. Std Err. (emu),AC Phase (deg),AC Phase Std. Err. (deg),AC Susceptibility (emu/Oe),AC Suscept. Std Err. (emu/Oe),AC X' (emu/Oe),AC X' Std Err. (emu/Oe),AC X'' (emu/Oe),AC X'' Std Err. (emu/Oe),AC Drive (Oe),AC Frequency (Hz),AC Averaging Time (sec),AC Cycles,AC Range,AC Measure Type,AC Signal' (V),AC Signal'' (V),AC Trim Coil Ratio,AC Trim Coil Phase,Min. Temperature (K),Max. Temperature (K),Min. Field (Oe),Max. Field (Oe),Mass (grams),Motor Lag (deg),Pressure (Torr),Measure Count,Measurement Number,SQUID Status (code),Motor Status (code),Measure Status (code),Motor Current (amps),Motor Temp. (C),Temp. Status (code),Field Status (code),Chamber Status (code),Chamber Temp (K),Redirection State,Average Temp (K),Rotation Angle (deg),Rotator state,DC Moment Fixed Ctr (emu),DC Moment Err Fixed Ctr (emu),DC Moment Free Ctr (emu),DC Moment Err Free Ctr (emu),DC Fixed Fit,DC Free Fit,DC Calculated Center (mm),DC Calculated Center Err (mm),DC Scan Length (mm),DC Scan Time (s),DC Number of Points,DC Squid Drift,DC Min V (V),DC Max V (V),DC Scans per Measure,Map 01,Map 02,Map 03,Map 04,Map 05,Map 06,Map 07,Map 08,Map 09,Map 10,Map 11,Map 12,Map 13,Map 14,Map 15,Map 16
,3877765548.24992,2.00000256299973,70000.3046875,-4.38183043065364E-4,2.01867800750808E-7,1,4,13.4005146026611,5.00875850054841,32.7799990773201,-0.545943216873977,-0.0818900144361041,1,-1.72913463812736E-7,,,,,,,,,,,,,,,,,,,,,1.9997855424881,2.00021958351135,70000.3046875,70000.3046875,55.1442828459962,5.64342660102098,2.15103054046631,54,1,0,0,1,0.304107666015625,33.2355842590332,1,1,3,2.0003023147583,0,2.00000256299973,,,,,,,,,,,,,,,,,,,,,,,,,,,,,,,,,
,3877765722.17249,2.00006049871445,50000.23046875,-3.08015834571621E-4,5.89877169895516E-8,1,4,13.4005146026611,5.00838011987722,32.7799990773201,-0.383711397057054,-0.0576426134349058,1,-1.89795467786831E-7,,,,,,,,,,,,,,,,,,,,,1.99978530406952,2.00033569335938,50000.23046875,50000.23046875,54.6557650214769,5.64266792497034,2.14347839355469,54,1,0,0,1,0.3045654296875,34.2131004333496,1,1,3,2.00033569335938,0,2.00006049871445,,,,,,,,,,,,,,,,,,,,,,,,,,,,,,,,,
,3877765891.27447,2.00051152706146,29999.548828125,-1.79206394024716E-4,4.7701920816821E-8,1,4,13.4005146026611,5.00837535826729,32.7799990773201,-0.223262158929777,-0.0334319992796481,1,-2.61867370372536E-8,,,,,,,,,,,,,,,,,,,,,2.00021266937256,2.00081038475037,29999.548828125,29999.548828125,54.1062801724577,5.64206108393985,2.14499545097351,52,1,68,0,0,0.31219482421875,34.2131004333496,1,1,3,2.00081038475037,0,2.00051152706146,,,,,,,,,,,,,,,,,,,,,,,,,,,,,,,,,
,3877766080.39654,1.99946111440659,9999.8076171875,-5.47478595691084E-5,1.93301049164605E-8,1,4,13.4005146026611,5.00824010738901,32.7799990773201,-0.0681961235920109,-0.0102684504708143,1,-5.23910529177384E-8,,,,,,,,,,,,,,,,,,,,,1.99902737140656,1.99989485740662,9999.8076171875,9999.8076171875,53.7021782280153,5.64110287120388,2.14224195480347,53,1,68,0,0,0.29754638671875,33.7243423461914,1,1,3,1.99997401237488,0,1.99946111440659,,,,,,,,,,,,,,,,,,,,,,,,,,,,,,,,,
,3877766158.16941,1.99976801872253,8499.52734375,-4.60382094782407E-5,1.6858536803076E-8,1,4,13.4005146026611,5.00819143695636,32.7799990773201,-0.0573472101440748,-0.00862838313923784,1,-3.89372963599365E-8,,,,,,,,,,,,,,,,,,,,,1.99976253509521,1.99977350234985,8499.52734375,8499.52734375,53.5560136949191,5.64179238450844,2.1484272480011,54,1,0,0,1,0.304641723632812,34.7018585205078,1,1,3,1.99977350234985,0,1.99976801872253,,,,,,,,,,,,,,,,,,,,,,,,,,,,,,,,,
,3877766222.75413,2.00054693222046,6499.56787109375,-3.46358236887839E-5,1.40087290195421E-8,1,4,13.4005146026611,5.0082278846402,32.7799990773201,-0.0431435501078953,-0.0064967042251193,1,-3.35204906635752E-8,,,,,,,,,,,,,,,,,,,,,2.00049185752869,2.00060200691223,6499.56787109375,6499.56787109375,53.5638299801114,5.64168506946778,2.14696669578552,54,1,0,0,1,0.304946899414063,34.7018585205078,1,1,3,2.00060200691223,0,2.00054693222046,,,,,,,,,,,,,,,,,,,,,,,,,,,,,,,,,
,3877766291.55548,1.99972015619278,4499.533203125,-2.35671090087456E-5,1.21076065838316E-8,1,4,13.4005146026611,5.0080198102083,32.7799990773201,-0.0293516535881897,-0.0044378328595157,1,-3.69076069473474E-8,,,,,,,,,,,,,,,,,,,,,1.99954926967621,1.99989104270935,4499.533203125,4499.533203125,53.5689105654864,5.6418931649658,2.14077353477478,54,1,0,0,1,0.305557250976562,34.7018585205078,1,1,3,1.99989104270935,0,1.99972015619278,,,,,,,,,,,,,,,,,,,,,,,,,,,,,,,,,
,3877766377.36246,1.99943274259567,2999.78125,-1.54690273220877E-5,8.57560390360701E-9,1,4,13.4005146026611,5.00797808663717,32.7799990773201,-0.019270326339392,-0.00288178141008462,1,7.38640309290473E-10,,,,,,,,,,,,,,,,,,,,,1.99942862987518,1.99943685531616,2999.78125,2999.78125,53.5302199537845,5.64177791815214,2.13815569877625,54,1,0,0,1,0.298538208007812,34.7018585205078,1,1,3,1.99991607666016,0,1.99943274259567,,,,,,,,,,,,,,,,,,,,,,,,,,,,,,,,,
,3877766434.90019,1.99936908483505,2799.5146484375,-1.44735893181956E-5,5.1021558472462E-8,1,4,13.4005146026611,5.0079984642194,32.7799990773201,-0.0180717805211352,-0.00241957201309158,1,2.22874087563335E-7,,,,,,,,,,,,,,,,,,,,,1.99896574020386,1.99977242946625,2799.5146484375,2799.5146484375,53.6036930345922,5.64125225850939,2.13519191741943,53,1,68,0,0,0.305404663085937,34.7018585205078,1,1,3,1.99977242946625,0,1.99936908483505,,,,,,,,,,,,,,,,,,,,,,,,,,,,,,,,,
,3877766494.17473,2.00002241134644,2599.62573242187,-1.34300116741269E-5,1.72988014227978E-8,1,4,13.4005146026611,5.00783851858622,32.7799990773201,-0.0167655820285482,-0.002261291073771,1,1.93738603065248E-7,,,,,,,,,,,,,,,,,,,,,2.00000262260437,2.0000422000885,2599.62573242187,2599.62573242187,53.4712070005826,5.642539386935,2.13703489303589,52,1,68,0,0,0.299148559570313,35.190616607666,1,1,3,2.00000262260437,0,2.00002241134644,,,,,,,,,,,,,,,,,,,,,,,,,,,,,,,,,
,3877766551.40073,2.00025236606598,2399.71142578125,-1.24228452795631E-5,1.91050480604578E-8,1,4,13.4005146026611,5.00763890526142,32.7799990773201,-0.0155094384920775,-0.00207799695672677,1,1.90123737884559E-7,,,,,,,,,,,,,,,,,,,,,2.00022625923157,2.00027847290039,2399.71142578125,2399.71142578125,53.5892329069864,5.64311693902945,2.13356685638428,54,1,0,0,1,0.30548095703125,35.190616607666,1,1,3,2.00022625923157,0,2.00025236606598,,,,,,,,,,,,,,,,,,,,,,,,,,,,,,,,,
,3877766608.49444,1.99977540969849,2199.646484375,-1.13421871779934E-5,2.09508504085638E-8,1,4,13.4005146026611,5.00766686736194,32.7799990773201,-0.0141673530187636,-0.00185069796244722,1,2.10955704985547E-7,,,,,,,,,,,,,,,,,,,,,1.9995174407959,2.00003337860107,2199.646484375,2199.646484375,53.5048170269095,5.64313672345724,2.12957215309143,54,1,0,0,1,0.298690795898438,34.7018585205078,1,1,3,2.00003337860107,0,1.99977540969849,,,,,,,,,,,,,,,,,,,,,,,,,,,,,,,,,
,3877766666.79582,1.99965840578079,1999.7197265625,-1.01210638186504E-5,2.70704457894668E-7,1,4,13.4005146026611,5.00781049392103,32.7799990773201,-0.0126086810490635,-0.00187807596115469,1,6.36418396256991E-9,,,,,,,,,,,,,,,,,,,,,1.99929916858673,2.00001764297485,1999.7197265625,1999.7197265625,53.493092599121,5.6421239249993,2.12448573112488,54,1,0,0,1,0.305023193359375,34.7018585205078,1,1,3,2.00001764297485,0,1.99965840578079,,,,,,,,,,,,,,,,,,,,,,,,,,,,,,,,,
,3877766724.96576,1.99975836277008,1799.76794433594,-9.24529797830406E-6,1.86860671490087E-8,1,4,13.4005146026611,5.00786487741882,32.7799990773201,-0.0115527062467989,-0.00148251405871544,1,1.92922849841023E-7,,,,,,,,,,,,,,,,,,,,,1.99953627586365,1.99998044967651,1799.76794433594,1799.76794433594,53.4680804865057,5.64220704601803,2.12872433662415,54,1,0,0,1,0.307083129882812,34.7018585205078,1,1,3,1.99953627586365,0,1.99975836277008,,,,,,,,,,,,,,,,,,,,,,,,,,,,,,,,,
,3877766782.84645,1.99988436698914,1599.76574707031,-8.24240369491779E-6,2.08151372048251E-8,1,4,13.4005146026611,5.007814776128,32.7799990773201,-0.010299617593197,-0.00132001757342633,1,1.7332841414265E-7,,,,,,,,,,,,,,,,,,,,,1.99970173835754,2.00006699562073,1599.76574707031,1599.76574707031,53.5814166217941,5.64200944107738,2.12431406974792,54,1,0,0,1,0.298004150390625,34.7018585205078,1,1,3,2.00006699562073,0,1.99988436698914,,,,,,,,,,,,,,,,,,,,,,,,,,,,,,,,,
,3877766840.65016,1.99939113855362,1399.763671875,-7.19666316025011E-6,2.06913486343422E-8,1,4,13.4005146026611,5.00801536988867,32.7799990773201,-0.00899810240329905,-0.00112100666060133,1,1.76704541922259E-7,,,,,,,,,,,,,,,,,,,,,1.99919021129608,1.99959206581116,1399.763671875,1399.763671875,53.5970491921788,5.64204482603538,2.11936140060425,54,1,0,0,1,0.304183959960937,34.7018585205078,1,1,3,1.99959206581116,0,1.99939113855362,,,,,,,,,,,,,,,,,,,,,,,,,,,,,,,,,
,3877766898.52582,1.99997961521149,1199.64819335938,-6.13082114673343E-6,2.17651106279351E-8,1,4,13.4005146026611,5.00814227823444,32.7799990773201,-0.0076794987800903,-8.63007185715681E-4,1,2.24391039372013E-7,,,,,,,,,,,,,,,,,,,,,1.99973344802856,2.00022578239441,1199.64819335938,1199.64819335938,53.5251393684095,5.64087149387915,2.11709308624268,54,1,0,0,1,0.304336547851562,34.7018585205078,1,1,3,1.99973344802856,0,1.99997961521149,,,,,,,,,,,,,,,,,,,,,,,,,,,,,,,,,
,3877766955.14456,1.99966597557068,999.822143554687,-5.11467100368087E-6,1.89918293668176E-8,1,4,13.4005146026611,5.0082817104113,32.7799990773201,-0.00641284573873669,-6.80338039416721E-4,1,2.19032318320726E-7,,,,,,,,,,,,,,,,,,,,,1.99920558929443,2.00012636184692,999.822143554687,999.822143554687,53.5263118111883,5.64064918875618,2.12123823165894,54,1,0,0,1,0.304489135742188,34.7018585205078,1,1,3,2.00012636184692,0,1.99966597557068,,,,,,,,,,,,,,,,,,,,,,,,,,,,,,,,,
,3877767012.56321,2.00021398067474,799.744445800781,-4.06645848204251E-6,2.25292039864105E-8,1,4,13.4005146026611,5.00821768140646,32.7799990773201,-0.00511016261004877,-4.62877482249465E-4,1,2.36769895223348E-7,,,,,,,,,,,,,,,,,,,,,2.0001220703125,2.00030589103699,799.744445800781,799.744445800781,53.5399903102749,5.64017028102214,2.1139075756073,53,1,68,0,0,0.3057861328125,34.7018585205078,1,1,3,2.00030589103699,0,2.00021398067474,,,,,,,,,,,,,,,,,,,,,,,,,,,,,,,,,
,3877767103.26562,1.9995698928833,600.019165039063,-3.09237794187719E-6,2.62267386565432E-8,1,4,13.4005146026611,5.00744053950924,32.7799990773201,-0.00390156006380473,-2.42760936767782E-4,1,2.67696580744986E-7,,,,,,,,,,,,,,,,,,,,,1.99938786029816,1.99975192546844,600.019165039063,600.019165039063,53.6103368770057,5.6441163160519,2.10938429832458,52,1,68,0,0,0.298919677734375,34.2131004333496,1,1,3,1.99975192546844,0,1.9995698928833,,,,,,,,,,,,,,,,,,,,,,,,,,,,,,,,,
,3877767192.93693,1.99970602989197,399.966613769531,-2.00966270460193E-6,2.87633035317072E-8,1,4,13.4005146026611,5.00770242251097,32.7799990773201,-0.00255559681334583,-2.48790749921212E-5,1,2.80660100682877E-7,,,,,,,,,,,,,,,,,,,,,1.99951720237732,1.99989485740662,399.966613769531,399.966613769531,53.6314408470249,5.64248216493024,2.1122715473175,52,1,68,0,0,0.306015014648438,34.7018585205078,1,1,3,1.99951720237732,0,1.99970602989197,,,,,,,,,,,,,,,,,,,,,,,,,,,,,,,,,
,3877767284.45809,1.9999281167984,200.140670776367,-9.84887851189147E-7,5.48813817397249E-8,1,4,13.4005146026611,5.00727444989084,32.7799990773201,-0.00128541553551796,2.09261747294221E-4,1,3.15349755826461E-7,,,,,,,,,,,,,,,,,,,,,1.99960684776306,2.00024938583374,200.140670776367,200.140670776367,53.5376454247172,5.64480272940605,2.11124897003174,54,1,0,0,1,0.29937744140625,34.7018585205078,1,1,3,2.00024938583374,0,1.9999281167984,,,,,,,,,,,,,,,,,,,,,,,,,,,,,,,,,
,3877767356.98729,2.00031191110611,0.151059061288834,1.79187614276973E-7,2.62969607215624E-8,1,4,13.4005146026611,5.00749394032666,32.7799990773201,1.84036367720489E-4,2.95112071930287E-4,1,2.10126082617072E-7,,,,,,,,,,,,,,,,,,,,,1.99979746341705,2.00082635879517,0.151059061288834,0.151059061288834,53.5302199537845,5.64325342258973,2.11299514770508,52,1,68,0,0,0.299224853515625,34.7018585205078,1,1,3,2.00082635879517,0,2.00031191110611,,,,,,,,,,,,,,,,,,,,,,,,,,,,,,,,,
,3877767414.12118,2.00022387504578,-199.674896240234,1.36270253730624E-6,8.50825639999242E-8,1,4,13.4005146026611,5.00763756214087,32.7799990773201,0.00166879496635554,4.45099798964155E-4,1,1.53483224401332E-7,,,,,,,,,,,,,,,,,,,,,2.00020027160645,2.00024747848511,-199.674896240234,-199.674896240234,53.457528501496,5.64268397850873,2.10666251182556,54,1,0,0,1,0.29754638671875,34.7018585205078,1,1,3,2.00020027160645,0,2.00022387504578,,,,,,,,,,,,,,,,,,,,,,,,,,,,,,,,,
,3877767471.78816,2.00020372867584,-399.71484375,2.31110013017218E-6,1.4910483184691E-8,1,4,13.4005146026611,5.00770339862909,32.7799990773201,0.00284480208110196,6.57779880746395E-4,1,1.82342956896298E-7,,,,,,,,,,,,,,,,,,,,,2.0000376701355,2.00036978721619,-399.71484375,-399.71484375,53.4950466704191,5.64270617885825,2.10282802581787,54,1,0,0,1,0.298309326171875,34.7018585205078,1,1,3,2.00036978721619,0,2.00020372867584,,,,,,,,,,,,,,,,,,,,,,,,,,,,,,,,,
,3877767546.38474,1.9994381070137,-599.628967285156,3.32778296389331E-6,1.66975107861078E-8,1,4,13.4005146026611,5.0076321368789,32.7799990773201,0.00410272769174685,9.03396046766487E-4,1,2.27449900968735E-7,,,,,,,,,,,,,,,,,,,,,1.99900448322296,1.99987173080444,-599.628967285156,-599.628967285156,53.5587493947364,5.64255510781795,2.10621881484985,54,1,0,0,1,0.30059814453125,34.7018585205078,1,1,3,1.99900448322296,0,1.9994381070137,,,,,,,,,,,,,,,,,,,,,,,,,,,,,,,,,
,3877767604.39625,1.99994730949402,-799.706665039063,4.35293675343684E-6,1.66956387483497E-8,1,4,13.4005146026611,5.00781002150536,32.7799990773201,0.00538154898206978,0.00108367347197083,1,2.18780596846216E-7,,,,,,,,,,,,,,,,,,,,,1.99987268447876,2.00002193450928,-799.706665039063,-799.706665039063,53.5536688093614,5.6417362516231,2.10603833198547,54,1,0,0,1,0.299835205078125,34.7018585205078,1,1,3,1.99987268447876,0,1.99994730949402,,,,,,,,,,,,,,,,,,,,,,,,,,,,,,,,,
,3877767670.60138,2.00010669231415,-999.608093261719,5.40194183587535E-6,4.08878288132852E-8,1,4,13.4005146026611,5.00767062816638,32.7799990773201,0.00668744836664992,0.00128279853740591,10,2.21749905716216E-7,,,,,,,,,,,,,,,,,,,,,1.99977231025696,2.00044107437134,-999.608093261719,-999.608093261719,53.4950466704191,5.64212954496682,2.10435175895691,54,1,0,0,1,0.298004150390625,34.7018585205078,1,1,3,1.99977231025696,0,2.00010669231415,,,,,,,,,,,,,,,,,,,,,,,,,,,,,,,,,
,3877767753.53845,2.00023424625397,-1199.6103515625,6.46127310334502E-6,2.20625574185878E-8,1,4,13.4005146026611,5.00691198694734,32.7799990773201,0.00800406843301254,0.00148795871303656,1,2.28238721435773E-7,,,,,,,,,,,,,,,,,,,,,2.00006532669067,2.00040316581726,-1199.6103515625,-1199.6103515625,53.5759452221595,5.64488850411041,2.09094500541687,54,1,0,0,1,0.300140380859375,34.7018585205078,1,1,3,2.00040316581726,0,2.00023424625397,,,,,,,,,,,,,,,,,,,,,,,,,,,,,,,,,
,3877767828.74908,1.99988341331482,-1399.67553710938,7.5619726802677E-6,2.07478826857343E-8,1,4,13.4005146026611,5.00733719641841,32.7799990773201,0.00939591962726199,0.00155969082390028,1,1.21031830088111E-7,,,,,,,,,,,,,,,,,,,,,1.99949645996094,2.0002703666687,-1399.67553710938,-1399.67553710938,53.5110700550634,5.64385692749861,2.07944989204407,52,1,68,0,0,0.30670166015625,34.7018585205078,1,1,3,2.0002703666687,0,1.99988341331482,,,,,,,,,,,,,,,,,,,,,,,,,,,,,,,,,
,3877767888.42603,1.99993044137955,-1599.71545410156,8.52072052139026E-6,1.21226876997556E-7,1,4,13.4005146026611,5.00772660373023,32.7799990773201,0.0106002100372121,0.0016782535667097,1,7.26551448193173E-8,,,,,,,,,,,,,,,,,,,,,1.99980032444,2.00006055831909,-1599.71545410156,-1599.71545410156,53.4891844565249,5.64272997234223,2.08075904846191,54,1,0,0,1,0.305938720703125,34.7018585205078,1,1,3,1.99980032444,0,1.99993044137955,,,,,,,,,,,,,,,,,,,,,,,,,,,,,,,,,
,3877767950.33316,1.99996548891068,-1799.76794433594,9.67826222337585E-6,2.5300555408365E-8,1,4,13.4005146026611,5.00763069171399,32.7799990773201,0.0120285332365482,0.00198236824710568,1,1.43679998127958E-7,,,,,,,,,,,,,,,,,,,,,1.99959814548492,2.00033283233643,-1799.76794433594,-1799.76794433594,53.5485882239864,5.6421657787604,2.08281397819519,54,1,0,0,1,0.298919677734375,34.2131004333496,1,1,3,1.99959814548492,0,1.99996548891068,,,,,,,,,,,,,,,,,,,,,,,,,,,,,,,,,
,3877768009.19568,1.99992567300797,-1999.70715332031,1.0711376127392E-5,9.39121532755692E-9,1,4,13.4005146026611,5.00739003235322,32.7799990773201,0.0133178913040802,0.00215200437487457,1,1.25436171125515E-7,,,,,,,,,,,,,,,,,,,,,1.99932086467743,2.0005304813385,-1999.70715332031,-1999.70715332031,53.6150266481211,5.64370534784709,2.07868003845215,54,1,0,0,1,0.29937744140625,34.7018585205078,1,1,3,1.99932086467743,0,1.99992567300797,,,,,,,,,,,,,,,,,,,,,,,,,,,,,,,,,
,3877768066.84594,2.00050735473633,-2199.55834960938,1.17788209120645E-5,9.94304675972365E-9,1,4,13.4005146026611,5.00748962833654,32.7799990773201,0.0146495036518636,0.00233973966256515,1,1.16428882101639E-7,,,,,,,,,,,,,,,,,,,,,2.0004096031189,2.00060510635376,-2199.55834960938,-2199.55834960938,53.5544504378807,5.6431979897673,2.0781683921814,54,1,0,0,1,0.299072265625,34.2131004333496,1,1,3,2.00060510635376,0,2.00050735473633,,,,,,,,,,,,,,,,,,,,,,,,,,,,,,,,,
,3877768124.53016,1.99989193677902,-2399.48510742187,1.28809022827909E-5,5.56981281143858E-8,1,4,13.4005146026611,5.00746566780905,32.7799990773201,0.0160364572773912,0.00244910987930457,1,3.93856988699591E-8,,,,,,,,,,,,,,,,,,,,,1.99955403804779,2.00022983551025,-2399.48510742187,-2399.48510742187,53.4884028280057,5.64325317810788,2.07847428321838,54,1,0,0,1,0.298843383789063,34.2131004333496,1,1,3,2.00022983551025,0,1.99989193677902,,,,,,,,,,,,,,,,,,,,,,,,,,,,,,,,,
,3877768186.79223,1.9994335770607,-2599.51245117187,1.39071219186051E-5,9.23874479068998E-9,1,4,13.4005146026611,5.00748759325625,32.7799990773201,0.0173074201167943,0.00268947131074587,1,7.88326292627091E-8,,,,,,,,,,,,,,,,,,,,,1.9993439912796,1.9995231628418,-2599.51245117187,-2599.51245117187,53.4059410192268,5.64257390943751,2.0635621547699,54,1,0,0,1,0.298614501953125,34.2131004333496,1,1,3,1.9995231628418,0,1.9994335770607,,,,,,,,,,,,,,,,,,,,,,,,,,,,,,,,,
,3877768246.53328,2.00048160552979,-2799.5146484375,1.49607438854095E-5,6.45895936058108E-8,1,4,13.4005146026611,5.0076101429684,32.7799990773201,0.0186078150854509,0.00297003618047713,1,1.46388288216846E-7,,,,,,,,,,,,,,,,,,,,,2.00003290176392,2.00093030929565,-2799.5146484375,-2799.5146484375,53.4692529292845,5.64195017918265,2.06579542160034,54,1,0,0,1,0.303878784179687,33.7243423461914,1,1,3,2.00093030929565,0,2.00048160552979,,,,,,,,,,,,,,,,,,,,,,,,,,,,,,,,,
,3877768306.04644,2.00030672550201,-2999.6552734375,1.60444713119625E-5,1.67943262332675E-8,1,4,13.4005146026611,5.00770997476282,32.7799990773201,0.0199698495995554,0.00309459530403089,1,8.4199458967209E-8,,,,,,,,,,,,,,,,,,,,,2.00001311302185,2.00060033798218,-2999.6552734375,-2999.6552734375,53.4164930042364,5.64152553300057,2.05533885955811,54,1,0,0,1,0.2984619140625,34.7018585205078,1,1,3,2.00001311302185,0,2.00030672550201,,,,,,,,,,,,,,,,,,,,,,,,,,,,,,,,,
,3877768384.05592,2.00010496377945,-4499.59619140625,2.42434036711246E-5,5.11386122197697E-8,1,4,13.4005146026611,5.00777296715534,32.7799990773201,0.0301988301823987,0.00451830475361513,1,5.85564766255582E-10,,,,,,,,,,,,,,,,,,,,,1.99935376644135,2.00085616111755,-4499.59619140625,-4499.59619140625,53.4637815296499,5.64166232033132,2.05324482917786,54,1,0,0,1,0.298233032226562,34.2131004333496,1,1,3,2.00085616111755,0,2.00010496377945,,,,,,,,,,,,,,,,,,,,,,,,,,,,,,,,,
,3877768451.81212,1.99993348121643,-6499.857421875,3.52411574474265E-5,1.5801591558654E-8,1,4,13.4005146026611,5.0078291106421,32.7799990773201,0.0439051169139351,0.00652643289214876,1,-3.25877754338111E-8,,,,,,,,,,,,,,,,,,,,,1.99972867965698,2.00013828277588,-6499.857421875,-6499.857421875,53.5767268506787,5.64150532625058,2.05021595954895,54,1,0,0,1,0.3057861328125,34.2131004333496,1,1,3,1.99972867965698,0,1.99993348121643,,,,,,,,,,,,,,,,,,,,,,,,,,,,,,,,,
,3877768518.04358,2.00082778930664,-8499.6025390625,4.65772895780711E-5,3.07063195177789E-8,1,4,13.4005146026611,5.00786156940393,32.7799990773201,0.0580295312212494,0.00862058252378476,1,-4.73301849332657E-8,,,,,,,,,,,,,,,,,,,,,2.00080609321594,2.00084948539734,-8499.6025390625,-8499.6025390625,53.6396479464768,5.64176844570854,2.05256605148315,53,1,68,0,0,0.298690795898438,34.7018585205078,1,1,3,2.00084948539734,0,2.00082778930664,,,,,,,,,,,,,,,,,,,,,,,,,,,,,,,,,
,3877768599.25618,2.00035345554352,-9999.845703125,5.52407046399397E-5,1.99694231675978E-8,1,4,13.4005146026611,5.00780074786986,32.7799990773201,0.0688162031402037,0.0102619567730573,1,-2.55377767981984E-8,,,,,,,,,,,,,,,,,,,,,2.00024509429932,2.00046181678772,-9999.845703125,-9999.845703125,53.6302684042461,5.64182759548768,2.05420327186584,54,1,0,0,1,0.297775268554687,34.2131004333496,1,1,3,2.00024509429932,0,2.00035345554352,,,,,,,,,,,,,,,,,,,,,,,,,,,,,,,,,
,3877768755.71787,2.00018185377121,-29999.638671875,1.79525396344335E-4,5.27683855127939E-8,1,4,13.4005146026611,5.00741378759696,32.7799990773201,0.223617606297975,0.0333619170224271,1,-7.05979841930248E-8,,,,,,,,,,,,,,,,,,,,,1.99978411197662,2.0005795955658,-29999.638671875,-29999.638671875,54.0062317219961,5.64418117661518,2.04194521903992,54,1,0,0,1,0.307235717773438,34.7018585205078,1,1,3,1.99978411197662,0,2.00018185377121,,,,,,,,,,,,,,,,,,,,,,,,,,,,,,,,,
,3877768922.50169,1.99989807605743,-49999.703125,3.08517984678911E-4,8.78699740883829E-8,1,4,13.4005146026611,5.00765744641572,32.7799990773201,0.384352154117613,0.0571051595276075,10,-3.0746653931916E-7,,,,,,,,,,,,,,,,,,,,,1.99959826469421,2.00019788742065,-49999.703125,-49999.703125,54.6631904924096,5.64365483606798,2.03804659843445,54,1,0,0,1,0.298919677734375,34.7018585205078,1,1,3,2.00019788742065,0,1.99989807605743,,,,,,,,,,,,,,,,,,,,,,,,,,,,,,,,,
,3877769104.94299,2.00052440166473,-69999.609375,4.38024165211052E-4,2.10990446082168E-7,1,4,13.4005146026611,5.00765827414442,32.7799990773201,0.545602962600545,0.0816664375156179,1,3.73731466702775E-8,,,,,,,,,,,,,,,,,,,,,2.00032997131348,2.00071883201599,-69999.609375,-69999.609375,55.2720791088905,5.64497104090282,2.04279065132141,54,1,0,0,1,0.298614501953125,34.7018585205078,1,1,3,2.00032997131348,0,2.00052440166473,,,,,,,,,,,,,,,,,,,,,,,,,,,,,,,,,
,3877769264.60505,1.99947834014893,-49999.6171875,3.0803720972457E-4,9.46781018455243E-8,1,4,13.4005146026611,5.0078264085074,32.7799990773201,0.383697427737564,0.0575126997789873,1,8.9456639665911E-8,,,,,,,,,,,,,,,,,,,,,1.99901878833771,1.99993789196014,-49999.6171875,-49999.6171875,54.7351003161789,5.64380027229136,2.04240560531616,54,1,0,0,1,0.299301147460937,35.190616607666,1,1,3,1.99993789196014,0,1.99947834014893,,,,,,,,,,,,,,,,,,,,,,,,,,,,,,,,,
,3877769425.36178,1.99986410140991,-29999.5625,1.79260225514885E-4,4.48821809003599E-8,1,4,13.4005146026611,5.00804923992011,32.7799990773201,0.223312466231744,0.0334151520391531,1,7.05255285947294E-9,,,,,,,,,,,,,,,,,,,,,1.99944090843201,2.00028729438782,-29999.5625,-29999.5625,54.0351519772076,5.64197193974639,2.0385639667511,54,1,0,0,1,0.29815673828125,34.7018585205078,1,1,3,1.99944090843201,0,1.99986410140991,,,,,,,,,,,,,,,,,,,,,,,,,,,,,,,,,
,3877769583.80505,1.99970799684525,-10000.2109375,5.48461203174994E-5,2.35527290496884E-8,1,4,13.4005146026611,5.00799252110371,32.7799990773201,0.0683125610867975,0.0102944543908662,1,5.91358187116279E-8,,,,,,,,,,,,,,,,,,,,,1.9995790719986,1.99983692169189,-10000.2109375,-10000.2109375,53.5736003366018,5.6396757124457,2.03542828559875,53,1,68,0,0,0.30517578125,34.2131004333496,1,1,3,1.9995790719986,0,1.99970799684525,,,,,,,,,,,,,,,,,,,,,,,,,,,,,,,,,
,3877769660.60606,2.00011813640594,-8500.017578125,4.61281947398763E-5,2.07669620014064E-8,1,4,13.4005146026611,5.00808985206132,32.7799990773201,0.0574572621218338,0.00864773409742307,1,4.12057995914682E-8,,,,,,,,,,,,,,,,,,,,,1.99994802474976,2.00028824806213,-8500.017578125,-8500.017578125,53.5845431358711,5.63973842999232,2.03370332717896,54,1,0,0,1,0.298233032226562,34.7018585205078,1,1,3,2.00028824806213,0,2.00011813640594,,,,,,,,,,,,,,,,,,,,,,,,,,,,,,,,,
,3877769727.07236,2.0000205039978,-6499.9326171875,3.47587746069883E-5,1.78221218322525E-8,1,4,13.4005146026611,5.00806221492552,32.7799990773201,0.0432918054080136,0.00653881496833029,1,4.91722640409407E-8,,,,,,,,,,,,,,,,,,,,,1.99982500076294,2.00021600723267,-6499.9326171875,-6499.9326171875,53.5896237212461,5.63997830844918,2.03473019599915,54,1,0,0,1,0.312957763671875,35.6793746948242,1,1,3,1.99982500076294,0,2.0000205039978,,,,,,,,,,,,,,,,,,,,,,,,,,,,,,,,,
,3877769790.56911,1.99965262413025,-4500.13720703125,2.36695140430169E-5,1.33775058709583E-8,1,4,13.4005146026611,5.00803403774948,32.7799990773201,0.0294814823309479,0.0044426191433033,1,2.54163987348163E-8,,,,,,,,,,,,,,,,,,,,,1.99959087371826,1.99971437454224,-4500.13720703125,-4500.13720703125,53.5259209969287,5.63898982197297,2.03872108459473,54,1,0,0,1,0.298080444335937,34.7018585205078,1,1,3,1.99959087371826,0,1.99965262413025,,,,,,,,,,,,,,,,,,,,,,,,,,,,,,,,,
,3877769870.74924,1.99971735477448,-3000.20922851562,1.55596700270061E-5,9.61372394350359E-9,1,4,13.4005146026611,5.00809893800274,32.7799990773201,0.0193861951091282,0.00288340326234787,1,-1.30743695185827E-8,,,,,,,,,,,,,,,,,,,,,1.99948418140411,1.99995052814484,-3000.20922851562,-3000.20922851562,53.6271418901691,5.64018041770951,2.0379695892334,54,1,0,0,1,0.298843383789063,35.190616607666,1,1,3,1.99995052814484,0,1.99971735477448,,,,,,,,,,,,,,,,,,,,,,,,,,,,,,,,,
,3877769925.52399,2.00052815675735,-2800.1943359375,1.45910025109715E-5,1.70473208357326E-8,1,4,13.4005146026611,5.00806522634227,32.7799990773201,0.0182118195767334,0.00248539050848681,1,-1.87640455524352E-7,,,,,,,,,,,,,,,,,,,,,1.99986684322357,2.00118947029114,-2800.1943359375,-2800.1943359375,53.5517147380633,5.63977207619981,2.03675222396851,54,1,0,0,1,0.303192138671875,34.7018585205078,1,1,3,2.00118947029114,0,2.00052815675735,,,,,,,,,,,,,,,,,,,,,,,,,,,,,,,,,
,3877769981.9404,1.99969583749771,-2600.25512695313,1.35267202795356E-5,1.69292701015103E-8,1,4,13.4005146026611,5.0079035590565,32.7799990773201,0.016886806343061,0.00227634614646102,1,-1.96152949775421E-7,,,,,,,,,,,,,,,,,,,,,1.99968194961548,1.99970972537994,-2600.25512695313,-2600.25512695313,53.4254817322076,5.63947231047172,2.03311944007874,54,1,0,0,1,0.306167602539063,35.190616607666,1,1,3,1.99970972537994,0,1.99969583749771,,,,,,,,,,,,,,,,,,,,,,,,,,,,,,,,,
,3877770040.11386,1.99983882904053,-2400.2275390625,1.24835493541698E-5,2.0058759316026E-8,1,4,13.4005146026611,5.00801525218436,32.7799990773201,0.0155865112408933,0.0020907180525201,1,-1.89168253017384E-7,,,,,,,,,,,,,,,,,,,,,1.99961066246033,2.00006699562073,-2400.2275390625,-2400.2275390625,53.4344704601787,5.6393115215679,2.03216481208801,54,1,0,0,1,0.306396484375,35.190616607666,1,1,3,1.99961066246033,0,1.99983882904053,,,,,,,,,,,,,,,,,,,,,,,,,,,,,,,,,
,3877770097.25953,2.0004278421402,-2200.23803710938,1.14247711399575E-5,1.76542192071904E-8,1,4,13.4005146026611,5.00801555968272,32.7799990773201,0.0142633784020534,0.00192129518430927,1,-1.66783456035524E-7,,,,,,,,,,,,,,,,,,,,,2.00024175643921,2.00061392784119,-2200.23803710938,-2200.23803710938,53.5071619124672,5.63934714939816,2.03371071815491,52,1,68,0,0,0.298309326171875,35.190616607666,1,1,3,2.00024175643921,0,2.0004278421402,,,,,,,,,,,,,,,,,,,,,,,,,,,,,,,,,
,3877770153.77055,1.99985879659653,-2000.32397460938,1.03828473795563E-5,1.74776453078285E-8,1,4,13.4005146026611,5.00796357167906,32.7799990773201,0.0129669252793097,0.00171572894511004,1,-1.75913421641655E-7,,,,,,,,,,,,,,,,,,,,,1.99937689304352,2.00034070014954,-2000.32397460938,-2000.32397460938,53.5935318638422,5.6384866203238,2.03498673439026,54,1,0,0,1,0.3118896484375,34.7018585205078,1,1,3,1.99937689304352,0,1.99985879659653,,,,,,,,,,,,,,,,,,,,,,,,,,,,,,,,,
,3877770227.69044,2.00062167644501,-1800.12048339844,9.34110824464753E-6,1.95961731032199E-8,1,4,13.4005146026611,5.00796638513247,32.7799990773201,0.0116773049886953,0.00146753248887512,1,-2.19315597578338E-7,,,,,,,,,,,,,,,,,,,,,2.0001916885376,2.00105166435242,-1800.12048339844,-1800.12048339844,53.5181047117364,5.63903472457125,2.03329586982727,53,1,68,0,0,0.298843383789063,34.7018585205078,1,1,3,2.00105166435242,0,2.00062167644501,,,,,,,,,,,,,,,,,,,,,,,,,,,,,,,,,
,3877770285.32623,1.99996560811996,-1600.017578125,8.34258234209134E-6,2.19008237891253E-8,1,4,13.4005146026611,5.00804716781977,32.7799990773201,0.010429866012942,0.0013068012294019,1,-1.98992390901824E-7,,,,,,,,,,,,,,,,,,,,,1.99970591068268,2.00022530555725,-1600.017578125,-1600.017578125,53.5181047117364,5.63984489933423,2.0316321849823,54,1,0,0,1,0.304641723632812,34.7018585205078,1,1,3,1.99970591068268,0,1.99996560811996,,,,,,,,,,,,,,,,,,,,,,,,,,,,,,,,,
,3877770342.26808,2.00014066696167,-1400.00280761719,7.28423913253472E-6,2.23168141197105E-8,1,4,13.4005146026611,5.00804096149487,32.7799990773201,0.00911402542233913,0.00109213890091951,1,-2.12984808202732E-7,,,,,,,,,,,,,,,,,,,,,1.99995183944702,2.00032949447632,-1400.00280761719,-1400.00280761719,53.597830820698,5.63940342234739,2.03240656852722,54,1,0,0,1,0.305252075195313,34.7018585205078,1,1,3,1.99995183944702,0,2.00014066696167,,,,,,,,,,,,,,,,,,,,,,,,,,,,,,,,,
,3877770400.5882,2.00001621246338,-1200.05090332031,6.24158255864562E-6,2.23518084267209E-8,1,4,13.4005146026611,5.00802259855177,32.7799990773201,0.00781844180415496,8.75468545028066E-4,1,-2.30933968460969E-7,,,,,,,,,,,,,,,,,,,,,1.99970531463623,2.00032711029053,-1200.05090332031,-1200.05090332031,53.5442892671307,5.63932994673984,2.03692889213562,53,1,68,0,0,0.304946899414063,34.7018585205078,1,1,3,2.00032711029053,0,2.00001621246338,,,,,,,,,,,,,,,,,,,,,,,,,,,,,,,,,
,3877770466.2769,2.00013434886932,-1000.11163330078,5.20512635717668E-6,2.38866355018616E-8,1,4,13.4005146026611,5.00802236950157,32.7799990773201,0.00652992219994564,6.64680988177416E-4,10,-2.45092802670039E-7,,,,,,,,,,,,,,,,,,,,,2.00011038780212,2.00015830993652,-1000.11163330078,-1000.11163330078,53.5728187080826,5.63969201298246,2.03046464920044,54,1,0,0,1,0.304412841796875,35.190616607666,1,1,3,2.00015830993652,0,2.00013434886932,,,,,,,,,,,,,,,,,,,,,,,,,,,,,,,,,
,3877770532.08796,1.99934905767441,-800.197631835938,4.1355973406131E-6,2.13652686260553E-8,1,4,13.4005146026611,5.00792701639644,32.7799990773201,0.00518703156651134,5.34840294401316E-4,1,-1.89313964752427E-7,,,,,,,,,,,,,,,,,,,,,1.99896192550659,1.99973618984222,-800.197631835938,-800.197631835938,53.5560136949191,5.63924777081997,2.03080034255981,54,1,0,0,1,0.296859741210937,35.190616607666,1,1,3,1.99896192550659,0,1.99934905767441,,,,,,,,,,,,,,,,,,,,,,,,,,,,,,,,,
,3877770588.04772,2.0001266002655,-600.107238769531,3.12224812338936E-6,3.69118912103672E-8,1,4,13.4005146026611,5.00785268892729,32.7799990773201,0.0039401798191647,2.41923874244289E-4,1,-2.72859368304909E-7,,,,,,,,,,,,,,,,,,,,,1.99990344047546,2.00034976005554,-600.107238769531,-600.107238769531,53.5153690119191,5.63801946095831,2.03747415542603,53,1,68,0,0,0.299072265625,34.7018585205078,1,1,3,2.00034976005554,0,2.0001266002655,,,,,,,,,,,,,,,,,,,,,,,,,,,,,,,,,
,3877770661.95095,2.0000793337822,-400.155456542969,2.07862522283002E-6,2.79093641781396E-8,1,4,13.4005146026611,5.00805646991086,32.7799990773201,0.00263327183456617,9.44728588232913E-5,1,-2.35113675844586E-7,,,,,,,,,,,,,,,,,,,,,1.99966466426849,2.0004940032959,-400.155456542969,-400.155456542969,53.5610942802941,5.6388130446904,2.03580188751221,52,1,68,0,0,0.304718017578125,34.7018585205078,1,1,3,1.99966466426849,0,2.0000793337822,,,,,,,,,,,,,,,,,,,,,,,,,,,,,,,,,
,3877770726.95005,1.99987101554871,-200.027374267578,1.06142297633562E-6,2.63326820428823E-8,1,4,13.4005146026611,5.00787127556511,32.7799990773201,0.00137056076212948,-1.25459471851556E-4,10,-2.59497174651914E-7,,,,,,,,,,,,,,,,,,,,,1.99919247627258,2.00054955482483,-200.027374267578,-200.027374267578,53.4289990605441,5.63778569443871,2.03055191040039,54,1,0,0,1,0.305023193359375,34.7018585205078,1,1,3,2.00054955482483,0,1.99987101554871,,,,,,,,,,,,,,,,,,,,,,,,,,,,,,,,,
,3877770808.64868,1.99993127584457,-0.214000344276428,1.31265506398358E-8,3.12075081181178E-8,1,4,13.4005146026611,5.00787496996192,32.7799990773201,5.88363885294905E-5,-2.81554608372699E-4,1,-2.27986413755177E-7,,,,,,,,,,,,,,,,,,,,,1.99973666667938,2.00012588500977,-0.214000344276428,-0.214000344276428,53.4778508429961,5.63838043904439,2.02818584442139,52,1,68,0,0,0.303726196289063,33.7243423461914,1,1,3,1.99973666667938,0,1.99993127584457,,,,,,,,,,,,,,,,,,,,,,,,,,,,,,,,,
,3877770881.63743,1.9999315738678,200.014785766602,-1.10866707069174E-6,3.63575375229768E-8,1,4,13.4005146026611,5.00791400337946,32.7799990773201,-0.0013401390251419,-4.80227723896873E-4,1,-2.19657027446845E-7,,,,,,,,,,,,,,,,,,,,,1.99944448471069,2.0004186630249,200.014785766602,200.014785766602,53.4794141000345,5.63868377346805,2.03012108802795,52,1,68,0,0,0.298919677734375,34.7018585205078,1,1,3,1.99944448471069,0,1.9999315738678,,,,,,,,,,,,,,,,,,,,,,,,,,,,,,,,,
,3877770939.40028,1.99974656105042,399.689666748047,-2.23977977093817E-6,1.08362930123455E-8,1,4,13.4005146026611,5.00780333899853,32.7799990773201,-0.00280196942032356,-3.37481033983229E-4,1,6.41331891400198E-8,,,,,,,,,,,,,,,,,,,,,1.9995151758194,1.99997794628143,399.689666748047,399.689666748047,53.4547928016787,5.63857510592395,2.02764844894409,54,1,0,0,1,0.30426025390625,34.7018585205078,1,1,3,1.9995151758194,0,1.99974656105042,,,,,,,,,,,,,,,,,,,,,,,,,,,,,,,,,
,3877771014.4798,1.99957662820816,599.855529785156,-3.21145733330233E-6,1.57665106788048E-8,1,4,13.4005146026611,5.00783608941522,32.7799990773201,-0.00396058999892053,-8.64838197178462E-4,1,-2.13856903857549E-7,,,,,,,,,,,,,,,,,,,,,1.99930083751678,1.99985241889954,599.855529785156,599.855529785156,53.501299698573,5.63887217823879,2.0319128036499,53,1,68,0,0,0.305252075195313,34.7018585205078,1,1,3,1.99930083751678,0,1.99957662820816,,,,,,,,,,,,,,,,,,,,,,,,,,,,,,,,,
,3877771072.13632,1.99966299533844,799.681457519531,-4.25092699479553E-6,2.03928275949749E-8,1,4,13.4005146026611,5.00777678142812,32.7799990773201,-0.00525621454035735,-0.00105272445157479,1,-2.09203165376139E-7,,,,,,,,,,,,,,,,,,,,,1.99936974048614,1.99995625019073,799.681457519531,799.681457519531,53.501299698573,5.63816276151171,2.03039860725403,54,1,0,0,1,0.298843383789063,34.7018585205078,1,1,3,1.99995148181915,0,1.99966299533844,,,,,,,,,,,,,,,,,,,,,,,,,,,,,,,,,
,3877771146.38582,1.99963599443436,999.9228515625,-5.2662797122721E-6,5.11733511766993E-8,1,4,13.4005146026611,5.00787543468972,32.7799990773201,-0.00652780578510417,-0.00119764077230691,1,-1.73623413035448E-7,,,,,,,,,,,,,,,,,,,,,1.99935078620911,1.99992120265961,999.9228515625,999.9228515625,53.5040353983903,5.63871192277896,2.03070831298828,52,1,68,0,0,0.298690795898438,34.7018585205078,1,1,3,1.99935078620911,0,1.99963599443436,,,,,,,,,,,,,,,,,,,,,,,,,,,,,,,,,
,3877771204.04402,2.00032126903534,1199.6103515625,-6.38176475561567E-6,1.85455911158289E-8,1,4,13.4005146026611,5.00774626236613,32.7799990773201,-0.00792485889406061,-0.0013533954554921,1,-1.31827604827856E-7,,,,,,,,,,,,,,,,,,,,,2.00011277198791,2.00052976608276,1199.6103515625,1199.6103515625,53.3992971768133,5.6381242518413,2.03236842155457,54,1,0,0,1,0.298080444335937,34.7018585205078,1,1,3,2.00011277198791,0,2.00032126903534,,,,,,,,,,,,,,,,,,,,,,,,,,,,,,,,,
,3877771262.39705,2.00002694129944,1399.73840332031,-7.45538674676287E-6,1.82630080210234E-8,1,4,13.4005146026611,5.00783074952718,32.7799990773201,-0.00926021002517131,-0.00156833827972276,1,-1.43745891422379E-7,,,,,,,,,,,,,,,,,,,,,1.99958372116089,2.00047016143799,1399.73840332031,1399.73840332031,53.5270934397076,5.63886416252803,2.03124380111694,54,1,0,0,1,0.2996826171875,34.7018585205078,1,1,3,2.00047016143799,0,2.00002694129944,,,,,,,,,,,,,,,,,,,,,,,,,,,,,,,,,
,3877771320.04631,2.00003957748413,1599.61474609375,-8.48219032234522E-6,1.90282190182321E-8,1,4,13.4005146026611,5.00767979872623,32.7799990773201,-0.0105395516016744,-0.00175478422753752,1,-1.39876267705123E-7,,,,,,,,,,,,,,,,,,,,,1.99960899353027,2.00047016143799,1599.61474609375,1599.61474609375,53.5411627530537,5.639306407273,2.03095436096191,54,1,0,0,1,0.298385620117188,34.7018585205078,1,1,3,2.00047016143799,0,2.00003957748413,,,,,,,,,,,,,,,,,,,,,,,,,,,,,,,,,
,3877771377.75606,1.99969339370728,1799.66723632813,-9.55800655336613E-6,1.03970768817104E-8,1,4,13.4005146026611,5.00770487103267,32.7799990773201,-0.0118834675699316,-0.00193005587245601,1,-1.19639907643034E-7,,,,,,,,,,,,,,,,,,,,,1.99954724311829,1.99983954429626,1799.66723632813,1799.66723632813,53.4950466704191,5.63871374956556,2.02614784240723,54,1,0,0,1,0.304183959960937,34.7018585205078,1,1,3,1.99954724311829,0,1.99969339370728,,,,,,,,,,,,,,,,,,,,,,,,,,,,,,,,,
,3877771436.45853,1.99980711936951,2000.08483886719,-1.06330868795655E-5,2.76156296702959E-8,1,4,13.4005146026611,5.00770348173686,32.7799990773201,-0.0132192232067933,-0.00215307213298677,1,-1.37853788093531E-7,,,,,,,,,,,,,,,,,,,,,1.99976396560669,1.99985027313232,2000.08483886719,2000.08483886719,53.4751151431787,5.63905247888853,2.02690005302429,54,1,0,0,1,0.298690795898438,34.2131004333496,1,1,3,1.99976396560669,0,1.99980711936951,,,,,,,,,,,,,,,,,,,,,,,,,,,,,,,,,
,3877771494.03816,2.0003337264061,2199.79736328125,-1.16922186968001E-5,2.41721598779448E-8,1,4,13.4005146026611,5.00765138064532,32.7799990773201,-0.0145449709649129,-0.00230580148886141,1,-1.02053075887653E-7,,,,,,,,,,,,,,,,,,,,,1.99987614154816,2.00079131126404,2199.79736328125,2199.79736328125,53.416883818496,5.6389006122703,2.02857398986816,54,1,0,0,1,0.297622680664063,34.7018585205078,1,1,3,2.00079131126404,0,2.0003337264061,,,,,,,,,,,,,,,,,,,,,,,,,,,,,,,,,
,3877771552.42785,1.99938851594925,2399.96337890625,-1.27408013053304E-5,8.92158407372978E-9,1,4,13.4005146026611,5.00757851293509,32.7799990773201,-0.0158522400605925,-0.00249136157395251,1,-9.4203078275671E-8,,,,,,,,,,,,,,,,,,,,,1.99894595146179,1.99983108043671,2399.96337890625,2399.96337890625,53.396561476996,5.63950718854607,2.03411483764648,54,1,0,0,1,0.306320190429687,34.7018585205078,1,1,3,1.99894595146179,0,1.99938851594925,,,,,,,,,,,,,,,,,,,,,,,,,,,,,,,,,
,3877771610.10374,1.99974018335342,2599.80200195313,-1.37934802160121E-5,9.35340323881505E-9,1,4,13.4005146026611,5.00757509239418,32.7799990773201,-0.0171636659929143,-0.0026859176463531,1,-9.29269843163676E-8,,,,,,,,,,,,,,,,,,,,,1.99950647354126,1.99997389316559,2599.80200195313,2599.80200195313,53.4907477135634,5.63911083662203,2.02597618103027,54,1,0,0,1,0.299301147460937,34.2131004333496,1,1,3,1.99950647354126,0,1.99974018335342,,,,,,,,,,,,,,,,,,,,,,,,,,,,,,,,,
,3877771667.72831,1.99991893768311,2799.9677734375,-1.48659690703817E-5,9.47057110022788E-9,1,4,13.4005146026611,5.00765549300929,32.7799990773201,-0.0185005753827537,-0.00288170448575432,1,-8.96217141201503E-8,,,,,,,,,,,,,,,,,,,,,1.99960994720459,2.00022792816162,2799.9677734375,2799.9677734375,53.5298291395249,5.63898848079046,2.03089761734009,54,1,0,0,1,0.29876708984375,34.7018585205078,1,1,3,1.99960994720459,0,1.99991893768311,,,,,,,,,,,,,,,,,,,,,,,,,,,,,,,,,
,3877771725.37949,1.99927622079849,2999.8818359375,-1.59264807767416E-5,1.02997823754322E-8,1,4,13.4005146026611,5.00762891760987,32.7799990773201,-0.0198197241627207,-0.00309061447944468,1,-9.87104341084131E-8,,,,,,,,,,,,,,,,,,,,,1.99869048595428,1.9998619556427,2999.8818359375,2999.8818359375,53.4508846590826,5.63857409036062,2.03033256530762,54,1,0,0,1,0.298385620117188,34.7018585205078,1,1,3,1.99869048595428,0,1.99927622079849,,,,,,,,,,,,,,,,,,,,,,,,,,,,,,,,,
,3877771798.07096,1.99967306852341,4499.62109375,-2.40963057128842E-5,1.22334069525643E-8,1,4,13.4005146026611,5.00775467374681,32.7799990773201,-0.0300219467454272,-0.00444739837304411,1,3.43141823203939E-8,,,,,,,,,,,,,,,,,,,,,1.99963057041168,1.99971556663513,4499.62109375,4499.62109375,53.6263602616499,5.63848822673269,2.02608752250671,54,1,0,0,1,0.299301147460937,34.2131004333496,1,1,3,1.99971556663513,0,1.99967306852341,,,,,,,,,,,,,,,,,,,,,,,,,,,,,,,,,
,3877771861.79322,2.00056743621826,6499.630859375,-3.51674561970532E-5,2.17077690920256E-8,1,4,13.4005146026611,5.00767814479312,32.7799990773201,-0.0438194190524709,-0.00645923929406469,1,7.5285509583321E-8,,,,,,,,,,,,,,,,,,,,,2.00021409988403,2.00092077255249,6499.630859375,6499.630859375,53.5141965691403,5.63883714033761,2.03236722946167,54,1,0,0,1,0.303878784179687,34.7018585205078,1,1,3,2.00021409988403,0,2.00056743621826,,,,,,,,,,,,,,,,,,,,,,,,,,,,,,,,,
,3877771926.71168,2.00020360946655,8499.8916015625,-4.64746989612075E-5,1.90030413811583E-8,1,4,13.4005146026611,5.0077619303846,32.7799990773201,-0.0579030668738065,-0.00858156097916003,1,6.31169901905317E-8,,,,,,,,,,,,,,,,,,,,,2.00018835067749,2.00021886825562,8499.8916015625,8499.8916015625,53.6271418901691,5.63921807221906,2.02612280845642,53,1,68,0,0,0.297470092773438,34.2131004333496,1,1,3,2.00021886825562,0,2.00020360946655,,,,,,,,,,,,,,,,,,,,,,,,,,,,,,,,,
,3877772000.10288,1.99996739625931,10000.0341796875,-5.51146916995398E-5,2.0102117060839E-8,1,4,13.4005146026611,5.00783817480883,32.7799990773201,-0.068663398572278,-0.0102155319364828,1,4.40417899684654E-8,,,,,,,,,,,,,,,,,,,,,1.99977838993073,2.00015640258789,10000.0341796875,10000.0341796875,53.4899660850441,5.63894725750622,2.02753353118896,54,1,0,0,1,0.304031372070313,34.2131004333496,1,1,3,1.9990142583847,0,1.99996739625931,,,,,,,,,,,,,,,,,,,,,,,,,,,,,,,,,
,3877772154.79608,1.99976617097855,30000.1796875,-1.79346902425759E-4,3.855630052171E-8,1,4,13.4005146026611,5.00766724029531,32.7799990773201,-0.223421508195901,-0.0332613924625425,1,1.26493912713865E-7,,,,,,,,,,,,,,,,,,,,,1.99946057796478,2.00007176399231,30000.1796875,30000.1796875,54.1078434294961,5.64007201636783,2.02964901924133,54,1,0,0,1,0.298614501953125,33.7243423461914,1,1,3,2.00007176399231,0,1.99976617097855,,,,,,,,,,,,,,,,,,,,,,,,,,,,,,,,,
,3877772327.72689,2.00001865625381,50000.23046875,-3.08152518005312E-4,9.48836277798918E-8,1,4,13.4005146026611,5.00782467810621,32.7799990773201,-0.383874856335007,-0.0573070280950906,1,9.28792380182556E-8,,,,,,,,,,,,,,,,,,,,,1.99984061717987,2.00019669532776,50000.23046875,50000.23046875,54.6303620946019,5.64038135323362,2.02850246429443,54,1,0,0,1,0.299148559570313,34.2131004333496,1,1,3,2.00012135505676,0,2.00001865625381,,,,,,,,,,,,,,,,,,,,,,,,,,,,,,,,,
,3877772485.22892,2.00063705444336,70000.3828125,-4.37805739073647E-4,2.0869417684433E-7,1,4,13.4005146026611,5.00784737177984,32.7799990773201,-0.545415387068916,-0.0812576054773241,1,2.61611579948233E-7,,,,,,,,,,,,,,,,,,,,,2.00055766105652,2.0007164478302,70000.3828125,70000.3828125,55.1970427710443,5.64289873940284,2.02274417877197,52,1,32,0,0,0.29937744140625,34.7018585205078,1,1,3,2.0007164478302,0,2.00063705444336,,,,,,,,,,,,,,,,,,,,,,,,,,,,,,,,,