File: SQUID/Reference/STO/A6/STO_MH_10K_FC_1T.csv
Comment,Time Stamp (sec),Temperature (K),Magnetic Field (Oe),Moment (emu),M. Std. Err. (emu),Transport Action,Averaging Time (sec),Frequency (Hz),Peak Amplitude (mm),Center Position (mm),Lockin Signal' (V),Lockin Signal (V),Range,M. Quad. Signal (emu),AC Moment (emu),AC M. Std Err. (emu),AC Phase (deg),AC Phase Std. Err. (deg),AC Susceptibility (emu/Oe),AC Suscept. Std Err. (emu/Oe),AC X' (emu/Oe),AC X' Std Err. (emu/Oe),AC X'' (emu/Oe),AC X'' Std Err. (emu/Oe),AC Drive (Oe),AC Frequency (Hz),AC Averaging Time (sec),AC Cycles,AC Range,AC Measure Type,AC Signal' (V),AC Signal'' (V),AC Trim Coil Ratio,AC Trim Coil Phase,Min. Temperature (K),Max. Temperature (K),Min. Field (Oe),Max. Field (Oe),Mass (grams),Motor Lag (deg),Pressure (Torr),Measure Count,Measurement Number,SQUID Status (code),Motor Status (code),Measure Status (code),Motor Current (amps),Motor Temp. (C),Temp. Status (code),Field Status (code),Chamber Status (code),Chamber Temp (K),Redirection State,Average Temp (K),Rotation Angle (deg),Rotator state,DC Moment Fixed Ctr (emu),DC Moment Err Fixed Ctr (emu),DC Moment Free Ctr (emu),DC Moment Err Free Ctr (emu),DC Fixed Fit,DC Free Fit,DC Calculated Center (mm),DC Calculated Center Err (mm),DC Scan Length (mm),DC Scan Time (s),DC Number of Points,DC Squid Drift,DC Min V (V),DC Max V (V),DC Scans per Measure,Map 01,Map 02,Map 03,Map 04,Map 05,Map 06,Map 07,Map 08,Map 09,Map 10,Map 11,Map 12,Map 13,Map 14,Map 15,Map 16
,3877779789.14122,10.0000019073486,69999.765625,-4.43120590028069E-4,1.87418879468317E-7,1,4,13.4005146026611,5.00761827583674,32.7799990773201,-0.551993634472528,-0.0822899780238708,1,2.23694950255326E-7,,,,,,,,,,,,,,,,,,,,,9.99996662139893,10.0000371932983,69999.765625,69999.765625,54.1137056433903,5.64067215552355,3.85362601280212,54,1,0,0,1,0.3057861328125,33.7243423461914,1,1,3,10.0000371932983,0,10.0000019073486,,,,,,,,,,,,,,,,,,,,,,,,,,,,,,,,,
,3877779961.67286,10.0010814666748,50000.08203125,-3.14793632005856E-4,1.71633764477127E-7,1,4,13.4005146026611,5.00728127034102,32.7799990773201,-0.392119236070376,-0.058327132118114,1,2.60328261540227E-7,,,,,,,,,,,,,,,,,,,,,10.0009918212891,10.0011711120605,50000.08203125,50000.08203125,53.8850793015153,5.64131996337838,3.85816287994385,54,1,0,0,1,0.307159423828125,35.6793746948242,1,1,3,10.0009918212891,0,10.0010814666748,,,,,,,,,,,,,,,,,,,,,,,,,,,,,,,,,
,3877780119.59861,10.0003428459167,29999.5625,-1.87800922305649E-4,9.12951932282828E-8,1,4,13.4005146026611,5.00726151110162,32.7799990773201,-0.233897339926849,-0.0350209919049897,1,-2.46517405858824E-8,,,,,,,,,,,,,,,,,,,,,10.0001010894775,10.000584602356,29999.5625,29999.5625,53.623233747573,5.63914164951476,3.87358212471008,53,1,68,0,0,0.298690795898438,34.7018585205078,1,1,3,10.000584602356,0,10.0003428459167,,,,,,,,,,,,,,,,,,,,,,,,,,,,,,,,,
,3877780279.18836,10.0004105567932,9999.6064453125,-6.22199730331946E-5,3.24982039661362E-8,1,4,13.4005146026611,5.00755667852754,32.7799990773201,-0.077500503263508,-0.0115901487351858,1,2.70859480330275E-9,,,,,,,,,,,,,,,,,,,,,10.0004034042358,10.0004177093506,9999.6064453125,9999.6064453125,53.4723794433614,5.63764316011924,3.87564468383789,54,1,0,0,1,0.306243896484375,34.7018585205078,1,1,3,10.0004177093506,0,10.0004105567932,,,,,,,,,,,,,,,,,,,,,,,,,,,,,,,,,
,3877780358.58674,10.0002746582031,8499.6650390625,-5.28160669600818E-5,1.88557044015661E-8,1,4,13.4005146026611,5.00750526747996,32.7799990773201,-0.0657851599067439,-0.00984495358329711,1,-3.06163181120949E-9,,,,,,,,,,,,,,,,,,,,,10.00026512146,10.0002841949463,8499.6650390625,8499.6650390625,53.5458525241691,5.63784891252655,3.87581205368042,54,1,0,0,1,0.299301147460937,35.190616607666,1,1,3,10.0002841949463,0,10.0002746582031,,,,,,,,,,,,,,,,,,,,,,,,,,,,,,,,,
,3877780426.72868,10.0000505447388,6499.65576171875,-4.03039926822729E-5,1.62995555289888E-8,1,4,13.4005146026611,5.00752132995193,32.7799990773201,-0.0501986633829091,-0.00752798201117978,1,-1.45833976434258E-8,,,,,,,,,,,,,,,,,,,,,9.99999713897705,10.0001039505005,6499.65576171875,6499.65576171875,53.4852763139287,5.63815560567292,3.8759024143219,54,1,0,0,1,0.298843383789063,35.190616607666,1,1,3,9.99999713897705,0,10.0000505447388,,,,,,,,,,,,,,,,,,,,,,,,,,,,,,,,,
,3877780494.798,10.0001463890076,4499.68408203125,-2.78080029852196E-5,1.13902349709784E-8,1,4,13.4005146026611,5.00758686491378,32.7799990773201,-0.0346322963383764,-0.00521568682663546,1,-2.74122666696372E-8,,,,,,,,,,,,,,,,,,,,,10.0001153945923,10.0001773834229,4499.68408203125,4499.68408203125,53.5138057548807,5.63808740432516,3.88438987731934,52,1,68,0,0,0.299072265625,34.7018585205078,1,1,3,10.0001153945923,0,10.0001463890076,,,,,,,,,,,,,,,,,,,,,,,,,,,,,,,,,
,3877780576.96717,10.000072479248,2999.57983398438,-1.84584159689616E-5,7.13816102969563E-9,1,4,13.4005146026611,5.00759828258059,32.7799990773201,-0.0229951321629379,-0.00341656918233538,1,1.8344354201759E-8,,,,,,,,,,,,,,,,,,,,,10.000020980835,10.0001239776611,2999.57983398438,2999.57983398438,53.3746758784576,5.63746699128193,3.88681793212891,54,1,0,0,1,0.298538208007812,34.7018585205078,1,1,3,10.000020980835,0,10.000072479248,,,,,,,,,,,,,,,,,,,,,,,,,,,,,,,,,
,3877780634.65061,9.99994707107544,2799.80419921875,-1.72969059378102E-5,1.47632479386596E-8,1,4,13.4005146026611,5.00760682659394,32.7799990773201,-0.0215809030132752,-0.00298295560184687,1,1.92712898311726E-7,,,,,,,,,,,,,,,,,,,,,9.99977779388428,10.0001163482666,2799.80419921875,2799.80419921875,53.4712070005826,5.63829066182686,3.8885543346405,53,1,68,0,0,0.298385620117188,34.7018585205078,1,1,3,10.0001163482666,0,9.99994707107544,,,,,,,,,,,,,,,,,,,,,,,,,,,,,,,,,
,3877780695.14071,9.99999761581421,2599.68872070313,-1.6072374491162E-5,1.62264881689732E-8,1,4,13.4005146026611,5.00759616166707,32.7799990773201,-0.0200573468829046,-0.00274289238180303,1,2.02253247237166E-7,,,,,,,,,,,,,,,,,,,,,9.99996471405029,10.0000305175781,2599.68872070313,2599.68872070313,53.5685197512268,5.63822081574215,3.88975119590759,53,1,68,0,0,0.305099487304687,35.190616607666,1,1,3,9.99999141693115,0,9.99999761581421,,,,,,,,,,,,,,,,,,,,,,,,,,,,,,,,,
,3877780755.9697,9.99996042251587,2399.81225585938,-1.48104371543324E-5,1.50011706173003E-8,1,4,13.4005146026611,5.00760009994065,32.7799990773201,-0.0184829406352482,-0.00252489688496944,1,1.88490643465498E-7,,,,,,,,,,,,,,,,,,,,,9.99985027313232,10.0000705718994,2399.81225585938,2399.81225585938,53.5548412521403,5.63784425061129,3.88967490196228,54,1,0,0,1,0.298233032226562,34.7018585205078,1,1,3,9.99985027313232,0,9.99996042251587,,,,,,,,,,,,,,,,,,,,,,,,,,,,,,,,,
,3877780820.82129,9.99996185302734,2199.81005859375,-1.35473872125878E-5,3.71432305597296E-8,1,4,13.4005146026611,5.00760941399635,32.7799990773201,-0.0169168355461233,-0.00224208806759503,10,2.26597850306149E-7,,,,,,,,,,,,,,,,,,,,,9.99993515014648,9.9999885559082,2199.81005859375,2199.81005859375,53.506380283948,5.63803520740639,3.88080382347107,54,1,0,0,1,0.29754638671875,35.190616607666,1,1,3,9.99997425079346,0,9.99996185302734,,,,,,,,,,,,,,,,,,,,,,,,,,,,,,,,,
,3877780888.13176,10.0001201629639,1999.75756835938,-1.23225622125654E-5,1.78576367448977E-8,1,4,13.4005146026611,5.00763647874293,32.7799990773201,-0.0153854883405987,-0.00205279970461148,1,1.95349749026374E-7,,,,,,,,,,,,,,,,,,,,,9.99995422363281,10.0002861022949,1999.75756835938,1999.75756835938,53.5388178674961,5.6375622806916,3.88662242889404,54,1,0,0,1,0.299224853515625,35.190616607666,1,1,3,10.0002861022949,0,10.0001201629639,,,,,,,,,,,,,,,,,,,,,,,,,,,,,,,,,
,3877780945.34952,9.99998569488525,1799.73022460938,-1.10414116830985E-5,2.06952426068316E-8,1,4,13.4005146026611,5.00759642443934,32.7799990773201,-0.013789341183414,-0.00181526596216112,1,1.94378181465661E-7,,,,,,,,,,,,,,,,,,,,,9.99994277954102,10.0000286102295,1799.73022460938,1799.73022460938,53.5560136949191,5.63769592337946,3.89341592788696,54,1,0,0,1,0.298995971679687,35.190616607666,1,1,3,9.99994277954102,0,9.99998569488525,,,,,,,,,,,,,,,,,,,,,,,,,,,,,,,,,
,3877781003.01263,10.0000939369202,1599.74060058594,-9.83598812788724E-6,1.76354468683009E-8,1,4,13.4005146026611,5.00765732296694,32.7799990773201,-0.0122887882151373,-0.00158595543712231,1,1.98173132481236E-7,,,,,,,,,,,,,,,,,,,,,10.0000896453857,10.0000982284546,1599.74060058594,1599.74060058594,53.3359852667556,5.63753462675032,3.88387870788574,52,1,68,0,0,0.298538208007812,34.7018585205078,1,1,3,10.0000896453857,0,10.0000939369202,,,,,,,,,,,,,,,,,,,,,,,,,,,,,,,,,
,3877781062.81327,10.0001606941223,1399.62512207031,-8.55998468099182E-6,1.88972333982465E-8,1,4,13.4005146026611,5.00762235830866,32.7799990773201,-0.0107048793065855,-0.00131070516059967,1,2.28255881750667E-7,,,,,,,,,,,,,,,,,,,,,10.0001430511475,10.0001783370972,1399.62512207031,1399.62512207031,53.5263118111883,5.63731404818557,3.8924195766449,54,1,0,0,1,0.299606323242188,34.7018585205078,1,1,3,10.0001430511475,0,10.0001606941223,,,,,,,,,,,,,,,,,,,,,,,,,,,,,,,,,
,3877781119.11598,9.99991607666016,1199.64819335938,-7.32889148369995E-6,2.00982203018023E-8,1,4,13.4005146026611,5.00766689052096,32.7799990773201,-0.00916990918066846,-0.00109221998072012,1,2.19507892146805E-7,,,,,,,,,,,,,,,,,,,,,9.99990940093994,9.99992275238037,1199.64819335938,1199.64819335938,53.3875727490249,5.63803264725919,3.89281105995178,54,1,0,0,1,0.2984619140625,34.7018585205078,1,1,3,9.99992275238037,0,9.99991607666016,,,,,,,,,,,,,,,,,,,,,,,,,,,,,,,,,
,3877781175.71122,10.0001635551453,999.822143554687,-6.07344999556326E-6,2.1509204996939E-8,1,4,13.4005146026611,5.00762046985587,32.7799990773201,-0.00760711739005599,-8.50863102146962E-4,1,2.2545732894869E-7,,,,,,,,,,,,,,,,,,,,,10.0000467300415,10.000280380249,999.822143554687,999.822143554687,53.5110700550634,5.6377616221645,3.89148736000061,54,1,0,0,1,0.298995971679687,34.7018585205078,1,1,3,10.000280380249,0,10.0001635551453,,,,,,,,,,,,,,,,,,,,,,,,,,,,,,,,,
,3877781233.18097,9.99990606307983,799.744445800781,-4.85875741253111E-6,2.28336696114719E-8,1,4,13.4005146026611,5.00764286588199,32.7799990773201,-0.00609547201192867,-6.15562747280407E-4,1,2.32654679627409E-7,,,,,,,,,,,,,,,,,,,,,9.99990463256836,9.99990749359131,799.744445800781,799.744445800781,53.4207919610922,5.63724737120231,3.88413095474243,54,1,0,0,1,0.30487060546875,34.7018585205078,1,1,3,9.99990749359131,0,9.99990606307983,,,,,,,,,,,,,,,,,,,,,,,,,,,,,,,,,
,3877781291.34587,10.0000057220459,599.943603515625,-3.5995659743708E-6,2.54765094081768E-8,1,4,13.4005146026611,5.00762192422525,32.7799990773201,-0.00452380922242685,-4.02145789243905E-4,1,2.15620709763132E-7,,,,,,,,,,,,,,,,,,,,,9.99991512298584,10.000096321106,599.943603515625,599.943603515625,53.5220128543326,5.63743035307443,3.88717079162598,54,1,0,0,1,0.297698974609375,34.7018585205078,1,1,3,10.000096321106,0,10.0000057220459,,,,,,,,,,,,,,,,,,,,,,,,,,,,,,,,,
,3877781356.6684,10.0000429153442,399.765197753906,-2.35040613873957E-6,2.53578524297045E-8,1,4,13.4005146026611,5.007613062536,32.7799990773201,-0.00297731327546562,-1.06084706901432E-4,10,2.66438750211988E-7,,,,,,,,,,,,,,,,,,,,,10.0000143051147,10.0000715255737,399.765197753906,399.765197753906,53.5052078411691,5.63762504866811,3.89382791519165,54,1,0,0,1,0.297393798828125,34.7018585205078,1,1,3,10.0000143051147,0,10.0000429153442,,,,,,,,,,,,,,,,,,,,,,,,,,,,,,,,,
,3877781439.59501,10.0000839233398,200.140670776367,-1.13173763354458E-6,2.2675358716525E-8,1,4,13.4005146026611,5.00764500022276,32.7799990773201,-0.00145668499857789,1.03164928429911E-4,1,2.52123701943266E-7,,,,,,,,,,,,,,,,,,,,,10.0000505447388,10.0001173019409,200.140670776367,200.140670776367,53.5935318638422,5.63816119472874,3.8952944278717,54,1,0,0,1,0.299148559570313,35.190616607666,1,1,3,10.0000505447388,0,10.0000839233398,,,,,,,,,,,,,,,,,,,,,,,,,,,,,,,,,
,3877781522.76174,10.0000948905945,0.113294303417206,1.41276840453057E-7,2.94706121554207E-8,1,4,13.4005146026611,5.00758871870784,32.7799990773201,1.27819470733226E-4,3.48221535540893E-4,10,2.58428966575035E-7,,,,,,,,,,,,,,,,,,,,,9.99997615814209,10.0002136230469,0.113294303417206,0.113294303417206,53.5395994960153,5.63819118908009,3.88842225074768,54,1,0,0,1,0.29815673828125,35.190616607666,1,1,3,10.0002136230469,0,10.0000948905945,,,,,,,,,,,,,,,,,,,,,,,,,,,,,,,,,
,3877781590.24921,10.0000081062317,-199.825958251953,1.4051400428675E-6,1.38825082094307E-8,1,4,13.4005146026611,5.00756092014441,32.7799990773201,0.00172869585796207,4.05688332066618E-4,1,1.15501479279731E-7,,,,,,,,,,,,,,,,,,,,,9.99992084503174,10.0000953674316,-199.825958251953,-199.825958251953,53.4356429029576,5.63835690931293,3.88598918914795,54,1,0,0,1,0.298309326171875,34.7018585205078,1,1,3,9.99992084503174,0,10.0000081062317,,,,,,,,,,,,,,,,,,,,,,,,,,,,,,,,,
,3877781647.87942,10.0000562667847,-399.891082763672,2.58436353220637E-6,1.46575842444331E-8,1,4,13.4005146026611,5.00757267063212,32.7799990773201,0.00318507160328086,7.08672345854457E-4,1,1.82341946934411E-7,,,,,,,,,,,,,,,,,,,,,10.0000457763672,10.0000667572021,-399.891082763672,-399.891082763672,53.5372546104576,5.63883020012923,3.89650297164917,54,1,0,0,1,0.299072265625,34.2131004333496,1,1,3,10.0000457763672,0,10.0000562667847,,,,,,,,,,,,,,,,,,,,,,,,,,,,,,,,,
,3877781705.74999,9.99979782104492,-599.817810058594,3.83978148856208E-6,1.62801284631317E-8,1,4,13.4005146026611,5.00759903793364,32.7799990773201,0.00474894519923959,9.41886825230616E-4,1,1.81766284497122E-7,,,,,,,,,,,,,,,,,,,,,9.99976444244385,9.999831199646,-599.817810058594,-599.817810058594,53.5157598261787,5.63827650238241,3.88817811012268,54,1,0,0,1,0.299301147460937,34.7018585205078,1,1,3,9.99976444244385,0,9.99979782104492,,,,,,,,,,,,,,,,,,,,,,,,,,,,,,,,,
,3877781763.35354,9.99996519088745,-799.668884277344,5.08642594897518E-6,1.752043825741E-8,1,4,13.4005146026611,5.00758507159672,32.7799990773201,0.00629990599226086,0.00118640219994106,1,1.91583669216334E-7,,,,,,,,,,,,,,,,,,,,,9.99995899200439,9.99997138977051,-799.668884277344,-799.668884277344,53.4715978148422,5.63826829320481,3.88832998275757,54,1,0,0,1,0.2984619140625,35.190616607666,1,1,3,9.99995899200439,0,9.99996519088745,,,,,,,,,,,,,,,,,,,,,,,,,,,,,,,,,
,3877781828.96366,9.99992227554321,-999.570373535156,6.31978588070041E-6,3.0685793849823E-8,1,4,13.4005146026611,5.00756811386423,32.7799990773201,0.00784270863259049,0.00137223694854249,10,1.56279919373835E-7,,,,,,,,,,,,,,,,,,,,,9.99990081787109,9.99994373321533,-999.570373535156,-999.570373535156,53.531783210823,5.63846871107577,3.8881459236145,54,1,0,0,1,0.298309326171875,34.7018585205078,1,1,3,9.99990081787109,0,9.99992227554321,,,,,,,,,,,,,,,,,,,,,,,,,,,,,,,,,
,3877781912.61505,9.99991703033447,-1199.59777832031,7.59385539142543E-6,1.40438629474121E-8,1,4,13.4005146026611,5.00758408307512,32.7799990773201,0.00943150215722116,0.00159767798884688,1,1.46673390021963E-7,,,,,,,,,,,,,,,,,,,,,9.99984931945801,9.99998474121094,-1199.59777832031,-1199.59777832031,53.5044262126499,5.63870902991965,3.89500904083252,54,1,0,0,1,0.299072265625,34.7018585205078,1,1,3,9.99998474121094,0,9.99991703033447,,,,,,,,,,,,,,,,,,,,,,,,,,,,,,,,,
,3877781988.71892,9.9999623298645,-1399.56225585938,8.81658826480171E-6,1.35626652035333E-8,1,4,13.4005146026611,5.00763270799332,32.7799990773201,0.0109586240975367,0.00179913891559172,1,1.25479802990585E-7,,,,,,,,,,,,,,,,,,,,,9.99993324279785,9.99999141693115,-1399.56225585938,-1399.56225585938,53.4841038711499,5.63856912327883,3.88610243797302,53,1,68,0,0,0.306015014648438,34.7018585205078,1,1,3,9.99999141693115,0,9.9999623298645,,,,,,,,,,,,,,,,,,,,,,,,,,,,,,,,,
,3877782079.65904,9.99976682662964,-1599.5517578125,1.00761586921109E-5,1.68685069508943E-8,1,4,13.4005146026611,5.00758102280678,32.7799990773201,0.0125255482339485,0.00204601189082088,1,1.35274415023935E-7,,,,,,,,,,,,,,,,,,,,,9.99963855743408,9.9998950958252,-1599.5517578125,-1599.5517578125,53.4512754733422,5.63768796312207,3.89453625679016,52,1,68,0,0,0.298233032226562,35.190616607666,1,1,3,9.9998950958252,0,9.99976682662964,,,,,,,,,,,,,,,,,,,,,,,,,,,,,,,,,
,3877782140.27871,9.99999809265137,-1799.50354003906,1.13186985759095E-5,1.08458286029271E-8,1,4,13.4005146026611,5.0075881281217,32.7799990773201,0.0140783706143738,0.00224344807563581,1,1.07902797028392E-7,,,,,,,,,,,,,,,,,,,,,9.99997615814209,10.0000200271606,-1799.50354003906,-1799.50354003906,53.4336888316595,5.63790060406042,3.89773201942444,54,1,0,0,1,0.2984619140625,34.7018585205078,1,1,3,9.99997615814209,0,9.99999809265137,,,,,,,,,,,,,,,,,,,,,,,,,,,,,,,,,
,3877782198.81552,9.99998998641968,-1999.65686035156,1.25522667880566E-5,3.02137423640702E-8,1,4,13.4005146026611,5.00760749852262,32.7799990773201,0.0156064595822718,0.00253025476499246,1,1.53615000825166E-7,,,,,,,,,,,,,,,,,,,,,9.99993705749512,10.0000429153442,-1999.65686035156,-1999.65686035156,53.4966099274576,5.63797980611368,3.88940119743347,54,1,0,0,1,0.300140380859375,35.190616607666,1,1,3,9.99993705749512,0,9.99998998641968,,,,,,,,,,,,,,,,,,,,,,,,,,,,,,,,,
,3877782256.48276,10.0000138282776,-2199.6337890625,1.37700386640151E-5,1.23501849684383E-7,1,4,13.4005146026611,5.00756315682518,32.7799990773201,0.0171505914460684,0.00257337433360327,1,6.08695354368018E-9,,,,,,,,,,,,,,,,,,,,,10.0000095367432,10.000018119812,-2199.6337890625,-2199.6337890625,53.5849339501307,5.63789420199387,3.89499235153198,54,1,0,0,1,0.298233032226562,34.7018585205078,1,1,3,10.000018119812,0,10.0000138282776,,,,,,,,,,,,,,,,,,,,,,,,,,,,,,,,,
,3877782315.1344,9.99996185302734,-2399.61083984375,1.50624892824905E-5,1.33030879021873E-8,1,4,13.4005146026611,5.00758811641044,32.7799990773201,0.0187476991971033,0.00290030094063489,1,7.5196828917849E-8,,,,,,,,,,,,,,,,,,,,,9.99972248077393,10.0002012252808,-2399.61083984375,-2399.61083984375,53.4794141000345,5.63789924669059,3.8989098072052,54,1,0,0,1,0.305709838867188,34.7018585205078,1,1,3,10.0002012252808,0,9.99996185302734,,,,,,,,,,,,,,,,,,,,,,,,,,,,,,,,,
,3877782373.85942,10.0000076293945,-2599.587890625,1.63870328501015E-5,7.07818139776848E-8,1,4,13.4005146026611,5.00759548217848,32.7799990773201,0.0204027641929941,0.00311246855472651,1,4.73829384982429E-8,,,,,,,,,,,,,,,,,,,,,9.99971199035645,10.0003032684326,-2599.587890625,-2599.587890625,53.4204011468326,5.63819759783914,3.88890719413757,54,1,0,0,1,0.3057861328125,36.1681327819824,1,1,3,9.99971199035645,0,10.0000076293945,,,,,,,,,,,,,,,,,,,,,,,,,,,,,,,,,
,3877782433.4506,9.99983072280884,-2799.7412109375,1.75483830296786E-5,8.72964202343321E-9,1,4,13.4005146026611,5.00757862265108,32.7799990773201,0.0218458046689458,0.00335176473836029,1,6.57788464489297E-8,,,,,,,,,,,,,,,,,,,,,9.99981594085693,9.99984550476074,-2799.7412109375,-2799.7412109375,53.4024236908903,5.63796513676832,3.89377975463867,54,1,0,0,1,0.299835205078125,34.7018585205078,1,1,3,9.99984550476074,0,9.99983072280884,,,,,,,,,,,,,,,,,,,,,,,,,,,,,,,,,
,3877782495.38063,10.0000472068787,-2999.70556640625,1.87935269772588E-5,1.31132501407185E-8,1,4,13.4005146026611,5.00760381690723,32.7799990773201,0.023390889024906,0.00362402265524074,1,9.80702830636796E-8,,,,,,,,,,,,,,,,,,,,,10.0000314712524,10.0000629425049,-2999.70556640625,-2999.70556640625,53.4508846590826,5.63788630981312,3.89650440216064,54,1,0,0,1,0.306320190429687,34.7018585205078,1,1,3,10.0000314712524,0,10.0000472068787,,,,,,,,,,,,,,,,,,,,,,,,,,,,,,,,,
,3877782574.70771,9.99999523162842,-4499.47021484375,2.81817243278954E-5,7.55086453549762E-9,1,4,13.4005146026611,5.00757622679712,32.7799990773201,0.0351105195001768,0.00519958643764487,1,-4.14076496130745E-8,,,,,,,,,,,,,,,,,,,,,9.99985694885254,10.0001335144043,-4499.47021484375,-4499.47021484375,53.3664687790057,5.63790959241519,3.89058804512024,54,1,0,0,1,0.305557250976562,34.7018585205078,1,1,3,10.0001335144043,0,9.99999523162842,,,,,,,,,,,,,,,,,,,,,,,,,,,,,,,,,
,3877782642.04181,9.99994707107544,-6499.69384765625,4.06566693052758E-5,1.21697937344625E-8,1,4,13.4005146026611,5.00762363863551,32.7799990773201,0.0506521518055741,0.00750861958695262,1,-5.38920642542887E-8,,,,,,,,,,,,,,,,,,,,,9.99991703033447,9.99997711181641,-6499.69384765625,-6499.69384765625,53.3574800510345,5.63790675188388,3.89624643325806,54,1,0,0,1,0.304412841796875,34.7018585205078,1,1,3,9.99997711181641,0,9.99994707107544,,,,,,,,,,,,,,,,,,,,,,,,,,,,,,,,,
,3877782708.09872,9.99999761581421,-8499.501953125,5.31307759821336E-5,1.55520688437262E-8,1,4,13.4005146026611,5.00766160063283,32.7799990773201,0.0661958912793001,0.00979804822304856,1,-8.20181433401772E-8,,,,,,,,,,,,,,,,,,,,,9.99993324279785,10.0000619888306,-8499.501953125,-8499.501953125,53.4309531318422,5.63797489046327,3.89844655990601,53,1,68,0,0,0.29876708984375,34.7018585205078,1,1,3,9.99993324279785,0,9.99999761581421,,,,,,,,,,,,,,,,,,,,,,,,,,,,,,,,,
,3877782789.12738,9.99983930587769,-9999.59375,6.24698356098902E-5,1.6635215297968E-8,1,4,13.4005146026611,5.00766359223118,32.7799990773201,0.0778244156672387,0.0115677581124034,1,-5.83397102264661E-8,,,,,,,,,,,,,,,,,,,,,9.99982357025146,9.99985504150391,-9999.59375,-9999.59375,53.5829798788326,5.63803911392826,3.88874578475952,54,1,0,0,1,0.298309326171875,35.190616607666,1,1,3,9.99985504150391,0,9.99983930587769,,,,,,,,,,,,,,,,,,,,,,,,,,,,,,,,,
,3877782946.08034,10.0000491142273,-29999.625,1.88022904055854E-4,3.54044592226672E-8,1,4,13.4005146026611,5.00763730839231,32.7799990773201,0.23422759663058,0.0348707310779699,1,-1.32137497917704E-7,,,,,,,,,,,,,,,,,,,,,10.0000343322754,10.0000638961792,-29999.625,-29999.625,53.5329556536018,5.63810272445293,3.88829565048218,54,1,0,0,1,0.306320190429687,34.7018585205078,1,1,3,10.0000638961792,0,10.0000491142273,,,,,,,,,,,,,,,,,,,,,,,,,,,,,,,,,
,3877783105.1965,9.99972343444824,-49999.6171875,3.1493718455857E-4,5.76064958527282E-8,1,4,13.4005146026611,5.00764826048135,32.7799990773201,0.392322296141014,0.0584663110119224,1,-1.74865043669406E-7,,,,,,,,,,,,,,,,,,,,,9.9996223449707,9.99982452392578,-49999.6171875,-49999.6171875,53.8041807497749,5.63914981434803,3.89260125160217,52,1,68,0,0,0.305557250976562,34.7018585205078,1,1,3,9.99982452392578,0,9.99972343444824,,,,,,,,,,,,,,,,,,,,,,,,,,,,,,,,,
,3877783281.74292,10.0002193450928,-69999.5,4.43026071165996E-4,8.86958563001335E-8,1,4,13.4005146026611,5.00765460952516,32.7799990773201,0.551878379893347,0.0822940499342461,1,-2.06956552036486E-7,,,,,,,,,,,,,,,,,,,,,10.0001726150513,10.0002660751343,-69999.5,-69999.5,54.2579161051884,5.64082914589673,3.89014649391174,51,1,68,0,0,0.30487060546875,34.7018585205078,1,1,3,10.0002660751343,0,10.0002193450928,,,,,,,,,,,,,,,,,,,,,,,,,,,,,,,,,
,3877783459.40552,9.99992036819458,-49999.640625,3.14735526897593E-4,7.11989660328727E-8,1,4,13.4005146026611,5.00769862438484,32.7799990773201,0.39206542762079,0.0585043800666249,1,-1.14796081605824E-7,,,,,,,,,,,,,,,,,,,,,9.99983882904053,10.0000019073486,-49999.640625,-49999.640625,53.8514692751884,5.63943350278505,3.8946008682251,54,1,0,0,1,0.29815673828125,34.7018585205078,1,1,3,9.99983882904053,0,9.99992036819458,,,,,,,,,,,,,,,,,,,,,,,,,,,,,,,,,
,3877783627.61558,10.0001530647278,-29999.625,1.87916469139746E-4,3.79070344955079E-8,1,4,13.4005146026611,5.00771512197004,32.7799990773201,0.234116165769931,0.034744293841654,10,-2.18327728872334E-7,,,,,,,,,,,,,,,,,,,,,10.0001258850098,10.0001802444458,-29999.625,-29999.625,53.6337857325826,5.63818032713317,3.88800644874573,54,1,0,0,1,0.298614501953125,34.7018585205078,1,1,3,10.0001802444458,0,10.0001530647278,,,,,,,,,,,,,,,,,,,,,,,,,,,,,,,,,
,3877783792.67172,10.0001049041748,-10000.09765625,6.22070241390839E-5,1.95619945564691E-8,1,4,13.4005146026611,5.00766895788377,32.7799990773201,0.0774805860555805,0.0116296575129524,1,3.06550146827781E-8,,,,,,,,,,,,,,,,,,,,,10.0000877380371,10.0001220703125,-10000.09765625,-10000.09765625,53.4544019874191,5.63749475974719,3.88699173927307,54,1,0,0,1,0.306396484375,34.7018585205078,1,1,3,10.0000877380371,0,10.0001049041748,,,,,,,,,,,,,,,,,,,,,,,,,,,,,,,,,
,3877783865.97614,10.0001301765442,-8500.1064453125,5.28112272624132E-5,1.84645056552751E-8,1,4,13.4005146026611,5.00768613929536,32.7799990773201,0.0657795928816226,0.00986366809470705,1,1.84107452039788E-8,,,,,,,,,,,,,,,,,,,,,10.0001268386841,10.0001335144043,-8500.1064453125,-8500.1064453125,53.333640381198,5.63776454515901,3.88736486434937,52,1,68,0,0,0.305862426757812,34.7018585205078,1,1,3,10.0001268386841,0,10.0001301765442,,,,,,,,,,,,,,,,,,,,,,,,,,,,,,,,,
,3877783931.83213,10.0002102851868,-6499.970703125,4.03034037598898E-5,1.12961588717713E-8,1,4,13.4005146026611,5.00766895957702,32.7799990773201,0.0502001798187079,0.00752697075594188,1,1.36105862948328E-8,,,,,,,,,,,,,,,,,,,,,10.0000886917114,10.0003318786621,-6499.970703125,-6499.970703125,53.4813681713326,5.63777264195135,3.88800048828125,54,1,0,0,1,0.29937744140625,35.190616607666,1,1,3,10.0003318786621,0,10.0002102851868,,,,,,,,,,,,,,,,,,,,,,,,,,,,,,,,,
,3877783996.31031,10.0002017021179,-4500.1123046875,2.78161721419717E-5,1.02298742292283E-8,1,4,13.4005146026611,5.00769282395105,32.7799990773201,0.0346412721856544,0.00523223182774753,1,3.9348819429585E-8,,,,,,,,,,,,,,,,,,,,,10.0000953674316,10.0003080368042,-4500.1123046875,-4500.1123046875,53.4856671281884,5.63770628400392,3.89466094970703,53,1,68,0,0,0.29876708984375,34.7018585205078,1,1,3,10.0003080368042,0,10.0002017021179,,,,,,,,,,,,,,,,,,,,,,,,,,,,,,,,,
,3877784080.9798,10.0001049041748,-3000.20922851562,1.84718107657348E-5,6.58493890719615E-9,1,4,13.4005146026611,5.00774763911027,32.7799990773201,0.0230119260560415,0.00342488973719657,1,-1.37827815667541E-8,,,,,,,,,,,,,,,,,,,,,10.0000848770142,10.0001249313354,-3000.20922851562,-3000.20922851562,53.5298291395249,5.63811721455043,3.89264392852783,54,1,0,0,1,0.299301147460937,34.7018585205078,1,1,3,10.0000848770142,0,10.0001049041748,,,,,,,,,,,,,,,,,,,,,,,,,,,,,,,,,
,3877784138.09723,10.0000953674316,-2800.1943359375,1.72882692678686E-5,1.72027169363328E-8,1,4,13.4005146026611,5.00770500587141,32.7799990773201,0.0215703457439722,0.00298403909436342,1,-1.90616702598361E-7,,,,,,,,,,,,,,,,,,,,,9.99996662139893,10.0002241134644,-2800.1943359375,-2800.1943359375,53.455574430198,5.63784088881622,3.89854383468628,53,1,68,0,0,0.29815673828125,35.190616607666,1,1,3,9.99996662139893,0,10.0000953674316,,,,,,,,,,,,,,,,,,,,,,,,,,,,,,,,,
,3877784212.4267,9.99995851516724,-2600.3935546875,1.6043983832699E-5,1.97476930752071E-8,1,4,13.4005146026611,5.00770018174753,32.7799990773201,0.0200236979744077,0.00273010812800083,1,-2.08333396990266E-7,,,,,,,,,,,,,,,,,,,,,9.99988460540771,10.0000324249268,-2600.3935546875,-2600.3935546875,53.470816186323,5.63778157828426,3.89501214027405,54,1,0,0,1,0.306472778320313,34.7018585205078,1,1,3,10.0000324249268,0,9.99995851516724,,,,,,,,,,,,,,,,,,,,,,,,,,,,,,,,,
,3877784269.03218,9.99992370605469,-2400.353515625,1.48229066294708E-5,1.74841650954102E-8,1,4,13.4005146026611,5.00773702755915,32.7799990773201,0.018502376030304,0.00250594969605533,1,-2.05644241065472E-7,,,,,,,,,,,,,,,,,,,,,9.9996395111084,10.000207901001,-2400.353515625,-2400.353515625,53.5196679687749,5.63788695458466,3.8941376209259,52,1,68,0,0,0.298919677734375,35.190616607666,1,1,3,9.9996395111084,0,9.99992370605469,,,,,,,,,,,,,,,,,,,,,,,,,,,,,,,,,
,3877784327.58417,10.0001068115234,-2200.38916015625,1.3577921375724E-5,1.90485185535119E-8,1,4,13.4005146026611,5.00772585841317,32.7799990773201,0.0169530805383042,0.00226348932378599,1,-2.14043141399994E-7,,,,,,,,,,,,,,,,,,,,,10.0000581741333,10.0001554489136,-2200.38916015625,-2200.38916015625,53.4215735896114,5.63792526797862,3.88845276832581,53,1,68,0,0,0.306320190429687,34.7018585205078,1,1,3,10.0000581741333,0,10.0001068115234,,,,,,,,,,,,,,,,,,,,,,,,,,,,,,,,,
,3877784384.59034,10.0000901222229,-2000.27368164062,1.23078186996875E-5,1.78345038827648E-8,1,4,13.4005146026611,5.00775862806547,32.7799990773201,0.0153679456705127,0.00204813027531507,1,-1.96948986623968E-7,,,,,,,,,,,,,,,,,,,,,10.0000839233398,10.000096321106,-2000.27368164062,-2000.27368164062,53.5392086817557,5.63772481690856,3.88844656944275,52,1,68,0,0,0.299148559570313,34.7018585205078,1,1,3,10.000096321106,0,10.0000901222229,,,,,,,,,,,,,,,,,,,,,,,,,,,,,,,,,
,3877784459.69596,10.0001845359802,-1800.01977539062,1.10571238274544E-5,1.84970713171447E-8,1,4,13.4005146026611,5.00771070147759,32.7799990773201,0.0138104380451769,0.00181099601629017,1,-2.00203038168206E-7,,,,,,,,,,,,,,,,,,,,,10.0001173019409,10.0002517700195,-1800.01977539062,-1800.01977539062,53.3770207640153,5.63827886136448,3.88928174972534,54,1,0,0,1,0.298004150390625,35.190616607666,1,1,3,10.0002517700195,0,10.0001845359802,,,,,,,,,,,,,,,,,,,,,,,,,,,,,,,,,
,3877784516.8525,9.99997043609619,-1599.95458984375,9.81555033791983E-6,1.8362940271904E-8,1,4,13.4005146026611,5.00768297690802,32.7799990773201,0.0122683939740912,0.00154889791323476,1,-2.24875035976264E-7,,,,,,,,,,,,,,,,,,,,,9.99988174438477,10.0000591278076,-1599.95458984375,-1599.95458984375,53.4637815296499,5.63750907899736,3.89773321151733,54,1,0,0,1,0.304412841796875,35.190616607666,1,1,3,10.0000591278076,0,9.99997043609619,,,,,,,,,,,,,,,,,,,,,,,,,,,,,,,,,
,3877784575.61535,10.000048160553,-1400.12866210938,8.57898743921602E-6,1.91005235184025E-8,1,4,13.4005146026611,5.00767631107733,32.7799990773201,0.0107245671856322,0.0013419648367708,1,-2.06018795165524E-7,,,,,,,,,,,,,,,,,,,,,9.99991226196289,10.0001840591431,-1400.12866210938,-1400.12866210938,53.5231852971114,5.63795827480382,3.89879941940308,52,1,68,0,0,0.298004150390625,34.7018585205078,1,1,3,10.0001840591431,0,10.000048160553,,,,,,,,,,,,,,,,,,,,,,,,,,,,,,,,,
,3877784632.73141,10.0000686645508,-1200.15161132812,7.38221700646739E-6,2.21288574828915E-8,1,4,13.4005146026611,5.0077209932925,32.7799990773201,0.00923945736147028,0.00108221639545146,1,-2.35529197844022E-7,,,,,,,,,,,,,,,,,,,,,9.99993228912354,10.000205039978,-1200.15161132812,-1200.15161132812,53.4227460323903,5.63786120710628,3.88798785209656,52,1,68,0,0,0.298614501953125,34.7018585205078,1,1,3,9.99993228912354,0,10.0000686645508,,,,,,,,,,,,,,,,,,,,,,,,,,,,,,,,,
,3877784689.51875,9.99997854232788,-1000.08648681641,6.07761180395978E-6,2.39236057395485E-8,1,4,13.4005146026611,5.00772710434144,32.7799990773201,0.00760974818283301,8.70245968038148E-4,1,-2.1053967401408E-7,,,,,,,,,,,,,,,,,,,,,9.99994945526123,10.0000076293945,-1000.08648681641,-1000.08648681641,53.5290475110057,5.63768092901188,3.89797878265381,53,1,68,0,0,0.298843383789063,35.190616607666,1,1,3,10.0000076293945,0,9.99997854232788,,,,,,,,,,,,,,,,,,,,,,,,,,,,,,,,,
,3877784747.47568,10.0000782012939,-800.159851074219,4.82466773501715E-6,2.35755699828357E-8,1,4,13.4005146026611,5.00770054726608,32.7799990773201,0.00605010565849245,6.29283742984824E-4,1,-2.16547731127247E-7,,,,,,,,,,,,,,,,,,,,,9.99995899200439,10.0001974105835,-800.159851074219,-800.159851074219,53.6627059877941,5.63793501159434,3.89673829078674,54,1,0,0,1,0.29815673828125,34.7018585205078,1,1,3,10.0001974105835,0,10.0000782012939,,,,,,,,,,,,,,,,,,,,,,,,,,,,,,,,,
,3877784804.44978,9.9998950958252,-600.25830078125,3.60541562101624E-6,2.2496204731529E-8,1,4,13.4005146026611,5.00775219661978,32.7799990773201,0.00453337803555429,3.89094095624118E-4,1,-2.26985349445914E-7,,,,,,,,,,,,,,,,,,,,,9.99988651275635,9.99990367889404,-600.25830078125,-600.25830078125,53.5204495972941,5.6382011527106,3.88812851905823,52,1,68,0,0,0.2984619140625,34.7018585205078,1,1,3,9.99990367889404,0,9.9998950958252,,,,,,,,,,,,,,,,,,,,,,,,,,,,,,,,,
,3877784861.8425,9.99995088577271,-400.230987548828,2.39189762215878E-6,2.47604506410027E-8,1,4,13.4005146026611,5.00773551809308,32.7799990773201,0.00302082505622747,1.6912672021811E-4,1,-2.22038510714428E-7,,,,,,,,,,,,,,,,,,,,,9.99991321563721,9.9999885559082,-400.230987548828,-400.230987548828,53.3637330791883,5.6374343198483,3.89155602455139,54,1,0,0,1,0.307083129882812,35.190616607666,1,1,3,9.99991321563721,0,9.99995088577271,,,,,,,,,,,,,,,,,,,,,,,,,,,,,,,,,
,3877784919.24968,10.0000596046448,-200.191024780273,1.0978424835969E-6,2.24090265470935E-8,1,4,13.4005146026611,5.00775561985677,32.7799990773201,0.0014052356438955,-4.74973796180938E-5,1,-2.02361076177512E-7,,,,,,,,,,,,,,,,,,,,,10.0000200271606,10.0000991821289,-200.191024780273,-200.191024780273,53.4129756758999,5.637709369433,3.89744806289673,54,1,0,0,1,0.304718017578125,34.7018585205078,1,1,3,10.0000200271606,0,10.0000596046448,,,,,,,,,,,,,,,,,,,,,,,,,,,,,,,,,
,3877784977.20872,10.000283241272,-0.226588606834412,-1.61078815412494E-7,2.4557694731879E-8,1,4,13.4005146026611,5.00774028070586,32.7799990773201,-1.54536773692778E-4,-3.38251335746414E-4,1,-2.47450837097192E-7,,,,,,,,,,,,,,,,,,,,,10.0002040863037,10.0003623962402,-0.226588606834412,-0.226588606834412,53.4661264152076,5.6374865043162,3.89774417877197,54,1,0,0,1,0.299224853515625,35.190616607666,1,1,3,10.0002040863037,0,10.000283241272,,,,,,,,,,,,,,,,,,,,,,,,,,,,,,,,,
,3877785034.86026,10.0000367164612,199.863723754883,-1.14745550397139E-6,4.35817051012936E-7,1,4,13.4005146026611,5.00773182100849,32.7799990773201,-0.0013617594076299,-6.65432852733868E-4,1,-3.62556636508007E-7,,,,,,,,,,,,,,,,,,,,,10.0000143051147,10.0000591278076,199.863723754883,199.863723754883,53.4794141000345,5.63695023440249,3.88797402381897,50,1,68,0,0,0.298919677734375,34.7018585205078,1,1,3,10.0000591278076,0,10.0000367164612,,,,,,,,,,,,,,,,,,,,,,,,,,,,,,,,,
,3877785109.10106,10.0001134872437,399.765197753906,-2.64191379861195E-6,1.66651132811356E-8,1,4,13.4005146026611,5.00774564934575,32.7799990773201,-0.00326227905753787,-6.83557570799797E-4,1,-1.53543268802294E-7,,,,,,,,,,,,,,,,,,,,,9.99993228912354,10.0002946853638,399.765197753906,399.765197753906,53.3594341223326,5.63760893040764,3.89688038825989,54,1,0,0,1,0.2978515625,34.7018585205078,1,1,3,9.99993228912354,0,10.0001134872437,,,,,,,,,,,,,,,,,,,,,,,,,,,,,,,,,
,3877785175.23118,9.99994611740112,599.754821777344,-3.85836858564251E-6,1.91267472295808E-8,1,4,13.4005146026611,5.00772783160935,32.7799990773201,-0.00477177667172903,-9.48673765224291E-4,10,-1.84407139844443E-7,,,,,,,,,,,,,,,,,,,,,9.99981307983398,10.0000791549683,599.754821777344,599.754821777344,53.4075042762653,5.63820948632497,3.89196276664734,54,1,0,0,1,0.305633544921875,35.190616607666,1,1,3,9.99981307983398,0,9.99994611740112,,,,,,,,,,,,,,,,,,,,,,,,,,,,,,,,,
,3877785240.68111,10.0000901222229,799.643737792969,-5.06223959102837E-6,2.90172152196365E-8,1,4,13.4005146026611,5.0076958824183,32.7799990773201,-0.00626834436049318,-0.00119282334653562,1,-2.00327280431443E-7,,,,,,,,,,,,,,,,,,,,,10.0000848770142,10.0000953674316,799.643737792969,799.643737792969,53.4778508429961,5.63761648382452,3.89192128181458,54,1,0,0,1,0.30517578125,34.7018585205078,1,1,3,10.0000953674316,0,10.0000901222229,,,,,,,,,,,,,,,,,,,,,,,,,,,,,,,,,
,3877785298.5045,9.99999189376831,999.74658203125,-6.33687498606224E-6,6.18913409831595E-8,1,4,13.4005146026611,5.00770557821993,32.7799990773201,-0.00787474665097149,-0.00130561596659526,1,-1.00197563606728E-7,,,,,,,,,,,,,,,,,,,,,9.99997234344482,10.0000114440918,999.74658203125,999.74658203125,53.4579193157556,5.63757401004512,3.90062952041626,54,1,0,0,1,0.2984619140625,35.190616607666,1,1,3,9.99994468688965,0,9.99999189376831,,,,,,,,,,,,,,,,,,,,,,,,,,,,,,,,,
,3877785356.18874,10.0000305175781,1199.64819335938,-7.56530730405895E-6,1.69960384527891E-8,1,4,13.4005146026611,5.00771496688555,32.7799990773201,-0.00939680012743093,-0.00158898140580542,1,-1.43915504633907E-7,,,,,,,,,,,,,,,,,,,,,9.99998188018799,10.0000791549683,1199.64819335938,1199.64819335938,53.4837130568903,5.63744039828864,3.89215326309204,54,1,0,0,1,0.299148559570313,34.7018585205078,1,1,3,10.0000791549683,0,10.0000305175781,,,,,,,,,,,,,,,,,,,,,,,,,,,,,,,,,
,3877785421.90533,10.000036239624,1399.78881835938,-8.81473767008326E-6,2.83891608976526E-8,1,4,13.4005146026611,5.00772334815284,32.7799990773201,-0.0109469850603252,-0.00186308778446809,10,-1.77058314034069E-7,,,,,,,,,,,,,,,,,,,,,9.99994373321533,10.0001287460327,1399.78881835938,1399.78881835938,53.4766784002172,5.63791199921088,3.891117811203,54,1,0,0,1,0.298080444335937,34.7018585205078,1,1,3,10.0001287460327,0,10.000036239624,,,,,,,,,,,,,,,,,,,,,,,,,,,,,,,,,
,3877785488.79068,10.0000338554382,1599.47619628906,-1.00616550569236E-5,1.00670978982194E-8,1,4,13.4005146026611,5.00769284570652,32.7799990773201,-0.012509250080962,-0.00203416826191729,1,-1.27884638960884E-7,,,,,,,,,,,,,,,,,,,,,9.99995708465576,10.0001106262207,1599.47619628906,1599.47619628906,53.3348128239768,5.63743111780909,3.89854288101196,54,1,0,0,1,0.299148559570313,34.7018585205078,1,1,3,10.0001106262207,0,10.0000338554382,,,,,,,,,,,,,,,,,,,,,,,,,,,,,,,,,
,3877785546.61621,10.0000166893005,1799.55395507813,-1.13292297845118E-5,9.32809668410599E-9,1,4,13.4005146026611,5.00772827162064,32.7799990773201,-0.0140891290526097,-0.00226495364743213,1,-1.23521607153404E-7,,,,,,,,,,,,,,,,,,,,,9.99996376037598,10.0000696182251,1799.55395507813,1799.55395507813,53.4399418598133,5.63803835457802,3.8960165977478,54,1,0,0,1,0.29876708984375,35.190616607666,1,1,3,9.99996376037598,0,10.0000166893005,,,,,,,,,,,,,,,,,,,,,,,,,,,,,,,,,
,3877785604.31477,10.0000424385071,1999.93371582031,-1.25583801864376E-5,1.49881418713833E-8,1,4,13.4005146026611,5.00768208113802,32.7799990773201,-0.0156235471354383,-0.0024702967532439,1,-1.04523275793901E-7,,,,,,,,,,,,,,,,,,,,,10.0000257492065,10.0000591278076,1999.93371582031,1999.93371582031,53.4379877885153,5.63807168255534,3.88987112045288,54,1,0,0,1,0.298538208007812,34.7018585205078,1,1,3,10.0000591278076,0,10.0000424385071,,,,,,,,,,,,,,,,,,,,,,,,,,,,,,,,,
,3877785661.99564,10.0000705718994,2199.8603515625,-1.38376099267841E-5,2.64055926897643E-8,1,4,13.4005146026611,5.00767170452845,32.7799990773201,-0.0172193194884784,-0.002692730890604,1,-9.17370568308021E-8,,,,,,,,,,,,,,,,,,,,,10.0000200271606,10.0001211166382,2199.8603515625,2199.8603515625,53.528656696746,5.63770204079594,3.89838480949402,52,1,68,0,0,0.299301147460937,34.7018585205078,1,1,3,10.0001211166382,0,10.0000705718994,,,,,,,,,,,,,,,,,,,,,,,,,,,,,,,,,
,3877785719.57856,10.0001330375671,2400.0009765625,-1.5085538456584E-5,8.44988590386273E-9,1,4,13.4005146026611,5.00770298119088,32.7799990773201,-0.0187741197769533,-0.00292401672372709,1,-9.07133206709841E-8,,,,,,,,,,,,,,,,,,,,,10.0000858306885,10.0001802444458,2400.0009765625,2400.0009765625,53.4571376872364,5.63732852821629,3.89503121376038,54,1,0,0,1,0.306320190429687,34.7018585205078,1,1,3,10.0000858306885,0,10.0001330375671,,,,,,,,,,,,,,,,,,,,,,,,,,,,,,,,,
,3877785777.2179,9.99996900558472,2599.75170898438,-1.63162256687685E-5,8.91718960463937E-9,1,4,13.4005146026611,5.00766573520128,32.7799990773201,-0.0203092549043114,-0.00313751002331369,1,-7.80298946476661E-8,,,,,,,,,,,,,,,,,,,,,9.99982357025146,10.000114440918,2599.75170898438,2599.75170898438,53.3840554206883,5.63762106605078,3.89875102043152,54,1,0,0,1,0.30487060546875,34.7018585205078,1,1,3,9.99982357025146,0,9.99996900558472,,,,,,,,,,,,,,,,,,,,,,,,,,,,,,,,,
,3877785834.93767,9.99998998641968,2799.84204101562,-1.75619265989459E-5,1.1478608597744E-8,1,4,13.4005146026611,5.00771729729332,32.7799990773201,-0.0218603688450643,-0.00337548757215969,1,-8.26933971074086E-8,,,,,,,,,,,,,,,,,,,,,9.99998283386231,9.99999713897705,2799.84204101562,2799.84204101562,53.4544019874191,5.63771050813103,3.890061378479,54,1,0,0,1,0.298309326171875,34.7018585205078,1,1,3,9.99998283386231,0,9.99998998641968,,,,,,,,,,,,,,,,,,,,,,,,,,,,,,,,,
,3877785892.49937,10.0000038146973,2999.73071289063,-1.88007723543712E-5,1.18375736165599E-8,1,4,13.4005146026611,5.00769474866623,32.7799990773201,-0.0234057465226036,-0.00359044513956112,1,-6.99562908122334E-8,,,,,,,,,,,,,,,,,,,,,9.99995040893555,10.000057220459,2999.73071289063,2999.73071289063,53.4465857022268,5.63765168588814,3.88840460777283,54,1,0,0,1,0.298614501953125,34.7018585205078,1,1,3,10.000057220459,0,10.0000038146973,,,,,,,,,,,,,,,,,,,,,,,,,,,,,,,,,
,3877785970.57585,10.0000677108765,4499.759765625,-2.81834359999083E-5,7.6872070550455E-8,1,4,13.4005146026611,5.00767315418728,32.7799990773201,-0.0351301147740817,-0.00508965920368726,1,1.30027581451886E-7,,,,,,,,,,,,,,,,,,,,,10.0000114440918,10.0001239776611,4499.759765625,4499.759765625,53.4970007417172,5.6371480623309,3.89332556724548,54,1,0,0,1,0.303955078125,34.2131004333496,1,1,3,10.0000114440918,0,10.0000677108765,,,,,,,,,,,,,,,,,,,,,,,,,,,,,,,,,
,3877786035.7887,10.000020980835,6499.630859375,-4.06486900884957E-5,1.09437409874108E-8,1,4,13.4005146026611,5.00770489123638,32.7799990773201,-0.0506447311515965,-0.00749814710182409,1,6.12425078862332E-8,,,,,,,,,,,,,,,,,,,,,10.0000143051147,10.0000276565552,6499.630859375,6499.630859375,53.4266541749864,5.63793867111786,3.89271545410156,54,1,0,0,1,0.297164916992188,34.7018585205078,1,1,3,10.0000276565552,0,10.000020980835,,,,,,,,,,,,,,,,,,,,,,,,,,,,,,,,,
,3877786100.63111,9.9997181892395,8499.9169921875,-5.31361998611539E-5,1.69593156272978E-8,1,4,13.4005146026611,5.00769278272426,32.7799990773201,-0.0662067591365289,-0.00977550989580988,1,1.00991935096539E-7,,,,,,,,,,,,,,,,,,,,,9.9996280670166,9.9998083114624,8499.9169921875,8499.9169921875,53.4407234883326,5.63775704161654,3.88920593261719,54,1,0,0,1,0.298385620117188,34.7018585205078,1,1,3,9.9996280670166,0,9.9997181892395,,,,,,,,,,,,,,,,,,,,,,,,,,,,,,,,,
,3877786173.51741,10.0001153945923,9999.9462890625,-6.24841311787915E-5,1.80462723946118E-8,1,4,13.4005146026611,5.00774922413368,32.7799990773201,-0.0778499633143064,-0.0115313909770894,1,8.98955792178008E-8,,,,,,,,,,,,,,,,,,,,,10.0001039505005,10.0001268386841,9999.9462890625,9999.9462890625,53.5591402089961,5.63735682289056,3.8901731967926,54,1,0,0,1,0.297470092773438,33.7243423461914,1,1,3,10.0001039505005,0,10.0001153945923,,,,,,,,,,,,,,,,,,,,,,,,,,,,,,,,,
,3877786325.82784,10.0000720024109,30000.2421875,-1.88039379556465E-4,3.79722764109231E-8,1,4,13.4005146026611,5.00780544582794,32.7799990773201,-0.234263932222908,-0.0348432212217443,1,1.58000413762468E-7,,,,,,,,,,,,,,,,,,,,,10.0000171661377,10.0001268386841,30000.2421875,30000.2421875,53.5880604642076,5.63759758761902,3.88686466217041,53,1,68,0,0,0.30517578125,34.7018585205078,1,1,3,10.0000171661377,0,10.0000720024109,,,,,,,,,,,,,,,,,,,,,,,,,,,,,,,,,
,3877786480.54461,10.0001759529114,50000.30859375,-3.14987108520108E-4,1.5395654181558E-7,1,4,13.4005146026611,5.00782838245973,32.7799990773201,-0.392434089905153,-0.0582788184955272,1,3.35207998156626E-7,,,,,,,,,,,,,,,,,,,,,10.000129699707,10.0002222061157,50000.30859375,50000.30859375,53.8971945435634,5.63897853507696,3.89452171325684,53,1,68,0,0,0.313262939453125,34.7018585205078,1,1,3,10.000129699707,0,10.0001759529114,,,,,,,,,,,,,,,,,,,,,,,,,,,,,,,,,
,3877786655.69299,10.0002093315125,70000.3828125,-4.43056721838198E-4,2.11122413137515E-7,1,4,13.4005146026611,5.00781756017887,32.7799990773201,-0.55194487313495,-0.0822820467091875,1,2.24182621107917E-7,,,,,,,,,,,,,,,,,,,,,10.000147819519,10.0002708435059,70000.3828125,70000.3828125,54.141453455823,5.64038939626254,3.89130544662476,53,1,68,0,0,0.298843383789063,34.7018585205078,1,1,3,10.0002708435059,0,10.0002093315125,,,,,,,,,,,,,,,,,,,,,,,,,,,,,,,,,