File: SQUID/Reference/STO/A6/STO_MH_350K_FC_1T.csv
Comment,Time Stamp (sec),Temperature (K),Magnetic Field (Oe),Moment (emu),M. Std. Err. (emu),Transport Action,Averaging Time (sec),Frequency (Hz),Peak Amplitude (mm),Center Position (mm),Lockin Signal' (V),Lockin Signal (V),Range,M. Quad. Signal (emu),AC Moment (emu),AC M. Std Err. (emu),AC Phase (deg),AC Phase Std. Err. (deg),AC Susceptibility (emu/Oe),AC Suscept. Std Err. (emu/Oe),AC X' (emu/Oe),AC X' Std Err. (emu/Oe),AC X'' (emu/Oe),AC X'' Std Err. (emu/Oe),AC Drive (Oe),AC Frequency (Hz),AC Averaging Time (sec),AC Cycles,AC Range,AC Measure Type,AC Signal' (V),AC Signal'' (V),AC Trim Coil Ratio,AC Trim Coil Phase,Min. Temperature (K),Max. Temperature (K),Min. Field (Oe),Max. Field (Oe),Mass (grams),Motor Lag (deg),Pressure (Torr),Measure Count,Measurement Number,SQUID Status (code),Motor Status (code),Measure Status (code),Motor Current (amps),Motor Temp. (C),Temp. Status (code),Field Status (code),Chamber Status (code),Chamber Temp (K),Redirection State,Average Temp (K),Rotation Angle (deg),Rotator state,DC Moment Fixed Ctr (emu),DC Moment Err Fixed Ctr (emu),DC Moment Free Ctr (emu),DC Moment Err Free Ctr (emu),DC Fixed Fit,DC Free Fit,DC Calculated Center (mm),DC Calculated Center Err (mm),DC Scan Length (mm),DC Scan Time (s),DC Number of Points,DC Squid Drift,DC Min V (V),DC Max V (V),DC Scans per Measure,Map 01,Map 02,Map 03,Map 04,Map 05,Map 06,Map 07,Map 08,Map 09,Map 10,Map 11,Map 12,Map 13,Map 14,Map 15,Map 16
,3877825596.77503,350.056594848633,69999.828125,-4.69021071801033E-4,1.62085771447701E-7,1,4,13.4005146026611,4.99770864346791,33.1399999558926,-0.582659724886647,-0.0867334408460567,1,3.37702169825539E-7,,,,,,,,,,,,,,,,,,,,,350.056549072266,350.056640625,69999.828125,69999.828125,53.1741881632749,5.63898243148651,7.291672706604,54,1,0,0,1,0.296554565429687,33.7243423461914,1,1,3,350.056549072266,0,350.056594848633,,,,,,,,,,,,,,,,,,,,,,,,,,,,,,,,,
,3877825768.80556,349.990570068359,49999.6015625,-3.37100532714125E-4,6.03228177146105E-8,1,4,13.4005146026611,4.99769326475188,33.1399999558926,-0.418751509982375,-0.0624914237453763,1,1.19078427235452E-7,,,,,,,,,,,,,,,,,,,,,349.979278564453,350.001861572266,49999.6015625,49999.6015625,53.4215735896114,5.63919965704171,7.29997873306274,54,1,0,0,1,0.296707153320313,34.7018585205078,1,1,3,350.001861572266,0,349.990570068359,,,,,,,,,,,,,,,,,,,,,,,,,,,,,,,,,
,3877825926.22806,350.049789428711,29999.73828125,-2.05463227940218E-4,3.43608428450395E-8,1,4,13.4005146026611,4.99770361026156,33.1399999558926,-0.255241747802821,-0.0380125125206294,1,1.33927290394912E-7,,,,,,,,,,,,,,,,,,,,,350.04931640625,350.050262451172,29999.73828125,29999.73828125,53.607991991448,5.63939943581081,7.30790662765503,54,1,0,0,1,0.29632568359375,35.190616607666,1,1,3,350.04931640625,0,350.049789428711,,,,,,,,,,,,,,,,,,,,,,,,,,,,,,,,,
,3877826084.42425,350.036651611328,9999.6064453125,-7.38409983623497E-5,1.47978972337476E-8,1,4,13.4005146026611,4.9977520156262,33.1399999558926,-0.0917280626548965,-0.0136880101272288,1,2.6727560578629E-8,,,,,,,,,,,,,,,,,,,,,350.036376953125,350.036926269531,9999.6064453125,9999.6064453125,53.6255786331307,5.63912250770935,7.32224178314209,54,1,0,0,1,0.296173095703125,35.190616607666,1,1,3,350.036376953125,0,350.036651611328,,,,,,,,,,,,,,,,,,,,,,,,,,,,,,,,,
,3877826165.50595,350.01628112793,8499.6650390625,-6.39701392370513E-5,1.29581385058418E-8,1,4,13.4005146026611,4.99774562948451,33.1399999558926,-0.0794699099033125,-0.01183186581526,1,4.43659987041992E-8,,,,,,,,,,,,,,,,,,,,,350.015686035156,350.016876220703,8499.6650390625,8499.6650390625,53.694361942823,5.63938242403126,7.3188910484314,54,1,0,0,1,0.297088623046875,35.190616607666,1,1,3,350.016876220703,0,350.01628112793,,,,,,,,,,,,,,,,,,,,,,,,,,,,,,,,,
,3877826231.66614,349.739959716797,6499.517578125,-5.07881398852299E-5,1.17036637000934E-8,1,4,13.4005146026611,4.99774528131226,33.1399999558926,-0.0630902816393589,-0.00941822787350534,1,1.55041393680879E-8,,,,,,,,,,,,,,,,,,,,,349.734954833984,349.744964599609,6499.517578125,6499.517578125,53.6263602616499,5.63917510647306,7.3208475112915,52,1,68,0,0,0.296401977539063,35.6793746948242,1,1,3,349.734954833984,0,349.739959716797,,,,,,,,,,,,,,,,,,,,,,,,,,,,,,,,,
,3877826310.58564,349.603790283203,4499.734375,-3.67456517393323E-5,8.61533376330908E-9,1,4,13.4005146026611,4.9977626101438,33.1399999558926,-0.0456494068155974,-0.00679528883261186,1,2.64425556387762E-8,,,,,,,,,,,,,,,,,,,,,349.589996337891,349.617584228516,4499.734375,4499.734375,53.5935318638422,5.63929556643457,7.33033323287964,54,1,0,0,1,0.304946899414063,35.190616607666,1,1,3,349.617584228516,0,349.603790283203,,,,,,,,,,,,,,,,,,,,,,,,,,,,,,,,,
,3877826396.42711,349.884262084961,2999.49169921875,-2.51090054270344E-5,8.00988450737626E-9,1,4,13.4005146026611,4.99775961184096,33.1399999558926,-0.0312004007573229,-0.00459444305710389,1,5.74381372120748E-8,,,,,,,,,,,,,,,,,,,,,349.884155273438,349.884368896484,2999.49169921875,2999.49169921875,53.5970491921788,5.63878054133327,7.32808542251587,54,1,0,0,1,0.297012329101562,35.190616607666,1,1,3,349.884368896484,0,349.884262084961,,,,,,,,,,,,,,,,,,,,,,,,,,,,,,,,,
,3877826456.32382,350.006286621094,2799.70336914062,-2.35853840357239E-5,3.25912052765602E-8,1,4,13.4005146026611,4.9977587578788,33.1399999558926,-0.029332777730987,-0.00414429979098946,1,1.9189668933431E-7,,,,,,,,,,,,,,,,,,,,,349.993377685547,350.019195556641,2799.70336914062,2799.70336914062,53.5861063929095,5.63951587825907,7.33184623718262,54,1,0,0,1,0.297088623046875,35.190616607666,1,1,3,350.019195556641,0,350.006286621094,,,,,,,,,,,,,,,,,,,,,,,,,,,,,,,,,
,3877826514.71317,350.078704833984,2599.63842773438,-2.20322162739221E-5,1.72963224746564E-8,1,4,13.4005146026611,4.99774048580543,33.1399999558926,-0.0274100274824746,-0.00381093016680304,1,2.27912890835182E-7,,,,,,,,,,,,,,,,,,,,,350.067718505859,350.089691162109,2599.63842773438,2599.63842773438,53.594704306621,5.639397173368,7.33226346969604,53,1,68,0,0,0.296478271484375,35.190616607666,1,1,3,350.089691162109,0,350.078704833984,,,,,,,,,,,,,,,,,,,,,,,,,,,,,,,,,
,3877826572.78972,350.261154174805,2399.62329101562,-2.04065500558312E-5,2.00362532218987E-8,1,4,13.4005146026611,4.99777722026714,33.1399999558926,-0.025387373746766,-0.0035327303174321,1,2.0871595078917E-7,,,,,,,,,,,,,,,,,,,,,350.251434326172,350.270874023438,2399.62329101562,2399.62329101562,53.5739911508614,5.63971230121297,7.33314085006714,54,1,0,0,1,0.29693603515625,35.190616607666,1,1,3,350.270874023438,0,350.261154174805,,,,,,,,,,,,,,,,,,,,,,,,,,,,,,,,,
,3877826631.40218,350.108840942383,2199.55834960938,-1.87958521002814E-5,1.79322882937403E-8,1,4,13.4005146026611,4.99775662353936,33.1399999558926,-0.0233921127605099,-0.00319564402447634,1,2.39117517353836E-7,,,,,,,,,,,,,,,,,,,,,350.097076416016,350.12060546875,2199.55834960938,2199.55834960938,53.6244061903518,5.63898991832093,7.33634328842163,54,1,0,0,1,0.296096801757812,35.190616607666,1,1,3,350.097076416016,0,350.108840942383,,,,,,,,,,,,,,,,,,,,,,,,,,,,,,,,,
,3877826690.84601,349.993728637695,1999.68200683594,-1.7194645222389E-5,1.79729363691131E-8,1,4,13.4005146026611,4.99779919555471,33.1399999558926,-0.0213994040177541,-0.00292481097003002,1,2.1764676949259E-7,,,,,,,,,,,,,,,,,,,,,349.986175537109,350.001281738281,1999.68200683594,1999.68200683594,53.6369122466595,5.63937088054782,7.33903503417969,54,1,0,0,1,0.297622680664063,35.190616607666,1,1,3,350.001281738281,0,349.993728637695,,,,,,,,,,,,,,,,,,,,,,,,,,,,,,,,,
,3877826748.43583,350.07177734375,1799.73022460938,-1.55704126240985E-5,2.00060970036681E-8,1,4,13.4005146026611,4.99776719260478,33.1399999558926,-0.0193821828879046,-0.00261927152355368,1,2.20621687140658E-7,,,,,,,,,,,,,,,,,,,,,350.055450439453,350.088104248047,1799.73022460938,1799.73022460938,53.6806834437364,5.63877058724666,7.34085512161255,54,1,0,0,1,0.297775268554687,36.6568908691406,1,1,3,350.089172363281,0,350.07177734375,,,,,,,,,,,,,,,,,,,,,,,,,,,,,,,,,
,3877826808.4946,349.993499755859,1599.76574707031,-1.39735686944827E-5,2.27689655853528E-8,1,4,13.4005146026611,4.99774458238966,33.1399999558926,-0.0173980199407734,-0.00232581855231741,1,2.1797294420163E-7,,,,,,,,,,,,,,,,,,,,,349.981018066406,350.005981445313,1599.76574707031,1599.76574707031,53.5755544078999,5.63870451245894,7.34109258651733,53,1,68,0,0,0.297317504882812,35.190616607666,1,1,3,349.981018066406,0,349.993499755859,,,,,,,,,,,,,,,,,,,,,,,,,,,,,,,,,
,3877826898.13849,349.852294921875,1399.7509765625,-1.23372614979217E-5,2.24119722856559E-8,1,4,13.4005146026611,4.99785877519206,33.1399999558926,-0.0153769049678415,-0.00194854848366379,1,2.76960745869511E-7,,,,,,,,,,,,,,,,,,,,,349.843170166016,349.861419677734,1399.7509765625,1399.7509765625,53.5931410495826,5.6393899514718,7.34164714813232,52,1,68,0,0,0.296096801757812,35.190616607666,1,1,3,349.861419677734,0,349.852294921875,,,,,,,,,,,,,,,,,,,,,,,,,,,,,,,,,
,3877826955.87349,350.03434753418,1199.69848632812,-1.07106163873762E-5,2.36548479637153E-8,1,4,13.4005146026611,4.99780533771385,33.1399999558926,-0.0133492932655053,-0.0016915798786701,1,2.40468754258071E-7,,,,,,,,,,,,,,,,,,,,,350.021606445313,350.047088623047,1199.69848632812,1199.69848632812,53.5118516835826,5.63958330965174,7.34491157531738,53,1,68,0,0,0.296859741210937,35.190616607666,1,1,3,350.047088623047,0,350.03434753418,,,,,,,,,,,,,,,,,,,,,,,,,,,,,,,,,
,3877827047.52605,349.943878173828,999.935424804687,-9.02218069696182E-6,2.21126303371637E-8,1,4,13.4005146026611,4.99773622080421,33.1399999558926,-0.0112524908574945,-0.00137264461362292,1,2.44620413113495E-7,,,,,,,,,,,,,,,,,,,,,349.942687988281,349.945068359375,999.935424804687,999.935424804687,53.613072576823,5.63945830699375,7.34597396850586,54,1,0,0,1,0.296173095703125,35.190616607666,1,1,3,349.945068359375,0,349.943878173828,,,,,,,,,,,,,,,,,,,,,,,,,,,,,,,,,
,3877827129.14364,349.825790405273,799.845153808594,-7.32671579469977E-6,2.56852684114226E-8,1,4,13.4005146026611,4.99770685563589,33.1399999558926,-0.00914516383884246,-0.00106563893967441,10,2.38135982823368E-7,,,,,,,,,,,,,,,,,,,,,349.809906005859,349.841674804687,799.845153808594,799.845153808594,53.5911869782845,5.63949807357246,7.34755659103394,54,1,0,0,1,0.303268432617188,35.190616607666,1,1,3,349.841674804687,0,349.825790405273,,,,,,,,,,,,,,,,,,,,,,,,,,,,,,,,,
,3877827196.53303,349.979080200195,599.956176757812,-5.59088973299897E-6,9.78320762357318E-8,1,4,13.4005146026611,4.99767317030067,33.1399999558926,-0.00697849057901831,-8.12891928727354E-4,1,1.81935599546633E-7,,,,,,,,,,,,,,,,,,,,,349.978088378906,349.980072021484,599.956176757812,599.956176757812,53.6212796762749,5.63931441687816,7.35060977935791,54,1,0,0,1,0.302734375,35.190616607666,1,1,3,349.978088378906,0,349.979080200195,,,,,,,,,,,,,,,,,,,,,,,,,,,,,,,,,
,3877827271.72254,350.088684082031,400.054748535156,-3.74270031883038E-6,6.11587930156575E-8,1,4,13.4005146026611,4.99769037322767,33.1399999558926,-0.00470419841797587,-3.26411351942069E-4,1,2.97105342574099E-7,,,,,,,,,,,,,,,,,,,,,350.086090087891,350.091278076172,400.054748535156,400.054748535156,53.5036445841307,5.63942025750933,7.34804391860962,54,1,0,0,1,0.298233032226562,35.190616607666,1,1,3,350.086090087891,0,350.088684082031,,,,,,,,,,,,,,,,,,,,,,,,,,,,,,,,,
,3877827345.86921,349.753616333008,200.27912902832,-1.9035956157181E-6,2.58486052557734E-8,1,4,13.4005146026611,4.9976957927246,33.1399999558926,-0.00241332261133139,-2.77071714628411E-5,1,2.62460376747062E-7,,,,,,,,,,,,,,,,,,,,,349.750793457031,349.756439208984,200.27912902832,200.27912902832,53.5591402089961,5.63915937252882,7.34908437728882,54,1,0,0,1,0.296478271484375,34.7018585205078,1,1,3,349.756439208984,0,349.753616333008,,,,,,,,,,,,,,,,,,,,,,,,,,,,,,,,,
,3877827406.06394,349.803131103516,0.214000344276428,1.69084799156239E-7,1.06258454762571E-8,1,4,13.4005146026611,4.99775490901947,33.1399999558926,1.83768831311268E-4,2.06984631540781E-4,1,1.41337263032638E-7,,,,,,,,,,,,,,,,,,,,,349.797332763672,349.808929443359,0.214000344276428,0.214000344276428,53.5626575373326,5.63945843700291,7.35358142852783,53,1,68,0,0,0.3033447265625,34.7018585205078,1,1,3,349.809753417969,0,349.803131103516,,,,,,,,,,,,,,,,,,,,,,,,,,,,,,,,,
,3877827480.41561,349.977478027344,-199.750427246094,2.17745359172111E-6,2.0637810052796E-8,1,4,13.4005146026611,4.99775875185576,33.1399999558926,0.00267039494229459,6.34428850231633E-4,1,1.8500762991171E-7,,,,,,,,,,,,,,,,,,,,,349.975219726562,349.979736328125,-199.750427246094,-199.750427246094,53.6173715336788,5.63962643552743,7.35629034042358,54,1,0,0,1,0.297317504882812,34.7018585205078,1,1,3,349.979736328125,0,349.977478027344,,,,,,,,,,,,,,,,,,,,,,,,,,,,,,,,,
,3877827537.94542,350.010025024414,-399.777801513672,4.10017338261582E-6,6.00171722378648E-8,1,4,13.4005146026611,4.99769064851712,33.1399999558926,0.00505911783978378,9.88554189795893E-4,1,1.82481213528698E-7,,,,,,,,,,,,,,,,,,,,,350.006256103516,350.013793945313,-399.777801513672,-399.777801513672,53.5509331095441,5.63945221878808,7.34952974319458,54,1,0,0,1,0.2972412109375,34.7018585205078,1,1,3,350.013793945313,0,350.010025024414,,,,,,,,,,,,,,,,,,,,,,,,,,,,,,,,,
,3877827596.54757,349.810913085937,-599.729675292969,5.8557182825237E-6,1.68539213729917E-8,1,4,13.4005146026611,4.99771030912944,33.1399999558926,0.00724519177719367,0.00127877021891984,1,1.5349711654875E-7,,,,,,,,,,,,,,,,,,,,,349.801300048828,349.820526123047,-599.729675292969,-599.729675292969,53.5466341526884,5.63950961370514,7.35379791259766,54,1,0,0,1,0.297698974609375,34.7018585205078,1,1,3,349.801300048828,0,349.810913085937,,,,,,,,,,,,,,,,,,,,,,,,,,,,,,,,,
,3877827654.21803,349.877777099609,-799.757019042969,7.62108896880047E-6,1.71225598520309E-8,1,4,13.4005146026611,4.99774720243038,33.1399999558926,0.00943199402251282,0.001648009077215,1,1.86651299894345E-7,,,,,,,,,,,,,,,,,,,,,349.870758056641,349.884796142578,-799.757019042969,-799.757019042969,53.6416020177749,5.63939815296741,7.35207986831665,52,1,68,0,0,0.29693603515625,34.7018585205078,1,1,3,349.884796142578,0,349.877777099609,,,,,,,,,,,,,,,,,,,,,,,,,,,,,,,,,
,3877827729.09305,349.781127929687,-999.507385253906,9.27963975740647E-6,4.27324934985331E-8,1,4,13.4005146026611,4.9977780145229,33.1399999558926,0.0114964291656805,0.0019285697961421,1,1.64392546097238E-7,,,,,,,,,,,,,,,,,,,,,349.7705078125,349.791748046875,-999.507385253906,-999.507385253906,53.5478065954672,5.63941511424136,7.35688018798828,53,1,68,0,0,0.30364990234375,35.190616607666,1,1,3,349.7705078125,0,349.781127929687,,,,,,,,,,,,,,,,,,,,,,,,,,,,,,,,,
,3877827788.32873,349.958267211914,-1199.54748535156,1.10036852622609E-5,4.04015392160144E-8,1,4,13.4005146026611,4.99773223110296,33.1399999558926,0.0136449031998452,0.00220161113327866,1,1.26316990026901E-7,,,,,,,,,,,,,,,,,,,,,349.957733154297,349.958801269531,-1199.54748535156,-1199.54748535156,53.5728187080826,5.6395514017312,7.35585594177246,54,1,0,0,1,0.297775268554687,34.7018585205078,1,1,3,349.958801269531,0,349.958267211914,,,,,,,,,,,,,,,,,,,,,,,,,,,,,,,,,
,3877827855.57643,349.952499389648,-1399.5244140625,1.26320530643645E-5,1.14668402847743E-8,1,4,13.4005146026611,4.99770477577159,33.1399999558926,0.0156641703558443,0.00252631029556238,10,1.44136938692575E-7,,,,,,,,,,,,,,,,,,,,,349.938201904297,349.966796875,-1399.5244140625,-1399.5244140625,53.486057942448,5.63959038009124,7.355628490448,54,1,0,0,1,0.303878784179687,34.7018585205078,1,1,3,349.966796875,0,349.952499389648,,,,,,,,,,,,,,,,,,,,,,,,,,,,,,,,,
,3877827924.23396,349.865768432617,-1599.71545410156,1.42537995117738E-5,7.1961032941577E-8,1,4,13.4005146026611,4.99768915464253,33.1399999558926,0.0176925194392629,0.0027342769757226,1,6.89675394240044E-8,,,,,,,,,,,,,,,,,,,,,349.848785400391,349.882751464844,-1599.71545410156,-1599.71545410156,53.5020813270922,5.63944567006075,7.35547542572022,52,1,68,0,0,0.297164916992188,35.190616607666,1,1,3,349.882751464844,0,349.865768432617,,,,,,,,,,,,,,,,,,,,,,,,,,,,,,,,,
,3877827984.98972,349.831146240234,-1799.50354003906,1.58597977985604E-5,1.16835159096242E-8,1,4,13.4005146026611,4.99771347837417,33.1399999558926,0.0196775851204149,0.00309927908593153,1,1.22550501532367E-7,,,,,,,,,,,,,,,,,,,,,349.827117919922,349.835174560547,-1799.50354003906,-1799.50354003906,53.5732095223422,5.63959941095258,7.35889291763306,54,1,0,0,1,0.296859741210937,35.190616607666,1,1,3,349.827117919922,0,349.831146240234,,,,,,,,,,,,,,,,,,,,,,,,,,,,,,,,,
,3877828043.8273,349.8251953125,-1999.56872558594,1.74496050958156E-5,2.47535222468617E-8,1,4,13.4005146026611,4.99769738262357,33.1399999558926,0.0216585511829345,0.00335274279223942,1,8.87885708054004E-8,,,,,,,,,,,,,,,,,,,,,349.815612792969,349.834777832031,-1999.56872558594,-1999.56872558594,53.552105552323,5.6395108577281,7.35677671432495,54,1,0,0,1,0.298233032226562,34.7018585205078,1,1,3,349.834777832031,0,349.8251953125,,,,,,,,,,,,,,,,,,,,,,,,,,,,,,,,,
,3877828102.72005,349.787368774414,-2199.58349609375,1.90668813043251E-5,2.10455077314431E-8,1,4,13.4005146026611,4.99764621263105,33.1399999558926,0.023666614842808,0.00365654432826943,1,9.14731237726818E-8,,,,,,,,,,,,,,,,,,,,,349.770080566406,349.804656982422,-2199.58349609375,-2199.58349609375,53.572427893823,5.63952243702125,7.35564613342285,54,1,0,0,1,0.297088623046875,34.7018585205078,1,1,3,349.804656982422,0,349.787368774414,,,,,,,,,,,,,,,,,,,,,,,,,,,,,,,,,
,3877828160.18158,349.858337402344,-2399.5478515625,2.06826314563784E-5,7.53392164217393E-9,1,4,13.4005146026611,4.99769498704693,33.1399999558926,0.0256792165926927,0.00392157726173464,1,6.30928362305163E-8,,,,,,,,,,,,,,,,,,,,,349.846313476562,349.870361328125,-2399.5478515625,-2399.5478515625,53.6521540027845,5.63923272688505,7.3598952293396,54,1,0,0,1,0.297088623046875,34.7018585205078,1,1,3,349.870361328125,0,349.858337402344,,,,,,,,,,,,,,,,,,,,,,,,,,,,,,,,,
,3877828219.88427,349.774612426758,-2599.53759765625,2.22717004753675E-5,6.93531380951952E-9,1,4,13.4005146026611,4.99769048223815,33.1399999558926,0.0276540770791955,0.00420994727643345,1,5.75360248558708E-8,,,,,,,,,,,,,,,,,,,,,349.768890380859,349.780334472656,-2599.53759765625,-2599.53759765625,53.6279235186884,5.63909912159594,7.35541725158691,54,1,0,0,1,0.296707153320313,34.7018585205078,1,1,3,349.780334472656,0,349.774612426758,,,,,,,,,,,,,,,,,,,,,,,,,,,,,,,,,
,3877828279.56919,349.850875854492,-2799.5146484375,2.38384008131357E-5,8.64998841643277E-9,1,4,13.4005146026611,4.99774486513026,33.1399999558926,0.0296011783554913,0.00449729141839774,1,5.44404043792553E-8,,,,,,,,,,,,,,,,,,,,,349.839263916016,349.862487792969,-2799.5146484375,-2799.5146484375,53.5095067980249,5.63929368143758,7.36366176605225,54,1,0,0,1,0.29815673828125,34.2131004333496,1,1,3,349.86376953125,0,349.850875854492,,,,,,,,,,,,,,,,,,,,,,,,,,,,,,,,,
,3877828340.2445,350.049240112305,-2999.6552734375,2.54173414388511E-5,1.4659542921955E-8,1,4,13.4005146026611,4.99773332132175,33.1399999558926,0.0315633317027888,0.00478435079642414,1,4.93485522301533E-8,,,,,,,,,,,,,,,,,,,,,350.0419921875,350.056488037109,-2999.6552734375,-2999.6552734375,53.5798533647557,5.6392329342744,7.36394071578979,54,1,0,0,1,0.29693603515625,34.7018585205078,1,1,3,350.041778564453,0,350.049240112305,,,,,,,,,,,,,,,,,,,,,,,,,,,,,,,,,
,3877828420.18777,349.903762817383,-4499.7724609375,3.70593761180033E-5,7.19336167275972E-9,1,4,13.4005146026611,4.99776226154175,33.1399999558926,0.0460484738059456,0.0067909405014925,1,-7.68738381129004E-8,,,,,,,,,,,,,,,,,,,,,349.897918701172,349.909606933594,-4499.7724609375,-4499.7724609375,53.6119001340441,5.63931072399083,7.35820960998535,54,1,0,0,1,0.29693603515625,35.190616607666,1,1,3,349.909606933594,0,349.903762817383,,,,,,,,,,,,,,,,,,,,,,,,,,,,,,,,,
,3877828487.13585,349.892562866211,-6499.66845703125,5.10214280378484E-5,9.03878079930892E-9,1,4,13.4005146026611,4.99774473931324,33.1399999558926,0.0633956985929346,0.00935700300850372,1,-9.96901831618834E-8,,,,,,,,,,,,,,,,,,,,,349.88525390625,349.899871826172,-6499.66845703125,-6499.66845703125,53.5806349932749,5.63922344220864,7.36458396911621,54,1,0,0,1,0.303802490234375,34.7018585205078,1,1,3,349.88525390625,0,349.892562866211,,,,,,,,,,,,,,,,,,,,,,,,,,,,,,,,,
,3877828553.47591,349.93049621582,-8499.6025390625,6.42550834585342E-5,1.15049956749089E-8,1,4,13.4005146026611,4.99776059751324,33.1399999558926,0.0798399899341989,0.0117792668331106,1,-1.29376156649871E-7,,,,,,,,,,,,,,,,,,,,,349.91748046875,349.943511962891,-8499.6025390625,-8499.6025390625,53.6439469033326,5.63945131066574,7.36473083496094,54,1,0,0,1,0.296401977539063,34.2131004333496,1,1,3,349.943511962891,0,349.93049621582,,,,,,,,,,,,,,,,,,,,,,,,,,,,,,,,,
,3877828635.00809,349.93896484375,-9999.669921875,7.40971815816746E-5,1.45556710538532E-8,1,4,13.4005146026611,4.99776716770751,33.1399999558926,0.0920634798600517,0.0136233463477189,1,-1.17154639579201E-7,,,,,,,,,,,,,,,,,,,,,349.937774658203,349.940155029297,-9999.669921875,-9999.669921875,53.5071619124672,5.63943528976949,7.35982322692871,54,1,0,0,1,0.303268432617188,34.7018585205078,1,1,3,349.940155029297,0,349.93896484375,,,,,,,,,,,,,,,,,,,,,,,,,,,,,,,,,
,3877828791.47889,349.906921386719,-29999.638671875,2.0562683857275E-4,3.41778915146257E-8,1,4,13.4005146026611,4.99774229052505,33.1399999558926,0.255468474230674,0.0379047579255528,1,-2.45481294855613E-7,,,,,,,,,,,,,,,,,,,,,349.905120849609,349.908721923828,-29999.638671875,-29999.638671875,53.5052078411691,5.63921728780803,7.36080408096313,54,1,0,0,1,0.29693603515625,34.7018585205078,1,1,3,349.908721923828,0,349.906921386719,,,,,,,,,,,,,,,,,,,,,,,,,,,,,,,,,
,3877828958.76464,349.86799621582,-49999.6015625,3.37408971676983E-4,7.64585617532066E-8,1,4,13.4005146026611,4.99768668526014,33.1399999558926,0.419230307940909,0.0619039225509225,10,-6.38098405921185E-7,,,,,,,,,,,,,,,,,,,,,349.85546875,349.880523681641,-49999.6015625,-49999.6015625,53.4375969742557,5.63949275504866,7.36652088165283,54,1,0,0,1,0.29541015625,35.190616607666,1,1,3,349.880523681641,0,349.86799621582,,,,,,,,,,,,,,,,,,,,,,,,,,,,,,,,,
,3877829143.23772,350.19206237793,-69999.7890625,4.68853426327732E-4,1.56406439085682E-7,1,4,13.4005146026611,4.99769564388733,33.1399999558926,0.582442395533489,0.0867485435484379,1,-3.00210653900861E-7,,,,,,,,,,,,,,,,,,,,,350.177581787109,350.20654296875,-69999.7890625,-69999.7890625,53.6572345881595,5.63891955446293,7.36553525924683,53,1,68,0,0,0.297012329101562,34.7018585205078,1,1,3,350.20654296875,0,350.19206237793,,,,,,,,,,,,,,,,,,,,,,,,,,,,,,,,,
,3877829303.36684,349.976089477539,-49999.62890625,3.36997842024163E-4,6.56669177839331E-8,1,4,13.4005146026611,4.99771029217163,33.1399999558926,0.418637335521271,0.0623965274955497,1,-1.80352917650389E-7,,,,,,,,,,,,,,,,,,,,,349.963775634766,349.988403320313,-49999.62890625,-49999.62890625,53.8119970349672,5.63917385853749,7.36368179321289,54,1,0,0,1,0.296859741210937,34.7018585205078,1,1,3,349.988403320313,0,349.976089477539,,,,,,,,,,,,,,,,,,,,,,,,,,,,,,,,,
,3877829464.14524,349.825622558594,-29999.763671875,2.05371210175115E-4,3.74347725335035E-8,1,4,13.4005146026611,4.99776969539372,33.1399999558926,0.255132910131958,0.0379911741451712,1,-1.37906726511817E-7,,,,,,,,,,,,,,,,,,,,,349.822418212891,349.828826904297,-29999.763671875,-29999.763671875,54.019519406823,5.63956186129702,7.36321353912354,54,1,0,0,1,0.296630859375,35.190616607666,1,1,3,349.828826904297,0,349.825622558594,,,,,,,,,,,,,,,,,,,,,,,,,,,,,,,,,
,3877829621.16298,349.916580200195,-9999.732421875,7.38017389105103E-5,1.36790517714268E-8,1,4,13.4005146026611,4.99776069097415,33.1399999558926,0.0916818285335994,0.0136653062942447,1,-3.91588756734355E-8,,,,,,,,,,,,,,,,,,,,,349.903228759766,349.929931640625,-9999.732421875,-9999.732421875,53.5427260100922,5.63962904681254,7.36629199981689,54,1,0,0,1,0.296859741210937,35.190616607666,1,1,3,349.929931640625,0,349.916580200195,,,,,,,,,,,,,,,,,,,,,,,,,,,,,,,,,
,3877829699.08976,350.020690917969,-8500.04296875,6.39320142479225E-5,1.1613134743794E-8,1,4,13.4005146026611,4.99772673344352,33.1399999558926,0.0794198689184216,0.0118398459833187,1,-3.21878945548171E-8,,,,,,,,,,,,,,,,,,,,,350.018829345703,350.022552490234,-8500.04296875,-8500.04296875,53.5653932371499,5.63930253394504,7.36570072174072,54,1,0,0,1,0.297088623046875,35.190616607666,1,1,3,350.022552490234,0,350.020690917969,,,,,,,,,,,,,,,,,,,,,,,,,,,,,,,,,
,3877829764.32682,349.697601318359,-6500.02099609375,5.07618383850133E-5,1.11442302252455E-8,1,4,13.4005146026611,4.99777695675582,33.1399999558926,0.063056684332473,0.00942335724004726,1,-7.50754375342372E-9,,,,,,,,,,,,,,,,,,,,,349.695007324219,349.7001953125,-6500.02099609375,-6500.02099609375,53.5614850945537,5.63962608209199,7.36537504196167,54,1,0,0,1,0.296554565429687,34.7018585205078,1,1,3,349.7001953125,0,349.697601318359,,,,,,,,,,,,,,,,,,,,,,,,,,,,,,,,,
,3877829829.26937,349.994171142578,-4500.02392578125,3.67119555891373E-5,8.88663162709935E-9,1,4,13.4005146026611,4.99776762508102,33.1399999558926,0.0456036763146613,0.00681536210862719,1,-5.24973273794612E-9,,,,,,,,,,,,,,,,,,,,,349.990325927734,349.998016357422,-4500.02392578125,-4500.02392578125,53.5497606667653,5.63921023835162,7.36745548248291,54,1,0,0,1,0.29754638671875,35.190616607666,1,1,3,349.998016357422,0,349.994171142578,,,,,,,,,,,,,,,,,,,,,,,,,,,,,,,,,
,3877829902.4174,349.918807983398,-3000.07080078125,2.51120539093139E-5,9.76088610533794E-9,1,4,13.4005146026611,4.9977751727847,33.1399999558926,0.0312020861270804,0.00460998600741168,1,-4.53976383948666E-8,,,,,,,,,,,,,,,,,,,,,349.918365478516,349.919250488281,-3000.07080078125,-3000.07080078125,53.5923594210634,5.6396971096845,7.36630487442017,54,1,0,0,1,0.297164916992188,35.190616607666,1,1,3,349.919250488281,0,349.918807983398,,,,,,,,,,,,,,,,,,,,,,,,,,,,,,,,,
,3877829959.60895,349.776809692383,-2800.16918945313,2.35880684409218E-5,1.61371663522492E-8,1,4,13.4005146026611,4.99774144053543,33.1399999558926,0.0293377381246667,0.00413295843322198,1,-2.01412378053752E-7,,,,,,,,,,,,,,,,,,,,,349.769989013672,349.783630371094,-2800.16918945313,-2800.16918945313,53.6595794737172,5.63950801668074,7.36275672912598,54,1,0,0,1,0.297393798828125,34.7018585205078,1,1,3,349.769989013672,0,349.776809692383,,,,,,,,,,,,,,,,,,,,,,,,,,,,,,,,,
,3877830015.48316,349.748443603516,-2600.31811523438,2.2001924216221E-5,1.6604395454465E-8,1,4,13.4005146026611,4.99773979391436,33.1399999558926,0.0273753976020787,0.00378522486563069,1,-2.44074723867697E-7,,,,,,,,,,,,,,,,,,,,,349.738189697266,349.758697509766,-2600.31811523438,-2600.31811523438,53.5896237212461,5.63981750063003,7.36620473861694,53,1,68,0,0,0.296249389648438,35.190616607666,1,1,3,349.738189697266,0,349.748443603516,,,,,,,,,,,,,,,,,,,,,,,,,,,,,,,,,
,3877830072.33763,349.988494873047,-2400.29052734375,2.03930016066054E-5,1.89126607960859E-8,1,4,13.4005146026611,4.99773008095696,33.1399999558926,0.0253721374200295,0.00351727593329418,1,-2.19093145067685E-7,,,,,,,,,,,,,,,,,,,,,349.983825683594,349.9931640625,-2400.29052734375,-2400.29052734375,53.6654416876114,5.63963554754454,7.36590528488159,53,1,68,0,0,0.296630859375,36.1681327819824,1,1,3,349.9931640625,0,349.988494873047,,,,,,,,,,,,,,,,,,,,,,,,,,,,,,,,,
,3877830129.03323,349.9013671875,-2200.26318359375,1.8810582308237E-5,1.62809940164673E-8,1,4,13.4005146026611,4.99775079330218,33.1399999558926,0.023405285406841,0.00323237852510051,1,-2.11744016663773E-7,,,,,,,,,,,,,,,,,,,,,349.899688720703,349.903045654297,-2200.26318359375,-2200.26318359375,53.5923594210634,5.63959252971832,7.36804056167603,54,1,0,0,1,0.296859741210937,35.190616607666,1,1,3,349.903045654297,0,349.9013671875,,,,,,,,,,,,,,,,,,,,,,,,,,,,,,,,,
,3877830185.69929,349.996566772461,-2000.26110839844,1.71937358204512E-5,1.89049589016565E-8,1,4,13.4005146026611,4.99777274784319,33.1399999558926,0.021396593661126,0.00293479572171561,1,-2.0945518076605E-7,,,,,,,,,,,,,,,,,,,,,349.986541748047,350.006591796875,-2000.26110839844,-2000.26110839844,53.5767268506787,5.63941558317963,7.36685132980347,53,1,68,0,0,0.29693603515625,35.190616607666,1,1,3,349.986541748047,0,349.996566772461,,,,,,,,,,,,,,,,,,,,,,,,,,,,,,,,,
,3877830241.9098,349.93913269043,-1799.95678710938,1.55725200735961E-5,1.93893561488116E-8,1,4,13.4005146026611,4.9977650679389,33.1399999558926,0.019383182934745,0.00263039890272678,1,-2.11977712277916E-7,,,,,,,,,,,,,,,,,,,,,349.928558349609,349.94970703125,-1799.95678710938,-1799.95678710938,53.5001272557941,5.63919150365203,7.36870527267456,53,1,68,0,0,0.297088623046875,34.7018585205078,1,1,3,349.94970703125,0,349.93913269043,,,,,,,,,,,,,,,,,,,,,,,,,,,,,,,,,
,3877830299.27642,349.935363769531,-1600.130859375,1.39630438216347E-5,1.96490957453758E-8,1,4,13.4005146026611,4.99776465751443,33.1399999558926,0.0173887661912404,0.00229899423001543,1,-2.38003662811905E-7,,,,,,,,,,,,,,,,,,,,,349.931945800781,349.938781738281,-1600.130859375,-1600.130859375,53.5681289369672,5.6393663767431,7.36413955688477,53,1,68,0,0,0.298614501953125,35.190616607666,1,1,3,349.938781738281,0,349.935363769531,,,,,,,,,,,,,,,,,,,,,,,,,,,,,,,,,
,3877830357.4787,349.866012573242,-1400.07836914062,1.23655017059087E-5,1.8347229919553E-8,1,4,13.4005146026611,4.9977612039246,33.1399999558926,0.0154012688652898,0.0020225629994644,1,-2.21557749623885E-7,,,,,,,,,,,,,,,,,,,,,349.858093261719,349.873931884766,-1400.07836914062,-1400.07836914062,53.6033022203326,5.63941045525273,7.36452150344849,54,1,0,0,1,0.297317504882812,34.7018585205078,1,1,3,349.858093261719,0,349.866012573242,,,,,,,,,,,,,,,,,,,,,,,,,,,,,,,,,
,3877830430.78985,349.650543212891,-1200.10119628906,1.0717856454101E-5,2.47249897334091E-8,1,4,13.4005146026611,4.99771884142035,33.1399999558926,0.0133607940663047,0.00167396008788079,1,-2.55703641399285E-7,,,,,,,,,,,,,,,,,,,,,349.647186279297,349.653900146484,-1200.10119628906,-1200.10119628906,53.5888420927268,5.6398326385462,7.36418056488037,52,1,68,0,0,0.296859741210937,34.7018585205078,1,1,3,349.653900146484,0,349.650543212891,,,,,,,,,,,,,,,,,,,,,,,,,,,,,,,,,
,3877830487.93021,349.853286743164,-999.998352050781,9.03221236036166E-6,2.78257658360049E-8,1,4,13.4005146026611,4.99777439037213,33.1399999558926,0.011265276107154,0.00137316089861733,1,-2.4571727477664E-7,,,,,,,,,,,,,,,,,,,,,349.846252441406,349.860321044922,-999.998352050781,-999.998352050781,53.6247970046114,5.63999565690019,7.36613082885742,53,1,68,0,0,0.303878784179687,35.190616607666,1,1,3,349.860321044922,0,349.853286743164,,,,,,,,,,,,,,,,,,,,,,,,,,,,,,,,,
,3877830545.70976,349.998840332031,-800.184997558594,7.31086777875492E-6,2.22379298922368E-8,1,4,13.4005146026611,4.99773113810974,33.1399999558926,0.00912232249623533,0.00108421109207832,1,-2.20819591829758E-7,,,,,,,,,,,,,,,,,,,,,349.985870361328,350.011810302734,-800.184997558594,-800.184997558594,53.4891844565249,5.63986952931635,7.36496210098267,54,1,0,0,1,0.297012329101562,34.7018585205078,1,1,3,350.011810302734,0,349.998840332031,,,,,,,,,,,,,,,,,,,,,,,,,,,,,,,,,
,3877830603.67221,349.986785888672,-600.157592773437,5.57502124482469E-6,2.47079554978049E-8,1,4,13.4005146026611,4.99774525671358,33.1399999558926,0.00696661291433926,7.58535473738093E-4,1,-2.23334330454316E-7,,,,,,,,,,,,,,,,,,,,,349.984832763672,349.988739013672,-600.157592773437,-600.157592773437,53.6158082766403,5.63995104949864,7.36722421646118,53,1,68,0,0,0.296554565429687,35.190616607666,1,1,3,349.988739013672,0,349.986785888672,,,,,,,,,,,,,,,,,,,,,,,,,,,,,,,,,
,3877830668.26076,350.181213378906,-400.205810546875,3.82196761294172E-6,2.35046137548861E-8,1,4,13.4005146026611,4.99770778642524,33.1399999558926,0.00479375144194215,4.00851854339975E-4,10,-2.49036006494658E-7,,,,,,,,,,,,,,,,,,,,,350.167846679687,350.194580078125,-400.205810546875,-400.205810546875,53.6083828057076,5.64010677040573,7.36690711975098,54,1,0,0,1,0.296478271484375,35.190616607666,1,1,3,350.194580078125,0,350.181213378906,,,,,,,,,,,,,,,,,,,,,,,,,,,,,,,,,
,3877830733.98728,350.010314941406,-200.065139770508,1.92179431205395E-6,2.81561050040728E-8,1,4,13.4005146026611,4.99769446232286,33.1399999558926,0.00242608817426444,9.68605890451171E-5,1,-2.09510437740945E-7,,,,,,,,,,,,,,,,,,,,,349.992706298828,350.027923583984,-200.065139770508,-200.065139770508,53.6173715336788,5.63944996126954,7.36596918106079,53,1,68,0,0,0.2972412109375,35.190616607666,1,1,3,349.992706298828,0,350.010314941406,,,,,,,,,,,,,,,,,,,,,,,,,,,,,,,,,
,3877830807.60198,349.803298950195,-0.100706040859222,-2.51788215326547E-7,1.06048193679942E-8,1,4,13.4005146026611,4.99770063933737,33.1399999558926,-3.08796332715504E-4,-7.32786875864846E-5,1,-2.13273466815371E-8,,,,,,,,,,,,,,,,,,,,,349.798278808594,349.808319091797,-0.100706040859222,-0.100706040859222,53.5685197512268,5.6399445713305,7.36562395095825,54,1,0,0,1,0.296554565429687,34.7018585205078,1,1,3,349.808319091797,0,349.803298950195,,,,,,,,,,,,,,,,,,,,,,,,,,,,,,,,,
,3877830865.29263,349.873229980469,199.788192749023,-1.50919495901512E-6,1.02697590129841E-6,1,4,13.4005146026611,4.99773508956946,33.1399999558926,-0.00168090883131168,-0.00157567567927202,1,-1.04272576421617E-6,,,,,,,,,,,,,,,,,,,,,349.872711181641,349.873748779297,199.788192749023,199.788192749023,53.6076011771884,5.63988325198261,7.36675930023193,54,1,0,0,1,0.303268432617188,34.7018585205078,1,1,3,349.873748779297,0,349.873229980469,,,,,,,,,,,,,,,,,,,,,,,,,,,,,,,,,
,3877830939.6798,349.801147460937,399.651916503906,-4.09144053241088E-6,2.63502977560357E-8,1,4,13.4005146026611,4.9977021479142,33.1399999558926,-0.00504879976945284,-9.83504240033489E-4,1,-1.79719549051719E-7,,,,,,,,,,,,,,,,,,,,,349.799774169922,349.802520751953,399.651916503906,399.651916503906,53.5993940777364,5.63989720068317,7.36534023284912,53,1,68,0,0,0.296630859375,34.7018585205078,1,1,3,349.802520751953,0,349.801147460937,,,,,,,,,,,,,,,,,,,,,,,,,,,,,,,,,
,3877831005.92411,349.835540771484,599.817810058594,-5.83100128066674E-6,1.32999838404876E-8,1,4,13.4005146026611,4.99773351680639,33.1399999558926,-0.00720661645560443,-0.00132712801821826,10,-1.96118224501414E-7,,,,,,,,,,,,,,,,,,,,,349.83251953125,349.838562011719,599.817810058594,599.817810058594,53.5044262126499,5.6397006663892,7.36770725250244,54,1,0,0,1,0.29754638671875,34.2131004333496,1,1,3,349.838562011719,0,349.835540771484,,,,,,,,,,,,,,,,,,,,,,,,,,,,,,,,,
,3877831072.51464,349.981964111328,799.543029785156,-7.5656189063578E-6,2.51735416635459E-8,1,4,13.4005146026611,4.99770356554175,33.1399999558926,-0.00935764686077121,-0.00167330827607364,1,-2.15332706396197E-7,,,,,,,,,,,,,,,,,,,,,349.974975585937,349.988952636719,799.543029785156,799.543029785156,53.6216704905345,5.64000614744954,7.36691617965698,52,1,68,0,0,0.296707153320313,35.190616607666,1,1,3,349.974975585937,0,349.981964111328,,,,,,,,,,,,,,,,,,,,,,,,,,,,,,,,,
,3877831130.25137,349.907852172852,999.708801269531,-9.28138426176533E-6,2.26214383528796E-8,1,4,13.4005146026611,4.99769583558348,33.1399999558926,-0.01150566466025,-0.00187982876144263,1,-1.24928094508493E-7,,,,,,,,,,,,,,,,,,,,,349.9072265625,349.908477783203,999.708801269531,999.708801269531,53.6388663179576,5.63983190484918,7.36346292495727,52,1,68,0,0,0.2972412109375,34.7018585205078,1,1,3,349.908477783203,0,349.907852172852,,,,,,,,,,,,,,,,,,,,,,,,,,,,,,,,,
,3877831187.91986,349.935852050781,1199.58520507812,-1.09317488188855E-5,3.80403260358678E-8,1,4,13.4005146026611,4.9976990896736,33.1399999558926,-0.0135549868325796,-0.00219112277063621,1,-1.28650990107471E-7,,,,,,,,,,,,,,,,,,,,,349.929840087891,349.941864013672,1199.58520507812,1199.58520507812,53.5802441790153,5.64009842044285,7.36940765380859,54,1,0,0,1,0.297393798828125,35.190616607666,1,1,3,349.941864013672,0,349.935852050781,,,,,,,,,,,,,,,,,,,,,,,,,,,,,,,,,
,3877831245.45199,349.904510498047,1399.72583007812,-1.26034489836836E-5,1.24193006672759E-8,1,4,13.4005146026611,4.99774384208622,33.1399999558926,-0.0156308352186443,-0.0025074894218966,1,-1.33242036323727E-7,,,,,,,,,,,,,,,,,,,,,349.901153564453,349.907867431641,1399.72583007812,1399.72583007812,53.6404295749961,5.63978682482618,7.36908912658691,54,1,0,0,1,0.296401977539063,34.7018585205078,1,1,3,349.907867431641,0,349.904510498047,,,,,,,,,,,,,,,,,,,,,,,,,,,,,,,,,
,3877831303.13833,349.962265014648,1599.60217285156,-1.42191793460832E-5,1.07374719737923E-8,1,4,13.4005146026611,4.99773851079906,33.1399999558926,-0.0176400993376788,-0.00279246147378273,1,-1.20957244260034E-7,,,,,,,,,,,,,,,,,,,,,349.948028564453,349.976501464844,1599.60217285156,1599.60217285156,53.6365214323999,5.63994667054153,7.37091493606567,54,1,0,0,1,0.296478271484375,34.7018585205078,1,1,3,349.976501464844,0,349.962265014648,,,,,,,,,,,,,,,,,,,,,,,,,,,,,,,,,
,3877831362.40203,349.987564086914,1799.83093261719,-1.58578303710645E-5,1.88761872376112E-8,1,4,13.4005146026611,4.99773463852979,33.1399999558926,-0.0196750769425036,-0.00310014148366929,1,-1.23524297089808E-7,,,,,,,,,,,,,,,,,,,,,349.986907958984,349.988220214844,1799.83093261719,1799.83093261719,53.6591886594576,5.63983089039029,7.36690473556519,54,1,0,0,1,0.296783447265625,34.7018585205078,1,1,3,349.988220214844,0,349.987564086914,,,,,,,,,,,,,,,,,,,,,,,,,,,,,,,,,
,3877831420.3333,349.983535766602,1999.85827636719,-1.74076043288277E-5,9.61849703900292E-8,1,4,13.4005146026611,4.9977407866551,33.1399999558926,-0.0216240479189236,-0.00322862834821546,1,4.8789183049452E-9,,,,,,,,,,,,,,,,,,,,,349.977386474609,349.989685058594,1999.85827636719,1999.85827636719,53.6009573347749,5.64009962053554,7.36728429794312,54,1,0,0,1,0.303955078125,34.7018585205078,1,1,3,349.989685058594,0,349.983535766602,,,,,,,,,,,,,,,,,,,,,,,,,,,,,,,,,
,3877831477.90558,349.894943237305,2199.78491210938,-1.90515243960294E-5,9.61313707844558E-9,1,4,13.4005146026611,4.99769306755004,33.1399999558926,-0.0236517678964522,-0.00362754787694394,1,-7.03880203628133E-8,,,,,,,,,,,,,,,,,,,,,349.892486572266,349.897399902344,2199.78491210938,2199.78491210938,53.569301379746,5.63978868924752,7.36388969421387,54,1,0,0,1,0.29693603515625,34.7018585205078,1,1,3,349.897399902344,0,349.894943237305,,,,,,,,,,,,,,,,,,,,,,,,,,,,,,,,,
,3877831535.67899,349.789031982422,2399.98852539062,-2.06720888541436E-5,7.67772596646906E-9,1,4,13.4005146026611,4.99773179710217,33.1399999558926,-0.0256648843269116,-0.00392969537366637,1,-7.11728528633377E-8,,,,,,,,,,,,,,,,,,,,,349.783081054687,349.794982910156,2399.98852539062,2399.98852539062,53.5950951208807,5.63994603168809,7.3681960105896,54,1,0,0,1,0.29754638671875,35.190616607666,1,1,3,349.794982910156,0,349.789031982422,,,,,,,,,,,,,,,,,,,,,,,,,,,,,,,,,
,3877831593.41475,350.022796630859,2599.78930664062,-2.22438826478332E-5,1.09793627179431E-8,1,4,13.4005146026611,4.99773018924555,33.1399999558926,-0.0276203783324472,-0.00420116228972886,1,-5.4587369945196E-8,,,,,,,,,,,,,,,,,,,,,350.004730224609,350.040863037109,2599.78930664062,2599.78930664062,53.6439469033326,5.63970374690464,7.36960363388062,54,1,0,0,1,0.296173095703125,35.190616607666,1,1,3,350.040863037109,0,350.022796630859,,,,,,,,,,,,,,,,,,,,,,,,,,,,,,,,,
,3877831651.0489,350.045181274414,2799.75390625,-2.3858551854217E-5,1.06023100542035E-8,1,4,13.4005146026611,4.99774364547619,33.1399999558926,-0.0296278984731493,-0.00448967517051267,1,-4.52957514563249E-8,,,,,,,,,,,,,,,,,,,,,350.041625976562,350.048736572266,2799.75390625,2799.75390625,53.5435076386114,5.64020899466041,7.36808109283447,54,1,0,0,1,0.303955078125,34.7018585205078,1,1,3,350.048736572266,0,350.045181274414,,,,,,,,,,,,,,,,,,,,,,,,,,,,,,,,,
,3877831708.64511,350.016296386719,2999.642578125,-2.54364149713763E-5,1.13424321968063E-8,1,4,13.4005146026611,4.99772355762716,33.1399999558926,-0.0315886973099114,-0.00477611977187414,1,-3.98794257154128E-8,,,,,,,,,,,,,,,,,,,,,350.011596679687,350.02099609375,2999.642578125,2999.642578125,53.6033022203326,5.63965700900261,7.36864709854126,54,1,0,0,1,0.29693603515625,34.7018585205078,1,1,3,350.02099609375,0,350.016296386719,,,,,,,,,,,,,,,,,,,,,,,,,,,,,,,,,
,3877831787.56595,350.000183105469,4499.6083984375,-3.70485585747501E-5,9.46592509874151E-9,1,4,13.4005146026611,4.99776299611119,33.1399999558926,-0.0460345770046275,-0.00679206695072895,1,7.43498883972665E-8,,,,,,,,,,,,,,,,,,,,,350.000152587891,350.000213623047,4499.6083984375,4499.6083984375,53.5880604642076,5.63972977776122,7.36953401565552,54,1,0,0,1,0.297698974609375,35.190616607666,1,1,3,350.000213623047,0,350.000183105469,,,,,,,,,,,,,,,,,,,,,,,,,,,,,,,,,
,3877831852.53385,349.832626342773,6499.744140625,-5.09967712012833E-5,1.24227649810587E-8,1,4,13.4005146026611,4.9977694402278,33.1399999558926,-0.0633671076588871,-0.0093418000694273,1,1.0829274803958E-7,,,,,,,,,,,,,,,,,,,,,349.827362060547,349.837890625,6499.744140625,6499.744140625,53.6244061903518,5.63981037320781,7.37044715881348,54,1,0,0,1,0.29693603515625,34.2131004333496,1,1,3,349.827362060547,0,349.832626342773,,,,,,,,,,,,,,,,,,,,,,,,,,,,,,,,,
,3877831917.56937,349.918045043945,8499.98046875,-6.42338267340424E-5,1.17310045758192E-8,1,4,13.4005146026611,4.9977142746817,33.1399999558926,-0.0798146665549423,-0.0117610135057559,1,1.40768090010503E-7,,,,,,,,,,,,,,,,,,,,,349.903625488281,349.932464599609,8499.98046875,8499.98046875,53.5990032634768,5.63996998987743,7.36849164962769,54,1,0,0,1,0.296630859375,34.7018585205078,1,1,3,349.932464599609,0,349.918045043945,,,,,,,,,,,,,,,,,,,,,,,,,,,,,,,,,
,3877831992.1389,349.83821105957,9999.9208984375,-7.40816762810611E-5,1.38611081112876E-8,1,4,13.4005146026611,4.99771821438228,33.1399999558926,-0.0920433132222309,-0.0136178993710162,1,1.19069833661531E-7,,,,,,,,,,,,,,,,,,,,,349.837524414063,349.838897705078,9999.9208984375,9999.9208984375,53.4864487567076,5.64003797155921,7.36664342880249,54,1,0,0,1,0.296630859375,34.2131004333496,1,1,3,349.838897705078,0,349.83821105957,,,,,,,,,,,,,,,,,,,,,,,,,,,,,,,,,
,3877832144.89484,349.995010375977,29999.73828125,-2.05543291366815E-4,3.64593621631895E-8,1,4,13.4005146026611,4.99769413926178,33.1399999558926,-0.255363804979141,-0.0378716436743713,1,2.59230353090163E-7,,,,,,,,,,,,,,,,,,,,,349.983428955078,350.006591796875,29999.73828125,29999.73828125,53.5415535673134,5.64024685023356,7.37124061584473,52,1,68,0,0,0.296554565429687,34.7018585205078,1,1,3,350.006591796875,0,349.995010375977,,,,,,,,,,,,,,,,,,,,,,,,,,,,,,,,,
,3877832299.65232,350.029846191406,50000.18359375,-3.37087571189934E-4,5.86990719378159E-8,1,4,13.4005146026611,4.99767260108495,33.1399999558926,-0.418770392959704,-0.0622385963486537,1,3.20389592214121E-7,,,,,,,,,,,,,,,,,,,,,350.028656005859,350.031036376953,50000.18359375,50000.18359375,53.359043308073,5.64002712841477,7.36886024475098,54,1,0,0,1,0.296707153320313,34.7018585205078,1,1,3,350.028656005859,0,350.029846191406,,,,,,,,,,,,,,,,,,,,,,,,,,,,,,,,,
,3877832474.87124,349.910293579102,70000.3046875,-4.68699959169251E-4,1.47895665481722E-7,1,4,13.4005146026611,4.99769079113572,33.1399999558926,-0.582251552225717,-0.0867160478848321,1,3.03318815718416E-7,,,,,,,,,,,,,,,,,,,,,349.907867431641,349.912719726562,70000.3046875,70000.3046875,53.203499232746,5.64047002864289,7.36882448196411,54,1,0,0,1,0.297317504882812,34.7018585205078,1,1,3,349.912719726562,0,349.910293579102,,,,,,,,,,,,,,,,,,,,,,,,,,,,,,,,,