File: SQUID/Reference/STO/A6/STO_MH_300K_FC_1T.csv
Comment,Time Stamp (sec),Temperature (K),Magnetic Field (Oe),Moment (emu),M. Std. Err. (emu),Transport Action,Averaging Time (sec),Frequency (Hz),Peak Amplitude (mm),Center Position (mm),Lockin Signal' (V),Lockin Signal (V),Range,M. Quad. Signal (emu),AC Moment (emu),AC M. Std Err. (emu),AC Phase (deg),AC Phase Std. Err. (deg),AC Susceptibility (emu/Oe),AC Suscept. Std Err. (emu/Oe),AC X' (emu/Oe),AC X' Std Err. (emu/Oe),AC X'' (emu/Oe),AC X'' Std Err. (emu/Oe),AC Drive (Oe),AC Frequency (Hz),AC Averaging Time (sec),AC Cycles,AC Range,AC Measure Type,AC Signal' (V),AC Signal'' (V),AC Trim Coil Ratio,AC Trim Coil Phase,Min. Temperature (K),Max. Temperature (K),Min. Field (Oe),Max. Field (Oe),Mass (grams),Motor Lag (deg),Pressure (Torr),Measure Count,Measurement Number,SQUID Status (code),Motor Status (code),Measure Status (code),Motor Current (amps),Motor Temp. (C),Temp. Status (code),Field Status (code),Chamber Status (code),Chamber Temp (K),Redirection State,Average Temp (K),Rotation Angle (deg),Rotator state,DC Moment Fixed Ctr (emu),DC Moment Err Fixed Ctr (emu),DC Moment Free Ctr (emu),DC Moment Err Free Ctr (emu),DC Fixed Fit,DC Free Fit,DC Calculated Center (mm),DC Calculated Center Err (mm),DC Scan Length (mm),DC Scan Time (s),DC Number of Points,DC Squid Drift,DC Min V (V),DC Max V (V),DC Scans per Measure,Map 01,Map 02,Map 03,Map 04,Map 05,Map 06,Map 07,Map 08,Map 09,Map 10,Map 11,Map 12,Map 13,Map 14,Map 15,Map 16
,3877818140.10571,299.981674194336,69999.609375,-4.69243246728045E-4,2.11756443188709E-7,1,4,13.4005146026611,4.9975013643075,33.050000667572,-0.582898958796539,-0.0867890266487095,1,3.22131408120183E-7,,,,,,,,,,,,,,,,,,,,,299.981384277344,299.981964111328,69999.609375,69999.609375,53.1319802232364,5.63833743406175,6.6125545501709,54,1,0,0,1,0.297393798828125,33.7243423461914,1,1,3,299.981964111328,0,299.981674194336,,,,,,,,,,,,,,,,,,,,,,,,,,,,,,,,,
,3877818310.73147,299.84765625,49999.6796875,-3.37450295932013E-4,3.80819609099109E-8,1,4,13.4005146026611,4.99744292929353,33.050000667572,-0.41916087132898,-0.062523287039766,1,1.42219003727455E-7,,,,,,,,,,,,,,,,,,,,,299.826873779297,299.868438720703,49999.6796875,49999.6796875,53.4340796459191,5.64012030615817,6.77667999267578,54,1,0,0,1,0.2972412109375,34.7018585205078,1,1,3,299.868438720703,0,299.84765625,,,,,,,,,,,,,,,,,,,,,,,,,,,,,,,,,
,3877818484.83529,300.071228027344,29999.537109375,-2.05827617925703E-4,3.33501718639523E-8,1,4,13.4005146026611,4.99749135198916,33.050000667572,-0.2556766243947,-0.038094990774756,1,1.20214698705303E-7,,,,,,,,,,,,,,,,,,,,,300.068542480469,300.073913574219,29999.537109375,29999.537109375,53.4684713007653,5.63978977517161,7.05467700958252,54,1,0,0,1,0.297164916992188,34.7018585205078,1,1,3,300.068542480469,0,300.071228027344,,,,,,,,,,,,,,,,,,,,,,,,,,,,,,,,,
,3877818642.97942,300.065795898438,9999.7197265625,-7.41881257016058E-5,1.31722167826225E-8,1,4,13.4005146026611,4.9975629028417,33.050000667572,-0.0921546568064489,-0.0137498792819795,1,2.82619335598777E-8,,,,,,,,,,,,,,,,,,,,,300.046722412109,300.084869384766,9999.7197265625,9999.7197265625,53.5384270532364,5.64075354588398,7.33055448532104,54,1,0,0,1,0.297698974609375,35.190616607666,1,1,3,300.084869384766,0,300.065795898438,,,,,,,,,,,,,,,,,,,,,,,,,,,,,,,,,
,3877818729.24241,300.111587524414,8499.8291015625,-6.43121906062486E-5,1.02624209405494E-8,1,4,13.4005146026611,4.99752630872178,33.050000667572,-0.0798865042329887,-0.0119173055157339,1,2.61625837923385E-8,,,,,,,,,,,,,,,,,,,,,300.095031738281,300.128143310547,8499.8291015625,8499.8291015625,53.6021297775537,5.64112218809985,7.47521018981934,54,1,0,0,1,0.297164916992188,35.190616607666,1,1,3,300.095031738281,0,300.111587524414,,,,,,,,,,,,,,,,,,,,,,,,,,,,,,,,,
,3877818797.1478,300.104202270508,6499.744140625,-5.11380413634428E-5,1.1983999163063E-8,1,4,13.4005146026611,4.99749956805261,33.050000667572,-0.0635206335805108,-0.00948200537321709,1,1.59780869355576E-8,,,,,,,,,,,,,,,,,,,,,300.098999023438,300.109405517578,6499.744140625,6499.744140625,53.5020813270922,5.6409660352999,7.60121631622314,54,1,0,0,1,0.297775268554687,35.190616607666,1,1,3,300.109405517578,0,300.104202270508,,,,,,,,,,,,,,,,,,,,,,,,,,,,,,,,,
,3877818864.23451,300.166015625,4499.5205078125,-3.7945027133208E-5,8.75350331563299E-9,1,4,13.4005146026611,4.99767580871708,33.050000667572,-0.0471340716870443,-0.00704487313999017,1,4.79842276512158E-9,,,,,,,,,,,,,,,,,,,,,300.149871826172,300.182159423828,4499.5205078125,4499.5205078125,53.6759936726211,5.63984324836538,7.65707397460937,54,1,0,0,1,0.297317504882812,35.190616607666,1,1,3,300.182159423828,0,300.166015625,,,,,,,,,,,,,,,,,,,,,,,,,,,,,,,,,
,3877818952.47035,300.126235961914,2999.73071289063,-2.51235441801642E-5,6.86824699858913E-9,1,4,13.4005146026611,4.99764220199839,33.050000667572,-0.0312169915798777,-0.00459994851512691,1,5.50591269069424E-8,,,,,,,,,,,,,,,,,,,,,300.125549316406,300.126922607422,2999.73071289063,2999.73071289063,53.5778992934576,5.64000249295029,7.62937116622925,54,1,0,0,1,0.296401977539063,35.6793746948242,1,1,3,300.126922607422,0,300.126235961914,,,,,,,,,,,,,,,,,,,,,,,,,,,,,,,,,
,3877819015.81937,300.033279418945,2799.76635742187,-2.36053784342691E-5,1.45351267727899E-8,1,4,13.4005146026611,4.99759405542386,33.050000667572,-0.0293608717922027,-0.00411699323938761,1,2.16717699785182E-7,,,,,,,,,,,,,,,,,,,,,300.0234375,300.043121337891,2799.76635742187,2799.76635742187,53.5954859351403,5.63958629120285,7.61303329467773,53,1,68,0,0,0.2978515625,35.190616607666,1,1,3,300.0234375,0,300.033279418945,,,,,,,,,,,,,,,,,,,,,,,,,,,,,,,,,
,3877819074.92469,300.073471069336,2599.56274414062,-2.20030256274076E-5,1.6228413123064E-8,1,4,13.4005146026611,4.99755669621728,33.050000667572,-0.0273663808107136,-0.00384526952470713,1,1.95742029135887E-7,,,,,,,,,,,,,,,,,,,,,300.063232421875,300.083709716797,2599.56274414062,2599.56274414062,53.668959015948,5.63986617672614,7.6117696762085,52,1,68,0,0,0.29754638671875,35.190616607666,1,1,3,300.083709716797,0,300.073471069336,,,,,,,,,,,,,,,,,,,,,,,,,,,,,,,,,
,3877819134.74362,300.313934326172,2399.5478515625,-2.04250198012647E-5,1.92174644381648E-8,1,4,13.4005146026611,4.99742507575629,33.050000667572,-0.025408477893755,-0.00353134793835402,1,2.12311313153964E-7,,,,,,,,,,,,,,,,,,,,,300.299896240234,300.327972412109,2399.5478515625,2399.5478515625,53.5802441790153,5.64055082166626,7.60803842544556,53,1,68,0,0,0.297393798828125,35.190616607666,1,1,3,300.327972412109,0,300.313934326172,,,,,,,,,,,,,,,,,,,,,,,,,,,,,,,,,
,3877819194.50925,300.267150878906,2199.68408203125,-1.88185870184393E-5,1.74910344206733E-8,1,4,13.4005146026611,4.99739264967847,33.050000667572,-0.0234159894648925,-0.00321275169035913,1,2.28482402756359E-7,,,,,,,,,,,,,,,,,,,,,300.261566162109,300.272735595703,2199.68408203125,2199.68408203125,53.7389147684191,5.64073586691256,7.60782194137573,52,1,68,0,0,0.296783447265625,34.7018585205078,1,1,3,300.261566162109,0,300.267150878906,,,,,,,,,,,,,,,,,,,,,,,,,,,,,,,,,
,3877819269.75279,300.007064819336,1999.64428710938,-1.71971405673513E-5,1.84373163356808E-8,1,4,13.4005146026611,4.99733858565506,33.050000667572,-0.0213995236772306,-0.00292635765616968,1,2.16470917817796E-7,,,,,,,,,,,,,,,,,,,,,300.006408691406,300.007720947266,1999.64428710938,1999.64428710938,53.6900629859672,5.64041150311664,7.60746765136719,54,1,0,0,1,0.299911499023438,35.190616607666,1,1,3,300.006408691406,0,300.007064819336,,,,,,,,,,,,,,,,,,,,,,,,,,,,,,,,,
,3877819329.48988,300.125335693359,1799.76794433594,-1.55935417337211E-5,2.05045181740673E-8,1,4,13.4005146026611,4.9973603145943,33.050000667572,-0.0194075051359418,-0.00263126360782116,1,2.14186096820174E-7,,,,,,,,,,,,,,,,,,,,,300.106353759766,300.144317626953,1799.76794433594,1799.76794433594,53.5833706930922,5.63998586333301,7.60605335235596,52,1,68,0,0,0.297927856445313,35.190616607666,1,1,3,300.144317626953,0,300.125335693359,,,,,,,,,,,,,,,,,,,,,,,,,,,,,,,,,
,3877819408.49354,300.172256469727,1599.52661132813,-1.39849685550959E-5,3.27407489182563E-8,1,4,13.4005146026611,4.99731903995953,33.050000667572,-0.017408658934464,-0.00233732467969753,1,2.10191016485847E-7,,,,,,,,,,,,,,,,,,,,,300.157775878906,300.186737060547,1599.52661132813,1599.52661132813,53.5653932371499,5.63953301591932,7.60525178909302,54,1,0,0,1,0.297393798828125,35.6793746948242,1,1,3,300.186737060547,0,300.172256469727,,,,,,,,,,,,,,,,,,,,,,,,,,,,,,,,,
,3877819469.84017,300.240493774414,1399.73840332031,-1.23280555524312E-5,1.73360239891414E-8,1,4,13.4005146026611,4.99741111841887,33.050000667572,-0.015349016658373,-0.0020436953275465,1,1.98782290168676E-7,,,,,,,,,,,,,,,,,,,,,300.233520507812,300.247467041016,1399.73840332031,1399.73840332031,53.6337857325826,5.63998739710713,7.61784410476685,54,1,0,0,1,0.2978515625,35.190616607666,1,1,3,300.233520507812,0,300.240493774414,,,,,,,,,,,,,,,,,,,,,,,,,,,,,,,,,
,3877819530.43457,300.293060302734,1199.62292480469,-1.06936284832151E-5,2.14944718381275E-8,1,4,13.4005146026611,4.99733964941451,33.050000667572,-0.0133237335221604,-0.00170637789142953,1,2.25835392761681E-7,,,,,,,,,,,,,,,,,,,,,300.275543212891,300.310577392578,1199.62292480469,1199.62292480469,53.6627059877941,5.639756210207,7.61605978012085,54,1,0,0,1,0.296859741210937,35.190616607666,1,1,3,300.310577392578,0,300.293060302734,,,,,,,,,,,,,,,,,,,,,,,,,,,,,,,,,
,3877819589.21855,300.331329345703,999.620727539063,-9.02284246055388E-6,1.8712703996285E-8,1,4,13.4005146026611,4.99738917000871,33.050000667572,-0.0112496486149021,-0.00138981539860388,1,2.30787347727163E-7,,,,,,,,,,,,,,,,,,,,,300.318420410156,300.34423828125,999.620727539063,999.620727539063,53.562266723073,5.63999817076062,7.61634731292725,54,1,0,0,1,0.297012329101562,35.190616607666,1,1,3,300.34423828125,0,300.331329345703,,,,,,,,,,,,,,,,,,,,,,,,,,,,,,,,,
,3877819656.17975,300.296630859375,799.60595703125,-7.35656801477933E-6,2.49008299288916E-8,1,4,13.4005146026611,4.99737194916541,33.050000667572,-0.00918363692154101,-0.00105602155310117,10,2.50264426733369E-7,,,,,,,,,,,,,,,,,,,,,300.289855957031,300.303405761719,799.60595703125,799.60595703125,53.543898452871,5.64022402321785,7.62132883071899,54,1,0,0,1,0.298004150390625,35.190616607666,1,1,3,300.289855957031,0,300.296630859375,,,,,,,,,,,,,,,,,,,,,,,,,,,,,,,,,
,3877819722.74736,300.342483520508,599.80517578125,-5.56988132006917E-6,2.54654456867799E-8,1,4,13.4005146026611,4.99740279086575,33.050000667572,-0.00696150429184152,-7.44514108067139E-4,1,2.33795741170509E-7,,,,,,,,,,,,,,,,,,,,,300.32861328125,300.356353759766,599.80517578125,599.80517578125,53.5204495972941,5.63985502276706,7.61030054092407,52,1,68,0,0,0.297393798828125,35.190616607666,1,1,3,300.357391357422,0,300.342483520508,,,,,,,,,,,,,,,,,,,,,,,,,,,,,,,,,
,3877819809.0677,300.260620117188,399.727447509766,-3.77301425302681E-6,2.58018291884374E-8,1,4,13.4005146026611,4.99745284772181,33.050000667572,-0.00473467514311363,-3.77894161197759E-4,1,2.60173306559838E-7,,,,,,,,,,,,,,,,,,,,,300.254486083984,300.266754150391,399.727447509766,399.727447509766,53.5935318638422,5.63988109442401,7.58923387527466,53,1,68,0,0,0.29693603515625,35.190616607666,1,1,3,300.266754150391,0,300.260620117188,,,,,,,,,,,,,,,,,,,,,,,,,,,,,,,,,
,3877819890.24403,300.001312255859,199.851135253906,-1.91372058384327E-6,3.23619878732161E-8,1,4,13.4005146026611,4.99742751915202,33.050000667572,-0.00242174903459006,-5.61115059960105E-5,10,2.411045554615E-7,,,,,,,,,,,,,,,,,,,,,299.987487792969,300.01513671875,199.851135253906,199.851135253906,53.6779477439191,5.63977758312876,7.56465005874634,54,1,0,0,1,0.297393798828125,35.190616607666,1,1,3,299.987487792969,0,300.001312255859,,,,,,,,,,,,,,,,,,,,,,,,,,,,,,,,,
,3877819981.93777,300.121765136719,0.0125882551074028,1.14265536342996E-7,2.90500206004355E-8,1,4,13.4005146026611,4.99742466612053,33.050000667572,1.01498144337407E-4,2.91470038727851E-4,10,2.17573891905577E-7,,,,,,,,,,,,,,,,,,,,,300.108917236328,300.134613037109,0.0125882551074028,0.0125882551074028,53.6349581753614,5.63978012662403,7.54428911209106,54,1,0,0,1,0.296859741210937,34.7018585205078,1,1,3,300.134613037109,0,300.121765136719,,,,,,,,,,,,,,,,,,,,,,,,,,,,,,,,,
,3877820047.36703,300.319747924805,-199.76301574707,2.12666426133881E-6,2.9216225972387E-8,1,4,13.4005146026611,4.99743374445516,33.050000667572,0.00260218428147388,6.57583697481972E-4,1,2.11294205439422E-7,,,,,,,,,,,,,,,,,,,,,300.312713623047,300.326782226562,-199.76301574707,-199.76301574707,53.594704306621,5.63927645900957,7.52353143692017,54,1,0,0,1,0.303802490234375,34.7018585205078,1,1,3,300.326782226562,0,300.319747924805,,,,,,,,,,,,,,,,,,,,,,,,,,,,,,,,,
,3877820107.35746,300.363784790039,-399.765197753906,4.11462177095269E-6,1.23698768981382E-8,1,4,13.4005146026611,4.99746178211386,33.050000667572,0.00510759529474337,7.84910808651905E-4,1,1.64159272554571E-8,,,,,,,,,,,,,,,,,,,,,300.353668212891,300.373901367188,-399.765197753906,-399.765197753906,53.5524963665826,5.63958325582831,7.51456689834595,54,1,0,0,1,0.297012329101562,34.7018585205078,1,1,3,300.373901367188,0,300.363784790039,,,,,,,,,,,,,,,,,,,,,,,,,,,,,,,,,
,3877820165.17705,300.288955688477,-599.780029296875,5.76773529207503E-6,1.78239442733086E-8,1,4,13.4005146026611,4.99745458860685,33.050000667572,0.00713168676190237,0.00128709958987804,1,1.73438640014927E-7,,,,,,,,,,,,,,,,,,,,,300.28271484375,300.295196533203,-599.780029296875,-599.780029296875,53.6111185055249,5.63924874146062,7.50326681137085,54,1,0,0,1,0.303802490234375,35.190616607666,1,1,3,300.295562744141,0,300.288955688477,,,,,,,,,,,,,,,,,,,,,,,,,,,,,,,,,
,3877820222.82614,300.276870727539,-799.744445800781,7.57786984731395E-6,1.78489615281241E-8,1,4,13.4005146026611,4.99749053455953,33.050000667572,0.00937619996628319,0.00164944820855081,1,1.94370659756296E-7,,,,,,,,,,,,,,,,,,,,,300.276672363281,300.277069091797,-799.744445800781,-799.744445800781,53.5169322689576,5.63997301577881,7.48961448669434,54,1,0,0,1,0.2978515625,35.190616607666,1,1,3,300.276672363281,0,300.276870727539,,,,,,,,,,,,,,,,,,,,,,,,,,,,,,,,,
,3877820280.41328,300.324813842773,-999.671081542969,9.28473060586782E-6,3.12952573028371E-8,1,4,13.4005146026611,4.99746231712011,33.050000667572,0.0115014214122035,0.00193144582040576,1,1.66083811052531E-7,,,,,,,,,,,,,,,,,,,,,300.310272216797,300.33935546875,-999.671081542969,-999.671081542969,53.5564045091787,5.63869956809625,7.4771523475647,53,1,68,0,0,0.297622680664063,35.190616607666,1,1,3,300.33935546875,0,300.324813842773,,,,,,,,,,,,,,,,,,,,,,,,,,,,,,,,,
,3877820355.49303,300.27165222168,-1199.54748535156,1.09305522080948E-5,1.85726664908328E-8,1,4,13.4005146026611,4.99749399765823,33.050000667572,0.0135450996233653,0.00224172679317134,1,1.69672685545642E-7,,,,,,,,,,,,,,,,,,,,,300.269836425781,300.273468017578,-1199.54748535156,-1199.54748535156,53.6400387607364,5.63937373867681,7.46374034881592,54,1,0,0,1,0.297470092773438,34.7018585205078,1,1,3,300.269836425781,0,300.27165222168,,,,,,,,,,,,,,,,,,,,,,,,,,,,,,,,,
,3877820430.49433,300.144607543945,-1399.49926757812,1.25631879788785E-5,1.29193344351062E-8,1,4,13.4005146026611,4.99751557060904,33.050000667572,0.015579834424754,0.00249980515406098,1,1.33207353848683E-7,,,,,,,,,,,,,,,,,,,,,300.140411376953,300.148803710937,-1399.49926757812,-1399.49926757812,53.5575769519576,5.63970879416809,7.45131540298462,53,1,68,0,0,0.297470092773438,34.7018585205078,1,1,3,300.140411376953,0,300.144607543945,,,,,,,,,,,,,,,,,,,,,,,,,,,,,,,,,
,3877820507.44025,300.235595703125,-1599.791015625,1.42101428518352E-5,3.1423076285035E-8,1,4,13.4005146026611,4.99754776893556,33.050000667572,0.017624496358181,0.00281360338994151,1,1.39450290914533E-7,,,,,,,,,,,,,,,,,,,,,300.218322753906,300.252868652344,-1599.791015625,-1599.791015625,53.5767268506787,5.63927475435804,7.44025230407715,52,1,68,0,0,0.298004150390625,35.190616607666,1,1,3,300.252868652344,0,300.235595703125,,,,,,,,,,,,,,,,,,,,,,,,,,,,,,,,,
,3877820589.76929,300.436996459961,-1799.50354003906,1.5830696999253E-5,2.52479605424353E-8,1,4,13.4005146026611,4.99759541551184,33.050000667572,0.0196588488349477,0.00297303517408617,1,2.53501411967702E-8,,,,,,,,,,,,,,,,,,,,,300.427581787109,300.446411132812,-1799.50354003906,-1799.50354003906,53.6634876163134,5.63907661494567,7.42855978012085,54,1,0,0,1,0.302276611328125,34.2131004333496,1,1,3,300.427581787109,0,300.436996459961,,,,,,,,,,,,,,,,,,,,,,,,,,,,,,,,,
,3877820648.91002,300.338256835937,-1999.7197265625,1.74653274098446E-5,2.23686923774525E-8,1,4,13.4005146026611,4.99754076510374,33.050000667572,0.0216743815581547,0.00337388689949609,1,1.03577950729001E-7,,,,,,,,,,,,,,,,,,,,,300.337341308594,300.339172363281,-1999.7197265625,-1999.7197265625,53.5587493947364,5.63935169435097,7.4212441444397,52,1,68,0,0,0.297012329101562,35.6793746948242,1,1,3,300.339172363281,0,300.338256835937,,,,,,,,,,,,,,,,,,,,,,,,,,,,,,,,,
,3877820706.70942,300.08073425293,-2199.646484375,1.90473532783649E-5,1.99386525888732E-8,1,4,13.4005146026611,4.99755076829119,33.050000667572,0.023637066042712,0.00368397069232773,1,1.16553743362767E-7,,,,,,,,,,,,,,,,,,,,,300.07568359375,300.085784912109,-2199.646484375,-2199.646484375,53.4583101300153,5.63934483333208,7.40986394882202,54,1,0,0,1,0.297317504882812,35.190616607666,1,1,3,300.07568359375,0,300.08073425293,,,,,,,,,,,,,,,,,,,,,,,,,,,,,,,,,
,3877820765.35918,300.163269042969,-2399.5478515625,2.06425163481182E-5,1.16265860595484E-8,1,4,13.4005146026611,4.99757960876864,33.050000667572,0.0256282729393215,0.00391591032628753,1,6.46335093862664E-8,,,,,,,,,,,,,,,,,,,,,300.153167724609,300.173370361328,-2399.5478515625,-2399.5478515625,53.5067710982076,5.6395223057963,7.4088077545166,54,1,0,0,1,0.297164916992188,34.7018585205078,1,1,3,300.173370361328,0,300.163269042969,,,,,,,,,,,,,,,,,,,,,,,,,,,,,,,,,
,3877820824.30071,300.083038330078,-2599.57543945313,2.2254452943119E-5,6.73292922936549E-9,1,4,13.4005146026611,4.99753938241719,33.050000667572,0.0276301309744769,0.00421560517720687,1,6.48147389924774E-8,,,,,,,,,,,,,,,,,,,,,300.070617675781,300.095458984375,-2599.57543945313,-2599.57543945313,53.543898452871,5.63941368739138,7.39860534667969,54,1,0,0,1,0.297088623046875,34.7018585205078,1,1,3,300.095458984375,0,300.083038330078,,,,,,,,,,,,,,,,,,,,,,,,,,,,,,,,,
,3877820884.1503,300.006103515625,-2799.66577148438,2.39203725221169E-5,9.67854504634446E-8,1,4,13.4005146026611,4.99752511474234,33.050000667572,0.0297020905525952,0.0045061086800603,1,4.94995520048506E-8,,,,,,,,,,,,,,,,,,,,,300.000732421875,300.011474609375,-2799.66577148438,-2799.66577148438,53.5497606667653,5.63920357857535,7.39253568649292,54,1,0,0,1,0.303802490234375,35.190616607666,1,1,3,300.000732421875,0,300.006103515625,,,,,,,,,,,,,,,,,,,,,,,,,,,,,,,,,
,3877820945.34842,300.255187988281,-2999.642578125,2.53860305042525E-5,1.91196286039951E-8,1,4,13.4005146026611,4.99752824781367,33.050000667572,0.0315209169389746,0.00478969207329878,1,5.85539790320494E-8,,,,,,,,,,,,,,,,,,,,,300.234405517578,300.275970458984,-2999.642578125,-2999.642578125,53.5255301826691,5.64001237475729,7.38819408416748,54,1,0,0,1,0.297470092773438,34.7018585205078,1,1,3,300.275970458984,0,300.255187988281,,,,,,,,,,,,,,,,,,,,,,,,,,,,,,,,,
,3877821030.45711,300.23356628418,-4499.734375,3.71220717707574E-5,4.24519961606542E-8,1,4,13.4005146026611,4.99753210926223,33.050000667572,0.046131424015715,0.00674837200079753,1,-1.20171797606632E-7,,,,,,,,,,,,,,,,,,,,,300.224945068359,300.2421875,-4499.734375,-4499.734375,53.5517147380633,5.63940372430257,7.38010215759277,54,1,0,0,1,0.304183959960937,34.7018585205078,1,1,3,300.224945068359,0,300.23356628418,,,,,,,,,,,,,,,,,,,,,,,,,,,,,,,,,
,3877821098.21668,300.20458984375,-6499.4921875,5.13070591359577E-5,1.6103167491442E-8,1,4,13.4005146026611,4.99755359811018,33.050000667572,0.0637441847821223,0.00942897503025079,1,-8.40717127480956E-8,,,,,,,,,,,,,,,,,,,,,300.188903808594,300.220275878906,-6499.4921875,-6499.4921875,53.5802441790153,5.63922832811313,7.373215675354,54,1,0,0,1,0.29815673828125,34.7018585205078,1,1,3,300.220275878906,0,300.20458984375,,,,,,,,,,,,,,,,,,,,,,,,,,,,,,,,,
,3877821164.21594,300.205108642578,-8499.65234375,6.4634512756801E-5,1.09392475408743E-7,1,4,13.4005146026611,4.9975324019437,33.050000667572,0.0803262207925284,0.0117150009562897,1,-2.37270175961425E-7,,,,,,,,,,,,,,,,,,,,,300.194549560547,300.215667724609,-8499.65234375,-8499.65234375,53.506380283948,5.63954896906496,7.36567163467407,54,1,0,0,1,0.297317504882812,34.7018585205078,1,1,3,300.194549560547,0,300.205108642578,,,,,,,,,,,,,,,,,,,,,,,,,,,,,,,,,
,3877821251.26912,300.135452270508,-9999.5810546875,7.44855091430307E-5,1.48663189200615E-8,1,4,13.4005146026611,4.99755355591772,33.050000667572,0.0925424994398356,0.0136800711281874,1,-1.2892133958186E-7,,,,,,,,,,,,,,,,,,,,,300.135406494141,300.135498046875,-9999.5810546875,-9999.5810546875,53.5177138974768,5.64011350261857,7.35937786102295,54,1,0,0,1,0.2978515625,34.7018585205078,1,1,3,300.135406494141,0,300.135452270508,,,,,,,,,,,,,,,,,,,,,,,,,,,,,,,,,
,3877821408.53311,299.914916992188,-29999.638671875,2.06077443085908E-4,3.45617302215469E-8,1,4,13.4005146026611,4.99760447749302,33.050000667572,0.256013312710861,0.0380204698132111,1,-2.18554014432231E-7,,,,,,,,,,,,,,,,,,,,,299.895965576172,299.933868408203,-29999.638671875,-29999.638671875,53.4583101300153,5.6395724321979,7.34692573547363,54,1,0,0,1,0.297393798828125,34.7018585205078,1,1,3,299.933868408203,0,299.914916992188,,,,,,,,,,,,,,,,,,,,,,,,,,,,,,,,,
,3877821591.79065,299.976379394531,-49999.58984375,3.38050562178413E-4,4.31790579209058E-8,1,4,13.4005146026611,4.99761244027128,33.050000667572,0.420012881809094,0.0620595551601872,10,-6.07744073176723E-7,,,,,,,,,,,,,,,,,,,,,299.95751953125,299.995239257812,-49999.58984375,-49999.58984375,53.3191802535922,5.63893923579362,7.32972860336304,54,1,0,0,1,0.297393798828125,34.7018585205078,1,1,3,299.997314453125,0,299.976379394531,,,,,,,,,,,,,,,,,,,,,,,,,,,,,,,,,
,3877821758.51492,300.190582275391,-69999.625,4.69525683548359E-4,2.09301110975234E-7,1,4,13.4005146026611,4.99757962744404,33.050000667572,0.583245900217541,0.0869547554134201,1,-2.32489045676683E-7,,,,,,,,,,,,,,,,,,,,,300.170806884766,300.210357666016,-69999.625,-69999.625,53.3266057245249,5.63896813955696,7.32343769073486,52,1,68,0,0,0.297775268554687,35.190616607666,1,1,3,300.210357666016,0,300.190582275391,,,,,,,,,,,,,,,,,,,,,,,,,,,,,,,,,
,3877821919.6611,300.172561645508,-49999.6796875,3.37541929590354E-4,9.51326910135682E-8,1,4,13.4005146026611,4.99763019871409,33.050000667572,0.419305868862172,0.0624821900300167,1,-1.91653647214748E-7,,,,,,,,,,,,,,,,,,,,,300.169403076172,300.175720214844,-49999.6796875,-49999.6796875,53.3500545801018,5.63955464300034,7.3069372177124,54,1,0,0,1,0.297775268554687,35.190616607666,1,1,3,300.169403076172,0,300.172561645508,,,,,,,,,,,,,,,,,,,,,,,,,,,,,,,,,
,3877822078.14822,299.980941772461,-29999.587890625,2.0586700090108E-4,3.91850496467304E-8,1,4,13.4005146026611,4.997598535158,33.050000667572,0.255741001355017,0.0380514360205356,1,-1.62092016742269E-7,,,,,,,,,,,,,,,,,,,,,299.98046875,299.981414794922,-29999.587890625,-29999.587890625,53.4262633607268,5.63904939333947,7.30390119552612,54,1,0,0,1,0.296249389648438,35.190616607666,1,1,3,299.981414794922,0,299.980941772461,,,,,,,,,,,,,,,,,,,,,,,,,,,,,,,,,
,3877822236.81917,300.137954711914,-10000.2861328125,7.41918311691364E-5,1.07930193387824E-8,1,4,13.4005146026611,4.99759834393128,33.050000667572,0.0921639588912385,0.0137254058997334,1,-4.8629119237215E-8,,,,,,,,,,,,,,,,,,,,,300.119781494141,300.156127929687,-10000.2861328125,-10000.2861328125,53.5712554510441,5.63947225545912,7.29459714889526,54,1,0,0,1,0.2984619140625,35.190616607666,1,1,3,300.156127929687,0,300.137954711914,,,,,,,,,,,,,,,,,,,,,,,,,,,,,,,,,
,3877822320.36253,300.306213378906,-8500.1064453125,6.43000084307732E-5,1.3220966407682E-8,1,4,13.4005146026611,4.99764609255631,33.050000667572,0.0798772065817233,0.0118943616062706,1,-4.31335332869716E-8,,,,,,,,,,,,,,,,,,,,,300.303802490234,300.308624267578,-8500.1064453125,-8500.1064453125,53.6216704905345,5.63950849634166,7.29241418838501,54,1,0,0,1,0.296630859375,34.7018585205078,1,1,3,300.308624267578,0,300.306213378906,,,,,,,,,,,,,,,,,,,,,,,,,,,,,,,,,
,3877822386.4065,300.061309814453,-6500.0712890625,5.11333629014071E-5,1.01782376439999E-8,1,4,13.4005146026611,4.9976227851635,33.050000667572,0.0635187942817855,0.00946956953030811,1,-2.55534738787891E-8,,,,,,,,,,,,,,,,,,,,,300.0537109375,300.068908691406,-6500.0712890625,-6500.0712890625,53.6142450196018,5.63941711911407,7.28832101821899,52,1,68,0,0,0.296707153320313,34.7018585205078,1,1,3,300.068908691406,0,300.061309814453,,,,,,,,,,,,,,,,,,,,,,,,,,,,,,,,,
,3877822452.25413,300.235137939453,-4500.25048828125,3.79424865879177E-5,9.14081273852817E-9,1,4,13.4005146026611,4.99762218700748,33.050000667572,0.0471340542960644,0.00701858362238548,1,-2.54981283557868E-8,,,,,,,,,,,,,,,,,,,,,300.229644775391,300.240631103516,-4500.25048828125,-4500.25048828125,53.4954374846787,5.63984833685467,7.28388404846191,54,1,0,0,1,0.29693603515625,35.190616607666,1,1,3,300.229644775391,0,300.235137939453,,,,,,,,,,,,,,,,,,,,,,,,,,,,,,,,,
,3877822538.57485,300.405517578125,-3000.18408203125,2.51122899578789E-5,7.59489130574475E-9,1,4,13.4005146026611,4.99764664323043,33.050000667572,0.0312009013076323,0.0046122343618712,1,-4.34892502306562E-8,,,,,,,,,,,,,,,,,,,,,300.404754638672,300.406280517578,-3000.18408203125,-3000.18408203125,53.5321740250826,5.63951679956156,7.28017663955688,54,1,0,0,1,0.296478271484375,35.190616607666,1,1,3,300.404571533203,0,300.405517578125,,,,,,,,,,,,,,,,,,,,,,,,,,,,,,,,,
,3877822593.32454,300.289947509766,-2800.29516601562,2.3618152006372E-5,1.58633404491022E-8,1,4,13.4005146026611,4.99759514798808,33.050000667572,0.029379110897489,0.00410356611398759,1,-2.29439444745444E-7,,,,,,,,,,,,,,,,,,,,,300.278991699219,300.300903320313,-2800.29516601562,-2800.29516601562,53.6111185055249,5.63960187773661,7.27899694442749,54,1,0,0,1,0.297393798828125,34.7018585205078,1,1,3,300.300903320313,0,300.289947509766,,,,,,,,,,,,,,,,,,,,,,,,,,,,,,,,,
,3877822651.89084,300.294052124023,-2600.35595703125,2.20268983274E-5,1.86659143385296E-8,1,4,13.4005146026611,4.99761086587051,33.050000667572,0.0274029196106133,0.00380650851547284,1,-2.30565713909528E-7,,,,,,,,,,,,,,,,,,,,,300.285736083984,300.302368164063,-2600.35595703125,-2600.35595703125,53.6119001340441,5.63970219033369,7.27412557601929,53,1,68,0,0,0.296554565429687,35.190616607666,1,1,3,300.302368164063,0,300.294052124023,,,,,,,,,,,,,,,,,,,,,,,,,,,,,,,,,
,3877822707.98057,300.190567016602,-2400.29052734375,2.04113625302755E-5,1.84279268644745E-8,1,4,13.4005146026611,4.99758426132968,33.050000667572,0.0253989463906006,0.00348685897587908,1,-2.46212252459068E-7,,,,,,,,,,,,,,,,,,,,,300.173919677734,300.207214355469,-2400.29052734375,-2400.29052734375,53.5915777925441,5.63900546768297,7.2713828086853,53,1,68,0,0,0.297012329101562,35.190616607666,1,1,3,300.173919677734,0,300.190567016602,,,,,,,,,,,,,,,,,,,,,,,,,,,,,,,,,
,3877822764.53377,300.227737426758,-2200.30102539062,1.88187632560474E-5,1.80067239477719E-8,1,4,13.4005146026611,4.9976811837066,33.050000667572,0.023415510514349,0.00323036243802393,1,-2.14540161336971E-7,,,,,,,,,,,,,,,,,,,,,300.225677490234,300.229797363281,-2200.30102539062,-2200.30102539062,53.501299698573,5.63991097899167,7.26887273788452,54,1,0,0,1,0.297317504882812,35.190616607666,1,1,3,300.229797363281,0,300.227737426758,,,,,,,,,,,,,,,,,,,,,,,,,,,,,,,,,
,3877822822.0237,300.341506958008,-2000.42468261719,1.72055119605134E-5,2.32428262946077E-8,1,4,13.4005146026611,4.99760172696474,33.050000667572,0.0214167783019986,0.00289284185336513,1,-2.44879698570825E-7,,,,,,,,,,,,,,,,,,,,,300.328186035156,300.354827880859,-2000.42468261719,-2000.42468261719,53.5931410495826,5.6395868761707,7.26695775985718,54,1,0,0,1,0.296783447265625,35.190616607666,1,1,3,300.354827880859,0,300.341506958008,,,,,,,,,,,,,,,,,,,,,,,,,,,,,,,,,
,3877822879.64517,300.301864624023,-1800.158203125,1.55896281580851E-5,2.02896083694382E-8,1,4,13.4005146026611,4.99765016392133,33.050000667572,0.019408054266057,0.0026051184672345,1,-2.34821222059503E-7,,,,,,,,,,,,,,,,,,,,,300.291473388672,300.312255859375,-1800.158203125,-1800.158203125,53.6048654773711,5.63964739989826,7.26460313796997,54,1,0,0,1,0.297012329101562,35.190616607666,1,1,3,300.312255859375,0,300.301864624023,,,,,,,,,,,,,,,,,,,,,,,,,,,,,,,,,
,3877822944.9062,300.064910888672,-1600.15600585938,1.39968111196421E-5,2.24870524344884E-8,1,4,13.4005146026611,4.99760727828526,33.050000667572,0.0174320226423423,0.00229126283237466,10,-2.49197801725827E-7,,,,,,,,,,,,,,,,,,,,,300.062377929687,300.067443847656,-1600.15600585938,-1600.15600585938,53.5911869782845,5.63928566692305,7.26631498336792,54,1,0,0,1,0.297393798828125,35.190616607666,1,1,3,300.062377929687,0,300.064910888672,,,,,,,,,,,,,,,,,,,,,,,,,,,,,,,,,
,3877823010.21465,299.897445678711,-1400.07836914062,1.23635398580986E-5,2.18592881582458E-8,1,4,13.4005146026611,4.99763760969287,33.050000667572,0.0154029519761396,0.00199102282936694,1,-2.46599887814093E-7,,,,,,,,,,,,,,,,,,,,,299.88134765625,299.913543701172,-1400.07836914062,-1400.07836914062,53.6099460627461,5.63946934649639,7.26371479034424,54,1,0,0,1,0.296859741210937,35.190616607666,1,1,3,299.913543701172,0,299.897445678711,,,,,,,,,,,,,,,,,,,,,,,,,,,,,,,,,
,3877823083.9239,300.144912719727,-1200.11376953125,1.07177420551045E-5,2.42424222702734E-8,1,4,13.4005146026611,4.99767787119775,33.050000667572,0.013355439640469,0.0017077377460701,1,-2.28478043104709E-7,,,,,,,,,,,,,,,,,,,,,300.129486083984,300.160339355469,-1200.11376953125,-1200.11376953125,53.5423351958326,5.63958204249103,7.25800800323486,52,1,68,0,0,0.29754638671875,34.7018585205078,1,1,3,300.160339355469,0,300.144912719727,,,,,,,,,,,,,,,,,,,,,,,,,,,,,,,,,
,3877823151.27293,300.399154663086,-1000.18719482422,9.00724907750354E-6,1.32041891498271E-8,1,4,13.4005146026611,4.99768404558069,33.050000667572,0.0112130075269601,0.00150870333863641,1,-1.32835430254757E-7,,,,,,,,,,,,,,,,,,,,,300.398040771484,300.400268554687,-1000.18719482422,-1000.18719482422,53.6298775899864,5.63985383611906,7.25713205337524,54,1,0,0,1,0.303878784179687,35.190616607666,1,1,3,300.398040771484,0,300.399154663086,,,,,,,,,,,,,,,,,,,,,,,,,,,,,,,,,
,3877823208.0654,300.216430664063,-800.285705566406,7.38734735376465E-6,5.07819529420493E-8,1,4,13.4005146026611,4.99767387370447,33.050000667572,0.00921959268755485,0.00108224147872374,1,-2.33832120717418E-7,,,,,,,,,,,,,,,,,,,,,300.212005615234,300.220855712891,-800.285705566406,-800.285705566406,53.5755544078999,5.6391179224934,7.26025915145874,52,1,68,0,0,0.2972412109375,35.190616607666,1,1,3,300.212005615234,0,300.216430664063,,,,,,,,,,,,,,,,,,,,,,,,,,,,,,,,,
,3877823263.87623,300.233093261719,-600.170227050781,5.63758731156983E-6,3.3092762503134E-8,1,4,13.4005146026611,4.99764787654782,33.050000667572,0.00704769815360304,7.46343846224165E-4,1,-2.42492235892208E-7,,,,,,,,,,,,,,,,,,,,,300.215789794922,300.250396728516,-600.170227050781,-600.170227050781,53.6451193461114,5.63943746698196,7.25378799438477,54,1,0,0,1,0.296859741210937,34.7018585205078,1,1,3,300.250396728516,0,300.233093261719,,,,,,,,,,,,,,,,,,,,,,,,,,,,,,,,,
,3877823320.18658,300.302581787109,-400.155456542969,3.79416434236532E-6,2.32239414645361E-8,1,4,13.4005146026611,4.99775422353778,33.050000667572,0.00476301289742403,3.70719586679653E-4,1,-2.69138749943313E-7,,,,,,,,,,,,,,,,,,,,,300.291351318359,300.313812255859,-400.155456542969,-400.155456542969,53.5599218375153,5.63949011222393,7.25029754638672,53,1,68,0,0,0.297088623046875,35.190616607666,1,1,3,300.291351318359,0,300.302581787109,,,,,,,,,,,,,,,,,,,,,,,,,,,,,,,,,
,3877823388.99176,300.454559326172,-200.102905273438,1.86946693456444E-6,1.22486741752156E-8,1,4,13.4005146026611,4.99764785321567,33.050000667572,0.00234024096774738,2.26298971106695E-4,1,-9.74751159020885E-8,,,,,,,,,,,,,,,,,,,,,300.450775146484,300.458343505859,-200.102905273438,-200.102905273438,53.4844946854095,5.63937912697264,7.24911451339722,53,1,68,0,0,0.296859741210937,34.7018585205078,1,1,3,300.450775146484,0,300.454559326172,,,,,,,,,,,,,,,,,,,,,,,,,,,,,,,,,
,3877823455.65083,300.437561035156,-0.251765102148056,-8.93401281988793E-8,3.01039279802354E-8,1,4,13.4005146026611,4.99763046472181,33.050000667572,-6.15289442685775E-5,-3.47115198314054E-4,1,-2.66087298724405E-7,,,,,,,,,,,,,,,,,,,,,300.435424804687,300.439697265625,-0.251765102148056,-0.251765102148056,53.4997364415345,5.64003054517016,7.24775886535645,54,1,0,0,1,0.296478271484375,34.7018585205078,1,1,3,300.439697265625,0,300.437561035156,,,,,,,,,,,,,,,,,,,,,,,,,,,,,,,,,
,3877823515.982,300.201889038086,199.926666259766,-2.12717011984316E-6,2.31357102352524E-8,1,4,13.4005146026611,4.99762426421327,33.050000667572,-0.0026030127974929,-6.57303126562405E-4,1,-2.10964395461287E-7,,,,,,,,,,,,,,,,,,,,,300.187408447266,300.216369628906,199.926666259766,199.926666259766,53.6615335450153,5.63953320812593,7.24612951278686,54,1,0,0,1,0.297622680664063,34.7018585205078,1,1,3,300.216369628906,0,300.201889038086,,,,,,,,,,,,,,,,,,,,,,,,,,,,,,,,,
,3877823573.63502,300.183898925781,399.765197753906,-4.0162673810519E-6,1.88718417412059E-8,1,4,13.4005146026611,4.99762542690569,33.050000667572,-0.00495678305575916,-9.59712695742991E-4,1,-1.71828121252575E-7,,,,,,,,,,,,,,,,,,,,,300.171661376953,300.196136474609,399.765197753906,399.765197753906,53.6548897026018,5.639668195262,7.24736213684082,54,1,0,0,1,0.2960205078125,34.7018585205078,1,1,3,300.171661376953,0,300.183898925781,,,,,,,,,,,,,,,,,,,,,,,,,,,,,,,,,
,3877823631.25658,300.168960571289,599.91845703125,-5.78575462862816E-6,2.29011063566334E-8,1,4,13.4005146026611,4.99760699021378,33.050000667572,-0.00715373957374585,-0.0012947399790748,1,-1.76849904587247E-7,,,,,,,,,,,,,,,,,,,,,300.156463623047,300.181457519531,599.91845703125,599.91845703125,53.5310015823037,5.64003102967314,7.24388027191162,54,1,0,0,1,0.297164916992188,35.190616607666,1,1,3,300.181457519531,0,300.168960571289,,,,,,,,,,,,,,,,,,,,,,,,,,,,,,,,,
,3877823688.88478,300.152236938477,799.694091796875,-7.54602772879433E-6,2.03422304036945E-8,1,4,13.4005146026611,4.99763051509522,33.050000667572,-0.00933030905033502,-0.00168842837130946,1,-2.30463728194734E-7,,,,,,,,,,,,,,,,,,,,,300.143493652344,300.160980224609,799.694091796875,799.694091796875,53.5450708956499,5.63953574483265,7.24175548553467,52,1,68,0,0,0.29632568359375,35.190616607666,1,1,3,300.160980224609,0,300.152236938477,,,,,,,,,,,,,,,,,,,,,,,,,,,,,,,,,
,3877823746.56358,300.261962890625,999.834716796875,-9.2583782586544E-6,6.28904470316072E-8,1,4,13.4005146026611,4.99765784782604,33.050000667572,-0.0114936134298466,-0.00176424701089812,1,-3.5335069962784E-8,,,,,,,,,,,,,,,,,,,,,300.251556396484,300.272369384766,999.834716796875,999.834716796875,53.5782901077172,5.63926000646617,7.2402548789978,53,1,68,0,0,0.296096801757812,35.190616607666,1,1,3,300.272369384766,0,300.261962890625,,,,,,,,,,,,,,,,,,,,,,,,,,,,,,,,,
,3877823804.43688,300.314117431641,1199.68591308594,-1.09203796092665E-5,1.54051259276051E-8,1,4,13.4005146026611,4.99762758255533,33.050000667572,-0.0135352957376325,-0.00222437930742979,1,-1.57160951209459E-7,,,,,,,,,,,,,,,,,,,,,300.308532714844,300.319702148438,1199.68591308594,1199.68591308594,53.547024966948,5.63986282822255,7.24142646789551,54,1,0,0,1,0.296630859375,34.7018585205078,1,1,3,300.319702148438,0,300.314117431641,,,,,,,,,,,,,,,,,,,,,,,,,,,,,,,,,
,3877823870.51031,300.368408203125,1399.85168457031,-1.25533189576915E-5,1.57152948376426E-8,1,4,13.4005146026611,4.99768117503774,33.050000667572,-0.0155691996444956,-0.0024920631674074,10,-1.28357578768659E-7,,,,,,,,,,,,,,,,,,,,,300.353698730469,300.383117675781,1399.85168457031,1399.85168457031,53.6373030609191,5.6397987199369,7.23765230178833,54,1,0,0,1,0.296478271484375,34.7018585205078,1,1,3,300.353698730469,0,300.368408203125,,,,,,,,,,,,,,,,,,,,,,,,,,,,,,,,,
,3877823937.08829,300.117095947266,1599.75317382813,-1.42094836392658E-5,1.00789944013186E-8,1,4,13.4005146026611,4.99762495816192,33.050000667572,-0.0176277147286513,-0.00278910170971641,1,-1.19774324683007E-7,,,,,,,,,,,,,,,,,,,,,300.108093261719,300.126098632812,1599.75317382813,1599.75317382813,53.5399903102749,5.63972503265774,7.2330846786499,53,1,68,0,0,0.297775268554687,35.190616607666,1,1,3,300.126098632812,0,300.117095947266,,,,,,,,,,,,,,,,,,,,,,,,,,,,,,,,,
,3877823994.78064,300.210311889648,1799.61694335938,-1.5825696032599E-5,1.72963462632167E-8,1,4,13.4005146026611,4.99769065411701,33.050000667572,-0.0196420954152118,-0.00304615871492045,1,-8.49029729450043E-8,,,,,,,,,,,,,,,,,,,,,300.207061767578,300.213562011719,1799.61694335938,1799.61694335938,53.6146358338614,5.63961975701809,7.23379325866699,54,1,0,0,1,0.29693603515625,34.7018585205078,1,1,3,300.213562011719,0,300.210311889648,,,,,,,,,,,,,,,,,,,,,,,,,,,,,,,,,
,3877824052.42685,300.184509277344,1999.99670410156,-1.75020266978773E-5,5.28337404129271E-8,1,4,13.4005146026611,4.99762864850887,33.050000667572,-0.0217142046831275,-0.00342287448700299,1,-1.37459546203054E-7,,,,,,,,,,,,,,,,,,,,,300.163604736328,300.205413818359,1999.99670410156,1999.99670410156,53.547024966948,5.64020907497943,7.23183441162109,54,1,0,0,1,0.2972412109375,35.190616607666,1,1,3,300.205413818359,0,300.184509277344,,,,,,,,,,,,,,,,,,,,,,,,,,,,,,,,,
,3877824111.07465,300.249725341797,2199.93603515625,-1.90726428336008E-5,8.91001068142229E-9,1,4,13.4005146026611,4.99764465980116,33.050000667572,-0.0236775564950688,-0.00363224220759289,1,-7.10476846077977E-8,,,,,,,,,,,,,,,,,,,,,300.245239257812,300.254211425781,2199.93603515625,2199.93603515625,53.5181047117364,5.63978718748726,7.23143100738525,54,1,0,0,1,0.304641723632812,33.2355842590332,1,1,3,300.254211425781,0,300.249725341797,,,,,,,,,,,,,,,,,,,,,,,,,,,,,,,,,
,3877824168.75326,300.124404907227,2400.08911132813,-2.06631478303973E-5,7.30158398782752E-9,1,4,13.4005146026611,4.99763697090283,33.050000667572,-0.025652885178188,-0.00392934329613568,1,-7.23109672188104E-8,,,,,,,,,,,,,,,,,,,,,300.119415283203,300.12939453125,2400.08911132813,2400.08911132813,53.460655015573,5.63961770273448,7.23083305358887,54,1,0,0,1,0.296630859375,34.7018585205078,1,1,3,300.119415283203,0,300.124404907227,,,,,,,,,,,,,,,,,,,,,,,,,,,,,,,,,
,3877824227.00511,300.078674316406,2599.90283203125,-2.22542618356802E-5,8.14870686009207E-9,1,4,13.4005146026611,4.99765607199483,33.050000667572,-0.0276323151283436,-0.00420555799491115,1,-5.66437552709935E-8,,,,,,,,,,,,,,,,,,,,,300.066589355469,300.090759277344,2599.90283203125,2599.90283203125,53.5853247643903,5.6397213941695,7.22649526596069,54,1,0,0,1,0.296249389648438,35.190616607666,1,1,3,300.090759277344,0,300.078674316406,,,,,,,,,,,,,,,,,,,,,,,,,,,,,,,,,
,3877824284.85276,300.103561401367,2799.90478515625,-2.38329904202767E-5,1.11295687852501E-8,1,4,13.4005146026611,4.99762047961123,33.050000667572,-0.0295936575871773,-0.00449458495790624,1,-5.31970273560303E-8,,,,,,,,,,,,,,,,,,,,,300.10107421875,300.106048583984,2799.90478515625,2799.90478515625,53.5052078411691,5.63959448610475,7.23040533065796,54,1,0,0,1,0.297088623046875,34.7018585205078,1,1,3,300.10107421875,0,300.103561401367,,,,,,,,,,,,,,,,,,,,,,,,,,,,,,,,,
,3877824342.61057,300.072692871094,2999.78125,-2.54371770740314E-5,9.56892114237962E-9,1,4,13.4005146026611,4.99766641473433,33.050000667572,-0.0315872077612208,-0.00478909008782846,1,-5.02688767895396E-8,,,,,,,,,,,,,,,,,,,,,300.070983886719,300.074401855469,2999.78125,2999.78125,53.5380362389768,5.63992083333036,7.2291841506958,54,1,0,0,1,0.29815673828125,35.190616607666,1,1,3,300.070983886719,0,300.072692871094,,,,,,,,,,,,,,,,,,,,,,,,,,,,,,,,,
,3877824426.65323,300.077392578125,4499.8857421875,-3.7165720753101E-5,2.38925533765713E-8,1,4,13.4005146026611,4.99764533934605,33.050000667572,-0.0461822757973443,-0.0067889802087526,1,9.41814404792253E-8,,,,,,,,,,,,,,,,,,,,,300.068420410156,300.086364746094,4499.8857421875,4499.8857421875,53.5747727793807,5.63981045140335,7.22625875473022,54,1,0,0,1,0.303802490234375,34.7018585205078,1,1,3,300.086364746094,0,300.077392578125,,,,,,,,,,,,,,,,,,,,,,,,,,,,,,,,,
,3877824492.23069,300.331039428711,6499.90771484375,-5.13232031411389E-5,1.03133713460018E-8,1,4,13.4005146026611,4.99767034626187,33.050000667572,-0.0637705566474773,-0.00940398079822404,1,1.06856909665331E-7,,,,,,,,,,,,,,,,,,,,,300.318634033203,300.343444824219,6499.90771484375,6499.90771484375,53.5489790382461,5.6394872190153,7.22350978851318,54,1,0,0,1,0.296554565429687,34.7018585205078,1,1,3,300.343444824219,0,300.331039428711,,,,,,,,,,,,,,,,,,,,,,,,,,,,,,,,,
,3877824557.0502,300.381423950195,8500.1689453125,-6.46156839355762E-5,1.02160730411561E-8,1,4,13.4005146026611,4.99765358252124,33.050000667572,-0.0802876128350853,-0.0118318711580979,1,1.40685595863159E-7,,,,,,,,,,,,,,,,,,,,,300.370391845703,300.392456054687,8500.1689453125,8500.1689453125,53.5818074360538,5.63948800042627,7.22080278396606,54,1,0,0,1,0.296478271484375,35.190616607666,1,1,3,300.392456054687,0,300.381423950195,,,,,,,,,,,,,,,,,,,,,,,,,,,,,,,,,
,3877824636.64074,300.153015136719,10000.1103515625,-7.44920507053528E-5,1.62034201946064E-8,1,4,13.4005146026611,4.99767035453418,33.050000667572,-0.0925528088434507,-0.0136873775165758,1,1.24378190447373E-7,,,,,,,,,,,,,,,,,,,,,300.152526855469,300.153503417969,10000.1103515625,10000.1103515625,53.4872303852268,5.63987757644817,7.218674659729,54,1,0,0,1,0.296783447265625,34.7018585205078,1,1,3,300.152526855469,0,300.153015136719,,,,,,,,,,,,,,,,,,,,,,,,,,,,,,,,,
,3877824789.06338,300.034332275391,29999.9140625,-2.06095242672707E-4,3.75021667944621E-8,1,4,13.4005146026611,4.99766456324996,33.050000667572,-0.256042331663161,-0.0380070366334028,1,2.32546492963427E-7,,,,,,,,,,,,,,,,,,,,,300.032470703125,300.036193847656,29999.9140625,29999.9140625,53.5610942802941,5.64026214070972,7.22236728668213,54,1,0,0,1,0.297012329101562,34.7018585205078,1,1,3,300.032470703125,0,300.034332275391,,,,,,,,,,,,,,,,,,,,,,,,,,,,,,,,,
,3877824959.90324,300.097366333008,50000.33203125,-3.3777883267789E-4,6.56125596769377E-8,1,4,13.4005146026611,4.99765979223137,33.050000667572,-0.419628303307509,-0.0623616688932035,1,3.24537063773639E-7,,,,,,,,,,,,,,,,,,,,,300.097076416016,300.09765625,50000.33203125,50000.33203125,53.3262149102653,5.6395970164442,7.21611642837524,54,1,0,0,1,0.297012329101562,34.7018585205078,1,1,3,300.097076416016,0,300.097366333008,,,,,,,,,,,,,,,,,,,,,,,,,,,,,,,,,
,3877825118.90322,300.022415161133,70000.4296875,-4.69429539990273E-4,2.75043206315741E-7,1,4,13.4005146026611,4.99767018446522,33.050000667572,-0.58314856361245,-0.0868903576547414,1,2.71726612714289E-7,,,,,,,,,,,,,,,,,,,,,300.000030517578,300.044799804687,70000.4296875,70000.4296875,53.3019844261691,5.64008033410898,7.21150159835815,54,1,0,0,1,0.297698974609375,34.7018585205078,1,1,3,300.044799804687,0,300.022415161133,,,,,,,,,,,,,,,,,,,,,,,,,,,,,,,,,