File: SQUID/Reference/STO/A6/STO_MH_50K_FC_1T.csv
Comment,Time Stamp (sec),Temperature (K),Magnetic Field (Oe),Moment (emu),M. Std. Err. (emu),Transport Action,Averaging Time (sec),Frequency (Hz),Peak Amplitude (mm),Center Position (mm),Lockin Signal' (V),Lockin Signal (V),Range,M. Quad. Signal (emu),AC Moment (emu),AC M. Std Err. (emu),AC Phase (deg),AC Phase Std. Err. (deg),AC Susceptibility (emu/Oe),AC Suscept. Std Err. (emu/Oe),AC X' (emu/Oe),AC X' Std Err. (emu/Oe),AC X'' (emu/Oe),AC X'' Std Err. (emu/Oe),AC Drive (Oe),AC Frequency (Hz),AC Averaging Time (sec),AC Cycles,AC Range,AC Measure Type,AC Signal' (V),AC Signal'' (V),AC Trim Coil Ratio,AC Trim Coil Phase,Min. Temperature (K),Max. Temperature (K),Min. Field (Oe),Max. Field (Oe),Mass (grams),Motor Lag (deg),Pressure (Torr),Measure Count,Measurement Number,SQUID Status (code),Motor Status (code),Measure Status (code),Motor Current (amps),Motor Temp. (C),Temp. Status (code),Field Status (code),Chamber Status (code),Chamber Temp (K),Redirection State,Average Temp (K),Rotation Angle (deg),Rotator state,DC Moment Fixed Ctr (emu),DC Moment Err Fixed Ctr (emu),DC Moment Free Ctr (emu),DC Moment Err Free Ctr (emu),DC Fixed Fit,DC Free Fit,DC Calculated Center (mm),DC Calculated Center Err (mm),DC Scan Length (mm),DC Scan Time (s),DC Number of Points,DC Squid Drift,DC Min V (V),DC Max V (V),DC Scans per Measure,Map 01,Map 02,Map 03,Map 04,Map 05,Map 06,Map 07,Map 08,Map 09,Map 10,Map 11,Map 12,Map 13,Map 14,Map 15,Map 16
,3877794250.11021,49.9994812011719,69999.5625,-4.55524854628866E-4,2.31694856390125E-7,1,4,13.4005146026611,4.99759990516502,32.7799990773201,-0.565863325802297,-0.0843217228716955,1,2.58242588191726E-7,,,,,,,,,,,,,,,,,,,,,49.9993286132812,49.9996337890625,69999.5625,69999.5625,53.4059410192268,5.63831825610265,4.97306871414185,54,1,0,0,1,0.297012329101562,34.2131004333496,1,1,3,49.9996337890625,0,49.9994812011719,,,,,,,,,,,,,,,,,,,,,,,,,,,,,,,,,
,3877794405.69917,50.004545211792,49999.640625,-3.25908734449245E-4,8.4083271531213E-8,1,4,13.4005146026611,4.9975747571206,32.7799990773201,-0.404824589106444,-0.0604872567005945,1,5.67040494260191E-8,,,,,,,,,,,,,,,,,,,,,50.0041770935059,50.0049133300781,49999.640625,49999.640625,53.4817589855922,5.63862516614401,5.01267576217651,54,1,0,0,1,0.2960205078125,34.7018585205078,1,1,3,50.0041770935059,0,50.004545211792,,,,,,,,,,,,,,,,,,,,,,,,,,,,,,,,,
,3877794564.86174,50.0458889007568,29999.5,-1.96230584042178E-4,3.5246756857919E-8,1,4,13.4005146026611,4.99756330942011,32.7799990773201,-0.243754022735706,-0.0363608895267987,1,8.12749556051803E-8,,,,,,,,,,,,,,,,,,,,,50.0393676757812,50.0524101257324,29999.5,29999.5,53.4602642013134,5.63790784627935,5.03974199295044,54,1,0,0,1,0.296859741210937,34.7018585205078,1,1,3,50.0524101257324,0,50.0458889007568,,,,,,,,,,,,,,,,,,,,,,,,,,,,,,,,,
,3877794723.78006,50.0425987243652,9999.6318359375,-6.70669035912305E-5,1.48415129878874E-8,1,4,13.4005146026611,4.99756809078486,32.7799990773201,-0.0833105399791754,-0.0124195808076359,1,3.39891529288825E-8,,,,,,,,,,,,,,,,,,,,,50.0369529724121,50.0482444763184,9999.6318359375,9999.6318359375,53.4563560587172,5.63846310355797,5.04937791824341,54,1,0,0,1,0.298004150390625,34.2131004333496,1,1,3,50.0482444763184,0,50.0425987243652,,,,,,,,,,,,,,,,,,,,,,,,,,,,,,,,,
,3877794805.41938,50.0152778625488,8499.5517578125,-5.73781266729155E-5,1.36308038084104E-8,1,4,13.4005146026611,4.99764419626975,32.7799990773201,-0.0712746124597799,-0.0106392828480346,1,1.80799287329372E-8,,,,,,,,,,,,,,,,,,,,,50.0144195556641,50.0161361694336,8499.5517578125,8499.5517578125,53.5001272557941,5.63784170762752,5.05793714523315,54,1,0,0,1,0.297622680664063,34.7018585205078,1,1,3,50.0144195556641,0,50.0152778625488,,,,,,,,,,,,,,,,,,,,,,,,,,,,,,,,,
,3877794872.69339,50.043493270874,6499.58056640625,-4.44514744172529E-5,1.35936517475887E-8,1,4,13.4005146026611,4.99760175247855,32.7799990773201,-0.0552165231719262,-0.00824265520089158,1,1.3699047355785E-8,,,,,,,,,,,,,,,,,,,,,50.0380249023438,50.0489616394043,6499.58056640625,6499.58056640625,53.5376454247172,5.637809403816,5.05903100967407,53,1,68,0,0,0.297088623046875,34.7018585205078,1,1,3,50.0489616394043,0,50.043493270874,,,,,,,,,,,,,,,,,,,,,,,,,,,,,,,,,
,3877794940.40713,50.0334873199463,4499.58349609375,-3.15070148250316E-5,1.06745743015661E-8,1,4,13.4005146026611,4.99760808580287,32.7799990773201,-0.039136635896619,-0.00584684021733061,1,6.11023748634135E-9,,,,,,,,,,,,,,,,,,,,,50.0332412719727,50.0337333679199,4499.58349609375,4499.58349609375,53.4520571018614,5.63771022261518,5.05630207061768,54,1,0,0,1,0.296630859375,34.2131004333496,1,1,3,50.0332412719727,0,50.0334873199463,,,,,,,,,,,,,,,,,,,,,,,,,,,,,,,,,
,3877795024.89852,50.0315608978271,2999.69311523438,-2.18061486738843E-5,1.14889190291172E-8,1,4,13.4005146026611,4.99758904217478,32.7799990773201,-0.0270937178740934,-0.00399835147405613,1,4.30753871066969E-8,,,,,,,,,,,,,,,,,,,,,50.0311813354492,50.0319404602051,2999.69311523438,2999.69311523438,53.4497122163037,5.63794704611984,5.06242895126343,54,1,0,0,1,0.29754638671875,34.7018585205078,1,1,3,50.0311813354492,0,50.0315608978271,,,,,,,,,,,,,,,,,,,,,,,,,,,,,,,,,
,3877795092.76894,50.0316219329834,2799.69091796875,-2.06137987761915E-5,1.94298083942259E-8,1,4,13.4005146026611,4.99755118828655,32.7799990773201,-0.0256478005918573,-0.00354019492385117,10,2.3352933345955E-7,,,,,,,,,,,,,,,,,,,,,50.0289154052734,50.0343284606934,2799.69091796875,2799.69091796875,53.5466341526884,5.6379469718366,5.06612586975098,54,1,0,0,1,0.298843383789063,34.7018585205078,1,1,3,50.0289154052734,0,50.0316219329834,,,,,,,,,,,,,,,,,,,,,,,,,,,,,,,,,
,3877795177.71219,50.0136947631836,2599.65087890625,-1.9304080456585E-5,2.03167446940098E-8,1,4,13.4005146026611,4.99757006163259,32.7799990773201,-0.0240153745571289,-0.00333529927753315,1,2.02576736977085E-7,,,,,,,,,,,,,,,,,,,,,50.0128974914551,50.0144920349121,2599.65087890625,2599.65087890625,53.493092599121,5.63780166670142,5.06983423233032,53,1,68,0,0,0.297088623046875,34.7018585205078,1,1,3,50.012809753418,0,50.0136947631836,,,,,,,,,,,,,,,,,,,,,,,,,,,,,,,,,
,3877795235.4375,50.0570297241211,2399.63598632813,-1.8052221687798E-5,1.85888219541666E-8,1,4,13.4005146026611,4.99761953065712,32.7799990773201,-0.0224723403888051,-0.00302520851185082,1,2.6498912336682E-7,,,,,,,,,,,,,,,,,,,,,50.0535926818848,50.0604667663574,2399.63598632813,2399.63598632813,53.5931410495826,5.63759255358067,5.07089948654175,54,1,0,0,1,0.296707153320313,34.7018585205078,1,1,3,50.0604667663574,0,50.0570297241211,,,,,,,,,,,,,,,,,,,,,,,,,,,,,,,,,
,3877795292.89863,50.0208587646484,2199.62133789062,-1.67059251706349E-5,2.90140156689359E-8,1,4,13.4005146026611,4.99756010038221,32.7799990773201,-0.020798989588496,-0.00277992806754724,1,2.61022725421491E-7,,,,,,,,,,,,,,,,,,,,,50.0208473205566,50.0208702087402,2199.62133789062,2199.62133789062,53.5220128543326,5.63759080151756,5.06311750411987,54,1,0,0,1,0.296478271484375,35.190616607666,1,1,3,50.0208702087402,0,50.0208587646484,,,,,,,,,,,,,,,,,,,,,,,,,,,,,,,,,
,3877795350.41785,50.0293598175049,1999.73229980469,-1.54269404671404E-5,2.05259232443082E-8,1,4,13.4005146026611,4.99755210362301,32.7799990773201,-0.0192073008512271,-0.00256242266548083,1,2.44800393862194E-7,,,,,,,,,,,,,,,,,,,,,50.0270118713379,50.0317077636719,1999.73229980469,1999.73229980469,53.4958282989384,5.63760809174827,5.06304121017456,54,1,0,0,1,0.296478271484375,35.190616607666,1,1,3,50.0270118713379,0,50.0293598175049,,,,,,,,,,,,,,,,,,,,,,,,,,,,,,,,,
,3877795409.65335,50.0120716094971,1799.71765136719,-1.41098316968551E-5,2.23330661010581E-8,1,4,13.4005146026611,4.9975269856978,32.7799990773201,-0.017570229995659,-0.00232412715406291,1,2.39604644620212E-7,,,,,,,,,,,,,,,,,,,,,50.0108757019043,50.0132675170898,1799.71765136719,1799.71765136719,53.5310015823037,5.63764029529569,5.06600999832153,54,1,0,0,1,0.29632568359375,35.190616607666,1,1,3,50.0132675170898,0,50.0120716094971,,,,,,,,,,,,,,,,,,,,,,,,,,,,,,,,,
,3877795476.07826,50.039867401123,1599.58959960938,-1.28507646284104E-5,6.03906484198734E-8,1,4,13.4005146026611,4.99753522570134,32.7799990773201,-0.0160145328246993,-0.00203575135687077,10,2.83429180974765E-7,,,,,,,,,,,,,,,,,,,,,50.0396842956543,50.0400505065918,1599.58959960938,1599.58959960938,53.4317347603614,5.63759560589004,5.0694694519043,54,1,0,0,1,0.297393798828125,35.190616607666,1,1,3,50.0400505065918,0,50.039867401123,,,,,,,,,,,,,,,,,,,,,,,,,,,,,,,,,
,3877795542.16207,50.0639934539795,1399.77624511719,-1.15419969618969E-5,2.04874794254111E-8,1,4,13.4005146026611,4.99749868785741,32.7799990773201,-0.0143876723623984,-0.00179990153740497,1,2.77511444492999E-7,,,,,,,,,,,,,,,,,,,,,50.0598220825195,50.0681648254395,1399.77624511719,1399.77624511719,53.5517147380633,5.6374144721721,5.07119989395142,53,1,68,0,0,0.297317504882812,34.7018585205078,1,1,3,50.0593109130859,0,50.0639934539795,,,,,,,,,,,,,,,,,,,,,,,,,,,,,,,,,
,3877795617.35914,50.0089569091797,1199.67333984375,-1.02584846703212E-5,2.23783586666066E-8,1,4,13.4005146026611,4.99755690455625,32.7799990773201,-0.0127878669870638,-0.00160012046146626,1,2.46370608510034E-7,,,,,,,,,,,,,,,,,,,,,50.0084228515625,50.0094909667969,1199.67333984375,1199.67333984375,53.5650024228903,5.63760918180486,5.07149887084961,54,1,0,0,1,0.297470092773438,35.190616607666,1,1,3,50.0084228515625,0,50.0089569091797,,,,,,,,,,,,,,,,,,,,,,,,,,,,,,,,,
,3877795673.9605,50.043514251709,999.85986328125,-8.97243896068273E-6,2.17398746148502E-8,1,4,13.4005146026611,4.9975556475964,32.7799990773201,-0.0111946270718703,-0.00133331989080645,1,2.68783273376355E-7,,,,,,,,,,,,,,,,,,,,,50.0404624938965,50.0465660095215,999.85986328125,999.85986328125,53.4289990605441,5.63768579518692,5.05761241912842,54,1,0,0,1,0.296478271484375,34.7018585205078,1,1,3,50.0404624938965,0,50.043514251709,,,,,,,,,,,,,,,,,,,,,,,,,,,,,,,,,
,3877795731.0176,50.0112590789795,799.782165527344,-7.63970030116316E-6,2.42649063372211E-8,1,4,13.4005146026611,4.99748836109494,32.7799990773201,-0.00953512877110606,-0.00111187416559302,1,2.47679949393487E-7,,,,,,,,,,,,,,,,,,,,,50.0109710693359,50.011547088623,799.782165527344,799.782165527344,53.4442408166691,5.63771765617313,5.06076240539551,54,1,0,0,1,0.2978515625,34.7018585205078,1,1,3,50.011547088623,0,50.0112590789795,,,,,,,,,,,,,,,,,,,,,,,,,,,,,,,,,
,3877795805.09026,50.017951965332,600.107238769531,-6.43158988420112E-6,6.60508508882341E-8,1,4,13.4005146026611,4.99751816710788,32.7799990773201,-0.00804408442018971,-8.24190546007185E-4,1,2.98574283027968E-7,,,,,,,,,,,,,,,,,,,,,50.0164375305176,50.0194664001465,600.107238769531,600.107238769531,53.4039869479287,5.63806297022117,5.0635142326355,53,1,68,0,0,0.296859741210937,35.190616607666,1,1,3,50.0164375305176,0,50.017951965332,,,,,,,,,,,,,,,,,,,,,,,,,,,,,,,,,
,3877795878.84117,50.0014610290527,400.00439453125,-5.07298901960328E-6,2.76582222449301E-8,1,4,13.4005146026611,4.99749363387342,32.7799990773201,-0.00634449857247849,-6.52224779591264E-4,1,2.33781186001367E-7,,,,,,,,,,,,,,,,,,,,,50.0013694763184,50.0015525817871,400.00439453125,400.00439453125,53.5595310232557,5.63766224745995,5.05804347991943,54,1,0,0,1,0.296401977539063,34.7018585205078,1,1,3,50.0015525817871,0,50.0014610290527,,,,,,,,,,,,,,,,,,,,,,,,,,,,,,,,,
,3877795952.7678,50.0507183074951,200.16584777832,-3.74925066325167E-6,2.22197006739011E-8,1,4,13.4005146026611,4.99754471657168,32.7799990773201,-0.00470520008698224,-3.74024512192207E-4,1,2.59741663398531E-7,,,,,,,,,,,,,,,,,,,,,50.0501403808594,50.0512962341309,200.16584777832,200.16584777832,53.4856671281884,5.63825265742312,5.0653772354126,54,1,0,0,1,0.296401977539063,35.190616607666,1,1,3,50.0512962341309,0,50.0507183074951,,,,,,,,,,,,,,,,,,,,,,,,,,,,,,,,,
,3877796026.55033,50.0118598937988,0.239176839590073,4.0225659631579E-6,2.60767918387387E-8,1,4,13.4005146026611,4.99752974797957,32.7799990773201,0.00495982147021061,9.91955852104194E-4,1,1.96865332359619E-7,,,,,,,,,,,,,,,,,,,,,50.0107841491699,50.0129356384277,0.239176839590073,0.239176839590073,53.4622182726114,5.63762721228064,5.06597852706909,54,1,0,0,1,0.296783447265625,34.7018585205078,1,1,3,50.0107841491699,0,50.0118598937988,,,,,,,,,,,,,,,,,,,,,,,,,,,,,,,,,
,3877796107.30288,50.0104846954346,-199.825958251953,5.26487348793188E-6,3.95974600733846E-8,1,4,13.4005146026611,4.99752469337713,32.7799990773201,0.00648943268312722,0.00131263672563911,10,2.69203108142467E-7,,,,,,,,,,,,,,,,,,,,,50.0080070495605,50.0129623413086,-199.825958251953,-199.825958251953,53.452447916121,5.63737405498645,5.07013654708862,54,1,0,0,1,0.303878784179687,35.190616607666,1,1,3,50.0129623413086,0,50.0104846954346,,,,,,,,,,,,,,,,,,,,,,,,,,,,,,,,,
,3877796189.89389,50.0025501251221,-399.802978515625,6.62384594038411E-6,2.00741247528936E-8,1,4,13.4005146026611,4.99738974121584,32.7799990773201,0.00819379248412151,0.00145344334837749,1,1.79315986621814E-7,,,,,,,,,,,,,,,,,,,,,50.00244140625,50.0026588439941,-399.802978515625,-399.802978515625,53.4512754733422,5.63850670030513,5.07397508621216,54,1,0,0,1,0.29693603515625,34.7018585205078,1,1,3,50.00244140625,0,50.0025501251221,,,,,,,,,,,,,,,,,,,,,,,,,,,,,,,,,
,3877796247.57312,50.0076560974121,-599.528259277344,7.92274080528737E-6,1.61543975286499E-8,1,4,13.4005146026611,4.99747167841055,32.7799990773201,0.00980548718032676,0.00170695482894943,1,1.89086017721738E-7,,,,,,,,,,,,,,,,,,,,,50.0072746276855,50.0080375671387,-599.528259277344,-599.528259277344,53.5907961640249,5.63795043985454,5.07338809967041,54,1,0,0,1,0.297317504882812,34.7018585205078,1,1,3,50.0080375671387,0,50.0076560974121,,,,,,,,,,,,,,,,,,,,,,,,,,,,,,,,,
,3877796305.325,50.0170936584473,-799.593383789063,9.18893643304687E-6,2.18453146221478E-8,1,4,13.4005146026611,4.9974462442944,32.7799990773201,0.011381799760864,0.00191756454983839,1,1.69245060287801E-7,,,,,,,,,,,,,,,,,,,,,50.0163192749023,50.0178680419922,-799.593383789063,-799.593383789063,53.5458525241691,5.63794592228483,5.06616020202637,54,1,0,0,1,0.29693603515625,34.7018585205078,1,1,3,50.0163192749023,0,50.0170936584473,,,,,,,,,,,,,,,,,,,,,,,,,,,,,,,,,
,3877796380.42419,50.0065517425537,-999.570373535156,1.05641685244628E-5,5.21088954412887E-8,1,4,13.4005146026611,4.99745659072874,32.7799990773201,0.0130913482907463,0.00216384139755102,1,1.61794092750638E-7,,,,,,,,,,,,,,,,,,,,,50.00634765625,50.0067558288574,-999.570373535156,-999.570373535156,53.4997364415345,5.63781198148868,5.07994937896729,54,1,0,0,1,0.2984619140625,34.7018585205078,1,1,3,50.0067558288574,0,50.0065517425537,,,,,,,,,,,,,,,,,,,,,,,,,,,,,,,,,
,3877796456.23156,50.0405235290527,-1199.52221679688,1.17708468614433E-5,1.62632478644868E-8,1,4,13.4005146026611,4.99747418783357,32.7799990773201,0.0145821413310193,0.00244190563223418,1,2.05144829800786E-7,,,,,,,,,,,,,,,,,,,,,50.0398941040039,50.0411529541016,-1199.52221679688,-1199.52221679688,53.3832737921691,5.63818622306237,5.07602071762085,54,1,0,0,1,0.297164916992188,34.2131004333496,1,1,3,50.0411529541016,0,50.0405235290527,,,,,,,,,,,,,,,,,,,,,,,,,,,,,,,,,
,3877796526.29034,50.0326480865479,-1399.65026855469,1.31010629896363E-5,6.95266404469988E-8,1,4,13.4005146026611,4.99749162040244,32.7799990773201,0.0162353674266543,0.00268292883824225,10,2.00191187008247E-7,,,,,,,,,,,,,,,,,,,,,50.0306549072266,50.0346412658691,-1399.65026855469,-1399.65026855469,53.5778992934576,5.63792924264784,5.07996892929077,54,1,0,0,1,0.297088623046875,34.7018585205078,1,1,3,50.0306549072266,0,50.0326480865479,,,,,,,,,,,,,,,,,,,,,,,,,,,,,,,,,
,3877796596.89864,50.0379581451416,-1599.70288085938,1.44248648141904E-5,9.97304241074749E-9,1,4,13.4005146026611,4.99748151639753,32.7799990773201,0.0178923869406662,0.0028433094424892,1,1.31287701372989E-7,,,,,,,,,,,,,,,,,,,,,50.0364799499512,50.039436340332,-1599.70288085938,-1599.70288085938,53.5517147380633,5.6375348478104,5.07872915267944,53,1,68,0,0,0.297012329101562,34.7018585205078,1,1,3,50.0364799499512,0,50.0379581451416,,,,,,,,,,,,,,,,,,,,,,,,,,,,,,,,,
,3877796674.64066,50.0218830108643,-1799.65466308594,1.57412672522635E-5,2.71863816209076E-8,1,4,13.4005146026611,4.99752206582754,32.7799990773201,0.0195228611624079,0.00312016004352899,1,1.57226879969875E-7,,,,,,,,,,,,,,,,,,,,,50.0196990966797,50.0240669250488,-1799.65466308594,-1799.65466308594,53.4559652444576,5.63807057443513,5.08432722091675,54,1,0,0,1,0.296859741210937,34.2131004333496,1,1,3,50.0196990966797,0,50.0218830108643,,,,,,,,,,,,,,,,,,,,,,,,,,,,,,,,,
,3877796733.19724,50.0312576293945,-1999.65686035156,1.70261118766923E-5,1.11780220278198E-8,1,4,13.4005146026611,4.99754355621405,32.7799990773201,0.0211252670437448,0.00331622917185985,1,1.22860128909862E-7,,,,,,,,,,,,,,,,,,,,,50.0291862487793,50.0333290100098,-1999.65686035156,-1999.65686035156,53.5435076386114,5.63761707843565,5.08488512039185,52,1,68,0,0,0.304946899414063,34.2131004333496,1,1,3,50.0291862487793,0,50.0312576293945,,,,,,,,,,,,,,,,,,,,,,,,,,,,,,,,,
,3877796790.89105,50.0835418701172,-2199.646484375,1.82545253019314E-5,4.14738866428177E-8,1,4,13.4005146026611,4.99754078311433,32.7799990773201,0.0226515810777584,0.00354098837345314,1,1.20050555631667E-7,,,,,,,,,,,,,,,,,,,,,50.0827903747559,50.0842933654785,-2199.646484375,-2199.646484375,53.5485882239864,5.63812973095405,5.07504558563232,52,1,68,0,0,0.29754638671875,34.7018585205078,1,1,3,50.0842933654785,0,50.0835418701172,,,,,,,,,,,,,,,,,,,,,,,,,,,,,,,,,
,3877796849.73743,50.0273742675781,-2399.57299804687,1.95806908460566E-5,4.76474078215943E-8,1,4,13.4005146026611,4.99756224657919,32.7799990773201,0.024298157446142,0.00379274530170262,1,1.24333038570201E-7,,,,,,,,,,,,,,,,,,,,,50.0246505737305,50.0300979614258,-2399.57299804687,-2399.57299804687,53.5106792408037,5.63861907032132,5.07326316833496,54,1,0,0,1,0.296707153320313,34.7018585205078,1,1,3,50.0246505737305,0,50.0273742675781,,,,,,,,,,,,,,,,,,,,,,,,,,,,,,,,,
,3877796910.14704,50.0090351104736,-2599.78930664062,2.08908425914955E-5,1.53816631072908E-8,1,4,13.4005146026611,4.99754412325209,32.7799990773201,0.0259315482084024,0.00399487180151578,1,9.10878257682652E-8,,,,,,,,,,,,,,,,,,,,,50.0086250305176,50.0094451904297,-2599.78930664062,-2599.78930664062,53.8893782583711,5.63790552734044,5.07670307159424,54,1,0,0,1,0.297622680664063,34.7018585205078,1,1,3,50.0086250305176,0,50.0090351104736,,,,,,,,,,,,,,,,,,,,,,,,,,,,,,,,,
,3877796970.79086,50.0454807281494,-2799.72875976562,2.22341757891454E-5,2.35381455490882E-8,1,4,13.4005146026611,4.99752964551106,32.7799990773201,0.0276018018301577,0.00423233262212953,1,8.1324478700572E-8,,,,,,,,,,,,,,,,,,,,,50.042106628418,50.0488548278809,-2799.72875976562,-2799.72875976562,53.8373999618422,5.63761531138435,5.07911348342895,54,1,0,0,1,0.297088623046875,34.7018585205078,1,1,3,50.0488548278809,0,50.0454807281494,,,,,,,,,,,,,,,,,,,,,,,,,,,,,,,,,
,3877797033.03864,50.0359992980957,-2999.66796875,2.35001090778996E-5,2.17127130779953E-8,1,4,13.4005146026611,4.99755040386211,32.7799990773201,0.0291716064077158,0.00448611033892318,1,9.62422474604485E-8,,,,,,,,,,,,,,,,,,,,,50.0343742370605,50.0376243591309,-2999.66796875,-2999.66796875,53.9261147987749,5.63780022444046,5.08062410354614,54,1,0,0,1,0.29632568359375,34.7018585205078,1,1,3,50.0376434326172,0,50.0359992980957,,,,,,,,,,,,,,,,,,,,,,,,,,,,,,,,,
,3877797112.91273,50.0376472473145,-4499.4951171875,3.32334412429343E-5,8.06761698164277E-9,1,4,13.4005146026611,4.99755532101791,32.7799990773201,0.0412894808511997,0.00610720590638715,1,-5.4686400096772E-8,,,,,,,,,,,,,,,,,,,,,50.0355606079102,50.0397338867188,-4499.4951171875,-4499.4951171875,53.8991486148615,5.63803739889146,5.08634090423584,54,1,0,0,1,0.295639038085937,34.2131004333496,1,1,3,50.0397338867188,0,50.0376472473145,,,,,,,,,,,,,,,,,,,,,,,,,,,,,,,,,
,3877797180.87434,50.0201740264893,-6499.83203125,4.62295524974187E-5,9.23654102329489E-9,1,4,13.4005146026611,4.99754954781534,32.7799990773201,0.0574379594248764,0.00848138406678431,1,-8.73937230726652E-8,,,,,,,,,,,,,,,,,,,,,50.0179214477539,50.0224266052246,-6499.83203125,-6499.83203125,53.8538141607461,5.63797904224434,5.08259153366089,54,1,0,0,1,0.29693603515625,34.7018585205078,1,1,3,50.0179214477539,0,50.0201740264893,,,,,,,,,,,,,,,,,,,,,,,,,,,,,,,,,
,3877797247.65151,50.0171871185303,-8499.5517578125,5.91796848100496E-5,1.27721626083822E-8,1,4,13.4005146026611,4.9975452720084,32.7799990773201,0.0735239798514958,0.0108826215619403,1,-9.14351843502005E-8,,,,,,,,,,,,,,,,,,,,,50.0153541564941,50.0190200805664,-8499.5517578125,-8499.5517578125,53.9054016430153,5.63859536711169,5.08155536651611,54,1,0,0,1,0.297012329101562,34.2131004333496,1,1,3,50.0153541564941,0,50.0171871185303,,,,,,,,,,,,,,,,,,,,,,,,,,,,,,,,,
,3877797328.42545,50.0524883270264,-9999.7451171875,6.88515568906882E-5,1.20708901400919E-8,1,4,13.4005146026611,4.99755241301014,32.7799990773201,0.0855363986391492,0.012687593985551,1,-8.51442939813688E-8,,,,,,,,,,,,,,,,,,,,,50.0519981384277,50.052978515625,-9999.7451171875,-9999.7451171875,53.8127786634865,5.6378666180574,5.0826268196106,54,1,0,0,1,0.296783447265625,34.7018585205078,1,1,3,50.0519981384277,0,50.0524883270264,,,,,,,,,,,,,,,,,,,,,,,,,,,,,,,,,
,3877797484.98307,50.0011291503906,-29999.6875,1.97967907734678E-4,4.02828665204973E-8,1,4,13.4005146026611,4.99756313288729,32.7799990773201,0.245930186240511,0.0365617862823692,1,-1.79427431913754E-7,,,,,,,,,,,,,,,,,,,,,50.0010414123535,50.0012168884277,-29999.6875,-29999.6875,53.8155143633038,5.63810992816989,5.07710313796997,52,1,68,0,0,0.29754638671875,33.7243423461914,1,1,3,50.0012168884277,0,50.0011291503906,,,,,,,,,,,,,,,,,,,,,,,,,,,,,,,,,
,3877797651.97166,50.0312385559082,-49999.65234375,3.27379369722873E-4,6.20663941800388E-8,1,4,13.4005146026611,4.99759774453753,32.7799990773201,0.406743017399866,0.0601651577756261,10,-5.36330185507775E-7,,,,,,,,,,,,,,,,,,,,,50.0261573791504,50.036319732666,-49999.65234375,-49999.65234375,53.8026174927365,5.63801170048685,5.09055805206299,54,1,0,0,1,0.296859741210937,34.2131004333496,1,1,3,50.036319732666,0,50.0312385559082,,,,,,,,,,,,,,,,,,,,,,,,,,,,,,,,,
,3877797818.7575,50.0183067321777,-69999.5625,4.56419847446546E-4,1.47574834476936E-7,1,4,13.4005146026611,4.99750453142139,32.7799990773201,0.566969822555589,0.0844191917480163,1,-3.11842131821252E-7,,,,,,,,,,,,,,,,,,,,,50.0181350708008,50.0184783935547,-69999.5625,-69999.5625,53.7783870086403,5.6381487884183,5.07856798171997,52,1,68,0,0,0.29754638671875,34.7018585205078,1,1,3,50.018482208252,0,50.0183067321777,,,,,,,,,,,,,,,,,,,,,,,,,,,,,,,,,
,3877797978.29545,50.0144691467285,-49999.7421875,3.26999198740629E-4,8.29388684844173E-8,1,4,13.4005146026611,4.99753984597245,32.7799990773201,0.406190397383063,0.0605869694129986,1,-1.39076768053434E-7,,,,,,,,,,,,,,,,,,,,,50.0132751464844,50.0156631469727,-49999.7421875,-49999.7421875,53.9351035267461,5.63807654415495,5.08570337295532,54,1,0,0,1,0.296859741210937,34.7018585205078,1,1,3,50.0132751464844,0,50.0144691467285,,,,,,,,,,,,,,,,,,,,,,,,,,,,,,,,,
,3877798154.30483,50.0156383514404,-29999.61328125,1.97766383250226E-4,3.94367795559851E-8,1,4,13.4005146026611,4.99751840633299,32.7799990773201,0.245660920579513,0.0366299891616459,1,-9.40019654425148E-8,,,,,,,,,,,,,,,,,,,,,50.0142364501953,50.0170402526855,-29999.61328125,-29999.61328125,53.8577223033422,5.63758992047545,5.08129692077637,50,1,32,0,0,0.297622680664063,34.7018585205078,1,1,3,50.0142364501953,0,50.0156383514404,,,,,,,,,,,,,,,,,,,,,,,,,,,,,,,,,
,3877798327.73969,50.0144424438477,-10000.134765625,6.8565424249022E-5,1.4840004778406E-8,1,4,13.4005146026611,4.99753406559907,32.7799990773201,0.085165180390732,0.0127371396498045,1,-2.39930473091535E-9,,,,,,,,,,,,,,,,,,,,,50.0130043029785,50.0158805847168,-10000.134765625,-10000.134765625,53.9550350539865,5.63762781929169,5.08295917510986,53,1,68,0,0,0.2972412109375,34.7018585205078,1,1,3,50.0130043029785,0,50.0144424438477,,,,,,,,,,,,,,,,,,,,,,,,,,,,,,,,,
,3877798403.97341,50.1070384979248,-8500.09375,5.88640253824597E-5,1.67775433329847E-8,1,4,13.4005146026611,4.99753303001355,32.7799990773201,0.0731165092067322,0.0109251375302534,1,-9.95516495208959E-9,,,,,,,,,,,,,,,,,,,,,50.1043548583984,50.1097221374512,-8500.09375,-8500.09375,53.9296321271115,5.63800838072958,5.0841794013977,54,1,0,0,1,0.297164916992188,34.7018585205078,1,1,3,50.1097221374512,0,50.1070384979248,,,,,,,,,,,,,,,,,,,,,,,,,,,,,,,,,
,3877798468.31198,50.0203723907471,-6499.89501953125,4.59056744959017E-5,1.18977902453374E-8,1,4,13.4005146026611,4.99755041113189,32.7799990773201,0.0570193953598783,0.00853009460356063,1,2.71051100169142E-10,,,,,,,,,,,,,,,,,,,,,50.020191192627,50.0205535888672,-6499.89501953125,-6499.89501953125,53.9210342133999,5.63819059124466,5.0879864692688,54,1,0,0,1,0.296478271484375,34.7018585205078,1,1,3,50.020191192627,0,50.0203723907471,,,,,,,,,,,,,,,,,,,,,,,,,,,,,,,,,
,3877798533.10511,50.0565948486328,-4500.099609375,3.28804505218735E-5,9.24569801144419E-9,1,4,13.4005146026611,4.99756361286981,32.7799990773201,0.0408391210667784,0.00612187603065031,1,9.91811454762387E-9,,,,,,,,,,,,,,,,,,,,,50.0540313720703,50.0591583251953,-4500.099609375,-4500.099609375,53.9249423559961,5.63822131275906,5.08098793029785,54,1,0,0,1,0.296630859375,34.7018585205078,1,1,3,50.0591583251953,0,50.0565948486328,,,,,,,,,,,,,,,,,,,,,,,,,,,,,,,,,
,3877798615.09864,50.0540904998779,-3000.15893554687,2.31616766925242E-5,7.66683280085442E-9,1,4,13.4005146026611,4.99756072349756,32.7799990773201,0.0287732348287632,0.00427676073159087,1,-2.16851740626034E-8,,,,,,,,,,,,,,,,,,,,,50.0535049438477,50.0546760559082,-3000.15893554687,-3000.15893554687,53.9507360971307,5.63777446822016,5.08061361312866,54,1,0,0,1,0.297164916992188,35.190616607666,1,1,3,50.0535049438477,0,50.0540904998779,,,,,,,,,,,,,,,,,,,,,,,,,,,,,,,,,
,3877798672.45345,50.0539817810059,-2800.16918945313,2.1940798791584E-5,1.84988508846043E-8,1,4,13.4005146026611,4.9975807591829,32.7799990773201,0.0272909129845866,0.00382276783622519,1,-2.04569833196407E-7,,,,,,,,,,,,,,,,,,,,,50.053466796875,50.0544967651367,-2800.16918945313,-2800.16918945313,53.9452646974961,5.63776415279915,5.09140491485596,52,1,68,0,0,0.296630859375,36.1681327819824,1,1,3,50.053466796875,0,50.0539817810059,,,,,,,,,,,,,,,,,,,,,,,,,,,,,,,,,
,3877798729.7623,50.0376625061035,-2600.1669921875,2.06251172063701E-5,1.94329143275324E-8,1,4,13.4005146026611,4.99757221177608,32.7799990773201,0.0256594463003796,0.00355945900330898,1,-2.19730101860438E-7,,,,,,,,,,,,,,,,,,,,,50.0352935791016,50.0400314331055,-2600.1669921875,-2600.1669921875,53.8506876466692,5.63777313970191,5.07975244522095,54,1,0,0,1,0.2972412109375,35.190616607666,1,1,3,50.0352935791016,0,50.0376625061035,,,,,,,,,,,,,,,,,,,,,,,,,,,,,,,,,
,3877798788.46104,50.038444519043,-2400.1396484375,1.93581160814256E-5,2.09018923686784E-8,1,4,13.4005146026611,4.99757437704361,32.7799990773201,0.0240811285684875,0.00335465652062934,1,-1.95079199410901E-7,,,,,,,,,,,,,,,,,,,,,50.0361595153809,50.0407295227051,-2400.1396484375,-2400.1396484375,53.9671502960346,5.63763507144948,5.09227561950684,52,1,68,0,0,0.296859741210937,34.7018585205078,1,1,3,50.0407371520996,0,50.038444519043,,,,,,,,,,,,,,,,,,,,,,,,,,,,,,,,,
,3877798846.97398,50.0240573883057,-2200.3134765625,1.80655797490915E-5,1.64466682472458E-8,1,4,13.4005146026611,4.99755138713993,32.7799990773201,0.0224772055038398,0.00310315697700343,1,-2.04185551933976E-7,,,,,,,,,,,,,,,,,,,,,50.0230484008789,50.0250663757324,-2200.3134765625,-2200.3134765625,53.9761390240057,5.63735792298139,5.08621978759766,53,1,68,0,0,0.296859741210937,34.7018585205078,1,1,3,50.0250663757324,0,50.0240573883057,,,,,,,,,,,,,,,,,,,,,,,,,,,,,,,,,
,3877798906.40391,50.0336074829102,-2000.24853515625,1.67512642771871E-5,1.83387629931137E-8,1,4,13.4005146026611,4.99756520710388,32.7799990773201,0.0208400759718826,0.0028903615461203,1,-1.78900072768826E-7,,,,,,,,,,,,,,,,,,,,,50.0307769775391,50.0364379882812,-2000.24853515625,-2000.24853515625,53.9374484123038,5.63801693960516,5.0856990814209,52,1,68,0,0,0.297317504882812,35.190616607666,1,1,3,50.0307769775391,0,50.0336074829102,,,,,,,,,,,,,,,,,,,,,,,,,,,,,,,,,
,3877798965.21805,50.001371383667,-1800.03234863281,1.549105257597E-5,2.2286833137631E-8,1,4,13.4005146026611,4.99761607892717,32.7799990773201,0.0192806163103163,0.00261892819155997,1,-2.08937056363829E-7,,,,,,,,,,,,,,,,,,,,,50.0013046264648,50.0014381408691,-1800.03234863281,-1800.03234863281,53.9218158419192,5.63785945308759,5.08186197280884,53,1,68,0,0,0.298233032226562,34.7018585205078,1,1,3,50.0012245178223,0,50.001371383667,,,,,,,,,,,,,,,,,,,,,,,,,,,,,,,,,
,3877799021.43331,50.0536785125732,-1599.95458984375,1.41553919776273E-5,2.15443661967339E-8,1,4,13.4005146026611,4.99759967568943,32.7799990773201,0.0176186905679015,0.00238938343307479,1,-1.93921959676766E-7,,,,,,,,,,,,,,,,,,,,,50.0503082275391,50.0570487976074,-1599.95458984375,-1599.95458984375,53.9519085399096,5.63717864619883,5.08924913406372,54,1,0,0,1,0.296249389648438,35.190616607666,1,1,3,50.0570487976074,0,50.0536785125732,,,,,,,,,,,,,,,,,,,,,,,,,,,,,,,,,
,3877799079.41279,50.04075050354,-1399.91467285156,1.28284982249083E-5,2.00624182927137E-8,1,4,13.4005146026611,4.99761627895857,32.7799990773201,0.0159706735634309,0.00214239526613374,1,-1.94279326208684E-7,,,,,,,,,,,,,,,,,,,,,50.039478302002,50.0420227050781,-1399.91467285156,-1399.91467285156,53.9030567574576,5.63766009350438,5.09210920333862,52,1,68,0,0,0.296783447265625,35.190616607666,1,1,3,50.039478302002,0,50.04075050354,,,,,,,,,,,,,,,,,,,,,,,,,,,,,,,,,
,3877799137.00642,50.0219078063965,-1200.0634765625,1.15514725633068E-5,1.99026705599456E-8,1,4,13.4005146026611,4.99755325480673,32.7799990773201,0.0143867129358016,0.00188825094950221,1,-2.07822088772659E-7,,,,,,,,,,,,,,,,,,,,,50.0200614929199,50.023754119873,-1200.0634765625,-1200.0634765625,53.9272872415538,5.63835389144002,5.08859825134277,53,1,68,0,0,0.296783447265625,35.190616607666,1,1,3,50.0200614929199,0,50.0219078063965,,,,,,,,,,,,,,,,,,,,,,,,,,,,,,,,,
,3877799195.42151,50.0522117614746,-1000.01092529297,1.02827677656191E-5,2.24032889624925E-8,1,4,13.4005146026611,4.99749563894426,32.7799990773201,0.0128159115376991,0.00161728959671818,1,-2.36158221391873E-7,,,,,,,,,,,,,,,,,,,,,50.0516128540039,50.0528106689453,-1000.01092529297,-1000.01092529297,53.9491728400922,5.63800640971521,5.08077335357666,52,1,68,0,0,0.29754638671875,34.7018585205078,1,1,3,50.0516128540039,0,50.0522117614746,,,,,,,,,,,,,,,,,,,,,,,,,,,,,,,,,
,3877799286.41715,50.0398216247559,-800.096923828125,8.99740360686199E-6,2.69219868167558E-8,1,4,13.4005146026611,4.99749983110826,32.7799990773201,0.0112254737543832,0.00133784689528399,1,-2.68856356396944E-7,,,,,,,,,,,,,,,,,,,,,50.0336036682129,50.0460395812988,-800.096923828125,-800.096923828125,53.8983669863422,5.63788115217466,5.0935754776001,52,1,68,0,0,0.29693603515625,34.7018585205078,1,1,3,50.0460395812988,0,50.0398216247559,,,,,,,,,,,,,,,,,,,,,,,,,,,,,,,,,
,3877799361.45219,50.0183601379395,-600.019165039063,7.6690250173384E-6,2.7238053377629E-8,1,4,13.4005146026611,4.9974777948293,32.7799990773201,0.00956956784667697,0.00113039629588665,1,-2.37151847298768E-7,,,,,,,,,,,,,,,,,,,,,50.0170631408691,50.0196571350098,-600.019165039063,-600.019165039063,53.9702768101115,5.63788171551704,5.09375095367432,52,1,68,0,0,0.296249389648438,34.7018585205078,1,1,3,50.0170631408691,0,50.0183601379395,,,,,,,,,,,,,,,,,,,,,,,,,,,,,,,,,
,3877799419.32464,50.0172252655029,-400.016967773438,6.37507218907239E-6,2.4400800614062E-8,1,4,13.4005146026611,4.99749621075899,32.7799990773201,0.00796215667552461,8.91753392612072E-4,1,-2.35720635793463E-7,,,,,,,,,,,,,,,,,,,,,50.0165596008301,50.0178909301758,-400.016967773438,-400.016967773438,53.9030567574576,5.63785022884935,5.08209753036499,53,1,68,0,0,0.296783447265625,34.7018585205078,1,1,3,50.0178909301758,0,50.0172252655029,,,,,,,,,,,,,,,,,,,,,,,,,,,,,,,,,
,3877799485.59667,50.0500621795654,-200.140670776367,5.11719193060821E-6,2.98497650720111E-8,1,4,13.4005146026611,4.9974862451715,32.7799990773201,0.00639834967404878,6.67383602060077E-4,10,-2.28188176071105E-7,,,,,,,,,,,,,,,,,,,,,50.0469589233398,50.053165435791,-200.140670776367,-200.140670776367,53.8448254327749,5.63797275067273,5.0806188583374,54,1,0,0,1,0.297012329101562,34.7018585205078,1,1,3,50.053165435791,0,50.0500621795654,,,,,,,,,,,,,,,,,,,,,,,,,,,,,,,,,
,3877799559.51914,50.0308322906494,-0.113294303417206,3.75457765216828E-6,2.76447191519125E-8,1,4,13.4005146026611,4.99751402071396,32.7799990773201,0.00470882997982552,3.9470596906467E-4,10,-2.43885395060547E-7,,,,,,,,,,,,,,,,,,,,,50.0272102355957,50.0344543457031,-0.113294303417206,-0.113294303417206,53.892504772448,5.63852739607656,5.0827784538269,54,1,0,0,1,0.297393798828125,34.7018585205078,1,1,3,50.0344543457031,0,50.0308322906494,,,,,,,,,,,,,,,,,,,,,,,,,,,,,,,,,
,3877799641.24596,50.0338249206543,199.939254760742,-8.94700728897024E-6,3.31345804663625E-8,1,4,13.4005146026611,4.99754379118734,32.7799990773201,-0.0110708762565293,-0.00194442422021516,1,-2.27018420258861E-7,,,,,,,,,,,,,,,,,,,,,50.0315093994141,50.0361404418945,199.939254760742,199.939254760742,53.9343218982269,5.63747741730169,5.08628225326538,54,1,0,0,1,0.296478271484375,34.7018585205078,1,1,3,50.0315093994141,0,50.0338249206543,,,,,,,,,,,,,,,,,,,,,,,,,,,,,,,,,
,3877799701.24118,50.0207614898682,399.815551757812,-1.0873574711532E-5,6.0846554808991E-7,1,4,13.4005146026611,4.99750636374421,32.7799990773201,-0.013434992195512,-0.00249441699122889,1,-3.81630285345251E-7,,,,,,,,,,,,,,,,,,,,,50.0205726623535,50.0209503173828,399.815551757812,399.815551757812,53.8870333728134,5.63774946925116,5.0915641784668,54,1,0,0,1,0.296859741210937,34.7018585205078,1,1,3,50.0205726623535,0,50.0207614898682,,,,,,,,,,,,,,,,,,,,,,,,,,,,,,,,,
,3877799758.94014,50.018705368042,599.817810058594,-1.15628495080364E-5,1.57532168522428E-8,1,4,13.4005146026611,4.99754849606332,32.7799990773201,-0.0143296630692952,-0.00236606368248977,1,-1.75159545925705E-7,,,,,,,,,,,,,,,,,,,,,50.0170440673828,50.0203666687012,599.817810058594,599.817810058594,53.9354943410057,5.63802383653442,5.08666324615479,52,1,68,0,0,0.296707153320313,34.2131004333496,1,1,3,50.0170440673828,0,50.018705368042,,,,,,,,,,,,,,,,,,,,,,,,,,,,,,,,,
,3877799816.77573,50.0385150909424,799.668884277344,-1.28615547727623E-5,2.31722214371877E-8,1,4,13.4005146026611,4.99754074929529,32.7799990773201,-0.0159401146870101,-0.00262498495329207,1,-1.89340356180124E-7,,,,,,,,,,,,,,,,,,,,,50.0362510681152,50.0407791137695,799.668884277344,799.668884277344,53.9456555117557,5.63779192424385,5.09252691268921,54,1,0,0,1,0.297393798828125,34.7018585205078,1,1,3,50.0362510681152,0,50.0385150909424,,,,,,,,,,,,,,,,,,,,,,,,,,,,,,,,,
,3877799874.51863,50.0559997558594,999.85986328125,-1.41606247982117E-5,3.19874467379518E-8,1,4,13.4005146026611,4.99752562090725,32.7799990773201,-0.0175639108334737,-0.00279750114314244,1,-1.33908125258083E-7,,,,,,,,,,,,,,,,,,,,,50.0534706115723,50.0585289001465,999.85986328125,999.85986328125,53.9272872415538,5.63759308571332,5.09450769424438,54,1,0,0,1,0.296707153320313,34.7018585205078,1,1,3,50.0585289001465,0,50.0559997558594,,,,,,,,,,,,,,,,,,,,,,,,,,,,,,,,,
,3877799932.17786,50.0701599121094,1199.69848632812,-1.55016639707293E-5,1.69083337738383E-8,1,4,13.4005146026611,4.99757319889809,32.7799990773201,-0.0192312617901304,-0.00303735225509608,1,-1.26366935832367E-7,,,,,,,,,,,,,,,,,,,,,50.0679092407227,50.0724105834961,1199.69848632812,1199.69848632812,53.8901598868903,5.63777648588835,5.08152103424072,52,1,68,0,0,0.29693603515625,35.190616607666,1,1,3,50.0724105834961,0,50.0701599121094,,,,,,,,,,,,,,,,,,,,,,,,,,,,,,,,,
,3877799989.9561,50.0618381500244,1399.86437988281,-1.68436198284757E-5,3.75943995139398E-8,1,4,13.4005146026611,4.99754338960505,32.7799990773201,-0.0209021005709161,-0.0032588735187198,1,-1.03983498176158E-7,,,,,,,,,,,,,,,,,,,,,50.0609512329102,50.0627250671387,1399.86437988281,1399.86437988281,53.9593340108422,5.6382654895317,5.08741235733032,53,1,68,0,0,0.295181274414063,34.7018585205078,1,1,3,50.0627250671387,0,50.0618381500244,,,,,,,,,,,,,,,,,,,,,,,,,,,,,,,,,
,3877800047.62062,50.0460300445557,1599.56433105469,-1.81095935757177E-5,1.39769195528709E-8,1,4,13.4005146026611,4.99756572741558,32.7799990773201,-0.0224683032709255,-0.00353691568642025,1,-1.38432670098127E-7,,,,,,,,,,,,,,,,,,,,,50.0456695556641,50.0463905334473,1599.56433105469,1599.56433105469,53.9667594817749,5.63757653654169,5.08277416229248,52,1,68,0,0,0.296096801757812,34.2131004333496,1,1,3,50.0463905334473,0,50.0460300445557,,,,,,,,,,,,,,,,,,,,,,,,,,,,,,,,,
,3877800105.40956,50.0273036956787,1799.60424804687,-1.94584561328575E-5,3.37218995128875E-8,1,4,13.4005146026611,4.99758316502195,32.7799990773201,-0.0241514664591501,-0.00373665925742953,1,-9.74469151161267E-8,,,,,,,,,,,,,,,,,,,,,50.0254554748535,50.0291519165039,1799.60424804687,1799.60424804687,53.8604580031595,5.63754272539379,5.09211587905884,54,1,0,0,1,0.298080444335937,34.7018585205078,1,1,3,50.0254554748535,0,50.0273036956787,,,,,,,,,,,,,,,,,,,,,,,,,,,,,,,,,
,3877800163.13158,50.0328922271729,2000.04711914062,-2.07410215964705E-5,1.50015478199235E-8,1,4,13.4005146026611,4.99758070672222,32.7799990773201,-0.0257420356208192,-0.00399170148814865,1,-1.10914802171207E-7,,,,,,,,,,,,,,,,,,,,,50.0294456481934,50.0363388061523,2000.04711914062,2000.04711914062,53.8885966298519,5.63770241177765,5.08844423294067,54,1,0,0,1,0.297088623046875,34.7018585205078,1,1,3,50.0363388061523,0,50.0328922271729,,,,,,,,,,,,,,,,,,,,,,,,,,,,,,,,,
,3877800220.86388,50.0198707580566,2199.93603515625,-2.204553673478E-5,1.10618557509186E-8,1,4,13.4005146026611,4.99755198197144,32.7799990773201,-0.0273643112602357,-0.00421973259453423,1,-9.93782703775987E-8,,,,,,,,,,,,,,,,,,,,,50.0183982849121,50.0213432312012,2199.93603515625,2199.93603515625,53.892504772448,5.63731570601503,5.09242963790894,54,1,0,0,1,0.29571533203125,34.2131004333496,1,1,3,50.0183982849121,0,50.0198707580566,,,,,,,,,,,,,,,,,,,,,,,,,,,,,,,,,
,3877800279.48043,50.0271873474121,2399.92553710938,-2.33479125797231E-5,1.08350861629631E-8,1,4,13.4005146026611,4.997603756963,32.7799990773201,-0.0289866487122921,-0.00443348177385603,1,-7.65859281961772E-8,,,,,,,,,,,,,,,,,,,,,50.0271453857422,50.027229309082,2399.92553710938,2399.92553710938,53.8819527874384,5.63759701486628,5.08639001846313,54,1,0,0,1,0.297317504882812,34.7018585205078,1,1,3,50.027229309082,0,50.0271873474121,,,,,,,,,,,,,,,,,,,,,,,,,,,,,,,,,
,3877800337.22564,50.0732650756836,2599.77685546875,-2.46576531688516E-5,8.82663386893529E-9,1,4,13.4005146026611,4.99758749360983,32.7799990773201,-0.0306154177399132,-0.00466308920874756,1,-6.55253461061273E-8,,,,,,,,,,,,,,,,,,,,,50.0729293823242,50.073600769043,2599.77685546875,2599.77685546875,53.8577223033422,5.63771155420516,5.08208894729614,54,1,0,0,1,0.296173095703125,34.2131004333496,1,1,3,50.073600769043,0,50.0732650756836,,,,,,,,,,,,,,,,,,,,,,,,,,,,,,,,,
,3877800394.82227,50.0069522857666,2799.93017578125,-2.59589921659969E-5,9.1148468238228E-9,1,4,13.4005146026611,4.99757267425613,32.7799990773201,-0.0322345787308814,-0.00488559076010534,1,-5.00008553091144E-8,,,,,,,,,,,,,,,,,,,,,50.0062789916992,50.007625579834,2799.93017578125,2799.93017578125,53.8104337779288,5.63721469539624,5.09310150146484,54,1,0,0,1,0.297927856445313,34.7018585205078,1,1,3,50.0062789916992,0,50.0069522857666,,,,,,,,,,,,,,,,,,,,,,,,,,,,,,,,,
,3877800452.42624,50.0450096130371,2999.81884765625,-2.72551884885846E-5,1.90014622715267E-8,1,4,13.4005146026611,4.99754205115444,32.7799990773201,-0.0338475097693943,-0.00510496595810387,1,-3.27483762665451E-8,,,,,,,,,,,,,,,,,,,,,50.0444946289063,50.045524597168,2999.81884765625,2999.81884765625,53.9780930953038,5.63749792675844,5.09338092803955,54,1,0,0,1,0.296401977539063,34.7018585205078,1,1,3,50.0444946289063,0,50.0450096130371,,,,,,,,,,,,,,,,,,,,,,,,,,,,,,,,,
,3877800530.20107,50.0240898132324,4499.7724609375,-3.70408491164119E-5,9.77063189408172E-9,1,4,13.4005146026611,4.99756973420521,32.7799990773201,-0.0460220245585019,-0.00679350384157512,1,7.17437466231157E-8,,,,,,,,,,,,,,,,,,,,,50.0231895446777,50.0249900817871,4499.7724609375,4499.7724609375,53.8440438042557,5.63765234265692,5.08500385284424,54,1,0,0,1,0.303497314453125,34.2131004333496,1,1,3,50.0249900817871,0,50.0240898132324,,,,,,,,,,,,,,,,,,,,,,,,,,,,,,,,,
,3877800596.0108,50.0054206848145,6499.69384765625,-4.99838866077579E-5,1.32782965866638E-8,1,4,13.4005146026611,4.99755463004146,32.7799990773201,-0.0621036690967028,-0.00916319318171074,1,1.00112983565939E-7,,,,,,,,,,,,,,,,,,,,,50.0049209594727,50.0059204101562,6499.69384765625,6499.69384765625,53.9194709563615,5.63795715330575,5.09113645553589,54,1,0,0,1,0.29693603515625,34.2131004333496,1,1,3,50.0049209594727,0,50.0054206848145,,,,,,,,,,,,,,,,,,,,,,,,,,,,,,,,,
,3877800660.86673,50.0604248046875,8499.9931640625,-6.30551014715557E-5,1.41921908903986E-8,1,4,13.4005146026611,4.99760174709657,32.7799990773201,-0.0783440193395627,-0.0115684617636854,1,1.19158455316351E-7,,,,,,,,,,,,,,,,,,,,,50.0598945617676,50.0609550476074,8499.9931640625,8499.9931640625,53.8026174927365,5.63769748299409,5.08551454544067,54,1,0,0,1,0.296707153320313,34.7018585205078,1,1,3,50.0609550476074,0,50.0604248046875,,,,,,,,,,,,,,,,,,,,,,,,,,,,,,,,,
,3877800734.8659,50.002347946167,10000.1103515625,-7.28024986220046E-5,1.36540611740244E-8,1,4,13.4005146026611,4.99755882075264,32.7799990773201,-0.090443771420145,-0.0134234676981763,1,8.37574435702824E-8,,,,,,,,,,,,,,,,,,,,,50.0023460388184,50.0023498535156,10000.1103515625,10000.1103515625,53.9397932978615,5.6374978320529,5.08387279510498,54,1,0,0,1,0.296478271484375,34.7018585205078,1,1,3,50.0023498535156,0,50.002347946167,,,,,,,,,,,,,,,,,,,,,,,,,,,,,,,,,
,3877800887.6318,50.0105457305908,30000.431640625,-2.01955392483451E-4,4.31352678477001E-8,1,4,13.4005146026611,4.99755856891368,32.7799990773201,-0.250888100470931,-0.0372668148470925,1,2.0828418155656E-7,,,,,,,,,,,,,,,,,,,,,50.009765625,50.0113258361816,30000.431640625,30000.431640625,53.8882058155922,5.63819200135865,5.08439588546753,52,1,68,0,0,0.296783447265625,34.7018585205078,1,1,3,50.009765625,0,50.0105457305908,,,,,,,,,,,,,,,,,,,,,,,,,,,,,,,,,
,3877801060.58344,50.0135154724121,50000.2578125,-3.31020520377313E-4,1.30241192890206E-7,1,4,13.4005146026611,4.99754694615285,32.7799990773201,-0.411224945455108,-0.0610745183262345,1,3.48218558238966E-7,,,,,,,,,,,,,,,,,,,,,50.0116119384766,50.0154190063477,50000.2578125,50000.2578125,53.8452162470345,5.63812206873453,5.08864259719849,54,1,0,0,1,0.2972412109375,34.2131004333496,1,1,3,50.0154190063477,0,50.0135154724121,,,,,,,,,,,,,,,,,,,,,,,,,,,,,,,,,
,3877801218.45039,50.0574340820313,70000.3203125,-4.60513563847043E-4,2.65650421004177E-7,1,4,13.4005146026611,4.99756431540276,32.7799990773201,-0.572053526718285,-0.0852522388956334,1,2.54701510376125E-7,,,,,,,,,,,,,,,,,,,,,50.0522956848145,50.062572479248,70000.3203125,70000.3203125,53.7979277216211,5.6383585390624,5.09195232391357,54,1,0,0,1,0.296478271484375,34.7018585205078,1,1,3,50.062572479248,0,50.0574340820313,,,,,,,,,,,,,,,,,,,,,,,,,,,,,,,,,