File: SQUID/Reference/STO/A6/STO_MH_20K_FC_1T.csv
Comment,Time Stamp (sec),Temperature (K),Magnetic Field (Oe),Moment (emu),M. Std. Err. (emu),Transport Action,Averaging Time (sec),Frequency (Hz),Peak Amplitude (mm),Center Position (mm),Lockin Signal' (V),Lockin Signal (V),Range,M. Quad. Signal (emu),AC Moment (emu),AC M. Std Err. (emu),AC Phase (deg),AC Phase Std. Err. (deg),AC Susceptibility (emu/Oe),AC Suscept. Std Err. (emu/Oe),AC X' (emu/Oe),AC X' Std Err. (emu/Oe),AC X'' (emu/Oe),AC X'' Std Err. (emu/Oe),AC Drive (Oe),AC Frequency (Hz),AC Averaging Time (sec),AC Cycles,AC Range,AC Measure Type,AC Signal' (V),AC Signal'' (V),AC Trim Coil Ratio,AC Trim Coil Phase,Min. Temperature (K),Max. Temperature (K),Min. Field (Oe),Max. Field (Oe),Mass (grams),Motor Lag (deg),Pressure (Torr),Measure Count,Measurement Number,SQUID Status (code),Motor Status (code),Measure Status (code),Motor Current (amps),Motor Temp. (C),Temp. Status (code),Field Status (code),Chamber Status (code),Chamber Temp (K),Redirection State,Average Temp (K),Rotation Angle (deg),Rotator state,DC Moment Fixed Ctr (emu),DC Moment Err Fixed Ctr (emu),DC Moment Free Ctr (emu),DC Moment Err Free Ctr (emu),DC Fixed Fit,DC Free Fit,DC Calculated Center (mm),DC Calculated Center Err (mm),DC Scan Length (mm),DC Scan Time (s),DC Number of Points,DC Squid Drift,DC Min V (V),DC Max V (V),DC Scans per Measure,Map 01,Map 02,Map 03,Map 04,Map 05,Map 06,Map 07,Map 08,Map 09,Map 10,Map 11,Map 12,Map 13,Map 14,Map 15,Map 16
,3877786859.19837,20.001651763916,69999.625,-4.48187924028917E-4,1.83085878569814E-7,1,4,13.4005146026611,5.00769521044401,32.7799990773201,-0.558422602387409,-0.0825334428916727,10,7.87700279963363E-7,,,,,,,,,,,,,,,,,,,,,20.0016078948975,20.0016956329346,69999.625,69999.625,53.5755544078999,5.63876029757408,4.4512825012207,54,1,0,0,1,0.305709838867188,33.7243423461914,1,1,3,20.0015735626221,0,20.001651763916,,,,,,,,,,,,,,,,,,,,,,,,,,,,,,,,,
,3877787038.51582,19.9986133575439,49999.9296875,-3.19308637257892E-4,7.7818717050098E-8,1,4,13.4005146026611,5.00763064972885,32.7799990773201,-0.39773290487339,-0.0594983165526233,1,6.0159853102123E-11,,,,,,,,,,,,,,,,,,,,,19.9954090118408,20.0018177032471,49999.9296875,49999.9296875,53.5767268506787,5.63827505883408,4.45401048660278,54,1,0,0,1,0.30548095703125,34.7018585205078,1,1,3,20.0018177032471,0,19.9986133575439,,,,,,,,,,,,,,,,,,,,,,,,,,,,,,,,,
,3877787197.18288,19.9999265670776,29999.587890625,-1.91241203294729E-4,5.90890056229808E-8,1,4,13.4005146026611,5.00759774649516,32.7799990773201,-0.238211410036962,-0.0356190750572195,1,1.24737043613687E-8,,,,,,,,,,,,,,,,,,,,,19.9982109069824,20.0016422271729,29999.587890625,29999.587890625,53.5587493947364,5.63818236210614,4.45560836791992,54,1,0,0,1,0.299224853515625,34.7018585205078,1,1,3,20.0016422271729,0,19.9999265670776,,,,,,,,,,,,,,,,,,,,,,,,,,,,,,,,,
,3877787354.88504,20.0000162124634,9999.6064453125,-6.3515714941894E-5,2.25811168381198E-8,1,4,13.4005146026611,5.0075209296888,32.7799990773201,-0.0791089584637757,-0.0118629291938026,1,-2.25500597339853E-8,,,,,,,,,,,,,,,,,,,,,20.0000114440918,20.000020980835,9999.6064453125,9999.6064453125,53.5505422952845,5.63788707429555,4.45748376846313,54,1,0,0,1,0.2972412109375,34.7018585205078,1,1,3,20.0000114440918,0,20.0000162124634,,,,,,,,,,,,,,,,,,,,,,,,,,,,,,,,,
,3877787439.87456,19.9994010925293,8499.615234375,-5.39561144199535E-5,1.37406846047366E-8,1,4,13.4005146026611,5.00758166937165,32.7799990773201,-0.0672076848699142,-0.010050299259144,1,2.79278074885779E-9,,,,,,,,,,,,,,,,,,,,,19.9983711242676,20.000431060791,8499.615234375,8499.615234375,53.4266541749864,5.63787397701123,4.44484901428223,54,1,0,0,1,0.3057861328125,34.7018585205078,1,1,3,20.000431060791,0,19.9994010925293,,,,,,,,,,,,,,,,,,,,,,,,,,,,,,,,,
,3877787508.35102,19.9995098114014,6499.58056640625,-4.11901140938954E-5,1.13736755741298E-8,1,4,13.4005146026611,5.00757473249915,32.7799990773201,-0.051301571333783,-0.00770378035463421,1,-2.30719404229023E-8,,,,,,,,,,,,,,,,,,,,,19.9992771148682,19.9997425079346,6499.58056640625,6499.58056640625,53.4465857022268,5.63801407539148,4.45447587966919,54,1,0,0,1,0.299911499023438,35.190616607666,1,1,3,19.9997425079346,0,19.9995098114014,,,,,,,,,,,,,,,,,,,,,,,,,,,,,,,,,
,3877787576.00848,20.0001487731934,4499.68408203125,-2.84041729742743E-5,1.07587902358722E-8,1,4,13.4005146026611,5.00759415312625,32.7799990773201,-0.035375726582021,-0.00532160849251185,1,-2.32574774777397E-8,,,,,,,,,,,,,,,,,,,,,20.0000247955322,20.0002727508545,4499.68408203125,4499.68408203125,53.4852763139287,5.63732157505171,4.45096254348755,54,1,0,0,1,0.299148559570313,35.190616607666,1,1,3,20.0000247955322,0,20.0001487731934,,,,,,,,,,,,,,,,,,,,,,,,,,,,,,,,,
,3877787657.55054,20.0003108978271,2999.56713867188,-1.88563174462603E-5,7.13240317642761E-9,1,4,13.4005146026611,5.00757768259469,32.7799990773201,-0.0234921132482062,-0.00348071773660044,1,2.63515725891504E-8,,,,,,,,,,,,,,,,,,,,,20.0002670288086,20.0003547668457,2999.56713867188,2999.56713867188,53.4755059574383,5.63791171720979,4.44805908203125,54,1,0,0,1,0.298385620117188,35.190616607666,1,1,3,20.00022315979,0,20.0003108978271,,,,,,,,,,,,,,,,,,,,,,,,,,,,,,,,,
,3877787725.82677,20.0009527206421,2799.75390625,-1.76825599023825E-5,1.56297982518533E-8,1,4,13.4005146026611,5.00760153708478,32.7799990773201,-0.0220639968778984,-0.00303638441582086,10,2.07506655238203E-7,,,,,,,,,,,,,,,,,,,,,20.0004577636719,20.0014476776123,2799.75390625,2799.75390625,53.5888420927268,5.63812188596915,4.44401121139526,54,1,0,0,1,0.2984619140625,35.190616607666,1,1,3,20.0004234313965,0,20.0009527206421,,,,,,,,,,,,,,,,,,,,,,,,,,,,,,,,,
,3877787793.70789,20.0008726119995,2599.7138671875,-1.6377837600579E-5,1.76078823680246E-8,1,4,13.4005146026611,5.0075691314092,32.7799990773201,-0.0204406291233588,-0.00278004707190425,1,2.18102924217473E-7,,,,,,,,,,,,,,,,,,,,,20.000638961792,20.001106262207,2599.7138671875,2599.7138671875,53.572427893823,5.63814238579957,4.44841814041138,53,1,68,0,0,0.29815673828125,35.190616607666,1,1,3,20.000638961792,0,20.0008726119995,,,,,,,,,,,,,,,,,,,,,,,,,,,,,,,,,
,3877787851.14062,20.0000314712524,2399.51000976562,-1.51309432135332E-5,1.72743466542913E-8,1,4,13.4005146026611,5.00758819615355,32.7799990773201,-0.0188827040635674,-0.00258056390702317,1,1.91738411986769E-7,,,,,,,,,,,,,,,,,,,,,19.9999465942383,20.0001163482666,2399.51000976562,2399.51000976562,53.4985639987557,5.63774188053084,4.45333814620972,54,1,0,0,1,0.29815673828125,34.7018585205078,1,1,3,20.0001163482666,0,20.0000314712524,,,,,,,,,,,,,,,,,,,,,,,,,,,,,,,,,
,3877787919.26512,20.0001077651978,2199.62133789062,-1.38686225769729E-5,1.99743108311337E-8,1,4,13.4005146026611,5.00761412102665,32.7799990773201,-0.0173120966647332,-0.00233465069725333,10,2.00343407880968E-7,,,,,,,,,,,,,,,,,,,,,19.9998435974121,20.0003719329834,2199.62133789062,2199.62133789062,53.5661748656691,5.63808094514579,4.4471549987793,54,1,0,0,1,0.306930541992188,35.190616607666,1,1,3,20.0003719329834,0,20.0001077651978,,,,,,,,,,,,,,,,,,,,,,,,,,,,,,,,,
,3877787983.31141,20.0003633499146,1999.77014160156,-1.25837478427635E-5,2.2879207735994E-8,1,4,13.4005146026611,5.00761365570718,32.7799990773201,-0.015715740937927,-0.00206791256146825,1,2.22278022887321E-7,,,,,,,,,,,,,,,,,,,,,20.000129699707,20.0005970001221,1999.77014160156,1999.77014160156,53.4833222426306,5.63797148080053,4.44161987304687,54,1,0,0,1,0.299530029296875,34.7018585205078,1,1,3,20.000129699707,0,20.0003633499146,,,,,,,,,,,,,,,,,,,,,,,,,,,,,,,,,
,3877788040.84966,19.9995517730713,1799.83093261719,-1.12791731452863E-5,1.64595092931648E-8,1,4,13.4005146026611,5.00763659852696,32.7799990773201,-0.0140873354183253,-0.00184834660164913,1,2.03404360680099E-7,,,,,,,,,,,,,,,,,,,,,19.9976444244385,20.0014591217041,1799.83093261719,1799.83093261719,53.5325648393422,5.63763170253788,4.44656181335449,53,1,68,0,0,0.301361083984375,34.7018585205078,1,1,3,20.0014591217041,0,19.9995517730713,,,,,,,,,,,,,,,,,,,,,,,,,,,,,,,,,
,3877788098.4004,20.000244140625,1599.7783203125,-1.00218578545523E-5,2.16997309673458E-8,1,4,13.4005146026611,5.00762621851892,32.7799990773201,-0.0125200613612554,-0.00162151419746319,1,1.97419660760076E-7,,,,,,,,,,,,,,,,,,,,,20.000072479248,20.000415802002,1599.7783203125,1599.7783203125,53.3668595932653,5.63809469221675,4.45109891891479,52,1,68,0,0,0.306167602539063,33.7243423461914,1,1,3,20.000072479248,0,20.000244140625,,,,,,,,,,,,,,,,,,,,,,,,,,,,,,,,,
,3877788172.39436,20.0001945495605,1399.80139160156,-8.73777322616814E-6,2.21404066811916E-8,1,4,13.4005146026611,5.00760071671441,32.7799990773201,-0.0109272176028633,-0.00133747293783255,1,2.33355661694444E-7,,,,,,,,,,,,,,,,,,,,,19.9999923706055,20.0003967285156,1399.80139160156,1399.80139160156,53.5071619124672,5.63747143771605,4.45945930480957,54,1,0,0,1,0.298843383789063,34.7018585205078,1,1,3,19.9999923706055,0,20.0001945495605,,,,,,,,,,,,,,,,,,,,,,,,,,,,,,,,,
,3877788228.35154,20.0002765655518,1199.68591308594,-7.48039743644489E-6,1.96513276101447E-8,1,4,13.4005146026611,5.00758452133549,32.7799990773201,-0.00935967246223132,-0.00111200416660626,1,2.26268708005045E-7,,,,,,,,,,,,,,,,,,,,,20.0001831054687,20.0003700256348,1199.68591308594,1199.68591308594,53.4665172294672,5.63814898730799,4.45514583587646,54,1,0,0,1,0.298385620117188,34.7018585205078,1,1,3,20.0001831054687,0,20.0002765655518,,,,,,,,,,,,,,,,,,,,,,,,,,,,,,,,,
,3877788302.23564,20.0001859664917,999.885070800781,-6.22998013260591E-6,2.37377342056399E-8,1,4,13.4005146026611,5.00762941884,32.7799990773201,-0.00781181761958728,-8.15147596150299E-4,1,2.77548176500423E-7,,,,,,,,,,,,,,,,,,,,,20.0000667572021,20.0003051757813,999.885070800781,999.885070800781,53.5388178674961,5.63768812483613,4.46035814285278,53,1,68,0,0,0.298538208007812,35.190616607666,1,1,3,20.0000667572021,0,20.0001859664917,,,,,,,,,,,,,,,,,,,,,,,,,,,,,,,,,
,3877788369.72352,20.0001029968262,799.845153808594,-4.97320331154809E-6,5.74282407390023E-8,1,4,13.4005146026611,5.00762554354638,32.7799990773201,-0.0062453063058444,-5.88023234693786E-4,10,2.7188204428565E-7,,,,,,,,,,,,,,,,,,,,,19.9999656677246,20.0002403259277,799.845153808594,799.845153808594,53.4188378897941,5.63768325039309,4.46057176589966,54,1,0,0,1,0.298690795898438,34.7018585205078,1,1,3,19.9999656677246,0,20.0001029968262,,,,,,,,,,,,,,,,,,,,,,,,,,,,,,,,,
,3877788460.09951,19.9997339248657,600.044311523437,-3.67960754957554E-6,2.83804386737434E-8,1,4,13.4005146026611,5.00766983987235,32.7799990773201,-0.00463284821677603,-3.55050661210745E-4,10,2.65407336476118E-7,,,,,,,,,,,,,,,,,,,,,19.9996910095215,19.99977684021,600.044311523437,600.044311523437,53.4375969742557,5.63743037454053,4.45050048828125,54,1,0,0,1,0.29876708984375,35.190616607666,1,1,3,19.9996910095215,0,19.9997339248657,,,,,,,,,,,,,,,,,,,,,,,,,,,,,,,,,
,3877788542.27569,19.9988069534302,400.079925537109,-2.43181513879557E-6,3.2541182257982E-8,1,4,13.4005146026611,5.00767335561749,32.7799990773201,-0.00307829786215088,-1.24399909318918E-4,1,2.63914800176617E-7,,,,,,,,,,,,,,,,,,,,,19.996732711792,20.0008811950684,400.079925537109,400.079925537109,53.4813681713326,5.63728249364156,4.454176902771,53,1,68,0,0,0.298614501953125,34.7018585205078,1,1,3,20.0008811950684,0,19.9988069534302,,,,,,,,,,,,,,,,,,,,,,,,,,,,,,,,,
,3877788633.91553,19.9999179840088,200.266555786133,-1.15955537961366E-6,2.30827443409645E-8,1,4,13.4005146026611,5.00768222771184,32.7799990773201,-0.00149918222453211,1.50335101780352E-4,1,2.94152902999401E-7,,,,,,,,,,,,,,,,,,,,,19.9998168945313,20.0000190734863,200.266555786133,200.266555786133,53.4133664901595,5.63736670047591,4.4590916633606,54,1,0,0,1,0.305099487304687,34.7018585205078,1,1,3,19.9998168945313,0,19.9999179840088,,,,,,,,,,,,,,,,,,,,,,,,,,,,,,,,,
,3877788707.94926,19.999490737915,0.251765102148056,1.45303923464349E-7,2.55964633928378E-8,1,4,13.4005146026611,5.00766084108997,32.7799990773201,1.31512086304231E-4,3.57844013802935E-4,1,2.65545981731881E-7,,,,,,,,,,,,,,,,,,,,,19.9992904663086,19.9996910095215,0.251765102148056,0.251765102148056,53.5153690119191,5.63749810207309,4.45735502243042,53,1,68,0,0,0.299072265625,34.7018585205078,1,1,3,19.9996910095215,0,19.999490737915,,,,,,,,,,,,,,,,,,,,,,,,,,,,,,,,,
,3877788781.88538,19.9999561309814,-199.687484741211,1.37758142595424E-6,2.75153832629871E-8,1,4,13.4005146026611,5.00764674117236,32.7799990773201,0.00168091643360868,4.90763754334404E-4,1,1.87916372847609E-7,,,,,,,,,,,,,,,,,,,,,19.9998893737793,20.0000228881836,-199.687484741211,-199.687484741211,53.4923109706018,5.63725224596581,4.45875787734985,54,1,0,0,1,0.304412841796875,34.7018585205078,1,1,3,20.0000228881836,0,19.9999561309814,,,,,,,,,,,,,,,,,,,,,,,,,,,,,,,,,
,3877788856.26232,20.0001592636108,-399.689666748047,2.68698934341847E-6,1.5799186333033E-8,1,4,13.4005146026611,5.00765232640724,32.7799990773201,0.00331690511482228,7.01536227927099E-4,1,1.61248110585272E-7,,,,,,,,,,,,,,,,,,,,,19.999849319458,20.0004692077637,-399.689666748047,-399.689666748047,53.4661264152076,5.63739978563786,4.46510982513428,53,1,68,0,0,0.306015014648438,34.7018585205078,1,1,3,19.999849319458,0,20.0001592636108,,,,,,,,,,,,,,,,,,,,,,,,,,,,,,,,,
,3877788939.54848,20.0000915527344,-599.679321289063,3.88520130640236E-6,2.52810364894446E-8,1,4,13.4005146026611,5.00754660874524,32.7799990773201,0.00480173214621097,9.75186370480094E-4,10,2.01717054523894E-7,,,,,,,,,,,,,,,,,,,,,20.0000305175781,20.0001525878906,-599.679321289063,-599.679321289063,53.5220128543326,5.63747566929582,4.47052383422852,54,1,0,0,1,0.297698974609375,34.7018585205078,1,1,3,20.0001525878906,0,20.0000915527344,,,,,,,,,,,,,,,,,,,,,,,,,,,,,,,,,
,3877789022.44257,19.9997587203979,-799.681457519531,5.19534639964647E-6,1.6541898900624E-8,1,4,13.4005146026611,5.00764933046157,32.7799990773201,0.00643225318213252,0.00122970510543004,1,2.10037090849162E-7,,,,,,,,,,,,,,,,,,,,,19.9996089935303,19.9999084472656,-799.681457519531,-799.681457519531,53.4329072031403,5.63727467741164,4.46761512756348,54,1,0,0,1,0.298309326171875,34.7018585205078,1,1,3,19.9999084472656,0,19.9997587203979,,,,,,,,,,,,,,,,,,,,,,,,,,,,,,,,,
,3877789080.49722,19.9997472763062,-999.645874023437,6.48146362059358E-6,2.90865719209424E-8,1,4,13.4005146026611,5.00764962817504,32.7799990773201,0.00804364881288528,0.00140658041034983,1,1.59640391247018E-7,,,,,,,,,,,,,,,,,,,,,19.9995536804199,19.9999408721924,-999.645874023437,-999.645874023437,53.4512754733422,5.63692038910219,4.45887613296509,53,1,68,0,0,0.298385620117188,34.7018585205078,1,1,3,19.9999408721924,0,19.9997472763062,,,,,,,,,,,,,,,,,,,,,,,,,,,,,,,,,
,3877789138.87625,20.0002450942993,-1199.8369140625,7.7428864769736E-6,1.43887696998847E-8,1,4,13.4005146026611,5.00767629968938,32.7799990773201,0.00961037792432804,0.00167230570005266,1,1.84258229924469E-7,,,,,,,,,,,,,,,,,,,,,20.0000991821289,20.0003910064697,-1199.8369140625,-1199.8369140625,53.475896771698,5.63723496772495,4.4666919708252,53,1,68,0,0,0.299148559570313,34.7018585205078,1,1,3,20.0000991821289,0,20.0002450942993,,,,,,,,,,,,,,,,,,,,,,,,,,,,,,,,,
,3877789213.95429,20.0000667572021,-1399.78881835938,9.02558055242719E-6,1.10751953084313E-8,1,4,13.4005146026611,5.00765741590894,32.7799990773201,0.0112189061447991,0.00183888045321325,1,1.26111016291681E-7,,,,,,,,,,,,,,,,,,,,,20.0000228881836,20.0001106262207,-1399.78881835938,-1399.78881835938,53.4919201563422,5.63710107661677,4.47087669372559,54,1,0,0,1,0.306243896484375,34.7018585205078,1,1,3,20.0000228881836,0,20.0000667572021,,,,,,,,,,,,,,,,,,,,,,,,,,,,,,,,,
,3877789273.73631,19.9998893737793,-1599.791015625,1.03074383677353E-5,1.0569185544965E-8,1,4,13.4005146026611,5.00761983105557,32.7799990773201,0.012816000344816,0.00207419675781032,1,1.23286099350916E-7,,,,,,,,,,,,,,,,,,,,,19.999755859375,20.0000228881836,-1599.791015625,-1599.791015625,53.457528501496,5.63718772455731,4.46793270111084,53,1,68,0,0,0.29876708984375,34.7018585205078,1,1,3,19.999719619751,0,19.9998893737793,,,,,,,,,,,,,,,,,,,,,,,,,,,,,,,,,
,3877789334.65182,20.0001220703125,-1799.8056640625,1.15582788015452E-5,1.79623732081914E-8,1,4,13.4005146026611,5.00759875832708,32.7799990773201,0.0143710405527105,0.00232681371087983,1,1.38986071223706E-7,,,,,,,,,,,,,,,,,,,,,20.0000743865967,20.0001697540283,-1799.8056640625,-1799.8056640625,53.3989063625537,5.63785536013564,4.46701431274414,54,1,0,0,1,0.307159423828125,34.7018585205078,1,1,3,20.0000743865967,0,20.0001220703125,,,,,,,,,,,,,,,,,,,,,,,,,,,,,,,,,
,3877789393.50786,20.0004177093506,-1999.68200683594,1.28459024387065E-5,8.69367047859565E-9,1,4,13.4005146026611,5.00761493699193,32.7799990773201,0.0159797266910564,0.00253495995886679,1,1.1346214668279E-7,,,,,,,,,,,,,,,,,,,,,20.0002174377441,20.000617980957,-1999.68200683594,-1999.68200683594,53.5259209969287,5.6376756992642,4.46429824829102,54,1,0,0,1,0.298309326171875,34.7018585205078,1,1,3,20.0002174377441,0,20.0004177093506,,,,,,,,,,,,,,,,,,,,,,,,,,,,,,,,,
,3877789451.25,20.0004148483276,-2199.54565429687,1.41352964790226E-5,3.87004118349117E-8,1,4,13.4005146026611,5.00762543363034,32.7799990773201,0.0175854466238627,0.00277791405736955,1,1.1561990627912E-7,,,,,,,,,,,,,,,,,,,,,20.0002975463867,20.0005321502686,-2199.54565429687,-2199.54565429687,53.5110700550634,5.63805925820214,4.4709300994873,54,1,0,0,1,0.297698974609375,34.2131004333496,1,1,3,20.0002975463867,0,20.0004148483276,,,,,,,,,,,,,,,,,,,,,,,,,,,,,,,,,
,3877789509.94891,19.9999208450317,-2399.68627929687,1.53695130713558E-5,3.61042896099024E-8,1,4,13.4005146026611,5.00765361429764,32.7799990773201,0.0191374780353548,0.0029107514968666,1,3.76152700832208E-8,,,,,,,,,,,,,,,,,,,,,19.999828338623,20.0000133514404,-2399.68627929687,-2399.68627929687,53.3879635632845,5.63760460323859,4.47171783447266,54,1,0,0,1,0.298690795898438,34.7018585205078,1,1,3,20.0000133514404,0,19.9999208450317,,,,,,,,,,,,,,,,,,,,,,,,,,,,,,,,,
,3877789568.42612,19.9999866485596,-2599.56274414062,1.66629613941619E-5,1.29992367349155E-8,1,4,13.4005146026611,5.00762523858418,32.7799990773201,0.0207393893608825,0.0032123216171584,1,8.62493082871E-8,,,,,,,,,,,,,,,,,,,,,19.9999198913574,20.0000534057617,-2599.56274414062,-2599.56274414062,53.465735600948,5.63775897714198,4.46240329742432,54,1,0,0,1,0.298614501953125,34.7018585205078,1,1,3,19.9999198913574,0,19.9999866485596,,,,,,,,,,,,,,,,,,,,,,,,,,,,,,,,,
,3877789628.41514,19.9988880157471,-2799.53979492187,1.79213002102149E-5,3.06343947972842E-8,1,4,13.4005146026611,5.00756476922046,32.7799990773201,0.022313902700058,0.00339661794806313,1,4.60129357416365E-8,,,,,,,,,,,,,,,,,,,,,19.9971103668213,20.0006656646729,-2799.53979492187,-2799.53979492187,53.4872303852268,5.63758125366262,4.47141361236572,54,1,0,0,1,0.298843383789063,34.7018585205078,1,1,3,20.0006656646729,0,19.9988880157471,,,,,,,,,,,,,,,,,,,,,,,,,,,,,,,,,
,3877789688.61509,20.0000972747803,-2999.51684570313,1.91915959691541E-5,1.19942397042198E-8,1,4,13.4005146026611,5.00763436795933,32.7799990773201,0.0238915239623653,0.00366749366972267,1,7.33962430058749E-8,,,,,,,,,,,,,,,,,,,,,19.9998645782471,20.0003299713135,-2999.51684570313,-2999.51684570313,53.5884512784672,5.63731761689684,4.46144676208496,54,1,0,0,1,0.297927856445313,34.2131004333496,1,1,3,20.0003623962402,0,20.0000972747803,,,,,,,,,,,,,,,,,,,,,,,,,,,,,,,,,
,3877789767.59937,20.000129699707,-4499.873046875,2.87816625548735E-5,1.06151425982583E-8,1,4,13.4005146026611,5.00760273486937,32.7799990773201,0.0358589782766391,0.00530527776886032,1,-4.63336367723062E-8,,,,,,,,,,,,,,,,,,,,,19.999942779541,20.000316619873,-4499.873046875,-4499.873046875,53.4043777621883,5.63748320692976,4.46407222747803,54,1,0,0,1,0.298995971679687,34.7018585205078,1,1,3,20.000316619873,0,20.000129699707,,,,,,,,,,,,,,,,,,,,,,,,,,,,,,,,,
,3877789834.98233,19.9984540939331,-6499.517578125,4.15094908769755E-5,1.23719809454653E-8,1,4,13.4005146026611,5.00764763938587,32.7799990773201,0.0517180752493817,0.00764552803953158,1,-7.15967361516494E-8,,,,,,,,,,,,,,,,,,,,,19.9957580566406,20.0011501312256,-6499.517578125,-6499.517578125,53.386400306246,5.63746744059776,4.4738245010376,54,1,0,0,1,0.298843383789063,34.7018585205078,1,1,3,20.0011501312256,0,19.9984540939331,,,,,,,,,,,,,,,,,,,,,,,,,,,,,,,,,
,3877789900.33509,19.9999799728394,-8499.501953125,5.42545820592963E-5,1.71004744656805E-8,1,4,13.4005146026611,5.007660040578,32.7799990773201,0.0675969943036147,0.0099987580438464,1,-8.89962887217101E-8,,,,,,,,,,,,,,,,,,,,,19.9999294281006,20.0000305175781,-8499.501953125,-8499.501953125,53.4950466704191,5.63846046695917,4.4667501449585,52,1,68,0,0,0.299224853515625,35.190616607666,1,1,3,19.9999294281006,0,19.9999799728394,,,,,,,,,,,,,,,,,,,,,,,,,,,,,,,,,
,3877789981.52649,20.000636100769,-9999.681640625,6.38137851112968E-5,1.38999310727674E-8,1,4,13.4005146026611,5.00762133313138,32.7799990773201,0.0794988456560913,0.0118092205135364,1,-6.54249460041365E-8,,,,,,,,,,,,,,,,,,,,,20.0006160736084,20.0006561279297,-9999.681640625,-9999.681640625,53.526702625448,5.63730629719583,4.46246385574341,54,1,0,0,1,0.298233032226562,33.7243423461914,1,1,3,20.0006504058838,0,20.000636100769,,,,,,,,,,,,,,,,,,,,,,,,,,,,,,,,,
,3877790139.17491,20.0001564025879,-29999.650390625,1.91483573757936E-4,4.88121465113471E-8,1,4,13.4005146026611,5.00768324172697,32.7799990773201,0.23853573475978,0.0355532046762222,1,-1.02294677545586E-7,,,,,,,,,,,,,,,,,,,,,20.0000953674316,20.0002174377441,-29999.650390625,-29999.650390625,53.6017389632941,5.63726207718361,4.47316646575928,54,1,0,0,1,0.29815673828125,34.7018585205078,1,1,3,20.0000953674316,0,20.0001564025879,,,,,,,,,,,,,,,,,,,,,,,,,,,,,,,,,
,3877790305.49034,20.0001277923584,-49999.65234375,3.19681771305282E-4,5.83226556885512E-8,1,4,13.4005146026611,5.00770792872893,32.7799990773201,0.398296338962837,0.0589670586311887,10,-4.83405341811718E-7,,,,,,,,,,,,,,,,,,,,,20.0001068115234,20.0001487731934,-49999.65234375,-49999.65234375,53.6161990908999,5.63795751195523,4.47165107727051,54,1,0,0,1,0.298690795898438,34.7018585205078,1,1,3,20.0001068115234,0,20.0001277923584,,,,,,,,,,,,,,,,,,,,,,,,,,,,,,,,,
,3877790473.20013,19.9994039535522,-69999.546875,4.47905824420533E-4,2.62006170502821E-7,1,4,13.4005146026611,5.00770843368329,32.7799990773201,0.557945610423573,0.0833345615743243,1,-1.02602902213108E-7,,,,,,,,,,,,,,,,,,,,,19.999324798584,19.9994831085205,-69999.546875,-69999.546875,53.6408203892557,5.63846028187098,4.46667623519897,54,1,0,0,1,0.297622680664063,34.7018585205078,1,1,3,19.9994831085205,0,19.9994039535522,,,,,,,,,,,,,,,,,,,,,,,,,,,,,,,,,
,3877790634.93425,19.9996843338013,-49999.75390625,3.19300568977583E-4,6.20832891806899E-8,1,4,13.4005146026611,5.00769743786758,32.7799990773201,0.397750947642848,0.059359696157802,1,-1.11029106076397E-7,,,,,,,,,,,,,,,,,,,,,19.9996757507324,19.9996929168701,-49999.75390625,-49999.75390625,53.6251878188711,5.63835209273647,4.4679536819458,54,1,0,0,1,0.299453735351562,34.7018585205078,1,1,3,19.9996757507324,0,19.9996843338013,,,,,,,,,,,,,,,,,,,,,,,,,,,,,,,,,
,3877790795.53125,20.0003366470337,-29999.537109375,1.91257218467455E-4,3.62513655180259E-8,1,4,13.4005146026611,5.00772398220148,32.7799990773201,0.238248503805123,0.0355648189803279,1,-5.94339321138657E-8,,,,,,,,,,,,,,,,,,,,,20.0002326965332,20.0004405975342,-29999.537109375,-29999.537109375,53.5841523216114,5.63759673944708,4.46470594406128,54,1,0,0,1,0.307464599609375,34.7018585205078,1,1,3,20.0004405975342,0,20.0003366470337,,,,,,,,,,,,,,,,,,,,,,,,,,,,,,,,,
,3877790952.29727,20.0000257492065,-10000.248046875,6.35290355535524E-5,1.68482713993828E-8,1,4,13.4005146026611,5.00770282131237,32.7799990773201,0.0791318303931846,0.0118508888749586,1,1.04077780406489E-8,,,,,,,,,,,,,,,,,,,,,19.9999599456787,20.0000915527344,-10000.248046875,-10000.248046875,53.5098976122845,5.6370878319981,4.46484756469727,54,1,0,0,1,0.305252075195313,35.190616607666,1,1,3,19.9999599456787,0,20.0000257492065,,,,,,,,,,,,,,,,,,,,,,,,,,,,,,,,,
,3877791030.80954,19.9999074935913,-8500.0556640625,5.39425330503323E-5,1.39859219382981E-8,1,4,13.4005146026611,5.00771854495267,32.7799990773201,0.0671920085860949,0.0100570212818162,1,4.32708325363335E-9,,,,,,,,,,,,,,,,,,,,,19.9998645782471,19.9999504089355,-8500.0556640625,-8500.0556640625,53.411803233121,5.6371331206575,4.46889066696167,52,1,68,0,0,0.298385620117188,34.7018585205078,1,1,3,19.9998645782471,0,19.9999074935913,,,,,,,,,,,,,,,,,,,,,,,,,,,,,,,,,
,3877791097.30547,20.0006189346313,-6500.0458984375,4.11838666616297E-5,1.42717811648876E-8,1,4,13.4005146026611,5.00772734311471,32.7799990773201,0.0512984198264106,0.00768659971071193,1,9.95042678892654E-9,,,,,,,,,,,,,,,,,,,,,20.0003871917725,20.0008506774902,-6500.0458984375,-6500.0458984375,53.513414940621,5.63632003817472,4.47219324111938,54,1,0,0,1,0.304641723632812,35.190616607666,1,1,3,20.0003871917725,0,20.0006189346313,,,,,,,,,,,,,,,,,,,,,,,,,,,,,,,,,
,3877791162.13278,20.0001573562622,-4500.06201171875,2.84100779697745E-5,9.17923155826407E-9,1,4,13.4005146026611,5.00772585116035,32.7799990773201,0.0353838215108456,0.00532665513282789,1,2.6268514196351E-8,,,,,,,,,,,,,,,,,,,,,20.0000858306885,20.0002288818359,-4500.06201171875,-4500.06201171875,53.513414940621,5.63698027561872,4.47439241409302,54,1,0,0,1,0.305633544921875,34.7018585205078,1,1,3,20.0002288818359,0,20.0001573562622,,,,,,,,,,,,,,,,,,,,,,,,,,,,,,,,,
,3877791245.59886,20.0012044906616,-3000.15893554687,1.88493123514979E-5,7.50625853353899E-9,1,4,13.4005146026611,5.0077422996573,32.7799990773201,0.0234831573384427,0.00348832644833445,1,-1.93238087546403E-8,,,,,,,,,,,,,,,,,,,,,20.001163482666,20.0012454986572,-3000.15893554687,-3000.15893554687,53.4954374846787,5.63733174991449,4.47050905227661,54,1,0,0,1,0.306015014648438,35.190616607666,1,1,3,20.001163482666,0,20.0012044906616,,,,,,,,,,,,,,,,,,,,,,,,,,,,,,,,,
,3877791301.95038,20.0002841949463,-2800.3076171875,1.76915340199391E-5,2.01432534505669E-8,1,4,13.4005146026611,5.00775313936994,32.7799990773201,0.0220767971011919,0.00303358670347141,1,-2.11198271559743E-7,,,,,,,,,,,,,,,,,,,,,20.0001602172852,20.0004081726074,-2800.3076171875,-2800.3076171875,53.4798049142941,5.63758847866923,4.46418952941895,54,1,0,0,1,0.3045654296875,35.190616607666,1,1,3,20.0001430511475,0,20.0002841949463,,,,,,,,,,,,,,,,,,,,,,,,,,,,,,,,,
,3877791357.98563,19.9998588562012,-2600.35595703125,1.63822097966169E-5,1.74632085186829E-8,1,4,13.4005146026611,5.00769211472707,32.7799990773201,0.0204437851464795,0.00280095698139886,1,-2.02046954819651E-7,,,,,,,,,,,,,,,,,,,,,19.9996032714844,20.000114440918,-2600.35595703125,-2600.35595703125,53.4774600287364,5.63779068975734,4.47126245498657,53,1,68,0,0,0.299224853515625,35.190616607666,1,1,3,20.000114440918,0,19.9998588562012,,,,,,,,,,,,,,,,,,,,,,,,,,,,,,,,,
,3877791415.21316,20.000114440918,-2400.31567382813,1.51296373857867E-5,1.83765141347129E-8,1,4,13.4005146026611,5.00774783413673,32.7799990773201,0.0188826879251837,0.00257529492364229,1,-1.95865302285321E-7,,,,,,,,,,,,,,,,,,,,,20.0000381469727,20.0001907348633,-2400.31567382813,-2400.31567382813,53.4821497998518,5.63769554883692,4.46832990646362,54,1,0,0,1,0.30517578125,34.7018585205078,1,1,3,20.0000381469727,0,20.000114440918,,,,,,,,,,,,,,,,,,,,,,,,,,,,,,,,,
,3877791472.14973,20.0003967285156,-2200.30102539062,1.38601166413966E-5,1.96978619572437E-8,1,4,13.4005146026611,5.00771680060249,32.7799990773201,0.0173018679317526,0.00233399919337694,1,-1.99647721852606E-7,,,,,,,,,,,,,,,,,,,,,20.0002994537354,20.0004940032959,-2200.30102539062,-2200.30102539062,53.455574430198,5.63743078920437,4.47327852249146,53,1,68,0,0,0.2978515625,34.7018585205078,1,1,3,20.0002994537354,0,20.0003967285156,,,,,,,,,,,,,,,,,,,,,,,,,,,,,,,,,
,3877791530.80788,19.9988985061646,-2000.412109375,1.25551187662185E-5,2.05576685271253E-8,1,4,13.4005146026611,5.00766865192844,32.7799990773201,0.0156797146829461,0.0020666644966628,1,-2.19022738645898E-7,,,,,,,,,,,,,,,,,,,,,19.9965286254883,20.0012683868408,-2000.412109375,-2000.412109375,53.4864487567076,5.63779252013529,4.46574831008911,54,1,0,0,1,0.30548095703125,35.190616607666,1,1,3,20.0012683868408,0,19.9988985061646,,,,,,,,,,,,,,,,,,,,,,,,,,,,,,,,,
,3877791588.55751,20.000018119812,-1800.12048339844,1.13006448362593E-5,1.752267551984E-8,1,4,13.4005146026611,5.00767727207139,32.7799990773201,0.0141131540194161,0.00185963468420941,1,-1.97571040002027E-7,,,,,,,,,,,,,,,,,,,,,19.9998683929443,20.0001678466797,-1800.12048339844,-1800.12048339844,53.4360337172172,5.63790305169341,4.46377086639404,52,1,68,0,0,0.306396484375,34.7018585205078,1,1,3,19.9998683929443,0,20.000018119812,,,,,,,,,,,,,,,,,,,,,,,,,,,,,,,,,
,3877791647.04005,19.9997282028198,-1600.10571289062,1.0028473466468E-5,2.13155774590264E-8,1,4,13.4005146026611,5.00772988711627,32.7799990773201,0.012528410858024,0.00162448838668474,1,-1.96059308096987E-7,,,,,,,,,,,,,,,,,,,,,19.9992294311523,20.0002269744873,-1600.10571289062,-1600.10571289062,53.4309531318422,5.6376702479538,4.46199321746826,53,1,68,0,0,0.298919677734375,34.7018585205078,1,1,3,20.0002269744873,0,19.9997282028198,,,,,,,,,,,,,,,,,,,,,,,,,,,,,,,,,
,3877791705.59146,20.0000076293945,-1400.06579589844,8.73437987320548E-6,2.03736187385419E-8,1,4,13.4005146026611,5.00770560724711,32.7799990773201,0.0109203011819136,0.00135699755391,1,-2.17205015896608E-7,,,,,,,,,,,,,,,,,,,,,19.9999599456787,20.0000553131104,-1400.06579589844,-1400.06579589844,53.4977823702364,5.63763291155915,4.47335243225098,54,1,0,0,1,0.298309326171875,34.7018585205078,1,1,3,19.9999599456787,0,20.0000076293945,,,,,,,,,,,,,,,,,,,,,,,,,,,,,,,,,
,3877791763.80353,20.0003070831299,-1200.11376953125,7.46153537871523E-6,2.23941728186595E-8,1,4,13.4005146026611,5.00772292432409,32.7799990773201,0.00933515087900936,0.00111781005791827,1,-2.18820574031902E-7,,,,,,,,,,,,,,,,,,,,,19.9998435974121,20.0007705688477,-1200.11376953125,-1200.11376953125,53.5095067980249,5.63769627195439,4.47440624237061,54,1,0,0,1,0.298309326171875,34.7018585205078,1,1,3,20.0007705688477,0,20.0003070831299,,,,,,,,,,,,,,,,,,,,,,,,,,,,,,,,,
,3877791844.58481,20.0004730224609,-1000.23754882813,6.21841029045818E-6,2.41964039499607E-8,1,4,13.4005146026611,5.00767630566996,32.7799990773201,0.00779361908791434,8.39000230615479E-4,10,-2.56676793463262E-7,,,,,,,,,,,,,,,,,,,,,20.0002746582031,20.0006713867187,-1000.23754882813,-1000.23754882813,53.5130241263614,5.63784657914696,4.46872758865356,54,1,0,0,1,0.2984619140625,34.7018585205078,1,1,3,20.0002746582031,0,20.0004730224609,,,,,,,,,,,,,,,,,,,,,,,,,,,,,,,,,
,3877791911.2912,19.9998435974121,-800.260559082031,4.81275042864797E-6,1.29224851178187E-7,1,4,13.4005146026611,5.00771913812618,32.7799990773201,0.0060284069216972,6.73094257930048E-4,1,-1.79596429426116E-7,,,,,,,,,,,,,,,,,,,,,19.999813079834,19.9998741149902,-800.260559082031,-800.260559082031,53.5059894696884,5.63742403753377,4.4635968208313,52,1,68,0,0,0.306243896484375,34.7018585205078,1,1,3,19.999813079834,0,19.9998435974121,,,,,,,,,,,,,,,,,,,,,,,,,,,,,,,,,
,3877791985.50174,20.0001811981201,-600.182800292969,3.67969689438749E-6,5.86934214258148E-8,1,4,13.4005146026611,5.00771369769115,32.7799990773201,0.00463745182546771,3.25420699259634E-4,1,-2.89211219352578E-7,,,,,,,,,,,,,,,,,,,,,20.0000915527344,20.0002708435059,-600.182800292969,-600.182800292969,53.4133664901595,5.63762651503767,4.47418546676636,53,1,68,0,0,0.298309326171875,34.7018585205078,1,1,3,20.0000915527344,0,20.0001811981201,,,,,,,,,,,,,,,,,,,,,,,,,,,,,,,,,
,3877792041.75839,20.0001010894775,-400.205810546875,2.34067574153898E-6,2.87372932739807E-8,1,4,13.4005146026611,5.00767701588103,32.7799990773201,0.00296625446591075,9.75322681210739E-5,1,-2.71850658534229E-7,,,,,,,,,,,,,,,,,,,,,19.9998550415039,20.0003471374512,-400.205810546875,-400.205810546875,53.498173184496,5.63826208881257,4.47337579727173,53,1,68,0,0,0.29998779296875,34.7018585205078,1,1,3,19.9998550415039,0,20.0001010894775,,,,,,,,,,,,,,,,,,,,,,,,,,,,,,,,,
,3877792116.71328,19.9989910125732,-200.16584777832,1.09936482571233E-6,2.3976818891943E-8,1,4,13.4005146026611,5.00761688728981,32.7799990773201,0.00141357197353145,-9.06261960422774E-5,1,-2.37215172844979E-7,,,,,,,,,,,,,,,,,,,,,19.9972343444824,20.0007476806641,-200.16584777832,-200.16584777832,53.5614850945537,5.63862365842866,4.47455978393555,53,1,68,0,0,0.298538208007812,34.7018585205078,1,1,3,20.0007476806641,0,19.9989910125732,,,,,,,,,,,,,,,,,,,,,,,,,,,,,,,,,
,3877792175.31498,20.0009822845459,-0.302118122577667,-1.35107060591018E-7,2.63775286407569E-8,1,4,13.4005146026611,5.00765013131273,32.7799990773201,-1.26740669036639E-4,-3.02930538039473E-4,1,-2.22986732795091E-7,,,,,,,,,,,,,,,,,,,,,20.0006942749023,20.0012702941895,-0.302118122577667,-0.302118122577667,53.4368153457364,5.63764520010424,4.46965932846069,53,1,68,0,0,0.299530029296875,34.2131004333496,1,1,3,20.0006942749023,0,20.0009822845459,,,,,,,,,,,,,,,,,,,,,,,,,,,,,,,,,
,3877792233.02429,20.0001745223999,199.926666259766,-1.4409395581788E-6,1.60940376320858E-8,1,4,13.4005146026611,5.00769041187663,32.7799990773201,-0.00177348654814547,-4.11469016567696E-4,1,-1.14775101549722E-7,,,,,,,,,,,,,,,,,,,,,19.9998531341553,20.0004959106445,199.926666259766,199.926666259766,53.5712554510441,5.63803760246451,4.46617650985718,54,1,0,0,1,0.299224853515625,35.190616607666,1,1,3,19.9998531341553,0,20.0001745223999,,,,,,,,,,,,,,,,,,,,,,,,,,,,,,,,,
,3877792290.75272,20.0001258850098,399.777801513672,-2.67380198773287E-6,1.93550674206503E-8,1,4,13.4005146026611,5.00764290527613,32.7799990773201,-0.00329947041516751,-7.05759639073765E-4,1,-1.6661297384795E-7,,,,,,,,,,,,,,,,,,,,,19.9999942779541,20.0002574920654,399.777801513672,399.777801513672,53.4489305877845,5.63758517512317,4.4756646156311,54,1,0,0,1,0.30609130859375,34.7018585205078,1,1,3,19.9999942779541,0,20.0001258850098,,,,,,,,,,,,,,,,,,,,,,,,,,,,,,,,,
,3877792373.4804,20.0001468658447,599.943603515625,-3.89554215553161E-6,1.33111502541518E-8,1,4,13.4005146026611,5.00767735884866,32.7799990773201,-0.00481886123325715,-9.49921570617851E-4,10,-1.79858685003506E-7,,,,,,,,,,,,,,,,,,,,,19.9999294281006,20.0003643035889,599.943603515625,599.943603515625,53.488012013746,5.63819077418719,4.46288967132568,54,1,0,0,1,0.30487060546875,34.7018585205078,1,1,3,19.9999294281006,0,20.0001468658447,,,,,,,,,,,,,,,,,,,,,,,,,,,,,,,,,
,3877792455.64911,20.0000066757202,799.857727050781,-5.23687833540474E-6,6.17716858273743E-8,1,4,13.4005146026611,5.00761371249448,32.7799990773201,-0.00648077485666051,-0.00125846582043762,1,-2.26923822709388E-7,,,,,,,,,,,,,,,,,,,,,19.9992752075195,20.0007381439209,799.857727050781,799.857727050781,53.5001272557941,5.63708944195971,4.46984052658081,54,1,0,0,1,0.298080444335937,34.7018585205078,1,1,3,20.0007381439209,0,20.0000066757202,,,,,,,,,,,,,,,,,,,,,,,,,,,,,,,,,
,3877792513.97974,20.000147819519,999.822143554687,-6.44946607408282E-6,3.66944438782656E-8,1,4,13.4005146026611,5.00781477759258,32.7799990773201,-0.0080120080794229,-0.0013482282751063,1,-1.17531014126441E-7,,,,,,,,,,,,,,,,,,,,,20.0000076293945,20.0002880096436,999.822143554687,999.822143554687,53.432125574621,5.63712415019331,4.47292852401733,53,1,68,0,0,0.305404663085937,34.7018585205078,1,1,3,20.0002880096436,0,20.000147819519,,,,,,,,,,,,,,,,,,,,,,,,,,,,,,,,,
,3877792571.82355,20.0004110336304,1199.68591308594,-7.75333783903165E-6,1.80534573179541E-8,1,4,13.4005146026611,5.00777945680024,32.7799990773201,-0.00962838398808628,-0.00164281273315197,1,-1.589794998609E-7,,,,,,,,,,,,,,,,,,,,,20.0002880096436,20.0005340576172,1199.68591308594,1199.68591308594,53.5036445841307,5.63725106819885,4.47304439544678,54,1,0,0,1,0.313186645507812,35.190616607666,1,1,3,20.0002880096436,0,20.0004110336304,,,,,,,,,,,,,,,,,,,,,,,,,,,,,,,,,
,3877792629.56002,19.999852180481,1399.86437988281,-9.03559524013952E-6,8.77519604376814E-8,1,4,13.4005146026611,5.00776361930145,32.7799990773201,-0.0112263903185987,-0.00187638573148389,1,-1.54678054360827E-7,,,,,,,,,,,,,,,,,,,,,19.9996662139893,20.0000381469727,1399.86437988281,1399.86437988281,53.5634391658518,5.63774796112492,4.47300148010254,54,1,0,0,1,0.304794311523438,34.2131004333496,1,1,3,19.9996662139893,0,19.999852180481,,,,,,,,,,,,,,,,,,,,,,,,,,,,,,,,,
,3877792695.98786,19.9998245239258,1599.74060058594,-1.03289364999158E-5,5.95449087145482E-8,1,4,13.4005146026611,5.00771247953671,32.7799990773201,-0.0128468672222477,-0.00205314431684409,10,-1.03126073830435E-7,,,,,,,,,,,,,,,,,,,,,19.9997043609619,19.9999446868896,1599.74060058594,1599.74060058594,53.3727218071595,5.63754086010541,4.47171783447266,54,1,0,0,1,0.298309326171875,34.7018585205078,1,1,3,19.9999446868896,0,19.9998245239258,,,,,,,,,,,,,,,,,,,,,,,,,,,,,,,,,
,3877792762.21301,20.0002059936523,1799.78051757813,-1.16462028504275E-5,7.7116920050766E-8,1,4,13.4005146026611,5.00765141951072,32.7799990773201,-0.014475554366201,-0.00237810469176877,1,-1.66982993941639E-7,,,,,,,,,,,,,,,,,,,,,20.0000972747803,20.0003147125244,1799.78051757813,1799.78051757813,53.513414940621,5.6377945089638,4.47112941741943,54,1,0,0,1,0.299453735351562,34.2131004333496,1,1,3,20.0000972747803,0,20.0002059936523,,,,,,,,,,,,,,,,,,,,,,,,,,,,,,,,,
,3877792819.846,19.9999094009399,1999.92114257813,-1.29189643940749E-5,7.16283786219744E-8,1,4,13.4005146026611,5.00764936478182,32.7799990773201,-0.0160604160721433,-0.00261859530031676,1,-1.69656894627613E-7,,,,,,,,,,,,,,,,,,,,,19.9997501373291,20.0000686645508,1999.92114257813,1999.92114257813,53.4887936422653,5.63744527584745,4.46520662307739,52,1,68,0,0,0.305709838867188,34.7018585205078,1,1,3,20.0000686645508,0,19.9999094009399,,,,,,,,,,,,,,,,,,,,,,,,,,,,,,,,,
,3877792877.78798,20.0000162124634,2199.89819335938,-1.41177663895142E-5,3.87081198544292E-8,1,4,13.4005146026611,5.00765125780071,32.7799990773201,-0.0175739413268252,-0.00270645854171714,1,-6.08605077221757E-8,,,,,,,,,,,,,,,,,,,,,19.9999084472656,20.0001239776611,2199.89819335938,2199.89819335938,53.425090917948,5.63794237166942,4.46866130828857,54,1,0,0,1,0.306167602539063,34.7018585205078,1,1,3,20.0001239776611,0,20.0000162124634,,,,,,,,,,,,,,,,,,,,,,,,,,,,,,,,,
,3877792935.55182,19.9999217987061,2400.03881835938,-1.53172515256656E-5,7.62986400933592E-8,1,4,13.4005146026611,5.00759698024455,32.7799990773201,-0.0190618268279424,-0.00296949937978806,1,-9.26347425302172E-8,,,,,,,,,,,,,,,,,,,,,19.999605178833,20.0002384185791,2400.03881835938,2400.03881835938,53.4786324715153,5.63787141709758,4.4680027961731,54,1,0,0,1,0.30487060546875,34.7018585205078,1,1,3,19.999605178833,0,19.9999217987061,,,,,,,,,,,,,,,,,,,,,,,,,,,,,,,,,
,3877792993.11971,20.0000314712524,2599.90283203125,-1.66743716991345E-5,1.25001549474249E-8,1,4,13.4005146026611,5.00763478913861,32.7799990773201,-0.0207515852837904,-0.00322830805227778,1,-9.73697653951843E-8,,,,,,,,,,,,,,,,,,,,,19.9999923706055,20.0000705718994,2599.90283203125,2599.90283203125,53.5091159837653,5.63814394647415,4.46400690078735,54,1,0,0,1,0.299606323242188,34.7018585205078,1,1,3,20.0000705718994,0,20.0000314712524,,,,,,,,,,,,,,,,,,,,,,,,,,,,,,,,,
,3877793051.7188,20.0000791549683,2800.04345703125,-1.7939498757601E-5,7.7279988330777E-9,1,4,13.4005146026611,5.00767952468368,32.7799990773201,-0.0223330774975862,-0.00342825091332032,1,-6.85984819094923E-8,,,,,,,,,,,,,,,,,,,,,20.0000762939453,20.0000820159912,2800.04345703125,2800.04345703125,53.4876211994864,5.63788645899735,4.46269369125366,54,1,0,0,1,0.298309326171875,34.7018585205078,1,1,3,20.0000820159912,0,20.0000791549683,,,,,,,,,,,,,,,,,,,,,,,,,,,,,,,,,
,3877793109.31456,19.9992532730103,2999.80639648438,-1.92084039484253E-5,1.01951043083332E-8,1,4,13.4005146026611,5.00764347728698,32.7799990773201,-0.0239154114017761,-0.00365131269585905,1,-5.78839939528369E-8,,,,,,,,,,,,,,,,,,,,,19.998161315918,20.0003452301025,2999.80639648438,2999.80639648438,53.3770207640153,5.63809575639258,4.46844053268433,54,1,0,0,1,0.2984619140625,34.7018585205078,1,1,3,20.0003452301025,0,19.9992532730103,,,,,,,,,,,,,,,,,,,,,,,,,,,,,,,,,
,3877793187.75195,19.9999961853027,4499.48291015625,-2.87787489375826E-5,9.80910805978138E-9,1,4,13.4005146026611,5.00760628365272,32.7799990773201,-0.0358574044579644,-0.00529123786338384,1,5.71736156985642E-8,,,,,,,,,,,,,,,,,,,,,19.9999961853027,19.9999961853027,4499.48291015625,4499.48291015625,53.4919201563422,5.6386164486194,4.4613471031189,54,1,0,0,1,0.298233032226562,34.2131004333496,1,1,3,19.9999961853027,0,19.9999961853027,,,,,,,,,,,,,,,,,,,,,,,,,,,,,,,,,
,3877793252.32484,19.9990224838257,6499.857421875,-4.41961989321359E-5,1.53111033678584E-8,1,4,13.4005146026611,5.00764070643986,32.7799990773201,-0.0550683146717035,-0.00812107953321016,1,9.17178027487192E-8,,,,,,,,,,,,,,,,,,,,,19.9971237182617,20.0009212493896,6499.857421875,6499.857421875,53.5130241263614,5.63805228633993,4.47284078598022,54,1,0,0,1,0.298233032226562,34.2131004333496,1,1,3,20.0009212493896,0,19.9990224838257,,,,,,,,,,,,,,,,,,,,,,,,,,,,,,,,,
,3877793317.25798,19.9993076324463,8500.3330078125,-5.69818337889677E-5,1.61430812989009E-8,1,4,13.4005146026611,5.00762934493955,32.7799990773201,-0.0710010569845426,-0.0104563125450578,1,1.29572710083959E-7,,,,,,,,,,,,,,,,,,,,,19.9983654022217,20.0002498626709,8500.3330078125,8500.3330078125,53.5661748656691,5.63784616837898,4.46581745147705,54,1,0,0,1,0.298385620117188,34.2131004333496,1,1,3,20.0002498626709,0,19.9993076324463,,,,,,,,,,,,,,,,,,,,,,,,,,,,,,,,,
,3877793391.72238,19.9998054504395,10000.123046875,-6.65458284368553E-5,1.88682059224984E-8,1,4,13.4005146026611,5.00760868075838,32.7799990773201,-0.0829066491598356,-0.012284463638864,1,9.25504374197794E-8,,,,,,,,,,,,,,,,,,,,,19.9997882843018,19.9998226165771,10000.123046875,10000.123046875,53.5630483515922,5.6375614681279,4.46263074874878,54,1,0,0,1,0.306472778320313,34.7018585205078,1,1,3,19.9998226165771,0,19.9998054504395,,,,,,,,,,,,,,,,,,,,,,,,,,,,,,,,,
,3877793544.61518,20.0001726150513,29999.953125,-1.94196382934394E-4,3.5712641567843E-8,1,4,13.4005146026611,5.00766164684707,32.7799990773201,-0.241923597007159,-0.0359904464970906,1,1.56917942589339E-7,,,,,,,,,,,,,,,,,,,,,20.0001621246338,20.0001831054687,29999.953125,29999.953125,53.4461948879672,5.63814684582559,4.47056913375854,53,1,64,0,0,0.30548095703125,34.2131004333496,1,1,3,20.0001831054687,0,20.0001726150513,,,,,,,,,,,,,,,,,,,,,,,,,,,,,,,,,
,3877793725.77874,20.0000114440918,50000.21875,-3.22487238060393E-4,7.72564644754122E-8,1,4,13.4005146026611,5.00759555686903,32.7799990773201,-0.401791021677662,-0.0594030450203909,10,5.5157815555424E-7,,,,,,,,,,,,,,,,,,,,,19.9999408721924,20.0000820159912,50000.21875,50000.21875,53.5739911508614,5.63865049582205,4.47374725341797,54,1,0,0,1,0.298538208007812,34.7018585205078,1,1,3,20.0000820159912,0,20.0000114440918,,,,,,,,,,,,,,,,,,,,,,,,,,,,,,,,,
,3877793900.83894,19.9998912811279,70000.40625,-4.50723639790666E-4,4.72110877603152E-6,1,4,13.4005146026611,5.00768102246549,32.7799990773201,-0.56250620607262,-0.0768070516573801,10,5.7639724038653E-6,,,,,,,,,,,,,,,,,,,,,19.9996681213379,20.000114440918,70000.40625,70000.40625,53.7107761417268,5.63972579164376,4.46405124664307,54,1,0,0,1,0.299453735351562,34.2131004333496,1,1,3,20.000114440918,0,19.9998912811279,,,,,,,,,,,,,,,,,,,,,,,,,,,,,,,,,