File: SQUID/Reference/STO/A6/STO_MT_FC_1T.csv
Comment,Time Stamp (sec),Temperature (K),Magnetic Field (Oe),Moment (emu),M. Std. Err. (emu),Transport Action,Averaging Time (sec),Frequency (Hz),Peak Amplitude (mm),Center Position (mm),Lockin Signal' (V),Lockin Signal (V),Range,M. Quad. Signal (emu),AC Moment (emu),AC M. Std Err. (emu),AC Phase (deg),AC Phase Std. Err. (deg),AC Susceptibility (emu/Oe),AC Suscept. Std Err. (emu/Oe),AC X' (emu/Oe),AC X' Std Err. (emu/Oe),AC X'' (emu/Oe),AC X'' Std Err. (emu/Oe),AC Drive (Oe),AC Frequency (Hz),AC Averaging Time (sec),AC Cycles,AC Range,AC Measure Type,AC Signal' (V),AC Signal'' (V),AC Trim Coil Ratio,AC Trim Coil Phase,Min. Temperature (K),Max. Temperature (K),Min. Field (Oe),Max. Field (Oe),Mass (grams),Motor Lag (deg),Pressure (Torr),Measure Count,Measurement Number,SQUID Status (code),Motor Status (code),Measure Status (code),Motor Current (amps),Motor Temp. (C),Temp. Status (code),Field Status (code),Chamber Status (code),Chamber Temp (K),Redirection State,Average Temp (K),Rotation Angle (deg),Rotator state,DC Moment Fixed Ctr (emu),DC Moment Err Fixed Ctr (emu),DC Moment Free Ctr (emu),DC Moment Err Free Ctr (emu),DC Fixed Fit,DC Free Fit,DC Calculated Center (mm),DC Calculated Center Err (mm),DC Scan Length (mm),DC Scan Time (s),DC Number of Points,DC Squid Drift,DC Min V (V),DC Max V (V),DC Scans per Measure,Map 01,Map 02,Map 03,Map 04,Map 05,Map 06,Map 07,Map 08,Map 09,Map 10,Map 11,Map 12,Map 13,Map 14,Map 15,Map 16
,3877762571.20396,349.919509887695,10000.3623046875,-6.56240181896002E-5,1.63507347817562E-8,1,4,13.4005146026611,5.00902110108336,33.1399999558926,-0.081794965489257,-0.0120888035899264,1,1.15559166539055E-7,,,,,,,,,,,,,,,,,,,,,349.918975830078,349.920043945313,10000.3623046875,10000.3623046875,53.4629999011307,5.63882354383209,6.32615041732788,54,1,0,0,1,0.309524536132812,33.2355842590332,1,1,3,349.920043945313,0,349.919509887695,,,,,,,,,,,,,,,,,,,,,,,,,,,,,,,,,
,3877762593.87325,349.777130126953,10000.3623046875,-6.55978950159837E-5,1.71839820730789E-8,1,4,13.4005146026611,5.00900192708509,33.1399999558926,-0.081757980258471,-0.0121105817925396,1,9.41220753973849E-8,,,,,,,,,,,,,,,,,,,,,349.735015869141,349.819244384766,10000.3623046875,10000.3623046875,53.4465857022268,5.63865610928416,6.34097909927368,54,1,0,0,1,0.304107666015625,33.7243423461914,2,1,3,349.735015869141,0,349.777130126953,,,,,,,,,,,,,,,,,,,,,,,,,,,,,,,,,
,3877762618.04783,348.646102905273,10000.3623046875,-6.56283599687329E-5,1.4525504271567E-8,1,4,13.4005146026611,5.0088630791704,33.1399999558926,-0.0817957932956163,-0.012095603875162,1,1.10323386847728E-7,,,,,,,,,,,,,,,,,,,,,348.546325683594,348.745880126953,10000.3623046875,10000.3623046875,53.5243577398903,5.63927915010319,6.34439945220947,54,1,0,0,1,0.304412841796875,35.190616607666,2,1,3,348.546325683594,0,348.646102905273,,,,,,,,,,,,,,,,,,,,,,,,,,,,,,,,,
,3877762642.26484,346.546310424805,10000.3623046875,-6.56621246690205E-5,1.48782179686882E-8,1,4,13.4005146026611,5.0088394901445,33.1399999558926,-0.0818374482364319,-0.0121010051631745,1,1.1097567717172E-7,,,,,,,,,,,,,,,,,,,,,346.307281494141,346.785339355469,10000.3623046875,10000.3623046875,53.4536203588999,5.63943288578458,6.35041999816895,54,1,0,0,1,0.304794311523438,34.2131004333496,2,1,3,346.307281494141,0,346.546310424805,,,,,,,,,,,,,,,,,,,,,,,,,,,,,,,,,
,3877762666.44025,343.284255981445,10000.3623046875,-6.56922030898845E-5,1.61669269406834E-8,1,4,13.4005146026611,5.00874778584421,33.1399999558926,-0.0818744064980925,-0.0120957752518907,1,1.19424096903997E-7,,,,,,,,,,,,,,,,,,,,,343.023803710937,343.544708251953,10000.3623046875,10000.3623046875,53.607991991448,5.6395779230292,6.36372566223145,54,1,0,0,1,0.304489135742188,33.7243423461914,2,1,3,343.023803710937,0,343.284255981445,,,,,,,,,,,,,,,,,,,,,,,,,,,,,,,,,
,3877762690.72794,338.797729492188,10000.3623046875,-6.57052483081853E-5,1.26309971708047E-8,1,4,13.4005146026611,5.00874199484784,33.1300012767315,-0.0818880460799149,-0.0121147812976939,1,1.06106158773781E-7,,,,,,,,,,,,,,,,,,,,,338.466247558594,339.129211425781,10000.3623046875,10000.3623046875,53.6154174623807,5.63957315966241,6.35085344314575,54,1,0,0,1,0.310211181640625,34.2131004333496,2,1,3,338.466247558594,0,338.797729492188,,,,,,,,,,,,,,,,,,,,,,,,,,,,,,,,,
,3877762714.97958,333.077987670898,10000.3623046875,-6.57196011689679E-5,1.85854739131333E-8,1,4,13.4005146026611,5.00869956609982,33.110000193119,-0.0819046079674531,-0.0121196660920088,1,1.04217697043376E-7,,,,,,,,,,,,,,,,,,,,,332.429595947266,333.726379394531,10000.3623046875,10000.3623046875,53.5376454247172,5.63926515267078,6.3465690612793,54,1,0,0,1,0.309829711914063,34.2131004333496,2,1,3,332.429595947266,0,333.077987670898,,,,,,,,,,,,,,,,,,,,,,,,,,,,,,,,,
,3877762738.93653,326.876190185547,10000.3623046875,-6.57318928682443E-5,1.67698717134924E-8,1,4,13.4005146026611,5.00870243630688,33.110000193119,-0.0819175852104709,-0.0121380340555119,1,9.13224586083331E-8,,,,,,,,,,,,,,,,,,,,,326.28662109375,327.465759277344,10000.3623046875,10000.3623046875,53.5255301826691,5.6394866392715,6.33740663528442,54,1,0,0,1,0.30487060546875,33.7243423461914,2,1,3,326.28662109375,0,326.876190185547,,,,,,,,,,,,,,,,,,,,,,,,,,,,,,,,,
,3877762763.36892,319.834396362305,10000.3623046875,-6.57503053365242E-5,1.49987191214796E-8,1,4,13.4005146026611,5.00867701476715,33.100001513958,-0.0819360188169214,-0.0121676289010792,1,7.025529687765E-8,,,,,,,,,,,,,,,,,,,,,319.411346435547,320.257446289063,10000.3623046875,10000.3623046875,53.4755059574383,5.6390395174896,6.33080148696899,54,1,0,0,1,0.304641723632812,34.2131004333496,2,1,3,319.411346435547,0,319.834396362305,,,,,,,,,,,,,,,,,,,,,,,,,,,,,,,,,
,3877762787.32987,313.876068115234,10000.3623046875,-6.57239687276575E-5,1.14163823120615E-8,1,4,13.4005146026611,5.0086819327149,33.0800004303455,-0.0819082376053115,-0.0121298408250576,1,9.66570951268578E-8,,,,,,,,,,,,,,,,,,,,,313.377777099609,314.374359130859,10000.3623046875,10000.3623046875,53.5884512784672,5.63910967180755,6.32771825790405,54,1,0,0,1,0.29571533203125,34.2131004333496,2,1,3,313.377777099609,0,313.876068115234,,,,,,,,,,,,,,,,,,,,,,,,,,,,,,,,,
,3877762811.54882,308.236114501953,10000.3623046875,-6.57341675147597E-5,1.36317889490687E-8,1,4,13.4005146026611,5.00871315478482,33.0800004303455,-0.0819260173571517,-0.0121027109460446,1,1.20041463810068E-7,,,,,,,,,,,,,,,,,,,,,307.822418212891,308.649810791016,10000.3623046875,10000.3623046875,53.4622182726114,5.63917409499995,6.32431888580322,54,1,0,0,1,0.302886962890625,34.2131004333496,2,1,3,307.822418212891,0,308.236114501953,,,,,,,,,,,,,,,,,,,,,,,,,,,,,,,,,
,3877762835.66874,303.40657043457,10000.3623046875,-6.56765893411047E-5,1.30594354333702E-8,1,4,13.4005146026611,5.00878333501948,33.0800004303455,-0.0818504382014665,-0.0121285852412569,1,9.08525668210838E-8,,,,,,,,,,,,,,,,,,,,,302.999694824219,303.813446044922,10000.3623046875,10000.3623046875,53.4848854996691,5.63925549058211,6.31326580047607,54,1,0,0,1,0.302963256835937,33.7243423461914,2,1,3,302.999694824219,0,303.40657043457,,,,,,,,,,,,,,,,,,,,,,,,,,,,,,,,,
,3877762859.8663,298.518402099609,10000.3623046875,-6.57063853862623E-5,1.75285946435092E-8,1,4,13.4005146026611,5.00875096290324,33.0599993467331,-0.0818853400615541,-0.0121439534057477,1,8.28879062954267E-8,,,,,,,,,,,,,,,,,,,,,298.197174072266,298.839630126953,10000.3623046875,10000.3623046875,53.4497122163037,5.63872475897795,6.31403160095215,54,1,0,0,1,0.303192138671875,34.7018585205078,2,1,3,298.197174072266,0,298.518402099609,,,,,,,,,,,,,,,,,,,,,,,,,,,,,,,,,
,3877762883.99143,294.641464233398,10000.3623046875,-6.57032111504564E-5,1.52574866540209E-8,1,4,13.4005146026611,5.00877803422677,33.0599993467331,-0.0818841785533931,-0.0121289136561344,1,9.45570541434076E-8,,,,,,,,,,,,,,,,,,,,,294.378173828125,294.904754638672,10000.3623046875,10000.3623046875,53.5059894696884,5.63880791693039,6.31274843215942,54,1,0,0,1,0.303955078125,34.2131004333496,2,1,3,294.378173828125,0,294.641464233398,,,,,,,,,,,,,,,,,,,,,,,,,,,,,,,,,
,3877762908.17963,290.653991699219,10000.3623046875,-6.56947788597762E-5,1.42876880518624E-8,1,4,13.4005146026611,5.00879177173847,33.0599993467331,-0.081873995442666,-0.0121273233325254,1,9.46092808173052E-8,,,,,,,,,,,,,,,,,,,,,290.303924560547,291.004058837891,10000.3623046875,10000.3623046875,53.587669649948,5.63895614872937,6.30272960662842,54,1,0,0,1,0.303802490234375,34.2131004333496,2,1,3,290.303924560547,0,290.653991699219,,,,,,,,,,,,,,,,,,,,,,,,,,,,,,,,,
,3877762932.38412,286.612075805664,10000.3623046875,-6.56850170983476E-5,1.51972455615255E-8,1,4,13.4005146026611,5.00879349832874,33.0399982631207,-0.0818598990758668,-0.0121386956717353,1,8.40266710672357E-8,,,,,,,,,,,,,,,,,,,,,286.323791503906,286.900360107422,10000.3623046875,10000.3623046875,53.4192287040537,5.63849001964078,6.29272937774658,54,1,0,0,1,0.31005859375,34.2131004333496,2,1,3,286.323791503906,0,286.612075805664,,,,,,,,,,,,,,,,,,,,,,,,,,,,,,,,,
,3877762956.53726,282.809646606445,10000.3623046875,-6.56702492313077E-5,1.31137635812296E-8,1,4,13.4005146026611,5.00879064073232,33.0399982631207,-0.0818439149717834,-0.0121193412520589,1,9.73428419156461E-8,,,,,,,,,,,,,,,,,,,,,282.529388427734,283.089904785156,10000.3623046875,10000.3623046875,53.6189347907172,5.63910267494003,6.2937331199646,54,1,0,0,1,0.309982299804687,34.7018585205078,2,1,3,282.529388427734,0,282.809646606445,,,,,,,,,,,,,,,,,,,,,,,,,,,,,,,,,
,3877762980.71469,278.882888793945,10000.3623046875,-6.56611015312731E-5,1.59075746003963E-8,1,4,13.4005146026611,5.00879364044047,33.0399982631207,-0.0818327845123022,-0.0121163148987879,1,9.84113773215746E-8,,,,,,,,,,,,,,,,,,,,,278.6171875,279.148590087891,10000.3623046875,10000.3623046875,53.4723794433614,5.63900610838752,6.28556203842163,54,1,0,0,1,0.309677124023438,34.2131004333496,2,1,3,278.584197998047,0,278.882888793945,,,,,,,,,,,,,,,,,,,,,,,,,,,,,,,,,
,3877763004.93258,274.935363769531,10000.3623046875,-6.56645681749157E-5,1.56191675316899E-8,1,4,13.4005146026611,5.00878021279636,33.0399982631207,-0.081835914615637,-0.0121228166823762,1,9.36754335657071E-8,,,,,,,,,,,,,,,,,,,,,274.618713378906,275.252014160156,10000.3623046875,10000.3623046875,53.5102884265441,5.63911582349409,6.27966928482056,54,1,0,0,1,0.310592651367188,34.7018585205078,2,1,3,274.605285644531,0,274.935363769531,,,,,,,,,,,,,,,,,,,,,,,,,,,,,,,,,
,3877763029.11254,270.664138793945,10000.3623046875,-6.56360857665996E-5,1.43353279519231E-8,1,4,13.4005146026611,5.00876077411879,33.0200009047985,-0.081799353246424,-0.0121216429181806,1,9.0303895421355E-8,,,,,,,,,,,,,,,,,,,,,270.37744140625,270.950836181641,10000.3623046875,10000.3623046875,53.511460869323,5.63941731665945,6.26874685287476,54,1,0,0,1,0.295867919921875,33.7243423461914,2,1,3,270.37744140625,0,270.664138793945,,,,,,,,,,,,,,,,,,,,,,,,,,,,,,,,,
,3877763053.25389,266.74821472168,10000.3623046875,-6.56644373010498E-5,1.56849869995953E-8,1,4,13.4005146026611,5.00874128943651,33.0200009047985,-0.0818375765984736,-0.0121045191897058,1,1.08235260342701E-7,,,,,,,,,,,,,,,,,,,,,266.399566650391,267.096862792969,10000.3623046875,10000.3623046875,53.4286082462845,5.63926941043638,6.26833486557007,54,1,0,0,1,0.303802490234375,34.2131004333496,2,1,3,266.399566650391,0,266.74821472168,,,,,,,,,,,,,,,,,,,,,,,,,,,,,,,,,
,3877763077.4311,262.761749267578,10000.3623046875,-6.56628563259914E-5,1.44425124252506E-8,1,4,13.4005146026611,5.00879308878069,33.0200009047985,-0.0818357319833742,-0.0121114689536508,1,1.02561555469283E-7,,,,,,,,,,,,,,,,,,,,,262.480072021484,263.043426513672,10000.3623046875,10000.3623046875,53.5395994960153,5.63949728863052,6.26651096343994,54,1,0,0,1,0.31036376953125,35.190616607666,2,1,3,262.480072021484,0,262.761749267578,,,,,,,,,,,,,,,,,,,,,,,,,,,,,,,,,
,3877763101.62985,258.711990356445,10000.3623046875,-6.56948460495013E-5,1.583442899976E-8,1,4,13.4005146026611,5.00877666121126,32.9999998211861,-0.0818750551577277,-0.0121184528311763,1,1.01697449986454E-7,,,,,,,,,,,,,,,,,,,,,258.435516357422,258.988464355469,10000.3623046875,10000.3623046875,53.6040838488518,5.63853781073681,6.2548041343689,54,1,0,0,1,0.305252075195313,34.7018585205078,2,1,3,258.435516357422,0,258.711990356445,,,,,,,,,,,,,,,,,,,,,,,,,,,,,,,,,
,3877763125.7906,254.869514465332,10000.3623046875,-6.57015736521891E-5,1.6185957058851E-8,1,4,13.4005146026611,5.00878627122261,32.9999998211861,-0.0818843995608739,-0.0121147778180779,1,1.05679366573319E-7,,,,,,,,,,,,,,,,,,,,,254.588195800781,255.150833129883,10000.3623046875,10000.3623046875,53.460655015573,5.63876298672724,6.24997520446777,54,1,0,0,1,0.304412841796875,34.7018585205078,2,1,3,254.588195800781,0,254.869514465332,,,,,,,,,,,,,,,,,,,,,,,,,,,,,,,,,
,3877763149.98548,250.686935424805,10000.3623046875,-6.5718904300455E-5,1.38354913313215E-8,1,4,13.4005146026611,5.00875668610072,32.9999998211861,-0.0819055721287289,-0.0121162063473764,1,1.07045167154185E-7,,,,,,,,,,,,,,,,,,,,,250.363754272461,251.010116577148,10000.3623046875,10000.3623046875,53.5872788356884,5.63888820982942,6.2415599822998,54,1,0,0,1,0.304031372070313,34.2131004333496,2,1,3,250.363754272461,0,250.686935424805,,,,,,,,,,,,,,,,,,,,,,,,,,,,,,,,,
,3877763174.1312,246.687103271484,10000.3623046875,-6.57243758314087E-5,1.52903660873443E-8,1,4,13.4005146026611,5.008736095935,32.9999998211861,-0.0819111200124493,-0.0121224978713856,1,1.02758391938463E-7,,,,,,,,,,,,,,,,,,,,,246.385833740234,246.988372802734,10000.3623046875,10000.3623046875,53.4993456272749,5.63822358233373,6.23748540878296,54,1,0,0,1,0.31036376953125,34.2131004333496,2,1,3,246.385833740234,0,246.687103271484,,,,,,,,,,,,,,,,,,,,,,,,,,,,,,,,,
,3877763198.32512,242.576469421387,10000.3623046875,-6.57284011868323E-5,1.2900840458114E-8,1,4,13.4005146026611,5.00874794913565,32.9799987375736,-0.0819158815914672,-0.0121267971521291,1,9.99422586050956E-8,,,,,,,,,,,,,,,,,,,,,242.248519897461,242.904418945313,10000.3623046875,10000.3623046875,53.5481974097268,5.63859764340514,6.22956943511963,54,1,0,0,1,0.303115844726562,34.2131004333496,2,1,3,242.248519897461,0,242.576469421387,,,,,,,,,,,,,,,,,,,,,,,,,,,,,,,,,
,3877763222.52437,238.578857421875,10000.3623046875,-6.57167700429339E-5,1.49824565849903E-8,1,4,13.4005146026611,5.00877993179291,32.9799987375736,-0.0819031899888612,-0.0121175857306196,1,1.05681924015555E-7,,,,,,,,,,,,,,,,,,,,,238.310089111328,238.847625732422,10000.3623046875,10000.3623046875,53.5208404115537,5.6390277581765,6.21538543701172,54,1,0,0,1,0.30426025390625,34.7018585205078,2,1,3,238.310089111328,0,238.578857421875,,,,,,,,,,,,,,,,,,,,,,,,,,,,,,,,,
,3877763246.71794,234.531127929687,10000.3623046875,-6.57163296570141E-5,1.31840040081405E-8,1,4,13.4005146026611,5.00876237277653,32.9799987375736,-0.0819013911398416,-0.0121231186208376,1,1.01127874720719E-7,,,,,,,,,,,,,,,,,,,,,234.272842407227,234.789413452148,10000.3623046875,10000.3623046875,53.5810258075345,5.63849228533914,6.216064453125,54,1,0,0,1,0.304183959960937,34.2131004333496,2,1,3,234.272842407227,0,234.531127929687,,,,,,,,,,,,,,,,,,,,,,,,,,,,,,,,,
,3877763270.84587,230.381782531738,10000.3623046875,-6.56864645452953E-5,1.55230075016137E-8,1,4,13.4005146026611,5.0087494479548,32.9799987375736,-0.0818632812432863,-0.0121215373816982,1,9.78942057167558E-8,,,,,,,,,,,,,,,,,,,,,230.073944091797,230.68962097168,10000.3623046875,10000.3623046875,53.5098976122845,5.63893783604792,6.21065664291382,54,1,0,0,1,0.31036376953125,34.7018585205078,2,1,3,230.073944091797,0,230.381782531738,,,,,,,,,,,,,,,,,,,,,,,,,,,,,,,,,
,3877763295.06304,226.325805664062,10000.3623046875,-6.57089971522581E-5,1.77803730451829E-8,1,4,13.4005146026611,5.00882276537895,32.9600013792515,-0.0818952044715827,-0.0121114634568296,1,1.09548838306332E-7,,,,,,,,,,,,,,,,,,,,,226.019515991211,226.632095336914,10000.3623046875,10000.3623046875,53.508334355246,5.63899410932977,6.19741106033325,54,1,0,0,1,0.303955078125,35.190616607666,2,1,3,226.019515991211,0,226.325805664062,,,,,,,,,,,,,,,,,,,,,,,,,,,,,,,,,
,3877763319.21051,222.728141784668,10000.3623046875,-6.56878291704925E-5,1.29912570184495E-8,1,4,13.4005146026611,5.0087823760683,32.9600013792515,-0.0818665054335896,-0.0121167444615083,1,1.02034352597885E-7,,,,,,,,,,,,,,,,,,,,,222.470764160156,222.98551940918,10000.3623046875,10000.3623046875,53.4598733870537,5.6385337544772,6.1864595413208,54,1,0,0,1,0.303878784179687,34.7018585205078,2,1,3,222.470764160156,0,222.728141784668,,,,,,,,,,,,,,,,,,,,,,,,,,,,,,,,,
,3877763343.42706,218.614334106445,10000.3623046875,-6.56766405124559E-5,1.34315737228692E-8,1,4,13.4005146026611,5.00883079097914,32.9600013792515,-0.0818563683482163,-0.0120967850515392,1,1.16510448195263E-7,,,,,,,,,,,,,,,,,,,,,218.324829101562,218.903839111328,10000.3623046875,10000.3623046875,53.521622040073,5.63814747364273,6.18077230453491,54,1,0,0,1,0.302963256835937,34.7018585205078,2,1,3,218.324829101562,0,218.614334106445,,,,,,,,,,,,,,,,,,,,,,,,,,,,,,,,,
,3877763367.60215,214.742767333984,10000.3623046875,-6.56420327618154E-5,1.56322496540834E-8,1,4,13.4005146026611,5.00882805511265,32.9600013792515,-0.0818117484790904,-0.0120999199230617,1,1.08810028496046E-7,,,,,,,,,,,,,,,,,,,,,214.467071533203,215.018463134766,10000.3623046875,10000.3623046875,53.4915293420826,5.63916284311624,6.1765832901001,54,1,0,0,1,0.303192138671875,34.7018585205078,2,1,3,214.467071533203,0,214.742767333984,,,,,,,,,,,,,,,,,,,,,,,,,,,,,,,,,
,3877763392.04678,210.504989624023,10000.3623046875,-6.56628088914053E-5,1.48943539563956E-8,1,4,13.4005146026611,5.00879218693189,32.940000295639,-0.0818353144075657,-0.0121137157048263,1,1.00748857356632E-7,,,,,,,,,,,,,,,,,,,,,210.199813842773,210.810165405273,10000.3623046875,10000.3623046875,53.5349097248999,5.6382270386686,6.16839933395386,53,1,64,0,0,0.30487060546875,34.2131004333496,2,1,3,210.199813842773,0,210.504989624023,,,,,,,,,,,,,,,,,,,,,,,,,,,,,,,,,
,3877763415.93317,206.640518188477,10000.3623046875,-6.55336028641693E-5,1.71757423669024E-8,1,4,13.4005146026611,5.00876244166197,32.940000295639,-0.0816729641105503,-0.0120940801504041,1,9.70986133518119E-8,,,,,,,,,,,,,,,,,,,,,206.325439453125,206.955596923828,10000.3623046875,10000.3623046875,53.5036445841307,5.63805611673669,6.15833282470703,54,1,0,0,1,0.311050415039063,34.7018585205078,2,1,3,206.325439453125,0,206.640518188477,,,,,,,,,,,,,,,,,,,,,,,,,,,,,,,,,
,3877763440.08654,202.52271270752,10000.3623046875,-6.55149557026033E-5,1.77262194106659E-8,1,4,13.4005146026611,5.00881068339058,32.940000295639,-0.0816515678680107,-0.0120858268340657,1,1.01063526876481E-7,,,,,,,,,,,,,,,,,,,,,202.204040527344,202.841384887695,10000.3623046875,10000.3623046875,53.460655015573,5.63864908848623,6.14391565322876,54,1,0,0,1,0.303878784179687,34.7018585205078,2,1,3,202.204040527344,0,202.52271270752,,,,,,,,,,,,,,,,,,,,,,,,,,,,,,,,,
,3877763464.30174,198.654594421387,10000.3623046875,-6.55484799798623E-5,1.72610933415236E-8,1,4,13.4005146026611,5.00882824754163,32.9499989748001,-0.0816927538314867,-0.0120987274948464,1,9.57726173067849E-8,,,,,,,,,,,,,,,,,,,,,198.297515869141,199.011672973633,10000.3623046875,10000.3623046875,53.4966099274576,5.63840795470215,6.13678503036499,54,1,0,0,1,0.31005859375,34.7018585205078,2,1,3,198.297515869141,0,198.654594421387,,,,,,,,,,,,,,,,,,,,,,,,,,,,,,,,,
,3877763488.70129,194.433609008789,10000.3623046875,-6.54866691642643E-5,1.61413880389592E-8,1,4,13.4005146026611,5.00880470452813,32.9199992120266,-0.081616575282912,-0.012077933321831,1,1.03150861225959E-7,,,,,,,,,,,,,,,,,,,,,194.041213989258,194.82600402832,10000.3623046875,10000.3623046875,53.4723794433614,5.63878909945162,6.13177394866943,54,1,0,0,1,0.304718017578125,34.7018585205078,2,1,3,194.041213989258,0,194.433609008789,,,,,,,,,,,,,,,,,,,,,,,,,,,,,,,,,
,3877763512.62397,190.329803466797,10000.3623046875,-6.54658324440046E-5,1.64090097552138E-8,1,4,13.4005146026611,5.00881374138861,32.9199992120266,-0.0815899885021828,-0.0120796259266385,1,9.86998463427727E-8,,,,,,,,,,,,,,,,,,,,,189.999237060547,190.660369873047,10000.3623046875,10000.3623046875,53.4458040737076,5.63783752198573,6.11438322067261,54,1,0,0,1,0.311203002929687,34.7018585205078,2,1,3,189.999237060547,0,190.329803466797,,,,,,,,,,,,,,,,,,,,,,,,,,,,,,,,,
,3877763536.7918,186.434844970703,10000.3623046875,-6.54704009433594E-5,1.66286284695293E-8,1,4,13.4005146026611,5.00878593823325,32.9199992120266,-0.0815950098207023,-0.0120806385356086,1,9.84953743039662E-8,,,,,,,,,,,,,,,,,,,,,186.112518310547,186.757171630859,10000.3623046875,10000.3623046875,53.4762875859576,5.63844683002178,6.10882520675659,54,1,0,0,1,0.304107666015625,34.7018585205078,2,1,3,186.112518310547,0,186.434844970703,,,,,,,,,,,,,,,,,,,,,,,,,,,,,,,,,
,3877763561.05991,182.463424682617,10000.3623046875,-6.5434742990762E-5,1.96556654577272E-8,1,4,13.4005146026611,5.00882927036711,32.9199992120266,-0.0815548386091578,-0.0120522596563367,1,1.16053951916666E-7,,,,,,,,,,,,,,,,,,,,,182.05241394043,182.874435424805,10000.3623046875,10000.3623046875,53.4442408166691,5.63824887719659,6.10389089584351,53,1,64,0,0,0.29632568359375,34.2131004333496,2,1,3,182.05241394043,0,182.463424682617,,,,,,,,,,,,,,,,,,,,,,,,,,,,,,,,,
,3877763585.23656,178.370971679687,10000.3623046875,-6.54156309043935E-5,1.67003228544043E-8,1,4,13.4005146026611,5.00876474578495,32.9199992120266,-0.0815292455129613,-0.0120505600474448,1,1.14384805656376E-7,,,,,,,,,,,,,,,,,,,,,178.06689453125,178.675048828125,10000.3623046875,10000.3623046875,53.6427744605538,5.63837861287212,6.08618640899658,54,1,0,0,1,0.303115844726562,34.7018585205078,2,1,3,178.06689453125,0,178.370971679687,,,,,,,,,,,,,,,,,,,,,,,,,,,,,,,,,
,3877763609.33677,174.70858001709,10000.3623046875,-6.53572658504336E-5,1.25073935204247E-8,1,4,13.4005146026611,5.00870742978063,32.9000018537045,-0.0814468525374724,-0.0120954223895192,1,6.94934329205889E-8,,,,,,,,,,,,,,,,,,,,,174.352172851562,175.064987182617,10000.3623046875,10000.3623046875,53.4755059574383,5.63856632727108,6.08202219009399,54,1,0,0,1,0.304031372070313,35.190616607666,2,1,3,174.352172851562,0,174.70858001709,,,,,,,,,,,,,,,,,,,,,,,,,,,,,,,,,
,3877763633.5094,170.592407226562,10000.3623046875,-6.53480973908952E-5,1.70179941859294E-8,1,4,13.4005146026611,5.00861731463621,32.9000018537045,-0.0814360360667218,-0.0120756614623986,1,8.3737916807888E-8,,,,,,,,,,,,,,,,,,,,,170.268966674805,170.91584777832,10000.3623046875,10000.3623046875,53.4891844565249,5.63817376321382,6.06843900680542,54,1,0,0,1,0.311203002929687,34.7018585205078,2,1,3,170.268966674805,0,170.592407226562,,,,,,,,,,,,,,,,,,,,,,,,,,,,,,,,,
,3877763657.69058,166.646171569824,10000.3623046875,-6.53359821414002E-5,1.42697340231466E-8,1,4,13.4005146026611,5.00862613736978,32.9000018537045,-0.0814219523330288,-0.0120680130424335,1,8.80880234266061E-8,,,,,,,,,,,,,,,,,,,,,166.302352905273,166.989990234375,10000.3623046875,10000.3623046875,53.4477581450057,5.63919598966048,6.05629253387451,54,1,0,0,1,0.296707153320313,34.2131004333496,2,1,3,166.302352905273,0,166.646171569824,,,,,,,,,,,,,,,,,,,,,,,,,,,,,,,,,
,3877763681.86532,162.744132995605,10000.3623046875,-6.52943694991098E-5,1.29899758117503E-8,1,4,13.4005146026611,5.00864010653527,32.9000018537045,-0.0813716616777921,-0.012052017952925,1,9.47383726480377E-8,,,,,,,,,,,,,,,,,,,,,162.369155883789,163.119110107422,10000.3623046875,10000.3623046875,53.4954374846787,5.63926003162601,6.04510164260864,54,1,0,0,1,0.297317504882812,35.190616607666,2,1,3,162.369155883789,0,162.744132995605,,,,,,,,,,,,,,,,,,,,,,,,,,,,,,,,,
,3877763706.04934,158.610855102539,10000.3623046875,-6.52844743787319E-5,1.66571573721798E-8,1,4,13.4005146026611,5.00864214995102,32.9000018537045,-0.0813624650536337,-0.012029552084075,1,1.11294637396003E-7,,,,,,,,,,,,,,,,,,,,,158.274047851562,158.947662353516,10000.3623046875,10000.3623046875,53.5708646367845,5.63855304059444,6.03885984420776,54,1,0,0,1,0.29693603515625,34.7018585205078,2,1,3,158.274047851562,0,158.610855102539,,,,,,,,,,,,,,,,,,,,,,,,,,,,,,,,,
,3877763730.21631,154.507850646973,10000.3623046875,-6.52685739950331E-5,1.54335349074125E-8,1,4,13.4005146026611,5.00866077867,32.880000770092,-0.0813411887282378,-0.0120392714517111,1,1.01165548176784E-7,,,,,,,,,,,,,,,,,,,,,154.16584777832,154.849853515625,10000.3623046875,10000.3623046875,53.5657840514095,5.63887937379968,6.02421760559082,54,1,0,0,1,0.297088623046875,34.7018585205078,2,1,3,154.16584777832,0,154.507850646973,,,,,,,,,,,,,,,,,,,,,,,,,,,,,,,,,
,3877763754.38868,150.613525390625,10000.3623046875,-6.52709728892538E-5,1.49503616395157E-8,1,4,13.4005146026611,5.00862634298598,32.880000770092,-0.0813423811104701,-0.01204638742181,1,9.57202911106956E-8,,,,,,,,,,,,,,,,,,,,,150.263961791992,150.963088989258,10000.3623046875,10000.3623046875,53.3676412217845,5.6389422488398,6.01122903823853,54,1,0,0,1,0.3045654296875,34.7018585205078,2,1,3,150.263961791992,0,150.613525390625,,,,,,,,,,,,,,,,,,,,,,,,,,,,,,,,,
,3877763778.5576,146.621360778809,10000.3623046875,-6.52636243337966E-5,1.60319894121566E-8,1,4,13.4005146026611,5.00859872948644,32.880000770092,-0.0813293809741036,-0.0120664330566927,1,7.8457768102672E-8,,,,,,,,,,,,,,,,,,,,,146.294082641602,146.948638916016,10000.3623046875,10000.3623046875,53.4993456272749,5.63896281831839,6.00350379943848,54,1,0,0,1,0.296783447265625,34.2131004333496,2,1,3,146.294082641602,0,146.621360778809,,,,,,,,,,,,,,,,,,,,,,,,,,,,,,,,,
,3877763802.79734,142.52970123291,10000.3623046875,-6.52478792359141E-5,1.59774164505914E-8,1,4,13.4005146026611,5.00861839506454,32.880000770092,-0.0813123651760224,-0.0120491555712647,1,9.00224618330628E-8,,,,,,,,,,,,,,,,,,,,,142.161544799805,142.897857666016,10000.3623046875,10000.3623046875,53.5657840514095,5.6382989547644,5.9875602722168,54,1,0,0,1,0.302886962890625,34.7018585205078,2,1,3,142.161544799805,0,142.52970123291,,,,,,,,,,,,,,,,,,,,,,,,,,,,,,,,,
,3877763826.97493,138.418281555176,10000.3623046875,-6.51603736809044E-5,1.63799353173405E-8,1,4,13.4005146026611,5.0086092837689,32.8699983656406,-0.081200870986126,-0.012047924041502,1,7.78960113854822E-8,,,,,,,,,,,,,,,,,,,,,138.065216064453,138.771347045898,10000.3623046875,10000.3623046875,53.5399903102749,5.63879776387423,5.98150730133057,54,1,0,0,1,0.30487060546875,34.7018585205078,2,1,3,138.065216064453,0,138.418281555176,,,,,,,,,,,,,,,,,,,,,,,,,,,,,,,,,
,3877763851.10761,134.469421386719,10000.3623046875,-6.51467647050844E-5,1.58828950349001E-8,1,4,13.4005146026611,5.00865736197782,32.8699983656406,-0.0811826434405879,-0.0120613294900001,1,6.52308159238117E-8,,,,,,,,,,,,,,,,,,,,,134.103775024414,134.835067749023,10000.3623046875,10000.3623046875,53.5048170269095,5.63948274277951,5.96857595443726,54,1,0,0,1,0.30426025390625,34.2131004333496,2,1,3,134.103775024414,0,134.469421386719,,,,,,,,,,,,,,,,,,,,,,,,,,,,,,,,,
,3877763875.27088,130.516174316406,10000.3623046875,-6.51509433310659E-5,1.62231155237027E-8,1,4,13.4005146026611,5.00863311232067,32.8699983656406,-0.0811924164547347,-0.0120278276682236,1,9.2678877958603E-8,,,,,,,,,,,,,,,,,,,,,130.208053588867,130.824295043945,10000.3623046875,10000.3623046875,53.4841038711499,5.63894933379905,5.96144723892212,54,1,0,0,1,0.311508178710937,34.2131004333496,2,1,3,130.208053588867,0,130.516174316406,,,,,,,,,,,,,,,,,,,,,,,,,,,,,,,,,
,3877763910.86519,124.454483032227,10000.3623046875,-6.51598823182612E-5,1.53983421590844E-8,1,4,13.4005146026611,5.00865329987875,32.8599996864796,-0.0812019757904685,-0.0120431695526923,1,8.17571905736431E-8,,,,,,,,,,,,,,,,,,,,,123.846092224121,125.062873840332,10000.3623046875,10000.3623046875,53.5227944828518,5.63912317149903,5.94240951538086,52,1,68,0,0,0.2972412109375,34.7018585205078,2,1,3,123.83056640625,0,124.454483032227,,,,,,,,,,,,,,,,,,,,,,,,,,,,,,,,,
,3877763947.84106,118.440860748291,10000.3623046875,-6.51524934686356E-5,1.48259853653219E-8,1,4,13.4005146026611,5.00859497616313,32.8599996864796,-0.0811913427430725,-0.0120423011757536,1,8.11915185208587E-8,,,,,,,,,,,,,,,,,,,,,118.178131103516,118.703590393066,10000.3623046875,10000.3623046875,53.5685197512268,5.63947168009357,5.91985273361206,54,1,0,0,1,0.2978515625,34.2131004333496,2,1,3,118.178131103516,0,118.440860748291,,,,,,,,,,,,,,,,,,,,,,,,,,,,,,,,,
,3877763972.1873,114.422523498535,10000.3623046875,-6.5176796359181E-5,1.58596140701446E-8,1,4,13.4005146026611,5.00859778578467,32.8399986028671,-0.0812225465699918,-0.0120410903322477,1,8.58064881504166E-8,,,,,,,,,,,,,,,,,,,,,113.999954223633,114.845092773438,10000.3623046875,10000.3623046875,53.508334355246,5.63918656195159,5.91283702850342,54,1,0,0,1,0.296707153320313,34.2131004333496,2,1,3,113.999954223633,0,114.422523498535,,,,,,,,,,,,,,,,,,,,,,,,,,,,,,,,,
,3877763996.29294,110.305931091309,10000.3623046875,-6.51451454774171E-5,1.44346221073988E-8,1,4,13.4005146026611,5.00855868145056,32.8399986028671,-0.0811849158703014,-0.0120170753877346,1,1.00240982544483E-7,,,,,,,,,,,,,,,,,,,,,109.959808349609,110.652053833008,10000.3623046875,10000.3623046875,53.5442892671307,5.63904162637006,5.89481163024902,53,1,64,0,0,0.305633544921875,34.2131004333496,2,1,3,109.959808349609,0,110.305931091309,,,,,,,,,,,,,,,,,,,,,,,,,,,,,,,,,
,3877764020.34465,106.361881256104,10000.3623046875,-6.51468682073448E-5,1.60284514312725E-8,1,4,13.4005146026611,5.00854922782226,32.8399986028671,-0.0811874353377482,-0.0120134391953563,1,1.03391714437073E-7,,,,,,,,,,,,,,,,,,,,,106.04224395752,106.681518554688,10000.3623046875,10000.3623046875,53.5552320663999,5.6396672438942,5.88143444061279,54,1,0,0,1,0.29693603515625,34.2131004333496,2,1,3,106.04224395752,0,106.361881256104,,,,,,,,,,,,,,,,,,,,,,,,,,,,,,,,,
,3877764044.52802,102.420761108398,10000.3623046875,-6.51073252477883E-5,1.37099823692897E-8,1,4,13.4005146026611,5.00849372619996,32.8500010073185,-0.0811360247221899,-0.0120118082932535,1,9.8636001149429E-8,,,,,,,,,,,,,,,,,,,,,102.08373260498,102.757789611816,10000.3623046875,10000.3623046875,53.5157598261787,5.63928800335325,5.86428451538086,54,1,0,0,1,0.302963256835937,34.7018585205078,2,1,3,102.08373260498,0,102.420761108398,,,,,,,,,,,,,,,,,,,,,,,,,,,,,,,,,
,3877764068.87238,98.4975891113281,10000.3623046875,-6.50729466780389E-5,1.63966305264747E-8,1,4,13.4005146026611,5.00857865180818,32.8399986028671,-0.0810899088853224,-0.0120404807206796,1,7.07088951983087E-8,,,,,,,,,,,,,,,,,,,,,98.1899871826172,98.8051910400391,10000.3623046875,10000.3623046875,53.4692529292845,5.63946785242066,5.85206842422485,53,1,64,0,0,0.311813354492188,34.7018585205078,2,1,3,98.1899871826172,0,98.4975891113281,,,,,,,,,,,,,,,,,,,,,,,,,,,,,,,,,
,3877764092.88629,94.4801063537598,10000.3623046875,-6.50457366514746E-5,1.72911756430963E-8,1,4,13.4005146026611,5.00856851420329,32.8399986028671,-0.0810581866326336,-0.0120192715617487,1,8.36338237892362E-8,,,,,,,,,,,,,,,,,,,,,94.0626220703125,94.897590637207,10000.3623046875,10000.3623046875,53.4837130568903,5.6392925961116,5.82943964004517,54,1,0,0,1,0.304183959960937,34.7018585205078,2,1,3,94.0626220703125,0,94.4801063537598,,,,,,,,,,,,,,,,,,,,,,,,,,,,,,,,,
,3877764129.15061,88.4687156677246,10000.3623046875,-6.50376251920476E-5,1.7159184527576E-8,1,4,13.4005146026611,5.00855620364639,32.820001244545,-0.0810477075396033,-0.0120183490850842,1,8.31276532156812E-8,,,,,,,,,,,,,,,,,,,,,88.1491546630859,88.7882766723633,10000.3623046875,10000.3623046875,53.4461948879672,5.63892109492577,5.80379009246826,54,1,0,0,1,0.305099487304687,34.7018585205078,2,1,3,88.1491546630859,0,88.4687156677246,,,,,,,,,,,,,,,,,,,,,,,,,,,,,,,,,
,3877764153.38272,84.5867385864258,10000.3623046875,-6.50045137254055E-5,1.43376943013026E-8,1,4,13.4005146026611,5.00860305246455,32.820001244545,-0.0810084928304334,-0.012005778325282,1,8.83898263690033E-8,,,,,,,,,,,,,,,,,,,,,84.2696685791016,84.90380859375,10000.3623046875,10000.3623046875,53.5493698525057,5.63918609426765,5.78707361221314,53,1,64,0,0,0.2978515625,34.2131004333496,2,1,3,84.2696685791016,0,84.5867385864258,,,,,,,,,,,,,,,,,,,,,,,,,,,,,,,,,
,3877764177.49023,80.5341529846191,10000.3623046875,-6.49759677658588E-5,1.47508542773682E-8,1,4,13.4005146026611,5.00863636031096,32.820001244545,-0.0809725201693441,-0.0120083140950116,1,8.21738855617947E-8,,,,,,,,,,,,,,,,,,,,,80.2542572021484,80.8140487670898,10000.3623046875,10000.3623046875,53.4903568993037,5.63915909158688,5.76673316955566,54,1,0,0,1,0.303802490234375,33.7243423461914,2,1,3,80.2542572021484,0,80.5341529846191,,,,,,,,,,,,,,,,,,,,,,,,,,,,,,,,,
,3877764214.02756,74.0503578186035,10000.3623046875,-6.49383089256243E-5,1.52329331277287E-8,1,4,13.4005146026611,5.00864085986606,32.820001244545,-0.0809242289552629,-0.0120111470632893,1,7.42787283472672E-8,,,,,,,,,,,,,,,,,,,,,73.6345520019531,74.4661636352539,10000.3623046875,10000.3623046875,53.4927017848614,5.63901423728903,5.74109601974487,54,1,0,0,1,0.303497314453125,34.7018585205078,2,1,3,73.6147842407227,0,74.0503578186035,,,,,,,,,,,,,,,,,,,,,,,,,,,,,,,,,
,3877764237.93367,70.1143379211426,10000.3623046875,-6.48925406056465E-5,1.59309029761654E-8,1,4,13.4005146026611,5.00862512543505,32.820001244545,-0.0808669631949896,-0.0120017970966713,1,7.48940178283557E-8,,,,,,,,,,,,,,,,,,,,,69.7629013061523,70.4657745361328,10000.3623046875,10000.3623046875,53.4805865428134,5.63857911995194,5.71733427047729,54,1,0,0,1,0.304336547851562,34.2131004333496,2,1,3,69.7629013061523,0,70.1143379211426,,,,,,,,,,,,,,,,,,,,,,,,,,,,,,,,,
,3877764262.11407,65.9460334777832,10000.3623046875,-6.48447267852073E-5,1.72215308688957E-8,1,4,13.4005146026611,5.00860602971502,32.8000001609325,-0.0808092447458762,-0.0119775408145076,1,8.71582083660685E-8,,,,,,,,,,,,,,,,,,,,,65.5744781494141,66.3175888061523,10000.3623046875,10000.3623046875,53.554059623621,5.63869832254841,5.69331932067871,53,1,68,0,0,0.3118896484375,34.2131004333496,2,1,3,65.5744781494141,0,65.9460334777832,,,,,,,,,,,,,,,,,,,,,,,,,,,,,,,,,
,3877764286.37412,61.8301048278809,10000.3623046875,-6.48169852289647E-5,4.65125748296497E-8,1,4,13.4005146026611,5.00864868050715,32.8000001609325,-0.0807752947058519,-0.0119748316764879,1,8.52969896364407E-8,,,,,,,,,,,,,,,,,,,,,61.4820938110352,62.1781158447266,10000.3623046875,10000.3623046875,53.536863796198,5.63914312004171,5.66338586807251,53,1,64,0,0,0.311813354492188,34.7018585205078,2,1,3,61.4820938110352,0,61.8301048278809,,,,,,,,,,,,,,,,,,,,,,,,,,,,,,,,,
,3877764310.47586,57.7121276855469,10000.3623046875,-6.47739078468187E-5,1.4858501604795E-8,1,4,13.4005146026611,5.00865621722068,32.8000001609325,-0.0807250300877261,-0.0119451802391825,1,1.02671098412602E-7,,,,,,,,,,,,,,,,,,,,,57.3447227478027,58.079532623291,10000.3623046875,10000.3623046875,53.5005180700537,5.63918359563857,5.62825393676758,53,1,68,0,0,0.303802490234375,34.7018585205078,2,1,3,57.3215446472168,0,57.7121276855469,,,,,,,,,,,,,,,,,,,,,,,,,,,,,,,,,
,3877764334.8167,53.5732460021973,10000.3623046875,-6.47149963830382E-5,1.6504971977803E-8,1,4,13.4005146026611,5.00864186902319,32.8000001609325,-0.0806490034576009,-0.0119495418382072,1,9.03193232581505E-8,,,,,,,,,,,,,,,,,,,,,53.1879806518555,53.9585113525391,10000.3623046875,10000.3623046875,53.475896771698,5.63846497281777,5.59832429885864,53,1,64,0,0,0.303573608398438,34.2131004333496,2,1,3,53.1879806518555,0,53.5732460021973,,,,,,,,,,,,,,,,,,,,,,,,,,,,,,,,,
,3877764370.02682,47.6274833679199,10000.3623046875,-6.45825385528538E-5,1.85807473094762E-8,1,4,13.4005146026611,5.00868044551962,32.8000001609325,-0.0804813025906063,-0.0119485811626413,1,7.13787096460968E-8,,,,,,,,,,,,,,,,,,,,,47.1573257446289,48.0976409912109,10000.3623046875,10000.3623046875,53.511460869323,5.63877083170229,5.53283977508545,54,1,0,0,1,0.297317504882812,34.7018585205078,2,1,3,47.1573257446289,0,47.6274833679199,,,,,,,,,,,,,,,,,,,,,,,,,,,,,,,,,
,3877764418.8658,39.1777381896973,10000.3623046875,-6.44398096851751E-5,1.44382733828347E-8,1,4,13.4005146026611,5.00869387569126,32.8000001609325,-0.0803022222787848,-0.0119323516812309,1,6.3088803533698E-8,,,,,,,,,,,,,,,,,,,,,39.1235427856445,39.23193359375,10000.3623046875,10000.3623046875,53.6119001340441,5.63882794624688,5.44578075408936,54,1,0,0,1,0.305938720703125,34.7018585205078,2,1,3,39.1235427856445,0,39.1777381896973,,,,,,,,,,,,,,,,,,,,,,,,,,,,,,,,,
,3877764443.75417,34.9130210876465,10000.3623046875,-6.43325447207551E-5,1.93771823103305E-8,1,4,13.4005146026611,5.00873109241768,32.7799990773201,-0.0801719119034835,-0.0118957257125841,1,7.6537173505026E-8,,,,,,,,,,,,,,,,,,,,,34.5904655456543,35.2355766296387,10000.3623046875,10000.3623046875,53.6548897026018,5.64152923344101,5.38255929946899,53,1,64,0,0,0.304031372070313,34.7018585205078,2,1,3,34.5904655456543,0,34.9130210876465,,,,,,,,,,,,,,,,,,,,,,,,,,,,,,,,,
,3877764480.00434,28.7286281585693,10000.3623046875,-6.40957957309472E-5,1.86547299583567E-8,1,4,13.4005146026611,5.00872414048789,32.7799990773201,-0.0798776763773114,-0.0118455176826304,1,8.13982643462901E-8,,,,,,,,,,,,,,,,,,,,,28.4512710571289,29.0059852600098,10000.3623046875,10000.3623046875,53.4848854996691,5.63867043765657,5.2596321105957,54,1,0,0,1,0.304489135742188,34.7018585205078,2,1,3,28.4512710571289,0,28.7286281585693,,,,,,,,,,,,,,,,,,,,,,,,,,,,,,,,,
,3877764503.89556,24.6883840560913,10000.3623046875,-6.39472208006336E-5,1.87352153280458E-8,1,4,13.4005146026611,5.00874476458096,32.7799990773201,-0.0796914330940642,-0.0118284512604921,1,7.29241161939956E-8,,,,,,,,,,,,,,,,,,,,,24.3952407836914,24.9815273284912,10000.3623046875,10000.3623046875,53.6036930345922,5.63878383028721,5.16435050964355,54,1,0,0,1,0.298843383789063,34.2131004333496,2,1,3,24.3720951080322,0,24.6883840560913,,,,,,,,,,,,,,,,,,,,,,,,,,,,,,,,,
,3877764528.10324,20.6490144729614,10000.3623046875,-6.37154090032924E-5,1.6803479142098E-8,1,4,13.4005146026611,5.00874218840469,32.7799990773201,-0.0793998419701488,-0.0118032700925378,1,5.84493950899585E-8,,,,,,,,,,,,,,,,,,,,,20.3827896118164,20.9152393341064,10000.3623046875,10000.3623046875,53.5755544078999,5.63942906100092,5.02774143218994,54,1,0,0,1,0.2972412109375,35.6793746948242,2,1,3,20.3827896118164,0,20.6490144729614,,,,,,,,,,,,,,,,,,,,,,,,,,,,,,,,,
,3877764552.31244,16.6295928955078,10000.3623046875,-6.34008629675309E-5,1.98017793839437E-8,1,4,13.4005146026611,5.00870787359745,32.7799990773201,-0.0790094393484599,-0.0117293139618606,1,7.06602877032096E-8,,,,,,,,,,,,,,,,,,,,,16.3123722076416,16.946813583374,10000.3623046875,10000.3623046875,53.5501514810249,5.6381180829301,4.84881258010864,54,1,0,0,1,0.311660766601562,34.7018585205078,2,1,3,16.3123722076416,0,16.6295928955078,,,,,,,,,,,,,,,,,,,,,,,,,,,,,,,,,
,3877764588.66606,10.801173210144,10000.3623046875,-6.26024044584823E-5,2.04869580120299E-8,1,4,13.4005146026611,5.00871869967065,32.7799990773201,-0.078007804623407,-0.0116273587903446,1,3.30712320787365E-8,,,,,,,,,,,,,,,,,,,,,10.7178936004639,10.8844528198242,10000.3623046875,10000.3623046875,53.4477581450057,5.6392058575259,4.37701606750488,51,1,100,0,0,0.303955078125,34.7018585205078,2,1,3,10.7178936004639,0,10.801173210144,,,,,,,,,,,,,,,,,,,,,,,,,,,,,,,,,
,3877764636.33889,9.02325534820557,10000.3623046875,-6.19913773752865E-5,1.77506011613914E-8,1,4,13.4005146026611,5.00867888009007,32.7799990773201,-0.0772447260965084,-0.0115192887603768,1,2.82972532665984E-8,,,,,,,,,,,,,,,,,,,,,8.9379301071167,9.10858058929443,10000.3623046875,10000.3623046875,53.6861548433711,5.63931112851756,3.90780329704285,52,1,68,0,0,0.304641723632812,35.190616607666,6,1,3,8.9379301071167,0,9.02325534820557,,,,,,,,,,,,,,,,,,,,,,,,,,,,,,,,,
,3877764683.74798,6.05792188644409,10000.3623046875,-6.06615571834997E-5,1.96041267011301E-8,1,4,13.4005146026611,5.00874789991015,32.7799990773201,-0.0755959680874419,-0.0112268299541725,1,6.42614993614215E-8,,,,,,,,,,,,,,,,,,,,,6.0432562828064,6.07258749008179,10000.3623046875,10000.3623046875,53.6150266481211,5.63970214751495,3.29356169700623,54,1,0,0,1,0.311050415039063,34.7018585205078,6,1,3,6.0432562828064,0,6.05792188644409,,,,,,,,,,,,,,,,,,,,,,,,,,,,,,,,,
,3877764709.38796,3.59546518325806,10000.3623046875,-5.80059521593271E-5,3.65084292222342E-8,1,4,13.4005146026611,5.00872409239074,32.7799990773201,-0.0722853504283586,-0.0107402427592636,1,5.74630999971031E-8,,,,,,,,,,,,,,,,,,,,,3.29570817947388,3.89522218704224,10000.3623046875,10000.3623046875,53.6427744605538,5.63916448133636,2.79083323478699,52,1,32,0,0,0.303878784179687,35.190616607666,6,1,3,3.29570817947388,0,3.59546518325806,,,,,,,,,,,,,,,,,,,,,,,,,,,,,,,,,
,3877764733.58247,2.36713397502899,10000.3623046875,-5.58063083052477E-5,1.50308745916131E-8,1,4,13.4005146026611,5.00871969169356,32.7799990773201,-0.0695417899869238,-0.0103486056544178,1,4.27185979036046E-8,,,,,,,,,,,,,,,,,,,,,2.35826992988586,2.37599802017212,10000.3623046875,10000.3623046875,53.4997364415345,5.63982034073053,2.42160248756409,54,1,0,0,1,0.313262939453125,34.7018585205078,6,1,3,2.35826992988586,0,2.36713397502899,,,,,,,,,,,,,,,,,,,,,,,,,,,,,,,,,
,3877764757.78186,2.34046673774719,10000.3623046875,-5.5720628945168E-5,1.98973956524625E-8,1,4,13.4005146026611,5.00872478234831,32.7799990773201,-0.069438218477387,-0.0103120274697667,1,5.92700893009053E-8,,,,,,,,,,,,,,,,,,,,,2.34000444412231,2.34092903137207,10000.3623046875,10000.3623046875,53.5677381227076,5.64013249776661,2.38312864303589,54,1,0,0,1,0.304641723632812,34.2131004333496,6,1,3,2.34000444412231,0,2.34046673774719,,,,,,,,,,,,,,,,,,,,,,,,,,,,,,,,,
,3877764781.92898,2.34114873409271,10000.3623046875,-5.57193478177946E-5,2.20323286311104E-8,1,4,13.4005146026611,5.0086809088862,32.7799990773201,-0.0694347907700633,-0.0103182227634425,1,5.40048615361591E-8,,,,,,,,,,,,,,,,,,,,,2.34031295776367,2.34198451042175,10000.3623046875,10000.3623046875,53.6216704905345,5.64032320398091,2.38301682472229,54,1,0,0,1,0.302886962890625,34.2131004333496,6,1,3,2.34198451042175,0,2.34114873409271,,,,,,,,,,,,,,,,,,,,,,,,,,,,,,,,,
,3877764806.10549,2.38227820396423,10000.3623046875,-5.58251380403139E-5,2.22836978893848E-8,1,4,13.4005146026611,5.00870086845934,32.7799990773201,-0.0695688551613387,-0.0103255292505936,1,6.40124939274509E-8,,,,,,,,,,,,,,,,,,,,,2.37742829322815,2.38712811470032,10000.3623046875,10000.3623046875,53.6552805168614,5.64013758894722,2.40659308433533,54,1,0,0,1,0.30517578125,34.7018585205078,6,1,3,2.38778829574585,0,2.38227820396423,,,,,,,,,,,,,,,,,,,,,,,,,,,,,,,,,
,3877764830.28122,2.43671059608459,10000.3623046875,-5.59488872658203E-5,1.86678856993493E-8,1,4,13.4005146026611,5.00872999624374,32.7799990773201,-0.0697254410861655,-0.0103364435421887,1,7.38324269401021E-8,,,,,,,,,,,,,,,,,,,,,2.43321657180786,2.44020462036133,10000.3623046875,10000.3623046875,53.6482458601884,5.64023691598098,2.43009996414185,54,1,0,0,1,0.298004150390625,34.7018585205078,6,1,3,2.44036054611206,0,2.43671059608459,,,,,,,,,,,,,,,,,,,,,,,,,,,,,,,,,
,3877764854.51012,2.47746706008911,10000.3623046875,-5.60437678892485E-5,2.2292183339925E-8,1,4,13.4005146026611,5.00866348634801,32.7799990773201,-0.0698407735591019,-0.0103645753077875,1,6.52937385513595E-8,,,,,,,,,,,,,,,,,,,,,2.47466516494751,2.48026895523071,10000.3623046875,10000.3623046875,53.5575769519576,5.6399146658212,2.44662594795227,54,1,0,0,1,0.304946899414063,34.7018585205078,6,1,3,2.48075270652771,0,2.47746706008911,,,,,,,,,,,,,,,,,,,,,,,,,,,,,,,,,
,3877764878.64981,2.48109030723572,10000.3623046875,-5.60439562354699E-5,2.25511078348683E-8,1,4,13.4005146026611,5.00864081733093,32.7799990773201,-0.0698425517654516,-0.0103512734730237,1,7.59452870938957E-8,,,,,,,,,,,,,,,,,,,,,2.47673583030701,2.48544478416443,10000.3623046875,10000.3623046875,53.5829798788326,5.63995295014942,2.45308899879456,54,1,0,0,1,0.3045654296875,34.7018585205078,6,1,3,2.47673583030701,0,2.48109030723572,,,,,,,,,,,,,,,,,,,,,,,,,,,,,,,,,
,3877764902.81456,2.50355529785156,10000.3623046875,-5.61047833809109E-5,1.87278184008386E-8,1,4,13.4005146026611,5.00863514055814,32.7799990773201,-0.069916370286095,-0.0103750199446886,1,6.5972651980135E-8,,,,,,,,,,,,,,,,,,,,,2.50274395942688,2.50436663627625,10000.3623046875,10000.3623046875,53.5122424978422,5.6399614186571,2.46623277664185,54,1,0,0,1,0.304183959960937,34.7018585205078,6,1,3,2.50436663627625,0,2.50355529785156,,,,,,,,,,,,,,,,,,,,,,,,,,,,,,,,,
,3877764926.99088,2.49865865707397,10000.3623046875,-5.60867039914989E-5,1.94579886043757E-8,1,4,13.4005146026611,5.00863250790334,32.7799990773201,-0.0698951806989923,-0.0103623649259082,1,7.34188540677066E-8,,,,,,,,,,,,,,,,,,,,,2.49617457389832,2.50114274024963,10000.3623046875,10000.3623046875,53.6478550459288,5.63943442290389,2.46998143196106,54,1,0,0,1,0.2972412109375,34.7018585205078,6,1,3,2.49617457389832,0,2.49865865707397,,,,,,,,,,,,,,,,,,,,,,,,,,,,,,,,,
,3877764951.16807,2.47029936313629,10000.3623046875,-5.60302778060363E-5,1.81597363205386E-8,1,4,13.4005146026611,5.00859554167018,32.7799990773201,-0.0698197003938653,-0.0103815255114205,1,4.95136602778614E-8,,,,,,,,,,,,,,,,,,,,,2.46733045578003,2.47326827049255,10000.3623046875,10000.3623046875,53.5923594210634,5.639370664924,2.4553804397583,54,1,0,0,1,0.303268432617188,34.2131004333496,6,1,3,2.46733045578003,0,2.47029936313629,,,,,,,,,,,,,,,,,,,,,,,,,,,,,,,,,
,3877764975.34844,2.4273521900177,10000.3623046875,-5.59420643818512E-5,2.28436163792112E-8,1,4,13.4005146026611,5.0085971319135,32.7799990773201,-0.0697158685623293,-0.0103246720775739,1,8.19520386702159E-8,,,,,,,,,,,,,,,,,,,,,2.42331218719482,2.43139219284058,10000.3623046875,10000.3623046875,53.5700830082653,5.63955489029078,2.44077944755554,54,1,0,0,1,0.303497314453125,34.2131004333496,6,1,3,2.42331218719482,0,2.4273521900177,,,,,,,,,,,,,,,,,,,,,,,,,,,,,,,,,
,3877764999.51084,2.22341012954712,10000.3623046875,-5.54016415826007E-5,1.69816669440113E-8,1,4,13.4005146026611,5.00858026490633,32.7799990773201,-0.0690394682764232,-0.0102422107190318,1,6.72533462836664E-8,,,,,,,,,,,,,,,,,,,,,2.20217561721802,2.24464464187622,10000.3623046875,10000.3623046875,53.6658325018711,5.6406537650989,2.33710694313049,54,1,0,0,1,0.303268432617188,34.7018585205078,6,1,3,2.20217561721802,0,2.22341012954712,,,,,,,,,,,,,,,,,,,,,,,,,,,,,,,,,
,3877765023.70388,1.99779105186462,10000.3623046875,-5.48210240581974E-5,2.24084784703098E-8,1,4,13.4005146026611,5.00855915425574,32.7799990773201,-0.0683124662642376,-0.0101552369148401,1,5.015448794641E-8,,,,,,,,,,,,,,,,,,,,,1.99717712402344,1.99840497970581,10000.3623046875,10000.3623046875,53.6634876163134,5.64042855806581,2.21430659294128,54,1,0,0,1,0.304183959960937,34.2131004333496,6,1,3,1.99840497970581,0,1.99779105186462,,,,,,,,,,,,,,,,,,,,,,,,,,,,,,,,,
,3877765047.89134,2.00001090764999,10000.3623046875,-5.48473679054818E-5,1.68026869812977E-8,1,4,13.4005146026611,5.00860251221512,32.7799990773201,-0.0683478140608264,-0.010148917049081,1,5.92663298330054E-8,,,,,,,,,,,,,,,,,,,,,1.99856579303741,2.00145602226257,10000.3623046875,10000.3623046875,53.6427744605538,5.64012263612949,2.1999351978302,54,1,0,0,1,0.29754638671875,34.7018585205078,5,1,3,2.00145602226257,0,2.00001090764999,,,,,,,,,,,,,,,,,,,,,,,,,,,,,,,,,
,3877765072.06422,1.9995282292366,10000.3623046875,-5.4826908608499E-5,2.56834894539631E-8,1,4,13.4005146026611,5.00857537671034,32.7900014817715,-0.0683199818294956,-0.0101572182303702,1,4.94814536149595E-8,,,,,,,,,,,,,,,,,,,,,1.99942755699158,1.99962890148163,10000.3623046875,10000.3623046875,53.5466341526884,5.63964352863855,2.19181895256042,54,1,0,0,1,0.303573608398438,34.2131004333496,5,1,3,1.99942755699158,0,1.9995282292366,,,,,,,,,,,,,,,,,,,,,,,,,,,,,,,,,
,3877765096.23353,1.99856966733932,10000.3623046875,-5.48449984494994E-5,1.97611143247415E-8,1,4,13.4005146026611,5.0085825438324,32.7799990773201,-0.0683433377649899,-0.0101560613074836,1,5.31324429235909E-8,,,,,,,,,,,,,,,,,,,,,1.99743819236755,1.9997011423111,10000.3623046875,10000.3623046875,53.7283627834095,5.64036273537609,2.18488073348999,54,1,0,0,1,0.302734375,34.2131004333496,5,1,3,1.99743819236755,0,1.99856966733932,,,,,,,,,,,,,,,,,,,,,,,,,,,,,,,,,
,3877765112.45424,1.99969947338104,10000.3623046875,-5.48662508002921E-5,1.83715054018648E-8,1,4,13.4005146026611,5.00857114926998,32.7799990773201,-0.0683686680708497,-0.0101662163210266,1,4.8135218894893E-8,,,,,,,,,,,,,,,,,,,,,1.9993155002594,2.00008344650269,10000.3623046875,10000.3623046875,53.6634876163134,5.64048592084445,2.18342661857605,54,1,0,0,1,0.304031372070313,34.7018585205078,1,1,3,2.00008344650269,0,1.99969947338104,,,,,,,,,,,,,,,,,,,,,,,,,,,,,,,,,