File: SQUID/Reference/STO/A6/STO_MH_100K_FC_1T.csv
Comment,Time Stamp (sec),Temperature (K),Magnetic Field (Oe),Moment (emu),M. Std. Err. (emu),Transport Action,Averaging Time (sec),Frequency (Hz),Peak Amplitude (mm),Center Position (mm),Lockin Signal' (V),Lockin Signal (V),Range,M. Quad. Signal (emu),AC Moment (emu),AC M. Std Err. (emu),AC Phase (deg),AC Phase Std. Err. (deg),AC Susceptibility (emu/Oe),AC Suscept. Std Err. (emu/Oe),AC X' (emu/Oe),AC X' Std Err. (emu/Oe),AC X'' (emu/Oe),AC X'' Std Err. (emu/Oe),AC Drive (Oe),AC Frequency (Hz),AC Averaging Time (sec),AC Cycles,AC Range,AC Measure Type,AC Signal' (V),AC Signal'' (V),AC Trim Coil Ratio,AC Trim Coil Phase,Min. Temperature (K),Max. Temperature (K),Min. Field (Oe),Max. Field (Oe),Mass (grams),Motor Lag (deg),Pressure (Torr),Measure Count,Measurement Number,SQUID Status (code),Motor Status (code),Measure Status (code),Motor Current (amps),Motor Temp. (C),Temp. Status (code),Field Status (code),Chamber Status (code),Chamber Temp (K),Redirection State,Average Temp (K),Rotation Angle (deg),Rotator state,DC Moment Fixed Ctr (emu),DC Moment Err Fixed Ctr (emu),DC Moment Free Ctr (emu),DC Moment Err Free Ctr (emu),DC Fixed Fit,DC Free Fit,DC Calculated Center (mm),DC Calculated Center Err (mm),DC Scan Length (mm),DC Scan Time (s),DC Number of Points,DC Squid Drift,DC Min V (V),DC Max V (V),DC Scans per Measure,Map 01,Map 02,Map 03,Map 04,Map 05,Map 06,Map 07,Map 08,Map 09,Map 10,Map 11,Map 12,Map 13,Map 14,Map 15,Map 16
,3877801688.55621,99.9937705993652,69999.7734375,-4.63424368871559E-4,1.85208136349857E-7,1,4,13.4005146026611,4.99747396322042,32.8000001609325,-0.575661351054268,-0.0857450024868534,1,2.91676107875395E-7,,,,,,,,,,,,,,,,,,,,,99.9936447143555,99.993896484375,69999.7734375,69999.7734375,53.6365214323999,5.63882784260394,5.271155834198,54,1,0,0,1,0.296630859375,33.2355842590332,1,1,3,99.993896484375,0,99.9937705993652,,,,,,,,,,,,,,,,,,,,,,,,,,,,,,,,,
,3877801860.22459,100.116340637207,49999.6796875,-3.33063226817317E-4,7.14925491257896E-8,1,4,13.4005146026611,4.99749321166971,32.8000001609325,-0.413703625383665,-0.0618029964624131,1,6.6556216271977E-8,,,,,,,,,,,,,,,,,,,,,100.104232788086,100.128448486328,49999.6796875,49999.6796875,53.6955343856018,5.63855919061773,5.2759575843811,54,1,0,0,1,0.297317504882812,34.7018585205078,1,1,3,100.128448486328,0,100.116340637207,,,,,,,,,,,,,,,,,,,,,,,,,,,,,,,,,
,3877802017.28395,100.09415435791,29999.548828125,-2.02954343919325E-4,3.76096198227377E-8,1,4,13.4005146026611,4.99751910445706,32.8000001609325,-0.252099578844741,-0.0376293952275732,1,6.54777598324555E-8,,,,,,,,,,,,,,,,,,,,,100.073089599609,100.115219116211,29999.548828125,29999.548828125,53.8268479768326,5.63806053594339,5.28748846054077,54,1,0,0,1,0.303955078125,34.7018585205078,1,1,3,100.115219116211,0,100.09415435791,,,,,,,,,,,,,,,,,,,,,,,,,,,,,,,,,
,3877802176.6895,100.068176269531,9999.7578125,-7.28080270458624E-5,1.69406054663205E-8,1,4,13.4005146026611,4.99748925438136,32.8000001609325,-0.0904372224688191,-0.0135021312227284,1,2.10416922103385E-8,,,,,,,,,,,,,,,,,,,,,100.064949035645,100.071403503418,9999.7578125,9999.7578125,53.8631937029769,5.63854478618475,5.29448318481445,54,1,0,0,1,0.296630859375,34.7018585205078,1,1,3,100.064949035645,0,100.068176269531,,,,,,,,,,,,,,,,,,,,,,,,,,,,,,,,,
,3877802259.99212,100.094806671143,8499.501953125,-6.30428926571823E-5,1.34758093579146E-8,1,4,13.4005146026611,4.99750065885099,32.8000001609325,-0.0783082714402315,-0.0116886307530683,1,2.03203677455656E-8,,,,,,,,,,,,,,,,,,,,,100.075645446777,100.113967895508,8499.501953125,8499.501953125,53.9655870389961,5.63819986599963,5.29718685150146,54,1,0,0,1,0.297012329101562,34.7018585205078,1,1,3,100.113967895508,0,100.094806671143,,,,,,,,,,,,,,,,,,,,,,,,,,,,,,,,,
,3877802329.60596,100.203392028809,6499.54248046875,-5.00063491071422E-5,1.04552484840742E-8,1,4,13.4005146026611,4.9975149024268,32.8000001609325,-0.0621157681812633,-0.00926827258902733,1,1.87921125075497E-8,,,,,,,,,,,,,,,,,,,,,100.201400756836,100.205383300781,6499.54248046875,6499.54248046875,53.8792170876211,5.63851850121402,5.2939920425415,54,1,0,0,1,0.298538208007812,35.190616607666,1,1,3,100.201400756836,0,100.203392028809,,,,,,,,,,,,,,,,,,,,,,,,,,,,,,,,,
,3877802399.65877,100.096645355225,4499.79736328125,-3.69656310126452E-5,1.10783553019064E-8,1,4,13.4005146026611,4.99753357049866,32.8000001609325,-0.0459147250713879,-0.00686906977440511,1,-4.01346188382019E-10,,,,,,,,,,,,,,,,,,,,,100.096488952637,100.096801757813,4499.79736328125,4499.79736328125,53.9905991516115,5.63840501227128,5.30006837844849,54,1,0,0,1,0.295486450195313,34.7018585205078,1,1,3,100.096260070801,0,100.096645355225,,,,,,,,,,,,,,,,,,,,,,,,,,,,,,,,,
,3877802484.2692,100.244750976562,2999.57983398438,-2.71846529671172E-5,7.75354353115807E-9,1,4,13.4005146026611,4.99748636711553,32.8000001609325,-0.0337737427317071,-0.00499570959646824,1,4.45983981614415E-8,,,,,,,,,,,,,,,,,,,,,100.244239807129,100.245262145996,2999.57983398438,2999.57983398438,53.922988284698,5.63826514023599,5.30718231201172,54,1,0,0,1,0.296859741210937,34.7018585205078,1,1,3,100.244239807129,0,100.244750976562,,,,,,,,,,,,,,,,,,,,,,,,,,,,,,,,,
,3877802544.38415,100.170810699463,2799.7412109375,-2.59621732517894E-5,1.48323378736086E-8,1,4,13.4005146026611,4.99749704727059,32.8000001609325,-0.0322824232860666,-0.00458809595046034,1,1.89904777959398E-7,,,,,,,,,,,,,,,,,,,,,100.168724060059,100.172897338867,2799.7412109375,2799.7412109375,53.8585039318615,5.63816996299286,5.30775928497314,52,1,68,0,0,0.297622680664063,35.6793746948242,1,1,3,100.172897338867,0,100.170810699463,,,,,,,,,,,,,,,,,,,,,,,,,,,,,,,,,
,3877802604.11958,100.229724884033,2599.65087890625,-2.46656500782774E-5,1.84539852050624E-8,1,4,13.4005146026611,4.99747905591401,32.8000001609325,-0.0306769260134956,-0.00431344604130951,1,2.17056057913297E-7,,,,,,,,,,,,,,,,,,,,,100.218620300293,100.240829467773,2599.65087890625,2599.65087890625,53.9065740857942,5.63825075499707,5.30864095687866,53,1,68,0,0,0.296173095703125,35.190616607666,1,1,3,100.240829467773,0,100.229724884033,,,,,,,,,,,,,,,,,,,,,,,,,,,,,,,,,
,3877802662.35349,100.249698638916,2399.76196289062,-2.33547971592852E-5,1.63267316066967E-8,1,4,13.4005146026611,4.99749041512355,32.8000001609325,-0.0290479408816469,-0.0040759065253934,1,2.1221502604786E-7,,,,,,,,,,,,,,,,,,,,,100.248008728027,100.251388549805,2399.76196289062,2399.76196289062,53.8065256353326,5.63756666455255,5.31438159942627,54,1,0,0,1,0.297470092773438,35.190616607666,1,1,3,100.248008728027,0,100.249698638916,,,,,,,,,,,,,,,,,,,,,,,,,,,,,,,,,
,3877802720.03987,100.108707427979,2199.55834960938,-2.20483582125428E-5,1.87393447934604E-8,1,4,13.4005146026611,4.99746828226311,32.8000001609325,-0.0274253271034071,-0.00383141854926173,1,2.13598335115225E-7,,,,,,,,,,,,,,,,,,,,,100.104713439941,100.112701416016,2199.55834960938,2199.55834960938,53.9683227388134,5.6382794299401,5.31214141845703,54,1,0,0,1,0.296707153320313,34.7018585205078,1,1,3,100.104713439941,0,100.108707427979,,,,,,,,,,,,,,,,,,,,,,,,,,,,,,,,,
,3877802778.12031,100.110908508301,1999.68200683594,-2.07529013167055E-5,2.2098194686144E-8,1,4,13.4005146026611,4.99747391323534,32.8000001609325,-0.0258154122246345,-0.00359677265082372,1,2.08725485621966E-7,,,,,,,,,,,,,,,,,,,,,100.110374450684,100.111442565918,1999.68200683594,1999.68200683594,53.8682742883518,5.63798739489014,5.31195640563965,54,1,0,0,1,0.296630859375,34.7018585205078,1,1,3,100.110374450684,0,100.110908508301,,,,,,,,,,,,,,,,,,,,,,,,,,,,,,,,,
,3877802836.89623,100.31742477417,1799.73022460938,-1.94421552379834E-5,1.78891084377586E-8,1,4,13.4005146026611,4.99751656044039,32.8000001609325,-0.0241877059275154,-0.00335294835527833,1,2.08982430912778E-7,,,,,,,,,,,,,,,,,,,,,100.317207336426,100.317642211914,1799.73022460938,1799.73022460938,53.9104822283903,5.63848847056284,5.31642293930054,53,1,68,0,0,0.297927856445313,35.190616607666,1,1,3,100.317207336426,0,100.31742477417,,,,,,,,,,,,,,,,,,,,,,,,,,,,,,,,,
,3877802897.37112,100.15633392334,1599.74060058594,-1.8132824364697E-5,1.82881208684652E-8,1,4,13.4005146026611,4.99749961400437,32.8000001609325,-0.0225656011404143,-0.00308085719427547,1,2.32162240063079E-7,,,,,,,,,,,,,,,,,,,,,100.153961181641,100.158706665039,1599.74060058594,1599.74060058594,53.8581131176019,5.63796723319357,5.3126015663147,54,1,0,0,1,0.297317504882812,34.7018585205078,1,1,3,100.153961181641,0,100.15633392334,,,,,,,,,,,,,,,,,,,,,,,,,,,,,,,,,
,3877802953.85583,100.173053741455,1399.59997558594,-1.67901458593182E-5,6.55528133169964E-8,1,4,13.4005146026611,4.99751255244555,32.8000001609325,-0.0208997419860527,-0.00281947124988034,1,2.41755727957637E-7,,,,,,,,,,,,,,,,,,,,,100.166931152344,100.179176330566,1399.59997558594,1399.59997558594,54.0179561497846,5.63791173183732,5.31399583816528,54,1,0,0,1,0.29754638671875,35.190616607666,1,1,3,100.179176330566,0,100.173053741455,,,,,,,,,,,,,,,,,,,,,,,,,,,,,,,,,
,3877803009.61744,100.175182342529,1199.64819335938,-1.55343485705115E-5,2.57774041233964E-8,1,4,13.4005146026611,4.99749654768362,32.8000001609325,-0.0193454597901525,-0.00254859353529934,1,2.71969711788736E-7,,,,,,,,,,,,,,,,,,,,,100.174102783203,100.176261901855,1199.64819335938,1199.64819335938,53.887424187073,5.63783371047708,5.323326587677,53,1,68,0,0,0.296630859375,35.190616607666,1,1,3,100.176239013672,0,100.175182342529,,,,,,,,,,,,,,,,,,,,,,,,,,,,,,,,,
,3877803083.8834,100.100238800049,999.834716796875,-1.41957187972574E-5,2.31487814316252E-8,1,4,13.4005146026611,4.99751602848299,32.8000001609325,-0.0176739757484263,-0.00235932849316407,1,2.24106631619531E-7,,,,,,,,,,,,,,,,,,,,,100.096542358398,100.103935241699,999.834716796875,999.834716796875,53.9249423559961,5.63814847910332,5.32034301757812,54,1,0,0,1,0.297317504882812,34.7018585205078,1,1,3,100.096542358398,0,100.100238800049,,,,,,,,,,,,,,,,,,,,,,,,,,,,,,,,,
,3877803157.68352,100.081722259521,799.782165527344,-1.29024838377916E-5,2.65100982178327E-8,1,4,13.4005146026611,4.99748138818026,32.8000001609325,-0.016073860542561,-0.00207654789154796,1,2.58295898279123E-7,,,,,,,,,,,,,,,,,,,,,100.077705383301,100.085739135742,799.782165527344,799.782165527344,53.8741365022461,5.63807644386473,5.32548999786377,54,1,0,0,1,0.298080444335937,35.190616607666,1,1,3,100.085739135742,0,100.081722259521,,,,,,,,,,,,,,,,,,,,,,,,,,,,,,,,,
,3877803232.91538,100.05838394165,599.905822753906,-1.16235771828807E-5,2.19019666784972E-8,1,4,13.4005146026611,4.99742432264937,32.8000001609325,-0.0144792327962177,-0.00187830695817468,1,2.26559655169825E-7,,,,,,,,,,,,,,,,,,,,,100.055694580078,100.061073303223,599.905822753906,599.905822753906,54.044922333698,5.63784850245965,5.32870483398438,54,1,0,0,1,0.2972412109375,34.7018585205078,1,1,3,100.061073303223,0,100.05838394165,,,,,,,,,,,,,,,,,,,,,,,,,,,,,,,,,
,3877803288.83558,100.044952392578,399.828155517578,-9.94588293424026E-6,5.2925160397279E-7,1,4,13.4005146026611,4.99741985775736,32.8000001609325,-0.0123239653861434,-0.00204428433681412,1,-1.58046256105151E-7,,,,,,,,,,,,,,,,,,,,,100.043914794922,100.045989990234,399.828155517578,399.828155517578,53.9319770126692,5.6380533836375,5.32033252716064,54,1,0,0,1,0.296630859375,34.7018585205078,1,1,3,100.045989990234,0,100.044952392578,,,,,,,,,,,,,,,,,,,,,,,,,,,,,,,,,
,3877803363.19629,100.035152435303,200.153259277344,-8.95018180873292E-6,2.84869999427042E-8,1,4,13.4005146026611,4.9974897389991,32.8000001609325,-0.0111590385715718,-0.00138087749459087,1,2.27145210653528E-7,,,,,,,,,,,,,,,,,,,,,100.03360748291,100.036697387695,200.153259277344,200.153259277344,53.8905507011499,5.63815591767345,5.3272590637207,54,1,0,0,1,0.296859741210937,35.190616607666,1,1,3,100.03360748291,0,100.035152435303,,,,,,,,,,,,,,,,,,,,,,,,,,,,,,,,,
,3877803436.66766,100.007175445557,0.188823834061623,8.38477073757767E-6,2.76711894425395E-8,1,4,13.4005146026611,4.9974997556866,32.8000001609325,0.0103694451218325,0.00185965469715066,1,2.42896959335935E-7,,,,,,,,,,,,,,,,,,,,,100.006637573242,100.007713317871,0.188823834061623,0.188823834061623,53.9182985135826,5.63770544688337,5.32429170608521,52,1,68,0,0,0.296859741210937,34.7018585205078,1,1,3,100.006637573242,0,100.007175445557,,,,,,,,,,,,,,,,,,,,,,,,,,,,,,,,,
,3877803527.06789,100.090915679932,-199.788192749023,9.73172117520825E-6,2.96290836895463E-8,1,4,13.4005146026611,4.99749880777813,32.8000001609325,0.0120472617502201,0.00207786660635858,1,2.17084207257343E-7,,,,,,,,,,,,,,,,,,,,,100.086791992187,100.095039367676,-199.788192749023,-199.788192749023,53.978874723823,5.63815183330924,5.32286739349365,54,1,0,0,1,0.298004150390625,34.7018585205078,1,1,3,100.095039367676,0,100.090915679932,,,,,,,,,,,,,,,,,,,,,,,,,,,,,,,,,
,3877803602.0406,100.064334869385,-399.853332519531,1.10564256725309E-5,1.45212438035839E-8,1,4,13.4005146026611,4.99749886486829,32.8000001609325,0.0136976451365895,0.00229064156614238,1,1.90221597454352E-7,,,,,,,,,,,,,,,,,,,,,100.054946899414,100.073722839355,-399.853332519531,-399.853332519531,53.5607034660345,5.63860360614047,5.32412385940552,52,1,68,0,0,0.298080444335937,34.7018585205078,1,1,3,100.073722839355,0,100.064334869385,,,,,,,,,,,,,,,,,,,,,,,,,,,,,,,,,
,3877803676.5333,100.077480316162,-599.679321289063,1.23602695327143E-5,1.37730846893386E-8,1,4,13.4005146026611,4.99746799279029,32.8000001609325,0.0153188988609909,0.00252015015684814,1,1.79969426646521E-7,,,,,,,,,,,,,,,,,,,,,100.076614379883,100.078346252441,-599.679321289063,-599.679321289063,53.4989548130153,5.63813452326936,5.32236051559448,52,1,68,0,0,0.296707153320313,35.190616607666,1,1,3,100.076614379883,0,100.077480316162,,,,,,,,,,,,,,,,,,,,,,,,,,,,,,,,,
,3877803750.69031,100.149345397949,-799.744445800781,1.3649678578895E-5,1.74387656038123E-8,1,4,13.4005146026611,4.99746865308205,32.8000001609325,0.0169157636590547,0.00279099248543325,1,2.05138315951981E-7,,,,,,,,,,,,,,,,,,,,,100.14672088623,100.151969909668,-799.744445800781,-799.744445800781,53.5626575373326,5.63782167679643,5.3323335647583,54,1,0,0,1,0.297927856445313,34.7018585205078,1,1,3,100.14672088623,0,100.149345397949,,,,,,,,,,,,,,,,,,,,,,,,,,,,,,,,,
,3877803808.26644,100.189247131348,-999.545166015625,1.49622531068215E-5,3.87245838470988E-8,1,4,13.4005146026611,4.99741967981659,32.8000001609325,0.0185603320548983,0.00293783171484433,1,1.2703891919375E-7,,,,,,,,,,,,,,,,,,,,,100.18529510498,100.193199157715,-999.545166015625,-999.545166015625,53.4755059574383,5.63786577438398,5.32308912277222,52,1,68,0,0,0.297012329101562,34.7018585205078,1,1,3,100.18529510498,0,100.189247131348,,,,,,,,,,,,,,,,,,,,,,,,,,,,,,,,,
,3877803867.08432,100.163722991943,-1199.6103515625,1.63196887315368E-5,2.39232762537888E-8,1,4,13.4005146026611,4.99737237135482,32.8000001609325,0.0202474860955503,0.00318055961159586,1,1.194333364899E-7,,,,,,,,,,,,,,,,,,,,,100.156387329102,100.171058654785,-1199.6103515625,-1199.6103515625,53.4985639987557,5.6384370910615,5.33465814590454,52,1,68,0,0,0.298309326171875,34.7018585205078,1,1,3,100.156387329102,0,100.163722991943,,,,,,,,,,,,,,,,,,,,,,,,,,,,,,,,,
,3877803942.67089,100.125457763672,-1399.5244140625,1.76180039594412E-5,2.07140032540801E-8,1,4,13.4005146026611,4.99745637528154,32.8000001609325,0.0218648228964675,0.00339335684045727,1,9.64781281104339E-8,,,,,,,,,,,,,,,,,,,,,100.122009277344,100.12890625,-1399.5244140625,-1399.5244140625,53.6040838488518,5.6382321353297,5.33347415924072,52,1,68,0,0,0.296859741210937,35.190616607666,1,1,3,100.122009277344,0,100.125457763672,,,,,,,,,,,,,,,,,,,,,,,,,,,,,,,,,
,3877804002.42651,100.18888092041,-1599.52661132813,1.8916164495205E-5,9.81709535529836E-9,1,4,13.4005146026611,4.99755790046043,32.8000001609325,0.0234741271190523,0.00365984374034052,1,1.1674857131701E-7,,,,,,,,,,,,,,,,,,,,,100.183197021484,100.194564819336,-1599.52661132813,-1599.52661132813,53.4465857022268,5.63761354810503,5.33101320266724,52,1,68,0,0,0.296707153320313,34.7018585205078,1,1,3,100.194564819336,0,100.18888092041,,,,,,,,,,,,,,,,,,,,,,,,,,,,,,,,,
,3877804063.90306,100.135498046875,-1799.66723632813,2.0229998073861E-5,9.24024627590886E-9,1,4,13.4005146026611,4.99757899694093,32.8000001609325,0.0251088109963765,0.00388648288103851,1,1.02652748267067E-7,,,,,,,,,,,,,,,,,,,,,100.129600524902,100.141395568848,-1799.66723632813,-1799.66723632813,53.3821013493903,5.63822724719733,5.33390665054321,54,1,0,0,1,0.297012329101562,35.190616607666,1,1,3,100.141510009766,0,100.135498046875,,,,,,,,,,,,,,,,,,,,,,,,,,,,,,,,,
,3877804122.89167,100.097759246826,-1999.65686035156,2.15144967756174E-5,1.34539374274422E-8,1,4,13.4005146026611,4.99757780840406,32.8000001609325,0.026707074430588,0.00410654973776047,1,8.76725319698034E-8,,,,,,,,,,,,,,,,,,,,,100.096977233887,100.098541259766,-1999.65686035156,-1999.65686035156,53.536863796198,5.63803357761665,5.3331995010376,54,1,0,0,1,0.296096801757812,35.190616607666,1,1,3,100.096977233887,0,100.097759246826,,,,,,,,,,,,,,,,,,,,,,,,,,,,,,,,,
,3877804194.38922,100.243118286133,-2199.60864257813,2.28075085318727E-5,5.21533232738138E-8,1,4,13.4005146026611,4.99754508132281,32.8000001609325,0.0283201850652777,0.00429791612706634,1,4.83432715512842E-8,,,,,,,,,,,,,,,,,,,,,100.238464355469,100.247772216797,-2199.60864257813,-2199.60864257813,53.4762875859576,5.63784985225458,5.33006572723389,54,1,0,0,1,0.2972412109375,34.2131004333496,1,1,3,100.247772216797,0,100.243118286133,,,,,,,,,,,,,,,,,,,,,,,,,,,,,,,,,
,3877804252.85346,100.11109161377,-2399.560546875,2.41461751839199E-5,9.17297032716534E-9,1,4,13.4005146026611,4.99758605175169,32.8000001609325,0.029980037594148,0.00456841302020078,1,6.58189119841521E-8,,,,,,,,,,,,,,,,,,,,,100.107139587402,100.115043640137,-2399.560546875,-2399.560546875,53.5044262126499,5.63787798690849,5.33103799819946,54,1,0,0,1,0.297470092773438,34.7018585205078,1,1,3,100.107139587402,0,100.11109161377,,,,,,,,,,,,,,,,,,,,,,,,,,,,,,,,,
,3877804311.6119,100.18185043335,-2599.57543945313,2.54478767846483E-5,8.20951327615343E-9,1,4,13.4005146026611,4.99756455083161,32.8000001609325,0.0315985933007827,0.00479764810374597,1,5.56682184342813E-8,,,,,,,,,,,,,,,,,,,,,100.171409606934,100.192291259766,-2599.57543945313,-2599.57543945313,53.503253769871,5.63805201606067,5.33514785766602,54,1,0,0,1,0.2972412109375,33.7243423461914,1,1,3,100.192840576172,0,100.18185043335,,,,,,,,,,,,,,,,,,,,,,,,,,,,,,,,,
,3877804371.10787,100.175090789795,-2799.69091796875,2.67484215727463E-5,8.52970962349406E-9,1,4,13.4005146026611,4.9975807970105,32.8000001609325,0.0332143268441906,0.00503819661966652,1,5.47582356670175E-8,,,,,,,,,,,,,,,,,,,,,100.170463562012,100.179718017578,-2799.69091796875,-2799.69091796875,53.496219113198,5.63782419370929,5.33718538284302,54,1,0,0,1,0.296707153320313,34.7018585205078,1,1,3,100.170463562012,0,100.175090789795,,,,,,,,,,,,,,,,,,,,,,,,,,,,,,,,,
,3877804432.43875,100.098209381104,-2999.66796875,2.80592514484831E-5,1.30043629057727E-8,1,4,13.4005146026611,4.99760361643556,32.8000001609325,0.0348406329938323,0.00529591969308434,1,6.61269037022077E-8,,,,,,,,,,,,,,,,,,,,,100.094352722168,100.102066040039,-2999.66796875,-2999.66796875,53.4313439461018,5.6375806938778,5.3381462097168,54,1,0,0,1,0.296096801757812,34.7018585205078,1,1,3,100.092765808105,0,100.098209381104,,,,,,,,,,,,,,,,,,,,,,,,,,,,,,,,,
,3877804512.27509,100.129413604736,-4499.646484375,3.78753885057671E-5,1.18393710910644E-8,1,4,13.4005146026611,4.9975771057167,32.8000001609325,0.0470584528651418,0.00695029651281068,1,-7.03660322260286E-8,,,,,,,,,,,,,,,,,,,,,100.116577148438,100.142250061035,-4499.646484375,-4499.646484375,53.5579677662172,5.63795197230274,5.33717155456543,54,1,0,0,1,0.297927856445313,34.7018585205078,1,1,3,100.143180847168,0,100.129413604736,,,,,,,,,,,,,,,,,,,,,,,,,,,,,,,,,
,3877804578.04118,100.075401306152,-6499.66845703125,5.08878366340122E-5,1.14116605411055E-8,1,4,13.4005146026611,4.99757393154559,32.8000001609325,0.0632246544686844,0.00934560833725242,1,-8.85189359899854E-8,,,,,,,,,,,,,,,,,,,,,100.071716308594,100.079086303711,-6499.66845703125,-6499.66845703125,53.552105552323,5.63769462941553,5.33652305603027,54,1,0,0,1,0.29693603515625,34.7018585205078,1,1,3,100.071716308594,0,100.075401306152,,,,,,,,,,,,,,,,,,,,,,,,,,,,,,,,,
,3877804644.37638,100.167934417725,-8499.6650390625,6.39038894068587E-5,1.31891916040069E-8,1,4,13.4005146026611,4.99755039262628,32.8000001609325,0.079392217647297,0.0117591268559886,1,-9.24957234126325E-8,,,,,,,,,,,,,,,,,,,,,100.161277770996,100.174591064453,-8499.6650390625,-8499.6650390625,53.5564045091787,5.63768762242026,5.33807229995728,52,1,68,0,0,0.29693603515625,35.190616607666,1,1,3,100.174591064453,0,100.167934417725,,,,,,,,,,,,,,,,,,,,,,,,,,,,,,,,,
,3877804726.75424,100.375499725342,-9999.48046875,7.36692326967991E-5,1.21369457381788E-8,1,4,13.4005146026611,4.99759494125477,32.8000001609325,0.091524394593571,0.0135637706030478,1,-1.00570095715772E-7,,,,,,,,,,,,,,,,,,,,,100.374771118164,100.37622833252,-9999.48046875,-9999.48046875,53.4766784002172,5.63735223762905,5.34182453155518,54,1,0,0,1,0.297012329101562,34.7018585205078,1,1,3,100.374771118164,0,100.375499725342,,,,,,,,,,,,,,,,,,,,,,,,,,,,,,,,,
,3877804883.51111,100.120758056641,-29999.67578125,2.03751615187615E-4,3.20970070041976E-8,1,4,13.4005146026611,4.99756943960252,32.8000001609325,0.253112082302715,0.0376533807231951,1,-1.65861497349872E-7,,,,,,,,,,,,,,,,,,,,,100.111534118652,100.129981994629,-29999.67578125,-29999.67578125,53.4196195183133,5.63806330636763,5.34269762039185,54,1,0,0,1,0.296096801757812,34.2131004333496,1,1,3,100.129981994629,0,100.120758056641,,,,,,,,,,,,,,,,,,,,,,,,,,,,,,,,,
,3877805042.39365,100.019760131836,-49999.640625,3.3404626761374E-4,6.37911736598792E-8,1,4,13.4005146026611,4.99753140628624,32.8000001609325,0.414957560423118,0.0617959363233633,1,-2.19829546285225E-7,,,,,,,,,,,,,,,,,,,,,100.01887512207,100.020645141602,-49999.640625,-49999.640625,53.3563076082556,5.63754156084116,5.33969116210937,54,1,0,0,1,0.297012329101562,33.2355842590332,1,1,3,100.01887512207,0,100.019760131836,,,,,,,,,,,,,,,,,,,,,,,,,,,,,,,,,
,3877805202.05718,100.078525543213,-69999.625,4.64389639791262E-4,1.46400777281156E-7,1,4,13.4005146026611,4.99753250863567,32.8000001609325,0.576863386620979,0.0859683035512529,1,-2.57429027760311E-7,,,,,,,,,,,,,,,,,,,,,100.060073852539,100.096977233887,-69999.625,-69999.625,53.3289506100826,5.63733568344993,5.33903932571411,54,1,0,0,1,0.29693603515625,34.7018585205078,1,1,3,100.096977233887,0,100.078525543213,,,,,,,,,,,,,,,,,,,,,,,,,,,,,,,,,
,3877805361.96426,100.06294631958,-49999.9296875,3.33807267713457E-4,6.88984391327371E-8,1,4,13.4005146026611,4.99750835998488,32.8000001609325,0.414645015175928,0.0618380832477578,1,-1.4982303049891E-7,,,,,,,,,,,,,,,,,,,,,100.055267333984,100.070625305176,-49999.9296875,-49999.9296875,53.3824921636499,5.63742481333082,5.33995771408081,54,1,0,0,1,0.297012329101562,35.190616607666,1,1,3,100.070625305176,0,100.06294631958,,,,,,,,,,,,,,,,,,,,,,,,,,,,,,,,,
,3877805529.3067,100.073936462402,-29999.662109375,2.03723821718246E-4,3.94303771450079E-8,1,4,13.4005146026611,4.99753665465801,32.8000001609325,0.253104190319089,0.0374543139682586,10,-3.2169222467416E-7,,,,,,,,,,,,,,,,,,,,,100.064888000488,100.082984924316,-29999.662109375,-29999.662109375,53.4833222426306,5.63770591704848,5.33752584457397,54,1,0,0,1,0.296478271484375,34.7018585205078,1,1,3,100.082984924316,0,100.073936462402,,,,,,,,,,,,,,,,,,,,,,,,,,,,,,,,,
,3877805694.16645,100.014598846436,-10000.3115234375,7.33774470795304E-5,1.65005451210035E-8,1,4,13.4005146026611,4.9974309102219,32.8000001609325,0.0911450619054609,0.0135939096769887,1,-3.21535253123397E-8,,,,,,,,,,,,,,,,,,,,,100.01309967041,100.016098022461,-10000.3115234375,-10000.3115234375,53.496219113198,5.63789014507758,5.34406280517578,54,1,0,0,1,0.2960205078125,34.7018585205078,1,1,3,100.016098022461,0,100.014598846436,,,,,,,,,,,,,,,,,,,,,,,,,,,,,,,,,
,3877805774.41053,100.148727416992,-8500.1435546875,6.35955022554262E-5,1.16816292158418E-8,1,4,13.4005146026611,4.99737437799504,32.8000001609325,0.0789914019219109,0.0117939795290939,1,-1.78351996584038E-8,,,,,,,,,,,,,,,,,,,,,100.144874572754,100.15258026123,-8500.1435546875,-8500.1435546875,53.498173184496,5.63839190091005,5.33604001998901,52,1,68,0,0,0.297012329101562,35.190616607666,1,1,3,100.15258026123,0,100.148727416992,,,,,,,,,,,,,,,,,,,,,,,,,,,,,,,,,
,3877805840.61898,100.220996856689,-6500.02099609375,5.05628940555762E-5,1.33863749613918E-8,1,4,13.4005146026611,4.99737483687233,32.8000001609325,0.0628044125229635,0.0093724442807258,1,-1.78834875211259E-8,,,,,,,,,,,,,,,,,,,,,100.212921142578,100.229072570801,-6500.02099609375,-6500.02099609375,53.6107276912653,5.63872340109334,5.34198331832886,54,1,0,0,1,0.2972412109375,35.190616607666,1,1,3,100.229072570801,0,100.220996856689,,,,,,,,,,,,,,,,,,,,,,,,,,,,,,,,,
,3877805906.53859,100.107353210449,-4500.07421875,3.75089301923714E-5,9.10519190348067E-9,1,4,13.4005146026611,4.99736069502362,32.8000001609325,0.0465884844956802,0.00696174764729309,1,-5.98720251966096E-9,,,,,,,,,,,,,,,,,,,,,100.103569030762,100.111137390137,-4500.07421875,-4500.07421875,53.503253769871,5.63780446497225,5.34407711029053,53,1,68,0,0,0.297927856445313,34.7018585205078,1,1,3,100.111137390137,0,100.107353210449,,,,,,,,,,,,,,,,,,,,,,,,,,,,,,,,,
,3877805987.21298,100.194538116455,-3000.15893554687,2.773557149809E-5,8.16498721295946E-9,1,4,13.4005146026611,4.99732661517259,32.8000001609325,0.0344566810372417,0.00509653071422578,1,-4.56574342172E-8,,,,,,,,,,,,,,,,,,,,,100.193756103516,100.195320129395,-3000.15893554687,-3000.15893554687,53.5274842539672,5.63824270028796,5.343101978302,54,1,0,0,1,0.2972412109375,34.7018585205078,1,1,3,100.193756103516,0,100.194538116455,,,,,,,,,,,,,,,,,,,,,,,,,,,,,,,,,
,3877806043.66746,100.153018951416,-2800.18188476562,2.65035319896554E-5,1.94200762971543E-8,1,4,13.4005146026611,4.99737214727504,32.8000001609325,0.0329603202465644,0.00464414460357311,1,-2.25633098882196E-7,,,,,,,,,,,,,,,,,,,,,100.148933410645,100.157104492187,-2800.18188476562,-2800.18188476562,53.4755059574383,5.63802154768034,5.33969783782959,54,1,0,0,1,0.2978515625,34.7018585205078,1,1,3,100.157104492187,0,100.153018951416,,,,,,,,,,,,,,,,,,,,,,,,,,,,,,,,,
,3877806102.74638,100.105247497559,-2600.1669921875,2.52004162137317E-5,2.0430056463301E-8,1,4,13.4005146026611,4.99738109151014,32.8000001609325,0.0313403036418415,0.00441256800955342,1,-2.17152766796476E-7,,,,,,,,,,,,,,,,,,,,,100.100112915039,100.110382080078,-2600.1669921875,-2600.1669921875,53.480977357073,5.63844816474333,5.34867191314697,52,1,68,0,0,0.29693603515625,34.7018585205078,1,1,3,100.100112915039,0,100.105247497559,,,,,,,,,,,,,,,,,,,,,,,,,,,,,,,,,
,3877806160.4099,100.143325805664,-2400.27807617187,2.3892112920669E-5,1.90995386798574E-8,1,4,13.4005146026611,4.997417261967,32.8000001609325,0.0297137422801361,0.00418219849310647,1,-2.06949316199166E-7,,,,,,,,,,,,,,,,,,,,,100.142784118652,100.143867492676,-2400.27807617187,-2400.27807617187,53.4755059574383,5.63819709394398,5.34700393676758,54,1,0,0,1,0.297622680664063,34.7018585205078,1,1,3,100.142784118652,0,100.143325805664,,,,,,,,,,,,,,,,,,,,,,,,,,,,,,,,,
,3877806217.22418,100.168796539307,-2200.3134765625,2.2566248817912E-5,1.8933539560682E-8,1,4,13.4005146026611,4.99739565650103,32.8000001609325,0.0280692485601388,0.00391930791406687,1,-2.20247070639466E-7,,,,,,,,,,,,,,,,,,,,,100.165916442871,100.171676635742,-2200.3134765625,-2200.3134765625,53.5372546104576,5.63813639837603,5.34209489822388,54,1,0,0,1,0.297317504882812,34.7018585205078,1,1,3,100.165916442871,0,100.168796539307,,,,,,,,,,,,,,,,,,,,,,,,,,,,,,,,,
,3877806273.11333,100.166595458984,-2000.24853515625,2.12674837338624E-5,1.74692369869858E-8,1,4,13.4005146026611,4.99738812198686,32.8000001609325,0.0264510731118122,0.00371136489237012,1,-1.93373205501733E-7,,,,,,,,,,,,,,,,,,,,,100.158996582031,100.174194335938,-2000.24853515625,-2000.24853515625,53.4915293420826,5.63831866110358,5.34929656982422,52,1,68,0,0,0.296401977539063,34.7018585205078,1,1,3,100.174194335938,0,100.166595458984,,,,,,,,,,,,,,,,,,,,,,,,,,,,,,,,,
,3877806330.0821,100.28316116333,-1799.96936035156,1.99677698147858E-5,2.22389462556842E-8,1,4,13.4005146026611,4.99731431877537,32.8000001609325,0.0248429149176377,0.00342530424352055,1,-2.29201465063654E-7,,,,,,,,,,,,,,,,,,,,,100.27214050293,100.29418182373,-1799.96936035156,-1799.96936035156,53.3942165914383,5.63815017893905,5.34871101379395,53,1,68,0,0,0.297393798828125,35.190616607666,1,1,3,100.29418182373,0,100.28316116333,,,,,,,,,,,,,,,,,,,,,,,,,,,,,,,,,
,3877806388.49062,100.19539642334,-1600.11828613281,1.86722452948453E-5,1.90520996735557E-8,1,4,13.4005146026611,4.99734275723557,32.8000001609325,0.0232392183444815,0.00314997567251711,1,-2.57097587395675E-7,,,,,,,,,,,,,,,,,,,,,100.192024230957,100.198768615723,-1600.11828613281,-1600.11828613281,53.437206159996,5.63844795131946,5.34641742706299,54,1,0,0,1,0.297088623046875,35.190616607666,1,1,3,100.192024230957,0,100.19539642334,,,,,,,,,,,,,,,,,,,,,,,,,,,,,,,,,
,3877806446.24915,100.189079284668,-1400.07836914062,1.73577479699537E-5,2.20582561982063E-8,1,4,13.4005146026611,4.99742025366842,32.8000001609325,0.0216016749436492,0.00294170382072283,1,-2.28195240296947E-7,,,,,,,,,,,,,,,,,,,,,100.187477111816,100.19068145752,-1400.07836914062,-1400.07836914062,53.5728187080826,5.63793242083468,5.34398460388184,54,1,0,0,1,0.29632568359375,34.7018585205078,1,1,3,100.187477111816,0,100.189079284668,,,,,,,,,,,,,,,,,,,,,,,,,,,,,,,,,
,3877806504.33502,100.16389465332,-1200.10119628906,1.60399724409778E-5,2.36094924773365E-8,1,4,13.4005146026611,4.99740259232526,32.8000001609325,0.0199624621548939,0.0027126488801959,1,-2.15469450422633E-7,,,,,,,,,,,,,,,,,,,,,100.161727905273,100.166061401367,-1200.10119628906,-1200.10119628906,53.4891844565249,5.63827412749799,5.34520101547241,54,1,0,0,1,0.297622680664063,34.7018585205078,1,1,3,100.166061401367,0,100.16389465332,,,,,,,,,,,,,,,,,,,,,,,,,,,,,,,,,
,3877806571.45104,100.1279296875,-1000.06127929688,1.47777270038991E-5,2.42910918413725E-8,1,4,13.4005146026611,4.99743500879618,32.8000001609325,0.0184019836982982,0.00243051482747923,10,-2.53815239831096E-7,,,,,,,,,,,,,,,,,,,,,100.125900268555,100.129959106445,-1000.06127929688,-1000.06127929688,53.5071619124672,5.63853305646685,5.34197235107422,54,1,0,0,1,0.297164916992188,35.190616607666,1,1,3,100.129959106445,0,100.1279296875,,,,,,,,,,,,,,,,,,,,,,,,,,,,,,,,,
,3877806654.56112,100.165016174316,-800.096923828125,1.33068325811522E-5,1.74500046251479E-7,1,4,13.4005146026611,4.99745412779268,32.8000001609325,0.0165447502652743,0.00236033135816384,1,-9.0294370800844E-8,,,,,,,,,,,,,,,,,,,,,100.160331726074,100.169700622559,-800.096923828125,-800.096923828125,53.5360821676787,5.63847193031891,5.3422999382019,53,1,68,0,0,0.297317504882812,35.190616607666,1,1,3,100.160331726074,0,100.165016174316,,,,,,,,,,,,,,,,,,,,,,,,,,,,,,,,,
,3877806729.57656,100.10453414917,-600.182800292969,1.21074737176761E-5,2.32929188367082E-8,1,4,13.4005146026611,4.99747462199523,32.8000001609325,0.0150793509260527,0.00197573896237884,1,-2.20525898885895E-7,,,,,,,,,,,,,,,,,,,,,100.101417541504,100.107650756836,-600.182800292969,-600.182800292969,53.5071619124672,5.63801406013708,5.34910297393799,52,1,68,0,0,0.2978515625,35.190616607666,1,1,3,100.101417541504,0,100.10453414917,,,,,,,,,,,,,,,,,,,,,,,,,,,,,,,,,
,3877806788.00555,100.2116355896,-400.218383789063,1.07806909561632E-5,2.36367906918007E-8,1,4,13.4005146026611,4.99745619750417,32.8000001609325,0.0134402624985733,0.00166942322503996,1,-2.68656807484672E-7,,,,,,,,,,,,,,,,,,,,,100.209747314453,100.213523864746,-400.218383789063,-400.218383789063,53.533737282121,5.63798890544315,5.34767532348633,53,1,68,0,0,0.303268432617188,35.190616607666,1,1,3,100.209747314453,0,100.2116355896,,,,,,,,,,,,,,,,,,,,,,,,,,,,,,,,,
,3877806861.63317,100.171962738037,-200.128082275391,9.53184107516147E-6,3.27865603868804E-8,1,4,13.4005146026611,4.99745923164924,32.8000001609325,0.0118922879072449,0.00141618371077952,1,-2.85723014003461E-7,,,,,,,,,,,,,,,,,,,,,100.171752929688,100.172172546387,-200.128082275391,-200.128082275391,53.5501514810249,5.63811868881129,5.34655570983887,54,1,0,0,1,0.297317504882812,34.7018585205078,1,1,3,100.171630859375,0,100.171962738037,,,,,,,,,,,,,,,,,,,,,,,,,,,,,,,,,
,3877806936.07932,100.182849884033,-0.125882551074028,-9.24553320239376E-6,2.75268065391047E-8,1,4,13.4005146026611,4.99750044198288,32.8000001609325,-0.0114379505916282,-0.0020238347325912,1,-2.46313142982648E-7,,,,,,,,,,,,,,,,,,,,,100.178688049316,100.18701171875,-0.125882551074028,-0.125882551074028,53.5509331095441,5.63823032550026,5.34714317321777,52,1,68,0,0,0.296859741210937,34.7018585205078,1,1,3,100.18701171875,0,100.182849884033,,,,,,,,,,,,,,,,,,,,,,,,,,,,,,,,,
,3877806993.61565,100.111347198486,199.76301574707,-1.05622414177534E-5,3.62398956488003E-8,1,4,13.4005146026611,4.99745954916116,32.8000001609325,-0.0130874722281124,-0.00217346758267786,1,-1.69831056041179E-7,,,,,,,,,,,,,,,,,,,,,100.10977935791,100.112915039062,199.76301574707,199.76301574707,53.5247485541499,5.63865634984805,5.35333395004272,52,1,68,0,0,0.296859741210937,34.7018585205078,1,1,3,100.112915039062,0,100.111347198486,,,,,,,,,,,,,,,,,,,,,,,,,,,,,,,,,
,3877807051.18343,100.175609588623,399.677093505859,-1.19307390387373E-5,1.96598912646453E-8,1,4,13.4005146026611,4.99750207840395,32.8000001609325,-0.0147980691508828,-0.00235655923967382,1,-1.12498291941351E-7,,,,,,,,,,,,,,,,,,,,,100.172096252441,100.179122924805,399.677093505859,399.677093505859,53.4633907153903,5.63853164366566,5.34731292724609,54,1,0,0,1,0.29693603515625,34.7018585205078,1,1,3,100.172096252441,0,100.175609588623,,,,,,,,,,,,,,,,,,,,,,,,,,,,,,,,,
,3877807108.91301,100.158241271973,599.830383300781,-1.32076633021963E-5,1.49709060135115E-8,1,4,13.4005146026611,4.9974836594129,32.8000001609325,-0.01637226803606,-0.00267244106679442,1,-1.75805516867162E-7,,,,,,,,,,,,,,,,,,,,,100.15641784668,100.160064697266,599.830383300781,599.830383300781,53.4207919610922,5.6386184144839,5.34298086166382,54,1,0,0,1,0.296401977539063,34.7018585205078,1,1,3,100.160064697266,0,100.158241271973,,,,,,,,,,,,,,,,,,,,,,,,,,,,,,,,,
,3877807167.76464,100.173458099365,799.706665039063,-1.45102770434873E-5,1.79294383428731E-8,1,4,13.4005146026611,4.99743692980088,32.8000001609325,-0.0179912675692388,-0.00290582395166509,1,-1.68870436968903E-7,,,,,,,,,,,,,,,,,,,,,100.171058654785,100.175857543945,799.706665039063,799.706665039063,53.4430683738903,5.63786582142847,5.34550046920776,54,1,0,0,1,0.296859741210937,34.7018585205078,1,1,3,100.171058654785,0,100.173458099365,,,,,,,,,,,,,,,,,,,,,,,,,,,,,,,,,
,3877807225.43306,100.262096405029,999.671081542969,-1.57801927053929E-5,4.80516880588683E-8,1,4,13.4005146026611,4.99741116844709,32.8000001609325,-0.0195678985664612,-0.00314536774829732,1,-1.71777131586093E-7,,,,,,,,,,,,,,,,,,,,,100.254539489746,100.269653320312,999.671081542969,999.671081542969,53.4512754733422,5.63843540730074,5.34212160110474,53,1,68,0,0,0.296707153320313,34.7018585205078,1,1,3,100.269653320312,0,100.262096405029,,,,,,,,,,,,,,,,,,,,,,,,,,,,,,,,,
,3877807283.18859,100.273170471191,1199.6103515625,-1.71583619994514E-5,1.29553405801701E-8,1,4,13.4005146026611,4.99737507542952,32.8000001609325,-0.0212876950136939,-0.00334622502049365,1,-1.27352833611154E-7,,,,,,,,,,,,,,,,,,,,,100.267890930176,100.278450012207,1199.6103515625,1199.6103515625,53.5446800813903,5.63830596066164,5.34822511672974,52,1,68,0,0,0.297622680664063,34.7018585205078,1,1,3,100.278450012207,0,100.273170471191,,,,,,,,,,,,,,,,,,,,,,,,,,,,,,,,,
,3877807340.74676,100.184989929199,1399.71325683594,-1.84369947396049E-5,1.3099993795129E-8,1,4,13.4005146026611,4.9974157301132,32.8000001609325,-0.0228747564356951,-0.00359260169838886,1,-1.34408968246273E-7,,,,,,,,,,,,,,,,,,,,,100.179809570312,100.190170288086,1399.71325683594,1399.71325683594,53.4587009442749,5.63746269203153,5.34329748153687,54,1,0,0,1,0.297927856445313,34.7018585205078,1,1,3,100.179809570312,0,100.184989929199,,,,,,,,,,,,,,,,,,,,,,,,,,,,,,,,,
,3877807398.48677,100.19388961792,1599.61474609375,-1.97673143796875E-5,1.2227694770821E-8,1,4,13.4005146026611,4.99745227334327,32.8000001609325,-0.0245352267152016,-0.00378706773329103,1,-9.193831582445E-8,,,,,,,,,,,,,,,,,,,,,100.189521789551,100.198257446289,1599.61474609375,1599.61474609375,53.4989548130153,5.63775575257337,5.34577226638794,52,1,68,0,0,0.297393798828125,34.7018585205078,1,1,3,100.189521789551,0,100.19388961792,,,,,,,,,,,,,,,,,,,,,,,,,,,,,,,,,
,3877807456.13231,100.076656341553,1799.66723632813,-2.10685312106335E-5,4.40118332566864E-8,1,4,13.4005146026611,4.99737789353172,32.8000001609325,-0.0261522706830359,-0.00401945365359708,1,-8.44479987437998E-8,,,,,,,,,,,,,,,,,,,,,100.070503234863,100.082809448242,1799.66723632813,1799.66723632813,53.541944381573,5.63752027717484,5.3487114906311,54,1,0,0,1,0.297393798828125,34.7018585205078,1,1,3,100.082809448242,0,100.076656341553,,,,,,,,,,,,,,,,,,,,,,,,,,,,,,,,,
,3877807513.58139,100.110572814941,1999.88342285156,-2.24475657844636E-5,4.60658832759854E-8,1,4,13.4005146026611,4.99746790943278,32.8000001609325,-0.0278540721836622,-0.00435411711370399,1,-1.47511088418501E-7,,,,,,,,,,,,,,,,,,,,,100.110397338867,100.110748291016,1999.88342285156,1999.88342285156,53.577508479198,5.63773530925389,5.34794855117798,52,1,68,0,0,0.297088623046875,34.7018585205078,1,1,3,100.110748291016,0,100.110572814941,,,,,,,,,,,,,,,,,,,,,,,,,,,,,,,,,
,3877807571.30745,100.141025543213,2199.77221679687,-2.37053842796823E-5,1.22807440989974E-8,1,4,13.4005146026611,4.99747735583443,32.8000001609325,-0.0294265974409659,-0.00452000970710241,1,-9.29007888756264E-8,,,,,,,,,,,,,,,,,,,,,100.140907287598,100.141143798828,2199.77221679687,2199.77221679687,53.4868395709672,5.63716290983788,5.34549856185913,54,1,0,0,1,0.296783447265625,34.7018585205078,1,1,3,100.141143798828,0,100.141025543213,,,,,,,,,,,,,,,,,,,,,,,,,,,,,,,,,
,3877807628.8195,100.115676879883,2399.93823242187,-2.50153160639747E-5,9.08909004697787E-9,1,4,13.4005146026611,4.99747663095817,32.8000001609325,-0.0310573100457937,-0.00473876463836991,1,-7.30644218898724E-8,,,,,,,,,,,,,,,,,,,,,100.115432739258,100.115921020508,2399.93823242187,2399.93823242187,53.5509331095441,5.63813607645772,5.34020376205444,54,1,0,0,1,0.2978515625,34.7018585205078,1,1,3,100.115921020508,0,100.115676879883,,,,,,,,,,,,,,,,,,,,,,,,,,,,,,,,,
,3877807686.40646,100.128910064697,2599.8271484375,-2.63213584123032E-5,1.04729790688534E-8,1,4,13.4005146026611,4.99745960233796,32.8000001609325,-0.0326818953641388,-0.00496443739449132,1,-5.93977926721721E-8,,,,,,,,,,,,,,,,,,,,,100.11661529541,100.141204833984,2599.8271484375,2599.8271484375,53.5794625504961,5.63771655682292,5.34535455703735,54,1,0,0,1,0.297088623046875,34.7018585205078,1,1,3,100.141204833984,0,100.128910064697,,,,,,,,,,,,,,,,,,,,,,,,,,,,,,,,,
,3877807744.0483,100.277233123779,2800.00561523438,-2.76122758881594E-5,1.2002755727059E-8,1,4,13.4005146026611,4.99734956305653,32.8000001609325,-0.0342867869030256,-0.0051871543806632,1,-4.57245844497879E-8,,,,,,,,,,,,,,,,,,,,,100.271606445312,100.282859802246,2800.00561523438,2800.00561523438,53.4399418598133,5.63806977101371,5.34031295776367,54,1,0,0,1,0.297012329101562,34.7018585205078,1,1,3,100.282859802246,0,100.277233123779,,,,,,,,,,,,,,,,,,,,,,,,,,,,,,,,,
,3877807801.66712,100.177272796631,2999.642578125,-2.89230033075665E-5,1.16540269189234E-8,1,4,13.4005146026611,4.99734942795999,32.8000001609325,-0.0359159195800615,-0.0054228602200636,1,-3.94226330382712E-8,,,,,,,,,,,,,,,,,,,,,100.169876098633,100.184669494629,2999.642578125,2999.642578125,53.5466341526884,5.63816537568094,5.34461402893066,54,1,0,0,1,0.297317504882812,34.7018585205078,1,1,3,100.169876098633,0,100.177272796631,,,,,,,,,,,,,,,,,,,,,,,,,,,,,,,,,
,3877807879.43012,100.206432342529,4499.81005859375,-3.87299372229508E-5,1.00267354791815E-8,1,4,13.4005146026611,4.99733168199843,32.8000001609325,-0.0481169405373892,-0.00710623263811087,1,7.22665052031502E-8,,,,,,,,,,,,,,,,,,,,,100.199287414551,100.213577270508,4499.81005859375,4499.81005859375,53.5517147380633,5.63844160349592,5.34819364547729,54,1,0,0,1,0.29876708984375,34.7018585205078,1,1,3,100.199287414551,0,100.206432342529,,,,,,,,,,,,,,,,,,,,,,,,,,,,,,,,,
,3877807945.14662,100.164096832275,6499.78173828125,-5.1752643444515E-5,1.29033958151096E-8,1,4,13.4005146026611,4.99730051200964,32.8000001609325,-0.0642990090281317,-0.00947150616632676,1,1.15946408815554E-7,,,,,,,,,,,,,,,,,,,,,100.153717041016,100.174476623535,6499.78173828125,6499.78173828125,53.4680804865057,5.63860564470799,5.35008096694946,54,1,0,0,1,0.296478271484375,34.7018585205078,1,1,3,100.174476623535,0,100.164096832275,,,,,,,,,,,,,,,,,,,,,,,,,,,,,,,,,
,3877808010.2345,100.234172821045,8500.017578125,-6.47690507351596E-5,1.56381386620361E-8,1,4,13.4005146026611,4.99730200880405,32.8000001609325,-0.0804688326888131,-0.0118682674471571,1,1.33385815644431E-7,,,,,,,,,,,,,,,,,,,,,100.224746704102,100.243598937988,8500.017578125,8500.017578125,53.4180562612749,5.63861253423625,5.35340690612793,53,1,68,0,0,0.297470092773438,34.7018585205078,1,1,3,100.224746704102,0,100.234172821045,,,,,,,,,,,,,,,,,,,,,,,,,,,,,,,,,
,3877808082.32132,100.110515594482,10000.0341796875,-7.45268629974796E-5,1.34879775629299E-8,1,4,13.4005146026611,4.99737580548632,32.8000001609325,-0.0925872616861348,-0.0137003933899949,1,1.18197141603662E-7,,,,,,,,,,,,,,,,,,,,,100.109893798828,100.111137390137,10000.0341796875,10000.0341796875,53.399687991073,5.63811251502006,5.35446786880493,54,1,0,0,1,0.296096801757812,34.7018585205078,1,1,3,100.109893798828,0,100.110515594482,,,,,,,,,,,,,,,,,,,,,,,,,,,,,,,,,
,3877808234.87058,100.024429321289,29999.7890625,-2.04678605965062E-4,3.41163017626333E-8,1,4,13.4005146026611,4.99732861143993,32.8000001609325,-0.254254351518718,-0.0377695814086068,1,2.08930655755549E-7,,,,,,,,,,,,,,,,,,,,,100.024208068848,100.02465057373,29999.7890625,29999.7890625,53.4794141000345,5.63869710055736,5.35027408599854,54,1,0,0,1,0.297775268554687,34.7018585205078,1,1,3,100.02465057373,0,100.024429321289,,,,,,,,,,,,,,,,,,,,,,,,,,,,,,,,,
,3877808407.39921,100.020397186279,50000.20703125,-3.35044969054971E-4,1.52093211688842E-7,1,4,13.4005146026611,4.99732335881188,32.8000001609325,-0.416164893471053,-0.0620373166428024,1,1.71984437982417E-7,,,,,,,,,,,,,,,,,,,,,100.019348144531,100.021446228027,50000.20703125,50000.20703125,53.3680320360441,5.63892176293164,5.34711694717407,54,1,0,0,1,0.297775268554687,33.2355842590332,1,1,3,100.021446228027,0,100.020397186279,,,,,,,,,,,,,,,,,,,,,,,,,,,,,,,,,
,3877808564.76754,100.154987335205,70000.3671875,-4.65348837126334E-4,1.6002088229913E-7,1,4,13.4005146026611,4.99739566595608,32.8000001609325,-0.578046471615511,-0.086050762525382,1,3.31875963322495E-7,,,,,,,,,,,,,,,,,,,,,100.143630981445,100.166343688965,70000.3671875,70000.3671875,53.1847401482845,5.63886085340612,5.33773708343506,53,1,68,0,0,0.297088623046875,34.7018585205078,1,1,3,100.166343688965,0,100.154987335205,,,,,,,,,,,,,,,,,,,,,,,,,,,,,,,,,