File: SQUID/Reference/STO/A6/STO_MH_5K_FC_1T.csv
Comment,Time Stamp (sec),Temperature (K),Magnetic Field (Oe),Moment (emu),M. Std. Err. (emu),Transport Action,Averaging Time (sec),Frequency (Hz),Peak Amplitude (mm),Center Position (mm),Lockin Signal' (V),Lockin Signal (V),Range,M. Quad. Signal (emu),AC Moment (emu),AC M. Std Err. (emu),AC Phase (deg),AC Phase Std. Err. (deg),AC Susceptibility (emu/Oe),AC Suscept. Std Err. (emu/Oe),AC X' (emu/Oe),AC X' Std Err. (emu/Oe),AC X'' (emu/Oe),AC X'' Std Err. (emu/Oe),AC Drive (Oe),AC Frequency (Hz),AC Averaging Time (sec),AC Cycles,AC Range,AC Measure Type,AC Signal' (V),AC Signal'' (V),AC Trim Coil Ratio,AC Trim Coil Phase,Min. Temperature (K),Max. Temperature (K),Min. Field (Oe),Max. Field (Oe),Mass (grams),Motor Lag (deg),Pressure (Torr),Measure Count,Measurement Number,SQUID Status (code),Motor Status (code),Measure Status (code),Motor Current (amps),Motor Temp. (C),Temp. Status (code),Field Status (code),Chamber Status (code),Chamber Temp (K),Redirection State,Average Temp (K),Rotation Angle (deg),Rotator state,DC Moment Fixed Ctr (emu),DC Moment Err Fixed Ctr (emu),DC Moment Free Ctr (emu),DC Moment Err Free Ctr (emu),DC Fixed Fit,DC Free Fit,DC Calculated Center (mm),DC Calculated Center Err (mm),DC Scan Length (mm),DC Scan Time (s),DC Number of Points,DC Squid Drift,DC Min V (V),DC Max V (V),DC Scans per Measure,Map 01,Map 02,Map 03,Map 04,Map 05,Map 06,Map 07,Map 08,Map 09,Map 10,Map 11,Map 12,Map 13,Map 14,Map 15,Map 16
,3877772628.61048,5.00008106231689,69999.9140625,-4.39876744459747E-4,1.65584166699311E-7,1,4,13.4005146026611,5.00763446398262,32.7799990773201,-0.548017334133111,-0.0812730256315579,10,5.55164841400762E-7,,,,,,,,,,,,,,,,,,,,,5.00001335144043,5.00014877319336,69999.9140625,69999.9140625,54.7194677457943,5.64193673711752,3.05535197257996,54,1,0,0,1,0.29876708984375,34.2131004333496,1,1,3,5.00014877319336,0,5.00008106231689,,,,,,,,,,,,,,,,,,,,,,,,,,,,,,,,,
,3877772808.35819,5.00018000602722,50000.15625,-3.1040468777119E-4,9.44628147363414E-8,1,4,13.4005146026611,5.00736774273147,32.7799990773201,-0.386611780626253,-0.0578478696326187,1,-1.03096393704875E-8,,,,,,,,,,,,,,,,,,,,,5.00000190734863,5.00035810470581,50000.15625,50000.15625,54.2297774784961,5.64117939390941,3.06942772865295,52,1,32,0,0,0.298385620117188,34.2131004333496,1,1,3,5.00035810470581,0,5.00018000602722,,,,,,,,,,,,,,,,,,,,,,,,,,,,,,,,,
,3877772981.76644,5.00002837181091,29999.5625,-1.83197536289513E-4,3.95866005090597E-8,1,4,13.4005146026611,5.00759528564751,32.7799990773201,-0.228188545400644,-0.0341440227542745,1,-6.61315323262331E-9,,,,,,,,,,,,,,,,,,,,,4.99997997283936,5.00007677078247,29999.5625,29999.5625,53.7193740554384,5.63939640786245,3.07381081581116,54,1,0,0,1,0.30426025390625,34.7018585205078,1,1,3,4.99997997283936,0,5.00002837181091,,,,,,,,,,,,,,,,,,,,,,,,,,,,,,,,,
,3877773140.50248,5.00007963180542,9999.64453125,-5.97426405040251E-5,2.72855087519225E-8,1,4,13.4005146026611,5.0076153769217,32.7799990773201,-0.07441079498189,-0.0111635542738659,1,-2.52518363958038E-8,,,,,,,,,,,,,,,,,,,,,5.00004053115845,5.00011873245239,9999.64453125,9999.64453125,53.5110700550634,5.63828203138974,3.07878994941711,54,1,0,0,1,0.30609130859375,35.190616607666,1,1,3,5.00004053115845,0,5.00007963180542,,,,,,,,,,,,,,,,,,,,,,,,,,,,,,,,,
,3877773219.65334,5.00006294250488,8499.640625,-5.069429922645E-5,1.86545343291001E-8,1,4,13.4005146026611,5.00763865335518,32.7799990773201,-0.0631431675955373,-0.00946031012628039,1,-1.13712597838583E-8,,,,,,,,,,,,,,,,,,,,,4.99999713897705,5.00012874603271,8499.640625,8499.640625,53.526702625448,5.63798093646805,3.07642769813538,54,1,0,0,1,0.298690795898438,34.7018585205078,1,1,3,5.00012874603271,0,5.00006294250488,,,,,,,,,,,,,,,,,,,,,,,,,,,,,,,,,
,3877773286.16274,5.00001406669617,6499.78173828125,-3.86429003800766E-5,1.36785614418611E-8,1,4,13.4005146026611,5.00754489506075,32.7799990773201,-0.0481273004284338,-0.00723640392180133,1,-2.89419688896843E-8,,,,,,,,,,,,,,,,,,,,,4.99994277954102,5.00008535385132,6499.78173828125,6499.78173828125,53.4876211994864,5.63749919189392,3.07174372673035,54,1,0,0,1,0.304794311523438,34.7018585205078,1,1,3,5.00005483627319,0,5.00001406669617,,,,,,,,,,,,,,,,,,,,,,,,,,,,,,,,,
,3877773352.55661,5.00009632110596,4499.69677734375,-2.66443215787082E-5,1.14749904900806E-8,1,4,13.4005146026611,5.00774331759102,32.7799990773201,-0.0331847216573766,-0.00499608198744487,1,-2.50109665845525E-8,,,,,,,,,,,,,,,,,,,,,5.0000524520874,5.00014019012451,4499.69677734375,4499.69677734375,53.5958767493999,5.63839380861351,3.08102369308472,54,1,0,0,1,0.2996826171875,35.190616607666,1,1,3,5.00014019012451,0,5.00009632110596,,,,,,,,,,,,,,,,,,,,,,,,,,,,,,,,,
,3877773433.77775,5.00010657310486,2999.68041992188,-1.76789581631393E-5,9.88354575606428E-9,1,4,13.4005146026611,5.00785445057651,32.7799990773201,-0.0220242299772009,-0.00328218082041608,1,9.82155866512245E-9,,,,,,,,,,,,,,,,,,,,,5.00003433227539,5.00017881393433,2999.68041992188,2999.68041992188,53.4973915559768,5.63772383623073,3.08086800575256,54,1,0,0,1,0.296096801757812,35.190616607666,1,1,3,5.00001859664917,0,5.00010657310486,,,,,,,,,,,,,,,,,,,,,,,,,,,,,,,,,
,3877773490.5283,4.99991226196289,2799.53979492187,-1.66222179351832E-5,1.67004878775203E-8,1,4,13.4005146026611,5.00761968970451,32.7799990773201,-0.020739698924297,-0.00286318763083585,1,1.87944959146454E-7,,,,,,,,,,,,,,,,,,,,,4.99983930587769,4.9999852180481,2799.53979492187,2799.53979492187,53.4973915559768,5.63800441233559,3.07931423187256,52,1,68,0,0,0.304794311523438,35.190616607666,1,1,3,4.99983930587769,0,4.99991226196289,,,,,,,,,,,,,,,,,,,,,,,,,,,,,,,,,
,3877773558.79007,5.00006723403931,2599.77685546875,-1.53870143792089E-5,1.83084331674734E-8,1,4,13.4005146026611,5.00771947726261,32.7799990773201,-0.0192054452412065,-0.00260780304070613,10,2.08253373087726E-7,,,,,,,,,,,,,,,,,,,,,4.99981641769409,5.00031805038452,2599.77685546875,2599.77685546875,53.432125574621,5.6382963597937,3.07520270347595,54,1,0,0,1,0.305633544921875,34.7018585205078,1,1,3,5.00031805038452,0,5.00006723403931,,,,,,,,,,,,,,,,,,,,,,,,,,,,,,,,,
,3877773625.06555,5.00023436546326,2399.5478515625,-1.41941966775773E-5,1.81947663252326E-8,1,4,13.4005146026611,5.00774139613494,32.7799990773201,-0.0177188152405616,-0.00239169948231822,1,2.03315284014977E-7,,,,,,,,,,,,,,,,,,,,,5.00014305114746,5.00032567977905,2399.5478515625,2399.5478515625,53.5907961640249,5.63761578992742,3.08026123046875,54,1,0,0,1,0.303192138671875,34.7018585205078,1,1,3,5.00014305114746,0,5.00023436546326,,,,,,,,,,,,,,,,,,,,,,,,,,,,,,,,,
,3877773682.96046,4.99993085861206,2199.48266601562,-1.29651329142261E-5,1.69745286913246E-8,1,4,13.4005146026611,5.0077966336072,32.7799990773201,-0.0161841112469141,-0.00218929022692744,1,1.81975551762227E-7,,,,,,,,,,,,,,,,,,,,,4.99973678588867,5.00012493133545,2199.48266601562,2199.48266601562,53.4989548130153,5.63874200597423,3.08231592178345,54,1,0,0,1,0.304412841796875,34.7018585205078,1,1,3,4.99973678588867,0,4.99993085861206,,,,,,,,,,,,,,,,,,,,,,,,,,,,,,,,,
,3877773741.7728,4.99996376037598,1999.63159179687,-1.17922836074653E-5,1.79299981114953E-8,1,4,13.4005146026611,5.00779645949565,32.7799990773201,-0.0147255839065276,-0.00195436134019977,1,1.95121735379878E-7,,,,,,,,,,,,,,,,,,,,,4.99979448318481,5.00013303756714,1999.63159179687,1999.63159179687,53.3735034356787,5.63822208186178,3.07736754417419,54,1,0,0,1,0.306167602539063,34.7018585205078,1,1,3,5.00013303756714,0,4.99996376037598,,,,,,,,,,,,,,,,,,,,,,,,,,,,,,,,,
,3877773800.43841,5.00007390975952,1799.52880859375,-1.05902837990754E-5,2.75978281470777E-8,1,4,13.4005146026611,5.00786745710545,32.7799990773201,-0.0132237397450424,-0.0017626198768887,1,1.69265109470302E-7,,,,,,,,,,,,,,,,,,,,,4.99959564208984,5.0005521774292,1799.52880859375,1799.52880859375,53.3656871504864,5.63823165776418,3.07898569107056,54,1,0,0,1,0.298385620117188,34.2131004333496,1,1,3,4.99959564208984,0,5.00007390975952,,,,,,,,,,,,,,,,,,,,,,,,,,,,,,,,,
,3877773861.59818,4.99989366531372,1599.48889160156,-9.3970963105527E-6,1.75468909416151E-8,1,4,13.4005146026611,5.00766497572199,32.7799990773201,-0.0117436532029402,-0.00149394642777373,1,2.06386469983808E-7,,,,,,,,,,,,,,,,,,,,,4.99985218048096,4.99993515014648,1599.48889160156,1599.48889160156,53.3942165914383,5.63781072074867,3.07730770111084,54,1,0,0,1,0.306396484375,34.7018585205078,1,1,3,4.99993515014648,0,4.99989366531372,,,,,,,,,,,,,,,,,,,,,,,,,,,,,,,,,
,3877773919.92232,4.99998760223389,1399.68811035156,-8.21347859766938E-6,2.71654105765766E-8,1,4,13.4005146026611,5.00769582972028,32.7799990773201,-0.01026928574913,-0.00127420752434089,1,2.05742850943584E-7,,,,,,,,,,,,,,,,,,,,,4.9998927116394,5.00008249282837,1399.68811035156,1399.68811035156,53.4856671281884,5.63761037578867,3.0777006149292,54,1,0,0,1,0.3057861328125,34.7018585205078,1,1,3,4.9998927116394,0,4.99998760223389,,,,,,,,,,,,,,,,,,,,,,,,,,,,,,,,,
,3877773995.04857,5.00003862380981,1199.59777832031,-6.9858986116977E-6,2.4460145256304E-8,1,4,13.4005146026611,5.00770268131234,32.7799990773201,-0.00874595780704349,-0.00100692854294657,1,2.36679479675209E-7,,,,,,,,,,,,,,,,,,,,,4.99993228912354,5.00014495849609,1199.59777832031,1199.59777832031,53.3953890342172,5.63829340297099,3.0748598575592,54,1,0,0,1,0.299224853515625,34.7018585205078,1,1,3,5.00014495849609,0,5.00003862380981,,,,,,,,,,,,,,,,,,,,,,,,,,,,,,,,,
,3877774061.79283,5.00024580955505,999.9228515625,-5.87571168115181E-6,3.59008130365499E-8,1,4,13.4005146026611,5.00766781508889,32.7799990773201,-0.00735560149391655,-8.49522895339664E-4,10,1.96961858639215E-7,,,,,,,,,,,,,,,,,,,,,5.00013160705566,5.00036001205444,999.9228515625,999.9228515625,53.4379877885153,5.63758445254678,3.07650876045227,54,1,0,0,1,0.298080444335937,34.2131004333496,1,1,3,5.00036001205444,0,5.00024580955505,,,,,,,,,,,,,,,,,,,,,,,,,,,,,,,,,
,3877774152.21694,5.00004649162292,799.83251953125,-4.64544804051263E-6,2.53820984807063E-8,1,4,13.4005146026611,5.00764965224819,32.7799990773201,-0.00583551608685581,-5.37489817797101E-4,10,2.6342416461959E-7,,,,,,,,,,,,,,,,,,,,,4.99993181228638,5.00016117095947,799.83251953125,799.83251953125,53.4798049142941,5.63803395823831,3.07563090324402,54,1,0,0,1,0.298080444335937,34.7018585205078,1,1,3,5.00016117095947,0,5.00004649162292,,,,,,,,,,,,,,,,,,,,,,,,,,,,,,,,,
,3877774233.92669,5.00002670288086,600.019165039063,-3.45787337616581E-6,2.35237051312882E-8,1,4,13.4005146026611,5.00761423338572,32.7799990773201,-0.00434564185246757,-3.86874588205473E-4,1,2.0668378583252E-7,,,,,,,,,,,,,,,,,,,,,4.99980735778809,5.00024604797363,600.019165039063,600.019165039063,53.5122424978422,5.63781629418769,3.08471155166626,54,1,0,0,1,0.297775268554687,35.190616607666,1,1,3,5.00024604797363,0,5.00002670288086,,,,,,,,,,,,,,,,,,,,,,,,,,,,,,,,,
,3877774300.01594,4.99988102912903,399.941436767578,-2.29333150640539E-6,2.4434829305057E-8,1,4,13.4005146026611,5.00760939798085,32.7799990773201,-0.00290570583189896,-9.88741984447644E-5,10,2.63689437295122E-7,,,,,,,,,,,,,,,,,,,,,4.99976539611816,4.99999666213989,399.941436767578,399.941436767578,53.4614366440922,5.63842207533722,3.08016848564148,54,1,0,0,1,0.306320190429687,34.7018585205078,1,1,3,4.99999666213989,0,4.99988102912903,,,,,,,,,,,,,,,,,,,,,,,,,,,,,,,,,
,3877774364.1048,5.00020623207092,200.102905273438,-1.05647630304724E-6,2.61883275886796E-8,1,4,13.4005146026611,5.00761613807943,32.7799990773201,-0.00135919213540158,9.22168542976203E-5,1,2.32076349491071E-7,,,,,,,,,,,,,,,,,,,,,5.00011920928955,5.0002932548523,200.102905273438,200.102905273438,53.3633422649287,5.63764830147044,3.08107757568359,54,1,0,0,1,0.299530029296875,34.7018585205078,1,1,3,5.0002932548523,0,5.00020623207092,,,,,,,,,,,,,,,,,,,,,,,,,,,,,,,,,
,3877774445.40671,5.00010561943054,0.251765102148056,1.48196834673843E-7,2.78358812398221E-8,1,4,13.4005146026611,5.00772501616519,32.7799990773201,1.3754373399877E-4,3.42173794273479E-4,10,2.52528011363371E-7,,,,,,,,,,,,,,,,,,,,,4.99996709823608,5.000244140625,0.251765102148056,0.251765102148056,53.4719886291018,5.63760550821854,3.08730697631836,54,1,0,0,1,0.29815673828125,34.2131004333496,1,1,3,5.000244140625,0,5.00010561943054,,,,,,,,,,,,,,,,,,,,,,,,,,,,,,,,,
,3877774510.64896,5.00008392333984,-199.876312255859,1.3093050795537E-6,2.57902815980308E-8,1,4,13.4005146026611,5.00763708454589,32.7799990773201,0.00159518717309406,4.82579892723995E-4,1,1.91560985131276E-7,,,,,,,,,,,,,,,,,,,,,4.99992322921753,5.00024461746216,-199.876312255859,-199.876312255859,53.569301379746,5.63707709532784,3.0776960849762,54,1,0,0,1,0.299224853515625,34.7018585205078,1,1,3,5.00024461746216,0,5.00008392333984,,,,,,,,,,,,,,,,,,,,,,,,,,,,,,,,,
,3877774568.22857,5.00005984306335,-399.954040527344,2.50214772807605E-6,1.45990917592975E-8,1,4,13.4005146026611,5.00766678673137,32.7799990773201,0.00308115200803735,7.04024679406706E-4,1,1.90894767509097E-7,,,,,,,,,,,,,,,,,,,,,5.00001573562622,5.00010395050049,-399.954040527344,-399.954040527344,53.5157598261787,5.63763187094292,3.08611178398132,54,1,0,0,1,0.305709838867188,34.7018585205078,1,1,3,5.0001015663147,0,5.00005984306335,,,,,,,,,,,,,,,,,,,,,,,,,,,,,,,,,
,3877774643.38866,5.00009965896606,-599.717102050781,3.70950156927785E-6,2.47586406122912E-8,1,4,13.4005146026611,5.00767747930191,32.7799990773201,0.00459040739148872,8.93313340762767E-4,1,1.62243458484348E-7,,,,,,,,,,,,,,,,,,,,,4.99995565414429,5.00024366378784,-599.717102050781,-599.717102050781,53.4344704601787,5.63809367001475,3.0838725566864,52,1,68,0,0,0.298690795898438,34.2131004333496,1,1,3,4.99995565414429,0,5.00009965896606,,,,,,,,,,,,,,,,,,,,,,,,,,,,,,,,,
,3877774701.86886,4.99979472160339,-799.706665039063,4.87009715827654E-6,2.90318093135118E-8,1,4,13.4005146026611,5.00758957172451,32.7799990773201,0.00602790535544747,0.00116314806921115,1,2.0527479041937E-7,,,,,,,,,,,,,,,,,,,,,4.99971342086792,4.99987602233887,-799.706665039063,-799.706665039063,53.5943134923614,5.63895639044042,3.08840680122375,54,1,0,0,1,0.298614501953125,33.2355842590332,1,1,3,4.99971342086792,0,4.99979472160339,,,,,,,,,,,,,,,,,,,,,,,,,,,,,,,,,
,3877774775.98887,4.99991965293884,-999.708801269531,6.04970765248182E-6,3.22068658141568E-8,1,4,13.4005146026611,5.00756732017116,32.7799990773201,0.00749682783132222,0.00138524285063122,1,2.071238094488E-7,,,,,,,,,,,,,,,,,,,,,4.99971961975098,5.00011968612671,-999.708801269531,-999.708801269531,53.4766784002172,5.63843225867797,3.07768034934998,54,1,0,0,1,0.305023193359375,34.2131004333496,1,1,3,5.00011968612671,0,4.99991965293884,,,,,,,,,,,,,,,,,,,,,,,,,,,,,,,,,
,3877774850.27246,5.00024056434631,-1199.68591308594,7.22949839191447E-6,2.13424508603139E-8,1,4,13.4005146026611,5.00761382944807,32.7799990773201,0.00897570715058741,0.00154336936695712,1,1.57567952377207E-7,,,,,,,,,,,,,,,,,,,,,4.99992227554321,5.00055885314941,-1199.68591308594,-1199.68591308594,53.4368153457364,5.63854693308615,3.08466911315918,53,1,68,0,0,0.304183959960937,34.7018585205078,1,1,3,5.00055885314941,0,5.00024056434631,,,,,,,,,,,,,,,,,,,,,,,,,,,,,,,,,
,3877774932.82219,4.99997973442078,-1399.65026855469,8.48487259629365E-6,6.33729607944528E-8,1,4,13.4005146026611,5.00755458844102,32.7799990773201,0.0105430046059271,0.00175201142081455,10,1.37298138414429E-7,,,,,,,,,,,,,,,,,,,,,4.99988174438477,5.00007772445679,-1399.65026855469,-1399.65026855469,53.4395510455537,5.63895582211815,3.08746075630188,54,1,0,0,1,0.306243896484375,34.7018585205078,1,1,3,5.00007772445679,0,4.99997973442078,,,,,,,,,,,,,,,,,,,,,,,,,,,,,,,,,
,3877775017.29665,4.99975728988647,-1599.75317382813,9.68531826580612E-6,7.47294104453562E-8,1,4,13.4005146026611,5.00755491892329,32.7799990773201,0.0120489165744451,0.00190443398878796,1,8.00894764639879E-8,,,,,,,,,,,,,,,,,,,,,4.99959087371826,4.99992370605469,-1599.75317382813,-1599.75317382813,53.4637815296499,5.6381611810925,3.07960534095764,52,1,68,0,0,0.298309326171875,34.7018585205078,1,1,3,4.99992370605469,0,4.99975728988647,,,,,,,,,,,,,,,,,,,,,,,,,,,,,,,,,
,3877775093.09067,4.99972581863403,-1799.8056640625,1.08461198523906E-5,8.82457645768235E-9,1,4,13.4005146026611,5.00756260331738,32.7799990773201,0.013486877959564,0.00217380184634997,1,1.22695923854482E-7,,,,,,,,,,,,,,,,,,,,,4.99962091445923,4.99983072280884,-1799.8056640625,-1799.8056640625,53.4559652444576,5.6387185613239,3.08517003059387,54,1,0,0,1,0.298995971679687,34.7018585205078,1,1,3,4.99983072280884,0,4.99972581863403,,,,,,,,,,,,,,,,,,,,,,,,,,,,,,,,,
,3877775152.01421,5.00003790855408,-1999.66943359375,1.19657851988821E-5,8.32073504680431E-8,1,4,13.4005146026611,5.00759668658439,32.7799990773201,0.014878429319162,0.00240401916637498,1,1.40009514405823E-7,,,,,,,,,,,,,,,,,,,,,4.99990224838257,5.00017356872559,-1999.66943359375,-1999.66943359375,53.4356429029576,5.63805952040636,3.08498191833496,52,1,68,0,0,0.299301147460937,34.2131004333496,1,1,3,4.99990224838257,0,5.00003790855408,,,,,,,,,,,,,,,,,,,,,,,,,,,,,,,,,
,3877775209.63412,5.0001049041748,-2199.65893554687,1.32180816384098E-5,4.3259418338006E-8,1,4,13.4005146026611,5.00754491825761,32.7799990773201,0.016441142268521,0.00261662430211181,1,1.23389692525047E-7,,,,,,,,,,,,,,,,,,,,,5.00000858306885,5.00020122528076,-2199.65893554687,-2199.65893554687,53.5501514810249,5.6382793852819,3.08552145957947,54,1,0,0,1,0.298614501953125,34.7018585205078,1,1,3,5.00020122528076,0,5.0001049041748,,,,,,,,,,,,,,,,,,,,,,,,,,,,,,,,,
,3877775267.33364,5.00017642974854,-2399.68627929687,1.44293016896836E-5,1.04171975741271E-8,1,4,13.4005146026611,5.00759720169382,32.7799990773201,0.0179554764501412,0.0028062231763693,1,9.43835029872263E-8,,,,,,,,,,,,,,,,,,,,,5.00013732910156,5.00021553039551,-2399.68627929687,-2399.68627929687,53.4293898748037,5.63817475392303,3.08047461509705,54,1,0,0,1,0.29815673828125,34.7018585205078,1,1,3,5.00021553039551,0,5.00017642974854,,,,,,,,,,,,,,,,,,,,,,,,,,,,,,,,,
,3877775325.08936,5.00006556510925,-2599.4873046875,1.56251357971239E-5,1.48840668794119E-8,1,4,13.4005146026611,5.00753458880175,32.7799990773201,0.019446931249239,0.00301382015437219,1,8.22013110133416E-8,,,,,,,,,,,,,,,,,,,,,5.00003862380981,5.00009250640869,-2599.4873046875,-2599.4873046875,53.4551836159384,5.63863713352912,3.08221292495728,54,1,0,0,1,0.298919677734375,34.7018585205078,1,1,3,5.00009250640869,0,5.00006556510925,,,,,,,,,,,,,,,,,,,,,,,,,,,,,,,,,
,3877775383.86723,5.00014472007751,-2799.501953125,1.68490449928308E-5,4.02593131346642E-8,1,4,13.4005146026611,5.007493676586,32.7799990773201,0.0209779894509118,0.00319618112585002,1,4.55486280727543E-8,,,,,,,,,,,,,,,,,,,,,5.00008726119995,5.00020217895508,-2799.501953125,-2799.501953125,53.594704306621,5.63872686898417,3.08092617988586,54,1,0,0,1,0.298233032226562,34.7018585205078,1,1,3,5.00008726119995,0,5.00014472007751,,,,,,,,,,,,,,,,,,,,,,,,,,,,,,,,,
,3877775444.29915,4.99975180625916,-2999.79370117188,1.7999635469221E-5,1.05455785521558E-8,1,4,13.4005146026611,5.00754820809027,32.7799990773201,0.0224018758521539,0.00347467938634637,1,9.69779366944421E-8,,,,,,,,,,,,,,,,,,,,,4.99959659576416,4.99990701675415,-2999.79370117188,-2999.79370117188,53.4997364415345,5.63921590811464,3.08449482917786,54,1,0,0,1,0.29876708984375,34.7018585205078,1,1,3,4.99959659576416,0,4.99975180625916,,,,,,,,,,,,,,,,,,,,,,,,,,,,,,,,,
,3877775523.13846,4.99998903274536,-4499.6083984375,2.70422995697582E-5,4.31257007548504E-8,1,4,13.4005146026611,5.0074999360979,32.7799990773201,0.0336905597913404,0.00498709484296174,1,-4.14669301820677E-8,,,,,,,,,,,,,,,,,,,,,4.99985122680664,5.00012683868408,-4499.6083984375,-4499.6083984375,53.5005180700537,5.63878593018871,3.08357238769531,54,1,0,0,1,0.30609130859375,34.2131004333496,1,1,3,4.99985122680664,0,4.99998903274536,,,,,,,,,,,,,,,,,,,,,,,,,,,,,,,,,
,3877775588.30141,5.00013852119446,-6499.55517578125,3.89927875423442E-5,1.59920490224401E-8,1,4,13.4005146026611,5.00755888614117,32.7799990773201,0.0485800903325738,0.00718939678840754,1,-6.11607935477472E-8,,,,,,,,,,,,,,,,,,,,,5.00000476837158,5.00027227401733,-6499.55517578125,-6499.55517578125,53.4278266177653,5.63873201218727,3.07460761070251,54,1,0,0,1,0.299224853515625,34.2131004333496,1,1,3,5.00000476837158,0,5.00013852119446,,,,,,,,,,,,,,,,,,,,,,,,,,,,,,,,,
,3877775655.37975,5.00006508827209,-8499.640625,5.10039393834564E-5,1.9148959436563E-8,1,4,13.4005146026611,5.0075692640032,32.7799990773201,0.0635426153389875,0.00941763388754284,1,-6.90638899621711E-8,,,,,,,,,,,,,,,,,,,,,4.99998569488525,5.00014448165894,-8499.640625,-8499.640625,53.5052078411691,5.63882411174734,3.07831430435181,54,1,0,0,1,0.305099487304687,34.2131004333496,1,1,3,5.00014448165894,0,5.00006508827209,,,,,,,,,,,,,,,,,,,,,,,,,,,,,,,,,
,3877775737.3957,4.99991822242737,-9999.5439453125,6.00597945832979E-5,2.0001412228348E-8,1,4,13.4005146026611,5.00760468214256,32.7799990773201,0.0748229568588301,0.0111067188001575,1,-6.77947924920645E-8,,,,,,,,,,,,,,,,,,,,,4.99990749359131,4.99992895126343,-9999.5439453125,-9999.5439453125,53.3594341223326,5.63837531985216,3.0754234790802,54,1,0,0,1,0.305099487304687,34.7018585205078,1,1,3,4.99992895126343,0,4.99991822242737,,,,,,,,,,,,,,,,,,,,,,,,,,,,,,,,,
,3877775894.33136,5.00012803077698,-29999.67578125,1.8352836665091E-4,3.55839711643551E-8,1,4,13.4005146026611,5.00759899130292,32.7799990773201,0.22862911202801,0.034016859489885,1,-1.44995729590768E-7,,,,,,,,,,,,,,,,,,,,,5.00011348724365,5.0001425743103,-29999.67578125,-29999.67578125,53.7576738528807,5.63927058054217,3.08441472053528,54,1,0,0,1,0.304641723632812,34.2131004333496,1,1,3,5.00011348724365,0,5.00012803077698,,,,,,,,,,,,,,,,,,,,,,,,,,,,,,,,,
,3877776053.42182,5.00009918212891,-49999.55078125,3.10692488710636E-4,6.72153786083169E-8,1,4,13.4005146026611,5.00766748944539,32.7799990773201,0.387035078216267,0.057689377541721,1,-1.63869338491134E-7,,,,,,,,,,,,,,,,,,,,,5.0000467300415,5.00015163421631,-49999.55078125,-49999.55078125,54.248145748698,5.63987882555256,3.08496141433716,52,1,68,0,0,0.298004150390625,34.2131004333496,1,1,3,5.0000467300415,0,5.00009918212891,,,,,,,,,,,,,,,,,,,,,,,,,,,,,,,,,
,3877776245.25492,5.00011038780212,-69999.609375,4.39548395297851E-4,1.2242401982995E-7,1,4,13.4005146026611,5.00770066820514,32.7799990773201,0.547555211011075,0.0816361471532984,1,-2.15735428919552E-7,,,,,,,,,,,,,,,,,,,,,5.00007200241089,5.00014877319336,-69999.609375,-69999.609375,54.7749633706596,5.64105806342083,3.0835280418396,54,1,0,0,1,0.299072265625,34.7018585205078,1,1,3,5.00014877319336,0,5.00011038780212,,,,,,,,,,,,,,,,,,,,,,,,,,,,,,,,,
,3877776406.96466,5.00022292137146,-49999.73046875,3.1043326392505E-4,8.2778898289201E-8,1,4,13.4005146026611,5.00769076151094,32.7799990773201,0.386692024723188,0.0577929941103573,1,-4.22075210422921E-8,,,,,,,,,,,,,,,,,,,,,5.00012636184692,5.000319480896,-49999.73046875,-49999.73046875,54.1758451106692,5.64041001198457,3.08428382873535,54,1,0,0,1,0.306472778320313,34.7018585205078,1,1,3,5.000319480896,0,5.00022292137146,,,,,,,,,,,,,,,,,,,,,,,,,,,,,,,,,
,3877776565.55476,5.00009727478027,-29999.67578125,1.83241089525553E-4,4.73068816523751E-8,1,4,13.4005146026611,5.00766877398241,32.7799990773201,0.228256892672088,0.034089898554306,1,-4.39160797973636E-8,,,,,,,,,,,,,,,,,,,,,4.99996280670166,5.00023174285889,-29999.67578125,-29999.67578125,53.8104337779288,5.6389727917134,3.08553647994995,54,1,0,0,1,0.298919677734375,34.7018585205078,1,1,3,5.00023174285889,0,5.00009727478027,,,,,,,,,,,,,,,,,,,,,,,,,,,,,,,,,
,3877776723.5207,5.00003099441528,-10000.2734375,5.97627007787637E-5,2.40228586993975E-8,1,4,13.4005146026611,5.00747379235784,32.7799990773201,0.0744306880458448,0.0111812373649766,1,3.68021666439163E-8,,,,,,,,,,,,,,,,,,,,,4.99983406066895,5.00022792816162,-10000.2734375,-10000.2734375,53.4540111731595,5.6390878784431,3.08340382575989,54,1,0,0,1,0.29693603515625,34.7018585205078,1,1,3,5.00022792816162,0,5.00003099441528,,,,,,,,,,,,,,,,,,,,,,,,,,,,,,,,,
,3877776803.07902,4.99986577033997,-8500.1064453125,5.06847665739924E-5,2.18227058343373E-8,1,4,13.4005146026611,5.00748626229762,32.7799990773201,0.063126091380649,0.00947495518197751,1,2.48782232992678E-8,,,,,,,,,,,,,,,,,,,,,4.99971294403076,5.00001859664917,-8500.1064453125,-8500.1064453125,53.526702625448,5.63892267835152,3.07650113105774,54,1,0,0,1,0.30487060546875,34.7018585205078,1,1,3,5.00001859664917,0,4.99986577033997,,,,,,,,,,,,,,,,,,,,,,,,,,,,,,,,,
,3877776866.57707,5.00016188621521,-6500.00830078125,3.86538515358306E-5,2.02942885899009E-8,1,4,13.4005146026611,5.00756705444458,32.7799990773201,0.0481404126113364,0.00724401159240918,1,3.33755183386615E-8,,,,,,,,,,,,,,,,,,,,,5.00008821487427,5.00023555755615,-6500.00830078125,-6500.00830078125,53.4501030305633,5.63923436330195,3.07798719406128,54,1,0,0,1,0.299758911132812,34.7018585205078,1,1,3,5.00023555755615,0,5.00016188621521,,,,,,,,,,,,,,,,,,,,,,,,,,,,,,,,,
,3877776932.29425,5.00004911422729,-4500.28857421875,2.66462553058931E-5,1.08943077557681E-8,1,4,13.4005146026611,5.00757316318917,32.7799990773201,0.0331890129151548,0.00497308397779093,1,6.44859960699635E-9,,,,,,,,,,,,,,,,,,,,,5.00000143051147,5.00009679794312,-4500.28857421875,-4500.28857421875,53.541944381573,5.63866517119967,3.08245229721069,54,1,0,0,1,0.298995971679687,34.7018585205078,1,1,3,5.00000143051147,0,5.00004911422729,,,,,,,,,,,,,,,,,,,,,,,,,,,,,,,,,
,3877777015.50531,5.00002932548523,-3000.4736328125,1.7672961553252E-5,1.04087942778512E-8,1,4,13.4005146026611,5.00748681421108,32.7799990773201,0.0220149375197278,0.00327780745281232,1,-1.21652736940199E-8,,,,,,,,,,,,,,,,,,,,,4.99998331069946,5.000075340271,-3000.4736328125,-3000.4736328125,53.4864487567076,5.63848688057887,3.07764053344727,54,1,0,0,1,0.29876708984375,35.190616607666,1,1,3,5.000075340271,0,5.00002932548523,,,,,,,,,,,,,,,,,,,,,,,,,,,,,,,,,
,3877777072.44803,5.00002336502075,-2800.29516601562,1.65781516222744E-5,1.83322601401975E-8,1,4,13.4005146026611,5.00745601075322,32.7799990773201,0.0206862797420125,0.00283870223206357,1,-2.00906250461782E-7,,,,,,,,,,,,,,,,,,,,,4.99994516372681,5.0001015663147,-2800.29516601562,-2800.29516601562,53.4293898748037,5.6385264754662,3.07924723625183,53,1,68,0,0,0.306472778320313,34.7018585205078,1,1,3,5.0001015663147,0,5.00002336502075,,,,,,,,,,,,,,,,,,,,,,,,,,,,,,,,,
,3877777128.78144,5.00011157989502,-2600.2802734375,1.53862820957483E-5,1.84153625706044E-8,1,4,13.4005146026611,5.00742609927195,32.7799990773201,0.0192002423737965,0.00262562223919696,1,-1.93665910082447E-7,,,,,,,,,,,,,,,,,,,,,5.00001573562622,5.00020742416382,-2600.2802734375,-2600.2802734375,53.4239184751691,5.63911366364513,3.08305478096008,53,1,68,0,0,0.307235717773438,34.7018585205078,1,1,3,5.00001573562622,0,5.00011157989502,,,,,,,,,,,,,,,,,,,,,,,,,,,,,,,,,
,3877777185.13411,5.00005149841309,-2400.29052734375,1.41814261351203E-5,2.04784582208633E-8,1,4,13.4005146026611,5.00749284714647,32.7799990773201,0.0176970851919493,0.00241986578076263,1,-1.78658282015438E-7,,,,,,,,,,,,,,,,,,,,,5.00001859664917,5.000084400177,-2400.29052734375,-2400.29052734375,53.4547928016787,5.63890838600664,3.07848238945007,54,1,0,0,1,0.298233032226562,34.7018585205078,1,1,3,5.00001859664917,0,5.00005149841309,,,,,,,,,,,,,,,,,,,,,,,,,,,,,,,,,
,3877777242.01655,4.99984765052795,-2200.50244140625,1.30136396037127E-5,2.84583976074268E-8,1,4,13.4005146026611,5.00741637677927,32.7799990773201,0.0162447596090171,0.00218506366120684,1,-1.92438670222146E-7,,,,,,,,,,,,,,,,,,,,,4.99977970123291,4.999915599823,-2200.50244140625,-2200.50244140625,53.5263118111883,5.63826456726827,3.08315205574036,52,1,68,0,0,0.299072265625,34.7018585205078,1,1,3,4.99977970123291,0,4.99984765052795,,,,,,,,,,,,,,,,,,,,,,,,,,,,,,,,,
,3877777298.67266,4.99998736381531,-2000.37438964844,1.18112036896233E-5,2.08126128394649E-8,1,4,13.4005146026611,5.00751145153348,32.7799990773201,0.0147484591458947,0.0019545190207777,1,-1.97700644980206E-7,,,,,,,,,,,,,,,,,,,,,4.99963521957397,5.00033950805664,-2000.37438964844,-2000.37438964844,53.4743335146595,5.63851010451397,3.0825023651123,52,1,68,0,0,0.298233032226562,35.190616607666,1,1,3,4.99963521957397,0,4.99998736381531,,,,,,,,,,,,,,,,,,,,,,,,,,,,,,,,,
,3877777358.13857,5.00023341178894,-1800.17077636719,1.05930036719922E-5,2.02132455747538E-8,1,4,13.4005146026611,5.00752739132673,32.7799990773201,0.0132330306998268,0.00171510740753129,1,-2.07682809140125E-7,,,,,,,,,,,,,,,,,,,,,4.99993848800659,5.00052833557129,-1800.17077636719,-1800.17077636719,53.4712070005826,5.63880254262712,3.0754873752594,52,1,68,0,0,0.298690795898438,34.7018585205078,1,1,3,4.99993848800659,0,5.00023341178894,,,,,,,,,,,,,,,,,,,,,,,,,,,,,,,,,
,3877777432.46705,4.99995589256287,-1600.04272460938,9.43216135717352E-6,3.27955677546652E-8,1,4,13.4005146026611,5.00744053454344,32.7799990773201,0.0117823156291051,0.00152897544062629,1,-1.83433291768232E-7,,,,,,,,,,,,,,,,,,,,,4.99980878829956,5.00010299682617,-1600.04272460938,-1600.04272460938,53.4751151431787,5.6390096336879,3.0827624797821,54,1,0,0,1,0.2984619140625,34.7018585205078,1,1,3,4.99980878829956,0,4.99995589256287,,,,,,,,,,,,,,,,,,,,,,,,,,,,,,,,,
,3877777490.78439,4.99995732307434,-1400.05310058594,8.21505485840535E-6,1.99334524841922E-8,1,4,13.4005146026611,5.00742410357476,32.7799990773201,0.0102712803870991,0.00126898811680045,1,-2.10091550248687E-7,,,,,,,,,,,,,,,,,,,,,4.99972534179687,5.00018930435181,-1400.05310058594,-1400.05310058594,53.4184470755345,5.63838262340285,3.07648825645447,52,1,68,0,0,0.306320190429687,34.7018585205078,1,1,3,4.99972534179687,0,4.99995732307434,,,,,,,,,,,,,,,,,,,,,,,,,,,,,,,,,
,3877777548.24493,5.00022053718567,-1200.26489257812,7.00921593532952E-6,2.28679249061393E-8,1,4,13.4005146026611,5.00747575809274,32.7799990773201,0.00877211083104648,0.00102682459247127,1,-2.24142727256472E-7,,,,,,,,,,,,,,,,,,,,,5.000168800354,5.00027227401733,-1200.26489257812,-1200.26489257812,53.4833222426306,5.63803849607837,3.07739734649658,53,1,68,0,0,0.298538208007812,34.7018585205078,1,1,3,5.00025129318237,0,5.00022053718567,,,,,,,,,,,,,,,,,,,,,,,,,,,,,,,,,
,3877777605.35441,5.00010061264038,-1000.22497558594,5.81653871241019E-6,2.16329467587607E-8,1,4,13.4005146026611,5.00743700612798,32.7799990773201,0.00728353067410404,8.24369084459048E-4,1,-2.08261122838863E-7,,,,,,,,,,,,,,,,,,,,,5.00004577636719,5.00015544891357,-1000.22497558594,-1000.22497558594,53.5102884265441,5.63854520332356,3.08144378662109,54,1,0,0,1,0.298538208007812,35.190616607666,1,1,3,5.00015544891357,0,5.00010061264038,,,,,,,,,,,,,,,,,,,,,,,,,,,,,,,,,
,3877777663.84497,5.00015234947205,-800.222778320312,4.63603022687786E-6,2.23714782241447E-8,1,4,13.4005146026611,5.00751721396864,32.7799990773201,0.00581599483942744,5.86352219503647E-4,1,-2.22770321304901E-7,,,,,,,,,,,,,,,,,,,,,5.00006484985352,5.00023984909058,-800.222778320312,-800.222778320312,53.4024236908903,5.6382894357895,3.07628107070923,54,1,0,0,1,0.30426025390625,34.7018585205078,1,1,3,5.00003337860107,0,5.00015234947205,,,,,,,,,,,,,,,,,,,,,,,,,,,,,,,,,
,3877777721.99813,5.0001494884491,-600.170227050781,3.43492381409931E-6,2.43985034529369E-8,1,4,13.4005146026611,5.00750920317899,32.7799990773201,0.00431014633689189,4.27929551554012E-4,1,-1.70280629304962E-7,,,,,,,,,,,,,,,,,,,,,4.99987888336182,5.00042009353638,-600.170227050781,-600.170227050781,53.5681289369672,5.63813846498452,3.07765579223633,53,1,68,0,0,0.306015014648438,34.7018585205078,1,1,3,5.00042009353638,0,5.0001494884491,,,,,,,,,,,,,,,,,,,,,,,,,,,,,,,,,
,3877777795.19735,4.99992489814758,-400.331695556641,2.25821187887511E-6,2.61780287353546E-8,1,4,13.4005146026611,5.00750285024485,32.7799990773201,0.00285982772478141,1.06017951564646E-4,1,-2.52698030979524E-7,,,,,,,,,,,,,,,,,,,,,4.99980640411377,5.0000433921814,-400.331695556641,-400.331695556641,53.5501514810249,5.63801303352499,3.07648515701294,53,1,68,0,0,0.29876708984375,34.7018585205078,1,1,3,5.0000433921814,0,4.99992489814758,,,,,,,,,,,,,,,,,,,,,,,,,,,,,,,,,
,3877777852.90995,5.00008320808411,-200.27912902832,1.06918207709735E-6,2.64682989344038E-8,1,4,13.4005146026611,5.00750076452538,32.7799990773201,0.00137473974073697,-8.82792574335616E-5,1,-2.30818136235784E-7,,,,,,,,,,,,,,,,,,,,,5.00005054473877,5.00011587142944,-200.27912902832,-200.27912902832,53.569301379746,5.63804896971661,3.08032274246216,53,1,68,0,0,0.298080444335937,34.7018585205078,1,1,3,5.00011587142944,0,5.00008320808411,,,,,,,,,,,,,,,,,,,,,,,,,,,,,,,,,
,3877777909.78135,4.99993777275085,-0.276941627264023,-1.53172643249878E-7,2.6271317627545E-8,1,4,13.4005146026611,5.00750941399108,32.7799990773201,-1.50150352681939E-4,-3.00182803584504E-4,1,-2.18087770318509E-7,,,,,,,,,,,,,,,,,,,,,4.99982261657715,5.00005292892456,-0.276941627264023,-0.276941627264023,53.3973431055153,5.63816289801546,3.08601522445679,53,1,68,0,0,0.29815673828125,34.7018585205078,1,1,3,4.99982261657715,0,4.99993777275085,,,,,,,,,,,,,,,,,,,,,,,,,,,,,,,,,
,3877777982.94835,4.99990701675415,199.951843261719,-1.29309327147814E-6,3.14893849427423E-8,1,4,13.4005146026611,5.00754293353841,32.7799990773201,-0.00157103772240838,-5.05713900881208E-4,1,-2.12569294992106E-7,,,,,,,,,,,,,,,,,,,,,4.99977445602417,5.00003957748413,199.951843261719,199.951843261719,53.4876211994864,5.63793828922902,3.07650661468506,54,1,0,0,1,0.298309326171875,34.7018585205078,1,1,3,4.99977445602417,0,4.99990701675415,,,,,,,,,,,,,,,,,,,,,,,,,,,,,,,,,
,3877778042.51834,4.99993705749512,399.689666748047,-2.52708033695363E-6,1.35100477767493E-8,1,4,13.4005146026611,5.00750792075839,32.7799990773201,-0.00313448403563573,-5.58810023580326E-4,1,-7.06045828565328E-8,,,,,,,,,,,,,,,,,,,,,4.99976539611816,5.00010871887207,399.689666748047,399.689666748047,53.5310015823037,5.63798983066866,3.08432817459106,54,1,0,0,1,0.298690795898438,34.7018585205078,1,1,3,5.00010871887207,0,4.99993705749512,,,,,,,,,,,,,,,,,,,,,,,,,,,,,,,,,
,3877778100.06997,5.00024509429932,599.767456054687,-3.67530298156674E-6,1.95605517139771E-8,1,4,13.4005146026611,5.00751971252452,32.7799990773201,-0.00454309104252948,-9.17100442725767E-4,1,-1.86488336401461E-7,,,,,,,,,,,,,,,,,,,,,5.0002179145813,5.00027227401733,599.767456054687,599.767456054687,53.3269965387845,5.63830134752681,3.0853374004364,53,1,68,0,0,0.306549072265625,34.7018585205078,1,1,3,5.0002179145813,0,5.00024509429932,,,,,,,,,,,,,,,,,,,,,,,,,,,,,,,,,
,3877778157.66082,4.99993109703064,799.694091796875,-4.8777575433202E-6,1.57395782082305E-8,1,4,13.4005146026611,5.00754340006441,32.7799990773201,-0.00603951382511627,-0.00115022449799053,1,-1.93765302336218E-7,,,,,,,,,,,,,,,,,,,,,4.99982309341431,5.00003910064697,799.694091796875,799.694091796875,53.5481974097268,5.63854768415592,3.08025670051575,53,1,68,0,0,0.2984619140625,34.7018585205078,1,1,3,4.99982309341431,0,4.99993109703064,,,,,,,,,,,,,,,,,,,,,,,,,,,,,,,,,
,3877778231.8652,5.00007057189941,999.809509277344,-6.06482150365682E-6,2.96939284604211E-8,1,4,13.4005146026611,5.00749141861856,32.7799990773201,-0.00752556908830968,-0.00132068113573721,1,-1.53052867755915E-7,,,,,,,,,,,,,,,,,,,,,4.99994802474976,5.00019311904907,999.809509277344,999.809509277344,53.4700345578037,5.63857625235257,3.0856671333313,52,1,68,0,0,0.298233032226562,34.7018585205078,1,1,3,4.99994802474976,0,5.00007057189941,,,,,,,,,,,,,,,,,,,,,,,,,,,,,,,,,
,3877778306.83086,5.00005626678467,1199.7236328125,-7.25059549532874E-6,1.59329337892648E-8,1,4,13.4005146026611,5.00765432865265,32.7799990773201,-0.00899939526403554,-0.00156531482912017,1,-1.7201612711441E-7,,,,,,,,,,,,,,,,,,,,,4.99989891052246,5.00021362304687,1199.7236328125,1199.7236328125,53.376239135496,5.63768740174568,3.07834553718567,53,1,68,0,0,0.304641723632812,34.7018585205078,1,1,3,5.00021362304687,0,5.00005626678467,,,,,,,,,,,,,,,,,,,,,,,,,,,,,,,,,
,3877778373.07281,5.00010776519775,1399.67553710938,-8.46557274418034E-6,1.14318981849692E-8,1,4,13.4005146026611,5.0076258351773,32.7799990773201,-0.010515631382168,-0.00177213362753128,10,-1.5631187114317E-7,,,,,,,,,,,,,,,,,,,,,5.00007152557373,5.00014400482178,1399.67553710938,1399.67553710938,53.536863796198,5.63799472965307,3.07451176643372,54,1,0,0,1,0.29876708984375,34.7018585205078,1,1,3,5.00014400482178,0,5.00010776519775,,,,,,,,,,,,,,,,,,,,,,,,,,,,,,,,,
,3877778440.20842,5.00027012825012,1599.57690429687,-9.58772015384643E-6,1.34252479617219E-7,1,4,13.4005146026611,5.00759116455845,32.7799990773201,-0.0118959807009276,-0.0020967727474886,1,-2.49089533519781E-7,,,,,,,,,,,,,,,,,,,,,5.00009727478027,5.00044298171997,1599.57690429687,1599.57690429687,53.3985155482941,5.63819699253899,3.07927012443542,54,1,0,0,1,0.298690795898438,34.7018585205078,1,1,3,5.00044298171997,0,5.00027012825012,,,,,,,,,,,,,,,,,,,,,,,,,,,,,,,,,
,3877778514.4901,5.00008177757263,1799.61694335938,-1.08669369614189E-5,2.45887575379694E-8,1,4,13.4005146026611,5.00757794069474,32.7799990773201,-0.0135089081707518,-0.00220414217925384,1,-1.43932579660924E-7,,,,,,,,,,,,,,,,,,,,,5.00002479553223,5.00013875961304,1799.61694335938,1799.61694335938,53.4559652444576,5.63783056024148,3.07768654823303,54,1,0,0,1,0.298843383789063,34.7018585205078,1,1,3,5.00002479553223,0,5.00008177757263,,,,,,,,,,,,,,,,,,,,,,,,,,,,,,,,,
,3877778572.13151,4.99991393089294,1999.93371582031,-1.20412235453206E-5,3.97243760300448E-8,1,4,13.4005146026611,5.00756097133261,32.7799990773201,-0.0149852003517244,-0.00233145254798926,1,-7.04844480916474E-8,,,,,,,,,,,,,,,,,,,,,4.99980449676514,5.00002336502075,1999.93371582031,1999.93371582031,53.391480891621,5.63797410976814,3.08490514755249,54,1,0,0,1,0.307159423828125,34.7018585205078,1,1,3,5.00002336502075,0,4.99991393089294,,,,,,,,,,,,,,,,,,,,,,,,,,,,,,,,,
,3877778629.62564,5.00016474723816,2199.873046875,-1.32348583249541E-5,8.26170043285847E-9,1,4,13.4005146026611,5.00752651444888,32.7799990773201,-0.016464942330582,-0.00259976286150366,1,-1.07353670391351E-7,,,,,,,,,,,,,,,,,,,,,5.00003051757812,5.00029897689819,2199.873046875,2199.873046875,53.4887936422653,5.63820114742364,3.07826948165894,54,1,0,0,1,0.299453735351562,34.7018585205078,1,1,3,5.00003051757812,0,5.00016474723816,,,,,,,,,,,,,,,,,,,,,,,,,,,,,,,,,
,3877778687.24761,4.99995374679565,2399.8876953125,-1.4436782636063E-5,9.96280272932779E-9,1,4,13.4005146026611,5.00755844418343,32.7799990773201,-0.0179637865093863,-0.00281302686447031,1,-9.8751033284323E-8,,,,,,,,,,,,,,,,,,,,,4.99989175796509,5.00001573562622,2399.8876953125,2399.8876953125,53.4751151431787,5.63779227512597,3.07402348518372,54,1,0,0,1,0.298614501953125,34.7018585205078,1,1,3,4.99989175796509,0,4.99995374679565,,,,,,,,,,,,,,,,,,,,,,,,,,,,,,,,,
,3877778745.08161,5.0000216960907,2599.73901367187,-1.56309568309343E-5,1.32223888930148E-8,1,4,13.4005146026611,5.0075424074735,32.7799990773201,-0.0194498148716557,-0.00304438691944708,1,-1.05865508964442E-7,,,,,,,,,,,,,,,,,,,,,4.99978733062744,5.00025606155396,2599.73901367187,2599.73901367187,53.376239135496,5.63765516712811,3.0797700881958,54,1,0,0,1,0.30609130859375,34.7018585205078,1,1,3,4.99978733062744,0,5.0000216960907,,,,,,,,,,,,,,,,,,,,,,,,,,,,,,,,,
,3877778802.67691,4.9998939037323,2799.89233398438,-1.68044541643795E-5,3.55703670304741E-8,1,4,13.4005146026611,5.00755123647907,32.7799990773201,-0.0209217001080628,-0.00319517699537919,1,-5.13717545112114E-8,,,,,,,,,,,,,,,,,,,,,4.99987316131592,4.99991464614868,2799.89233398438,2799.89233398438,53.4856671281884,5.63828972345707,3.07522535324097,54,1,0,0,1,0.298614501953125,34.7018585205078,1,1,3,4.99991464614868,0,4.9998939037323,,,,,,,,,,,,,,,,,,,,,,,,,,,,,,,,,
,3877778860.2874,4.99989438056946,2999.80639648438,-1.80132633393346E-5,9.70128366459227E-9,1,4,13.4005146026611,5.00753870939157,32.7799990773201,-0.0224208888957611,-0.00346318537373958,1,-8.57188074046412E-8,,,,,,,,,,,,,,,,,,,,,4.9998140335083,4.99997472763062,2999.80639648438,2999.80639648438,53.4360337172172,5.63800405278126,3.08314442634583,54,1,0,0,1,0.305938720703125,34.7018585205078,1,1,3,4.99997472763062,0,4.99989438056946,,,,,,,,,,,,,,,,,,,,,,,,,,,,,,,,,
,3877778937.16045,5.00013756752014,4499.6337890625,-2.71000766349353E-5,4.45597949335062E-8,1,4,13.4005146026611,5.00760919200699,32.7799990773201,-0.0337654060957615,-0.00498563448773203,1,5.14045473058796E-8,,,,,,,,,,,,,,,,,,,,,5.00010061264038,5.0001745223999,4499.6337890625,4499.6337890625,53.4254817322076,5.63873137690216,3.07842326164246,54,1,0,0,1,0.29876708984375,34.7018585205078,1,1,3,5.00010061264038,0,5.00013756752014,,,,,,,,,,,,,,,,,,,,,,,,,,,,,,,,,
,3877779003.0617,4.99998784065247,6499.68115234375,-3.90069882920553E-5,1.75038992693712E-8,1,4,13.4005146026611,5.00752064914818,32.7799990773201,-0.048597278082508,-0.00719184384010968,1,6.1258922230512E-8,,,,,,,,,,,,,,,,,,,,,4.99981355667114,5.00016212463379,6499.68115234375,6499.68115234375,53.5145873833999,5.6385209589362,3.08322358131409,54,1,0,0,1,0.29876708984375,34.7018585205078,1,1,3,4.99981355667114,0,4.99998784065247,,,,,,,,,,,,,,,,,,,,,,,,,,,,,,,,,
,3877779068.03227,4.99998164176941,8499.9296875,-5.10353280078086E-5,2.06659876185434E-8,1,4,13.4005146026611,5.00753697251911,32.7799990773201,-0.0635845726271445,-0.00940044737410678,1,8.7489348607049E-8,,,,,,,,,,,,,,,,,,,,,4.99992179870605,5.00004148483276,8499.9296875,8499.9296875,53.5005180700537,5.637969350794,3.07353639602661,54,1,0,0,1,0.29815673828125,34.7018585205078,1,1,3,4.99992179870605,0,4.99998164176941,,,,,,,,,,,,,,,,,,,,,,,,,,,,,,,,,
,3877779140.59939,4.99983954429626,9999.9208984375,-6.00676065723249E-5,2.18059611912678E-8,1,4,13.4005146026611,5.00755204961678,32.7799990773201,-0.0748300023531065,-0.0111186109214407,1,5.92849458930376E-8,,,,,,,,,,,,,,,,,,,,,4.99979972839355,4.99987936019897,9999.9208984375,9999.9208984375,53.470816186323,5.63866161062333,3.08197331428528,54,1,0,0,1,0.306320190429687,33.7243423461914,1,1,3,4.99979972839355,0,4.99983954429626,,,,,,,,,,,,,,,,,,,,,,,,,,,,,,,,,
,3877779295.1942,4.99995398521423,30000.205078125,-1.83456883627958E-4,3.55973263275591E-8,1,4,13.4005146026611,5.00756939144882,32.7799990773201,-0.228539106643585,-0.0339970962118009,1,1.49943318307446E-7,,,,,,,,,,,,,,,,,,,,,4.99986171722412,5.00004625320435,30000.205078125,30000.205078125,53.7209373124768,5.63950515897333,3.08234810829163,53,1,68,0,0,0.2984619140625,34.7018585205078,1,1,3,4.99986171722412,0,4.99995398521423,,,,,,,,,,,,,,,,,,,,,,,,,,,,,,,,,
,3877779459.88618,5.00000977516174,50000.47265625,-3.10850599618206E-4,8.635415347888E-8,1,4,13.4005146026611,5.00753386545308,32.7799990773201,-0.387281452100881,-0.0572897199738236,10,5.06656672724127E-7,,,,,,,,,,,,,,,,,,,,,4.99999856948853,5.00002098083496,50000.47265625,50000.47265625,54.1684196397365,5.64038548682792,3.08398365974426,54,1,0,0,1,0.297698974609375,34.7018585205078,1,1,3,5.00002098083496,0,5.00000977516174,,,,,,,,,,,,,,,,,,,,,,,,,,,,,,,,,
,3877779626.73036,4.99985790252686,70000.328125,-4.39550261509078E-4,1.23921355225606E-7,1,4,13.4005146026611,5.0075822538195,32.7799990773201,-0.547533267508847,-0.0816750366326094,1,1.82626509275439E-7,,,,,,,,,,,,,,,,,,,,,4.9997992515564,4.99991655349731,70000.328125,70000.328125,54.5932347399385,5.64177234281386,3.0777850151062,54,1,0,0,1,0.305709838867188,34.7018585205078,1,1,3,4.99991655349731,0,4.99985790252686,,,,,,,,,,,,,,,,,,,,,,,,,,,,,,,,,