File: SQUID/Reference/STO/A6/STO_MH_200K_FC_1T.csv
Comment,Time Stamp (sec),Temperature (K),Magnetic Field (Oe),Moment (emu),M. Std. Err. (emu),Transport Action,Averaging Time (sec),Frequency (Hz),Peak Amplitude (mm),Center Position (mm),Lockin Signal' (V),Lockin Signal (V),Range,M. Quad. Signal (emu),AC Moment (emu),AC M. Std Err. (emu),AC Phase (deg),AC Phase Std. Err. (deg),AC Susceptibility (emu/Oe),AC Suscept. Std Err. (emu/Oe),AC X' (emu/Oe),AC X' Std Err. (emu/Oe),AC X'' (emu/Oe),AC X'' Std Err. (emu/Oe),AC Drive (Oe),AC Frequency (Hz),AC Averaging Time (sec),AC Cycles,AC Range,AC Measure Type,AC Signal' (V),AC Signal'' (V),AC Trim Coil Ratio,AC Trim Coil Phase,Min. Temperature (K),Max. Temperature (K),Min. Field (Oe),Max. Field (Oe),Mass (grams),Motor Lag (deg),Pressure (Torr),Measure Count,Measurement Number,SQUID Status (code),Motor Status (code),Measure Status (code),Motor Current (amps),Motor Temp. (C),Temp. Status (code),Field Status (code),Chamber Status (code),Chamber Temp (K),Redirection State,Average Temp (K),Rotation Angle (deg),Rotator state,DC Moment Fixed Ctr (emu),DC Moment Err Fixed Ctr (emu),DC Moment Free Ctr (emu),DC Moment Err Free Ctr (emu),DC Fixed Fit,DC Free Fit,DC Calculated Center (mm),DC Calculated Center Err (mm),DC Scan Length (mm),DC Scan Time (s),DC Number of Points,DC Squid Drift,DC Min V (V),DC Max V (V),DC Scans per Measure,Map 01,Map 02,Map 03,Map 04,Map 05,Map 06,Map 07,Map 08,Map 09,Map 10,Map 11,Map 12,Map 13,Map 14,Map 15,Map 16
,3877809346.69161,199.981651306152,69999.6640625,-4.67532795531455E-4,1.78512051631883E-7,1,4,13.4005146026611,4.99742899696163,32.8899994492531,-0.580892125503794,-0.085604022708018,10,1.01890676488039E-6,,,,,,,,,,,,,,,,,,,,,199.9814453125,199.981857299805,69999.6640625,69999.6640625,53.1386240656499,5.63894775721619,5.57303619384766,54,1,0,0,1,0.298309326171875,33.7243423461914,1,1,3,199.981857299805,0,199.981651306152,,,,,,,,,,,,,,,,,,,,,,,,,,,,,,,,,
,3877809525.56101,200.183876037598,49999.703125,-3.3624709822504E-4,7.74684036122778E-8,1,4,13.4005146026611,4.99745135779628,32.8899994492531,-0.417658502930287,-0.0623594191219606,1,9.42786644095493E-8,,,,,,,,,,,,,,,,,,,,,200.169036865234,200.198715209961,49999.703125,49999.703125,53.3066741972845,5.63920742077232,5.58566284179687,54,1,0,0,1,0.298004150390625,34.7018585205078,1,1,3,200.198715209961,0,200.183876037598,,,,,,,,,,,,,,,,,,,,,,,,,,,,,,,,,
,3877809683.24665,200.142601013184,29999.587890625,-2.052657719562E-4,3.69209735059889E-8,1,4,13.4005146026611,4.99736775335454,32.8899994492531,-0.254960226892047,-0.0380541959201695,1,6.79490832930158E-8,,,,,,,,,,,,,,,,,,,,,200.138198852539,200.147003173828,29999.587890625,29999.587890625,53.4020328766306,5.63901365398466,5.58476686477661,54,1,0,0,1,0.297470092773438,34.7018585205078,1,1,3,200.138198852539,0,200.142601013184,,,,,,,,,,,,,,,,,,,,,,,,,,,,,,,,,
,3877809842.68731,200.227897644043,9999.7705078125,-7.4358770041156E-5,1.40527449515468E-8,1,4,13.4005146026611,4.99726548816968,32.8899994492531,-0.092356069992206,-0.0137994827774827,1,1.29284865568158E-8,,,,,,,,,,,,,,,,,,,,,200.224884033203,200.230911254883,9999.7705078125,9999.7705078125,53.597830820698,5.63982438312728,5.58358430862427,54,1,0,0,1,0.297317504882812,35.190616607666,1,1,3,200.224884033203,0,200.227897644043,,,,,,,,,,,,,,,,,,,,,,,,,,,,,,,,,
,3877809940.04134,200.425918579102,8499.841796875,-6.45543728080795E-5,1.18867178387453E-8,1,4,13.4005146026611,4.99728574704399,32.8899994492531,-0.0801904268584182,-0.0119045833258624,1,7.19881350881648E-8,,,,,,,,,,,,,,,,,,,,,200.418106079102,200.433731079102,8499.841796875,8499.841796875,53.4825406141114,5.63939491072792,5.58591508865356,54,1,0,0,1,0.297622680664063,35.190616607666,1,1,3,200.418106079102,0,200.425918579102,,,,,,,,,,,,,,,,,,,,,,,,,,,,,,,,,
,3877810007.84157,200.030502319336,6499.7060546875,-5.13953154955835E-5,1.00056195605962E-8,1,4,13.4005146026611,4.99729099365328,32.8899994492531,-0.0638376201120943,-0.0095214895976256,1,2.22280233893315E-8,,,,,,,,,,,,,,,,,,,,,200.025054931641,200.035949707031,6499.7060546875,6499.7060546875,53.6087736199672,5.63916956608354,5.58225440979004,54,1,0,0,1,0.297393798828125,35.190616607666,1,1,3,200.035949707031,0,200.030502319336,,,,,,,,,,,,,,,,,,,,,,,,,,,,,,,,,
,3877810075.46932,200.093955993652,4499.67138671875,-3.82767599653551E-5,1.06578088835061E-8,1,4,13.4005146026611,4.99733264428399,32.8899994492531,-0.0475433839478998,-0.00709364419740075,1,1.46109423955318E-8,,,,,,,,,,,,,,,,,,,,,200.092864990234,200.09504699707,4499.67138671875,4499.67138671875,53.5493698525057,5.63894283987263,5.57642889022827,54,1,0,0,1,0.298080444335937,35.190616607666,1,1,3,200.092864990234,0,200.093955993652,,,,,,,,,,,,,,,,,,,,,,,,,,,,,,,,,
,3877810163.77862,200.40340423584,2999.59228515625,-2.84336111857993E-5,8.49952299383175E-9,1,4,13.4005146026611,4.99728558984562,32.8899994492531,-0.0353241100565364,-0.00522045562767296,1,5.0254837561028E-8,,,,,,,,,,,,,,,,,,,,,200.402389526367,200.404418945313,2999.59228515625,2999.59228515625,53.5556228806595,5.63893155723005,5.57340002059937,54,1,0,0,1,0.297088623046875,35.190616607666,1,1,3,200.402389526367,0,200.40340423584,,,,,,,,,,,,,,,,,,,,,,,,,,,,,,,,,
,3877810223.21987,200.222778320313,2799.615234375,-2.72124026216351E-5,1.62203252588821E-8,1,4,13.4005146026611,4.99730051915928,32.8899994492531,-0.0338349363867643,-0.00481017839553408,1,1.97919561630859E-7,,,,,,,,,,,,,,,,,,,,,200.215118408203,200.230438232422,2799.615234375,2799.615234375,53.4000788053326,5.63927414974686,5.56641101837158,53,1,68,0,0,0.297164916992188,35.190616607666,1,1,3,200.215118408203,0,200.222778320313,,,,,,,,,,,,,,,,,,,,,,,,,,,,,,,,,
,3877810283.84135,200.382736206055,2599.61328125,-2.58803847056808E-5,1.92471837018935E-8,1,4,13.4005146026611,4.99734209348972,32.8899994492531,-0.0321815888520582,-0.00455832413451424,1,2.01479685718216E-7,,,,,,,,,,,,,,,,,,,,,200.359436035156,200.406036376953,2599.61328125,2599.61328125,53.4614366440922,5.63909420540083,5.56773138046265,54,1,0,0,1,0.298080444335937,35.6793746948242,1,1,3,200.406036376953,0,200.382736206055,,,,,,,,,,,,,,,,,,,,,,,,,,,,,,,,,
,3877810429.20917,200.445655822754,2399.7744140625,-2.02418064760079E-5,9.51264401267064E-9,1,4,13.4005146026611,4.99739858580991,32.8899994492531,-0.0251605854814162,-0.00363193965757241,1,1.03893991613925E-7,,,,,,,,,,,,,,,,,,,,,200.437973022461,200.453338623047,2399.7744140625,2399.7744140625,53.5407719387941,5.63908862180463,5.56318044662476,54,1,0,0,1,0.297164916992188,35.6793746948242,1,1,3,200.436981201172,0,200.445655822754,,,,,,,,,,,,,,,,,,,,,,,,,,,,,,,,,
,3877810562.26658,200.186454772949,2199.79736328125,-1.86651365611113E-5,1.93955403226236E-8,1,4,13.4005146026611,4.99740782076248,32.8899994492531,-0.0232259783936393,-0.00318102753006083,1,2.31079916312251E-7,,,,,,,,,,,,,,,,,,,,,200.167175292969,200.20573425293,2199.79736328125,2199.79736328125,53.5982216349576,5.63949327539824,5.56233930587769,54,1,0,0,1,0.296859741210937,35.190616607666,1,1,3,200.20573425293,0,200.186454772949,,,,,,,,,,,,,,,,,,,,,,,,,,,,,,,,,
,3877810637.31844,200.134124755859,1999.61901855469,-1.71051806615614E-5,1.94088098179158E-8,1,4,13.4005146026611,4.99730215642671,32.8899994492531,-0.0212844349485314,-0.00291361936610233,1,2.12946393138366E-7,,,,,,,,,,,,,,,,,,,,,200.132598876953,200.135650634766,1999.61901855469,1999.61901855469,53.5485882239864,5.63935298472543,5.55964231491089,54,1,0,0,1,0.298080444335937,34.2131004333496,1,1,3,200.132598876953,0,200.134124755859,,,,,,,,,,,,,,,,,,,,,,,,,,,,,,,,,
,3877810707.95696,200.384559631348,1799.62951660156,-1.54569918531085E-5,9.49858179749915E-9,1,4,13.4005146026611,4.99733577208831,32.8899994492531,-0.0192203440673071,-0.00272238473035778,1,1.20379570085862E-7,,,,,,,,,,,,,,,,,,,,,200.381195068359,200.387924194336,1799.62951660156,1799.62951660156,53.554059623621,5.63919475378622,5.55801963806152,54,1,0,0,1,0.296859741210937,35.190616607666,1,1,3,200.381195068359,0,200.384559631348,,,,,,,,,,,,,,,,,,,,,,,,,,,,,,,,,
,3877810807.20048,200.469268798828,1599.5517578125,-1.38451059086463E-5,9.95095283803197E-9,1,4,13.4005146026611,4.99731766675666,32.8899994492531,-0.0172163387106805,-0.0024356838015428,1,1.1007478443402E-7,,,,,,,,,,,,,,,,,,,,,200.453567504883,200.484970092773,1599.5517578125,1599.5517578125,53.5212312258134,5.6392066670114,5.55686330795288,54,1,0,0,1,0.297164916992188,35.190616607666,1,1,3,200.453567504883,0,200.469268798828,,,,,,,,,,,,,,,,,,,,,,,,,,,,,,,,,
,3877810867.41818,200.270347595215,1399.68811035156,-1.22600960431238E-5,2.08926829047175E-8,1,4,13.4005146026611,4.99728631841996,32.8899994492531,-0.0152647093814817,-0.00202674795670896,1,2.02203568532083E-7,,,,,,,,,,,,,,,,,,,,,200.263916015625,200.276779174805,1399.68811035156,1399.68811035156,53.5481974097268,5.6392943470446,5.55079221725464,54,1,0,0,1,0.297012329101562,35.190616607666,1,1,3,200.263916015625,0,200.270347595215,,,,,,,,,,,,,,,,,,,,,,,,,,,,,,,,,
,3877810945.30711,200.227188110352,1199.6103515625,-1.06430960671687E-5,2.5716985501398E-8,1,4,13.4005146026611,4.99729665567861,32.8899994492531,-0.0132638170547164,-0.00167687491680352,10,2.4201368647457E-7,,,,,,,,,,,,,,,,,,,,,200.217559814453,200.23681640625,1199.6103515625,1199.6103515625,53.4481489592653,5.63921500283467,5.55868148803711,54,1,0,0,1,0.2972412109375,34.7018585205078,1,1,3,200.217559814453,0,200.227188110352,,,,,,,,,,,,,,,,,,,,,,,,,,,,,,,,,
,3877811028.04403,200.13143157959,999.809509277344,-8.96672301599982E-6,3.25909802112942E-8,1,4,13.4005146026611,4.99734789252421,32.8899994492531,-0.0111909137272142,-0.00130518997026493,1,2.90514070878205E-7,,,,,,,,,,,,,,,,,,,,,200.118927001953,200.143936157227,999.809509277344,999.809509277344,53.526702625448,5.63948936281073,5.55608892440796,54,1,0,0,1,0.297088623046875,34.7018585205078,1,1,3,200.143936157227,0,200.13143157959,,,,,,,,,,,,,,,,,,,,,,,,,,,,,,,,,
,3877811111.19366,200.08186340332,799.71923828125,-7.31101892103725E-6,2.67516798543931E-8,1,4,13.4005146026611,4.99730968311068,32.8899994492531,-0.00913171106756251,-0.00101540602961499,10,2.7613700847241E-7,,,,,,,,,,,,,,,,,,,,,200.079162597656,200.084564208984,799.71923828125,799.71923828125,53.4641723439095,5.63866908441421,5.5595269203186,54,1,0,0,1,0.297470092773438,35.190616607666,1,1,3,200.079162597656,0,200.08186340332,,,,,,,,,,,,,,,,,,,,,,,,,,,,,,,,,
,3877811185.68274,200.085647583008,600.03173828125,-5.57489149344385E-6,1.30755918125376E-7,1,4,13.4005146026611,4.99729585835908,32.8899994492531,-0.00694629445140124,-8.87300026599314E-4,10,1.19563838425376E-7,,,,,,,,,,,,,,,,,,,,,200.085159301758,200.086135864258,600.03173828125,600.03173828125,53.4954374846787,5.63834343862514,5.55485057830811,54,1,0,0,1,0.296859741210937,34.7018585205078,1,1,3,200.086135864258,0,200.085647583008,,,,,,,,,,,,,,,,,,,,,,,,,,,,,,,,,
,3877811276.26863,200.375175476074,399.928863525391,-3.76727021587473E-6,2.61896246509568E-8,1,4,13.4005146026611,4.9974042185451,32.8899994492531,-0.00473164525211161,-3.4895302203103E-4,10,2.82611008592819E-7,,,,,,,,,,,,,,,,,,,,,200.365844726562,200.384506225586,399.928863525391,399.928863525391,53.5270934397076,5.63913065733664,5.55270099639893,54,1,0,0,1,0.296859741210937,34.7018585205078,1,1,3,200.384506225586,0,200.375175476074,,,,,,,,,,,,,,,,,,,,,,,,,,,,,,,,,
,3877811371.34934,200.254447937012,200.128082275391,-1.89219050368958E-6,2.58321873966436E-8,1,4,13.4005146026611,4.99736400825383,32.8899994492531,-0.00239632798773711,-4.29977708418317E-5,1,2.48441247067549E-7,,,,,,,,,,,,,,,,,,,,,200.241821289062,200.267074584961,200.128082275391,200.128082275391,53.470816186323,5.63852312481952,5.56145000457764,53,1,68,0,0,0.29693603515625,34.7018585205078,1,1,3,200.241821289062,0,200.254447937012,,,,,,,,,,,,,,,,,,,,,,,,,,,,,,,,,
,3877811477.26362,200.37818145752,0.151059061288834,1.16444449803035E-7,2.85977037630593E-8,1,4,13.4005146026611,4.99736042483861,32.8899994492531,8.96647742369627E-5,3.89051632074336E-4,1,2.95818120011137E-7,,,,,,,,,,,,,,,,,,,,,200.376220703125,200.380142211914,0.151059061288834,0.151059061288834,53.4481489592653,5.63888598312887,5.55575752258301,52,1,68,0,0,0.297470092773438,34.7018585205078,1,1,3,200.380142211914,0,200.37818145752,,,,,,,,,,,,,,,,,,,,,,,,,,,,,,,,,
,3877811547.15829,200.267631530762,-199.674896240234,2.09066164167706E-6,2.99760046862584E-8,1,4,13.4005146026611,4.99741130173119,32.8899994492531,0.00255551687466369,6.63818019536004E-4,1,2.21702678262885E-7,,,,,,,,,,,,,,,,,,,,,200.260665893555,200.274597167969,-199.674896240234,-199.674896240234,53.5552320663999,5.63895165141744,5.56112337112427,54,1,0,0,1,0.297317504882812,34.7018585205078,1,1,3,200.260665893555,0,200.267631530762,,,,,,,,,,,,,,,,,,,,,,,,,,,,,,,,,
,3877811606.59413,200.232620239258,-399.727447509766,3.9549722438556E-6,1.32795752898559E-8,1,4,13.4005146026611,4.99736893738369,32.8899994492531,0.00487954452433498,9.53278900450289E-4,1,1.75872981966609E-7,,,,,,,,,,,,,,,,,,,,,200.224700927734,200.240539550781,-399.727447509766,-399.727447509766,53.4512754733422,5.63876166754902,5.55335807800293,52,1,32,0,0,0.298080444335937,35.190616607666,1,1,3,200.240539550781,0,200.232620239258,,,,,,,,,,,,,,,,,,,,,,,,,,,,,,,,,
,3877811681.02291,200.248664855957,-599.628967285156,5.74051501342731E-6,1.92217675086728E-8,1,4,13.4005146026611,4.99739636889477,32.8899994492531,0.00709660069819422,0.00128978126335359,1,1.79686604840447E-7,,,,,,,,,,,,,,,,,,,,,200.224517822266,200.272811889648,-599.628967285156,-599.628967285156,53.4680804865057,5.63888683887882,5.56283378601074,53,1,68,0,0,0.296401977539063,34.7018585205078,1,1,3,200.272811889648,0,200.248664855957,,,,,,,,,,,,,,,,,,,,,,,,,,,,,,,,,
,3877811766.97701,200.323234558105,-799.681457519531,7.48334333850415E-6,2.28847278788892E-8,1,4,13.4005146026611,4.99738001233167,32.8899994492531,0.00925869670165486,0.00163054486070573,1,1.93332776995155E-7,,,,,,,,,,,,,,,,,,,,,200.31852722168,200.327941894531,-799.681457519531,-799.681457519531,53.4485397735249,5.63887926033247,5.55941104888916,54,1,0,0,1,0.297622680664063,35.190616607666,1,1,3,200.327941894531,0,200.323234558105,,,,,,,,,,,,,,,,,,,,,,,,,,,,,,,,,
,3877811824.64916,200.409622192383,-999.645874023437,9.13105686281636E-6,4.24670199982576E-8,1,4,13.4005146026611,4.99742128825372,32.8899994492531,0.0113224946887384,0.00182214014988109,1,1.01086458243931E-7,,,,,,,,,,,,,,,,,,,,,200.409103393555,200.410140991211,-999.645874023437,-999.645874023437,53.4508846590826,5.63860901643507,5.55739212036133,52,1,68,0,0,0.297622680664063,34.7018585205078,1,1,3,200.410140991211,0,200.409622192383,,,,,,,,,,,,,,,,,,,,,,,,,,,,,,,,,
,3877811907.953,200.381126403809,-1199.86206054688,1.08447228780299E-5,1.77397791990168E-8,1,4,13.4005146026611,4.99744122507032,32.8899994492531,0.0134459944370204,0.00217427053700805,10,1.28229021172371E-7,,,,,,,,,,,,,,,,,,,,,200.379119873047,200.38313293457,-1199.86206054688,-1199.86206054688,53.4125848616403,5.63836464761665,5.56798791885376,54,1,0,0,1,0.297470092773438,35.190616607666,1,1,3,200.38313293457,0,200.381126403809,,,,,,,,,,,,,,,,,,,,,,,,,,,,,,,,,
,3877811983.27194,200.299293518066,-1399.72583007812,1.2469393297063E-5,1.18967620919535E-8,1,4,13.4005146026611,4.99743780764677,32.8899994492531,0.0154602340537971,0.00250078815937618,10,1.48073737325266E-7,,,,,,,,,,,,,,,,,,,,,200.280181884766,200.318405151367,-1399.72583007812,-1399.72583007812,53.5638299801114,5.63908061527487,5.56105995178223,54,1,0,0,1,0.297698974609375,34.7018585205078,1,1,3,200.319763183594,0,200.299293518066,,,,,,,,,,,,,,,,,,,,,,,,,,,,,,,,,
,3877812051.52207,200.157821655273,-1599.71545410156,1.41462142823602E-5,3.80989908032896E-8,1,4,13.4005146026611,4.99748687054887,32.8899994492531,0.0175520094311436,0.00275342614872533,1,1.00603417127285E-7,,,,,,,,,,,,,,,,,,,,,200.15348815918,200.162155151367,-1599.71545410156,-1599.71545410156,53.4798049142941,5.63837924674586,5.57042789459229,54,1,0,0,1,0.29632568359375,34.7018585205078,1,1,3,200.15348815918,0,200.157821655273,,,,,,,,,,,,,,,,,,,,,,,,,,,,,,,,,
,3877812111.40584,200.173477172852,-1799.60424804687,1.57519022016642E-5,1.39343228702455E-8,1,4,13.4005146026611,4.99747977532782,32.8899994492531,0.0195420545346338,0.00308055154174909,1,1.23776756515367E-7,,,,,,,,,,,,,,,,,,,,,200.166915893555,200.180038452148,-1799.60424804687,-1799.60424804687,53.4477581450057,5.63861251078101,5.56820917129517,53,1,68,0,0,0.297164916992188,34.7018585205078,1,1,3,200.166915893555,0,200.173477172852,,,,,,,,,,,,,,,,,,,,,,,,,,,,,,,,,
,3877812170.07041,200.201484680176,-1999.68200683594,1.72941042768423E-5,5.85626914017989E-8,1,4,13.4005146026611,4.99749863796464,32.8899994492531,0.0214518394467447,0.00340629392877219,1,1.55314825040932E-7,,,,,,,,,,,,,,,,,,,,,200.198776245117,200.204193115234,-1999.68200683594,-1999.68200683594,53.4852763139287,5.63913363942979,5.56939697265625,54,1,0,0,1,0.303955078125,35.190616607666,1,1,3,200.198776245117,0,200.201484680176,,,,,,,,,,,,,,,,,,,,,,,,,,,,,,,,,
,3877812227.74746,200.161415100098,-2199.54565429687,1.89383775983989E-5,1.107828546328E-8,1,4,13.4005146026611,4.9974862313438,32.8899994492531,0.0235069351716769,0.00362586823367072,1,8.61310221104592E-8,,,,,,,,,,,,,,,,,,,,,200.154998779297,200.167831420898,-2199.54565429687,-2199.54565429687,53.5181047117364,5.63858322899549,5.56734037399292,54,1,0,0,1,0.297927856445313,34.7018585205078,1,1,3,200.154998779297,0,200.161415100098,,,,,,,,,,,,,,,,,,,,,,,,,,,,,,,,,
,3877812300.21589,200.23006439209,-2399.57299804687,2.05389077347164E-5,2.96566899653462E-8,1,4,13.4005146026611,4.9975231938255,32.9000018537045,0.0255029497922834,0.00387137414561387,1,4.43267255710056E-8,,,,,,,,,,,,,,,,,,,,,200.207565307617,200.252563476562,-2399.57299804687,-2399.57299804687,53.4977823702364,5.63892490082945,5.56841850280762,54,1,0,0,1,0.296859741210937,34.7018585205078,1,1,3,200.252563476562,0,200.23006439209,,,,,,,,,,,,,,,,,,,,,,,,,,,,,,,,,
,3877812374.23376,200.257659912109,-2599.68872070313,2.21407915836936E-5,7.8749869214081E-9,1,4,13.4005146026611,4.99748419674707,32.9000018537045,0.027489175280885,0.00419009154082849,1,6.13291454161695E-8,,,,,,,,,,,,,,,,,,,,,200.248779296875,200.266540527344,-2599.68872070313,-2599.68872070313,53.4696437435441,5.63929281834355,5.56704568862915,54,1,0,0,1,0.29693603515625,34.2131004333496,1,1,3,200.266540527344,0,200.257659912109,,,,,,,,,,,,,,,,,,,,,,,,,,,,,,,,,
,3877812434.00123,200.237831115723,-2799.52734375,2.37194144180866E-5,7.81429655617259E-9,1,4,13.4005146026611,4.99749065893744,32.9000018537045,0.0294497946602968,0.0044847909682738,1,6.24337435686576E-8,,,,,,,,,,,,,,,,,,,,,200.229034423828,200.246627807617,-2799.52734375,-2799.52734375,53.381319720871,5.63909735087935,5.57018709182739,54,1,0,0,1,0.296707153320313,34.7018585205078,1,1,3,200.229034423828,0,200.237831115723,,,,,,,,,,,,,,,,,,,,,,,,,,,,,,,,,
,3877812510.93457,200.423812866211,-2999.6552734375,2.53172808780645E-5,1.89282173873629E-8,1,4,13.4005146026611,4.99741127129586,32.9000018537045,0.0314371489208951,0.00475900947884425,1,4.42617207435075E-8,,,,,,,,,,,,,,,,,,,,,200.418563842773,200.429061889648,-2999.6552734375,-2999.6552734375,53.5220128543326,5.63833606344167,5.56856298446655,54,1,0,0,1,0.296859741210937,34.7018585205078,1,1,3,200.429061889648,0,200.423812866211,,,,,,,,,,,,,,,,,,,,,,,,,,,,,,,,,
,3877812663.31739,200.163604736328,-4499.7724609375,3.70456017846065E-5,9.09320180312686E-9,1,4,13.4005146026611,4.99734227031874,32.9000018537045,0.0460254865229364,0.00679066706284202,1,-7.43901587900063E-8,,,,,,,,,,,,,,,,,,,,,200.162612915039,200.164596557617,-4499.7724609375,-4499.7724609375,53.5294383252653,5.63866962142369,5.57622861862183,54,1,0,0,1,0.297088623046875,34.2131004333496,1,1,3,200.162612915039,0,200.163604736328,,,,,,,,,,,,,,,,,,,,,,,,,,,,,,,,,
,3877812731.51077,200.340827941895,-6499.66845703125,5.15128606768693E-5,9.82959015813383E-9,1,4,13.4005146026611,4.99738713381183,32.9000018537045,0.0639985699909826,0.00945511897572344,1,-9.34551870634642E-8,,,,,,,,,,,,,,,,,,,,,200.33772277832,200.343933105469,-6499.66845703125,-6499.66845703125,53.503253769871,5.63864905157431,5.57814311981201,54,1,0,0,1,0.296783447265625,34.7018585205078,1,1,3,200.33772277832,0,200.340827941895,,,,,,,,,,,,,,,,,,,,,,,,,,,,,,,,,
,3877812797.21853,200.076622009277,-8499.703125,6.48837209545257E-5,1.20358614345447E-8,1,4,13.4005146026611,4.99733587719888,32.9000018537045,0.0806092510048808,0.01190819308144,1,-1.18484863641136E-7,,,,,,,,,,,,,,,,,,,,,200.07373046875,200.079513549805,-8499.703125,-8499.703125,53.4344704601787,5.63826105816961,5.57647132873535,52,1,68,0,0,0.296401977539063,34.2131004333496,1,1,3,200.079513549805,0,200.076622009277,,,,,,,,,,,,,,,,,,,,,,,,,,,,,,,,,
,3877812879.77159,200.234100341797,-9999.5185546875,7.47094987870605E-5,1.5602412355177E-8,1,4,13.4005146026611,4.99739550717641,32.9000018537045,0.0928152101116726,0.0137304239443451,1,-1.21400926426204E-7,,,,,,,,,,,,,,,,,,,,,200.232482910156,200.235717773438,-9999.5185546875,-9999.5185546875,53.4747243289191,5.63811905661974,5.57284784317017,54,1,0,0,1,0.297088623046875,34.2131004333496,1,1,3,200.232482910156,0,200.234100341797,,,,,,,,,,,,,,,,,,,,,,,,,,,,,,,,,
,3877813036.36843,200.124374389648,-29999.650390625,2.05684520638266E-4,3.748355094997E-8,1,4,13.4005146026611,4.9974056110361,32.9000018537045,0.255509307405537,0.037956798158418,1,-2.09333223827328E-7,,,,,,,,,,,,,,,,,,,,,200.120971679687,200.127777099609,-29999.650390625,-29999.650390625,53.5024721413518,5.63868032478386,5.57374382019043,54,1,0,0,1,0.296707153320313,34.7018585205078,1,1,3,200.127777099609,0,200.124374389648,,,,,,,,,,,,,,,,,,,,,,,,,,,,,,,,,
,3877813211.79846,200.091606140137,-49999.62890625,3.36954850444116E-4,8.15128907054992E-8,1,4,13.4005146026611,4.99746490454394,32.9000018537045,0.418566646977943,0.0623074573331714,1,-2.42179397900744E-7,,,,,,,,,,,,,,,,,,,,,200.062713623047,200.120498657227,-49999.62890625,-49999.62890625,53.4125848616403,5.63838797299579,5.5832896232605,53,1,68,0,0,0.296859741210937,34.7018585205078,1,1,3,200.120498657227,0,200.091606140137,,,,,,,,,,,,,,,,,,,,,,,,,,,,,,,,,
,3877813388.1054,200.239814758301,-69999.5234375,4.68129685541017E-4,1.33240883789471E-7,1,4,13.4005146026611,4.99739498794011,32.9000018537045,0.581484189907723,0.0866751514426129,1,-2.45150654195112E-7,,,,,,,,,,,,,,,,,,,,,200.213684082031,200.26594543457,-69999.5234375,-69999.5234375,53.1757514203133,5.63833698397422,5.57703065872192,54,1,0,0,1,0.2972412109375,34.7018585205078,1,1,3,200.26594543457,0,200.239814758301,,,,,,,,,,,,,,,,,,,,,,,,,,,,,,,,,
,3877813550.21399,200.301467895508,-49999.65234375,3.36781650221465E-4,7.65911941702563E-8,1,4,13.4005146026611,4.99740739472296,32.9000018537045,0.41833372175429,0.062348192340693,1,-1.8266488381187E-7,,,,,,,,,,,,,,,,,,,,,200.286972045898,200.315963745117,-49999.65234375,-49999.65234375,53.3625606364095,5.63788585907291,5.59069204330444,54,1,0,0,1,0.296630859375,34.7018585205078,1,1,3,200.315963745117,0,200.301467895508,,,,,,,,,,,,,,,,,,,,,,,,,,,,,,,,,
,3877813711.94216,200.232475280762,-29999.61328125,2.05538791136038E-4,3.69453293514802E-8,1,4,13.4005146026611,4.9974602047716,32.9000018537045,0.255318871941998,0.0380194588951813,1,-1.37551708633684E-7,,,,,,,,,,,,,,,,,,,,,200.207763671875,200.257186889648,-29999.61328125,-29999.61328125,53.4786324715153,5.63795346895782,5.59105253219604,54,1,0,0,1,0.297317504882812,34.7018585205078,1,1,3,200.257186889648,0,200.232475280762,,,,,,,,,,,,,,,,,,,,,,,,,,,,,,,,,
,3877813868.53694,200.156867980957,-10000.3115234375,7.4422439416923E-5,1.40384267111184E-8,1,4,13.4005146026611,4.9974554092632,32.9000018537045,0.092441437307116,0.013802880165777,1,-2.03089414716954E-8,,,,,,,,,,,,,,,,,,,,,200.151382446289,200.162353515625,-10000.3115234375,-10000.3115234375,53.5583585804768,5.63806430330995,5.58964395523071,54,1,0,0,1,0.297698974609375,35.190616607666,1,1,3,200.162353515625,0,200.156867980957,,,,,,,,,,,,,,,,,,,,,,,,,,,,,,,,,
,3877813946.29189,200.27466583252,-8500.09375,6.45840492320006E-5,1.27176109342467E-8,1,4,13.4005146026611,4.99746931311879,32.9000018537045,0.0802272311728352,0.0119386528675578,1,-4.94908698882493E-8,,,,,,,,,,,,,,,,,,,,,200.264694213867,200.284637451172,-8500.09375,-8500.09375,53.5009088843133,5.6383434984004,5.58715009689331,54,1,0,0,1,0.297775268554687,34.7018585205078,1,1,3,200.284637451172,0,200.27466583252,,,,,,,,,,,,,,,,,,,,,,,,,,,,,,,,,
,3877814036.98502,200.457962036133,-6499.8701171875,5.14816548212846E-5,1.15289464916467E-8,1,4,13.4005146026611,4.99744798053431,32.9000018537045,0.0639562820392451,0.00948036054967698,1,-6.85944793667398E-8,,,,,,,,,,,,,,,,,,,,,200.451202392578,200.464721679687,-6499.8701171875,-6499.8701171875,53.5005180700537,5.63814756065491,5.59499835968018,54,1,0,0,1,0.296859741210937,34.7018585205078,1,1,3,200.451202392578,0,200.457962036133,,,,,,,,,,,,,,,,,,,,,,,,,,,,,,,,,
,3877814103.68451,200.304336547852,-4500.2001953125,3.83171139265608E-5,9.47534376115327E-9,1,4,13.4005146026611,4.99744399690356,32.9000018537045,0.0475926610298624,0.00711692771974688,1,-2.07997597520218E-9,,,,,,,,,,,,,,,,,,,,,200.285049438477,200.323623657227,-4500.2001953125,-4500.2001953125,53.5794625504961,5.63813009548534,5.58656358718872,53,1,68,0,0,0.296554565429687,35.190616607666,1,1,3,200.323623657227,0,200.304336547852,,,,,,,,,,,,,,,,,,,,,,,,,,,,,,,,,
,3877814183.83889,200.203155517578,-3000.17138671875,2.84604216985381E-5,7.89063710174279E-9,1,4,13.4005146026611,4.99748117033121,32.9000018537045,0.0353597597035516,0.00522296026822481,1,-5.24793382624841E-8,,,,,,,,,,,,,,,,,,,,,200.202117919922,200.204193115234,-3000.17138671875,-3000.17138671875,53.5149781976595,5.63838501213922,5.58760547637939,54,1,0,0,1,0.2972412109375,35.190616607666,1,1,3,200.202117919922,0,200.203155517578,,,,,,,,,,,,,,,,,,,,,,,,,,,,,,,,,
,3877814238.36268,200.273727416992,-2800.3330078125,2.72671596604941E-5,1.7636683499168E-8,1,4,13.4005146026611,4.99749720133754,32.9000018537045,0.0339102335277817,0.00478438648850227,1,-2.27089344808369E-7,,,,,,,,,,,,,,,,,,,,,200.268783569336,200.278671264648,-2800.3330078125,-2800.3330078125,53.5333464678614,5.63852171377384,5.59526920318604,54,1,0,0,1,0.29693603515625,35.190616607666,1,1,3,200.278671264648,0,200.273727416992,,,,,,,,,,,,,,,,,,,,,,,,,,,,,,,,,
,3877814309.11592,200.419563293457,-2600.36840820313,2.58816056496944E-5,1.008800340168E-8,1,4,13.4005146026611,4.99744965048473,32.9000018537045,0.032162869760028,0.00470044111926686,1,-8.73530052514434E-8,,,,,,,,,,,,,,,,,,,,,200.413070678711,200.426055908203,-2600.36840820313,-2600.36840820313,53.5255301826691,5.63806326776454,5.59405088424683,54,1,0,0,1,0.297393798828125,35.190616607666,1,1,3,200.412490844727,0,200.419563293457,,,,,,,,,,,,,,,,,,,,,,,,,,,,,,,,,
,3877814383.29956,200.303230285645,-2400.27807617187,2.03096600789634E-5,1.82910521873014E-8,1,4,13.4005146026611,4.99746733594096,32.9000018537045,0.0252674266801971,0.00349703383695543,1,-2.22714386412264E-7,,,,,,,,,,,,,,,,,,,,,200.286926269531,200.319534301758,-2400.27807617187,-2400.27807617187,53.4375969742557,5.63833646608163,5.59215831756592,54,1,0,0,1,0.29754638671875,34.7018585205078,1,1,3,200.319534301758,0,200.303230285645,,,,,,,,,,,,,,,,,,,,,,,,,,,,,,,,,
,3877814440.86697,200.337394714355,-2200.3134765625,1.87284279992732E-5,1.96702119036609E-8,1,4,13.4005146026611,4.99751279590671,32.9000018537045,0.0233035196181329,0.00320461511923616,1,-2.21632959030229E-7,,,,,,,,,,,,,,,,,,,,,200.326904296875,200.347885131836,-2200.3134765625,-2200.3134765625,53.4766784002172,5.63782871128344,5.59183502197266,52,1,68,0,0,0.29693603515625,35.190616607666,1,1,3,200.347885131836,0,200.337394714355,,,,,,,,,,,,,,,,,,,,,,,,,,,,,,,,,
,3877814571.46017,200.25830078125,-2000.21069335938,1.71234497931908E-5,2.08043157656847E-8,1,4,13.4005146026611,4.9974794856076,32.9000018537045,0.0213120123607254,0.00289156728153259,1,-2.33550108473888E-7,,,,,,,,,,,,,,,,,,,,,200.257919311523,200.258682250977,-2000.21069335938,-2000.21069335938,53.5782901077172,5.63852322621393,5.59408950805664,52,1,68,0,0,0.29632568359375,34.7018585205078,1,1,3,200.258682250977,0,200.25830078125,,,,,,,,,,,,,,,,,,,,,,,,,,,,,,,,,
,3877814659.98445,200.44605255127,-1800.13305664062,1.5481183827377E-5,1.07617378654967E-8,1,4,13.4005146026611,4.99747749303967,32.9000018537045,0.0192523515372917,0.00271899237781237,1,-1.26816765542714E-7,,,,,,,,,,,,,,,,,,,,,200.436584472656,200.455520629883,-1800.13305664062,-1800.13305664062,53.5227944828518,5.63790231430251,5.5955548286438,54,1,0,0,1,0.296859741210937,34.7018585205078,1,1,3,200.436584472656,0,200.44605255127,,,,,,,,,,,,,,,,,,,,,,,,,,,,,,,,,
,3877814742.16848,200.379447937012,-1600.08044433594,1.38885274507332E-5,2.36487458205511E-8,1,4,13.4005146026611,4.99747189551663,32.9000018537045,0.0172915646896131,0.00230648948809083,1,-2.20670200059347E-7,,,,,,,,,,,,,,,,,,,,,200.361175537109,200.397720336914,-1600.08044433594,-1600.08044433594,53.491138527823,5.63786435835518,5.59195947647095,53,1,68,0,0,0.296401977539063,34.7018585205078,6,1,3,200.397720336914,0,200.379447937012,,,,,,,,,,,,,,,,,,,,,,,,,,,,,,,,,
,3877814830.4329,200.371147155762,-1400.01538085938,1.22903241155096E-5,2.12065610096735E-8,1,4,13.4005146026611,4.99747336174767,32.9000018537045,0.0153161856199869,0.00194469426500819,10,-2.72872885165785E-7,,,,,,,,,,,,,,,,,,,,,200.365081787109,200.377212524414,-1400.01538085938,-1400.01538085938,53.5599218375153,5.63820157849175,5.59223890304565,54,1,0,0,1,0.29693603515625,34.7018585205078,1,1,3,200.377212524414,0,200.371147155762,,,,,,,,,,,,,,,,,,,,,,,,,,,,,,,,,
,3877814897.6766,200.306800842285,-1200.05090332031,1.0592605872583E-5,6.71170976504594E-8,1,4,13.4005146026611,4.99749155181201,32.9000018537045,0.0131914419560907,0.00173701644807121,1,-1.86114356176233E-7,,,,,,,,,,,,,,,,,,,,,200.302154541016,200.311447143555,-1200.05090332031,-1200.05090332031,53.5270934397076,5.6382551517041,5.59216690063477,54,1,0,0,1,0.297470092773438,34.7018585205078,1,1,3,200.302154541016,0,200.306800842285,,,,,,,,,,,,,,,,,,,,,,,,,,,,,,,,,
,3877814953.97082,200.178985595703,-1000.13684082031,8.9942651224153E-6,6.33692925789558E-8,1,4,13.4005146026611,4.99750046622901,32.9000018537045,0.0112032016383227,0.00146010229625967,1,-1.69959310261161E-7,,,,,,,,,,,,,,,,,,,,,200.171417236328,200.186553955078,-1000.13684082031,-1000.13684082031,53.5075527267268,5.63801055964781,5.58985805511475,52,1,68,0,0,0.296783447265625,34.7018585205078,1,1,3,200.186553955078,0,200.178985595703,,,,,,,,,,,,,,,,,,,,,,,,,,,,,,,,,
,3877815027.51832,200.456359863281,-800.159851074219,7.25448619688838E-6,1.02517295290226E-8,1,4,13.4005146026611,4.99746408176363,32.9000018537045,0.00902913342590068,0.00122390572758208,1,-9.98507492960778E-8,,,,,,,,,,,,,,,,,,,,,200.44758605957,200.465133666992,-800.159851074219,-800.159851074219,53.4665172294672,5.63829242467154,5.58740949630737,54,1,0,0,1,0.303802490234375,34.7018585205078,1,1,3,200.44758605957,0,200.456359863281,,,,,,,,,,,,,,,,,,,,,,,,,,,,,,,,,
,3877815126.00696,200.467636108398,-600.107238769531,5.51161023407014E-6,1.05199497521235E-8,1,4,13.4005146026611,4.99749091014785,32.9000018537045,0.00686285341358546,9.10486776587537E-4,1,-9.14687037133761E-8,,,,,,,,,,,,,,,,,,,,,200.455383300781,200.479888916016,-600.107238769531,-600.107238769531,53.5810258075345,5.63756850770785,5.58997440338135,52,1,68,0,0,0.29632568359375,35.190616607666,1,1,3,200.455383300781,0,200.467636108398,,,,,,,,,,,,,,,,,,,,,,,,,,,,,,,,,
,3877815213.98572,200.451240539551,-400.155456542969,3.71404639064721E-6,1.16428311237251E-8,1,4,13.4005146026611,4.99749019726382,32.9000018537045,0.00463109399166154,5.70077739508417E-4,1,-9.6627948221495E-8,,,,,,,,,,,,,,,,,,,,,200.446441650391,200.456039428711,-400.155456542969,-400.155456542969,53.496219113198,5.63781961061557,5.58878231048584,54,1,0,0,1,0.296783447265625,34.7018585205078,1,1,3,200.446441650391,0,200.451240539551,,,,,,,,,,,,,,,,,,,,,,,,,,,,,,,,,
,3877815279.38103,200.242660522461,-200.065139770508,1.92087119811902E-6,2.53873290845332E-8,1,4,13.4005146026611,4.99740965408601,32.9000018537045,0.00242663049558817,8.40976601740886E-5,10,-2.19641810342817E-7,,,,,,,,,,,,,,,,,,,,,200.231231689453,200.254089355469,-200.065139770508,-200.065139770508,53.4430683738903,5.6384264776701,5.5841064453125,54,1,0,0,1,0.297088623046875,35.190616607666,1,1,3,200.231231689453,0,200.242660522461,,,,,,,,,,,,,,,,,,,,,,,,,,,,,,,,,
,3877815428.9214,200.158309936523,-0.0251765102148056,-9.24503804951715E-8,1.51342268989592E-8,1,4,13.4005146026611,4.99738250121036,32.9000018537045,-6.91550064765194E-5,-3.22485632521014E-4,1,-2.45811535662325E-7,,,,,,,,,,,,,,,,,,,,,200.145233154297,200.17138671875,-0.0251765102148056,-0.0251765102148056,53.435252088698,5.63822236183134,5.5874400138855,52,1,68,0,0,0.304489135742188,34.7018585205078,1,1,3,200.17138671875,0,200.158309936523,,,,,,,,,,,,,,,,,,,,,,,,,,,,,,,,,
,3877815486.51725,200.339782714844,199.851135253906,-2.10667075186965E-6,1.93092593157129E-8,1,4,13.4005146026611,4.99737320621948,32.9000018537045,-0.00257733699218619,-6.53660168118126E-4,1,-2.11135147370618E-7,,,,,,,,,,,,,,,,,,,,,200.316604614258,200.36296081543,199.851135253906,199.851135253906,53.5677381227076,5.63842275539025,5.58762264251709,54,1,0,0,1,0.297012329101562,34.7018585205078,1,1,3,200.36296081543,0,200.339782714844,,,,,,,,,,,,,,,,,,,,,,,,,,,,,,,,,
,3877815556.62732,200.248031616211,399.538604736328,-3.95677301183313E-6,1.95678696722361E-8,1,4,13.4005146026611,4.99743752492538,32.9000018537045,-0.00487903568605775,-9.72611642294446E-4,1,-1.91153901801774E-7,,,,,,,,,,,,,,,,,,,,,200.235198974609,200.260864257813,399.538604736328,399.538604736328,53.3617790078903,5.63854703230202,5.5834903717041,54,1,0,0,1,0.297470092773438,34.7018585205078,1,1,3,200.235198974609,0,200.248031616211,,,,,,,,,,,,,,,,,,,,,,,,,,,,,,,,,
,3877815614.11429,200.238838195801,599.69189453125,-5.7267910737209E-6,1.50271916588167E-8,1,4,13.4005146026611,4.99738167259827,32.9000018537045,-0.00707782481061976,-0.00129859658544882,1,-1.88841343319846E-7,,,,,,,,,,,,,,,,,,,,,200.236663818359,200.241012573242,599.69189453125,599.69189453125,53.4841038711499,5.63812613183353,5.58733463287354,54,1,0,0,1,0.29632568359375,34.7018585205078,1,1,3,200.241012573242,0,200.238838195801,,,,,,,,,,,,,,,,,,,,,,,,,,,,,,,,,
,3877815689.12806,200.386833190918,799.580749511719,-7.46784769988058E-6,2.87268611687134E-8,1,4,13.4005146026611,4.99737520505531,32.9000018537045,-0.0092273429194467,-0.00170851662626964,1,-2.58429815425506E-7,,,,,,,,,,,,,,,,,,,,,200.383331298828,200.390335083008,799.580749511719,799.580749511719,53.4719886291018,5.63809843058619,5.58495378494263,53,1,68,0,0,0.296630859375,35.190616607666,1,1,3,200.383331298828,0,200.386833190918,,,,,,,,,,,,,,,,,,,,,,,,,,,,,,,,,
,3877815778.70251,200.471771240234,999.734008789063,-9.18320322284083E-6,2.22136499348124E-8,1,4,13.4005146026611,4.99739177913288,32.9000018537045,-0.011394866665027,-0.00178035827808197,1,-5.96582316878455E-8,,,,,,,,,,,,,,,,,,,,,200.459533691406,200.484008789062,999.734008789063,999.734008789063,53.521622040073,5.63790868335477,5.58782005310059,54,1,0,0,1,0.297393798828125,34.7018585205078,1,1,3,200.459533691406,0,200.471771240234,,,,,,,,,,,,,,,,,,,,,,,,,,,,,,,,,
,3877815846.72682,200.368141174316,1199.57263183594,-1.08033018118751E-5,6.24462143928542E-8,1,4,13.4005146026611,4.99743307477543,32.9000018537045,-0.0133999166343058,-0.00213046946468765,10,-9.91644754955572E-8,,,,,,,,,,,,,,,,,,,,,200.351058959961,200.385223388672,1199.57263183594,1199.57263183594,53.4649539724287,5.63791893967352,5.59131097793579,54,1,0,0,1,0.29693603515625,34.7018585205078,1,1,3,200.385223388672,0,200.368141174316,,,,,,,,,,,,,,,,,,,,,,,,,,,,,,,,,
,3877815946.31166,200.42098236084,1399.56225585938,-1.24650883366236E-5,1.2538394799818E-8,1,4,13.4005146026611,4.99737302134441,32.9000018537045,-0.0154555725308401,-0.00249348532322511,1,-1.42874559726436E-7,,,,,,,,,,,,,,,,,,,,,200.419097900391,200.422866821289,1399.56225585938,1399.56225585938,53.4989548130153,5.63773351786608,5.58591079711914,54,1,0,0,1,0.296707153320313,34.7018585205078,1,1,3,200.422866821289,0,200.42098236084,,,,,,,,,,,,,,,,,,,,,,,,,,,,,,,,,
,3877816029.26427,200.37873840332,1599.76574707031,-1.41266793105369E-5,2.10261041964851E-8,1,4,13.4005146026611,4.99745549922776,32.9000018537045,-0.0175262800300716,-0.00275853860274751,1,-1.0766129679194E-7,,,,,,,,,,,,,,,,,,,,,200.367919921875,200.389556884766,1599.76574707031,1599.76574707031,53.4434591881499,5.63829733232455,5.5874228477478,54,1,0,0,1,0.297470092773438,34.7018585205078,1,1,3,200.367919921875,0,200.37873840332,,,,,,,,,,,,,,,,,,,,,,,,,,,,,,,,,
,3877816089.50131,200.286476135254,1799.62951660156,-1.58869181019927E-5,7.56409785772682E-8,1,4,13.4005146026611,4.99741574259089,32.9000018537045,-0.0197174444676012,-0.00305181341784602,1,-8.04861088799094E-8,,,,,,,,,,,,,,,,,,,,,200.270370483398,200.302581787109,1799.62951660156,1799.62951660156,53.4157113757172,5.63796499434366,5.58701419830322,54,1,0,0,1,0.296859741210937,34.7018585205078,1,1,3,200.302581787109,0,200.286476135254,,,,,,,,,,,,,,,,,,,,,,,,,,,,,,,,,
,3877816158.99645,200.444473266602,1999.89599609375,-1.73778993734998E-5,7.72904872842076E-9,1,4,13.4005146026611,4.99749001053678,32.9000018537045,-0.0215776473590221,-0.00327626375995743,1,-3.80987162581571E-8,,,,,,,,,,,,,,,,,,,,,200.435958862305,200.452987670898,1999.89599609375,1999.89599609375,53.4602642013134,5.63841002681288,5.59075975418091,54,1,0,0,1,0.296096801757812,34.2131004333496,1,1,3,200.435958862305,0,200.444473266602,,,,,,,,,,,,,,,,,,,,,,,,,,,,,,,,,
,3877816217.13915,200.224594116211,2199.81005859375,-1.89579371882973E-5,8.91334714022952E-9,1,4,13.4005146026611,4.99746277044618,32.9000018537045,-0.0235330017506422,-0.00361659909094118,1,-7.57615556362102E-8,,,,,,,,,,,,,,,,,,,,,200.224411010742,200.22477722168,2199.81005859375,2199.81005859375,53.4594825727941,5.63802884746078,5.58720111846924,54,1,0,0,1,0.296783447265625,34.7018585205078,1,1,3,200.224411010742,0,200.224594116211,,,,,,,,,,,,,,,,,,,,,,,,,,,,,,,,,
,3877816274.7628,200.3466796875,2399.76196289062,-2.05869360699633E-5,1.38971423959314E-8,1,4,13.4005146026611,4.99742472310509,32.9000018537045,-0.0255587735891635,-0.00390109155686441,1,-6.11539426773662E-8,,,,,,,,,,,,,,,,,,,,,200.324951171875,200.368408203125,2399.76196289062,2399.76196289062,53.486057942448,5.63806195401009,5.58111619949341,54,1,0,0,1,0.2972412109375,34.7018585205078,1,1,3,200.368408203125,0,200.3466796875,,,,,,,,,,,,,,,,,,,,,,,,,,,,,,,,,
,3877816332.43392,200.312889099121,2599.66357421875,-2.21686872734218E-5,7.8678796257623E-9,1,4,13.4005146026611,4.9974121126057,32.9000018537045,-0.0275228560929102,-0.00419794382866133,1,-6.35462773864331E-8,,,,,,,,,,,,,,,,,,,,,200.311752319336,200.314025878906,2599.66357421875,2599.66357421875,53.5098976122845,5.63815554046234,5.58193635940552,54,1,0,0,1,0.2972412109375,34.7018585205078,1,1,3,200.311752319336,0,200.312889099121,,,,,,,,,,,,,,,,,,,,,,,,,,,,,,,,,
,3877816401.89789,200.423782348633,2799.79150390625,-2.37583893677366E-5,6.92488863287183E-9,1,4,13.4005146026611,4.99744811977725,32.9000018537045,-0.0295066814631602,-0.0044329636928743,1,-1.49196463444443E-8,,,,,,,,,,,,,,,,,,,,,200.416198730469,200.431365966797,2799.79150390625,2799.79150390625,53.518495525996,5.63855323683719,5.584641456604,54,1,0,0,1,0.297927856445313,34.7018585205078,1,1,3,200.416198730469,0,200.423782348633,,,,,,,,,,,,,,,,,,,,,,,,,,,,,,,,,
,3877816549.56083,200.170616149902,2999.63012695313,-2.53352697319883E-5,7.51052698358295E-9,1,4,13.4005146026611,4.99744580366244,32.9000018537045,-0.0314728569695528,-0.00467509085206561,1,2.60302334065403E-8,,,,,,,,,,,,,,,,,,,,,200.164245605469,200.176986694336,2999.63012695313,2999.63012695313,53.427044989246,5.63828427249772,5.58385419845581,54,1,0,0,1,0.297622680664063,34.7018585205078,1,1,3,200.164245605469,0,200.170616149902,,,,,,,,,,,,,,,,,,,,,,,,,,,,,,,,,
,3877816644.22692,200.334503173828,4499.62109375,-3.70529315975786E-5,1.82571884142701E-8,1,4,13.4005146026611,4.99743972757389,32.9000018537045,-0.0460361527680344,-0.00679017238403452,1,7.60342055842093E-8,,,,,,,,,,,,,,,,,,,,,200.31315612793,200.355850219727,4499.62109375,4499.62109375,53.5227944828518,5.63858024698056,5.58061981201172,54,1,0,0,1,0.297088623046875,34.2131004333496,1,1,3,200.355850219727,0,200.334503173828,,,,,,,,,,,,,,,,,,,,,,,,,,,,,,,,,
,3877816709.88595,200.233825683594,6499.55517578125,-5.15183702216216E-5,1.26989894267907E-8,1,4,13.4005146026611,4.99746775815172,32.9000018537045,-0.0640089560638739,-0.00944233676224203,1,1.04742374560583E-7,,,,,,,,,,,,,,,,,,,,,200.227447509766,200.240203857422,6499.55517578125,6499.55517578125,53.5313923965634,5.63821856467086,5.58228492736816,54,1,0,0,1,0.2972412109375,34.7018585205078,1,1,3,200.227447509766,0,200.233825683594,,,,,,,,,,,,,,,,,,,,,,,,,,,,,,,,,
,3877816774.82795,200.331069946289,8499.5146484375,-6.48676171408784E-5,1.36723362373397E-8,1,4,13.4005146026611,4.99746132409363,32.9000018537045,-0.0805959051121429,-0.0118800631890616,1,1.39060397075423E-7,,,,,,,,,,,,,,,,,,,,,200.330978393555,200.331161499023,8499.5146484375,8499.5146484375,53.5403811245345,5.63786087263005,5.58259344100952,54,1,0,0,1,0.296096801757812,34.7018585205078,1,1,3,200.330978393555,0,200.331069946289,,,,,,,,,,,,,,,,,,,,,,,,,,,,,,,,,
,3877816876.73387,200.289207458496,9999.87109375,-7.47086707510849E-5,1.50378342631988E-8,1,4,13.4005146026611,4.99742094846648,32.9000018537045,-0.0928126877943001,-0.0137447763681936,1,1.09800467086717E-7,,,,,,,,,,,,,,,,,,,,,200.287475585938,200.290939331055,9999.87109375,9999.87109375,53.5544504378807,5.63779051900382,5.57530546188354,54,1,0,0,1,0.296707153320313,34.7018585205078,1,1,3,200.287475585938,0,200.289207458496,,,,,,,,,,,,,,,,,,,,,,,,,,,,,,,,,
,3877817031.60146,200.184097290039,30000.1796875,-2.06059199683137E-4,2.85568404965378E-7,1,4,13.4005146026611,4.99742922832205,32.9000018537045,-0.255983996045424,-0.037975695434494,1,2.50370616063691E-7,,,,,,,,,,,,,,,,,,,,,200.156127929687,200.212066650391,30000.1796875,30000.1796875,53.5247485541499,5.63802870040771,5.57792139053345,54,1,0,0,1,0.296783447265625,34.2131004333496,1,1,3,200.212066650391,0,200.184097290039,,,,,,,,,,,,,,,,,,,,,,,,,,,,,,,,,
,3877817187.64278,200.185134887695,50000.4609375,-3.36931974750682E-4,9.9760169137753E-8,1,4,13.4005146026611,4.99748798029778,32.9000018537045,-0.418547046284946,-0.0622627873778797,1,2.750455106753E-7,,,,,,,,,,,,,,,,,,,,,200.178894042969,200.191375732422,50000.4609375,50000.4609375,53.3234792104479,5.6385081173589,5.5767650604248,52,1,68,0,0,0.29632568359375,34.7018585205078,1,1,3,200.178894042969,0,200.185134887695,,,,,,,,,,,,,,,,,,,,,,,,,,,,,,,,,
,3877817361.80572,200.02099609375,70000.3828125,-4.68174714011964E-4,2.65299613090336E-7,1,4,13.4005146026611,4.99749133884204,32.9000018537045,-0.581603603774158,-0.0863664032068138,1,5.02343956827819E-7,,,,,,,,,,,,,,,,,,,,,199.989410400391,200.052581787109,70000.3828125,70000.3828125,53.1925564334768,5.63895375074851,5.57870244979858,53,1,64,0,0,0.297012329101562,34.2131004333496,1,1,3,200.052581787109,0,200.02099609375,,,,,,,,,,,,,,,,,,,,,,,,,,,,,,,,,