File: SQUID/22163_LCOT/LCOT_MH_350K_FC+1T.dat
[Header]
; MPMS3 Data File (default extension .dat)
; Copyright (c) 2007, Quantum Design, Inc. All rights reserved.
TITLE,
FILEOPENTIME,3878525781.9448,11/25/2022,8:17 am
BYAPP,SQUID AC,0.9.1.0
INFO,MPMS3 Measurement Release 1.1.16 Build 347, MultiVu Release 2.3.3.2,APPNAME
INFO,0,MOMENT_UNITS
INFO,LCOT,SAMPLE_MATERIAL
INFO,,SAMPLE_COMMENT
INFO,1.8,SAMPLE_MASS
INFO,,SAMPLE_VOLUME
INFO,,SAMPLE_MOLECULAR_WEIGHT
INFO,,SAMPLE_SIZE
INFO,,SAMPLE_SHAPE
INFO,Quartz,SAMPLE_HOLDER
INFO,Standard,SAMPLE_HOLDER_DETAIL
INFO,65.79,SAMPLE_OFFSET
DATATYPE,COMMENT,1
DATATYPE,TIME,2
STARTUPAXIS,X,2
STARTUPAXIS,Y1,5
FIELDGROUP, VSM,2,3,4,5,6,8,9,10,11,14,15
FIELDGROUP, DC, 2,3,4,14,56,57,58,59,60,61,62,63,64,65,66,67,68,69
FIELDGROUP, AC, 2,3,4,11,16,17,18,19,20,21,22,23,24,25,26,27,28,29,30
STARTUPGROUP, All
[Data]
Comment,Time Stamp (sec),Temperature (K),Magnetic Field (Oe),Moment (emu),M. Std. Err. (emu),Transport Action,Averaging Time (sec),Frequency (Hz),Peak Amplitude (mm),Center Position (mm),Lockin Signal' (V),Lockin Signal (V),Range,M. Quad. Signal (emu),AC Moment (emu),AC M. Std Err. (emu),AC Phase (deg),AC Phase Std. Err. (deg),AC Susceptibility (emu/Oe),AC Suscept. Std Err. (emu/Oe),AC X' (emu/Oe),AC X' Std Err. (emu/Oe),AC X'' (emu/Oe),AC X'' Std Err. (emu/Oe),AC Drive (Oe),AC Frequency (Hz),AC Averaging Time (sec),AC Cycles,AC Range,AC Measure Type,AC Signal' (V),AC Signal'' (V),AC Trim Coil Ratio,AC Trim Coil Phase,Min. Temperature (K),Max. Temperature (K),Min. Field (Oe),Max. Field (Oe),Mass (grams),Motor Lag (deg),Pressure (Torr),Measure Count,Measurement Number,SQUID Status (code),Motor Status (code),Measure Status (code),Motor Current (amps),Motor Temp. (C),Temp. Status (code),Field Status (code),Chamber Status (code),Chamber Temp (K),Redirection State,Average Temp (K),Rotation Angle (deg),Rotator state,DC Moment Fixed Ctr (emu),DC Moment Err Fixed Ctr (emu),DC Moment Free Ctr (emu),DC Moment Err Free Ctr (emu),DC Fixed Fit,DC Free Fit,DC Calculated Center (mm),DC Calculated Center Err (mm),DC Scan Length (mm),DC Scan Time (s),DC Number of Points,DC Squid Drift,DC Min V (V),DC Max V (V),DC Scans per Measure,Sample Resistance,He3 Temperature,Sorb Resistance,Sorb Temperature,Map 05,Map 06,Map 07,Map 08,Map 09,Map 10,Map 11,Map 12,Map 13,Map 14,Map 15,Map 16
,3878525824.52276,350.03125,69999.75,-0.000453834952987279,8.96763021504136E-8,1,4,13.4005146026611,4.99644915841486,33.2400016486645,-0.563604384657253,-0.0838344695466988,1,3.75954159330365E-7,,,,,,,,,,,,,,,,,,,,,350.031066894531,350.031433105469,69999.75,69999.75,53.5224036685922,5.64039853386775,6.2460241317749,54,1,0,0,1,0.298538208007812,32.7468223571777,1,1,3,350.031066894531,0,350.03125,,,,,,,,,,,,,,,,,,,,,,,,,,,,,,,,,
,3878525995.00932,349.859924316406,49999.58984375,-0.000323103714353604,6.80223288009046E-8,1,4,13.4005146026611,4.99643668420737,33.2400016486645,-0.401220943778992,-0.0598903959689309,1,1.02234211546126E-7,,,,,,,,,,,,,,,,,,,,,349.847534179687,349.872314453125,49999.58984375,49999.58984375,53.7006149709768,5.63928385509419,6.25266742706299,54,1,0,0,1,0.2984619140625,33.7243423461914,1,1,3,349.873291015625,0,349.859924316406,,,,,,,,,,,,,,,,,,,,,,,,,,,,,,,,,
,3878526153.2644,350.111877441406,29999.525390625,-0.000192677448310784,3.26041591643926E-8,1,4,13.4005146026611,4.99656806639968,33.2400016486645,-0.239270721448077,-0.0357121207618324,1,6.40430424596624E-8,,,,,,,,,,,,,,,,,,,,,350.098419189453,350.125335693359,29999.525390625,29999.525390625,53.7819043369768,5.63968419870869,6.26646852493286,54,1,0,0,1,0.298309326171875,34.7018585205078,1,1,3,350.125335693359,0,350.111877441406,,,,,,,,,,,,,,,,,,,,,,,,,,,,,,,,,
,3878526312.31448,350.033538818359,9999.64453125,-6.24200650230407E-5,1.38529493148927E-8,1,4,13.4005146026611,4.99654158427365,33.2400016486645,-0.077511240418775,-0.0115871364066489,1,6.35492417355715E-9,,,,,,,,,,,,,,,,,,,,,350.033416748047,350.033660888672,9999.64453125,9999.64453125,53.9538626112076,5.63927977537883,6.26876497268677,54,1,0,0,1,0.297317504882812,34.2131004333496,1,1,3,350.033416748047,0,350.033538818359,,,,,,,,,,,,,,,,,,,,,,,,,,,,,,,,,
,3878526394.26342,349.785842895508,8499.5146484375,-5.26426170422769E-5,1.43150268430336E-8,1,4,13.4005146026611,4.996555096039,33.2400016486645,-0.0653695387207407,-0.00977636167973884,1,1.98397520307524E-9,,,,,,,,,,,,,,,,,,,,,349.783477783203,349.788208007812,8499.5146484375,8499.5146484375,53.8932864009672,5.6396247100654,6.27536344528198,54,1,0,0,1,0.29876708984375,34.7018585205078,1,1,3,349.783477783203,0,349.785842895508,,,,,,,,,,,,,,,,,,,,,,,,,,,,,,,,,
,3878526462.1666,349.803573608398,6499.55517578125,-3.96510969096138E-5,9.51024475333647E-9,1,4,13.4005146026611,4.99656659888141,33.2400016486645,-0.0492351722886076,-0.00737817510849484,1,-1.01583889446294E-8,,,,,,,,,,,,,,,,,,,,,349.789764404297,349.8173828125,6499.55517578125,6499.55517578125,53.9050108287557,5.6396807093889,6.28023958206177,53,1,68,0,0,0.298309326171875,34.7018585205078,1,1,3,349.8173828125,0,349.803573608398,,,,,,,,,,,,,,,,,,,,,,,,,,,,,,,,,
,3878526529.91782,349.955276489258,4499.62109375,-2.66837484340494E-5,8.37579390657029E-9,1,4,13.4005146026611,4.99657461008936,33.2400016486645,-0.0331344252324267,-0.0049594547699903,1,-2.16518660964087E-9,,,,,,,,,,,,,,,,,,,,,349.935760498047,349.974792480469,4499.62109375,4499.62109375,53.8694467311307,5.63977637652626,6.28202342987061,54,1,0,0,1,0.297698974609375,34.2131004333496,1,1,3,349.974792480469,0,349.955276489258,,,,,,,,,,,,,,,,,,,,,,,,,,,,,,,,,
,3878526613.17415,349.954071044922,2999.47900390625,-1.70511153301743E-5,7.89208030396397E-9,1,4,13.4005146026611,4.99665346113731,33.2400016486645,-0.0211776780497008,-0.00314203190303784,1,2.04936832401585E-8,,,,,,,,,,,,,,,,,,,,,349.953765869141,349.954376220703,2999.47900390625,2999.47900390625,53.8502968324095,5.63958509804308,6.28758525848389,54,1,0,0,1,0.298538208007812,34.2131004333496,1,1,3,349.954376220703,0,349.954071044922,,,,,,,,,,,,,,,,,,,,,,,,,,,,,,,,,
,3878526671.05731,349.916259765625,2799.77905273438,-1.586015998435E-5,1.5882809806295E-8,1,4,13.4005146026611,4.99663809178172,33.2400016486645,-0.0197341537186317,-0.00268364333382504,1,2.11460709080774E-7,,,,,,,,,,,,,,,,,,,,,349.901275634766,349.931243896484,2799.77905273438,2799.77905273438,53.8362275190634,5.63952523599451,6.28689098358154,52,1,68,0,0,0.29876708984375,34.7018585205078,1,1,3,349.931243896484,0,349.916259765625,,,,,,,,,,,,,,,,,,,,,,,,,,,,,,,,,
,3878526732.42002,349.891830444336,2599.6005859375,-1.45814492214058E-5,1.7929738758255E-8,1,4,13.4005146026611,4.99663791816276,33.2400016486645,-0.0181455137449116,-0.00245117439945136,1,2.0737916772956E-7,,,,,,,,,,,,,,,,,,,,,349.88916015625,349.894500732422,2599.6005859375,2599.6005859375,53.9237699132172,5.64050653111701,6.29162549972534,54,1,0,0,1,0.298995971679687,34.2131004333496,1,1,3,349.88916015625,0,349.891830444336,,,,,,,,,,,,,,,,,,,,,,,,,,,,,,,,,
,3878526790.76877,350.087280273438,2399.63598632813,-1.332113469993E-5,1.46844900731311E-8,1,4,13.4005146026611,4.99669977691755,33.2400016486645,-0.0165779042724983,-0.00223621286501063,1,1.91982310016312E-7,,,,,,,,,,,,,,,,,,,,,350.075256347656,350.099304199219,2399.63598632813,2399.63598632813,53.8581131176019,5.64006697987122,6.29242563247681,53,1,68,0,0,0.297470092773438,34.7018585205078,1,1,3,350.099304199219,0,350.087280273438,,,,,,,,,,,,,,,,,,,,,,,,,,,,,,,,,
,3878526857.10008,350.004028320313,2199.57080078125,-1.2063372035941E-5,1.89904756295501E-8,1,4,13.4005146026611,4.99665570127086,33.2400016486645,-0.0150195994866439,-0.00197729934991377,10,2.12306958923926E-7,,,,,,,,,,,,,,,,,,,,,349.997741699219,350.010314941406,2199.57080078125,2199.57080078125,53.9210342133999,5.64067972607247,6.29581689834595,54,1,0,0,1,0.29754638671875,34.2131004333496,1,1,3,349.997741699219,0,350.004028320313,,,,,,,,,,,,,,,,,,,,,,,,,,,,,,,,,
,3878526923.53483,349.961364746094,1999.70715332031,-1.07861481225891E-5,1.96691485079125E-8,1,4,13.4005146026611,4.99661749293863,33.2400016486645,-0.0134347162003388,-0.00173130878965242,1,2.19320913701175E-7,,,,,,,,,,,,,,,,,,,,,349.958923339844,349.963806152344,1999.70715332031,1999.70715332031,53.9468279545346,5.64058289073813,6.29883766174316,54,1,0,0,1,0.2984619140625,34.2131004333496,1,1,3,349.963806152344,0,349.961364746094,,,,,,,,,,,,,,,,,,,,,,,,,,,,,,,,,
,3878526981.2973,349.92741394043,1799.71765136719,-9.53961028609599E-6,1.74327509173124E-8,1,4,13.4005146026611,4.99668549451661,33.2400016486645,-0.0118843546108698,-0.00151761260554389,1,2.04959041956775E-7,,,,,,,,,,,,,,,,,,,,,349.921630859375,349.933197021484,1799.71765136719,1799.71765136719,53.7670533951115,5.6397438760275,6.29697704315186,54,1,0,0,1,0.297927856445313,34.7018585205078,1,1,3,349.933197021484,0,349.92741394043,,,,,,,,,,,,,,,,,,,,,,,,,,,,,,,,,
,3878527041.42681,349.976211547852,1599.56433105469,-8.30709390018151E-6,2.16634390203816E-8,1,4,13.4005146026611,4.99663054250839,33.2400016486645,-0.0103576525681543,-0.00126192644150986,1,2.26466299458732E-7,,,,,,,,,,,,,,,,,,,,,349.966979980469,349.985443115234,1599.56433105469,1599.56433105469,54.0140480071884,5.64031777123819,6.30358171463013,54,1,0,0,1,0.297317504882812,34.2131004333496,1,1,3,349.985443115234,0,349.976211547852,,,,,,,,,,,,,,,,,,,,,,,,,,,,,,,,,
,3878527097.89685,349.929641723633,1399.72583007812,-7.08304649447433E-6,2.36195836365427E-8,1,4,13.4005146026611,4.99665375947691,33.2400016486645,-0.00883564467767869,-0.00104837315007259,1,2.15335361002684E-7,,,,,,,,,,,,,,,,,,,,,349.929290771484,349.929992675781,1399.72583007812,1399.72583007812,53.9272872415538,5.63995357227557,6.30272436141968,54,1,0,0,1,0.297622680664063,34.2131004333496,1,1,3,349.929992675781,0,349.929641723633,,,,,,,,,,,,,,,,,,,,,,,,,,,,,,,,,
,3878527172.15241,349.821960449219,1199.67333984375,-5.84355356512288E-6,2.22255164347917E-8,1,4,13.4005146026611,4.9966797149978,33.2400016486645,-0.00729841657127009,-0.000805381977618056,1,2.25598014270756E-7,,,,,,,,,,,,,,,,,,,,,349.815216064453,349.828704833984,1199.67333984375,1199.67333984375,53.8096521494095,5.63996298429877,6.30628299713135,52,1,68,0,0,0.297927856445313,34.2131004333496,1,1,3,349.815216064453,0,349.821960449219,,,,,,,,,,,,,,,,,,,,,,,,,,,,,,,,,
,3878527246.62969,349.870635986328,999.872497558594,-4.68042075029309E-6,2.13094523024896E-8,1,4,13.4005146026611,4.99664046076817,33.2400016486645,-0.00585445843150309,-0.000586088501532475,1,2.28188950554312E-7,,,,,,,,,,,,,,,,,,,,,349.862152099609,349.879119873047,999.872497558594,999.872497558594,53.8631937029769,5.64085735549392,6.30400991439819,54,1,0,0,1,0.298309326171875,34.2131004333496,1,1,3,349.879119873047,0,349.870635986328,,,,,,,,,,,,,,,,,,,,,,,,,,,,,,,,,
,3878527320.14044,349.751083374023,799.782165527344,-3.54996472872878E-6,2.87192419596276E-8,1,4,13.4005146026611,4.99671071140777,33.2400016486645,-0.00445784166688738,-0.00032878893200107,1,2.66286534911308E-7,,,,,,,,,,,,,,,,,,,,,349.736938476562,349.765228271484,799.782165527344,799.782165527344,53.9444830689769,5.64066893445736,6.30822467803955,53,1,68,0,0,0.298385620117188,33.7243423461914,1,1,3,349.736938476562,0,349.751083374023,,,,,,,,,,,,,,,,,,,,,,,,,,,,,,,,,
,3878527407.20467,349.626663208008,600.107238769531,-2.42110162798824E-6,3.55529534856137E-8,1,4,13.4005146026611,4.99663545473476,33.2400016486645,-0.00305442787026226,-0.000129229664459383,1,2.58113958671584E-7,,,,,,,,,,,,,,,,,,,,,349.611694335937,349.641632080078,600.107238769531,600.107238769531,53.8428713614768,5.64038741326454,6.31023645401001,54,1,0,0,1,0.297775268554687,34.2131004333496,1,1,3,349.641632080078,0,349.626663208008,,,,,,,,,,,,,,,,,,,,,,,,,,,,,,,,,
,3878527463.08314,349.802093505859,399.991790771484,-1.29947123199401E-6,2.57594414675943E-8,1,4,13.4005146026611,4.99671292621485,33.2400016486645,-0.00166190605342179,8.08827245192997E-5,1,2.59525890695111E-7,,,,,,,,,,,,,,,,,,,,,349.795196533203,349.808990478516,399.991790771484,399.991790771484,53.8291928623903,5.63986905908579,6.30707931518555,54,1,0,0,1,0.298080444335937,34.2131004333496,1,1,3,349.808990478516,0,349.802093505859,,,,,,,,,,,,,,,,,,,,,,,,,,,,,,,,,
,3878527537.15003,349.986480712891,200.228790283203,-3.05278143462158E-7,2.58307088425092E-8,1,4,13.4005146026611,4.99682219337352,33.2400016486645,-0.000425024435417998,0.000250223863389604,1,2.47161080456091E-7,,,,,,,,,,,,,,,,,,,,,349.978729248047,349.994232177734,200.228790283203,200.228790283203,53.8327101907268,5.64076141878995,6.3166651725769,52,1,68,0,0,0.298309326171875,34.2131004333496,1,1,3,349.994232177734,0,349.986480712891,,,,,,,,,,,,,,,,,,,,,,,,,,,,,,,,,
,3878527628.6432,349.960433959961,0.188823834061623,5.13737125715385E-7,2.92134537637505E-8,1,4,13.4005146026611,4.99666892947709,33.2400016486645,0.000591654935572474,0.000404941908245781,1,2.4924251193653E-7,,,,,,,,,,,,,,,,,,,,,349.948486328125,349.972381591797,0.188823834061623,0.188823834061623,53.8893782583711,5.6406578764786,6.31780958175659,54,1,0,0,1,0.297393798828125,33.7243423461914,1,1,3,349.948486328125,0,349.960433959961,,,,,,,,,,,,,,,,,,,,,,,,,,,,,,,,,
,3878527685.76175,349.873489379883,-199.83854675293,1.20380404293544E-6,2.93690378447152E-8,1,4,13.4005146026611,4.99657240102785,33.2400016486645,0.00146071000533276,0.000451739197937088,1,1.83707836913203E-7,,,,,,,,,,,,,,,,,,,,,349.865020751953,349.881958007812,-199.83854675293,-199.83854675293,53.897585357823,5.64057695417712,6.31931972503662,52,1,68,0,0,0.298080444335937,34.2131004333496,1,1,3,349.881958007812,0,349.873489379883,,,,,,,,,,,,,,,,,,,,,,,,,,,,,,,,,
,3878527768.61646,349.915054321289,-399.840728759766,1.93280498713526E-6,2.12035323196161E-8,1,4,13.4005146026611,4.99658039188497,33.2400016486645,0.00236050379242426,0.000623628868569365,10,2.13076908452417E-7,,,,,,,,,,,,,,,,,,,,,349.912322998047,349.917785644531,-399.840728759766,-399.840728759766,53.8346642620249,5.64033644858845,6.31965446472168,54,1,0,0,1,0.2978515625,34.2131004333496,1,1,3,349.912322998047,0,349.915054321289,,,,,,,,,,,,,,,,,,,,,,,,,,,,,,,,,
,3878527851.52233,349.851760864258,-599.641540527344,2.85809603893569E-6,1.52054515771983E-8,1,4,13.4005146026611,4.99658992930684,33.2400016486645,0.00351256856158759,0.000775033934560485,1,1.96584941715281E-7,,,,,,,,,,,,,,,,,,,,,349.839691162109,349.863830566406,-599.641540527344,-599.641540527344,53.9069649000538,5.64072056352066,6.31947708129883,53,1,64,0,0,0.297698974609375,33.7243423461914,1,1,3,349.863830566406,0,349.851760864258,,,,,,,,,,,,,,,,,,,,,,,,,,,,,,,,,
,3878527909.25352,349.794342041016,-799.631103515625,3.89265875339538E-6,2.15850058263846E-8,1,4,13.4005146026611,4.9965415215429,33.2400016486645,0.00479325074788156,0.000993522777866782,1,2.17781688044867E-7,,,,,,,,,,,,,,,,,,,,,349.789123535156,349.799560546875,-799.631103515625,-799.631103515625,53.8182500631211,5.64044090949399,6.32024335861206,54,1,0,0,1,0.298080444335937,34.2131004333496,1,1,3,349.799560546875,0,349.794342041016,,,,,,,,,,,,,,,,,,,,,,,,,,,,,,,,,
,3878527983.58793,350.052947998047,-999.545166015625,5.01903929987759E-6,6.7436429568443E-8,1,4,13.4005146026611,4.99651346285328,33.2400016486645,0.00620638009378874,0.00110584499362194,1,1.39743938672583E-7,,,,,,,,,,,,,,,,,,,,,350.037719726562,350.068176269531,-999.545166015625,-999.545166015625,53.9257239845153,5.64063237287413,6.31884908676147,54,1,0,0,1,0.298690795898438,34.7018585205078,1,1,3,350.068176269531,0,350.052947998047,,,,,,,,,,,,,,,,,,,,,,,,,,,,,,,,,
,3878528067.38252,350.150802612305,-1199.58520507812,6.17712353340875E-6,1.47473091925959E-8,1,4,13.4005146026611,4.99653629000532,33.2400016486645,0.0076393315704059,0.00135530918655827,10,1.6739369120686E-7,,,,,,,,,,,,,,,,,,,,,350.139617919922,350.161987304687,-1199.58520507812,-1199.58520507812,53.968713553073,5.64055672523001,6.32105016708374,54,1,0,0,1,0.298309326171875,34.2131004333496,1,1,3,350.163116455078,0,350.150802612305,,,,,,,,,,,,,,,,,,,,,,,,,,,,,,,,,
,3878528151.81782,349.876068115234,-1399.53698730469,7.38093105160996E-6,1.35088418524942E-8,1,4,13.4005146026611,4.99649311431486,33.2400016486645,0.0091378695939901,0.00155334507162228,1,1.46808272421257E-7,,,,,,,,,,,,,,,,,,,,,349.867858886719,349.88427734375,-1399.53698730469,-1399.53698730469,53.907746528573,5.64138517014369,6.32362508773804,52,1,68,0,0,0.29937744140625,34.7018585205078,1,1,3,349.88427734375,0,349.876068115234,,,,,,,,,,,,,,,,,,,,,,,,,,,,,,,,,
,3878528212.54574,349.891326904297,-1599.69030761719,8.59507298723181E-6,2.20854963829322E-8,1,4,13.4005146026611,4.99649905417575,33.2400016486645,0.0106451842288984,0.00178116956482102,1,1.48650852390165E-7,,,,,,,,,,,,,,,,,,,,,349.869842529297,349.912811279297,-1599.69030761719,-1599.69030761719,53.8491243896307,5.64057279787631,6.32165765762329,54,1,0,0,1,0.297927856445313,33.7243423461914,1,1,3,349.912811279297,0,349.891326904297,,,,,,,,,,,,,,,,,,,,,,,,,,,,,,,,,
,3878528273.30027,349.877059936523,-1799.70495605469,9.83461231152478E-6,1.69009942656106E-8,1,4,13.4005146026611,4.99652652121837,33.2400016486645,0.0121898899259903,0.00197511563600198,1,1.19400828942422E-7,,,,,,,,,,,,,,,,,,,,,349.876098632812,349.878021240234,-1799.70495605469,-1799.70495605469,53.9104822283903,5.64081332687891,6.32388353347778,54,1,0,0,1,0.297698974609375,33.7243423461914,1,1,3,349.878021240234,0,349.877059936523,,,,,,,,,,,,,,,,,,,,,,,,,,,,,,,,,
,3878528332.126,349.777770996094,-1999.61901855469,1.10766936808996E-5,7.2971375693662E-9,1,4,13.4005146026611,4.99651258705262,33.2400016486645,0.0137340572557051,0.00219330513145298,1,1.09312162013666E-7,,,,,,,,,,,,,,,,,,,,,349.759460449219,349.796081542969,-1999.61901855469,-1999.61901855469,53.8628028887172,5.64075321510813,6.32753038406372,54,1,0,0,1,0.298309326171875,33.7243423461914,1,1,3,349.796081542969,0,349.777770996094,,,,,,,,,,,,,,,,,,,,,,,,,,,,,,,,,
,3878528389.68386,350.046249389648,-2199.646484375,1.2333906394061E-5,7.79574017999608E-9,1,4,13.4005146026611,4.99656023044852,33.2400016486645,0.0152969742887801,0.00241629276928215,1,1.00791797066997E-7,,,,,,,,,,,,,,,,,,,,,350.046081542969,350.046417236328,-2199.646484375,-2199.646484375,53.8178592488615,5.64105536831602,6.32684898376465,54,1,0,0,1,0.298538208007812,33.7243423461914,1,1,3,350.046081542969,0,350.046249389648,,,,,,,,,,,,,,,,,,,,,,,,,,,,,,,,,
,3878528450.09888,349.814514160156,-2399.71142578125,1.35811048825865E-5,2.17531837270689E-8,1,4,13.4005146026611,4.99653090035666,33.2400016486645,0.016850048224982,0.00261788993652198,1,7.65844201884387E-8,,,,,,,,,,,,,,,,,,,,,349.804565429687,349.824462890625,-2399.71142578125,-2399.71142578125,53.8631937029769,5.64082107318449,6.32122898101807,54,1,0,0,1,0.298233032226562,34.2131004333496,1,1,3,349.824462890625,0,349.814514160156,,,,,,,,,,,,,,,,,,,,,,,,,,,,,,,,,
,3878528509.81235,349.894668579102,-2599.76416015625,1.4860527414119E-5,6.79857659716233E-9,1,4,13.4005146026611,4.99654642524265,33.2400016486645,0.0184382452836103,0.00285957679594867,1,7.98154646413439E-8,,,,,,,,,,,,,,,,,,,,,349.880493164063,349.908843994141,-2599.76416015625,-2599.76416015625,53.8350550762845,5.64112148588577,6.33178091049194,54,1,0,0,1,0.2978515625,34.2131004333496,1,1,3,349.908843994141,0,349.894668579102,,,,,,,,,,,,,,,,,,,,,,,,,,,,,,,,,
,3878528568.63399,349.929977416992,-2799.56494140625,1.61250867124315E-5,8.15549056846867E-9,1,4,13.4005146026611,4.99653379726885,33.2400016486645,0.0200123828207768,0.00306812460952631,1,5.86005175423868E-8,,,,,,,,,,,,,,,,,,,,,349.923126220703,349.936828613281,-2799.56494140625,-2799.56494140625,53.7811227084576,5.64060110089801,6.3270902633667,54,1,0,0,1,0.298843383789063,34.2131004333496,1,1,3,349.936828613281,0,349.929977416992,,,,,,,,,,,,,,,,,,,,,,,,,,,,,,,,,
,3878528630.09468,350.01513671875,-2999.69311523438,1.73927362662388E-5,1.24086822811578E-8,1,4,13.4005146026611,4.99652001550307,33.2400016486645,0.021583146448076,0.0033253280319576,1,7.61086898619073E-8,,,,,,,,,,,,,,,,,,,,,349.999816894531,350.030456542969,-2999.69311523438,-2999.69311523438,53.8534233464865,5.6408368355989,6.33257818222046,54,1,0,0,1,0.298385620117188,33.7243423461914,1,1,3,350.031097412109,0,350.01513671875,,,,,,,,,,,,,,,,,,,,,,,,,,,,,,,,,
,3878528709.51915,350.12712097168,-4499.533203125,2.70514878439367E-5,1.10943878583342E-8,1,4,13.4005146026611,4.99653464381448,33.2400016486645,0.0335991332382551,0.00497129068180288,1,-4.32699672825138E-8,,,,,,,,,,,,,,,,,,,,,350.115081787109,350.13916015625,-4499.533203125,-4499.533203125,53.8815619731788,5.64042122601797,6.32914113998413,54,1,0,0,1,0.29876708984375,33.7243423461914,1,1,3,350.13916015625,0,350.12712097168,,,,,,,,,,,,,,,,,,,,,,,,,,,,,,,,,
,3878528776.65776,350.006057739258,-6499.76904296875,3.99888100266694E-5,1.07566839557545E-8,1,4,13.4005146026611,4.99651893465234,33.2400016486645,0.0496688575952975,0.00734059989301642,1,-7.05421462939809E-8,,,,,,,,,,,,,,,,,,,,,349.995147705078,350.016967773438,-6499.76904296875,-6499.76904296875,53.7572830386211,5.64087823879551,6.32762432098389,54,1,0,0,1,0.298309326171875,33.7243423461914,1,1,3,350.016967773438,0,350.006057739258,,,,,,,,,,,,,,,,,,,,,,,,,,,,,,,,,
,3878528842.04627,350.025436401367,-8499.6279296875,5.29723914302428E-5,1.05850317676114E-8,1,4,13.4005146026611,4.99658427013739,33.2500003278255,0.0657979136676733,0.0097151117113849,1,-1.00705530164932E-7,,,,,,,,,,,,,,,,,,,,,350.021148681641,350.029724121094,-8499.6279296875,-8499.6279296875,53.9167352565442,5.64078672557041,6.32689428329468,54,1,0,0,1,0.2984619140625,34.2131004333496,1,1,3,350.029724121094,0,350.025436401367,,,,,,,,,,,,,,,,,,,,,,,,,,,,,,,,,
,3878528916.76238,349.927856445313,-9999.896484375,6.2704597027107E-5,1.32314628597041E-8,1,4,13.4005146026611,4.99660708260764,33.2400016486645,0.0778843266241594,0.0115176083262785,1,-1.05081463552501E-7,,,,,,,,,,,,,,,,,,,,,349.927612304687,349.928100585937,-9999.896484375,-9999.896484375,53.7697890949288,5.6405981149349,6.33037567138672,54,1,0,0,1,0.298538208007812,33.7243423461914,1,1,3,349.928100585937,0,349.927856445313,,,,,,,,,,,,,,,,,,,,,,,,,,,,,,,,,
,3878529074.67419,350.022674560547,-29999.587890625,0.000192895544205783,3.52698767533685E-8,1,4,13.4005146026611,4.99660787365557,33.2400016486645,0.239562646132897,0.0356298325831645,1,-1.63256402046847E-7,,,,,,,,,,,,,,,,,,,,,350.021667480469,350.023681640625,-29999.587890625,-29999.587890625,53.8045715640345,5.64007799232317,6.33209228515625,54,1,0,0,1,0.298309326171875,33.7243423461914,1,1,3,350.023681640625,0,350.022674560547,,,,,,,,,,,,,,,,,,,,,,,,,,,,,,,,,
,3878529250.56577,350.023635864258,-49999.703125,0.000323289224043693,7.40649013967281E-8,1,4,13.4005146026611,4.99672097332401,33.2400016486645,0.401508620400067,0.0597602249457025,1,-2.38651328655451E-7,,,,,,,,,,,,,,,,,,,,,350.021667480469,350.025604248047,-49999.703125,-49999.703125,53.7506391962076,5.63941250212436,6.33731079101562,54,1,0,0,1,0.298538208007812,33.7243423461914,1,1,3,350.021667480469,0,350.023635864258,,,,,,,,,,,,,,,,,,,,,,,,,,,,,,,,,
,3878529426.10886,349.861877441406,-69999.5390625,0.000453702528763639,1.25119632956468E-7,1,4,13.4005146026611,4.99645963052008,33.2500003278255,0.563418063668355,0.0839674848450131,1,-2.49220695857935E-7,,,,,,,,,,,,,,,,,,,,,349.846832275391,349.876922607422,-69999.5390625,-69999.5390625,53.5462433384287,5.63994538680331,6.33241128921509,54,1,0,0,1,0.297698974609375,34.2131004333496,1,1,3,349.876922607422,0,349.861877441406,,,,,,,,,,,,,,,,,,,,,,,,,,,,,,,,,
,3878529587.34385,349.95491027832,-49999.58984375,0.000323070152076864,8.90572671202238E-8,1,4,13.4005146026611,4.99649376995197,33.2400016486645,0.401202587580547,0.0597721462193442,1,-1.93214792459502E-7,,,,,,,,,,,,,,,,,,,,,349.940216064453,349.969604492188,-49999.58984375,-49999.58984375,53.7635360667749,5.64034869669148,6.33669328689575,54,1,0,0,1,0.298233032226562,34.2131004333496,1,1,3,349.969604492188,0,349.95491027832,,,,,,,,,,,,,,,,,,,,,,,,,,,,,,,,,
,3878529746.25343,349.934722900391,-29999.5625,0.000192644790168593,2.8959124298817E-8,1,4,13.4005146026611,4.99654759773432,33.2400016486645,0.23923668844684,0.035653087834914,1,-1.0653267422081E-7,,,,,,,,,,,,,,,,,,,,,349.932464599609,349.936981201172,-29999.5625,-29999.5625,53.7768237516018,5.63936602979318,6.33635759353638,54,1,0,0,1,0.299072265625,34.2131004333496,1,1,3,349.936981201172,0,349.934722900391,,,,,,,,,,,,,,,,,,,,,,,,,,,,,,,,,
,3878529903.73631,350.018997192383,-10000.072265625,6.24138507394073E-5,1.22677588357444E-8,1,4,13.4005146026611,4.99657746272333,33.2400016486645,0.0775050507036567,0.0115811011517757,1,-1.03793658889107E-8,,,,,,,,,,,,,,,,,,,,,350.002685546875,350.035308837891,-10000.072265625,-10000.072265625,53.9139995567269,5.64083083665683,6.3334903717041,54,1,0,0,1,0.297164916992188,34.2131004333496,1,1,3,350.035308837891,0,350.018997192383,,,,,,,,,,,,,,,,,,,,,,,,,,,,,,,,,
,3878529977.15915,350.049102783203,-8499.904296875,5.26446081565051E-5,1.15390254340839E-8,1,4,13.4005146026611,4.99658470678736,33.2400016486645,0.0653729908589035,0.00977389017840971,1,-4.33748051862441E-9,,,,,,,,,,,,,,,,,,,,,350.047485351562,350.050720214844,-8499.904296875,-8499.904296875,53.8475611325922,5.64111555725048,6.34454822540283,52,1,68,0,0,0.298843383789063,34.2131004333496,1,1,3,350.050720214844,0,350.049102783203,,,,,,,,,,,,,,,,,,,,,,,,,,,,,,,,,
,3878530044.17065,349.869842529297,-6499.9580078125,3.96522096817808E-5,1.06050473768625E-8,1,4,13.4005146026611,4.99654619974099,33.2400016486645,0.0492379558284358,0.00736708769933405,1,1.0970400489344E-9,,,,,,,,,,,,,,,,,,,,,349.867797851562,349.871887207031,-6499.9580078125,-6499.9580078125,53.9042292002365,5.63992702396723,6.34141874313354,52,1,68,0,0,0.297927856445313,34.2131004333496,1,1,3,349.871887207031,0,349.869842529297,,,,,,,,,,,,,,,,,,,,,,,,,,,,,,,,,
,3878530107.82171,349.704071044922,-4500.16259765625,2.6684290261724E-5,9.02664935139489E-9,1,4,13.4005146026611,4.99654347825422,33.2400016486645,0.0331315852519463,0.00498106191551356,1,1.95195410901049E-8,,,,,,,,,,,,,,,,,,,,,349.702606201172,349.705535888672,-4500.16259765625,-4500.16259765625,53.9245515417365,5.64072372249971,6.342857837677,54,1,0,0,1,0.299530029296875,34.2131004333496,1,1,3,349.702606201172,0,349.704071044922,,,,,,,,,,,,,,,,,,,,,,,,,,,,,,,,,
,3878530189.05471,349.961944580078,-3000.2216796875,1.70525939846067E-5,7.59399790794628E-9,1,4,13.4005146026611,4.9965678432213,33.2400016486645,0.0211806584890686,0.00313118506687914,1,-2.93892329371682E-8,,,,,,,,,,,,,,,,,,,,,349.961883544922,349.962005615234,-3000.2216796875,-3000.2216796875,53.9050108287557,5.64043719847329,6.33885002136231,54,1,0,0,1,0.298919677734375,35.190616607666,1,1,3,349.961883544922,0,349.961944580078,,,,,,,,,,,,,,,,,,,,,,,,,,,,,,,,,
,3878530244.66253,349.852890014648,-2800.20703125,1.5861440366859E-5,1.82763190287819E-8,1,4,13.4005146026611,4.99655501140293,33.2400016486645,0.0197292449055325,0.00272418984074872,1,-1.78949315109817E-7,,,,,,,,,,,,,,,,,,,,,349.843872070313,349.861907958984,-2800.20703125,-2800.20703125,53.7545473388038,5.6416732330029,6.34011030197144,52,1,68,0,0,0.298919677734375,34.2131004333496,1,1,3,349.861907958984,0,349.852890014648,,,,,,,,,,,,,,,,,,,,,,,,,,,,,,,,,
,3878530300.5445,350.039474487305,-2600.22998046875,1.46048323438199E-5,1.75411051885915E-8,1,4,13.4005146026611,4.99652367400289,33.2400016486645,0.0181735075090701,0.00245852198076648,1,-2.04896788463904E-7,,,,,,,,,,,,,,,,,,,,,350.027893066406,350.051055908203,-2600.22998046875,-2600.22998046875,53.8311469336884,5.64064965443464,6.33766460418701,54,1,0,0,1,0.299072265625,34.2131004333496,1,1,3,350.051055908203,0,350.039474487305,,,,,,,,,,,,,,,,,,,,,,,,,,,,,,,,,
,3878530358.57876,350.042297363281,-2400.18994140625,1.3337298453224E-5,1.87650477108208E-8,1,4,13.4005146026611,4.99662954095739,33.2400016486645,0.0165990365969824,0.00222990105716391,1,-1.99447736004749E-7,,,,,,,,,,,,,,,,,,,,,350.039916992188,350.044677734375,-2400.18994140625,-2400.18994140625,53.8495152038903,5.64114719268529,6.34599304199219,54,1,0,0,1,0.298919677734375,34.2131004333496,1,1,3,350.044677734375,0,350.042297363281,,,,,,,,,,,,,,,,,,,,,,,,,,,,,,,,,
,3878530416.55922,349.791931152344,-2200.3388671875,1.20552369251936E-5,1.88120512782527E-8,1,4,13.4005146026611,4.9965751457401,33.2400016486645,0.015008146722044,0.00198250745508428,1,-2.06859920807383E-7,,,,,,,,,,,,,,,,,,,,,349.77978515625,349.804077148438,-2200.3388671875,-2200.3388671875,53.8663202170538,5.64083998559728,6.33953666687012,54,1,0,0,1,0.298004150390625,34.2131004333496,1,1,3,349.77978515625,0,349.791931152344,,,,,,,,,,,,,,,,,,,,,,,,,,,,,,,,,
,3878530474.07482,349.783737182617,-2000.32397460938,1.08231517668893E-5,1.84966791009956E-8,1,4,13.4005146026611,4.99654931619552,33.2400016486645,0.0134828789134415,0.00172163771410132,1,-2.32618044331519E-7,,,,,,,,,,,,,,,,,,,,,349.776062011719,349.791412353516,-2000.32397460938,-2000.32397460938,53.8334918192461,5.64090083392779,6.34178018569946,52,1,68,0,0,0.298843383789063,34.2131004333496,1,1,3,349.791412353516,0,349.783737182617,,,,,,,,,,,,,,,,,,,,,,,,,,,,,,,,,
,3878530531.03112,349.736801147461,-1800.044921875,9.57234218159638E-6,1.74019074722078E-8,1,4,13.4005146026611,4.99659555333558,33.2400016486645,0.0119278085286704,0.00150287812298095,1,-2.21690458472207E-7,,,,,,,,,,,,,,,,,,,,,349.734558105469,349.739044189453,-1800.044921875,-1800.044921875,53.8514692751884,5.64042779420787,6.34422969818115,54,1,0,0,1,0.298385620117188,34.2131004333496,1,1,3,349.739044189453,0,349.736801147461,,,,,,,,,,,,,,,,,,,,,,,,,,,,,,,,,
,3878530587.73897,349.823394775391,-1599.99243164062,8.31831999657165E-6,1.81452375186212E-8,1,4,13.4005146026611,4.99645480025087,33.2400016486645,0.0103662428064538,0.00129629918255009,1,-2.00414022817647E-7,,,,,,,,,,,,,,,,,,,,,349.803680419922,349.843109130859,-1599.99243164062,-1599.99243164062,53.9054016430153,5.64110919410036,6.34172630310059,54,1,0,0,1,0.298309326171875,33.7243423461914,1,1,3,349.843109130859,0,349.823394775391,,,,,,,,,,,,,,,,,,,,,,,,,,,,,,,,,
,3878530643.39511,350.119216918945,-1399.97766113281,7.07408976203605E-6,2.21004345363126E-8,1,4,13.4005146026611,4.99651401063719,33.2400016486645,0.00882336970925121,0.00105206299319865,1,-2.10990913149904E-7,,,,,,,,,,,,,,,,,,,,,350.107269287109,350.131164550781,-1399.97766113281,-1399.97766113281,53.8291928623903,5.64075160275727,6.34051656723022,53,1,68,0,0,0.297470092773438,34.2131004333496,1,1,3,350.107269287109,0,350.119216918945,,,,,,,,,,,,,,,,,,,,,,,,,,,,,,,,,
,3878530709.35161,349.854782104492,-1200.15161132812,5.928632266017E-6,2.01640913829048E-8,1,4,13.4005146026611,4.99647867609809,33.2400016486645,0.00740587032611926,0.000806297534283504,10,-2.37551397874636E-7,,,,,,,,,,,,,,,,,,,,,349.853332519531,349.856231689453,-1200.15161132812,-1200.15161132812,53.8756997592846,5.64115529744748,6.34584712982178,54,1,0,0,1,0.297317504882812,34.2131004333496,1,1,3,349.856414794922,0,349.854782104492,,,,,,,,,,,,,,,,,,,,,,,,,,,,,,,,,
,3878530774.43421,349.84033203125,-1000.07391357422,4.6830157234583E-6,2.26948157987961E-8,1,4,13.4005146026611,4.99643793085733,33.2400016486645,0.00585559844701894,0.000598235033001097,1,-2.18768277087302E-7,,,,,,,,,,,,,,,,,,,,,349.829925537109,349.850738525391,-1000.07391357422,-1000.07391357422,53.8424805472172,5.64076393754415,6.3446216583252,53,1,68,0,0,0.297622680664063,34.2131004333496,1,1,3,349.850738525391,0,349.84033203125,,,,,,,,,,,,,,,,,,,,,,,,,,,,,,,,,
,3878530832.64278,350.022979736328,-800.134643554687,3.54746128151383E-6,2.14172733831031E-8,1,4,13.4005146026611,4.99649929183238,33.2400016486645,0.00445167418898354,0.000346986665491474,1,-2.51241253694238E-7,,,,,,,,,,,,,,,,,,,,,350.012115478516,350.033843994141,-800.134643554687,-800.134643554687,53.9648054104769,5.64126793744411,6.34577703475952,53,1,68,0,0,0.2978515625,33.2355842590332,1,1,3,350.033843994141,0,350.022979736328,,,,,,,,,,,,,,,,,,,,,,,,,,,,,,,,,
,3878530889.86711,350.063995361328,-600.019165039063,2.33625083732283E-6,1.0290480643993E-7,1,4,13.4005146026611,4.99647274757385,33.2500003278255,0.00293391916452359,0.000213787826903281,1,-1.77318731491641E-7,,,,,,,,,,,,,,,,,,,,,350.063537597656,350.064453125,-600.019165039063,-600.019165039063,53.912827113948,5.64130143860025,6.3403959274292,52,1,68,0,0,0.29754638671875,33.7243423461914,1,1,3,350.063537597656,0,350.063995361328,,,,,,,,,,,,,,,,,,,,,,,,,,,,,,,,,
,3878530963.93782,349.977767944336,-400.092498779297,1.31727845648213E-6,2.40368549149472E-8,1,4,13.4005146026611,4.99647858821314,33.2400016486645,0.00167210532973502,1.33268998398666E-6,1,-1.95983489682321E-7,,,,,,,,,,,,,,,,,,,,,349.964294433594,349.991241455078,-400.092498779297,-400.092498779297,53.8491243896307,5.64114509459543,6.3461651802063,54,1,0,0,1,0.298309326171875,33.2355842590332,1,1,3,349.964294433594,0,349.977767944336,,,,,,,,,,,,,,,,,,,,,,,,,,,,,,,,,
,3878531020.66766,349.656204223633,-200.128082275391,3.23005656934834E-7,2.90367809970039E-8,1,4,13.4005146026611,4.99644925537163,33.2400016486645,0.000445923301264629,-0.000239756943856643,1,-2.41404674476811E-7,,,,,,,,,,,,,,,,,,,,,349.651245117188,349.661163330078,-200.128082275391,-200.128082275391,53.8897690726307,5.64118862216471,6.34748363494873,53,1,68,0,0,0.299453735351562,34.2131004333496,1,1,3,349.661163330078,0,349.656204223633,,,,,,,,,,,,,,,,,,,,,,,,,,,,,,,,,
,3878531078.66021,349.834808349609,-0.125882551074028,-5.24870921252436E-7,2.90823641486758E-8,1,4,13.4005146026611,4.99650837499553,33.2400016486645,-0.000612922092998581,-0.000357066504109662,1,-2.09036465941727E-7,,,,,,,,,,,,,,,,,,,,,349.830078125,349.839538574219,-0.125882551074028,-0.125882551074028,53.9429198119384,5.6409873842784,6.34552621841431,52,1,68,0,0,0.298080444335937,34.2131004333496,1,1,3,349.830078125,0,349.834808349609,,,,,,,,,,,,,,,,,,,,,,,,,,,,,,,,,
,3878531135.93799,349.850845336914,199.914077758789,-1.17335801425574E-6,1.48073590681785E-8,1,4,13.4005146026611,4.99643225710225,33.2400016486645,-0.00143037991076506,-0.000395713393481213,1,-1.43156823563029E-7,,,,,,,,,,,,,,,,,,,,,349.836303710937,349.865386962891,199.914077758789,199.914077758789,53.7447769823134,5.64093966798212,6.34489965438843,53,1,68,0,0,0.298614501953125,34.2131004333496,1,1,3,349.865386962891,0,349.850845336914,,,,,,,,,,,,,,,,,,,,,,,,,,,,,,,,,
,3878531193.58583,350.033020019531,399.752624511719,-1.90749784493622E-6,2.31920800345451E-8,1,4,13.4005146026611,4.99651197781851,33.2400016486645,-0.00233928124560321,-0.000550413321264471,1,-1.5791021405739E-7,,,,,,,,,,,,,,,,,,,,,350.024658203125,350.041381835937,399.752624511719,399.752624511719,53.7928471362461,5.64084937332232,6.34624671936035,54,1,0,0,1,0.297393798828125,34.2131004333496,1,1,3,350.024658203125,0,350.033020019531,,,,,,,,,,,,,,,,,,,,,,,,,,,,,,,,,
,3878531251.90971,349.799774169922,599.931030273437,-2.82725991437332E-6,1.66246269550526E-8,1,4,13.4005146026611,4.99648303756923,33.2400016486645,-0.00348074767719108,-0.000725334158808488,1,-1.61191868788234E-7,,,,,,,,,,,,,,,,,,,,,349.788848876953,349.810699462891,599.931030273437,599.931030273437,53.8155143633038,5.64104973727138,6.34654378890991,53,1,68,0,0,0.298004150390625,33.7243423461914,1,1,3,349.788848876953,0,349.799774169922,,,,,,,,,,,,,,,,,,,,,,,,,,,,,,,,,
,3878531318.05579,349.586654663086,799.593383789063,-3.90240120739668E-6,1.17289219437832E-8,1,4,13.4005146026611,4.99646177462542,33.2400016486645,-0.00482012331277254,-0.000895825720950441,1,-1.37663429156077E-7,,,,,,,,,,,,,,,,,,,,,349.584228515625,349.589080810547,799.593383789063,799.593383789063,53.9155628137653,5.64108446703891,6.3465895652771,52,1,68,0,0,0.297698974609375,34.2131004333496,1,1,3,349.589385986328,0,349.586654663086,,,,,,,,,,,,,,,,,,,,,,,,,,,,,,,,,
,3878531380.57575,349.633392333984,999.759155273437,-5.01585117099385E-6,2.70934913939524E-8,1,4,13.4005146026611,4.99645291663347,33.2400016486645,-0.00621322511962995,-0.00103230926677067,1,-8.10150306335017E-8,,,,,,,,,,,,,,,,,,,,,349.6220703125,349.644714355469,999.759155273437,999.759155273437,53.9859093804961,5.64089051183056,6.34960460662842,52,1,68,0,0,0.29754638671875,33.7243423461914,1,1,3,349.644714355469,0,349.633392333984,,,,,,,,,,,,,,,,,,,,,,,,,,,,,,,,,
,3878531438.25594,349.850677490234,1199.64819335938,-6.1749212853085E-6,2.07929440580405E-8,1,4,13.4005146026611,4.99641796876057,33.2400016486645,-0.00763511789972633,-0.0013630494245221,1,-1.73992877995045E-7,,,,,,,,,,,,,,,,,,,,,349.850463867188,349.850891113281,1199.64819335938,1199.64819335938,53.7776053801211,5.64122783838564,6.35329055786133,52,1,68,0,0,0.298538208007812,33.7243423461914,1,1,3,349.850891113281,0,349.850677490234,,,,,,,,,,,,,,,,,,,,,,,,,,,,,,,,,
,3878531495.93845,349.802215576172,1399.876953125,-7.3822733521098E-6,1.60526451135887E-8,1,4,13.4005146026611,4.99641439839113,33.2400016486645,-0.00913860235824276,-0.00155845600504038,1,-1.50751131058576E-7,,,,,,,,,,,,,,,,,,,,,349.797088623047,349.807342529297,1399.876953125,1399.876953125,53.9011026861596,5.64148086051989,6.34846019744873,53,1,68,0,0,0.29876708984375,34.2131004333496,1,1,3,349.797088623047,0,349.802215576172,,,,,,,,,,,,,,,,,,,,,,,,,,,,,,,,,
,3878531553.55112,349.791625976562,1599.72802734375,-8.57120851714561E-6,2.28757626099239E-8,1,4,13.4005146026611,4.99645137288312,33.2400016486645,-0.0106155587497209,-0.00177571211154762,1,-1.47844914603573E-7,,,,,,,,,,,,,,,,,,,,,349.790496826172,349.792755126953,1599.72802734375,1599.72802734375,53.9081373428326,5.64071128067155,6.34985208511353,52,1,68,0,0,0.298843383789063,34.2131004333496,1,1,3,349.790588378906,0,349.791625976562,,,,,,,,,,,,,,,,,,,,,,,,,,,,,,,,,
,3878531612.15532,349.807434082031,1799.60424804687,-9.80798777259927E-6,3.58405808424517E-8,1,4,13.4005146026611,4.99650061270795,33.2500003278255,-0.012155309983804,-0.00197972029788093,1,-1.27103494081001E-7,,,,,,,,,,,,,,,,,,,,,349.800964355469,349.813903808594,1799.60424804687,1799.60424804687,53.8909415154095,5.64003050341137,6.35290145874023,53,1,68,0,0,0.297927856445313,33.7243423461914,1,1,3,349.813903808594,0,349.807434082031,,,,,,,,,,,,,,,,,,,,,,,,,,,,,,,,,
,3878531669.7336,349.953491210937,1999.99670410156,-1.11231139158713E-5,6.23637149180413E-8,1,4,13.4005146026611,4.9964505439443,33.2400016486645,-0.0137939615086887,-0.00218516280261654,1,-9.58413812046925E-8,,,,,,,,,,,,,,,,,,,,,349.946624755859,349.960357666016,1999.99670410156,1999.99670410156,53.8424805472172,5.64078193277014,6.34990167617798,53,1,68,0,0,0.298004150390625,34.2131004333496,1,1,3,349.946624755859,0,349.953491210937,,,,,,,,,,,,,,,,,,,,,,,,,,,,,,,,,
,3878531727.41204,350.012786865234,2199.89819335938,-1.23793646140106E-5,4.5446528583471E-8,1,4,13.4005146026611,4.99644287830978,33.2400016486645,-0.0153541324681138,-0.0024165345176591,1,-9.42502135429095E-8,,,,,,,,,,,,,,,,,,,,,350.000152587891,350.025421142578,2199.89819335938,2199.89819335938,53.8717916166884,5.64089329627973,6.34829568862915,54,1,0,0,1,0.298995971679687,33.7243423461914,1,1,3,350.025421142578,0,350.012786865234,,,,,,,,,,,,,,,,,,,,,,,,,,,,,,,,,
,3878531785.14752,349.876678466797,2400.05151367187,-1.35789480236896E-5,8.6407673721378E-9,1,4,13.4005146026611,4.99643069940178,33.2400016486645,-0.016844959093835,-0.00263036928951548,1,-8.70164073647688E-8,,,,,,,,,,,,,,,,,,,,,349.860961914063,349.892395019531,2400.05151367187,2400.05151367187,53.9198617706211,5.64153760357617,6.35227918624878,54,1,0,0,1,0.298690795898438,33.7243423461914,1,1,3,349.892395019531,0,349.876678466797,,,,,,,,,,,,,,,,,,,,,,,,,,,,,,,,,
,3878531842.8261,349.92024230957,2599.92797851562,-1.48538834796055E-5,7.24966564493252E-9,1,4,13.4005146026611,4.99644558187852,33.2400016486645,-0.0184301270453078,-0.00285389852504995,1,-7.63015162324291E-8,,,,,,,,,,,,,,,,,,,,,349.919128417969,349.921356201172,2599.92797851562,2599.92797851562,53.8346642620249,5.64070650689555,6.35564708709717,54,1,0,0,1,0.297927856445313,33.7243423461914,1,1,3,349.921356201172,0,349.92024230957,,,,,,,,,,,,,,,,,,,,,,,,,,,,,,,,,
,3878531901.51941,349.835083007812,2799.90478515625,-1.62267822713227E-5,1.45263688936044E-7,1,4,13.4005146026611,4.99647675466257,33.2400016486645,-0.0201214865703737,-0.00319963375355992,1,-1.49335284876766E-7,,,,,,,,,,,,,,,,,,,,,349.828125,349.842041015625,2799.90478515625,2799.90478515625,53.8729640594672,5.64126599248335,6.35238695144653,54,1,0,0,1,0.298843383789063,33.7243423461914,1,1,3,349.842041015625,0,349.835083007812,,,,,,,,,,,,,,,,,,,,,,,,,,,,,,,,,
,3878531959.20283,349.830673217773,2999.80639648438,-1.73854434176354E-5,9.89274396275303E-9,1,4,13.4005146026611,4.99648480964257,33.2400016486645,-0.0215765320748528,-0.00330619702691651,1,-6.18193342208199E-8,,,,,,,,,,,,,,,,,,,,,349.822204589844,349.839141845703,2999.80639648438,2999.80639648438,54.0136571929288,5.64092169762452,6.35031890869141,54,1,0,0,1,0.297622680664063,34.2131004333496,1,1,3,349.839141845703,0,349.830673217773,,,,,,,,,,,,,,,,,,,,,,,,,,,,,,,,,
,3878532036.13173,349.999862670898,4499.47021484375,-2.70380137228377E-5,1.21938959289174E-8,1,4,13.4005146026611,4.99653523257136,33.2400016486645,-0.0335848915975312,-0.00495218185725362,1,5.66436453432206E-8,,,,,,,,,,,,,,,,,,,,,349.985443115234,350.014282226562,4499.47021484375,4499.47021484375,53.9014935004192,5.64048958443821,6.34860324859619,54,1,0,0,1,0.297775268554687,34.2131004333496,1,1,3,350.014282226562,0,349.999862670898,,,,,,,,,,,,,,,,,,,,,,,,,,,,,,,,,
,3878532102.13889,350.006546020508,6499.69384765625,-3.99740076312582E-5,1.191375260767E-8,1,4,13.4005146026611,4.9965059846682,33.2400016486645,-0.0496553243571146,-0.00730421461352247,1,9.76082723286337E-8,,,,,,,,,,,,,,,,,,,,,349.995361328125,350.017730712891,6499.69384765625,6499.69384765625,53.8119970349672,5.64076550073237,6.35039377212524,54,1,0,0,1,0.298614501953125,34.2131004333496,1,1,3,350.017730712891,0,350.006546020508,,,,,,,,,,,,,,,,,,,,,,,,,,,,,,,,,
,3878532166.56924,350.010375976562,8500.0048828125,-5.29445701076732E-5,1.58932853800292E-8,1,4,13.4005146026611,4.99647407406927,33.2400016486645,-0.0657630825079247,-0.00969796377819336,1,1.10111775910015E-7,,,,,,,,,,,,,,,,,,,,,350.005615234375,350.01513671875,8500.0048828125,8500.0048828125,53.9171260708038,5.64062100761263,6.35264539718628,54,1,0,0,1,0.2984619140625,34.2131004333496,1,1,3,350.01513671875,0,350.010375976562,,,,,,,,,,,,,,,,,,,,,,,,,,,,,,,,,
,3878532240.68274,349.849792480469,10000.009765625,-6.26835699924371E-5,1.4186912789141E-8,1,4,13.4005146026611,4.99645238640017,33.2400016486645,-0.0778548672037279,-0.0115130246043759,1,1.05225265651925E-7,,,,,,,,,,,,,,,,,,,,,349.849029541016,349.850555419922,10000.009765625,10000.009765625,53.8362275190634,5.64077332108723,6.35438585281372,54,1,0,0,1,0.298233032226562,34.2131004333496,1,1,3,349.850555419922,0,349.849792480469,,,,,,,,,,,,,,,,,,,,,,,,,,,,,,,,,
,3878532393.59313,349.846282958984,30000.166015625,-0.000192846655452501,3.46176588895318E-8,1,4,13.4005146026611,4.99639555427324,33.2400016486645,-0.239497061133149,-0.0355559662203105,1,2.13723766954619E-7,,,,,,,,,,,,,,,,,,,,,349.843658447266,349.848907470703,30000.166015625,30000.166015625,53.8995394291211,5.64062820544417,6.355628490448,54,1,0,0,1,0.2984619140625,33.7243423461914,1,1,3,349.848907470703,0,349.846282958984,,,,,,,,,,,,,,,,,,,,,,,,,,,,,,,,,
,3878532551.409,349.995452880859,50000.3203125,-0.000323117450825217,7.7970573484361E-8,1,4,13.4005146026611,4.99640042278712,33.2400016486645,-0.401269514874036,-0.0596544149237754,1,2.93845684783249E-7,,,,,,,,,,,,,,,,,,,,,349.977020263672,350.013885498047,50000.3203125,50000.3203125,53.7330525545249,5.64002514376673,6.35330772399902,54,1,0,0,1,0.297698974609375,33.7243423461914,1,1,3,350.013885498047,0,349.995452880859,,,,,,,,,,,,,,,,,,,,,,,,,,,,,,,,,
,3878532710.56269,350.070449829102,70000.1796875,-0.000453611659827177,8.69550762436657E-8,1,4,13.4005146026611,4.99633443680903,33.2400016486645,-0.563313281130098,-0.0837617186904536,1,3.9897089264083E-7,,,,,,,,,,,,,,,,,,,,,350.063171386719,350.077728271484,70000.1796875,70000.1796875,53.5810258075345,5.64076439546107,6.35636234283447,53,1,68,0,0,0.298919677734375,33.7243423461914,1,1,3,350.077728271484,0,350.070449829102,,,,,,,,,,,,,,,,,,,,,,,,,,,,,,,,,