File: SQUID/22163_LCOT/LCOT_MH_5K_FC_p1T.csv
Comment,Time Stamp (sec),Temperature (K),Magnetic Field (Oe),Moment (emu),M. Std. Err. (emu),Transport Action,Averaging Time (sec),Frequency (Hz),Peak Amplitude (mm),Center Position (mm),Lockin Signal' (V),Lockin Signal (V),Range,M. Quad. Signal (emu),AC Moment (emu),AC M. Std Err. (emu),AC Phase (deg),AC Phase Std. Err. (deg),AC Susceptibility (emu/Oe),AC Suscept. Std Err. (emu/Oe),AC X' (emu/Oe),AC X' Std Err. (emu/Oe),AC X'' (emu/Oe),AC X'' Std Err. (emu/Oe),AC Drive (Oe),AC Frequency (Hz),AC Averaging Time (sec),AC Cycles,AC Range,AC Measure Type,AC Signal' (V),AC Signal'' (V),AC Trim Coil Ratio,AC Trim Coil Phase,Min. Temperature (K),Max. Temperature (K),Min. Field (Oe),Max. Field (Oe),Mass (grams),Motor Lag (deg),Pressure (Torr),Measure Count,Measurement Number,SQUID Status (code),Motor Status (code),Measure Status (code),Motor Current (amps),Motor Temp. (C),Temp. Status (code),Field Status (code),Chamber Status (code),Chamber Temp (K),Redirection State,Average Temp (K),Rotation Angle (deg),Rotator state,DC Moment Fixed Ctr (emu),DC Moment Err Fixed Ctr (emu),DC Moment Free Ctr (emu),DC Moment Err Free Ctr (emu),DC Fixed Fit,DC Free Fit,DC Calculated Center (mm),DC Calculated Center Err (mm),DC Scan Length (mm),DC Scan Time (s),DC Number of Points,DC Squid Drift,DC Min V (V),DC Max V (V),DC Scans per Measure,Sample Resistance,He3 Temperature,Sorb Resistance,Sorb Temperature,Map 05,Map 06,Map 07,Map 08,Map 09,Map 10,Map 11,Map 12,Map 13,Map 14,Map 15,Map 16
,3878472894.73032,5.00016617774963,70000.3828125,-4.30952284320343E-4,2.63690647294468E-7,1,4,13.4005146026611,4.9761301371241,32.8599996864796,-0.532040211203817,-0.0798013607272406,1,-1.67493252857283E-7,,,,,,,,,,,,,,,,,,,,,5.00016403198242,5.00016832351685,70000.3828125,70000.3828125,54.4818526759481,5.6437066402104,2.9027681350708,53,1,68,0,0,0.29571533203125,32.7468223571777,1,1,3,5.00016403198242,0,5.00016617774963,,,,,,,,,,,,,,,,,,,,,,,,,,,,,,,,,
,3878473086.45782,4.99991703033447,50000.41015625,-3.03384047844051E-4,1.02357794490562E-7,1,4,13.4005146026611,4.97608474943967,32.8599996864796,-0.374511921050431,-0.0563904110389614,1,-2.89746906218727E-7,,,,,,,,,,,,,,,,,,,,,4.99984836578369,4.99998569488525,50000.41015625,50000.41015625,54.2469733059192,5.64372207818372,2.91139221191406,54,1,0,0,1,0.297927856445313,33.7243423461914,1,1,3,4.99998569488525,0,4.99991703033447,,,,,,,,,,,,,,,,,,,,,,,,,,,,,,,,,
,3878473251.02202,5.00008797645569,30000.2421875,-1.78323381779708E-4,4.31380420777483E-8,1,4,13.4005146026611,4.97598166819562,32.8599996864796,-0.220168778749345,-0.032848850823934,10,6.89600929699447E-8,,,,,,,,,,,,,,,,,,,,,4.99998617172241,5.00018978118897,30000.2421875,30000.2421875,53.8866425585538,5.64198384745861,2.91927480697632,54,1,0,0,1,0.296783447265625,35.190616607666,1,1,3,5.00018978118897,0,5.00008797645569,,,,,,,,,,,,,,,,,,,,,,,,,,,,,,,,,
,3878473413.69855,5.00002384185791,9999.958984375,-5.52993160080228E-5,2.21587022943268E-8,1,4,13.4005146026611,4.97595551194476,32.8599996864796,-0.0682623532953893,-0.0102735232976077,1,-4.90376063423385E-8,,,,,,,,,,,,,,,,,,,,,4.99999523162842,5.0000524520874,9999.958984375,9999.958984375,53.5958767493999,5.64072221334636,2.92087030410767,54,1,0,0,1,0.297012329101562,33.7243423461914,1,1,3,4.99999523162842,0,5.00002384185791,,,,,,,,,,,,,,,,,,,,,,,,,,,,,,,,,
,3878473485.74794,5.00003337860107,8500.1064453125,-4.62540871933119E-5,2.02682060152683E-8,1,4,13.4005146026611,4.97594802786348,32.8699983656406,-0.057096799421034,-0.00859213890161061,1,-4.02544296356059E-8,,,,,,,,,,,,,,,,,,,,,4.99997282028198,5.00009393692017,8500.1064453125,8500.1064453125,53.4813681713326,5.64040830889646,2.91875743865967,52,1,68,0,0,0.2984619140625,34.2131004333496,1,1,3,5.00009393692017,0,5.00003337860107,,,,,,,,,,,,,,,,,,,,,,,,,,,,,,,,,
,3878473551.83501,4.999920129776,6499.8701171875,-3.41079943473385E-5,1.47605730450284E-8,1,4,13.4005146026611,4.97592880652518,32.8599996864796,-0.0421010491631551,-0.00635046944752649,1,-4.15242068314361E-8,,,,,,,,,,,,,,,,,,,,,4.99964141845703,5.00019884109497,6499.8701171875,6499.8701171875,53.486057942448,5.64062534211763,2.91837382316589,52,1,68,0,0,0.297088623046875,33.7243423461914,1,1,3,4.99964141845703,0,4.999920129776,,,,,,,,,,,,,,,,,,,,,,,,,,,,,,,,,
,3878473616.17018,4.99975848197937,4499.7470703125,-2.20931225545018E-5,1.26988130178163E-8,1,4,13.4005146026611,4.9759814975374,32.8599996864796,-0.0272664268078647,-0.00414376572299111,1,-5.13986144868415E-8,,,,,,,,,,,,,,,,,,,,,4.99966716766357,4.99984979629517,4499.7470703125,4499.7470703125,53.7033506707941,5.64157300632302,2.91277623176575,54,1,0,0,1,0.298080444335937,34.2131004333496,1,1,3,4.99966716766357,0,4.99975848197937,,,,,,,,,,,,,,,,,,,,,,,,,,,,,,,,,
,3878473695.70039,4.99995303153992,2999.57983398438,-1.31981614454325E-5,8.88468778845114E-9,1,4,13.4005146026611,4.97600932992785,32.8599996864796,-0.016295272634768,-0.00243190681384201,1,4.56781620414971E-9,,,,,,,,,,,,,,,,,,,,,4.99981069564819,5.00009536743164,2999.57983398438,2999.57983398438,53.6025205918134,5.64079583514852,2.91978621482849,54,1,0,0,1,0.297927856445313,33.7243423461914,1,1,3,5.00009536743164,0,4.99995303153992,,,,,,,,,,,,,,,,,,,,,,,,,,,,,,,,,
,3878473759.69033,4.99987626075745,2799.91748046875,-1.21631422440738E-5,1.77544187773291E-8,1,4,13.4005146026611,4.97599181627868,32.8599996864796,-0.0150551253960364,-0.00198832256367654,10,2.09021721511759E-7,,,,,,,,,,,,,,,,,,,,,4.9997706413269,4.99998188018799,2799.91748046875,2799.91748046875,53.5298291395249,5.64065333958274,2.9174964427948,54,1,0,0,1,0.29693603515625,36.1681327819824,1,1,3,4.99998188018799,0,4.99987626075745,,,,,,,,,,,,,,,,,,,,,,,,,,,,,,,,,
,3878473825.20439,5.00008010864258,2599.81469726562,-1.10163388185805E-5,1.84236696463425E-8,1,4,13.4005146026611,4.9759938257319,32.8599996864796,-0.0136364687423569,-0.00179543941731636,1,1.93700077899452E-7,,,,,,,,,,,,,,,,,,,,,5.00005292892456,5.0001072883606,2599.81469726562,2599.81469726562,53.4375969742557,5.64077588161746,2.91425561904907,54,1,0,0,1,0.296783447265625,33.7243423461914,1,1,3,5.00005292892456,0,5.00008010864258,,,,,,,,,,,,,,,,,,,,,,,,,,,,,,,,,
,3878473900.00383,5.00007104873657,2400.1142578125,-9.88232177301759E-6,2.00057192059122E-8,1,4,13.4005146026611,4.97605556132843,32.8599996864796,-0.0122378587505324,-0.0015778310747038,1,2.00339559549553E-7,,,,,,,,,,,,,,,,,,,,,5.0000696182251,5.00007247924805,2400.1142578125,2400.1142578125,53.6619243592749,5.64087877307686,2.91193151473999,54,1,0,0,1,0.297088623046875,34.2131004333496,1,1,3,5.00007247924805,0,5.00007104873657,,,,,,,,,,,,,,,,,,,,,,,,,,,,,,,,,
,3878473975.33347,4.99982285499573,2200.04931640625,-8.78411680415304E-6,1.73239036703333E-8,1,4,13.4005146026611,4.97595649332051,32.8599996864796,-0.0108842517355434,-0.00135787061902841,1,2.14185341854065E-7,,,,,,,,,,,,,,,,,,,,,4.99975919723511,4.99988651275635,2200.04931640625,2200.04931640625,53.4747243289191,5.64094833983791,2.91487169265747,54,1,0,0,1,0.298233032226562,34.2131004333496,1,1,3,4.99975919723511,0,4.99982285499573,,,,,,,,,,,,,,,,,,,,,,,,,,,,,,,,,
,3878474049.23658,4.99713206291199,2000.185546875,-7.62253819919903E-6,1.78868784428079E-8,1,4,13.4005146026611,4.9760569086736,32.8599996864796,-0.00944576468980601,-0.00117474947913723,1,1.88773981121164E-7,,,,,,,,,,,,,,,,,,,,,4.99678421020508,4.9974799156189,2000.185546875,2000.185546875,53.5778992934576,5.64058896924574,2.91464757919312,53,1,68,0,0,0.29632568359375,34.2131004333496,1,1,3,4.99678421020508,0,4.99713206291199,,,,,,,,,,,,,,,,,,,,,,,,,,,,,,,,,
,3878474123.51261,5.00000643730164,1799.85607910156,-6.48739398372067E-6,2.03566403327623E-8,1,4,13.4005146026611,4.97608040672125,32.8599996864796,-0.00804439113056227,-9.64843576867403E-4,1,1.88985878136733E-7,,,,,,,,,,,,,,,,,,,,,4.99995136260986,5.00006151199341,1799.85607910156,1799.85607910156,53.4731610718807,5.64092637760648,2.89982032775879,53,1,68,0,0,0.297622680664063,34.2131004333496,1,1,3,4.9999098777771,0,5.00000643730164,,,,,,,,,,,,,,,,,,,,,,,,,,,,,,,,,
,3878474197.34221,4.99987602233887,1599.85388183594,-5.35829390644501E-6,1.99536026038123E-8,1,4,13.4005146026611,4.97604245334791,32.8599996864796,-0.00665378509848851,-7.33047792293328E-4,1,2.0781927856284E-7,,,,,,,,,,,,,,,,,,,,,4.99984455108643,4.99990749359131,1599.85388183594,1599.85388183594,53.5462433384287,5.64108229905766,2.89485859870911,52,1,68,0,0,0.299911499023438,34.2131004333496,1,1,3,4.99984455108643,0,4.99987602233887,,,,,,,,,,,,,,,,,,,,,,,,,,,,,,,,,
,3878474270.86811,5.00003695487976,1400.16650390625,-4.2670538665149E-6,2.1867304245302E-8,1,4,13.4005146026611,4.97596550938841,32.8599996864796,-0.00531085363478384,-5.0181733018365E-4,1,2.31857955843493E-7,,,,,,,,,,,,,,,,,,,,,4.9999885559082,5.00008535385132,1400.16650390625,1400.16650390625,53.5907961640249,5.64099394799593,2.89933681488037,54,1,0,0,1,0.297775268554687,33.7243423461914,1,1,3,4.9999885559082,0,5.00003695487976,,,,,,,,,,,,,,,,,,,,,,,,,,,,,,,,,
,3878474326.83886,4.99995136260986,1200.11376953125,-3.1970694812722E-6,2.30659485185336E-8,1,4,13.4005146026611,4.97599357399763,32.8599996864796,-0.00398860882951208,-3.12843601233722E-4,1,2.24863721471038E-7,,,,,,,,,,,,,,,,,,,,,4.99988555908203,5.0000171661377,1200.11376953125,1200.11376953125,53.5407719387941,5.64108168454091,2.89429759979248,54,1,0,0,1,0.297775268554687,34.2131004333496,1,1,3,4.99988555908203,0,4.99995136260986,,,,,,,,,,,,,,,,,,,,,,,,,,,,,,,,,
,3878474384.11446,5.00013065338135,1000.27532958984,-2.11994693195012E-6,2.10521242704969E-8,1,4,13.4005146026611,4.97601473134742,32.8599996864796,-0.00265720880856827,-1.24662586898654E-4,1,2.16156958612879E-7,,,,,,,,,,,,,,,,,,,,,5.00007104873657,5.00019025802612,1000.27532958984,1000.27532958984,53.4340796459191,5.64030831626665,2.89026260375977,54,1,0,0,1,0.298995971679687,34.2131004333496,1,1,3,5.00007104873657,0,5.00013065338135,,,,,,,,,,,,,,,,,,,,,,,,,,,,,,,,,
,3878474448.87814,5.00005674362183,800.172424316406,-1.08872455872619E-6,2.21113522856589E-8,1,4,13.4005146026611,4.97611471325715,32.8599996864796,-0.00139423472915818,1.3353964936531E-4,10,2.71027715189207E-7,,,,,,,,,,,,,,,,,,,,,5.0000319480896,5.00008153915405,800.172424316406,800.172424316406,53.374285064198,5.64051288881009,2.89566874504089,54,1,0,0,1,0.298385620117188,34.2131004333496,1,1,3,5.00008153915405,0,5.00005674362183,,,,,,,,,,,,,,,,,,,,,,,,,,,,,,,,,
,3878474516.06945,4.99992275238037,600.522705078125,-2.56255325993718E-8,3.48620808854911E-8,1,4,13.4005146026611,4.97603939511655,32.8599996864796,-6.67125380884688E-5,2.2973561875319E-4,1,1.89913096640281E-7,,,,,,,,,,,,,,,,,,,,,4.99987030029297,4.99997520446777,600.522705078125,600.522705078125,53.3746758784576,5.64027889009429,2.88828349113464,54,1,0,0,1,0.29632568359375,34.2131004333496,1,1,3,4.99987030029297,0,4.99992275238037,,,,,,,,,,,,,,,,,,,,,,,,,,,,,,,,,
,3878474573.19155,4.99967956542969,400.356872558594,9.10344296289496E-7,2.58788714868656E-8,1,4,13.4005146026611,4.97601491294964,32.8599996864796,0.00107870997715344,4.70291099552744E-4,1,2.44743879191419E-7,,,,,,,,,,,,,,,,,,,,,4.99961853027344,4.99974060058594,400.356872558594,400.356872558594,53.511460869323,5.64032948890674,2.88851499557495,54,1,0,0,1,0.298538208007812,33.7243423461914,1,1,3,4.99969005584717,0,4.99967956542969,,,,,,,,,,,,,,,,,,,,,,,,,,,,,,,,,
,3878474632.51321,4.99975657463074,200.266555786133,1.88721396972718E-6,2.19476188957236E-8,1,4,13.4005146026611,4.97613735902203,32.8599996864796,0.00229255525504646,5.99106085145435E-4,1,2.02930814806937E-7,,,,,,,,,,,,,,,,,,,,,4.99957513809204,4.99993801116943,200.266555786133,200.266555786133,53.5524963665826,5.64108608317974,2.89048600196838,54,1,0,0,1,0.297622680664063,34.2131004333496,1,1,3,4.99993801116943,0,4.99975657463074,,,,,,,,,,,,,,,,,,,,,,,,,,,,,,,,,
,3878474710.1856,4.99990320205688,0.188823834061623,2.66034764371219E-6,2.36956771403226E-8,1,4,13.4005146026611,4.97597166347277,32.8599996864796,0.00324244110859712,7.71989269963345E-4,1,2.27330886160312E-7,,,,,,,,,,,,,,,,,,,,,4.99982070922852,4.99998569488525,0.188823834061623,0.188823834061623,53.4106307903422,5.6404266028455,2.88649892807007,54,1,0,0,1,0.296783447265625,34.2131004333496,1,1,3,4.99982070922852,0,4.99990320205688,,,,,,,,,,,,,,,,,,,,,,,,,,,,,,,,,
,3878474778.40327,4.99995112419128,-199.80078125,3.41898509907423E-6,1.36713344495938E-8,1,4,13.4005146026611,4.97590959996433,32.8599996864796,0.00421773366660133,6.52960643056359E-4,10,1.7440830562075E-8,,,,,,,,,,,,,,,,,,,,,4.99987697601318,5.00002527236938,-199.80078125,-199.80078125,53.5517147380633,5.64095581024871,2.88403797149658,54,1,0,0,1,0.296707153320313,34.2131004333496,1,1,3,4.99987697601318,0,4.99995112419128,,,,,,,,,,,,,,,,,,,,,,,,,,,,,,,,,
,3878474845.0764,4.99992918968201,-399.802978515625,3.98125944821789E-6,1.27333086750821E-8,1,4,13.4005146026611,4.97591915514591,32.8599996864796,0.00488081917023463,9.64642793944376E-4,1,1.85789356220964E-7,,,,,,,,,,,,,,,,,,,,,4.99989175796509,4.99996662139893,-399.802978515625,-399.802978515625,53.4950466704191,5.6411759804021,2.87611699104309,52,1,68,0,0,0.297698974609375,33.7243423461914,1,1,3,4.99989175796509,0,4.99992918968201,,,,,,,,,,,,,,,,,,,,,,,,,,,,,,,,,
,3878474919.34321,5.00008296966553,-599.57861328125,4.7113477391739E-6,1.30978705452371E-8,1,4,13.4005146026611,4.97584818360715,32.8599996864796,0.00578264073732438,0.00109548181574258,1,1.82570110940398E-7,,,,,,,,,,,,,,,,,,,,,5.00006151199341,5.00010442733765,-599.57861328125,-599.57861328125,53.5329556536018,5.64077841369981,2.87556624412537,54,1,0,0,1,0.297470092773438,33.7243423461914,1,1,3,5.00010442733765,0,5.00008296966553,,,,,,,,,,,,,,,,,,,,,,,,,,,,,,,,,
,3878474985.78232,4.99997591972351,-799.656311035156,5.46284460972303E-6,7.6194557279793E-8,1,4,13.4005146026611,4.97581987098908,32.8599996864796,0.0067139993969981,0.0012098076488042,10,1.62764490300244E-7,,,,,,,,,,,,,,,,,,,,,4.99986219406128,5.00008964538574,-799.656311035156,-799.656311035156,53.3848370492076,5.64166719443694,2.87351012229919,54,1,0,0,1,0.2978515625,34.2131004333496,1,1,3,5.00008964538574,0,4.99997591972351,,,,,,,,,,,,,,,,,,,,,,,,,,,,,,,,,
,3878475052.03603,5.00015091896057,-999.52001953125,6.47374997960249E-6,4.26862536405955E-8,1,4,13.4005146026611,4.97584629478482,32.8599996864796,0.00796808846460068,0.0013561727960254,1,1.30090259144062E-7,,,,,,,,,,,,,,,,,,,,,5.00012254714966,5.00017929077148,-999.52001953125,-999.52001953125,53.5020813270922,5.64139609627632,2.87260174751282,52,1,68,0,0,0.29632568359375,33.7243423461914,1,1,3,5.00012254714966,0,5.00015091896057,,,,,,,,,,,,,,,,,,,,,,,,,,,,,,,,,
,3878475127.08046,4.9998733997345,-1199.59777832031,7.43399293599636E-6,2.11418646561364E-8,1,4,13.4005146026611,4.97578174102057,32.8599996864796,0.00914743347323315,0.00157324348473426,1,1.62298058932057E-7,,,,,,,,,,,,,,,,,,,,,4.9996223449707,5.00012445449829,-1199.59777832031,-1199.59777832031,53.663878430573,5.64107640325408,2.87112188339233,53,1,68,0,0,0.299148559570313,34.2131004333496,1,1,3,4.9996223449707,0,4.9998733997345,,,,,,,,,,,,,,,,,,,,,,,,,,,,,,,,,
,3878475220.09425,5.00013136863708,-1399.5244140625,8.41786633402447E-6,1.20373270861839E-8,1,4,13.4005146026611,4.97574145365267,32.8599996864796,0.0103614206751396,0.00175830036838573,1,1.6503486195289E-7,,,,,,,,,,,,,,,,,,,,,5.00006914138794,5.00019359588623,-1399.5244140625,-1399.5244140625,53.3828829779095,5.64163052682987,2.871248960495,53,1,68,0,0,0.297775268554687,33.7243423461914,1,1,3,5.00019359588623,0,5.00013136863708,,,,,,,,,,,,,,,,,,,,,,,,,,,,,,,,,
,3878475311.91059,4.99981236457825,-1599.67761230469,9.41194351833006E-6,7.00422529889363E-8,1,4,13.4005146026611,4.97585410957254,32.8599996864796,0.011601298718328,0.00185961201018157,1,9.83457356777855E-8,,,,,,,,,,,,,,,,,,,,,4.99977684020996,4.99984788894653,-1599.67761230469,-1599.67761230469,53.4028145051499,5.64113409730157,2.86655807495117,53,1,68,0,0,0.299911499023438,33.7243423461914,1,1,3,4.99984788894653,0,4.99981236457825,,,,,,,,,,,,,,,,,,,,,,,,,,,,,,,,,
,3878475372.82896,4.99992322921753,-1799.66723632813,1.05334563762426E-5,1.38511664940878E-8,1,4,13.4005146026611,4.97579222462326,32.8599996864796,0.0129805592358523,0.00210058830213564,1,1.257985750854E-7,,,,,,,,,,,,,,,,,,,,,4.99991035461426,4.9999361038208,-1799.66723632813,-1799.66723632813,53.3371577095345,5.64112551624578,2.8655858039856,54,1,0,0,1,0.299453735351562,33.7243423461914,1,1,3,4.9999361038208,0,4.99992322921753,,,,,,,,,,,,,,,,,,,,,,,,,,,,,,,,,
,3878475432.23537,4.99992537498474,-1999.58129882813,1.16589291283997E-5,7.61437547659775E-9,1,4,13.4005146026611,4.97582431432588,32.8599996864796,0.0143683506905897,0.00232022621273758,1,1.35330972197394E-7,,,,,,,,,,,,,,,,,,,,,4.99981546401978,5.00003528594971,-1999.58129882813,-1999.58129882813,53.6517631885249,5.64151489390542,2.86427474021912,54,1,0,0,1,0.299072265625,33.7243423461914,1,1,3,4.99981546401978,0,4.99992537498474,,,,,,,,,,,,,,,,,,,,,,,,,,,,,,,,,
,3878475491.05151,5.00011610984802,-2199.6337890625,1.27729466448633E-5,2.77431410304127E-8,1,4,13.4005146026611,4.97579578970748,32.8599996864796,0.0157435404457289,0.00252577981262279,1,1.35200288154653E-7,,,,,,,,,,,,,,,,,,,,,5.00008583068848,5.00014638900757,-2199.6337890625,-2199.6337890625,53.5204495972941,5.64137353997306,2.87123823165894,54,1,0,0,1,0.2972412109375,33.7243423461914,1,1,3,5.00008583068848,0,5.00011610984802,,,,,,,,,,,,,,,,,,,,,,,,,,,,,,,,,
,3878475548.62904,4.99998807907105,-2399.57299804687,1.3912642928922E-5,2.82157266025272E-8,1,4,13.4005146026611,4.97576142107463,32.8599996864796,0.0171632130371087,0.0026502856499187,1,6.55828905284774E-8,,,,,,,,,,,,,,,,,,,,,4.99983930587769,5.0001368522644,-2399.57299804687,-2399.57299804687,53.4645631581691,5.64032741176819,2.86825346946716,54,1,0,0,1,0.297927856445313,34.2131004333496,1,1,3,4.99983930587769,0,4.99998807907105,,,,,,,,,,,,,,,,,,,,,,,,,,,,,,,,,
,3878475609.63885,4.99996376037598,-2599.73901367187,1.50406039796393E-5,1.03772414585966E-8,1,4,13.4005146026611,4.97579792757873,32.8599996864796,0.0185520644902152,0.00288416589792247,1,8.62743642706785E-8,,,,,,,,,,,,,,,,,,,,,4.99990797042847,5.00001955032349,-2599.73901367187,-2599.73901367187,53.4442408166691,5.64022623821002,2.86516118049622,54,1,0,0,1,0.297317504882812,33.7243423461914,1,1,3,4.99990797042847,0,4.99996376037598,,,,,,,,,,,,,,,,,,,,,,,,,,,,,,,,,
,3878475669.23121,5.00022530555725,-2799.77905273438,1.62296352954841E-5,7.25789967005381E-8,1,4,13.4005146026611,4.97577552849869,32.8599996864796,0.020029235450827,0.00304083630029689,1,3.53256435660196E-8,,,,,,,,,,,,,,,,,,,,,5.00007200241089,5.00037860870361,-2799.77905273438,-2799.77905273438,53.5544504378807,5.64135761882149,2.85909175872803,54,1,0,0,1,0.297698974609375,33.2355842590332,1,1,3,5.00037860870361,0,5.00022530555725,,,,,,,,,,,,,,,,,,,,,,,,,,,,,,,,,
,3878475730.96758,4.99994945526123,-2999.73071289063,1.73375901132396E-5,9.69679282297649E-9,1,4,13.4005146026611,4.97579112083504,32.8599996864796,0.0213842472442963,0.00333150543914315,1,1.05022273175177E-7,,,,,,,,,,,,,,,,,,,,,4.9998950958252,5.00000381469727,-2999.73071289063,-2999.73071289063,53.4360337172172,5.64155540926494,2.86527180671692,54,1,0,0,1,0.297775268554687,33.7243423461914,1,1,3,4.9998950958252,0,4.99994945526123,,,,,,,,,,,,,,,,,,,,,,,,,,,,,,,,,
,3878475809.40999,5.00014734268188,-4499.59619140625,2.62455908077574E-5,2.66144066462183E-8,1,4,13.4005146026611,4.97576466409767,32.8699983656406,0.0323987951759873,0.00485849165924079,1,9.3741037051605E-9,,,,,,,,,,,,,,,,,,,,,5.00004816055298,5.00024652481079,-4499.59619140625,-4499.59619140625,53.4266541749864,5.64131997424347,2.86382532119751,54,1,0,0,1,0.299224853515625,34.2131004333496,1,1,3,5.00004816055298,0,5.00014734268188,,,,,,,,,,,,,,,,,,,,,,,,,,,,,,,,,
,3878475877.73009,5.00002503395081,-6499.8701171875,3.82520458029101E-5,1.43699272569758E-8,1,4,13.4005146026611,4.97568197562467,32.8599996864796,0.0472280297658049,0.00702073866283684,1,-3.50870691210302E-8,,,,,,,,,,,,,,,,,,,,,4.99993991851807,5.00011014938354,-6499.8701171875,-6499.8701171875,53.447367330746,5.64045017722566,2.86565947532654,54,1,0,0,1,0.297393798828125,33.7243423461914,1,1,3,5.00011014938354,0,5.00002503395081,,,,,,,,,,,,,,,,,,,,,,,,,,,,,,,,,
,3878475943.48481,4.99970865249634,-8499.6904296875,5.03347004176205E-5,1.61946495493846E-8,1,4,13.4005146026611,4.9756996893774,32.8599996864796,0.0621462813306246,0.0092381107875697,1,-4.64221696383313E-8,,,,,,,,,,,,,,,,,,,,,4.99967241287231,4.99974489212036,-8499.6904296875,-8499.6904296875,53.4633907153903,5.64167734463463,2.86330270767212,54,1,0,0,1,0.297393798828125,33.7243423461914,1,1,3,4.99967241287231,0,4.99970865249634,,,,,,,,,,,,,,,,,,,,,,,,,,,,,,,,,
,3878476077.69146,5.00037550926209,-9999.7197265625,5.93291223632908E-5,2.09396610555667E-8,1,4,13.4005146026611,4.9757366294667,32.8599996864796,0.0732481063835499,0.0109157363388441,1,-3.30626018892988E-8,,,,,,,,,,,,,,,,,,,,,5.00029802322388,5.00045299530029,-9999.7197265625,-9999.7197265625,53.5661748656691,5.64173843338553,2.84689259529114,54,1,0,0,1,0.299148559570313,33.7243423461914,1,1,3,5.00029802322388,0,5.00037550926209,,,,,,,,,,,,,,,,,,,,,,,,,,,,,,,,,
,3878476234.27449,4.99969267845154,-29999.587890625,1.82014115312718E-4,5.62749621862356E-8,1,4,13.4005146026611,4.97563990499612,32.8599996864796,0.224684918065061,0.033652361161538,1,3.23914776307642E-8,,,,,,,,,,,,,,,,,,,,,4.9996600151062,4.99972534179687,-29999.587890625,-29999.587890625,53.7533748960249,5.64185777339518,2.85047960281372,54,1,0,0,1,0.29815673828125,34.2131004333496,1,1,3,4.9996600151062,0,4.99969267845154,,,,,,,,,,,,,,,,,,,,,,,,,,,,,,,,,
,3878476394.23722,4.99990725517273,-49999.6640625,3.06557207825838E-4,6.9686517744168E-8,1,4,13.4005146026611,4.97562914216507,32.8599996864796,0.378402232459953,0.0568266016881455,1,1.74280651650645E-7,,,,,,,,,,,,,,,,,,,,,4.99975109100342,5.00006341934204,-49999.6640625,-49999.6640625,54.3177106869096,5.64261386473195,2.84741234779358,54,1,0,0,1,0.2978515625,33.7243423461914,1,1,3,4.99975109100342,0,4.99990725517273,,,,,,,,,,,,,,,,,,,,,,,,,,,,,,,,,
,3878476569.59006,5.00000762939453,-69999.578125,4.31715556182077E-4,1.65524580538358E-7,1,4,13.4005146026611,4.97574131338348,32.8599996864796,0.532919261338376,0.0799657389237893,1,1.93561000962509E-7,,,,,,,,,,,,,,,,,,,,,4.99995851516724,5.00005674362183,-69999.578125,-69999.578125,54.6495119933231,5.64418288835445,2.8371593952179,54,1,0,0,1,0.2984619140625,34.2131004333496,1,1,3,4.99995851516724,0,5.00000762939453,,,,,,,,,,,,,,,,,,,,,,,,,,,,,,,,,
,3878476731.89295,5.00007057189941,-49999.6171875,3.04383478583913E-4,8.9882666652988E-8,1,4,13.4005146026611,4.97572961228224,32.8599996864796,0.375739698459576,0.0563585809641338,1,1.19034011505382E-7,,,,,,,,,,,,,,,,,,,,,5.00002145767212,5.00011968612671,-49999.6171875,-49999.6171875,54.3321708145154,5.64226092562501,2.84016489982605,52,1,32,0,0,0.298080444335937,34.2131004333496,1,1,3,5.00002145767212,0,5.00007057189941,,,,,,,,,,,,,,,,,,,,,,,,,,,,,,,,,
,3878476891.47071,4.99998426437378,-29999.701171875,1.78981368627586E-4,3.33433218932603E-8,1,4,13.4005146026611,4.97562387339715,32.8699983656406,0.220935899576707,0.0331201306900545,1,5.50521497400191E-8,,,,,,,,,,,,,,,,,,,,,4.99997854232788,4.99998998641968,-29999.701171875,-29999.701171875,53.7600187384384,5.64177634806774,2.83315229415894,54,1,0,0,1,0.299453735351562,34.2131004333496,1,1,3,4.99997854232788,0,4.99998426437378,,,,,,,,,,,,,,,,,,,,,,,,,,,,,,,,,
,3878477048.72322,4.99979496002197,-10000.123046875,5.59804558401681E-5,3.48053587564835E-8,1,4,13.4005146026611,4.97565598562268,32.8599996864796,0.0690977714697351,0.0103961664211303,1,4.71953947470142E-8,,,,,,,,,,,,,,,,,,,,,4.99974727630615,4.99984264373779,-10000.123046875,-10000.123046875,53.4629999011307,5.63959864413118,2.83688807487488,54,1,0,0,1,0.2984619140625,33.2355842590332,1,1,3,4.99974727630615,0,4.99979496002197,,,,,,,,,,,,,,,,,,,,,,,,,,,,,,,,,
,3878477121.41859,5.00003695487976,-8500.09375,4.68543095648125E-5,1.68442653070579E-8,1,4,13.4005146026611,4.97566967889435,32.8599996864796,0.0578314416875505,0.00871456357388328,1,5.01828429735765E-8,,,,,,,,,,,,,,,,,,,,,5.00001764297485,5.00005626678467,-8500.09375,-8500.09375,53.6924078715249,5.64063658664273,2.83529233932495,53,1,68,0,0,0.296630859375,33.7243423461914,1,1,3,5.00001764297485,0,5.00003695487976,,,,,,,,,,,,,,,,,,,,,,,,,,,,,,,,,
,3878477188.04418,4.9999680519104,-6500.00830078125,3.4757019838292E-5,1.41130775403483E-8,1,4,13.4005146026611,4.97562078213408,32.8599996864796,0.0428994230943999,0.00646417558159384,1,3.69911388019933E-8,,,,,,,,,,,,,,,,,,,,,4.99984216690063,5.00009393692017,-6500.00830078125,-6500.00830078125,53.6752120441018,5.64007525751039,2.82786917686462,53,1,68,0,0,0.298843383789063,34.2131004333496,1,1,3,4.99984216690063,0,4.9999680519104,,,,,,,,,,,,,,,,,,,,,,,,,,,,,,,,,
,3878477250.43197,4.99998307228088,-4500.50244140625,2.27224228147492E-5,1.16210902186929E-8,1,4,13.4005146026611,4.97569047630902,32.8699983656406,0.0280414822669306,0.00425674827555771,1,4.90567949899957E-8,,,,,,,,,,,,,,,,,,,,,4.99996423721313,5.00000190734863,-4500.50244140625,-4500.50244140625,53.5220128543326,5.64105020048823,2.83145809173584,52,1,68,0,0,0.297470092773438,34.2131004333496,1,1,3,4.99996423721313,0,4.99998307228088,,,,,,,,,,,,,,,,,,,,,,,,,,,,,,,,,
,3878477324.18248,4.99998450279236,-3000.1083984375,1.38217256132508E-5,8.27830331796222E-9,1,4,13.4005146026611,4.97567180548099,32.8599996864796,0.0170626524299689,0.00255248083896495,1,1.03908232734803E-11,,,,,,,,,,,,,,,,,,,,,4.99995946884155,5.00000953674316,-3000.1083984375,-3000.1083984375,53.5052078411691,5.64060520071627,2.82777404785156,54,1,0,0,1,0.299911499023438,34.2131004333496,1,1,3,5.00000953674316,0,4.99998450279236,,,,,,,,,,,,,,,,,,,,,,,,,,,,,,,,,
,3878477380.22151,4.99999785423279,-2800.23217773438,1.277718180704E-5,1.54416090950184E-8,1,4,13.4005146026611,4.97561514348061,32.8599996864796,0.0158055925638998,0.00214121054399582,1,-1.76856993715612E-7,,,,,,,,,,,,,,,,,,,,,4.99996280670166,5.00003290176392,-2800.23217773438,-2800.23217773438,53.6224521190538,5.64003235597095,2.83215546607971,54,1,0,0,1,0.296783447265625,34.2131004333496,1,1,3,4.99996280670166,0,4.99999785423279,,,,,,,,,,,,,,,,,,,,,,,,,,,,,,,,,
,3878477438.29819,4.99994874000549,-2600.2802734375,1.16227019808697E-5,1.99402129618296E-8,1,4,13.4005146026611,4.97558221341215,32.8599996864796,0.0143787808154046,0.0019381429492072,1,-1.68638317966349E-7,,,,,,,,,,,,,,,,,,,,,4.99970960617065,5.00018787384033,-2600.2802734375,-2600.2802734375,53.4633907153903,5.64027119992466,2.82714676856995,52,1,68,0,0,0.298385620117188,34.2131004333496,1,1,3,4.99970960617065,0,4.99994874000549,,,,,,,,,,,,,,,,,,,,,,,,,,,,,,,,,
,3878477494.52928,5.00026965141296,-2400.2275390625,1.04978918256959E-5,2.00730790885287E-8,1,4,13.4005146026611,4.97555257020651,32.8599996864796,0.0129906106780916,0.0017273394994841,1,-1.71129101144255E-7,,,,,,,,,,,,,,,,,,,,,5.00017690658569,5.00036239624023,-2400.2275390625,-2400.2275390625,53.528656696746,5.63999936903978,2.83720755577087,54,1,0,0,1,0.298995971679687,33.7243423461914,1,1,3,5.00017690658569,0,5.00026965141296,,,,,,,,,,,,,,,,,,,,,,,,,,,,,,,,,
,3878477552.21479,5.00006365776062,-2200.41430664062,9.3590945832862E-6,1.724895060193E-8,1,4,13.4005146026611,4.97557279611191,32.8599996864796,0.0115912199463578,0.00147481123377057,1,-2.05348090474857E-7,,,,,,,,,,,,,,,,,,,,,4.9999566078186,5.00017070770264,-2200.41430664062,-2200.41430664062,53.5599218375153,5.64090506446329,2.83493137359619,54,1,0,0,1,0.298004150390625,34.2131004333496,1,1,3,5.00017070770264,0,5.00006365776062,,,,,,,,,,,,,,,,,,,,,,,,,,,,,,,,,
,3878477610.26222,4.99996709823608,-2000.32397460938,8.21938582182165E-6,1.95907506847501E-8,1,4,13.4005146026611,4.98585388669097,32.8599996864796,0.010214676652288,0.00126257647358126,1,-2.09741063126219E-7,,,,,,,,,,,,,,,,,,,,,4.99986886978149,5.00006532669067,-2000.32397460938,-2000.32397460938,53.5435076386114,5.641217246111,2.83519315719604,54,1,0,0,1,0.298538208007812,34.2131004333496,1,1,3,4.99986886978149,0,4.99996709823608,,,,,,,,,,,,,,,,,,,,,,,,,,,,,,,,,
,3878477677.51755,4.99991774559021,-1800.05749511719,7.13371111282519E-6,1.94748434200064E-8,1,4,13.4005146026611,4.98594352536647,32.8599996864796,0.00887659347357971,0.00102283559972333,10,-2.409989740408E-7,,,,,,,,,,,,,,,,,,,,,4.99990463256836,4.99993085861206,-1800.05749511719,-1800.05749511719,53.6548897026018,5.64071973818936,2.82959485054016,54,1,0,0,1,0.299072265625,33.7243423461914,1,1,3,4.99993085861206,0,4.99991774559021,,,,,,,,,,,,,,,,,,,,,,,,,,,,,,,,,
,3878477744.21046,5.00015449523926,-1600.00500488281,5.98902269246357E-6,2.11899536160483E-8,1,4,13.4005146026611,4.9857810262135,32.8599996864796,0.00745318362415278,8.5007802966193E-4,1,-2.09268232488238E-7,,,,,,,,,,,,,,,,,,,,,5.00007677078247,5.00023221969604,-1600.00500488281,-1600.00500488281,53.5610942802941,5.6397643561809,2.82785606384277,53,1,68,0,0,0.298995971679687,34.2131004333496,1,1,3,5.00023221969604,0,5.00015449523926,,,,,,,,,,,,,,,,,,,,,,,,,,,,,,,,,
,3878477818.08066,4.99968242645264,-1399.96508789062,4.89716221776141E-6,2.15818938498725E-8,1,4,13.4005146026611,4.98575661096867,32.8599996864796,0.00610616131346953,6.1613728032259E-4,1,-2.34895443384879E-7,,,,,,,,,,,,,,,,,,,,,4.9996452331543,4.99971961975098,-1399.96508789062,-1399.96508789062,53.6478550459288,5.64054747555849,2.82719540596008,53,1,68,0,0,0.298843383789063,34.2131004333496,1,1,3,4.99971961975098,0,4.99968242645264,,,,,,,,,,,,,,,,,,,,,,,,,,,,,,,,,
,3878477875.65262,5.00005793571472,-1200.13903808594,3.78540610075728E-6,2.15565964071995E-8,1,4,13.4005146026611,4.98578972253927,32.8599996864796,0.00473027746511094,4.07440531589972E-4,1,-2.37163125395753E-7,,,,,,,,,,,,,,,,,,,,,4.99993085861206,5.00018501281738,-1200.13903808594,-1200.13903808594,53.523576111371,5.64033024831434,2.82893681526184,53,1,68,0,0,0.297698974609375,34.2131004333496,1,1,3,5.00018501281738,0,5.00005793571472,,,,,,,,,,,,,,,,,,,,,,,,,,,,,,,,,
,3878477934.5606,5.00002336502075,-1000.06127929688,2.72548367210885E-6,1.97578660890086E-8,1,4,13.4005146026611,4.98577602563756,32.8599996864796,0.00342080315056261,1.92900468939774E-4,1,-2.51899511605918E-7,,,,,,,,,,,,,,,,,,,,,4.99977970123291,5.00026702880859,-1000.06127929688,-1000.06127929688,53.4489305877845,5.64040911725262,2.82911658287048,53,1,68,0,0,0.299835205078125,33.7243423461914,1,1,3,4.99977970123291,0,5.00002336502075,,,,,,,,,,,,,,,,,,,,,,,,,,,,,,,,,
,3878478008.36381,5.00003719329834,-800.071716308594,2.1197668304505E-6,5.18114054857868E-7,1,4,13.4005146026611,4.98582108255406,32.8599996864796,0.00260966707986762,4.90445453374368E-4,1,7.90500283235309E-8,,,,,,,,,,,,,,,,,,,,,4.999831199646,5.00024318695068,-800.071716308594,-800.071716308594,53.4501030305633,5.64102424825045,2.82588720321655,52,1,68,0,0,0.297393798828125,33.7243423461914,1,1,3,5.00024318695068,0,5.00003719329834,,,,,,,,,,,,,,,,,,,,,,,,,,,,,,,,,
,3878478082.54901,4.99998307228088,-600.03173828125,6.8569643463119E-7,2.60295376290244E-8,1,4,13.4005146026611,4.98574339465052,32.8599996864796,8.9710142461214E-4,-1.95326176558104E-4,1,-2.60352847504669E-7,,,,,,,,,,,,,,,,,,,,,4.99987745285034,5.00008869171143,-600.03173828125,-600.03173828125,53.3883543775441,5.64006896186478,2.83464574813843,52,1,68,0,0,0.2978515625,34.2131004333496,1,1,3,4.99987745285034,0,4.99998307228088,,,,,,,,,,,,,,,,,,,,,,,,,,,,,,,,,
,3878478139.46098,4.99989676475525,-400.243560791016,-3.15107756789836E-7,2.15311976464686E-8,1,4,13.4005146026611,4.9858770855172,32.8599996864796,-3.47717247753647E-4,-3.41777005093111E-4,1,-2.28925600539496E-7,,,,,,,,,,,,,,,,,,,,,4.99980545043945,4.99998807907105,-400.243560791016,-400.243560791016,53.5392086817557,5.64051570374125,2.8306405544281,53,1,68,0,0,0.298080444335937,33.7243423461914,1,1,3,4.99980545043945,0,4.99989676475525,,,,,,,,,,,,,,,,,,,,,,,,,,,,,,,,,
,3878478196.19444,5.0002281665802,-200.153259277344,-1.24036482363182E-6,2.39964266609144E-8,1,4,13.4005146026611,4.98582670404221,32.8599996864796,-0.00149141494290207,-5.2504908439658E-4,1,-2.38553337669718E-7,,,,,,,,,,,,,,,,,,,,,5.00011777877808,5.00033855438232,-200.153259277344,-200.153259277344,53.3961706627364,5.64139952641446,2.83284544944763,54,1,0,0,1,0.299072265625,33.7243423461914,1,1,3,5.00033855438232,0,5.0002281665802,,,,,,,,,,,,,,,,,,,,,,,,,,,,,,,,,
,3878478270.5768,5.00001621246338,-0.138470813632011,-2.037324039459E-6,2.59403816379189E-8,1,4,13.4005146026611,4.98582900636954,32.8599996864796,-0.0024776526577443,-6.75416621776863E-4,1,-2.40790991656601E-7,,,,,,,,,,,,,,,,,,,,,4.99998950958252,5.00004291534424,-0.138470813632011,-0.138470813632011,53.2523510151979,5.6413886533839,2.83113980293274,52,1,68,0,0,0.297927856445313,33.7243423461914,1,1,3,4.99998950958252,0,5.00001621246338,,,,,,,,,,,,,,,,,,,,,,,,,,,,,,,,,
,3878478327.75308,5.0000274181366,199.914077758789,-2.69383328063146E-6,2.90947934786279E-8,1,4,13.4005146026611,4.98584679812915,32.8599996864796,-0.00330466048579068,-7.01948650853717E-4,1,-1.64009438696757E-7,,,,,,,,,,,,,,,,,,,,,4.99980068206787,5.00025415420532,199.914077758789,199.914077758789,53.5814166217941,5.64128448550294,2.82830166816711,54,1,0,0,1,0.298614501953125,33.7243423461914,1,1,3,5.00025415420532,0,5.0000274181366,,,,,,,,,,,,,,,,,,,,,,,,,,,,,,,,,
,3878478386.13615,4.99995374679565,399.740020751953,-3.30666807689479E-6,1.5683176661721E-8,1,4,13.4005146026611,4.98584495057824,32.8599996864796,-0.00406827263439954,-7.82630692482099E-4,1,-1.37503373254923E-7,,,,,,,,,,,,,,,,,,,,,4.9999361038208,4.99997138977051,399.740020751953,399.740020751953,53.4813681713326,5.64179419795949,2.83503603935242,52,1,68,0,0,0.300674438476562,34.2131004333496,1,1,3,4.99997138977051,0,4.99995374679565,,,,,,,,,,,,,,,,,,,,,,,,,,,,,,,,,
,3878478444.04782,4.99990940093994,599.767456054687,-3.99403627096217E-6,1.69485666059841E-8,1,4,13.4005146026611,4.9857313790006,32.8599996864796,-0.00490843439564945,-9.81163890563809E-4,1,-1.95065455576518E-7,,,,,,,,,,,,,,,,,,,,,4.99990081787109,4.99991798400879,599.767456054687,599.767456054687,53.5122424978422,5.64028771371499,2.83334565162659,54,1,0,0,1,0.2972412109375,33.7243423461914,1,1,3,4.99991798400879,0,4.99990940093994,,,,,,,,,,,,,,,,,,,,,,,,,,,,,,,,,
,3878478501.73938,5.0000946521759,799.681457519531,-4.87452286379834E-6,2.14148264767204E-8,1,4,13.4005146026611,4.98583352281136,32.8599996864796,-0.00599593345746643,-0.00116232788806044,1,-2.09660825947327E-7,,,,,,,,,,,,,,,,,,,,,5.00004482269287,5.00014448165894,799.681457519531,799.681457519531,53.4876211994864,5.64102217268273,2.82386946678162,54,1,0,0,1,0.2972412109375,34.2131004333496,1,1,3,5.00014448165894,0,5.0000946521759,,,,,,,,,,,,,,,,,,,,,,,,,,,,,,,,,
,3878478559.38629,5.00011038780212,999.796936035156,-5.81277094820355E-6,8.34099015489681E-8,1,4,13.4005146026611,4.9857493176467,32.8599996864796,-0.00715700007597145,-0.00133829859283562,1,-2.1146898144665E-7,,,,,,,,,,,,,,,,,,,,,4.99989080429077,5.00032997131348,999.796936035156,999.796936035156,53.5818074360538,5.63986607341124,2.82758402824402,54,1,0,0,1,0.2984619140625,34.2131004333496,1,1,3,5.00032997131348,0,5.00011038780212,,,,,,,,,,,,,,,,,,,,,,,,,,,,,,,,,
,3878478616.97358,5.00007963180542,1199.71105957031,-6.75831661545995E-6,2.10972909336666E-8,1,4,13.4005146026611,4.98563319594053,32.8599996864796,-0.00833637086179211,-0.00145276318408687,1,-1.62519397753808E-7,,,,,,,,,,,,,,,,,,,,,4.99995803833008,5.00020122528076,1199.71105957031,1199.71105957031,53.440332674073,5.6412963746954,2.82449126243591,52,1,68,0,0,0.2984619140625,34.2131004333496,1,1,3,5.00020122528076,0,5.00007963180542,,,,,,,,,,,,,,,,,,,,,,,,,,,,,,,,,
,3878478690.39744,5.0000205039978,1399.80139160156,-7.79464958322152E-6,1.22910361332259E-8,1,4,13.4005146026611,4.9856323289797,32.8599996864796,-0.00962153297849502,-0.00162974362224863,1,-1.50453031379323E-7,,,,,,,,,,,,,,,,,,,,,4.99979782104492,5.00024318695068,1399.80139160156,1399.80139160156,53.3922625201403,5.6413627493445,2.82572436332703,53,1,68,0,0,0.298004150390625,33.7243423461914,1,1,3,4.99979782104492,0,5.0000205039978,,,,,,,,,,,,,,,,,,,,,,,,,,,,,,,,,
,3878478765.14268,4.99996709823608,1599.51403808594,-8.79222264764599E-6,7.6029704412027E-8,1,4,13.4005146026611,4.98571003996108,32.8599996864796,-0.0108519001199842,-0.00184672376717945,1,-1.76463223880864E-7,,,,,,,,,,,,,,,,,,,,,4.99990129470825,5.00003290176392,1599.51403808594,1599.51403808594,53.4934834133807,5.64098269019024,2.8271963596344,53,1,68,0,0,0.297622680664063,34.2131004333496,1,1,3,5.00003290176392,0,4.99996709823608,,,,,,,,,,,,,,,,,,,,,,,,,,,,,,,,,
,3878478823.89972,4.99999904632568,1799.55395507813,-9.96049998201996E-6,9.47936536226424E-8,1,4,13.4005146026611,4.9856258344781,32.8599996864796,-0.0122938043699972,-0.00209048233601989,1,-1.98636666365679E-7,,,,,,,,,,,,,,,,,,,,,4.99998950958252,5.00000858306885,1799.55395507813,1799.55395507813,53.5431168243518,5.64043985556838,2.82491230964661,52,1,68,0,0,0.2978515625,34.2131004333496,1,1,3,5.00000858306885,0,4.99999904632568,,,,,,,,,,,,,,,,,,,,,,,,,,,,,,,,,
,3878478881.35863,5.00014686584473,2000.02185058594,-1.10568658967951E-5,1.35790150809939E-8,1,4,13.4005146026611,4.98574493255431,32.8599996864796,-0.0136645797175881,-0.00220620480105527,1,-1.28046560412825E-7,,,,,,,,,,,,,,,,,,,,,5.00009632110596,5.0001974105835,2000.02185058594,2000.02185058594,53.6212796762749,5.63996913318691,2.82424139976501,54,1,0,0,1,0.298690795898438,34.2131004333496,1,1,3,5.00009632110596,0,5.00014686584473,,,,,,,,,,,,,,,,,,,,,,,,,,,,,,,,,
,3878478939.08406,4.99990653991699,2199.93603515625,-1.22340681113966E-5,4.03721776839934E-8,1,4,13.4005146026611,4.98576664066125,32.8599996864796,-0.0151254423932451,-0.00240146859042308,1,-1.09658933763299E-7,,,,,,,,,,,,,,,,,,,,,4.99975252151489,5.00006055831909,2199.93603515625,2199.93603515625,53.5610942802941,5.64009764399182,2.82297658920288,54,1,0,0,1,0.298385620117188,33.7243423461914,1,1,3,5.00006055831909,0,4.99990653991699,,,,,,,,,,,,,,,,,,,,,,,,,,,,,,,,,
,3878478996.67239,4.99990153312683,2399.8876953125,-1.33055716873521E-5,8.47498081263687E-9,1,4,13.4005146026611,4.98573882213475,32.8599996864796,-0.0164551123821397,-0.00257796435695872,1,-9.19503734252778E-8,,,,,,,,,,,,,,,,,,,,,4.99976825714111,5.00003480911255,2399.8876953125,2399.8876953125,53.5431168243518,5.64015020893372,2.83204936981201,54,1,0,0,1,0.297927856445313,33.7243423461914,1,1,3,5.00003480911255,0,4.99990153312683,,,,,,,,,,,,,,,,,,,,,,,,,,,,,,,,,
,3878479054.2711,5.00005531311035,2599.77685546875,-1.44539228876827E-5,8.14472793921891E-9,1,4,13.4005146026611,4.98567404603155,32.8599996864796,-0.0178777628525202,-0.00278168562975845,1,-8.47633809585455E-8,,,,,,,,,,,,,,,,,,,,,4.99998426437378,5.00012636184692,2599.77685546875,2599.77685546875,53.4094583475633,5.64025125846441,2.82809901237488,54,1,0,0,1,0.297470092773438,33.7243423461914,1,1,3,5.00012636184692,0,5.00005531311035,,,,,,,,,,,,,,,,,,,,,,,,,,,,,,,,,
,3878479112.88483,5.00017261505127,2799.98046875,-1.55925316090525E-5,1.23244900425358E-8,1,4,13.4005146026611,4.98579596169189,32.8599996864796,-0.0192883088339985,-0.0029904707447254,1,-8.3003457979227E-8,,,,,,,,,,,,,,,,,,,,,5.00001668930054,5.000328540802,2799.98046875,2799.98046875,53.6122909483037,5.6403871788391,2.82854127883911,54,1,0,0,1,0.297164916992188,33.7243423461914,1,1,3,5.000328540802,0,5.00017261505127,,,,,,,,,,,,,,,,,,,,,,,,,,,,,,,,,
,3878479170.62983,5.00005912780762,2999.80639648438,-1.67371702645837E-5,1.49049431183042E-8,1,4,13.4005146026611,4.98560562076275,32.8599996864796,-0.0207046152269382,-0.00319999060095543,1,-8.11504640456749E-8,,,,,,,,,,,,,,,,,,,,,4.99987649917603,5.00024175643921,2999.80639648438,2999.80639648438,53.3387209665729,5.63964885630739,2.82818508148193,54,1,0,0,1,0.29998779296875,34.2131004333496,1,1,3,4.99987649917603,0,5.00005912780762,,,,,,,,,,,,,,,,,,,,,,,,,,,,,,,,,
,3878479249.28672,5.00012612342834,4499.55810546875,-2.56857769097174E-5,2.14365656968761E-8,1,4,13.4005146026611,4.98570085405347,32.8599996864796,-0.0318046806108257,-0.00471451790060982,1,3.41843856110925E-8,,,,,,,,,,,,,,,,,,,,,4.99993705749512,5.00031518936157,4499.55810546875,4499.55810546875,53.2937773267172,5.64008110564161,2.8286349773407,54,1,0,0,1,0.298690795898438,33.7243423461914,1,1,3,5.00031518936157,0,5.00012612342834,,,,,,,,,,,,,,,,,,,,,,,,,,,,,,,,,
,3878479314.06847,5.00013065338135,6499.56787109375,-3.77282399824969E-5,1.21376399304402E-8,1,4,13.4005146026611,4.98566539028449,32.8599996864796,-0.0467186882386197,-0.00690315232641972,1,6.76921944400749E-8,,,,,,,,,,,,,,,,,,,,,5.00003099441528,5.00023031234741,6499.56787109375,6499.56787109375,53.5833706930922,5.64024766026463,2.82255482673645,54,1,0,0,1,0.297393798828125,34.2131004333496,1,1,3,5.00003099441528,0,5.00013065338135,,,,,,,,,,,,,,,,,,,,,,,,,,,,,,,,,
,3878479378.58366,5.00006794929504,8500.0556640625,-4.98008512497767E-5,1.41762469037534E-8,1,4,13.4005146026611,4.98559224548739,32.8599996864796,-0.0616646686272422,-0.00912662820894068,1,7.74520802228889E-8,,,,,,,,,,,,,,,,,,,,,5.00003480911255,5.00010108947754,8500.0556640625,8500.0556640625,53.7307076689672,5.64043427097728,2.82979989051819,52,1,68,0,0,0.297775268554687,34.2131004333496,1,1,3,5.00010108947754,0,5.00006794929504,,,,,,,,,,,,,,,,,,,,,,,,,,,,,,,,,
,3878479455.95046,4.9998722076416,10000.072265625,-5.88116045846083E-5,1.72432088599578E-8,1,4,13.4005146026611,4.98567151579893,32.8599996864796,-0.0728163653338571,-0.0108267943590681,1,5.22138844952039E-8,,,,,,,,,,,,,,,,,,,,,4.99979448318481,4.99994993209839,10000.072265625,10000.072265625,53.4501030305633,5.63962225801872,2.825847864151,54,1,0,0,1,0.297927856445313,33.7243423461914,1,1,3,4.99979448318481,0,4.9998722076416,,,,,,,,,,,,,,,,,,,,,,,,,,,,,,,,,
,3878479609.45346,4.99989247322082,30000.2421875,-1.81546504222019E-4,5.62835256078144E-8,1,4,13.4005146026611,4.98576314015777,32.8599996864796,-0.224771218981488,-0.0335065276550343,1,9.31203117714205E-8,,,,,,,,,,,,,,,,,,,,,4.99979066848755,4.9999942779541,30000.2421875,30000.2421875,53.8018358642172,5.64074965291603,2.8230676651001,54,1,0,0,1,0.297470092773438,33.7243423461914,1,1,3,4.9999942779541,0,4.99989247322082,,,,,,,,,,,,,,,,,,,,,,,,,,,,,,,,,
,3878479784.38144,4.99984169006348,50000.41015625,-3.06056192601158E-4,8.25534413206009E-8,1,4,13.4005146026611,4.9857166653749,32.8599996864796,-0.378891488587649,-0.056680615357422,1,-6.17875550412032E-10,,,,,,,,,,,,,,,,,,,,,4.99976110458374,4.99992227554321,50000.41015625,50000.41015625,54.3110668444961,5.64242234095433,2.82510280609131,54,1,0,0,1,0.298385620117188,33.7243423461914,1,1,3,4.99976110458374,0,4.99984169006348,,,,,,,,,,,,,,,,,,,,,,,,,,,,,,,,,
,3878479959.88477,4.9999988079071,70000.1796875,-4.3161327415751E-4,2.27611561296802E-7,1,4,13.4005146026611,4.9858345070148,32.8599996864796,-0.534366168572722,-0.0798037241260955,1,1.05997508222743E-7,,,,,,,,,,,,,,,,,,,,,4.99996185302734,5.00003576278687,70000.1796875,70000.1796875,54.5510267999,5.64336607344615,2.82324862480164,52,1,68,0,0,0.298004150390625,33.7243423461914,1,1,3,4.99996185302734,0,4.9999988079071,,,,,,,,,,,,,,,,,,,,,,,,,,,,,,,,,