File: SQUID/22163_LCOT/LCOT_MH_100K_FC+1T.dat
[Header]
; MPMS3 Data File (default extension .dat)
; Copyright (c) 2007, Quantum Design, Inc. All rights reserved.
TITLE,
FILEOPENTIME,3878501785.849,11/25/2022,1:37 am
BYAPP,SQUID AC,0.9.1.0
INFO,MPMS3 Measurement Release 1.1.16 Build 347, MultiVu Release 2.3.3.2,APPNAME
INFO,0,MOMENT_UNITS
INFO,LCOT,SAMPLE_MATERIAL
INFO,,SAMPLE_COMMENT
INFO,1.8,SAMPLE_MASS
INFO,,SAMPLE_VOLUME
INFO,,SAMPLE_MOLECULAR_WEIGHT
INFO,,SAMPLE_SIZE
INFO,,SAMPLE_SHAPE
INFO,Quartz,SAMPLE_HOLDER
INFO,Standard,SAMPLE_HOLDER_DETAIL
INFO,65.79,SAMPLE_OFFSET
DATATYPE,COMMENT,1
DATATYPE,TIME,2
STARTUPAXIS,X,2
STARTUPAXIS,Y1,5
FIELDGROUP, VSM,2,3,4,5,6,8,9,10,11,14,15
FIELDGROUP, DC, 2,3,4,14,56,57,58,59,60,61,62,63,64,65,66,67,68,69
FIELDGROUP, AC, 2,3,4,11,16,17,18,19,20,21,22,23,24,25,26,27,28,29,30
STARTUPGROUP, All
[Data]
Comment,Time Stamp (sec),Temperature (K),Magnetic Field (Oe),Moment (emu),M. Std. Err. (emu),Transport Action,Averaging Time (sec),Frequency (Hz),Peak Amplitude (mm),Center Position (mm),Lockin Signal' (V),Lockin Signal (V),Range,M. Quad. Signal (emu),AC Moment (emu),AC M. Std Err. (emu),AC Phase (deg),AC Phase Std. Err. (deg),AC Susceptibility (emu/Oe),AC Suscept. Std Err. (emu/Oe),AC X' (emu/Oe),AC X' Std Err. (emu/Oe),AC X'' (emu/Oe),AC X'' Std Err. (emu/Oe),AC Drive (Oe),AC Frequency (Hz),AC Averaging Time (sec),AC Cycles,AC Range,AC Measure Type,AC Signal' (V),AC Signal'' (V),AC Trim Coil Ratio,AC Trim Coil Phase,Min. Temperature (K),Max. Temperature (K),Min. Field (Oe),Max. Field (Oe),Mass (grams),Motor Lag (deg),Pressure (Torr),Measure Count,Measurement Number,SQUID Status (code),Motor Status (code),Measure Status (code),Motor Current (amps),Motor Temp. (C),Temp. Status (code),Field Status (code),Chamber Status (code),Chamber Temp (K),Redirection State,Average Temp (K),Rotation Angle (deg),Rotator state,DC Moment Fixed Ctr (emu),DC Moment Err Fixed Ctr (emu),DC Moment Free Ctr (emu),DC Moment Err Free Ctr (emu),DC Fixed Fit,DC Free Fit,DC Calculated Center (mm),DC Calculated Center Err (mm),DC Scan Length (mm),DC Scan Time (s),DC Number of Points,DC Squid Drift,DC Min V (V),DC Max V (V),DC Scans per Measure,Sample Resistance,He3 Temperature,Sorb Resistance,Sorb Temperature,Map 05,Map 06,Map 07,Map 08,Map 09,Map 10,Map 11,Map 12,Map 13,Map 14,Map 15,Map 16
,3878501829.19283,99.9954643249512,69999.7265625,-0.000447307813081769,8.4808316680509E-8,1,4,13.4005146026611,5.00602984507863,32.8899994492531,-0.556959154528226,-0.0830535017344402,1,2.07522448129543E-7,,,,,,,,,,,,,,,,,,,,,99.9953994750977,99.9955291748047,69999.7265625,69999.7265625,53.2234307599864,5.64105800269429,4.87973165512085,54,1,0,0,1,0.301971435546875,32.7468223571777,1,1,3,99.9955291748047,0,99.9954643249512,,,,,,,,,,,,,,,,,,,,,,,,,,,,,,,,,
,3878502000.78837,100.034362792969,49999.84375,-0.000318429505158306,5.8410262696135E-8,1,4,13.4005146026611,5.00522543208657,32.8899994492531,-0.396374021122247,-0.0592779816926678,1,1.34610112114774E-8,,,,,,,,,,,,,,,,,,,,,100.032211303711,100.036514282227,49999.84375,49999.84375,53.447367330746,5.64406659641238,4.88861227035522,53,1,68,0,0,0.303268432617188,34.2131004333496,1,1,3,100.032211303711,0,100.034362792969,,,,,,,,,,,,,,,,,,,,,,,,,,,,,,,,,
,3878502175.28313,100.05883026123,29999.7265625,-0.000189890070921894,3.25358030046894E-8,1,4,13.4005146026611,5.00574600491562,32.8899994492531,-0.236405115659835,-0.0353561110257149,1,6.78686491199657E-9,,,,,,,,,,,,,,,,,,,,,100.041488647461,100.076171875,29999.7265625,29999.7265625,53.4231368466499,5.64181457504022,4.89697790145874,54,1,0,0,1,0.301361083984375,34.7018585205078,1,1,3,100.076171875,0,100.05883026123,,,,,,,,,,,,,,,,,,,,,,,,,,,,,,,,,
,3878502334.19849,100.097328186035,9999.59375,-6.13414861784832E-5,1.6382138891237E-8,1,4,13.4005146026611,5.00602257768299,32.8899994492531,-0.0763699445617578,-0.011445697489247,1,-1.66736938536748E-8,,,,,,,,,,,,,,,,,,,,,100.091835021973,100.102821350098,9999.59375,9999.59375,53.5513239238037,5.64016030851962,4.88943672180176,52,1,68,0,0,0.302276611328125,34.2131004333496,1,1,3,100.102821350098,0,100.097328186035,,,,,,,,,,,,,,,,,,,,,,,,,,,,,,,,,
,3878502418.14667,100.181804656982,8499.8671875,-5.17006969019105E-5,1.34437517613867E-8,1,4,13.4005146026611,5.00603404326282,32.8899994492531,-0.0643684363242187,-0.00963993005690804,1,-8.49106482931464E-9,,,,,,,,,,,,,,,,,,,,,100.180885314941,100.182723999023,8499.8671875,8499.8671875,53.4501030305633,5.63948994077635,4.90497493743897,54,1,0,0,1,0.302200317382812,34.2131004333496,1,1,3,100.182723999023,0,100.181804656982,,,,,,,,,,,,,,,,,,,,,,,,,,,,,,,,,
,3878502487.04287,100.302272796631,6499.66845703125,-3.88770821921105E-5,9.30101510468296E-9,1,4,13.4005146026611,5.00612945860069,32.8899994492531,-0.0484026867180564,-0.00725826290327575,1,-1.37625914109002E-8,,,,,,,,,,,,,,,,,,,,,100.300163269043,100.304382324219,6499.66845703125,6499.66845703125,53.5278750682268,5.63949726940183,4.8978910446167,54,1,0,0,1,0.300750732421875,34.7018585205078,1,1,3,100.304382324219,0,100.302272796631,,,,,,,,,,,,,,,,,,,,,,,,,,,,,,,,,
,3878502553.55293,100.214530944824,4499.57080078125,-2.60564950386859E-5,8.05284839809483E-8,1,4,13.4005146026611,5.0056709740528,32.8899994492531,-0.0324195901131142,-0.00497820262411228,1,-1.00906016421779E-7,,,,,,,,,,,,,,,,,,,,,100.211036682129,100.21802520752,4499.57080078125,4499.57080078125,53.5544504378807,5.64194843353905,4.90674877166748,52,1,68,0,0,0.300750732421875,34.2131004333496,1,1,3,100.21802520752,0,100.214530944824,,,,,,,,,,,,,,,,,,,,,,,,,,,,,,,,,
,3878502638.78728,100.162132263184,2999.79370117188,-1.65920250025729E-5,6.12348878398473E-9,1,4,13.4005146026611,5.00596979749579,32.8899994492531,-0.0206610741590369,-0.00306669053464973,1,1.89167243746371E-8,,,,,,,,,,,,,,,,,,,,,100.162017822266,100.162246704102,2999.79370117188,2999.79370117188,53.5778992934576,5.63942990309153,4.90172481536865,54,1,0,0,1,0.30181884765625,34.7018585205078,1,1,3,100.161758422852,0,100.162132263184,,,,,,,,,,,,,,,,,,,,,,,,,,,,,,,,,
,3878502698.49613,100.142955780029,2799.59008789062,-1.54285994453259E-5,1.65394244997096E-8,1,4,13.4005146026611,5.00616340547483,32.8899994492531,-0.0192463752775093,-0.00263116090389947,1,1.94804570989772E-7,,,,,,,,,,,,,,,,,,,,,100.139442443848,100.146469116211,2799.59008789062,2799.59008789062,53.4399418598133,5.63921109721447,4.90841579437256,52,1,68,0,0,0.302963256835937,34.2131004333496,1,1,3,100.146469116211,0,100.142955780029,,,,,,,,,,,,,,,,,,,,,,,,,,,,,,,,,
,3878502760.08311,100.077423095703,2599.7138671875,-1.41634105596299E-5,1.58151241489609E-8,1,4,13.4005146026611,5.00614809906395,32.8899994492531,-0.0176725564335602,-0.00238521281600392,1,2.03065310552833E-7,,,,,,,,,,,,,,,,,,,,,100.075569152832,100.079277038574,2599.7138671875,2599.7138671875,53.4813681713326,5.63860322159214,4.90207958221436,52,1,68,0,0,0.300445556640625,34.7018585205078,1,1,3,100.075569152832,0,100.077423095703,,,,,,,,,,,,,,,,,,,,,,,,,,,,,,,,,
,3878502817.98694,100.1037940979,2399.58569335938,-1.29356341062411E-5,1.73375680251092E-8,1,4,13.4005146026611,5.00615933103284,32.8899994492531,-0.0161454811757421,-0.00214605866869661,1,2.11480578452536E-7,,,,,,,,,,,,,,,,,,,,,100.099800109863,100.107788085938,2399.58569335938,2399.58569335938,53.4458040737076,5.63918314070193,4.91315603256226,52,1,68,0,0,0.301132202148438,34.7018585205078,1,1,3,100.107788085938,0,100.1037940979,,,,,,,,,,,,,,,,,,,,,,,,,,,,,,,,,
,3878502893.25175,100.063774108887,2199.54565429687,-1.1686284392412E-5,1.77723038394305E-8,1,4,13.4005146026611,5.00619372200003,32.8899994492531,-0.0145903725359557,-0.00191130213670038,1,2.13145402025745E-7,,,,,,,,,,,,,,,,,,,,,100.060874938965,100.066673278809,2199.54565429687,2199.54565429687,53.5384270532364,5.63833745300833,4.91505908966064,54,1,0,0,1,0.302963256835937,34.7018585205078,1,1,3,100.060874938965,0,100.063774108887,,,,,,,,,,,,,,,,,,,,,,,,,,,,,,,,,
,3878502950.51412,100.190773010254,1999.66943359375,-1.04615436333039E-5,2.25288449350329E-8,1,4,13.4005146026611,5.00620826883825,32.8899994492531,-0.0130657985108608,-0.00168114334856106,1,2.1478785379109E-7,,,,,,,,,,,,,,,,,,,,,100.18643951416,100.195106506348,1999.66943359375,1999.66943359375,53.4610458298326,5.639246083527,4.90784502029419,54,1,0,0,1,0.300521850585937,34.7018585205078,1,1,3,100.18643951416,0,100.190773010254,,,,,,,,,,,,,,,,,,,,,,,,,,,,,,,,,
,3878503009.14256,100.287364959717,1799.55395507813,-9.22687709106085E-6,1.84951343212963E-8,1,4,13.4005146026611,5.00625194921278,32.8899994492531,-0.0115285853741907,-0.00145156401556352,1,2.14488070847441E-7,,,,,,,,,,,,,,,,,,,,,100.283920288086,100.290809631348,1799.55395507813,1799.55395507813,53.5263118111883,5.63908841431033,4.90884351730347,53,1,68,0,0,0.302734375,34.7018585205078,1,1,3,100.290809631348,0,100.287364959717,,,,,,,,,,,,,,,,,,,,,,,,,,,,,,,,,
,3878503083.1316,100.204601287842,1599.56433105469,-8.0254017322028E-6,2.02605232320863E-8,1,4,13.4005146026611,5.00627656500044,32.8899994492531,-0.0100248692351434,-0.00127989381419066,1,1.72635466831901E-7,,,,,,,,,,,,,,,,,,,,,100.199775695801,100.209426879883,1599.56433105469,1599.56433105469,53.4540111731595,5.63972002913145,4.91674518585205,54,1,0,0,1,0.300979614257812,34.2131004333496,1,1,3,100.199775695801,0,100.204601287842,,,,,,,,,,,,,,,,,,,,,,,,,,,,,,,,,
,3878503139.71511,100.14826965332,1399.7509765625,-6.81200512658354E-6,1.9309530029767E-8,1,4,13.4005146026611,5.00616036479727,32.8899994492531,-0.00851624981229637,-0.00103713364035947,1,1.86058632719202E-7,,,,,,,,,,,,,,,,,,,,,100.145858764648,100.150680541992,1399.7509765625,1399.7509765625,53.4774600287364,5.63930296248803,4.91549491882324,54,1,0,0,1,0.29998779296875,34.2131004333496,1,1,3,100.145858764648,0,100.14826965332,,,,,,,,,,,,,,,,,,,,,,,,,,,,,,,,,
,3878503198.23364,100.224166870117,1199.63562011719,-5.64847663093425E-6,5.73009652875863E-8,1,4,13.4005146026611,5.00622516308232,32.8899994492531,-0.00707175622116905,-0.000793142542827084,1,2.07975266147853E-7,,,,,,,,,,,,,,,,,,,,,100.221527099609,100.226806640625,1199.63562011719,1199.63562011719,53.4289990605441,5.63859394437427,4.90907955169678,54,1,0,0,1,0.300750732421875,34.2131004333496,1,1,3,100.221527099609,0,100.224166870117,,,,,,,,,,,,,,,,,,,,,,,,,,,,,,,,,
,3878503254.53317,100.284725189209,999.771789550781,-4.44061999799986E-6,2.29026811588516E-8,1,4,13.4005146026611,5.00621391525209,32.8899994492531,-0.00557520733286907,-0.000518747237906921,1,2.4766304129422E-7,,,,,,,,,,,,,,,,,,,,,100.275253295898,100.29419708252,999.771789550781,999.771789550781,53.513414940621,5.63851205675254,4.92025852203369,54,1,0,0,1,0.299224853515625,34.2131004333496,1,1,3,100.29419708252,0,100.284725189209,,,,,,,,,,,,,,,,,,,,,,,,,,,,,,,,,
,3878503310.63811,100.249549865723,799.882873535156,-3.28714471134738E-6,2.49019035766287E-8,1,4,13.4005146026611,5.0062133976641,32.8899994492531,-0.00414124609113567,-0.000288876216239418,1,2.59728690770133E-7,,,,,,,,,,,,,,,,,,,,,100.246025085449,100.253074645996,799.882873535156,799.882873535156,53.4661264152076,5.63934071154428,4.92166709899902,52,1,68,0,0,0.3009033203125,34.7018585205078,1,1,3,100.253074645996,0,100.249549865723,,,,,,,,,,,,,,,,,,,,,,,,,,,,,,,,,
,3878503367.83019,100.130851745605,600.03173828125,-2.22660314915026E-6,2.40691391180315E-8,1,4,13.4005146026611,5.00623106241427,32.8899994492531,-0.00281218673970436,-0.00014868415700893,1,2.13672580870536E-7,,,,,,,,,,,,,,,,,,,,,100.125526428223,100.136177062988,600.03173828125,600.03173828125,53.4110216046018,5.63861127032784,4.92264080047607,54,1,0,0,1,0.300064086914063,34.2131004333496,1,1,3,100.125526428223,0,100.130851745605,,,,,,,,,,,,,,,,,,,,,,,,,,,,,,,,,
,3878503432.70498,100.095924377441,399.954040527344,-1.05715878828481E-6,2.35710850377713E-7,1,4,13.4005146026611,5.00632643726053,32.8899994492531,-0.00140846391402045,0.000419017379514096,10,4.94663250246491E-7,,,,,,,,,,,,,,,,,,,,,100.085540771484,100.106307983398,399.954040527344,399.954040527344,53.4762875859576,5.63844729304893,4.91892099380493,54,1,0,0,1,0.300750732421875,34.2131004333496,1,1,3,100.106307983398,0,100.095924377441,,,,,,,,,,,,,,,,,,,,,,,,,,,,,,,,,
,3878503522.81071,100.09659576416,200.16584777832,-1.94068962868431E-7,2.44611198654478E-8,1,4,13.4005146026611,5.00633625148108,32.8899994492531,-0.000291084589362006,0.000294335329045822,10,2.65415754996454E-7,,,,,,,,,,,,,,,,,,,,,100.082786560059,100.110404968262,200.16584777832,200.16584777832,53.4837130568903,5.63736310004485,4.91821575164795,54,1,0,0,1,0.299224853515625,34.2131004333496,1,1,3,100.110404968262,0,100.09659576416,,,,,,,,,,,,,,,,,,,,,,,,,,,,,,,,,
,3878503614.64156,100.076168060303,0.302118122577667,6.38487454952311E-7,6.34737358692681E-8,1,4,13.4005146026611,5.00642452756866,32.8899994492531,0.000762103829894629,0.000339078484494497,10,1.76797493697411E-7,,,,,,,,,,,,,,,,,,,,,100.067878723145,100.084457397461,0.302118122577667,0.302118122577667,53.4954374846787,5.63826483115448,4.9167013168335,54,1,0,0,1,0.301055908203125,34.2131004333496,1,1,3,100.084457397461,0,100.076168060303,,,,,,,,,,,,,,,,,,,,,,,,,,,,,,,,,
,3878503696.38759,100.031890869141,-199.83854675293,1.31688202398595E-6,3.02423111042659E-8,1,4,13.4005146026611,5.00632817041351,32.8899994492531,0.00160375913113566,0.000485684190305417,1,1.93062238422186E-7,,,,,,,,,,,,,,,,,,,,,100.030311584473,100.033470153809,-199.83854675293,-199.83854675293,53.4747243289191,5.6387592810322,4.91756248474121,54,1,0,0,1,0.299911499023438,34.2131004333496,1,1,3,100.030311584473,0,100.031890869141,,,,,,,,,,,,,,,,,,,,,,,,,,,,,,,,,
,3878503754.13941,100.115989685059,-399.865905761719,2.02776227300105E-6,1.50175596827007E-8,1,4,13.4005146026611,5.00642383788098,32.8899994492531,0.00249811332983896,0.000557064852107858,1,1.440337735801E-7,,,,,,,,,,,,,,,,,,,,,100.108818054199,100.123161315918,-399.865905761719,-399.865905761719,53.521622040073,5.63868476858969,4.91666126251221,53,1,68,0,0,0.300827026367188,33.7243423461914,1,1,3,100.123161315918,0,100.115989685059,,,,,,,,,,,,,,,,,,,,,,,,,,,,,,,,,
,3878503844.94888,100.117744445801,-599.742248535156,2.8515018907114E-6,1.98070113266069E-8,1,4,13.4005146026611,5.0063017801987,32.8899994492531,0.00351227039420089,0.000786904260014785,1,2.05411211969576E-7,,,,,,,,,,,,,,,,,,,,,100.106567382813,100.128921508789,-599.742248535156,-599.742248535156,53.5095067980249,5.63925488271686,4.92826700210571,54,1,0,0,1,0.300140380859375,34.2131004333496,1,1,3,100.128921508789,0,100.117744445801,,,,,,,,,,,,,,,,,,,,,,,,,,,,,,,,,
,3878503920.21683,100.074493408203,-799.845153808594,3.81624062890202E-6,1.83909210767406E-8,1,4,13.4005146026611,5.00630341936587,32.8899994492531,0.00470703367046575,0.0010099057974006,1,2.40188800421077E-7,,,,,,,,,,,,,,,,,,,,,100.070861816406,100.078125,-799.845153808594,-799.845153808594,53.4227460323903,5.6385562439587,4.92193984985352,54,1,0,0,1,0.298919677734375,34.2131004333496,1,1,3,100.070861816406,0,100.074493408203,,,,,,,,,,,,,,,,,,,,,,,,,,,,,,,,,
,3878503995.14171,100.099094390869,-999.696228027344,4.88295451859551E-6,5.33873697198297E-8,1,4,13.4005146026611,5.00627452139648,32.8899994492531,0.00605189379220639,0.00109698349407773,1,1.50555865926536E-7,,,,,,,,,,,,,,,,,,,,,100.095588684082,100.102600097656,-999.696228027344,-999.696228027344,53.4551836159384,5.63914996248069,4.92694759368897,54,1,0,0,1,0.30059814453125,34.2131004333496,1,1,3,100.095588684082,0,100.099094390869,,,,,,,,,,,,,,,,,,,,,,,,,,,,,,,,,
,3878504069.45318,100.120735168457,-1199.56005859375,6.02888907972665E-6,1.73649170899577E-8,1,4,13.4005146026611,5.00623976601069,32.8899994492531,0.00747926303978489,0.0013064152596133,1,1.47341359643477E-7,,,,,,,,,,,,,,,,,,,,,100.113510131836,100.127960205078,-1199.56005859375,-1199.56005859375,53.4114124188614,5.63945349324631,4.92051124572754,52,1,68,0,0,0.301284790039063,34.2131004333496,1,1,3,100.127960205078,0,100.120735168457,,,,,,,,,,,,,,,,,,,,,,,,,,,,,,,,,
,3878504161.31971,100.089660644531,-1399.57482910156,7.18325801532304E-6,1.43121745703591E-8,1,4,13.4005146026611,5.00626940013042,32.8899994492531,0.00891515925753832,0.00153152874977961,1,1.55440911970007E-7,,,,,,,,,,,,,,,,,,,,,100.086555480957,100.092765808105,-1399.57482910156,-1399.57482910156,53.4532295446403,5.63844524927918,4.92863178253174,52,1,68,0,0,0.30181884765625,34.2131004333496,1,1,3,100.086555480957,0,100.089660644531,,,,,,,,,,,,,,,,,,,,,,,,,,,,,,,,,
,3878504237.34379,100.092308044434,-1599.53918457031,8.35746014636819E-6,1.96623999065901E-8,1,4,13.4005146026611,5.00636442658585,32.8899994492531,0.0103804377320235,0.00173046583699553,1,1.39522366231081E-7,,,,,,,,,,,,,,,,,,,,,100.091377258301,100.093238830566,-1599.53918457031,-1599.53918457031,53.369204478823,5.63824088482246,4.92673969268799,54,1,0,0,1,0.300064086914063,34.7018585205078,1,1,3,100.091377258301,0,100.092308044434,,,,,,,,,,,,,,,,,,,,,,,,,,,,,,,,,
,3878504296.93396,100.088031768799,-1799.52880859375,9.57578155667404E-6,1.00647081721013E-8,1,4,13.4005146026611,5.00631416893148,32.8899994492531,0.011901924311662,0.00192635017441931,1,1.14606523298725E-7,,,,,,,,,,,,,,,,,,,,,100.08553314209,100.090530395508,-1799.52880859375,-1799.52880859375,53.3668595932653,5.63874699797776,4.9272575378418,52,1,68,0,0,0.301284790039063,34.2131004333496,1,1,3,100.08553314209,0,100.088031768799,,,,,,,,,,,,,,,,,,,,,,,,,,,,,,,,,
,3878504372.41543,100.135696411133,-1999.79528808594,1.08158770435912E-5,9.83083432398447E-9,1,4,13.4005146026611,5.006344726405,32.8899994492531,0.0134446621996939,0.00216725108363311,1,1.22552624855588E-7,,,,,,,,,,,,,,,,,,,,,100.125114440918,100.146278381348,-1999.79528808594,-1999.79528808594,53.4590917585345,5.6386788808965,4.93014287948608,54,1,0,0,1,0.299758911132812,34.2131004333496,1,1,3,100.146278381348,0,100.135696411133,,,,,,,,,,,,,,,,,,,,,,,,,,,,,,,,,
,3878504430.03821,100.167995452881,-2199.60864257813,1.20566012628353E-5,1.31151063633468E-8,1,4,13.4005146026611,5.00632892832041,32.8899994492531,0.0149959423191292,0.00235525152100155,1,8.79413168463226E-8,,,,,,,,,,,,,,,,,,,,,100.162452697754,100.173538208008,-2199.60864257813,-2199.60864257813,53.437206159996,5.63740290463664,4.92847061157227,54,1,0,0,1,0.300827026367188,34.2131004333496,1,1,3,100.162452697754,0,100.167995452881,,,,,,,,,,,,,,,,,,,,,,,,,,,,,,,,,
,3878504487.78691,100.10192489624,-2399.61083984375,1.32652105919742E-5,1.15827678065642E-8,1,4,13.4005146026611,5.00637866854844,32.8899994492531,0.0165027820871127,0.00256900725125692,1,7.87822867710492E-8,,,,,,,,,,,,,,,,,,,,,100.096069335938,100.107780456543,-2399.61083984375,-2399.61083984375,53.3750666927172,5.6381699561967,4.92856884002686,54,1,0,0,1,0.2996826171875,34.7018585205078,1,1,3,100.107780456543,0,100.10192489624,,,,,,,,,,,,,,,,,,,,,,,,,,,,,,,,,
,3878504545.32075,100.161064147949,-2599.62573242187,1.45390048060077E-5,1.40851690708941E-8,1,4,13.4005146026611,5.0063867946883,32.8899994492531,0.0180938497742927,0.00277329455268226,1,5.22891012343294E-8,,,,,,,,,,,,,,,,,,,,,100.152053833008,100.170074462891,-2599.62573242187,-2599.62573242187,53.4688621150249,5.63894528867332,4.92655563354492,54,1,0,0,1,0.302505493164063,34.2131004333496,1,1,3,100.170074462891,0,100.161064147949,,,,,,,,,,,,,,,,,,,,,,,,,,,,,,,,,
,3878504603.84654,100.231300354004,-2799.53979492187,1.57684725932314E-5,9.86584999275301E-9,1,4,13.4005146026611,5.00639960343447,32.8899994492531,0.0196215462619377,0.00302421091014859,1,6.98706961813101E-8,,,,,,,,,,,,,,,,,,,,,100.22420501709,100.238395690918,-2799.53979492187,-2799.53979492187,53.4872303852268,5.63920808461089,4.92972469329834,54,1,0,0,1,0.299301147460937,33.7243423461914,1,1,3,100.22420501709,0,100.231300354004,,,,,,,,,,,,,,,,,,,,,,,,,,,,,,,,,
,3878504664.32652,100.193634033203,-2999.73071289063,1.70204324511726E-5,7.75114861136991E-9,1,4,13.4005146026611,5.00631113727273,32.8899994492531,0.0211793109090944,0.00326151508713542,1,7.32283840153128E-8,,,,,,,,,,,,,,,,,,,,,100.188117980957,100.199150085449,-2999.73071289063,-2999.73071289063,53.4942650418999,5.63872883123116,4.93448829650879,54,1,0,0,1,0.3009033203125,33.7243423461914,1,1,3,100.188117980957,0,100.193634033203,,,,,,,,,,,,,,,,,,,,,,,,,,,,,,,,,
,3878504756.41212,100.098846435547,-4499.58349609375,2.6535711649789E-5,8.11340301541082E-9,1,4,13.4005146026611,5.0064444240599,32.9000018537045,0.0330534047086057,0.00486738001507895,1,-6.06458568864356E-8,,,,,,,,,,,,,,,,,,,,,100.095489501953,100.102203369141,-4499.58349609375,-4499.58349609375,53.3899176345826,5.63873827865834,4.93330430984497,54,1,0,0,1,0.300140380859375,34.2131004333496,1,1,3,100.095489501953,0,100.098846435547,,,,,,,,,,,,,,,,,,,,,,,,,,,,,,,,,
,3878504823.56174,100.159378051758,-6499.76904296875,3.93073885145067E-5,1.21712276882354E-8,1,4,13.4005146026611,5.00635407788458,32.9000018537045,0.048956654429103,0.00723773087864569,1,-6.74637031941262E-8,,,,,,,,,,,,,,,,,,,,,100.147270202637,100.171485900879,-6499.76904296875,-6499.76904296875,53.5353005391595,5.63820767930049,4.93598127365112,54,1,0,0,1,0.30059814453125,33.2355842590332,1,1,3,100.171485900879,0,100.159378051758,,,,,,,,,,,,,,,,,,,,,,,,,,,,,,,,,
,3878504889.11949,100.161373138428,-8499.58984375,5.21052132700791E-5,1.18315318127879E-8,1,4,13.4005146026611,5.00642295994292,32.9000018537045,0.0648971510876794,0.00959583753207302,1,-8.8273405448898E-8,,,,,,,,,,,,,,,,,,,,,100.153160095215,100.169586181641,-8499.58984375,-8499.58984375,53.5278750682268,5.63841637513194,4.93548393249512,54,1,0,0,1,0.300674438476562,33.7243423461914,1,1,3,100.169586181641,0,100.161373138428,,,,,,,,,,,,,,,,,,,,,,,,,,,,,,,,,
,3878504971.70076,100.113563537598,-9999.5185546875,6.17376051574766E-5,1.01564616635439E-8,1,4,13.4005146026611,5.00639928975791,32.9000018537045,0.0768912191226171,0.0113869882016166,1,-9.06997070211022E-8,,,,,,,,,,,,,,,,,,,,,100.113311767578,100.113815307617,-9999.5185546875,-9999.5185546875,53.5052078411691,5.63933833438046,4.9347505569458,54,1,0,0,1,0.301895141601562,34.2131004333496,1,1,3,100.113311767578,0,100.113563537598,,,,,,,,,,,,,,,,,,,,,,,,,,,,,,,,,
,3878505128.10549,100.165576934814,-29999.650390625,0.000190316200840831,3.42356728159835E-8,1,4,13.4005146026611,5.00629066906988,32.9000018537045,0.237001790467555,0.035239537830764,1,-1.68475793284822E-7,,,,,,,,,,,,,,,,,,,,,100.152557373047,100.178596496582,-29999.650390625,-29999.650390625,53.4719886291018,5.63841127761902,4.93136215209961,54,1,0,0,1,0.301971435546875,34.2131004333496,1,1,3,100.178596496582,0,100.165576934814,,,,,,,,,,,,,,,,,,,,,,,,,,,,,,,,,
,3878505294.72749,100.129486083984,-49999.73046875,0.000319216286824719,6.27462603017499E-8,1,4,13.4005146026611,5.00639058392408,32.9000018537045,0.397579987731652,0.0587936518145886,10,-5.35620088029439E-7,,,,,,,,,,,,,,,,,,,,,100.104164123535,100.154808044434,-49999.73046875,-49999.73046875,53.3574800510345,5.6383292304327,4.9355640411377,54,1,0,0,1,0.30181884765625,34.2131004333496,1,1,3,100.154808044434,0,100.129486083984,,,,,,,,,,,,,,,,,,,,,,,,,,,,,,,,,
,3878505463.8361,100.206550598145,-69999.6484375,0.000447777177317213,9.61156137429343E-8,1,4,13.4005146026611,5.00636937921551,32.9000018537045,0.557607436427108,0.0830750894521061,1,-2.66724553229946E-7,,,,,,,,,,,,,,,,,,,,,100.195739746094,100.217361450195,-69999.6484375,-69999.6484375,53.1331526660152,5.63842619139445,4.93532514572144,54,1,0,0,1,0.300674438476562,34.2131004333496,1,1,3,100.218063354492,0,100.206550598145,,,,,,,,,,,,,,,,,,,,,,,,,,,,,,,,,
,3878505623.96416,100.020900726318,-49999.62890625,0.000318779061287017,7.77034977073251E-8,1,4,13.4005146026611,5.00630753066957,32.9000018537045,0.396953730843689,0.0591963332420776,1,-1.45717781425515E-7,,,,,,,,,,,,,,,,,,,,,100.019950866699,100.021850585938,-49999.62890625,-49999.62890625,53.3023752404287,5.63903280210069,4.93976354598999,54,1,0,0,1,0.298995971679687,33.7243423461914,1,1,3,100.019950866699,0,100.020900726318,,,,,,,,,,,,,,,,,,,,,,,,,,,,,,,,,
,3878505784.96097,100.051761627197,-29999.525390625,0.000190020262711564,3.14304396045501E-8,1,4,13.4005146026611,5.00635982660655,32.9000018537045,0.236623378043168,0.0352820114586685,1,-9.06410227065169E-8,,,,,,,,,,,,,,,,,,,,,100.049377441406,100.054145812988,-29999.525390625,-29999.525390625,53.396561476996,5.6385963561814,4.93745470046997,54,1,0,0,1,0.302200317382812,34.2131004333496,1,1,3,100.049377441406,0,100.051761627197,,,,,,,,,,,,,,,,,,,,,,,,,,,,,,,,,
,3878505941.17454,100.007053375244,-10000.123046875,6.14065583499826E-5,1.57230791257842E-8,1,4,13.4005146026611,5.00632020395138,32.9000018537045,0.0764621680931681,0.0114263453798548,1,-9.36680226388694E-9,,,,,,,,,,,,,,,,,,,,,100.004364013672,100.009742736816,-10000.123046875,-10000.123046875,53.4024236908903,5.6384467959579,4.93767976760864,54,1,0,0,1,0.29937744140625,34.7018585205078,1,1,3,100.009742736816,0,100.007053375244,,,,,,,,,,,,,,,,,,,,,,,,,,,,,,,,,
,3878506013.47519,100.166412353516,-8500.1943359375,5.17651821146976E-5,1.19322403191449E-8,1,4,13.4005146026611,5.00644904376332,32.9000018537045,0.0644593811179377,0.00963175321293615,1,-8.61956743425724E-9,,,,,,,,,,,,,,,,,,,,,100.162712097168,100.170112609863,-8500.1943359375,-8500.1943359375,53.4704253720634,5.63860727750788,4.94148683547974,54,1,0,0,1,0.299911499023438,34.2131004333496,1,1,3,100.162712097168,0,100.166412353516,,,,,,,,,,,,,,,,,,,,,,,,,,,,,,,,,
,3878506080.50297,100.158973693848,-6500.423828125,3.89212866727079E-5,1.00716552607199E-8,1,4,13.4005146026611,5.0063548537654,32.9000018537045,0.048462302915758,0.00725674306611554,1,5.56233156007757E-9,,,,,,,,,,,,,,,,,,,,,100.149742126465,100.16820526123,-6500.423828125,-6500.423828125,53.3797564638326,5.63946395260072,4.93617486953735,53,1,68,0,0,0.301055908203125,34.2131004333496,1,1,3,100.16820526123,0,100.158973693848,,,,,,,,,,,,,,,,,,,,,,,,,,,,,,,,,
,3878506145.44329,100.203861236572,-4500.25048828125,2.61327113620987E-5,7.8182954725386E-9,1,4,13.4005146026611,5.00638000472089,32.9000018537045,0.0325364729645865,0.00488937277716422,1,1.73732617476579E-8,,,,,,,,,,,,,,,,,,,,,100.20288848877,100.204833984375,-4500.25048828125,-4500.25048828125,53.4927017848614,5.63899134742829,4.93524360656738,54,1,0,0,1,0.300979614257812,34.7018585205078,1,1,3,100.204833984375,0,100.203861236572,,,,,,,,,,,,,,,,,,,,,,,,,,,,,,,,,
,3878506226.39505,100.236663818359,-3000.13354492188,1.66311292535683E-5,5.05238627476737E-9,1,4,13.4005146026611,5.00638226303145,32.9000018537045,0.0207129166133558,0.00306917578614156,1,-2.30542989857484E-8,,,,,,,,,,,,,,,,,,,,,100.235641479492,100.237686157227,-3000.13354492188,-3000.13354492188,53.4086767190441,5.63903095162992,4.94102811813354,54,1,0,0,1,0.302047729492188,34.2131004333496,1,1,3,100.235641479492,0,100.236663818359,,,,,,,,,,,,,,,,,,,,,,,,,,,,,,,,,
,3878506282.01413,100.165271759033,-2800.18188476562,1.54403916654804E-5,1.84891052308359E-8,1,4,13.4005146026611,5.00626812813303,32.9000018537045,0.019263584975846,0.00262030606091432,1,-2.05348239931875E-7,,,,,,,,,,,,,,,,,,,,,100.160766601562,100.169776916504,-2800.18188476562,-2800.18188476562,53.4723794433614,5.63868660469848,4.94077777862549,54,1,0,0,1,0.302505493164063,34.2131004333496,1,1,3,100.169776916504,0,100.165271759033,,,,,,,,,,,,,,,,,,,,,,,,,,,,,,,,,
,3878506341.67938,100.217025756836,-2600.49438476562,1.42011934531502E-5,1.64263615522185E-8,1,4,13.4005146026611,5.00634723230685,32.9000018537045,0.0177201671614365,0.00239517674605106,1,-2.00821807792414E-7,,,,,,,,,,,,,,,,,,,,,100.214904785156,100.219146728516,-2600.49438476562,-2600.49438476562,53.3953890342172,5.63930256901851,4.9394359588623,53,1,68,0,0,0.302276611328125,34.2131004333496,1,1,3,100.219146728516,0,100.217025756836,,,,,,,,,,,,,,,,,,,,,,,,,,,,,,,,,
,3878506398.33891,100.123046875,-2400.44165039062,1.29619978700802E-5,1.58915904955978E-8,1,4,13.4005146026611,5.00638417189607,32.9000018537045,0.0161762482442078,0.00217165475055214,1,-1.94976417166546E-7,,,,,,,,,,,,,,,,,,,,,100.115844726562,100.130249023438,-2400.44165039062,-2400.44165039062,53.4903568993037,5.63952986978117,4.94475841522217,54,1,0,0,1,0.299301147460937,34.2131004333496,1,1,3,100.130668640137,0,100.123046875,,,,,,,,,,,,,,,,,,,,,,,,,,,,,,,,,
,3878506457.74789,100.197326660156,-2200.48974609375,1.17303477631229E-5,1.8526121459215E-8,1,4,13.4005146026611,5.00640657214167,32.9000018537045,0.0146417774515793,0.00194856371813951,1,-1.89903621899537E-7,,,,,,,,,,,,,,,,,,,,,100.193786621094,100.200866699219,-2200.48974609375,-2200.48974609375,53.5618759088134,5.63912720790232,4.93964862823486,54,1,0,0,1,0.301055908203125,34.2131004333496,1,1,3,100.200866699219,0,100.197326660156,,,,,,,,,,,,,,,,,,,,,,,,,,,,,,,,,
,3878506516.00847,100.081035614014,-2000.36181640625,1.04870137351305E-5,1.8604527253781E-8,1,4,13.4005146026611,5.00631650787041,32.9000018537045,0.0130997165256654,0.00167384591725153,1,-2.24499525282176E-7,,,,,,,,,,,,,,,,,,,,,100.07691192627,100.085159301758,-2000.36181640625,-2000.36181640625,53.5239669256307,5.63940686605749,4.9376974105835,54,1,0,0,1,0.301666259765625,34.7018585205078,1,1,3,100.07691192627,0,100.081035614014,,,,,,,,,,,,,,,,,,,,,,,,,,,,,,,,,
,3878506574.85539,100.153064727783,-1800.24633789062,9.27800377802893E-6,1.86904630034672E-8,1,4,13.4005146026611,5.00638977595571,32.9000018537045,0.0115911125331167,0.00147169364752216,1,-2.06015073182491E-7,,,,,,,,,,,,,,,,,,,,,100.139541625977,100.16658782959,-1800.24633789062,-1800.24633789062,53.450493844823,5.63923529860452,4.93605899810791,53,1,68,0,0,0.298614501953125,34.2131004333496,1,1,3,100.16658782959,0,100.153064727783,,,,,,,,,,,,,,,,,,,,,,,,,,,,,,,,,
,3878506631.7662,100.136856079102,-1600.11828613281,8.05460280592823E-6,1.84639983434614E-8,1,4,13.4005146026611,5.00645211972491,32.9000018537045,0.0100635953110334,0.00127287206688652,1,-1.82693228865126E-7,,,,,,,,,,,,,,,,,,,,,100.129028320312,100.144683837891,-1600.11828613281,-1600.11828613281,53.5055986554287,5.63996340409315,4.93968486785889,54,1,0,0,1,0.301055908203125,34.2131004333496,1,1,3,100.129028320312,0,100.136856079102,,,,,,,,,,,,,,,,,,,,,,,,,,,,,,,,,
,3878506705.69577,100.10396194458,-1400.12866210938,6.80521041259915E-6,1.97354192530182E-8,1,4,13.4005146026611,5.00640471938133,32.9000018537045,0.00850573714093237,0.001053541209024,1,-1.71922164462256E-7,,,,,,,,,,,,,,,,,,,,,100.099975585938,100.107948303223,-1400.12866210938,-1400.12866210938,53.4938742276403,5.64035628058718,4.93754243850708,54,1,0,0,1,0.300979614257812,34.2131004333496,1,1,3,100.107948303223,0,100.10396194458,,,,,,,,,,,,,,,,,,,,,,,,,,,,,,,,,
,3878506762.81591,100.198375701904,-1200.12646484375,5.6299440635231E-6,2.11620703891242E-8,1,4,13.4005146026611,5.00654525892368,32.9000018537045,0.00705520626098535,0.000750353557971795,1,-2.39622189787443E-7,,,,,,,,,,,,,,,,,,,,,100.189422607422,100.207328796387,-1200.12646484375,-1200.12646484375,53.4973915559768,5.64020668930205,4.93977117538452,54,1,0,0,1,0.301742553710937,34.2131004333496,1,1,3,100.207328796387,0,100.198375701904,,,,,,,,,,,,,,,,,,,,,,,,,,,,,,,,,
,3878506821.51647,100.148948669434,-1000.08648681641,4.4901519760747E-6,2.30353932575304E-8,1,4,13.4005146026611,5.00649985941587,32.9000018537045,0.00563467882908001,0.000545740667505793,1,-2.3342823206216E-7,,,,,,,,,,,,,,,,,,,,,100.142822265625,100.155075073242,-1000.08648681641,-1000.08648681641,53.5177138974768,5.6402761656342,4.94788312911987,53,1,68,0,0,0.300674438476562,34.2131004333496,1,1,3,100.155075073242,0,100.148948669434,,,,,,,,,,,,,,,,,,,,,,,,,,,,,,,,,
,3878506879.26726,100.098243713379,-800.273132324219,3.33348308660705E-6,2.60825774403207E-8,1,4,13.4005146026611,5.00648142308071,32.9000018537045,0.00419750691828977,0.000309228036963898,1,-2.50333863095253E-7,,,,,,,,,,,,,,,,,,,,,100.091819763184,100.104667663574,-800.273132324219,-800.273132324219,53.4411143025922,5.64036075042756,4.9402756690979,52,1,68,0,0,0.30029296875,34.2131004333496,1,1,3,100.104667663574,0,100.098243713379,,,,,,,,,,,,,,,,,,,,,,,,,,,,,,,,,
,3878506936.86575,100.185722351074,-600.195373535156,2.34113791264151E-6,1.43163093593658E-7,1,4,13.4005146026611,5.00651826115543,32.9000018537045,0.0029381159058377,0.000283119721504909,1,-1.22854526576871E-7,,,,,,,,,,,,,,,,,,,,,100.18310546875,100.188339233398,-600.195373535156,-600.195373535156,53.4837130568903,5.63963229518461,4.93746852874756,52,1,68,0,0,0.301895141601562,34.2131004333496,1,1,3,100.188339233398,0,100.185722351074,,,,,,,,,,,,,,,,,,,,,,,,,,,,,,,,,
,3878506995.65215,100.148178100586,-400.281341552734,1.02686228235486E-6,1.82202759364043E-7,1,4,13.4005146026611,5.00654127411845,32.9000018537045,0.00129571914346652,7.73614893142322E-5,1,-9.14858907129431E-8,,,,,,,,,,,,,,,,,,,,,100.135902404785,100.160453796387,-400.281341552734,-400.281341552734,53.462609086871,5.63896745441461,4.93783330917358,53,1,68,0,0,0.300827026367188,34.2131004333496,1,1,3,100.160453796387,0,100.148178100586,,,,,,,,,,,,,,,,,,,,,,,,,,,,,,,,,
,3878507052.7106,100.125282287598,-200.178436279297,2.42362348530454E-7,3.11903800278552E-8,1,4,13.4005146026611,5.00647146683536,32.9000018537045,0.000337170105909628,-0.000191359023439895,1,-1.89932838771176E-7,,,,,,,,,,,,,,,,,,,,,100.115989685059,100.134574890137,-200.178436279297,-200.178436279297,53.3578708652941,5.64020646635318,4.94644975662231,53,1,68,0,0,0.30059814453125,34.2131004333496,1,1,3,100.134574890137,0,100.125282287598,,,,,,,,,,,,,,,,,,,,,,,,,,,,,,,,,
,3878507111.72871,100.107746124268,-0.188823834061623,-6.60500208363166E-7,2.99630590732713E-8,1,4,13.4005146026611,5.00644670052201,32.9000018537045,-0.000776283370444131,-0.000431656166078175,1,-2.47850788472122E-7,,,,,,,,,,,,,,,,,,,,,100.103507995605,100.11198425293,-0.188823834061623,-0.188823834061623,53.552105552323,5.64027935577862,4.93866968154907,53,1,68,0,0,0.30059814453125,34.2131004333496,1,1,3,100.103507995605,0,100.107746124268,,,,,,,,,,,,,,,,,,,,,,,,,,,,,,,,,
,3878507192.66499,100.17147064209,199.750427246094,-1.21341584803892E-6,1.30445385237651E-7,1,4,13.4005146026611,5.00641155183425,32.9000018537045,-0.0014895425691569,-0.000368956320328494,10,-1.14787477252963E-7,,,,,,,,,,,,,,,,,,,,,100.165534973145,100.177406311035,199.750427246094,199.750427246094,53.5665656799287,5.63909347677011,4.93812608718872,54,1,0,0,1,0.299606323242188,34.2131004333496,1,1,3,100.165534973145,0,100.17147064209,,,,,,,,,,,,,,,,,,,,,,,,,,,,,,,,,
,3878507258.91292,100.228630065918,399.614135742188,-1.99191015907627E-6,1.6034796111613E-8,1,4,13.4005146026611,5.00646689915141,32.9000018537045,-0.0024424574443353,-0.000624211830509345,1,-2.03316225545088E-7,,,,,,,,,,,,,,,,,,,,,100.222145080566,100.23511505127,399.614135742188,399.614135742188,53.5200587830345,5.63895519095284,4.94742202758789,52,1,68,0,0,0.299148559570313,34.2131004333496,1,1,3,100.23511505127,0,100.228630065918,,,,,,,,,,,,,,,,,,,,,,,,,,,,,,,,,
,3878507316.68607,100.133411407471,599.780029296875,-2.86230493921488E-6,1.5780631377621E-8,1,4,13.4005146026611,5.00643431779983,32.9000018537045,-0.0035332952458536,-0.000739191012371272,1,-1.65453719060645E-7,,,,,,,,,,,,,,,,,,,,,100.127067565918,100.139755249023,599.780029296875,599.780029296875,53.472770257621,5.63895533562099,4.93810510635376,54,1,0,0,1,0.301589965820313,34.2131004333496,1,1,3,100.126312255859,0,100.133411407471,,,,,,,,,,,,,,,,,,,,,,,,,,,,,,,,,
,3878507374.20665,100.203163146973,799.60595703125,-3.79365726760504E-6,5.50944124726519E-8,1,4,13.4005146026611,5.00645540381868,32.9000018537045,-0.00468701734414855,-0.000952901330205317,1,-1.97753259462031E-7,,,,,,,,,,,,,,,,,,,,,100.198875427246,100.207450866699,799.60595703125,799.60595703125,53.4426775596307,5.63956658330087,4.94281578063965,54,1,0,0,1,0.3021240234375,34.2131004333496,1,1,3,100.198875427246,0,100.203163146973,,,,,,,,,,,,,,,,,,,,,,,,,,,,,,,,,
,3878507431.90686,100.14183807373,999.796936035156,-4.91248118132917E-6,2.46576748140086E-8,1,4,13.4005146026611,5.00645480723502,32.9000018537045,-0.00609337778373527,-0.00107304054233821,1,-1.26866267549376E-7,,,,,,,,,,,,,,,,,,,,,100.139122009277,100.144554138184,999.796936035156,999.796936035156,53.4864487567076,5.63905316568565,4.94762516021729,53,1,68,0,0,0.301055908203125,34.7018585205078,1,1,3,100.139122009277,0,100.14183807373,,,,,,,,,,,,,,,,,,,,,,,,,,,,,,,,,
,3878507490.33907,100.191970825195,1199.47192382812,-6.0350002093824E-6,1.46000693668088E-8,1,4,13.4005146026611,5.00650461419164,32.9000018537045,-0.00749024341547391,-0.00128881596385014,1,-1.32216029746185E-7,,,,,,,,,,,,,,,,,,,,,100.186599731445,100.197341918945,1199.47192382812,1199.47192382812,53.4532295446403,5.63955004127422,4.94005393981934,52,1,68,0,0,0.2996826171875,33.7243423461914,1,1,3,100.197341918945,0,100.191970825195,,,,,,,,,,,,,,,,,,,,,,,,,,,,,,,,,
,3878507548.02328,100.14123916626,1399.65026855469,-7.20418747420469E-6,1.21430023216901E-8,1,4,13.4005146026611,5.00637867376664,32.9000018537045,-0.00894524337182116,-0.00151039753035925,1,-1.35301923258258E-7,,,,,,,,,,,,,,,,,,,,,100.138626098633,100.143852233887,1399.65026855469,1399.65026855469,53.5544504378807,5.6395590464585,4.94341278076172,52,1,68,0,0,0.299911499023438,33.7243423461914,1,1,3,100.138229370117,0,100.14123916626,,,,,,,,,,,,,,,,,,,,,,,,,,,,,,,,,
,3878507605.95706,100.154716491699,1599.52661132813,-8.38249542602741E-6,1.20070514947375E-8,1,4,13.4005146026611,5.00645442617269,32.9000018537045,-0.010415100693996,-0.00171359302050794,1,-1.22191999519107E-7,,,,,,,,,,,,,,,,,,,,,100.149269104004,100.160163879395,1599.52661132813,1599.52661132813,53.4923109706018,5.63917560738265,4.94603681564331,53,1,68,0,0,0.299606323242188,34.2131004333496,1,1,3,100.149269104004,0,100.154716491699,,,,,,,,,,,,,,,,,,,,,,,,,,,,,,,,,
,3878507665.47136,100.177642822266,1799.54138183594,-9.61027201002115E-6,6.52806720133782E-8,1,4,13.4005146026611,5.00643562070344,32.9000018537045,-0.0119432304653198,-0.00194650872933378,1,-1.25583619532535E-7,,,,,,,,,,,,,,,,,,,,,100.169578552246,100.185707092285,1799.54138183594,1799.54138183594,53.5685197512268,5.63921742199848,4.94774103164673,53,1,68,0,0,0.299758911132812,34.2131004333496,1,1,3,100.185707092285,0,100.177642822266,,,,,,,,,,,,,,,,,,,,,,,,,,,,,,,,,
,3878507723.27857,100.193248748779,2000.02185058594,-1.08020482810976E-5,9.75632261525876E-9,1,4,13.4005146026611,5.00647292887927,32.9000018537045,-0.013431390573203,-0.00214157902227604,1,-1.03942254799631E-7,,,,,,,,,,,,,,,,,,,,,100.189872741699,100.196624755859,2000.02185058594,2000.02185058594,53.401642062371,5.63976509510782,4.94909954071045,53,1,68,0,0,0.300445556640625,34.7018585205078,1,1,3,100.196624755859,0,100.193248748779,,,,,,,,,,,,,,,,,,,,,,,,,,,,,,,,,
,3878507780.96796,100.108333587646,2199.79736328125,-1.2064775591813E-5,4.0662809386062E-8,1,4,13.4005146026611,5.00635777097456,32.9000018537045,-0.0150075860118279,-0.00234780529448264,1,-8.07231336191683E-8,,,,,,,,,,,,,,,,,,,,,100.107025146484,100.109642028809,2199.79736328125,2199.79736328125,53.4813681713326,5.63963545050557,4.94200038909912,54,1,0,0,1,0.300979614257812,34.2131004333496,1,1,3,100.107025146484,0,100.108333587646,,,,,,,,,,,,,,,,,,,,,,,,,,,,,,,,,
,3878507838.68099,100.073535919189,2399.8876953125,-1.32691377917912E-5,3.81415875672776E-8,1,4,13.4005146026611,5.00638190223762,32.9000018537045,-0.0165050044609954,-0.00258767344217435,1,-9.31837893991177E-8,,,,,,,,,,,,,,,,,,,,,100.072227478027,100.074844360352,2399.8876953125,2399.8876953125,53.4188378897941,5.6392668167514,4.94832897186279,54,1,0,0,1,0.3009033203125,33.7243423461914,1,1,3,100.074844360352,0,100.073535919189,,,,,,,,,,,,,,,,,,,,,,,,,,,,,,,,,
,3878507896.35326,100.145317077637,2599.81469726562,-1.45015437027245E-5,8.96662875435085E-9,1,4,13.4005146026611,5.00634352184557,32.9000018537045,-0.0180439623598163,-0.0027864961690246,1,-6.85223221832693E-8,,,,,,,,,,,,,,,,,,,,,100.137634277344,100.15299987793,2599.81469726562,2599.81469726562,53.3281689815633,5.63892803954681,4.93996858596802,54,1,0,0,1,0.300216674804687,33.7243423461914,1,1,3,100.15299987793,0,100.145317077637,,,,,,,,,,,,,,,,,,,,,,,,,,,,,,,,,
,3878507954.11759,100.174770355225,2799.93017578125,-1.57534531948145E-5,7.38463054132653E-9,1,4,13.4005146026611,5.00637313263498,32.9000018537045,-0.0196041826781888,-0.0030114763310066,1,-6.19082720196628E-8,,,,,,,,,,,,,,,,,,,,,100.174301147461,100.175239562988,2799.93017578125,2799.93017578125,53.5005180700537,5.63908342537311,4.94299554824829,54,1,0,0,1,0.302047729492188,33.7243423461914,1,1,3,100.174301147461,0,100.174770355225,,,,,,,,,,,,,,,,,,,,,,,,,,,,,,,,,
,3878508011.73854,100.189876556396,2999.79370117188,-1.69957470391646E-5,1.06869347057412E-8,1,4,13.4005146026611,5.00638609233701,32.9000018537045,-0.0211505057550173,-0.00324703073528849,1,-6.52339447376481E-8,,,,,,,,,,,,,,,,,,,,,100.185432434082,100.194320678711,2999.79370117188,2999.79370117188,53.3500545801018,5.6386972586841,4.93938398361206,54,1,0,0,1,0.301513671875,34.2131004333496,1,1,3,100.194320678711,0,100.189876556396,,,,,,,,,,,,,,,,,,,,,,,,,,,,,,,,,
,3878508090.65722,100.169258117676,4499.68408203125,-2.65346036621589E-5,9.40461504650636E-9,1,4,13.4005146026611,5.00642057351378,32.9000018537045,-0.0330520437638423,-0.00486554449648213,1,6.19281653625463E-8,,,,,,,,,,,,,,,,,,,,,100.160705566406,100.177810668945,4499.68408203125,4499.68408203125,53.3613881936306,5.63919501208161,4.94344329833984,54,1,0,0,1,0.30029296875,33.7243423461914,1,1,3,100.177810668945,0,100.169258117676,,,,,,,,,,,,,,,,,,,,,,,,,,,,,,,,,
,3878508155.16743,100.184684753418,6499.744140625,-3.92945065343351E-5,3.24160885947316E-8,1,4,13.4005146026611,5.00640263127957,32.9000018537045,-0.0489389701469984,-0.0072508561175975,1,5.50746125062811E-8,,,,,,,,,,,,,,,,,,,,,100.178657531738,100.190711975098,6499.744140625,6499.744140625,53.4547928016787,5.63844825530773,4.94760990142822,54,1,0,0,1,0.29998779296875,34.2131004333496,1,1,3,100.178657531738,0,100.184684753418,,,,,,,,,,,,,,,,,,,,,,,,,,,,,,,,,
,3878508220.23703,100.252407073975,8500.04296875,-5.21210382794403E-5,1.34972009840735E-8,1,4,13.4005146026611,5.00643044542516,32.9000018537045,-0.0649185359630054,-0.00958848351376547,1,9.65627837611582E-8,,,,,,,,,,,,,,,,,,,,,100.238815307617,100.265998840332,8500.04296875,8500.04296875,53.5818074360538,5.63895080041557,4.94591474533081,53,1,68,0,0,0.301284790039063,34.2131004333496,1,1,3,100.265998840332,0,100.252407073975,,,,,,,,,,,,,,,,,,,,,,,,,,,,,,,,,
,3878508293.44429,100.113662719727,10000.0341796875,-6.17430855617194E-5,1.26108581694456E-8,1,4,13.4005146026611,5.00632226492434,32.9000018537045,-0.0768984575278062,-0.011373937097871,1,1.01804366816248E-7,,,,,,,,,,,,,,,,,,,,,100.112716674805,100.114608764648,10000.0341796875,10000.0341796875,53.4227460323903,5.63885232374394,4.94676208496094,54,1,0,0,1,0.29998779296875,34.2131004333496,1,1,3,100.112716674805,0,100.113662719727,,,,,,,,,,,,,,,,,,,,,,,,,,,,,,,,,
,3878508445.9751,100.036464691162,30000.341796875,-0.000190372335194314,3.49826698871608E-8,1,4,13.4005146026611,5.00633947143764,32.9000018537045,-0.237075300479638,-0.0352479089508937,1,1.70535931991766E-7,,,,,,,,,,,,,,,,,,,,,100.03441619873,100.038513183594,30000.341796875,30000.341796875,53.4465857022268,5.63868070596438,4.94332981109619,54,1,0,0,1,0.299758911132812,34.2131004333496,1,1,3,100.03441619873,0,100.036464691162,,,,,,,,,,,,,,,,,,,,,,,,,,,,,,,,,
,3878508619.32694,100.052547454834,50000.39453125,-0.000319125409484634,5.76693507084599E-8,1,4,13.4005146026611,5.00638070753736,32.9000018537045,-0.397416009312626,-0.0591089548711059,1,2.68674642901005E-7,,,,,,,,,,,,,,,,,,,,,100.032531738281,100.072563171387,50000.39453125,50000.39453125,53.1749697917941,5.63907280910674,4.94656848907471,54,1,0,0,1,0.30029296875,33.7243423461914,1,1,3,100.072563171387,0,100.052547454834,,,,,,,,,,,,,,,,,,,,,,,,,,,,,,,,,
,3878508803.31751,100.03734588623,70000.453125,-0.000448131672869135,9.27238774727836E-8,1,4,13.4005146026611,5.00631658550445,32.9000018537045,-0.558143842983171,-0.0824498419326953,10,8.2091776667985E-7,,,,,,,,,,,,,,,,,,,,,100.035911560059,100.038780212402,70000.453125,70000.453125,53.2429714729672,5.63874940836115,4.94642400741577,54,1,0,0,1,0.2984619140625,34.2131004333496,1,1,3,100.035911560059,0,100.03734588623,,,,,,,,,,,,,,,,,,,,,,,,,,,,,,,,,