File: SQUID/22163_LCOT/LCOT_MH_50K_FC+1T.csv
Comment,Time Stamp (sec),Temperature (K),Magnetic Field (Oe),Moment (emu),M. Std. Err. (emu),Transport Action,Averaging Time (sec),Frequency (Hz),Peak Amplitude (mm),Center Position (mm),Lockin Signal' (V),Lockin Signal (V),Range,M. Quad. Signal (emu),AC Moment (emu),AC M. Std Err. (emu),AC Phase (deg),AC Phase Std. Err. (deg),AC Susceptibility (emu/Oe),AC Suscept. Std Err. (emu/Oe),AC X' (emu/Oe),AC X' Std Err. (emu/Oe),AC X'' (emu/Oe),AC X'' Std Err. (emu/Oe),AC Drive (Oe),AC Frequency (Hz),AC Averaging Time (sec),AC Cycles,AC Range,AC Measure Type,AC Signal' (V),AC Signal'' (V),AC Trim Coil Ratio,AC Trim Coil Phase,Min. Temperature (K),Max. Temperature (K),Min. Field (Oe),Max. Field (Oe),Mass (grams),Motor Lag (deg),Pressure (Torr),Measure Count,Measurement Number,SQUID Status (code),Motor Status (code),Measure Status (code),Motor Current (amps),Motor Temp. (C),Temp. Status (code),Field Status (code),Chamber Status (code),Chamber Temp (K),Redirection State,Average Temp (K),Rotation Angle (deg),Rotator state,DC Moment Fixed Ctr (emu),DC Moment Err Fixed Ctr (emu),DC Moment Free Ctr (emu),DC Moment Err Free Ctr (emu),DC Fixed Fit,DC Free Fit,DC Calculated Center (mm),DC Calculated Center Err (mm),DC Scan Length (mm),DC Scan Time (s),DC Number of Points,DC Squid Drift,DC Min V (V),DC Max V (V),DC Scans per Measure,Sample Resistance,He3 Temperature,Sorb Resistance,Sorb Temperature,Map 05,Map 06,Map 07,Map 08,Map 09,Map 10,Map 11,Map 12,Map 13,Map 14,Map 15,Map 16
,3878494445.14415,50.0285892486572,69999.625,-4.44250795272877E-4,1.65366722265604E-7,1,4,13.4005146026611,4.99649112191524,32.8599996864796,-0.551759056984045,-0.0817276263766821,10,6.39714983647108E-7,,,,,,,,,,,,,,,,,,,,,50.0281372070313,50.0290412902832,69999.625,69999.625,53.3094098971018,5.63859445940039,4.58112621307373,54,1,0,0,1,0.298233032226562,33.2355842590332,1,1,3,50.0281372070313,0,50.0285892486572,,,,,,,,,,,,,,,,,,,,,,,,,,,,,,,,,
,3878494637.5367,50.0005054473877,50000.00390625,-3.16159949413313E-4,7.51426859766524E-8,1,4,13.4005146026611,4.99662203788228,32.8699983656406,-0.392613625766438,-0.058640730098802,1,7.23479043381564E-8,,,,,,,,,,,,,,,,,,,,,50.0004768371582,50.0005340576172,50000.00390625,50000.00390625,53.5227944828518,5.63738238655056,4.63610172271729,53,1,68,0,0,0.298233032226562,34.2131004333496,1,1,3,50.0005340576172,0,50.0005054473877,,,,,,,,,,,,,,,,,,,,,,,,,,,,,,,,,
,3878494827.34305,50.0044059753418,29999.775390625,-1.88202162664054E-4,3.57912508118336E-8,1,4,13.4005146026611,4.99650907669658,32.880000770092,-0.233704007845484,-0.0349178312378475,1,3.37520433780307E-8,,,,,,,,,,,,,,,,,,,,,50.0038070678711,50.0050048828125,29999.775390625,29999.775390625,53.4661264152076,5.63806416852433,4.65934228897095,54,1,0,0,1,0.298233032226562,34.2131004333496,1,1,3,50.0050048828125,0,50.0044059753418,,,,,,,,,,,,,,,,,,,,,,,,,,,,,,,,,
,3878494986.14146,50.0154495239258,9999.556640625,-6.07602887342047E-5,1.55300338000829E-8,1,4,13.4005146026611,4.99645543681554,32.8699983656406,-0.0754470390246235,-0.0112875991744543,1,-9.34828058045869E-10,,,,,,,,,,,,,,,,,,,,,50.0141258239746,50.016773223877,9999.556640625,9999.556640625,53.4032053194095,5.63751052690906,4.66694593429565,53,1,68,0,0,0.2984619140625,34.7018585205078,1,1,3,50.0141258239746,0,50.0154495239258,,,,,,,,,,,,,,,,,,,,,,,,,,,,,,,,,
,3878495068.60221,50.0213756561279,8499.65234375,-5.11968802043435E-5,1.27780151967186E-8,1,4,13.4005146026611,4.99653161938244,32.8699983656406,-0.0635731952678471,-0.00951225951365619,1,-1.65494737789359E-9,,,,,,,,,,,,,,,,,,,,,50.0197601318359,50.0229911804199,8499.65234375,8499.65234375,53.4528387303807,5.63745451267681,4.66896677017212,52,1,68,0,0,0.298919677734375,35.190616607666,1,1,3,50.0197601318359,0,50.0213756561279,,,,,,,,,,,,,,,,,,,,,,,,,,,,,,,,,
,3878495136.54741,50.0199108123779,6499.5927734375,-3.84923551229251E-5,1.21495208620023E-8,1,4,13.4005146026611,4.99644347711483,32.8699983656406,-0.0477941578903746,-0.00716594669324926,1,-1.27884818112175E-8,,,,,,,,,,,,,,,,,,,,,50.017765045166,50.0220565795898,6499.5927734375,6499.5927734375,53.5005180700537,5.63818067188006,4.66482496261597,52,1,68,0,0,0.298385620117188,34.2131004333496,1,1,3,50.0221176147461,0,50.0199108123779,,,,,,,,,,,,,,,,,,,,,,,,,,,,,,,,,
,3878495204.95328,50.0285415649414,4499.59619140625,-2.58125541144583E-5,7.36824866493624E-9,1,4,13.4005146026611,4.99649878625886,32.8699983656406,-0.0320491732296795,-0.00481594406656517,1,-1.70025578130753E-8,,,,,,,,,,,,,,,,,,,,,50.0262985229492,50.0307846069336,4499.59619140625,4499.59619140625,53.4614366440922,5.63742539960278,4.67000770568848,54,1,0,0,1,0.298385620117188,34.2131004333496,1,1,3,50.0262985229492,0,50.0285415649414,,,,,,,,,,,,,,,,,,,,,,,,,,,,,,,,,
,3878495290.6517,50.0116767883301,2999.63012695313,-1.63979336417229E-5,6.13844243528815E-9,1,4,13.4005146026611,4.99659936428485,32.8699983656406,-0.020367661133209,-0.00301125615233356,1,2.80574207508128E-8,,,,,,,,,,,,,,,,,,,,,50.0115852355957,50.0117683410645,2999.63012695313,2999.63012695313,53.4559652444576,5.6377542008546,4.67801952362061,54,1,0,0,1,0.298080444335937,34.7018585205078,1,1,3,50.0115852355957,0,50.0116767883301,,,,,,,,,,,,,,,,,,,,,,,,,,,,,,,,,
,3878495350.01118,50.0062084197998,2799.75390625,-1.52323494696505E-5,1.53158440124318E-8,1,4,13.4005146026611,4.99659405393203,32.8699983656406,-0.0189522209000761,-0.00258099003260829,1,2.00184546794214E-7,,,,,,,,,,,,,,,,,,,,,50.0054321289063,50.0069847106934,2799.75390625,2799.75390625,53.577508479198,5.63847311780349,4.67407512664795,53,1,68,0,0,0.297393798828125,34.2131004333496,1,1,3,50.0054321289063,0,50.0062084197998,,,,,,,,,,,,,,,,,,,,,,,,,,,,,,,,,
,3878495419.95786,50.0536499023438,2599.65087890625,-1.40253920146237E-5,1.8710149010126E-8,1,4,13.4005146026611,4.9965693211409,32.8699983656406,-0.0174564439601451,-0.00233601610110693,10,2.1689654767954E-7,,,,,,,,,,,,,,,,,,,,,50.0511131286621,50.0561866760254,2599.65087890625,2599.65087890625,53.411803233121,5.63810482865809,4.68614768981934,54,1,0,0,1,0.298004150390625,33.7243423461914,1,1,3,50.0561904907227,0,50.0536499023438,,,,,,,,,,,,,,,,,,,,,,,,,,,,,,,,,
,3878495486.02711,50.0367946624756,2399.72412109375,-1.27688775438526E-5,1.74613295496516E-8,1,4,13.4005146026611,4.99656911371956,32.8699983656406,-0.0158972691748741,-0.00209515977602319,1,2.22893485422486E-7,,,,,,,,,,,,,,,,,,,,,50.0337867736816,50.0398025512695,2399.72412109375,2399.72412109375,53.5274842539672,5.63730149573313,4.68366670608521,54,1,0,0,1,0.297775268554687,34.7018585205078,1,1,3,50.0398025512695,0,50.0367946624756,,,,,,,,,,,,,,,,,,,,,,,,,,,,,,,,,
,3878495552.67952,50.0444259643555,2199.57080078125,-1.15405304275454E-5,1.7311163299264E-8,1,4,13.4005146026611,4.99659902855466,32.8699983656406,-0.0143710976842534,-0.00187355794397332,10,2.17611018993321E-7,,,,,,,,,,,,,,,,,,,,,50.0425033569336,50.0463485717773,2199.57080078125,2199.57080078125,53.5450708956499,5.63821611469453,4.67734909057617,54,1,0,0,1,0.297775268554687,34.7018585205078,1,1,3,50.0425033569336,0,50.0444259643555,,,,,,,,,,,,,,,,,,,,,,,,,,,,,,,,,
,3878495619.24272,50.0605297088623,1999.74499511719,-1.03257004590665E-5,1.74843701101969E-8,1,4,13.4005146026611,4.99661203364169,32.8699983656406,-0.012862258021862,-0.00165022373570382,1,2.1573642031262E-7,,,,,,,,,,,,,,,,,,,,,50.059627532959,50.0614318847656,1999.74499511719,1999.74499511719,53.4821497998518,5.63761177054571,4.6877007484436,54,1,0,0,1,0.299148559570313,34.7018585205078,1,1,3,50.059627532959,0,50.0605297088623,,,,,,,,,,,,,,,,,,,,,,,,,,,,,,,,,
,3878495693.78672,50.0284614562988,1799.79309082031,-9.06965936890639E-6,4.45134242822012E-8,1,4,13.4005146026611,4.99667364379984,32.8699983656406,-0.0112970702798753,-0.0014547877029046,1,1.85245225818151E-7,,,,,,,,,,,,,,,,,,,,,50.0261383056641,50.0307846069336,1799.79309082031,1799.79309082031,53.355916793996,5.63820066950239,4.68059730529785,54,1,0,0,1,0.298080444335937,34.2131004333496,1,1,3,50.0307846069336,0,50.0284614562988,,,,,,,,,,,,,,,,,,,,,,,,,,,,,,,,,
,3878495760.98736,50.0284843444824,1599.791015625,-7.9098490970746E-6,1.83300503468205E-8,1,4,13.4005146026611,4.99665857699083,32.8699983656406,-0.00986479343635192,-0.00118577580660081,10,2.28372195219605E-7,,,,,,,,,,,,,,,,,,,,,50.0266723632812,50.0302963256836,1599.791015625,1599.791015625,53.6916262430057,5.63795330859227,4.69104957580566,54,1,0,0,1,0.29815673828125,34.2131004333496,1,1,3,50.030387878418,0,50.0284843444824,,,,,,,,,,,,,,,,,,,,,,,,,,,,,,,,,
,3878495826.35619,50.0090885162354,1399.73840332031,-6.72232719054734E-6,2.08831418107923E-8,1,4,13.4005146026611,4.99660599780251,32.8699983656406,-0.0083923540450767,-9.49541352758763E-4,1,2.40952031852084E-7,,,,,,,,,,,,,,,,,,,,,50.0081062316895,50.0100708007812,1399.73840332031,1399.73840332031,53.4336888316595,5.63802381778474,4.69261932373047,54,1,0,0,1,0.298233032226562,34.2131004333496,1,1,3,50.0101051330566,0,50.0090885162354,,,,,,,,,,,,,,,,,,,,,,,,,,,,,,,,,
,3878495885.23474,50.0574436187744,1199.68591308594,-5.52243169930521E-6,2.34184810685461E-8,1,4,13.4005146026611,4.99664772742319,32.8699983656406,-0.00690167407530891,-7.31767046394665E-4,1,2.36835840441343E-7,,,,,,,,,,,,,,,,,,,,,50.0547027587891,50.0601844787598,1199.68591308594,1199.68591308594,53.5849339501307,5.63791751437166,4.68803310394287,54,1,0,0,1,0.299835205078125,34.2131004333496,1,1,3,50.0601844787598,0,50.0574436187744,,,,,,,,,,,,,,,,,,,,,,,,,,,,,,,,,
,3878495942.4853,50.0672836303711,999.834716796875,-4.37232239456385E-6,2.30690482059273E-8,1,4,13.4005146026611,4.99664073814387,32.8699983656406,-0.00546959336219716,-5.44056614990412E-4,1,2.15947366490218E-7,,,,,,,,,,,,,,,,,,,,,50.0643768310547,50.0701904296875,999.834716796875,999.834716796875,53.4157113757172,5.63888660424287,4.68720293045044,54,1,0,0,1,0.2978515625,34.2131004333496,1,1,3,50.0643768310547,0,50.0672836303711,,,,,,,,,,,,,,,,,,,,,,,,,,,,,,,,,
,3878496000.92389,50.0645275115967,799.731811523437,-3.23861677338339E-6,2.41448791466553E-8,1,4,13.4005146026611,4.9966472988862,32.880000770092,-0.00406227940283264,-3.30143273893805E-4,1,2.18615452744048E-7,,,,,,,,,,,,,,,,,,,,,50.0642509460449,50.0648040771484,799.731811523437,799.731811523437,53.6271418901691,5.6381460169654,4.6836109161377,54,1,0,0,1,0.299224853515625,34.2131004333496,1,1,3,50.0648040771484,0,50.0645275115967,,,,,,,,,,,,,,,,,,,,,,,,,,,,,,,,,
,3878496057.27088,50.0103759765625,599.893249511719,-2.13062172956525E-6,2.11743163914401E-8,1,4,13.4005146026611,4.9965873307449,32.8699983656406,-0.00268761113850607,-1.15829825763546E-4,1,2.25449512850777E-7,,,,,,,,,,,,,,,,,,,,,50.0099792480469,50.0107727050781,599.893249511719,599.893249511719,53.4289990605441,5.63785916795888,4.6877589225769,54,1,0,0,1,0.297622680664063,34.2131004333496,1,1,3,50.0099792480469,0,50.0103759765625,,,,,,,,,,,,,,,,,,,,,,,,,,,,,,,,,
,3878496116.05579,50.0367183685303,399.941436767578,-1.15273985751808E-6,5.66307004437692E-8,1,4,13.4005146026611,4.99656939982062,32.8699983656406,-0.00147408955528178,7.10713075143804E-5,1,2.29677174347016E-7,,,,,,,,,,,,,,,,,,,,,50.0352973937988,50.0381393432617,399.941436767578,399.941436767578,53.4051593907076,5.6375017203118,4.68696546554565,54,1,0,0,1,0.297698974609375,34.7018585205078,1,1,3,50.0381393432617,0,50.0367183685303,,,,,,,,,,,,,,,,,,,,,,,,,,,,,,,,,
,3878496172.80461,50.0384216308594,200.153259277344,-1.22290852242806E-7,2.50550980008343E-8,1,4,13.4005146026611,4.99667619412987,32.8699983656406,-1.93004516596712E-4,2.52322244896208E-4,1,2.21485348200403E-7,,,,,,,,,,,,,,,,,,,,,50.038028717041,50.0388145446777,200.153259277344,200.153259277344,53.5564045091787,5.63849688210034,4.69710731506348,54,1,0,0,1,0.297088623046875,34.2131004333496,1,1,3,50.038028717041,0,50.0384216308594,,,,,,,,,,,,,,,,,,,,,,,,,,,,,,,,,
,3878496229.2836,50.0299758911133,0.138470813632011,7.24362127796443E-7,2.36491862049103E-8,1,4,13.4005146026611,4.99664803030979,32.8699983656406,8.64469962962458E-4,3.68746827912288E-4,1,1.88588623110335E-7,,,,,,,,,,,,,,,,,,,,,50.0272598266602,50.0326919555664,0.138470813632011,0.138470813632011,53.475896771698,5.63839793131029,4.69888019561768,54,1,0,0,1,0.296783447265625,33.7243423461914,1,1,3,50.0326919555664,0,50.0299758911133,,,,,,,,,,,,,,,,,,,,,,,,,,,,,,,,,
,3878496304.85212,50.0148105621338,-199.813369750977,1.46647596780481E-6,1.14208909665385E-8,1,4,13.4005146026611,4.99659727834423,32.8699983656406,0.00181934757706606,2.83618042053822E-4,1,9.0227120371216E-9,,,,,,,,,,,,,,,,,,,,,50.0138778686523,50.0157432556152,-199.813369750977,-199.813369750977,53.5435076386114,5.63868066059456,4.69225931167603,54,1,0,0,1,0.29876708984375,34.7018585205078,1,1,3,50.0138778686523,0,50.0148105621338,,,,,,,,,,,,,,,,,,,,,,,,,,,,,,,,,
,3878496363.27234,50.0079975128174,-399.689666748047,2.05986980210854E-6,2.10621646249975E-8,1,4,13.4005146026611,4.99663926553783,32.8699983656406,0.00252641839049355,5.93171952265089E-4,1,1.69533748586203E-7,,,,,,,,,,,,,,,,,,,,,50.0073280334473,50.0086669921875,-399.689666748047,-399.689666748047,53.5153690119191,5.63860427904706,4.6967396736145,53,1,68,0,0,0.298919677734375,34.2131004333496,1,1,3,50.0073280334473,0,50.0079975128174,,,,,,,,,,,,,,,,,,,,,,,,,,,,,,,,,
,3878496437.83054,50.0027351379395,-599.603759765625,2.87335709467336E-6,1.24800633777245E-8,1,4,13.4005146026611,4.99657654136918,32.8699983656406,0.00353532814129953,7.52315598291623E-4,1,1.76009070743661E-7,,,,,,,,,,,,,,,,,,,,,50.0019798278809,50.003490447998,-599.603759765625,-599.603759765625,53.5087251695057,5.63816430573674,4.6965913772583,54,1,0,0,1,0.2984619140625,34.2131004333496,1,1,3,50.003490447998,0,50.0027351379395,,,,,,,,,,,,,,,,,,,,,,,,,,,,,,,,,
,3878496495.4442,50.014554977417,-799.631103515625,3.8110019834243E-6,1.88962495042727E-8,1,4,13.4005146026611,4.99660735852159,32.8699983656406,0.00469952974907412,9.27637367372769E-4,1,1.76924701110336E-7,,,,,,,,,,,,,,,,,,,,,50.0131492614746,50.0159606933594,-799.631103515625,-799.631103515625,53.5161506404384,5.63840448460746,4.69553565979004,52,1,68,0,0,0.297622680664063,33.7243423461914,1,1,3,50.0131492614746,0,50.014554977417,,,,,,,,,,,,,,,,,,,,,,,,,,,,,,,,,
,3878496553.19914,50.0406341552734,-999.545166015625,4.90686617875215E-6,2.61629251762278E-8,1,4,13.4005146026611,4.99655451742886,32.8699983656406,0.00606489948860302,0.00110013240542747,1,1.51913680443313E-7,,,,,,,,,,,,,,,,,,,,,50.0399360656738,50.041332244873,-999.545166015625,-999.545166015625,53.4887936422653,5.63799933465502,4.69812726974487,53,1,68,0,0,0.297470092773438,33.7243423461914,1,1,3,50.0399360656738,0,50.0406341552734,,,,,,,,,,,,,,,,,,,,,,,,,,,,,,,,,
,3878496636.93513,50.0105075836182,-1199.63562011719,5.9710183869773E-6,1.48583873495925E-8,1,4,13.4005146026611,4.99661689974891,32.8699983656406,0.00738424241438471,0.00131254410602083,10,1.6376243357334E-7,,,,,,,,,,,,,,,,,,,,,50.009578704834,50.0114364624023,-1199.63562011719,-1199.63562011719,53.5392086817557,5.63745344867406,4.69151830673218,54,1,0,0,1,0.29754638671875,33.7243423461914,1,1,3,50.009578704834,0,50.0105075836182,,,,,,,,,,,,,,,,,,,,,,,,,,,,,,,,,
,3878496728.94277,50.0284767150879,-1399.5244140625,7.17430985603348E-6,7.64485711552094E-8,1,4,13.4005146026611,4.99658232073565,32.8699983656406,0.00887380469606396,0.00156659985698985,10,1.88360421877085E-7,,,,,,,,,,,,,,,,,,,,,50.0261917114258,50.03076171875,-1399.5244140625,-1399.5244140625,53.6482458601884,5.63744416928721,4.69636917114258,54,1,0,0,1,0.297775268554687,33.7243423461914,1,1,3,50.03076171875,0,50.0284767150879,,,,,,,,,,,,,,,,,,,,,,,,,,,,,,,,,
,3878496797.6811,50.0269603729248,-1599.69030761719,8.2886146721351E-6,1.02726731826332E-8,1,4,13.4005146026611,4.9965055885925,32.8699983656406,0.0102686352179625,0.00169769445174363,1,1.27268008338766E-7,,,,,,,,,,,,,,,,,,,,,50.0253562927246,50.028564453125,-1599.69030761719,-1599.69030761719,53.5661748656691,5.63726934708542,4.70238351821899,54,1,0,0,1,0.297775268554687,33.7243423461914,1,1,3,50.0253562927246,0,50.0269603729248,,,,,,,,,,,,,,,,,,,,,,,,,,,,,,,,,
,3878496859.5217,50.0075244903564,-1799.70495605469,9.4801868168046E-6,1.12436190270574E-8,1,4,13.4005146026611,4.99653170682058,32.8699983656406,0.0117536601280375,0.00188348606517375,1,9.86274561951616E-8,,,,,,,,,,,,,,,,,,,,,50.0071792602539,50.007869720459,-1799.70495605469,-1799.70495605469,53.6349581753614,5.63646265386552,4.70020866394043,54,1,0,0,1,0.2984619140625,34.2131004333496,1,1,3,50.0071792602539,0,50.0075244903564,,,,,,,,,,,,,,,,,,,,,,,,,,,,,,,,,
,3878496917.47698,50.0219402313232,-1999.68200683594,1.06763954636053E-5,1.0233658163165E-8,1,4,13.4005146026611,4.99658573039776,32.8699983656406,0.0132366993054672,0.00212275658880043,1,1.12344960877299E-7,,,,,,,,,,,,,,,,,,,,,50.0172462463379,50.0266342163086,-1999.68200683594,-1999.68200683594,53.6560621453807,5.63811853258126,4.70238542556763,54,1,0,0,1,0.297775268554687,33.2355842590332,1,1,3,50.0266342163086,0,50.0219402313232,,,,,,,,,,,,,,,,,,,,,,,,,,,,,,,,,
,3878496976.16201,50.0393352508545,-2199.72192382813,1.18968986853382E-5,8.6904205046629E-9,1,4,13.4005146026611,4.99655391266779,32.8699983656406,0.0147571369040139,0.00231608898233203,1,8.54735043005564E-8,,,,,,,,,,,,,,,,,,,,,50.0361557006836,50.0425148010254,-2199.72192382813,-2199.72192382813,53.470816186323,5.63837433218285,4.70253896713257,54,1,0,0,1,0.296707153320313,33.7243423461914,1,1,3,50.0361557006836,0,50.0393352508545,,,,,,,,,,,,,,,,,,,,,,,,,,,,,,,,,
,3878497033.90047,50.0039615631103,-2399.48510742187,1.31147268720589E-5,1.10931675550628E-8,1,4,13.4005146026611,4.99651426813449,32.8699983656406,0.0162664631793361,0.00256056740894686,1,1.00198442812403E-7,,,,,,,,,,,,,,,,,,,,,50.003547668457,50.0043754577637,-2399.48510742187,-2399.48510742187,53.541944381573,5.63783232845215,4.6980128288269,54,1,0,0,1,0.297698974609375,34.2131004333496,1,1,3,50.003547668457,0,50.0039615631103,,,,,,,,,,,,,,,,,,,,,,,,,,,,,,,,,
,3878497091.53205,50.0152530670166,-2599.51245117187,1.43528268042834E-5,7.24032261509311E-9,1,4,13.4005146026611,4.99653653278091,32.8699983656406,0.0178087747889738,0.00275846442073048,1,7.43432391777248E-8,,,,,,,,,,,,,,,,,,,,,50.0140838623047,50.0164222717285,-2599.51245117187,-2599.51245117187,53.3633422649287,5.63785829247858,4.70338010787964,54,1,0,0,1,0.297775268554687,34.2131004333496,1,1,3,50.0140838623047,0,50.0152530670166,,,,,,,,,,,,,,,,,,,,,,,,,,,,,,,,,
,3878497151.7554,50.0323238372803,-2799.77905273438,1.55787623121713E-5,7.63414119341529E-9,1,4,13.4005146026611,4.99655728060931,32.8699983656406,0.0193279945189775,0.00300756555626046,1,9.15420832075869E-8,,,,,,,,,,,,,,,,,,,,,50.0298690795898,50.0347785949707,-2799.77905273438,-2799.77905273438,53.5016905128326,5.63776372082678,4.69105625152588,54,1,0,0,1,0.298538208007812,34.2131004333496,1,1,3,50.0298690795898,0,50.0323238372803,,,,,,,,,,,,,,,,,,,,,,,,,,,,,,,,,
,3878497212.3093,50.0457401275635,-2999.80639648438,1.68220173453113E-5,7.47288469602635E-9,1,4,13.4005146026611,4.99656668638075,32.8699983656406,0.0208742356214072,0.00322268703859574,1,7.87918821100102E-8,,,,,,,,,,,,,,,,,,,,,50.0454177856445,50.0460624694824,-2999.80639648438,-2999.80639648438,53.4458040737076,5.63852230183611,4.70064735412598,54,1,0,0,1,0.298233032226562,34.2131004333496,1,1,3,50.0460624694824,0,50.0457401275635,,,,,,,,,,,,,,,,,,,,,,,,,,,,,,,,,
,3878497290.97206,50.0050716400146,-4499.759765625,2.62553132651568E-5,6.88879899793045E-9,1,4,13.4005146026611,4.9965018895138,32.8699983656406,0.0326100760556434,0.00482409082308871,1,-4.2674073871386E-8,,,,,,,,,,,,,,,,,,,,,50.0045318603516,50.0056114196777,-4499.759765625,-4499.759765625,53.562266723073,5.63717360194365,4.69245719909668,54,1,0,0,1,0.298385620117188,34.2131004333496,1,1,3,50.0045318603516,0,50.0050716400146,,,,,,,,,,,,,,,,,,,,,,,,,,,,,,,,,
,3878497358.2181,50.0067558288574,-6499.4921875,3.89005257858401E-5,8.78616850081304E-9,1,4,13.4005146026611,4.99652496029516,32.8699983656406,0.0483180991113951,0.00713493063956982,1,-7.33809507697113E-8,,,,,,,,,,,,,,,,,,,,,50.0066986083984,50.0068130493164,-6499.4921875,-6499.4921875,53.6318316612845,5.63846205498684,4.70185089111328,54,1,0,0,1,0.2978515625,34.2131004333496,1,1,3,50.0066986083984,0,50.0067558288574,,,,,,,,,,,,,,,,,,,,,,,,,,,,,,,,,
,3878497423.35128,50.0549488067627,-8499.6279296875,5.16301878037819E-5,1.35700709911742E-8,1,4,13.4005146026611,4.99647956418773,32.8699983656406,0.0641271716812807,0.00947994547577017,1,-8.90768992159064E-8,,,,,,,,,,,,,,,,,,,,,50.0522422790527,50.0576553344727,-8499.6279296875,-8499.6279296875,53.5435076386114,5.63758589579812,4.69975996017456,52,1,68,0,0,0.29937744140625,33.2355842590332,1,1,3,50.0522422790527,0,50.0549488067627,,,,,,,,,,,,,,,,,,,,,,,,,,,,,,,,,
,3878497504.61796,50.024435043335,-9999.556640625,6.11231174330263E-5,1.3925133114911E-8,1,4,13.4005146026611,4.99649143916792,32.8699983656406,0.0759128949778225,0.0112577881322517,1,-7.74414664476516E-8,,,,,,,,,,,,,,,,,,,,,50.0241394042969,50.024730682373,-9999.556640625,-9999.556640625,53.5106792408037,5.63757382738561,4.6972541809082,54,1,0,0,1,0.299301147460937,33.7243423461914,1,1,3,50.0241394042969,0,50.024435043335,,,,,,,,,,,,,,,,,,,,,,,,,,,,,,,,,
,3878497661.18529,50.0440654754639,-29999.73828125,1.88582661165618E-4,3.69241778951124E-8,1,4,13.4005146026611,4.99651344456352,32.8699983656406,0.234195720373332,0.0348619011120411,1,-1.35748459092358E-7,,,,,,,,,,,,,,,,,,,,,50.0373916625977,50.0507392883301,-29999.73828125,-29999.73828125,53.4266541749864,5.63729136172137,4.70229911804199,54,1,0,0,1,0.298995971679687,34.2131004333496,1,1,3,50.0507392883301,0,50.0440654754639,,,,,,,,,,,,,,,,,,,,,,,,,,,,,,,,,
,3878497829.43772,50.0123233795166,-49999.56640625,3.16235659173326E-4,5.07797704306162E-8,1,4,13.4005146026611,4.9965568240845,32.8699983656406,0.392775768905559,0.058150322811576,10,-4.77741552727381E-7,,,,,,,,,,,,,,,,,,,,,50.0112342834473,50.0134124755859,-49999.56640625,-49999.56640625,53.4739427003999,5.63843422289671,4.69352531433105,54,1,0,0,1,0.299072265625,33.7243423461914,1,1,3,50.0112342834473,0,50.0123233795166,,,,,,,,,,,,,,,,,,,,,,,,,,,,,,,,,
,3878498015.07601,50.0118751525879,-69999.5,4.43884577128473E-4,1.77112343210658E-7,1,4,13.4005146026611,4.9965357001697,32.8699983656406,0.551233072843457,0.0821828807458161,1,-2.19129186005439E-7,,,,,,,,,,,,,,,,,,,,,50.0109825134277,50.012767791748,-69999.5,-69999.5,53.3074558258037,5.63898595578974,4.6950306892395,54,1,0,0,1,0.2978515625,34.2131004333496,1,1,3,50.0109825134277,0,50.0118751525879,,,,,,,,,,,,,,,,,,,,,,,,,,,,,,,,,
,3878498175.83568,50.026237487793,-49999.6015625,3.15954890959863E-4,5.85639521576354E-8,1,4,13.4005146026611,4.99649605468262,32.880000770092,0.392357219275316,0.0585197975636166,1,-1.37395221725421E-7,,,,,,,,,,,,,,,,,,,,,50.0215911865234,50.0308837890625,-49999.6015625,-49999.6015625,53.447367330746,5.63777602245503,4.69509887695313,54,1,0,0,1,0.298385620117188,34.2131004333496,1,1,3,50.0308837890625,0,50.026237487793,,,,,,,,,,,,,,,,,,,,,,,,,,,,,,,,,
,3878498336.93416,50.0001831054687,-29999.6875,1.88327124633809E-4,2.85729237441427E-8,1,4,13.4005146026611,4.99644443083831,32.8699983656406,0.233859536076871,0.0349096935992483,1,-5.84896655503271E-8,,,,,,,,,,,,,,,,,,,,,50.0001182556152,50.0002479553223,-29999.6875,-29999.6875,53.5818074360538,5.6371225652545,4.69268035888672,54,1,0,0,1,0.299072265625,34.2131004333496,1,1,3,50.0002479553223,0,50.0001831054687,,,,,,,,,,,,,,,,,,,,,,,,,,,,,,,,,
,3878498493.17459,50.0369491577148,-9999.93359375,6.08333588704502E-5,1.17256102664588E-8,1,4,13.4005146026611,4.99651600333345,32.8699983656406,0.0755404790583853,0.0112918365040221,1,-6.7378992761521E-9,,,,,,,,,,,,,,,,,,,,,50.0334510803223,50.0404472351074,-9999.93359375,-9999.93359375,53.5392086817557,5.63831216685578,4.69431734085083,54,1,0,0,1,0.298538208007812,34.2131004333496,1,1,3,50.0404472351074,0,50.0369491577148,,,,,,,,,,,,,,,,,,,,,,,,,,,,,,,,,
,3878498566.54172,50.0178833007812,-8500.4208984375,5.12505654485575E-5,1.03229718045851E-8,1,4,13.4005146026611,4.99641385775575,32.8699983656406,0.0636372073131817,0.00952560155933036,1,4.62173053712212E-9,,,,,,,,,,,,,,,,,,,,,50.016544342041,50.0192222595215,-8500.4208984375,-8500.4208984375,53.668959015948,5.63802395159274,4.69586849212646,53,1,68,0,0,0.2984619140625,34.2131004333496,1,1,3,50.016544342041,0,50.0178833007812,,,,,,,,,,,,,,,,,,,,,,,,,,,,,,,,,
,3878498631.33511,50.0589771270752,-6500.3984375,3.85274286913442E-5,9.92224960731333E-9,1,4,13.4005146026611,4.99646743263343,32.8699983656406,0.0478378663401441,0.00717360679270754,1,1.3671873580456E-8,,,,,,,,,,,,,,,,,,,,,50.0549621582031,50.0629920959473,-6500.3984375,-6500.3984375,53.6544988883422,5.63801343988937,4.69598579406738,53,1,68,0,0,0.29876708984375,34.2131004333496,1,1,3,50.0629920959473,0,50.0589771270752,,,,,,,,,,,,,,,,,,,,,,,,,,,,,,,,,
,3878498697.74324,50.0226783752441,-4500.25048828125,2.58515859048805E-5,6.93720713040074E-9,1,4,13.4005146026611,4.99648603844634,32.8699983656406,0.032097005844038,0.00482665211203046,1,1.98009893176371E-8,,,,,,,,,,,,,,,,,,,,,50.0205688476562,50.024787902832,-4500.25048828125,-4500.25048828125,53.5771176649383,5.63811531825713,4.69211292266846,52,1,68,0,0,0.298843383789063,34.2131004333496,1,1,3,50.0205688476562,0,50.0226783752441,,,,,,,,,,,,,,,,,,,,,,,,,,,,,,,,,
,3878498776.61464,50.0551910400391,-3000.4482421875,1.64464887349105E-5,6.3681936470649E-9,1,4,13.4005146026611,4.99646785761926,32.8699983656406,0.0204262971504068,0.00302621656034626,1,-2.31834909051518E-8,,,,,,,,,,,,,,,,,,,,,50.0543479919434,50.0560340881348,-3000.4482421875,-3000.4482421875,53.5630483515922,5.63884195632348,4.69990825653076,54,1,0,0,1,0.298385620117188,34.2131004333496,1,1,3,50.0543479919434,0,50.0551910400391,,,,,,,,,,,,,,,,,,,,,,,,,,,,,,,,,
,3878498841.35222,50.0264205932617,-2800.25732421875,1.53120733073766E-5,1.69356923867588E-8,1,4,13.4005146026611,4.99648257814462,32.8699983656406,0.0190530369430909,0.00257958982006988,10,-2.13173439044671E-7,,,,,,,,,,,,,,,,,,,,,50.0235824584961,50.0292587280273,-2800.25732421875,-2800.25732421875,53.4899660850441,5.63838125838421,4.69333410263062,54,1,0,0,1,0.297164916992188,34.2131004333496,1,1,3,50.0235824584961,0,50.0264205932617,,,,,,,,,,,,,,,,,,,,,,,,,,,,,,,,,
,3878498907.96485,50.0241661071777,-2600.33081054687,1.40522261118407E-5,1.68856507748346E-8,1,4,13.4005146026611,4.99654537189655,32.8699983656406,0.0174848702256185,0.00237292371953541,1,-1.91175885671936E-7,,,,,,,,,,,,,,,,,,,,,50.0231590270996,50.0251731872559,-2600.33081054687,-2600.33081054687,53.5931410495826,5.6381614735618,4.70280981063843,54,1,0,0,1,0.299835205078125,34.2131004333496,1,1,3,50.0251731872559,0,50.0241661071777,,,,,,,,,,,,,,,,,,,,,,,,,,,,,,,,,
,3878498964.8346,50.0394611358643,-2400.240234375,1.27862339509188E-5,1.94555938194184E-8,1,4,13.4005146026611,4.99646597752396,32.8699983656406,0.0159075849384436,0.00217036227302166,1,-1.64878096368109E-7,,,,,,,,,,,,,,,,,,,,,50.0387153625488,50.0402069091797,-2400.240234375,-2400.240234375,53.4852763139287,5.63867924690176,4.69453573226929,53,1,64,0,0,0.2984619140625,34.2131004333496,1,1,3,50.0402069091797,0,50.0394611358643,,,,,,,,,,,,,,,,,,,,,,,,,,,,,,,,,
,3878499020.48514,50.0347347259521,-2200.38916015625,1.15788874837085E-5,1.95231542237425E-8,1,4,13.4005146026611,4.9964454961185,32.880000770092,0.0144124199931503,0.00191862462647968,1,-1.8699019549426E-7,,,,,,,,,,,,,,,,,,,,,50.0346412658691,50.0348281860352,-2200.38916015625,-2200.38916015625,53.5024721413518,5.63796993404137,4.70171499252319,54,1,0,0,1,0.298004150390625,34.2131004333496,1,1,3,50.0348281860352,0,50.0347347259521,,,,,,,,,,,,,,,,,,,,,,,,,,,,,,,,,
,3878499077.13253,50.029203414917,-2000.412109375,1.03449443465909E-5,1.84146795822552E-8,1,4,13.4005146026611,4.99640258094177,32.8699983656406,0.0128827859901915,0.00167116336151118,1,-2.01673512489808E-7,,,,,,,,,,,,,,,,,,,,,50.0271148681641,50.0312919616699,-2000.412109375,-2000.412109375,53.5884512784672,5.63788286712643,4.69607067108154,54,1,0,0,1,0.297622680664063,34.2131004333496,1,1,3,50.0271148681641,0,50.029203414917,,,,,,,,,,,,,,,,,,,,,,,,,,,,,,,,,
,3878499134.44009,50.049337387085,-1800.12048339844,9.1326387405341E-6,2.16891273172343E-8,1,4,13.4005146026611,4.99641550940861,32.8699983656406,0.0113750346884902,0.00146250507041345,1,-1.88366662815907E-7,,,,,,,,,,,,,,,,,,,,,50.0479545593262,50.0507202148438,-1800.12048339844,-1800.12048339844,53.5528871808422,5.63743655822792,4.70026969909668,52,1,68,0,0,0.2978515625,34.2131004333496,1,1,3,50.0507202148438,0,50.049337387085,,,,,,,,,,,,,,,,,,,,,,,,,,,,,,,,,
,3878499192.83907,50.035551071167,-1600.05529785156,7.91782494817309E-6,1.88434511155691E-8,1,4,13.4005146026611,4.99644629169615,32.8699983656406,0.00986568718277561,0.00124349348819581,1,-1.83026328849031E-7,,,,,,,,,,,,,,,,,,,,,50.0334358215332,50.0376663208008,-1600.05529785156,-1600.05529785156,53.4481489592653,5.63828497401725,4.69979476928711,54,1,0,0,1,0.298538208007812,34.2131004333496,1,1,3,50.0334358215332,0,50.035551071167,,,,,,,,,,,,,,,,,,,,,,,,,,,,,,,,,
,3878499250.33052,50.0293216705322,-1400.02795410156,6.75340781775651E-6,2.23241294076762E-8,1,4,13.4005146026611,4.99647762184008,32.8699983656406,0.00842939379973445,9.63649674845108E-4,1,-2.34212134922473E-7,,,,,,,,,,,,,,,,,,,,,50.0271301269531,50.0315132141113,-1400.02795410156,-1400.02795410156,53.5407719387941,5.63841777661083,4.70317459106445,52,1,68,0,0,0.298385620117188,34.7018585205078,1,1,3,50.0271301269531,0,50.0293216705322,,,,,,,,,,,,,,,,,,,,,,,,,,,,,,,,,
,3878499309.71273,50.0356540679932,-1200.15161132812,5.54000540456845E-6,2.3813483927174E-8,1,4,13.4005146026611,4.99591901960602,32.8699983656406,0.00692123774818001,7.40531556913767E-4,1,-2.3228496257157E-7,,,,,,,,,,,,,,,,,,,,,50.0335960388184,50.037712097168,-1200.15161132812,-1200.15161132812,53.4590917585345,5.64104399468721,4.6925802230835,52,1,68,0,0,0.298614501953125,34.2131004333496,1,1,3,50.0335960388184,0,50.0356540679932,,,,,,,,,,,,,,,,,,,,,,,,,,,,,,,,,
,3878499367.38128,50.0525455474854,-1000.21234130859,4.39454063146613E-6,2.68847123744111E-8,1,4,13.4005146026611,4.99588481246919,32.8699983656406,0.0055015813354012,5.1088524904186E-4,1,-2.4589658182278E-7,,,,,,,,,,,,,,,,,,,,,50.0489349365234,50.0561561584473,-1000.21234130859,-1000.21234130859,53.6595794737172,5.64091101755583,4.70507860183716,52,1,68,0,0,0.299072265625,34.2131004333496,1,1,3,50.0561561584473,0,50.0525455474854,,,,,,,,,,,,,,,,,,,,,,,,,,,,,,,,,
,3878499425.14636,50.0573883056641,-800.172424316406,3.24109110813951E-6,2.3669716083928E-8,1,4,13.4005146026611,4.99591420118309,32.8699983656406,0.00406484371029508,3.28349553688881E-4,1,-2.20375731243052E-7,,,,,,,,,,,,,,,,,,,,,50.0567359924316,50.0580406188965,-800.172424316406,-800.172424316406,53.587669649948,5.64115214512901,4.7032265663147,53,1,68,0,0,0.29876708984375,34.2131004333496,1,1,3,50.0567359924316,0,50.0573883056641,,,,,,,,,,,,,,,,,,,,,,,,,,,,,,,,,
,3878499499.64942,50.0350284576416,-600.132446289063,2.18790234896743E-6,2.66752115810869E-8,1,4,13.4005146026611,4.99602903970312,32.8699983656406,0.00276579172391179,7.64273935114876E-5,1,-2.65739698406377E-7,,,,,,,,,,,,,,,,,,,,,50.0328330993652,50.037223815918,-600.132446289063,-600.132446289063,53.6490274887076,5.64046602149791,4.69314241409302,53,1,68,0,0,0.298614501953125,34.2131004333496,1,1,3,50.037223815918,0,50.0350284576416,,,,,,,,,,,,,,,,,,,,,,,,,,,,,,,,,
,3878499574.56426,50.0372066497803,-400.155456542969,1.12135551205365E-6,2.43314359641751E-8,1,4,13.4005146026611,4.99550716120963,32.8699983656406,0.00143766153804521,-9.67388167461181E-5,1,-2.4567575460582E-7,,,,,,,,,,,,,,,,,,,,,50.0342597961426,50.040153503418,-400.155456542969,-400.155456542969,53.4063318334864,5.64257125167175,4.69535350799561,53,1,68,0,0,0.298690795898438,34.2131004333496,1,1,3,50.0342597961426,0,50.0372066497803,,,,,,,,,,,,,,,,,,,,,,,,,,,,,,,,,
,3878499649.78837,50.0012607574463,-200.24137878418,1.27012947599549E-7,2.59170832516266E-8,1,4,13.4005146026611,4.99555980639386,32.8699983656406,1.96965171521716E-4,-2.39059685149918E-4,1,-2.11571849060479E-7,,,,,,,,,,,,,,,,,,,,,50.0011177062988,50.0014038085937,-200.24137878418,-200.24137878418,53.602911406073,5.64217464396288,4.69545984268188,53,1,68,0,0,0.298919677734375,34.2131004333496,1,1,3,50.0014038085937,0,50.0012607574463,,,,,,,,,,,,,,,,,,,,,,,,,,,,,,,,,
,3878499706.67439,50.0454406738281,-0.214000344276428,-6.90875659622193E-7,2.85162877711196E-8,1,4,13.4005146026611,4.99553844056055,32.8699983656406,-8.12374375254126E-4,-4.30976975553304E-4,1,-2.43819366531817E-7,,,,,,,,,,,,,,,,,,,,,50.0425453186035,50.0483360290527,-0.214000344276428,-0.214000344276428,53.528656696746,5.64203054930113,4.69733238220215,53,1,68,0,0,0.29937744140625,34.2131004333496,1,1,3,50.0425453186035,0,50.0454406738281,,,,,,,,,,,,,,,,,,,,,,,,,,,,,,,,,
,3878499764.3082,50.0225601196289,199.863723754883,-1.42692170268236E-6,1.51340859240618E-8,1,4,13.4005146026611,4.99567938068669,32.880000770092,-0.00176656480058607,-2.97658492000226E-4,1,-2.6308282571031E-8,,,,,,,,,,,,,,,,,,,,,50.021614074707,50.0235061645508,199.863723754883,199.863723754883,53.5478065954672,5.64170461878004,4.70535087585449,54,1,0,0,1,0.30029296875,34.2131004333496,1,1,3,50.021614074707,0,50.0225601196289,,,,,,,,,,,,,,,,,,,,,,,,,,,,,,,,,
,3878499822.7305,50.0185966491699,399.752624511719,-2.01486111381256E-6,2.11742321839513E-8,1,4,13.4005146026611,4.99560533462034,32.8699983656406,-0.00247326499323622,-5.61555787692101E-4,1,-1.50937547440376E-7,,,,,,,,,,,,,,,,,,,,,50.0168342590332,50.0203590393066,399.752624511719,399.752624511719,53.5071619124672,5.64211996500323,4.70655107498169,54,1,0,0,1,0.299453735351562,33.7243423461914,1,1,3,50.0168342590332,0,50.0185966491699,,,,,,,,,,,,,,,,,,,,,,,,,,,,,,,,,
,3878499880.53308,50.002161026001,599.91845703125,-2.85896273140049E-6,1.6117939341886E-8,1,4,13.4005146026611,4.9955699739202,32.8699983656406,-0.00351494493900339,-7.59568221461798E-4,1,-1.84175575408861E-7,,,,,,,,,,,,,,,,,,,,,50.0020523071289,50.002269744873,599.91845703125,599.91845703125,53.4993456272749,5.6422981093493,4.69660186767578,54,1,0,0,1,0.299072265625,34.2131004333496,1,1,3,50.002269744873,0,50.002161026001,,,,,,,,,,,,,,,,,,,,,,,,,,,,,,,,,
,3878499938.16366,50.0077362060547,799.744445800781,-3.80030715209132E-6,2.13164799377661E-8,1,4,13.4005146026611,4.99554818295511,32.880000770092,-0.00468705813579559,-9.10669559000602E-4,1,-1.65078145844856E-7,,,,,,,,,,,,,,,,,,,,,50.0071411132812,50.0083312988281,799.744445800781,799.744445800781,53.4641723439095,5.64199340611486,4.69815158843994,54,1,0,0,1,0.299530029296875,34.2131004333496,1,1,3,50.0071411132812,0,50.0077362060547,,,,,,,,,,,,,,,,,,,,,,,,,,,,,,,,,
,3878499995.85822,50.0480651855469,999.897644042969,-4.81237069215708E-6,4.79885054691537E-8,1,4,13.4005146026611,4.99545987165729,32.8699983656406,-0.00595055279894734,-0.001050039485251,1,-1.25968655422446E-7,,,,,,,,,,,,,,,,,,,,,50.0461616516113,50.0499687194824,999.897644042969,999.897644042969,53.425090917948,5.64231020904213,4.69618225097656,52,1,68,0,0,0.300140380859375,34.2131004333496,1,1,3,50.0499687194824,0,50.0480651855469,,,,,,,,,,,,,,,,,,,,,,,,,,,,,,,,,
,3878500053.45776,50.0353031158447,1199.64819335938,-5.93436953449904E-6,1.68401418743674E-8,1,4,13.4005146026611,4.99539481849928,32.8699983656406,-0.00734026520531752,-0.00127824309124461,1,-1.41974986334781E-7,,,,,,,,,,,,,,,,,,,,,50.0352973937988,50.0353088378906,1199.64819335938,1199.64819335938,53.5059894696884,5.64143314976403,4.69654321670532,52,1,68,0,0,0.300216674804687,34.2131004333496,1,1,3,50.0352973937988,0,50.0353031158447,,,,,,,,,,,,,,,,,,,,,,,,,,,,,,,,,
,3878500127.47478,50.0242938995361,1399.78881835938,-7.07496175535108E-6,1.15615213515867E-8,1,4,13.4005146026611,4.99562986182783,32.8699983656406,-0.00875137146067986,-0.00152587687171808,1,-1.70755893907272E-7,,,,,,,,,,,,,,,,,,,,,50.0220375061035,50.0265502929687,1399.78881835938,1399.78881835938,53.5153690119191,5.64085086668703,4.69546365737915,53,1,68,0,0,0.298690795898438,34.2131004333496,1,1,3,50.0220375061035,0,50.0242938995361,,,,,,,,,,,,,,,,,,,,,,,,,,,,,,,,,
,3878500185.27896,50.0314044952393,1599.67761230469,-8.24363200171376E-6,1.74085277420747E-8,1,4,13.4005146026611,4.99587952824714,32.8699983656406,-0.0102078769856285,-0.00170982975915584,1,-1.44011633464584E-7,,,,,,,,,,,,,,,,,,,,,50.0291595458984,50.0336494445801,1599.67761230469,1599.67761230469,53.5302199537845,5.64096508699717,4.70514965057373,52,1,68,0,0,0.299606323242188,33.7243423461914,1,1,3,50.0291595458984,0,50.0314044952393,,,,,,,,,,,,,,,,,,,,,,,,,,,,,,,,,
,3878500242.93206,50.0041980743408,1799.73022460938,-9.45149108794476E-6,8.91656361937162E-9,1,4,13.4005146026611,4.99554192147021,32.8699983656406,-0.0117113282557355,-0.00190068726134194,1,-1.17197308707272E-7,,,,,,,,,,,,,,,,,,,,,50.0039863586426,50.0044097900391,1799.73022460938,1799.73022460938,53.526702625448,5.64243465738872,4.69708681106567,52,1,68,0,0,0.299835205078125,34.2131004333496,1,1,3,50.0039863586426,0,50.0041980743408,,,,,,,,,,,,,,,,,,,,,,,,,,,,,,,,,
,3878500300.56059,50.0207996368408,1999.98413085938,-1.06413128691771E-5,3.427857717822E-8,1,4,13.4005146026611,4.99538310055249,32.880000770092,-0.0131826657433053,-0.00215578582537982,1,-1.44777062606924E-7,,,,,,,,,,,,,,,,,,,,,50.0191307067871,50.0224685668945,1999.98413085938,1999.98413085938,53.4923109706018,5.64229793538705,4.69637775421143,54,1,0,0,1,0.30059814453125,33.7243423461914,1,1,3,50.0191307067871,0,50.0207996368408,,,,,,,,,,,,,,,,,,,,,,,,,,,,,,,,,
,3878500358.18597,50.0196437835693,2199.873046875,-1.18715316975284E-5,1.05118248620048E-8,1,4,13.4005146026611,4.99572347897298,32.8699983656406,-0.0147214157213173,-0.00231614987431002,1,-8.97514883581381E-8,,,,,,,,,,,,,,,,,,,,,50.0191993713379,50.0200881958008,2199.873046875,2199.873046875,53.4387694170345,5.64126138886577,4.69451808929443,54,1,0,0,1,0.29937744140625,33.7243423461914,1,1,3,50.0191993713379,0,50.0196437835693,,,,,,,,,,,,,,,,,,,,,,,,,,,,,,,,,
,3878500415.94065,50.0319309234619,2399.98852539062,-1.30885929099221E-5,6.80784627867125E-9,1,4,13.4005146026611,4.99584699959194,32.8699983656406,-0.0162350819271414,-0.00252778591989469,1,-7.80890323124001E-8,,,,,,,,,,,,,,,,,,,,,50.0295524597168,50.034309387207,2399.98852539062,2399.98852539062,53.4223552181307,5.64091572764037,4.69364500045776,54,1,0,0,1,0.298843383789063,34.2131004333496,1,1,3,50.0295524597168,0,50.0319309234619,,,,,,,,,,,,,,,,,,,,,,,,,,,,,,,,,
,3878500473.7346,50.0387554168701,2599.87744140625,-1.43350722305619E-5,7.89671895747957E-9,1,4,13.4005146026611,4.9959275492573,32.8699983656406,-0.0177839523873754,-0.00275295833455205,1,-7.2943512407416E-8,,,,,,,,,,,,,,,,,,,,,50.0350570678711,50.0424537658691,2599.87744140625,2599.87744140625,53.4497122163037,5.64030965103508,4.70096397399902,54,1,0,0,1,0.29876708984375,33.7243423461914,1,1,3,50.0425567626953,0,50.0387554168701,,,,,,,,,,,,,,,,,,,,,,,,,,,,,,,,,
,3878500531.29863,50.049877166748,2800.03076171875,-1.55630053490007E-5,7.79040968840457E-9,1,4,13.4005146026611,4.99614011873324,32.880000770092,-0.0193086262249435,-0.00298787394838291,1,-7.83226757095831E-8,,,,,,,,,,,,,,,,,,,,,50.0475692749023,50.0521850585937,2800.03076171875,2800.03076171875,53.5290475110057,5.63923194339764,4.70031642913818,54,1,0,0,1,0.298385620117188,34.7018585205078,1,1,3,50.0521850585937,0,50.049877166748,,,,,,,,,,,,,,,,,,,,,,,,,,,,,,,,,
,3878500588.96854,50.0128421783447,2999.7685546875,-1.67993502202679E-5,9.43775113145345E-9,1,4,13.4005146026611,4.99618298723195,32.8699983656406,-0.02084488783847,-0.00321117208851472,1,-7.31877452499637E-8,,,,,,,,,,,,,,,,,,,,,50.0118865966797,50.0137977600098,2999.7685546875,2999.7685546875,53.425090917948,5.63931356143812,4.70646715164185,54,1,0,0,1,0.299835205078125,34.2131004333496,1,1,3,50.0118865966797,0,50.0128421783447,,,,,,,,,,,,,,,,,,,,,,,,,,,,,,,,,
,3878500667.12532,50.0490703582764,4499.57080078125,-2.61534081731237E-5,8.13531554352031E-8,1,4,13.4005146026611,4.99631698308575,32.8699983656406,-0.0324825955447594,-0.00479995251208699,1,4.6668551254662E-8,,,,,,,,,,,,,,,,,,,,,50.0463333129883,50.0518074035645,4499.57080078125,4499.57080078125,53.5145873833999,5.63818101499818,4.70426368713379,54,1,0,0,1,0.298385620117188,34.7018585205078,1,1,3,50.0518074035645,0,50.0490703582764,,,,,,,,,,,,,,,,,,,,,,,,,,,,,,,,,
,3878500733.00854,50.008638381958,6499.71875,-3.88723403973014E-5,1.05947144169245E-8,1,4,13.4005146026611,4.9963247268845,32.8699983656406,-0.0482801415030691,-0.00713096040527913,1,7.20396228294889E-8,,,,,,,,,,,,,,,,,,,,,50.0077590942383,50.0095176696777,6499.71875,6499.71875,53.4649539724287,5.63846827798784,4.70413208007812,54,1,0,0,1,0.297470092773438,34.2131004333496,1,1,3,50.0077590942383,0,50.008638381958,,,,,,,,,,,,,,,,,,,,,,,,,,,,,,,,,
,3878500797.87668,50.0754890441895,8500.0048828125,-5.15815349380111E-5,1.292633562784E-8,1,4,13.4005146026611,4.99625993933514,32.8699983656406,-0.0640642539304942,-0.00946070401907456,1,9.68254585714904E-8,,,,,,,,,,,,,,,,,,,,,50.0749549865723,50.0760231018066,8500.0048828125,8500.0048828125,53.5431168243518,5.63840082518243,4.69547557830811,54,1,0,0,1,0.298995971679687,33.7243423461914,1,1,3,50.0760231018066,0,50.0754890441895,,,,,,,,,,,,,,,,,,,,,,,,,,,,,,,,,
,3878500870.13405,50.0049800872803,10000.0595703125,-6.10939075288473E-5,1.42120775549344E-8,1,4,13.4005146026611,4.99622439332367,32.880000770092,-0.0758715859631134,-0.0112472382217649,1,8.08900324294236E-8,,,,,,,,,,,,,,,,,,,,,50.0048904418945,50.005069732666,10000.0595703125,10000.0595703125,53.5095067980249,5.63850185696724,4.69954872131348,54,1,0,0,1,0.298385620117188,34.2131004333496,1,1,3,50.0048904418945,0,50.0049800872803,,,,,,,,,,,,,,,,,,,,,,,,,,,,,,,,,
,3878501025.85987,50.0054378509521,30000.505859375,-1.88553703592278E-4,3.3963931346133E-8,1,4,13.4005146026611,4.99629430479814,32.8699983656406,-0.234154922141688,-0.0347906063101409,1,1.87111059734983E-7,,,,,,,,,,,,,,,,,,,,,50.0050773620605,50.0057983398438,30000.505859375,30000.505859375,53.4844946854095,5.63832963562865,4.6943244934082,52,1,68,0,0,0.29876708984375,33.7243423461914,1,1,3,50.0050773620605,0,50.0054378509521,,,,,,,,,,,,,,,,,,,,,,,,,,,,,,,,,
,3878501183.39834,50.0229949951172,50000.2578125,-3.16156567638116E-4,4.89909127384077E-8,1,4,13.4005146026611,4.99639476820742,32.8699983656406,-0.392610105463197,-0.0584646712814764,1,2.10622901023966E-7,,,,,,,,,,,,,,,,,,,,,50.0215644836426,50.0244255065918,50000.2578125,50000.2578125,53.3422382949095,5.63803285595233,4.70602989196777,54,1,0,0,1,0.297927856445313,33.7243423461914,1,1,3,50.0244255065918,0,50.0229949951172,,,,,,,,,,,,,,,,,,,,,,,,,,,,,,,,,
,3878501350.56729,50.0164985656738,70000.2890625,-4.44102423151141E-4,2.20279744210623E-7,1,4,13.4005146026611,4.99639731910013,32.8699983656406,-0.551587414043431,-0.0815167902915251,10,7.85585598303012E-7,,,,,,,,,,,,,,,,,,,,,50.0160827636719,50.0169143676758,70000.2890625,70000.2890625,53.4207919610922,5.63916393224428,4.70568084716797,54,1,0,0,1,0.298995971679687,34.2131004333496,1,1,3,50.0169143676758,0,50.0164985656738,,,,,,,,,,,,,,,,,,,,,,,,,,,,,,,,,