File: SQUID/22163_LCOT/LCOT_MH_300K_FC+1T.csv
Comment,Time Stamp (sec),Temperature (K),Magnetic Field (Oe),Moment (emu),M. Std. Err. (emu),Transport Action,Averaging Time (sec),Frequency (Hz),Peak Amplitude (mm),Center Position (mm),Lockin Signal' (V),Lockin Signal (V),Range,M. Quad. Signal (emu),AC Moment (emu),AC M. Std Err. (emu),AC Phase (deg),AC Phase Std. Err. (deg),AC Susceptibility (emu/Oe),AC Suscept. Std Err. (emu/Oe),AC X' (emu/Oe),AC X' Std Err. (emu/Oe),AC X'' (emu/Oe),AC X'' Std Err. (emu/Oe),AC Drive (Oe),AC Frequency (Hz),AC Averaging Time (sec),AC Cycles,AC Range,AC Measure Type,AC Signal' (V),AC Signal'' (V),AC Trim Coil Ratio,AC Trim Coil Phase,Min. Temperature (K),Max. Temperature (K),Min. Field (Oe),Max. Field (Oe),Mass (grams),Motor Lag (deg),Pressure (Torr),Measure Count,Measurement Number,SQUID Status (code),Motor Status (code),Measure Status (code),Motor Current (amps),Motor Temp. (C),Temp. Status (code),Field Status (code),Chamber Status (code),Chamber Temp (K),Redirection State,Average Temp (K),Rotation Angle (deg),Rotator state,DC Moment Fixed Ctr (emu),DC Moment Err Fixed Ctr (emu),DC Moment Free Ctr (emu),DC Moment Err Free Ctr (emu),DC Fixed Fit,DC Free Fit,DC Calculated Center (mm),DC Calculated Center Err (mm),DC Scan Length (mm),DC Scan Time (s),DC Number of Points,DC Squid Drift,DC Min V (V),DC Max V (V),DC Scans per Measure,Sample Resistance,He3 Temperature,Sorb Resistance,Sorb Temperature,Map 05,Map 06,Map 07,Map 08,Map 09,Map 10,Map 11,Map 12,Map 13,Map 14,Map 15,Map 16
,3878518189.3946,299.990737915039,69999.5390625,-4.53999560134799E-4,2.21657289289411E-7,1,4,13.4005146026611,5.00634855952272,33.1499986350536,-0.565468737055753,-0.0834536835512872,10,8.93114366687349E-7,,,,,,,,,,,,,,,,,,,,,299.990509033203,299.990966796875,69999.5390625,69999.5390625,53.1311985947172,5.64295395187318,5.82194709777832,54,1,0,0,1,0.301055908203125,33.2355842590332,1,1,3,299.990966796875,0,299.990737915039,,,,,,,,,,,,,,,,,,,,,,,,,,,,,,,,,
,3878518376.64391,300.120574951172,49999.578125,-3.23293547341754E-4,7.78072583367367E-8,1,4,13.4005146026611,5.00632808945287,33.1499986350536,-0.402633142172914,-0.0596638687071661,10,4.45845857367444E-7,,,,,,,,,,,,,,,,,,,,,300.099975585937,300.141174316406,49999.578125,49999.578125,53.2308562309191,5.64269194135037,6.13990640640259,54,1,0,0,1,0.301971435546875,34.2131004333496,1,1,3,300.14208984375,0,300.120574951172,,,,,,,,,,,,,,,,,,,,,,,,,,,,,,,,,
,3878518559.09795,300.127899169922,29999.548828125,-1.92674628388982E-4,2.52032915823132E-8,1,4,13.4005146026611,5.00634708572913,33.1499986350536,-0.239920483246373,-0.0358241939708978,1,5.21849990380096E-8,,,,,,,,,,,,,,,,,,,,,300.110656738281,300.145141601562,29999.548828125,29999.548828125,53.4583101300153,5.64283874502166,6.48979616165161,54,1,0,0,1,0.301132202148438,34.7018585205078,1,1,3,300.145141601562,0,300.127899169922,,,,,,,,,,,,,,,,,,,,,,,,,,,,,,,,,
,3878518718.66713,299.915756225586,9999.7451171875,-6.23955217881593E-5,1.14437475789249E-8,1,4,13.4005146026611,5.00659871680884,33.1499986350536,-0.0776983039838179,-0.0116202548481076,1,2.30374432186352E-9,,,,,,,,,,,,,,,,,,,,,299.915191650391,299.916320800781,9999.7451171875,9999.7451171875,53.5055986554287,5.6411819670942,6.7926549911499,54,1,0,0,1,0.298538208007812,34.7018585205078,1,1,3,299.916320800781,0,299.915756225586,,,,,,,,,,,,,,,,,,,,,,,,,,,,,,,,,
,3878518797.48644,299.903213500977,8499.4892578125,-5.26310392151509E-5,1.24608454493445E-8,1,4,13.4005146026611,5.00657642605687,33.1499986350536,-0.0655387038594003,-0.00980120923131108,1,2.33857275464191E-9,,,,,,,,,,,,,,,,,,,,,299.8984375,299.907989501953,8499.4892578125,8499.4892578125,53.5251393684095,5.64148613946784,6.81987428665161,53,1,68,0,0,0.3021240234375,34.7018585205078,1,1,3,299.898315429687,0,299.903213500977,,,,,,,,,,,,,,,,,,,,,,,,,,,,,,,,,
,3878518865.02744,299.906600952148,6499.69384765625,-3.96751621281013E-5,4.7906849413924E-8,1,4,13.4005146026611,5.00648288778512,33.1499986350536,-0.0494027469841524,-0.00739756457687811,1,-5.66964401571272E-9,,,,,,,,,,,,,,,,,,,,,299.893585205078,299.919616699219,6499.69384765625,6499.69384765625,53.5231852971114,5.64097463218416,6.78625774383545,53,1,68,0,0,0.30120849609375,35.190616607666,1,1,3,299.919616699219,0,299.906600952148,,,,,,,,,,,,,,,,,,,,,,,,,,,,,,,,,
,3878518933.56483,300.13703918457,4499.78466796875,-2.66458425109268E-5,8.83888591415941E-9,1,4,13.4005146026611,5.00655244738881,33.1499986350536,-0.0331768819379728,-0.00498602921018428,1,-1.80441681621342E-8,,,,,,,,,,,,,,,,,,,,,300.121551513672,300.152526855469,4499.78466796875,4499.78466796875,53.4649539724287,5.64120616750443,6.7504997253418,54,1,0,0,1,0.298919677734375,34.7018585205078,1,1,3,300.152526855469,0,300.13703918457,,,,,,,,,,,,,,,,,,,,,,,,,,,,,,,,,
,3878519017.59022,300.285049438477,2999.5546875,-1.70065342267908E-5,6.73392374882758E-9,1,4,13.4005146026611,5.00656473249811,33.1499986350536,-0.0211811446308891,-0.00314123560168692,1,2.1469757387549E-8,,,,,,,,,,,,,,,,,,,,,300.284851074219,300.285247802734,2999.5546875,2999.5546875,53.414929747198,5.64129715298751,6.70769548416138,54,1,0,0,1,0.301132202148438,34.2131004333496,1,1,3,300.285247802734,0,300.285049438477,,,,,,,,,,,,,,,,,,,,,,,,,,,,,,,,,
,3878519075.16989,300.157241821289,2799.75390625,-1.58222894176217E-5,1.68117832708384E-8,1,4,13.4005146026611,5.00654756118164,33.1499986350536,-0.0197382637757059,-0.00270752613119343,1,1.92598655245797E-7,,,,,,,,,,,,,,,,,,,,,300.151794433594,300.162689208984,2799.75390625,2799.75390625,53.5044262126499,5.64064002986885,6.68597602844238,52,1,68,0,0,0.301513671875,34.7018585205078,1,1,3,300.151794433594,0,300.157241821289,,,,,,,,,,,,,,,,,,,,,,,,,,,,,,,,,
,3878519150.97619,300.092926025391,2599.63842773438,-1.45590951819049E-5,1.69497556000173E-8,1,4,13.4005146026611,5.00652265146971,33.1499986350536,-0.0181668449196103,-0.0024610081272954,1,2.01588712467838E-7,,,,,,,,,,,,,,,,,,,,,300.085540771484,300.100311279297,2599.63842773438,2599.63842773438,53.4661264152076,5.64091837422423,6.65748929977417,53,1,68,0,0,0.3009033203125,34.7018585205078,1,1,3,300.085540771484,0,300.092926025391,,,,,,,,,,,,,,,,,,,,,,,,,,,,,,,,,
,3878519210.4128,299.953002929687,2399.5478515625,-1.32846403948357E-5,1.54677095066157E-8,1,4,13.4005146026611,5.00654737725702,33.1499986350536,-0.0165760265209334,-0.00225005825606211,1,1.80358154687314E-7,,,,,,,,,,,,,,,,,,,,,299.951385498047,299.954620361328,2399.5478515625,2399.5478515625,53.552105552323,5.64145146208097,6.64077568054199,52,1,68,0,0,0.299453735351562,34.7018585205078,1,1,3,299.954620361328,0,299.953002929687,,,,,,,,,,,,,,,,,,,,,,,,,,,,,,,,,
,3878519287.7309,299.913879394531,2199.83520507813,-1.20144525646057E-5,1.39720172564518E-8,1,4,13.4005146026611,5.00656514199704,33.1499986350536,-0.0149973888849673,-0.00199364783431727,1,1.96267964445279E-7,,,,,,,,,,,,,,,,,,,,,299.910858154297,299.916900634766,2199.83520507813,2199.83520507813,53.4958282989384,5.64245474718404,6.61144685745239,53,1,68,0,0,0.300827026367188,34.7018585205078,1,1,3,299.916900634766,0,299.913879394531,,,,,,,,,,,,,,,,,,,,,,,,,,,,,,,,,
,3878519345.94252,299.957336425781,1999.63159179687,-1.07743212856837E-5,2.189573846735E-8,1,4,13.4005146026611,5.00653570485021,33.1499986350536,-0.0134564251252593,-0.00173987475350024,1,2.1453565491433E-7,,,,,,,,,,,,,,,,,,,,,299.954650878906,299.960021972656,1999.63159179687,1999.63159179687,53.4028145051499,5.64170901941076,6.59347438812256,54,1,0,0,1,0.299835205078125,34.2131004333496,1,1,3,299.960021972656,0,299.957336425781,,,,,,,,,,,,,,,,,,,,,,,,,,,,,,,,,
,3878519413.76842,300.11540222168,1799.64208984375,-9.51217702773161E-6,1.95734992555199E-8,1,4,13.4005146026611,5.00652543854665,33.1499986350536,-0.0118830379693376,-0.00151611541330325,10,2.05416957133296E-7,,,,,,,,,,,,,,,,,,,,,300.105010986328,300.125793457031,1799.64208984375,1799.64208984375,53.4172746327557,5.64196293199717,6.57178688049316,54,1,0,0,1,0.30029296875,34.7018585205078,1,1,3,300.105010986328,0,300.11540222168,,,,,,,,,,,,,,,,,,,,,,,,,,,,,,,,,
,3878519490.06134,300.302993774414,1599.51403808594,-8.29572521077938E-6,2.33741264660874E-8,1,4,13.4005146026611,5.00650426038184,33.1499986350536,-0.0103746183347659,-0.00124676493686233,10,2.39744505411483E-7,,,,,,,,,,,,,,,,,,,,,300.296112060547,300.309875488281,1599.51403808594,1599.51403808594,53.4110216046018,5.64189639599826,6.54891490936279,54,1,0,0,1,0.301513671875,34.7018585205078,1,1,3,300.309875488281,0,300.302993774414,,,,,,,,,,,,,,,,,,,,,,,,,,,,,,,,,
,3878519564.65587,300.272247314453,1399.70068359375,-7.08648338153236E-6,1.99560845398716E-8,1,4,13.4005146026611,5.00648383434924,33.1499986350536,-0.00886812100095598,-0.00102605785794618,10,2.3608886080118E-7,,,,,,,,,,,,,,,,,,,,,300.271697998047,300.272796630859,1399.70068359375,1399.70068359375,53.5564045091787,5.64141739367343,6.52761316299438,54,1,0,0,1,0.301284790039063,34.2131004333496,1,1,3,300.272796630859,0,300.272247314453,,,,,,,,,,,,,,,,,,,,,,,,,,,,,,,,,
,3878519646.41751,300.003173828125,1199.66076660156,-5.89929202007367E-6,1.99357982235663E-8,1,4,13.4005146026611,5.00650628991274,33.1499986350536,-0.00739191714472869,-7.91217320046436E-4,1,2.47091808743928E-7,,,,,,,,,,,,,,,,,,,,,299.990264892578,300.016082763672,1199.66076660156,1199.66076660156,53.4989548130153,5.64168743780228,6.5075831413269,52,1,68,0,0,0.300369262695313,34.7018585205078,1,1,3,299.990264892578,0,300.003173828125,,,,,,,,,,,,,,,,,,,,,,,,,,,,,,,,,
,3878519737.23696,299.972671508789,999.822143554687,-4.70157286170784E-6,2.30991964067485E-8,1,4,13.4005146026611,5.00649385457338,33.1499986350536,-0.00589625751560929,-5.96322764342481E-4,1,2.2443345879868E-7,,,,,,,,,,,,,,,,,,,,,299.971435546875,299.973907470703,999.822143554687,999.822143554687,53.4841038711499,5.64080183964601,6.48396968841553,54,1,0,0,1,0.300750732421875,34.7018585205078,1,1,3,299.973907470703,0,299.972671508789,,,,,,,,,,,,,,,,,,,,,,,,,,,,,,,,,
,3878519795.03132,300.16178894043,799.706665039063,-3.50360547129583E-6,2.02980849630856E-8,1,4,13.4005146026611,5.00647363482815,33.1499986350536,-0.00440728988510756,-3.54587229202321E-4,1,2.39355470279507E-7,,,,,,,,,,,,,,,,,,,,,300.156036376953,300.167541503906,799.706665039063,799.706665039063,53.4786324715153,5.64134598389705,6.47584056854248,54,1,0,0,1,0.300216674804687,34.7018585205078,1,1,3,300.156036376953,0,300.16178894043,,,,,,,,,,,,,,,,,,,,,,,,,,,,,,,,,
,3878519868.78528,300.134124755859,600.044311523437,-2.47664485871463E-6,7.13794470860433E-8,1,4,13.4005146026611,5.00647341200445,33.1499986350536,-0.00314192697780409,-7.36283146394847E-5,1,3.11361300942211E-7,,,,,,,,,,,,,,,,,,,,,300.123718261719,300.14453125,600.044311523437,600.044311523437,53.4903568993037,5.64115362279445,6.45460510253906,53,1,68,0,0,0.301055908203125,34.2131004333496,1,1,3,300.14453125,0,300.134124755859,,,,,,,,,,,,,,,,,,,,,,,,,,,,,,,,,
,3878519959.29082,300.055084228516,399.966613769531,-1.149845499399E-6,2.15410471265664E-7,1,4,13.4005146026611,5.00650232418433,33.1499986350536,-0.00149081363028353,1.80277759230429E-4,1,3.16786321764194E-7,,,,,,,,,,,,,,,,,,,,,300.052093505859,300.058074951172,399.966613769531,399.966613769531,53.503253769871,5.64189412956552,6.44330787658691,52,1,68,0,0,0.299606323242188,34.2131004333496,1,1,3,300.052093505859,0,300.055084228516,,,,,,,,,,,,,,,,,,,,,,,,,,,,,,,,,
,3878520042.1755,300.102127075195,200.115493774414,-3.26171904995269E-7,2.50246624232603E-8,1,4,13.4005146026611,5.00641930479,33.1499986350536,-4.52052974098444E-4,2.46131163902278E-4,10,2.4645961362459E-7,,,,,,,,,,,,,,,,,,,,,300.092834472656,300.111419677734,200.115493774414,200.115493774414,53.5036445841307,5.6428232285731,6.42696619033814,54,1,0,0,1,0.301284790039063,33.7243423461914,1,1,3,300.111419677734,0,300.102127075195,,,,,,,,,,,,,,,,,,,,,,,,,,,,,,,,,
,3878520125.24604,300.26383972168,0.163647323846817,5.46604674727956E-7,2.44812755977168E-8,1,4,13.4005146026611,5.00644048035938,33.1499986350536,6.44653856867488E-4,3.42297160734115E-4,1,1.93126260878048E-7,,,,,,,,,,,,,,,,,,,,,300.262023925781,300.265655517578,0.163647323846817,0.163647323846817,53.3942165914383,5.64194588448063,6.41028022766113,54,1,0,0,1,0.300979614257812,33.7243423461914,1,1,3,300.265655517578,0,300.26383972168,,,,,,,,,,,,,,,,,,,,,,,,,,,,,,,,,
,3878520182.88204,300.201644897461,-199.83854675293,1.17770304637497E-6,3.24525945139558E-8,1,4,13.4005146026611,5.00647642691363,33.1499986350536,0.00143246241751612,4.46788514609213E-4,1,1.82630046228579E-7,,,,,,,,,,,,,,,,,,,,,300.196258544922,300.20703125,-199.83854675293,-199.83854675293,53.4798049142941,5.64172496894346,6.40419483184814,54,1,0,0,1,0.301589965820313,34.2131004333496,1,1,3,300.196258544922,0,300.201644897461,,,,,,,,,,,,,,,,,,,,,,,,,,,,,,,,,
,3878520240.51982,300.147644042969,-399.740020751953,1.93779023481326E-6,2.83586283601886E-8,1,4,13.4005146026611,5.00642699342303,33.1499986350536,0.00237884174531822,5.88715058584095E-4,1,1.82910658505457E-7,,,,,,,,,,,,,,,,,,,,,300.1376953125,300.157592773438,-399.740020751953,-399.740020751953,53.4712070005826,5.6413826025419,6.39825010299683,53,1,68,0,0,0.301284790039063,34.2131004333496,1,1,3,300.157592773438,0,300.147644042969,,,,,,,,,,,,,,,,,,,,,,,,,,,,,,,,,
,3878520323.63457,300.160751342773,-599.591186523437,2.82395592042727E-6,1.51984593703707E-8,1,4,13.4005146026611,5.00662439254151,33.1499986350536,0.00347801322805924,7.83660797802496E-4,10,2.06870331905997E-7,,,,,,,,,,,,,,,,,,,,,300.151916503906,300.169586181641,-599.591186523437,-599.591186523437,53.5231852971114,5.64204709356531,6.38500547409058,54,1,0,0,1,0.300979614257812,34.2131004333496,1,1,3,300.169586181641,0,300.160751342773,,,,,,,,,,,,,,,,,,,,,,,,,,,,,,,,,
,3878520406.26239,300.225189208984,-799.643737792969,3.91344190726696E-6,3.66957347959677E-8,1,4,13.4005146026611,5.00644782290822,33.1499986350536,0.00483337745358456,9.93830566775184E-4,1,2.12705571805824E-7,,,,,,,,,,,,,,,,,,,,,300.210815429687,300.239562988281,-799.643737792969,-799.643737792969,53.5325648393422,5.64140875103815,6.37089395523071,53,1,68,0,0,0.301895141601562,34.2131004333496,1,1,3,300.239562988281,0,300.225189208984,,,,,,,,,,,,,,,,,,,,,,,,,,,,,,,,,
,3878520480.71337,300.177932739258,-999.595520019531,4.99436787664558E-6,4.23368496253142E-8,1,4,13.4005146026611,5.00640770129859,33.1499986350536,0.00618796702019703,0.00113704080821694,1,1.66026214041517E-7,,,,,,,,,,,,,,,,,,,,,300.16162109375,300.194244384766,-999.595520019531,-999.595520019531,53.4622182726114,5.64075733375505,6.36619997024536,52,1,68,0,0,0.301742553710937,34.2131004333496,1,1,3,300.194244384766,0,300.177932739258,,,,,,,,,,,,,,,,,,,,,,,,,,,,,,,,,
,3878520562.92161,300.026062011719,-1199.57263183594,6.16984665287429E-6,1.92433375577168E-8,1,4,13.4005146026611,5.00646362866636,33.1499986350536,0.00765266161862561,0.00135006382219094,10,1.61242818524794E-7,,,,,,,,,,,,,,,,,,,,,300.0244140625,300.027709960937,-1199.57263183594,-1199.57263183594,53.4071134620056,5.64129697533208,6.35106754302979,54,1,0,0,1,0.300827026367188,34.2131004333496,1,1,3,300.0244140625,0,300.026062011719,,,,,,,,,,,,,,,,,,,,,,,,,,,,,,,,,
,3878520632.98559,300.102920532227,-1399.70068359375,7.34922249483667E-6,1.09202278406311E-8,1,4,13.4005146026611,5.00647657257735,33.1499986350536,0.00912603022296712,0.0015378299983496,1,1.35602895770721E-7,,,,,,,,,,,,,,,,,,,,,300.090484619141,300.115356445313,-1399.70068359375,-1399.70068359375,53.5474157812076,5.64113119998894,6.34270906448364,52,1,68,0,0,0.30059814453125,34.2131004333496,1,1,3,300.115356445313,0,300.102920532227,,,,,,,,,,,,,,,,,,,,,,,,,,,,,,,,,
,3878520726.89768,300.214782714844,-1599.67761230469,8.55978462570677E-6,1.18913395834689E-8,1,4,13.4005146026611,5.0065752821185,33.1499986350536,0.0106323266474953,0.00177270054561066,1,1.43090977014278E-7,,,,,,,,,,,,,,,,,,,,,300.195678710937,300.23388671875,-1599.67761230469,-1599.67761230469,53.4094583475633,5.64218624103331,6.33481311798096,54,1,0,0,1,0.299224853515625,34.7018585205078,1,1,3,300.23388671875,0,300.214782714844,,,,,,,,,,,,,,,,,,,,,,,,,,,,,,,,,
,3878520787.90989,300.145874023438,-1799.60424804687,9.84338271576206E-6,2.98609874552802E-8,1,4,13.4005146026611,5.00645455957658,33.1499986350536,0.0122370231116369,0.00196680805757971,1,1.07005521274023E-7,,,,,,,,,,,,,,,,,,,,,300.142913818359,300.148834228516,-1799.60424804687,-1799.60424804687,53.4231368466499,5.64091240381375,6.32820987701416,54,1,0,0,1,0.299758911132812,34.2131004333496,1,1,3,300.142913818359,0,300.145874023438,,,,,,,,,,,,,,,,,,,,,,,,,,,,,,,,,
,3878520846.66673,300.366119384766,-1999.58129882813,1.10655041971251E-5,2.01792962489365E-8,1,4,13.4005146026611,5.0065239785512,33.1499986350536,0.0137589370763102,0.00219540476546898,1,1.07732188098922E-7,,,,,,,,,,,,,,,,,,,,,300.362518310547,300.369720458984,-1999.58129882813,-1999.58129882813,53.4063318334864,5.6399617028684,6.32250785827637,54,1,0,0,1,0.300140380859375,34.2131004333496,1,1,3,300.362518310547,0,300.366119384766,,,,,,,,,,,,,,,,,,,,,,,,,,,,,,,,,
,3878520905.24255,300.294570922852,-2199.6337890625,1.22518220294355E-5,6.14749225022426E-8,1,4,13.4005146026611,5.00650879953706,33.1499986350536,0.0152385684686359,0.00239988515482828,1,9.44865599468471E-8,,,,,,,,,,,,,,,,,,,,,300.281646728516,300.307495117188,-2199.6337890625,-2199.6337890625,53.4782416572557,5.63992402193502,6.31729364395142,54,1,0,0,1,0.300827026367188,34.2131004333496,1,1,3,300.307495117188,0,300.294570922852,,,,,,,,,,,,,,,,,,,,,,,,,,,,,,,,,
,3878520964.94284,300.195053100586,-2399.787109375,1.35914064666639E-5,2.36453952597408E-8,1,4,13.4005146026611,5.00653019407344,33.1499986350536,0.0169103971856753,0.00262499975777512,1,7.48639096720605E-8,,,,,,,,,,,,,,,,,,,,,300.183502197266,300.206604003906,-2399.787109375,-2399.787109375,53.462609086871,5.64029328877068,6.31296348571777,54,1,0,0,1,0.299758911132812,34.2131004333496,1,1,3,300.183502197266,0,300.195053100586,,,,,,,,,,,,,,,,,,,,,,,,,,,,,,,,,
,3878521025.85466,300.055297851562,-2599.65087890625,1.48302170320473E-5,7.02153500203828E-9,1,4,13.4005146026611,5.00659905925427,33.1499986350536,0.0184541084630553,0.0028507369939732,1,7.07839170199342E-8,,,,,,,,,,,,,,,,,,,,,300.043060302734,300.067535400391,-2599.65087890625,-2599.65087890625,53.5110700550634,5.64033335081193,6.30666494369507,54,1,0,0,1,0.300521850585937,33.7243423461914,1,1,3,300.067535400391,0,300.055297851562,,,,,,,,,,,,,,,,,,,,,,,,,,,,,,,,,
,3878521085.12245,299.996704101562,-2799.71606445313,1.60915949931052E-5,1.11438891036244E-8,1,4,13.4005146026611,5.00664748456321,33.1499986350536,0.020025771937395,0.00308130701451886,1,6.72160413922587E-8,,,,,,,,,,,,,,,,,,,,,299.993072509766,300.000335693359,-2799.71606445313,-2799.71606445313,53.5040353983903,5.64039240093286,6.29963970184326,54,1,0,0,1,0.300827026367188,33.7243423461914,1,1,3,300.000335693359,0,299.996704101562,,,,,,,,,,,,,,,,,,,,,,,,,,,,,,,,,
,3878521146.45269,300.113891601562,-2999.60498046875,1.73717420765846E-5,8.23597781104249E-9,1,4,13.4005146026611,5.00655766990743,33.1499986350536,0.0216184664061691,0.00332561138088143,1,7.19676167249432E-8,,,,,,,,,,,,,,,,,,,,,300.111511230469,300.116271972656,-2999.60498046875,-2999.60498046875,53.4508846590826,5.64092300187675,6.29685306549072,54,1,0,0,1,0.2996826171875,34.2131004333496,1,1,3,300.116271972656,0,300.113891601562,,,,,,,,,,,,,,,,,,,,,,,,,,,,,,,,,
,3878521225.09555,300.183547973633,-4499.57080078125,2.69035673184377E-5,1.03312895696833E-7,1,4,13.4005146026611,5.00658946912018,33.1499986350536,0.0335075371961028,0.00497137419900805,1,-3.23200539746087E-8,,,,,,,,,,,,,,,,,,,,,300.165618896484,300.201477050781,-4499.57080078125,-4499.57080078125,53.4887936422653,5.64083222237048,6.29274129867554,54,1,0,0,1,0.30059814453125,34.2131004333496,1,1,3,300.202484130859,0,300.183547973633,,,,,,,,,,,,,,,,,,,,,,,,,,,,,,,,,
,3878521291.8598,300.055786132812,-6499.4921875,3.99727798342623E-5,1.06736509083394E-8,1,4,13.4005146026611,5.00660997343232,33.1499986350536,0.0497899421128858,0.00735411307211362,1,-7.39567177839134E-8,,,,,,,,,,,,,,,,,,,,,300.050140380859,300.061431884766,-6499.4921875,-6499.4921875,53.4254817322076,5.64026549498311,6.28359365463257,54,1,0,0,1,0.301513671875,33.7243423461914,1,1,3,300.061431884766,0,300.055786132812,,,,,,,,,,,,,,,,,,,,,,,,,,,,,,,,,
,3878521358.1756,300.245666503906,-8499.6650390625,5.29723167298968E-5,1.23392848365262E-8,1,4,13.4005146026611,5.00655499252549,33.1499986350536,0.06598050103469,0.00974961429954903,1,-9.47784548248714E-8,,,,,,,,,,,,,,,,,,,,,300.243499755859,300.247833251953,-8499.6650390625,-8499.6650390625,53.4629999011307,5.64050173863535,6.28074741363525,54,1,0,0,1,0.299606323242188,33.7243423461914,1,1,3,300.243499755859,0,300.245666503906,,,,,,,,,,,,,,,,,,,,,,,,,,,,,,,,,
,3878521439.2667,300.151184082031,-9999.6943359375,6.27169628745048E-5,1.51177631005572E-8,1,4,13.4005146026611,5.00652275449988,33.1499986350536,0.0781125369066671,0.0115754974888495,1,-8.61347020176461E-8,,,,,,,,,,,,,,,,,,,,,300.151000976562,300.1513671875,-9999.6943359375,-9999.6943359375,53.4086767190441,5.63965326419595,6.27886199951172,54,1,0,0,1,0.301284790039063,33.7243423461914,1,1,3,300.151000976562,0,300.151184082031,,,,,,,,,,,,,,,,,,,,,,,,,,,,,,,,,
,3878521596.78737,299.97607421875,-29999.701171875,1.9299013714964E-4,3.28856724311184E-8,1,4,13.4005146026611,5.00650670201545,33.1499986350536,0.240352173475525,0.0356965927629542,1,-2.0313877044501E-7,,,,,,,,,,,,,,,,,,,,,299.975524902344,299.976623535156,-29999.701171875,-29999.701171875,53.391480891621,5.64023621569846,6.26565456390381,52,1,68,0,0,0.2996826171875,34.2131004333496,1,1,3,299.975524902344,0,299.97607421875,,,,,,,,,,,,,,,,,,,,,,,,,,,,,,,,,
,3878521755.7888,299.947250366211,-49999.6640625,3.23473380761408E-4,6.42652987669407E-8,1,4,13.4005146026611,5.00656800399128,33.1499986350536,0.40283600900029,0.0600225359747196,1,-1.87926738555762E-7,,,,,,,,,,,,,,,,,,,,,299.947174072266,299.947326660156,-49999.6640625,-49999.6640625,53.3098007113614,5.6403992955874,6.25681257247925,54,1,0,0,1,0.299301147460937,34.7018585205078,1,1,3,299.947326660156,0,299.947250366211,,,,,,,,,,,,,,,,,,,,,,,,,,,,,,,,,
,3878521915.31836,300.099945068359,-69999.5625,4.54055639776145E-4,7.87503760758196E-8,1,4,13.4005146026611,5.00658470932691,33.1499986350536,0.565444491091343,0.0843478168590136,1,-1.87883937861313E-7,,,,,,,,,,,,,,,,,,,,,300.078460693359,300.121429443359,-69999.5625,-69999.5625,53.1651994353037,5.64105797147239,6.24444437026978,54,1,0,0,1,0.298843383789063,34.2131004333496,1,1,3,300.121429443359,0,300.099945068359,,,,,,,,,,,,,,,,,,,,,,,,,,,,,,,,,
,3878522075.90264,300.022521972656,-49999.65234375,3.23244016927833E-4,8.36825548342158E-8,1,4,13.4005146026611,5.00659616225501,33.1499986350536,0.402535115689118,0.060103590976508,1,-8.89028152632323E-8,,,,,,,,,,,,,,,,,,,,,300.01123046875,300.033813476562,-49999.65234375,-49999.65234375,53.376239135496,5.64060840117882,6.23605489730835,54,1,0,0,1,0.301132202148438,33.7243423461914,1,1,3,300.033813476562,0,300.022521972656,,,,,,,,,,,,,,,,,,,,,,,,,,,,,,,,,
,3878522234.69534,300.028045654297,-29999.701171875,1.92775452867218E-4,3.14974213368374E-8,1,4,13.4005146026611,5.00662711207758,33.1499986350536,0.240079992970048,0.0357442023328367,1,-1.33754503749406E-7,,,,,,,,,,,,,,,,,,,,,300.015014648438,300.041076660156,-29999.701171875,-29999.701171875,53.4266541749864,5.64075231735726,6.2334680557251,54,1,0,0,1,0.300521850585937,34.2131004333496,1,1,3,300.041076660156,0,300.028045654297,,,,,,,,,,,,,,,,,,,,,,,,,,,,,,,,,
,3878522393.40615,300.110061645508,-10000.072265625,6.24181171570074E-5,1.40936487703169E-8,1,4,13.4005146026611,5.00660875778444,33.1499986350536,0.0777289037635822,0.0116094891414809,1,-1.43554474803155E-8,,,,,,,,,,,,,,,,,,,,,300.107727050781,300.112396240234,-10000.072265625,-10000.072265625,53.5614850945537,5.64073536449749,6.22443962097168,52,1,68,0,0,0.301284790039063,34.7018585205078,1,1,3,300.107727050781,0,300.110061645508,,,,,,,,,,,,,,,,,,,,,,,,,,,,,,,,,
,3878522465.56288,300.177520751953,-8499.904296875,5.26304836464988E-5,1.80558962562547E-8,1,4,13.4005146026611,5.00667270206156,33.1499986350536,0.0655371235661611,0.00981908685878523,1,1.1889322856967E-8,,,,,,,,,,,,,,,,,,,,,300.152557373047,300.202484130859,-8499.904296875,-8499.904296875,53.4848854996691,5.64098249775467,6.21983480453491,53,1,68,0,0,0.301055908203125,34.7018585205078,1,1,3,300.202484130859,0,300.177520751953,,,,,,,,,,,,,,,,,,,,,,,,,,,,,,,,,
,3878522532.57455,300.060699462891,-6500.02099609375,3.96438571025049E-5,9.5991228335571E-9,1,4,13.4005146026611,5.00671818634033,33.1499986350536,0.0493672525020691,0.00739059338928332,1,4.36430114617702E-9,,,,,,,,,,,,,,,,,,,,,300.050903320313,300.070495605469,-6500.02099609375,-6500.02099609375,53.5513239238037,5.64053422620463,6.21946477890015,54,1,0,0,1,0.299301147460937,34.2131004333496,1,1,3,300.050445556641,0,300.060699462891,,,,,,,,,,,,,,,,,,,,,,,,,,,,,,,,,
,3878522598.62567,299.988906860352,-4499.986328125,2.66623994708946E-5,9.48238413307702E-9,1,4,13.4005146026611,5.00666852786583,33.1499986350536,0.0331997699779769,0.00498128895297721,1,1.16309549981797E-8,,,,,,,,,,,,,,,,,,,,,299.979400634766,299.998413085937,-4499.986328125,-4499.986328125,53.4665172294672,5.64077644683005,6.2152247428894,52,1,68,0,0,0.30059814453125,34.2131004333496,1,1,3,299.998413085937,0,299.988906860352,,,,,,,,,,,,,,,,,,,,,,,,,,,,,,,,,
,3878522670.32089,300.210067749023,-3000.04541015625,1.70283710863897E-5,6.52254590390512E-9,1,4,13.4005146026611,5.00668637847058,33.1499986350536,0.021209427621213,0.0031429333720939,1,-2.34587387096698E-8,,,,,,,,,,,,,,,,,,,,,300.209289550781,300.210845947266,-3000.04541015625,-3000.04541015625,53.5919686068037,5.64006878860607,6.21359634399414,54,1,0,0,1,0.300827026367188,34.2131004333496,1,1,3,300.209289550781,0,300.210067749023,,,,,,,,,,,,,,,,,,,,,,,,,,,,,,,,,
,3878522726.24915,300.102462768555,-2800.21948242187,1.58347987570636E-5,1.71979334834944E-8,1,4,13.4005146026611,5.00668290429805,33.1499986350536,0.0197546348609993,0.00270964125422474,1,-1.92853633029197E-7,,,,,,,,,,,,,,,,,,,,,300.091156005859,300.11376953125,-2800.21948242187,-2800.21948242187,53.4188378897941,5.64038801076513,6.21407032012939,54,1,0,0,1,0.300521850585937,34.2131004333496,1,1,3,300.11376953125,0,300.102462768555,,,,,,,,,,,,,,,,,,,,,,,,,,,,,,,,,
,3878522785.04694,300.201354980469,-2600.22998046875,1.4535740333874E-5,1.84229254563287E-8,1,4,13.4005146026611,5.00670683574124,33.1499986350536,0.0181355804610686,0.00247760970449129,1,-1.84865071058093E-7,,,,,,,,,,,,,,,,,,,,,300.189208984375,300.213500976562,-2600.22998046875,-2600.22998046875,53.4184470755345,5.64049599122159,6.21327209472656,54,1,0,0,1,0.2996826171875,34.7018585205078,1,1,3,300.213500976562,0,300.201354980469,,,,,,,,,,,,,,,,,,,,,,,,,,,,,,,,,
,3878522841.80018,300.36669921875,-2400.18994140625,1.32861852026941E-5,1.82134886879121E-8,1,4,13.4005146026611,5.00667131367826,33.1499986350536,0.0165838212858303,0.00221501217475707,1,-2.08795077730478E-7,,,,,,,,,,,,,,,,,,,,,300.363037109375,300.370361328125,-2400.18994140625,-2400.18994140625,53.4966099274576,5.64004434595026,6.21250438690186,54,1,0,0,1,0.299224853515625,34.7018585205078,1,1,3,300.370361328125,0,300.36669921875,,,,,,,,,,,,,,,,,,,,,,,,,,,,,,,,,
,3878522908.60031,300.421157836914,-2200.2255859375,1.19989545557988E-5,1.06521299256359E-8,1,4,13.4005146026611,5.00671675991774,33.1499986350536,0.0149593771969342,0.00212017644859336,1,-9.24114893116299E-8,,,,,,,,,,,,,,,,,,,,,300.414276123047,300.428039550781,-2200.2255859375,-2200.2255859375,53.5614850945537,5.64020238102557,6.20419025421143,54,1,0,0,1,0.300140380859375,34.7018585205078,1,1,3,300.414276123047,0,300.421157836914,,,,,,,,,,,,,,,,,,,,,,,,,,,,,,,,,
,3878522966.41945,300.363067626953,-2000.27368164062,1.07916330907572E-5,2.07050668348151E-8,1,4,13.4005146026611,5.00667095322851,33.1499986350536,0.0134770473665133,0.00175281753822485,1,-2.06784629112435E-7,,,,,,,,,,,,,,,,,,,,,300.352569580078,300.373565673828,-2000.27368164062,-2000.27368164062,53.480977357073,5.64033571716579,6.20736265182495,54,1,0,0,1,0.300445556640625,34.2131004333496,1,1,3,300.352569580078,0,300.363067626953,,,,,,,,,,,,,,,,,,,,,,,,,,,,,,,,,
,3878523023.14566,300.185577392578,-1800.03234863281,9.51410804285361E-6,2.42238417385145E-8,1,4,13.4005146026611,5.00671587829438,33.1499986350536,0.0118857330407509,0.00151883890094106,1,-2.0358353743907E-7,,,,,,,,,,,,,,,,,,,,,300.178802490234,300.192352294922,-1800.03234863281,-1800.03234863281,53.4977823702364,5.64010022155653,6.20737218856812,54,1,0,0,1,0.299911499023438,34.2131004333496,1,1,3,300.178802490234,0,300.185577392578,,,,,,,,,,,,,,,,,,,,,,,,,,,,,,,,,
,3878523080.07451,300.142578125,-1599.99243164062,8.2854517656292E-6,1.71299867240418E-8,1,4,13.4005146026611,5.00669226303219,33.1499986350536,0.0103618323903087,0.00124850829223891,1,-2.36860253628272E-7,,,,,,,,,,,,,,,,,,,,,300.1416015625,300.1435546875,-1599.99243164062,-1599.99243164062,53.4903568993037,5.64052856943211,6.20598793029785,54,1,0,0,1,0.299911499023438,34.2131004333496,1,1,3,300.1416015625,0,300.142578125,,,,,,,,,,,,,,,,,,,,,,,,,,,,,,,,,
,3878523151.93364,300.0234375,-1399.96508789062,7.06478313561678E-6,2.21369797991351E-8,1,4,13.4005146026611,5.00679505120831,33.1499986350536,0.00884426628836037,0.00100607281083164,1,-2.48962419139174E-7,,,,,,,,,,,,,,,,,,,,,300.021667480469,300.025207519531,-1399.96508789062,-1399.96508789062,53.5630483515922,5.64083495105656,6.20233821868897,53,1,68,0,0,0.299758911132812,34.2131004333496,1,1,3,300.025207519531,0,300.0234375,,,,,,,,,,,,,,,,,,,,,,,,,,,,,,,,,
,3878523210.28197,300.185241699219,-1200.13903808594,5.85530567518451E-6,2.1655101832729E-8,1,4,13.4005146026611,5.00674530771777,33.1499986350536,0.0073320705921459,8.20268671659155E-4,1,-2.17225306501727E-7,,,,,,,,,,,,,,,,,,,,,300.170837402344,300.199645996094,-1200.13903808594,-1200.13903808594,53.4528387303807,5.64034558383305,6.20203495025635,54,1,0,0,1,0.2984619140625,34.2131004333496,1,1,3,300.199645996094,0,300.185241699219,,,,,,,,,,,,,,,,,,,,,,,,,,,,,,,,,
,3878523267.54907,300.176986694336,-1000.04870605469,4.67372476461324E-6,2.18307617466305E-8,1,4,13.4005146026611,5.0067270735273,33.1499986350536,0.00586157877968968,5.93738927629648E-4,1,-2.22373625622918E-7,,,,,,,,,,,,,,,,,,,,,300.174743652344,300.179229736328,-1000.04870605469,-1000.04870605469,53.5098976122845,5.6403425452577,6.20167446136475,52,1,68,0,0,0.298843383789063,34.2131004333496,1,1,3,300.174743652344,0,300.176986694336,,,,,,,,,,,,,,,,,,,,,,,,,,,,,,,,,
,3878523324.31133,299.914627075195,-800.147277832031,3.53789633721132E-6,2.18900578125673E-8,1,4,13.4005146026611,5.00678490765607,33.1499986350536,0.00445185598691939,3.51111591247806E-4,1,-2.47300900063078E-7,,,,,,,,,,,,,,,,,,,,,299.910827636719,299.918426513672,-800.147277832031,-800.147277832031,53.4231368466499,5.63993721742173,6.19655847549438,53,1,68,0,0,0.298309326171875,34.2131004333496,1,1,3,299.910827636719,0,299.914627075195,,,,,,,,,,,,,,,,,,,,,,,,,,,,,,,,,
,3878523382.05143,299.994705200195,-600.03173828125,2.3745385904043E-6,1.78984463868591E-7,1,4,13.4005146026611,5.00667571313338,33.1499986350536,0.00304100559242698,-1.19536220193813E-4,1,-4.51208221922291E-7,,,,,,,,,,,,,,,,,,,,,299.9736328125,300.015777587891,-600.03173828125,-600.03173828125,53.5349097248999,5.64066516849427,6.19502782821655,53,1,68,0,0,0.299530029296875,34.2131004333496,1,1,3,300.015777587891,0,299.994705200195,,,,,,,,,,,,,,,,,,,,,,,,,,,,,,,,,
,3878523439.9181,300.311645507812,-400.092498779297,1.32659232146613E-6,2.72412922995862E-8,1,4,13.4005146026611,5.00663361200391,33.1499986350536,0.00169961794296857,-7.1513717587847E-5,1,-2.55878796918445E-7,,,,,,,,,,,,,,,,,,,,,300.292175292969,300.331115722656,-400.092498779297,-400.092498779297,53.4688621150249,5.64089473755122,6.19071292877197,52,1,68,0,0,0.300216674804687,34.7018585205078,1,1,3,300.331115722656,0,300.311645507812,,,,,,,,,,,,,,,,,,,,,,,,,,,,,,,,,
,3878523497.85798,300.293823242188,-200.014785766602,2.34955030226009E-7,6.48923454301196E-9,1,4,13.4005146026611,5.00660860905181,33.1499986350536,2.76627413122092E-4,1.50393824821459E-4,1,8.56260729587645E-8,,,,,,,,,,,,,,,,,,,,,300.284210205078,300.303436279297,-200.014785766602,-200.014785766602,53.3817105351306,5.64149533934577,6.19400262832642,54,1,0,0,1,0.2996826171875,34.2131004333496,1,1,3,300.284210205078,0,300.293823242188,,,,,,,,,,,,,,,,,,,,,,,,,,,,,,,,,
,3878523556.33627,300.277008056641,-0.100706040859222,-5.35998346947802E-7,1.13289826186223E-8,1,4,13.4005146026611,5.00654728050544,33.1499986350536,-6.21637902708086E-4,-4.06028634317517E-4,1,-2.45885198341674E-7,,,,,,,,,,,,,,,,,,,,,300.258331298828,300.295684814453,-0.100706040859222,-0.100706040859222,53.486057942448,5.64138474051061,6.18872785568237,52,1,68,0,0,0.2996826171875,33.7243423461914,1,1,3,300.295684814453,0,300.277008056641,,,,,,,,,,,,,,,,,,,,,,,,,,,,,,,,,
,3878523625.10597,300.329696655273,199.901489257813,-1.17445287637018E-6,2.27985635762797E-8,1,4,13.4005146026611,5.00658528920418,33.1499986350536,-0.00142154391040582,-4.92420503468857E-4,1,-2.19750393087246E-7,,,,,,,,,,,,,,,,,,,,,300.326904296875,300.332489013672,199.901489257813,199.901489257813,53.4317347603614,5.64090309201858,6.1897234916687,54,1,0,0,1,0.29937744140625,34.2131004333496,1,1,3,300.332489013672,0,300.329696655273,,,,,,,,,,,,,,,,,,,,,,,,,,,,,,,,,
,3878523683.00498,300.335540771484,399.790374755859,-1.93219475014282E-6,1.40895151361902E-8,1,4,13.4005146026611,5.00659893034238,33.1499986350536,-0.00237312851829065,-5.80078237934502E-4,1,-1.7678918300049E-7,,,,,,,,,,,,,,,,,,,,,300.322937011719,300.34814453125,399.790374755859,399.790374755859,53.5001272557941,5.64065153947819,6.19042348861694,53,1,68,0,0,0.299911499023438,34.2131004333496,1,1,3,300.34814453125,0,300.335540771484,,,,,,,,,,,,,,,,,,,,,,,,,,,,,,,,,
,3878523740.7717,300.316787719727,599.91845703125,-2.83237296242973E-6,1.67238738450358E-8,1,4,13.4005146026611,5.00649038092411,33.1499986350536,-0.00349280466694755,-7.55514929302135E-4,1,-1.83031433703373E-7,,,,,,,,,,,,,,,,,,,,,300.306640625,300.326934814453,599.91845703125,599.91845703125,53.470816186323,5.64128763951161,6.18449878692627,54,1,0,0,1,0.30029296875,34.2131004333496,1,1,3,300.326934814453,0,300.316787719727,,,,,,,,,,,,,,,,,,,,,,,,,,,,,,,,,
,3878523798.47872,300.186538696289,799.819946289063,-3.85693869157584E-6,2.59985458265761E-8,1,4,13.4005146026611,5.00660205033789,33.1499986350536,-0.0047713100328214,-9.29301726393704E-4,1,-1.69303692215638E-7,,,,,,,,,,,,,,,,,,,,,300.179870605469,300.193206787109,799.819946289063,799.819946289063,53.457528501496,5.64129061067249,6.19112634658813,54,1,0,0,1,0.30029296875,34.2131004333496,1,1,3,300.179870605469,0,300.186538696289,,,,,,,,,,,,,,,,,,,,,,,,,,,,,,,,,
,3878523856.9143,300.132720947266,999.822143554687,-4.9742836209692E-6,3.63922517183034E-8,1,4,13.4005146026611,5.00654042296845,33.1499986350536,-0.00615961998668778,-0.0011571857266499,1,-1.85174554188532E-7,,,,,,,,,,,,,,,,,,,,,300.129608154297,300.135833740234,999.822143554687,999.822143554687,53.4309531318422,5.64108986812052,6.18313312530518,52,1,68,0,0,0.301742553710937,34.2131004333496,1,1,3,300.129608154297,0,300.132720947266,,,,,,,,,,,,,,,,,,,,,,,,,,,,,,,,,
,3878523914.59142,300.111999511719,1199.68591308594,-6.14030671282083E-6,1.57639827049788E-8,1,4,13.4005146026611,5.00655696411407,33.1499986350536,-0.00761462899665596,-0.00135427570718702,1,-1.69015959637715E-7,,,,,,,,,,,,,,,,,,,,,300.110656738281,300.113342285156,1199.68591308594,1199.68591308594,53.4774600287364,5.64111880843856,6.1851601600647,53,1,64,0,0,0.2996826171875,33.7243423461914,1,1,3,300.113342285156,0,300.111999511719,,,,,,,,,,,,,,,,,,,,,,,,,,,,,,,,,
,3878523972.3335,300.170913696289,1399.81396484375,-7.34819858749516E-6,1.23856499704211E-8,1,4,13.4005146026611,5.0065460234815,33.1499986350536,-0.00912244544153512,-0.00155429262223995,1,-1.48952670323999E-7,,,,,,,,,,,,,,,,,,,,,300.165954589844,300.175872802734,1399.81396484375,1399.81396484375,53.4383786027749,5.6409615280508,6.18535232543945,53,1,68,0,0,0.299606323242188,34.2131004333496,1,1,3,300.175872802734,0,300.170913696289,,,,,,,,,,,,,,,,,,,,,,,,,,,,,,,,,
,3878524029.96688,300.240966796875,1599.72802734375,-8.55990560482853E-6,9.97455848596983E-8,1,4,13.4005146026611,5.00646321872665,33.1499986350536,-0.0106142293911705,-0.00189242639081136,1,-2.3926728268472E-7,,,,,,,,,,,,,,,,,,,,,300.2353515625,300.24658203125,1599.72802734375,1599.72802734375,53.5224036685922,5.64141602281757,6.18406248092651,53,1,68,0,0,0.2996826171875,34.2131004333496,1,1,3,300.24658203125,0,300.240966796875,,,,,,,,,,,,,,,,,,,,,,,,,,,,,,,,,
,3878524087.54303,300.191284179687,1799.76794433594,-9.74531658367654E-6,7.65826243603836E-8,1,4,13.4005146026611,5.0064652404131,33.1499986350536,-0.0121151152016324,-0.00194742596930226,1,-1.06105472588E-7,,,,,,,,,,,,,,,,,,,,,300.182312011719,300.200256347656,1799.76794433594,1799.76794433594,53.4332980173999,5.64176126404898,6.18251466751099,53,1,68,0,0,0.29876708984375,34.2131004333496,1,1,3,300.200256347656,0,300.191284179687,,,,,,,,,,,,,,,,,,,,,,,,,,,,,,,,,
,3878524145.09757,300.371246337891,2000.03442382813,-1.10460349293732E-5,1.20294421982605E-8,1,4,13.4005146026611,5.00643658358354,33.1499986350536,-0.0137324978446656,-0.0022041614541683,1,-1.17720104541856E-7,,,,,,,,,,,,,,,,,,,,,300.360015869141,300.382476806641,2000.03442382813,2000.03442382813,53.4587009442749,5.64138341387527,6.18243980407715,54,1,0,0,1,0.30120849609375,34.2131004333496,1,1,3,300.382476806641,0,300.371246337891,,,,,,,,,,,,,,,,,,,,,,,,,,,,,,,,,
,3878524202.73993,300.326507568359,2199.873046875,-1.23033746234915E-5,8.16823299762974E-9,1,4,13.4005146026611,5.00650929166752,33.1499986350536,-0.0153020879120936,-0.00241401273396965,1,-9.81198244937687E-8,,,,,,,,,,,,,,,,,,,,,300.316436767578,300.336578369141,2199.873046875,2199.873046875,53.4055502049672,5.64120251503643,6.18241310119629,54,1,0,0,1,0.302276611328125,33.7243423461914,1,1,3,300.316436767578,0,300.326507568359,,,,,,,,,,,,,,,,,,,,,,,,,,,,,,,,,
,3878524260.3478,300.042236328125,2400.08911132813,-1.35599676022601E-5,7.19447931565789E-9,1,4,13.4005146026611,5.0064916316048,33.1499986350536,-0.0168681973615164,-0.00263829861141069,1,-9.02696767636088E-8,,,,,,,,,,,,,,,,,,,,,300.035522460937,300.048950195313,2400.08911132813,2400.08911132813,53.4106307903422,5.64121048312223,6.17940807342529,54,1,0,0,1,0.300369262695313,34.2131004333496,1,1,3,300.035522460937,0,300.042236328125,,,,,,,,,,,,,,,,,,,,,,,,,,,,,,,,,
,3878524318.1045,300.199157714844,2599.96557617187,-1.4831020943128E-5,1.00501446879112E-8,1,4,13.4005146026611,5.00653792428181,33.1499986350536,-0.0184541917519469,-0.0028548671214245,1,-7.40195076864526E-8,,,,,,,,,,,,,,,,,,,,,300.176086425781,300.222229003906,2599.96557617187,2599.96557617187,53.4665172294672,5.6409669132179,6.17840147018433,54,1,0,0,1,0.300064086914063,33.7243423461914,1,1,3,300.222229003906,0,300.199157714844,,,,,,,,,,,,,,,,,,,,,,,,,,,,,,,,,
,3878524375.75928,300.308578491211,2799.93017578125,-1.61006060048585E-5,8.53350514442003E-9,1,4,13.4005146026611,5.00640514471788,33.1499986350536,-0.020034850347908,-0.00308803621271244,1,-7.14397046694014E-8,,,,,,,,,,,,,,,,,,,,,300.299346923828,300.317810058594,2799.93017578125,2799.93017578125,53.4680804865057,5.64146042579649,6.17789363861084,54,1,0,0,1,0.300064086914063,33.2355842590332,1,1,3,300.317810058594,0,300.308578491211,,,,,,,,,,,,,,,,,,,,,,,,,,,,,,,,,
,3878524461.95035,300.400985717773,2999.7685546875,-1.73621903912124E-5,8.26641274163831E-9,1,4,13.4005146026611,5.00651478418741,33.1499986350536,-0.0216018309467143,-0.00335375760590417,1,-9.603191785602E-8,,,,,,,,,,,,,,,,,,,,,300.393920898438,300.408050537109,2999.7685546875,2999.7685546875,53.4704253720634,5.64145026533947,6.1778826713562,54,1,0,0,1,0.300216674804687,34.2131004333496,1,1,3,300.408050537109,0,300.400985717773,,,,,,,,,,,,,,,,,,,,,,,,,,,,,,,,,
,3878524551.34701,300.39665222168,4499.5078125,-2.70222810328065E-5,8.33060195261996E-9,1,4,13.4005146026611,5.00654435679272,33.1499986350536,-0.0336594454821654,-0.00496331272263405,1,5.65024933958203E-8,,,,,,,,,,,,,,,,,,,,,300.396148681641,300.397155761719,4499.5078125,4499.5078125,53.5450708956499,5.64099048712553,6.17712783813477,54,1,0,0,1,0.300827026367188,33.7243423461914,1,1,3,300.397155761719,0,300.39665222168,,,,,,,,,,,,,,,,,,,,,,,,,,,,,,,,,
,3878524615.83887,300.008697509766,6499.90771484375,-3.99742700635647E-5,8.3572828104578E-9,1,4,13.4005146026611,5.00658045303263,33.1499986350536,-0.049794724755115,-0.00733202040470352,1,9.18726395232883E-8,,,,,,,,,,,,,,,,,,,,,300.002777099609,300.014617919922,6499.90771484375,6499.90771484375,53.4614366440922,5.64067585161081,6.17662715911865,54,1,0,0,1,0.299148559570313,33.7243423461914,1,1,3,300.002777099609,0,300.008697509766,,,,,,,,,,,,,,,,,,,,,,,,,,,,,,,,,
,3878524680.52349,300.244247436523,8500.357421875,-5.29740861847462E-5,1.32767231797086E-8,1,4,13.4005146026611,5.00652296192563,33.1499986350536,-0.0659838495009169,-0.00973825683969915,1,1.04093958700482E-7,,,,,,,,,,,,,,,,,,,,,300.244079589844,300.244415283203,8500.357421875,8500.357421875,53.4989548130153,5.64084330943156,6.17525768280029,53,1,68,0,0,0.300979614257812,33.7243423461914,1,1,3,300.244079589844,0,300.244247436523,,,,,,,,,,,,,,,,,,,,,,,,,,,,,,,,,
,3878524847.45508,300.169204711914,9999.783203125,-6.27018923571279E-5,1.34124963843596E-8,1,4,13.4005146026611,5.00653108458805,33.1499986350536,-0.078099370759473,-0.011536496910577,1,1.15221997627044E-7,,,,,,,,,,,,,,,,,,,,,300.167907714844,300.170501708984,9999.783203125,9999.783203125,53.3934349629191,5.64089616093675,6.17156410217285,54,1,0,0,1,0.301284790039063,34.2131004333496,1,1,3,300.167907714844,0,300.169204711914,,,,,,,,,,,,,,,,,,,,,,,,,,,,,,,,,
,3878525000.22158,300.119598388672,30000.380859375,-1.92973505745984E-4,3.01416543244436E-8,1,4,13.4005146026611,5.00647915011471,33.1499986350536,-0.240331234132483,-0.0356823944621965,1,2.11832620234043E-7,,,,,,,,,,,,,,,,,,,,,300.117523193359,300.121673583984,30000.380859375,30000.380859375,53.4907477135634,5.64093018994743,6.16864585876465,54,1,0,0,1,0.300445556640625,34.2131004333496,1,1,3,300.121673583984,0,300.119598388672,,,,,,,,,,,,,,,,,,,,,,,,,,,,,,,,,
,3878525157.09892,300.034042358398,50000.359375,-3.23459926761542E-4,8.97204651384326E-8,1,4,13.4005146026611,5.00651787982477,33.1499986350536,-0.402825310922145,-0.0599410203959494,1,2.5070222822987E-7,,,,,,,,,,,,,,,,,,,,,300.032928466797,300.03515625,50000.359375,50000.359375,53.1765330488325,5.64092068342537,6.16905498504639,52,1,68,0,0,0.300369262695313,33.7243423461914,1,1,3,300.032928466797,0,300.034042358398,,,,,,,,,,,,,,,,,,,,,,,,,,,,,,,,,
,3878525348.03532,300.037673950195,70000.40625,-4.54067588566552E-4,1.35258041245574E-7,1,4,13.4005146026611,5.00656445114808,33.1499986350536,-0.565474230737757,-0.084228843165671,1,2.8483132792584E-7,,,,,,,,,,,,,,,,,,,,,300.019744873047,300.055603027344,70000.40625,70000.40625,53.2050624897845,5.64115352800286,6.16665029525757,54,1,0,0,1,0.30059814453125,33.7243423461914,1,1,3,300.055603027344,0,300.037673950195,,,,,,,,,,,,,,,,,,,,,,,,,,,,,,,,,