File: SQUID/22163_LCOT/LCOT_MH_10K_FC+1T.csv
Comment,Time Stamp (sec),Temperature (K),Magnetic Field (Oe),Moment (emu),M. Std. Err. (emu),Transport Action,Averaging Time (sec),Frequency (Hz),Peak Amplitude (mm),Center Position (mm),Lockin Signal' (V),Lockin Signal (V),Range,M. Quad. Signal (emu),AC Moment (emu),AC M. Std Err. (emu),AC Phase (deg),AC Phase Std. Err. (deg),AC Susceptibility (emu/Oe),AC Suscept. Std Err. (emu/Oe),AC X' (emu/Oe),AC X' Std Err. (emu/Oe),AC X'' (emu/Oe),AC X'' Std Err. (emu/Oe),AC Drive (Oe),AC Frequency (Hz),AC Averaging Time (sec),AC Cycles,AC Range,AC Measure Type,AC Signal' (V),AC Signal'' (V),AC Trim Coil Ratio,AC Trim Coil Phase,Min. Temperature (K),Max. Temperature (K),Min. Field (Oe),Max. Field (Oe),Mass (grams),Motor Lag (deg),Pressure (Torr),Measure Count,Measurement Number,SQUID Status (code),Motor Status (code),Measure Status (code),Motor Current (amps),Motor Temp. (C),Temp. Status (code),Field Status (code),Chamber Status (code),Chamber Temp (K),Redirection State,Average Temp (K),Rotation Angle (deg),Rotator state,DC Moment Fixed Ctr (emu),DC Moment Err Fixed Ctr (emu),DC Moment Free Ctr (emu),DC Moment Err Free Ctr (emu),DC Fixed Fit,DC Free Fit,DC Calculated Center (mm),DC Calculated Center Err (mm),DC Scan Length (mm),DC Scan Time (s),DC Number of Points,DC Squid Drift,DC Min V (V),DC Max V (V),DC Scans per Measure,Sample Resistance,He3 Temperature,Sorb Resistance,Sorb Temperature,Map 05,Map 06,Map 07,Map 08,Map 09,Map 10,Map 11,Map 12,Map 13,Map 14,Map 15,Map 16
,3878480123.80369,10.0001158714294,70000.0390625,-4.37509354418034E-4,2.37533362388922E-6,1,4,13.4005146026611,5.006673585669,32.8599996864796,-0.545104908292867,-0.0795894570343341,10,1.53547847535957E-6,,,,,,,,,,,,,,,,,,,,,10.000111579895,10.0001201629639,70000.0390625,70000.0390625,54.116050528948,5.64219505013125,3.5407018661499,54,1,0,0,1,0.300827026367188,33.2355842590332,1,1,3,10.000111579895,0,10.0001158714294,,,,,,,,,,,,,,,,,,,,,,,,,,,,,,,,,
,3878480287.35208,10.0004782676697,50000.49609375,-3.07755470771537E-4,8.23364600063387E-8,1,4,13.4005146026611,5.0063008800565,32.8599996864796,-0.38318723211505,-0.0574089803683522,1,-6.79730612376956E-8,,,,,,,,,,,,,,,,,,,,,10.0002126693726,10.0007438659668,50000.49609375,50000.49609375,53.8628028887172,5.6445351233402,3.55247592926025,52,1,32,0,0,0.303115844726562,34.7018585205078,1,1,3,10.0007438659668,0,10.0004782676697,,,,,,,,,,,,,,,,,,,,,,,,,,,,,,,,,
,3878480459.78043,10.0001659393311,29999.6875,-1.81937377751171E-4,3.65702787368396E-8,1,4,13.4005146026611,5.00643209058674,32.8599996864796,-0.226539894910409,-0.0339344187610644,1,-3.56980740299292E-8,,,,,,,,,,,,,,,,,,,,,10.0001287460327,10.0002031326294,29999.6875,29999.6875,53.6576254024191,5.64164005749179,3.55869483947754,54,1,0,0,1,0.300750732421875,34.2131004333496,1,1,3,10.0002136230469,0,10.0001659393311,,,,,,,,,,,,,,,,,,,,,,,,,,,,,,,,,
,3878480616.50308,10.0000767707825,9999.568359375,-5.69649693334497E-5,1.60569418338179E-8,1,4,13.4005146026611,5.00640255472109,32.8599996864796,-0.0709237116476422,-0.0106637077966615,1,-4.23844688292158E-8,,,,,,,,,,,,,,,,,,,,,9.99998760223389,10.0001659393311,9999.568359375,9999.568359375,53.531783210823,5.64077171956398,3.55974555015564,54,1,0,0,1,0.30181884765625,34.2131004333496,1,1,3,10.0001659393311,0,10.0000767707825,,,,,,,,,,,,,,,,,,,,,,,,,,,,,,,,,
,3878480697.12018,10.0000696182251,8499.765625,-4.77292184805532E-5,1.43482077614056E-8,1,4,13.4005146026611,5.00646041512248,32.8599996864796,-0.0594308234723534,-0.00890126116861486,1,-8.46459278885247E-9,,,,,,,,,,,,,,,,,,,,,9.99999904632568,10.0001401901245,8499.765625,8499.765625,53.5364729819384,5.64003628341553,3.56291604042053,53,1,68,0,0,0.300445556640625,34.2131004333496,1,1,3,10.0001401901245,0,10.0000696182251,,,,,,,,,,,,,,,,,,,,,,,,,,,,,,,,,
,3878480764.37038,9.99994421005249,6499.71875,-3.53463800649367E-5,1.25937686361496E-8,1,4,13.4005146026611,5.00641654752001,32.8599996864796,-0.044008775096046,-0.00661065211892326,1,-2.13741814099024E-8,,,,,,,,,,,,,,,,,,,,,9.99993896484375,9.99994945526123,6499.71875,6499.71875,53.4008604338518,5.6401722314232,3.56283211708069,54,1,0,0,1,0.299224853515625,34.2131004333496,1,1,3,9.99993896484375,0,9.99994421005249,,,,,,,,,,,,,,,,,,,,,,,,,,,,,,,,,
,3878480833.06917,10.0000667572021,4499.6083984375,-2.30000103400647E-5,9.43958754952053E-9,1,4,13.4005146026611,5.00638284202573,32.8599996864796,-0.0286331617601325,-0.0043231191609593,1,-3.124377647743E-8,,,,,,,,,,,,,,,,,,,,,9.99993324279785,10.0002002716064,4499.6083984375,4499.6083984375,53.4864487567076,5.63954234014824,3.56164193153381,54,1,0,0,1,0.30059814453125,34.2131004333496,1,1,3,9.99993324279785,0,10.0000667572021,,,,,,,,,,,,,,,,,,,,,,,,,,,,,,,,,
,3878480917.91946,10.0001058578491,2999.74340820313,-1.38895889373736E-5,8.4396066932391E-9,1,4,13.4005146026611,5.006371862667,32.8599996864796,-0.017297362546854,-0.00257062498373997,1,1.33177396806705E-8,,,,,,,,,,,,,,,,,,,,,10.0000696182251,10.0001420974731,2999.74340820313,2999.74340820313,53.4954374846787,5.64065766630084,3.56552457809448,54,1,0,0,1,0.300369262695313,34.7018585205078,1,1,3,10.000036239624,0,10.0001058578491,,,,,,,,,,,,,,,,,,,,,,,,,,,,,,,,,
,3878480976.44971,9.99999856948852,2799.79150390625,-1.28124565039506E-5,1.67561965393452E-8,1,4,13.4005146026611,5.00632761146991,32.8599996864796,-0.015992636619367,-0.00212474215100427,1,2.10254563419443E-7,,,,,,,,,,,,,,,,,,,,,9.99999713897705,10,2799.79150390625,2799.79150390625,53.4559652444576,5.64030496975777,3.56797194480896,53,1,68,0,0,0.301742553710937,34.2131004333496,1,1,3,9.99999713897705,0,9.99999856948852,,,,,,,,,,,,,,,,,,,,,,,,,,,,,,,,,
,3878481060.32619,9.99991226196289,2599.75170898438,-1.16977101106409E-5,1.59346101862014E-8,1,4,13.4005146026611,5.0064232171818,32.8599996864796,-0.0146040318208673,-0.00192360028808682,10,2.05076447401829E-7,,,,,,,,,,,,,,,,,,,,,9.99990844726563,9.99991607666016,2599.75170898438,2599.75170898438,53.6580162166788,5.64066747903416,3.56530833244324,54,1,0,0,1,0.300216674804687,34.2131004333496,1,1,3,9.99991607666016,0,9.99991226196289,,,,,,,,,,,,,,,,,,,,,,,,,,,,,,,,,
,3878481142.47992,10.0000004768372,2399.61083984375,-1.05398457920668E-5,1.73673149737167E-8,1,4,13.4005146026611,5.00642063951928,32.8599996864796,-0.0131623218072555,-0.0017075428184199,1,2.05380220191805E-7,,,,,,,,,,,,,,,,,,,,,9.99989891052246,10.0001020431519,2399.61083984375,2399.61083984375,53.401642062371,5.64075744635778,3.57519364356995,54,1,0,0,1,0.301437377929687,34.2131004333496,1,1,3,9.99987888336182,0,10.0000004768372,,,,,,,,,,,,,,,,,,,,,,,,,,,,,,,,,
,3878481201.28566,9.99993753433228,2199.7470703125,-9.36120734362357E-6,1.64706581347377E-8,1,4,13.4005146026611,5.00634067279084,32.8599996864796,-0.0116914479403669,-0.00150794267578355,1,1.8933361305226E-7,,,,,,,,,,,,,,,,,,,,,9.99991989135742,9.99995517730713,2199.7470703125,2199.7470703125,53.3879635632845,5.64015276950367,3.57399368286133,54,1,0,0,1,0.300827026367188,34.2131004333496,1,1,3,9.99991989135742,0,9.99993753433228,,,,,,,,,,,,,,,,,,,,,,,,,,,,,,,,,
,3878481257.99463,10.0000166893005,1999.78271484375,-8.21046511180215E-6,2.41426298322379E-8,1,4,13.4005146026611,5.00644677664246,32.8599996864796,-0.0102613508036679,-0.00127722583793901,1,2.02511286853963E-7,,,,,,,,,,,,,,,,,,,,,9.99991607666016,10.0001173019409,1999.78271484375,1999.78271484375,53.531783210823,5.64039922490638,3.56594109535217,53,1,68,0,0,0.300827026367188,34.2131004333496,1,1,3,10.0001173019409,0,10.0000166893005,,,,,,,,,,,,,,,,,,,,,,,,,,,,,,,,,
,3878481331.60103,9.99992227554321,1799.50354003906,-7.05962914406441E-6,1.87548882951424E-8,1,4,13.4005146026611,5.00644487267033,32.8599996864796,-0.00883514823943931,-0.0010172845169647,1,2.39108428369027E-7,,,,,,,,,,,,,,,,,,,,,9.99985980987549,9.99998474121094,1799.50354003906,1799.50354003906,53.5036445841307,5.64040069147196,3.56846404075623,54,1,0,0,1,0.301437377929687,33.7243423461914,1,1,3,9.99985980987549,0,9.99992227554321,,,,,,,,,,,,,,,,,,,,,,,,,,,,,,,,,
,3878481389.32386,9.99976205825806,1599.51403808594,-5.8849931351923E-6,1.88881234604893E-8,1,4,13.4005146026611,5.00641416310647,32.8599996864796,-0.00737258387403047,-7.97480144371001E-4,1,2.39906796288884E-7,,,,,,,,,,,,,,,,,,,,,9.99974822998047,9.99977588653564,1599.51403808594,1599.51403808594,53.6369122466595,5.64028460037449,3.5697283744812,54,1,0,0,1,0.30120849609375,34.2131004333496,1,1,3,9.99974822998047,0,9.99976205825806,,,,,,,,,,,,,,,,,,,,,,,,,,,,,,,,,
,3878481464.01765,9.99999284744263,1399.71325683594,-4.77087825654983E-6,1.99994056775034E-8,1,4,13.4005146026611,5.00647423269492,32.8599996864796,-0.0059861108244912,-5.85256174439903E-4,1,2.43685863567724E-7,,,,,,,,,,,,,,,,,,,,,9.99992561340332,10.0000600814819,1399.71325683594,1399.71325683594,53.4833222426306,5.6395274828748,3.57053351402283,54,1,0,0,1,0.30181884765625,34.2131004333496,1,1,3,10.0000600814819,0,9.99999284744263,,,,,,,,,,,,,,,,,,,,,,,,,,,,,,,,,
,3878481521.38975,10.0002083778381,1199.77392578125,-3.623967434828E-6,2.23976521958511E-8,1,4,13.4005146026611,5.00645949894859,32.8599996864796,-0.00455246779526108,-4.0828627031437E-4,1,2.14234894956801E-7,,,,,,,,,,,,,,,,,,,,,10.0000591278076,10.0003576278687,1199.77392578125,1199.77392578125,53.4958282989384,5.63948586980737,3.5782516002655,54,1,0,0,1,0.300369262695313,34.2131004333496,1,1,3,10.0003576278687,0,10.0002083778381,,,,,,,,,,,,,,,,,,,,,,,,,,,,,,,,,
,3878481577.9031,10.0000228881836,999.897644042969,-2.50792234475185E-6,2.11319288628725E-8,1,4,13.4005146026611,5.00651496020528,32.8599996864796,-0.00316153354280845,-2.08987473294899E-4,1,2.07337767471951E-7,,,,,,,,,,,,,,,,,,,,,9.99999523162842,10.0000505447388,999.897644042969,999.897644042969,53.4735518861403,5.63947186087249,3.57156777381897,54,1,0,0,1,0.301055908203125,34.2131004333496,1,1,3,10.0001239776611,0,10.0000228881836,,,,,,,,,,,,,,,,,,,,,,,,,,,,,,,,,
,3878481634.15981,10.0000004768372,799.794799804687,-1.41375196595807E-6,2.26014742539979E-8,1,4,13.4005146026611,5.00649589950635,32.8599996864796,-0.00180527325514583,3.64806445006978E-5,1,2.40785324631701E-7,,,,,,,,,,,,,,,,,,,,,9.99983596801758,10.0001649856567,799.794799804687,799.794799804687,53.4946558561595,5.63981727642034,3.5789806842804,54,1,0,0,1,0.300064086914063,34.2131004333496,1,1,3,10.0001649856567,0,10.0000004768372,,,,,,,,,,,,,,,,,,,,,,,,,,,,,,,,,
,3878481693.03383,10.0000448226929,599.956176757812,-3.85842205072838E-7,2.43930182923321E-8,1,4,13.4005146026611,5.00645064380315,32.8599996864796,-5.26546111462428E-4,2.3627474403689E-4,1,2.47468636970339E-7,,,,,,,,,,,,,,,,,,,,,9.99990463256836,10.0001850128174,599.956176757812,599.956176757812,53.5884512784672,5.63962577100039,3.57979083061218,54,1,0,0,1,0.301589965820313,33.7243423461914,1,1,3,10.0001850128174,0,10.0000448226929,,,,,,,,,,,,,,,,,,,,,,,,,,,,,,,,,
,3878481751.76113,10.0000114440918,400.067321777344,6.77564446607003E-7,2.46590451181427E-8,1,4,13.4005146026611,5.00649674283319,32.8599996864796,8.00820114060976E-4,4.12932881618539E-4,1,2.30257018712911E-7,,,,,,,,,,,,,,,,,,,,,9.99969291687012,10.0003299713135,400.067321777344,400.067321777344,53.4934834133807,5.64013711431047,3.57761907577515,54,1,0,0,1,0.298538208007812,33.7243423461914,1,1,3,9.99969291687012,0,10.0000114440918,,,,,,,,,,,,,,,,,,,,,,,,,,,,,,,,,
,3878481809.21681,10.0000076293945,200.20361328125,1.62503703325315E-6,3.81316721277263E-8,1,4,13.4005146026611,5.00645588968356,32.8599996864796,0.00197605168918201,6.19834742713476E-4,1,2.5468455277031E-7,,,,,,,,,,,,,,,,,,,,,9.99998378753662,10.0000314712524,200.20361328125,200.20361328125,53.4497122163037,5.64123306540093,3.57228207588196,54,1,0,0,1,0.301666259765625,34.2131004333496,1,1,3,10.0000314712524,0,10.0000076293945,,,,,,,,,,,,,,,,,,,,,,,,,,,,,,,,,
,3878481867.51861,10.0000562667847,0.188823834061623,2.49311631656624E-6,2.24440302452082E-8,1,4,13.4005146026611,5.00641165094949,32.8599996864796,0.00306975530499769,6.95888182065882E-4,1,1.85909530968349E-7,,,,,,,,,,,,,,,,,,,,,10.0000553131104,10.000057220459,0.188823834061623,0.188823834061623,53.4364245314768,5.63932710715662,3.57503366470337,54,1,0,0,1,0.30120849609375,34.7018585205078,1,1,3,10.0000553131104,0,10.0000562667847,,,,,,,,,,,,,,,,,,,,,,,,,,,,,,,,,
,3878481933.32896,9.99993371963501,-199.750427246094,3.1553742351883E-6,3.32466330490859E-8,1,4,13.4005146026611,5.00640722967826,32.8599996864796,0.00389179148843914,8.36567436314294E-4,10,1.99819471885777E-7,,,,,,,,,,,,,,,,,,,,,9.99990940093994,9.99995803833008,-199.750427246094,-199.750427246094,53.5313923965634,5.64042507418706,3.57824850082397,54,1,0,0,1,0.299835205078125,34.2131004333496,1,1,3,9.99990940093994,0,9.99993371963501,,,,,,,,,,,,,,,,,,,,,,,,,,,,,,,,,
,3878481999.5654,9.99990367889404,-399.790374755859,3.87371406578744E-6,9.69369757926039E-9,1,4,13.4005146026611,5.00654273397215,32.8599996864796,0.00483232883350117,6.63625670704069E-4,1,-4.65487632044011E-8,,,,,,,,,,,,,,,,,,,,,9.99972152709961,10.0000858306885,-399.790374755859,-399.790374755859,53.381319720871,5.64019172148943,3.57870888710022,54,1,0,0,1,0.30792236328125,33.7243423461914,1,1,3,10.0000858306885,0,9.99990367889404,,,,,,,,,,,,,,,,,,,,,,,,,,,,,,,,,
,3878482057.24524,9.99997854232788,-599.754821777344,4.60706982560398E-6,1.73682980933381E-8,1,4,13.4005146026611,5.00649648786641,32.8599996864796,0.00570704949874083,0.0010569212649982,1,1.59598889510185E-7,,,,,,,,,,,,,,,,,,,,,9.99984931945801,10.0001077651978,-599.754821777344,-599.754821777344,53.4516662876018,5.64049623620441,3.57725739479065,52,1,68,0,0,0.29876708984375,33.7243423461914,1,1,3,9.99984931945801,0,9.99997854232788,,,,,,,,,,,,,,,,,,,,,,,,,,,,,,,,,
,3878482139.7392,10.0000743865967,-799.631103515625,5.43288266495903E-6,7.70296237793917E-8,1,4,13.4005146026611,5.00644791385621,32.8599996864796,0.00670955415044392,0.0013826401455966,10,2.97654470933161E-7,,,,,,,,,,,,,,,,,,,,,10.0000104904175,10.0001382827759,-799.631103515625,-799.631103515625,53.4692529292845,5.63958704330002,3.58150219917297,54,1,0,0,1,0.301055908203125,33.7243423461914,1,1,3,10.0001382827759,0,10.0000743865967,,,,,,,,,,,,,,,,,,,,,,,,,,,,,,,,,
,3878482222.62157,10.0000329017639,-999.532592773437,6.41915474010773E-6,4.22297476582365E-8,1,4,13.4005146026611,5.00655453601899,32.8599996864796,0.0079571185579827,0.00143787628468355,1,1.94439283366563E-7,,,,,,,,,,,,,,,,,,,,,10.0000267028809,10.000039100647,-999.532592773437,-999.532592773437,53.5321740250826,5.63978253936923,3.5731418132782,52,1,68,0,0,0.298919677734375,34.2131004333496,1,1,3,10.000039100647,0,10.0000329017639,,,,,,,,,,,,,,,,,,,,,,,,,,,,,,,,,
,3878482305.90752,9.99994659423828,-1199.58520507812,7.48580280175727E-6,3.59506116792195E-8,1,4,13.4005146026611,5.00653308236859,32.8599996864796,0.00928963465910704,0.00160750095389649,10,1.71102338638186E-7,,,,,,,,,,,,,,,,,,,,,9.99987125396729,10.0000219345093,-1199.58520507812,-1199.58520507812,53.5282658824864,5.64101659773331,3.58134365081787,54,1,0,0,1,0.30059814453125,33.7243423461914,1,1,3,10.0000219345093,0,9.99994659423828,,,,,,,,,,,,,,,,,,,,,,,,,,,,,,,,,
,3878482391.08089,10.0000152587891,-1399.51184082031,8.52855437016343E-6,1.68919761382771E-8,1,4,13.4005146026611,5.00647296988222,32.8599996864796,0.0105936862633757,0.00176314635526924,1,1.40130712653063E-7,,,,,,,,,,,,,,,,,,,,,9.99991703033447,10.0001134872437,-1399.51184082031,-1399.51184082031,53.4934834133807,5.63976984694516,3.58018684387207,52,1,68,0,0,0.302047729492188,33.7243423461914,1,1,3,9.99991703033447,0,10.0000152587891,,,,,,,,,,,,,,,,,,,,,,,,,,,,,,,,,
,3878482451.86948,9.9999942779541,-1599.52661132813,9.73043388274291E-6,7.01049883119999E-8,1,4,13.4005146026611,5.00646076722944,32.8599996864796,0.0120880724559526,0.00200144290165516,1,1.5171392446205E-7,,,,,,,,,,,,,,,,,,,,,9.99998664855957,10.0000019073486,-1599.52661132813,-1599.52661132813,53.4669080437268,5.63952179383844,3.58137798309326,54,1,0,0,1,0.300064086914063,33.7243423461914,1,1,3,10.0000019073486,0,9.9999942779541,,,,,,,,,,,,,,,,,,,,,,,,,,,,,,,,,
,3878482513.75502,10.000150680542,-1799.66723632813,1.07679224933893E-5,8.05759003935632E-9,1,4,13.4005146026611,5.00642123212415,32.8599996864796,0.0133869958605247,0.00214660805163303,1,1.13110869977919E-7,,,,,,,,,,,,,,,,,,,,,10.000147819519,10.0001535415649,-1799.66723632813,-1799.66723632813,53.3250424674864,5.63943794898298,3.57513785362244,54,1,0,0,1,0.299606323242188,33.7243423461914,1,1,3,10.000147819519,0,10.000150680542,,,,,,,,,,,,,,,,,,,,,,,,,,,,,,,,,
,3878482571.70771,9.99996423721314,-1999.6064453125,1.19032346269523E-5,2.40501008821134E-8,1,4,13.4005146026611,5.00650927418133,32.8599996864796,0.0148036962959506,0.00234034904763819,1,9.88209816029736E-8,,,,,,,,,,,,,,,,,,,,,9.99995994567871,9.99996852874756,-1999.6064453125,-1999.6064453125,53.488012013746,5.63981244277388,3.57829403877258,54,1,0,0,1,0.301284790039063,33.7243423461914,1,1,3,9.99996852874756,0,9.99996423721314,,,,,,,,,,,,,,,,,,,,,,,,,,,,,,,,,
,3878482629.50593,9.99998617172241,-2199.6337890625,1.30905272131349E-5,7.46018974576053E-9,1,4,13.4005146026611,5.00652389701171,32.8599996864796,0.0162809147074365,0.00257011048202743,1,1.05716142523147E-7,,,,,,,,,,,,,,,,,,,,,9.99995994567871,10.0000123977661,-2199.6337890625,-2199.6337890625,53.3992971768133,5.63956355041022,3.57612895965576,54,1,0,0,1,0.299453735351562,33.7243423461914,1,1,3,9.99995994567871,0,9.99998617172241,,,,,,,,,,,,,,,,,,,,,,,,,,,,,,,,,
,3878482688.0365,10.0001020431519,-2399.58569335938,1.42628381657619E-5,6.16904209422844E-9,1,4,13.4005146026611,5.00642580135302,32.8599996864796,0.0177404353287904,0.00278694070766036,1,1.04536785050361E-7,,,,,,,,,,,,,,,,,,,,,10.0000782012939,10.0001258850098,-2399.58569335938,-2399.58569335938,53.465735600948,5.6396343105745,3.5712685585022,54,1,0,0,1,0.30029296875,34.2131004333496,1,1,3,10.0001258850098,0,10.0001020431519,,,,,,,,,,,,,,,,,,,,,,,,,,,,,,,,,
,3878482747.79465,9.99996852874756,-2599.61328125,1.54653314130603E-5,1.97382834377346E-8,1,4,13.4005146026611,5.00650729419443,32.8599996864796,0.0192452811911324,0.00296368234531125,1,6.6536815400223E-8,,,,,,,,,,,,,,,,,,,,,9.99994659423828,9.99999046325684,-2599.61328125,-2599.61328125,53.399687991073,5.63969404141213,3.58318996429443,54,1,0,0,1,0.300064086914063,33.7243423461914,1,1,3,9.99994659423828,0,9.99996852874756,,,,,,,,,,,,,,,,,,,,,,,,,,,,,,,,,
,3878482808.30006,10.0000386238098,-2799.75390625,1.66525134357774E-5,9.78076487925116E-9,1,4,13.4005146026611,5.0065598520458,32.8599996864796,0.0207186675027776,0.00321973902670591,1,9.45361162744985E-8,,,,,,,,,,,,,,,,,,,,,10.0000295639038,10.0000476837158,-2799.75390625,-2799.75390625,53.3269965387845,5.64056513303993,3.57172441482544,54,1,0,0,1,0.300140380859375,33.7243423461914,1,1,3,10.0000295639038,0,10.0000386238098,,,,,,,,,,,,,,,,,,,,,,,,,,,,,,,,,
,3878482868.94224,10.0000376701355,-2999.7685546875,1.78310036335584E-5,9.40180549237419E-9,1,4,13.4005146026611,5.00631808911532,32.8599996864796,0.0221854857815742,0.00343355410978297,1,9.01341450494244E-8,,,,,,,,,,,,,,,,,,,,,9.99990653991699,10.000168800354,-2999.7685546875,-2999.7685546875,53.4227460323903,5.63975672764984,3.57760047912598,54,1,0,0,1,0.299606323242188,32.2580642700195,1,1,3,10.000168800354,0,10.0000376701355,,,,,,,,,,,,,,,,,,,,,,,,,,,,,,,,,
,3878482948.45209,10.0000367164612,-4499.57080078125,2.70113081826074E-5,2.56552557110426E-8,1,4,13.4005146026611,5.00637984778817,32.8599996864796,0.0336402137855967,0.00498792906039263,1,-3.49084701774502E-8,,,,,,,,,,,,,,,,,,,,,9.99985790252686,10.0002155303955,-4499.57080078125,-4499.57080078125,53.4297806890633,5.64008381530247,3.57295274734497,54,1,0,0,1,0.299758911132812,35.190616607666,1,1,3,10.0002155303955,0,10.0000367164612,,,,,,,,,,,,,,,,,,,,,,,,,,,,,,,,,
,3878483016.18124,10.0000100135803,-6499.744140625,3.94014142148287E-5,1.06704185506887E-8,1,4,13.4005146026611,5.00645039744783,32.8599996864796,0.0490729925492711,0.00726920531361952,1,-5.64090294410024E-8,,,,,,,,,,,,,,,,,,,,,9.99996089935303,10.0000591278076,-6499.744140625,-6499.744140625,53.4274358035057,5.63987487026178,3.57739639282227,54,1,0,0,1,0.300216674804687,33.7243423461914,1,1,3,10.0000591278076,0,10.0000100135803,,,,,,,,,,,,,,,,,,,,,,,,,,,,,,,,,
,3878483081.2669,10.0000104904175,-8499.5771484375,5.17934864564761E-5,1.59260451413476E-8,1,4,13.4005146026611,5.00646011659651,32.8599996864796,0.0645013339262375,0.00959354463394225,1,-4.3562347791788E-8,,,,,,,,,,,,,,,,,,,,,9.99998760223389,10.0000333786011,-8499.5771484375,-8499.5771484375,53.4243092894287,5.63977957490816,3.57370591163635,53,1,68,0,0,0.300674438476562,34.2131004333496,1,1,3,9.99996662139893,0,10.0000104904175,,,,,,,,,,,,,,,,,,,,,,,,,,,,,,,,,
,3878483162.35088,10.0001220703125,-9999.505859375,6.1085334684248E-5,1.32385267396178E-8,1,4,13.4005146026611,5.00641624303172,32.8599996864796,0.0760742834294965,0.011299653933553,1,-6.3304988309001E-8,,,,,,,,,,,,,,,,,,,,,10.000054359436,10.000189781189,-9999.505859375,-9999.505859375,53.5227944828518,5.63997036429611,3.57170939445496,54,1,0,0,1,0.301895141601562,33.7243423461914,1,1,3,10.000054359436,0,10.0001220703125,,,,,,,,,,,,,,,,,,,,,,,,,,,,,,,,,
,3878483318.40257,10.0000100135803,-29999.6875,1.85918855874202E-4,3.6134057979979E-8,1,4,13.4005146026611,5.00645100648303,32.8599996864796,0.231523850428342,0.0345088749111415,1,-9.87126531218898E-8,,,,,,,,,,,,,,,,,,,,,9.99997615814209,10.0000438690186,-29999.6875,-29999.6875,53.7920655077268,5.6401675575939,3.57641553878784,52,1,68,0,0,0.299835205078125,33.7243423461914,1,1,3,9.99997615814209,0,10.0000100135803,,,,,,,,,,,,,,,,,,,,,,,,,,,,,,,,,
,3878483477.30173,10.0001492500305,-49999.79296875,3.1100315270121E-4,6.48137444809694E-8,1,4,13.4005146026611,5.00645387206685,32.8599996864796,0.387262548643886,0.0579165232870429,1,-1.22296154301942E-8,,,,,,,,,,,,,,,,,,,,,10.0001010894775,10.0001974105835,-49999.79296875,-49999.79296875,53.7811227084576,5.64166547136787,3.57076191902161,54,1,0,0,1,0.300445556640625,34.2131004333496,1,1,3,10.0001010894775,0,10.0001492500305,,,,,,,,,,,,,,,,,,,,,,,,,,,,,,,,,
,3878483637.59667,10.0002012252808,-69999.828125,4.36152361800762E-4,1.31287507333705E-7,1,4,13.4005146026611,5.00651897241713,32.8599996864796,0.54309636507787,0.0813069524181921,1,4.95495388274874E-8,,,,,,,,,,,,,,,,,,,,,10.0000448226929,10.0003576278687,-69999.828125,-69999.828125,54.1723277823327,5.64254602085938,3.56975722312927,54,1,0,0,1,0.29937744140625,33.7243423461914,1,1,3,10.0000448226929,0,10.0002012252808,,,,,,,,,,,,,,,,,,,,,,,,,,,,,,,,,
,3878483797.78891,10.000075340271,-49999.69140625,3.08690319270727E-4,8.03794104407366E-8,1,4,13.4005146026611,5.00646359334378,32.8599996864796,0.384374358753088,0.0575480244277177,1,3.76944243742667E-8,,,,,,,,,,,,,,,,,,,,,10.0000085830688,10.0001420974731,-49999.69140625,-49999.69140625,53.826457162573,5.64112633651832,3.57827830314636,54,1,0,0,1,0.30670166015625,34.2131004333496,1,1,3,10.0001420974731,0,10.000075340271,,,,,,,,,,,,,,,,,,,,,,,,,,,,,,,,,
,3878483957.94616,10.0000324249268,-29999.67578125,1.82743749191619E-4,3.86625221723001E-8,1,4,13.4005146026611,5.00649015789195,32.8599996864796,0.227552816609162,0.0340507735167215,1,8.06984027682292E-9,,,,,,,,,,,,,,,,,,,,,9.99999809265137,10.0000667572021,-29999.67578125,-29999.67578125,53.6634876163134,5.64059558426086,3.57786965370178,54,1,0,0,1,0.300979614257812,33.7243423461914,1,1,3,9.99999809265137,0,10.0000324249268,,,,,,,,,,,,,,,,,,,,,,,,,,,,,,,,,
,3878484116.20821,9.99999523162842,-10000.0849609375,5.77300653323835E-5,1.47790945376172E-8,1,4,13.4005146026611,5.00654124877727,32.8599996864796,0.0718790709625345,0.010807352869582,1,4.29556074746697E-8,,,,,,,,,,,,,,,,,,,,,9.99985408782959,10.0001363754272,-10000.0849609375,-10000.0849609375,53.4286082462845,5.64051932925761,3.57426476478577,54,1,0,0,1,0.299911499023438,34.2131004333496,1,1,3,9.99989414215088,0,9.99999523162842,,,,,,,,,,,,,,,,,,,,,,,,,,,,,,,,,
,3878484189.20516,9.99992990493774,-8500.0810546875,4.84696276722458E-5,1.49682145038557E-8,1,4,13.4005146026611,5.00659566169885,32.8599996864796,0.0603524860294652,0.00905672864746236,1,2.22827127959411E-8,,,,,,,,,,,,,,,,,,,,,9.99983215332031,10.0000276565552,-8500.0810546875,-8500.0810546875,53.5052078411691,5.63988411670803,3.57629942893982,52,1,68,0,0,0.299530029296875,34.2131004333496,1,1,3,10.0000276565552,0,9.99992990493774,,,,,,,,,,,,,,,,,,,,,,,,,,,,,,,,,
,3878484255.204,10.0001301765442,-6499.9453125,3.60841027994231E-5,1.40172426852536E-8,1,4,13.4005146026611,5.00651103145368,32.8599996864796,0.044928217603407,0.00675054461989041,1,2.3219187763684E-8,,,,,,,,,,,,,,,,,,,,,10.0001010894775,10.0001592636108,-6499.9453125,-6499.9453125,53.4004696195922,5.64007161279227,3.57954072952271,53,1,68,0,0,0.299301147460937,33.7243423461914,1,1,3,10.0001592636108,0,10.0001301765442,,,,,,,,,,,,,,,,,,,,,,,,,,,,,,,,,
,3878484320.96096,9.99999618530273,-4500.37646484375,2.39218826162786E-5,1.61955397099832E-7,1,4,13.4005146026611,5.00666349751621,32.8599996864796,0.0297938063574812,0.0044255307864791,1,-2.46942451652598E-8,,,,,,,,,,,,,,,,,,,,,9.99997711181641,10.0000152587891,-4500.37646484375,-4500.37646484375,53.5442892671307,5.6389163981301,3.57950711250305,53,1,68,0,0,0.299224853515625,33.7243423461914,1,1,3,10.0000152587891,0,9.99999618530273,,,,,,,,,,,,,,,,,,,,,,,,,,,,,,,,,
,3878484400.75194,10.000105381012,-3000.25952148438,1.46337132953133E-5,7.10098593598761E-9,1,4,13.4005146026611,5.00662273898036,32.8599996864796,0.0182249019708336,0.00271141287679152,1,-1.17193900495859E-8,,,,,,,,,,,,,,,,,,,,,10.0000429153442,10.0001678466797,-3000.25952148438,-3000.25952148438,53.5677381227076,5.64002350317666,3.57808423042297,54,1,0,0,1,0.300445556640625,33.7243423461914,1,1,3,10.0000429153442,0,10.000105381012,,,,,,,,,,,,,,,,,,,,,,,,,,,,,,,,,
,3878484456.10953,9.99988985061646,-2800.21948242187,1.36062475248919E-5,1.75831748225733E-8,1,4,13.4005146026611,5.00658385030143,32.8599996864796,0.0169760221459554,0.0023143491656993,1,-1.76857773708361E-7,,,,,,,,,,,,,,,,,,,,,9.99987125396729,9.99990844726563,-2800.21948242187,-2800.21948242187,53.508334355246,5.63879288175649,3.57790565490723,54,1,0,0,1,0.300445556640625,34.2131004333496,1,1,3,9.99990844726563,0,9.99988985061646,,,,,,,,,,,,,,,,,,,,,,,,,,,,,,,,,
,3878484513.02222,10.0000205039978,-2600.2802734375,1.24361074371914E-5,1.89502288584886E-8,1,4,13.4005146026611,5.00659639161921,32.8599996864796,0.0155253653667681,0.00205361979380997,1,-2.11198206455332E-7,,,,,,,,,,,,,,,,,,,,,9.99992179870605,10.0001192092896,-2600.2802734375,-2600.2802734375,53.4231368466499,5.63946894524235,3.58208870887756,54,1,0,0,1,0.300521850585937,34.7018585205078,1,1,3,9.99992179870605,0,10.0000205039978,,,,,,,,,,,,,,,,,,,,,,,,,,,,,,,,,
,3878484569.80861,10.0001120567322,-2400.32836914062,1.12619675062846E-5,2.26704752670078E-8,1,4,13.4005146026611,5.00655348475447,32.8599996864796,0.0140559180052476,0.00188290666407214,1,-1.72627789035994E-7,,,,,,,,,,,,,,,,,,,,,10.0000696182251,10.0001544952393,-2400.32836914062,-2400.32836914062,53.4919201563422,5.63954964876466,3.58322072029114,54,1,0,0,1,0.301132202148438,34.2131004333496,1,1,3,10.0001544952393,0,10.0001120567322,,,,,,,,,,,,,,,,,,,,,,,,,,,,,,,,,
,3878484626.10354,9.99993705749512,-2200.37646484375,1.0107252013427E-5,1.8438136062839E-8,1,4,13.4005146026611,5.00660761019974,32.8599996864796,0.0126225008768948,0.00163921704279855,1,-1.95607544416002E-7,,,,,,,,,,,,,,,,,,,,,9.99992847442627,9.99994564056397,-2200.37646484375,-2200.37646484375,53.5548412521403,5.63960295071979,3.58289551734924,54,1,0,0,1,0.300064086914063,34.2131004333496,1,1,3,9.99994564056397,0,9.99993705749512,,,,,,,,,,,,,,,,,,,,,,,,,,,,,,,,,
,3878484682.46218,10.0000228881836,-2000.31140136719,8.91378659824803E-6,1.88289407375012E-8,1,4,13.4005146026611,5.00656074596631,32.8599996864796,0.0111404275375847,0.00138856054420436,1,-2.1834786183606E-7,,,,,,,,,,,,,,,,,,,,,10.0000028610229,10.0000429153442,-2000.31140136719,-2000.31140136719,53.5360821676787,5.63972479862562,3.5813901424408,54,1,0,0,1,0.299224853515625,33.7243423461914,1,1,3,10.0000028610229,0,10.0000228881836,,,,,,,,,,,,,,,,,,,,,,,,,,,,,,,,,
,3878484739.03324,10.0000772476196,-1800.03234863281,7.74113304430393E-6,1.70194974046584E-8,1,4,13.4005146026611,5.00656206462876,32.8599996864796,0.0096781447613321,0.00118387555565375,1,-2.07301126094116E-7,,,,,,,,,,,,,,,,,,,,,10.0000524520874,10.0001020431519,-1800.03234863281,-1800.03234863281,53.3852278634672,5.63937784593471,3.57667326927185,54,1,0,0,1,0.298690795898438,34.2131004333496,1,1,3,10.0001020431519,0,10.0000772476196,,,,,,,,,,,,,,,,,,,,,,,,,,,,,,,,,
,3878484795.77871,10.000009059906,-1600.130859375,6.63106797468314E-6,2.06563130036402E-8,1,4,13.4005146026611,5.0065914061797,32.8599996864796,0.00830144406213873,9.40180838493523E-4,1,-2.36950223225495E-7,,,,,,,,,,,,,,,,,,,,,9.99998092651367,10.0000371932983,-1600.130859375,-1600.130859375,53.5700830082653,5.63944647616413,3.5702919960022,53,1,68,0,0,0.301284790039063,34.2131004333496,1,1,3,10.0000371932983,0,10.000009059906,,,,,,,,,,,,,,,,,,,,,,,,,,,,,,,,,
,3878484852.0248,10.0000104904175,-1400.19165039062,5.48660347548397E-6,1.95700456796491E-8,1,4,13.4005146026611,5.00663034424935,32.8599996864796,0.0068703160374195,7.67533261450772E-4,1,-2.04397544753588E-7,,,,,,,,,,,,,,,,,,,,,10.0000047683716,10.0000162124634,-1400.19165039062,-1400.19165039062,53.557186137698,5.63923899883814,3.57381820678711,52,1,68,0,0,0.3009033203125,34.2131004333496,1,1,3,10.0000162124634,0,10.0000104904175,,,,,,,,,,,,,,,,,,,,,,,,,,,,,,,,,
,3878484908.90969,9.99990081787109,-1200.1767578125,4.32938303175943E-6,2.12360887372428E-8,1,4,13.4005146026611,5.00668598072841,32.8599996864796,0.00542880467052987,5.55694659423681E-4,1,-2.01407576359791E-7,,,,,,,,,,,,,,,,,,,,,9.99985790252686,9.99994373321533,-1200.1767578125,-1200.1767578125,53.501299698573,5.63952295464381,3.58344912528992,53,1,68,0,0,0.299148559570313,34.2131004333496,1,1,3,9.99994373321533,0,9.99990081787109,,,,,,,,,,,,,,,,,,,,,,,,,,,,,,,,,
,3878484982.14218,10.0000205039978,-1000.1494140625,3.23643132479104E-6,2.24499672644339E-8,1,4,13.4005146026611,5.00673077666674,32.8599996864796,0.00407077973684845,3.32358390138361E-4,1,-2.17258590671085E-7,,,,,,,,,,,,,,,,,,,,,9.99995803833008,10.0000829696655,-1000.1494140625,-1000.1494140625,53.3566984225153,5.63960564729442,3.57976150512695,52,1,68,0,0,0.2996826171875,34.2131004333496,1,1,3,10.0000829696655,0,10.0000205039978,,,,,,,,,,,,,,,,,,,,,,,,,,,,,,,,,
,3878485038.90754,10.0001339912415,-800.184997558594,2.14990440596705E-6,2.23083343638304E-8,1,4,13.4005146026611,5.00665603210315,32.8599996864796,0.00272022206513956,1.12942428205845E-4,1,-2.30915139961088E-7,,,,,,,,,,,,,,,,,,,,,10.0000648498535,10.0002031326294,-800.184997558594,-800.184997558594,53.4442408166691,5.64005030702603,3.57377481460571,53,1,68,0,0,0.300750732421875,33.7243423461914,1,1,3,10.0002031326294,0,10.0001339912415,,,,,,,,,,,,,,,,,,,,,,,,,,,,,,,,,
,3878485095.01595,10.000048160553,-600.245727539063,1.11503580591936E-6,2.49719909611377E-8,1,4,13.4005146026611,5.00665172128585,32.8599996864796,0.00142896176113632,-6.26554680203142E-5,1,-2.17117414861813E-7,,,,,,,,,,,,,,,,,,,,,9.99999046325684,10.0001058578491,-600.245727539063,-600.245727539063,53.5259209969287,5.6393286239492,3.57782125473022,53,1,68,0,0,0.302505493164063,34.2131004333496,1,1,3,10.0001058578491,0,10.000048160553,,,,,,,,,,,,,,,,,,,,,,,,,,,,,,,,,
,3878485168.10074,10.0001058578491,-400.218383789063,8.97063759240745E-8,2.83739095020519E-8,1,4,13.4005146026611,5.00657923329761,32.8599996864796,1.61510694762072E-4,-3.16221963738763E-4,1,-2.67363941604762E-7,,,,,,,,,,,,,,,,,,,,,10.0000629425049,10.0001487731934,-400.218383789063,-400.218383789063,53.5243577398903,5.63903526027189,3.57961058616638,52,1,68,0,0,0.299911499023438,33.7243423461914,1,1,3,10.0000629425049,0,10.0001058578491,,,,,,,,,,,,,,,,,,,,,,,,,,,,,,,,,
,3878485225.18011,9.9998984336853,-200.16584777832,-9.0319729364798E-7,2.66730572665645E-8,1,4,13.4005146026611,5.00657715032173,32.8599996864796,-0.00107926910387028,-4.719261014637E-4,1,-2.43871263652392E-7,,,,,,,,,,,,,,,,,,,,,9.99981784820557,9.99997901916504,-200.16584777832,-200.16584777832,53.3930441486595,5.63918258428614,3.57681012153625,53,1,68,0,0,0.299224853515625,34.2131004333496,1,1,3,9.99981784820557,0,9.9998984336853,,,,,,,,,,,,,,,,,,,,,,,,,,,,,,,,,
,3878485281.90016,9.99994039535522,-0.176235571503639,-1.73800655561525E-6,1.33341673637638E-8,1,4,13.4005146026611,5.00666076909689,32.8599996864796,-0.00212233993251072,-6.04163714526792E-4,1,-2.25172079362996E-7,,,,,,,,,,,,,,,,,,,,,9.9998607635498,10.0000200271606,-0.176235571503639,-0.176235571503639,53.5782901077172,5.63959976785971,3.57167530059814,52,1,68,0,0,0.300140380859375,34.2131004333496,1,1,3,10.0000200271606,0,9.99994039535522,,,,,,,,,,,,,,,,,,,,,,,,,,,,,,,,,
,3878485339.38312,10.0000801086426,199.901489257813,-2.42391158805887E-6,2.65869324310761E-8,1,4,13.4005146026611,5.00661984279275,32.8599996864796,-0.00297726147522408,-7.26453061206439E-4,1,-2.20774718860794E-7,,,,,,,,,,,,,,,,,,,,,10.0000114440918,10.0001487731934,199.901489257813,199.901489257813,53.4192287040537,5.63941022878234,3.58128023147583,54,1,0,0,1,0.300369262695313,33.7243423461914,1,1,3,10.0001487731934,0,10.0000801086426,,,,,,,,,,,,,,,,,,,,,,,,,,,,,,,,,
,3878485397.06745,9.99969053268433,399.765197753906,-3.09143388265873E-6,2.2417465131466E-8,1,4,13.4005146026611,5.00676697032089,32.8599996864796,-0.00381630392402738,-7.99693710288206E-4,1,-1.79706897366462E-7,,,,,,,,,,,,,,,,,,,,,9.99958419799805,9.99979686737061,399.765197753906,399.765197753906,53.3828829779095,5.63924671501613,3.58210372924805,52,1,68,0,0,0.298690795898438,33.7243423461914,1,1,3,9.99979686737061,0,9.99969053268433,,,,,,,,,,,,,,,,,,,,,,,,,,,,,,,,,
,3878485454.68572,9.99987554550171,599.767456054687,-3.84473807374797E-6,1.85537266015381E-8,1,4,13.4005146026611,5.00661383526946,32.8599996864796,-0.00475147189373329,-9.58189636398172E-4,1,-1.94324802291612E-7,,,,,,,,,,,,,,,,,,,,,9.99982357025146,9.99992752075195,599.767456054687,599.767456054687,53.562266723073,5.63821408192087,3.57727241516113,54,1,0,0,1,0.302276611328125,33.7243423461914,1,1,3,9.99992752075195,0,9.99987554550171,,,,,,,,,,,,,,,,,,,,,,,,,,,,,,,,,
,3878485512.31401,9.99991893768311,799.643737792969,-4.69493589162755E-6,3.08378613025369E-8,1,4,13.4005146026611,5.00669405204382,32.8599996864796,-0.00580907799072731,-0.00112484920987393,1,-2.00956138517178E-7,,,,,,,,,,,,,,,,,,,,,9.99982738494873,10.0000104904175,799.643737792969,799.643737792969,53.4907477135634,5.63884794536512,3.58071446418762,54,1,0,0,1,0.299224853515625,33.7243423461914,1,1,3,9.99982738494873,0,9.99991893768311,,,,,,,,,,,,,,,,,,,,,,,,,,,,,,,,,
,3878485570.83589,9.99997234344482,999.771789550781,-5.73809244186015E-6,3.26706083272117E-8,1,4,13.4005146026611,5.00662985333905,32.8599996864796,-0.00712163376036173,-0.00122783475342992,1,-1.27624680289404E-7,,,,,,,,,,,,,,,,,,,,,9.99994373321533,10.0000009536743,999.771789550781,999.771789550781,53.5321740250826,5.6387378177729,3.57777810096741,54,1,0,0,1,0.3021240234375,34.2131004333496,1,1,3,9.99994373321533,0,9.99997234344482,,,,,,,,,,,,,,,,,,,,,,,,,,,,,,,,,
,3878485628.52697,10.0000686645508,1199.64819335938,-6.71252624028705E-6,1.98225260713749E-8,1,4,13.4005146026611,5.00663723791153,32.8599996864796,-0.00832636226735841,-0.00146758641537866,1,-1.74384603947254E-7,,,,,,,,,,,,,,,,,,,,,10.0000247955322,10.0001125335693,1199.64819335938,1199.64819335938,53.5255301826691,5.63870514115627,3.57450842857361,54,1,0,0,1,0.300216674804687,34.2131004333496,1,1,3,10.0001125335693,0,10.0000686645508,,,,,,,,,,,,,,,,,,,,,,,,,,,,,,,,,
,3878485686.24513,10.0000505447388,1399.77624511719,-7.78699633227169E-6,1.42723317144558E-8,1,4,13.4005146026611,5.00666293019917,32.8599996864796,-0.00967135513071536,-0.00162144347795276,1,-1.37195220676326E-7,,,,,,,,,,,,,,,,,,,,,9.99999141693115,10.0001096725464,1399.77624511719,1399.77624511719,53.5118516835826,5.63857295500718,3.58039164543152,53,1,68,0,0,0.301284790039063,33.7243423461914,1,1,3,9.99999141693115,0,10.0000505447388,,,,,,,,,,,,,,,,,,,,,,,,,,,,,,,,,
,3878485744.94269,9.9999475479126,1599.52661132813,-8.92702594606876E-6,4.31338963182316E-8,1,4,13.4005146026611,5.00663696407979,32.8599996864796,-0.0110906889900139,-0.00183534003196879,1,-1.38431715578813E-7,,,,,,,,,,,,,,,,,,,,,9.99987983703613,10.0000152587891,1599.52661132813,1599.52661132813,53.5329556536018,5.63822907682816,3.57923030853271,52,1,68,0,0,0.30029296875,34.2131004333496,1,1,3,10.0000152587891,0,9.9999475479126,,,,,,,,,,,,,,,,,,,,,,,,,,,,,,,,,
,3878485819.05562,9.99982261657715,1799.54138183594,-1.00203973741991E-5,9.83533885264281E-9,1,4,13.4005146026611,5.00666994752353,32.8599996864796,-0.0124544075014922,-0.00202519079660345,1,-1.27313727548465E-7,,,,,,,,,,,,,,,,,,,,,9.9998140335083,9.999831199646,1799.54138183594,1799.54138183594,53.4618274583518,5.63894201050542,3.57231688499451,52,1,68,0,0,0.300140380859375,33.7243423461914,1,1,3,9.999831199646,0,9.99982261657715,,,,,,,,,,,,,,,,,,,,,,,,,,,,,,,,,
,3878485877.73169,9.99989938735962,1999.93371582031,-1.11884946653687E-5,7.60131491710821E-9,1,4,13.4005146026611,5.00665479985796,32.8599996864796,-0.0139118192030573,-0.00222358688488795,1,-1.11900550496251E-7,,,,,,,,,,,,,,,,,,,,,9.99989891052246,9.99989986419678,1999.93371582031,1999.93371582031,53.5595310232557,5.63824148382176,3.56969261169434,54,1,0,0,1,0.299072265625,34.2131004333496,1,1,3,9.99989891052246,0,9.99989938735962,,,,,,,,,,,,,,,,,,,,,,,,,,,,,,,,,
,3878485935.46894,10.0000166893005,2199.91064453125,-1.23539994678074E-5,5.31227588144844E-8,1,4,13.4005146026611,5.00666286082227,32.8599996864796,-0.0153544913712861,-0.0024990470552415,1,-1.58749380902793E-7,,,,,,,,,,,,,,,,,,,,,9.99998378753662,10.0000495910645,2199.91064453125,2199.91064453125,53.4340796459191,5.63828721065258,3.57539319992065,54,1,0,0,1,0.301284790039063,34.2131004333496,1,1,3,9.99998378753662,0,10.0000166893005,,,,,,,,,,,,,,,,,,,,,,,,,,,,,,,,,
,3878485993.12498,9.99998664855957,2400.013671875,-1.3539974406811E-5,8.35444785913949E-9,1,4,13.4005146026611,5.00664481149602,32.8599996864796,-0.0168442847374938,-0.00263293150630236,1,-8.88598923136986E-8,,,,,,,,,,,,,,,,,,,,,9.99995231628418,10.000020980835,2400.013671875,2400.013671875,53.4063318334864,5.63819450726299,3.57121539115906,54,1,0,0,1,0.299606323242188,33.7243423461914,1,1,3,9.99995231628418,0,9.99998664855957,,,,,,,,,,,,,,,,,,,,,,,,,,,,,,,,,
,3878486050.91611,10.0000147819519,2599.73901367187,-1.47302422835571E-5,1.05907420094929E-8,1,4,13.4005146026611,5.00664800456869,32.8599996864796,-0.0183280512966001,-0.00284428084745904,1,-8.05236774325831E-8,,,,,,,,,,,,,,,,,,,,,9.99997711181641,10.0000524520874,2599.73901367187,2599.73901367187,53.4211827753518,5.63911999814166,3.57406568527222,54,1,0,0,1,0.300750732421875,33.7243423461914,1,1,3,9.99997711181641,0,10.0000147819519,,,,,,,,,,,,,,,,,,,,,,,,,,,,,,,,,
,3878486108.52851,10.0001287460327,2799.8544921875,-1.59188783554941E-5,8.03220195597718E-9,1,4,13.4005146026611,5.00658413187602,32.8599996864796,-0.0198086934431545,-0.00306010940901478,1,-7.6074288752586E-8,,,,,,,,,,,,,,,,,,,,,10.0001077651978,10.0001497268677,2799.8544921875,2799.8544921875,53.4884028280057,5.63865890331191,3.57599210739136,54,1,0,0,1,0.301589965820313,33.7243423461914,1,1,3,10.0001077651978,0,10.0001287460327,,,,,,,,,,,,,,,,,,,,,,,,,,,,,,,,,
,3878486166.28182,9.99998760223389,2999.75610351562,-1.71111799863438E-5,1.11424060818471E-8,1,4,13.4005146026611,5.00653416802276,32.8599996864796,-0.0212947990567227,-0.00327081565381106,1,-6.69589547479748E-8,,,,,,,,,,,,,,,,,,,,,9.99989986419678,10.000075340271,2999.75610351562,2999.75610351562,53.4137573044191,5.63892133399306,3.57292699813843,54,1,0,0,1,0.300445556640625,33.7243423461914,1,1,3,10.000075340271,0,9.99998760223389,,,,,,,,,,,,,,,,,,,,,,,,,,,,,,,,,
,3878486244.91938,9.99999809265137,4499.8603515625,-2.63069541840547E-5,2.05089620169882E-8,1,4,13.4005146026611,5.00651543867488,32.8599996864796,-0.0327658233210234,-0.00484748433844934,1,4.24803242995382E-8,,,,,,,,,,,,,,,,,,,,,9.99996280670166,10.0000333786011,4499.8603515625,4499.8603515625,53.5341280963807,5.63897197176589,3.57892632484436,54,1,0,0,1,0.29815673828125,33.7243423461914,1,1,3,10.0000333786011,0,9.99999809265137,,,,,,,,,,,,,,,,,,,,,,,,,,,,,,,,,
,3878486310.13323,10.0002398490906,6499.68115234375,-3.87150490163316E-5,6.07561859878652E-8,1,4,13.4005146026611,5.00652476293342,32.8599996864796,-0.048219498570732,-0.00714040630137034,1,5.72888413648032E-8,,,,,,,,,,,,,,,,,,,,,10.0001487731934,10.0003309249878,6499.68115234375,6499.68115234375,53.3770207640153,5.6387198159995,3.5783519744873,54,1,0,0,1,0.30059814453125,33.7243423461914,1,1,3,10.0003309249878,0,10.0002398490906,,,,,,,,,,,,,,,,,,,,,,,,,,,,,,,,,
,3878486375.03137,10.0001592636108,8500.017578125,-5.10864540741249E-5,1.75249601175314E-8,1,4,13.4005146026611,5.00653609750442,32.8599996864796,-0.0636296542334631,-0.00941279889214048,1,8.31091009641244E-8,,,,,,,,,,,,,,,,,,,,,10.0000877380371,10.0002307891846,8500.017578125,8500.017578125,53.4129756758999,5.6393115706709,3.57309818267822,53,1,68,0,0,0.29998779296875,34.2131004333496,1,1,3,10.0000877380371,0,10.0001592636108,,,,,,,,,,,,,,,,,,,,,,,,,,,,,,,,,
,3878486455.15305,9.99999523162842,10000.2734375,-6.03800691803582E-5,1.63976758251982E-8,1,4,13.4005146026611,5.00656361028993,32.8599996864796,-0.0751992224012818,-0.0111685432849898,1,6.34649057115866E-8,,,,,,,,,,,,,,,,,,,,,9.99997997283935,10.0000104904175,10000.2734375,10000.2734375,53.6271418901691,5.63855734063415,3.56906294822693,54,1,0,0,1,0.299301147460937,33.7243423461914,1,1,3,10.0000104904175,0,9.99999523162842,,,,,,,,,,,,,,,,,,,,,,,,,,,,,,,,,
,3878486608.8502,10.0000143051147,30000.3671875,-1.85378030474391E-4,1.39355849484706E-7,1,4,13.4005146026611,5.0065638008013,32.8599996864796,-0.230856430568453,-0.034417623947037,1,9.19615077041507E-8,,,,,,,,,,,,,,,,,,,,,9.99996471405029,10.0000638961792,30000.3671875,30000.3671875,53.6220613047941,5.64002328328252,3.57854819297791,52,1,68,0,0,0.300674438476562,33.7243423461914,1,1,3,10.0000638961792,0,10.0000143051147,,,,,,,,,,,,,,,,,,,,,,,,,,,,,,,,,
,3878486768.20467,10.0001473426819,50000.39453125,-3.10399245111848E-4,9.63099098053959E-8,1,4,13.4005146026611,5.00655073668571,32.8599996864796,-0.386538628637607,-0.0576878836081597,1,1.06759154769747E-7,,,,,,,,,,,,,,,,,,,,,10.0001335144043,10.0001611709595,50000.39453125,50000.39453125,53.877263016323,5.63995305311857,3.57337665557861,54,1,0,0,1,0.3021240234375,34.2131004333496,1,1,3,10.0001611709595,0,10.0001473426819,,,,,,,,,,,,,,,,,,,,,,,,,,,,,,,,,
,3878486944.05573,10.0000939369202,70000.4296875,-4.35678543007053E-4,1.56091477333073E-7,1,4,13.4005146026611,5.00667906525928,32.8599996864796,-0.542550781814551,-0.0810874767861747,1,5.87356932753319E-8,,,,,,,,,,,,,,,,,,,,,10.0000429153442,10.0001449584961,70000.4296875,70000.4296875,54.0249908064576,5.64177519903019,3.57483243942261,52,1,68,0,0,0.301132202148438,33.2355842590332,1,1,3,10.0001449584961,0,10.0000939369202,,,,,,,,,,,,,,,,,,,,,,,,,,,,,,,,,