File: SQUID/22163_LCOT/LCOT_MH_20K_FC+1T.csv
Comment,Time Stamp (sec),Temperature (K),Magnetic Field (Oe),Moment (emu),M. Std. Err. (emu),Transport Action,Averaging Time (sec),Frequency (Hz),Peak Amplitude (mm),Center Position (mm),Lockin Signal' (V),Lockin Signal (V),Range,M. Quad. Signal (emu),AC Moment (emu),AC M. Std Err. (emu),AC Phase (deg),AC Phase Std. Err. (deg),AC Susceptibility (emu/Oe),AC Suscept. Std Err. (emu/Oe),AC X' (emu/Oe),AC X' Std Err. (emu/Oe),AC X'' (emu/Oe),AC X'' Std Err. (emu/Oe),AC Drive (Oe),AC Frequency (Hz),AC Averaging Time (sec),AC Cycles,AC Range,AC Measure Type,AC Signal' (V),AC Signal'' (V),AC Trim Coil Ratio,AC Trim Coil Phase,Min. Temperature (K),Max. Temperature (K),Min. Field (Oe),Max. Field (Oe),Mass (grams),Motor Lag (deg),Pressure (Torr),Measure Count,Measurement Number,SQUID Status (code),Motor Status (code),Measure Status (code),Motor Current (amps),Motor Temp. (C),Temp. Status (code),Field Status (code),Chamber Status (code),Chamber Temp (K),Redirection State,Average Temp (K),Rotation Angle (deg),Rotator state,DC Moment Fixed Ctr (emu),DC Moment Err Fixed Ctr (emu),DC Moment Free Ctr (emu),DC Moment Err Free Ctr (emu),DC Fixed Fit,DC Free Fit,DC Calculated Center (mm),DC Calculated Center Err (mm),DC Scan Length (mm),DC Scan Time (s),DC Number of Points,DC Squid Drift,DC Min V (V),DC Max V (V),DC Scans per Measure,Sample Resistance,He3 Temperature,Sorb Resistance,Sorb Temperature,Map 05,Map 06,Map 07,Map 08,Map 09,Map 10,Map 11,Map 12,Map 13,Map 14,Map 15,Map 16
,3878487147.72228,20.0017309188843,69999.6640625,-4.38844967455282E-4,2.13441520735481E-7,1,4,13.4005146026611,5.00662550392628,32.8599996864796,-0.546575914699805,-0.0810729112772537,10,5.4313616817091E-7,,,,,,,,,,,,,,,,,,,,,20.0016708374023,20.0017910003662,69999.6640625,69999.6640625,53.6165899051595,5.64062150358681,4.10300350189209,54,1,0,0,1,0.300445556640625,33.2355842590332,1,1,3,20.0016708374023,0,20.0017309188843,,,,,,,,,,,,,,,,,,,,,,,,,,,,,,,,,
,3878487312.52763,19.999508857727,50000.30859375,-3.11793191487939E-4,7.4289046751599E-8,1,4,13.4005146026611,5.00645240991001,32.8599996864796,-0.388241985098509,-0.0580914660273317,1,-1.0098494865735E-8,,,,,,,,,,,,,,,,,,,,,19.9978332519531,20.001184463501,50000.30859375,50000.30859375,53.6642692448326,5.63977491825057,4.09883737564087,54,1,0,0,1,0.299148559570313,34.2131004333496,1,1,3,20.001184463501,0,19.999508857727,,,,,,,,,,,,,,,,,,,,,,,,,,,,,,,,,
,3878487486.84137,19.9999485015869,29999.73828125,-1.85474896463525E-4,3.9421650259373E-8,1,4,13.4005146026611,5.00631920172952,32.8599996864796,-0.230928061298844,-0.0346553401904144,1,-8.63496413856428E-8,,,,,,,,,,,,,,,,,,,,,19.999792098999,20.0001049041748,29999.73828125,29999.73828125,53.523576111371,5.64049646898613,4.10025548934937,54,1,0,0,1,0.300674438476562,33.7243423461914,1,1,3,20.0001049041748,0,19.9999485015869,,,,,,,,,,,,,,,,,,,,,,,,,,,,,,,,,
,3878487645.78305,20.0001096725464,9999.5185546875,-5.98108365038283E-5,1.82363538091172E-8,1,4,13.4005146026611,5.00646745705815,32.8599996864796,-0.0744671287588746,-0.0112043603145051,1,-5.06936605021429E-8,,,,,,,,,,,,,,,,,,,,,19.9999656677246,20.0002536773682,9999.5185546875,9999.5185546875,53.5325648393422,5.63985284817697,4.09906053543091,54,1,0,0,1,0.299835205078125,34.2131004333496,1,1,3,19.9999656677246,0,20.0001096725464,,,,,,,,,,,,,,,,,,,,,,,,,,,,,,,,,
,3878487725.57367,20.0002355575562,8499.52734375,-5.03854387201814E-5,1.54794183611964E-8,1,4,13.4005146026611,5.00640343091807,32.8599996864796,-0.0627347104341945,-0.0094135369375979,1,-2.26312572848174E-8,,,,,,,,,,,,,,,,,,,,,20.0001983642578,20.0002727508545,8499.52734375,8499.52734375,53.4755059574383,5.63981827697062,4.09476566314697,53,1,68,0,0,0.300369262695313,34.7018585205078,1,1,3,20.0001983642578,0,20.0002355575562,,,,,,,,,,,,,,,,,,,,,,,,,,,,,,,,,
,3878487794.54644,19.9999351501465,6499.4794921875,-3.78549014109706E-5,1.3242001109501E-8,1,4,13.4005146026611,5.00657531663046,32.8599996864796,-0.0471346544108045,-0.00707677413836818,1,-2.02026511357476E-8,,,,,,,,,,,,,,,,,,,,,19.999813079834,20.000057220459,6499.4794921875,6499.4794921875,53.5509331095441,5.63919219619935,4.10288715362549,54,1,0,0,1,0.30181884765625,34.2131004333496,1,1,3,19.999813079834,0,19.9999351501465,,,,,,,,,,,,,,,,,,,,,,,,,,,,,,,,,
,3878487864.11321,19.9998970031738,4499.57080078125,-2.53616949811173E-5,1.0366243010325E-8,1,4,13.4005146026611,5.00670093690409,32.8599996864796,-0.0315764977304286,-0.00476461470265219,1,-3.21761670802326E-8,,,,,,,,,,,,,,,,,,,,,19.9992485046387,20.000545501709,4499.57080078125,4499.57080078125,53.491138527823,5.63970139885406,4.10409879684448,54,1,0,0,1,0.300827026367188,34.7018585205078,1,1,3,20.000545501709,0,19.9998970031738,,,,,,,,,,,,,,,,,,,,,,,,,,,,,,,,,
,3878487946.90399,19.9999780654907,2999.59228515625,-1.60902767195119E-5,7.33201401724836E-9,1,4,13.4005146026611,5.0065127113056,32.8599996864796,-0.0200406189317062,-0.00296568547813163,1,2.53460934741131E-8,,,,,,,,,,,,,,,,,,,,,19.9999580383301,19.9999980926514,2999.59228515625,2999.59228515625,53.5556228806595,5.63910014780423,4.09031629562378,54,1,0,0,1,0.300369262695313,34.2131004333496,1,1,3,19.9999980926514,0,19.9999780654907,,,,,,,,,,,,,,,,,,,,,,,,,,,,,,,,,
,3878488006.34384,20.0000476837158,2799.80419921875,-1.49818724179283E-5,1.62763500352389E-8,1,4,13.4005146026611,5.00618883550315,32.8599996864796,-0.0186928518732223,-0.00253084584019441,1,2.08559515278814E-7,,,,,,,,,,,,,,,,,,,,,19.9999198913574,20.0001754760742,2799.80419921875,2799.80419921875,53.440332674073,5.6410475855606,4.08899927139282,52,1,68,0,0,0.300369262695313,34.2131004333496,1,1,3,19.9998950958252,0,20.0000476837158,,,,,,,,,,,,,,,,,,,,,,,,,,,,,,,,,
,3878488065.34079,19.9998149871826,2599.67602539062,-1.3738884241948E-5,1.92530726210598E-8,1,4,13.4005146026611,5.00644190256866,32.8599996864796,-0.0171429426151488,-0.00232268634172496,1,1.89930247846907E-7,,,,,,,,,,,,,,,,,,,,,19.9997901916504,19.9998397827148,2599.67602539062,2599.67602539062,53.4172746327557,5.64016756528019,4.0975923538208,53,1,68,0,0,0.302276611328125,34.2131004333496,1,1,3,19.9997901916504,0,19.9998149871826,,,,,,,,,,,,,,,,,,,,,,,,,,,,,,,,,
,3878488122.37613,20.0003032684326,2399.5478515625,-1.25264450613004E-5,1.89500798993667E-8,1,4,13.4005146026611,5.00658377253423,32.8599996864796,-0.015633348053729,-0.00210022031326241,1,1.87283497999551E-7,,,,,,,,,,,,,,,,,,,,,20.0002288818359,20.0003776550293,2399.5478515625,2399.5478515625,53.4696437435441,5.63956134556676,4.09132146835327,54,1,0,0,1,0.29998779296875,35.190616607666,1,1,3,20.0003776550293,0,20.0003032684326,,,,,,,,,,,,,,,,,,,,,,,,,,,,,,,,,
,3878488187.70278,19.9996719360352,2199.60864257813,-1.13148773521838E-5,1.95495311789952E-8,1,4,13.4005146026611,5.00668419682939,32.8599996864796,-0.0141322316677752,-0.00182656448613165,10,2.25842649685889E-7,,,,,,,,,,,,,,,,,,,,,19.9985294342041,20.0008144378662,2199.60864257813,2199.60864257813,53.5302199537845,5.63953833631982,4.09120988845825,54,1,0,0,1,0.298843383789063,34.2131004333496,1,1,3,20.0008144378662,0,19.9996719360352,,,,,,,,,,,,,,,,,,,,,,,,,,,,,,,,,
,3878488270.52612,20.0004720687866,1999.70715332031,-1.01140357844145E-5,1.97036512325243E-8,1,4,13.4005146026611,5.00666119968475,32.8599996864796,-0.0126371648771666,-0.00160021292695285,1,2.2796388430853E-7,,,,,,,,,,,,,,,,,,,,,20.0001392364502,20.000804901123,1999.70715332031,1999.70715332031,53.6548897026018,5.6383723667177,4.09462881088257,54,1,0,0,1,0.300750732421875,34.2131004333496,1,1,3,20.0001392364502,0,20.0004720687866,,,,,,,,,,,,,,,,,,,,,,,,,,,,,,,,,
,3878488328.06226,19.9993753433228,1799.78051757813,-8.90445876660791E-6,1.66746622234042E-8,1,4,13.4005146026611,5.00666770001431,32.8599996864796,-0.0111287450671752,-0.00138953503811201,1,2.16203223660835E-7,,,,,,,,,,,,,,,,,,,,,19.9980525970459,20.0006980895996,1799.78051757813,1799.78051757813,53.3817105351306,5.63823719066004,4.0956506729126,53,1,68,0,0,0.300369262695313,33.7243423461914,1,1,3,20.0006980895996,0,19.9993753433228,,,,,,,,,,,,,,,,,,,,,,,,,,,,,,,,,
,3878488406.00312,20.0002317428589,1599.7783203125,-7.70406385051561E-6,1.70444784310035E-8,1,4,13.4005146026611,5.00662304655198,32.8599996864796,-0.00963168154888421,-0.00118011471816648,1,2.04792124483893E-7,,,,,,,,,,,,,,,,,,,,,20.0001411437988,20.0003223419189,1599.7783203125,1599.7783203125,53.5864972071691,5.63772661493828,4.10361003875732,54,1,0,0,1,0.299148559570313,34.2131004333496,1,1,3,20.0001449584961,0,20.0002317428589,,,,,,,,,,,,,,,,,,,,,,,,,,,,,,,,,
,3878488480.03787,20.0001211166382,1399.57482910156,-6.54029463369524E-6,2.08870673629121E-8,1,4,13.4005146026611,5.00665194722034,32.8599996864796,-0.00818917246849991,-9.191089140125E-4,1,2.40305477803053E-7,,,,,,,,,,,,,,,,,,,,,20.0000267028809,20.0002155303955,1399.57482910156,1399.57482910156,53.5458525241691,5.63813298205601,4.1041841506958,54,1,0,0,1,0.30120849609375,33.7243423461914,1,1,3,20.0002155303955,0,20.0001211166382,,,,,,,,,,,,,,,,,,,,,,,,,,,,,,,,,
,3878488546.25175,19.9998626708984,1199.7236328125,-5.37903123547467E-6,2.05968514313003E-8,1,4,13.4005146026611,5.00670510808705,32.8599996864796,-0.0067489361633137,-6.64386585730447E-4,10,2.71148068032699E-7,,,,,,,,,,,,,,,,,,,,,19.9998455047607,19.9998798370361,1199.7236328125,1199.7236328125,53.4782416572557,5.63840775053121,4.1019401550293,54,1,0,0,1,0.300216674804687,34.2131004333496,1,1,3,19.9998798370361,0,19.9998626708984,,,,,,,,,,,,,,,,,,,,,,,,,,,,,,,,,
,3878488625.88458,19.999077796936,999.85986328125,-4.25423133503281E-6,2.5066311170657E-8,1,4,13.4005146026611,5.00677124505012,32.8599996864796,-0.00533992063100927,-5.1113382171201E-4,1,2.25958965957911E-7,,,,,,,,,,,,,,,,,,,,,19.9988613128662,19.9992942810059,999.85986328125,999.85986328125,53.5173230832172,5.638798080346,4.10407781600952,54,1,0,0,1,0.301437377929687,33.7243423461914,1,1,3,19.9992942810059,0,19.999077796936,,,,,,,,,,,,,,,,,,,,,,,,,,,,,,,,,
,3878488682.77954,20.0010919570923,799.757019042969,-3.09337903522444E-6,2.34715937922093E-8,1,4,13.4005146026611,5.0066391732468,32.8599996864796,-0.00389289292868408,-3.03329506523852E-4,1,2.19163494786912E-7,,,,,,,,,,,,,,,,,,,,,20.0010547637939,20.0011291503906,799.757019042969,799.757019042969,53.4735518861403,5.63904052870523,4.10042285919189,54,1,0,0,1,0.300521850585937,34.2131004333496,1,1,3,20.0011291503906,0,20.0010919570923,,,,,,,,,,,,,,,,,,,,,,,,,,,,,,,,,
,3878488740.412,20.0000162124634,599.981384277344,-2.03359180782229E-6,2.22162227702891E-8,1,4,13.4005146026611,5.00666721512803,32.8599996864796,-0.00257226362327247,-1.12173283017297E-4,1,2.14133427441651E-7,,,,,,,,,,,,,,,,,,,,,19.9998798370361,20.0001525878906,599.981384277344,599.981384277344,53.4544019874191,5.63873638568515,4.11052322387695,54,1,0,0,1,0.301513671875,34.2131004333496,1,1,3,19.9998645782471,0,20.0000162124634,,,,,,,,,,,,,,,,,,,,,,,,,,,,,,,,,
,3878488799.08112,20.0001058578491,399.991790771484,-9.78000356202587E-7,2.86185551549262E-8,1,4,13.4005146026611,5.00673900433459,32.8599996864796,-0.00126144596440188,1.08902093128366E-4,1,2.33753571565714E-7,,,,,,,,,,,,,,,,,,,,,20.0000534057617,20.0001583099365,399.991790771484,399.991790771484,53.501299698573,5.63850448102113,4.10872411727905,54,1,0,0,1,0.306320190429687,34.2131004333496,1,1,3,20.0001583099365,0,20.0001058578491,,,,,,,,,,,,,,,,,,,,,,,,,,,,,,,,,
,3878488855.44278,19.999924659729,200.216201782227,-9.4653133361391E-9,2.67996707413546E-8,1,4,13.4005146026611,5.00663749781567,32.8599996864796,-5.34291803381166E-5,2.76606476093609E-4,1,2.2354324421457E-7,,,,,,,,,,,,,,,,,,,,,19.9997825622559,20.0000667572021,200.216201782227,200.216201782227,53.5200587830345,5.63901294837378,4.10119819641113,54,1,0,0,1,0.300369262695313,33.7243423461914,1,1,3,20.0000667572021,0,19.999924659729,,,,,,,,,,,,,,,,,,,,,,,,,,,,,,,,,
,3878488929.1123,20.0002450942993,0.163647323846817,7.95156418264009E-7,2.43187925739235E-8,1,4,13.4005146026611,5.00656271835975,32.8599996864796,9.43867322353631E-4,4.57554931162153E-4,1,2.48494111249224E-7,,,,,,,,,,,,,,,,,,,,,20.0001335144043,20.0003566741943,0.163647323846817,0.163647323846817,53.493092599121,5.63812069507287,4.10406827926636,52,1,68,0,0,0.30120849609375,34.2131004333496,1,1,3,20.0001335144043,0,20.0002450942993,,,,,,,,,,,,,,,,,,,,,,,,,,,,,,,,,
,3878489001.78955,20.0005044937134,-199.813369750977,1.52231530531636E-6,1.56259382500634E-8,1,4,13.4005146026611,5.00672205080575,32.8599996864796,0.00185948797463782,5.25823452800986E-4,1,1.94520633981021E-7,,,,,,,,,,,,,,,,,,,,,20.0003547668457,20.0006542205811,-199.813369750977,-199.813369750977,53.3891360060633,5.63948287936421,4.10835409164429,53,1,68,0,0,0.298538208007812,34.7018585205078,1,1,3,20.0003547668457,0,20.0005044937134,,,,,,,,,,,,,,,,,,,,,,,,,,,,,,,,,
,3878489076.05217,19.9999160766602,-399.840728759766,2.20588326492969E-6,1.41629707050254E-8,1,4,13.4005146026611,5.00663722254759,32.8599996864796,0.00271059001566985,6.53645954393989E-4,1,1.94920235546983E-7,,,,,,,,,,,,,,,,,,,,,19.9998054504395,20.0000267028809,-399.840728759766,-399.840728759766,53.4782416572557,5.6389810441856,4.10569190979004,53,1,68,0,0,0.300674438476562,33.7243423461914,1,1,3,20.0000267028809,0,19.9999160766602,,,,,,,,,,,,,,,,,,,,,,,,,,,,,,,,,
,3878489167.30226,19.9999418258667,-599.729675292969,2.97549095368049E-6,1.83160802005979E-8,1,4,13.4005146026611,5.00662932610074,32.8599996864796,0.00367023873370813,7.8835680334401E-4,1,1.87971866891951E-7,,,,,,,,,,,,,,,,,,,,,19.9998970031738,19.9999866485596,-599.729675292969,-599.729675292969,53.3621698221499,5.63873224462115,4.11531066894531,53,1,68,0,0,0.299148559570313,33.7243423461914,1,1,3,19.9999866485596,0,19.9999418258667,,,,,,,,,,,,,,,,,,,,,,,,,,,,,,,,,
,3878489249.46573,20.0000457763672,-799.681457519531,3.8809804469583E-6,2.36829664572114E-8,1,4,13.4005146026611,5.00664885165834,32.8599996864796,0.0047938913778921,9.83389218797186E-4,10,2.09131962829138E-7,,,,,,,,,,,,,,,,,,,,,19.9996223449707,20.0004692077637,-799.681457519531,-799.681457519531,53.5575769519576,5.63888496700393,4.11640691757202,54,1,0,0,1,0.301132202148438,34.2131004333496,1,1,3,20.0004692077637,0,20.0000457763672,,,,,,,,,,,,,,,,,,,,,,,,,,,,,,,,,
,3878489323.79604,20.0000257492065,-999.620727539063,4.85770333830425E-6,3.63278522346457E-8,1,4,13.4005146026611,5.00666888879292,32.8599996864796,0.00601832335784916,0.00111106679406213,10,1.65545682554862E-7,,,,,,,,,,,,,,,,,,,,,20.0000095367432,20.0000419616699,-999.620727539063,-999.620727539063,53.4672988579864,5.63837498891312,4.11782455444336,54,1,0,0,1,0.301284790039063,33.7243423461914,1,1,3,20.0000419616699,0,20.0000257492065,,,,,,,,,,,,,,,,,,,,,,,,,,,,,,,,,
,3878489416.1061,20.0005445480347,-1199.57263183594,5.93598586377617E-6,3.07385841069025E-8,1,4,13.4005146026611,5.00671840533292,32.8599996864796,0.00735722503619622,0.00133839213764582,10,1.86777148819341E-7,,,,,,,,,,,,,,,,,,,,,20.0003757476807,20.0007133483887,-1199.57263183594,-1199.57263183594,53.5579677662172,5.63883824931957,4.11514520645142,54,1,0,0,1,0.298919677734375,34.2131004333496,1,1,3,20.0003757476807,0,20.0005445480347,,,,,,,,,,,,,,,,,,,,,,,,,,,,,,,,,
,3878489500.37069,19.9998760223389,-1399.54956054688,7.04409587339455E-6,1.46226262631429E-8,1,4,13.4005146026611,5.00673018444953,32.8599996864796,0.00873894411000794,0.00153297315937319,1,1.77260343330975E-7,,,,,,,,,,,,,,,,,,,,,19.9998645782471,19.9998874664307,-1399.54956054688,-1399.54956054688,53.4520571018614,5.63853740750746,4.11584711074829,53,1,68,0,0,0.299072265625,33.7243423461914,1,1,3,19.9999446868896,0,19.9998760223389,,,,,,,,,,,,,,,,,,,,,,,,,,,,,,,,,
,3878489593.14263,19.9995946884155,-1599.53918457031,8.18297806858235E-6,1.62570540388926E-8,1,4,13.4005146026611,5.00665036259306,32.8599996864796,0.010159431511961,0.001728573922928,1,1.6399355976345E-7,,,,,,,,,,,,,,,,,,,,,19.9995403289795,19.9996490478516,-1599.53918457031,-1599.53918457031,53.3840554206883,5.63811592307405,4.10682010650635,52,1,68,0,0,0.29876708984375,33.7243423461914,1,1,3,19.9996490478516,0,19.9995946884155,,,,,,,,,,,,,,,,,,,,,,,,,,,,,,,,,
,3878489671.16658,20,-1799.66723632813,9.34428759499689E-6,7.88908470677825E-9,1,4,13.4005146026611,5.00662059114684,32.8599996864796,0.0116121693330005,0.0019001331755085,1,1.28050700151119E-7,,,,,,,,,,,,,,,,,,,,,19.9997081756592,20.0002918243408,-1799.66723632813,-1799.66723632813,53.4868395709672,5.63877501504839,4.1098952293396,54,1,0,0,1,0.299758911132812,33.7243423461914,1,1,3,20.0003032684326,0,20,,,,,,,,,,,,,,,,,,,,,,,,,,,,,,,,,
,3878489730.09291,19.9992237091064,-1999.63159179687,1.04856860358976E-5,4.68310782093709E-8,1,4,13.4005146026611,5.00665586957043,32.8599996864796,0.0130326995287334,0.0021189972095195,1,1.33046133896209E-7,,,,,,,,,,,,,,,,,,,,,19.9976654052734,20.0007820129395,-1999.63159179687,-1999.63159179687,53.4497122163037,5.63808776778141,4.10907077789307,54,1,0,0,1,0.299148559570313,34.2131004333496,1,1,3,20.0007820129395,0,19.9992237091064,,,,,,,,,,,,,,,,,,,,,,,,,,,,,,,,,
,3878489787.85455,19.9999265670776,-2199.646484375,1.1700379397951E-5,1.182345597079E-8,1,4,13.4005146026611,5.00668473158377,32.8599996864796,0.0145487014112722,0.00232345867454847,1,1.15511249742548E-7,,,,,,,,,,,,,,,,,,,,,19.9998722076416,19.9999809265137,-2199.646484375,-2199.646484375,53.4387694170345,5.6387673153342,4.11722183227539,54,1,0,0,1,0.300827026367188,34.2131004333496,1,1,3,19.9999809265137,0,19.9999265670776,,,,,,,,,,,,,,,,,,,,,,,,,,,,,,,,,
,3878489845.63898,20.0001735687256,-2399.64868164062,1.29510122079404E-5,4.74680767800517E-8,1,4,13.4005146026611,5.00668119711277,32.8599996864796,0.0160989252107928,0.00260419559496572,1,1.53867595745196E-7,,,,,,,,,,,,,,,,,,,,,20.000129699707,20.0002174377441,-2399.64868164062,-2399.64868164062,53.3856186777268,5.63841317493113,4.10899066925049,54,1,0,0,1,0.300064086914063,34.2131004333496,1,1,3,20.000129699707,0,20.0001735687256,,,,,,,,,,,,,,,,,,,,,,,,,,,,,,,,,
,3878489905.18555,19.9998664855957,-2599.80200195313,1.41122578433598E-5,1.38411848164993E-8,1,4,13.4005146026611,5.00675975384539,32.8599996864796,0.0175599048381497,0.00272349736041144,1,7.5907875988202E-8,,,,,,,,,,,,,,,,,,,,,19.9992618560791,20.0004711151123,-2599.80200195313,-2599.80200195313,53.5224036685922,5.63879906937704,4.11478137969971,54,1,0,0,1,0.300140380859375,33.7243423461914,1,1,3,20.0004711151123,0,19.9998664855957,,,,,,,,,,,,,,,,,,,,,,,,,,,,,,,,,
,3878489963.75116,19.9998893737793,-2799.75390625,1.53270702816453E-5,7.40509673071935E-9,1,4,13.4005146026611,5.00668888785455,32.8599996864796,0.0190714202989131,0.00295587904074093,1,8.08328313563506E-8,,,,,,,,,,,,,,,,,,,,,19.9986381530762,20.0011405944824,-2799.75390625,-2799.75390625,53.5501514810249,5.63886029197147,4.11821460723877,54,1,0,0,1,0.301513671875,33.7243423461914,1,1,3,20.0011405944824,0,19.9998893737793,,,,,,,,,,,,,,,,,,,,,,,,,,,,,,,,,
,3878490025.80259,20.000111579895,-2999.78125,1.65262772598414E-5,8.86200291509934E-9,1,4,13.4005146026611,5.00668024201702,32.8599996864796,0.0205624985096936,0.00319410291690134,1,9.27466581686469E-8,,,,,,,,,,,,,,,,,,,,,19.9999504089355,20.0002727508545,-2999.78125,-2999.78125,53.5204495972941,5.63769147503626,4.10892772674561,54,1,0,0,1,0.301284790039063,34.2131004333496,1,1,3,20.0002727508545,0,20.000111579895,,,,,,,,,,,,,,,,,,,,,,,,,,,,,,,,,
,3878490105.27551,19.9999732971191,-4499.58349609375,2.58178715680224E-5,2.92681655020456E-8,1,4,13.4005146026611,5.00665696816436,32.8599996864796,0.0321598316350608,0.00474485440436953,1,-5.18863759710392E-8,,,,,,,,,,,,,,,,,,,,,19.9995460510254,20.0004005432129,-4499.58349609375,-4499.58349609375,53.4262633607268,5.63804848544886,4.11218070983887,54,1,0,0,1,0.299530029296875,34.2131004333496,1,1,3,20.0004005432129,0,19.9999732971191,,,,,,,,,,,,,,,,,,,,,,,,,,,,,,,,,
,3878490172.51659,19.9999780654907,-6499.8447265625,3.82741466095927E-5,1.2973779504168E-8,1,4,13.4005146026611,5.00669185913202,32.8599996864796,0.0476704080342601,0.00707393754679695,1,-4.49766669188323E-8,,,,,,,,,,,,,,,,,,,,,19.9998016357422,20.0001544952393,-6499.8447265625,-6499.8447265625,53.4864487567076,5.63848269396748,4.11888599395752,54,1,0,0,1,0.299530029296875,33.7243423461914,1,1,3,20.0001544952393,0,19.9999780654907,,,,,,,,,,,,,,,,,,,,,,,,,,,,,,,,,
,3878490237.57831,20.0002756118774,-8499.5771484375,5.08030480638363E-5,1.53069370587534E-8,1,4,13.4005146026611,5.00671933712235,32.8599996864796,0.0632750851619904,0.00939325706329331,1,-5.67926816350538E-8,,,,,,,,,,,,,,,,,,,,,20.0002117156982,20.0003395080566,-8499.5771484375,-8499.5771484375,53.4989548130153,5.63872410236477,4.11544227600098,54,1,0,0,1,0.298309326171875,34.2131004333496,1,1,3,20.0003395080566,0,20.0002756118774,,,,,,,,,,,,,,,,,,,,,,,,,,,,,,,,,
,3878490318.68351,20,-9999.505859375,6.01685456272226E-5,1.90891475913221E-8,1,4,13.4005146026611,5.00662420193796,32.8599996864796,0.0749348583647904,0.0111442717960043,1,-5.14651953783799E-8,,,,,,,,,,,,,,,,,,,,,19.9999713897705,20.0000286102295,-9999.505859375,-9999.505859375,53.5181047117364,5.63813828183898,4.12073183059692,54,1,0,0,1,0.30029296875,35.190616607666,1,1,3,20.0000286102295,0,20,,,,,,,,,,,,,,,,,,,,,,,,,,,,,,,,,
,3878490474.63276,19.9999256134033,-29999.712890625,1.85846529140226E-4,4.86938064451665E-8,1,4,13.4005146026611,5.00673274433474,32.8599996864796,0.23144814438781,0.0345238768516713,1,-7.8026370463191E-8,,,,,,,,,,,,,,,,,,,,,19.9997539520264,20.0000972747803,-29999.712890625,-29999.712890625,53.5591402089961,5.63861196734764,4.11304044723511,54,1,0,0,1,0.299758911132812,33.7243423461914,1,1,3,20.0000972747803,0,19.9999256134033,,,,,,,,,,,,,,,,,,,,,,,,,,,,,,,,,
,3878490633.2527,20.0002489089966,-49999.640625,3.11959074976032E-4,7.68856594609194E-8,1,4,13.4005146026611,5.0067157526046,32.8599996864796,0.388476157707961,0.0581330010020694,1,1.52064708177432E-8,,,,,,,,,,,,,,,,,,,,,20.0000171661377,20.0004806518555,-49999.640625,-49999.640625,53.6115093197845,5.63980803163622,4.11845302581787,54,1,0,0,1,0.299911499023438,34.2131004333496,1,1,3,20.0004806518555,0,20.0002489089966,,,,,,,,,,,,,,,,,,,,,,,,,,,,,,,,,
,3878490808.96905,19.9999294281006,-69999.5625,4.38595296076909E-4,8.76166104604358E-8,1,4,13.4005146026611,5.00667703826932,32.8599996864796,0.546162031722965,0.081768500784183,1,5.18593606071386E-8,,,,,,,,,,,,,,,,,,,,,19.9998512268066,20.0000076293945,-69999.5625,-69999.5625,53.7056955563518,5.63931955005372,4.1080174446106,54,1,0,0,1,0.301589965820313,34.2131004333496,1,1,3,20.0000076293945,0,19.9999294281006,,,,,,,,,,,,,,,,,,,,,,,,,,,,,,,,,
,3878490969.09923,19.9999132156372,-49999.703125,3.11759929452875E-4,8.93457960157256E-8,1,4,13.4005146026611,5.00676762318527,32.8599996864796,0.388220466021267,0.0581857931073058,1,8.67141448503754E-8,,,,,,,,,,,,,,,,,,,,,19.9997329711914,20.000093460083,-49999.703125,-49999.703125,53.536863796198,5.63943343774234,4.10846710205078,54,1,0,0,1,0.2996826171875,33.7243423461914,1,1,3,19.9997329711914,0,19.9999132156372,,,,,,,,,,,,,,,,,,,,,,,,,,,,,,,,,
,3878491128.40036,20.0001611709595,-29999.7265625,1.85556454308735E-4,3.81270147304621E-8,1,4,13.4005146026611,5.00674521421876,32.8599996864796,0.231072504510729,0.0345716747731427,1,3.65320598952608E-9,,,,,,,,,,,,,,,,,,,,,20.0001049041748,20.0002174377441,-29999.7265625,-29999.7265625,53.5478065954672,5.63850226280489,4.1170825958252,54,1,0,0,1,0.29937744140625,34.2131004333496,1,1,3,20.0002174377441,0,20.0001611709595,,,,,,,,,,,,,,,,,,,,,,,,,,,,,,,,,
,3878491287.48934,20.0001153945923,-10000.1103515625,5.98534042589223E-5,1.79487978040301E-8,1,4,13.4005146026611,5.00666384482994,32.8599996864796,0.0745315091005383,0.0111641857752709,1,1.15706369918565E-8,,,,,,,,,,,,,,,,,,,,,20.0001010894775,20.000129699707,-10000.1103515625,-10000.1103515625,53.5149781976595,5.63834573097417,4.12032604217529,54,1,0,0,1,0.299148559570313,34.7018585205078,1,1,3,20.0001010894775,0,20.0001153945923,,,,,,,,,,,,,,,,,,,,,,,,,,,,,,,,,
,3878491359.12616,20.0002593994141,-8500.0302734375,5.04127144679574E-5,1.63091603518198E-8,1,4,13.4005146026611,5.00678869641351,32.8599996864796,0.0627746133984042,0.00942506890804753,1,2.69979812301406E-8,,,,,,,,,,,,,,,,,,,,,20.000072479248,20.0004463195801,-8500.0302734375,-8500.0302734375,53.4739427003999,5.63909913408554,4.10844278335571,53,1,68,0,0,0.300064086914063,33.7243423461914,1,1,3,20.0004463195801,0,20.0002593994141,,,,,,,,,,,,,,,,,,,,,,,,,,,,,,,,,
,3878491424.813,20.000129699707,-6500.24755859375,3.79017251695476E-5,1.2461813335722E-8,1,4,13.4005146026611,5.00670037194126,32.8599996864796,0.0471896249579014,0.00711906265880508,1,4.6958617702724E-8,,,,,,,,,,,,,,,,,,,,,19.9998912811279,20.0003681182861,-6500.24755859375,-6500.24755859375,53.4844946854095,5.63830309145935,4.11244010925293,54,1,0,0,1,0.306472778320313,34.2131004333496,1,1,3,19.9998912811279,0,20.000129699707,,,,,,,,,,,,,,,,,,,,,,,,,,,,,,,,,
,3878491488.87835,19.9997158050537,-4500.46484375,2.54167605146569E-5,1.07641873358766E-8,1,4,13.4005146026611,5.00676809582745,32.8599996864796,0.0316469115231794,0.00476661850129621,1,2.54760327760228E-8,,,,,,,,,,,,,,,,,,,,,19.9996891021729,19.9997425079346,-4500.46484375,-4500.46484375,53.4293898748037,5.63893289507109,4.11204671859741,53,1,68,0,0,0.3094482421875,34.2131004333496,1,1,3,19.9997291564941,0,19.9997158050537,,,,,,,,,,,,,,,,,,,,,,,,,,,,,,,,,
,3878491568.7646,20.0000228881836,-3000.4482421875,1.6135640952155E-5,6.92776839257843E-9,1,4,13.4005146026611,5.00679874278409,32.8599996864796,0.0200966735867891,0.00298800315171475,1,-1.44012451231676E-8,,,,,,,,,,,,,,,,,,,,,19.9999313354492,20.000114440918,-3000.4482421875,-3000.4482421875,53.475896771698,5.6383197826805,4.10872220993042,54,1,0,0,1,0.299911499023438,34.2131004333496,1,1,3,20.000114440918,0,20.0000228881836,,,,,,,,,,,,,,,,,,,,,,,,,,,,,,,,,
,3878491623.25097,19.9999933242798,-2800.18188476562,1.49960986408596E-5,1.73081036995543E-8,1,4,13.4005146026611,5.00671003475153,32.8599996864796,0.0187078179526656,0.00257043397369888,1,-1.79193112861177E-7,,,,,,,,,,,,,,,,,,,,,19.9999904632568,19.9999961853027,-2800.18188476562,-2800.18188476562,53.4684713007653,5.6384789513051,4.11385202407837,54,1,0,0,1,0.301055908203125,34.7018585205078,1,1,3,19.9999904632568,0,19.9999933242798,,,,,,,,,,,,,,,,,,,,,,,,,,,,,,,,,
,3878491681.1462,20.000358581543,-2600.25512695313,1.37858609172973E-5,1.668140033632E-8,1,4,13.4005146026611,5.00674599206223,32.8599996864796,0.0171997278536553,0.00235282904464635,1,-1.72910860837622E-7,,,,,,,,,,,,,,,,,,,,,20.0001888275146,20.0005283355713,-2600.25512695313,-2600.25512695313,53.5157598261787,5.63898117463046,4.10676860809326,54,1,0,0,1,0.299072265625,34.2131004333496,1,1,3,20.0001945495605,0,20.000358581543,,,,,,,,,,,,,,,,,,,,,,,,,,,,,,,,,
,3878491739.45708,20.0001268386841,-2400.37866210938,1.25573023016661E-5,1.94823011420038E-8,1,4,13.4005146026611,5.00670406617706,32.8599996864796,0.0156766727624157,0.002076803151004,1,-2.1076087665799E-7,,,,,,,,,,,,,,,,,,,,,20.0000400543213,20.0002136230469,-2400.37866210938,-2400.37866210938,53.4465857022268,5.63745379492283,4.11748361587524,54,1,0,0,1,0.300140380859375,34.2131004333496,1,1,3,20.0000400543213,0,20.0001268386841,,,,,,,,,,,,,,,,,,,,,,,,,,,,,,,,,
,3878491796.46748,20.0003910064697,-2200.35131835938,1.13564249973873E-5,1.92371035837367E-8,1,4,13.4005146026611,5.00673844874535,32.8599996864796,0.0141788782943517,0.00186980532087573,1,-1.97356808849655E-7,,,,,,,,,,,,,,,,,,,,,20.0002880096436,20.0004940032959,-2200.35131835938,-2200.35131835938,53.4497122163037,5.63821791952038,4.11627960205078,54,1,0,0,1,0.302200317382812,34.7018585205078,1,1,3,20.0002880096436,0,20.0003910064697,,,,,,,,,,,,,,,,,,,,,,,,,,,,,,,,,
,3878491853.37497,20.0004663467407,-2000.26110839844,1.01469198348448E-5,1.82439115165846E-8,1,4,13.4005146026611,5.00673555654323,32.8599996864796,0.0126758569287767,0.00162322227979874,1,-2.14432789816145E-7,,,,,,,,,,,,,,,,,,,,,19.9997425079346,20.0011901855469,-2000.26110839844,-2000.26110839844,53.5771176649383,5.63854915872722,4.11201429367065,54,1,0,0,1,0.300064086914063,34.7018585205078,1,1,3,20.0011901855469,0,20.0004663467407,,,,,,,,,,,,,,,,,,,,,,,,,,,,,,,,,
,3878491911.68727,20.0000419616699,-1800.03234863281,8.94412608291382E-6,1.75513375909271E-8,1,4,13.4005146026611,5.00676835000865,32.8599996864796,0.0111782289495836,0.0013984802572941,1,-2.14985424139474E-7,,,,,,,,,,,,,,,,,,,,,19.9999694824219,20.000114440918,-1800.03234863281,-1800.03234863281,53.5462433384287,5.63818482343341,4.12005186080933,54,1,0,0,1,0.299530029296875,34.2131004333496,1,1,3,19.9999694824219,0,20.0000419616699,,,,,,,,,,,,,,,,,,,,,,,,,,,,,,,,,
,3878491969.52812,20.000675201416,-1599.97973632813,7.76130810519042E-6,2.0381618911815E-8,1,4,13.4005146026611,5.00668595887537,32.8599996864796,0.0097100568990517,0.00114453307339963,1,-2.41945416108447E-7,,,,,,,,,,,,,,,,,,,,,20.000560760498,20.000789642334,-1599.97973632813,-1599.97973632813,53.4286082462845,5.63790983533524,4.11917495727539,54,1,0,0,1,0.298233032226562,34.2131004333496,1,1,3,20.000560760498,0,20.000675201416,,,,,,,,,,,,,,,,,,,,,,,,,,,,,,,,,
,3878492026.66298,20.0001220703125,-1400.05310058594,6.58949339928289E-6,2.32839185404826E-8,1,4,13.4005146026611,5.0066708893957,32.8599996864796,0.00824987947810657,9.32304250859893E-4,1,-2.37072871106888E-7,,,,,,,,,,,,,,,,,,,,,20.0000400543213,20.0002040863037,-1400.05310058594,-1400.05310058594,53.5853247643903,5.63838472352702,4.12036371231079,53,1,68,0,0,0.3009033203125,34.2131004333496,1,1,3,20.0002040863037,0,20.0001220703125,,,,,,,,,,,,,,,,,,,,,,,,,,,,,,,,,
,3878492085.88385,20.0000152587891,-1200.10119628906,5.41753558089435E-6,2.01346354464458E-8,1,4,13.4005146026611,5.0067266663844,32.8599996864796,0.00678809908234506,7.30569026550833E-4,1,-2.23765175100327E-7,,,,,,,,,,,,,,,,,,,,,19.999906539917,20.0001239776611,-1200.10119628906,-1200.10119628906,53.4954374846787,5.63857393970423,4.11602783203125,54,1,0,0,1,0.300064086914063,34.2131004333496,1,1,3,20.0001239776611,0,20.0000152587891,,,,,,,,,,,,,,,,,,,,,,,,,,,,,,,,,
,3878492142.52822,20.0001840591431,-1000.06127929688,4.30483393912816E-6,2.01164852059691E-8,1,4,13.4005146026611,5.00656934581511,32.8599996864796,0.00539769981512074,5.53500698351747E-4,1,-1.99482531007451E-7,,,,,,,,,,,,,,,,,,,,,20.0001487731934,20.0002193450928,-1000.06127929688,-1000.06127929688,53.4211827753518,5.63850013767215,4.11978149414063,54,1,0,0,1,0.30029296875,34.2131004333496,1,1,3,20.0001487731934,0,20.0001840591431,,,,,,,,,,,,,,,,,,,,,,,,,,,,,,,,,
,3878492199.55338,19.999831199646,-800.071716308594,3.16093517469928E-6,2.88542429044285E-8,1,4,13.4005146026611,5.00660840564261,32.8599996864796,0.00397670570554867,3.17770594861411E-4,1,-2.17670454546111E-7,,,,,,,,,,,,,,,,,,,,,19.9993419647217,20.0003204345703,-800.071716308594,-800.071716308594,53.4000788053326,5.63880660494118,4.11466121673584,53,1,68,0,0,0.2996826171875,34.2131004333496,1,1,3,20.0003204345703,0,19.999831199646,,,,,,,,,,,,,,,,,,,,,,,,,,,,,,,,,
,3878492258.24444,20.000020980835,-600.107238769531,2.09794568483525E-6,2.58265115999262E-8,1,4,13.4005146026611,5.00657905621069,32.8599996864796,0.00265748741684795,8.97248547340712E-5,1,-2.41785533177063E-7,,,,,,,,,,,,,,,,,,,,,19.9995765686035,20.0004653930664,-600.107238769531,-600.107238769531,53.5610942802941,5.6376817210639,4.11011505126953,53,1,68,0,0,0.30120849609375,34.2131004333496,1,1,3,20.0004653930664,0,20.000020980835,,,,,,,,,,,,,,,,,,,,,,,,,,,,,,,,,
,3878492316.6231,20.0000734329224,-400.243560791016,1.02788844986914E-6,2.02366919025262E-8,1,4,13.4005146026611,5.00671039017045,32.8599996864796,0.00132760863112208,-1.2666616808294E-4,1,-2.55482273078941E-7,,,,,,,,,,,,,,,,,,,,,20.0000476837158,20.0000991821289,-400.243560791016,-400.243560791016,53.4813681713326,5.63818690369426,4.11704587936401,52,1,68,0,0,0.299530029296875,34.2131004333496,1,1,3,20.0000991821289,0,20.0000734329224,,,,,,,,,,,,,,,,,,,,,,,,,,,,,,,,,
,3878492389.93478,19.9996423721313,-200.178436279297,1.02939258640951E-7,2.86309633239936E-8,1,4,13.4005146026611,5.00669421495277,32.8599996864796,1.76928433726315E-4,-3.06640368445355E-4,1,-2.616410210194E-7,,,,,,,,,,,,,,,,,,,,,19.9993743896484,19.9999103546143,-200.178436279297,-200.178436279297,53.5325648393422,5.63825589931866,4.1088752746582,53,1,68,0,0,0.299911499023438,34.2131004333496,1,1,3,19.9999103546143,0,19.9996423721313,,,,,,,,,,,,,,,,,,,,,,,,,,,,,,,,,
,3878492447.55162,20.0000791549683,-0.214000344276428,-8.02850497672388E-7,2.63992493907643E-8,1,4,13.4005146026611,5.0066982581666,32.8599996864796,-9.48747708915454E-4,-4.90668877070032E-4,1,-2.73920736284087E-7,,,,,,,,,,,,,,,,,,,,,20.0000114440918,20.0001468658447,-0.214000344276428,-0.214000344276428,53.452447916121,5.63800252349379,4.11710214614868,52,1,68,0,0,0.300674438476562,34.2131004333496,1,1,3,20.0000114440918,0,20.0000791549683,,,,,,,,,,,,,,,,,,,,,,,,,,,,,,,,,
,3878492505.066,19.999960899353,199.863723754883,-1.44703150076414E-6,1.41076198424706E-8,1,4,13.4005146026611,5.00670746817561,32.8599996864796,-0.00176672084892759,-5.05177182826834E-4,1,-1.89204798609136E-7,,,,,,,,,,,,,,,,,,,,,19.9996891021729,20.0002326965332,199.863723754883,199.863723754883,53.4243092894287,5.63868130842167,4.11028385162354,54,1,0,0,1,0.300827026367188,34.2131004333496,1,1,3,19.9996891021729,0,19.999960899353,,,,,,,,,,,,,,,,,,,,,,,,,,,,,,,,,
,3878492562.72613,20.000358581543,399.790374755859,-2.13549078644576E-6,1.74350354621098E-8,1,4,13.4005146026611,5.0067055180198,32.8599996864796,-0.00262571078995786,-6.22310771697213E-4,1,-1.80277440420131E-7,,,,,,,,,,,,,,,,,,,,,20.000171661377,20.000545501709,399.790374755859,399.790374755859,53.5626575373326,5.6384552668086,4.10711193084717,54,1,0,0,1,0.301895141601562,34.2131004333496,1,1,3,20.0001888275146,0,20.000358581543,,,,,,,,,,,,,,,,,,,,,,,,,,,,,,,,,
,3878492620.51308,19.9995775222778,599.91845703125,-2.935935753857E-6,1.52189478214615E-8,1,4,13.4005146026611,5.00668134560683,32.8599996864796,-0.00362184001426006,-7.75617638028321E-4,1,-1.83649894532264E-7,,,,,,,,,,,,,,,,,,,,,19.9986190795898,20.0005359649658,599.91845703125,599.91845703125,53.462609086871,5.63870808213062,4.11746549606323,54,1,0,0,1,0.299224853515625,33.7243423461914,1,1,3,20.0005359649658,0,19.9995775222778,,,,,,,,,,,,,,,,,,,,,,,,,,,,,,,,,
,3878492678.19092,20.000129699707,799.643737792969,-3.83649074263447E-6,1.99996477299722E-8,1,4,13.4005146026611,5.00666740783327,32.8599996864796,-0.00473784979836802,-9.7954964058233E-4,1,-2.12699930520335E-7,,,,,,,,,,,,,,,,,,,,,20.0000076293945,20.0002517700195,799.643737792969,799.643737792969,53.5524963665826,5.6380366911609,4.11040067672729,54,1,0,0,1,0.300216674804687,33.7243423461914,1,1,3,20.0000076293945,0,20.000129699707,,,,,,,,,,,,,,,,,,,,,,,,,,,,,,,,,
,3878492735.98941,20.0001773834229,999.771789550781,-4.9322142093114E-6,7.73519233549997E-8,1,4,13.4005146026611,5.00670192182464,32.8599996864796,-0.00612851161337987,-0.00100900624273711,1,-7.24334017360848E-8,,,,,,,,,,,,,,,,,,,,,19.9999961853027,20.000358581543,999.771789550781,999.771789550781,53.4063318334864,5.6382050387947,4.11983919143677,53,1,68,0,0,0.29876708984375,33.7243423461914,1,1,3,19.9999961853027,0,20.0001773834229,,,,,,,,,,,,,,,,,,,,,,,,,,,,,,,,,
,3878492793.70209,20.0000286102295,1199.66076660156,-5.88285930403853E-6,1.89264212239879E-8,1,4,13.4005146026611,5.00663793032483,32.8599996864796,-0.00729794578601859,-0.00128138783917644,1,-1.48971727727015E-7,,,,,,,,,,,,,,,,,,,,,19.9998264312744,20.0002307891846,1199.66076660156,1199.66076660156,53.5454617099095,5.6383410810285,4.11715650558472,52,1,68,0,0,0.298233032226562,34.2131004333496,1,1,3,19.9998264312744,0,20.0000286102295,,,,,,,,,,,,,,,,,,,,,,,,,,,,,,,,,
,3878492868.85185,19.9999418258667,1399.80139160156,-7.02271106099049E-6,1.20784782364837E-8,1,4,13.4005146026611,5.0067013675389,32.8599996864796,-0.00872180802036241,-0.00146504146954152,1,-1.25918092497013E-7,,,,,,,,,,,,,,,,,,,,,19.9998970031738,19.9999866485596,1399.80139160156,1399.80139160156,53.3418474806499,5.63764087863348,4.10944557189941,52,1,68,0,0,0.300369262695313,34.2131004333496,1,1,3,19.9999866485596,0,19.9999418258667,,,,,,,,,,,,,,,,,,,,,,,,,,,,,,,,,
,3878492926.5955,19.9999132156372,1599.67761230469,-8.15027957753748E-6,1.14975000513946E-8,1,4,13.4005146026611,5.00667271781633,32.8599996864796,-0.0101303305033877,-0.00164525679205034,1,-1.01969687071459E-7,,,,,,,,,,,,,,,,,,,,,19.9997501373291,20.0000762939453,1599.67761230469,1599.67761230469,53.5302199537845,5.63820787442855,4.10737609863281,52,1,68,0,0,0.301971435546875,33.7243423461914,1,1,3,19.9997501373291,0,19.9999132156372,,,,,,,,,,,,,,,,,,,,,,,,,,,,,,,,,
,3878492984.20117,20.0000801086426,1799.64208984375,-9.3068240486607E-6,1.04306939064312E-8,1,4,13.4005146026611,5.0067596140511,32.8599996864796,-0.0115683697818082,-0.00187716342490452,1,-1.15150680017914E-7,,,,,,,,,,,,,,,,,,,,,20.0000305175781,20.000129699707,1799.64208984375,1799.64208984375,53.5196679687749,5.63772758442378,4.10899353027344,54,1,0,0,1,0.298843383789063,33.7243423461914,1,1,3,20.0000305175781,0,20.0000801086426,,,,,,,,,,,,,,,,,,,,,,,,,,,,,,,,,
,3878493041.82605,19.9998178482056,1999.90856933594,-1.04988510039184E-5,2.60977342483226E-8,1,4,13.4005146026611,5.00668234042918,32.8599996864796,-0.013051412718584,-0.00210660622887158,1,-1.21113774373721E-7,,,,,,,,,,,,,,,,,,,,,19.9997825622559,19.9998531341553,1999.90856933594,1999.90856933594,53.4669080437268,5.63687927814893,4.10718727111816,54,1,0,0,1,0.299301147460937,34.2131004333496,1,1,3,19.9998531341553,0,19.9998178482056,,,,,,,,,,,,,,,,,,,,,,,,,,,,,,,,,
,3878493099.58226,20.0001230239868,2199.873046875,-1.16728044775325E-5,9.00265904870516E-9,1,4,13.4005146026611,5.00675144386304,32.8599996864796,-0.0145173626973619,-0.00230012007631509,1,-1.00860196274096E-7,,,,,,,,,,,,,,,,,,,,,20.0000534057617,20.0001926422119,2199.873046875,2199.873046875,53.5255301826691,5.63789137478441,4.1168704032898,54,1,0,0,1,0.303192138671875,33.7243423461914,1,1,3,20.0001926422119,0,20.0001230239868,,,,,,,,,,,,,,,,,,,,,,,,,,,,,,,,,
,3878493158.06597,20.0004606246948,2400.03881835938,-1.28774911569858E-5,7.16783788040889E-9,1,4,13.4005146026611,5.00666550874456,32.8599996864796,-0.0160200335111345,-0.00250537488422246,1,-8.55182523362179E-8,,,,,,,,,,,,,,,,,,,,,20.0001773834229,20.0007438659668,2400.03881835938,2400.03881835938,53.5005180700537,5.63698328248982,4.12025451660156,54,1,0,0,1,0.299758911132812,34.2131004333496,1,1,3,20.0001773834229,0,20.0004606246948,,,,,,,,,,,,,,,,,,,,,,,,,,,,,,,,,
,3878493215.76024,20.0002546310425,2599.7265625,-1.4096777824143E-5,1.19091518563231E-8,1,4,13.4005146026611,5.00673245656563,32.8599996864796,-0.0175395917443779,-0.0027266229942011,1,-8.07502177843868E-8,,,,,,,,,,,,,,,,,,,,,20.0002498626709,20.0002593994141,2599.7265625,2599.7265625,53.440332674073,5.63796765822539,4.11789178848267,54,1,0,0,1,0.2996826171875,33.7243423461914,1,1,3,20.0002498626709,0,20.0002546310425,,,,,,,,,,,,,,,,,,,,,,,,,,,,,,,,,
,3878493273.42853,19.9999485015869,2799.8671875,-1.5286919400393E-5,1.05888481708394E-8,1,4,13.4005146026611,5.00677173192354,32.8599996864796,-0.0190235406183285,-0.00293724166166823,1,-7.18181646204364E-8,,,,,,,,,,,,,,,,,,,,,19.9997062683105,20.0001907348633,2799.8671875,2799.8671875,53.3672504075249,5.63857682768825,4.11999750137329,54,1,0,0,1,0.299148559570313,33.7243423461914,1,1,3,20.0001907348633,0,19.9999485015869,,,,,,,,,,,,,,,,,,,,,,,,,,,,,,,,,
,3878493331.26878,19.9996881484985,2999.78125,-1.65115389950926E-5,9.99074790019663E-9,1,4,13.4005146026611,5.00668874971167,32.8599996864796,-0.0205502192643107,-0.00315108820965294,1,-6.04030913388817E-8,,,,,,,,,,,,,,,,,,,,,19.9995250701904,19.9998512268066,2999.78125,2999.78125,53.486057942448,5.6374001557677,4.11012172698975,54,1,0,0,1,0.299530029296875,33.7243423461914,1,1,3,19.9998512268066,0,19.9996881484985,,,,,,,,,,,,,,,,,,,,,,,,,,,,,,,,,
,3878493409.43509,20.000283241272,4499.83544921875,-2.57926882350841E-5,9.18230838693358E-9,1,4,13.4005146026611,5.00667409021126,32.8599996864796,-0.0321267817469374,-0.00475250919703039,1,4.19902461459539E-8,,,,,,,,,,,,,,,,,,,,,20.0002708435059,20.0002956390381,4499.83544921875,4499.83544921875,53.457528501496,5.63781151957309,4.11756229400635,54,1,0,0,1,0.302047729492188,33.7243423461914,1,1,3,20.0002708435059,0,20.000283241272,,,,,,,,,,,,,,,,,,,,,,,,,,,,,,,,,
,3878493473.81679,20.0002088546753,6499.71875,-3.82099531135852E-5,2.35280180052134E-8,1,4,13.4005146026611,5.00669419819988,32.8599996864796,-0.0475942679885896,-0.00703679728001453,1,6.52022379131036E-8,,,,,,,,,,,,,,,,,,,,,20.0001926422119,20.0002250671387,6499.71875,6499.71875,53.4841038711499,5.63803178537973,4.11934518814087,54,1,0,0,1,0.299072265625,33.7243423461914,1,1,3,20.0002250671387,0,20.0002088546753,,,,,,,,,,,,,,,,,,,,,,,,,,,,,,,,,
,3878493538.66017,20.0002784729004,8500.0302734375,-5.07527844270632E-5,1.78247676023073E-8,1,4,13.4005146026611,5.00670849504477,32.8599996864796,-0.0632184842598373,-0.0093425315480909,1,8.99847499702675E-8,,,,,,,,,,,,,,,,,,,,,19.9999904632568,20.0005664825439,8500.0302734375,8500.0302734375,53.5231852971114,5.63746729825994,4.1166615486145,53,1,68,0,0,0.299835205078125,34.2131004333496,1,1,3,19.9999904632568,0,20.0002784729004,,,,,,,,,,,,,,,,,,,,,,,,,,,,,,,,,
,3878493618.6893,20.0002088546753,10000.1982421875,-6.01499302162144E-5,1.48154449621453E-8,1,4,13.4005146026611,5.00667466844539,32.8599996864796,-0.0749170052260824,-0.0111124028051773,1,7.43985107600022E-8,,,,,,,,,,,,,,,,,,,,,20.0001468658447,20.0002708435059,10000.1982421875,10000.1982421875,53.4989548130153,5.63826735882769,4.11521577835083,54,1,0,0,1,0.301284790039063,33.7243423461914,1,1,3,20.0001468658447,0,20.0002088546753,,,,,,,,,,,,,,,,,,,,,,,,,,,,,,,,,
,3878493772.70947,19.9999475479126,30000.35546875,-1.85838132449128E-4,3.6569222722887E-8,1,4,13.4005146026611,5.00669297563658,32.8599996864796,-0.231449657230486,-0.0344247378648175,1,1.56074191620115E-7,,,,,,,,,,,,,,,,,,,,,19.9997463226318,20.0001487731934,30000.35546875,30000.35546875,53.5423351958326,5.63833440945943,4.10979557037354,53,1,68,0,0,0.300369262695313,33.7243423461914,1,1,3,20.0001487731934,0,19.9999475479126,,,,,,,,,,,,,,,,,,,,,,,,,,,,,,,,,
,3878493931.59445,20.000244140625,50000.34765625,-3.11998644084725E-4,5.76164369815731E-8,1,4,13.4005146026611,5.00664894996638,32.8599996864796,-0.388551117261603,-0.0579191450191786,1,1.61577323339113E-7,,,,,,,,,,,,,,,,,,,,,20.0001564025879,20.0003318786621,50000.34765625,50000.34765625,53.6748212298422,5.63950722549707,4.11559677124023,54,1,0,0,1,0.300064086914063,33.7243423461914,1,1,3,20.0001564025879,0,20.000244140625,,,,,,,,,,,,,,,,,,,,,,,,,,,,,,,,,
,3878494106.7217,19.9999504089355,70000.40625,-4.38618677954438E-4,2.18371349510093E-7,1,4,13.4005146026611,5.0067118281655,32.8599996864796,-0.546222900912338,-0.081596863606786,1,9.0105728692469E-8,,,,,,,,,,,,,,,,,,,,,19.999906539917,19.9999942779541,70000.40625,70000.40625,53.5884512784672,5.63935323465182,4.11136674880981,52,1,68,0,0,0.30029296875,34.7018585205078,1,1,3,19.999906539917,0,19.9999504089355,,,,,,,,,,,,,,,,,,,,,,,,,,,,,,,,,