File: SQUID/22163_LCOT/LCOT_MH_200K_FC+1T.dat
[Header]
; MPMS3 Data File (default extension .dat)
; Copyright (c) 2007, Quantum Design, Inc. All rights reserved.
TITLE,
FILEOPENTIME,3878509543.55328,11/25/2022,3:46 am
BYAPP,SQUID AC,0.9.1.0
INFO,MPMS3 Measurement Release 1.1.16 Build 347, MultiVu Release 2.3.3.2,APPNAME
INFO,0,MOMENT_UNITS
INFO,LCOT,SAMPLE_MATERIAL
INFO,,SAMPLE_COMMENT
INFO,1.8,SAMPLE_MASS
INFO,,SAMPLE_VOLUME
INFO,,SAMPLE_MOLECULAR_WEIGHT
INFO,,SAMPLE_SIZE
INFO,,SAMPLE_SHAPE
INFO,Quartz,SAMPLE_HOLDER
INFO,Standard,SAMPLE_HOLDER_DETAIL
INFO,65.79,SAMPLE_OFFSET
DATATYPE,COMMENT,1
DATATYPE,TIME,2
STARTUPAXIS,X,2
STARTUPAXIS,Y1,5
FIELDGROUP, VSM,2,3,4,5,6,8,9,10,11,14,15
FIELDGROUP, DC, 2,3,4,14,56,57,58,59,60,61,62,63,64,65,66,67,68,69
FIELDGROUP, AC, 2,3,4,11,16,17,18,19,20,21,22,23,24,25,26,27,28,29,30
STARTUPGROUP, All
[Data]
Comment,Time Stamp (sec),Temperature (K),Magnetic Field (Oe),Moment (emu),M. Std. Err. (emu),Transport Action,Averaging Time (sec),Frequency (Hz),Peak Amplitude (mm),Center Position (mm),Lockin Signal' (V),Lockin Signal (V),Range,M. Quad. Signal (emu),AC Moment (emu),AC M. Std Err. (emu),AC Phase (deg),AC Phase Std. Err. (deg),AC Susceptibility (emu/Oe),AC Suscept. Std Err. (emu/Oe),AC X' (emu/Oe),AC X' Std Err. (emu/Oe),AC X'' (emu/Oe),AC X'' Std Err. (emu/Oe),AC Drive (Oe),AC Frequency (Hz),AC Averaging Time (sec),AC Cycles,AC Range,AC Measure Type,AC Signal' (V),AC Signal'' (V),AC Trim Coil Ratio,AC Trim Coil Phase,Min. Temperature (K),Max. Temperature (K),Min. Field (Oe),Max. Field (Oe),Mass (grams),Motor Lag (deg),Pressure (Torr),Measure Count,Measurement Number,SQUID Status (code),Motor Status (code),Measure Status (code),Motor Current (amps),Motor Temp. (C),Temp. Status (code),Field Status (code),Chamber Status (code),Chamber Temp (K),Redirection State,Average Temp (K),Rotation Angle (deg),Rotator state,DC Moment Fixed Ctr (emu),DC Moment Err Fixed Ctr (emu),DC Moment Free Ctr (emu),DC Moment Err Free Ctr (emu),DC Fixed Fit,DC Free Fit,DC Calculated Center (mm),DC Calculated Center Err (mm),DC Scan Length (mm),DC Scan Time (s),DC Number of Points,DC Squid Drift,DC Min V (V),DC Max V (V),DC Scans per Measure,Sample Resistance,He3 Temperature,Sorb Resistance,Sorb Temperature,Map 05,Map 06,Map 07,Map 08,Map 09,Map 10,Map 11,Map 12,Map 13,Map 14,Map 15,Map 16
,3878509583.96097,199.981986999512,70000.0625,-0.000450206047482802,2.00730958245046E-7,1,4,13.4005146026611,5.00630010639621,32.990001142025,-0.560625400583339,-0.0834960912009189,1,2.90662872411265E-7,,,,,,,,,,,,,,,,,,,,,199.981918334961,199.982055664062,70000.0625,70000.0625,53.1945105047749,5.64078230505406,5.13144016265869,54,1,0,0,1,0.300979614257812,33.2355842590332,1,1,3,199.982055664062,0,199.981986999512,,,,,,,,,,,,,,,,,,,,,,,,,,,,,,,,,
,3878509740.12073,200.238494873047,49999.58984375,-0.000320494016653861,9.26070044678738E-8,1,4,13.4005146026611,5.00629343367307,32.990001142025,-0.399070584601918,-0.0596288138830818,1,5.47428304090326E-8,,,,,,,,,,,,,,,,,,,,,200.226516723633,200.250473022461,49999.58984375,49999.58984375,53.4661264152076,5.64045327746341,5.13177490234375,54,1,0,0,1,0.301132202148438,34.2131004333496,1,1,3,200.250473022461,0,200.238494873047,,,,,,,,,,,,,,,,,,,,,,,,,,,,,,,,,
,3878509915.52056,200.17024230957,29999.625,-0.000191119797657337,2.89184615531264E-8,1,4,13.4005146026611,5.00637597247675,32.990001142025,-0.237990452657462,-0.0355077063736651,1,7.39961602987644E-8,,,,,,,,,,,,,,,,,,,,,200.158309936523,200.182174682617,29999.625,29999.625,53.4446316309287,5.64007894149723,5.12931203842163,54,1,0,0,1,0.30059814453125,34.2131004333496,1,1,3,200.182174682617,0,200.17024230957,,,,,,,,,,,,,,,,,,,,,,,,,,,,,,,,,
,3878510074.38607,200.135833740234,9999.783203125,-6.18232335798368E-5,1.4122868379636E-8,1,4,13.4005146026611,5.00640839054799,32.990001142025,-0.076981118402796,-0.0115160672707127,1,-1.30426715818516E-10,,,,,,,,,,,,,,,,,,,,,200.11604309082,200.155624389648,9999.783203125,9999.783203125,53.5966583779191,5.63944903388048,5.12403535842895,54,1,0,0,1,0.300216674804687,34.7018585205078,1,1,3,200.155624389648,0,200.135833740234,,,,,,,,,,,,,,,,,,,,,,,,,,,,,,,,,
,3878510169.62526,200.420837402344,8499.5146484375,-5.21413586181129E-5,1.24830649569458E-8,1,4,13.4005146026611,5.00630379721852,32.990001142025,-0.0649342346255525,-0.00964077535322055,1,5.73336376661639E-8,,,,,,,,,,,,,,,,,,,,,200.414459228516,200.427215576172,8499.5146484375,8499.5146484375,53.5896237212461,5.64021055733551,5.11842346191406,54,1,0,0,1,0.300979614257812,34.7018585205078,1,1,3,200.414459228516,0,200.420837402344,,,,,,,,,,,,,,,,,,,,,,,,,,,,,,,,,
,3878510237.8847,200.354225158691,6499.88232421875,-3.9221357073149E-5,1.11960413312981E-8,1,4,13.4005146026611,5.00640367673827,32.990001142025,-0.0488367112136218,-0.0073120283903453,1,-4.99365722681158E-9,,,,,,,,,,,,,,,,,,,,,200.349304199219,200.359146118164,6499.88232421875,6499.88232421875,53.5646116086307,5.64006887879585,5.12282752990723,54,1,0,0,1,0.301742553710937,34.7018585205078,1,1,3,200.349304199219,0,200.354225158691,,,,,,,,,,,,,,,,,,,,,,,,,,,,,,,,,
,3878510304.60469,200.134353637695,4499.6337890625,-2.63272075841044E-5,8.28404825783455E-9,1,4,13.4005146026611,5.00632381262579,32.990001142025,-0.0327794871381323,-0.00491651729481573,1,-1.01396088021865E-8,,,,,,,,,,,,,,,,,,,,,200.130661010742,200.138046264648,4499.6337890625,4499.6337890625,53.6025205918134,5.63986473326409,5.11369848251343,52,1,68,0,0,0.30059814453125,34.7018585205078,1,1,3,200.13020324707,0,200.134353637695,,,,,,,,,,,,,,,,,,,,,,,,,,,,,,,,,
,3878510380.51217,200.224922180176,2999.86938476562,-1.67676626492217E-5,7.07571496536431E-9,1,4,13.4005146026611,5.00633114115305,32.990001142025,-0.0208834337824943,-0.00308916442107884,1,2.73905282926545E-8,,,,,,,,,,,,,,,,,,,,,200.223068237305,200.226776123047,2999.86938476562,2999.86938476562,53.5403811245345,5.64082502520532,5.11341238021851,54,1,0,0,1,0.299911499023438,34.7018585205078,1,1,3,200.223068237305,0,200.224922180176,,,,,,,,,,,,,,,,,,,,,,,,,,,,,,,,,
,3878510466.87961,200.456130981445,2799.57763671875,-1.55593535524605E-5,9.0641834939675E-9,1,4,13.4005146026611,5.00632464133079,32.990001142025,-0.0193933685502408,-0.00276715113224732,1,1.05243998552488E-7,,,,,,,,,,,,,,,,,,,,,200.448745727539,200.463516235352,2799.57763671875,2799.57763671875,53.5087251695057,5.64018288500648,5.11667346954346,54,1,0,0,1,0.299606323242188,34.7018585205078,1,1,3,200.448745727539,0,200.456130981445,,,,,,,,,,,,,,,,,,,,,,,,,,,,,,,,,
,3878510539.97568,200.341651916504,2599.51245117187,-1.43209301596397E-5,1.89056382279786E-8,1,4,13.4005146026611,5.00641372370684,32.990001142025,-0.0178757183162764,-0.00237656078264193,1,2.33719780217623E-7,,,,,,,,,,,,,,,,,,,,,200.327209472656,200.356094360352,2599.51245117187,2599.51245117187,53.587669649948,5.64034473225647,5.11515283584595,52,1,68,0,0,0.300750732421875,34.7018585205078,1,1,3,200.327209472656,0,200.341651916504,,,,,,,,,,,,,,,,,,,,,,,,,,,,,,,,,
,3878510619.17603,200.277893066406,2399.673828125,-1.30639130308434E-5,1.75555532359234E-8,1,4,13.4005146026611,5.00638304358822,32.990001142025,-0.0163012398558828,-0.00220337403226701,1,1.84747945295744E-7,,,,,,,,,,,,,,,,,,,,,200.273300170898,200.282485961914,2399.673828125,2399.673828125,53.501299698573,5.64000994299666,5.10567712783814,54,1,0,0,1,0.300369262695313,34.7018585205078,1,1,3,200.282485961914,0,200.277893066406,,,,,,,,,,,,,,,,,,,,,,,,,,,,,,,,,
,3878510706.45452,200.411254882813,2199.70922851562,-1.17915811198256E-5,9.66704661688293E-9,1,4,13.4005146026611,5.00632783992108,32.990001142025,-0.0147035427596556,-0.00205456747243113,1,1.13896260295596E-7,,,,,,,,,,,,,,,,,,,,,200.406509399414,200.416000366211,2199.70922851562,2199.70922851562,53.5310015823037,5.64038696846628,5.11025524139404,54,1,0,0,1,0.300369262695313,34.2131004333496,1,1,3,200.406509399414,0,200.411254882813,,,,,,,,,,,,,,,,,,,,,,,,,,,,,,,,,
,3878510783.01276,200.32926940918,1999.66943359375,-1.05971269166837E-5,1.94730521383964E-8,1,4,13.4005146026611,5.00634441617259,32.990001142025,-0.0132402736121128,-0.00167199865342625,1,2.42465812849345E-7,,,,,,,,,,,,,,,,,,,,,200.310424804687,200.348114013672,1999.66943359375,1999.66943359375,53.4544019874191,5.64053103195814,5.10422849655151,54,1,0,0,1,0.300445556640625,34.7018585205078,1,1,3,200.348114013672,0,200.32926940918,,,,,,,,,,,,,,,,,,,,,,,,,,,,,,,,,
,3878510857.9151,200.290336608887,1799.70495605469,-9.35527429665732E-6,2.00634119752057E-8,1,4,13.4005146026611,5.00632636066133,32.990001142025,-0.0116889168630774,-0.00147405474175581,1,2.15657106725397E-7,,,,,,,,,,,,,,,,,,,,,200.289413452148,200.291259765625,1799.70495605469,1799.70495605469,53.528656696746,5.64054869882811,5.10538244247437,52,1,68,0,0,0.300750732421875,34.2131004333496,1,1,3,200.291259765625,0,200.290336608887,,,,,,,,,,,,,,,,,,,,,,,,,,,,,,,,,
,3878510917.68863,200.187400817871,1599.70288085938,-8.1049630323517E-6,1.8857444802051E-8,1,4,13.4005146026611,5.00623659864758,32.990001142025,-0.0101290639935853,-0.00125964956770932,1,2.00784723619881E-7,,,,,,,,,,,,,,,,,,,,,200.187026977539,200.187774658203,1599.70288085938,1599.70288085938,53.5220128543326,5.6404746773826,5.1028094291687,52,1,68,0,0,0.30120849609375,34.2131004333496,1,1,3,200.187774658203,0,200.187400817871,,,,,,,,,,,,,,,,,,,,,,,,,,,,,,,,,
,3878511001.79968,200.359817504883,1399.57482910156,-6.91557282533057E-6,2.2431667483506E-8,1,4,13.4005146026611,5.00628666735358,32.990001142025,-0.00865622848974641,-0.000984786686025467,10,2.43622153637955E-7,,,,,,,,,,,,,,,,,,,,,200.346984863281,200.372650146484,1399.57482910156,1399.57482910156,53.6126817625634,5.64016891115574,5.10751819610596,54,1,0,0,1,0.299911499023438,34.2131004333496,1,1,3,200.372650146484,0,200.359817504883,,,,,,,,,,,,,,,,,,,,,,,,,,,,,,,,,
,3878511079.65848,200.34188079834,1199.48449707031,-5.71397055456845E-6,2.24149407910911E-8,1,4,13.4005146026611,5.00623889808343,32.990001142025,-0.00715566016089329,-0.000789776802598015,1,2.20478337119171E-7,,,,,,,,,,,,,,,,,,,,,200.331161499023,200.352600097656,1199.48449707031,1199.48449707031,53.5564045091787,5.64074113182221,5.10444307327271,54,1,0,0,1,0.301132202148438,33.7243423461914,1,1,3,200.331161499023,0,200.34188079834,,,,,,,,,,,,,,,,,,,,,,,,,,,,,,,,,
,3878511154.51616,200.352691650391,999.847290039063,-4.52051726344443E-6,2.30488087117759E-8,1,4,13.4005146026611,5.00617636972459,32.990001142025,-0.00566967556305205,-0.000566736104503149,1,2.21068656115082E-7,,,,,,,,,,,,,,,,,,,,,200.335662841797,200.369720458984,999.847290039063,999.847290039063,53.6134633910826,5.64171289930529,5.10522747039795,54,1,0,0,1,0.301666259765625,34.2131004333496,1,1,3,200.369720458984,0,200.352691650391,,,,,,,,,,,,,,,,,,,,,,,,,,,,,,,,,
,3878511315.82323,200.147178649902,799.794799804687,-3.39221932256238E-6,1.88247314570423E-8,1,4,13.4005146026611,5.00622716082214,32.990001142025,-0.00427200406505643,-0.000309038854075017,1,2.59254747664655E-7,,,,,,,,,,,,,,,,,,,,,200.142578125,200.151779174805,799.794799804687,799.794799804687,53.5603126517749,5.64071361304256,5.10011911392212,52,1,68,0,0,0.301284790039063,35.6793746948242,1,1,3,200.151779174805,0,200.147178649902,,,,,,,,,,,,,,,,,,,,,,,,,,,,,,,,,
,3878511406.99147,200.373832702637,599.981384277344,-2.27168207786854E-6,2.09766559444724E-8,1,4,13.4005146026611,5.00627609589294,32.990001142025,-0.00287897105587874,-8.60932426388247E-5,1,2.70685971441482E-7,,,,,,,,,,,,,,,,,,,,,200.365371704102,200.382293701172,599.981384277344,599.981384277344,53.5524963665826,5.6408872486588,5.09941339492798,54,1,0,0,1,0.300674438476562,34.2131004333496,1,1,3,200.365371704102,0,200.373832702637,,,,,,,,,,,,,,,,,,,,,,,,,,,,,,,,,
,3878511465.49889,200.303398132324,399.828155517578,-1.23752110341855E-6,2.25645103274534E-8,1,4,13.4005146026611,5.00612159625522,32.990001142025,-0.00158891195037666,9.10212576112282E-5,1,2.5823018213117E-7,,,,,,,,,,,,,,,,,,,,,200.297897338867,200.308898925781,399.828155517578,399.828155517578,53.4841038711499,5.64130697075044,5.10070466995239,54,1,0,0,1,0.300064086914063,34.2131004333496,1,1,3,200.297897338867,0,200.303398132324,,,,,,,,,,,,,,,,,,,,,,,,,,,,,,,,,
,3878511551.80791,200.323669433594,200.039962768555,-2.51488945746032E-7,2.77215336741855E-8,1,4,13.4005146026611,5.00617822583813,32.990001142025,-0.000363619100367296,0.000290670768823397,1,2.71072681289015E-7,,,,,,,,,,,,,,,,,,,,,200.3154296875,200.331909179687,200.039962768555,200.039962768555,53.4520571018614,5.6403178736208,5.10223436355591,52,1,68,0,0,0.301361083984375,34.2131004333496,1,1,3,200.3154296875,0,200.323669433594,,,,,,,,,,,,,,,,,,,,,,,,,,,,,,,,,
,3878511699.24276,200.140037536621,0.176235571503639,5.74973557684674E-7,1.93895433370865E-8,1,4,13.4005146026611,5.0062059917891,32.990001142025,0.000664590926930849,0.000450123979844523,1,2.75500615249571E-7,,,,,,,,,,,,,,,,,,,,,200.138427734375,200.141647338867,0.176235571503639,0.176235571503639,53.4743335146595,5.64109228445614,5.10474252700806,53,1,68,0,0,0.301284790039063,34.2131004333496,1,1,3,200.138336181641,0,200.140037536621,,,,,,,,,,,,,,,,,,,,,,,,,,,,,,,,,
,3878511772.21464,200.071640014648,-200.002197265625,1.24524764710894E-6,3.14199464623535E-8,1,4,13.4005146026611,5.00617243197133,32.990001142025,0.00151328809861201,0.000480404799464181,1,1.99555129798276E-7,,,,,,,,,,,,,,,,,,,,,200.060897827148,200.082382202148,-200.002197265625,-200.002197265625,53.5341280963807,5.64092354606508,5.1041374206543,54,1,0,0,1,0.301132202148438,34.2131004333496,1,1,3,200.082382202148,0,200.071640014648,,,,,,,,,,,,,,,,,,,,,,,,,,,,,,,,,
,3878511829.87153,200.307022094727,-399.815551757812,1.76534431168255E-6,1.98481834456809E-7,1,4,13.4005146026611,5.00621263789155,32.990001142025,0.00215263289502527,0.000632443454355826,1,2.43855822096021E-7,,,,,,,,,,,,,,,,,,,,,200.302978515625,200.311065673828,-399.815551757812,-399.815551757812,53.4528387303807,5.64058539122335,5.11116313934326,54,1,0,0,1,0.3009033203125,34.2131004333496,1,1,3,200.311065673828,0,200.307022094727,,,,,,,,,,,,,,,,,,,,,,,,,,,,,,,,,
,3878511888.51426,200.345352172852,-599.754821777344,2.84067564204712E-6,2.80149447325483E-8,1,4,13.4005146026611,5.00619679100244,32.990001142025,0.00350184429816907,0.000763762651872865,1,1.88463255867523E-7,,,,,,,,,,,,,,,,,,,,,200.337997436523,200.35270690918,-599.754821777344,-599.754821777344,53.3766299497556,5.64069241819492,5.10538101196289,52,1,68,0,0,0.301132202148438,35.6793746948242,1,1,3,200.35270690918,0,200.345352172852,,,,,,,,,,,,,,,,,,,,,,,,,,,,,,,,,
,3878511971.03003,200.30379486084,-799.794799804687,3.88424649417055E-6,2.40912782309714E-8,1,4,13.4005146026611,5.00620515683161,32.990001142025,0.00479415856387236,0.00100530336187145,10,2.26341393653414E-7,,,,,,,,,,,,,,,,,,,,,200.276947021484,200.330642700195,-799.794799804687,-799.794799804687,53.5454617099095,5.64088449606301,5.10873985290527,54,1,0,0,1,0.30120849609375,34.7018585205078,1,1,3,200.330642700195,0,200.30379486084,,,,,,,,,,,,,,,,,,,,,,,,,,,,,,,,,
,3878512065.9625,200.359222412109,-999.721435546875,4.99036342788801E-6,4.24523280627169E-8,1,4,13.4005146026611,5.00600279527063,32.990001142025,0.00618530238120921,0.00111597318793451,1,1.49807289208937E-7,,,,,,,,,,,,,,,,,,,,,200.351837158203,200.366607666016,-999.721435546875,-999.721435546875,53.5575769519576,5.64192114722043,5.10408496856689,54,1,0,0,1,0.300979614257812,34.2131004333496,1,1,3,200.366607666016,0,200.359222412109,,,,,,,,,,,,,,,,,,,,,,,,,,,,,,,,,
,3878512140.1138,200.281677246094,-1199.57263183594,6.11517563792574E-6,2.22744322447331E-8,1,4,13.4005146026611,5.0059936710883,32.990001142025,0.00758225898292189,0.00134860050020094,1,1.68388254830313E-7,,,,,,,,,,,,,,,,,,,,,200.277572631836,200.285781860352,-1199.57263183594,-1199.57263183594,53.4282174320249,5.64202983625869,5.10620355606079,52,1,68,0,0,0.30029296875,34.2131004333496,1,1,3,200.285781860352,0,200.281677246094,,,,,,,,,,,,,,,,,,,,,,,,,,,,,,,,,
,3878512222.29854,200.237174987793,-1399.56225585938,7.27589178837044E-6,9.38762118574036E-9,1,4,13.4005146026611,5.00616528483035,32.990001142025,0.00903004129796302,0.00155005333770642,10,1.56497265484628E-7,,,,,,,,,,,,,,,,,,,,,200.232635498047,200.241714477539,-1399.56225585938,-1399.56225585938,53.4633907153903,5.64103924864068,5.11379480361938,54,1,0,0,1,0.301055908203125,34.2131004333496,1,1,3,200.232635498047,0,200.237174987793,,,,,,,,,,,,,,,,,,,,,,,,,,,,,,,,,
,3878512304.89269,200.364799499512,-1599.57690429687,8.48497745583386E-6,8.88052482283535E-9,1,4,13.4005146026611,5.00625171925121,32.990001142025,0.0105412863385384,0.00173811906400974,1,1.26636850218205E-7,,,,,,,,,,,,,,,,,,,,,200.360824584961,200.368774414062,-1599.57690429687,-1599.57690429687,53.516541454698,5.64011690005154,5.10844421386719,52,1,68,0,0,0.302963256835937,34.2131004333496,1,1,3,200.360824584961,0,200.364799499512,,,,,,,,,,,,,,,,,,,,,,,,,,,,,,,,,
,3878512381.9933,200.173324584961,-1799.6923828125,9.72098120443363E-6,1.17544328508145E-8,1,4,13.4005146026611,5.00613626232371,32.990001142025,0.0120808146823943,0.00196201889846746,1,1.21610000892387E-7,,,,,,,,,,,,,,,,,,,,,200.165328979492,200.18132019043,-1799.6923828125,-1799.6923828125,53.5310015823037,5.64084104405968,5.11294555664063,54,1,0,0,1,0.301055908203125,32.7468223571777,1,1,3,200.18132019043,0,200.173324584961,,,,,,,,,,,,,,,,,,,,,,,,,,,,,,,,,
,3878512439.4042,200.144325256348,-1999.78271484375,1.09310287521068E-5,1.09321116925987E-8,1,4,13.4005146026611,5.00617413104188,32.990001142025,0.0135890848533784,0.0021773133425401,1,1.13491052851566E-7,,,,,,,,,,,,,,,,,,,,,200.143844604492,200.144805908203,-1999.78271484375,-1999.78271484375,53.4903568993037,5.64112041925589,5.1114387512207,53,1,68,0,0,0.300827026367188,34.2131004333496,1,1,3,200.143844604492,0,200.144325256348,,,,,,,,,,,,,,,,,,,,,,,,,,,,,,,,,
,3878512497.15018,200.24853515625,-2199.69677734375,1.22087557493059E-5,3.99832339208501E-8,1,4,13.4005146026611,5.00621819455916,32.990001142025,0.0151925857171619,0.00233233216511571,1,4.68310235963134E-8,,,,,,,,,,,,,,,,,,,,,200.238342285156,200.258728027344,-2199.69677734375,-2199.69677734375,53.5892329069864,5.64056300112643,5.11207056045532,54,1,0,0,1,0.302352905273438,33.7243423461914,1,1,3,200.258728027344,0,200.24853515625,,,,,,,,,,,,,,,,,,,,,,,,,,,,,,,,,
,3878512555.89189,200.217010498047,-2399.71142578125,1.34267851155683E-5,5.84588493038513E-9,1,4,13.4005146026611,5.00634280525842,32.990001142025,0.0167026589235213,0.00260672368592634,1,8.49228625618837E-8,,,,,,,,,,,,,,,,,,,,,200.213302612305,200.220718383789,-2399.71142578125,-2399.71142578125,53.465735600948,5.64012225491746,5.11414051055908,54,1,0,0,1,0.300674438476562,33.7243423461914,1,1,3,200.220718383789,0,200.217010498047,,,,,,,,,,,,,,,,,,,,,,,,,,,,,,,,,
,3878512627.21202,200.325073242187,-2599.63842773438,1.47077911499715E-5,1.31758063203756E-8,1,4,13.4005146026611,5.00630861861177,32.990001142025,0.0183001918209963,0.0028275798670347,1,7.0685853209964E-8,,,,,,,,,,,,,,,,,,,,,200.306854248047,200.343292236328,-2599.63842773438,-2599.63842773438,53.3906992631018,5.64032506629877,5.11643171310425,54,1,0,0,1,0.301437377929687,34.2131004333496,1,1,3,200.343292236328,0,200.325073242187,,,,,,,,,,,,,,,,,,,,,,,,,,,,,,,,,
,3878512684.84092,200.32543182373,-2799.59008789062,1.59584838818752E-5,1.21086656911827E-8,1,4,13.4005146026611,5.00628660282238,32.990001142025,0.0198553705133167,0.00307386034335976,1,8.13974324274185E-8,,,,,,,,,,,,,,,,,,,,,200.32080078125,200.330062866211,-2799.59008789062,-2799.59008789062,53.4571376872364,5.64071668271726,5.12041425704956,54,1,0,0,1,0.30120849609375,34.2131004333496,1,1,3,200.32080078125,0,200.32543182373,,,,,,,,,,,,,,,,,,,,,,,,,,,,,,,,,
,3878512743.67667,200.303672790527,-2999.60498046875,1.71993823677036E-5,1.68737576499795E-8,1,4,13.4005146026611,5.00641409049648,32.990001142025,0.0214047231810891,0.00328172067356349,1,6.26102643794743E-8,,,,,,,,,,,,,,,,,,,,,200.291000366211,200.316345214844,-2999.60498046875,-2999.60498046875,53.4078950905249,5.63960984501666,5.12303876876831,54,1,0,0,1,0.300140380859375,34.2131004333496,1,1,3,200.316345214844,0,200.303672790527,,,,,,,,,,,,,,,,,,,,,,,,,,,,,,,,,
,3878512899.75893,200.305809020996,-4499.7216796875,2.68123490154907E-5,1.06491852184311E-8,1,4,13.4005146026611,5.00627624231526,32.990001142025,0.0333931769075716,0.00493957833758925,1,-4.38611939131892E-8,,,,,,,,,,,,,,,,,,,,,200.278793334961,200.332824707031,-4499.7216796875,-4499.7216796875,53.4215735896114,5.64029345596853,5.1177864074707,54,1,0,0,1,0.301437377929687,33.7243423461914,1,1,3,200.332824707031,0,200.305809020996,,,,,,,,,,,,,,,,,,,,,,,,,,,,,,,,,
,3878512983.45815,200.420791625977,-6499.7314453125,3.96681675620697E-5,1.20244031827752E-8,1,4,13.4005146026611,5.00634417909129,32.990001142025,0.0494061328415597,0.00730232929406904,1,-6.95383106674743E-8,,,,,,,,,,,,,,,,,,,,,200.404266357422,200.437316894531,-6499.7314453125,-6499.7314453125,53.4532295446403,5.64005935241669,5.12257957458496,54,1,0,0,1,0.30059814453125,33.7243423461914,1,1,3,200.437316894531,0,200.420791625977,,,,,,,,,,,,,,,,,,,,,,,,,,,,,,,,,
,3878513049.61901,200.221260070801,-8499.6279296875,5.25733634290425E-5,9.03501137842997E-9,1,4,13.4005146026611,5.00634314817148,32.990001142025,0.0654807292630158,0.00966876455074261,1,-9.95655688270306E-8,,,,,,,,,,,,,,,,,,,,,200.21044921875,200.232070922852,-8499.6279296875,-8499.6279296875,53.3910900773614,5.63988435133826,5.11651134490967,52,1,68,0,0,0.301361083984375,34.2131004333496,1,1,3,200.232070922852,0,200.221260070801,,,,,,,,,,,,,,,,,,,,,,,,,,,,,,,,,
,3878513217.30466,200.465171813965,-9999.669921875,6.2258623337241E-5,1.16274737788104E-8,1,4,13.4005146026611,5.00638620568842,32.990001142025,0.077540167832649,0.0114808448215434,1,-9.32310776050211E-8,,,,,,,,,,,,,,,,,,,,,200.464324951172,200.466018676758,-9999.669921875,-9999.669921875,53.5321740250826,5.63904363297526,5.12798357009888,54,1,0,0,1,0.301132202148438,34.2131004333496,1,1,3,200.464324951172,0,200.465171813965,,,,,,,,,,,,,,,,,,,,,,,,,,,,,,,,,
,3878513374.28282,200.100311279297,-29999.701171875,0.000191735828904356,3.09115649739036E-8,1,4,13.4005146026611,5.00631278094894,32.990001142025,0.238771719211473,0.0354987172928404,1,-1.7286667993969E-7,,,,,,,,,,,,,,,,,,,,,200.096145629883,200.104476928711,-29999.701171875,-29999.701171875,53.3727218071595,5.64052977470351,5.12803840637207,54,1,0,0,1,0.30181884765625,33.7243423461914,1,1,3,200.096145629883,0,200.100311279297,,,,,,,,,,,,,,,,,,,,,,,,,,,,,,,,,
,3878513549.88746,200.128562927246,-49999.73046875,0.000321354473954627,5.36244206878231E-8,1,4,13.4005146026611,5.00637358386387,32.990001142025,0.400183907625516,0.0595699939974724,1,-2.31772329582352E-7,,,,,,,,,,,,,,,,,,,,,200.097763061523,200.159362792969,-49999.73046875,-49999.73046875,53.3481005088037,5.63902465081081,5.12203025817871,54,1,0,0,1,0.300369262695313,34.2131004333496,1,1,3,200.161071777344,0,200.128562927246,,,,,,,,,,,,,,,,,,,,,,,,,,,,,,,,,
,3878513710.50027,200.262054443359,-69999.671875,0.000451032714998371,1.87398409267673E-7,1,4,13.4005146026611,5.00645755246772,32.990001142025,0.561662788310891,0.0837649061505193,1,-2.01394457039984E-7,,,,,,,,,,,,,,,,,,,,,200.236663818359,200.287445068359,-69999.671875,-69999.671875,53.1378424371306,5.63881598069178,5.1311616897583,54,1,0,0,1,0.29937744140625,34.2131004333496,1,1,3,200.287445068359,0,200.262054443359,,,,,,,,,,,,,,,,,,,,,,,,,,,,,,,,,
,3878513871.80891,200.230506896973,-49999.640625,0.000321142640137224,9.31340156919903E-8,1,4,13.4005146026611,5.00648689147566,32.990001142025,0.399926106032467,0.0595771224424921,1,-1.95872376073104E-7,,,,,,,,,,,,,,,,,,,,,200.207290649414,200.253723144531,-49999.640625,-49999.640625,53.3766299497556,5.63871771119201,5.13020944595337,54,1,0,0,1,0.300521850585937,34.7018585205078,1,1,3,200.253723144531,0,200.230506896973,,,,,,,,,,,,,,,,,,,,,,,,,,,,,,,,,
,3878514030.9436,200.031944274902,-29999.662109375,0.00019148839219818,5.38736577799141E-8,1,4,13.4005146026611,5.00645575886347,32.990001142025,0.238462994861003,0.0355218992484402,1,-1.18372923060382E-7,,,,,,,,,,,,,,,,,,,,,200.030471801758,200.033416748047,-29999.662109375,-29999.662109375,53.3957798484768,5.63921899873447,5.13146877288818,54,1,0,0,1,0.299301147460937,33.7243423461914,1,1,3,200.030471801758,0,200.031944274902,,,,,,,,,,,,,,,,,,,,,,,,,,,,,,,,,
,3878514189.06561,200.004470825195,-10000.0595703125,6.19047229069286E-5,2.86235945112496E-8,1,4,13.4005146026611,5.00646192955049,32.990001142025,0.0770834898888109,0.0115330900746151,1,1.47258665347122E-9,,,,,,,,,,,,,,,,,,,,,199.990310668945,200.018630981445,-10000.0595703125,-10000.0595703125,53.4751151431787,5.63998967445984,5.13078260421753,54,1,0,0,1,0.300674438476562,34.2131004333496,1,1,3,200.018630981445,0,200.004470825195,,,,,,,,,,,,,,,,,,,,,,,,,,,,,,,,,
,3878514260.84519,200.195320129395,-8500.3203125,5.22066784275224E-5,2.439741841477E-8,1,4,13.4005146026611,5.00645313394392,32.990001142025,0.0650094608997771,0.00971229028310727,1,-9.99535626361527E-9,,,,,,,,,,,,,,,,,,,,,200.194747924805,200.195892333984,-8500.3203125,-8500.3203125,53.4868395709672,5.63941457813808,5.13267993927002,52,1,68,0,0,0.2996826171875,34.2131004333496,1,1,3,200.195892333984,0,200.195320129395,,,,,,,,,,,,,,,,,,,,,,,,,,,,,,,,,
,3878514327.89455,200.382217407227,-6500.4365234375,3.92839975767013E-5,1.7093013900957E-8,1,4,13.4005146026611,5.00647856165775,32.990001142025,0.0489149207288742,0.0073292784329787,1,9.35338728428468E-9,,,,,,,,,,,,,,,,,,,,,200.365966796875,200.398468017578,-6500.4365234375,-6500.4365234375,53.5321740250826,5.63980705368849,5.12664842605591,52,1,68,0,0,0.298919677734375,34.7018585205078,1,1,3,200.398468017578,0,200.382217407227,,,,,,,,,,,,,,,,,,,,,,,,,,,,,,,,,
,3878514404.60985,200.369926452637,-4500.28857421875,2.63784506137774E-5,1.01934643643472E-8,1,4,13.4005146026611,5.00642882124825,32.990001142025,0.0328430838478111,0.00493403992816858,1,1.64304497177672E-8,,,,,,,,,,,,,,,,,,,,,200.361633300781,200.378219604492,-4500.28857421875,-4500.28857421875,53.5509331095441,5.63970664100011,5.13592672348022,52,1,68,0,0,0.298385620117188,34.7018585205078,1,1,3,200.361633300781,0,200.369926452637,,,,,,,,,,,,,,,,,,,,,,,,,,,,,,,,,
,3878514485.51824,200.354125976562,-3000.17138671875,1.68029817582493E-5,6.84199423640295E-9,1,4,13.4005146026611,5.00643375384842,32.990001142025,0.0209273844225167,0.00310002208465289,1,-2.40254608189707E-8,,,,,,,,,,,,,,,,,,,,,200.353851318359,200.354400634766,-3000.17138671875,-3000.17138671875,53.4641723439095,5.63983404553304,5.13281917572022,54,1,0,0,1,0.2996826171875,34.2131004333496,1,1,3,200.353851318359,0,200.354125976562,,,,,,,,,,,,,,,,,,,,,,,,,,,,,,,,,
,3878514552.39636,200.381614685059,-2800.3330078125,1.56267614725769E-5,1.67596822948191E-8,1,4,13.4005146026611,5.00645755406619,32.990001142025,0.019497230077295,0.00265142637278057,1,-2.08347089545749E-7,,,,,,,,,,,,,,,,,,,,,200.363906860352,200.399322509766,-2800.3330078125,-2800.3330078125,53.4958282989384,5.63942706216285,5.13485765457153,54,1,0,0,1,0.300674438476562,34.2131004333496,1,1,3,200.399322509766,0,200.381614685059,,,,,,,,,,,,,,,,,,,,,,,,,,,,,,,,,
,3878514611.24444,200.321479797363,-2600.36840820313,1.43943623553305E-5,1.80298975079415E-8,1,4,13.4005146026611,5.00647045687842,32.990001142025,0.0179651581560454,0.00240552739062708,1,-2.21472464408242E-7,,,,,,,,,,,,,,,,,,,,,200.298309326172,200.344650268555,-2600.36840820313,-2600.36840820313,53.4516662876018,5.63958967077951,5.135009765625,54,1,0,0,1,0.300216674804687,34.2131004333496,1,1,3,200.344650268555,0,200.321479797363,,,,,,,,,,,,,,,,,,,,,,,,,,,,,,,,,
,3878514668.82345,200.298629760742,-2400.32836914062,1.31049472158294E-5,1.68037339614525E-8,1,4,13.4005146026611,5.00631707515079,32.990001142025,0.0163590175834055,0.00216428805718183,1,-2.22244389821038E-7,,,,,,,,,,,,,,,,,,,,,200.280639648438,200.316619873047,-2400.32836914062,-2400.32836914062,53.4938742276403,5.64041661560423,5.129807472229,54,1,0,0,1,0.302886962890625,35.6793746948242,1,1,3,200.316619873047,0,200.298629760742,,,,,,,,,,,,,,,,,,,,,,,,,,,,,,,,,
,3878514741.25662,200.372871398926,-2200.326171875,1.18788833677604E-5,2.16209839860389E-8,1,4,13.4005146026611,5.00637599302135,32.990001142025,0.0148316120191071,0.00194274080645956,1,-2.16786668232222E-7,,,,,,,,,,,,,,,,,,,,,200.354965209961,200.390777587891,-2200.326171875,-2200.326171875,53.5907961640249,5.64002579455131,5.1341233253479,54,1,0,0,1,0.30059814453125,34.2131004333496,1,1,3,200.390777587891,0,200.372871398926,,,,,,,,,,,,,,,,,,,,,,,,,,,,,,,,,
,3878514818.14628,200.372970581055,-2000.44995117187,1.0629304053734E-5,1.69122172357121E-8,1,4,13.4005146026611,5.00639496831523,32.990001142025,0.0132710829307892,0.00174114570168588,10,-1.91766358064018E-7,,,,,,,,,,,,,,,,,,,,,200.361373901367,200.384567260742,-2000.44995117187,-2000.44995117187,53.5509331095441,5.64000366288351,5.13735055923462,53,1,64,0,0,0.30181884765625,34.7018585205078,1,1,3,200.361373901367,0,200.372970581055,,,,,,,,,,,,,,,,,,,,,,,,,,,,,,,,,
,3878514884.22121,200.378677368164,-1800.18334960938,9.36950167675186E-6,2.13426944930123E-8,1,4,13.4005146026611,5.00640910204431,32.990001142025,0.0117048463496008,0.00149048474950175,1,-2.04617921880485E-7,,,,,,,,,,,,,,,,,,,,,200.366775512695,200.390579223633,-1800.18334960938,-1800.18334960938,53.4637815296499,5.63964255838132,5.1357626914978,54,1,0,0,1,0.300521850585937,33.7243423461914,1,1,3,200.390579223633,0,200.378677368164,,,,,,,,,,,,,,,,,,,,,,,,,,,,,,,,,
,3878514940.76634,200.282279968262,-1600.11828613281,8.13743681053026E-6,1.91078214376376E-8,1,4,13.4005146026611,5.00642715144681,32.990001142025,0.0101731961590029,0.00124466065625207,1,-2.17733905300153E-7,,,,,,,,,,,,,,,,,,,,,200.274612426758,200.289947509766,-1600.11828613281,-1600.11828613281,53.4309531318422,5.63984630559885,5.13355302810669,54,1,0,0,1,0.298004150390625,34.2131004333496,1,1,3,200.289947509766,0,200.282279968262,,,,,,,,,,,,,,,,,,,,,,,,,,,,,,,,,
,3878515014.64814,200.303695678711,-1400.103515625,6.89585884297111E-6,2.22619271505422E-8,1,4,13.4005146026611,5.00645884492526,32.990001142025,0.00863134480840884,0.000986189335614908,1,-2.39584645771969E-7,,,,,,,,,,,,,,,,,,,,,200.286087036133,200.321304321289,-1400.103515625,-1400.103515625,53.5423351958326,5.64029853142458,5.12729406356812,54,1,0,0,1,0.30059814453125,33.7243423461914,1,1,3,200.321304321289,0,200.303695678711,,,,,,,,,,,,,,,,,,,,,,,,,,,,,,,,,
,3878515173.04234,200.135887145996,-1200.03833007812,5.76565126044408E-6,1.67837758170241E-8,1,4,13.4005146026611,5.00649640906702,32.990001142025,0.00723350912931807,0.000712686074716902,1,-2.90164785180065E-7,,,,,,,,,,,,,,,,,,,,,200.135879516602,200.135894775391,-1200.03833007812,-1200.03833007812,53.5001272557941,5.63993185626217,5.12856435775757,53,1,68,0,0,0.3021240234375,34.2131004333496,1,1,3,200.135879516602,0,200.135887145996,,,,,,,,,,,,,,,,,,,,,,,,,,,,,,,,,
,3878515230.18769,200.143043518066,-1000.16198730469,4.51974527870598E-6,2.07992189942736E-8,1,4,13.4005146026611,5.00639084099332,32.990001142025,0.00566715491769594,0.000579320587681149,1,-2.1087383919554E-7,,,,,,,,,,,,,,,,,,,,,200.138595581055,200.147491455078,-1000.16198730469,-1000.16198730469,53.4375969742557,5.64013616693991,5.13679027557373,54,1,0,0,1,0.299301147460937,34.2131004333496,1,1,3,200.147491455078,0,200.143043518066,,,,,,,,,,,,,,,,,,,,,,,,,,,,,,,,,
,3878515286.48457,200.201698303223,-800.222778320312,3.38415614159366E-6,2.06629533583124E-8,1,4,13.4005146026611,5.00634326500296,32.990001142025,0.00425397156850788,0.000361901327625517,1,-2.15602189807018E-7,,,,,,,,,,,,,,,,,,,,,200.184829711914,200.218566894531,-800.222778320312,-800.222778320312,53.5313923965634,5.64050868436061,5.13762521743774,54,1,0,0,1,0.300750732421875,34.2131004333496,1,1,3,200.218566894531,0,200.201698303223,,,,,,,,,,,,,,,,,,,,,,,,,,,,,,,,,
,3878515355.16561,200.383232116699,-600.107238769531,2.25477495392103E-6,2.8216558197358E-8,1,4,13.4005146026611,5.00644022126924,32.990001142025,0.00284805879985352,0.000149739318764824,1,-2.17046495895368E-7,,,,,,,,,,,,,,,,,,,,,200.374526977539,200.391937255859,-600.107238769531,-600.107238769531,53.4997364415345,5.64008378320423,5.13560104370117,54,1,0,0,1,0.300750732421875,34.2131004333496,1,1,3,200.391937255859,0,200.383232116699,,,,,,,,,,,,,,,,,,,,,,,,,,,,,,,,,
,3878515411.80693,200.344184875488,-400.193206787109,1.21210592479873E-6,2.22042504852556E-8,1,4,13.4005146026611,5.00635543584212,32.990001142025,0.00154696528334515,-2.62102850906452E-5,1,-2.02373263271592E-7,,,,,,,,,,,,,,,,,,,,,200.340042114258,200.348327636719,-400.193206787109,-400.193206787109,53.3848370492076,5.64025329898012,5.12939357757568,54,1,0,0,1,0.301742553710937,34.2131004333496,1,1,3,200.340042114258,0,200.344184875488,,,,,,,,,,,,,,,,,,,,,,,,,,,,,,,,,
,3878515468.67944,200.300498962402,-200.102905273438,2.2890798294139E-7,2.77527255840052E-8,1,4,13.4005146026611,5.00633040026581,32.990001142025,0.000328667363463029,-0.000249095841087545,1,-2.34295409319748E-7,,,,,,,,,,,,,,,,,,,,,200.295974731445,200.305023193359,-200.102905273438,-200.102905273438,53.435252088698,5.64112781433262,5.13243913650513,52,1,68,0,0,0.301437377929687,34.2131004333496,1,1,3,200.295974731445,0,200.300498962402,,,,,,,,,,,,,,,,,,,,,,,,,,,,,,,,,
,3878515541.659,200.23030090332,-0.327294647693634,-6.38055556278643E-7,3.28104734909431E-8,1,4,13.4005146026611,5.00645280782501,32.990001142025,-0.000748804785943219,-0.00042434689722083,1,-2.45337808545705E-7,,,,,,,,,,,,,,,,,,,,,200.228118896484,200.232482910156,-0.327294647693634,-0.327294647693634,53.5110700550634,5.64048734383041,5.1339635848999,53,1,68,0,0,0.299453735351562,34.7018585205078,1,1,3,200.228118896484,0,200.23030090332,,,,,,,,,,,,,,,,,,,,,,,,,,,,,,,,,
,3878515601.71499,200.230163574219,199.939254760742,-1.24097804959828E-6,1.9956288285638E-8,1,4,13.4005146026611,5.00636834763409,32.990001142025,-0.00150976603152095,-0.000468194841874824,1,-1.90366849375783E-7,,,,,,,,,,,,,,,,,,,,,200.224411010742,200.235916137695,199.939254760742,199.939254760742,53.4512754733422,5.64058349603752,5.13478708267212,54,1,0,0,1,0.299835205078125,34.7018585205078,1,1,3,200.235916137695,0,200.230163574219,,,,,,,,,,,,,,,,,,,,,,,,,,,,,,,,,
,3878515659.34457,200.240592956543,399.815551757812,-1.97462045137645E-6,1.46166411563195E-8,1,4,13.4005146026611,5.00637727582946,32.990001142025,-0.00242872179308047,-0.000568472727339147,1,-1.61150976606084E-7,,,,,,,,,,,,,,,,,,,,,200.233871459961,200.247314453125,399.815551757812,399.815551757812,53.369204478823,5.64034103063665,5.13795852661133,53,1,68,0,0,0.299072265625,34.2131004333496,1,1,3,200.233871459961,0,200.240592956543,,,,,,,,,,,,,,,,,,,,,,,,,,,,,,,,,
,3878515717.09475,200.295989990234,599.943603515625,-2.87554443124741E-6,1.34988655974494E-8,1,4,13.4005146026611,5.00632206365925,32.990001142025,-0.00354685358020946,-0.000760458724802396,1,-1.80572205357667E-7,,,,,,,,,,,,,,,,,,,,,200.290832519531,200.301147460938,599.943603515625,599.943603515625,53.381319720871,5.64093913594134,5.13013172149658,54,1,0,0,1,0.300827026367188,34.2131004333496,1,1,3,200.290832519531,0,200.295989990234,,,,,,,,,,,,,,,,,,,,,,,,,,,,,,,,,
,3878515774.77377,200.345069885254,799.631103515625,-3.82780219874685E-6,1.85367810986666E-8,1,4,13.4005146026611,5.0062969047679,32.990001142025,-0.00473100477938551,-0.000947991552208275,1,-1.88736117043523E-7,,,,,,,,,,,,,,,,,,,,,200.340408325195,200.349731445313,799.631103515625,799.631103515625,53.543898452871,5.64068892886081,5.11333322525024,54,1,0,0,1,0.300445556640625,34.2131004333496,1,1,3,200.340408325195,0,200.345069885254,,,,,,,,,,,,,,,,,,,,,,,,,,,,,,,,,
,3878515832.38728,200.189476013184,999.784362792969,-4.97264611523786E-6,3.69169672091171E-8,1,4,13.4005146026611,5.00636988866143,32.990001142025,-0.00615488260031634,-0.00117290301654682,1,-1.98086397641403E-7,,,,,,,,,,,,,,,,,,,,,200.171051025391,200.207901000977,999.784362792969,999.784362792969,53.3848370492076,5.64115069361792,5.11514902114868,53,1,68,0,0,0.301437377929687,34.2131004333496,1,1,3,200.207901000977,0,200.189476013184,,,,,,,,,,,,,,,,,,,,,,,,,,,,,,,,,
,3878515890.01041,200.28101348877,1199.69848632812,-6.1758240470461E-6,5.6039852927302E-8,1,4,13.4005146026611,5.00631945949628,32.990001142025,-0.00766536589468645,-0.00131389123211234,1,-1.31341512888724E-7,,,,,,,,,,,,,,,,,,,,,200.266540527344,200.295486450195,1199.69848632812,1199.69848632812,53.4395510455537,5.64052633855617,5.11614847183228,53,1,68,0,0,0.29998779296875,33.7243423461914,1,1,3,200.295486450195,0,200.28101348877,,,,,,,,,,,,,,,,,,,,,,,,,,,,,,,,,
,3878515948.24123,200.233100891113,1399.80139160156,-7.29564548384121E-6,1.19306911819937E-8,1,4,13.4005146026611,5.00636110675316,32.990001142025,-0.00906053667199268,-0.0015176870595227,1,-1.27480586815896E-7,,,,,,,,,,,,,,,,,,,,,200.228591918945,200.237609863281,1399.80139160156,1399.80139160156,53.4821497998518,5.64085490125543,5.1207423210144,52,1,68,0,0,0.301666259765625,34.2131004333496,1,1,3,200.228591918945,0,200.233100891113,,,,,,,,,,,,,,,,,,,,,,,,,,,,,,,,,
,3878516005.85612,200.308967590332,1599.70288085938,-8.55924132345719E-6,4.82905918126904E-8,1,4,13.4005146026611,5.00634104175469,32.990001142025,-0.0106293836285552,-0.00178298545804629,1,-1.51525302008418E-7,,,,,,,,,,,,,,,,,,,,,200.299942016602,200.317993164062,1599.70288085938,1599.70288085938,53.4325163888806,5.64063972351377,5.11830902099609,52,1,68,0,0,0.302200317382812,34.2131004333496,1,1,3,200.299942016602,0,200.308967590332,,,,,,,,,,,,,,,,,,,,,,,,,,,,,,,,,
,3878516078.30873,200.442642211914,1799.5791015625,-9.69646604099046E-6,5.11954592748989E-8,1,4,13.4005146026611,5.00627708602742,32.990001142025,-0.0120720614098979,-0.00181516902315963,1,-7.27649827957079E-9,,,,,,,,,,,,,,,,,,,,,200.431488037109,200.453796386719,1799.5791015625,1799.5791015625,53.4970007417172,5.64100197585567,5.12458324432373,52,1,68,0,0,0.29937744140625,35.6793746948242,1,1,3,200.431488037109,0,200.442642211914,,,,,,,,,,,,,,,,,,,,,,,,,,,,,,,,,
,3878516137.75696,200.379516601562,1999.92114257813,-1.09362571802985E-5,2.49261243612823E-8,1,4,13.4005146026611,5.0063196558664,32.990001142025,-0.0136027623906714,-0.00213415560997959,1,-7.79771891138478E-8,,,,,,,,,,,,,,,,,,,,,200.359649658203,200.399383544922,1999.92114257813,1999.92114257813,53.404768576448,5.64093774489757,5.11596155166626,54,1,0,0,1,0.300750732421875,34.7018585205078,6,1,3,200.399383544922,0,200.379516601562,,,,,,,,,,,,,,,,,,,,,,,,,,,,,,,,,
,3878516243.56239,200.438346862793,2199.93603515625,-1.22147602955559E-5,8.88523332888034E-9,1,4,13.4005146026611,5.00633060513415,32.990001142025,-0.015198122112589,-0.00234968192871,1,-5.98078003500797E-8,,,,,,,,,,,,,,,,,,,,,200.428253173828,200.448440551758,2199.93603515625,2199.93603515625,53.501299698573,5.6408739570756,5.12165212631226,54,1,0,0,1,0.300445556640625,34.2131004333496,1,1,3,200.428253173828,0,200.438346862793,,,,,,,,,,,,,,,,,,,,,,,,,,,,,,,,,
,3878516302.04005,200.329742431641,2400.02612304687,-1.34452699823566E-5,1.03446500088084E-8,1,4,13.4005146026611,5.00638638559405,32.990001142025,-0.0167265188197633,-0.00260592206703071,1,-8.14883807431527E-8,,,,,,,,,,,,,,,,,,,,,200.309677124023,200.349807739258,2400.02612304687,2400.02612304687,53.4364245314768,5.64073036103831,5.11992263793945,54,1,0,0,1,0.300140380859375,33.7243423461914,1,1,3,200.349807739258,0,200.329742431641,,,,,,,,,,,,,,,,,,,,,,,,,,,,,,,,,
,3878516360.61996,200.245979309082,2599.92797851562,-1.469023146528E-5,1.0498759271772E-8,1,4,13.4005146026611,5.00632400561686,32.990001142025,-0.0182748970225252,-0.00284777780473829,1,-8.95241770662871E-8,,,,,,,,,,,,,,,,,,,,,200.228881835938,200.263076782227,2599.92797851562,2599.92797851562,53.4669080437268,5.64071998773415,5.12646341323853,54,1,0,0,1,0.3021240234375,33.7243423461914,1,1,3,200.263076782227,0,200.245979309082,,,,,,,,,,,,,,,,,,,,,,,,,,,,,,,,,
,3878516430.95813,200.468315124512,2799.84204101562,-1.5966355257281E-5,1.2073979375602E-8,1,4,13.4005146026611,5.00633693563373,32.990001142025,-0.0198740714463035,-0.00301774211768777,1,-3.51160104073436E-8,,,,,,,,,,,,,,,,,,,,,200.462127685547,200.474502563477,2799.84204101562,2799.84204101562,53.432125574621,5.64144088561093,5.12683725357056,53,1,68,0,0,0.301284790039063,33.7243423461914,1,1,3,200.462127685547,0,200.468315124512,,,,,,,,,,,,,,,,,,,,,,,,,,,,,,,,,
,3878516488.85463,200.386161804199,2999.80639648438,-1.72153740040121E-5,1.79506027392544E-8,1,4,13.4005146026611,5.00635375151158,32.990001142025,-0.0214289132146782,-0.00325363662778364,1,-3.77079010556711E-8,,,,,,,,,,,,,,,,,,,,,200.371276855469,200.40104675293,2999.80639648438,2999.80639648438,53.4977823702364,5.64039126868512,5.12255525588989,54,1,0,0,1,0.299911499023438,34.2131004333496,1,1,3,200.40104675293,0,200.386161804199,,,,,,,,,,,,,,,,,,,,,,,,,,,,,,,,,
,3878516642.55187,200.092849731445,4499.5078125,-2.69052704008171E-5,7.0738764715815E-8,1,4,13.4005146026611,5.00639291198388,32.990001142025,-0.0335175869470136,-0.00490611987789636,1,8.47613819267193E-8,,,,,,,,,,,,,,,,,,,,,200.084976196289,200.100723266602,4499.5078125,4499.5078125,53.4161021899768,5.64104241106956,5.12721967697144,54,1,0,0,1,0.302886962890625,33.7243423461914,1,1,3,200.100723266602,0,200.092849731445,,,,,,,,,,,,,,,,,,,,,,,,,,,,,,,,,
,3878516722.04321,200.45352935791,6499.90771484375,-3.96748962878105E-5,7.89636279643042E-9,1,4,13.4005146026611,5.00628018267102,32.990001142025,-0.0494140196352843,-0.007300834269938,1,7.16407616472264E-8,,,,,,,,,,,,,,,,,,,,,200.44059753418,200.466461181641,6499.90771484375,6499.90771484375,53.4715978148422,5.64147180056906,5.12226057052612,54,1,0,0,1,0.301666259765625,33.7243423461914,1,1,3,200.44059753418,0,200.45352935791,,,,,,,,,,,,,,,,,,,,,,,,,,,,,,,,,
,3878516810.9273,200.386962890625,8500.3447265625,-5.25676480094183E-5,1.01487352975732E-8,1,4,13.4005146026611,5.00631634592337,32.990001142025,-0.0654721937740931,-0.00967383645789126,1,9.45791224011857E-8,,,,,,,,,,,,,,,,,,,,,200.381958007813,200.391967773438,8500.3447265625,8500.3447265625,53.5247485541499,5.64099838108413,5.12997055053711,54,1,0,0,1,0.300750732421875,34.2131004333496,1,1,3,200.381958007813,0,200.386962890625,,,,,,,,,,,,,,,,,,,,,,,,,,,,,,,,,
,3878516904.10285,200.257102966309,10000.248046875,-6.22680780803869E-5,1.29651969244394E-8,1,4,13.4005146026611,5.00632976777336,32.990001142025,-0.0775512657104337,-0.0114787657778329,1,9.61698317459619E-8,,,,,,,,,,,,,,,,,,,,,200.255981445313,200.258224487305,10000.248046875,10000.248046875,53.4801957285537,5.64133211545596,5.12988710403442,54,1,0,0,1,0.302581787109375,34.2131004333496,1,1,3,200.255981445313,0,200.257102966309,,,,,,,,,,,,,,,,,,,,,,,,,,,,,,,,,
,3878517056.80738,200.21174621582,30000.205078125,-0.00019176846542882,3.44823432170391E-8,1,4,13.4005146026611,5.00623674108034,32.990001142025,-0.238815549746249,-0.0354487952200984,1,2.17237589986886E-7,,,,,,,,,,,,,,,,,,,,,200.197052001953,200.226440429687,30000.205078125,30000.205078125,53.4907477135634,5.64210117930383,5.12446451187134,54,1,0,0,1,0.2996826171875,33.7243423461914,1,1,3,200.226440429687,0,200.21174621582,,,,,,,,,,,,,,,,,,,,,,,,,,,,,,,,,
,3878517229.77323,200.185409545898,50000.26953125,-0.00032132273699373,8.28202241158138E-8,1,4,13.4005146026611,5.00619115483131,32.990001142025,-0.400122236254433,-0.0595728623706444,1,2.22283492174431E-7,,,,,,,,,,,,,,,,,,,,,200.182327270508,200.188491821289,50000.26953125,50000.26953125,53.4841038711499,5.64237105311766,5.1272931098938,54,1,0,0,1,0.30120849609375,34.2131004333496,1,1,3,200.188491821289,0,200.185409545898,,,,,,,,,,,,,,,,,,,,,,,,,,,,,,,,,
,3878517404.96066,200.049110412598,70000.2265625,-0.000451133634602966,1.48270435016439E-7,1,4,13.4005146026611,5.00620807008608,32.990001142025,-0.561761271361136,-0.0836979284791467,1,2.6559679708607E-7,,,,,,,,,,,,,,,,,,,,,200.047409057617,200.050811767578,70000.2265625,70000.2265625,53.1691075778999,5.64205476529109,5.12217569351196,52,1,68,0,0,0.300521850585937,34.2131004333496,1,1,3,200.047409057617,0,200.049110412598,,,,,,,,,,,,,,,,,,,,,,,,,,,,,,,,,