File: SQUID/22163_LCOT/LCOT_MT_FC+1T.dat
[Header]
; MPMS3 Data File (default extension .dat)
; Copyright (c) 2007, Quantum Design, Inc. All rights reserved.
TITLE,
FILEOPENTIME,3878452964.6842,11/24/2022,12:03 pm
BYAPP,SQUID AC,0.9.1.0
INFO,MPMS3 Measurement Release 1.1.16 Build 347, MultiVu Release 2.3.3.2,APPNAME
INFO,0,MOMENT_UNITS
INFO,LCOT,SAMPLE_MATERIAL
INFO,,SAMPLE_COMMENT
INFO,1.8,SAMPLE_MASS
INFO,,SAMPLE_VOLUME
INFO,,SAMPLE_MOLECULAR_WEIGHT
INFO,,SAMPLE_SIZE
INFO,,SAMPLE_SHAPE
INFO,Quartz,SAMPLE_HOLDER
INFO,Standard,SAMPLE_HOLDER_DETAIL
INFO,65.79,SAMPLE_OFFSET
DATATYPE,COMMENT,1
DATATYPE,TIME,2
STARTUPAXIS,X,2
STARTUPAXIS,Y1,5
FIELDGROUP, VSM,2,3,4,5,6,8,9,10,11,14,15
FIELDGROUP, DC, 2,3,4,14,56,57,58,59,60,61,62,63,64,65,66,67,68,69
FIELDGROUP, AC, 2,3,4,11,16,17,18,19,20,21,22,23,24,25,26,27,28,29,30
STARTUPGROUP, All
[Data]
Comment,Time Stamp (sec),Temperature (K),Magnetic Field (Oe),Moment (emu),M. Std. Err. (emu),Transport Action,Averaging Time (sec),Frequency (Hz),Peak Amplitude (mm),Center Position (mm),Lockin Signal' (V),Lockin Signal (V),Range,M. Quad. Signal (emu),AC Moment (emu),AC M. Std Err. (emu),AC Phase (deg),AC Phase Std. Err. (deg),AC Susceptibility (emu/Oe),AC Suscept. Std Err. (emu/Oe),AC X' (emu/Oe),AC X' Std Err. (emu/Oe),AC X'' (emu/Oe),AC X'' Std Err. (emu/Oe),AC Drive (Oe),AC Frequency (Hz),AC Averaging Time (sec),AC Cycles,AC Range,AC Measure Type,AC Signal' (V),AC Signal'' (V),AC Trim Coil Ratio,AC Trim Coil Phase,Min. Temperature (K),Max. Temperature (K),Min. Field (Oe),Max. Field (Oe),Mass (grams),Motor Lag (deg),Pressure (Torr),Measure Count,Measurement Number,SQUID Status (code),Motor Status (code),Measure Status (code),Motor Current (amps),Motor Temp. (C),Temp. Status (code),Field Status (code),Chamber Status (code),Chamber Temp (K),Redirection State,Average Temp (K),Rotation Angle (deg),Rotator state,DC Moment Fixed Ctr (emu),DC Moment Err Fixed Ctr (emu),DC Moment Free Ctr (emu),DC Moment Err Free Ctr (emu),DC Fixed Fit,DC Free Fit,DC Calculated Center (mm),DC Calculated Center Err (mm),DC Scan Length (mm),DC Scan Time (s),DC Number of Points,DC Squid Drift,DC Min V (V),DC Max V (V),DC Scans per Measure,Sample Resistance,He3 Temperature,Sorb Resistance,Sorb Temperature,Map 05,Map 06,Map 07,Map 08,Map 09,Map 10,Map 11,Map 12,Map 13,Map 14,Map 15,Map 16
,3878452990.46991,349.932830810547,10000.3740234375,-6.25094097549526E-5,1.68437366455859E-8,1,4,13.4005146026611,4.97747476299389,33.2299992442131,-0.0772279604404367,-0.0114023481541083,1,1.19167903584977E-7,,,,,,,,,,,,,,,,,,,,,349.932281494141,349.933380126953,10000.3740234375,10000.3740234375,53.4282174320249,5.63634643917669,5.56977367401123,54,1,0,0,1,0.296783447265625,32.7468223571777,1,1,4,349.933380126953,0,349.932830810547,,,,,,,,,,,,,,,,,,,,,,,,,,,,,,,,,
,3878453191.03358,343.116271972656,10000.3740234375,-6.24716370400436E-5,1.48994417117235E-8,1,4,13.4005146026611,4.98753099963393,33.2299992442131,-0.0773984526888741,-0.0114395252432463,1,1.09613275964491E-7,,,,,,,,,,,,,,,,,,,,,343.064819335937,343.167724609375,10000.3740234375,10000.3740234375,53.5298291395249,5.63598364546588,5.60824823379517,54,1,0,0,1,0.29571533203125,34.2131004333496,2,1,4,343.064819335937,0,343.116271972656,,,,,,,,,,,,,,,,,,,,,,,,,,,,,,,,,
,3878453372.41811,337.901123046875,10000.3740234375,-6.24624682133595E-5,1.65449743813864E-8,1,4,13.4005146026611,4.98739254483993,33.2099981606007,-0.0773835716026263,-0.0114408040171171,1,1.06849679996022E-7,,,,,,,,,,,,,,,,,,,,,337.859710693359,337.942535400391,10000.3740234375,10000.3740234375,53.4653447866883,5.63531664689832,5.61116123199463,54,1,0,0,1,0.293807983398438,33.7243423461914,2,1,4,337.859710693359,0,337.901123046875,,,,,,,,,,,,,,,,,,,,,,,,,,,,,,,,,
,3878453553.75774,333.741271972656,10000.3740234375,-6.24623855825967E-5,1.69217429378179E-8,1,4,13.4005146026611,4.98736646144297,33.2099981606007,-0.0773834042179318,-0.0114373459388774,1,1.09561602221594E-7,,,,,,,,,,,,,,,,,,,,,333.7021484375,333.780395507812,10000.3740234375,10000.3740234375,53.511460869323,5.63640791438774,5.61368846893311,53,1,64,0,0,0.296096801757812,33.7243423461914,2,1,4,333.698974609375,0,333.741271972656,,,,,,,,,,,,,,,,,,,,,,,,,,,,,,,,,
,3878453735.04573,330.090103149414,10000.3740234375,-6.24520415447207E-5,1.59870062928593E-8,1,4,13.4005146026611,4.98731181742778,33.2099981606007,-0.0773668816229885,-0.0114521140757061,1,9.59484522847509E-8,,,,,,,,,,,,,,,,,,,,,330.053466796875,330.126739501953,10000.3740234375,10000.3740234375,53.7154659128422,5.6369074914944,5.61396646499634,54,1,0,0,1,0.295944213867188,34.2131004333496,2,1,4,330.053466796875,0,330.090103149414,,,,,,,,,,,,,,,,,,,,,,,,,,,,,,,,,
,3878453916.37216,326.821792602539,10000.3740234375,-6.24379354659708E-5,2.14523325523547E-8,1,4,13.4005146026611,4.98722800073385,33.1900008022785,-0.0773483991634672,-0.0114438072644167,1,1.00327471123662E-7,,,,,,,,,,,,,,,,,,,,,326.780609130859,326.862976074219,10000.3740234375,10000.3740234375,53.5755544078999,5.63707891234112,5.61140584945679,54,1,0,0,1,0.295944213867188,34.2131004333496,2,1,4,326.780609130859,0,326.821792602539,,,,,,,,,,,,,,,,,,,,,,,,,,,,,,,,,
,3878454097.67459,323.790435791016,10000.3740234375,-6.24206947788328E-5,1.67471183614054E-8,1,4,13.4005146026611,4.98700820963634,33.1900008022785,-0.0773260538816326,-0.0114145952067968,1,1.2076526171921E-7,,,,,,,,,,,,,,,,,,,,,323.760559082031,323.8203125,10000.3740234375,10000.3740234375,53.5302199537845,5.63832215792782,5.60897588729858,54,1,0,0,1,0.296401977539063,34.2131004333496,2,1,4,323.757720947266,0,323.790435791016,,,,,,,,,,,,,,,,,,,,,,,,,,,,,,,,,
,3878454279.00825,320.957107543945,10000.3740234375,-6.23865629193978E-5,1.8831075075593E-8,1,4,13.4005146026611,4.98718107020548,33.1900008022785,-0.07728498606514,-0.0114259028190696,1,1.0697718984762E-7,,,,,,,,,,,,,,,,,,,,,320.926025390625,320.988189697266,10000.3740234375,10000.3740234375,53.5857155786499,5.63819731361238,5.60824537277222,54,1,0,0,1,0.298080444335937,33.7243423461914,2,1,4,320.9228515625,0,320.957107543945,,,,,,,,,,,,,,,,,,,,,,,,,,,,,,,,,
,3878454460.36098,318.264495849609,10000.3740234375,-6.24048334702397E-5,1.5159578777088E-8,1,4,13.4005146026611,4.98710195541596,33.1900008022785,-0.0773068062752283,-0.0114229364942916,1,1.11900280225709E-7,,,,,,,,,,,,,,,,,,,,,318.241485595703,318.287506103516,10000.3740234375,10000.3740234375,53.4399418598133,5.63830252971854,5.60570955276489,54,1,0,0,1,0.297088623046875,34.2131004333496,2,1,4,318.241485595703,0,318.264495849609,,,,,,,,,,,,,,,,,,,,,,,,,,,,,,,,,
,3878454641.6594,315.699935913086,10000.3740234375,-6.24320491342686E-5,1.30146947273641E-8,1,4,13.4005146026611,4.98711492685312,33.1699997186661,-0.0773412656647939,-0.0114248671156927,1,1.14446338779094E-7,,,,,,,,,,,,,,,,,,,,,315.666687011719,315.733184814453,10000.3740234375,10000.3740234375,53.4743335146595,5.63802771047406,5.60037994384766,54,1,0,0,1,0.295257568359375,34.2131004333496,2,1,4,315.666687011719,0,315.699935913086,,,,,,,,,,,,,,,,,,,,,,,,,,,,,,,,,
,3878454835.06789,313.064605712891,10000.3740234375,-6.24220996225909E-5,1.5982531503336E-8,1,4,13.4005146026611,4.98710888929894,33.1699997186661,-0.0773284990214167,-0.0114250981746292,1,1.12755722990979E-7,,,,,,,,,,,,,,,,,,,,,313.043273925781,313.0859375,10000.3740234375,10000.3740234375,53.541944381573,5.6381615150779,5.59375667572022,54,1,0,0,1,0.296630859375,34.2131004333496,2,1,4,313.043273925781,0,313.064605712891,,,,,,,,,,,,,,,,,,,,,,,,,,,,,,,,,
,3878455016.40876,310.700180053711,10000.3740234375,-6.24385206693065E-5,1.50306542972163E-8,1,4,13.4005146026611,4.98704752618033,33.1699997186661,-0.0773484530544655,-0.0114215808590664,1,1.17893137068236E-7,,,,,,,,,,,,,,,,,,,,,310.673217773438,310.727142333984,10000.3740234375,10000.3740234375,53.5583585804768,5.6380463539149,5.59318208694458,54,1,0,0,1,0.295333862304687,34.2131004333496,2,1,4,310.673217773438,0,310.700180053711,,,,,,,,,,,,,,,,,,,,,,,,,,,,,,,,,
,3878455209.83245,308.270645141602,10000.3740234375,-6.24447037540458E-5,1.51719877210525E-8,1,4,13.4005146026611,4.9870539234514,33.1699997186661,-0.0773522041683097,-0.0114497897728763,1,9.60570135296958E-8,,,,,,,,,,,,,,,,,,,,,308.244903564453,308.29638671875,10000.3740234375,10000.3740234375,53.5849339501307,5.63806593484587,5.59360980987549,54,1,0,0,1,0.296783447265625,34.2131004333496,2,1,4,308.244903564453,0,308.270645141602,,,,,,,,,,,,,,,,,,,,,,,,,,,,,,,,,
,3878455391.16499,306.078338623047,10000.3740234375,-6.24322202646553E-5,1.41515987623782E-8,1,4,13.4005146026611,4.98702050158286,33.1699997186661,-0.077333773201569,-0.0114623701639512,1,8.3944370348241E-8,,,,,,,,,,,,,,,,,,,,,306.0517578125,306.104919433594,10000.3740234375,10000.3740234375,53.401642062371,5.63802401974935,5.58524131774902,54,1,0,0,1,0.29571533203125,33.7243423461914,2,1,4,306.0517578125,0,306.078338623047,,,,,,,,,,,,,,,,,,,,,,,,,,,,,,,,,
,3878455572.48809,303.952423095703,10000.3740234375,-6.24600000196003E-5,1.98007473916796E-8,1,4,13.4005146026611,4.98705694923597,33.1499986350536,-0.0773710203076172,-0.0114539254872229,1,9.50136718201224E-8,,,,,,,,,,,,,,,,,,,,,303.928100585937,303.976745605469,10000.3740234375,10000.3740234375,53.5939226781018,5.63808349066645,5.58634614944458,53,1,68,0,0,0.2960205078125,34.2131004333496,2,1,4,303.928100585937,0,303.952423095703,,,,,,,,,,,,,,,,,,,,,,,,,,,,,,,,,
,3878455753.82129,301.914352416992,10000.3740234375,-6.24413342504595E-5,1.21586841970503E-8,1,4,13.4005146026611,4.98704378307081,33.1499986350536,-0.0773479903390322,-0.0114479318036774,1,9.70268404341505E-8,,,,,,,,,,,,,,,,,,,,,301.894592285156,301.934112548828,10000.3740234375,10000.3740234375,53.462609086871,5.63794531666079,5.58113718032837,54,1,0,0,1,0.297012329101562,34.2131004333496,2,1,4,301.894592285156,0,301.914352416992,,,,,,,,,,,,,,,,,,,,,,,,,,,,,,,,,
,3878455935.15089,299.933242797852,10000.3740234375,-6.24391351255275E-5,1.47435139451498E-8,1,4,13.4005146026611,4.98703794654909,33.1499986350536,-0.0773458655787977,-0.0114426546602867,1,1.00943813002653E-7,,,,,,,,,,,,,,,,,,,,,299.911041259766,299.955444335937,10000.3740234375,10000.3740234375,53.3977339197749,5.63838132522281,5.5831503868103,54,1,0,0,1,0.295791625976562,34.2131004333496,2,1,4,299.911041259766,0,299.933242797852,,,,,,,,,,,,,,,,,,,,,,,,,,,,,,,,,
,3878456116.47515,298.015274047852,10000.3740234375,-6.24674675302129E-5,1.42179715927253E-8,1,4,13.4005146026611,4.9869781054738,33.1499986350536,-0.077382419391711,-0.0114292080703176,1,1.158845477013E-7,,,,,,,,,,,,,,,,,,,,,297.997924804687,298.032623291016,10000.3740234375,10000.3740234375,53.531783210823,5.63716067668793,5.56983613967895,54,1,0,0,1,0.296707153320313,33.7243423461914,2,1,4,297.997924804687,0,298.015274047852,,,,,,,,,,,,,,,,,,,,,,,,,,,,,,,,,
,3878456297.94616,296.142593383789,10000.3740234375,-6.24364787845236E-5,1.59825281211082E-8,1,4,13.4005146026611,4.98707260764428,33.1499986350536,-0.0773470807368222,-0.0114171991736242,1,1.21190760230849E-7,,,,,,,,,,,,,,,,,,,,,296.117767333984,296.167419433594,10000.3740234375,10000.3740234375,53.4712070005826,5.63761948630693,5.57273435592651,54,1,0,0,1,0.294570922851562,33.7243423461914,2,1,4,296.116058349609,0,296.142593383789,,,,,,,,,,,,,,,,,,,,,,,,,,,,,,,,,
,3878456479.15757,294.301559448242,10000.3740234375,-6.24368304087889E-5,1.33650701234006E-8,1,4,13.4005146026611,4.98698263619942,33.1499986350536,-0.0773449184952238,-0.0114212593935877,1,1.17731575278058E-7,,,,,,,,,,,,,,,,,,,,,294.285247802734,294.31787109375,10000.3740234375,10000.3740234375,53.5376454247172,5.63796684408844,5.56461811065674,54,1,0,0,1,0.2972412109375,34.2131004333496,2,1,4,294.285247802734,0,294.301559448242,,,,,,,,,,,,,,,,,,,,,,,,,,,,,,,,,
,3878456660.54845,292.50471496582,10000.3740234375,-6.243394675677E-5,1.39909171125771E-8,1,4,13.4005146026611,4.98697883432072,33.1300012767315,-0.0773403403187887,-0.0114268917821326,1,1.12742295342241E-7,,,,,,,,,,,,,,,,,,,,,292.482666015625,292.526763916016,10000.3740234375,10000.3740234375,53.6373030609191,5.63791472943196,5.56180858612061,54,1,0,0,1,0.295181274414063,34.2131004333496,2,1,4,292.482666015625,0,292.50471496582,,,,,,,,,,,,,,,,,,,,,,,,,,,,,,,,,
,3878456841.84328,290.728424072266,10000.3740234375,-6.24657219706114E-5,1.82382938434141E-8,1,4,13.4005146026611,4.98700265840001,33.1300012767315,-0.0773811547421835,-0.0114265382118025,1,1.17842986049982E-7,,,,,,,,,,,,,,,,,,,,,290.712860107422,290.743988037109,10000.3740234375,10000.3740234375,53.5485882239864,5.63767610928461,5.56079864501953,54,1,0,0,1,0.297164916992188,33.7243423461914,2,1,4,290.712860107422,0,290.728424072266,,,,,,,,,,,,,,,,,,,,,,,,,,,,,,,,,
,3878457023.12511,288.97802734375,10000.3740234375,-6.2470566163749E-5,1.6350995016104E-8,1,4,13.4005146026611,4.98692844131243,33.1300012767315,-0.077386622861765,-0.0114199508224913,1,1.23694346305812E-7,,,,,,,,,,,,,,,,,,,,,288.958923339844,288.997131347656,10000.3740234375,10000.3740234375,53.5771176649383,5.63773791836247,5.55648946762085,54,1,0,0,1,0.295257568359375,34.2131004333496,2,1,4,288.958923339844,0,288.97802734375,,,,,,,,,,,,,,,,,,,,,,,,,,,,,,,,,
,3878457204.46178,287.250915527344,10000.3740234375,-6.24133080299229E-5,1.80774758883509E-8,1,4,13.4005146026611,4.9868387109641,33.1300012767315,-0.0773173493996067,-0.0113850833789156,1,1.43052076876085E-7,,,,,,,,,,,,,,,,,,,,,287.232635498047,287.269195556641,10000.3740234375,10000.3740234375,53.5732095223422,5.63872671571656,5.55011892318726,54,1,0,0,1,0.2972412109375,34.2131004333496,2,1,4,287.232635498047,0,287.250915527344,,,,,,,,,,,,,,,,,,,,,,,,,,,,,,,,,
,3878457385.78607,285.550750732422,10000.3740234375,-6.24112732965308E-5,1.83028018491601E-8,1,4,13.4005146026611,4.98682764223778,33.1300012767315,-0.0773110405901438,-0.011408391187175,1,1.23897676439771E-7,,,,,,,,,,,,,,,,,,,,,285.529083251953,285.572418212891,10000.3740234375,10000.3740234375,53.5102884265441,5.63849807441487,5.54850482940674,54,1,0,0,1,0.296249389648438,34.2131004333496,2,1,4,285.529083251953,0,285.550750732422,,,,,,,,,,,,,,,,,,,,,,,,,,,,,,,,,
,3878457567.14589,283.869354248047,10000.3740234375,-6.24180195128414E-5,1.49504512957383E-8,1,4,13.4005146026611,4.98688767953792,33.1300012767315,-0.0773223186268509,-0.011399015547785,1,1.3263324524166E-7,,,,,,,,,,,,,,,,,,,,,283.851318359375,283.887390136719,10000.3740234375,10000.3740234375,53.3735034356787,5.63829165539336,5.53920936584473,54,1,0,0,1,0.294876098632812,33.7243423461914,2,1,4,283.851318359375,0,283.869354248047,,,,,,,,,,,,,,,,,,,,,,,,,,,,,,,,,
,3878457748.44854,282.220001220703,10000.3740234375,-6.23936160591655E-5,1.84866467848394E-8,1,4,13.4005146026611,4.98681273804917,33.1300012767315,-0.0772906532078103,-0.0113930216362247,1,1.33628841217649E-7,,,,,,,,,,,,,,,,,,,,,282.202178955078,282.237823486328,10000.3740234375,10000.3740234375,53.4532295446403,5.63865949342531,5.53612232208252,54,1,0,0,1,0.2978515625,33.7243423461914,2,1,4,282.202178955078,0,282.220001220703,,,,,,,,,,,,,,,,,,,,,,,,,,,,,,,,,
,3878457929.78072,280.57829284668,10000.3740234375,-6.23810194682463E-5,1.33917688316809E-8,1,4,13.4005146026611,4.98626451201516,33.110000193119,-0.0772602640779453,-0.0114081575602189,1,1.18101402430994E-7,,,,,,,,,,,,,,,,,,,,,280.56201171875,280.594573974609,10000.3740234375,10000.3740234375,53.6208888620153,5.64132722909473,5.53221750259399,54,1,0,0,1,0.2978515625,34.2131004333496,2,1,4,280.56201171875,0,280.57829284668,,,,,,,,,,,,,,,,,,,,,,,,,,,,,,,,,
,3878458111.09514,278.973663330078,10000.3740234375,-6.24028642899771E-5,1.62502011007578E-8,1,4,13.4005146026611,4.98655096041931,33.110000193119,-0.0772895446399293,-0.0114398229953749,1,9.65392478227796E-8,,,,,,,,,,,,,,,,,,,,,278.954742431641,278.992584228516,10000.3740234375,10000.3740234375,53.6720855300249,5.63958891224112,5.52658414840698,54,1,0,0,1,0.296630859375,33.7243423461914,2,1,4,278.954742431641,0,278.973663330078,,,,,,,,,,,,,,,,,,,,,,,,,,,,,,,,,
,3878458292.43016,277.373580932617,10000.3740234375,-6.23959266484623E-5,1.52373895313591E-8,1,4,13.4005146026611,4.98656475237963,33.110000193119,-0.0772838154877113,-0.0114214574852508,1,1.10368772389761E-7,,,,,,,,,,,,,,,,,,,,,277.358551025391,277.388610839844,10000.3740234375,10000.3740234375,53.5528871808422,5.63890778404855,5.52459812164307,54,1,0,0,1,0.299148559570313,34.2131004333496,2,1,4,277.358551025391,0,277.373580932617,,,,,,,,,,,,,,,,,,,,,,,,,,,,,,,,,
,3878458473.8245,275.80876159668,10000.3740234375,-6.23574698908411E-5,2.09360161086106E-8,1,4,13.4005146026611,4.9865739353592,33.110000193119,-0.0772348601890563,-0.0114246224021212,1,1.02083800486471E-7,,,,,,,,,,,,,,,,,,,,,275.789916992187,275.827606201172,10000.3740234375,10000.3740234375,53.5950951208807,5.63891697947307,5.52164459228516,54,1,0,0,1,0.297470092773438,33.7243423461914,2,1,4,275.789916992187,0,275.80876159668,,,,,,,,,,,,,,,,,,,,,,,,,,,,,,,,,
,3878458655.10518,274.255325317383,10000.3740234375,-6.23521720040066E-5,1.58144226817521E-8,1,4,13.4005146026611,4.98651986986307,33.110000193119,-0.0772299001301182,-0.0114049203524619,1,1.17062049647981E-7,,,,,,,,,,,,,,,,,,,,,274.239288330078,274.271362304687,10000.3740234375,10000.3740234375,53.582589064573,5.639706772206,5.51891708374023,54,1,0,0,1,0.298843383789063,33.7243423461914,2,1,4,274.239288330078,0,274.255325317383,,,,,,,,,,,,,,,,,,,,,,,,,,,,,,,,,
,3878458836.42917,272.729843139648,10000.3740234375,-6.23358990241624E-5,1.5754351502605E-8,1,4,13.4005146026611,4.9864016328612,33.110000193119,-0.0772058278146805,-0.0114105818355704,1,1.09749135616566E-7,,,,,,,,,,,,,,,,,,,,,272.71044921875,272.749237060547,10000.3740234375,10000.3740234375,53.3496637658422,5.64005462406483,5.52009582519531,54,1,0,0,1,0.297012329101562,34.2131004333496,2,1,4,272.71044921875,0,272.729843139648,,,,,,,,,,,,,,,,,,,,,,,,,,,,,,,,,
,3878459017.79034,271.212799072266,10000.3740234375,-6.23173729749655E-5,1.75666439623362E-8,1,4,13.4005146026611,4.98649482812329,33.110000193119,-0.0771850026316984,-0.0114068410202828,1,1.10240346742606E-7,,,,,,,,,,,,,,,,,,,,,271.199951171875,271.225646972656,10000.3740234375,10000.3740234375,53.5384270532364,5.63980366204942,5.51522970199585,54,1,0,0,1,0.298538208007812,34.2131004333496,2,1,4,271.199951171875,0,271.212799072266,,,,,,,,,,,,,,,,,,,,,,,,,,,,,,,,,
,3878459199.09493,269.71076965332,10000.3740234375,-6.23095798386134E-5,1.36734819218682E-8,1,4,13.4005146026611,4.98647826906214,33.0899991095066,-0.0771779696750681,-0.0113854482408343,1,1.26308321116913E-7,,,,,,,,,,,,,,,,,,,,,269.694946289062,269.726593017578,10000.3740234375,10000.3740234375,53.432125574621,5.64027425644491,5.50763702392578,54,1,0,0,1,0.297470092773438,34.7018585205078,2,1,4,269.694946289062,0,269.71076965332,,,,,,,,,,,,,,,,,,,,,,,,,,,,,,,,,
,3878459380.44465,268.238861083984,10000.3740234375,-6.22843425207329E-5,1.37598967993888E-8,1,4,13.4005146026611,4.98649258687516,33.0899991095066,-0.0771474551069314,-0.0113779797887123,1,1.2860145446842E-7,,,,,,,,,,,,,,,,,,,,,268.222595214844,268.255126953125,10000.3740234375,10000.3740234375,53.5098976122845,5.64049062086397,5.50290107727051,54,1,0,0,1,0.297470092773438,33.7243423461914,2,1,4,268.222595214844,0,268.238861083984,,,,,,,,,,,,,,,,,,,,,,,,,,,,,,,,,
,3878459561.76121,266.775924682617,10000.3740234375,-6.2224012406777E-5,1.47024912834467E-8,1,4,13.4005146026611,4.98653340869881,33.0899991095066,-0.0770730114856367,-0.0113711110661845,1,1.25228992044202E-7,,,,,,,,,,,,,,,,,,,,,266.759124755859,266.792724609375,10000.3740234375,10000.3740234375,53.5501514810249,5.63960951515215,5.50075626373291,54,1,0,0,1,0.296478271484375,34.2131004333496,2,1,4,266.759124755859,0,266.775924682617,,,,,,,,,,,,,,,,,,,,,,,,,,,,,,,,,
,3878459743.08076,265.333023071289,10000.3740234375,-6.2207610234943E-5,1.81604308485848E-8,1,4,13.4005146026611,4.98657739430891,33.0899991095066,-0.0770500360074345,-0.0113924019372329,1,1.05695026899694E-7,,,,,,,,,,,,,,,,,,,,,265.317718505859,265.348327636719,10000.3740234375,10000.3740234375,53.5067710982076,5.63909645738455,5.49220037460327,54,1,0,0,1,0.297470092773438,34.2131004333496,2,1,4,265.317718505859,0,265.333023071289,,,,,,,,,,,,,,,,,,,,,,,,,,,,,,,,,
,3878459924.41049,263.905258178711,10000.3740234375,-6.21743639494355E-5,1.78295666304689E-8,1,4,13.4005146026611,4.98637030827123,33.0899991095066,-0.0770022440869071,-0.0113998758193299,1,9.41496698984643E-8,,,,,,,,,,,,,,,,,,,,,263.888488769531,263.922027587891,10000.3740234375,10000.3740234375,53.4637815296499,5.64120439541194,5.49021148681641,54,1,0,0,1,0.298080444335937,34.2131004333496,2,1,4,263.888488769531,0,263.905258178711,,,,,,,,,,,,,,,,,,,,,,,,,,,,,,,,,
,3878460105.73524,262.497894287109,10000.3740234375,-6.21858676805633E-5,1.99343707832832E-8,1,4,13.4005146026611,4.98650855980852,33.0899991095066,-0.0770227414393157,-0.0113806674321957,1,1.11740997931312E-7,,,,,,,,,,,,,,,,,,,,,262.484985351562,262.510803222656,10000.3740234375,10000.3740234375,53.384446234948,5.6402305925858,5.48843860626221,54,1,0,0,1,0.29632568359375,33.7243423461914,2,1,4,262.484985351562,0,262.497894287109,,,,,,,,,,,,,,,,,,,,,,,,,,,,,,,,,
,3878460287.06589,261.110427856445,10000.3740234375,-6.21788047576012E-5,1.54209194397335E-8,1,4,13.4005146026611,4.98657208555912,33.0899991095066,-0.0770166757647597,-0.011370845166919,1,1.1878083014348E-7,,,,,,,,,,,,,,,,,,,,,261.093109130859,261.127746582031,10000.3740234375,10000.3740234375,53.5059894696884,5.63970533380443,5.48783779144287,54,1,0,0,1,0.2978515625,33.7243423461914,2,1,4,261.093109130859,0,261.110427856445,,,,,,,,,,,,,,,,,,,,,,,,,,,,,,,,,
,3878460468.396,259.748733520508,10000.3740234375,-6.21645496011558E-5,1.56052607285693E-8,1,4,13.4005146026611,4.98656488027582,33.0899991095066,-0.0769972323128186,-0.0113791148879748,1,1.09951322571419E-7,,,,,,,,,,,,,,,,,,,,,259.732696533203,259.764770507813,10000.3740234375,10000.3740234375,53.5243577398903,5.63936872600892,5.47914743423462,54,1,0,0,1,0.298004150390625,33.7243423461914,2,1,4,259.732696533203,0,259.748733520508,,,,,,,,,,,,,,,,,,,,,,,,,,,,,,,,,
,3878460649.72474,258.390075683594,10000.3740234375,-6.21777254354477E-5,1.35118234371956E-8,1,4,13.4005146026611,4.98671738488484,33.0899991095066,-0.0770179430362322,-0.011374742540024,1,1.15847321018265E-7,,,,,,,,,,,,,,,,,,,,,258.374816894531,258.405334472656,10000.3740234375,10000.3740234375,53.6732579728038,5.63977445297895,5.47706460952759,54,1,0,0,1,0.296783447265625,34.2131004333496,2,1,4,258.374816894531,0,258.390075683594,,,,,,,,,,,,,,,,,,,,,,,,,,,,,,,,,
,3878460831.10505,257.064743041992,10000.3740234375,-6.21950185579989E-5,1.31857694541363E-8,1,4,13.4005146026611,4.9867804569806,33.0700017511845,-0.0770396966296458,-0.0113850163689735,1,1.10300815260427E-7,,,,,,,,,,,,,,,,,,,,,257.052795410156,257.076690673828,10000.3740234375,10000.3740234375,53.5653932371499,5.63819272426416,5.47606325149536,54,1,0,0,1,0.296630859375,34.2131004333496,2,1,4,257.052795410156,0,257.064743041992,,,,,,,,,,,,,,,,,,,,,,,,,,,,,,,,,
,3878461012.38441,255.752365112305,10000.3740234375,-6.21700433525013E-5,1.6787346589371E-8,1,4,13.4005146026611,4.98677374122998,33.0700017511845,-0.0770085488792318,-0.0113808644930794,1,1.09900066737739E-7,,,,,,,,,,,,,,,,,,,,,255.738189697266,255.766540527344,10000.3740234375,10000.3740234375,53.4078950905249,5.63886097558267,5.46981000900269,54,1,0,0,1,0.295257568359375,33.7243423461914,2,1,4,255.738189697266,0,255.752365112305,,,,,,,,,,,,,,,,,,,,,,,,,,,,,,,,,
,3878461193.72347,254.464546203613,10000.3740234375,-6.21603775741151E-5,1.34848831179904E-8,1,4,13.4005146026611,4.98673218773828,33.0700017511845,-0.0769910142836717,-0.0114101268321827,1,8.47163214503154E-8,,,,,,,,,,,,,,,,,,,,,254.452926635742,254.476165771484,10000.3740234375,10000.3740234375,53.4309531318422,5.63887645978857,5.46474504470825,54,1,0,0,1,0.296859741210937,34.2131004333496,2,1,4,254.452926635742,0,254.464546203613,,,,,,,,,,,,,,,,,,,,,,,,,,,,,,,,,
,3878461387.13781,253.120819091797,10000.3740234375,-6.21558570667032E-5,1.90542392717747E-8,1,4,13.4005146026611,4.98672874205144,33.0700017511845,-0.0769897211403971,-0.0113800033857219,1,1.08356957348899E-7,,,,,,,,,,,,,,,,,,,,,253.106307983398,253.135330200195,10000.3740234375,10000.3740234375,53.4465857022268,5.6393118494118,5.46685171127319,54,1,0,0,1,0.303497314453125,33.7243423461914,2,1,4,253.106307983398,0,253.120819091797,,,,,,,,,,,,,,,,,,,,,,,,,,,,,,,,,
,3878461568.5264,251.882675170898,10000.3740234375,-6.21426145400165E-5,1.5447660448555E-8,1,4,13.4005146026611,4.9867013631721,33.0700017511845,-0.0769740393150551,-0.0113687088855053,1,1.15425997029064E-7,,,,,,,,,,,,,,,,,,,,,251.868942260742,251.896408081055,10000.3740234375,10000.3740234375,53.5239669256307,5.63919254638619,5.45635366439819,54,1,0,0,1,0.297698974609375,34.2131004333496,2,1,4,251.868942260742,0,251.882675170898,,,,,,,,,,,,,,,,,,,,,,,,,,,,,,,,,
,3878461749.80539,250.662582397461,10000.3740234375,-6.21750359646404E-5,1.72141189255662E-8,1,4,13.4005146026611,4.98668519381068,33.0700017511845,-0.0770122199218963,-0.0113854749835965,1,1.06694880003467E-7,,,,,,,,,,,,,,,,,,,,,250.648422241211,250.676742553711,10000.3740234375,10000.3740234375,53.4735518861403,5.63931824579628,5.44983959197998,54,1,0,0,1,0.305328369140625,34.2131004333496,2,1,4,250.648422241211,0,250.662582397461,,,,,,,,,,,,,,,,,,,,,,,,,,,,,,,,,
,3878461931.14321,249.466484069824,10000.3740234375,-6.2144301930534E-5,1.80414316674096E-8,1,4,13.4005146026611,4.98672214875795,33.0700017511845,-0.0769738612506789,-0.0113872542430244,1,1.00755992033905E-7,,,,,,,,,,,,,,,,,,,,,249.453216552734,249.479751586914,10000.3740234375,10000.3740234375,53.4485397735249,5.63915795430195,5.45262098312378,54,1,0,0,1,0.296173095703125,34.2131004333496,2,1,4,249.45231628418,0,249.466484069824,,,,,,,,,,,,,,,,,,,,,,,,,,,,,,,,,
,3878462112.48314,248.301208496094,10000.3740234375,-6.21333322018436E-5,1.53897993079023E-8,1,4,13.4005146026611,4.98664085954512,33.0700017511845,-0.076960651154011,-0.0113707002571462,1,1.12273051575908E-7,,,,,,,,,,,,,,,,,,,,,248.287124633789,248.315292358398,10000.3740234375,10000.3740234375,53.5771176649383,5.64012519906194,5.44703006744385,54,1,0,0,1,0.297317504882812,34.2131004333496,2,1,4,248.287124633789,0,248.301208496094,,,,,,,,,,,,,,,,,,,,,,,,,,,,,,,,,
,3878462293.83288,247.149124145508,10000.3740234375,-6.21171172854023E-5,1.56727145864221E-8,1,4,13.4005146026611,4.98669925973169,33.0700017511845,-0.0769421875246519,-0.0113655326250823,1,1.14171303679465E-7,,,,,,,,,,,,,,,,,,,,,247.137496948242,247.160751342773,10000.3740234375,10000.3740234375,53.5302199537845,5.63933807238424,5.44351720809937,54,1,0,0,1,0.2972412109375,33.7243423461914,2,1,4,247.137496948242,0,247.149124145508,,,,,,,,,,,,,,,,,,,,,,,,,,,,,,,,,
,3878462475.12505,246.026504516602,10000.3740234375,-6.21338166482813E-5,1.40768449843338E-8,1,4,13.4005146026611,4.98665944537874,33.0700017511845,-0.0769597942137189,-0.0113832771597573,1,1.02237003720271E-7,,,,,,,,,,,,,,,,,,,,,246.014175415039,246.038833618164,10000.3740234375,10000.3740234375,53.445413259448,5.63994617275668,5.43249607086182,54,1,0,0,1,0.29632568359375,33.7243423461914,2,1,4,246.014175415039,0,246.026504516602,,,,,,,,,,,,,,,,,,,,,,,,,,,,,,,,,
,3878462656.47163,244.922386169434,10000.3740234375,-6.21175412559064E-5,1.19765115420282E-8,1,4,13.4005146026611,4.9866890983008,33.0700017511845,-0.0769416345538626,-0.0113713148955738,1,1.09539047509211E-7,,,,,,,,,,,,,,,,,,,,,244.912857055664,244.931915283203,10000.3740234375,10000.3740234375,53.4141481186787,5.63938228918325,5.42679262161255,54,1,0,0,1,0.29632568359375,33.7243423461914,2,1,4,244.912857055664,0,244.922386169434,,,,,,,,,,,,,,,,,,,,,,,,,,,,,,,,,
,3878462837.77147,243.833587646484,10000.3740234375,-6.21270578242732E-5,1.7451233946234E-8,1,4,13.4005146026611,4.98661111709671,33.0700017511845,-0.0769511903725701,-0.0113764452668594,1,1.06618170932825E-7,,,,,,,,,,,,,,,,,,,,,243.821716308594,243.845458984375,10000.3740234375,10000.3740234375,53.6650508733518,5.63961941208291,5.42298650741577,54,1,0,0,1,0.297088623046875,33.7243423461914,2,1,4,243.821716308594,0,243.833587646484,,,,,,,,,,,,,,,,,,,,,,,,,,,,,,,,,
,3878463019.17644,242.76789855957,10000.3740234375,-6.21342046652485E-5,1.34724542707196E-8,1,4,13.4005146026611,4.98657517642126,33.050000667572,-0.0769594576169193,-0.011376348735719,1,1.07672384807113E-7,,,,,,,,,,,,,,,,,,,,,242.7578125,242.777984619141,10000.3740234375,10000.3740234375,53.5907961640249,5.63934018362865,5.41625261306763,54,1,0,0,1,0.296096801757812,33.7243423461914,2,1,4,242.757141113281,0,242.76789855957,,,,,,,,,,,,,,,,,,,,,,,,,,,,,,,,,
,3878463200.46037,241.730819702148,10000.3740234375,-6.21363051688263E-5,1.56479144715327E-8,1,4,13.4005146026611,4.98660326949013,33.050000667572,-0.0769603194354027,-0.0113925186799929,1,9.50009022111959E-8,,,,,,,,,,,,,,,,,,,,,241.719833374023,241.741806030273,10000.3740234375,10000.3740234375,53.4618274583518,5.63987709504191,5.41260671615601,54,1,0,0,1,0.296554565429687,33.7243423461914,2,1,4,241.719833374023,0,241.730819702148,,,,,,,,,,,,,,,,,,,,,,,,,,,,,,,,,
,3878463381.75464,240.711601257324,10000.3740234375,-6.21128352722651E-5,1.47334432858156E-8,1,4,13.4005146026611,4.98663306219119,33.050000667572,-0.0769333860852015,-0.0113783425347384,1,1.03015110880687E-7,,,,,,,,,,,,,,,,,,,,,240.69921875,240.723983764648,10000.3740234375,10000.3740234375,53.5642207943711,5.63994273244696,5.4021463394165,54,1,0,0,1,0.296554565429687,34.2131004333496,2,1,4,240.69921875,0,240.711601257324,,,,,,,,,,,,,,,,,,,,,,,,,,,,,,,,,
,3878463563.12117,239.712936401367,10000.3740234375,-6.21230049525416E-5,1.91800083595536E-8,1,4,13.4005146026611,4.98659308437496,33.050000667572,-0.0769459184176499,-0.0113747215375245,1,1.07357321396221E-7,,,,,,,,,,,,,,,,,,,,,239.701965332031,239.723907470703,10000.3740234375,10000.3740234375,53.6802926294768,5.64042027625845,5.39385175704956,54,1,0,0,1,0.296783447265625,34.2131004333496,2,1,4,239.701965332031,0,239.712936401367,,,,,,,,,,,,,,,,,,,,,,,,,,,,,,,,,
,3878463744.46024,238.728492736816,10000.3740234375,-6.21270331036882E-5,1.49991088397468E-8,1,4,13.4005146026611,4.98659687196859,33.050000667572,-0.0769485784799487,-0.0113915895207896,1,9.4347663320632E-8,,,,,,,,,,,,,,,,,,,,,238.716812133789,238.740173339844,10000.3740234375,10000.3740234375,53.5294383252653,5.64008048721908,5.37877416610718,54,1,0,0,1,0.296401977539063,33.7243423461914,2,1,4,238.716812133789,0,238.728492736816,,,,,,,,,,,,,,,,,,,,,,,,,,,,,,,,,
,3878463925.78809,237.76798248291,10000.3740234375,-6.20874640921497E-5,1.3716501586344E-8,1,4,13.4005146026611,4.98657959253072,33.050000667572,-0.0768993067818912,-0.0113835372379835,1,9.48864667578976E-8,,,,,,,,,,,,,,,,,,,,,237.758056640625,237.777908325195,10000.3740234375,10000.3740234375,53.6978792711595,5.64063447334228,5.3727650642395,54,1,0,0,1,0.296783447265625,33.7243423461914,2,1,4,237.757019042969,0,237.76798248291,,,,,,,,,,,,,,,,,,,,,,,,,,,,,,,,,
,3878464107.08341,236.820671081543,10000.3740234375,-6.20924660977969E-5,1.5723014238635E-8,1,4,13.4005146026611,4.98654383901863,33.050000667572,-0.0769061763048535,-0.0113746633906949,1,1.02708629543575E-7,,,,,,,,,,,,,,,,,,,,,236.808700561523,236.832641601562,10000.3740234375,10000.3740234375,53.4309531318422,5.64009834126117,5.36283588409424,54,1,0,0,1,0.296249389648438,33.7243423461914,2,1,4,236.808700561523,0,236.820671081543,,,,,,,,,,,,,,,,,,,,,,,,,,,,,,,,,
,3878464288.44309,235.898048400879,10000.3740234375,-6.20817166476538E-5,1.39218398112092E-8,1,4,13.4005146026611,4.98654090091368,33.050000667572,-0.0768917346629995,-0.0113797980866561,1,9.69463100777974E-8,,,,,,,,,,,,,,,,,,,,,235.887634277344,235.908462524414,10000.3740234375,10000.3740234375,53.5157598261787,5.64036972688215,5.3543872833252,54,1,0,0,1,0.296249389648438,34.2131004333496,2,1,4,235.887634277344,0,235.898048400879,,,,,,,,,,,,,,,,,,,,,,,,,,,,,,,,,
,3878464469.74026,234.9873046875,10000.3740234375,-6.20775480279423E-5,1.86621135096445E-8,1,4,13.4005146026611,4.98649909847124,33.050000667572,-0.076885721027277,-0.0113785433262177,1,9.72279932740215E-8,,,,,,,,,,,,,,,,,,,,,234.976837158203,234.997772216797,10000.3740234375,10000.3740234375,53.5415535673134,5.64069072380001,5.34527778625488,54,1,0,0,1,0.29632568359375,33.7243423461914,2,1,4,234.976837158203,0,234.9873046875,,,,,,,,,,,,,,,,,,,,,,,,,,,,,,,,,
,3878464651.09819,234.100975036621,10000.3740234375,-6.20624022031896E-5,1.58577317489267E-8,1,4,13.4005146026611,4.98644401801742,33.050000667572,-0.0768674253449586,-0.0113645352432424,1,1.06132868630182E-7,,,,,,,,,,,,,,,,,,,,,234.092239379883,234.109710693359,10000.3740234375,10000.3740234375,53.4790232857749,5.64058186934721,5.33543968200684,54,1,0,0,1,0.296783447265625,34.2131004333496,2,1,4,234.092239379883,0,234.100975036621,,,,,,,,,,,,,,,,,,,,,,,,,,,,,,,,,
,3878464832.42717,233.223533630371,10000.3740234375,-6.20643248388172E-5,2.24921606836083E-8,1,4,13.4005146026611,4.98648813453921,33.050000667572,-0.0768668012992166,-0.0113914942251226,1,8.47625085859562E-8,,,,,,,,,,,,,,,,,,,,,233.214416503906,233.232650756836,10000.3740234375,10000.3740234375,53.4688621150249,5.64075306102349,5.3363184928894,52,1,32,0,0,0.296173095703125,34.2131004333496,2,1,4,233.214416503906,0,233.223533630371,,,,,,,,,,,,,,,,,,,,,,,,,,,,,,,,,
,3878465013.77777,232.368324279785,10000.3740234375,-6.20727377526986E-5,1.21404235651576E-8,1,4,13.4005146026611,4.98619732953016,33.050000667572,-0.0768731209954043,-0.011377479320972,1,9.65877662089869E-8,,,,,,,,,,,,,,,,,,,,,232.360885620117,232.375762939453,10000.3740234375,10000.3740234375,53.435252088698,5.64209585810407,5.32593822479248,54,1,0,0,1,0.295867919921875,34.2131004333496,2,1,4,232.360885620117,0,232.368324279785,,,,,,,,,,,,,,,,,,,,,,,,,,,,,,,,,
,3878465195.07852,231.528564453125,10000.3740234375,-6.20877069464601E-5,1.44326184721691E-8,1,4,13.4005146026611,4.98629010110149,33.050000667572,-0.0768947598365833,-0.0113732071199131,1,1.02517235672451E-7,,,,,,,,,,,,,,,,,,,,,231.518798828125,231.538330078125,10000.3740234375,10000.3740234375,53.5427260100922,5.64101532200319,5.31670904159546,54,1,0,0,1,0.296249389648438,33.7243423461914,2,1,4,231.518798828125,0,231.528564453125,,,,,,,,,,,,,,,,,,,,,,,,,,,,,,,,,
,3878465376.42624,230.704635620117,10000.3740234375,-6.20571495266247E-5,1.49151582252959E-8,1,4,13.4005146026611,4.98617563327139,33.050000667572,-0.0768540651511853,-0.0113697516914636,1,1.00441103471739E-7,,,,,,,,,,,,,,,,,,,,,230.695770263672,230.713500976562,10000.3740234375,10000.3740234375,53.6799018152172,5.64219172167958,5.31701946258545,54,1,0,0,1,0.297317504882812,34.2131004333496,2,1,4,230.695770263672,0,230.704635620117,,,,,,,,,,,,,,,,,,,,,,,,,,,,,,,,,
,3878465557.75526,229.896659851074,10000.3740234375,-6.20582606919559E-5,1.35604175124827E-8,1,4,13.4005146026611,4.98605695055686,33.050000667572,-0.0768547536753549,-0.011357020772942,1,1.10583389142216E-7,,,,,,,,,,,,,,,,,,,,,229.887725830078,229.90559387207,10000.3740234375,10000.3740234375,53.6009573347749,5.64360215598893,5.30242729187012,54,1,0,0,1,0.298309326171875,34.2131004333496,2,1,4,229.887725830078,0,229.896659851074,,,,,,,,,,,,,,,,,,,,,,,,,,,,,,,,,
,3878465739.10401,229.102584838867,10000.3740234375,-6.2060366641644E-5,1.59233476256129E-8,1,4,13.4005146026611,4.9862423088908,33.050000667572,-0.0768598822418095,-0.0113679377507264,1,1.02559609900314E-7,,,,,,,,,,,,,,,,,,,,,229.095489501953,229.109680175781,10000.3740234375,10000.3740234375,53.5188863402557,5.64141987793128,5.2984938621521,54,1,0,0,1,0.29632568359375,34.2131004333496,2,1,4,229.095489501953,0,229.102584838867,,,,,,,,,,,,,,,,,,,,,,,,,,,,,,,,,
,3878465920.38736,228.324234008789,10000.3740234375,-6.20444674716615E-5,1.62496440531853E-8,1,4,13.4005146026611,4.98628899447246,33.050000667572,-0.0768416108788352,-0.0113624322880447,1,1.04748171581576E-7,,,,,,,,,,,,,,,,,,,,,228.314010620117,228.334457397461,10000.3740234375,10000.3740234375,53.6263602616499,5.6415554622942,5.29515504837036,54,1,0,0,1,0.297698974609375,34.7018585205078,2,1,4,228.314010620117,0,228.324234008789,,,,,,,,,,,,,,,,,,,,,,,,,,,,,,,,,
,3878466101.77824,227.558609008789,10000.3740234375,-6.20439444251324E-5,1.42942604055701E-8,1,4,13.4005146026611,4.98636171722946,33.050000667572,-0.0768423289164168,-0.0113639456449252,1,1.03635414267567E-7,,,,,,,,,,,,,,,,,,,,,227.552093505859,227.565124511719,10000.3740234375,10000.3740234375,53.6240153760922,5.64143127971001,5.29135942459106,54,1,0,0,1,0.296630859375,33.7243423461914,2,1,4,227.552093505859,0,227.558609008789,,,,,,,,,,,,,,,,,,,,,,,,,,,,,,,,,
,3878466283.04966,226.806427001953,10000.3740234375,-6.20457491972346E-5,1.70135467302499E-8,1,4,13.4005146026611,4.98635521132752,33.0299995839596,-0.0768453279778691,-0.0113582094259028,1,1.08521299846166E-7,,,,,,,,,,,,,,,,,,,,,226.798416137695,226.814437866211,10000.3740234375,10000.3740234375,53.6404295749961,5.64128759963902,5.28082799911499,54,1,0,0,1,0.296783447265625,33.7243423461914,2,1,4,226.798416137695,0,226.806427001953,,,,,,,,,,,,,,,,,,,,,,,,,,,,,,,,,
,3878466464.40314,226.073081970215,10000.3740234375,-6.20379852015386E-5,1.47142200227584E-8,1,4,13.4005146026611,4.98595899337382,33.0299995839596,-0.076826070176644,-0.0113627350320722,1,1.02682055492671E-7,,,,,,,,,,,,,,,,,,,,,226.065887451172,226.080276489258,10000.3740234375,10000.3740234375,53.5763360364191,5.64307639203956,5.27707099914551,54,1,0,0,1,0.296478271484375,34.2131004333496,2,1,4,226.065887451172,0,226.073081970215,,,,,,,,,,,,,,,,,,,,,,,,,,,,,,,,,
,3878466645.69527,225.356941223145,10000.3740234375,-6.20605024230996E-5,1.46014997166235E-8,1,4,13.4005146026611,4.98618023525386,33.0299995839596,-0.0768599897360983,-0.0113591988789879,1,1.0947766691313E-7,,,,,,,,,,,,,,,,,,,,,225.349273681641,225.364608764648,10000.3740234375,10000.3740234375,53.6713039015057,5.64228113121446,5.27449512481689,54,1,0,0,1,0.29754638671875,34.2131004333496,2,1,4,225.349273681641,0,225.356941223145,,,,,,,,,,,,,,,,,,,,,,,,,,,,,,,,,
,3878466827.03688,224.652725219727,10000.3740234375,-6.20329417221802E-5,1.28000979541131E-8,1,4,13.4005146026611,4.98626290463691,33.0299995839596,-0.0768274645079021,-0.0113556124913178,1,1.08464608983961E-7,,,,,,,,,,,,,,,,,,,,,224.645645141602,224.659805297852,10000.3740234375,10000.3740234375,53.4172746327557,5.64180909689324,5.26781415939331,54,1,0,0,1,0.297622680664063,34.2131004333496,2,1,4,224.645645141602,0,224.652725219727,,,,,,,,,,,,,,,,,,,,,,,,,,,,,,,,,
,3878467008.35599,223.961456298828,10000.3740234375,-6.2023110366216E-5,1.50859464481362E-8,1,4,13.4005146026611,4.98635907814829,33.0299995839596,-0.0768150771897228,-0.0113694225829441,1,9.60886636030007E-8,,,,,,,,,,,,,,,,,,,,,223.952697753906,223.97021484375,10000.3740234375,10000.3740234375,53.4215735896114,5.64151445290569,5.27041912078857,54,1,0,0,1,0.29693603515625,33.7243423461914,2,1,4,223.952697753906,0,223.961456298828,,,,,,,,,,,,,,,,,,,,,,,,,,,,,,,,,
,3878467189.76248,223.279724121094,10000.3740234375,-6.20185234751206E-5,1.64173321798172E-8,1,4,13.4005146026611,4.98618979104525,33.0299995839596,-0.0768064507681104,-0.0113632829634802,1,9.99239842826707E-8,,,,,,,,,,,,,,,,,,,,,223.27392578125,223.285522460938,10000.3740234375,10000.3740234375,53.6036930345922,5.64255659300744,5.26267004013062,54,1,0,0,1,0.295333862304687,33.7243423461914,2,1,4,223.27392578125,0,223.279724121094,,,,,,,,,,,,,,,,,,,,,,,,,,,,,,,,,
,3878467371.06516,222.6142578125,10000.3740234375,-6.20175128435857E-5,1.62477187172477E-8,1,4,13.4005146026611,4.98626637828637,33.0299995839596,-0.0768057801854513,-0.0113705190899818,1,9.41263056297655E-8,,,,,,,,,,,,,,,,,,,,,222.606216430664,222.622299194336,10000.3740234375,10000.3740234375,53.442286745371,5.64160006011654,5.25696229934692,54,1,0,0,1,0.296707153320313,33.7243423461914,2,1,4,222.606216430664,0,222.6142578125,,,,,,,,,,,,,,,,,,,,,,,,,,,,,,,,,
,3878467552.36842,221.960624694824,10000.3740234375,-6.20135663962504E-5,1.99602933887853E-8,1,4,13.4005146026611,4.98623302539841,33.0299995839596,-0.0768050671960839,-0.0113369669449618,1,1.20548172831955E-7,,,,,,,,,,,,,,,,,,,,,221.955001831055,221.966247558594,10000.3740234375,10000.3740234375,53.6513723742653,5.64240220843446,5.252037525177,54,1,0,0,1,0.297470092773438,34.2131004333496,2,1,4,221.955001831055,0,221.960624694824,,,,,,,,,,,,,,,,,,,,,,,,,,,,,,,,,
,3878467733.67327,221.317848205566,10000.3740234375,-6.20192492232346E-5,1.23600550987328E-8,1,4,13.4005146026611,4.98631019243647,33.0299995839596,-0.0768103651767987,-0.0113610306578605,1,1.02162393903781E-7,,,,,,,,,,,,,,,,,,,,,221.310287475586,221.325408935547,10000.3740234375,10000.3740234375,53.2867426700441,5.64106719157262,5.24907350540161,54,1,0,0,1,0.297012329101562,34.2131004333496,2,1,4,221.310287475586,0,221.317848205566,,,,,,,,,,,,,,,,,,,,,,,,,,,,,,,,,
,3878467915.0233,220.692375183105,10000.3740234375,-6.19883089661133E-5,1.77853795637192E-8,1,4,13.4005146026611,4.98630163101886,33.0299995839596,-0.0767719551316798,-0.0113547064694663,1,1.02619457609405E-7,,,,,,,,,,,,,,,,,,,,,220.686630249023,220.698120117187,10000.3740234375,10000.3740234375,53.5657840514095,5.64157621845641,5.25010442733765,54,1,0,0,1,0.297927856445313,33.7243423461914,2,1,4,220.686630249023,0,220.692375183105,,,,,,,,,,,,,,,,,,,,,,,,,,,,,,,,,
,3878468096.34861,220.075157165527,10000.3740234375,-6.20140381266014E-5,1.95741102000349E-8,1,4,13.4005146026611,4.98630368501891,33.0299995839596,-0.0768052640877542,-0.0113500722870494,1,1.10216401905338E-7,,,,,,,,,,,,,,,,,,,,,220.067504882813,220.082809448242,10000.3740234375,10000.3740234375,53.2922140696787,5.64192660424368,5.2358341217041,54,1,0,0,1,0.297775268554687,33.7243423461914,2,1,4,220.067504882813,0,220.075157165527,,,,,,,,,,,,,,,,,,,,,,,,,,,,,,,,,
,3878468277.73416,219.469909667969,10000.3740234375,-6.20069363695439E-5,1.5813376998976E-8,1,4,13.4005146026611,4.98625709018564,33.0299995839596,-0.0767958943811701,-0.0113457332441311,1,1.12538287354966E-7,,,,,,,,,,,,,,,,,,,,,219.464263916016,219.475555419922,10000.3740234375,10000.3740234375,53.5806349932749,5.64180158830305,5.23615598678589,54,1,0,0,1,0.298233032226562,33.7243423461914,2,1,4,219.464263916016,0,219.469909667969,,,,,,,,,,,,,,,,,,,,,,,,,,,,,,,,,
,3878468459.00651,218.87899017334,10000.3740234375,-6.19932701062242E-5,1.35674874988798E-8,1,4,13.4005146026611,4.98626725085371,33.0299995839596,-0.0767784780409987,-0.0113480115087484,1,1.08680064512466E-7,,,,,,,,,,,,,,,,,,,,,218.872985839844,218.884994506836,10000.3740234375,10000.3740234375,53.5095067980249,5.64136713497851,5.23644733428955,54,1,0,0,1,0.298309326171875,33.7243423461914,2,1,4,218.872985839844,0,218.87899017334,,,,,,,,,,,,,,,,,,,,,,,,,,,,,,,,,
,3878468640.34613,218.298400878906,10000.3740234375,-6.19814791485007E-5,1.62188832286725E-8,1,4,13.4005146026611,4.98618514685808,33.0299995839596,-0.076762295654625,-0.0113442978967541,1,1.0970388450937E-7,,,,,,,,,,,,,,,,,,,,,218.292053222656,218.304748535156,10000.3740234375,10000.3740234375,53.5591402089961,5.64201643081745,5.22884225845337,54,1,0,0,1,0.297775268554687,34.2131004333496,2,1,4,218.292053222656,0,218.298400878906,,,,,,,,,,,,,,,,,,,,,,,,,,,,,,,,,
,3878468821.68646,217.727600097656,10000.3740234375,-6.19845162185861E-5,1.4696181970726E-8,1,4,13.4005146026611,4.98631553563317,33.0299995839596,-0.076768392540489,-0.0113484779894795,1,1.07118265325652E-7,,,,,,,,,,,,,,,,,,,,,217.721145629883,217.73405456543,10000.3740234375,10000.3740234375,53.5231852971114,5.64141005800966,5.22497844696045,54,1,0,0,1,0.298080444335937,33.7243423461914,2,1,4,217.721145629883,0,217.727600097656,,,,,,,,,,,,,,,,,,,,,,,,,,,,,,,,,
,3878469003.00164,217.171058654785,10000.3740234375,-6.19580916845009E-5,1.56168386291897E-8,1,4,13.4005146026611,4.98633681882433,33.0299995839596,-0.0767344861570401,-0.0113546624104053,1,9.82254838114953E-8,,,,,,,,,,,,,,,,,,,,,217.164947509766,217.177169799805,10000.3740234375,10000.3740234375,53.6267510759095,5.64115465750904,5.22374248504639,54,1,0,0,1,0.298004150390625,34.2131004333496,2,1,4,217.164947509766,0,217.171058654785,,,,,,,,,,,,,,,,,,,,,,,,,,,,,,,,,
,3878469184.33108,216.623207092285,10000.3740234375,-6.195159045255E-5,1.48051560453476E-8,1,4,13.4005146026611,4.98633768889381,33.0299995839596,-0.0767257614416337,-0.0113580981408934,1,9.44803982760174E-8,,,,,,,,,,,,,,,,,,,,,216.617294311523,216.629119873047,10000.3740234375,10000.3740234375,53.5485882239864,5.64125587116859,5.22218465805054,54,1,0,0,1,0.298004150390625,34.2131004333496,2,1,4,216.617294311523,0,216.623207092285,,,,,,,,,,,,,,,,,,,,,,,,,,,,,,,,,
,3878469365.68048,216.085716247559,10000.3740234375,-6.19378605475221E-5,1.85349177598979E-8,1,4,13.4005146026611,4.98626103499072,33.0299995839596,-0.0767098917432463,-0.0113366964447667,1,1.09513649210363E-7,,,,,,,,,,,,,,,,,,,,,216.080856323242,216.090576171875,10000.3740234375,10000.3740234375,53.3269965387845,5.64125719050294,5.21430492401123,54,1,0,0,1,0.300064086914063,33.7243423461914,2,1,4,216.080856323242,0,216.085716247559,,,,,,,,,,,,,,,,,,,,,,,,,,,,,,,,,
,3878469547.05782,215.557502746582,10000.3740234375,-6.19673021869659E-5,1.44407805343365E-8,1,4,13.4005146026611,4.9862896807882,33.0299995839596,-0.0767476608612119,-0.0113375819023641,1,1.13276581701777E-7,,,,,,,,,,,,,,,,,,,,,215.551513671875,215.563491821289,10000.3740234375,10000.3740234375,53.5001272557941,5.64202543311132,5.21460676193237,54,1,0,0,1,0.29754638671875,33.7243423461914,2,1,4,215.551513671875,0,215.557502746582,,,,,,,,,,,,,,,,,,,,,,,,,,,,,,,,,
,3878469728.38723,215.040184020996,10000.3740234375,-6.19678568126752E-5,1.69355285855218E-8,1,4,13.4005146026611,4.98617083451159,33.0299995839596,-0.0767412418478141,-0.011367655549501,1,8.87640463805422E-8,,,,,,,,,,,,,,,,,,,,,215.034957885742,215.04541015625,10000.3740234375,10000.3740234375,53.5349097248999,5.64185648693607,5.20993661880493,54,1,0,0,1,0.2984619140625,33.7243423461914,2,1,4,215.034957885742,0,215.040184020996,,,,,,,,,,,,,,,,,,,,,,,,,,,,,,,,,
,3878469909.63589,214.532958984375,10000.3740234375,-6.19734123986164E-5,1.27713913289903E-8,1,4,13.4005146026611,4.98614758713288,33.0299995839596,-0.0767500378575327,-0.0113524378007559,1,1.01825997448587E-7,,,,,,,,,,,,,,,,,,,,,214.527465820313,214.538452148438,10000.3740234375,10000.3740234375,53.5607034660345,5.64249645247109,5.19968748092651,54,1,0,0,1,0.29754638671875,33.7243423461914,2,1,4,214.527465820313,0,214.532958984375,,,,,,,,,,,,,,,,,,,,,,,,,,,,,,,,,
,3878470090.96621,214.037384033203,10000.3740234375,-6.1951902135689E-5,1.65318670117994E-8,1,4,13.4005146026611,4.98615275185113,33.0299995839596,-0.0767225548870331,-0.0113549004214887,1,9.66325349175384E-8,,,,,,,,,,,,,,,,,,,,,214.031997680664,214.042770385742,10000.3740234375,10000.3740234375,53.4227460323903,5.64136942996134,5.19837427139282,54,1,0,0,1,0.298614501953125,34.2131004333496,2,1,4,214.031997680664,0,214.037384033203,,,,,,,,,,,,,,,,,,,,,,,,,,,,,,,,,
,3878470272.34496,213.549468994141,10000.3740234375,-6.19485641604024E-5,1.9329715505635E-8,1,4,13.4005146026611,4.98618368443512,33.0299995839596,-0.0767188798564843,-0.0113557827396748,1,9.55003758076856E-8,,,,,,,,,,,,,,,,,,,,,213.543365478516,213.555572509766,10000.3740234375,10000.3740234375,53.6201072334961,5.64162338220723,5.19415140151978,54,1,0,0,1,0.299148559570313,33.7243423461914,2,1,4,213.543365478516,0,213.549468994141,,,,,,,,,,,,,,,,,,,,,,,,,,,,,,,,,
,3878470453.65915,213.069000244141,10000.3740234375,-6.19446161935213E-5,1.5958802507072E-8,1,4,13.4005146026611,4.98615588592517,33.0299995839596,-0.0767143910698143,-0.0113482832258588,1,1.00895180653455E-7,,,,,,,,,,,,,,,,,,,,,213.064102172852,213.07389831543,10000.3740234375,10000.3740234375,53.3230883961883,5.6412323523082,5.19183015823364,54,1,0,0,1,0.296859741210937,34.7018585205078,2,1,4,213.064102172852,0,213.069000244141,,,,,,,,,,,,,,,,,,,,,,,,,,,,,,,,,
,3878470634.96835,212.613075256348,10000.3740234375,-6.19230862785257E-5,1.70239512764315E-8,1,4,13.4005146026611,4.98607781749769,33.0299995839596,-0.0766854409198942,-0.0113481187740759,1,9.76059842072722E-8,,,,,,,,,,,,,,,,,,,,,212.597702026367,212.628448486328,10000.3740234375,10000.3740234375,53.6877181004095,5.64145930537102,5.19507169723511,54,1,0,0,1,0.298309326171875,34.7018585205078,2,1,3,212.596343994141,0,212.613075256348,,,,,,,,,,,,,,,,,,,,,,,,,,,,,,,,,
,3878470816.29736,192.358955383301,10000.3740234375,-6.19246659102843E-5,1.34189729112355E-8,1,4,13.4005146026611,4.98604463396414,32.990001142025,-0.0766850559626776,-0.0113591673639458,1,8.8832865897875E-8,,,,,,,,,,,,,,,,,,,,,191.957626342773,192.760284423828,10000.3740234375,10000.3740234375,53.4782416572557,5.64211400189994,5.16898584365845,54,1,0,0,1,0.29815673828125,34.2131004333496,2,1,3,191.957626342773,0,192.358955383301,,,,,,,,,,,,,,,,,,,,,,,,,,,,,,,,,
,3878470997.61572,160.578659057617,10000.3740234375,-6.18269434128017E-5,1.32446691204509E-8,1,4,13.4005146026611,4.98615202313466,32.9700000584126,-0.0765674865883709,-0.0113340074652583,1,9.48121767404058E-8,,,,,,,,,,,,,,,,,,,,,160.211395263672,160.945922851562,10000.3740234375,10000.3740234375,53.4407234883326,5.64178630394263,5.14574384689331,54,1,0,0,1,0.297317504882812,33.7243423461914,2,1,3,160.211395263672,0,160.578659057617,,,,,,,,,,,,,,,,,,,,,,,,,,,,,,,,,
,3878471179.55418,130.315254211426,10000.3740234375,-6.16806535191774E-5,1.38252518710877E-8,1,4,13.4005146026611,4.98609184767738,32.930001616478,-0.0763840590220275,-0.0113134615196547,1,8.93677470802272E-8,,,,,,,,,,,,,,,,,,,,,130.079330444336,130.551177978516,10000.3740234375,10000.3740234375,53.6095552484864,5.6405830581407,5.10555553436279,53,1,64,0,0,0.297470092773438,33.7243423461914,2,1,3,130.079330444336,0,130.315254211426,,,,,,,,,,,,,,,,,,,,,,,,,,,,,,,,,
,3878471372.38457,98.3182563781738,10000.3740234375,-6.14963882934467E-5,1.84553182392653E-8,1,4,13.4005146026611,4.98598183100969,32.9199992120266,-0.0761540531332804,-0.0112756967495298,1,9.2022876342726E-8,,,,,,,,,,,,,,,,,,,,,98.0517120361328,98.5848007202148,10000.3740234375,10000.3740234375,53.3289506100826,5.64149702672737,5.05914402008057,54,1,0,0,1,0.296707153320313,33.7243423461914,2,1,3,98.0517120361328,0,98.3182563781738,,,,,,,,,,,,,,,,,,,,,,,,,,,,,,,,,
,3878471553.81542,67.7894325256348,10000.3740234375,-6.12816864904265E-5,1.98404658866011E-8,1,4,13.4005146026611,4.98613284252011,32.9000018537045,-0.0758910902892798,-0.0112388835506806,1,9.0024688571966E-8,,,,,,,,,,,,,,,,,,,,,67.5087509155273,68.0701141357422,10000.3740234375,10000.3740234375,53.4946558561595,5.6416174312426,4.95496940612793,54,1,0,0,1,0.298004150390625,33.7243423461914,2,1,3,67.5087509155273,0,67.7894325256348,,,,,,,,,,,,,,,,,,,,,,,,,,,,,,,,,
,3878471759.21445,32.7604389190674,10000.3740234375,-6.0455826974791E-5,3.84575269701804E-8,1,4,13.4005146026611,4.98605265003854,32.880000770092,-0.074857954287513,-0.0111453625760807,1,4.18124575949364E-8,,,,,,,,,,,,,,,,,,,,,32.4603080749512,33.0605697631836,10000.3740234375,10000.3740234375,53.4997364415345,5.64154155794922,4.67784786224365,54,1,0,0,1,0.298690795898438,34.2131004333496,2,1,3,32.4603080749512,0,32.7604389190674,,,,,,,,,,,,,,,,,,,,,,,,,,,,,,,,,
,3878471996.94952,2.50198483467102,10000.3740234375,-5.40790414811984E-5,2.04428241415306E-8,1,4,13.4005146026611,4.98632461087494,32.8599996864796,-0.0669694801103398,-0.00995513913848436,1,4.9832226132436E-8,,,,,,,,,,,,,,,,,,,,,2.48398041725159,2.51998925209045,10000.3740234375,10000.3740234375,53.6814650722557,5.64179686342453,2.23114347457886,54,1,0,0,1,0.296401977539063,33.7243423461914,6,1,3,2.48398041725159,0,2.50198483467102,,,,,,,,,,,,,,,,,,,,,,,,,,,,,,,,,
,3878472178.28949,2.34815800189972,10000.3740234375,-5.36606981221549E-5,2.06136220968591E-8,1,4,13.4005146026611,4.986307744593,32.8599996864796,-0.0664522094406183,-0.00987069166360652,1,5.54150494088537E-8,,,,,,,,,,,,,,,,,,,,,2.34318566322327,2.35313034057617,10000.3740234375,10000.3740234375,53.7338341830442,5.64178572678438,2.15203285217285,54,1,0,0,1,0.298080444335937,33.7243423461914,6,1,3,2.35313034057617,0,2.34815800189972,,,,,,,,,,,,,,,,,,,,,,,,,,,,,,,,,
,3878472359.60284,2.00001990795135,10000.3740234375,-5.27737874925996E-5,1.86221620034471E-8,1,4,13.4005146026611,4.98641003402481,32.8599996864796,-0.0653544823755275,-0.00971636378618749,1,4.76047129667519E-8,,,,,,,,,,,,,,,,,,,,,1.99945402145386,2.00058579444885,10000.3740234375,10000.3740234375,53.5732095223422,5.64131071422283,1.96743142604828,54,1,0,0,1,0.299148559570313,33.7243423461914,5,1,3,2.00058579444885,0,2.00001990795135,,,,,,,,,,,,,,,,,,,,,,,,,,,,,,,,,
,3878472387.83702,1.99991691112518,10000.3740234375,-5.2754922229069E-5,2.5102976030309E-8,1,4,13.4005146026611,4.98639150643383,32.8599996864796,-0.0653312322040099,-0.00970981288007466,1,5.00322962350874E-8,,,,,,,,,,,,,,,,,,,,,1.99985468387604,1.99997913837433,10000.3740234375,10000.3740234375,53.6408203892557,5.64249964726113,1.96594989299774,54,1,0,0,1,0.296554565429687,34.2131004333496,1,1,3,1.99985468387604,0,1.99991691112518,,,,,,,,,,,,,,,,,,,,,,,,,,,,,,,,,