File: SQUID/22129_LCOT/22129_lcot.rso.dat
[Header]
TITLE,MPMS RSO Measurement
BYAPP,MPMS Measurement,1.1,Summary
FILEOPENTIME, 1662036831.132000 9/1/2022, 2:53:51 PM

INFO, APPNAME, MPMS MultiVu Application, Revision 1.61,  Build 082

INFO, NAME,
INFO, WEIGHT, 9.700
INFO, AREA, 1.000
INFO, LENGTH, 1.000
INFO, SHAPE,
INFO, COMMENT,
INFO, SEQUENCE FILE: MT-350K^-0.5T.seq


INFO, BACKGROUND DATA FILE:, None


STARTUPAXIS,X,4,LINEAR,AUTO,0.000000,0.000000
STARTUPAXIS,Y1,5,LINEAR,AUTO,0.000000,0.000000


STARTUPGROUP,Longitudinal
FIELDGROUP,Longitudinal,1,2,3,4,5,6,7,8,9,10,11,19,20,21,22,23,35
FIELDGROUP,Transverse,1,2,3,4,12,13,14,15,16,17,18,24,25,26,27,28,35

PLOT_APPEARANCE,ALL,HORZ_GRID_ON,VERT_GRID_ON,MARKERS_AND_LINES

[Data]
Time,Comment,Field (Oe),Temperature (K),Long Moment (emu),Long Scan Std Dev,Long Offset (cm),Long Offset Std Dev,Long Algorithm,Long Reg Fit,Long Reg Factor,Trans Moment (emu),Trans Scan Std Dev,Trans Offset (cm),Trans Offset Std Dev,Trans Algorithm,Trans Reg Fit,Trans Reg Factor,Long Moment [w/o ABS] (emu),Long Scan Std Dev [w/o ABS],Long Offset [w/o ABS] (cm),Long Offset Std Dev [w/o ABS],Long Reg Fit [w/o ABS],Trans Moment [w/o ABS] (emu),Trans Scan Std Dev [w/o ABS],Trans Offset [w/o ABS] (cm),Trans Offset Std Dev [w/o ABS],Trans Reg Fit [w/o ABS],RSO Position (deg),Amplitude (cm),Frequency,Cycles to Average,Scans per Measurement,Delta Temp (K),Error,EC Comp. Running,Using ABS,
1662036831.132,,5.000000e+003,1.999879e+000,1.257725e-003,0.000000e+000,-1.005503e-002,0.000000e+000,3,7.005988e-001,1.825000e+000,,,,,,,,,,,,,,,,,,0,4.000000e+000,5.000000e-001,1,1,3.778934e-004,0,,0,
1662036959.263,,5.000000e+003,7.406426e+000,7.219322e-004,0.000000e+000,-5.386828e-003,0.000000e+000,3,6.997674e-001,1.825000e+000,,,,,,,,,,,,,,,,,,0,4.000000e+000,5.000000e-001,1,1,5.782671e-001,0,,0,
1662037025.943,,5.000000e+003,1.250564e+001,4.418057e-004,0.000000e+000,1.911714e-003,0.000000e+000,3,6.781360e-001,1.825000e+000,,,,,,,,,,,,,,,,,,0,4.000000e+000,5.000000e-001,1,1,4.620304e-001,0,,0,
1662037086.544,,5.000000e+003,1.737194e+001,3.233188e-004,0.000000e+000,8.168817e-003,0.000000e+000,3,6.567121e-001,1.825000e+000,,,,,,,,,,,,,,,,,,0,4.000000e+000,5.000000e-001,1,1,6.559601e-001,0,,0,
1662037156.604,,5.000000e+003,2.321251e+001,2.403397e-004,0.000000e+000,1.709501e-002,0.000000e+000,3,6.230021e-001,1.825000e+000,,,,,,,,,,,,,,,,,,0,4.000000e+000,5.000000e-001,1,1,5.164013e-001,0,,0,
1662037221.964,,5.000000e+003,2.851894e+001,1.873845e-004,0.000000e+000,2.708955e-002,0.000000e+000,3,5.806239e-001,1.825000e+000,,,,,,,,,,,,,,,,,,0,4.000000e+000,5.000000e-001,1,1,5.721912e-001,0,,0,
1662037268.824,,5.000000e+003,3.242274e+001,1.571459e-004,0.000000e+000,3.594742e-002,0.000000e+000,3,5.361927e-001,1.825000e+000,,,,,,,,,,,,,,,,,,0,4.000000e+000,5.000000e-001,1,1,4.774094e-001,0,,0,
1662037329.434,,5.000000e+003,3.745527e+001,1.361357e-004,0.000000e+000,4.599345e-002,0.000000e+000,3,4.950616e-001,1.825000e+000,,,,,,,,,,,,,,,,,,0,4.000000e+000,5.000000e-001,1,1,5.978699e-001,0,,0,
1662037389.324,,5.000000e+003,4.233646e+001,1.202770e-004,0.000000e+000,6.182748e-002,0.000000e+000,3,4.660181e-001,1.825000e+000,,,,,,,,,,,,,,,,,,0,4.000000e+000,5.000000e-001,1,1,4.713287e-001,0,,0,
1662037465.264,,5.000000e+003,4.862559e+001,9.862045e-005,0.000000e+000,1.321702e-001,0.000000e+000,3,3.945716e-001,1.825000e+000,,,,,,,,,,,,,,,,,,0,4.000000e+000,5.000000e-001,1,1,5.529518e-001,0,,0,
1662037511.425,,5.000000e+003,5.245799e+001,8.757272e-005,0.000000e+000,1.787443e-001,0.000000e+000,3,3.560752e-001,1.825000e+000,,,,,,,,,,,,,,,,,,0,4.000000e+000,5.000000e-001,1,1,5.430183e-001,0,,0,
1662037587.085,,5.000000e+003,5.872759e+001,7.005921e-005,0.000000e+000,2.735175e-001,0.000000e+000,3,2.635398e-001,1.825000e+000,,,,,,,,,,,,,,,,,,0,4.000000e+000,5.000000e-001,1,1,6.107903e-001,0,,0,
1662037635.095,,5.000000e+003,6.269138e+001,5.863732e-005,0.000000e+000,3.733408e-001,0.000000e+000,3,1.216343e-001,1.825000e+000,,,,,,,,,,,,,,,,,,0,4.000000e+000,5.000000e-001,1,1,6.926880e-001,0,,0,
1662037706.445,,5.000000e+003,6.866550e+001,6.991538e-006,0.000000e+000,-1.012081e+000,0.000000e+000,3,0.000000e+000,1.825000e+000,,,,,,,,,,,,,,,,,,0,4.000000e+000,5.000000e-001,1,1,6.831741e-001,0,,0,
1662037761.276,,5.000000e+003,7.331502e+001,-4.469164e-006,0.000000e+000,-1.821587e+000,0.000000e+000,3,0.000000e+000,1.825000e+000,,,,,,,,,,,,,,,,,,0,4.000000e+000,5.000000e-001,1,1,6.746597e-001,0,,0,
1662037810.226,,5.000000e+003,7.740428e+001,2.025019e-006,0.000000e+000,0.000000e+000,0.000000e+000,3,0.000000e+000,1.825000e+000,,,,,,,,,,,,,,,,,,0,4.000000e+000,5.000000e-001,1,1,6.596832e-001,0,,0,
1662037869.577,,5.000000e+003,8.236310e+001,-9.253558e-005,0.000000e+000,1.011698e+000,0.000000e+000,3,8.712569e-001,1.825000e+000,,,,,,,,,,,,,,,,,,0,4.000000e+000,5.000000e-001,1,1,6.531906e-001,0,,0,
1662037945.957,,5.000000e+003,8.873711e+001,-8.711025e-005,0.000000e+000,1.012484e+000,0.000000e+000,3,8.313065e-001,1.825000e+000,,,,,,,,,,,,,,,,,,0,4.000000e+000,5.000000e-001,1,1,5.386581e-001,0,,0,
1662037993.427,,5.000000e+003,9.274258e+001,-5.776413e-006,0.000000e+000,0.000000e+000,0.000000e+000,3,0.000000e+000,1.825000e+000,,,,,,,,,,,,,,,,,,0,4.000000e+000,5.000000e-001,1,1,6.218262e-001,0,,0,
1662038049.637,,5.000000e+003,9.745290e+001,-7.645785e-006,0.000000e+000,0.000000e+000,0.000000e+000,3,0.000000e+000,1.825000e+000,,,,,,,,,,,,,,,,,,0,4.000000e+000,5.000000e-001,1,1,6.186066e-001,0,,0,
1662038109.267,,5.000000e+003,1.024408e+002,-9.424111e-006,0.000000e+000,0.000000e+000,0.000000e+000,3,0.000000e+000,1.825000e+000,,,,,,,,,,,,,,,,,,0,4.000000e+000,5.000000e-001,1,1,6.113968e-001,0,,0,
1662038184.063,,5.000000e+003,1.086917e+002,-1.145768e-005,0.000000e+000,0.000000e+000,0.000000e+000,3,0.000000e+000,1.825000e+000,,,,,,,,,,,,,,,,,,0,4.000000e+000,5.000000e-001,1,1,5.105972e-001,0,,0,
1662038232.305,,5.000000e+003,1.127667e+002,6.568976e-007,0.000000e+000,0.000000e+000,0.000000e+000,3,0.000000e+000,1.825000e+000,,,,,,,,,,,,,,,,,,0,4.000000e+000,5.000000e-001,1,1,6.737976e-001,0,,0,
1662038289.394,,5.000000e+003,1.175291e+002,-7.025706e-005,0.000000e+000,1.033483e+000,0.000000e+000,3,6.128179e-001,1.825000e+000,,,,,,,,,,,,,,,,,,0,4.000000e+000,5.000000e-001,1,1,5.900955e-001,0,,0,
1662038349.024,,5.000000e+003,1.225377e+002,-6.811482e-005,0.000000e+000,1.038741e+000,0.000000e+000,3,5.757002e-001,1.825000e+000,,,,,,,,,,,,,,,,,,0,4.000000e+000,5.000000e-001,1,1,5.876007e-001,0,,0,
1662038424.134,,5.000000e+003,1.287677e+002,-6.555147e-005,0.000000e+000,1.046110e+000,0.000000e+000,3,5.276469e-001,1.825000e+000,,,,,,,,,,,,,,,,,,0,4.000000e+000,5.000000e-001,1,1,6.300964e-001,0,,0,
1662038471.394,,5.000000e+003,1.327736e+002,-6.413760e-005,0.000000e+000,1.050047e+000,0.000000e+000,3,4.993150e-001,1.825000e+000,,,,,,,,,,,,,,,,,,0,4.000000e+000,5.000000e-001,1,1,5.415955e-001,0,,0,
1662038527.614,,5.000000e+003,1.374536e+002,-6.245219e-005,0.000000e+000,1.056358e+000,0.000000e+000,3,4.649342e-001,1.825000e+000,,,,,,,,,,,,,,,,,,0,4.000000e+000,5.000000e-001,1,1,6.262970e-001,0,,0,
1662038587.514,,5.000000e+003,1.424257e+002,-6.078018e-005,0.000000e+000,1.062366e+000,0.000000e+000,3,4.282793e-001,1.825000e+000,,,,,,,,,,,,,,,,,,0,4.000000e+000,5.000000e-001,1,1,5.139008e-001,0,,0,
1662038663.974,,5.000000e+003,1.488255e+002,-5.864263e-005,0.000000e+000,1.069733e+000,0.000000e+000,3,3.811082e-001,1.825000e+000,,,,,,,,,,,,,,,,,,0,4.000000e+000,5.000000e-001,1,1,6.046143e-001,0,,0,
1662038710.134,,5.000000e+003,1.527048e+002,-5.769901e-005,0.000000e+000,1.074275e+000,0.000000e+000,3,3.562415e-001,1.825000e+000,,,,,,,,,,,,,,,,,,0,4.000000e+000,5.000000e-001,1,1,5.997925e-001,0,,0,
1662038766.785,,5.000000e+003,1.574287e+002,-5.627021e-005,0.000000e+000,1.079214e+000,0.000000e+000,3,3.221139e-001,1.825000e+000,,,,,,,,,,,,,,,,,,0,4.000000e+000,5.000000e-001,1,1,5.984955e-001,0,,0,
1662038826.495,,5.000000e+003,1.623934e+002,-5.491047e-005,0.000000e+000,1.084138e+000,0.000000e+000,3,2.875000e-001,1.825000e+000,,,,,,,,,,,,,,,,,,0,4.000000e+000,5.000000e-001,1,1,6.810913e-001,0,,0,
1662038905.595,,5.000000e+003,1.690052e+002,-5.321056e-005,0.000000e+000,1.090263e+000,0.000000e+000,3,2.404610e-001,1.825000e+000,,,,,,,,,,,,,,,,,,0,4.000000e+000,5.000000e-001,1,1,5.605011e-001,0,,0,
1662038950.545,,5.000000e+003,1.727880e+002,-5.234647e-005,0.000000e+000,1.093475e+000,0.000000e+000,3,2.157114e-001,1.825000e+000,,,,,,,,,,,,,,,,,,0,4.000000e+000,5.000000e-001,1,1,5.460052e-001,0,,0,
1662039005.686,,5.000000e+003,1.773795e+002,-5.137733e-005,0.000000e+000,1.097067e+000,0.000000e+000,3,1.862770e-001,1.825000e+000,,,,,,,,,,,,,,,,,,0,4.000000e+000,5.000000e-001,1,1,6.363983e-001,0,,0,
1662039065.836,,5.000000e+003,1.823700e+002,-5.015450e-005,0.000000e+000,1.100978e+000,0.000000e+000,3,1.497395e-001,1.825000e+000,,,,,,,,,,,,,,,,,,0,4.000000e+000,5.000000e-001,1,1,5.372009e-001,0,,0,
1662039144.737,,5.000000e+003,1.890016e+002,-4.884091e-005,0.000000e+000,1.106074e+000,0.000000e+000,3,1.101526e-001,1.825000e+000,,,,,,,,,,,,,,,,,,0,4.000000e+000,5.000000e-001,1,1,6.219025e-001,0,,0,
1662039191.377,,5.000000e+003,1.928806e+002,-4.812630e-005,0.000000e+000,1.108106e+000,0.000000e+000,3,8.555562e-002,1.825000e+000,,,,,,,,,,,,,,,,,,0,4.000000e+000,5.000000e-001,1,1,6.175079e-001,0,,0,
1662039246.607,,5.000000e+003,1.974485e+002,-4.747976e-005,0.000000e+000,1.110905e+000,0.000000e+000,3,6.065414e-002,1.825000e+000,,,,,,,,,,,,,,,,,,0,4.000000e+000,5.000000e-001,1,1,6.154938e-001,0,,0,
1662039307.117,,5.000000e+003,2.024699e+002,-4.680986e-005,0.000000e+000,1.113881e+000,0.000000e+000,3,3.698602e-002,1.825000e+000,,,,,,,,,,,,,,,,,,0,4.000000e+000,5.000000e-001,1,1,5.182953e-001,0,,0,
1662039386.467,,5.000000e+003,2.091669e+002,-4.569646e-005,0.000000e+000,1.116919e+000,0.000000e+000,3,0.000000e+000,1.825000e+000,,,,,,,,,,,,,,,,,,0,4.000000e+000,5.000000e-001,1,1,6.090088e-001,0,,0,
1662039433.167,,5.000000e+003,2.130565e+002,-4.509978e-005,0.000000e+000,1.118200e+000,0.000000e+000,3,0.000000e+000,1.825000e+000,,,,,,,,,,,,,,,,,,0,4.000000e+000,5.000000e-001,1,1,6.020966e-001,0,,0,
1662039486.108,,5.000000e+003,2.174373e+002,-4.438977e-005,0.000000e+000,1.120558e+000,0.000000e+000,3,0.000000e+000,1.825000e+000,,,,,,,,,,,,,,,,,,0,4.000000e+000,5.000000e-001,1,1,5.960999e-001,0,,0,
1662039544.214,,5.000000e+003,2.222960e+002,-4.371226e-005,0.000000e+000,1.123045e+000,0.000000e+000,3,0.000000e+000,1.825000e+000,,,,,,,,,,,,,,,,,,0,4.000000e+000,5.000000e-001,1,1,5.904083e-001,0,,0,
1662039625.434,,5.000000e+003,2.291024e+002,-4.256969e-005,0.000000e+000,1.125274e+000,0.000000e+000,3,0.000000e+000,1.825000e+000,,,,,,,,,,,,,,,,,,0,4.000000e+000,5.000000e-001,1,1,6.735992e-001,0,,0,
1662039671.364,,5.000000e+003,2.328577e+002,-4.200002e-005,0.000000e+000,1.126124e+000,0.000000e+000,3,0.000000e+000,1.825000e+000,,,,,,,,,,,,,,,,,,0,4.000000e+000,5.000000e-001,1,1,6.544037e-001,0,,0,
1662039725.274,,5.000000e+003,2.374090e+002,-4.133949e-005,0.000000e+000,1.127939e+000,0.000000e+000,3,0.000000e+000,1.825000e+000,,,,,,,,,,,,,,,,,,0,4.000000e+000,5.000000e-001,1,1,5.845947e-001,0,,0,
1662039786.124,,5.000000e+003,2.423980e+002,-4.065940e-005,0.000000e+000,1.129698e+000,0.000000e+000,3,0.000000e+000,1.825000e+000,,,,,,,,,,,,,,,,,,0,4.000000e+000,5.000000e-001,1,1,5.865936e-001,0,,0,
1662039864.724,,5.000000e+003,2.490623e+002,-6.891649e-005,0.000000e+000,-5.913934e-001,0.000000e+000,3,0.000000e+000,1.825000e+000,,,,,,,,,,,,,,,,,,0,4.000000e+000,5.000000e-001,1,1,6.654968e-001,0,,0,
1662039911.484,,5.000000e+003,2.529165e+002,-3.920979e-005,0.000000e+000,1.133973e+000,0.000000e+000,3,0.000000e+000,1.825000e+000,,,,,,,,,,,,,,,,,,0,4.000000e+000,5.000000e-001,1,1,6.514893e-001,0,,0,
1662039965.114,,5.000000e+003,2.573743e+002,-3.878888e-005,0.000000e+000,1.136192e+000,0.000000e+000,3,0.000000e+000,1.825000e+000,,,,,,,,,,,,,,,,,,0,4.000000e+000,5.000000e-001,1,1,7.420959e-001,0,,0,
1662040025.096,,5.000000e+003,2.623597e+002,-3.840175e-005,0.000000e+000,1.137823e+000,0.000000e+000,3,0.000000e+000,1.825000e+000,,,,,,,,,,,,,,,,,,0,4.000000e+000,5.000000e-001,1,1,5.382080e-001,0,,0,
1662040085.786,,5.000000e+003,2.673869e+002,-3.756812e-005,0.000000e+000,1.135588e+000,0.000000e+000,3,0.000000e+000,1.825000e+000,,,,,,,,,,,,,,,,,,0,4.000000e+000,5.000000e-001,1,1,6.343994e-001,0,,0,
1662040152.136,,5.000000e+003,2.729888e+002,-1.430235e-005,0.000000e+000,1.753264e+000,0.000000e+000,3,0.000000e+000,1.825000e+000,,,,,,,,,,,,,,,,,,0,4.000000e+000,5.000000e-001,1,1,5.260925e-001,0,,0,
1662040206.506,,5.000000e+003,2.775248e+002,-3.719538e-005,0.000000e+000,1.122100e+000,0.000000e+000,3,0.000000e+000,1.825000e+000,,,,,,,,,,,,,,,,,,0,4.000000e+000,5.000000e-001,1,1,5.354004e-001,0,,0,
1662040264.756,,5.000000e+003,2.823785e+002,-3.735339e-005,0.000000e+000,1.103323e+000,0.000000e+000,3,0.000000e+000,1.825000e+000,,,,,,,,,,,,,,,,,,0,4.000000e+000,5.000000e-001,1,1,7.081909e-001,0,,0,
1662040324.917,,5.000000e+003,2.873839e+002,-1.250838e-005,0.000000e+000,1.908009e+000,0.000000e+000,3,0.000000e+000,1.825000e+000,,,,,,,,,,,,,,,,,,0,4.000000e+000,5.000000e-001,1,1,7.012024e-001,0,,0,
1662040390.657,,5.000000e+003,2.928627e+002,-2.979136e-005,0.000000e+000,0.000000e+000,0.000000e+000,3,0.000000e+000,1.825000e+000,,,,,,,,,,,,,,,,,,0,4.000000e+000,5.000000e-001,1,1,5.175781e-001,0,,0,
1662040445.777,,5.000000e+003,2.974310e+002,-2.984235e-005,0.000000e+000,0.000000e+000,0.000000e+000,3,0.000000e+000,1.825000e+000,,,,,,,,,,,,,,,,,,0,4.000000e+000,5.000000e-001,1,1,6.538086e-001,0,,0,
1662040506.647,,5.000000e+003,3.025285e+002,-3.017076e-005,0.000000e+000,0.000000e+000,0.000000e+000,3,0.000000e+000,1.825000e+000,,,,,,,,,,,,,,,,,,0,4.000000e+000,5.000000e-001,1,1,6.112061e-001,0,,0,
1662040564.427,,5.000000e+003,3.073461e+002,-1.475287e-005,0.000000e+000,1.863483e+000,0.000000e+000,3,0.000000e+000,1.825000e+000,,,,,,,,,,,,,,,,,,0,4.000000e+000,5.000000e-001,1,1,5.909119e-001,0,,0,
1662040632.887,,5.000000e+003,3.130395e+002,-1.458801e-005,0.000000e+000,1.840028e+000,0.000000e+000,3,0.000000e+000,1.825000e+000,,,,,,,,,,,,,,,,,,0,4.000000e+000,5.000000e-001,1,1,5.130005e-001,0,,0,
1662040685.937,,5.000000e+003,3.174529e+002,-2.950354e-005,0.000000e+000,0.000000e+000,0.000000e+000,3,0.000000e+000,1.825000e+000,,,,,,,,,,,,,,,,,,0,4.000000e+000,5.000000e-001,1,1,5.745239e-001,0,,0,
1662040745.768,,5.000000e+003,3.224872e+002,-1.368902e-005,0.000000e+000,1.907579e+000,0.000000e+000,3,0.000000e+000,1.825000e+000,,,,,,,,,,,,,,,,,,0,4.000000e+000,5.000000e-001,1,1,6.653748e-001,0,,0,
1662040804.459,,5.000000e+003,3.273734e+002,-2.968989e-005,0.000000e+000,0.000000e+000,0.000000e+000,3,0.000000e+000,1.825000e+000,,,,,,,,,,,,,,,,,,0,4.000000e+000,5.000000e-001,1,1,5.745239e-001,0,,0,
1662040873.309,,5.000000e+003,3.330677e+002,-1.423713e-005,0.000000e+000,1.888101e+000,0.000000e+000,3,0.000000e+000,1.825000e+000,,,,,,,,,,,,,,,,,,0,4.000000e+000,5.000000e-001,1,1,6.386719e-001,0,,0,
1662040925.679,,5.000000e+003,3.374254e+002,-1.610173e-005,0.000000e+000,1.843299e+000,0.000000e+000,3,0.000000e+000,1.825000e+000,,,,,,,,,,,,,,,,,,0,4.000000e+000,5.000000e-001,1,1,6.665955e-001,0,,0,
1662040984.829,,5.000000e+003,3.424174e+002,-2.299466e-005,0.000000e+000,1.480246e+000,0.000000e+000,3,0.000000e+000,1.825000e+000,,,,,,,,,,,,,,,,,,0,4.000000e+000,5.000000e-001,1,1,6.357117e-001,0,,0,
1662041044.179,,5.000000e+003,3.473599e+002,-3.476807e-005,0.000000e+000,1.107313e+000,0.000000e+000,3,0.000000e+000,1.825000e+000,,,,,,,,,,,,,,,,,,0,4.000000e+000,5.000000e-001,1,1,6.385193e-001,0,,0,
1662043842.867,,5.000000e+003,3.466075e+002,-1.471242e-005,0.000000e+000,0.000000e+000,0.000000e+000,3,0.000000e+000,1.825000e+000,,,,,,,,,,,,,,,,,,0,4.000000e+000,5.000000e-001,1,1,4.786987e-001,0,,0,
1662043897.157,,5.000000e+003,3.412670e+002,-1.463905e-005,0.000000e+000,0.000000e+000,0.000000e+000,3,0.000000e+000,1.825000e+000,,,,,,,,,,,,,,,,,,0,4.000000e+000,5.000000e-001,1,1,8.618164e-001,0,,0,
1662043945.158,,5.000000e+003,3.345507e+002,-1.472020e-005,0.000000e+000,0.000000e+000,0.000000e+000,3,0.000000e+000,1.825000e+000,,,,,,,,,,,,,,,,,,0,4.000000e+000,5.000000e-001,1,1,1.077911e+000,0,,0,
1662043993.828,,5.000000e+003,3.270872e+002,-1.504248e-005,0.000000e+000,0.000000e+000,0.000000e+000,3,0.000000e+000,1.825000e+000,,,,,,,,,,,,,,,,,,0,4.000000e+000,5.000000e-001,1,1,1.098297e+000,0,,0,
1662044043.009,,5.000000e+003,3.201160e+002,-1.672299e-005,0.000000e+000,0.000000e+000,0.000000e+000,3,0.000000e+000,1.825000e+000,,,,,,,,,,,,,,,,,,0,4.000000e+000,5.000000e-001,1,1,1.016510e+000,0,,0,
1662044092.369,,5.000000e+003,3.139699e+002,-1.548114e-005,0.000000e+000,0.000000e+000,0.000000e+000,3,0.000000e+000,1.825000e+000,,,,,,,,,,,,,,,,,,0,4.000000e+000,5.000000e-001,1,1,8.482056e-001,0,,0,
1662044141.349,,5.000000e+003,3.091945e+002,-1.570911e-005,0.000000e+000,0.000000e+000,0.000000e+000,3,0.000000e+000,1.825000e+000,,,,,,,,,,,,,,,,,,0,4.000000e+000,5.000000e-001,1,1,6.701965e-001,0,,0,
1662044193.319,,5.000000e+003,3.050786e+002,-1.564999e-005,0.000000e+000,0.000000e+000,0.000000e+000,3,0.000000e+000,1.825000e+000,,,,,,,,,,,,,,,,,,0,4.000000e+000,5.000000e-001,1,1,5.534973e-001,0,,0,
1662044240.709,,5.000000e+003,3.019794e+002,-1.546328e-005,0.000000e+000,0.000000e+000,0.000000e+000,3,0.000000e+000,1.825000e+000,,,,,,,,,,,,,,,,,,0,4.000000e+000,5.000000e-001,1,1,4.733887e-001,0,,0,
1662044288.689,,5.000000e+003,2.993073e+002,-1.551316e-005,0.000000e+000,0.000000e+000,0.000000e+000,3,0.000000e+000,1.825000e+000,,,,,,,,,,,,,,,,,,0,4.000000e+000,5.000000e-001,1,1,3.712769e-001,0,,0,
1662044343.639,,5.000000e+003,2.966678e+002,-1.588771e-005,0.000000e+000,0.000000e+000,0.000000e+000,3,0.000000e+000,1.825000e+000,,,,,,,,,,,,,,,,,,0,4.000000e+000,5.000000e-001,1,1,3.381042e-001,0,,0,
1662044446.079,,5.000000e+003,2.916564e+002,-1.553561e-005,0.000000e+000,0.000000e+000,0.000000e+000,3,0.000000e+000,1.825000e+000,,,,,,,,,,,,,,,,,,0,4.000000e+000,5.000000e-001,1,1,4.125977e-001,0,,0,
1662044526.229,,5.000000e+003,2.864563e+002,-1.582648e-005,0.000000e+000,0.000000e+000,0.000000e+000,3,0.000000e+000,1.825000e+000,,,,,,,,,,,,,,,,,,0,4.000000e+000,5.000000e-001,1,1,5.640259e-001,0,,0,
1662044586.669,,5.000000e+003,2.815396e+002,-1.529544e-005,0.000000e+000,0.000000e+000,0.000000e+000,3,0.000000e+000,1.825000e+000,,,,,,,,,,,,,,,,,,0,4.000000e+000,5.000000e-001,1,1,6.571960e-001,0,,0,
1662044639.519,,5.000000e+003,2.764865e+002,-1.575773e-005,0.000000e+000,0.000000e+000,0.000000e+000,3,0.000000e+000,1.825000e+000,,,,,,,,,,,,,,,,,,0,4.000000e+000,5.000000e-001,1,1,5.861206e-001,0,,0,
1662044690.241,,5.000000e+003,2.713712e+002,-1.535311e-005,0.000000e+000,0.000000e+000,0.000000e+000,3,0.000000e+000,1.825000e+000,,,,,,,,,,,,,,,,,,0,4.000000e+000,5.000000e-001,1,1,8.842773e-001,0,,0,
1662044739.291,,5.000000e+003,2.664424e+002,8.313727e-005,0.000000e+000,-1.156685e+000,0.000000e+000,3,0.000000e+000,1.825000e+000,,,,,,,,,,,,,,,,,,0,4.000000e+000,5.000000e-001,1,1,9.080811e-001,0,,0,
1662044791.651,,5.000000e+003,2.614070e+002,-1.517255e-005,0.000000e+000,0.000000e+000,0.000000e+000,3,0.000000e+000,1.825000e+000,,,,,,,,,,,,,,,,,,0,4.000000e+000,5.000000e-001,1,1,6.262817e-001,0,,0,
1662044845.881,,5.000000e+003,2.564759e+002,-1.493442e-005,0.000000e+000,0.000000e+000,0.000000e+000,3,0.000000e+000,1.825000e+000,,,,,,,,,,,,,,,,,,0,4.000000e+000,5.000000e-001,1,1,7.085876e-001,0,,0,
1662044902.841,,5.000000e+003,2.517391e+002,-1.480959e-005,0.000000e+000,0.000000e+000,0.000000e+000,3,0.000000e+000,1.825000e+000,,,,,,,,,,,,,,,,,,0,4.000000e+000,5.000000e-001,1,1,4.703979e-001,0,,0,
1662044968.251,,5.000000e+003,2.465866e+002,-1.408771e-005,0.000000e+000,0.000000e+000,0.000000e+000,3,0.000000e+000,1.825000e+000,,,,,,,,,,,,,,,,,,0,4.000000e+000,5.000000e-001,1,1,6.128998e-001,0,,0,
1662045036.602,,5.000000e+003,2.416137e+002,-1.361413e-005,0.000000e+000,0.000000e+000,0.000000e+000,3,0.000000e+000,1.825000e+000,,,,,,,,,,,,,,,,,,0,4.000000e+000,5.000000e-001,1,1,4.553986e-001,0,,0,
1662045107.282,,5.000000e+003,2.366629e+002,-1.395692e-005,0.000000e+000,0.000000e+000,0.000000e+000,3,0.000000e+000,1.825000e+000,,,,,,,,,,,,,,,,,,0,4.000000e+000,5.000000e-001,1,1,5.767975e-001,0,,0,
1662045178.722,,5.000000e+003,2.316317e+002,-1.319590e-005,0.000000e+000,0.000000e+000,0.000000e+000,3,0.000000e+000,1.825000e+000,,,,,,,,,,,,,,,,,,0,4.000000e+000,5.000000e-001,1,1,5.771027e-001,0,,0,
1662045248.083,,5.000000e+003,2.265754e+002,-1.332919e-005,0.000000e+000,0.000000e+000,0.000000e+000,3,0.000000e+000,1.825000e+000,,,,,,,,,,,,,,,,,,0,4.000000e+000,5.000000e-001,1,1,5.900116e-001,0,,0,
1662045314.483,,5.000000e+003,2.215638e+002,-1.270650e-005,0.000000e+000,0.000000e+000,0.000000e+000,3,0.000000e+000,1.825000e+000,,,,,,,,,,,,,,,,,,0,4.000000e+000,5.000000e-001,1,1,5.522919e-001,0,,0,
1662045377.084,,5.000000e+003,2.167289e+002,-1.249332e-005,0.000000e+000,0.000000e+000,0.000000e+000,3,0.000000e+000,1.825000e+000,,,,,,,,,,,,,,,,,,0,4.000000e+000,5.000000e-001,1,1,5.139008e-001,0,,0,
1662045439.534,,5.000000e+003,2.116768e+002,-1.159014e-005,0.000000e+000,0.000000e+000,0.000000e+000,3,0.000000e+000,1.825000e+000,,,,,,,,,,,,,,,,,,0,4.000000e+000,5.000000e-001,1,1,6.123047e-001,0,,0,
1662045502.714,,5.000000e+003,2.066107e+002,-5.334833e-005,0.000000e+000,1.148062e+000,0.000000e+000,3,3.273054e-001,1.825000e+000,,,,,,,,,,,,,,,,,,0,4.000000e+000,5.000000e-001,1,1,5.877075e-001,0,,0,
1662045565.334,,5.000000e+003,2.016314e+002,-5.450972e-005,0.000000e+000,1.147817e+000,0.000000e+000,3,3.409683e-001,1.825000e+000,,,,,,,,,,,,,,,,,,0,4.000000e+000,5.000000e-001,1,1,6.089020e-001,0,,0,
1662045629.434,,5.000000e+003,1.965720e+002,-5.527158e-005,0.000000e+000,1.146200e+000,0.000000e+000,3,3.782710e-001,1.825000e+000,,,,,,,,,,,,,,,,,,0,4.000000e+000,5.000000e-001,1,1,6.046906e-001,0,,0,
1662045694.034,,5.000000e+003,1.915554e+002,-5.586023e-005,0.000000e+000,1.149098e+000,0.000000e+000,3,3.923025e-001,1.825000e+000,,,,,,,,,,,,,,,,,,0,4.000000e+000,5.000000e-001,1,1,5.836945e-001,0,,0,
1662045758.924,,5.000000e+003,1.866521e+002,-5.757374e-005,0.000000e+000,1.143629e+000,0.000000e+000,3,4.144502e-001,1.825000e+000,,,,,,,,,,,,,,,,,,0,4.000000e+000,5.000000e-001,1,1,5.870972e-001,0,,0,
1662045825.534,,5.000000e+003,1.816154e+002,-5.756902e-005,0.000000e+000,1.148725e+000,0.000000e+000,3,4.215081e-001,1.825000e+000,,,,,,,,,,,,,,,,,,0,4.000000e+000,5.000000e-001,1,1,6.183014e-001,0,,0,
1662045888.894,,5.000000e+003,1.765941e+002,-5.810764e-005,0.000000e+000,1.142061e+000,0.000000e+000,3,4.464572e-001,1.825000e+000,,,,,,,,,,,,,,,,,,0,4.000000e+000,5.000000e-001,1,1,6.262970e-001,0,,0,
1662045949.874,,5.000000e+003,1.716691e+002,1.039037e-004,0.000000e+000,-1.369982e+000,0.000000e+000,3,6.208383e-002,1.825000e+000,,,,,,,,,,,,,,,,,,0,4.000000e+000,5.000000e-001,1,1,5.668030e-001,0,,0,
1662046011.284,,5.000000e+003,1.665817e+002,-7.235207e-006,0.000000e+000,0.000000e+000,0.000000e+000,3,0.000000e+000,1.825000e+000,,,,,,,,,,,,,,,,,,0,4.000000e+000,5.000000e-001,1,1,6.497955e-001,0,,0,
1662046072.665,,5.000000e+003,1.615629e+002,-6.156110e-005,0.000000e+000,1.139613e+000,0.000000e+000,3,5.029014e-001,1.825000e+000,,,,,,,,,,,,,,,,,,0,4.000000e+000,5.000000e-001,1,1,5.957947e-001,0,,0,
1662046132.576,,5.000000e+003,1.565903e+002,-6.300461e-005,0.000000e+000,1.141923e+000,0.000000e+000,3,5.314220e-001,1.825000e+000,,,,,,,,,,,,,,,,,,0,4.000000e+000,5.000000e-001,1,1,6.784058e-001,0,,0,
1662046193.496,,5.000000e+003,1.515251e+002,-6.447332e-005,0.000000e+000,1.140405e+000,0.000000e+000,3,5.665476e-001,1.825000e+000,,,,,,,,,,,,,,,,,,0,4.000000e+000,5.000000e-001,1,1,6.150970e-001,0,,0,
1662046252.396,,5.000000e+003,1.466424e+002,-6.597157e-005,0.000000e+000,1.142208e+000,0.000000e+000,3,5.887157e-001,1.825000e+000,,,,,,,,,,,,,,,,,,0,4.000000e+000,5.000000e-001,1,1,6.212006e-001,0,,0,
1662046313.037,,5.000000e+003,1.415984e+002,-6.658043e-005,0.000000e+000,1.137055e+000,0.000000e+000,3,6.073239e-001,1.825000e+000,,,,,,,,,,,,,,,,,,0,4.000000e+000,5.000000e-001,1,1,6.374969e-001,0,,0,
1662046372.677,,5.000000e+003,1.366063e+002,-6.885429e-005,0.000000e+000,1.142598e+000,0.000000e+000,3,6.354397e-001,1.825000e+000,,,,,,,,,,,,,,,,,,0,4.000000e+000,5.000000e-001,1,1,7.266083e-001,0,,0,
1662046432.337,,5.000000e+003,1.315141e+002,6.792214e-007,0.000000e+000,0.000000e+000,0.000000e+000,3,0.000000e+000,1.825000e+000,,,,,,,,,,,,,,,,,,0,4.000000e+000,5.000000e-001,1,1,6.199036e-001,0,,0,
1662046490.538,,5.000000e+003,1.266622e+002,1.734770e-006,0.000000e+000,0.000000e+000,0.000000e+000,3,0.000000e+000,1.825000e+000,,,,,,,,,,,,,,,,,,0,4.000000e+000,5.000000e-001,1,1,6.657028e-001,0,,0,
1662046551.318,,5.000000e+003,1.215089e+002,2.598351e-006,0.000000e+000,0.000000e+000,0.000000e+000,3,0.000000e+000,1.825000e+000,,,,,,,,,,,,,,,,,,0,4.000000e+000,5.000000e-001,1,1,6.855011e-001,0,,0,
1662046607.198,,5.000000e+003,1.166580e+002,4.260821e-006,0.000000e+000,0.000000e+000,0.000000e+000,3,0.000000e+000,1.825000e+000,,,,,,,,,,,,,,,,,,0,4.000000e+000,5.000000e-001,1,1,6.661987e-001,0,,0,
1662046666.628,,5.000000e+003,1.115403e+002,6.322393e-006,0.000000e+000,0.000000e+000,0.000000e+000,3,0.000000e+000,1.825000e+000,,,,,,,,,,,,,,,,,,0,4.000000e+000,5.000000e-001,1,1,5.600967e-001,0,,0,
1662046725.068,,5.000000e+003,1.065060e+002,8.833288e-006,0.000000e+000,0.000000e+000,0.000000e+000,3,0.000000e+000,1.825000e+000,,,,,,,,,,,,,,,,,,0,4.000000e+000,5.000000e-001,1,1,6.580963e-001,0,,0,
1662046780.078,,5.000000e+003,1.016277e+002,1.039580e-005,0.000000e+000,0.000000e+000,0.000000e+000,3,0.000000e+000,1.825000e+000,,,,,,,,,,,,,,,,,,0,4.000000e+000,5.000000e-001,1,1,6.842041e-001,0,,0,
1662046837.719,,5.000000e+003,9.648244e+001,1.266807e-005,0.000000e+000,0.000000e+000,0.000000e+000,3,0.000000e+000,1.825000e+000,,,,,,,,,,,,,,,,,,0,4.000000e+000,5.000000e-001,1,1,6.964645e-001,0,,0,
1662046891.569,,5.000000e+003,9.155556e+001,-5.456178e-006,0.000000e+000,-1.808230e+000,0.000000e+000,3,0.000000e+000,1.825000e+000,,,,,,,,,,,,,,,,,,0,4.000000e+000,5.000000e-001,1,1,7.108612e-001,0,,0,
1662046946.019,,5.000000e+003,8.649941e+001,6.431882e-005,0.000000e+000,-8.156157e-001,0.000000e+000,3,5.125076e-001,1.825000e+000,,,,,,,,,,,,,,,,,,0,4.000000e+000,5.000000e-001,1,1,6.580505e-001,0,,0,
1662047003.639,,5.000000e+003,8.108052e+001,6.761466e-005,0.000000e+000,-7.812139e-001,0.000000e+000,3,5.165459e-001,1.825000e+000,,,,,,,,,,,,,,,,,,0,4.000000e+000,5.000000e-001,1,1,7.362061e-001,0,,0,
1662047053.271,,5.000000e+003,7.641710e+001,7.098164e-005,0.000000e+000,-7.459087e-001,0.000000e+000,3,5.315282e-001,1.825000e+000,,,,,,,,,,,,,,,,,,0,4.000000e+000,5.000000e-001,1,1,6.992569e-001,0,,0,
1662047103.641,,5.000000e+003,7.147731e+001,6.043366e-005,0.000000e+000,-6.593258e-001,0.000000e+000,3,2.532524e-001,1.825000e+000,,,,,,,,,,,,,,,,,,0,4.000000e+000,5.000000e-001,1,1,8.181534e-001,0,,0,
1662047154.031,,5.000000e+003,6.651201e+001,5.027247e-005,0.000000e+000,1.563151e-001,0.000000e+000,3,6.272951e-002,1.825000e+000,,,,,,,,,,,,,,,,,,0,4.000000e+000,5.000000e-001,1,1,7.601089e-001,0,,0,
1662047202.711,,5.000000e+003,6.157316e+001,6.607400e-005,0.000000e+000,3.913316e-001,0.000000e+000,3,2.199994e-001,1.825000e+000,,,,,,,,,,,,,,,,,,0,4.000000e+000,5.000000e-001,1,1,6.468773e-001,0,,0,
1662047252.711,,5.000000e+003,5.636396e+001,9.335128e-005,0.000000e+000,4.126911e-001,0.000000e+000,3,3.554007e-001,1.825000e+000,,,,,,,,,,,,,,,,,,0,4.000000e+000,5.000000e-001,1,1,7.832794e-001,0,,0,
1662047298.831,,5.000000e+003,5.136401e+001,1.097807e-004,0.000000e+000,4.160016e-001,0.000000e+000,3,4.223203e-001,1.825000e+000,,,,,,,,,,,,,,,,,,0,4.000000e+000,5.000000e-001,1,1,8.695984e-001,0,,0,
1662047347.452,,5.000000e+003,4.598373e+001,1.258947e-004,0.000000e+000,4.013056e-001,0.000000e+000,3,4.794130e-001,1.825000e+000,,,,,,,,,,,,,,,,,,0,4.000000e+000,5.000000e-001,1,1,9.223099e-001,0,,0,
1662047396.232,,5.000000e+003,4.036567e+001,1.442944e-004,0.000000e+000,3.789780e-001,0.000000e+000,3,5.327376e-001,1.825000e+000,,,,,,,,,,,,,,,,,,0,4.000000e+000,5.000000e-001,1,1,8.518410e-001,0,,0,
1662047445.582,,5.000000e+003,3.450732e+001,1.669229e-004,0.000000e+000,3.646060e-001,0.000000e+000,3,5.732955e-001,1.825000e+000,,,,,,,,,,,,,,,,,,0,4.000000e+000,5.000000e-001,1,1,7.343903e-001,0,,0,
1662047492.232,,5.000000e+003,2.926112e+001,1.940678e-004,0.000000e+000,3.477181e-001,0.000000e+000,3,6.143931e-001,1.825000e+000,,,,,,,,,,,,,,,,,,0,4.000000e+000,5.000000e-001,1,1,8.042202e-001,0,,0,
1662047540.654,,5.000000e+003,2.448679e+001,2.439308e-004,0.000000e+000,3.323526e-001,0.000000e+000,3,6.562115e-001,1.825000e+000,,,,,,,,,,,,,,,,,,0,4.000000e+000,5.000000e-001,1,1,8.421593e-001,0,,0,
1662047588.494,,5.000000e+003,2.069246e+001,2.888906e-004,0.000000e+000,3.231341e-001,0.000000e+000,3,6.875286e-001,1.825000e+000,,,,,,,,,,,,,,,,,,0,4.000000e+000,5.000000e-001,1,1,3.727913e-002,0,,0,
1662047639.224,,5.000000e+003,1.534066e+001,3.839370e-004,0.000000e+000,3.101355e-001,0.000000e+000,3,7.183553e-001,1.825000e+000,,,,,,,,,,,,,,,,,,0,4.000000e+000,5.000000e-001,1,1,1.041698e-001,0,,0,
1662047696.099,,5.000000e+003,1.107428e+001,4.847354e-004,0.000000e+000,3.023766e-001,0.000000e+000,3,7.317060e-001,1.825000e+000,,,,,,,,,,,,,,,,,,0,4.000000e+000,5.000000e-001,1,1,1.271231e+000,0,,0,
1662047797.081,,5.000000e+003,6.882423e+000,6.887628e-004,0.000000e+000,2.927212e-001,0.000000e+000,3,7.499273e-001,1.825000e+000,,,,,,,,,,,,,,,,,,0,4.000000e+000,5.000000e-001,1,1,2.193727e-001,0,,0,
1662052118.236,,1.000000e+004,2.000998e+000,2.327034e-003,0.000000e+000,3.397938e-003,0.000000e+000,3,6.482127e-001,1.825000e+000,,,,,,,,,,,,,,,,,,0,4.000000e+000,5.000000e-001,1,1,1.740456e-004,0,,0,
1662052512.339,,1.000000e+004,7.520236e+000,1.267321e-003,0.000000e+000,2.619044e-002,0.000000e+000,3,6.150896e-001,1.825000e+000,,,,,,,,,,,,,,,,,,0,4.000000e+000,5.000000e-001,1,1,4.303436e-001,0,,0,
1662052579.629,,1.000000e+004,1.250470e+001,8.347612e-004,0.000000e+000,2.493897e-002,0.000000e+000,3,6.296754e-001,1.825000e+000,,,,,,,,,,,,,,,,,,0,4.000000e+000,5.000000e-001,1,1,4.711800e-001,0,,0,
1662052640.361,,1.000000e+004,1.747808e+001,6.096192e-004,0.000000e+000,3.492529e-002,0.000000e+000,3,6.088414e-001,1.825000e+000,,,,,,,,,,,,,,,,,,0,4.000000e+000,5.000000e-001,1,1,6.541290e-001,0,,0,
1662052699.221,,1.000000e+004,2.232215e+001,4.749537e-004,0.000000e+000,4.505979e-002,0.000000e+000,3,5.837179e-001,1.825000e+000,,,,,,,,,,,,,,,,,,0,4.000000e+000,5.000000e-001,1,1,6.069393e-001,0,,0,
1662052771.341,,1.000000e+004,2.829002e+001,3.349137e-004,0.000000e+000,1.402959e-001,0.000000e+000,3,3.971159e-001,1.825000e+000,,,,,,,,,,,,,,,,,,0,4.000000e+000,5.000000e-001,1,1,5.745907e-001,0,,0,
1662052821.041,,1.000000e+004,3.235915e+001,2.997214e-004,0.000000e+000,7.267581e-002,0.000000e+000,3,4.980073e-001,1.825000e+000,,,,,,,,,,,,,,,,,,0,4.000000e+000,5.000000e-001,1,1,6.367798e-001,0,,0,
1662052883.471,,1.000000e+004,3.755338e+001,2.584838e-004,0.000000e+000,8.788321e-002,0.000000e+000,3,4.573699e-001,1.825000e+000,,,,,,,,,,,,,,,,,,0,4.000000e+000,5.000000e-001,1,1,5.945396e-001,0,,0,
1662052943.771,,1.000000e+004,4.245055e+001,2.257787e-004,0.000000e+000,1.093618e-001,0.000000e+000,3,4.153638e-001,1.825000e+000,,,,,,,,,,,,,,,,,,0,4.000000e+000,5.000000e-001,1,1,6.629906e-001,0,,0,
1662053007.921,,1.000000e+004,4.777328e+001,1.934113e-004,0.000000e+000,1.468772e-001,0.000000e+000,3,3.662814e-001,1.825000e+000,,,,,,,,,,,,,,,,,,0,4.000000e+000,5.000000e-001,1,1,4.585876e-001,0,,0,
1662053063.311,,1.000000e+004,5.236995e+001,1.691677e-004,0.000000e+000,1.830318e-001,0.000000e+000,3,3.212375e-001,1.825000e+000,,,,,,,,,,,,,,,,,,0,4.000000e+000,5.000000e-001,1,1,5.432396e-001,0,,0,
1662053124.461,,1.000000e+004,5.745049e+001,1.419110e-004,0.000000e+000,2.252772e-001,0.000000e+000,3,2.450879e-001,1.825000e+000,,,,,,,,,,,,,,,,,,0,4.000000e+000,5.000000e-001,1,1,5.311890e-001,0,,0,
1662053184.152,,1.000000e+004,6.243463e+001,1.010525e-004,0.000000e+000,6.130374e-001,0.000000e+000,3,0.000000e+000,1.825000e+000,,,,,,,,,,,,,,,,,,0,4.000000e+000,5.000000e-001,1,1,5.209808e-001,0,,0,
1662053248.252,,1.000000e+004,6.776643e+001,6.138822e-006,0.000000e+000,-1.017210e+000,0.000000e+000,3,0.000000e+000,1.825000e+000,,,,,,,,,,,,,,,,,,0,4.000000e+000,5.000000e-001,1,1,5.186462e-001,0,,0,
1662053308.662,,1.000000e+004,7.279297e+001,1.874427e-004,0.000000e+000,-8.094055e-001,0.000000e+000,3,5.110808e-001,1.825000e+000,,,,,,,,,,,,,,,,,,0,4.000000e+000,5.000000e-001,1,1,5.761642e-001,0,,0,
1662053371.752,,1.000000e+004,7.811366e+001,1.524210e-004,0.000000e+000,-9.523268e-001,0.000000e+000,3,5.479383e-001,1.825000e+000,,,,,,,,,,,,,,,,,,0,4.000000e+000,5.000000e-001,1,1,5.629730e-001,0,,0,
1662053422.462,,1.000000e+004,8.237348e+001,-1.824935e-005,0.000000e+000,0.000000e+000,0.000000e+000,3,0.000000e+000,1.825000e+000,,,,,,,,,,,,,,,,,,0,4.000000e+000,5.000000e-001,1,1,6.552429e-001,0,,0,
1662053492.562,,1.000000e+004,8.824738e+001,-2.330621e-005,0.000000e+000,0.000000e+000,0.000000e+000,3,0.000000e+000,1.825000e+000,,,,,,,,,,,,,,,,,,0,4.000000e+000,5.000000e-001,1,1,6.448441e-001,0,,0,
1662053543.982,,1.000000e+004,9.252803e+001,-2.624548e-005,0.000000e+000,0.000000e+000,0.000000e+000,3,0.000000e+000,1.825000e+000,,,,,,,,,,,,,,,,,,0,4.000000e+000,5.000000e-001,1,1,5.410995e-001,0,,0,
1662053603.142,,1.000000e+004,9.749573e+001,-1.648722e-004,0.000000e+000,9.313834e-001,0.000000e+000,3,8.174348e-001,1.825000e+000,,,,,,,,,,,,,,,,,,0,4.000000e+000,5.000000e-001,1,1,5.277100e-001,0,,0,
1662053662.852,,1.000000e+004,1.025356e+002,-1.586917e-004,0.000000e+000,9.388091e-001,0.000000e+000,3,7.811185e-001,1.825000e+000,,,,,,,,,,,,,,,,,,0,4.000000e+000,5.000000e-001,1,1,6.124954e-001,0,,0,
1662053730.502,,1.000000e+004,1.081358e+002,9.403585e-006,0.000000e+000,0.000000e+000,0.000000e+000,3,0.000000e+000,1.825000e+000,,,,,,,,,,,,,,,,,,0,4.000000e+000,5.000000e-001,1,1,6.011047e-001,0,,0,
1662053780.353,,1.000000e+004,1.123446e+002,-1.484407e-004,0.000000e+000,9.485429e-001,0.000000e+000,3,7.085743e-001,1.825000e+000,,,,,,,,,,,,,,,,,,0,4.000000e+000,5.000000e-001,1,1,6.758041e-001,0,,0,
1662053843.463,,1.000000e+004,1.175723e+002,-1.430019e-004,0.000000e+000,9.512407e-001,0.000000e+000,3,6.731492e-001,1.825000e+000,,,,,,,,,,,,,,,,,,0,4.000000e+000,5.000000e-001,1,1,6.764984e-001,0,,0,
1662053901.066,,1.000000e+004,1.224164e+002,-1.386241e-004,0.000000e+000,9.613011e-001,0.000000e+000,3,6.359865e-001,1.825000e+000,,,,,,,,,,,,,,,,,,0,4.000000e+000,5.000000e-001,1,1,6.592026e-001,0,,0,
1662053970.166,,1.000000e+004,1.282314e+002,-1.339457e-004,0.000000e+000,9.679384e-001,0.000000e+000,3,5.945964e-001,1.825000e+000,,,,,,,,,,,,,,,,,,0,4.000000e+000,5.000000e-001,1,1,6.381073e-001,0,,0,
1662054020.016,,1.000000e+004,1.323736e+002,1.329280e-004,0.000000e+000,-1.164895e+000,0.000000e+000,3,2.163644e-001,1.825000e+000,,,,,,,,,,,,,,,,,,0,4.000000e+000,5.000000e-001,1,1,6.281128e-001,0,,0,
1662054080.726,,1.000000e+004,1.374105e+002,-1.271556e-004,0.000000e+000,9.856861e-001,0.000000e+000,3,5.286149e-001,1.825000e+000,,,,,,,,,,,,,,,,,,0,4.000000e+000,5.000000e-001,1,1,7.021027e-001,0,,0,
1662054139.716,,1.000000e+004,1.423495e+002,-1.236959e-004,0.000000e+000,9.921042e-001,0.000000e+000,3,4.932158e-001,1.825000e+000,,,,,,,,,,,,,,,,,,0,4.000000e+000,5.000000e-001,1,1,6.988983e-001,0,,0,
1662054211.226,,1.000000e+004,1.483510e+002,-1.196483e-004,0.000000e+000,1.004449e+000,0.000000e+000,3,4.501784e-001,1.825000e+000,,,,,,,,,,,,,,,,,,0,4.000000e+000,5.000000e-001,1,1,5.352020e-001,0,,0,
1662054259.296,,1.000000e+004,1.524273e+002,-1.176021e-004,0.000000e+000,1.013261e+000,0.000000e+000,3,4.229826e-001,1.825000e+000,,,,,,,,,,,,,,,,,,0,4.000000e+000,5.000000e-001,1,1,5.095978e-001,0,,0,
1662054319.196,,1.000000e+004,1.573918e+002,-1.989090e-004,0.000000e+000,1.084368e+000,0.000000e+000,3,3.570162e-001,1.825000e+000,,,,,,,,,,,,,,,,,,0,4.000000e+000,5.000000e-001,1,1,6.587067e-001,0,,0,
1662054379.566,,1.000000e+004,1.624363e+002,-1.112113e-004,0.000000e+000,1.025107e+000,0.000000e+000,3,3.577064e-001,1.825000e+000,,,,,,,,,,,,,,,,,,0,4.000000e+000,5.000000e-001,1,1,5.810089e-001,0,,0,
1662054451.176,,1.000000e+004,1.684061e+002,-1.080979e-004,0.000000e+000,1.033415e+000,0.000000e+000,3,3.160158e-001,1.825000e+000,,,,,,,,,,,,,,,,,,0,4.000000e+000,5.000000e-001,1,1,6.529999e-001,0,,0,
1662054498.626,,1.000000e+004,1.723798e+002,-1.060591e-004,0.000000e+000,1.038534e+000,0.000000e+000,3,2.914648e-001,1.825000e+000,,,,,,,,,,,,,,,,,,0,4.000000e+000,5.000000e-001,1,1,6.446991e-001,0,,0,
1662054558.476,,1.000000e+004,1.773407e+002,-1.035227e-004,0.000000e+000,1.049325e+000,0.000000e+000,3,2.499971e-001,1.825000e+000,,,,,,,,,,,,,,,,,,0,4.000000e+000,5.000000e-001,1,1,5.415039e-001,0,,0,
1662054617.967,,1.000000e+004,1.822858e+002,-1.013619e-004,0.000000e+000,1.053510e+000,0.000000e+000,3,2.198214e-001,1.825000e+000,,,,,,,,,,,,,,,,,,0,4.000000e+000,5.000000e-001,1,1,5.411987e-001,0,,0,
1662054691.377,,1.000000e+004,1.884330e+002,-9.773348e-005,0.000000e+000,1.058532e+000,0.000000e+000,3,1.763008e-001,1.825000e+000,,,,,,,,,,,,,,,,,,0,4.000000e+000,5.000000e-001,1,1,7.104950e-001,0,,0,
1662054738.567,,1.000000e+004,1.923640e+002,-9.670780e-005,0.000000e+000,1.064832e+000,0.000000e+000,3,1.604608e-001,1.825000e+000,,,,,,,,,,,,,,,,,,0,4.000000e+000,5.000000e-001,1,1,6.192017e-001,0,,0,
1662054798.527,,1.000000e+004,1.973763e+002,-9.390600e-005,0.000000e+000,1.072335e+000,0.000000e+000,3,1.138453e-001,1.825000e+000,,,,,,,,,,,,,,,,,,0,4.000000e+000,5.000000e-001,1,1,6.097107e-001,0,,0,
1662054858.837,,1.000000e+004,2.024391e+002,-9.251724e-005,0.000000e+000,1.074359e+000,0.000000e+000,3,8.971000e-002,1.825000e+000,,,,,,,,,,,,,,,,,,0,4.000000e+000,5.000000e-001,1,1,6.026001e-001,0,,0,
1662054931.567,,1.000000e+004,2.083921e+002,-9.097561e-005,0.000000e+000,1.082851e+000,0.000000e+000,3,5.243119e-002,1.825000e+000,,,,,,,,,,,,,,,,,,0,4.000000e+000,5.000000e-001,1,1,6.042023e-001,0,,0,
1662054978.997,,1.000000e+004,2.124593e+002,-8.841815e-005,0.000000e+000,1.085752e+000,0.000000e+000,3,2.350315e-002,1.825000e+000,,,,,,,,,,,,,,,,,,0,4.000000e+000,5.000000e-001,1,1,6.046906e-001,0,,0,
1662055040.128,,1.000000e+004,2.174865e+002,-8.658809e-005,0.000000e+000,1.090162e+000,0.000000e+000,3,0.000000e+000,1.825000e+000,,,,,,,,,,,,,,,,,,0,4.000000e+000,5.000000e-001,1,1,6.815033e-001,0,,0,
1662055098.769,,1.000000e+004,2.223819e+002,-8.602248e-005,0.000000e+000,1.092210e+000,0.000000e+000,3,0.000000e+000,1.825000e+000,,,,,,,,,,,,,,,,,,0,4.000000e+000,5.000000e-001,1,1,5.978088e-001,0,,0,
1662055172.789,,1.000000e+004,2.286348e+002,-8.217199e-005,0.000000e+000,1.103265e+000,0.000000e+000,3,0.000000e+000,1.825000e+000,,,,,,,,,,,,,,,,,,0,4.000000e+000,5.000000e-001,1,1,5.830994e-001,0,,0,
1662055220.730,,1.000000e+004,2.325725e+002,-8.315669e-005,0.000000e+000,1.101078e+000,0.000000e+000,3,0.000000e+000,1.825000e+000,,,,,,,,,,,,,,,,,,0,4.000000e+000,5.000000e-001,1,1,5.820007e-001,0,,0,
1662055278.330,,1.000000e+004,2.373775e+002,-8.012235e-005,0.000000e+000,1.107563e+000,0.000000e+000,3,0.000000e+000,1.825000e+000,,,,,,,,,,,,,,,,,,0,4.000000e+000,5.000000e-001,1,1,6.792908e-001,0,,0,
1662055338.451,,1.000000e+004,2.424022e+002,-7.993665e-005,0.000000e+000,1.108944e+000,0.000000e+000,3,0.000000e+000,1.825000e+000,,,,,,,,,,,,,,,,,,0,4.000000e+000,5.000000e-001,1,1,5.782928e-001,0,,0,
1662055413.001,,1.000000e+004,2.485685e+002,-1.103788e-004,0.000000e+000,1.111948e+000,0.000000e+000,3,9.381238e-002,1.825000e+000,,,,,,,,,,,,,,,,,,0,4.000000e+000,5.000000e-001,1,1,6.539917e-001,0,,0,
1662055460.391,,1.000000e+004,2.526363e+002,-7.572802e-005,0.000000e+000,1.102566e+000,0.000000e+000,3,0.000000e+000,1.825000e+000,,,,,,,,,,,,,,,,,,0,4.000000e+000,5.000000e-001,1,1,5.778046e-001,0,,0,
1662055518.251,,1.000000e+004,2.573835e+002,-7.686466e-005,0.000000e+000,1.073844e+000,0.000000e+000,3,0.000000e+000,1.825000e+000,,,,,,,,,,,,,,,,,,0,4.000000e+000,5.000000e-001,1,1,5.730286e-001,0,,0,
1662055577.381,,1.000000e+004,2.623304e+002,-6.247914e-005,0.000000e+000,0.000000e+000,0.000000e+000,3,0.000000e+000,1.825000e+000,,,,,,,,,,,,,,,,,,0,4.000000e+000,5.000000e-001,1,1,6.163025e-001,0,,0,
1662055638.991,,1.000000e+004,2.674329e+002,-1.042579e-005,0.000000e+000,-6.421580e-001,0.000000e+000,3,0.000000e+000,1.825000e+000,,,,,,,,,,,,,,,,,,0,4.000000e+000,5.000000e-001,1,1,5.425110e-001,0,,0,
1662055707.891,,1.000000e+004,2.731878e+002,-6.347786e-005,0.000000e+000,0.000000e+000,0.000000e+000,3,0.000000e+000,1.825000e+000,,,,,,,,,,,,,,,,,,0,4.000000e+000,5.000000e-001,1,1,7.098083e-001,0,,0,
1662055758.741,,1.000000e+004,2.774467e+002,-1.355570e-005,0.000000e+000,1.873077e+000,0.000000e+000,3,0.000000e+000,1.825000e+000,,,,,,,,,,,,,,,,,,0,4.000000e+000,5.000000e-001,1,1,5.350037e-001,0,,0,
1662055817.661,,1.000000e+004,2.823783e+002,-1.360786e-005,0.000000e+000,1.922469e+000,0.000000e+000,3,0.000000e+000,1.825000e+000,,,,,,,,,,,,,,,,,,0,4.000000e+000,5.000000e-001,1,1,5.223999e-001,0,,0,
1662055879.561,,1.000000e+004,2.875108e+002,-6.319480e-005,0.000000e+000,0.000000e+000,0.000000e+000,3,0.000000e+000,1.825000e+000,,,,,,,,,,,,,,,,,,0,4.000000e+000,5.000000e-001,1,1,6.171875e-001,0,,0,
1662055946.831,,1.000000e+004,2.930966e+002,-1.532708e-005,0.000000e+000,1.904727e+000,0.000000e+000,3,0.000000e+000,1.825000e+000,,,,,,,,,,,,,,,,,,0,4.000000e+000,5.000000e-001,1,1,6.070862e-001,0,,0,
1662055999.241,,1.000000e+004,2.975356e+002,-1.782632e-005,0.000000e+000,1.846581e+000,0.000000e+000,3,0.000000e+000,1.825000e+000,,,,,,,,,,,,,,,,,,0,4.000000e+000,5.000000e-001,1,1,6.281128e-001,0,,0,
1662056058.642,,1.000000e+004,3.025013e+002,-6.362388e-005,0.000000e+000,0.000000e+000,0.000000e+000,3,0.000000e+000,1.825000e+000,,,,,,,,,,,,,,,,,,0,4.000000e+000,5.000000e-001,1,1,5.296021e-001,0,,0,
1662056118.512,,1.000000e+004,3.074446e+002,-6.277420e-005,0.000000e+000,0.000000e+000,0.000000e+000,3,0.000000e+000,1.825000e+000,,,,,,,,,,,,,,,,,,0,4.000000e+000,5.000000e-001,1,1,5.912170e-001,0,,0,
1662056187.432,,1.000000e+004,3.131348e+002,-6.352391e-005,0.000000e+000,1.138367e+000,0.000000e+000,3,0.000000e+000,1.825000e+000,,,,,,,,,,,,,,,,,,0,4.000000e+000,5.000000e-001,1,1,4.986877e-001,0,,0,
1662056239.123,,1.000000e+004,3.174303e+002,-6.148223e-005,0.000000e+000,0.000000e+000,0.000000e+000,3,0.000000e+000,1.825000e+000,,,,,,,,,,,,,,,,,,0,4.000000e+000,5.000000e-001,1,1,6.500244e-001,0,,0,
1662056299.714,,1.000000e+004,3.225458e+002,-6.142322e-005,0.000000e+000,0.000000e+000,0.000000e+000,3,0.000000e+000,1.825000e+000,,,,,,,,,,,,,,,,,,0,4.000000e+000,5.000000e-001,1,1,5.638123e-001,0,,0,
1662056357.214,,1.000000e+004,3.273492e+002,-6.065729e-005,0.000000e+000,0.000000e+000,0.000000e+000,3,0.000000e+000,1.825000e+000,,,,,,,,,,,,,,,,,,0,4.000000e+000,5.000000e-001,1,1,6.390991e-001,0,,0,
1662056426.634,,1.000000e+004,3.331349e+002,-6.131926e-005,0.000000e+000,0.000000e+000,0.000000e+000,3,0.000000e+000,1.825000e+000,,,,,,,,,,,,,,,,,,0,4.000000e+000,5.000000e-001,1,1,5.549011e-001,0,,0,
1662056479.614,,1.000000e+004,3.374556e+002,-6.098353e-005,0.000000e+000,0.000000e+000,0.000000e+000,3,0.000000e+000,1.825000e+000,,,,,,,,,,,,,,,,,,0,4.000000e+000,5.000000e-001,1,1,6.581116e-001,0,,0,
1662056538.165,,1.000000e+004,3.423904e+002,-5.882608e-005,0.000000e+000,0.000000e+000,0.000000e+000,3,0.000000e+000,1.825000e+000,,,,,,,,,,,,,,,,,,0,4.000000e+000,5.000000e-001,1,1,5.639038e-001,0,,0,
1662056598.705,,1.000000e+004,3.474848e+002,-6.983462e-005,0.000000e+000,1.130366e+000,0.000000e+000,3,0.000000e+000,1.825000e+000,,,,,,,,,,,,,,,,,,0,4.000000e+000,5.000000e-001,1,1,6.481934e-001,0,,0,
1662056965.306,,1.000000e+004,3.500385e+002,-5.003803e-005,0.000000e+000,-2.248656e-001,0.000000e+000,3,0.000000e+000,1.825000e+000,,,,,,,,,,,,,,,,,,0,4.000000e+000,5.000000e-001,1,1,9.399414e-003,0,,0,