File: SQUID/22129_LCOT/22129_MH-2K.rso.dat
[Header]
TITLE,MPMS RSO Measurement
BYAPP,MPMS Measurement,1.1,Summary
FILEOPENTIME, 1662291436.392000 9/4/2022, 1:37:16 PM

INFO, APPNAME, MPMS MultiVu Application, Revision 1.61,  Build 082

INFO, NAME,
INFO, WEIGHT, 9.700
INFO, AREA, 1.000
INFO, LENGTH, 1.000
INFO, SHAPE,
INFO, COMMENT,
INFO, SEQUENCE FILE: M(H)-5t.seq


INFO, BACKGROUND DATA FILE:, None


STARTUPAXIS,X,4,LINEAR,AUTO,0.000000,0.000000
STARTUPAXIS,Y1,5,LINEAR,AUTO,0.000000,0.000000


STARTUPGROUP,Longitudinal
FIELDGROUP,Longitudinal,1,2,3,4,5,6,7,8,9,10,11,19,20,21,22,23,35
FIELDGROUP,Transverse,1,2,3,4,12,13,14,15,16,17,18,24,25,26,27,28,35

PLOT_APPEARANCE,ALL,HORZ_GRID_ON,VERT_GRID_ON,MARKERS_AND_LINES

[Data]
Time,Comment,Field (Oe),Temperature (K),Long Moment (emu),Long Scan Std Dev,Long Offset (cm),Long Offset Std Dev,Long Algorithm,Long Reg Fit,Long Reg Factor,Trans Moment (emu),Trans Scan Std Dev,Trans Offset (cm),Trans Offset Std Dev,Trans Algorithm,Trans Reg Fit,Trans Reg Factor,Long Moment [w/o ABS] (emu),Long Scan Std Dev [w/o ABS],Long Offset [w/o ABS] (cm),Long Offset Std Dev [w/o ABS],Long Reg Fit [w/o ABS],Trans Moment [w/o ABS] (emu),Trans Scan Std Dev [w/o ABS],Trans Offset [w/o ABS] (cm),Trans Offset Std Dev [w/o ABS],Trans Reg Fit [w/o ABS],RSO Position (deg),Amplitude (cm),Frequency,Cycles to Average,Scans per Measurement,Delta Temp (K),Error,EC Comp. Running,Using ABS,
1662291436.392,,-1.944960e+000,5.004856e+000,1.089258e-007,0.000000e+000,0.000000e+000,0.000000e+000,3,0.000000e+000,1.825000e+000,,,,,,,,,,,,,,,,,,0,4.000000e+000,5.000000e-001,1,1,1.865864e-003,0,,0,
1662292490.905,,5.984472e+001,1.999792e+000,1.484494e-005,0.000000e+000,1.710047e-001,0.000000e+000,3,8.319373e-001,1.825000e+000,,,,,,,,,,,,,,,,,,0,4.000000e+000,5.000000e-001,1,1,8.702278e-005,0,,0,
1662292671.936,,1.413831e+002,1.999705e+000,3.584909e-005,0.000000e+000,2.717009e-001,0.000000e+000,3,7.874705e-001,1.825000e+000,,,,,,,,,,,,,,,,,,0,4.000000e+000,5.000000e-001,1,1,4.940033e-004,0,,0,
1662292886.487,,2.010782e+002,2.000692e+000,5.069068e-005,0.000000e+000,2.597953e-001,0.000000e+000,3,7.925168e-001,1.825000e+000,,,,,,,,,,,,,,,,,,0,4.000000e+000,5.000000e-001,1,1,2.028942e-004,0,,0,
1662293132.777,,6.015892e+002,2.000198e+000,1.529703e-004,0.000000e+000,2.844267e-001,0.000000e+000,3,7.818119e-001,1.825000e+000,,,,,,,,,,,,,,,,,,0,4.000000e+000,5.000000e-001,1,1,8.702278e-005,0,,0,
1662293335.398,,9.527280e+002,2.000039e+000,2.423098e-004,0.000000e+000,2.893614e-001,0.000000e+000,3,7.752879e-001,1.825000e+000,,,,,,,,,,,,,,,,,,0,4.000000e+000,5.000000e-001,1,1,2.911091e-004,0,,0,
1662293583.580,,7.032054e+003,1.999908e+000,1.844495e-003,0.000000e+000,3.011577e-001,0.000000e+000,3,7.838749e-001,1.825000e+000,,,,,,,,,,,,,,,,,,0,4.000000e+000,5.000000e-001,1,1,6.098747e-004,0,,0,
1662293765.250,,1.405813e+004,2.000431e+000,3.486241e-003,0.000000e+000,3.070320e-001,0.000000e+000,3,7.697177e-001,1.825000e+000,,,,,,,,,,,,,,,,,,0,4.000000e+000,5.000000e-001,1,1,1.459122e-004,0,,0,
1662293955.601,,2.208569e+004,2.000214e+000,5.338685e-003,0.000000e+000,3.088457e-001,0.000000e+000,3,7.729774e-001,1.825000e+000,,,,,,,,,,,,,,,,,,0,4.000000e+000,5.000000e-001,1,1,4.650354e-004,0,,0,
1662294138.342,,2.910922e+004,2.000169e+000,6.716597e-003,0.000000e+000,3.110314e-001,0.000000e+000,3,7.681701e-001,1.825000e+000,,,,,,,,,,,,,,,,,,0,4.000000e+000,5.000000e-001,1,1,8.702278e-005,0,,0,
1662294328.652,,3.713664e+004,1.999980e+000,8.260557e-003,0.000000e+000,3.149797e-001,0.000000e+000,3,7.714972e-001,1.825000e+000,,,,,,,,,,,,,,,,,,0,4.000000e+000,5.000000e-001,1,1,3.489256e-004,0,,0,
1662294510.693,,4.415942e+004,2.000271e+000,9.344923e-003,0.000000e+000,3.184825e-001,0.000000e+000,3,7.665245e-001,1.825000e+000,,,,,,,,,,,,,,,,,,0,4.000000e+000,5.000000e-001,1,1,5.793571e-005,0,,0,
1662294701.604,,5.218758e+004,2.000126e+000,1.060640e-002,0.000000e+000,3.216026e-001,0.000000e+000,3,7.719551e-001,1.825000e+000,,,,,,,,,,,,,,,,,,0,4.000000e+000,5.000000e-001,1,1,3.479719e-004,0,,0,
1662294890.635,,5.921186e+004,2.000460e+000,1.141577e-002,0.000000e+000,3.259469e-001,0.000000e+000,3,7.671492e-001,1.825000e+000,,,,,,,,,,,,,,,,,,0,4.000000e+000,5.000000e-001,1,1,2.038479e-004,0,,0,
1662295080.714,,6.723705e+004,2.000082e+000,1.233442e-002,0.000000e+000,3.318100e-001,0.000000e+000,3,7.683006e-001,1.825000e+000,,,,,,,,,,,,,,,,,,0,4.000000e+000,5.000000e-001,1,1,8.678436e-005,0,,0,
1662295301.012,,6.722209e+004,2.000286e+000,1.227726e-002,0.000000e+000,3.314446e-001,0.000000e+000,3,7.701379e-001,1.825000e+000,,,,,,,,,,,,,,,,,,0,4.000000e+000,5.000000e-001,1,1,8.702278e-005,0,,0,
1662295492.793,,5.919690e+004,1.999835e+000,1.141079e-002,0.000000e+000,3.307003e-001,0.000000e+000,3,7.691482e-001,1.825000e+000,,,,,,,,,,,,,,,,,,0,4.000000e+000,5.000000e-001,1,1,4.070997e-004,0,,0,
1662295674.653,,5.217263e+004,1.999763e+000,1.052460e-002,0.000000e+000,3.283890e-001,0.000000e+000,3,7.702369e-001,1.825000e+000,,,,,,,,,,,,,,,,,,0,4.000000e+000,5.000000e-001,1,1,3.004074e-005,0,,0,
1662295864.235,,4.413923e+004,1.999995e+000,9.355106e-003,0.000000e+000,3.252965e-001,0.000000e+000,3,7.756221e-001,1.825000e+000,,,,,,,,,,,,,,,,,,0,4.000000e+000,5.000000e-001,1,1,3.780127e-004,0,,0,
1662296048.005,,3.712468e+004,2.000112e+000,8.205539e-003,0.000000e+000,3.231283e-001,0.000000e+000,3,7.704546e-001,1.825000e+000,,,,,,,,,,,,,,,,,,0,4.000000e+000,5.000000e-001,1,1,2.028942e-004,0,,0,
1662296238.546,,2.909576e+004,1.999879e+000,6.725921e-003,0.000000e+000,3.189799e-001,0.000000e+000,3,7.673637e-001,1.825000e+000,,,,,,,,,,,,,,,,,,0,4.000000e+000,5.000000e-001,1,1,3.200769e-004,0,,0,
1662296427.406,,2.207223e+004,2.000213e+000,5.299810e-003,0.000000e+000,3.160734e-001,0.000000e+000,3,7.722690e-001,1.825000e+000,,,,,,,,,,,,,,,,,,0,4.000000e+000,5.000000e-001,1,1,5.793571e-005,0,,0,
1662296618.157,,1.404556e+004,1.999995e+000,3.469029e-003,0.000000e+000,3.167091e-001,0.000000e+000,3,7.645178e-001,1.825000e+000,,,,,,,,,,,,,,,,,,0,4.000000e+000,5.000000e-001,1,1,2.608299e-004,0,,0,
1662296807.958,,7.020385e+003,2.000184e+000,1.776696e-003,0.000000e+000,3.097838e-001,0.000000e+000,3,7.722839e-001,1.825000e+000,,,,,,,,,,,,,,,,,,0,4.000000e+000,5.000000e-001,1,1,1.740456e-004,0,,0,
1662297098.720,,9.537751e+002,2.000315e+000,2.505742e-004,0.000000e+000,2.662556e-001,0.000000e+000,3,7.701633e-001,1.825000e+000,,,,,,,,,,,,,,,,,,0,4.000000e+000,5.000000e-001,1,1,2.620220e-004,0,,0,
1662297289.080,,6.027859e+002,2.000140e+000,1.476325e-004,0.000000e+000,2.951104e-001,0.000000e+000,3,7.598998e-001,1.825000e+000,,,,,,,,,,,,,,,,,,0,4.000000e+000,5.000000e-001,1,1,2.908707e-005,0,,0,
1662297558.761,,2.016768e+002,2.000184e+000,4.465245e-005,0.000000e+000,2.305841e-001,0.000000e+000,3,7.174820e-001,1.825000e+000,,,,,,,,,,,,,,,,,,0,4.000000e+000,5.000000e-001,1,1,2.319813e-004,0,,0,
1662297773.762,,1.421312e+002,2.000170e+000,3.172115e-005,0.000000e+000,2.808068e-001,0.000000e+000,3,6.545215e-001,1.825000e+000,,,,,,,,,,,,,,,,,,0,4.000000e+000,5.000000e-001,1,1,2.908707e-005,0,,0,
1662297989.562,,6.089201e+001,1.999981e+000,1.206966e-005,0.000000e+000,1.994051e-001,0.000000e+000,3,2.078962e-001,1.825000e+000,,,,,,,,,,,,,,,,,,0,4.000000e+000,5.000000e-001,1,1,2.319813e-004,0,,0,
1662298172.522,,-1.152010e+001,2.000372e+000,-7.381715e-006,0.000000e+000,8.127340e-001,0.000000e+000,3,4.695813e-001,1.825000e+000,,,,,,,,,,,,,,,,,,0,4.000000e+000,5.000000e-001,1,1,8.702278e-005,0,,0,
1662298382.035,,-9.081433e+001,2.000010e+000,-2.577571e-005,0.000000e+000,4.651199e-001,0.000000e+000,3,5.221283e-001,1.825000e+000,,,,,,,,,,,,,,,,,,0,4.000000e+000,5.000000e-001,1,1,1.740456e-004,0,,0,
1662298578.845,,-1.611319e+002,2.000372e+000,-4.356822e-005,0.000000e+000,3.734811e-001,0.000000e+000,3,7.136103e-001,1.825000e+000,,,,,,,,,,,,,,,,,,0,4.000000e+000,5.000000e-001,1,1,2.884865e-005,0,,0,
1662298830.845,,-3.523358e+002,2.000213e+000,-9.492099e-005,0.000000e+000,3.389183e-001,0.000000e+000,3,6.514748e-001,1.825000e+000,,,,,,,,,,,,,,,,,,0,4.000000e+000,5.000000e-001,1,1,2.319813e-004,0,,0,
1662299030.336,,-7.037740e+002,1.999981e+000,-1.803950e-004,0.000000e+000,3.395456e-001,0.000000e+000,3,7.358505e-001,1.825000e+000,,,,,,,,,,,,,,,,,,0,4.000000e+000,5.000000e-001,1,1,0.000000e+000,0,,0,
1662299287.867,,-2.013475e+003,2.000315e+000,-5.214976e-004,0.000000e+000,2.993267e-001,0.000000e+000,3,7.843583e-001,1.825000e+000,,,,,,,,,,,,,,,,,,0,4.000000e+000,5.000000e-001,1,1,8.702278e-005,0,,0,
1662299537.598,,-1.004943e+004,2.000039e+000,-2.571343e-003,0.000000e+000,3.116970e-001,0.000000e+000,3,7.771916e-001,1.825000e+000,,,,,,,,,,,,,,,,,,0,4.000000e+000,5.000000e-001,1,1,2.319813e-004,0,,0,
1662299718.560,,-1.707130e+004,2.000257e+000,-4.187853e-003,0.000000e+000,3.138321e-001,0.000000e+000,3,7.714895e-001,1.825000e+000,,,,,,,,,,,,,,,,,,0,4.000000e+000,5.000000e-001,1,1,8.702278e-005,0,,0,
1662299909.130,,-2.509888e+004,1.999894e+000,-5.996860e-003,0.000000e+000,3.171286e-001,0.000000e+000,3,7.762221e-001,1.825000e+000,,,,,,,,,,,,,,,,,,0,4.000000e+000,5.000000e-001,1,1,1.749992e-004,0,,0,
1662300090.210,,-3.211867e+004,2.000329e+000,-7.311326e-003,0.000000e+000,3.209316e-001,0.000000e+000,3,7.704327e-001,1.825000e+000,,,,,,,,,,,,,,,,,,0,4.000000e+000,5.000000e-001,1,1,5.817413e-005,0,,0,
1662300281.580,,-4.014684e+004,2.000126e+000,-8.804808e-003,0.000000e+000,3.238675e-001,0.000000e+000,3,7.743111e-001,1.825000e+000,,,,,,,,,,,,,,,,,,0,4.000000e+000,5.000000e-001,1,1,2.319813e-004,0,,0,
1662300464.752,,-4.716961e+004,2.000213e+000,-9.831752e-003,0.000000e+000,3.262220e-001,0.000000e+000,3,7.693406e-001,1.825000e+000,,,,,,,,,,,,,,,,,,0,4.000000e+000,5.000000e-001,1,1,5.793571e-005,0,,0,
1662300654.862,,-5.519628e+004,2.000227e+000,-1.100611e-002,0.000000e+000,3.283672e-001,0.000000e+000,3,7.719643e-001,1.825000e+000,,,,,,,,,,,,,,,,,,0,4.000000e+000,5.000000e-001,1,1,2.610683e-004,0,,0,
1662300834.803,,-6.222205e+004,2.000358e+000,-1.177594e-002,0.000000e+000,3.305134e-001,0.000000e+000,3,7.691318e-001,1.825000e+000,,,,,,,,,,,,,,,,,,0,4.000000e+000,5.000000e-001,1,1,1.161098e-004,0,,0,
1662301025.344,,-7.025022e+004,2.000257e+000,-1.249243e-002,0.000000e+000,3.424620e-001,0.000000e+000,3,7.763158e-001,1.825000e+000,,,,,,,,,,,,,,,,,,0,4.000000e+000,5.000000e-001,1,1,1.449585e-004,0,,0,
1662301243.975,,-6.421339e+004,2.000314e+000,-1.196142e-002,0.000000e+000,3.321406e-001,0.000000e+000,3,7.701308e-001,1.825000e+000,,,,,,,,,,,,,,,,,,0,4.000000e+000,5.000000e-001,1,1,2.908707e-005,0,,0,
1662301436.115,,-5.618671e+004,1.999879e+000,-1.106202e-002,0.000000e+000,3.303162e-001,0.000000e+000,3,7.710757e-001,1.825000e+000,,,,,,,,,,,,,,,,,,0,4.000000e+000,5.000000e-001,1,1,2.789497e-005,0,,0,
1662301620.576,,-4.916245e+004,2.000576e+000,-1.007175e-002,0.000000e+000,3.270985e-001,0.000000e+000,3,7.691213e-001,1.825000e+000,,,,,,,,,,,,,,,,,,0,4.000000e+000,5.000000e-001,1,1,8.678436e-005,0,,0,
1662301811.667,,-4.113576e+004,2.000372e+000,-8.867367e-003,0.000000e+000,3.238692e-001,0.000000e+000,3,7.690778e-001,1.825000e+000,,,,,,,,,,,,,,,,,,0,4.000000e+000,5.000000e-001,1,1,2.028942e-004,0,,0,
1662301992.548,,-3.411299e+004,2.000576e+000,-7.665572e-003,0.000000e+000,3.222479e-001,0.000000e+000,3,7.710739e-001,1.825000e+000,,,,,,,,,,,,,,,,,,0,4.000000e+000,5.000000e-001,1,1,1.449585e-004,0,,0,
1662302181.219,,-2.608557e+004,2.000490e+000,-6.011158e-003,0.000000e+000,3.155754e-001,0.000000e+000,3,7.592097e-001,1.825000e+000,,,,,,,,,,,,,,,,,,0,4.000000e+000,5.000000e-001,1,1,8.702278e-005,0,,0,
1662302362.069,,-1.906279e+004,1.999835e+000,-4.628361e-003,0.000000e+000,3.155870e-001,0.000000e+000,3,7.712164e-001,1.825000e+000,,,,,,,,,,,,,,,,,,0,4.000000e+000,5.000000e-001,1,1,0.000000e+000,0,,0,
1662302561.310,,-1.103477e+004,1.999966e+000,-2.753680e-003,0.000000e+000,3.126934e-001,0.000000e+000,3,7.639611e-001,1.825000e+000,,,,,,,,,,,,,,,,,,0,4.000000e+000,5.000000e-001,1,1,3.198385e-004,0,,0,
1662302799.850,,-4.007951e+003,2.000184e+000,-1.020993e-003,0.000000e+000,3.054964e-001,0.000000e+000,3,7.750799e-001,1.825000e+000,,,,,,,,,,,,,,,,,,0,4.000000e+000,5.000000e-001,1,1,0.000000e+000,0,,0,
1662303105.211,,-8.046122e+002,2.000039e+000,-2.034873e-004,0.000000e+000,2.941498e-001,0.000000e+000,3,7.392677e-001,1.825000e+000,,,,,,,,,,,,,,,,,,0,4.000000e+000,5.000000e-001,1,1,5.793571e-005,0,,0,
1662303294.493,,-4.522765e+002,2.000271e+000,-1.179641e-004,0.000000e+000,2.951634e-001,0.000000e+000,3,7.765483e-001,1.825000e+000,,,,,,,,,,,,,,,,,,0,4.000000e+000,5.000000e-001,1,1,0.000000e+000,0,,0,
1662303584.754,,-1.826760e+002,2.000271e+000,-7.049163e-005,0.000000e+000,0.000000e+000,0.000000e+000,3,0.000000e+000,1.825000e+000,,,,,,,,,,,,,,,,,,0,4.000000e+000,5.000000e-001,1,1,2.319813e-004,0,,0,
1662303844.444,,-1.129569e+002,1.999908e+000,-2.796651e-005,0.000000e+000,2.253424e-001,0.000000e+000,3,8.102222e-001,1.825000e+000,,,,,,,,,,,,,,,,,,0,4.000000e+000,5.000000e-001,1,1,1.460314e-004,0,,0,
1662304027.035,,-3.201693e+001,2.000010e+000,-1.159613e-005,0.000000e+000,-4.001376e-001,0.000000e+000,3,7.955544e-002,1.825000e+000,,,,,,,,,,,,,,,,,,0,4.000000e+000,5.000000e-001,1,1,1.740456e-004,0,,0,
1662304273.137,,4.248975e+001,2.000170e+000,1.414774e-005,0.000000e+000,4.389526e-001,0.000000e+000,3,6.294200e-001,1.825000e+000,,,,,,,,,,,,,,,,,,0,4.000000e+000,5.000000e-001,1,1,2.908707e-005,0,,0,
1662304490.108,,1.222329e+002,2.000053e+000,2.925829e-005,0.000000e+000,3.499653e-001,0.000000e+000,3,6.284400e-001,1.825000e+000,,,,,,,,,,,,,,,,,,0,4.000000e+000,5.000000e-001,1,1,8.702278e-005,0,,0,
1662304665.330,,1.925504e+002,2.000126e+000,5.274666e-005,0.000000e+000,3.455600e-001,0.000000e+000,3,7.681770e-001,1.825000e+000,,,,,,,,,,,,,,,,,,0,4.000000e+000,5.000000e-001,1,1,0.000000e+000,0,,0,
1662309852.547,,5.999434e+001,3.820221e+000,5.853865e-005,0.000000e+000,0.000000e+000,0.000000e+000,3,0.000000e+000,1.825000e+000,,,,,,,,,,,,,,,,,,0,4.000000e+000,5.000000e-001,1,1,1.779079e-003,0,,0,
1662310178.177,,1.307607e+002,3.867862e+000,2.785412e-005,0.000000e+000,3.585444e-001,0.000000e+000,3,7.383898e-001,1.825000e+000,,,,,,,,,,,,,,,,,,0,4.000000e+000,5.000000e-001,1,1,2.974987e-003,0,,0,
1662310485.957,,2.036216e+002,3.911490e+000,4.485900e-005,0.000000e+000,3.406791e-001,0.000000e+000,3,6.988161e-001,1.825000e+000,,,,,,,,,,,,,,,,,,0,4.000000e+000,5.000000e-001,1,1,2.250910e-003,0,,0,
1662310798.800,,5.535637e+002,3.947032e+000,1.071237e-004,0.000000e+000,3.018436e-001,0.000000e+000,3,7.538882e-001,1.825000e+000,,,,,,,,,,,,,,,,,,0,4.000000e+000,5.000000e-001,1,1,6.449223e-004,0,,0,
1662311000.491,,9.542242e+002,3.970590e+000,1.866495e-004,0.000000e+000,3.046145e-001,0.000000e+000,3,7.677225e-001,1.825000e+000,,,,,,,,,,,,,,,,,,0,4.000000e+000,5.000000e-001,1,1,3.750324e-004,0,,0,
1662311321.252,,6.027710e+003,4.004819e+000,1.176278e-003,0.000000e+000,3.124889e-001,0.000000e+000,3,7.679955e-001,1.825000e+000,,,,,,,,,,,,,,,,,,0,4.000000e+000,5.000000e-001,1,1,8.621216e-004,0,,0,
1662311533.262,,1.405693e+004,4.022924e+000,2.742061e-003,0.000000e+000,3.156623e-001,0.000000e+000,3,7.715260e-001,1.825000e+000,,,,,,,,,,,,,,,,,,0,4.000000e+000,5.000000e-001,1,1,2.899170e-004,0,,0,
1662311742.882,,2.108255e+004,4.041046e+000,4.009726e-003,0.000000e+000,3.193289e-001,0.000000e+000,3,7.661308e-001,1.825000e+000,,,,,,,,,,,,,,,,,,0,4.000000e+000,5.000000e-001,1,1,2.645969e-003,0,,0,
1662311950.945,,2.910773e+004,4.042663e+000,5.460746e-003,0.000000e+000,3.230599e-001,0.000000e+000,3,7.695571e-001,1.825000e+000,,,,,,,,,,,,,,,,,,0,4.000000e+000,5.000000e-001,1,1,2.354145e-003,0,,0,
1662312149.166,,3.613349e+004,4.047034e+000,6.596643e-003,0.000000e+000,3.260529e-001,0.000000e+000,3,7.659959e-001,1.825000e+000,,,,,,,,,,,,,,,,,,0,4.000000e+000,5.000000e-001,1,1,1.673222e-003,0,,0,
1662312360.516,,4.415792e+004,4.047772e+000,7.864829e-003,0.000000e+000,3.287066e-001,0.000000e+000,3,7.676916e-001,1.825000e+000,,,,,,,,,,,,,,,,,,0,4.000000e+000,5.000000e-001,1,1,2.360821e-003,0,,0,
1662312559.106,,5.118519e+004,4.056308e+000,8.841150e-003,0.000000e+000,3.304993e-001,0.000000e+000,3,7.653303e-001,1.825000e+000,,,,,,,,,,,,,,,,,,0,4.000000e+000,5.000000e-001,1,1,2.474308e-003,0,,0,
1662312763.757,,5.921037e+004,4.057249e+000,9.911157e-003,0.000000e+000,3.334987e-001,0.000000e+000,3,7.669451e-001,1.825000e+000,,,,,,,,,,,,,,,,,,0,4.000000e+000,5.000000e-001,1,1,3.563881e-003,0,,0,
1662312960.837,,6.623464e+004,4.057000e+000,1.068073e-002,0.000000e+000,3.344445e-001,0.000000e+000,3,7.649955e-001,1.825000e+000,,,,,,,,,,,,,,,,,,0,4.000000e+000,5.000000e-001,1,1,6.928444e-004,0,,0,
1662313216.949,,6.721609e+004,4.045117e+000,1.078485e-002,0.000000e+000,3.355916e-001,0.000000e+000,3,7.666991e-001,1.825000e+000,,,,,,,,,,,,,,,,,,0,4.000000e+000,5.000000e-001,1,1,2.554893e-003,0,,0,
1662313415.811,,6.019482e+004,4.043349e+000,9.982556e-003,0.000000e+000,3.333689e-001,0.000000e+000,3,7.658917e-001,1.825000e+000,,,,,,,,,,,,,,,,,,0,4.000000e+000,5.000000e-001,1,1,7.853508e-004,0,,0,
1662313629.121,,5.216664e+004,4.037718e+000,8.958380e-003,0.000000e+000,3.305857e-001,0.000000e+000,3,7.665106e-001,1.825000e+000,,,,,,,,,,,,,,,,,,0,4.000000e+000,5.000000e-001,1,1,2.834797e-003,0,,0,
1662313830.461,,4.514386e+004,4.036496e+000,7.973137e-003,0.000000e+000,3.282865e-001,0.000000e+000,3,7.665226e-001,1.825000e+000,,,,,,,,,,,,,,,,,,0,4.000000e+000,5.000000e-001,1,1,1.173019e-003,0,,0,
1662314043.091,,3.712393e+004,4.032982e+000,6.748233e-003,0.000000e+000,3.256760e-001,0.000000e+000,3,7.667589e-001,1.825000e+000,,,,,,,,,,,,,,,,,,0,4.000000e+000,5.000000e-001,1,1,3.314972e-003,0,,0,
1662314245.533,,3.009816e+004,4.033860e+000,5.584511e-003,0.000000e+000,3.229855e-001,0.000000e+000,3,7.664301e-001,1.825000e+000,,,,,,,,,,,,,,,,,,0,4.000000e+000,5.000000e-001,1,1,1.169682e-003,0,,0,
1662314459.574,,2.207148e+004,4.030838e+000,4.175278e-003,0.000000e+000,3.207223e-001,0.000000e+000,3,7.677925e-001,1.825000e+000,,,,,,,,,,,,,,,,,,0,4.000000e+000,5.000000e-001,1,1,2.531052e-003,0,,0,
1662314671.055,,1.505094e+004,4.032105e+000,2.882296e-003,0.000000e+000,3.164242e-001,0.000000e+000,3,7.680191e-001,1.825000e+000,,,,,,,,,,,,,,,,,,0,4.000000e+000,5.000000e-001,1,1,7.801056e-004,0,,0,
1662314886.036,,7.021132e+003,4.028553e+000,1.356883e-003,0.000000e+000,3.164070e-001,0.000000e+000,3,7.574416e-001,1.825000e+000,,,,,,,,,,,,,,,,,,0,4.000000e+000,5.000000e-001,1,1,2.820015e-003,0,,0,
1662315144.836,,1.005989e+003,4.025736e+000,1.937243e-004,0.000000e+000,2.921824e-001,0.000000e+000,3,7.785945e-001,1.825000e+000,,,,,,,,,,,,,,,,,,0,4.000000e+000,5.000000e-001,1,1,8.740425e-004,0,,0,
1662315387.796,,6.033845e+002,4.027242e+000,1.053900e-004,0.000000e+000,2.956739e-001,0.000000e+000,3,6.763508e-001,1.825000e+000,,,,,,,,,,,,,,,,,,0,4.000000e+000,5.000000e-001,1,1,3.496647e-003,0,,0,
1662315667.728,,2.522455e+002,4.032104e+000,4.189000e-005,0.000000e+000,2.579595e-001,0.000000e+000,3,6.972376e-001,1.825000e+000,,,,,,,,,,,,,,,,,,0,4.000000e+000,5.000000e-001,1,1,0.000000e+000,0,,0,
1662315938.640,,1.427297e+002,4.028310e+000,2.861219e-005,0.000000e+000,2.316150e-001,0.000000e+000,3,6.248410e-001,1.825000e+000,,,,,,,,,,,,,,,,,,0,4.000000e+000,5.000000e-001,1,1,7.767677e-004,0,,0,
1662316142.470,,7.166405e+001,4.029525e+000,9.927944e-006,0.000000e+000,1.763465e-001,0.000000e+000,3,3.636269e-001,1.825000e+000,,,,,,,,,,,,,,,,,,0,4.000000e+000,5.000000e-001,1,1,4.858971e-004,0,,0,
1662316452.791,,-1.196895e+001,4.035226e+000,4.392059e-007,0.000000e+000,1.133682e+000,0.000000e+000,3,0.000000e+000,1.825000e+000,,,,,,,,,,,,,,,,,,0,4.000000e+000,5.000000e-001,1,1,1.950264e-004,0,,0,
1662316781.132,,-8.034155e+001,4.039086e+000,-1.770223e-005,0.000000e+000,4.115835e-001,0.000000e+000,3,7.342890e-001,1.825000e+000,,,,,,,,,,,,,,,,,,0,4.000000e+000,5.000000e-001,1,1,9.679794e-005,0,,0,
1662317011.913,,-1.612815e+002,4.034056e+000,-3.755681e-005,0.000000e+000,4.026986e-001,0.000000e+000,3,6.541501e-001,1.825000e+000,,,,,,,,,,,,,,,,,,0,4.000000e+000,5.000000e-001,1,1,2.730846e-003,0,,0,
1662317289.895,,-3.037120e+002,4.029087e+000,-5.973079e-005,0.000000e+000,3.172540e-001,0.000000e+000,3,7.622949e-001,1.825000e+000,,,,,,,,,,,,,,,,,,0,4.000000e+000,5.000000e-001,1,1,1.940727e-004,0,,0,
1662317530.645,,-7.048213e+002,4.031374e+000,-1.385525e-004,0.000000e+000,2.981926e-001,0.000000e+000,3,7.634624e-001,1.825000e+000,,,,,,,,,,,,,,,,,,0,4.000000e+000,5.000000e-001,1,1,2.918243e-004,0,,0,
1662317776.456,,-1.004644e+003,4.025396e+000,-1.974757e-004,0.000000e+000,3.034990e-001,0.000000e+000,3,7.723510e-001,1.825000e+000,,,,,,,,,,,,,,,,,,0,4.000000e+000,5.000000e-001,1,1,1.940727e-004,0,,0,
1662318026.957,,-9.040144e+003,4.024767e+000,-1.768645e-003,0.000000e+000,3.143716e-001,0.000000e+000,3,7.706275e-001,1.825000e+000,,,,,,,,,,,,,,,,,,0,4.000000e+000,5.000000e-001,1,1,3.782272e-003,0,,0,
1662318230.727,,-1.606502e+004,4.028212e+000,-3.078192e-003,0.000000e+000,3.170331e-001,0.000000e+000,3,7.664545e-001,1.825000e+000,,,,,,,,,,,,,,,,,,0,4.000000e+000,5.000000e-001,1,1,1.165867e-003,0,,0,
1662318450.160,,-2.409498e+004,4.028456e+000,-4.583062e-003,0.000000e+000,3.205086e-001,0.000000e+000,3,7.701859e-001,1.825000e+000,,,,,,,,,,,,,,,,,,0,4.000000e+000,5.000000e-001,1,1,2.624989e-003,0,,0,
1662318653.620,,-3.111552e+004,4.031423e+000,-5.770165e-003,0.000000e+000,3.242651e-001,0.000000e+000,3,7.660558e-001,1.825000e+000,,,,,,,,,,,,,,,,,,0,4.000000e+000,5.000000e-001,1,1,5.841255e-004,0,,0,
1662318865.430,,-3.914294e+004,4.030936e+000,-7.122298e-003,0.000000e+000,3.270696e-001,0.000000e+000,3,7.687236e-001,1.825000e+000,,,,,,,,,,,,,,,,,,0,4.000000e+000,5.000000e-001,1,1,2.727032e-003,0,,0,
1662319065.190,,-4.616722e+004,4.033421e+000,-8.147008e-003,0.000000e+000,3.289258e-001,0.000000e+000,3,7.654867e-001,1.825000e+000,,,,,,,,,,,,,,,,,,0,4.000000e+000,5.000000e-001,1,1,1.268387e-003,0,,0,
1662319277.262,,-5.419389e+004,4.032740e+000,-9.302491e-003,0.000000e+000,3.316403e-001,0.000000e+000,3,7.676142e-001,1.825000e+000,,,,,,,,,,,,,,,,,,0,4.000000e+000,5.000000e-001,1,1,3.410816e-003,0,,0,
1662319477.212,,-6.121816e+004,4.035421e+000,-1.012900e-002,0.000000e+000,3.333560e-001,0.000000e+000,3,7.652940e-001,1.825000e+000,,,,,,,,,,,,,,,,,,0,4.000000e+000,5.000000e-001,1,1,5.860329e-004,0,,0,
1662319685.203,,-6.924484e+004,4.033714e+000,-1.106879e-002,0.000000e+000,3.357790e-001,0.000000e+000,3,7.685186e-001,1.825000e+000,,,,,,,,,,,,,,,,,,0,4.000000e+000,5.000000e-001,1,1,3.024101e-003,0,,0,
1662319933.715,,-6.521578e+004,4.032397e+000,-1.056725e-002,0.000000e+000,3.343694e-001,0.000000e+000,3,7.662056e-001,1.825000e+000,,,,,,,,,,,,,,,,,,0,4.000000e+000,5.000000e-001,1,1,9.760857e-004,0,,0,
1662320144.985,,-5.719062e+004,4.032641e+000,-9.636731e-003,0.000000e+000,3.324573e-001,0.000000e+000,3,7.669103e-001,1.825000e+000,,,,,,,,,,,,,,,,,,0,4.000000e+000,5.000000e-001,1,1,2.827168e-003,0,,0,
1662320347.925,,-5.016783e+004,4.035421e+000,-8.695032e-003,0.000000e+000,3.295211e-001,0.000000e+000,3,7.662398e-001,1.825000e+000,,,,,,,,,,,,,,,,,,0,4.000000e+000,5.000000e-001,1,1,1.366138e-003,0,,0,
1662320560.227,,-4.214266e+004,4.034543e+000,-7.531312e-003,0.000000e+000,3.272772e-001,0.000000e+000,3,7.667179e-001,1.825000e+000,,,,,,,,,,,,,,,,,,0,4.000000e+000,5.000000e-001,1,1,2.732277e-003,0,,0,
1662320762.437,,-3.511763e+004,4.036447e+000,-6.420965e-003,0.000000e+000,3.243488e-001,0.000000e+000,3,7.665499e-001,1.825000e+000,,,,,,,,,,,,,,,,,,0,4.000000e+000,5.000000e-001,1,1,8.792877e-004,0,,0,
1662320975.218,,-2.709395e+004,4.034396e+000,-5.121817e-003,0.000000e+000,3.248668e-001,0.000000e+000,3,7.682378e-001,1.825000e+000,,,,,,,,,,,,,,,,,,0,4.000000e+000,5.000000e-001,1,1,2.830029e-003,0,,0,
1662321180.209,,-2.006892e+004,4.035665e+000,-3.813230e-003,0.000000e+000,3.196273e-001,0.000000e+000,3,7.665313e-001,1.825000e+000,,,,,,,,,,,,,,,,,,0,4.000000e+000,5.000000e-001,1,1,6.837845e-004,0,,0,
1662321403.480,,-1.204076e+004,4.033031e+000,-2.327795e-003,0.000000e+000,3.180584e-001,0.000000e+000,3,7.711382e-001,1.825000e+000,,,,,,,,,,,,,,,,,,0,4.000000e+000,5.000000e-001,1,1,3.022194e-003,0,,0,
1662321605.391,,-5.014240e+003,4.033518e+000,-9.640186e-004,0.000000e+000,3.176064e-001,0.000000e+000,3,7.596563e-001,1.825000e+000,,,,,,,,,,,,,,,,,,0,4.000000e+000,5.000000e-001,1,1,1.462936e-003,0,,0,
1662321872.091,,-8.544330e+002,4.027484e+000,-1.578090e-004,0.000000e+000,2.916425e-001,0.000000e+000,3,6.968863e-001,1.825000e+000,,,,,,,,,,,,,,,,,,0,4.000000e+000,5.000000e-001,1,1,3.399849e-003,0,,0,
1662322121.053,,-5.025461e+002,4.033226e+000,-9.129821e-005,0.000000e+000,2.767015e-001,0.000000e+000,3,7.464985e-001,1.825000e+000,,,,,,,,,,,,,,,,,,0,4.000000e+000,5.000000e-001,1,1,1.071930e-003,0,,0,
1662322396.134,,-1.921016e+002,4.028067e+000,-3.850652e-005,0.000000e+000,1.807487e-001,0.000000e+000,3,8.426484e-001,1.825000e+000,,,,,,,,,,,,,,,,,,0,4.000000e+000,5.000000e-001,1,1,2.429962e-003,0,,0,
1662322602.104,,-1.217840e+002,4.030498e+000,-2.113248e-005,0.000000e+000,1.753744e-001,0.000000e+000,3,7.369303e-001,1.825000e+000,,,,,,,,,,,,,,,,,,0,4.000000e+000,5.000000e-001,1,1,1.266003e-003,0,,0,
1662322837.876,,-4.189131e+001,4.031764e+000,-3.985949e-006,0.000000e+000,-5.156887e-001,0.000000e+000,3,2.797856e-001,1.825000e+000,,,,,,,,,,,,,,,,,,0,4.000000e+000,5.000000e-001,1,1,3.213882e-003,0,,0,
1662323070.796,,3.246576e+001,4.034640e+000,7.514665e-006,0.000000e+000,7.723093e-001,0.000000e+000,3,2.381823e-001,1.825000e+000,,,,,,,,,,,,,,,,,,0,4.000000e+000,5.000000e-001,1,1,3.900528e-004,0,,0,
1662323335.157,,1.132561e+002,4.036544e+000,2.674924e-005,0.000000e+000,3.257924e-001,0.000000e+000,3,7.292131e-001,1.825000e+000,,,,,,,,,,,,,,,,,,0,4.000000e+000,5.000000e-001,1,1,8.797646e-004,0,,0,
1662323533.209,,1.820775e+002,4.034835e+000,3.645661e-005,0.000000e+000,3.390536e-001,0.000000e+000,3,7.555252e-001,1.825000e+000,,,,,,,,,,,,,,,,,,0,4.000000e+000,5.000000e-001,1,1,7.810593e-004,0,,0,
1662327546.181,,4.922228e+001,4.043154e+000,1.142331e-005,0.000000e+000,3.897466e-001,0.000000e+000,3,6.830230e-001,1.825000e+000,,,,,,,,,,,,,,,,,,0,4.000000e+000,5.000000e-001,1,1,1.570225e-003,0,,0,
1662327741.363,,1.202879e+002,4.051664e+000,2.478791e-005,0.000000e+000,3.469562e-001,0.000000e+000,3,7.485065e-001,1.825000e+000,,,,,,,,,,,,,,,,,,0,4.000000e+000,5.000000e-001,1,1,4.940033e-004,0,,0,
1662327957.154,,2.018264e+002,4.058288e+000,4.142697e-005,0.000000e+000,3.368420e-001,0.000000e+000,3,7.599626e-001,1.825000e+000,,,,,,,,,,,,,,,,,,0,4.000000e+000,5.000000e-001,1,1,1.287937e-003,0,,0,
1662328207.934,,5.028453e+002,4.054726e+000,1.012944e-004,0.000000e+000,3.066596e-001,0.000000e+000,3,7.787018e-001,1.825000e+000,,,,,,,,,,,,,,,,,,0,4.000000e+000,5.000000e-001,1,1,9.918213e-005,0,,0,
1662328411.815,,9.056003e+002,4.051320e+000,1.785203e-004,0.000000e+000,2.917241e-001,0.000000e+000,3,7.836741e-001,1.825000e+000,,,,,,,,,,,,,,,,,,0,4.000000e+000,5.000000e-001,1,1,3.353119e-003,0,,0,
1662328706.056,,6.027411e+003,4.043007e+000,1.201780e-003,0.000000e+000,3.097390e-001,0.000000e+000,3,7.728733e-001,1.825000e+000,,,,,,,,,,,,,,,,,,0,4.000000e+000,5.000000e-001,1,1,3.042221e-003,0,,0,
1662328911.747,,1.305513e+004,4.043154e+000,2.507200e-003,0.000000e+000,3.150447e-001,0.000000e+000,3,7.665862e-001,1.825000e+000,,,,,,,,,,,,,,,,,,0,4.000000e+000,5.000000e-001,1,1,1.372814e-003,0,,0,
1662329125.458,,2.108105e+004,4.039234e+000,4.022584e-003,0.000000e+000,3.182833e-001,0.000000e+000,3,7.694052e-001,1.825000e+000,,,,,,,,,,,,,,,,,,0,4.000000e+000,5.000000e-001,1,1,3.327847e-003,0,,0,
1662329335.839,,2.810832e+004,4.041927e+000,5.246542e-003,0.000000e+000,3.220099e-001,0.000000e+000,3,7.658771e-001,1.825000e+000,,,,,,,,,,,,,,,,,,0,4.000000e+000,5.000000e-001,1,1,1.079082e-003,0,,0,
1662329546.691,,3.613574e+004,4.039381e+000,6.641189e-003,0.000000e+000,3.239177e-001,0.000000e+000,3,7.708911e-001,1.825000e+000,,,,,,,,,,,,,,,,,,0,4.000000e+000,5.000000e-001,1,1,2.840042e-003,0,,0,
1662329749.571,,4.315553e+004,4.041879e+000,7.697164e-003,0.000000e+000,3.280563e-001,0.000000e+000,3,7.660002e-001,1.825000e+000,,,,,,,,,,,,,,,,,,0,4.000000e+000,5.000000e-001,1,1,7.853508e-004,0,,0,
1662329960.332,,5.118369e+004,4.039968e+000,8.890807e-003,0.000000e+000,3.310524e-001,0.000000e+000,3,7.675043e-001,1.825000e+000,,,,,,,,,,,,,,,,,,0,4.000000e+000,5.000000e-001,1,1,3.818989e-003,0,,0,
1662330158.942,,5.820946e+004,4.042124e+000,9.769465e-003,0.000000e+000,3.325800e-001,0.000000e+000,3,7.658868e-001,1.825000e+000,,,,,,,,,,,,,,,,,,0,4.000000e+000,5.000000e-001,1,1,1.471043e-003,0,,0,
1662330367.144,,6.623763e+004,4.040507e+000,1.075188e-002,0.000000e+000,3.351389e-001,0.000000e+000,3,7.686924e-001,1.825000e+000,,,,,,,,,,,,,,,,,,0,4.000000e+000,5.000000e-001,1,1,3.527164e-003,0,,0,
1662330616.084,,6.821850e+004,4.038402e+000,1.089951e-002,0.000000e+000,3.361473e-001,0.000000e+000,3,7.662079e-001,1.825000e+000,,,,,,,,,,,,,,,,,,0,4.000000e+000,5.000000e-001,1,1,1.663208e-003,0,,0,
1662330827.156,,6.019482e+004,4.038599e+000,1.000362e-002,0.000000e+000,3.341338e-001,0.000000e+000,3,7.671409e-001,1.825000e+000,,,,,,,,,,,,,,,,,,0,4.000000e+000,5.000000e-001,1,1,3.621101e-003,0,,0,
1662331032.106,,5.317055e+004,4.041682e+000,9.080465e-003,0.000000e+000,3.346361e-001,0.000000e+000,3,7.623373e-001,1.825000e+000,,,,,,,,,,,,,,,,,,0,4.000000e+000,5.000000e-001,1,1,9.799004e-004,0,,0,
1662331242.306,,4.514237e+004,4.040459e+000,7.976971e-003,0.000000e+000,3.290789e-001,0.000000e+000,3,7.666548e-001,1.825000e+000,,,,,,,,,,,,,,,,,,0,4.000000e+000,5.000000e-001,1,1,4.017353e-003,0,,0,
1662331448.528,,3.812409e+004,4.042565e+000,6.896233e-003,0.000000e+000,3.260505e-001,0.000000e+000,3,7.660696e-001,1.825000e+000,,,,,,,,,,,,,,,,,,0,4.000000e+000,5.000000e-001,1,1,0.000000e+000,0,,0,
1662331660.569,,3.009891e+004,4.039870e+000,5.590684e-003,0.000000e+000,3.231732e-001,0.000000e+000,3,7.676527e-001,1.825000e+000,,,,,,,,,,,,,,,,,,0,4.000000e+000,5.000000e-001,1,1,3.035069e-003,0,,0,
1662331866.129,,2.307538e+004,4.041192e+000,4.358032e-003,0.000000e+000,3.201826e-001,0.000000e+000,3,7.674401e-001,1.825000e+000,,,,,,,,,,,,,,,,,,0,4.000000e+000,5.000000e-001,1,1,9.799004e-004,0,,0,
1662332085.270,,1.505035e+004,4.037522e+000,2.874932e-003,0.000000e+000,3.196684e-001,0.000000e+000,3,7.635777e-001,1.825000e+000,,,,,,,,,,,,,,,,,,0,4.000000e+000,5.000000e-001,1,1,3.225803e-003,0,,0,
1662332289.331,,8.023980e+003,4.037521e+000,1.547704e-003,0.000000e+000,3.139093e-001,0.000000e+000,3,7.672248e-001,1.825000e+000,,,,,,,,,,,,,,,,,,0,4.000000e+000,5.000000e-001,1,1,1.467228e-003,0,,0,
1662332554.071,,1.006439e+003,4.031812e+000,1.937478e-004,0.000000e+000,2.915849e-001,0.000000e+000,3,7.775100e-001,1.825000e+000,,,,,,,,,,,,,,,,,,0,4.000000e+000,5.000000e-001,1,1,0.000000e+000,0,,0,
1662332778.173,,6.550005e+002,4.034738e+000,1.244628e-004,0.000000e+000,2.958705e-001,0.000000e+000,3,7.380060e-001,1.825000e+000,,,,,,,,,,,,,,,,,,0,4.000000e+000,5.000000e-001,1,1,3.910065e-004,0,,0,
1662332973.824,,2.520959e+002,4.034396e+000,-2.236538e-005,0.000000e+000,-1.042039e+000,0.000000e+000,3,0.000000e+000,1.825000e+000,,,,,,,,,,,,,,,,,,0,4.000000e+000,5.000000e-001,1,1,2.830029e-003,0,,0,
1662333255.094,,1.523048e+002,4.034103e+000,2.686232e-005,0.000000e+000,1.715348e-001,0.000000e+000,3,6.591182e-001,1.825000e+000,,,,,,,,,,,,,,,,,,0,4.000000e+000,5.000000e-001,1,1,9.679794e-005,0,,0,
1662333467.505,,7.196327e+001,4.033080e+000,8.547925e-006,0.000000e+000,-5.460323e-001,0.000000e+000,3,0.000000e+000,1.825000e+000,,,,,,,,,,,,,,,,,,0,4.000000e+000,5.000000e-001,1,1,2.729893e-003,0,,0,
1662333680.476,,2.393787e+000,4.036446e+000,-2.546671e-006,0.000000e+000,1.061695e+000,0.000000e+000,3,0.000000e+000,1.825000e+000,,,,,,,,,,,,,,,,,,0,4.000000e+000,5.000000e-001,1,1,6.837845e-004,0,,0,
1662333907.037,,-8.064079e+001,4.034739e+000,-1.758575e-005,0.000000e+000,4.282923e-001,0.000000e+000,3,6.359385e-001,1.825000e+000,,,,,,,,,,,,,,,,,,0,4.000000e+000,5.000000e-001,1,1,2.926826e-003,0,,0,
1662334128.858,,-1.515567e+002,4.037229e+000,-3.369178e-005,0.000000e+000,3.182638e-001,0.000000e+000,3,7.642039e-001,1.825000e+000,,,,,,,,,,,,,,,,,,0,4.000000e+000,5.000000e-001,1,1,1.661301e-003,0,,0,
1662334420.859,,-3.029639e+002,4.032301e+000,-6.255159e-005,0.000000e+000,3.253971e-001,0.000000e+000,3,5.783876e-001,1.825000e+000,,,,,,,,,,,,,,,,,,0,4.000000e+000,5.000000e-001,1,1,3.509045e-003,0,,0,
1662334638.970,,-6.545516e+002,4.034738e+000,-1.289752e-004,0.000000e+000,3.095363e-001,0.000000e+000,3,7.640750e-001,1.825000e+000,,,,,,,,,,,,,,,,,,0,4.000000e+000,5.000000e-001,1,1,1.171112e-003,0,,0,
1662334889.598,,-1.004045e+003,4.028845e+000,-1.961542e-004,0.000000e+000,3.027587e-001,0.000000e+000,3,7.685277e-001,1.825000e+000,,,,,,,,,,,,,,,,,,0,4.000000e+000,5.000000e-001,1,1,3.596783e-003,0,,0,
1662335147.677,,-9.040742e+003,4.029136e+000,-1.768694e-003,0.000000e+000,3.118251e-001,0.000000e+000,3,7.734159e-001,1.825000e+000,,,,,,,,,,,,,,,,,,0,4.000000e+000,5.000000e-001,1,1,2.820015e-003,0,,0,
1662335349.769,,-1.606471e+004,4.032396e+000,-3.074221e-003,0.000000e+000,3.153951e-001,0.000000e+000,3,7.662111e-001,1.825000e+000,,,,,,,,,,,,,,,,,,0,4.000000e+000,5.000000e-001,1,1,1.168728e-003,0,,0,
1662335569.729,,-2.409273e+004,4.033178e+000,-4.564300e-003,0.000000e+000,3.190687e-001,0.000000e+000,3,7.681089e-001,1.825000e+000,,,,,,,,,,,,,,,,,,0,4.000000e+000,5.000000e-001,1,1,3.509998e-003,0,,0,
1662335771.479,,-3.111552e+004,4.036398e+000,-5.765579e-003,0.000000e+000,3.225746e-001,0.000000e+000,3,7.653849e-001,1.825000e+000,,,,,,,,,,,,,,,,,,0,4.000000e+000,5.000000e-001,1,1,5.869865e-004,0,,0,
1662335981.881,,-3.914519e+004,4.035421e+000,-7.128927e-003,0.000000e+000,3.266080e-001,0.000000e+000,3,7.697272e-001,1.825000e+000,,,,,,,,,,,,,,,,,,0,4.000000e+000,5.000000e-001,1,1,2.929211e-003,0,,0,
1662336181.331,,-4.616871e+004,4.038597e+000,-8.143885e-003,0.000000e+000,3.288741e-001,0.000000e+000,3,7.653527e-001,1.825000e+000,,,,,,,,,,,,,,,,,,0,4.000000e+000,5.000000e-001,1,1,1.272202e-003,0,,0,
1662336389.692,,-5.419389e+004,4.036789e+000,-9.287920e-003,0.000000e+000,3.312292e-001,0.000000e+000,3,7.672247e-001,1.825000e+000,,,,,,,,,,,,,,,,,,0,4.000000e+000,5.000000e-001,1,1,3.321648e-003,0,,0,
1662336589.083,,-6.121816e+004,4.039135e+000,-1.012617e-002,0.000000e+000,3.336222e-001,0.000000e+000,3,7.650570e-001,1.825000e+000,,,,,,,,,,,,,,,,,,0,4.000000e+000,5.000000e-001,1,1,7.829666e-004,0,,0,
1662336798.044,,-6.924484e+004,4.037522e+000,-1.104616e-002,0.000000e+000,3.359366e-001,0.000000e+000,3,7.677205e-001,1.825000e+000,,,,,,,,,,,,,,,,,,0,4.000000e+000,5.000000e-001,1,1,3.422260e-003,0,,0,
1662337046.405,,-6.521728e+004,4.035910e+000,-1.056703e-002,0.000000e+000,3.344436e-001,0.000000e+000,3,7.663119e-001,1.825000e+000,,,,,,,,,,,,,,,,,,0,4.000000e+000,5.000000e-001,1,1,7.810593e-004,0,,0,
1662337258.115,,-5.719361e+004,4.035275e+000,-9.625357e-003,0.000000e+000,3.326629e-001,0.000000e+000,3,7.665313e-001,1.825000e+000,,,,,,,,,,,,,,,,,,0,4.000000e+000,5.000000e-001,1,1,3.221989e-003,0,,0,
1662337461.956,,-5.016784e+004,4.038989e+000,-8.606474e-003,0.000000e+000,3.272097e-001,0.000000e+000,3,7.591394e-001,1.825000e+000,,,,,,,,,,,,,,,,,,0,4.000000e+000,5.000000e-001,1,1,6.847382e-004,0,,0,
1662337674.207,,-4.214341e+004,4.037327e+000,-7.520263e-003,0.000000e+000,3.287450e-001,0.000000e+000,3,7.671874e-001,1.825000e+000,,,,,,,,,,,,,,,,,,0,4.000000e+000,5.000000e-001,1,1,3.812313e-003,0,,0,
1662337878.208,,-3.511913e+004,4.038940e+000,-6.416867e-003,0.000000e+000,3.248222e-001,0.000000e+000,3,7.663649e-001,1.825000e+000,,,,,,,,,,,,,,,,,,0,4.000000e+000,5.000000e-001,1,1,1.369953e-003,0,,0,
1662338093.248,,-2.709395e+004,4.036790e+000,-5.059322e-003,0.000000e+000,3.211325e-001,0.000000e+000,3,7.659844e-001,1.825000e+000,,,,,,,,,,,,,,,,,,0,4.000000e+000,5.000000e-001,1,1,3.713131e-003,0,,0,
1662338295.629,,-2.006967e+004,4.037815e+000,-3.813717e-003,0.000000e+000,3.192811e-001,0.000000e+000,3,7.666123e-001,1.825000e+000,,,,,,,,,,,,,,,,,,0,4.000000e+000,5.000000e-001,1,1,1.075745e-003,0,,0,
1662338520.950,,-1.204285e+004,4.035031e+000,-2.312873e-003,0.000000e+000,3.159891e-001,0.000000e+000,3,7.659469e-001,1.825000e+000,,,,,,,,,,,,,,,,,,0,4.000000e+000,5.000000e-001,1,1,3.512859e-003,0,,0,
1662338724.950,,-5.014240e+003,4.035275e+000,-9.663100e-004,0.000000e+000,3.139532e-001,0.000000e+000,3,7.652380e-001,1.825000e+000,,,,,,,,,,,,,,,,,,0,4.000000e+000,5.000000e-001,1,1,9.727478e-005,0,,0,
1662338999.502,,-8.547323e+002,4.028845e+000,-1.600990e-004,0.000000e+000,3.098834e-001,0.000000e+000,3,7.224681e-001,1.825000e+000,,,,,,,,,,,,,,,,,,0,4.000000e+000,5.000000e-001,1,1,3.014088e-003,0,,0,
1662339250.183,,-5.025460e+002,4.035567e+000,-9.405050e-005,0.000000e+000,2.865829e-001,0.000000e+000,3,7.624178e-001,1.825000e+000,,,,,,,,,,,,,,,,,,0,4.000000e+000,5.000000e-001,1,1,1.074314e-003,0,,0,
1662339545.915,,-1.922512e+002,4.030693e+000,-3.278720e-005,0.000000e+000,2.053972e-001,0.000000e+000,3,7.597785e-001,1.825000e+000,,,,,,,,,,,,,,,,,,0,4.000000e+000,5.000000e-001,1,1,3.407001e-003,0,,0,
1662339749.385,,-1.216344e+002,4.032495e+000,-2.050618e-005,0.000000e+000,3.965338e-001,0.000000e+000,3,5.182582e-002,1.825000e+000,,,,,,,,,,,,,,,,,,0,4.000000e+000,5.000000e-001,1,1,3.900528e-004,0,,0,
1662339976.895,,-4.189131e+001,4.032544e+000,-7.911684e-007,0.000000e+000,0.000000e+000,0.000000e+000,3,0.000000e+000,1.825000e+000,,,,,,,,,,,,,,,,,,0,4.000000e+000,5.000000e-001,1,1,3.801823e-003,0,,0,
1662340180.166,,3.261538e+001,4.032885e+000,7.980707e-006,0.000000e+000,6.162218e-001,0.000000e+000,3,2.972844e-001,1.825000e+000,,,,,,,,,,,,,,,,,,0,4.000000e+000,5.000000e-001,1,1,5.850792e-004,0,,0,
1662340422.098,,1.131066e+002,4.034006e+000,2.162753e-005,0.000000e+000,4.223601e-001,0.000000e+000,3,6.405662e-001,1.825000e+000,,,,,,,,,,,,,,,,,,0,4.000000e+000,5.000000e-001,1,1,3.219128e-003,0,,0,
1662340629.588,,1.822271e+002,4.035665e+000,3.593513e-005,0.000000e+000,3.672372e-001,0.000000e+000,3,6.041911e-001,1.825000e+000,,,,,,,,,,,,,,,,,,0,4.000000e+000,5.000000e-001,1,1,4.882813e-004,0,,0,
1662344652.830,,4.473393e+001,4.044479e+000,1.064245e-005,0.000000e+000,4.053678e-001,0.000000e+000,3,6.998441e-001,1.825000e+000,,,,,,,,,,,,,,,,,,0,4.000000e+000,5.000000e-001,1,1,2.258778e-003,0,,0,
1662344883.690,,1.168468e+002,4.055764e+000,2.363759e-005,0.000000e+000,3.522048e-001,0.000000e+000,3,7.475716e-001,1.825000e+000,,,,,,,,,,,,,,,,,,0,4.000000e+000,5.000000e-001,1,1,1.386166e-003,0,,0,
1662345129.461,,1.980860e+002,4.060717e+000,3.946976e-005,0.000000e+000,3.309212e-001,0.000000e+000,3,7.559991e-001,1.825000e+000,,,,,,,,,,,,,,,,,,0,4.000000e+000,5.000000e-001,1,1,9.918213e-004,0,,0,
1662345415.712,,5.020973e+002,4.055121e+000,9.902419e-005,0.000000e+000,2.996200e-001,0.000000e+000,3,7.680828e-001,1.825000e+000,,,,,,,,,,,,,,,,,,0,4.000000e+000,5.000000e-001,1,1,8.897781e-004,0,,0,
1662345640.963,,9.047025e+002,4.050530e+000,1.760606e-004,0.000000e+000,3.024686e-001,0.000000e+000,3,7.629035e-001,1.825000e+000,,,,,,,,,,,,,,,,,,0,4.000000e+000,5.000000e-001,1,1,3.549099e-003,0,,0,
1662345926.404,,5.022168e+003,4.042124e+000,9.759761e-004,0.000000e+000,3.118428e-001,0.000000e+000,3,7.680742e-001,1.825000e+000,,,,,,,,,,,,,,,,,,0,4.000000e+000,5.000000e-001,1,1,9.679794e-005,0,,0,
1662346138.735,,1.305483e+004,4.037571e+000,2.533163e-003,0.000000e+000,3.137951e-001,0.000000e+000,3,7.707832e-001,1.825000e+000,,,,,,,,,,,,,,,,,,0,4.000000e+000,5.000000e-001,1,1,3.128052e-003,0,,0,
1662346341.706,,2.007790e+004,4.038989e+000,3.813297e-003,0.000000e+000,3.182891e-001,0.000000e+000,3,7.656772e-001,1.825000e+000,,,,,,,,,,,,,,,,,,0,4.000000e+000,5.000000e-001,1,1,1.467705e-003,0,,0,
1662346560.416,,2.810532e+004,4.037327e+000,5.275034e-003,0.000000e+000,3.217520e-001,0.000000e+000,3,7.689976e-001,1.825000e+000,,,,,,,,,,,,,,,,,,0,4.000000e+000,5.000000e-001,1,1,3.225803e-003,0,,0,
1662346766.217,,3.512811e+004,4.039135e+000,6.433974e-003,0.000000e+000,3.253523e-001,0.000000e+000,3,7.659335e-001,1.825000e+000,,,,,,,,,,,,,,,,,,0,4.000000e+000,5.000000e-001,1,1,7.829666e-004,0,,0,
1662346975.019,,4.315777e+004,4.037718e+000,7.732765e-003,0.000000e+000,3.279382e-001,0.000000e+000,3,7.684599e-001,1.825000e+000,,,,,,,,,,,,,,,,,,0,4.000000e+000,5.000000e-001,1,1,3.422260e-003,0,,0,
1662347172.109,,5.018280e+004,4.040409e+000,8.715566e-003,0.000000e+000,3.302906e-001,0.000000e+000,3,7.652858e-001,1.825000e+000,,,,,,,,,,,,,,,,,,0,4.000000e+000,5.000000e-001,1,1,1.566887e-003,0,,0,
1662347380.610,,5.820796e+004,4.039235e+000,9.810550e-003,0.000000e+000,3.327524e-001,0.000000e+000,3,7.678064e-001,1.825000e+000,,,,,,,,,,,,,,,,,,0,4.000000e+000,5.000000e-001,1,1,3.132820e-003,0,,0,
1662347582.071,,6.522925e+004,4.041829e+000,1.059061e-002,0.000000e+000,3.351845e-001,0.000000e+000,3,7.656901e-001,1.825000e+000,,,,,,,,,,,,,,,,,,0,4.000000e+000,5.000000e-001,1,1,9.822845e-005,0,,0,
1662347836.771,,6.821849e+004,4.035520e+000,1.090771e-002,0.000000e+000,3.364204e-001,0.000000e+000,3,7.668512e-001,1.825000e+000,,,,,,,,,,,,,,,,,,0,4.000000e+000,5.000000e-001,1,1,3.125191e-003,0,,0,
1662348040.281,,6.120021e+004,4.039527e+000,1.011817e-002,0.000000e+000,3.338760e-001,0.000000e+000,3,7.662721e-001,1.825000e+000,,,,,,,,,,,,,,,,,,0,4.000000e+000,5.000000e-001,1,1,7.839203e-004,0,,0,
1662348250.084,,5.317204e+004,4.038844e+000,9.107172e-003,0.000000e+000,3.319551e-001,0.000000e+000,3,7.666628e-001,1.825000e+000,,,,,,,,,,,,,,,,,,0,4.000000e+000,5.000000e-001,1,1,4.304886e-003,0,,0,
1662348454.384,,4.614777e+004,4.040947e+000,8.120830e-003,0.000000e+000,3.293880e-001,0.000000e+000,3,7.665855e-001,1.825000e+000,,,,,,,,,,,,,,,,,,0,4.000000e+000,5.000000e-001,1,1,1.274109e-003,0,,0,
1662348672.375,,3.812483e+004,4.039284e+000,6.907226e-003,0.000000e+000,3.268180e-001,0.000000e+000,3,7.667375e-001,1.825000e+000,,,,,,,,,,,,,,,,,,0,4.000000e+000,5.000000e-001,1,1,4.012585e-003,0,,0,
1662348875.376,,3.110280e+004,4.040408e+000,5.756027e-003,0.000000e+000,3.234833e-001,0.000000e+000,3,7.671456e-001,1.825000e+000,,,,,,,,,,,,,,,,,,0,4.000000e+000,5.000000e-001,1,1,1.370907e-003,0,,0,
1662349086.246,,2.307612e+004,4.037425e+000,4.340375e-003,0.000000e+000,3.212708e-001,0.000000e+000,3,7.633793e-001,1.825000e+000,,,,,,,,,,,,,,,,,,0,4.000000e+000,5.000000e-001,1,1,3.030777e-003,0,,0,
1662349295.326,,1.605395e+004,4.038450e+000,3.070713e-003,0.000000e+000,3.183109e-001,0.000000e+000,3,7.668735e-001,1.825000e+000,,,,,,,,,,,,,,,,,,0,4.000000e+000,5.000000e-001,1,1,9.789467e-004,0,,0,
1662349512.109,,8.023680e+003,4.033812e+000,1.535493e-003,0.000000e+000,3.166471e-001,0.000000e+000,3,7.610371e-001,1.825000e+000,,,,,,,,,,,,,,,,,,0,4.000000e+000,5.000000e-001,1,1,3.608704e-003,0,,0,
1662349714.819,,9.988081e+002,4.033372e+000,1.989648e-004,0.000000e+000,3.028067e-001,0.000000e+000,3,7.589331e-001,1.825000e+000,,,,,,,,,,,,,,,,,,0,4.000000e+000,5.000000e-001,1,1,1.754761e-003,0,,0,
1662349981.970,,6.545516e+002,4.028650e+000,1.138953e-004,0.000000e+000,2.554674e-001,0.000000e+000,3,5.613413e-001,1.825000e+000,,,,,,,,,,,,,,,,,,0,4.000000e+000,5.000000e-001,1,1,3.207684e-003,0,,0,
1662350201.880,,3.035624e+002,4.032641e+000,5.924699e-005,0.000000e+000,2.766893e-001,0.000000e+000,3,7.545256e-001,1.825000e+000,,,,,,,,,,,,,,,,,,0,4.000000e+000,5.000000e-001,1,1,1.267910e-003,0,,0,
1662350460.771,,1.521552e+002,4.028699e+000,2.361460e-005,0.000000e+000,1.818536e-001,0.000000e+000,3,6.656399e-001,1.825000e+000,,,,,,,,,,,,,,,,,,0,4.000000e+000,5.000000e-001,1,1,3.499985e-003,0,,0,
1662350679.343,,8.123917e+001,4.034104e+000,1.491507e-005,0.000000e+000,1.419405e-001,0.000000e+000,3,7.051672e-001,1.825000e+000,,,,,,,,,,,,,,,,,,0,4.000000e+000,5.000000e-001,1,1,1.657963e-003,0,,0,
1662350906.223,,2.393787e+000,4.034494e+000,1.911530e-006,0.000000e+000,1.217262e+000,0.000000e+000,3,0.000000e+000,1.825000e+000,,,,,,,,,,,,,,,,,,0,4.000000e+000,5.000000e-001,1,1,3.026009e-003,0,,0,
1662351106.135,,-7.151445e+001,4.036056e+000,-2.067303e-005,0.000000e+000,4.128306e-001,0.000000e+000,3,7.120568e-001,1.825000e+000,,,,,,,,,,,,,,,,,,0,4.000000e+000,5.000000e-001,1,1,1.073837e-003,0,,0,
1662351322.845,,-1.514072e+002,4.034786e+000,-3.087890e-005,0.000000e+000,3.795337e-001,0.000000e+000,3,6.070214e-001,1.825000e+000,,,,,,,,,,,,,,,,,,0,4.000000e+000,5.000000e-001,1,1,2.830982e-003,0,,0,
1662351599.685,,-2.519463e+002,4.032348e+000,-5.083286e-005,0.000000e+000,3.655197e-001,0.000000e+000,3,6.272923e-001,1.825000e+000,,,,,,,,,,,,,,,,,,0,4.000000e+000,5.000000e-001,1,1,4.878044e-004,0,,0,
1662351809.066,,-6.547014e+002,4.031911e+000,-1.289293e-004,0.000000e+000,3.104916e-001,0.000000e+000,3,7.765157e-001,1.825000e+000,,,,,,,,,,,,,,,,,,0,4.000000e+000,5.000000e-001,1,1,3.702164e-003,0,,0,
1662352008.268,,-1.005541e+003,4.033275e+000,-2.005201e-004,0.000000e+000,2.865300e-001,0.000000e+000,3,7.887598e-001,1.825000e+000,,,,,,,,,,,,,,,,,,0,4.000000e+000,5.000000e-001,1,1,9.751320e-004,0,,0,
1662352305.598,,-8.034003e+003,4.028991e+000,-1.576851e-003,0.000000e+000,3.121894e-001,0.000000e+000,3,7.719777e-001,1.825000e+000,,,,,,,,,,,,,,,,,,0,4.000000e+000,5.000000e-001,1,1,3.304958e-003,0,,0,
1662352507.430,,-1.506112e+004,4.032397e+000,-2.886238e-003,0.000000e+000,3.144395e-001,0.000000e+000,3,7.661610e-001,1.825000e+000,,,,,,,,,,,,,,,,,,0,4.000000e+000,5.000000e-001,1,1,7.796288e-004,0,,0,
1662352728.690,,-2.309034e+004,4.034493e+000,-4.363251e-003,0.000000e+000,3.177148e-001,0.000000e+000,3,7.655886e-001,1.825000e+000,,,,,,,,,,,,,,,,,,0,4.000000e+000,5.000000e-001,1,1,6.828308e-004,0,,0,
1662352932.190,,-3.011162e+004,4.035957e+000,-5.594674e-003,0.000000e+000,3.213693e-001,0.000000e+000,3,7.653483e-001,1.825000e+000,,,,,,,,,,,,,,,,,,0,4.000000e+000,5.000000e-001,1,1,2.932549e-004,0,,0,
1662353139.572,,-3.814054e+004,4.034934e+000,-6.966794e-003,0.000000e+000,3.244631e-001,0.000000e+000,3,7.689339e-001,1.825000e+000,,,,,,,,,,,,,,,,,,0,4.000000e+000,5.000000e-001,1,1,3.708839e-003,0,,0,
1662353340.063,,-4.516780e+004,4.037521e+000,-7.995866e-003,0.000000e+000,3.278019e-001,0.000000e+000,3,7.652066e-001,1.825000e+000,,,,,,,,,,,,,,,,,,0,4.000000e+000,5.000000e-001,1,1,1.075268e-003,0,,0,
1662353546.183,,-5.319298e+004,4.036252e+000,-9.172406e-003,0.000000e+000,3.302018e-001,0.000000e+000,3,7.680337e-001,1.825000e+000,,,,,,,,,,,,,,,,,,0,4.000000e+000,5.000000e-001,1,1,3.027916e-003,0,,0,
1662353739.064,,-6.021725e+004,4.038744e+000,-1.001736e-002,0.000000e+000,3.327682e-001,0.000000e+000,3,7.653369e-001,1.825000e+000,,,,,,,,,,,,,,,,,,0,4.000000e+000,5.000000e-001,1,1,1.369953e-003,0,,0,
1662353945.765,,-6.824095e+004,4.037180e+000,-1.096521e-002,0.000000e+000,3.352383e-001,0.000000e+000,3,7.687789e-001,1.825000e+000,,,,,,,,,,,,,,,,,,0,4.000000e+000,5.000000e-001,1,1,3.909111e-003,0,,0,
1662354192.065,,-6.622268e+004,4.035177e+000,-1.067603e-002,0.000000e+000,3.343977e-001,0.000000e+000,3,7.665163e-001,1.825000e+000,,,,,,,,,,,,,,,,,,0,4.000000e+000,5.000000e-001,1,1,1.464367e-003,0,,0,
1662354403.476,,-5.819451e+004,4.034641e+000,-9.765097e-003,0.000000e+000,3.326138e-001,0.000000e+000,3,7.667785e-001,1.825000e+000,,,,,,,,,,,,,,,,,,0,4.000000e+000,5.000000e-001,1,1,3.708363e-003,0,,0,
1662354603.538,,-5.117023e+004,4.037766e+000,-8.733785e-003,0.000000e+000,3.276040e-001,0.000000e+000,3,7.615531e-001,1.825000e+000,,,,,,,,,,,,,,,,,,0,4.000000e+000,5.000000e-001,1,1,1.367569e-003,0,,0,
1662354813.300,,-4.314430e+004,4.037278e+000,-7.684718e-003,0.000000e+000,3.280910e-001,0.000000e+000,3,7.665887e-001,1.825000e+000,,,,,,,,,,,,,,,,,,0,4.000000e+000,5.000000e-001,1,1,3.714085e-003,0,,0,
1662355015.280,,-3.612228e+004,4.039331e+000,-6.580573e-003,0.000000e+000,3.251283e-001,0.000000e+000,3,7.662526e-001,1.825000e+000,,,,,,,,,,,,,,,,,,0,4.000000e+000,5.000000e-001,1,1,7.829666e-004,0,,0,
1662355226.371,,-2.809636e+004,4.036984e+000,-5.230810e-003,0.000000e+000,3.239029e-001,0.000000e+000,3,7.641405e-001,1.825000e+000,,,,,,,,,,,,,,,,,,0,4.000000e+000,5.000000e-001,1,1,3.323078e-003,0,,0,
1662355430.941,,-2.107133e+004,4.038255e+000,-3.996347e-003,0.000000e+000,3.204922e-001,0.000000e+000,3,7.661067e-001,1.825000e+000,,,,,,,,,,,,,,,,,,0,4.000000e+000,5.000000e-001,1,1,3.905296e-004,0,,0,
1662355654.522,,-1.304675e+004,4.034786e+000,-2.502101e-003,0.000000e+000,3.173087e-001,0.000000e+000,3,7.643386e-001,1.825000e+000,,,,,,,,,,,,,,,,,,0,4.000000e+000,5.000000e-001,1,1,2.830982e-003,0,,0,
1662355858.503,,-6.019032e+003,4.035225e+000,-1.163533e-003,0.000000e+000,3.139574e-001,0.000000e+000,3,7.660518e-001,1.825000e+000,,,,,,,,,,,,,,,,,,0,4.000000e+000,5.000000e-001,1,1,1.171112e-003,0,,0,
1662356122.965,,-9.056003e+002,4.028407e+000,-1.700394e-004,0.000000e+000,3.176317e-001,0.000000e+000,3,7.815959e-001,1.825000e+000,,,,,,,,,,,,,,,,,,0,4.000000e+000,5.000000e-001,1,1,2.721786e-003,0,,0,
1662356316.855,,-5.540125e+002,4.031618e+000,-1.027553e-004,0.000000e+000,2.924951e-001,0.000000e+000,3,7.569035e-001,1.825000e+000,,,,,,,,,,,,,,,,,,0,4.000000e+000,5.000000e-001,1,1,1.364231e-003,0,,0,
1662356604.785,,-2.030232e+002,4.028845e+000,-3.754870e-005,0.000000e+000,2.185220e-001,0.000000e+000,3,7.912688e-001,1.825000e+000,,,,,,,,,,,,,,,,,,0,4.000000e+000,5.000000e-001,1,1,3.403187e-003,0,,0,
1662356808.736,,-1.319576e+002,4.031861e+000,-2.313296e-005,0.000000e+000,1.936929e-001,0.000000e+000,3,7.541406e-001,1.825000e+000,,,,,,,,,,,,,,,,,,0,4.000000e+000,5.000000e-001,1,1,6.818771e-004,0,,0,
1662357011.757,,-5.101764e+001,4.031522e+000,-1.051454e-005,0.000000e+000,1.385649e-001,0.000000e+000,3,0.000000e+000,1.825000e+000,,,,,,,,,,,,,,,,,,0,4.000000e+000,5.000000e-001,1,1,3.507137e-003,0,,0,
1662357237.408,,2.214255e+001,4.035421e+000,6.018660e-006,0.000000e+000,6.293800e-001,0.000000e+000,3,4.971706e-001,1.825000e+000,,,,,,,,,,,,,,,,,,0,4.000000e+000,5.000000e-001,1,1,1.959801e-004,0,,0,
1662357449.370,,1.023345e+002,4.033470e+000,2.266104e-005,0.000000e+000,4.542520e-001,0.000000e+000,3,3.545982e-001,1.825000e+000,,,,,,,,,,,,,,,,,,0,4.000000e+000,5.000000e-001,1,1,2.536297e-003,0,,0,
1662357669.280,,1.734001e+002,4.036104e+000,3.443273e-005,0.000000e+000,3.424470e-001,0.000000e+000,3,7.267019e-001,1.825000e+000,,,,,,,,,,,,,,,,,,0,4.000000e+000,5.000000e-001,1,1,0.000000e+000,0,,0,
1662361668.255,,4.039519e+001,4.041290e+000,8.354339e-006,0.000000e+000,4.804420e-001,0.000000e+000,3,5.304481e-001,1.825000e+000,,,,,,,,,,,,,,,,,,0,4.000000e+000,5.000000e-001,1,1,1.762867e-003,0,,0,
1662361730.352,,6.044318e+001,4.044331e+000,1.344807e-005,0.000000e+000,3.959901e-001,0.000000e+000,3,7.301894e-001,1.825000e+000,,,,,,,,,,,,,,,,,,0,4.000000e+000,5.000000e-001,1,1,1.177788e-003,0,,0,