File: SQUID/22129_LCOT/22129_MH.rso.dat
[Header]
TITLE,MPMS RSO Measurement
BYAPP,MPMS Measurement,1.1,Summary
FILEOPENTIME, 1662130718.051000 9/2/2022, 4:58:38 PM

INFO, APPNAME, MPMS MultiVu Application, Revision 1.61,  Build 082

INFO, NAME,
INFO, WEIGHT, 9.700
INFO, AREA, 1.000
INFO, LENGTH, 1.000
INFO, SHAPE,
INFO, COMMENT,
INFO, SEQUENCE FILE: M(H)-5t.seq


INFO, BACKGROUND DATA FILE:, None


STARTUPAXIS,X,4,LINEAR,AUTO,0.000000,0.000000
STARTUPAXIS,Y1,5,LINEAR,AUTO,0.000000,0.000000


STARTUPGROUP,Longitudinal
FIELDGROUP,Longitudinal,1,2,3,4,5,6,7,8,9,10,11,19,20,21,22,23,35
FIELDGROUP,Transverse,1,2,3,4,12,13,14,15,16,17,18,24,25,26,27,28,35

PLOT_APPEARANCE,ALL,HORZ_GRID_ON,VERT_GRID_ON,MARKERS_AND_LINES

[Data]
Time,Comment,Field (Oe),Temperature (K),Long Moment (emu),Long Scan Std Dev,Long Offset (cm),Long Offset Std Dev,Long Algorithm,Long Reg Fit,Long Reg Factor,Trans Moment (emu),Trans Scan Std Dev,Trans Offset (cm),Trans Offset Std Dev,Trans Algorithm,Trans Reg Fit,Trans Reg Factor,Long Moment [w/o ABS] (emu),Long Scan Std Dev [w/o ABS],Long Offset [w/o ABS] (cm),Long Offset Std Dev [w/o ABS],Long Reg Fit [w/o ABS],Trans Moment [w/o ABS] (emu),Trans Scan Std Dev [w/o ABS],Trans Offset [w/o ABS] (cm),Trans Offset Std Dev [w/o ABS],Trans Reg Fit [w/o ABS],RSO Position (deg),Amplitude (cm),Frequency,Cycles to Average,Scans per Measurement,Delta Temp (K),Error,EC Comp. Running,Using ABS,
1662130718.051,,0.000000e+000,2.000053e+000,-2.099558e-006,0.000000e+000,7.178960e-001,0.000000e+000,3,9.311917e-002,1.825000e+000,,,,,,,,,,,,,,,,,,0,4.000000e+000,5.000000e-001,1,1,2.030134e-004,0,,0,
1662130773.691,,5.236415e+000,2.000140e+000,9.643146e-007,0.000000e+000,-5.494140e-001,0.000000e+000,3,4.782140e-001,1.825000e+000,,,,,,,,,,,,,,,,,,0,4.000000e+000,5.000000e-001,1,1,2.908707e-005,0,,0,
1662130828.252,,1.196894e+001,2.000184e+000,4.491574e-006,0.000000e+000,3.884313e-001,0.000000e+000,3,0.000000e+000,1.825000e+000,,,,,,,,,,,,,,,,,,0,4.000000e+000,5.000000e-001,1,1,1.740456e-004,0,,0,
1662130875.332,,1.810303e+001,2.000184e+000,3.253738e-006,0.000000e+000,-2.381101e-001,0.000000e+000,3,4.503048e-002,1.825000e+000,,,,,,,,,,,,,,,,,,0,4.000000e+000,5.000000e-001,1,1,1.161098e-004,0,,0,
1662130944.182,,2.423711e+001,2.000242e+000,5.540294e-006,0.000000e+000,4.361284e-002,0.000000e+000,3,7.391014e-001,1.825000e+000,,,,,,,,,,,,,,,,,,0,4.000000e+000,5.000000e-001,1,1,5.817413e-005,0,,0,
1662131003.022,,3.052081e+001,2.000184e+000,7.588788e-006,0.000000e+000,1.242572e-001,0.000000e+000,3,7.871748e-001,1.825000e+000,,,,,,,,,,,,,,,,,,0,4.000000e+000,5.000000e-001,1,1,1.161098e-004,0,,0,
1662131083.542,,3.665489e+001,2.000257e+000,8.313318e-006,0.000000e+000,2.026767e-001,0.000000e+000,3,8.005748e-001,1.825000e+000,,,,,,,,,,,,,,,,,,0,4.000000e+000,5.000000e-001,1,1,2.908707e-005,0,,0,
1662131132.032,,4.248975e+001,2.000025e+000,1.034637e-005,0.000000e+000,2.294286e-001,0.000000e+000,3,7.975697e-001,1.825000e+000,,,,,,,,,,,,,,,,,,0,4.000000e+000,5.000000e-001,1,1,8.690357e-005,0,,0,
1662131179.122,,4.862383e+001,1.999923e+000,1.127819e-005,0.000000e+000,2.964047e-001,0.000000e+000,3,6.298549e-001,1.825000e+000,,,,,,,,,,,,,,,,,,0,4.000000e+000,5.000000e-001,1,1,5.900860e-005,0,,0,
1662131234.562,,5.460832e+001,1.999894e+000,1.311696e-005,0.000000e+000,2.433979e-001,0.000000e+000,3,7.935226e-001,1.825000e+000,,,,,,,,,,,,,,,,,,0,4.000000e+000,5.000000e-001,1,1,5.793571e-005,0,,0,
1662131282.053,,6.178967e+001,1.999879e+000,1.581431e-005,0.000000e+000,2.382016e-001,0.000000e+000,3,8.177109e-001,1.825000e+000,,,,,,,,,,,,,,,,,,0,4.000000e+000,5.000000e-001,1,1,2.789497e-005,0,,0,
1662131329.943,,6.777415e+001,1.999865e+000,1.743783e-005,0.000000e+000,2.238087e-001,0.000000e+000,3,8.285816e-001,1.825000e+000,,,,,,,,,,,,,,,,,,0,4.000000e+000,5.000000e-001,1,1,0.000000e+000,0,,0,
1662131377.063,,7.390821e+001,1.999908e+000,1.786625e-005,0.000000e+000,2.547588e-001,0.000000e+000,3,7.911375e-001,1.825000e+000,,,,,,,,,,,,,,,,,,0,4.000000e+000,5.000000e-001,1,1,1.460314e-004,0,,0,
1662131424.563,,8.004229e+001,1.999923e+000,1.960094e-005,0.000000e+000,2.719780e-001,0.000000e+000,3,7.830976e-001,1.825000e+000,,,,,,,,,,,,,,,,,,0,4.000000e+000,5.000000e-001,1,1,5.900860e-005,0,,0,
1662131471.793,,8.617638e+001,2.000010e+000,2.111201e-005,0.000000e+000,2.665042e-001,0.000000e+000,3,7.960225e-001,1.825000e+000,,,,,,,,,,,,,,,,,,0,4.000000e+000,5.000000e-001,1,1,1.740456e-004,0,,0,
1662131520.235,,9.201122e+001,1.999995e+000,2.319272e-005,0.000000e+000,2.755828e-001,0.000000e+000,3,7.778460e-001,1.825000e+000,,,,,,,,,,,,,,,,,,0,4.000000e+000,5.000000e-001,1,1,1.449585e-004,0,,0,
1662131567.156,,9.784617e+001,2.000053e+000,2.472303e-005,0.000000e+000,2.725493e-001,0.000000e+000,3,7.919315e-001,1.825000e+000,,,,,,,,,,,,,,,,,,0,4.000000e+000,5.000000e-001,1,1,8.702278e-005,0,,0,
1662131661.586,,9.979105e+001,1.999864e+000,2.482455e-005,0.000000e+000,2.727655e-001,0.000000e+000,3,7.817369e-001,1.825000e+000,,,,,,,,,,,,,,,,,,0,4.000000e+000,5.000000e-001,1,1,5.793571e-005,0,,0,
1662131745.716,,3.022159e+002,2.000112e+000,7.723604e-005,0.000000e+000,2.866947e-001,0.000000e+000,3,7.798930e-001,1.825000e+000,,,,,,,,,,,,,,,,,,0,4.000000e+000,5.000000e-001,1,1,2.884865e-005,0,,0,
1662131804.636,,5.016484e+002,1.999981e+000,1.290264e-004,0.000000e+000,2.911389e-001,0.000000e+000,3,7.818723e-001,1.825000e+000,,,,,,,,,,,,,,,,,,0,4.000000e+000,5.000000e-001,1,1,0.000000e+000,0,,0,
1662131876.516,,7.034748e+002,2.000112e+000,1.801526e-004,0.000000e+000,2.910029e-001,0.000000e+000,3,7.791820e-001,1.825000e+000,,,,,,,,,,,,,,,,,,0,4.000000e+000,5.000000e-001,1,1,2.884865e-005,0,,0,
1662131923.676,,9.044034e+002,2.000025e+000,2.428952e-004,0.000000e+000,3.049939e-001,0.000000e+000,3,7.502466e-001,1.825000e+000,,,,,,,,,,,,,,,,,,0,4.000000e+000,5.000000e-001,1,1,2.908707e-005,0,,0,
1662132010.816,,1.004494e+003,1.999807e+000,2.571297e-004,0.000000e+000,2.926539e-001,0.000000e+000,3,7.781433e-001,1.825000e+000,,,,,,,,,,,,,,,,,,0,4.000000e+000,5.000000e-001,1,1,1.170635e-004,0,,0,
1662132065.006,,1.204525e+003,1.999938e+000,3.188324e-004,0.000000e+000,2.972150e-001,0.000000e+000,3,7.960553e-001,1.825000e+000,,,,,,,,,,,,,,,,,,0,4.000000e+000,5.000000e-001,1,1,1.449585e-004,0,,0,
1662132126.446,,1.406051e+003,2.000053e+000,3.858962e-004,0.000000e+000,3.260736e-001,0.000000e+000,3,6.607147e-001,1.825000e+000,,,,,,,,,,,,,,,,,,0,4.000000e+000,5.000000e-001,1,1,8.702278e-005,0,,0,
1662132174.626,,1.607879e+003,2.000039e+000,4.253911e-004,0.000000e+000,3.128490e-001,0.000000e+000,3,7.612416e-001,1.825000e+000,,,,,,,,,,,,,,,,,,0,4.000000e+000,5.000000e-001,1,1,1.159906e-004,0,,0,
1662132228.716,,1.809106e+003,2.000039e+000,4.634889e-004,0.000000e+000,3.233105e-001,0.000000e+000,3,7.015130e-001,1.825000e+000,,,,,,,,,,,,,,,,,,0,4.000000e+000,5.000000e-001,1,1,5.793571e-005,0,,0,
1662132276.097,,2.007640e+003,2.000068e+000,4.618261e-004,0.000000e+000,4.007500e-001,0.000000e+000,3,6.477745e-001,1.825000e+000,,,,,,,,,,,,,,,,,,0,4.000000e+000,5.000000e-001,1,1,1.158714e-004,0,,0,
1662132323.477,,2.209168e+003,2.000025e+000,5.990773e-004,0.000000e+000,2.702433e-001,0.000000e+000,3,7.820535e-001,1.825000e+000,,,,,,,,,,,,,,,,,,0,4.000000e+000,5.000000e-001,1,1,8.690357e-005,0,,0,
1662132378.657,,2.410246e+003,2.000010e+000,6.340910e-004,0.000000e+000,3.053333e-001,0.000000e+000,3,7.762370e-001,1.825000e+000,,,,,,,,,,,,,,,,,,0,4.000000e+000,5.000000e-001,1,1,1.740456e-004,0,,0,
1662132426.597,,2.611325e+003,1.999966e+000,6.498446e-004,0.000000e+000,3.251768e-001,0.000000e+000,3,6.348832e-001,1.825000e+000,,,,,,,,,,,,,,,,,,0,4.000000e+000,5.000000e-001,1,1,1.461506e-004,0,,0,
1662132473.587,,2.810757e+003,1.999952e+000,7.142278e-004,0.000000e+000,2.699150e-001,0.000000e+000,3,7.813343e-001,1.825000e+000,,,,,,,,,,,,,,,,,,0,4.000000e+000,5.000000e-001,1,1,1.740456e-004,0,,0,
1662132521.018,,3.012135e+003,1.999937e+000,7.620580e-004,0.000000e+000,2.873253e-001,0.000000e+000,3,7.769433e-001,1.825000e+000,,,,,,,,,,,,,,,,,,0,4.000000e+000,5.000000e-001,1,1,8.809566e-005,0,,0,
1662132568.488,,3.213063e+003,1.999966e+000,8.291015e-004,0.000000e+000,3.065681e-001,0.000000e+000,3,7.695783e-001,1.825000e+000,,,,,,,,,,,,,,,,,,0,4.000000e+000,5.000000e-001,1,1,1.461506e-004,0,,0,
1662132616.618,,3.412795e+003,1.999966e+000,8.807857e-004,0.000000e+000,3.130178e-001,0.000000e+000,3,7.689465e-001,1.825000e+000,,,,,,,,,,,,,,,,,,0,4.000000e+000,5.000000e-001,1,1,1.461506e-004,0,,0,
1662132663.998,,3.613424e+003,2.000024e+000,9.432547e-004,0.000000e+000,3.020205e-001,0.000000e+000,3,7.874693e-001,1.825000e+000,,,,,,,,,,,,,,,,,,0,4.000000e+000,5.000000e-001,1,1,2.028942e-004,0,,0,
1662132711.128,,3.814802e+003,2.000039e+000,9.755050e-004,0.000000e+000,3.055983e-001,0.000000e+000,3,7.653372e-001,1.825000e+000,,,,,,,,,,,,,,,,,,0,4.000000e+000,5.000000e-001,1,1,1.739264e-004,0,,0,
1662132759.299,,4.015730e+003,1.999879e+000,1.033571e-003,0.000000e+000,3.018039e-001,0.000000e+000,3,7.737908e-001,1.825000e+000,,,,,,,,,,,,,,,,,,0,4.000000e+000,5.000000e-001,1,1,2.789497e-005,0,,0,
1662132806.220,,4.215013e+003,1.999981e+000,1.075217e-003,0.000000e+000,3.047119e-001,0.000000e+000,3,7.712694e-001,1.825000e+000,,,,,,,,,,,,,,,,,,0,4.000000e+000,5.000000e-001,1,1,1.161098e-004,0,,0,
1662132854.400,,4.416391e+003,2.000025e+000,1.127798e-003,0.000000e+000,3.026827e-001,0.000000e+000,3,7.759962e-001,1.825000e+000,,,,,,,,,,,,,,,,,,0,4.000000e+000,5.000000e-001,1,1,1.450777e-004,0,,0,
1662132901.780,,4.618367e+003,2.000025e+000,1.185448e-003,0.000000e+000,3.038363e-001,0.000000e+000,3,7.743641e-001,1.825000e+000,,,,,,,,,,,,,,,,,,0,4.000000e+000,5.000000e-001,1,1,8.690357e-005,0,,0,
1662132949.660,,4.819744e+003,2.000039e+000,1.234472e-003,0.000000e+000,3.069030e-001,0.000000e+000,3,7.760247e-001,1.825000e+000,,,,,,,,,,,,,,,,,,0,4.000000e+000,5.000000e-001,1,1,1.739264e-004,0,,0,
1662132997.291,,5.019028e+003,2.000053e+000,1.280925e-003,0.000000e+000,3.035624e-001,0.000000e+000,3,7.703863e-001,1.825000e+000,,,,,,,,,,,,,,,,,,0,4.000000e+000,5.000000e-001,1,1,8.702278e-005,0,,0,
1662133084.171,,4.917141e+003,1.999995e+000,1.246929e-003,0.000000e+000,3.058391e-001,0.000000e+000,3,7.694836e-001,1.825000e+000,,,,,,,,,,,,,,,,,,0,4.000000e+000,5.000000e-001,1,1,1.449585e-004,0,,0,
1662133132.311,,4.716512e+003,2.000053e+000,1.195475e-003,0.000000e+000,3.056593e-001,0.000000e+000,3,7.692989e-001,1.825000e+000,,,,,,,,,,,,,,,,,,0,4.000000e+000,5.000000e-001,1,1,2.884865e-005,0,,0,
1662133179.721,,4.515134e+003,2.000112e+000,1.144063e-003,0.000000e+000,3.056584e-001,0.000000e+000,3,7.690107e-001,1.825000e+000,,,,,,,,,,,,,,,,,,0,4.000000e+000,5.000000e-001,1,1,8.702278e-005,0,,0,
1662133227.351,,4.313009e+003,2.000068e+000,1.094546e-003,0.000000e+000,3.054475e-001,0.000000e+000,3,7.703040e-001,1.825000e+000,,,,,,,,,,,,,,,,,,0,4.000000e+000,5.000000e-001,1,1,0.000000e+000,0,,0,
1662133274.481,,4.114475e+003,2.000039e+000,1.043776e-003,0.000000e+000,3.050605e-001,0.000000e+000,3,7.699242e-001,1.825000e+000,,,,,,,,,,,,,,,,,,0,4.000000e+000,5.000000e-001,1,1,1.739264e-004,0,,0,
1662133323.171,,3.913696e+003,1.999966e+000,9.945510e-004,0.000000e+000,3.049245e-001,0.000000e+000,3,7.707096e-001,1.825000e+000,,,,,,,,,,,,,,,,,,0,4.000000e+000,5.000000e-001,1,1,1.461506e-004,0,,0,
1662133371.101,,3.712767e+003,1.999967e+000,9.424464e-004,0.000000e+000,3.046888e-001,0.000000e+000,3,7.698543e-001,1.825000e+000,,,,,,,,,,,,,,,,,,0,4.000000e+000,5.000000e-001,1,1,8.702278e-005,0,,0,
1662133418.741,,3.511090e+003,1.999967e+000,8.904769e-004,0.000000e+000,3.065492e-001,0.000000e+000,3,7.699980e-001,1.825000e+000,,,,,,,,,,,,,,,,,,0,4.000000e+000,5.000000e-001,1,1,8.702278e-005,0,,0,
1662133465.881,,3.311807e+003,1.999966e+000,8.425852e-004,0.000000e+000,3.051192e-001,0.000000e+000,3,7.698309e-001,1.825000e+000,,,,,,,,,,,,,,,,,,0,4.000000e+000,5.000000e-001,1,1,1.461506e-004,0,,0,
1662133513.071,,3.110429e+003,1.999995e+000,7.857771e-004,0.000000e+000,3.050000e-001,0.000000e+000,3,7.703138e-001,1.825000e+000,,,,,,,,,,,,,,,,,,0,4.000000e+000,5.000000e-001,1,1,2.040863e-004,0,,0,
1662133560.138,,2.909351e+003,2.000010e+000,7.307932e-004,0.000000e+000,3.028199e-001,0.000000e+000,3,7.661124e-001,1.825000e+000,,,,,,,,,,,,,,,,,,0,4.000000e+000,5.000000e-001,1,1,0.000000e+000,0,,0,
1662133608.739,,2.708274e+003,1.999894e+000,6.928573e-004,0.000000e+000,2.992166e-001,0.000000e+000,3,7.744190e-001,1.825000e+000,,,,,,,,,,,,,,,,,,0,4.000000e+000,5.000000e-001,1,1,5.793571e-005,0,,0,
1662133655.919,,2.508990e+003,2.000025e+000,6.365666e-004,0.000000e+000,2.997059e-001,0.000000e+000,3,7.728818e-001,1.825000e+000,,,,,,,,,,,,,,,,,,0,4.000000e+000,5.000000e-001,1,1,8.690357e-005,0,,0,
1662133710.559,,2.308361e+003,1.999865e+000,5.925942e-004,0.000000e+000,3.058768e-001,0.000000e+000,3,7.670271e-001,1.825000e+000,,,,,,,,,,,,,,,,,,0,4.000000e+000,5.000000e-001,1,1,1.739264e-004,0,,0,
1662133757.580,,2.106684e+003,1.999967e+000,5.298642e-004,0.000000e+000,3.053740e-001,0.000000e+000,3,7.653542e-001,1.825000e+000,,,,,,,,,,,,,,,,,,0,4.000000e+000,5.000000e-001,1,1,8.702278e-005,0,,0,
1662133805.000,,1.905905e+003,1.999908e+000,4.873664e-004,0.000000e+000,3.160350e-001,0.000000e+000,3,7.594242e-001,1.825000e+000,,,,,,,,,,,,,,,,,,0,4.000000e+000,5.000000e-001,1,1,3.004074e-005,0,,0,
1662133851.930,,1.706771e+003,1.999967e+000,4.384505e-004,0.000000e+000,3.180977e-001,0.000000e+000,3,7.589187e-001,1.825000e+000,,,,,,,,,,,,,,,,,,0,4.000000e+000,5.000000e-001,1,1,8.702278e-005,0,,0,
1662133900.060,,1.505095e+003,2.000068e+000,3.897530e-004,0.000000e+000,2.936727e-001,0.000000e+000,3,7.828640e-001,1.825000e+000,,,,,,,,,,,,,,,,,,0,4.000000e+000,5.000000e-001,1,1,5.793571e-005,0,,0,
1662133947.190,,1.303119e+003,2.000053e+000,3.307869e-004,0.000000e+000,2.960236e-001,0.000000e+000,3,7.268618e-001,1.825000e+000,,,,,,,,,,,,,,,,,,0,4.000000e+000,5.000000e-001,1,1,2.884865e-005,0,,0,
1662134009.341,,1.103986e+003,2.000097e+000,2.926586e-004,0.000000e+000,3.069783e-001,0.000000e+000,3,7.826955e-001,1.825000e+000,,,,,,,,,,,,,,,,,,0,4.000000e+000,5.000000e-001,1,1,5.793571e-005,0,,0,
1662134056.722,,9.033560e+002,1.999966e+000,2.240207e-004,0.000000e+000,2.808747e-001,0.000000e+000,3,6.316248e-001,1.825000e+000,,,,,,,,,,,,,,,,,,0,4.000000e+000,5.000000e-001,1,1,1.461506e-004,0,,0,
1662134110.872,,7.019786e+002,1.999908e+000,1.933021e-004,0.000000e+000,2.908016e-001,0.000000e+000,3,8.038667e-001,1.825000e+000,,,,,,,,,,,,,,,,,,0,4.000000e+000,5.000000e-001,1,1,8.690357e-005,0,,0,
1662134186.402,,5.004515e+002,2.000068e+000,1.277680e-004,0.000000e+000,2.735067e-001,0.000000e+000,3,7.960331e-001,1.825000e+000,,,,,,,,,,,,,,,,,,0,4.000000e+000,5.000000e-001,1,1,5.793571e-005,0,,0,
1662134253.173,,3.010189e+002,1.999966e+000,7.837857e-005,0.000000e+000,2.607526e-001,0.000000e+000,3,7.443950e-001,1.825000e+000,,,,,,,,,,,,,,,,,,0,4.000000e+000,5.000000e-001,1,1,1.461506e-004,0,,0,
1662134306.153,,9.949187e+001,1.999864e+000,3.519974e-005,0.000000e+000,-1.334312e-001,0.000000e+000,3,4.937732e-001,1.825000e+000,,,,,,,,,,,,,,,,,,0,4.000000e+000,5.000000e-001,1,1,5.793571e-005,0,,0,
1662134378.843,,-1.009880e+002,1.999980e+000,-2.896261e-005,0.000000e+000,2.861030e-001,0.000000e+000,3,4.625350e-001,1.825000e+000,,,,,,,,,,,,,,,,,,0,4.000000e+000,5.000000e-001,1,1,1.749992e-004,0,,0,
1662134447.473,,-3.020662e+002,1.999908e+000,-7.779575e-005,0.000000e+000,3.113457e-001,0.000000e+000,3,7.075310e-001,1.825000e+000,,,,,,,,,,,,,,,,,,0,4.000000e+000,5.000000e-001,1,1,8.690357e-005,0,,0,
1662134524.443,,-5.014988e+002,2.000082e+000,-1.303537e-004,0.000000e+000,3.041250e-001,0.000000e+000,3,7.791407e-001,1.825000e+000,,,,,,,,,,,,,,,,,,0,4.000000e+000,5.000000e-001,1,1,8.678436e-005,0,,0,
1662134586.093,,-7.036244e+002,2.000010e+000,-1.888094e-004,0.000000e+000,3.026131e-001,0.000000e+000,3,7.891860e-001,1.825000e+000,,,,,,,,,,,,,,,,,,0,4.000000e+000,5.000000e-001,1,1,1.740456e-004,0,,0,
1662134648.253,,-9.042537e+002,2.000025e+000,-2.383550e-004,0.000000e+000,3.014062e-001,0.000000e+000,3,7.845851e-001,1.825000e+000,,,,,,,,,,,,,,,,,,0,4.000000e+000,5.000000e-001,1,1,1.450777e-004,0,,0,
1662134696.463,,-1.105033e+003,1.999952e+000,-2.817840e-004,0.000000e+000,2.862278e-001,0.000000e+000,3,7.580546e-001,1.825000e+000,,,,,,,,,,,,,,,,,,0,4.000000e+000,5.000000e-001,1,1,1.740456e-004,0,,0,
1662134743.593,,-1.304017e+003,1.999952e+000,-3.325771e-004,0.000000e+000,3.054276e-001,0.000000e+000,3,7.082471e-001,1.825000e+000,,,,,,,,,,,,,,,,,,0,4.000000e+000,5.000000e-001,1,1,5.805492e-005,0,,0,
1662134791.793,,-1.506142e+003,1.999908e+000,-4.307900e-004,0.000000e+000,3.686004e-001,0.000000e+000,3,6.290102e-001,1.825000e+000,,,,,,,,,,,,,,,,,,0,4.000000e+000,5.000000e-001,1,1,2.039671e-004,0,,0,
1662134846.383,,-1.707669e+003,2.000010e+000,-4.504280e-004,0.000000e+000,3.253611e-001,0.000000e+000,3,7.527016e-001,1.825000e+000,,,,,,,,,,,,,,,,,,0,4.000000e+000,5.000000e-001,1,1,5.805492e-005,0,,0,
1662134892.263,,-1.907401e+003,2.000053e+000,-5.242201e-004,0.000000e+000,3.045845e-001,0.000000e+000,3,7.707658e-001,1.825000e+000,,,,,,,,,,,,,,,,,,0,4.000000e+000,5.000000e-001,1,1,8.702278e-005,0,,0,
1662134938.394,,-2.108330e+003,2.000010e+000,-4.975919e-004,0.000000e+000,3.364342e-001,0.000000e+000,3,6.657781e-001,1.825000e+000,,,,,,,,,,,,,,,,,,0,4.000000e+000,5.000000e-001,1,1,1.159906e-004,0,,0,
1662134985.275,,-2.309408e+003,2.000025e+000,-6.077887e-004,0.000000e+000,3.583551e-001,0.000000e+000,3,4.894083e-001,1.825000e+000,,,,,,,,,,,,,,,,,,0,4.000000e+000,5.000000e-001,1,1,2.908707e-005,0,,0,
1662135032.655,,-2.510486e+003,1.999995e+000,-6.015265e-004,0.000000e+000,3.236588e-001,0.000000e+000,3,7.127702e-001,1.825000e+000,,,,,,,,,,,,,,,,,,0,4.000000e+000,5.000000e-001,1,1,2.896786e-005,0,,0,
1662135091.545,,-2.710069e+003,2.000025e+000,-6.900657e-004,0.000000e+000,2.975212e-001,0.000000e+000,3,7.696202e-001,1.825000e+000,,,,,,,,,,,,,,,,,,0,4.000000e+000,5.000000e-001,1,1,2.908707e-005,0,,0,
1662135139.425,,-2.910548e+003,2.000010e+000,-7.254942e-004,0.000000e+000,2.926103e-001,0.000000e+000,3,7.182174e-001,1.825000e+000,,,,,,,,,,,,,,,,,,0,4.000000e+000,5.000000e-001,1,1,1.740456e-004,0,,0,
1662135193.545,,-3.111627e+003,1.999951e+000,-8.074924e-004,0.000000e+000,3.115338e-001,0.000000e+000,3,7.703667e-001,1.825000e+000,,,,,,,,,,,,,,,,,,0,4.000000e+000,5.000000e-001,1,1,1.170635e-004,0,,0,
1662135240.176,,-3.313154e+003,1.999938e+000,-8.604816e-004,0.000000e+000,3.052908e-001,0.000000e+000,3,7.703001e-001,1.825000e+000,,,,,,,,,,,,,,,,,,0,4.000000e+000,5.000000e-001,1,1,2.896786e-005,0,,0,
1662135286.576,,-3.512138e+003,1.999951e+000,-9.033069e-004,0.000000e+000,3.069511e-001,0.000000e+000,3,7.685291e-001,1.825000e+000,,,,,,,,,,,,,,,,,,0,4.000000e+000,5.000000e-001,1,1,1.170635e-004,0,,0,
1662135333.749,,-3.713515e+003,1.999937e+000,-9.523159e-004,0.000000e+000,3.080006e-001,0.000000e+000,3,7.681121e-001,1.825000e+000,,,,,,,,,,,,,,,,,,0,4.000000e+000,5.000000e-001,1,1,8.809566e-005,0,,0,
1662135381.409,,-3.914594e+003,1.999951e+000,-9.925014e-004,0.000000e+000,3.074318e-001,0.000000e+000,3,7.683703e-001,1.825000e+000,,,,,,,,,,,,,,,,,,0,4.000000e+000,5.000000e-001,1,1,1.170635e-004,0,,0,
1662135429.299,,-4.115521e+003,1.999980e+000,-1.052668e-003,0.000000e+000,3.022897e-001,0.000000e+000,3,7.689440e-001,1.825000e+000,,,,,,,,,,,,,,,,,,0,4.000000e+000,5.000000e-001,1,1,1.749992e-004,0,,0,
1662135477.179,,-4.314057e+003,1.999981e+000,-1.117712e-003,0.000000e+000,3.057017e-001,0.000000e+000,3,7.783440e-001,1.825000e+000,,,,,,,,,,,,,,,,,,0,4.000000e+000,5.000000e-001,1,1,5.805492e-005,0,,0,
1662135524.319,,-4.516182e+003,2.000010e+000,-1.162026e-003,0.000000e+000,3.058063e-001,0.000000e+000,3,7.744902e-001,1.825000e+000,,,,,,,,,,,,,,,,,,0,4.000000e+000,5.000000e-001,1,1,1.159906e-004,0,,0,
1662135571.759,,-4.717560e+003,1.999952e+000,-1.208689e-003,0.000000e+000,3.075178e-001,0.000000e+000,3,7.740760e-001,1.825000e+000,,,,,,,,,,,,,,,,,,0,4.000000e+000,5.000000e-001,1,1,0.000000e+000,0,,0,
1662135618.639,,-4.918188e+003,1.999893e+000,-1.278112e-003,0.000000e+000,3.036655e-001,0.000000e+000,3,7.830601e-001,1.825000e+000,,,,,,,,,,,,,,,,,,0,4.000000e+000,5.000000e-001,1,1,0.000000e+000,0,,0,
1662135704.820,,-5.016933e+003,1.999690e+000,-1.277123e-003,0.000000e+000,3.075752e-001,0.000000e+000,3,7.716443e-001,1.825000e+000,,,,,,,,,,,,,,,,,,0,4.000000e+000,5.000000e-001,1,1,2.321005e-004,0,,0,
1662135753.510,,-4.817650e+003,1.999777e+000,-1.223428e-003,0.000000e+000,3.077237e-001,0.000000e+000,3,7.702128e-001,1.825000e+000,,,,,,,,,,,,,,,,,,0,4.000000e+000,5.000000e-001,1,1,5.805492e-005,0,,0,
1662135800.640,,-4.616123e+003,1.999792e+000,-1.171523e-003,0.000000e+000,3.076341e-001,0.000000e+000,3,7.697312e-001,1.825000e+000,,,,,,,,,,,,,,,,,,0,4.000000e+000,5.000000e-001,1,1,2.801418e-005,0,,0,
1662135848.800,,-4.414297e+003,1.999966e+000,-1.120415e-003,0.000000e+000,3.075066e-001,0.000000e+000,3,7.698083e-001,1.825000e+000,,,,,,,,,,,,,,,,,,0,4.000000e+000,5.000000e-001,1,1,1.461506e-004,0,,0,
1662135895.600,,-4.213068e+003,2.000082e+000,-1.068760e-003,0.000000e+000,3.074659e-001,0.000000e+000,3,7.695510e-001,1.825000e+000,,,,,,,,,,,,,,,,,,0,4.000000e+000,5.000000e-001,1,1,1.449585e-004,0,,0,
1662135942.610,,-4.013637e+003,2.000112e+000,-1.018024e-003,0.000000e+000,3.076673e-001,0.000000e+000,3,7.693370e-001,1.825000e+000,,,,,,,,,,,,,,,,,,0,4.000000e+000,5.000000e-001,1,1,1.449585e-004,0,,0,
1662135991.240,,-3.812708e+003,2.000053e+000,-9.695693e-004,0.000000e+000,3.061665e-001,0.000000e+000,3,7.713423e-001,1.825000e+000,,,,,,,,,,,,,,,,,,0,4.000000e+000,5.000000e-001,1,1,8.702278e-005,0,,0,
1662136039.640,,-3.611480e+003,2.000010e+000,-9.184187e-004,0.000000e+000,3.071009e-001,0.000000e+000,3,7.705621e-001,1.825000e+000,,,,,,,,,,,,,,,,,,0,4.000000e+000,5.000000e-001,1,1,5.805492e-005,0,,0,
1662136085.960,,-3.410402e+003,2.000010e+000,-8.688719e-004,0.000000e+000,3.030691e-001,0.000000e+000,3,7.746649e-001,1.825000e+000,,,,,,,,,,,,,,,,,,0,4.000000e+000,5.000000e-001,1,1,1.159906e-004,0,,0,
1662136132.750,,-3.211118e+003,1.999952e+000,-8.148510e-004,0.000000e+000,3.067015e-001,0.000000e+000,3,7.711192e-001,1.825000e+000,,,,,,,,,,,,,,,,,,0,4.000000e+000,5.000000e-001,1,1,0.000000e+000,0,,0,
1662136179.950,,-3.010190e+003,1.999952e+000,-7.672148e-004,0.000000e+000,3.088805e-001,0.000000e+000,3,7.745718e-001,1.825000e+000,,,,,,,,,,,,,,,,,,0,4.000000e+000,5.000000e-001,1,1,1.740456e-004,0,,0,
1662136227.581,,-2.808812e+003,2.000025e+000,-7.162882e-004,0.000000e+000,3.083977e-001,0.000000e+000,3,7.715971e-001,1.825000e+000,,,,,,,,,,,,,,,,,,0,4.000000e+000,5.000000e-001,1,1,1.450777e-004,0,,0,
1662136274.261,,-2.609380e+003,2.000025e+000,-6.645730e-004,0.000000e+000,3.047799e-001,0.000000e+000,3,7.707213e-001,1.825000e+000,,,,,,,,,,,,,,,,,,0,4.000000e+000,5.000000e-001,1,1,1.450777e-004,0,,0,
1662136322.071,,-2.408152e+003,1.999938e+000,-6.084748e-004,0.000000e+000,3.019500e-001,0.000000e+000,3,7.564359e-001,1.825000e+000,,,,,,,,,,,,,,,,,,0,4.000000e+000,5.000000e-001,1,1,1.449585e-004,0,,0,
1662136369.082,,-2.206924e+003,1.999951e+000,-5.598066e-004,0.000000e+000,3.023534e-001,0.000000e+000,3,7.536809e-001,1.825000e+000,,,,,,,,,,,,,,,,,,0,4.000000e+000,5.000000e-001,1,1,1.170635e-004,0,,0,
1662136423.952,,-2.005247e+003,1.999995e+000,-5.065533e-004,0.000000e+000,3.156480e-001,0.000000e+000,3,7.389085e-001,1.825000e+000,,,,,,,,,,,,,,,,,,0,4.000000e+000,5.000000e-001,1,1,2.040863e-004,0,,0,
1662136471.083,,-1.807311e+003,1.999966e+000,-4.571094e-004,0.000000e+000,3.001119e-001,0.000000e+000,3,7.644426e-001,1.825000e+000,,,,,,,,,,,,,,,,,,0,4.000000e+000,5.000000e-001,1,1,1.461506e-004,0,,0,
1662136518.993,,-1.606083e+003,2.000025e+000,-4.002515e-004,0.000000e+000,3.148350e-001,0.000000e+000,3,7.540550e-001,1.825000e+000,,,,,,,,,,,,,,,,,,0,4.000000e+000,5.000000e-001,1,1,1.450777e-004,0,,0,
1662136566.124,,-1.404406e+003,2.000010e+000,-3.673241e-004,0.000000e+000,2.795835e-001,0.000000e+000,3,7.927589e-001,1.825000e+000,,,,,,,,,,,,,,,,,,0,4.000000e+000,5.000000e-001,1,1,1.159906e-004,0,,0,
1662136613.314,,-1.202430e+003,2.000010e+000,-3.023911e-004,0.000000e+000,3.215005e-001,0.000000e+000,3,6.555950e-001,1.825000e+000,,,,,,,,,,,,,,,,,,0,4.000000e+000,5.000000e-001,1,1,1.159906e-004,0,,0,
1662136660.534,,-1.003147e+003,1.999952e+000,-2.778952e-004,0.000000e+000,3.022560e-001,0.000000e+000,3,8.167259e-001,1.825000e+000,,,,,,,,,,,,,,,,,,0,4.000000e+000,5.000000e-001,1,1,1.740456e-004,0,,0,
1662136728.644,,-8.023681e+002,2.000097e+000,-2.034163e-004,0.000000e+000,3.055409e-001,0.000000e+000,3,7.383517e-001,1.825000e+000,,,,,,,,,,,,,,,,,,0,4.000000e+000,5.000000e-001,1,1,0.000000e+000,0,,0,
1662136803.514,,-6.011402e+002,2.000126e+000,-1.537344e-004,0.000000e+000,3.007842e-001,0.000000e+000,3,7.731538e-001,1.825000e+000,,,,,,,,,,,,,,,,,,0,4.000000e+000,5.000000e-001,1,1,0.000000e+000,0,,0,
1662136871.054,,-3.999124e+002,1.999923e+000,-9.932247e-005,0.000000e+000,3.428217e-001,0.000000e+000,3,6.851735e-001,1.825000e+000,,,,,,,,,,,,,,,,,,0,4.000000e+000,5.000000e-001,1,1,1.749992e-004,0,,0,
1662136928.174,,-2.004798e+002,1.999865e+000,-5.025378e-005,0.000000e+000,2.855229e-001,0.000000e+000,3,6.263654e-001,1.825000e+000,,,,,,,,,,,,,,,,,,0,4.000000e+000,5.000000e-001,1,1,1.169443e-004,0,,0,
1662137021.834,,-2.992236e-001,2.000097e+000,-5.246750e-006,0.000000e+000,-1.069187e+000,0.000000e+000,3,0.000000e+000,1.825000e+000,,,,,,,,,,,,,,,,,,0,4.000000e+000,5.000000e-001,1,1,5.793571e-005,0,,0,
1662137136.905,,1.021849e+002,2.000257e+000,3.075147e-005,0.000000e+000,3.439310e-001,0.000000e+000,3,5.521440e-001,1.825000e+000,,,,,,,,,,,,,,,,,,0,4.000000e+000,5.000000e-001,1,1,2.908707e-005,0,,0,
1662137206.305,,3.035623e+002,2.000372e+000,8.057501e-005,0.000000e+000,3.258874e-001,0.000000e+000,3,7.926204e-001,1.825000e+000,,,,,,,,,,,,,,,,,,0,4.000000e+000,5.000000e-001,1,1,2.884865e-005,0,,0,
1662137266.925,,5.029948e+002,2.000300e+000,1.323621e-004,0.000000e+000,2.904270e-001,0.000000e+000,3,7.945086e-001,1.825000e+000,,,,,,,,,,,,,,,,,,0,4.000000e+000,5.000000e-001,1,1,0.000000e+000,0,,0,
1662137343.175,,7.046717e+002,2.000039e+000,1.820600e-004,0.000000e+000,2.973029e-001,0.000000e+000,3,7.770741e-001,1.825000e+000,,,,,,,,,,,,,,,,,,0,4.000000e+000,5.000000e-001,1,1,0.000000e+000,0,,0,
1662137390.625,,9.057498e+002,1.999835e+000,2.384520e-004,0.000000e+000,2.953705e-001,0.000000e+000,3,7.880287e-001,1.825000e+000,,,,,,,,,,,,,,,,,,0,4.000000e+000,5.000000e-001,1,1,1.149178e-004,0,,0,
1662137437.306,,1.106230e+003,1.999850e+000,2.913042e-004,0.000000e+000,3.063791e-001,0.000000e+000,3,7.803569e-001,1.825000e+000,,,,,,,,,,,,,,,,,,0,4.000000e+000,5.000000e-001,1,1,2.039671e-004,0,,0,
1662137484.486,,1.305363e+003,1.999777e+000,3.252859e-004,0.000000e+000,3.104340e-001,0.000000e+000,3,7.422906e-001,1.825000e+000,,,,,,,,,,,,,,,,,,0,4.000000e+000,5.000000e-001,1,1,1.159906e-004,0,,0,
1662137538.876,,1.507489e+003,1.999893e+000,4.284470e-004,0.000000e+000,2.745462e-001,0.000000e+000,3,8.071327e-001,1.825000e+000,,,,,,,,,,,,,,,,,,0,4.000000e+000,5.000000e-001,1,1,1.169443e-004,0,,0,
1662137587.256,,1.709016e+003,1.999995e+000,4.815738e-004,0.000000e+000,3.497374e-001,0.000000e+000,3,5.822642e-001,1.825000e+000,,,,,,,,,,,,,,,,,,0,4.000000e+000,5.000000e-001,1,1,1.449585e-004,0,,0,
1662137635.677,,1.908299e+003,2.000053e+000,4.437125e-004,0.000000e+000,2.910763e-001,0.000000e+000,3,5.745282e-001,1.825000e+000,,,,,,,,,,,,,,,,,,0,4.000000e+000,5.000000e-001,1,1,1.448393e-004,0,,0,
1662137683.557,,2.109228e+003,1.999981e+000,5.631701e-004,0.000000e+000,2.874089e-001,0.000000e+000,3,8.116294e-001,1.825000e+000,,,,,,,,,,,,,,,,,,0,4.000000e+000,5.000000e-001,1,1,1.161098e-004,0,,0,
1662137745.007,,2.309856e+003,2.000141e+000,5.830880e-004,0.000000e+000,3.032336e-001,0.000000e+000,3,7.647105e-001,1.825000e+000,,,,,,,,,,,,,,,,,,0,4.000000e+000,5.000000e-001,1,1,8.702278e-005,0,,0,
1662137816.508,,2.512431e+003,2.000170e+000,6.491949e-004,0.000000e+000,3.086219e-001,0.000000e+000,3,7.623930e-001,1.825000e+000,,,,,,,,,,,,,,,,,,0,4.000000e+000,5.000000e-001,1,1,2.908707e-005,0,,0,
1662137863.389,,2.710816e+003,2.000010e+000,7.047993e-004,0.000000e+000,3.296979e-001,0.000000e+000,3,7.237052e-001,1.825000e+000,,,,,,,,,,,,,,,,,,0,4.000000e+000,5.000000e-001,1,1,5.805492e-005,0,,0,
1662137910.519,,2.912044e+003,1.999995e+000,7.337214e-004,0.000000e+000,3.124404e-001,0.000000e+000,3,7.336032e-001,1.825000e+000,,,,,,,,,,,,,,,,,,0,4.000000e+000,5.000000e-001,1,1,2.896786e-005,0,,0,
1662137964.159,,3.112972e+003,1.999967e+000,8.115572e-004,0.000000e+000,3.298607e-001,0.000000e+000,3,7.317542e-001,1.825000e+000,,,,,,,,,,,,,,,,,,0,4.000000e+000,5.000000e-001,1,1,8.702278e-005,0,,0,
1662138011.289,,3.314051e+003,1.999980e+000,8.133699e-004,0.000000e+000,2.970259e-001,0.000000e+000,3,7.148208e-001,1.825000e+000,,,,,,,,,,,,,,,,,,0,4.000000e+000,5.000000e-001,1,1,1.749992e-004,0,,0,
1662138057.929,,3.513783e+003,1.999952e+000,9.072617e-004,0.000000e+000,3.061762e-001,0.000000e+000,3,7.590661e-001,1.825000e+000,,,,,,,,,,,,,,,,,,0,4.000000e+000,5.000000e-001,1,1,0.000000e+000,0,,0,
1662138105.809,,3.715010e+003,1.999995e+000,9.635210e-004,0.000000e+000,3.091826e-001,0.000000e+000,3,7.759355e-001,1.825000e+000,,,,,,,,,,,,,,,,,,0,4.000000e+000,5.000000e-001,1,1,8.714199e-005,0,,0,
1662138152.719,,3.915939e+003,1.999938e+000,1.018808e-003,0.000000e+000,3.089574e-001,0.000000e+000,3,7.758722e-001,1.825000e+000,,,,,,,,,,,,,,,,,,0,4.000000e+000,5.000000e-001,1,1,1.449585e-004,0,,0,
1662138200.129,,4.116868e+003,1.999908e+000,1.077985e-003,0.000000e+000,3.068188e-001,0.000000e+000,3,7.792794e-001,1.825000e+000,,,,,,,,,,,,,,,,,,0,4.000000e+000,5.000000e-001,1,1,8.690357e-005,0,,0,
1662138247.009,,4.315403e+003,1.999923e+000,1.102640e-003,0.000000e+000,3.054028e-001,0.000000e+000,3,7.719374e-001,1.825000e+000,,,,,,,,,,,,,,,,,,0,4.000000e+000,5.000000e-001,1,1,1.159906e-004,0,,0,
1662138294.409,,4.517528e+003,1.999938e+000,1.161587e-003,0.000000e+000,3.053901e-001,0.000000e+000,3,7.772010e-001,1.825000e+000,,,,,,,,,,,,,,,,,,0,4.000000e+000,5.000000e-001,1,1,1.449585e-004,0,,0,
1662138342.799,,4.719206e+003,2.000010e+000,1.207394e-003,0.000000e+000,3.097933e-001,0.000000e+000,3,7.734703e-001,1.825000e+000,,,,,,,,,,,,,,,,,,0,4.000000e+000,5.000000e-001,1,1,1.740456e-004,0,,0,
1662138391.189,,4.919386e+003,1.999966e+000,1.258703e-003,0.000000e+000,3.077901e-001,0.000000e+000,3,7.749496e-001,1.825000e+000,,,,,,,,,,,,,,,,,,0,4.000000e+000,5.000000e-001,1,1,1.461506e-004,0,,0,
1662139440.784,,0.000000e+000,5.003245e+000,-2.649030e-006,0.000000e+000,1.058863e+000,0.000000e+000,3,2.777087e-001,1.825000e+000,,,,,,,,,,,,,,,,,,0,4.000000e+000,5.000000e-001,1,1,3.380775e-004,0,,0,
1662139488.644,,5.086794e+000,4.995126e+000,1.331217e-006,0.000000e+000,-7.800517e-001,0.000000e+000,3,0.000000e+000,1.825000e+000,,,,,,,,,,,,,,,,,,0,4.000000e+000,5.000000e-001,1,1,2.363682e-003,0,,0,
1662139535.774,,1.196894e+001,5.003248e+000,-4.921507e-007,0.000000e+000,-1.073614e+000,0.000000e+000,3,0.000000e+000,1.825000e+000,,,,,,,,,,,,,,,,,,0,4.000000e+000,5.000000e-001,1,1,7.117748e-003,0,,0,
1662139615.514,,1.855186e+001,5.000451e+000,2.593355e-006,0.000000e+000,-1.051727e-001,0.000000e+000,3,4.140364e-001,1.825000e+000,,,,,,,,,,,,,,,,,,0,4.000000e+000,5.000000e-001,1,1,1.523018e-003,0,,0,
1662139698.614,,2.423711e+001,5.000620e+000,4.324269e-006,0.000000e+000,2.444694e-002,0.000000e+000,3,7.045665e-001,1.825000e+000,,,,,,,,,,,,,,,,,,0,4.000000e+000,5.000000e-001,1,1,3.556252e-003,0,,0,
1662139753.844,,3.067042e+001,4.998928e+000,4.281897e-006,0.000000e+000,1.843809e-001,0.000000e+000,3,0.000000e+000,1.825000e+000,,,,,,,,,,,,,,,,,,0,4.000000e+000,5.000000e-001,1,1,2.535820e-003,0,,0,
1662139801.544,,3.650528e+001,4.999266e+000,5.512217e-006,0.000000e+000,2.985530e-001,0.000000e+000,3,2.612495e-001,1.825000e+000,,,,,,,,,,,,,,,,,,0,4.000000e+000,5.000000e-001,1,1,1.702309e-004,0,,0,
1662139849.174,,4.248975e+001,4.998928e+000,7.409680e-006,0.000000e+000,1.498184e-001,0.000000e+000,3,6.813268e-001,1.825000e+000,,,,,,,,,,,,,,,,,,0,4.000000e+000,5.000000e-001,1,1,3.551960e-003,0,,0,
1662139904.114,,4.817499e+001,5.000450e+000,7.788750e-006,0.000000e+000,2.126079e-001,0.000000e+000,3,7.591560e-001,1.825000e+000,,,,,,,,,,,,,,,,,,0,4.000000e+000,5.000000e-001,1,1,2.538204e-003,0,,0,
1662139951.316,,5.445870e+001,4.999689e+000,9.621204e-006,0.000000e+000,1.913758e-001,0.000000e+000,3,8.254359e-001,1.825000e+000,,,,,,,,,,,,,,,,,,0,4.000000e+000,5.000000e-001,1,1,2.707005e-003,0,,0,
1662139999.996,,6.149046e+001,4.997913e+000,9.718398e-006,0.000000e+000,1.922451e-001,0.000000e+000,3,7.627143e-001,1.825000e+000,,,,,,,,,,,,,,,,,,0,4.000000e+000,5.000000e-001,1,1,1.857758e-003,0,,0,
1662140046.686,,6.777414e+001,4.999519e+000,1.149848e-005,0.000000e+000,2.053436e-001,0.000000e+000,3,7.570637e-001,1.825000e+000,,,,,,,,,,,,,,,,,,0,4.000000e+000,5.000000e-001,1,1,1.354218e-003,0,,0,
1662140095.246,,7.345937e+001,4.998505e+000,1.181546e-005,0.000000e+000,3.366252e-001,0.000000e+000,3,6.718537e-001,1.825000e+000,,,,,,,,,,,,,,,,,,0,4.000000e+000,5.000000e-001,1,1,1.015186e-003,0,,0,
1662140141.916,,7.959345e+001,4.999774e+000,1.294412e-005,0.000000e+000,2.425362e-001,0.000000e+000,3,7.849690e-001,1.825000e+000,,,,,,,,,,,,,,,,,,0,4.000000e+000,5.000000e-001,1,1,8.449554e-004,0,,0,
1662140189.757,,8.557792e+001,4.999435e+000,1.392849e-005,0.000000e+000,2.444085e-001,0.000000e+000,3,7.730007e-001,1.825000e+000,,,,,,,,,,,,,,,,,,0,4.000000e+000,5.000000e-001,1,1,5.083084e-004,0,,0,
1662140236.777,,9.156239e+001,4.999859e+000,1.519912e-005,0.000000e+000,2.499513e-001,0.000000e+000,3,7.571092e-001,1.825000e+000,,,,,,,,,,,,,,,,,,0,4.000000e+000,5.000000e-001,1,1,1.015186e-003,0,,0,
1662140283.737,,9.769647e+001,4.999943e+000,1.640179e-005,0.000000e+000,2.610547e-001,0.000000e+000,3,7.783886e-001,1.825000e+000,,,,,,,,,,,,,,,,,,0,4.000000e+000,5.000000e-001,1,1,1.861095e-003,0,,0,
1662140386.587,,1.005392e+002,5.001381e+000,1.744681e-005,0.000000e+000,2.696138e-001,0.000000e+000,3,7.950251e-001,1.825000e+000,,,,,,,,,,,,,,,,,,0,4.000000e+000,5.000000e-001,1,1,6.761551e-004,0,,0,
1662140471.027,,3.028143e+002,5.000789e+000,5.241818e-005,0.000000e+000,2.897926e-001,0.000000e+000,3,7.744057e-001,1.825000e+000,,,,,,,,,,,,,,,,,,0,4.000000e+000,5.000000e-001,1,1,1.523972e-003,0,,0,
1662140528.228,,5.022469e+002,4.999774e+000,8.796909e-005,0.000000e+000,2.864563e-001,0.000000e+000,3,7.805807e-001,1.825000e+000,,,,,,,,,,,,,,,,,,0,4.000000e+000,5.000000e-001,1,1,2.537727e-003,0,,0,
1662140587.398,,7.043724e+002,4.999858e+000,1.234087e-004,0.000000e+000,2.920739e-001,0.000000e+000,3,7.770284e-001,1.825000e+000,,,,,,,,,,,,,,,,,,0,4.000000e+000,5.000000e-001,1,1,1.691818e-003,0,,0,
1662140645.839,,9.051514e+002,4.999689e+000,1.608635e-004,0.000000e+000,2.806539e-001,0.000000e+000,3,7.798543e-001,1.825000e+000,,,,,,,,,,,,,,,,,,0,4.000000e+000,5.000000e-001,1,1,2.707005e-003,0,,0,
1662140739.259,,1.003895e+003,5.001043e+000,1.744371e-004,0.000000e+000,2.950827e-001,0.000000e+000,3,7.705871e-001,1.825000e+000,,,,,,,,,,,,,,,,,,0,4.000000e+000,5.000000e-001,1,1,1.694202e-003,0,,0,
1662140800.919,,1.204226e+003,5.000112e+000,1.913564e-004,0.000000e+000,3.339872e-001,0.000000e+000,3,6.406603e-001,1.825000e+000,,,,,,,,,,,,,,,,,,0,4.000000e+000,5.000000e-001,1,1,2.539158e-003,0,,0,
1662140848.199,,1.405902e+003,4.999519e+000,2.574853e-004,0.000000e+000,3.184726e-001,0.000000e+000,3,7.350798e-001,1.825000e+000,,,,,,,,,,,,,,,,,,0,4.000000e+000,5.000000e-001,1,1,6.771088e-004,0,,0,
1662140919.729,,1.608476e+003,5.000874e+000,2.810145e-004,0.000000e+000,3.075809e-001,0.000000e+000,3,7.475240e-001,1.825000e+000,,,,,,,,,,,,,,,,,,0,4.000000e+000,5.000000e-001,1,1,3.390312e-004,0,,0,
1662140982.129,,1.808956e+003,4.999266e+000,3.106307e-004,0.000000e+000,3.539128e-001,0.000000e+000,3,6.768700e-001,1.825000e+000,,,,,,,,,,,,,,,,,,0,4.000000e+000,5.000000e-001,1,1,1.183987e-003,0,,0,
1662141036.579,,2.007790e+003,4.999182e+000,3.873133e-004,0.000000e+000,3.681038e-001,0.000000e+000,3,6.240849e-001,1.825000e+000,,,,,,,,,,,,,,,,,,0,4.000000e+000,5.000000e-001,1,1,1.691341e-003,0,,0,
1662141083.709,,2.209617e+003,4.999859e+000,4.141978e-004,0.000000e+000,2.251115e-001,0.000000e+000,3,5.881224e-001,1.825000e+000,,,,,,,,,,,,,,,,,,0,4.000000e+000,5.000000e-001,1,1,1.015186e-003,0,,0,
1662141131.899,,2.409947e+003,4.999519e+000,4.539458e-004,0.000000e+000,2.676039e-001,0.000000e+000,3,7.898741e-001,1.825000e+000,,,,,,,,,,,,,,,,,,0,4.000000e+000,5.000000e-001,1,1,1.354218e-003,0,,0,
1662141179.530,,2.611474e+003,4.999773e+000,4.481605e-004,0.000000e+000,3.383821e-001,0.000000e+000,3,6.837618e-001,1.825000e+000,,,,,,,,,,,,,,,,,,0,4.000000e+000,5.000000e-001,1,1,1.862049e-003,0,,0,
1662141226.460,,2.810907e+003,4.998927e+000,4.853606e-004,0.000000e+000,2.929966e-001,0.000000e+000,3,7.480044e-001,1.825000e+000,,,,,,,,,,,,,,,,,,0,4.000000e+000,5.000000e-001,1,1,5.068779e-004,0,,0,
1662141274.390,,3.011985e+003,4.999858e+000,5.222993e-004,0.000000e+000,3.025119e-001,0.000000e+000,3,7.632626e-001,1.825000e+000,,,,,,,,,,,,,,,,,,0,4.000000e+000,5.000000e-001,1,1,2.368927e-003,0,,0,
1662141323.270,,3.213063e+003,4.999604e+000,5.832301e-004,0.000000e+000,3.148381e-001,0.000000e+000,3,8.011919e-001,1.825000e+000,,,,,,,,,,,,,,,,,,0,4.000000e+000,5.000000e-001,1,1,2.537251e-003,0,,0,
1662141370.651,,3.412646e+003,5.000281e+000,6.081772e-004,0.000000e+000,2.933161e-001,0.000000e+000,3,7.576140e-001,1.825000e+000,,,,,,,,,,,,,,,,,,0,4.000000e+000,5.000000e-001,1,1,8.459091e-004,0,,0,
1662141419.831,,3.612677e+003,4.999604e+000,6.241560e-004,0.000000e+000,3.198646e-001,0.000000e+000,3,7.416486e-001,1.825000e+000,,,,,,,,,,,,,,,,,,0,4.000000e+000,5.000000e-001,1,1,1.524448e-003,0,,0,
1662141469.262,,3.814204e+003,4.997828e+000,6.778912e-004,0.000000e+000,3.170364e-001,0.000000e+000,3,7.470726e-001,1.825000e+000,,,,,,,,,,,,,,,,,,0,4.000000e+000,5.000000e-001,1,1,2.367020e-003,0,,0,
1662141516.642,,4.016030e+003,5.003499e+000,6.884317e-004,0.000000e+000,3.142183e-001,0.000000e+000,3,7.496042e-001,1.825000e+000,,,,,,,,,,,,,,,,,,0,4.000000e+000,5.000000e-001,1,1,5.083084e-004,0,,0,
1662141564.272,,4.214714e+003,5.001382e+000,7.323180e-004,0.000000e+000,3.009784e-001,0.000000e+000,3,7.737345e-001,1.825000e+000,,,,,,,,,,,,,,,,,,0,4.000000e+000,5.000000e-001,1,1,3.390312e-004,0,,0,
1662141611.152,,4.415792e+003,4.999435e+000,7.656625e-004,0.000000e+000,3.082042e-001,0.000000e+000,3,7.591363e-001,1.825000e+000,,,,,,,,,,,,,,,,,,0,4.000000e+000,5.000000e-001,1,1,2.536774e-003,0,,0,
1662141660.532,,4.617618e+003,4.999857e+000,8.111053e-004,0.000000e+000,3.091702e-001,0.000000e+000,3,7.758409e-001,1.825000e+000,,,,,,,,,,,,,,,,,,0,4.000000e+000,5.000000e-001,1,1,2.031326e-003,0,,0,
1662141709.712,,4.819296e+003,4.998758e+000,8.389423e-004,0.000000e+000,3.152079e-001,0.000000e+000,3,7.640753e-001,1.825000e+000,,,,,,,,,,,,,,,,,,0,4.000000e+000,5.000000e-001,1,1,8.449554e-004,0,,0,
1662141757.902,,5.018728e+003,4.999604e+000,8.809667e-004,0.000000e+000,3.133386e-001,0.000000e+000,3,7.660370e-001,1.825000e+000,,,,,,,,,,,,,,,,,,0,4.000000e+000,5.000000e-001,1,1,1.861095e-003,0,,0,
1662141845.033,,4.917291e+003,4.999266e+000,8.481316e-004,0.000000e+000,3.125978e-001,0.000000e+000,3,7.606391e-001,1.825000e+000,,,,,,,,,,,,,,,,,,0,4.000000e+000,5.000000e-001,1,1,8.473396e-004,0,,0,
1662141892.203,,4.716812e+003,4.999942e+000,8.122771e-004,0.000000e+000,3.124592e-001,0.000000e+000,3,7.596483e-001,1.825000e+000,,,,,,,,,,,,,,,,,,0,4.000000e+000,5.000000e-001,1,1,2.201080e-003,0,,0,
1662141940.393,,4.515584e+003,4.999266e+000,7.776676e-004,0.000000e+000,3.123344e-001,0.000000e+000,3,7.599365e-001,1.825000e+000,,,,,,,,,,,,,,,,,,0,4.000000e+000,5.000000e-001,1,1,5.068779e-004,0,,0,
1662141987.833,,4.313159e+003,4.999435e+000,7.430190e-004,0.000000e+000,3.119389e-001,0.000000e+000,3,7.604516e-001,1.825000e+000,,,,,,,,,,,,,,,,,,0,4.000000e+000,5.000000e-001,1,1,1.522064e-003,0,,0,
1662142035.473,,4.114175e+003,4.998927e+000,7.065675e-004,0.000000e+000,3.119317e-001,0.000000e+000,3,7.578240e-001,1.825000e+000,,,,,,,,,,,,,,,,,,0,4.000000e+000,5.000000e-001,1,1,1.702309e-004,0,,0,
1662142082.404,,3.913546e+003,4.999688e+000,6.737640e-004,0.000000e+000,3.120165e-001,0.000000e+000,3,7.607507e-001,1.825000e+000,,,,,,,,,,,,,,,,,,0,4.000000e+000,5.000000e-001,1,1,1.693249e-003,0,,0,
1662142131.584,,3.712767e+003,4.999774e+000,6.432632e-004,0.000000e+000,3.104224e-001,0.000000e+000,3,7.643064e-001,1.825000e+000,,,,,,,,,,,,,,,,,,0,4.000000e+000,5.000000e-001,1,1,2.199173e-003,0,,0,
1662142179.764,,3.511539e+003,4.999774e+000,6.075816e-004,0.000000e+000,3.101957e-001,0.000000e+000,3,7.645521e-001,1.825000e+000,,,,,,,,,,,,,,,,,,0,4.000000e+000,5.000000e-001,1,1,2.199173e-003,0,,0,
1662142227.394,,3.311956e+003,4.999942e+000,5.755464e-004,0.000000e+000,3.079305e-001,0.000000e+000,3,7.678024e-001,1.825000e+000,,,,,,,,,,,,,,,,,,0,4.000000e+000,5.000000e-001,1,1,1.523018e-003,0,,0,
1662142274.274,,3.111029e+003,4.999774e+000,5.341831e-004,0.000000e+000,3.155750e-001,0.000000e+000,3,7.622178e-001,1.825000e+000,,,,,,,,,,,,,,,,,,0,4.000000e+000,5.000000e-001,1,1,1.523018e-003,0,,0,
1662142321.954,,2.909949e+003,4.999604e+000,5.072856e-004,0.000000e+000,3.105488e-001,0.000000e+000,3,7.656865e-001,1.825000e+000,,,,,,,,,,,,,,,,,,0,4.000000e+000,5.000000e-001,1,1,2.537251e-003,0,,0,
1662142369.085,,2.708572e+003,4.999520e+000,4.727511e-004,0.000000e+000,3.003289e-001,0.000000e+000,3,7.617038e-001,1.825000e+000,,,,,,,,,,,,,,,,,,0,4.000000e+000,5.000000e-001,1,1,2.367973e-003,0,,0,
1662142416.515,,2.509589e+003,4.999182e+000,4.305232e-004,0.000000e+000,3.041691e-001,0.000000e+000,3,7.426932e-001,1.825000e+000,,,,,,,,,,,,,,,,,,0,4.000000e+000,5.000000e-001,1,1,1.015186e-003,0,,0,
1662142464.395,,2.308211e+003,4.998758e+000,3.977002e-004,0.000000e+000,2.970889e-001,0.000000e+000,3,7.796214e-001,1.825000e+000,,,,,,,,,,,,,,,,,,0,4.000000e+000,5.000000e-001,1,1,1.861095e-003,0,,0,
1662142527.795,,2.106833e+003,4.999604e+000,3.495648e-004,0.000000e+000,3.276631e-001,0.000000e+000,3,7.311206e-001,1.825000e+000,,,,,,,,,,,,,,,,,,0,4.000000e+000,5.000000e-001,1,1,1.524448e-003,0,,0,
1662142577.715,,1.906353e+003,4.999351e+000,3.294569e-004,0.000000e+000,3.037231e-001,0.000000e+000,3,7.500497e-001,1.825000e+000,,,,,,,,,,,,,,,,,,0,4.000000e+000,5.000000e-001,1,1,2.367973e-003,0,,0,
1662142586.685,,1.906353e+003,5.000365e+000,3.307198e-004,0.000000e+000,3.022830e-001,0.000000e+000,3,7.604619e-001,1.825000e+000,,,,,,,,,,,,,,,,,,0,4.000000e+000,5.000000e-001,1,1,3.390312e-004,0,,0,