File: SQUID/22157b_LCOT/LCOT_MH_350K_FC+1T_2.csv
Comment,Time Stamp (sec),Temperature (K),Magnetic Field (Oe),Moment (emu),M. Std. Err. (emu),Transport Action,Averaging Time (sec),Frequency (Hz),Peak Amplitude (mm),Center Position (mm),Lockin Signal' (V),Lockin Signal (V),Range,M. Quad. Signal (emu),AC Moment (emu),AC M. Std Err. (emu),AC Phase (deg),AC Phase Std. Err. (deg),AC Susceptibility (emu/Oe),AC Suscept. Std Err. (emu/Oe),AC X' (emu/Oe),AC X' Std Err. (emu/Oe),AC X'' (emu/Oe),AC X'' Std Err. (emu/Oe),AC Drive (Oe),AC Frequency (Hz),AC Averaging Time (sec),AC Cycles,AC Range,AC Measure Type,AC Signal' (V),AC Signal'' (V),AC Trim Coil Ratio,AC Trim Coil Phase,Min. Temperature (K),Max. Temperature (K),Min. Field (Oe),Max. Field (Oe),Mass (grams),Motor Lag (deg),Pressure (Torr),Measure Count,Measurement Number,SQUID Status (code),Motor Status (code),Measure Status (code),Motor Current (amps),Motor Temp. (C),Temp. Status (code),Field Status (code),Chamber Status (code),Chamber Temp (K),Redirection State,Average Temp (K),Rotation Angle (deg),Rotator state,DC Moment Fixed Ctr (emu),DC Moment Err Fixed Ctr (emu),DC Moment Free Ctr (emu),DC Moment Err Free Ctr (emu),DC Fixed Fit,DC Free Fit,DC Calculated Center (mm),DC Calculated Center Err (mm),DC Scan Length (mm),DC Scan Time (s),DC Number of Points,DC Squid Drift,DC Min V (V),DC Max V (V),DC Scans per Measure,Sample Resistance,He3 Temperature,Sorb Resistance,Sorb Temperature,Map 05,Map 06,Map 07,Map 08,Map 09,Map 10,Map 11,Map 12,Map 13,Map 14,Map 15,Map 16
,3878554540.16441,350.013442993164,69999.7734375,-1.3280416638696E-4,8.17271631100455E-8,1,4,13.4005146026611,4.99656407374924,32.8599996864796,-0.164938784796359,-0.0244804786393186,1,1.5229688553384E-7,,,,,,,,,,,,,,,,,,,,,350.013427734375,350.013458251953,69999.7734375,69999.7734375,53.4477581450057,5.63242777747042,6.25297021865845,54,1,0,0,1,0.299301147460937,33.7243423461914,1,1,3,350.013427734375,0,350.013442993164,,,,,,,,,,,,,,,,,,,,,,,,,,,,,,,,,
,3878554696.61454,349.775497436523,49999.640625,-9.43985529062111E-5,7.70796915818111E-8,1,4,13.4005146026611,4.99632208486895,32.8599996864796,-0.117203057163961,-0.017594711986906,1,-4.87265891838482E-8,,,,,,,,,,,,,,,,,,,,,349.769622802734,349.781372070313,49999.640625,49999.640625,53.7221097552557,5.63370698914679,6.42353057861328,54,1,0,0,1,0.298385620117188,34.7018585205078,1,1,3,349.781372070313,0,349.775497436523,,,,,,,,,,,,,,,,,,,,,,,,,,,,,,,,,
,3878554857.80505,349.962921142578,29999.67578125,-5.60783264239745E-5,3.4086787296254E-8,1,4,13.4005146026611,4.99632217347438,32.8599996864796,-0.0696232161379331,-0.0104679225865064,1,-4.15280907130411E-8,,,,,,,,,,,,,,,,,,,,,349.95068359375,349.975158691406,29999.67578125,29999.67578125,53.6748212298422,5.63421858438055,6.32711172103882,54,1,0,0,1,0.298309326171875,34.7018585205078,1,1,3,349.975158691406,0,349.962921142578,,,,,,,,,,,,,,,,,,,,,,,,,,,,,,,,,
,3878555015.89225,350.092681884766,9999.6064453125,-1.7821899315914E-5,1.23057355709322E-8,1,4,13.4005146026611,4.99616306871597,32.8599996864796,-0.0221194206536212,-0.0033674265254361,1,-4.60826313777129E-8,,,,,,,,,,,,,,,,,,,,,350.080291748047,350.105072021484,9999.6064453125,9999.6064453125,53.8811711589192,5.6359976056732,6.24658250808716,54,1,0,0,1,0.29815673828125,34.7018585205078,1,1,3,350.105072021484,0,350.092681884766,,,,,,,,,,,,,,,,,,,,,,,,,,,,,,,,,
,3878555098.5072,349.893356323242,8499.4638671875,-1.49523462410258E-5,1.11291634516606E-8,1,4,13.4005146026611,4.99596779757449,32.8599996864796,-0.018557927610635,-0.00281817802081934,1,-3.31089876672177E-8,,,,,,,,,,,,,,,,,,,,,349.887603759766,349.899108886719,8499.4638671875,8499.4638671875,53.9245515417365,5.63596789102339,6.21693181991577,54,1,0,0,1,0.299758911132812,34.7018585205078,1,1,3,349.887268066406,0,349.893356323242,,,,,,,,,,,,,,,,,,,,,,,,,,,,,,,,,
,3878555168.73792,349.719161987305,6499.71875,-1.1153331149106E-5,1.21509603384981E-8,1,4,13.4005146026611,4.99621798990177,32.8599996864796,-0.013841473382608,-0.00211782193226798,1,-3.72001959903878E-8,,,,,,,,,,,,,,,,,,,,,349.718597412109,349.7197265625,6499.71875,6499.71875,53.7987093501403,5.63374884846258,6.19254779815674,53,1,68,0,0,0.297698974609375,34.2131004333496,1,1,3,349.718597412109,0,349.719161987305,,,,,,,,,,,,,,,,,,,,,,,,,,,,,,,,,
,3878555248.52275,349.611053466797,4499.646484375,-7.37642703543434E-6,7.04612099511336E-9,1,4,13.4005146026611,4.99626345331207,32.8599996864796,-0.0091555177417587,-0.00139311907576293,1,-1.85200045629616E-8,,,,,,,,,,,,,,,,,,,,,349.597747802734,349.624359130859,4499.646484375,4499.646484375,53.821376577198,5.63379804155337,6.16207599639893,54,1,0,0,1,0.29815673828125,34.7018585205078,1,1,3,349.624359130859,0,349.611053466797,,,,,,,,,,,,,,,,,,,,,,,,,,,,,,,,,
,3878555341.94076,349.587142944336,2999.79370117188,-4.59030213460015E-6,6.44113236274415E-9,1,4,13.4005146026611,4.99625934925354,32.8599996864796,-0.00569731390103936,-8.67583976501263E-4,1,-1.20532992036656E-8,,,,,,,,,,,,,,,,,,,,,349.586242675781,349.588043212891,2999.79370117188,2999.79370117188,53.8389632188807,5.63354374263744,6.13851070404053,54,1,0,0,1,0.298080444335937,34.2131004333496,1,1,3,349.588043212891,0,349.587142944336,,,,,,,,,,,,,,,,,,,,,,,,,,,,,,,,,
,3878555414.0589,349.721008300781,2799.640625,-4.3020719889809E-6,1.78085752739458E-8,1,4,13.4005146026611,4.99627811870675,32.8599996864796,-0.00537637365946262,-5.67297385540877E-4,10,1.86676272638249E-7,,,,,,,,,,,,,,,,,,,,,349.718719482422,349.723297119141,2799.640625,2799.640625,53.8706191739095,5.63282914101082,6.12036466598511,54,1,0,0,1,0.299606323242188,34.7018585205078,1,1,3,349.723297119141,0,349.721008300781,,,,,,,,,,,,,,,,,,,,,,,,,,,,,,,,,
,3878555491.69297,349.766052246094,2599.63842773438,-3.95294564275916E-6,1.58204341395982E-8,1,4,13.4005146026611,4.99636961130706,32.8599996864796,-0.00494575856140995,-4.84055732321205E-4,10,2.01499874751393E-7,,,,,,,,,,,,,,,,,,,,,349.758361816406,349.773742675781,2599.63842773438,2599.63842773438,53.846779504073,5.63171189758003,6.09561729431152,54,1,0,0,1,0.29815673828125,35.190616607666,1,1,3,349.758361816406,0,349.766052246094,,,,,,,,,,,,,,,,,,,,,,,,,,,,,,,,,
,3878555558.42639,349.650451660156,2399.5478515625,-3.5673235340622E-6,1.6806731877361E-8,1,4,13.4005146026611,4.99642067918617,32.8599996864796,-0.00445973242363049,-4.61012497866975E-4,1,1.62376467920393E-7,,,,,,,,,,,,,,,,,,,,,349.648803710937,349.652099609375,2399.5478515625,2399.5478515625,53.8248939055345,5.63235711442274,6.08472394943237,53,1,68,0,0,0.297927856445313,34.7018585205078,1,1,3,349.652099609375,0,349.650451660156,,,,,,,,,,,,,,,,,,,,,,,,,,,,,,,,,
,3878555643.17254,349.82926940918,2199.77221679687,-3.24982781289096E-6,1.69538975341271E-8,1,4,13.4005146026611,4.99656767909256,32.8599996864796,-0.0040701990849319,-3.71732645657258E-4,10,1.86794295626672E-7,,,,,,,,,,,,,,,,,,,,,349.826782226562,349.831756591797,2199.77221679687,2199.77221679687,53.8225490199768,5.63295837731854,6.06708145141602,54,1,0,0,1,0.298385620117188,34.7018585205078,1,1,3,349.831756591797,0,349.82926940918,,,,,,,,,,,,,,,,,,,,,,,,,,,,,,,,,
,3878555726.50964,349.728408813477,1999.53088378906,-2.8835141296337E-6,1.96817762741548E-8,1,4,13.4005146026611,4.99658071531911,32.8599996864796,-0.00362095957062797,-2.66117204202292E-4,1,2.1704995432775E-7,,,,,,,,,,,,,,,,,,,,,349.721710205078,349.735107421875,1999.53088378906,1999.53088378906,53.7310984832268,5.63335983588013,6.04763507843018,54,1,0,0,1,0.298233032226562,34.7018585205078,1,1,3,349.721710205078,0,349.728408813477,,,,,,,,,,,,,,,,,,,,,,,,,,,,,,,,,
,3878555783.71528,349.925659179687,1799.8056640625,-2.52435266481189E-6,2.0083442399066E-8,1,4,13.4005146026611,4.99664183022061,32.8599996864796,-0.00317534657927823,-1.97223868315989E-4,1,2.18804605017251E-7,,,,,,,,,,,,,,,,,,,,,349.919860839844,349.931457519531,1799.8056640625,1799.8056640625,53.8381815903615,5.63233194549906,6.03905582427978,53,1,68,0,0,0.298233032226562,34.7018585205078,1,1,3,349.919860839844,0,349.925659179687,,,,,,,,,,,,,,,,,,,,,,,,,,,,,,,,,
,3878555860.03463,350.093978881836,1599.6650390625,-2.18626897922913E-6,1.76071711962786E-8,1,4,13.4005146026611,4.99667529964897,32.8599996864796,-0.00275028496551988,-1.69587163616109E-4,1,1.90486294444824E-7,,,,,,,,,,,,,,,,,,,,,350.077362060547,350.110595703125,1599.6650390625,1599.6650390625,53.9104822283903,5.63276935444011,6.02729082107544,54,1,0,0,1,0.29754638671875,34.7018585205078,1,1,3,350.110595703125,0,350.093978881836,,,,,,,,,,,,,,,,,,,,,,,,,,,,,,,,,
,3878555916.24444,350.101593017578,1399.68811035156,-1.80721095871368E-6,1.10297861007424E-7,1,4,13.4005146026611,4.99665883611576,32.8599996864796,-0.00226569907909432,-1.91840408055034E-4,1,1.15860621534627E-7,,,,,,,,,,,,,,,,,,,,,350.088012695313,350.115173339844,1399.68811035156,1399.68811035156,53.8987578006019,5.63341776242342,6.01987409591675,54,1,0,0,1,0.298233032226562,34.7018585205078,1,1,3,350.088012695313,0,350.101593017578,,,,,,,,,,,,,,,,,,,,,,,,,,,,,,,,,
,3878555973.82879,350.026153564453,1199.57263183594,-1.52578286708671E-6,2.22673245658284E-8,1,4,13.4005146026611,4.99664126869306,32.8599996864796,-0.00193274358131005,-2.90713029748937E-5,1,2.0483679900472E-7,,,,,,,,,,,,,,,,,,,,,350.016448974609,350.035858154297,1199.57263183594,1199.57263183594,53.922988284698,5.63299087270607,6.01157331466675,54,1,0,0,1,0.297393798828125,34.7018585205078,1,1,3,350.016448974609,0,350.026153564453,,,,,,,,,,,,,,,,,,,,,,,,,,,,,,,,,
,3878556047.43251,349.815689086914,999.784362792969,-1.25298208408461E-6,2.42480486247231E-8,1,4,13.4005146026611,4.99667827946278,32.8599996864796,-0.00160360738405685,8.58249059498373E-5,1,2.56551896491393E-7,,,,,,,,,,,,,,,,,,,,,349.804412841797,349.826965332031,999.784362792969,999.784362792969,53.7991001643999,5.63294867037604,5.99586820602417,52,1,68,0,0,0.298233032226562,34.2131004333496,1,1,3,349.804412841797,0,349.815689086914,,,,,,,,,,,,,,,,,,,,,,,,,,,,,,,,,
,3878556122.40856,349.813735961914,799.83251953125,-9.30938521221418E-7,2.51377251135887E-8,1,4,13.4005146026611,4.99649968802536,32.8599996864796,-0.00120724188678709,1.69756515582559E-4,1,2.7597185508681E-7,,,,,,,,,,,,,,,,,,,,,349.8056640625,349.821807861328,799.83251953125,799.83251953125,53.8948496580057,5.63285258456561,5.99393463134766,52,1,68,0,0,0.29876708984375,34.2131004333496,1,1,3,349.8056640625,0,349.813735961914,,,,,,,,,,,,,,,,,,,,,,,,,,,,,,,,,
,3878556216.23599,349.624099731445,600.006530761719,-6.02881663558498E-7,1.70719625345018E-8,1,4,13.4005146026611,4.99634490165865,32.8599996864796,-7.73828006552804E-4,5.67496490366579E-5,1,1.35891284315301E-7,,,,,,,,,,,,,,,,,,,,,349.623107910156,349.625091552734,600.006530761719,600.006530761719,53.7819043369768,5.63279447376373,5.98035001754761,53,1,64,0,0,0.298538208007812,34.2131004333496,1,1,3,349.625091552734,0,349.624099731445,,,,,,,,,,,,,,,,,,,,,,,,,,,,,,,,,
,3878556295.80918,349.710296630859,399.928863525391,-3.86993811049045E-7,2.43288797689817E-8,1,4,13.4005146026611,4.99642564906836,32.8599996864796,-5.25250689303194E-4,2.27038425331782E-4,1,2.40735430769276E-7,,,,,,,,,,,,,,,,,,,,,349.701446533203,349.719146728516,399.928863525391,399.928863525391,53.9046200144961,5.63243356927579,5.97441101074219,53,1,68,0,0,0.29876708984375,34.2131004333496,1,1,3,349.719146728516,0,349.710296630859,,,,,,,,,,,,,,,,,,,,,,,,,,,,,,,,,
,3878556387.36175,349.831207275391,200.077728271484,-1.07735446019843E-7,2.75034104916836E-8,1,4,13.4005146026611,4.99633941006409,32.8599996864796,-1.8464498287632E-4,3.20057015728707E-4,1,2.73878090478015E-7,,,,,,,,,,,,,,,,,,,,,349.817810058594,349.844604492188,200.077728271484,200.077728271484,53.8030083069961,5.63299162531033,5.96334457397461,52,1,68,0,0,0.298919677734375,34.2131004333496,1,1,3,349.844604492188,0,349.831207275391,,,,,,,,,,,,,,,,,,,,,,,,,,,,,,,,,
,3878556478.85779,349.929885864258,0.0503530204296112,2.89852938207895E-8,2.60755864054318E-8,1,4,13.4005146026611,4.99635210777139,32.8599996864796,-1.72140571531822E-5,3.61044385437573E-4,1,2.86434115963802E-7,,,,,,,,,,,,,,,,,,,,,349.927276611328,349.932495117188,0.0503530204296112,0.0503530204296112,53.7701799091884,5.63301950365692,5.95343589782715,53,1,68,0,0,0.299072265625,34.2131004333496,1,1,3,349.932495117188,0,349.929885864258,,,,,,,,,,,,,,,,,,,,,,,,,,,,,,,,,
,3878556553.9845,349.944488525391,-199.737838745117,1.96213971584953E-7,1.70046526067317E-8,1,4,13.4005146026611,4.99639727194652,32.8599996864796,2.02272632131266E-4,3.12969174959431E-4,1,2.22696769428907E-7,,,,,,,,,,,,,,,,,,,,,349.941467285156,349.947509765625,-199.737838745117,-199.737838745117,53.867101845573,5.63236538542347,5.95240783691406,54,1,0,0,1,0.298995971679687,34.7018585205078,1,1,3,349.947509765625,0,349.944488525391,,,,,,,,,,,,,,,,,,,,,,,,,,,,,,,,,
,3878556628.26376,349.880386352539,-399.790374755859,3.87102991019696E-7,1.92441717509079E-8,1,4,13.4005146026611,4.99640233767125,32.8599996864796,4.43690666657116E-4,3.19076406152371E-4,1,1.99059030704202E-7,,,,,,,,,,,,,,,,,,,,,349.877105712891,349.883666992188,-399.790374755859,-399.790374755859,53.8026174927365,5.63250869784525,5.93711853027344,53,1,68,0,0,0.297393798828125,36.1681327819824,1,1,3,349.883666992188,0,349.880386352539,,,,,,,,,,,,,,,,,,,,,,,,,,,,,,,,,
,3878556710.27904,349.879241943359,-599.654113769531,6.15598415139506E-7,2.06900598743306E-8,1,4,13.4005146026611,4.99649282873108,32.8599996864796,7.26772575946018E-4,3.65937078694404E-4,10,2.02609154661531E-7,,,,,,,,,,,,,,,,,,,,,349.869323730469,349.88916015625,-599.654113769531,-599.654113769531,53.8745273165057,5.63277929833913,5.93687868118286,54,1,0,0,1,0.297927856445313,34.2131004333496,1,1,3,349.88916015625,0,349.879241943359,,,,,,,,,,,,,,,,,,,,,,,,,,,,,,,,,
,3878556776.75248,349.748672485352,-799.656311035156,8.74881369251359E-7,1.96796231522218E-8,1,4,13.4005146026611,4.99646842139489,32.8599996864796,0.00105083606095211,3.99988062834072E-4,1,1.91246390325211E-7,,,,,,,,,,,,,,,,,,,,,349.739715576172,349.757629394531,-799.656311035156,-799.656311035156,53.8452162470345,5.63194700739127,5.93089723587036,54,1,0,0,1,0.298690795898438,34.2131004333496,1,1,3,349.739715576172,0,349.748672485352,,,,,,,,,,,,,,,,,,,,,,,,,,,,,,,,,
,3878556852.51053,349.894821166992,-999.734008789063,1.19063754349229E-6,4.59689702809574E-8,1,4,13.4005146026611,4.99647697713465,32.8599996864796,0.00145862108335054,3.53693664264112E-4,1,1.06728159692625E-7,,,,,,,,,,,,,,,,,,,,,349.8779296875,349.911712646484,-999.734008789063,-999.734008789063,53.9014935004192,5.6324404251686,5.93163824081421,54,1,0,0,1,0.298919677734375,34.2131004333496,1,1,3,349.911712646484,0,349.894821166992,,,,,,,,,,,,,,,,,,,,,,,,,,,,,,,,,
,3878556938.59661,349.780426025391,-1199.79907226562,1.54737978711867E-6,3.86462451506521E-8,1,4,13.4005146026611,4.99650196800667,32.8599996864796,0.00189391215853873,4.71426383851365E-4,10,1.4817277741097E-7,,,,,,,,,,,,,,,,,,,,,349.774322509766,349.786529541016,-1199.79907226562,-1199.79907226562,53.8952404722653,5.63228201139069,5.91604280471802,54,1,0,0,1,0.297775268554687,35.6793746948242,1,1,3,349.786529541016,0,349.780426025391,,,,,,,,,,,,,,,,,,,,,,,,,,,,,,,,,
,3878557032.60086,349.801712036133,-1399.67553710938,1.83535397471147E-6,1.11832462814738E-8,1,4,13.4005146026611,4.99653777319029,32.8599996864796,0.00224782990954838,5.496084853745E-4,10,1.68051140734039E-7,,,,,,,,,,,,,,,,,,,,,349.790313720703,349.813110351562,-1399.67553710938,-1399.67553710938,53.8557682320442,5.63237819473965,5.91413307189941,54,1,0,0,1,0.298538208007812,34.2131004333496,1,1,3,349.813110351562,0,349.801712036133,,,,,,,,,,,,,,,,,,,,,,,,,,,,,,,,,
,3878557127.11793,350.011016845703,-1599.6650390625,2.17749953629559E-6,1.05539969494649E-8,1,4,13.4005146026611,4.99659383083999,32.8599996864796,0.00267653948191952,5.8771143295185E-4,10,1.47545769575832E-7,,,,,,,,,,,,,,,,,,,,,349.993286132812,350.028747558594,-1599.6650390625,-1599.6650390625,53.8119970349672,5.63271211386616,5.91340398788452,54,1,0,0,1,0.298614501953125,34.7018585205078,1,1,3,350.028747558594,0,350.011016845703,,,,,,,,,,,,,,,,,,,,,,,,,,,,,,,,,
,3878557196.7393,350.064544677734,-1799.70495605469,2.58182054026065E-6,7.42036459388469E-8,1,4,13.4005146026611,4.99663888597424,32.8599996864796,0.00318929997221787,5.91648976804428E-4,1,9.02267408133102E-8,,,,,,,,,,,,,,,,,,,,,350.050445556641,350.078643798828,-1799.70495605469,-1799.70495605469,53.8014450499576,5.63310379815373,5.90618228912354,54,1,0,0,1,0.297622680664063,34.2131004333496,1,1,3,350.078643798828,0,350.064544677734,,,,,,,,,,,,,,,,,,,,,,,,,,,,,,,,,
,3878557273.00717,349.948043823242,-1999.79528808594,2.83548585276365E-6,5.59374202647837E-8,1,4,13.4005146026611,4.9966124667079,32.8599996864796,0.00350941730271382,6.04366013396085E-4,1,6.25245250380874E-8,,,,,,,,,,,,,,,,,,,,,349.938201904297,349.957885742188,-1999.79528808594,-1999.79528808594,53.9163444422846,5.63292901320045,5.90296363830566,54,1,0,0,1,0.297622680664063,33.7243423461914,1,1,3,349.938201904297,0,349.948043823242,,,,,,,,,,,,,,,,,,,,,,,,,,,,,,,,,
,3878557332.5989,349.899505615234,-2199.78491210938,3.2159071736442E-6,2.12000728939231E-8,1,4,13.4005146026611,4.99662184594237,32.8599996864796,0.00397825628709762,6.98891434383799E-4,1,8.17356485008323E-8,,,,,,,,,,,,,,,,,,,,,349.885650634766,349.913360595703,-2199.78491210938,-2199.78491210938,53.8288020481307,5.63268249058153,5.90189695358276,54,1,0,0,1,0.299072265625,33.7243423461914,1,1,3,349.913360595703,0,349.899505615234,,,,,,,,,,,,,,,,,,,,,,,,,,,,,,,,,
,3878557393.32772,349.705169677734,-2399.74926757813,3.57797877591938E-6,8.34445630073271E-9,1,4,13.4005146026611,4.99663882523829,32.8599996864796,0.00442253298717119,8.01961721785862E-4,1,1.10571143099013E-7,,,,,,,,,,,,,,,,,,,,,349.700012207031,349.710327148438,-2399.74926757813,-2399.74926757813,54.0097490503326,5.63253966502177,5.89918375015259,54,1,0,0,1,0.298690795898438,33.7243423461914,1,1,3,349.710327148438,0,349.705169677734,,,,,,,,,,,,,,,,,,,,,,,,,,,,,,,,,
,3878557459.23202,349.660659790039,-2599.66357421875,3.92795508285798E-6,9.96844142816907E-9,1,4,13.4005146026611,4.99686917921838,32.8599996864796,0.00485621095092083,8.75253897381028E-4,1,1.17193074487867E-7,,,,,,,,,,,,,,,,,,,,,349.652130126953,349.669189453125,-2599.66357421875,-2599.66357421875,53.8674926598326,5.63280454065456,5.8954930305481,54,1,0,0,1,0.297012329101562,34.2131004333496,1,1,3,349.670288085937,0,349.660659790039,,,,,,,,,,,,,,,,,,,,,,,,,,,,,,,,,
,3878557524.72624,349.608413696289,-2799.79150390625,4.30590530145906E-6,7.08425046016138E-9,1,4,13.4005146026611,4.99681491801978,32.8599996864796,0.00533161343567568,9.0453561373676E-4,1,8.4243984294352E-8,,,,,,,,,,,,,,,,,,,,,349.606201171875,349.610626220703,-2799.79150390625,-2799.79150390625,53.790893064948,5.63340364756425,5.89689683914185,54,1,0,0,1,0.298309326171875,34.2131004333496,1,1,3,349.610626220703,0,349.608413696289,,,,,,,,,,,,,,,,,,,,,,,,,,,,,,,,,
,3878557605.60403,349.669799804687,-2999.59228515625,4.6580368324626E-6,2.20715313615257E-8,1,4,13.4005146026611,4.99681280754611,32.8599996864796,0.00577142235221401,9.53106894926019E-4,1,7.067994704368E-8,,,,,,,,,,,,,,,,,,,,,349.654968261719,349.684631347656,-2999.59228515625,-2999.59228515625,53.790893064948,5.63326971049045,5.89064836502075,54,1,0,0,1,0.298080444335937,34.2131004333496,1,1,3,349.685943603516,0,349.669799804687,,,,,,,,,,,,,,,,,,,,,,,,,,,,,,,,,
,3878557684.60598,349.72119140625,-4499.646484375,7.50945516148367E-6,1.76766517112716E-8,1,4,13.4005146026611,4.99679533571967,32.8599996864796,0.00933350094690362,0.00134170564282405,1,-4.29485129887703E-8,,,,,,,,,,,,,,,,,,,,,349.713592529297,349.728790283203,-4499.646484375,-4499.646484375,53.9167352565442,5.63346665917886,5.88914012908936,54,1,0,0,1,0.297470092773438,33.7243423461914,1,1,3,349.713592529297,0,349.72119140625,,,,,,,,,,,,,,,,,,,,,,,,,,,,,,,,,
,3878557763.16972,349.609115600586,-6499.6181640625,1.12868970998107E-5,8.29899391315255E-9,1,4,13.4005146026611,4.99680362233962,32.8599996864796,0.014019848091984,0.00207456222422891,1,-1.7895528413571E-8,,,,,,,,,,,,,,,,,,,,,349.592926025391,349.625305175781,-6499.6181640625,-6499.6181640625,53.7162475413615,5.63320455417816,5.88863134384155,54,1,0,0,1,0.298385620117188,34.2131004333496,1,1,3,349.625305175781,0,349.609115600586,,,,,,,,,,,,,,,,,,,,,,,,,,,,,,,,,
,3878557834.48645,349.725357055664,-8499.8671875,1.50987037813538E-5,1.34903771432809E-8,1,4,13.4005146026611,4.9967231012298,32.8599996864796,0.0187582719475764,0.0027479185995263,1,-4.58437882624647E-8,,,,,,,,,,,,,,,,,,,,,349.71728515625,349.733428955078,-8499.8671875,-8499.8671875,53.801054235698,5.63381449097111,5.88521909713745,54,1,0,0,1,0.2972412109375,33.7243423461914,1,1,3,349.733428955078,0,349.725357055664,,,,,,,,,,,,,,,,,,,,,,,,,,,,,,,,,
,3878557915.42532,349.909820556641,-9999.5810546875,1.79554035430126E-5,1.70327229450106E-8,1,4,13.4005146026611,4.99675273589371,32.8599996864796,0.0223008280930393,0.00331281305635108,1,-1.83154221390192E-8,,,,,,,,,,,,,,,,,,,,,349.908660888672,349.910980224609,-9999.5810546875,-9999.5810546875,53.7850308510538,5.6335275481085,5.88355016708374,54,1,0,0,1,0.298995971679687,33.2355842590332,1,1,3,349.910980224609,0,349.909820556641,,,,,,,,,,,,,,,,,,,,,,,,,,,,,,,,,
,3878558072.46043,349.908752441406,-29999.6875,5.62211494291064E-5,3.4971870803071E-8,1,4,13.4005146026611,4.99671241055128,32.8599996864796,0.0698354240477011,0.0103135437342962,1,-1.05077050518209E-7,,,,,,,,,,,,,,,,,,,,,349.892639160156,349.924865722656,-29999.6875,-29999.6875,53.8788262733615,5.63401991397555,5.88033485412598,52,1,68,0,0,0.299148559570313,34.2131004333496,1,1,3,349.924865722656,0,349.908752441406,,,,,,,,,,,,,,,,,,,,,,,,,,,,,,,,,
,3878558232.01497,350.056350708008,-49999.69140625,9.45158078370211E-5,5.15071339106369E-8,1,4,13.4005146026611,4.99672660260657,32.8599996864796,0.117385949074033,0.0174580841559969,1,-8.04431771553534E-8,,,,,,,,,,,,,,,,,,,,,350.055297851562,350.057403564453,-49999.69140625,-49999.69140625,53.6986608996788,5.63344172762007,5.87005996704102,54,1,0,0,1,0.298614501953125,33.7243423461914,1,1,3,350.055297851562,0,350.056350708008,,,,,,,,,,,,,,,,,,,,,,,,,,,,,,,,,
,3878558392.16747,349.970809936523,-69999.609375,1.33087380809593E-4,1.30477186811927E-7,1,4,13.4005146026611,4.9967510788468,32.8599996864796,0.16528531945227,0.024626698648384,1,-7.79507867712208E-8,,,,,,,,,,,,,,,,,,,,,349.970367431641,349.971252441406,-69999.609375,-69999.609375,53.4688621150249,5.63344632198594,5.86904430389404,54,1,0,0,1,0.298080444335937,34.2131004333496,1,1,3,349.971252441406,0,349.970809936523,,,,,,,,,,,,,,,,,,,,,,,,,,,,,,,,,
,3878558552.65036,350.143646240234,-49999.7421875,9.45775981140687E-5,7.48520061509032E-8,1,4,13.4005146026611,4.99673917041808,32.8599996864796,0.117442273112848,0.0176088121923714,1,3.16407927792425E-8,,,,,,,,,,,,,,,,,,,,,350.129730224609,350.157562255859,-49999.7421875,-49999.7421875,53.5982216349576,5.63356589904511,5.86349630355835,54,1,0,0,1,0.29815673828125,33.2355842590332,1,1,3,350.157562255859,0,350.143646240234,,,,,,,,,,,,,,,,,,,,,,,,,,,,,,,,,
,3878558713.31819,349.898178100586,-29999.6875,5.61604380565894E-5,3.12554931282534E-8,1,4,13.4005146026611,4.99679533570558,32.8599996864796,0.069737437969361,0.0104643784068854,1,2.52728891888408E-8,,,,,,,,,,,,,,,,,,,,,349.888458251953,349.907897949219,-29999.6875,-29999.6875,53.7678350236307,5.63374514608854,5.86817502975464,54,1,0,0,1,0.298385620117188,34.2131004333496,1,1,3,349.907897949219,0,349.898178100586,,,,,,,,,,,,,,,,,,,,,,,,,,,,,,,,,
,3878558871.29868,350.14208984375,-10000.134765625,1.78475880956752E-5,1.23947979170981E-8,1,4,13.4005146026611,4.99669220150758,32.8599996864796,0.0221557847598309,0.00336478787367334,1,3.97127264905559E-8,,,,,,,,,,,,,,,,,,,,,350.131134033203,350.153045654297,-10000.134765625,-10000.134765625,53.8573314890826,5.63350879637714,5.85882329940796,54,1,0,0,1,0.297927856445313,34.7018585205078,1,1,3,350.153045654297,0,350.14208984375,,,,,,,,,,,,,,,,,,,,,,,,,,,,,,,,,
,3878558949.85653,350.146240234375,-8499.98046875,1.49832975154962E-5,1.64606613487231E-8,1,4,13.4005146026611,4.99673308412459,32.8599996864796,0.0185987883058534,0.00283493313647991,1,4.14844967318994E-8,,,,,,,,,,,,,,,,,,,,,350.143981933594,350.148498535156,-8499.98046875,-8499.98046875,53.7479034963903,5.63408374971953,5.86364507675171,53,1,68,0,0,0.298233032226562,34.7018585205078,1,1,3,350.148498535156,0,350.146240234375,,,,,,,,,,,,,,,,,,,,,,,,,,,,,,,,,
,3878559016.04596,350.211563110352,-6499.857421875,1.1150998823468E-5,1.08218876792941E-8,1,4,13.4005146026611,4.99663740719635,32.8599996864796,0.0138387536725622,0.00212733434425756,1,4.5008903943333E-8,,,,,,,,,,,,,,,,,,,,,350.208740234375,350.214385986328,-6499.857421875,-6499.857421875,53.740087211198,5.63387880260567,5.85900974273682,53,1,68,0,0,0.297698974609375,34.7018585205078,1,1,3,350.208740234375,0,350.211563110352,,,,,,,,,,,,,,,,,,,,,,,,,,,,,,,,,
,3878559098.13355,349.957260131836,-4500.23828125,7.37415512085475E-6,9.86673087615169E-9,1,4,13.4005146026611,4.99670484891045,32.8599996864796,0.00914891141289229,0.00142574295020303,1,4.4992399499294E-8,,,,,,,,,,,,,,,,,,,,,349.956359863281,349.958160400391,-4500.23828125,-4500.23828125,53.8159051775634,5.63358652038465,5.86008834838867,52,1,68,0,0,0.298843383789063,34.2131004333496,1,1,3,349.958160400391,0,349.957260131836,,,,,,,,,,,,,,,,,,,,,,,,,,,,,,,,,
,3878559187.41116,350.162048339844,-3000.3349609375,4.60247382794522E-6,5.93990003083784E-9,1,4,13.4005146026611,4.99670683447311,32.8599996864796,0.00571528313348623,8.55649806385855E-4,10,5.3453745508721E-10,,,,,,,,,,,,,,,,,,,,,350.160797119141,350.163299560547,-3000.3349609375,-3000.3349609375,53.8561590463038,5.63420718994402,5.86370801925659,54,1,0,0,1,0.297088623046875,34.7018585205078,1,1,3,350.163299560547,0,350.162048339844,,,,,,,,,,,,,,,,,,,,,,,,,,,,,,,,,
,3878559252.26215,349.900161743164,-2800.16918945313,4.33844774490903E-6,1.72826944553266E-8,1,4,13.4005146026611,4.99669717152378,32.8599996864796,0.00542233096721091,5.73089720915295E-4,1,-1.87507060828547E-7,,,,,,,,,,,,,,,,,,,,,349.884338378906,349.915985107422,-2800.16918945313,-2800.16918945313,53.8729640594672,5.63358524593008,5.86216163635254,53,1,68,0,0,0.298995971679687,34.7018585205078,1,1,3,349.884338378906,0,349.900161743164,,,,,,,,,,,,,,,,,,,,,,,,,,,,,,,,,
,3878559308.91298,349.9208984375,-2600.12939453125,3.95155563694201E-6,1.43272675236891E-8,1,4,13.4005146026611,4.99677304959452,32.8599996864796,0.00493811678599834,5.27134984668743E-4,1,-1.66645865209403E-7,,,,,,,,,,,,,,,,,,,,,349.906555175781,349.935241699219,-2600.12939453125,-2600.12939453125,53.8714008024288,5.63382804375285,5.8567910194397,53,1,68,0,0,0.29754638671875,34.7018585205078,1,1,3,349.935241699219,0,349.9208984375,,,,,,,,,,,,,,,,,,,,,,,,,,,,,,,,,
,3878559365.99806,350.115097045898,-2400.32836914062,3.58712951905769E-6,1.82617627956999E-8,1,4,13.4005146026611,4.99670216202824,32.8599996864796,0.00448772709039958,4.44355130968226E-4,1,-1.7878244258645E-7,,,,,,,,,,,,,,,,,,,,,350.11279296875,350.117401123047,-2400.32836914062,-2400.32836914062,53.9011026861596,5.63366407592064,5.85304069519043,54,1,0,0,1,0.297622680664063,34.7018585205078,1,1,3,350.117462158203,0,350.115097045898,,,,,,,,,,,,,,,,,,,,,,,,,,,,,,,,,
,3878559423.20372,350.111145019531,-2200.28833007813,3.25218490253358E-6,2.00724305196605E-8,1,4,13.4005146026611,4.99669986677079,32.8599996864796,0.00407407803301919,3.66828952692185E-4,1,-1.91106836607937E-7,,,,,,,,,,,,,,,,,,,,,350.107849121094,350.114440917969,-2200.28833007813,-2200.28833007813,53.7721339804865,5.63412132550283,5.85617351531982,54,1,0,0,1,0.297393798828125,34.2131004333496,1,1,3,350.107849121094,0,350.111145019531,,,,,,,,,,,,,,,,,,,,,,,,,,,,,,,,,
,3878559481.87447,349.955520629883,-2000.24853515625,2.8779739760108E-6,2.98967382368738E-8,1,4,13.4005146026611,4.99672478929019,32.8599996864796,0.0036107963538318,2.88024721046462E-4,1,-1.98588273249896E-7,,,,,,,,,,,,,,,,,,,,,349.953704833984,349.957336425781,-2000.24853515625,-2000.24853515625,53.8182500631211,5.63373222779666,5.85771131515503,53,1,68,0,0,0.297470092773438,34.7018585205078,1,1,3,349.957336425781,0,349.955520629883,,,,,,,,,,,,,,,,,,,,,,,,,,,,,,,,,
,3878559538.21177,349.873870849609,-1799.95678710938,2.53959442408366E-6,1.99922852119696E-8,1,4,13.4005146026611,4.99670856236866,32.8599996864796,0.00319489516967469,1.96302916654817E-4,1,-2.21829270496165E-7,,,,,,,,,,,,,,,,,,,,,349.872955322266,349.874786376953,-1799.95678710938,-1799.95678710938,53.7436045395345,5.63424094820352,5.85539293289185,54,1,0,0,1,0.29815673828125,34.7018585205078,1,1,3,349.873107910156,0,349.873870849609,,,,,,,,,,,,,,,,,,,,,,,,,,,,,,,,,
,3878559596.39824,349.838562011719,-1600.08044433594,2.21744847911218E-6,2.16993068908032E-8,1,4,13.4005146026611,4.99674549459971,32.8599996864796,0.00278964007072071,1.71494305753702E-4,1,-1.93617478283112E-7,,,,,,,,,,,,,,,,,,,,,349.835388183594,349.841735839844,-1600.08044433594,-1600.08044433594,53.8088705208903,5.63413392507489,5.85694408416748,53,1,68,0,0,0.298538208007812,34.2131004333496,1,1,3,349.841735839844,0,349.838562011719,,,,,,,,,,,,,,,,,,,,,,,,,,,,,,,,,
,3878559679.26756,349.822891235352,-1400.09094238281,1.8727589409342E-6,2.17275387068454E-8,1,4,13.4005146026611,4.99667204031702,32.8599996864796,0.00236704488136847,7.07214009244335E-5,10,-2.23202234846019E-7,,,,,,,,,,,,,,,,,,,,,349.820068359375,349.825714111328,-1400.09094238281,-1400.09094238281,53.8479519468519,5.63433995419969,5.85757493972778,54,1,0,0,1,0.297775268554687,34.7018585205078,1,1,3,349.820068359375,0,349.822891235352,,,,,,,,,,,,,,,,,,,,,,,,,,,,,,,,,
,3878559744.43724,349.937057495117,-1200.05090332031,1.57239650458225E-6,2.25095555007962E-8,1,4,13.4005146026611,4.9966492892465,32.8599996864796,0.00199474552956997,1.02332698498884E-5,1,-2.26980069899506E-7,,,,,,,,,,,,,,,,,,,,,349.924255371094,349.949859619141,-1200.05090332031,-1200.05090332031,53.8631937029769,5.63347766652583,5.85519218444824,52,1,68,0,0,0.29815673828125,34.2131004333496,1,1,3,349.949859619141,0,349.937057495117,,,,,,,,,,,,,,,,,,,,,,,,,,,,,,,,,
,3878559818.59843,350.140609741211,-1000.01092529297,1.23368293818769E-6,2.12241907069222E-8,1,4,13.4005146026611,4.99665169238483,32.8599996864796,0.00157824261911286,-8.01350331435703E-5,1,-2.49083375778077E-7,,,,,,,,,,,,,,,,,,,,,350.1279296875,350.153289794922,-1000.01092529297,-1000.01092529297,53.6576254024191,5.63392411158114,5.85465478897095,54,1,0,0,1,0.298385620117188,34.7018585205078,1,1,3,350.153289794922,0,350.140609741211,,,,,,,,,,,,,,,,,,,,,,,,,,,,,,,,,
,3878559892.00647,350.069839477539,-800.0087890625,9.54942394297655E-7,2.29284066315468E-8,1,4,13.4005146026611,4.99667649859635,32.8599996864796,0.00123521728621599,-1.52656022699138E-4,1,-2.65785138865868E-7,,,,,,,,,,,,,,,,,,,,,350.059326171875,350.080352783203,-800.0087890625,-800.0087890625,53.7486851249095,5.63346577697537,5.85075283050537,52,1,68,0,0,0.29754638671875,34.2131004333496,1,1,3,350.059326171875,0,350.069839477539,,,,,,,,,,,,,,,,,,,,,,,,,,,,,,,,,
,3878559966.16686,349.975387573242,-600.094665527344,6.22177393141077E-7,2.37928617960422E-8,1,4,13.4005146026611,4.99669142336829,32.8599996864796,8.19490047051207E-4,-1.97731618581781E-4,1,-2.52303588818635E-7,,,,,,,,,,,,,,,,,,,,,349.974731445313,349.976043701172,-600.094665527344,-600.094665527344,53.6814650722557,5.63397531915301,5.85512971878052,52,1,68,0,0,0.297698974609375,34.2131004333496,1,1,3,349.976043701172,0,349.975387573242,,,,,,,,,,,,,,,,,,,,,,,,,,,,,,,,,
,3878560047.49304,350.004898071289,-400.105102539063,3.92793523764753E-7,2.5892721693691E-8,1,4,13.4005146026611,4.99669812412185,32.8599996864796,5.3156393138177E-4,-2.19768413206722E-4,10,-2.35734672893515E-7,,,,,,,,,,,,,,,,,,,,,350.0048828125,350.004913330078,-400.105102539063,-400.105102539063,53.7740880517845,5.63380737439421,5.851158618927,54,1,0,0,1,0.2984619140625,34.2131004333496,1,1,3,350.0048828125,0,350.004898071289,,,,,,,,,,,,,,,,,,,,,,,,,,,,,,,,,
,3878560113.96991,350.080490112305,-200.039962768555,1.5073378816196E-7,2.26180625459869E-8,1,4,13.4005146026611,4.99663858391143,32.8599996864796,2.29202473927737E-4,-2.52918808842892E-4,1,-2.26222787077303E-7,,,,,,,,,,,,,,,,,,,,,350.077850341797,350.083129882812,-200.039962768555,-200.039962768555,53.9487820258326,5.63395988704762,5.85659599304199,52,1,68,0,0,0.297012329101562,34.7018585205078,1,1,3,350.083129882812,0,350.080490112305,,,,,,,,,,,,,,,,,,,,,,,,,,,,,,,,,
,3878560188.36668,349.962631225586,-0.0503530204296112,-2.61567828478495E-9,2.53282748106336E-8,1,4,13.4005146026611,4.99668757084793,32.8599996864796,3.58292274732211E-5,-2.6170906652438E-4,1,-2.10358497848461E-7,,,,,,,,,,,,,,,,,,,,,349.948333740234,349.976928710937,-0.0503530204296112,-0.0503530204296112,53.7217189409961,5.63375028949076,5.84691572189331,54,1,0,0,1,0.297470092773438,34.2131004333496,1,1,3,349.948333740234,0,349.962631225586,,,,,,,,,,,,,,,,,,,,,,,,,,,,,,,,,
,3878560245.38074,349.927047729492,199.876312255859,-1.77263539571131E-7,2.50232613342563E-8,1,4,13.4005146026611,4.99661908990875,32.8599996864796,-1.82230532764884E-4,-2.86221954237971E-4,1,-2.03976481425423E-7,,,,,,,,,,,,,,,,,,,,,349.920959472656,349.933135986328,199.876312255859,199.876312255859,53.8076980781114,5.63369897769508,5.85541820526123,52,1,68,0,0,0.297775268554687,34.7018585205078,1,1,3,349.933135986328,0,349.927047729492,,,,,,,,,,,,,,,,,,,,,,,,,,,,,,,,,
,3878560305.74132,350.095428466797,399.765197753906,-4.24613215219186E-7,1.28070454883525E-8,1,4,13.4005146026611,4.99671108377899,32.8599996864796,-5.12985396431723E-4,-1.74489474974128E-4,1,-7.69929099629748E-8,,,,,,,,,,,,,,,,,,,,,350.088195800781,350.102661132812,399.765197753906,399.765197753906,53.8428713614768,5.63291878067592,5.85230779647827,54,1,0,0,1,0.297470092773438,35.190616607666,1,1,3,350.102661132812,0,350.095428466797,,,,,,,,,,,,,,,,,,,,,,,,,,,,,,,,,
,3878560363.43846,349.94010925293,599.842956542969,-6.11162626496846E-7,1.53039748236278E-8,1,4,13.4005146026611,4.99672324573652,32.8599996864796,-7.21264840661486E-4,-3.65445848914563E-4,1,-2.02858117639798E-7,,,,,,,,,,,,,,,,,,,,,349.939178466797,349.941040039063,599.842956542969,599.842956542969,53.8245030912749,5.63371989468632,5.85617828369141,54,1,0,0,1,0.298385620117188,34.2131004333496,1,1,3,349.939178466797,0,349.94010925293,,,,,,,,,,,,,,,,,,,,,,,,,,,,,,,,,
,3878560421.11348,349.966323852539,799.568176269531,-8.5254442777931E-7,2.08372174776026E-8,1,4,13.4005146026611,4.99685498247254,32.8599996864796,-0.00102274914207258,-3.9896643162747E-4,1,-1.93730302674211E-7,,,,,,,,,,,,,,,,,,,,,349.959320068359,349.973327636719,799.568176269531,799.568176269531,53.9159536280249,5.63349362603332,5.84871339797974,54,1,0,0,1,0.298233032226562,34.2131004333496,1,1,3,349.973327636719,0,349.966323852539,,,,,,,,,,,,,,,,,,,,,,,,,,,,,,,,,
,3878560478.7525,349.8896484375,999.734008789063,-1.19899247449934E-6,2.73335194336261E-8,1,4,13.4005146026611,4.99683222297141,32.8599996864796,-0.00145969741046305,-4.18415036697126E-4,1,-1.57566847998002E-7,,,,,,,,,,,,,,,,,,,,,349.883270263672,349.896026611328,999.734008789063,999.734008789063,53.7830767797557,5.6337442852633,5.85314178466797,53,1,68,0,0,0.2972412109375,34.2131004333496,1,1,3,349.896026611328,0,349.8896484375,,,,,,,,,,,,,,,,,,,,,,,,,,,,,,,,,
,3878560536.50662,349.810668945313,1199.64819335938,-1.49294758350615E-6,1.39081100054475E-8,1,4,13.4005146026611,4.99679913725417,32.8599996864796,-0.00182363219799094,-4.80349594103852E-4,1,-1.63469366948288E-7,,,,,,,,,,,,,,,,,,,,,349.807159423828,349.814178466797,1199.64819335938,1199.64819335938,53.7572830386211,5.6337971615351,5.8460111618042,53,1,68,0,0,0.298309326171875,34.2131004333496,1,1,3,349.814178466797,0,349.810668945313,,,,,,,,,,,,,,,,,,,,,,,,,,,,,,,,,
,3878560594.18813,349.772354125977,1399.77624511719,-1.84465479358644E-6,2.78515630873768E-8,1,4,13.4005146026611,4.99684797913769,32.8599996864796,-0.00226704511352986,-5.01452135208372E-4,1,-1.27843588032306E-7,,,,,,,,,,,,,,,,,,,,,349.768615722656,349.776092529297,1399.77624511719,1399.77624511719,53.8358367048038,5.63373779500525,5.8511700630188,52,1,68,0,0,0.29754638671875,34.2131004333496,1,1,3,349.776092529297,0,349.772354125977,,,,,,,,,,,,,,,,,,,,,,,,,,,,,,,,,
,3878560658.4023,349.596649169922,1599.65246582031,-2.26289424909784E-6,7.47162347616785E-8,1,4,13.4005146026611,4.9967952397806,32.8599996864796,-0.00279583936758774,-5.16021539416389E-4,1,-7.70156440893867E-8,,,,,,,,,,,,,,,,,,,,,349.592193603516,349.601104736328,1599.65246582031,1599.65246582031,53.8542049750057,5.63339980723678,5.84786462783814,54,1,0,0,1,0.298614501953125,34.2131004333496,1,1,3,349.601104736328,0,349.596649169922,,,,,,,,,,,,,,,,,,,,,,,,,,,,,,,,,
,3878560718.26417,349.812408447266,1799.4658203125,-2.52807747414543E-6,3.34263134806067E-8,1,4,13.4005146026611,4.99671864903178,32.8599996864796,-0.00311903761788327,-6.05709754941108E-4,1,-1.09578525810107E-7,,,,,,,,,,,,,,,,,,,,,349.809509277344,349.815307617188,1799.4658203125,1799.4658203125,53.8999302433807,5.63379823674711,5.84834289550781,54,1,0,0,1,0.297393798828125,34.2131004333496,1,1,3,349.809509277344,0,349.812408447266,,,,,,,,,,,,,,,,,,,,,,,,,,,,,,,,,
,3878560775.60522,349.772705078125,1999.89599609375,-2.84018282497661E-6,3.67905548002866E-8,1,4,13.4005146026611,4.99674443252177,32.8599996864796,-0.00350838105896158,-6.52046407633145E-4,1,-1.0019947402249E-7,,,,,,,,,,,,,,,,,,,,,349.770660400391,349.774749755859,1999.89599609375,1999.89599609375,53.9237699132172,5.63401047563998,5.84697675704956,54,1,0,0,1,0.297470092773438,33.7243423461914,1,1,3,349.770660400391,0,349.772705078125,,,,,,,,,,,,,,,,,,,,,,,,,,,,,,,,,
,3878560833.40177,349.83723449707,2199.81005859375,-3.2280547665962E-6,2.76867459462797E-8,1,4,13.4005146026611,4.99676990454409,32.8599996864796,-0.00398393460126078,-7.65163536112453E-4,1,-1.33261638798712E-7,,,,,,,,,,,,,,,,,,,,,349.829071044922,349.845397949219,2199.81005859375,2199.81005859375,53.8377907761019,5.63374094658153,5.8475604057312,54,1,0,0,1,0.298385620117188,34.2131004333496,1,1,3,349.845397949219,0,349.83723449707,,,,,,,,,,,,,,,,,,,,,,,,,,,,,,,,,
,3878560891.02657,350.044418334961,2399.97583007813,-3.5885989264348E-6,9.00094637902898E-9,1,4,13.4005146026611,4.99671306703885,32.8599996864796,-0.00443701747621489,-7.95900944359491E-4,1,-1.04088393454232E-7,,,,,,,,,,,,,,,,,,,,,350.034027099609,350.054809570313,2399.97583007813,2399.97583007813,53.9573799395442,5.63398483206776,5.84867191314697,54,1,0,0,1,0.298004150390625,34.2131004333496,1,1,3,350.034027099609,0,350.044418334961,,,,,,,,,,,,,,,,,,,,,,,,,,,,,,,,,
,3878560948.75073,349.951354980469,2599.70141601562,-3.92499738803624E-6,7.11263557989926E-9,1,4,13.4005146026611,4.99677484364053,32.8599996864796,-0.00485629632907738,-8.48699598036343E-4,1,-9.62709633431125E-8,,,,,,,,,,,,,,,,,,,,,349.943786621094,349.958923339844,2599.70141601562,2599.70141601562,53.9823920521596,5.63398088270623,5.84498500823975,54,1,0,0,1,0.2972412109375,34.7018585205078,1,1,3,349.958923339844,0,349.951354980469,,,,,,,,,,,,,,,,,,,,,,,,,,,,,,,,,
,3878561006.41247,349.997848510742,2799.79150390625,-4.32744562129805E-6,2.97942555916365E-8,1,4,13.4005146026611,4.99675602781633,32.8599996864796,-0.00535976868499831,-8.98535487878868E-4,1,-7.62020003100479E-8,,,,,,,,,,,,,,,,,,,,,349.993865966797,350.001831054687,2799.79150390625,2799.79150390625,53.8987578006019,5.63385450904002,5.84883260726929,54,1,0,0,1,0.298538208007812,34.2131004333496,1,1,3,350.001831054687,0,349.997848510742,,,,,,,,,,,,,,,,,,,,,,,,,,,,,,,,,
,3878561064.12384,350.169036865234,2999.70556640625,-4.66107368480206E-6,1.02361180203916E-8,1,4,13.4005146026611,4.99674266549847,32.8599996864796,-0.00577344265460415,-9.64598482968423E-4,1,-7.94945725896491E-8,,,,,,,,,,,,,,,,,,,,,350.157165527344,350.180908203125,2999.70556640625,2999.70556640625,53.9468279545346,5.63408355639177,5.84928941726685,54,1,0,0,1,0.297698974609375,33.7243423461914,1,1,3,350.180908203125,0,350.169036865234,,,,,,,,,,,,,,,,,,,,,,,,,,,,,,,,,
,3878561143.70585,350.003204345703,4499.70947265625,-7.57156245754025E-6,9.77786570968263E-8,1,4,13.4005146026611,4.99680373240864,32.8599996864796,-0.00939351958720941,-0.00146776108940465,1,-4.92650436309098E-8,,,,,,,,,,,,,,,,,,,,,350.001678466797,350.004730224609,4499.70947265625,4499.70947265625,53.7948012075442,5.63416419499758,5.85167694091797,54,1,0,0,1,0.297775268554687,34.2131004333496,1,1,3,350.004943847656,0,350.003204345703,,,,,,,,,,,,,,,,,,,,,,,,,,,,,,,,,
,3878561208.23731,350.151550292969,6499.630859375,-1.12819541377546E-5,1.03047735800419E-8,1,4,13.4005146026611,4.9968170045247,32.8599996864796,-0.0140159820993508,-0.0020588127200201,1,2.98446997275848E-8,,,,,,,,,,,,,,,,,,,,,350.143157958984,350.159942626953,6499.630859375,6499.630859375,53.8389632188807,5.63359049303804,5.85105228424072,54,1,0,0,1,0.298690795898438,34.2131004333496,1,1,3,350.159942626953,0,350.151550292969,,,,,,,,,,,,,,,,,,,,,,,,,,,,,,,,,
,3878561272.91254,349.898345947266,8499.904296875,-1.50953727436191E-5,9.57444665634791E-9,1,4,13.4005146026611,4.99678220907362,32.8599996864796,-0.0187578967312461,-0.0027242783910321,1,6.44186840405547E-8,,,,,,,,,,,,,,,,,,,,,349.893463134766,349.903228759766,8499.904296875,8499.904296875,53.7854216653134,5.63355602145597,5.8484525680542,54,1,0,0,1,0.297698974609375,34.2131004333496,1,1,3,349.893463134766,0,349.898345947266,,,,,,,,,,,,,,,,,,,,,,,,,,,,,,,,,
,3878561347.04028,349.894119262695,10000.123046875,-1.79413779792754E-5,1.16515408406277E-8,1,4,13.4005146026611,4.99683252551852,32.8599996864796,-0.0222861906206729,-0.00329502991198205,1,3.05968074098411E-8,,,,,,,,,,,,,,,,,,,,,349.893157958984,349.895080566406,10000.123046875,10000.123046875,53.7791686371595,5.63338957027965,5.85050106048584,54,1,0,0,1,0.2972412109375,34.2131004333496,1,1,3,349.895080566406,0,349.894119262695,,,,,,,,,,,,,,,,,,,,,,,,,,,,,,,,,
,3878561500.04978,350.090591430664,30000.228515625,-5.62261635271546E-5,4.15511635104083E-8,1,4,13.4005146026611,4.99680415852581,32.8599996864796,-0.0698389908570361,-0.010344523731207,1,8.1093814927813E-8,,,,,,,,,,,,,,,,,,,,,350.079071044922,350.102111816406,30000.228515625,30000.228515625,53.8354458905442,5.63432510477672,5.84988975524902,53,1,68,0,0,0.297927856445313,33.7243423461914,1,1,3,350.102111816406,0,350.090591430664,,,,,,,,,,,,,,,,,,,,,,,,,,,,,,,,,
,3878561657.3918,350.075256347656,50000.30859375,-9.46547402148162E-5,9.34476078558822E-8,1,4,13.4005146026611,4.99688185985891,32.8599996864796,-0.117566852593292,-0.017462856593263,1,9.79952771877095E-8,,,,,,,,,,,,,,,,,,,,,350.061828613281,350.088684082031,50000.30859375,50000.30859375,53.6447285318518,5.6347797506986,5.84493017196655,53,1,68,0,0,0.298004150390625,34.2131004333496,1,1,3,350.088684082031,0,350.075256347656,,,,,,,,,,,,,,,,,,,,,,,,,,,,,,,,,
,3878561815.37574,350.060699462891,70000.40625,-1.32987375374253E-4,1.1573519284788E-7,1,4,13.4005146026611,4.99682570724726,32.8599996864796,-0.165157894357327,-0.024653357345879,1,4.1938348157603E-8,,,,,,,,,,,,,,,,,,,,,350.059326171875,350.062072753906,70000.40625,70000.40625,53.4884028280057,5.63415650638735,5.84939384460449,53,1,68,0,0,0.29754638671875,34.7018585205078,1,1,3,350.059326171875,0,350.060699462891,,,,,,,,,,,,,,,,,,,,,,,,,,,,,,,,,