File: SQUID/22157b_LCOT/LCOT_MT_FC+1T_2.csv
Comment,Time Stamp (sec),Temperature (K),Magnetic Field (Oe),Moment (emu),M. Std. Err. (emu),Transport Action,Averaging Time (sec),Frequency (Hz),Peak Amplitude (mm),Center Position (mm),Lockin Signal' (V),Lockin Signal (V),Range,M. Quad. Signal (emu),AC Moment (emu),AC M. Std Err. (emu),AC Phase (deg),AC Phase Std. Err. (deg),AC Susceptibility (emu/Oe),AC Suscept. Std Err. (emu/Oe),AC X' (emu/Oe),AC X' Std Err. (emu/Oe),AC X'' (emu/Oe),AC X'' Std Err. (emu/Oe),AC Drive (Oe),AC Frequency (Hz),AC Averaging Time (sec),AC Cycles,AC Range,AC Measure Type,AC Signal' (V),AC Signal'' (V),AC Trim Coil Ratio,AC Trim Coil Phase,Min. Temperature (K),Max. Temperature (K),Min. Field (Oe),Max. Field (Oe),Mass (grams),Motor Lag (deg),Pressure (Torr),Measure Count,Measurement Number,SQUID Status (code),Motor Status (code),Measure Status (code),Motor Current (amps),Motor Temp. (C),Temp. Status (code),Field Status (code),Chamber Status (code),Chamber Temp (K),Redirection State,Average Temp (K),Rotation Angle (deg),Rotator state,DC Moment Fixed Ctr (emu),DC Moment Err Fixed Ctr (emu),DC Moment Free Ctr (emu),DC Moment Err Free Ctr (emu),DC Fixed Fit,DC Free Fit,DC Calculated Center (mm),DC Calculated Center Err (mm),DC Scan Length (mm),DC Scan Time (s),DC Number of Points,DC Squid Drift,DC Min V (V),DC Max V (V),DC Scans per Measure,Sample Resistance,He3 Temperature,Sorb Resistance,Sorb Temperature,Map 05,Map 06,Map 07,Map 08,Map 09,Map 10,Map 11,Map 12,Map 13,Map 14,Map 15,Map 16
,3878534922.37544,349.920669555664,10000.3994140625,-1.78632079104356E-5,1.51743320695512E-8,1,4,13.4005146026611,5.00811912369462,32.8599996864796,-0.0222579405327944,-0.0032997169661804,1,2.35023393819212E-8,,,,,,,,,,,,,,,,,,,,,349.920257568359,349.921081542969,10000.3994140625,10000.3994140625,53.7002241567172,5.63013176963694,5.2987904548645,54,1,0,0,1,0.304946899414063,32.7468223571777,1,1,3,349.921081542969,0,349.920669555664,,,,,,,,,,,,,,,,,,,,,,,,,,,,,,,,,
,3878534945.08357,349.793533325195,10000.3994140625,-1.78411396200877E-5,1.31240661708209E-8,1,4,13.4005146026611,5.00799086041463,32.8599996864796,-0.0222318939393936,-0.00328050338790723,1,3.55297662904818E-8,,,,,,,,,,,,,,,,,,,,,349.734802246094,349.852264404297,10000.3994140625,10000.3994140625,53.8272387910922,5.63315100029399,5.30421543121338,54,1,0,0,1,0.302886962890625,33.2355842590332,2,1,3,349.734802246094,0,349.793533325195,,,,,,,,,,,,,,,,,,,,,,,,,,,,,,,,,
,3878534969.28745,348.778381347656,10000.3994140625,-1.78485501254905E-5,1.67980194490295E-8,1,4,13.4005146026611,5.00785180040486,32.8599996864796,-0.0222424516249443,-0.00326712120093069,1,4.72789672843588E-8,,,,,,,,,,,,,,,,,,,,,348.659973144531,348.896789550781,10000.3994140625,10000.3994140625,53.7733064232653,5.63425015961984,5.31178188323975,54,1,0,0,1,0.297012329101562,33.7243423461914,2,1,3,348.659973144531,0,348.778381347656,,,,,,,,,,,,,,,,,,,,,,,,,,,,,,,,,
,3878534993.45175,346.69108581543,10000.3994140625,-1.78479442381944E-5,1.55503386493673E-8,1,4,13.4005146026611,5.00779249386234,32.8599996864796,-0.0222382028388604,-0.00328784986276321,1,3.05042434929402E-8,,,,,,,,,,,,,,,,,,,,,346.453186035156,346.928985595703,10000.3994140625,10000.3994140625,53.7099945132076,5.63448499150786,5.31198167800903,54,1,0,0,1,0.297927856445313,33.7243423461914,2,1,3,346.453186035156,0,346.69108581543,,,,,,,,,,,,,,,,,,,,,,,,,,,,,,,,,
,3878535017.62879,343.396286010742,10000.3994140625,-1.78637836642512E-5,1.42147129326289E-8,1,4,13.4005146026611,5.00758187373997,32.8599996864796,-0.0222584949221418,-0.00327810714925486,1,4.0540311551589E-8,,,,,,,,,,,,,,,,,,,,,343.128936767578,343.663635253906,10000.3994140625,10000.3994140625,53.9054016430153,5.63589803024719,5.31942844390869,54,1,0,0,1,0.298385620117188,33.2355842590332,2,1,3,343.128936767578,0,343.396286010742,,,,,,,,,,,,,,,,,,,,,,,,,,,,,,,,,
,3878535041.88692,338.516311645508,10000.3994140625,-1.78678477295608E-5,1.43439461780835E-8,1,4,13.4005146026611,5.00726367314324,32.8399986028671,-0.0222621308978586,-0.00327488720156859,1,4.34997896145532E-8,,,,,,,,,,,,,,,,,,,,,338.046905517578,338.985717773438,10000.3994140625,10000.3994140625,53.7635360667749,5.63633752383731,5.31730794906616,54,1,0,0,1,0.299301147460937,33.7243423461914,2,1,3,338.046905517578,0,338.516311645508,,,,,,,,,,,,,,,,,,,,,,,,,,,,,,,,,
,3878535065.96561,332.806549072266,10000.3994140625,-1.78705305942638E-5,1.49916891928595E-8,1,4,13.4005146026611,5.00672275182406,32.8399986028671,-0.0222623804009032,-0.00327308410075114,1,4.49519184604836E-8,,,,,,,,,,,,,,,,,,,,,332.236602783203,333.376495361328,10000.3994140625,10000.3994140625,53.7854216653134,5.63900880536945,5.30270051956177,54,1,0,0,1,0.299072265625,33.7243423461914,2,1,3,332.236602783203,0,332.806549072266,,,,,,,,,,,,,,,,,,,,,,,,,,,,,,,,,
,3878535090.14812,326.313766479492,10000.3994140625,-1.78663519736631E-5,1.37243964435269E-8,1,4,13.4005146026611,5.00681660905373,32.820001244545,-0.0222576080826869,-0.00327340775014605,1,4.41358129421364E-8,,,,,,,,,,,,,,,,,,,,,325.769989013672,326.857543945313,10000.3994140625,10000.3994140625,53.7608003669576,5.63800247475647,5.30150985717773,54,1,0,0,1,0.300750732421875,33.7243423461914,2,1,3,325.769989013672,0,326.313766479492,,,,,,,,,,,,,,,,,,,,,,,,,,,,,,,,,
,3878535114.32563,319.956771850586,10000.3994140625,-1.78571091045703E-5,1.44446942166189E-8,1,4,13.4005146026611,5.00671876112184,32.8099988400936,-0.0222474703702692,-0.00325835766479394,1,5.47669314831707E-8,,,,,,,,,,,,,,,,,,,,,319.347534179687,320.566009521484,10000.3994140625,10000.3994140625,53.8260663483134,5.63837964484716,5.2946515083313,54,1,0,0,1,0.299835205078125,33.7243423461914,2,1,3,319.347534179687,0,319.956771850586,,,,,,,,,,,,,,,,,,,,,,,,,,,,,,,,,
,3878535138.50155,313.609130859375,10000.3994140625,-1.78535830985249E-5,1.42178307383448E-8,1,4,13.4005146026611,5.00676732577839,32.8099988400936,-0.0222396647255859,-0.00328258813522944,1,3.48175056738421E-8,,,,,,,,,,,,,,,,,,,,,313.128631591797,314.089630126953,10000.3994140625,10000.3994140625,53.7955828360634,5.63673290969503,5.29188442230225,54,1,0,0,1,0.299072265625,33.7243423461914,2,1,3,313.128631591797,0,313.609130859375,,,,,,,,,,,,,,,,,,,,,,,,,,,,,,,,,
,3878535162.85956,307.719833374023,10000.3994140625,-1.78578922695604E-5,2.06674978390239E-8,1,4,13.4005146026611,5.00620290242608,32.7900014817715,-0.0222421621161346,-0.00327861447378553,1,3.82380343551081E-8,,,,,,,,,,,,,,,,,,,,,307.269622802734,308.170043945313,10000.3994140625,10000.3994140625,53.7838584082749,5.6382352243303,5.29000425338745,53,1,64,0,0,0.3009033203125,33.7243423461914,2,1,3,307.269622802734,0,307.719833374023,,,,,,,,,,,,,,,,,,,,,,,,,,,,,,,,,
,3878535186.85734,302.80908203125,10000.3994140625,-1.78464374062239E-5,1.93353172780447E-8,1,4,13.4005146026611,5.00582590022524,32.7900014817715,-0.0222253443416689,-0.00327757166228249,1,3.70847869281154E-8,,,,,,,,,,,,,,,,,,,,,302.392578125,303.2255859375,10000.3994140625,10000.3994140625,53.7541565245441,5.64068975082389,5.28297805786133,54,1,0,0,1,0.301971435546875,33.7243423461914,2,1,3,302.392578125,0,302.80908203125,,,,,,,,,,,,,,,,,,,,,,,,,,,,,,,,,
,3878535211.06489,298.450805664063,10000.3994140625,-1.78432021345155E-5,1.44554306302574E-8,1,4,13.4005146026611,5.0062944934842,32.7900014817715,-0.0222247552251136,-0.00327385330251698,1,3.99316339391449E-8,,,,,,,,,,,,,,,,,,,,,298.070495605469,298.831115722656,10000.3994140625,10000.3994140625,53.770570723448,5.63791032874249,5.27812671661377,54,1,0,0,1,0.30059814453125,33.7243423461914,2,1,3,298.070495605469,0,298.450805664063,,,,,,,,,,,,,,,,,,,,,,,,,,,,,,,,,
,3878535235.23935,294.505966186523,10000.3994140625,-1.78403471015201E-5,1.47461464979228E-8,1,4,13.4005146026611,5.00660022085738,32.770000398159,-0.0222234212346532,-0.0032714373913966,1,4.16691161719487E-8,,,,,,,,,,,,,,,,,,,,,294.159362792969,294.852569580078,10000.3994140625,10000.3994140625,53.8100429636692,5.63635788746544,5.28259611129761,54,1,0,0,1,0.300140380859375,34.2131004333496,2,1,3,294.159362792969,0,294.505966186523,,,,,,,,,,,,,,,,,,,,,,,,,,,,,,,,,
,3878535259.38553,290.629211425781,10000.3994140625,-1.78277698563706E-5,1.38323579582676E-8,1,4,13.4005146026611,5.00654670767105,32.770000398159,-0.022205015128392,-0.00328517235103859,1,2.87183164894367E-8,,,,,,,,,,,,,,,,,,,,,290.270111083984,290.988311767578,10000.3994140625,10000.3994140625,53.8202041344192,5.63681999541234,5.27409791946411,54,1,0,0,1,0.301361083984375,33.7243423461914,2,1,3,290.270111083984,0,290.629211425781,,,,,,,,,,,,,,,,,,,,,,,,,,,,,,,,,
,3878535283.56683,286.775619506836,10000.3994140625,-1.78085898623001E-5,1.43866803684892E-8,1,4,13.4005146026611,5.00668597096052,32.770000398159,-0.022182558037907,-0.00327795826852363,1,3.17448513249642E-8,,,,,,,,,,,,,,,,,,,,,286.420562744141,287.130676269531,10000.3994140625,10000.3994140625,53.7967552788422,5.637189100414,5.26754474639893,54,1,0,0,1,0.2996826171875,33.7243423461914,2,1,3,286.420562744141,0,286.775619506836,,,,,,,,,,,,,,,,,,,,,,,,,,,,,,,,,
,3878535307.7447,282.712112426758,10000.3994140625,-1.78081729310708E-5,1.64144273685181E-8,1,4,13.4005146026611,5.00639080703407,32.7499993145466,-0.0221836909494245,-0.00325434489226081,1,5.04294011603206E-8,,,,,,,,,,,,,,,,,,,,,282.369598388672,283.054626464844,10000.3994140625,10000.3994140625,53.6924078715249,5.63818845837328,5.27154445648193,54,1,0,0,1,0.300216674804687,33.7243423461914,2,1,3,282.369598388672,0,282.712112426758,,,,,,,,,,,,,,,,,,,,,,,,,,,,,,,,,
,3878535331.9297,278.765182495117,10000.3994140625,-1.7792476382726E-5,1.58752421418649E-8,1,4,13.4005146026611,5.00675279252014,32.7499993145466,-0.0221639365963521,-0.00326812706700823,1,3.72781267644994E-8,,,,,,,,,,,,,,,,,,,,,278.414794921875,279.115570068359,10000.3994140625,10000.3994140625,53.8284112338711,5.63760334851489,5.26403522491455,54,1,0,0,1,0.30029296875,34.2131004333496,2,1,3,278.414794921875,0,278.765182495117,,,,,,,,,,,,,,,,,,,,,,,,,,,,,,,,,
,3878535356.12632,274.780044555664,10000.3994140625,-1.77965246893458E-5,1.57109840311083E-8,1,4,13.4005146026611,5.00671238397686,32.7499993145466,-0.0221689986305094,-0.00326703402582929,1,3.87318589922276E-8,,,,,,,,,,,,,,,,,,,,,274.404632568359,275.155456542969,10000.3994140625,10000.3994140625,53.8155143633038,5.6384735553934,5.25912761688232,54,1,0,0,1,0.300140380859375,33.7243423461914,2,1,3,274.404632568359,0,274.780044555664,,,,,,,,,,,,,,,,,,,,,,,,,,,,,,,,,
,3878535380.27409,270.780960083008,10000.3994140625,-1.77875198004902E-5,1.45044110330484E-8,1,4,13.4005146026611,5.0065954438142,32.7499993145466,-0.0221561875669121,-0.00327109142763598,1,3.40408002936903E-8,,,,,,,,,,,,,,,,,,,,,270.379943847656,271.181976318359,10000.3994140625,10000.3994140625,53.8901598868903,5.63797062548422,5.25957250595093,54,1,0,0,1,0.29937744140625,33.7243423461914,2,1,3,270.379943847656,0,270.780960083008,,,,,,,,,,,,,,,,,,,,,,,,,,,,,,,,,
,3878535404.49872,266.5927734375,10000.3994140625,-1.77764287908441E-5,1.45317974382976E-8,1,4,13.4005146026611,5.00644210295251,32.7299982309341,-0.0221416510019942,-0.00326739729553175,1,3.52358806880282E-8,,,,,,,,,,,,,,,,,,,,,266.285583496094,266.899963378906,10000.3994140625,10000.3994140625,53.674039601323,5.63819150799858,5.25867128372192,54,1,0,0,1,0.30059814453125,34.2131004333496,2,1,3,266.285583496094,0,266.5927734375,,,,,,,,,,,,,,,,,,,,,,,,,,,,,,,,,
,3878535428.63935,262.726257324219,10000.3994140625,-1.7771293123502E-5,1.6602247147772E-8,1,4,13.4005146026611,5.0064481604258,32.7299982309341,-0.0221364400579145,-0.00325878203486211,1,4.13908582315727E-8,,,,,,,,,,,,,,,,,,,,,262.356628417969,263.095886230469,10000.3994140625,10000.3994140625,53.8827344159576,5.63928242182026,5.25377035140991,54,1,0,0,1,0.30059814453125,34.2131004333496,2,1,3,262.356628417969,0,262.726257324219,,,,,,,,,,,,,,,,,,,,,,,,,,,,,,,,,
,3878535452.84827,258.7431640625,10000.3994140625,-1.77584928086051E-5,1.16773044384969E-8,1,4,13.4005146026611,5.00651691293006,32.7299982309341,-0.0221205231810113,-0.00325915211180515,1,3.92290581762537E-8,,,,,,,,,,,,,,,,,,,,,258.370208740234,259.116119384766,10000.3994140625,10000.3994140625,53.7365698828615,5.63864300510945,5.25082778930664,54,1,0,0,1,0.299606323242188,33.7243423461914,2,1,3,258.370208740234,0,258.7431640625,,,,,,,,,,,,,,,,,,,,,,,,,,,,,,,,,
,3878535476.99342,254.510559082031,10000.3994140625,-1.77556049383328E-5,1.4187939094009E-8,1,4,13.4005146026611,5.00646972949515,32.710000872612,-0.022115840273745,-0.00326388869687663,1,3.49586972801121E-8,,,,,,,,,,,,,,,,,,,,,254.181304931641,254.839813232422,10000.3994140625,10000.3994140625,53.770570723448,5.63867232783158,5.24312257766724,54,1,0,0,1,0.299072265625,33.7243423461914,2,1,3,254.181304931641,0,254.510559082031,,,,,,,,,,,,,,,,,,,,,,,,,,,,,,,,,
,3878535501.16761,250.460098266602,10000.3994140625,-1.77606562562969E-5,1.4438593318684E-8,1,4,13.4005146026611,5.00657026701839,32.710000872612,-0.0221244634442267,-0.0032534759048335,1,4.41500243667401E-8,,,,,,,,,,,,,,,,,,,,,250.109375,250.810821533203,10000.3994140625,10000.3994140625,53.6861548433711,5.63905121820583,5.24699926376343,54,1,0,0,1,0.298309326171875,33.7243423461914,2,1,3,250.109375,0,250.460098266602,,,,,,,,,,,,,,,,,,,,,,,,,,,,,,,,,
,3878535525.35243,246.526138305664,10000.3994140625,-1.77492417303987E-5,1.9594072314804E-8,1,4,13.4005146026611,5.00666139683604,32.710000872612,-0.0221091899830917,-0.00326227716586228,1,3.54412114717931E-8,,,,,,,,,,,,,,,,,,,,,246.174438476562,246.877838134766,10000.3994140625,10000.3994140625,53.9198617706211,5.63811750813114,5.24205923080444,54,1,0,0,1,0.300369262695313,33.7243423461914,2,1,3,246.150009155273,0,246.526138305664,,,,,,,,,,,,,,,,,,,,,,,,,,,,,,,,,
,3878535549.54068,242.837791442871,10000.3994140625,-1.77564153089518E-5,1.12098065093879E-8,1,4,13.4005146026611,5.00625534545414,32.710000872612,-0.0221142697351914,-0.0032722369774627,1,2.82182319662981E-8,,,,,,,,,,,,,,,,,,,,,242.557006835938,243.118576049805,10000.3994140625,10000.3994140625,53.8166868060826,5.64042606775538,5.23255968093872,54,1,0,0,1,0.299911499023438,34.2131004333496,2,1,3,242.557006835938,0,242.837791442871,,,,,,,,,,,,,,,,,,,,,,,,,,,,,,,,,
,3878535573.68516,238.788116455078,10000.3994140625,-1.77299031250069E-5,1.44048429224388E-8,1,4,13.4005146026611,5.00645159838634,32.6899997889996,-0.0220852548859102,-0.00324885424894192,1,4.31745491008068E-8,,,,,,,,,,,,,,,,,,,,,238.449554443359,239.126678466797,10000.3994140625,10000.3994140625,53.8690559168711,5.63990298763835,5.23103761672974,54,1,0,0,1,0.300216674804687,34.2131004333496,2,1,3,238.449554443359,0,238.788116455078,,,,,,,,,,,,,,,,,,,,,,,,,,,,,,,,,
,3878535597.90326,234.807991027832,10000.3994140625,-1.77347121454015E-5,1.42348859720854E-8,1,4,13.4005146026611,5.00613747518785,32.6899997889996,-0.0220877250013458,-0.00326002790130327,1,3.46908575622576E-8,,,,,,,,,,,,,,,,,,,,,234.495803833008,235.120178222656,10000.3994140625,10000.3994140625,53.8248939055345,5.63998211184941,5.2282223701477,54,1,0,0,1,0.298385620117188,33.7243423461914,2,1,3,234.495803833008,0,234.807991027832,,,,,,,,,,,,,,,,,,,,,,,,,,,,,,,,,
,3878535622.09367,230.763961791992,10000.3994140625,-1.77199822046684E-5,1.66504313217912E-8,1,4,13.4005146026611,5.00651414063065,32.6899997889996,-0.0220710350611556,-0.00326211600316128,1,3.10858642684515E-8,,,,,,,,,,,,,,,,,,,,,230.389678955078,231.138244628906,10000.3994140625,10000.3994140625,53.7752604945634,5.6391547393503,5.22802782058716,54,1,0,0,1,0.300827026367188,34.2131004333496,2,1,3,230.389678955078,0,230.763961791992,,,,,,,,,,,,,,,,,,,,,,,,,,,,,,,,,
,3878535646.3987,226.643196105957,10000.3994140625,-1.77275640836865E-5,1.55434941273075E-8,1,4,13.4005146026611,5.00654403818691,32.6899997889996,-0.022082929550626,-0.00324838753458197,1,4.32667964794041E-8,,,,,,,,,,,,,,,,,,,,,226.281768798828,227.004623413086,10000.3994140625,10000.3994140625,53.8495152038903,5.63950994409271,5.21704244613647,53,1,64,0,0,0.300445556640625,34.2131004333496,2,1,3,226.281768798828,0,226.643196105957,,,,,,,,,,,,,,,,,,,,,,,,,,,,,,,,,
,3878535670.42009,222.647018432617,10000.3994140625,-1.77210627262273E-5,1.44795721377233E-8,1,4,13.4005146026611,5.00653878020767,32.6899997889996,-0.0220722509166725,-0.00326422150532257,1,2.95746705189705E-8,,,,,,,,,,,,,,,,,,,,,222.294403076172,222.999633789062,10000.3994140625,10000.3994140625,53.8256755340538,5.63956695165159,5.2111120223999,54,1,0,0,1,0.30181884765625,33.7243423461914,2,1,3,222.294403076172,0,222.647018432617,,,,,,,,,,,,,,,,,,,,,,,,,,,,,,,,,
,3878535694.62441,218.515357971191,10000.3994140625,-1.77338030165111E-5,1.43305690327006E-8,1,4,13.4005146026611,5.00597671239447,32.6699987053871,-0.0220853981070846,-0.00326107097881863,1,3.35994981399294E-8,,,,,,,,,,,,,,,,,,,,,218.190551757813,218.84016418457,10000.3994140625,10000.3994140625,53.8483427611115,5.6407866197998,5.21269226074219,54,1,0,0,1,0.30242919921875,34.2131004333496,2,1,3,218.190551757813,0,218.515357971191,,,,,,,,,,,,,,,,,,,,,,,,,,,,,,,,,
,3878535718.77491,214.477653503418,10000.3994140625,-1.77111780414392E-5,1.37438336510217E-8,1,4,13.4005146026611,5.0058239180341,32.6699987053871,-0.0220554117183341,-0.00326257566717275,1,2.88945483386086E-8,,,,,,,,,,,,,,,,,,,,,214.138305664062,214.817001342773,10000.3994140625,10000.3994140625,53.7525932675057,5.64162604580754,5.2090539932251,54,1,0,0,1,0.30242919921875,34.7018585205078,2,1,3,214.138305664062,0,214.477653503418,,,,,,,,,,,,,,,,,,,,,,,,,,,,,,,,,
,3878535742.9555,210.367111206055,10000.3994140625,-1.77143158625471E-5,1.53982336111085E-8,1,4,13.4005146026611,5.00570914010017,32.6699987053871,-0.022058840843127,-0.0032615190735636,1,3.01286395270577E-8,,,,,,,,,,,,,,,,,,,,,210.030990600586,210.703231811523,10000.3994140625,10000.3994140625,53.8737456879865,5.64109631556524,5.19852781295776,54,1,0,0,1,0.301132202148438,34.2131004333496,2,1,3,210.030990600586,0,210.367111206055,,,,,,,,,,,,,,,,,,,,,,,,,,,,,,,,,
,3878535767.1232,206.520210266113,10000.3994140625,-1.77003929109718E-5,1.83690243396224E-8,1,4,13.4005146026611,5.00603020225081,32.650001347065,-0.0220421880662071,-0.00326788382871761,1,2.31687343559176E-8,,,,,,,,,,,,,,,,,,,,,206.210800170898,206.829620361328,10000.3994140625,10000.3994140625,53.8756997592846,5.64065520117616,5.19260597229004,54,1,0,0,1,0.301971435546875,34.2131004333496,2,1,3,206.210800170898,0,206.520210266113,,,,,,,,,,,,,,,,,,,,,,,,,,,,,,,,,
,3878535791.29481,202.463821411133,10000.3994140625,-1.76872662046666E-5,1.62290541798279E-8,1,4,13.4005146026611,5.00576662051659,32.650001347065,-0.0220258887543484,-0.00325406423895753,1,3.21122606541799E-8,,,,,,,,,,,,,,,,,,,,,202.090835571289,202.836807250977,10000.3994140625,10000.3994140625,53.7713523519672,5.64359221491128,5.1937141418457,54,1,0,0,1,0.302276611328125,34.2131004333496,2,1,3,202.090835571289,0,202.463821411133,,,,,,,,,,,,,,,,,,,,,,,,,,,,,,,,,
,3878535815.57169,198.464851379395,10000.3994140625,-1.76794341754848E-5,2.05723364858338E-8,1,4,13.4005146026611,5.0058337159486,32.650001347065,-0.0220171060896692,-0.00324895473998606,1,3.50936989091002E-8,,,,,,,,,,,,,,,,,,,,,198.165771484375,198.763931274414,10000.3994140625,10000.3994140625,53.8542049750057,5.64148437160378,5.18371534347534,53,1,64,0,0,0.301971435546875,34.2131004333496,2,1,3,198.165771484375,0,198.464851379395,,,,,,,,,,,,,,,,,,,,,,,,,,,,,,,,,
,3878535839.6445,194.342239379883,10000.3994140625,-1.76539269102229E-5,1.68528165146143E-8,1,4,13.4005146026611,5.00621280579418,32.650001347065,-0.0219865991135459,-0.00325175958058375,1,2.93015861280731E-8,,,,,,,,,,,,,,,,,,,,,193.971908569336,194.71257019043,10000.3994140625,10000.3994140625,53.8420897329576,5.64165970863273,5.1760458946228,54,1,0,0,1,0.300674438476562,34.7018585205078,2,1,3,193.971908569336,0,194.342239379883,,,,,,,,,,,,,,,,,,,,,,,,,,,,,,,,,
,3878535863.84206,190.397964477539,10000.3994140625,-1.76483116839119E-5,1.40089959017804E-8,1,4,13.4005146026611,5.006309506949,32.650001347065,-0.0219793356647391,-0.00325658684948677,1,2.46552461728047E-8,,,,,,,,,,,,,,,,,,,,,190.036148071289,190.759780883789,10000.3994140625,10000.3994140625,53.7955828360634,5.64159390947491,5.17534017562866,54,1,0,0,1,0.2996826171875,34.2131004333496,2,1,3,190.036148071289,0,190.397964477539,,,,,,,,,,,,,,,,,,,,,,,,,,,,,,,,,
,3878535888.02096,186.313781738281,10000.3994140625,-1.76513936936894E-5,1.50938766815862E-8,1,4,13.4005146026611,5.0058329248994,32.6300002634525,-0.021980317980958,-0.00325625474723224,1,2.50348912936242E-8,,,,,,,,,,,,,,,,,,,,,185.954330444336,186.673233032227,10000.3994140625,10000.3994140625,53.8108245921884,5.64266954357693,5.17002773284912,54,1,0,0,1,0.3021240234375,34.2131004333496,2,1,3,185.954330444336,0,186.313781738281,,,,,,,,,,,,,,,,,,,,,,,,,,,,,,,,,
,3878535912.18132,182.349311828613,10000.3994140625,-1.76469220888625E-5,1.67105583246282E-8,1,4,13.4005146026611,5.00633554958482,32.6300002634525,-0.0219754509865097,-0.00327182206444077,1,1.22308069166372E-8,,,,,,,,,,,,,,,,,,,,,182.013687133789,182.684936523438,10000.3994140625,10000.3994140625,53.8319285622076,5.64083615058643,5.15801858901978,54,1,0,0,1,0.300216674804687,34.2131004333496,2,1,3,182.013687133789,0,182.349311828613,,,,,,,,,,,,,,,,,,,,,,,,,,,,,,,,,
,3878535936.36206,178.647552490234,10000.3994140625,-1.76332490852436E-5,1.37135667249811E-8,1,4,13.4005146026611,5.00659485140775,32.6300002634525,-0.0219617613498168,-0.00325784522911975,1,2.15998294983449E-8,,,,,,,,,,,,,,,,,,,,,178.307479858398,178.98762512207,10000.3994140625,10000.3994140625,53.7686166521499,5.63917937521608,5.151442527771,54,1,0,0,1,0.300979614257812,34.2131004333496,2,1,3,178.307479858398,0,178.647552490234,,,,,,,,,,,,,,,,,,,,,,,,,,,,,,,,,
,3878535960.67506,174.642646789551,10000.3994140625,-1.76535630075032E-5,1.53088342747853E-8,1,4,13.4005146026611,5.00616094193266,32.6300002634525,-0.0219832340784206,-0.00326898145151496,1,1.53775510595077E-8,,,,,,,,,,,,,,,,,,,,,174.254837036133,175.030456542969,10000.3994140625,10000.3994140625,53.745167796573,5.63925878125969,5.15019083023071,53,1,64,0,0,0.300827026367188,33.7243423461914,2,1,3,174.254837036133,0,174.642646789551,,,,,,,,,,,,,,,,,,,,,,,,,,,,,,,,,
,3878535984.74563,170.744155883789,10000.3994140625,-1.76283087793598E-5,1.88181529824122E-8,1,4,13.4005146026611,5.0059806907475,32.6300002634525,-0.0219509886496979,-0.00326208380143783,1,1.70076296442929E-8,,,,,,,,,,,,,,,,,,,,,170.351760864258,171.13655090332,10000.3994140625,10000.3994140625,53.8272387910922,5.63969282831132,5.14170455932617,54,1,0,0,1,0.301742553710937,33.7243423461914,2,1,3,170.351760864258,0,170.744155883789,,,,,,,,,,,,,,,,,,,,,,,,,,,,,,,,,
,3878536008.88207,166.745574951172,10000.3994140625,-1.76183718251282E-5,1.31294776254467E-8,1,4,13.4005146026611,5.00597436481058,32.6099991798401,-0.0219396623559103,-0.00325297898431117,1,2.28294200599302E-8,,,,,,,,,,,,,,,,,,,,,166.418426513672,167.072723388672,10000.3994140625,10000.3994140625,53.8932864009672,5.63907066930813,5.13236331939697,54,1,0,0,1,0.29937744140625,33.7243423461914,2,1,3,166.418426513672,0,166.745574951172,,,,,,,,,,,,,,,,,,,,,,,,,,,,,,,,,
,3878536033.09532,162.590950012207,10000.3994140625,-1.76232112932541E-5,1.32165204021255E-8,1,4,13.4005146026611,5.00636906943857,32.6099991798401,-0.0219475004975685,-0.00325829324218877,1,1.95734751750857E-8,,,,,,,,,,,,,,,,,,,,,162.244232177734,162.93766784668,10000.3994140625,10000.3994140625,53.8647569600153,5.6375015051657,5.12619876861572,54,1,0,0,1,0.3009033203125,34.2131004333496,2,1,3,162.244232177734,0,162.590950012207,,,,,,,,,,,,,,,,,,,,,,,,,,,,,,,,,
,3878536057.45767,158.694709777832,10000.3994140625,-1.76214739461047E-5,1.66278810784567E-8,1,4,13.4005146026611,5.0065227595638,32.6099991798401,-0.0219476905786469,-0.00324867413899442,1,2.71507008181687E-8,,,,,,,,,,,,,,,,,,,,,158.359619140625,159.029800415039,10000.3994140625,10000.3994140625,53.7514208247268,5.63782106190063,5.12154626846313,53,1,64,0,0,0.301513671875,34.2131004333496,2,1,3,158.359619140625,0,158.694709777832,,,,,,,,,,,,,,,,,,,,,,,,,,,,,,,,,
,3878536081.41928,154.566581726074,10000.3994140625,-1.75883292453503E-5,2.31422813810241E-8,1,4,13.4005146026611,5.00617394649437,32.6099991798401,-0.0219034308861796,-0.00324788858162261,1,2.25692224685211E-8,,,,,,,,,,,,,,,,,,,,,154.204406738281,154.928756713867,10000.3994140625,10000.3994140625,53.7658809523326,5.63998853175645,5.11297130584717,54,1,0,0,1,0.302581787109375,34.2131004333496,2,1,3,154.204406738281,0,154.566581726074,,,,,,,,,,,,,,,,,,,,,,,,,,,,,,,,,
,3878536105.61087,150.674667358398,10000.3994140625,-1.75917298099158E-5,1.88452043801825E-8,1,4,13.4005146026611,5.00626601692971,32.5900018215179,-0.0219081936999813,-0.00324883654396386,1,2.23836653203952E-8,,,,,,,,,,,,,,,,,,,,,150.350570678711,150.998764038086,10000.3994140625,10000.3994140625,53.7107761417268,5.63977479303241,5.10374689102173,54,1,0,0,1,0.298843383789063,33.7243423461914,2,1,3,150.350570678711,0,150.674667358398,,,,,,,,,,,,,,,,,,,,,,,,,,,,,,,,,
,3878536129.77706,146.459747314453,10000.3994140625,-1.75916868325649E-5,1.47593660179471E-8,1,4,13.4005146026611,5.0060748705455,32.5900018215179,-0.0219052019393587,-0.00326047856989889,1,1.28874059333759E-8,,,,,,,,,,,,,,,,,,,,,146.111297607422,146.808197021484,10000.3994140625,10000.3994140625,53.8362275190634,5.63933480279104,5.1004114151001,54,1,0,0,1,0.301666259765625,34.2131004333496,2,1,3,146.111297607422,0,146.459747314453,,,,,,,,,,,,,,,,,,,,,,,,,,,,,,,,,
,3878536154.06892,142.426818847656,10000.3994140625,-1.75846066960967E-5,1.68980673018694E-8,1,4,13.4005146026611,5.00606813647009,32.5900018215179,-0.0219002354778535,-0.00323315029367636,1,3.37726457470471E-8,,,,,,,,,,,,,,,,,,,,,142.089965820312,142.763671875,10000.3994140625,10000.3994140625,53.9050108287557,5.64183047263979,5.08739709854126,53,1,64,0,0,0.30059814453125,34.2131004333496,2,1,3,142.089965820312,0,142.426818847656,,,,,,,,,,,,,,,,,,,,,,,,,,,,,,,,,
,3878536178.13582,138.461204528809,10000.3994140625,-1.75817277657691E-5,1.21505271042723E-8,1,4,13.4005146026611,5.00638959710045,32.5900018215179,-0.0218981296484416,-0.00323616184791036,1,3.11565193424442E-8,,,,,,,,,,,,,,,,,,,,,138.100982666016,138.821426391602,10000.3994140625,10000.3994140625,53.8276296053519,5.6393256393236,5.08218288421631,54,1,0,0,1,0.299224853515625,33.7243423461914,2,1,3,138.100982666016,0,138.461204528809,,,,,,,,,,,,,,,,,,,,,,,,,,,,,,,,,
,3878536202.31006,134.368499755859,10000.3994140625,-1.7567395434276E-5,1.87584436529679E-8,1,4,13.4005146026611,5.00649687805889,32.5900018215179,-0.0218790076505249,-0.00324649910096696,1,2.07887532519587E-8,,,,,,,,,,,,,,,,,,,,,134.020172119141,134.716827392578,10000.3994140625,10000.3994140625,53.806134821073,5.63965303328746,5.07341432571411,52,1,32,0,0,0.299301147460937,34.2131004333496,2,1,3,133.992797851562,0,134.368499755859,,,,,,,,,,,,,,,,,,,,,,,,,,,,,,,,,
,3878536226.4875,130.377067565918,10000.3994140625,-1.75691766965915E-5,1.64761027442804E-8,1,4,13.4005146026611,5.00636648470266,32.5700007379055,-0.0218804846414962,-0.00324634029449738,1,2.10878180379306E-8,,,,,,,,,,,,,,,,,,,,,130.016738891602,130.737396240234,10000.3994140625,10000.3994140625,53.7322709260057,5.6407562836722,5.0629711151123,54,1,0,0,1,0.301742553710937,34.2131004333496,2,1,3,130.016738891602,0,130.377067565918,,,,,,,,,,,,,,,,,,,,,,,,,,,,,,,,,
,3878536250.75134,126.405788421631,10000.3994140625,-1.75517127504273E-5,1.62350299893725E-8,1,4,13.4005146026611,5.006132917139,32.5700007379055,-0.0218558917271675,-0.00325237864350753,1,1.34555014429891E-8,,,,,,,,,,,,,,,,,,,,,126.142471313477,126.669105529785,10000.3994140625,10000.3994140625,53.7846400367942,5.6406755067104,5.05964374542236,50,1,96,0,0,0.301971435546875,34.2131004333496,2,1,3,126.142471313477,0,126.405788421631,,,,,,,,,,,,,,,,,,,,,,,,,,,,,,,,,
,3878536287.15357,120.348022460938,10000.3994140625,-1.75356490509136E-5,1.47028035921801E-8,1,4,13.4005146026611,5.00629265750635,32.5700007379055,-0.0218376568708607,-0.00324423968452254,1,1.77055798928321E-8,,,,,,,,,,,,,,,,,,,,,119.961372375488,120.734672546387,10000.3994140625,10000.3994140625,53.7592371099191,5.64086304334029,5.05190801620483,52,1,64,0,0,0.29998779296875,33.7243423461914,2,1,3,119.961372375488,0,120.348022460938,,,,,,,,,,,,,,,,,,,,,,,,,,,,,,,,,
,3878536311.14422,116.357089996338,10000.3994140625,-1.75225098477086E-5,1.83441477152263E-8,1,4,13.4005146026611,5.00644611755811,32.5700007379055,-0.0218247782577084,-0.00322490950449885,1,3.13755200564607E-8,,,,,,,,,,,,,,,,,,,,,116.018630981445,116.69554901123,10000.3994140625,10000.3994140625,53.7912838792076,5.64054494429245,5.03867292404175,54,1,0,0,1,0.298995971679687,33.7243423461914,2,1,3,116.018630981445,0,116.357089996338,,,,,,,,,,,,,,,,,,,,,,,,,,,,,,,,,
,3878536335.29619,112.35071182251,10000.3994140625,-1.75163236411143E-5,1.34379207295681E-8,1,4,13.4005146026611,5.00650949437919,32.5700007379055,-0.0218167578231194,-0.00322851720191764,1,2.75986931943328E-8,,,,,,,,,,,,,,,,,,,,,111.959327697754,112.742095947266,10000.3994140625,10000.3994140625,53.7729156090057,5.63944924885608,5.03055000305176,54,1,0,0,1,0.299758911132812,33.7243423461914,2,1,3,111.959327697754,0,112.35071182251,,,,,,,,,,,,,,,,,,,,,,,,,,,,,,,,,
,3878536360.05575,108.167011260986,10000.3994140625,-1.75215846295825E-5,1.72347495810627E-8,1,4,13.4005146026611,5.00648340292908,32.5499996542931,-0.0218246125488673,-0.003219696106888,1,3.54508495977209E-8,,,,,,,,,,,,,,,,,,,,,107.976295471191,108.357727050781,10000.3994140625,10000.3994140625,53.9022751289384,5.6424220728567,5.01570320129395,53,1,64,0,0,0.300369262695313,34.7018585205078,2,1,3,107.976295471191,0,108.167011260986,,,,,,,,,,,,,,,,,,,,,,,,,,,,,,,,,
,3878536383.75575,104.320133209229,10000.3994140625,-1.75136321566541E-5,1.56439897600125E-8,1,4,13.4005146026611,5.00659309353488,32.5499996542931,-0.0218163552171203,-0.00321178281177378,1,4.069521601573E-8,,,,,,,,,,,,,,,,,,,,,104.024337768555,104.615928649902,10000.3994140625,10000.3994140625,53.821376577198,5.63936437323696,5.01210975646973,54,1,0,0,1,0.299835205078125,34.2131004333496,2,1,3,104.024337768555,0,104.320133209229,,,,,,,,,,,,,,,,,,,,,,,,,,,,,,,,,
,3878536407.85431,100.445190429688,10000.3994140625,-1.74986149562193E-5,1.63925704595894E-8,1,4,13.4005146026611,5.00664446522342,32.5499996542931,-0.02179423984329,-0.00323395199436121,1,2.0682930563345E-8,,,,,,,,,,,,,,,,,,,,,100.168754577637,100.721626281738,10000.3994140625,10000.3994140625,53.8502968324095,5.63837653705397,4.99472618103027,54,1,0,0,1,0.299530029296875,34.2131004333496,2,1,3,100.168754577637,0,100.445190429688,,,,,,,,,,,,,,,,,,,,,,,,,,,,,,,,,
,3878536432.05621,96.4556579589844,10000.3994140625,-1.74883061522732E-5,1.43148793531764E-8,1,4,13.4005146026611,5.00672935781132,32.5499996542931,-0.0217831794732849,-0.00322368228920093,1,2.744917643809E-8,,,,,,,,,,,,,,,,,,,,,96.1902160644531,96.7210998535156,10000.3994140625,10000.3994140625,53.6799018152172,5.63788616731948,4.98413753509521,52,1,68,0,0,0.299835205078125,34.2131004333496,2,1,3,96.1902160644531,0,96.4556579589844,,,,,,,,,,,,,,,,,,,,,,,,,,,,,,,,,
,3878536456.18609,92.4291343688965,10000.3994140625,-1.74753045452924E-5,1.73573655082941E-8,1,4,13.4005146026611,5.00676929073663,32.5499996542931,-0.0217654658844848,-0.00323309806205678,1,1.797207534226E-8,,,,,,,,,,,,,,,,,,,,,92.1565704345703,92.7016983032227,10000.3994140625,10000.3994140625,53.7901114364288,5.63901585064258,4.97778367996216,54,1,0,0,1,0.300140380859375,34.2131004333496,2,1,3,92.1565704345703,0,92.4291343688965,,,,,,,,,,,,,,,,,,,,,,,,,,,,,,,,,
,3878536480.35698,88.26806640625,10000.3994140625,-1.74652854301567E-5,1.46197103779036E-8,1,4,13.4005146026611,5.00664026256707,32.5499996542931,-0.021752315600888,-0.00323037774308931,1,1.8564271383539E-8,,,,,,,,,,,,,,,,,,,,,87.9513397216797,88.5847930908203,10000.3994140625,10000.3994140625,53.8119970349672,5.63816708872936,4.96533298492432,54,1,0,0,1,0.301132202148438,34.7018585205078,2,1,3,87.9513397216797,0,88.26806640625,,,,,,,,,,,,,,,,,,,,,,,,,,,,,,,,,
,3878536504.53107,84.3674659729004,10000.3994140625,-1.74583253089372E-5,2.33262768285419E-8,1,4,13.4005146026611,5.00670512687544,32.5499996542931,-0.0217468904882624,-0.00321009994829689,1,3.38537288586222E-8,,,,,,,,,,,,,,,,,,,,,84.0642395019531,84.6706924438477,10000.3994140625,10000.3994140625,53.7998817929191,5.6390208381975,4.94886255264282,54,1,0,0,1,0.300521850585937,33.7243423461914,2,1,3,84.0642395019531,0,84.3674659729004,,,,,,,,,,,,,,,,,,,,,,,,,,,,,,,,,
,3878536528.73668,80.2232666015625,10000.3994140625,-1.74441194254992E-5,1.62751023580157E-8,1,4,13.4005146026611,5.00674992321139,32.5299985706806,-0.0217289482779584,-0.00321099414518765,1,3.10428033412242E-8,,,,,,,,,,,,,,,,,,,,,79.9011840820312,80.5453491210937,10000.3994140625,10000.3994140625,53.7330525545249,5.63799282037427,4.93107652664185,54,1,0,0,1,0.300369262695313,34.7018585205078,2,1,3,79.9011840820312,0,80.2232666015625,,,,,,,,,,,,,,,,,,,,,,,,,,,,,,,,,
,3878536552.9738,76.0744781494141,10000.3994140625,-1.74201528417979E-5,1.49446047179309E-8,1,4,13.4005146026611,5.00681288426624,32.5299985706806,-0.0216987796151096,-0.00321129558008652,1,2.72608267633678E-8,,,,,,,,,,,,,,,,,,,,,75.8089065551758,76.3400497436523,10000.3994140625,10000.3994140625,53.7588462956595,5.63851491088192,4.91888046264648,53,1,64,0,0,0.299606323242188,34.2131004333496,2,1,3,75.8089065551758,0,76.0744781494141,,,,,,,,,,,,,,,,,,,,,,,,,,,,,,,,,
,3878536577.06106,72.0253562927246,10000.3994140625,-1.74219854132771E-5,1.7665829362147E-8,1,4,13.4005146026611,5.0068458625208,32.5299985706806,-0.0217026298760872,-0.0032025198517,1,3.46056031016651E-8,,,,,,,,,,,,,,,,,,,,,71.6845321655273,72.3661804199219,10000.3994140625,10000.3994140625,53.7635360667749,5.63906058574637,4.89669418334961,54,1,0,0,1,0.299835205078125,33.7243423461914,2,1,3,71.6845321655273,0,72.0253562927246,,,,,,,,,,,,,,,,,,,,,,,,,,,,,,,,,
,3878536601.3258,67.8580551147461,10000.3994140625,-1.73968674228446E-5,1.66990613714406E-8,1,4,13.4005146026611,5.00693233234903,32.5299985706806,-0.0216682809350329,-0.00322192873149289,1,1.53252843122617E-8,,,,,,,,,,,,,,,,,,,,,67.5795364379883,68.1365737915039,10000.3994140625,10000.3994140625,53.8608488174192,5.63803109646231,4.88796901702881,54,1,0,0,1,0.299835205078125,33.7243423461914,2,1,3,67.5795364379883,0,67.8580551147461,,,,,,,,,,,,,,,,,,,,,,,,,,,,,,,,,
,3878536636.63478,61.7725734710693,10000.3994140625,-1.73714750293482E-5,1.47662673991453E-8,1,4,13.4005146026611,5.00691891827832,32.5299985706806,-0.0216396854196428,-0.00319640794962988,1,3.2009760296555E-8,,,,,,,,,,,,,,,,,,,,,61.2316780090332,62.3134689331055,10000.3994140625,10000.3994140625,53.7608003669576,5.63764255529313,4.8525447845459,54,1,0,0,1,0.299072265625,34.2131004333496,2,1,3,61.2316780090332,0,61.7725734710693,,,,,,,,,,,,,,,,,,,,,,,,,,,,,,,,,
,3878536661.76997,57.5017185211182,10000.3994140625,-1.73779972383698E-5,4.07602848114594E-8,1,4,13.4005146026611,5.00695937903525,32.5199998915195,-0.0216499278749301,-0.00318512250093091,1,4.20763404681005E-8,,,,,,,,,,,,,,,,,,,,,57.1787223815918,57.8247146606445,10000.3994140625,10000.3994140625,53.7783870086403,5.63766710238515,4.83243656158447,54,1,0,0,1,0.299911499023438,34.2131004333496,2,1,3,57.1787223815918,0,57.5017185211182,,,,,,,,,,,,,,,,,,,,,,,,,,,,,,,,,
,3878536685.92908,53.4351692199707,10000.3994140625,-1.73192477790064E-5,1.60415378132838E-8,1,4,13.4005146026611,5.0069849405799,32.5199998915195,-0.0215745721459106,-0.00318987409955554,1,2.94906617038648E-8,,,,,,,,,,,,,,,,,,,,,53.103385925293,53.7669525146484,10000.3994140625,10000.3994140625,53.7971460931018,5.63735310933766,4.80120658874512,54,1,0,0,1,0.30059814453125,34.7018585205078,2,1,3,53.103385925293,0,53.4351692199707,,,,,,,,,,,,,,,,,,,,,,,,,,,,,,,,,
,3878536710.03572,49.3048248291016,10000.3994140625,-1.72983758240591E-5,2.10017473449309E-8,1,4,13.4005146026611,5.00706413267412,32.5199998915195,-0.0215509621143835,-0.00317330777807076,1,3.97268861045791E-8,,,,,,,,,,,,,,,,,,,,,48.9468650817871,49.662784576416,10000.3994140625,10000.3994140625,53.7482943106499,5.63842364948749,4.77406549453735,53,1,68,0,0,0.299224853515625,34.2131004333496,2,1,3,48.9468650817871,0,49.3048248291016,,,,,,,,,,,,,,,,,,,,,,,,,,,,,,,,,
,3878536746.5795,43.0562973022461,10000.3994140625,-1.72439692835728E-5,1.64706857964037E-8,1,4,13.4005146026611,5.00704819932458,32.5100012123585,-0.0214813640039087,-0.00317481650750563,1,3.03652298328059E-8,,,,,,,,,,,,,,,,,,,,,42.8329162597656,43.2796783447266,10000.3994140625,10000.3994140625,53.8944588437461,5.63802083095878,4.71821212768555,54,1,0,0,1,0.299072265625,34.2131004333496,2,1,3,42.8329162597656,0,43.0562973022461,,,,,,,,,,,,,,,,,,,,,,,,,,,,,,,,,
,3878536776.96156,37.8109245300293,10000.3994140625,-1.71980569278222E-5,1.38143492960328E-8,1,4,13.4005146026611,5.00709733574862,32.5100012123585,-0.0214228700311442,-0.00317705844145461,10,2.17318547490575E-8,,,,,,,,,,,,,,,,,,,,,37.7332534790039,37.8885955810547,10000.3994140625,10000.3994140625,53.867101845573,5.63749584812149,4.67385911941528,52,1,68,0,0,0.299835205078125,34.2131004333496,2,1,3,37.7332534790039,0,37.8109245300293,,,,,,,,,,,,,,,,,,,,,,,,,,,,,,,,,
,3878536810.78826,32.0998392105103,10000.3994140625,-1.71152420591666E-5,1.69654911454964E-8,1,4,13.4005146026611,5.00710102420523,32.5100012123585,-0.0213257276137988,-0.00312169117121875,1,5.38025115548492E-8,,,,,,,,,,,,,,,,,,,,,31.7774448394775,32.422233581543,10000.3994140625,10000.3994140625,53.867101845573,5.63681248536906,4.59875583648682,54,1,0,0,1,0.299911499023438,33.7243423461914,2,1,3,31.7774448394775,0,32.0998392105103,,,,,,,,,,,,,,,,,,,,,,,,,,,,,,,,,
,3878536852.04717,25.0556049346924,10000.3994140625,-1.70363035222892E-5,2.13878783761042E-8,1,4,13.4005146026611,5.00731112131575,32.5100012123585,-0.021219353744087,-0.00316938307988516,10,3.84929170141836E-9,,,,,,,,,,,,,,,,,,,,,25.01828956604,25.0929203033447,10000.3994140625,10000.3994140625,53.8002726071788,5.63661667242242,4.46908378601074,54,1,0,0,1,0.298843383789063,34.2131004333496,2,1,3,25.01828956604,0,25.0556049346924,,,,,,,,,,,,,,,,,,,,,,,,,,,,,,,,,
,3878536883.30335,19.8513689041138,10000.3994140625,-1.68593313831498E-5,2.48985733044131E-8,1,4,13.4005146026611,5.00726102203162,32.4999988079071,-0.0210021181167929,-0.00311312947818447,1,2.25060360647465E-8,,,,,,,,,,,,,,,,,,,,,19.5741024017334,20.1286354064941,10000.3994140625,10000.3994140625,53.8432621757365,5.63741890414488,4.32027053833008,52,1,32,0,0,0.298690795898438,34.2131004333496,2,1,3,19.5572910308838,0,19.8513689041138,,,,,,,,,,,,,,,,,,,,,,,,,,,,,,,,,
,3878536919.83715,13.7879586219788,10000.3994140625,-1.66217940783896E-5,1.94228985300772E-8,1,4,13.4005146026611,5.00723954806011,32.4999988079071,-0.0207019900430629,-0.00309663916159964,1,1.97164167276279E-10,,,,,,,,,,,,,,,,,,,,,13.5230140686035,14.052903175354,10000.3994140625,10000.3994140625,53.8483427611115,5.63687363665917,4.05379390716553,54,1,0,0,1,0.299224853515625,34.2131004333496,2,1,3,13.5230140686035,0,13.7879586219788,,,,,,,,,,,,,,,,,,,,,,,,,,,,,,,,,
,3878536943.82608,9.94809722900391,10000.3994140625,-1.63204890405533E-5,1.99447178289533E-8,1,4,13.4005146026611,5.00731677746497,32.4999988079071,-0.0203339889404287,-0.00299492921785241,1,3.68395072323268E-8,,,,,,,,,,,,,,,,,,,,,9.56930732727051,10.3268871307373,10000.3994140625,10000.3994140625,53.8241122770153,5.63716129407234,3.68238568305969,53,1,68,0,0,0.297698974609375,33.7243423461914,2,1,3,9.56930732727051,0,9.94809722900391,,,,,,,,,,,,,,,,,,,,,,,,,,,,,,,,,
,3878536967.92347,9.74679565429688,10000.3994140625,-1.63422991203866E-5,2.52826311891674E-8,1,4,13.4005146026611,5.00737077740098,32.4999988079071,-0.020355696007152,-0.00303757092220547,1,5.90223712547551E-9,,,,,,,,,,,,,,,,,,,,,9.67495346069336,9.81863784790039,10000.3994140625,10000.3994140625,53.8307561194288,5.63769996760933,3.56474876403809,54,1,0,0,1,0.298614501953125,34.2131004333496,6,1,3,9.67495346069336,0,9.74679565429688,,,,,,,,,,,,,,,,,,,,,,,,,,,,,,,,,
,3878536992.10816,8.88382863998413,10000.3994140625,-1.62559958674042E-5,1.6412519826274E-8,1,4,13.4005146026611,5.00736806118603,32.4999988079071,-0.0202492488051688,-0.00301440101268922,1,1.15926246950262E-8,,,,,,,,,,,,,,,,,,,,,8.81685638427734,8.95080089569092,10000.3994140625,10000.3994140625,53.9663686675153,5.63671856159552,3.38980317115784,51,1,68,0,0,0.298538208007812,34.2131004333496,6,1,3,8.81685638427734,0,8.88382863998413,,,,,,,,,,,,,,,,,,,,,,,,,,,,,,,,,
,3878537028.65684,7.11131429672241,10000.3994140625,-1.5986297462953E-5,2.02870782382053E-8,1,4,13.4005146026611,5.00732223985277,32.490000128746,-0.0199126550148762,-0.00296695766447985,1,9.30827846669815E-9,,,,,,,,,,,,,,,,,,,,,6.92176818847656,7.30086040496826,10000.3994140625,10000.3994140625,53.902665943198,5.63879410439263,3.01518154144287,50,1,100,0,0,0.299530029296875,34.2131004333496,6,1,3,6.92176818847656,0,7.11131429672241,,,,,,,,,,,,,,,,,,,,,,,,,,,,,,,,,
,3878537052.58228,5.51051592826843,10000.3994140625,-1.56680549585379E-5,2.67966325188552E-8,1,4,13.4005146026611,5.00740086110234,32.490000128746,-0.0195213794915935,-0.00287652970672393,1,3.43556365937399E-8,,,,,,,,,,,,,,,,,,,,,5.41095733642578,5.61007452011108,10000.3994140625,10000.3994140625,53.8764813878038,5.63557712267732,2.7279965877533,54,1,0,0,1,0.2984619140625,35.6793746948242,6,1,3,5.41095733642578,0,5.51051592826843,,,,,,,,,,,,,,,,,,,,,,,,,,,,,,,,,
,3878537076.7282,3.06616187095642,10000.3994140625,-1.46573003752829E-5,2.34158714636542E-8,1,4,13.4005146026611,5.00739048766976,32.490000128746,-0.0182640230824244,-0.00267737814936258,1,4.30402183773126E-8,,,,,,,,,,,,,,,,,,,,,2.93814659118652,3.19417715072632,10000.3994140625,10000.3994140625,53.7584554813999,5.63615217128484,2.30096220970154,54,1,0,0,1,0.299224853515625,34.7018585205078,6,1,3,2.93814659118652,0,3.06616187095642,,,,,,,,,,,,,,,,,,,,,,,,,,,,,,,,,
,3878537113.24408,2.56971502304077,10000.3994140625,-1.42894017251592E-5,2.13809122219695E-8,1,4,13.4005146026611,5.00745784853382,32.490000128746,-0.0178031731358295,-0.00262865678471155,1,2.71617285641402E-8,,,,,,,,,,,,,,,,,,,,,2.56813931465149,2.57129073143005,10000.3994140625,10000.3994140625,53.9843461234576,5.63640677206679,2.13941955566406,54,1,0,0,1,0.29876708984375,33.7243423461914,6,1,3,2.56813931465149,0,2.56971502304077,,,,,,,,,,,,,,,,,,,,,,,,,,,,,,,,,
,3878537137.18093,2.58178293704987,10000.3994140625,-1.42877046110497E-5,1.94590718077037E-8,1,4,13.4005146026611,5.00741662636117,32.490000128746,-0.0178012190015137,-0.00262587341058296,1,2.91182512989366E-8,,,,,,,,,,,,,,,,,,,,,2.58019042015076,2.58337545394897,10000.3994140625,10000.3994140625,53.9085281570922,5.6368494380033,2.14081764221191,54,1,0,0,1,0.298919677734375,33.7243423461914,6,1,3,2.58345174789429,0,2.58178293704987,,,,,,,,,,,,,,,,,,,,,,,,,,,,,,,,,
,3878537161.37862,2.59838843345642,10000.3994140625,-1.43108878067704E-5,3.20280988999183E-8,1,4,13.4005146026611,5.00743113332876,32.490000128746,-0.0178264294657483,-0.00265518566997408,1,9.06102101724248E-9,,,,,,,,,,,,,,,,,,,,,2.5971417427063,2.59963512420654,10000.3994140625,10000.3994140625,53.9573799395442,5.63708696547911,2.15856337547302,54,1,0,0,1,0.298309326171875,34.2131004333496,6,1,3,2.59963512420654,0,2.59838843345642,,,,,,,,,,,,,,,,,,,,,,,,,,,,,,,,,
,3878537185.55701,2.59649980068207,10000.3994140625,-1.4311959684369E-5,2.01531094382745E-8,1,4,13.4005146026611,5.00741603245002,32.490000128746,-0.0178301599546737,-0.00263885893929878,1,2.23206212318157E-8,,,,,,,,,,,,,,,,,,,,,2.59538197517395,2.59761762619019,10000.3994140625,10000.3994140625,53.999197065323,5.6367250376152,2.16225600242615,54,1,0,0,1,0.301513671875,33.7243423461914,6,1,3,2.59761762619019,0,2.59649980068207,,,,,,,,,,,,,,,,,,,,,,,,,,,,,,,,,
,3878537209.73076,2.58416426181793,10000.3994140625,-1.42927309406417E-5,2.12101427290245E-8,1,4,13.4005146026611,5.00736583132581,32.490000128746,-0.0178076202855602,-0.0026241432859764,1,3.12293481896074E-8,,,,,,,,,,,,,,,,,,,,,2.58264589309692,2.58568263053894,10000.3994140625,10000.3994140625,53.9878634517942,5.63684889353116,2.15512490272522,54,1,0,0,1,0.299224853515625,34.2131004333496,6,1,3,2.58264589309692,0,2.58416426181793,,,,,,,,,,,,,,,,,,,,,,,,,,,,,,,,,
,3878537233.89542,2.55808866024017,10000.3994140625,-1.42873244604483E-5,1.81202849970648E-8,1,4,13.4005146026611,5.00739518342017,32.490000128746,-0.0177976841746499,-0.00264553887903562,1,1.32598583966213E-8,,,,,,,,,,,,,,,,,,,,,2.5556321144104,2.56054520606995,10000.3994140625,10000.3994140625,54.0984638872653,5.63708541981221,2.14967346191406,54,1,0,0,1,0.2984619140625,34.2131004333496,6,1,3,2.5556321144104,0,2.55808866024017,,,,,,,,,,,,,,,,,,,,,,,,,,,,,,,,,
,3878537258.06815,2.5193395614624,10000.3994140625,-1.42482386938586E-5,1.92640905983161E-8,1,4,13.4005146026611,5.00740630314928,32.490000128746,-0.0177535034979681,-0.00260854062557896,1,3.71243266030587E-8,,,,,,,,,,,,,,,,,,,,,2.51762270927429,2.52105641365051,10000.3994140625,10000.3994140625,53.9245515417365,5.63698582523674,2.13715624809265,54,1,0,0,1,0.299301147460937,33.7243423461914,6,1,3,2.52105641365051,0,2.5193395614624,,,,,,,,,,,,,,,,,,,,,,,,,,,,,,,,,
,3878537282.26647,2.52376890182495,10000.3994140625,-1.4237397455378E-5,1.83788897721279E-8,1,4,13.4005146026611,5.00740729751044,32.490000128746,-0.0177353051601389,-0.00263794105896412,1,1.18983449297145E-8,,,,,,,,,,,,,,,,,,,,,2.5236701965332,2.5238676071167,10000.3994140625,10000.3994140625,53.8987578006019,5.63626785520053,2.13947629928589,54,1,0,0,1,0.299453735351562,34.2131004333496,6,1,3,2.5238676071167,0,2.52376890182495,,,,,,,,,,,,,,,,,,,,,,,,,,,,,,,,,
,3878537306.4187,2.51223361492157,10000.3994140625,-1.42171483322666E-5,2.35310037688748E-8,1,4,13.4005146026611,5.00744150515031,32.490000128746,-0.0177113557123925,-0.00262682474542344,1,1.78143159298282E-8,,,,,,,,,,,,,,,,,,,,,2.50996470451355,2.51450252532959,10000.3994140625,10000.3994140625,53.9147811852461,5.63617851368132,2.14301538467407,54,1,0,0,1,0.297775268554687,34.2131004333496,6,1,3,2.50996470451355,0,2.51223361492157,,,,,,,,,,,,,,,,,,,,,,,,,,,,,,,,,
,3878537330.64151,2.48845732212067,10000.3994140625,-1.42242796455156E-5,2.81729566604417E-8,1,4,13.4005146026611,5.00739096874687,32.490000128746,-0.0177238278501462,-0.0026024483025027,1,3.8422612083077E-8,,,,,,,,,,,,,,,,,,,,,2.4866783618927,2.49023628234863,10000.3994140625,10000.3994140625,53.9308045698903,5.63759663525036,2.13468599319458,54,1,0,0,1,0.304412841796875,34.2131004333496,6,1,3,2.4866783618927,0,2.48845732212067,,,,,,,,,,,,,,,,,,,,,,,,,,,,,,,,,
,3878537354.83786,2.35353100299835,10000.3994140625,-1.40656881879184E-5,1.93881313890588E-8,1,4,13.4005146026611,5.00736726571011,32.490000128746,-0.0175221314083905,-0.00259996306888196,1,1.6679827012724E-8,,,,,,,,,,,,,,,,,,,,,2.3297803401947,2.377281665802,10000.3994140625,10000.3994140625,54.0589916470442,5.63701517897038,2.07525014877319,54,1,0,0,1,0.298690795898438,34.2131004333496,6,1,3,2.3297803401947,0,2.35353100299835,,,,,,,,,,,,,,,,,,,,,,,,,,,,,,,,,
,3878537378.93974,2.05478990077972,10000.3994140625,-1.37543766534701E-5,1.96409355426977E-8,1,4,13.4005146026611,5.0074206249083,32.490000128746,-0.0171355192217519,-0.00253614297976798,1,2.13797961234571E-8,,,,,,,,,,,,,,,,,,,,,2.01952958106995,2.0900502204895,10000.3994140625,10000.3994140625,53.9136087424672,5.63681305485443,1.93317461013794,54,1,0,0,1,0.303421020507812,33.7243423461914,2,1,3,2.01952958106995,0,2.05478990077972,,,,,,,,,,,,,,,,,,,,,,,,,,,,,,,,,
,3878537403.1453,2.00035786628723,10000.3994140625,-1.37031864274915E-5,2.03922367036346E-8,1,4,13.4005146026611,5.00742998903747,32.490000128746,-0.0170702270360009,-0.00253715801147379,1,1.29124411682905E-8,,,,,,,,,,,,,,,,,,,,,2.0001802444458,2.00053548812866,10000.3994140625,10000.3994140625,53.8928955867076,5.63689876697984,1.90452396869659,54,1,0,0,1,0.298690795898438,34.2131004333496,5,1,3,2.00053548812866,0,2.00035786628723,,,,,,,,,,,,,,,,,,,,,,,,,,,,,,,,,
,3878537427.32859,1.99955654144287,10000.3994140625,-1.37047528916736E-5,2.25686719871153E-8,1,4,13.4005146026611,5.00743411195896,32.490000128746,-0.0170710621272485,-0.00254504433711886,1,6.81745755974208E-9,,,,,,,,,,,,,,,,,,,,,1.99917793273926,1.99993515014648,10000.3994140625,10000.3994140625,53.9354943410057,5.63715453197269,1.89569509029388,54,1,0,0,1,0.298538208007812,34.2131004333496,5,1,3,1.99993515014648,0,1.99955654144287,,,,,,,,,,,,,,,,,,,,,,,,,,,,,,,,,
,3878537451.46978,1.99997174739838,10000.3994140625,-1.37229749781521E-5,1.825950460102E-8,1,4,13.4005146026611,5.00740629869882,32.490000128746,-0.0170943919740523,-0.00254329746243264,1,1.09300210295085E-8,,,,,,,,,,,,,,,,,,,,,1.99994993209839,1.99999356269836,10000.3994140625,10000.3994140625,54.0519569903711,5.63792952048234,1.8846093416214,54,1,0,0,1,0.300369262695313,34.2131004333496,5,1,3,1.99999356269836,0,1.99997174739838,,,,,,,,,,,,,,,,,,,,,,,,,,,,,,,,,
,3878537471.65627,1.99919325113297,10000.3994140625,-1.37287957614761E-5,1.92793695995348E-8,1,4,13.4005146026611,5.00740421014412,32.490000128746,-0.0171049174832434,-0.00252241752922252,1,2.85635089945522E-8,,,,,,,,,,,,,,,,,,,,,1.99897634983063,1.9994101524353,10000.3994140625,10000.3994140625,53.9577707538038,5.63674318608612,1.88319432735443,54,1,0,0,1,0.298995971679687,33.2355842590332,1,1,3,1.9994101524353,0,1.99919325113297,,,,,,,,,,,,,,,,,,,,,,,,,,,,,,,,,