File: SQUID/22157b_LCOT/LCOT_MH_100K_FC+1T_2.csv
Comment,Time Stamp (sec),Temperature (K),Magnetic Field (Oe),Moment (emu),M. Std. Err. (emu),Transport Action,Averaging Time (sec),Frequency (Hz),Peak Amplitude (mm),Center Position (mm),Lockin Signal' (V),Lockin Signal (V),Range,M. Quad. Signal (emu),AC Moment (emu),AC M. Std Err. (emu),AC Phase (deg),AC Phase Std. Err. (deg),AC Susceptibility (emu/Oe),AC Suscept. Std Err. (emu/Oe),AC X' (emu/Oe),AC X' Std Err. (emu/Oe),AC X'' (emu/Oe),AC X'' Std Err. (emu/Oe),AC Drive (Oe),AC Frequency (Hz),AC Averaging Time (sec),AC Cycles,AC Range,AC Measure Type,AC Signal' (V),AC Signal'' (V),AC Trim Coil Ratio,AC Trim Coil Phase,Min. Temperature (K),Max. Temperature (K),Min. Field (Oe),Max. Field (Oe),Mass (grams),Motor Lag (deg),Pressure (Torr),Measure Count,Measurement Number,SQUID Status (code),Motor Status (code),Measure Status (code),Motor Current (amps),Motor Temp. (C),Temp. Status (code),Field Status (code),Chamber Status (code),Chamber Temp (K),Redirection State,Average Temp (K),Rotation Angle (deg),Rotator state,DC Moment Fixed Ctr (emu),DC Moment Err Fixed Ctr (emu),DC Moment Free Ctr (emu),DC Moment Err Free Ctr (emu),DC Fixed Fit,DC Free Fit,DC Calculated Center (mm),DC Calculated Center Err (mm),DC Scan Length (mm),DC Scan Time (s),DC Number of Points,DC Squid Drift,DC Min V (V),DC Max V (V),DC Scans per Measure,Sample Resistance,He3 Temperature,Sorb Resistance,Sorb Temperature,Map 05,Map 06,Map 07,Map 08,Map 09,Map 10,Map 11,Map 12,Map 13,Map 14,Map 15,Map 16
,3878545817.51594,100.046863555908,69999.765625,-1.30749741127823E-4,1.19169923995296E-7,1,4,13.4005146026611,5.00697769505176,32.5199998915195,-0.162815873187717,-0.0244735336514805,1,-9.21121635183038E-8,,,,,,,,,,,,,,,,,,,,,100.046630859375,100.047096252441,69999.765625,69999.765625,53.480977357073,5.63345668608022,4.62348985671997,54,1,0,0,1,0.300521850585937,33.7243423461914,1,1,3,100.046630859375,0,100.046863555908,,,,,,,,,,,,,,,,,,,,,,,,,,,,,,,,,
,3878545971.36283,100.098651885986,49999.56640625,-9.2848048130619E-5,1.02822972553069E-7,1,4,13.4005146026611,5.00688422662553,32.5199998915195,-0.115606529153223,-0.0174409595649807,1,-1.15404452411185E-7,,,,,,,,,,,,,,,,,,,,,100.077514648438,100.119789123535,49999.56640625,49999.56640625,53.7353974400826,5.63545352886239,4.62501764297485,54,1,0,0,1,0.3009033203125,34.2131004333496,1,1,3,100.120399475098,0,100.098651885986,,,,,,,,,,,,,,,,,,,,,,,,,,,,,,,,,
,3878546130.97356,100.055732727051,29999.525390625,-5.51276516838745E-5,3.40094752507607E-8,1,4,13.4005146026611,5.00704965118651,32.5199998915195,-0.0686408605895206,-0.0103732281958181,1,-8.24474005483464E-8,,,,,,,,,,,,,,,,,,,,,100.038757324219,100.072708129883,29999.525390625,29999.525390625,53.8585039318615,5.63263252828068,4.6344723701477,54,1,0,0,1,0.298995971679687,34.2131004333496,1,1,3,100.072708129883,0,100.055732727051,,,,,,,,,,,,,,,,,,,,,,,,,,,,,,,,,
,3878546287.33033,100.100238800049,9999.7197265625,-1.74336192604297E-5,1.26786118221664E-8,1,4,13.4005146026611,5.00703036310252,32.5199998915195,-0.0217015908640866,-0.00331612562699811,1,-5.47420512674934E-8,,,,,,,,,,,,,,,,,,,,,100.080917358398,100.119560241699,9999.7197265625,9999.7197265625,53.9694951815922,5.6333410367367,4.63970851898193,54,1,0,0,1,0.30029296875,34.2131004333496,1,1,3,100.119560241699,0,100.100238800049,,,,,,,,,,,,,,,,,,,,,,,,,,,,,,,,,
,3878546374.14442,100.167068481445,8499.640625,-1.46136755236674E-5,1.65656231198981E-8,1,4,13.4005146026611,5.00675702345472,32.5199998915195,-0.018188379091769,-0.00278969138393553,1,-5.4055514522897E-8,,,,,,,,,,,,,,,,,,,,,100.161598205566,100.172538757324,8499.640625,8499.640625,53.8577223033422,5.6341488988711,4.6383581161499,54,1,0,0,1,0.299911499023438,34.7018585205078,1,1,3,100.172538757324,0,100.167068481445,,,,,,,,,,,,,,,,,,,,,,,,,,,,,,,,,
,3878546442.75822,100.197536468506,6499.65576171875,-1.08588476671399E-5,9.30740855584655E-9,1,4,13.4005146026611,5.00672684860149,32.5199998915195,-0.0135108091173383,-0.00210060981894245,1,-6.24242026842307E-8,,,,,,,,,,,,,,,,,,,,,100.18962097168,100.205451965332,6499.65576171875,6499.65576171875,53.9296321271115,5.63398350999253,4.64198637008667,54,1,0,0,1,0.30120849609375,34.7018585205078,1,1,3,100.205451965332,0,100.197536468506,,,,,,,,,,,,,,,,,,,,,,,,,,,,,,,,,
,3878546512.74931,100.277053833008,4499.70947265625,-7.14425814807568E-6,9.7423964296852E-9,1,4,13.4005146026611,5.00703120913325,32.5199998915195,-0.00888994028638806,-0.00138116917908336,1,-4.02812789795053E-8,,,,,,,,,,,,,,,,,,,,,100.27001953125,100.284088134766,4499.70947265625,4499.70947265625,53.8968037293038,5.63488422202293,4.64638233184814,53,1,68,0,0,0.298919677734375,34.2131004333496,1,1,3,100.284088134766,0,100.277053833008,,,,,,,,,,,,,,,,,,,,,,,,,,,,,,,,,
,3878546613.08524,100.10763168335,2999.81884765625,-4.41934936236442E-6,7.25927662453304E-9,1,4,13.4005146026611,5.00700054745833,32.5199998915195,-0.00550313624202154,-8.27783693510203E-4,1,-3.57225779015282E-9,,,,,,,,,,,,,,,,,,,,,100.107414245605,100.107849121094,2999.81884765625,2999.81884765625,54.0179561497846,5.63444010554803,4.64734792709351,54,1,0,0,1,0.299835205078125,34.7018585205078,1,1,3,100.107414245605,0,100.10763168335,,,,,,,,,,,,,,,,,,,,,,,,,,,,,,,,,
,3878546689.56875,100.062030792236,2799.57763671875,-4.13190586058831E-6,1.69821631595861E-8,1,4,13.4005146026611,5.00696242840741,32.5199998915195,-0.00517874734411285,-5.49319353058408E-4,1,1.77019841754328E-7,,,,,,,,,,,,,,,,,,,,,100.058403015137,100.065658569336,2799.57763671875,2799.57763671875,53.907746528573,5.63196334433983,4.64024305343628,52,1,68,0,0,0.299301147460937,34.2131004333496,1,1,3,100.058403015137,0,100.062030792236,,,,,,,,,,,,,,,,,,,,,,,,,,,,,,,,,
,3878546767.60071,100.169864654541,2599.68872070313,-3.80905212267655E-6,1.68484873532644E-8,1,4,13.4005146026611,5.00690971856198,32.5199998915195,-0.00477621584081841,-4.91754921930045E-4,1,1.74939701712977E-7,,,,,,,,,,,,,,,,,,,,,100.159797668457,100.179931640625,2599.68872070313,2599.68872070313,53.8952404722653,5.63235215361705,4.64947748184204,53,1,64,0,0,0.30731201171875,34.7018585205078,1,1,3,100.179931640625,0,100.169864654541,,,,,,,,,,,,,,,,,,,,,,,,,,,,,,,,,
,3878546840.81064,100.17834854126,2399.47265625,-3.42655863279124E-6,3.65713863496425E-8,1,4,13.4005146026611,5.00689720379689,32.5199998915195,-0.00429042443307928,-4.8357272466667E-4,1,1.24289842895938E-7,,,,,,,,,,,,,,,,,,,,,100.16431427002,100.1923828125,2399.47265625,2399.47265625,53.9409657406403,5.63134470880987,4.65014314651489,54,1,0,0,1,0.308074951171875,34.7018585205078,1,1,3,100.1923828125,0,100.17834854126,,,,,,,,,,,,,,,,,,,,,,,,,,,,,,,,,
,3878546901.43043,100.136680603027,2199.79736328125,-3.07999564587731E-6,1.80850679242923E-8,1,4,13.4005146026611,5.00692844257112,32.5199998915195,-0.00387275242977355,-3.26181122042945E-4,1,1.9883172434357E-7,,,,,,,,,,,,,,,,,,,,,100.130928039551,100.142433166504,2199.79736328125,2199.79736328125,53.8784354591019,5.63230086581391,4.64964532852173,53,1,64,0,0,0.30029296875,34.7018585205078,1,1,3,100.130928039551,0,100.136680603027,,,,,,,,,,,,,,,,,,,,,,,,,,,,,,,,,
,3878546959.86186,100.091773986816,1999.58129882813,-2.74199788938854E-6,1.80898909005758E-8,1,4,13.4005146026611,5.00698036352141,32.5199998915195,-0.00344841790984376,-2.86311703458147E-4,1,1.80286988166842E-7,,,,,,,,,,,,,,,,,,,,,100.090270996094,100.093276977539,1999.58129882813,1999.58129882813,53.8436529899961,5.63176490779406,4.65396404266357,54,1,0,0,1,0.300140380859375,34.7018585205078,1,1,3,100.093276977539,0,100.091773986816,,,,,,,,,,,,,,,,,,,,,,,,,,,,,,,,,
,3878547017.96101,100.210441589355,1799.60424804687,-2.40950255684952E-6,2.42726196475971E-8,1,4,13.4005146026611,5.0069877639128,32.5199998915195,-0.00303988305858079,-1.87320736001485E-4,1,2.10034580382691E-7,,,,,,,,,,,,,,,,,,,,,100.207275390625,100.213607788086,1799.60424804687,1799.60424804687,54.1371544989673,5.63234563621485,4.65470027923584,52,1,68,0,0,0.305709838867188,34.7018585205078,1,1,3,100.213607788086,0,100.210441589355,,,,,,,,,,,,,,,,,,,,,,,,,,,,,,,,,
,3878547097.15739,100.099597930908,1599.62731933594,-2.09984160497344E-6,2.34187061047487E-8,1,4,13.4005146026611,5.0069329057372,32.5199998915195,-0.00265118290257323,-1.49769939845664E-4,1,1.93861375814607E-7,,,,,,,,,,,,,,,,,,,,,100.098655700684,100.100540161133,1599.62731933594,1599.62731933594,53.892504772448,5.63237396251844,4.64717197418213,53,1,68,0,0,0.3009033203125,34.7018585205078,1,1,3,100.098655700684,0,100.099597930908,,,,,,,,,,,,,,,,,,,,,,,,,,,,,,,,,
,3878547171.06066,100.050018310547,1399.66296386719,-1.75893654166442E-6,3.2195051537491E-8,1,4,13.4005146026611,5.00691015425262,32.5199998915195,-0.0022317413060971,-5.20105920522527E-5,1,2.21362437523597E-7,,,,,,,,,,,,,,,,,,,,,100.04817199707,100.051864624023,1399.66296386719,1399.66296386719,53.7881573651307,5.63218031563989,4.6565842628479,54,1,0,0,1,0.298004150390625,34.2131004333496,1,1,3,100.04817199707,0,100.050018310547,,,,,,,,,,,,,,,,,,,,,,,,,,,,,,,,,
,3878547227.9906,100.12682723999,1199.54748535156,-1.4440013447024E-6,2.37478687647984E-8,1,4,13.4005146026611,5.00686894931769,32.5199998915195,-0.00183876492247686,1.65537189972237E-6,1,2.17342959693044E-7,,,,,,,,,,,,,,,,,,,,,100.12100982666,100.13264465332,1199.54748535156,1199.54748535156,53.7994909786595,5.63195814347126,4.64944267272949,54,1,0,0,1,0.308990478515625,34.7018585205078,1,1,3,100.13264465332,0,100.12682723999,,,,,,,,,,,,,,,,,,,,,,,,,,,,,,,,,
,3878547284.31138,100.233860015869,999.771789550781,-1.18447056901619E-6,4.67855873349123E-8,1,4,13.4005146026611,5.00697597570015,32.5199998915195,-0.00150910974846026,6.582036202165E-6,1,1.82474670683777E-7,,,,,,,,,,,,,,,,,,,,,100.223068237305,100.244651794434,999.771789550781,999.771789550781,53.8893782583711,5.63197855598091,4.65210199356079,54,1,0,0,1,0.298843383789063,34.2131004333496,1,1,3,100.244651794434,0,100.233860015869,,,,,,,,,,,,,,,,,,,,,,,,,,,,,,,,,
,3878547342.87631,100.162307739258,799.757019042969,-8.56421416592933E-7,2.28933172029188E-8,1,4,13.4005146026611,5.00693614850604,32.5199998915195,-0.00111241217924995,1.46979366976874E-4,1,2.46136490283776E-7,,,,,,,,,,,,,,,,,,,,,100.155830383301,100.168785095215,799.757019042969,799.757019042969,53.9554258682461,5.6314714255169,4.65484619140625,52,1,68,0,0,0.299148559570313,34.7018585205078,1,1,3,100.155830383301,0,100.162307739258,,,,,,,,,,,,,,,,,,,,,,,,,,,,,,,,,
,3878547433.70858,100.108898162842,600.006530761719,-5.48655714385157E-7,2.11827326696615E-8,1,4,13.4005146026611,5.00693374930943,32.5199998915195,-7.28072618399246E-4,1.97240132452545E-4,1,2.40455005089956E-7,,,,,,,,,,,,,,,,,,,,,100.104309082031,100.113487243652,600.006530761719,600.006530761719,53.9034475717172,5.63286100269507,4.6589822769165,53,1,68,0,0,0.299758911132812,34.2131004333496,1,1,3,100.104309082031,0,100.108898162842,,,,,,,,,,,,,,,,,,,,,,,,,,,,,,,,,
,3878547525.88855,100.141353607178,399.916259765625,-2.54271244506445E-7,2.28052503745529E-8,1,4,13.4005146026611,5.00701334440411,32.5199998915195,-3.62738677490546E-4,2.60604809093426E-4,1,2.47292692848999E-7,,,,,,,,,,,,,,,,,,,,,100.138374328613,100.144332885742,399.916259765625,399.916259765625,53.8526417179672,5.63308986694529,4.65367555618286,52,1,68,0,0,0.299072265625,34.7018585205078,1,1,3,100.138092041016,0,100.141353607178,,,,,,,,,,,,,,,,,,,,,,,,,,,,,,,,,
,3878547615.9789,100.155906677246,200.102905273438,-4.67314270080895E-8,2.78418791696171E-8,1,4,13.4005146026611,5.00689903668543,32.5199998915195,-1.1129839551438E-4,3.46264017514712E-4,1,2.85035820302219E-7,,,,,,,,,,,,,,,,,,,,,100.151252746582,100.16056060791,200.102905273438,200.102905273438,53.795973650323,5.63161302532387,4.66343069076538,53,1,68,0,0,0.298843383789063,34.2131004333496,1,1,3,100.16056060791,0,100.155906677246,,,,,,,,,,,,,,,,,,,,,,,,,,,,,,,,,
,3878547673.26506,100.247917175293,0.062941275537014,9.1712286544407E-8,2.67577504456745E-8,1,4,13.4005146026611,5.00695376613488,32.5199998915195,7.13022375163134E-5,3.0395335204217E-4,1,2.3034690044974E-7,,,,,,,,,,,,,,,,,,,,,100.247093200684,100.248741149902,0.062941275537014,0.062941275537014,53.7459494250922,5.63179217943926,4.65659666061401,54,1,0,0,1,0.2978515625,34.2131004333496,1,1,3,100.248741149902,0,100.247917175293,,,,,,,,,,,,,,,,,,,,,,,,,,,,,,,,,
,3878547738.5447,100.148345947266,-199.737838745117,2.69079868917209E-7,1.87929530984264E-8,1,4,13.4005146026611,5.00689831064194,32.5199998915195,2.99698818348103E-4,2.86771384127026E-4,10,1.90020702625084E-7,,,,,,,,,,,,,,,,,,,,,100.144981384277,100.151710510254,-199.737838745117,-199.737838745117,53.8327101907268,5.63225159658222,4.6634840965271,54,1,0,0,1,0.2984619140625,34.2131004333496,1,1,3,100.151832580566,0,100.148345947266,,,,,,,,,,,,,,,,,,,,,,,,,,,,,,,,,
,3878547820.83899,100.114688873291,-399.765197753906,4.22410996896544E-7,1.67292275329382E-8,1,4,13.4005146026611,5.00695314190902,32.5199998915195,4.85405250342628E-4,3.50451569785667E-4,1,2.18213296690221E-7,,,,,,,,,,,,,,,,,,,,,100.104286193848,100.125091552734,-399.765197753906,-399.765197753906,53.8647569600153,5.6313861117393,4.65621328353882,54,1,0,0,1,0.298004150390625,34.2131004333496,1,1,3,100.125091552734,0,100.114688873291,,,,,,,,,,,,,,,,,,,,,,,,,,,,,,,,,
,3878547895.65394,100.110446929932,-599.69189453125,6.21269378978507E-7,1.9540928529575E-8,1,4,13.4005146026611,5.00690522244164,32.5199998915195,7.34544962440705E-4,3.77485993593231E-4,1,2.10177293238328E-7,,,,,,,,,,,,,,,,,,,,,100.107940673828,100.112953186035,-599.69189453125,-599.69189453125,53.8026174927365,5.63166361762633,4.66298675537109,54,1,0,0,1,0.307693481445313,34.2131004333496,1,1,3,100.112953186035,0,100.110446929932,,,,,,,,,,,,,,,,,,,,,,,,,,,,,,,,,
,3878547969.70844,100.080856323242,-799.580749511719,8.701612155012E-7,3.23407721816086E-8,1,4,13.4005146026611,5.00693956136233,32.5199998915195,0.00104130415953297,4.45311434122399E-4,1,2.27403949947968E-7,,,,,,,,,,,,,,,,,,,,,100.077659606934,100.084053039551,-799.580749511719,-799.580749511719,53.8612396316788,5.63103338639828,4.65834903717041,54,1,0,0,1,0.30792236328125,34.2131004333496,1,1,3,100.077659606934,0,100.080856323242,,,,,,,,,,,,,,,,,,,,,,,,,,,,,,,,,
,3878548045.79196,100.082767486572,-999.759155273437,1.12711727901615E-6,4.37860180574912E-8,1,4,13.4005146026611,5.00693767140327,32.5199998915195,0.00136733032606088,4.52922817433931E-4,1,1.9507686071194E-7,,,,,,,,,,,,,,,,,,,,,100.073417663574,100.09211730957,-999.759155273437,-999.759155273437,53.8827344159576,5.63192617065308,4.66237831115723,52,1,68,0,0,0.305328369140625,34.2131004333496,1,1,3,100.09211730957,0,100.082767486572,,,,,,,,,,,,,,,,,,,,,,,,,,,,,,,,,
,3878548122.74957,100.087841033936,-1199.48449707031,1.42947627652531E-6,2.17015243647658E-8,1,4,13.4005146026611,5.00689117062948,32.5199998915195,0.00174604113254605,4.94632551409563E-4,1,1.83342936107886E-7,,,,,,,,,,,,,,,,,,,,,100.076805114746,100.098876953125,-1199.48449707031,-1199.48449707031,53.8522509037076,5.63214588000618,4.66840124130249,53,1,68,0,0,0.300369262695313,34.2131004333496,1,1,3,100.098876953125,0,100.087841033936,,,,,,,,,,,,,,,,,,,,,,,,,,,,,,,,,
,3878548206.60507,100.134777069092,-1399.58740234375,1.76992079881105E-6,1.42310440476096E-8,1,4,13.4005146026611,5.00697807293373,32.5199998915195,0.00216986401835985,5.59420866954269E-4,10,1.84427843849939E-7,,,,,,,,,,,,,,,,,,,,,100.131126403809,100.138427734375,-1399.58740234375,-1399.58740234375,53.8123878492269,5.632444300965,4.6599497795105,54,1,0,0,1,0.298843383789063,34.2131004333496,1,1,3,100.131126403809,0,100.134777069092,,,,,,,,,,,,,,,,,,,,,,,,,,,,,,,,,
,3878548299.37332,100.078483581543,-1599.60217285156,1.97564163232321E-6,9.00336338617776E-8,1,4,13.4005146026611,5.00694526909074,32.5199998915195,0.00242139165510674,6.2882997314881E-4,10,2.09391195049098E-7,,,,,,,,,,,,,,,,,,,,,100.07691192627,100.080055236816,-1599.60217285156,-1599.60217285156,53.8870333728134,5.63197379812394,4.65943431854248,54,1,0,0,1,0.300827026367188,33.7243423461914,1,1,3,100.080055236816,0,100.078483581543,,,,,,,,,,,,,,,,,,,,,,,,,,,,,,,,,
,3878548384.35617,100.048763275146,-1799.818359375,2.45746175377418E-6,4.49736698131491E-8,1,4,13.4005146026611,5.00692264790097,32.5199998915195,0.00303416304122674,6.33377173933318E-4,1,1.40968374911836E-7,,,,,,,,,,,,,,,,,,,,,100.048561096191,100.048965454102,-1799.818359375,-1799.818359375,53.8135602920057,5.63168404942181,4.66143751144409,54,1,0,0,1,0.298233032226562,34.2131004333496,1,1,3,100.048561096191,0,100.048763275146,,,,,,,,,,,,,,,,,,,,,,,,,,,,,,,,,
,3878548442.15713,100.082969665527,-1999.55615234375,2.77083370017797E-6,1.35451074999749E-8,1,4,13.4005146026611,5.00688544185225,32.5199998915195,0.0034255561104986,6.8394498178731E-4,1,1.34700530509723E-7,,,,,,,,,,,,,,,,,,,,,100.077781677246,100.088157653809,-1999.55615234375,-1999.55615234375,53.8346642620249,5.63164789941898,4.66239786148071,54,1,0,0,1,0.299453735351562,33.7243423461914,1,1,3,100.088157653809,0,100.082969665527,,,,,,,,,,,,,,,,,,,,,,,,,,,,,,,,,
,3878548501.56724,100.14966583252,-2199.62133789062,3.15004189302846E-6,5.70205385740527E-8,1,4,13.4005146026611,5.00689529473738,32.5199998915195,0.00391226723150759,6.57967226454254E-4,1,5.71120190327037E-8,,,,,,,,,,,,,,,,,,,,,100.149635314941,100.149696350098,-2199.62133789062,-2199.62133789062,53.8205949486788,5.63128997586392,4.66143274307251,54,1,0,0,1,0.300445556640625,34.2131004333496,1,1,3,100.149696350098,0,100.14966583252,,,,,,,,,,,,,,,,,,,,,,,,,,,,,,,,,
,3878548574.93217,100.122253417969,-2399.5478515625,3.48931750807356E-6,6.12842206685926E-9,1,4,13.4005146026611,5.00698225599897,32.5199998915195,0.00433409551857133,7.2649910676291E-4,1,6.13744958103022E-8,,,,,,,,,,,,,,,,,,,,,100.119667053223,100.124839782715,-2399.5478515625,-2399.5478515625,53.8921139581884,5.63242929951136,4.66522169113159,54,1,0,0,1,0.298385620117188,33.7243423461914,1,1,3,100.119667053223,0,100.122253417969,,,,,,,,,,,,,,,,,,,,,,,,,,,,,,,,,
,3878548635.94416,100.200092315674,-2599.75170898438,3.81857818407129E-6,7.84534831407284E-9,1,4,13.4005146026611,5.00694117242338,32.5199998915195,0.00473756753356926,8.31473606796418E-4,1,9.64178584878769E-8,,,,,,,,,,,,,,,,,,,,,100.19026184082,100.209922790527,-2599.75170898438,-2599.75170898438,53.8471703183326,5.63233242023836,4.66854667663574,54,1,0,0,1,0.29876708984375,34.2131004333496,1,1,3,100.209922790527,0,100.200092315674,,,,,,,,,,,,,,,,,,,,,,,,,,,,,,,,,
,3878548697.73703,100.145576477051,-2799.67822265625,4.18534527269994E-6,9.20430734640743E-9,1,4,13.4005146026611,5.00684717047455,32.5199998915195,0.00519142610471829,9.18259202707401E-4,1,1.11257894489035E-7,,,,,,,,,,,,,,,,,,,,,100.140403747559,100.150749206543,-2799.67822265625,-2799.67822265625,53.9374484123038,5.63221095668272,4.67002725601196,54,1,0,0,1,0.306854248046875,33.7243423461914,1,1,3,100.140403747559,0,100.145576477051,,,,,,,,,,,,,,,,,,,,,,,,,,,,,,,,,
,3878548759.5039,100.116970062256,-2999.68041992188,4.52657556843554E-6,1.24102714924828E-8,1,4,13.4005146026611,5.00685388069262,32.5199998915195,0.00561773952242024,9.72757722756958E-4,1,1.03972651239866E-7,,,,,,,,,,,,,,,,,,,,,100.107727050781,100.12621307373,-2999.68041992188,-2999.68041992188,53.6584070309384,5.63248919279137,4.6618800163269,54,1,0,0,1,0.308303833007812,34.2131004333496,1,1,3,100.12621307373,0,100.116970062256,,,,,,,,,,,,,,,,,,,,,,,,,,,,,,,,,
,3878548838.60742,100.099082946777,-4499.646484375,7.33500944049088E-6,9.08887350192406E-9,1,4,13.4005146026611,5.00684694092795,32.5199998915195,0.0091371289395904,0.00134913810628837,1,-1.39177500134543E-8,,,,,,,,,,,,,,,,,,,,,100.085250854492,100.112915039062,-4499.646484375,-4499.646484375,53.836618333323,5.63229551916585,4.66154289245605,54,1,0,0,1,0.299453735351562,33.7243423461914,1,1,3,100.113754272461,0,100.099082946777,,,,,,,,,,,,,,,,,,,,,,,,,,,,,,,,,
,3878548906.35193,100.148765563965,-6499.52978515625,1.1041903466682E-5,9.89691419559963E-9,1,4,13.4005146026611,5.00682027127599,32.5199998915195,0.0137561870123543,0.00202071416230251,1,-2.91603084083681E-8,,,,,,,,,,,,,,,,,,,,,100.142623901367,100.154907226562,-6499.52978515625,-6499.52978515625,53.8045715640345,5.63136914612822,4.66398525238037,54,1,0,0,1,0.299530029296875,33.7243423461914,1,1,3,100.154907226562,0,100.148765563965,,,,,,,,,,,,,,,,,,,,,,,,,,,,,,,,,
,3878548971.94511,100.179695129395,-8499.5517578125,1.47942318943727E-5,1.37823560810417E-8,1,4,13.4005146026611,5.00675741091223,32.5199998915195,0.0184294926876361,0.00271460457935588,1,-3.32508706202972E-8,,,,,,,,,,,,,,,,,,,,,100.177810668945,100.181579589844,-8499.5517578125,-8499.5517578125,53.8553774177845,5.63158092786343,4.66492319107056,54,1,0,0,1,0.301361083984375,34.2131004333496,1,1,3,100.181579589844,0,100.179695129395,,,,,,,,,,,,,,,,,,,,,,,,,,,,,,,,,
,3878549053.4896,100.283256530762,-9999.8330078125,1.76005194614421E-5,1.89810245569048E-8,1,4,13.4005146026611,5.00676661200712,32.5199998915195,0.0219203738217796,0.00326315129128162,1,-1.25683053328804E-8,,,,,,,,,,,,,,,,,,,,,100.282981872559,100.283531188965,-9999.8330078125,-9999.8330078125,53.8424805472172,5.63175903118368,4.67071628570557,54,1,0,0,1,0.300369262695313,33.7243423461914,1,1,3,100.282981872559,0,100.283256530762,,,,,,,,,,,,,,,,,,,,,,,,,,,,,,,,,
,3878549210.53142,100.170650482178,-29999.61328125,5.53033252507479E-5,3.89906987195098E-8,1,4,13.4005146026611,5.00682840263013,32.5199998915195,0.0688799185516098,0.0102413569263978,1,-4.921057461944E-8,,,,,,,,,,,,,,,,,,,,,100.161651611328,100.179649353027,-29999.61328125,-29999.61328125,53.7608003669576,5.63297990480841,4.66644954681396,54,1,0,0,1,0.298080444335937,34.2131004333496,1,1,3,100.179946899414,0,100.170650482178,,,,,,,,,,,,,,,,,,,,,,,,,,,,,,,,,
,3878549370.99194,100.049293518066,-49999.62890625,9.31081262924931E-5,8.32945307921823E-8,1,4,13.4005146026611,5.00676041096336,32.5199998915195,0.115955345489305,0.0172953714244264,1,-3.99271848528684E-8,,,,,,,,,,,,,,,,,,,,,100.046936035156,100.051651000977,-49999.62890625,-49999.62890625,53.7455586108326,5.63153984524851,4.66417503356934,54,1,0,0,1,0.300674438476562,34.2131004333496,1,1,3,100.046936035156,0,100.049293518066,,,,,,,,,,,,,,,,,,,,,,,,,,,,,,,,,
,3878549530.75929,100.054565429688,-69999.5390625,1.30937525056383E-4,1.64212341637934E-7,1,4,13.4005146026611,5.00683339354139,32.5199998915195,0.163046250183402,0.024486914235093,1,7.55572540602729E-8,,,,,,,,,,,,,,,,,,,,,100.052726745605,100.05640411377,-69999.5390625,-69999.5390625,53.6900629859672,5.63205789724769,4.66623544692993,54,1,0,0,1,0.297775268554687,34.2131004333496,1,1,3,100.052726745605,0,100.054565429688,,,,,,,,,,,,,,,,,,,,,,,,,,,,,,,,,
,3878549690.46558,100.038196563721,-49999.6015625,9.29984445777339E-5,6.15302783127821E-8,1,4,13.4005146026611,5.0068093414072,32.5199998915195,0.11579613297981,0.017436998725506,1,9.00183307127225E-8,,,,,,,,,,,,,,,,,,,,,100.020835876465,100.055557250977,-49999.6015625,-49999.6015625,53.7439953537942,5.63210251815149,4.67023277282715,54,1,0,0,1,0.299530029296875,33.7243423461914,1,1,3,100.055557250977,0,100.038196563721,,,,,,,,,,,,,,,,,,,,,,,,,,,,,,,,,
,3878549852.55157,100.159809112549,-29999.6875,5.51948466225417E-5,3.38922628064517E-8,1,4,13.4005146026611,5.00674403947475,32.5199998915195,0.0687238445441881,0.01035034598303,1,5.47313379239231E-8,,,,,,,,,,,,,,,,,,,,,100.149208068848,100.17041015625,-29999.6875,-29999.6875,53.841698918698,5.63114124926057,4.67374277114868,54,1,0,0,1,0.308074951171875,34.7018585205078,1,1,3,100.17041015625,0,100.159809112549,,,,,,,,,,,,,,,,,,,,,,,,,,,,,,,,,
,3878550009.75957,100.059181213379,-10000.185546875,1.74524580252185E-5,1.35720652006653E-8,1,4,13.4005146026611,5.00683210519803,32.5199998915195,0.0217222467175438,0.00333016944875169,1,6.33484887586858E-8,,,,,,,,,,,,,,,,,,,,,100.050216674805,100.068145751953,-10000.185546875,-10000.185546875,53.8862517442942,5.63179718742,4.67450618743897,54,1,0,0,1,0.29998779296875,34.2131004333496,1,1,3,100.068145751953,0,100.059181213379,,,,,,,,,,,,,,,,,,,,,,,,,,,,,,,,,
,3878550093.8707,100.094802856445,-8499.98046875,1.46399323501159E-5,1.25043313701547E-8,1,4,13.4005146026611,5.00684522189177,32.5199998915195,0.0182224335281897,0.00278858180569926,1,4.91814975974131E-8,,,,,,,,,,,,,,,,,,,,,100.083854675293,100.105751037598,-8499.98046875,-8499.98046875,53.8377907761019,5.63159561612878,4.67480945587158,52,1,68,0,0,0.299911499023438,34.2131004333496,1,1,3,100.105751037598,0,100.094802856445,,,,,,,,,,,,,,,,,,,,,,,,,,,,,,,,,
,3878550159.84746,100.088043212891,-6499.9326171875,1.08943796001044E-5,1.19879508880956E-8,1,4,13.4005146026611,5.00683228271675,32.5199998915195,0.0135565860425429,0.00209973577402739,1,5.63573256648747E-8,,,,,,,,,,,,,,,,,,,,,100.085861206055,100.090225219727,-6499.9326171875,-6499.9326171875,53.7318801117461,5.63103928318166,4.67502737045288,53,1,68,0,0,0.305862426757812,34.7018585205078,1,1,3,100.085861206055,0,100.088043212891,,,,,,,,,,,,,,,,,,,,,,,,,,,,,,,,,
,3878550222.68596,100.177673339844,-4500.06201171875,7.16441273850535E-6,8.9076478627297E-9,1,4,13.4005146026611,5.00684209485892,32.5199998915195,0.00891315725874207,0.0013942950858034,1,4.78649214200747E-8,,,,,,,,,,,,,,,,,,,,,100.17455291748,100.180793762207,-4500.06201171875,-4500.06201171875,53.7572830386211,5.63128831879139,4.67604637145996,54,1,0,0,1,0.300216674804687,34.7018585205078,1,1,3,100.17455291748,0,100.177673339844,,,,,,,,,,,,,,,,,,,,,,,,,,,,,,,,,
,3878550302.18781,100.098804473877,-3000.13354492188,4.44406461092932E-6,6.58294045243668E-9,1,4,13.4005146026611,5.00687025098558,32.5199998915195,0.0055342210574478,8.28974896194161E-4,1,8.55716991197098E-10,,,,,,,,,,,,,,,,,,,,,100.098526000977,100.099082946777,-3000.13354492188,-3000.13354492188,53.9112638569095,5.63144194674497,4.6751446723938,54,1,0,0,1,0.298919677734375,34.2131004333496,1,1,3,100.098342895508,0,100.098804473877,,,,,,,,,,,,,,,,,,,,,,,,,,,,,,,,,
,3878550357.44646,100.035388946533,-2800.11889648438,4.18508490227892E-6,1.59276978533379E-8,1,4,13.4005146026611,5.00680844026535,32.5199998915195,0.0052432825119857,5.69009966213655E-4,1,-1.69144450881889E-7,,,,,,,,,,,,,,,,,,,,,100.033737182617,100.037040710449,-2800.11889648438,-2800.11889648438,53.8307561194288,5.63116385406352,4.66830968856812,53,1,68,0,0,0.301284790039063,34.2131004333496,1,1,3,100.033737182617,0,100.035388946533,,,,,,,,,,,,,,,,,,,,,,,,,,,,,,,,,
,3878550414.72613,100.082824707031,-2600.15454101562,3.81417597146057E-6,1.86257599190633E-8,1,4,13.4005146026611,5.00686837096906,32.5199998915195,0.0047848971351908,4.76957864520651E-4,1,-1.87583567771146E-7,,,,,,,,,,,,,,,,,,,,,100.082328796387,100.083320617676,-2600.15454101562,-2600.15454101562,53.9605064536211,5.63205783505872,4.64616918563843,54,1,0,0,1,0.308914184570313,34.7018585205078,1,1,3,100.083320617676,0,100.082824707031,,,,,,,,,,,,,,,,,,,,,,,,,,,,,,,,,
,3878550471.92696,100.111213684082,-2400.27807617187,3.43465361049139E-6,2.32438341225274E-8,1,4,13.4005146026611,5.00686403361166,32.5199998915195,0.00431471014905146,3.89855444356546E-4,1,-2.00751585479571E-7,,,,,,,,,,,,,,,,,,,,,100.096733093262,100.125694274902,-2400.27807617187,-2400.27807617187,53.7123393987653,5.6317769217332,4.64968538284302,54,1,0,0,1,0.30029296875,34.7018585205078,1,1,3,100.125694274902,0,100.111213684082,,,,,,,,,,,,,,,,,,,,,,,,,,,,,,,,,
,3878550528.72107,100.163734436035,-2200.25073242187,3.10778334956887E-6,1.67098808652803E-8,1,4,13.4005146026611,5.00687585459838,32.5199998915195,0.00390870436835063,3.21970637021223E-4,1,-2.06365729386867E-7,,,,,,,,,,,,,,,,,,,,,100.162101745605,100.165367126465,-2200.25073242187,-2200.25073242187,53.8131694777461,5.63209222661838,4.66010332107544,54,1,0,0,1,0.305709838867188,34.7018585205078,1,1,3,100.162101745605,0,100.163734436035,,,,,,,,,,,,,,,,,,,,,,,,,,,,,,,,,
,3878550585.49082,100.137084960938,-2000.21069335938,2.78439157469365E-6,2.29231651557396E-8,1,4,13.4005146026611,5.00680162169495,32.5199998915195,0.00350552481830081,2.64211298441733E-4,1,-2.04364142381746E-7,,,,,,,,,,,,,,,,,,,,,100.12865447998,100.145515441895,-2000.21069335938,-2000.21069335938,53.7768237516018,5.6315402923206,4.65996837615967,54,1,0,0,1,0.300216674804687,34.7018585205078,1,1,3,100.145515441895,0,100.137084960938,,,,,,,,,,,,,,,,,,,,,,,,,,,,,,,,,
,3878550641.17653,100.252742767334,-1799.98193359375,2.42161975988211E-6,2.03428795919516E-8,1,4,13.4005146026611,5.00677303248831,32.5199998915195,0.00305453077414004,1.91302734175102E-4,1,-2.08640620396285E-7,,,,,,,,,,,,,,,,,,,,,100.246543884277,100.258941650391,-1799.98193359375,-1799.98193359375,53.877263016323,5.63178125823908,4.6545991897583,54,1,0,0,1,0.300445556640625,34.2131004333496,1,1,3,100.258941650391,0,100.252742767334,,,,,,,,,,,,,,,,,,,,,,,,,,,,,,,,,
,3878550697.90827,100.196632385254,-1599.904296875,2.10203662109038E-6,2.14013985375114E-8,1,4,13.4005146026611,5.00684633320784,32.5199998915195,0.00265669769694999,1.31154725857045E-4,1,-2.09134801979102E-7,,,,,,,,,,,,,,,,,,,,,100.193946838379,100.199317932129,-1599.904296875,-1599.904296875,53.8733548737269,5.63194699693524,4.65828037261963,54,1,0,0,1,0.300979614257812,34.7018585205078,1,1,3,100.199317932129,0,100.196632385254,,,,,,,,,,,,,,,,,,,,,,,,,,,,,,,,,
,3878550754.50178,100.145412445068,-1400.02795410156,1.76868103228231E-6,1.90975009241463E-8,1,4,13.4005146026611,5.00684542595305,32.5199998915195,0.00224064375937256,7.51651236868746E-5,1,-2.04226360238703E-7,,,,,,,,,,,,,,,,,,,,,100.140892028809,100.149932861328,-1400.02795410156,-1400.02795410156,53.8436529899961,5.63234212220977,4.66208124160767,54,1,0,0,1,0.29998779296875,34.7018585205078,1,1,3,100.149932861328,0,100.145412445068,,,,,,,,,,,,,,,,,,,,,,,,,,,,,,,,,
,3878550811.37853,100.211818695068,-1200.02575683594,1.46083151963647E-6,2.1217404099411E-8,1,4,13.4005146026611,5.00684995626337,32.5199998915195,0.00186489975005176,-3.31830086399978E-5,1,-2.45177248586507E-7,,,,,,,,,,,,,,,,,,,,,100.206672668457,100.21696472168,-1200.02575683594,-1200.02575683594,53.8694467311307,5.63220061618352,4.6662712097168,52,1,68,0,0,0.299606323242188,34.2131004333496,1,1,3,100.206672668457,0,100.211818695068,,,,,,,,,,,,,,,,,,,,,,,,,,,,,,,,,
,3878550870.01586,100.244869232178,-1000.02355957031,1.15697091351784E-6,2.1769718534084E-8,1,4,13.4005146026611,5.00683862145877,32.5199998915195,0.00147812041974284,-3.38629384130892E-5,1,-2.00267640700492E-7,,,,,,,,,,,,,,,,,,,,,100.24040222168,100.249336242676,-1000.02355957031,-1000.02355957031,53.8604580031595,5.63188613200885,4.66256856918335,54,1,0,0,1,0.299224853515625,34.2131004333496,1,1,3,100.24040222168,0,100.244869232178,,,,,,,,,,,,,,,,,,,,,,,,,,,,,,,,,
,3878550926.28915,100.135303497314,-800.059143066406,8.31514001408297E-7,2.26063414765436E-8,1,4,13.4005146026611,5.00683302066564,32.5199998915195,0.0010797262118082,-1.40678898017089E-4,1,-2.3735461250944E-7,,,,,,,,,,,,,,,,,,,,,100.132423400879,100.13818359375,-800.059143066406,-800.059143066406,53.8030083069961,5.63168100798499,4.66141033172607,53,1,68,0,0,0.300369262695313,34.7018585205078,1,1,3,100.13818359375,0,100.135303497314,,,,,,,,,,,,,,,,,,,,,,,,,,,,,,,,,
,3878550984.53135,100.161819458008,-599.956176757812,5.28764331067037E-7,2.70105502465124E-8,1,4,13.4005146026611,5.00684795061286,32.5199998915195,7.00282657223809E-4,-1.80879419110615E-4,1,-2.24345563117106E-7,,,,,,,,,,,,,,,,,,,,,100.157608032227,100.166030883789,-599.956176757812,-599.956176757812,53.795973650323,5.63213468297989,4.66768074035645,54,1,0,0,1,0.300369262695313,34.2131004333496,1,1,3,100.157608032227,0,100.161819458008,,,,,,,,,,,,,,,,,,,,,,,,,,,,,,,,,
,3878551059.27652,100.080303192139,-400.130279541016,2.82563214287044E-7,2.44661455064698E-8,1,4,13.4005146026611,5.00680925510442,32.5199998915195,3.96206273968953E-4,-2.43659057159079E-4,1,-2.37929382780575E-7,,,,,,,,,,,,,,,,,,,,,100.07878112793,100.081825256348,-400.130279541016,-400.130279541016,53.8209857629384,5.6319812999843,4.66041994094849,53,1,68,0,0,0.30029296875,34.7018585205078,1,1,3,100.07878112793,0,100.080303192139,,,,,,,,,,,,,,,,,,,,,,,,,,,,,,,,,
,3878551115.55269,100.192253112793,-200.102905273438,7.33559242592415E-8,2.53958763428733E-8,1,4,13.4005146026611,5.00681894047654,32.5199998915195,1.34425159508391E-4,-2.74268979102379E-4,1,-2.31212613585743E-7,,,,,,,,,,,,,,,,,,,,,100.179710388184,100.204795837402,-200.102905273438,-200.102905273438,53.9796563523422,5.63143713123796,4.66495418548584,53,1,68,0,0,0.300216674804687,34.2131004333496,1,1,3,100.204795837402,0,100.192253112793,,,,,,,,,,,,,,,,,,,,,,,,,,,,,,,,,
,3878551171.7519,100.19539642334,-0.0251765102148056,-1.1244047984022E-7,2.809188136063E-8,1,4,13.4005146026611,5.00686088035729,32.5199998915195,-1.0184225053549E-4,-2.76199849276847E-4,1,-2.04966514488011E-7,,,,,,,,,,,,,,,,,,,,,100.188331604004,100.202461242676,-0.0251765102148056,-0.0251765102148056,54.0081857932942,5.6325786187125,4.65990018844604,54,1,0,0,1,0.2996826171875,34.7018585205078,1,1,3,100.188331604004,0,100.19539642334,,,,,,,,,,,,,,,,,,,,,,,,,,,,,,,,,
,3878551229.10894,100.139457702637,199.83854675293,-2.51372616842107E-7,2.93395907382302E-8,1,4,13.4005146026611,5.00687022965824,32.5199998915195,-2.72967138163839E-4,-3.14739991289328E-4,1,-2.15129978830001E-7,,,,,,,,,,,,,,,,,,,,,100.13062286377,100.148292541504,199.83854675293,199.83854675293,53.841698918698,5.63216231572775,4.66804933547974,54,1,0,0,1,0.300521850585937,34.2131004333496,1,1,3,100.148292541504,0,100.139457702637,,,,,,,,,,,,,,,,,,,,,,,,,,,,,,,,,
,3878551289.23416,100.201755523682,399.752624511719,-4.06387608784479E-7,1.74586072916326E-8,1,4,13.4005146026611,5.00691864514959,32.5199998915195,-4.74496276922839E-4,-2.86962113397911E-4,1,-1.6963215498008E-7,,,,,,,,,,,,,,,,,,,,,100.19645690918,100.207054138184,399.752624511719,399.752624511719,53.8065256353326,5.63272075430679,4.66529321670532,53,1,68,0,0,0.2984619140625,34.7018585205078,1,1,3,100.19645690918,0,100.201755523682,,,,,,,,,,,,,,,,,,,,,,,,,,,,,,,,,
,3878551372.05882,100.061729431152,599.931030273437,-3.45061256077652E-7,7.92751766316602E-7,1,4,13.4005146026611,5.00691345017858,32.5199998915195,-2.50879700598442E-4,-0.00125981978068355,10,-9.59994275267227E-7,,,,,,,,,,,,,,,,,,,,,100.05850982666,100.064949035645,599.931030273437,599.931030273437,53.8545957892653,5.63106147653313,4.66221904754639,54,1,0,0,1,0.301284790039063,34.2131004333496,1,1,3,100.064949035645,0,100.061729431152,,,,,,,,,,,,,,,,,,,,,,,,,,,,,,,,,
,3878551438.71082,100.0749168396,799.757019042969,-8.53447040893008E-7,2.47141304059544E-8,1,4,13.4005146026611,5.00684715213474,32.5199998915195,-0.00102942889141361,-3.82248364777624E-4,1,-1.79274031487021E-7,,,,,,,,,,,,,,,,,,,,,100.062454223633,100.087379455566,799.757019042969,799.757019042969,53.8639753314961,5.63181961772758,4.67250871658325,53,1,64,0,0,0.300064086914063,34.2131004333496,1,1,3,100.087379455566,0,100.0749168396,,,,,,,,,,,,,,,,,,,,,,,,,,,,,,,,,
,3878551496.72602,100.183170318604,999.796936035156,-1.13632568545076E-6,3.34273615115179E-8,1,4,13.4005146026611,5.00692301571848,32.5199998915195,-0.0013760826786983,-4.72751101902676E-4,1,-2.09622552165258E-7,,,,,,,,,,,,,,,,,,,,,100.180679321289,100.185661315918,999.796936035156,999.796936035156,53.9339310839672,5.63222714307476,4.66521787643433,54,1,0,0,1,0.301437377929687,34.2131004333496,1,1,3,100.185661315918,0,100.183170318604,,,,,,,,,,,,,,,,,,,,,,,,,,,,,,,,,
,3878551554.50779,100.130123138428,1199.63562011719,-1.43401610382952E-6,1.66984540903422E-8,1,4,13.4005146026611,5.00691676390121,32.5199998915195,-0.00175578345592856,-4.68233833727867E-4,1,-1.61463277307294E-7,,,,,,,,,,,,,,,,,,,,,100.12548828125,100.134757995605,1199.63562011719,1199.63562011719,53.7662717665922,5.63278044985423,4.67234516143799,53,1,68,0,0,0.299224853515625,34.2131004333496,1,1,3,100.134757995605,0,100.130123138428,,,,,,,,,,,,,,,,,,,,,,,,,,,,,,,,,
,3878551612.14103,100.108253479004,1399.73840332031,-1.75538938340009E-6,1.32898700027697E-8,1,4,13.4005146026611,5.00689006431724,32.5199998915195,-0.00215605528137923,-5.27679622116197E-4,1,-1.61124859867175E-7,,,,,,,,,,,,,,,,,,,,,100.106246948242,100.110260009766,1399.73840332031,1399.73840332031,53.8448254327749,5.63185069838519,4.67442035675049,52,1,68,0,0,0.299911499023438,34.2131004333496,1,1,3,100.106246948242,0,100.108253479004,,,,,,,,,,,,,,,,,,,,,,,,,,,,,,,,,
,3878551687.26596,100.090713500977,1599.69030761719,-2.07427575401105E-6,1.34276749973722E-8,1,4,13.4005146026611,5.00693820997062,32.5199998915195,-0.00255403473237654,-5.81611227857613E-4,1,-1.56721566182973E-7,,,,,,,,,,,,,,,,,,,,,100.085067749023,100.09635925293,1599.69030761719,1599.69030761719,53.7752604945634,5.63265583667246,4.66368341445923,53,1,68,0,0,0.305633544921875,34.2131004333496,1,1,3,100.085067749023,0,100.090713500977,,,,,,,,,,,,,,,,,,,,,,,,,,,,,,,,,
,3878551744.98148,100.138656616211,1799.73022460938,-2.42282364852638E-6,4.0404627153609E-8,1,4,13.4005146026611,5.00689932616484,32.5199998915195,-0.00298796147110872,-6.47276351465681E-4,1,-1.57314175147889E-7,,,,,,,,,,,,,,,,,,,,,100.134223937988,100.143089294434,1799.73022460938,1799.73022460938,53.8209857629384,5.63186903302644,4.66771650314331,53,1,68,0,0,0.299758911132812,34.7018585205078,1,1,3,100.134223937988,0,100.138656616211,,,,,,,,,,,,,,,,,,,,,,,,,,,,,,,,,
,3878551820.08386,100.133186340332,1999.97155761719,-2.75495054348535E-6,7.49485063272493E-9,1,4,13.4005146026611,5.0069394885963,32.5199998915195,-0.00340726259215604,-6.71402757230597E-4,1,-1.26997150865535E-7,,,,,,,,,,,,,,,,,,,,,100.123336791992,100.143035888672,1999.97155761719,1999.97155761719,53.8663202170538,5.63302655590659,4.66509437561035,52,1,68,0,0,0.299453735351562,34.2131004333496,1,1,3,100.143035888672,0,100.133186340332,,,,,,,,,,,,,,,,,,,,,,,,,,,,,,,,,
,3878551877.61657,100.147918701172,2199.82275390625,-3.10137241412992E-6,7.25981464880673E-9,1,4,13.4005146026611,5.00688547771909,32.5199998915195,-0.00384047052037419,-7.23604641051153E-4,1,-1.17100232497745E-7,,,,,,,,,,,,,,,,,,,,,100.144660949707,100.151176452637,2199.82275390625,2199.82275390625,53.836618333323,5.6322636801721,4.67125701904297,54,1,0,0,1,0.298843383789063,34.2131004333496,1,1,3,100.151176452637,0,100.147918701172,,,,,,,,,,,,,,,,,,,,,,,,,,,,,,,,,
,3878551936.19027,100.139156341553,2400.03881835938,-3.46310614976174E-6,8.0025578810213E-9,1,4,13.4005146026611,5.00689054197232,32.5199998915195,-0.00429378746050826,-7.72099379025774E-4,1,-1.01926949721554E-7,,,,,,,,,,,,,,,,,,,,,100.135536193848,100.142776489258,2400.03881835938,2400.03881835938,53.8530325322269,5.63301806050899,4.67401790618897,54,1,0,0,1,0.298995971679687,34.2131004333496,1,1,3,100.142776489258,0,100.139156341553,,,,,,,,,,,,,,,,,,,,,,,,,,,,,,,,,
,3878551993.76888,100.183917999268,2599.87744140625,-3.81946456113837E-6,1.31096782948495E-8,1,4,13.4005146026611,5.00696022254387,32.5199998915195,-0.00473780429583662,-8.37608027388093E-4,1,-1.01207479139657E-7,,,,,,,,,,,,,,,,,,,,,100.180717468262,100.187118530273,2599.87744140625,2599.87744140625,53.8592855603807,5.63154055674519,4.66912937164307,54,1,0,0,1,0.298309326171875,34.7018585205078,1,1,3,100.180717468262,0,100.183917999268,,,,,,,,,,,,,,,,,,,,,,,,,,,,,,,,,
,3878552051.56785,100.174854278564,2800.04345703125,-4.1724845403312E-6,1.06686269576699E-8,1,4,13.4005146026611,5.00685185728676,32.5199998915195,-0.00517995015573178,-8.85561229712673E-4,1,-8.69244622553602E-8,,,,,,,,,,,,,,,,,,,,,100.172584533691,100.177124023438,2800.04345703125,2800.04345703125,53.7584554813999,5.6317539936142,4.67398929595947,54,1,0,0,1,0.2984619140625,34.7018585205078,1,1,3,100.177124023438,0,100.174854278564,,,,,,,,,,,,,,,,,,,,,,,,,,,,,,,,,
,3878552109.18063,100.1442527771,2999.74340820313,-4.52616801063032E-6,1.47722534682426E-8,1,4,13.4005146026611,5.00693976322422,32.5199998915195,-0.00562077352227677,-9.49931154980536E-4,1,-8.56856873659544E-8,,,,,,,,,,,,,,,,,,,,,100.142135620117,100.146369934082,2999.74340820313,2999.74340820313,53.9456555117557,5.63283605247828,4.66569137573242,54,1,0,0,1,0.299224853515625,34.2131004333496,1,1,3,100.142135620117,0,100.1442527771,,,,,,,,,,,,,,,,,,,,,,,,,,,,,,,,,
,3878552186.72722,100.221408843994,4499.7470703125,-7.31169700067128E-6,8.98777083889161E-9,1,4,13.4005146026611,5.00692427766652,32.5199998915195,-0.00910976130550312,-0.0013350145511698,1,2.17946801204332E-8,,,,,,,,,,,,,,,,,,,,,100.221351623535,100.221466064453,4499.7470703125,4499.7470703125,53.8956312865249,5.63181757342597,4.67233228683472,54,1,0,0,1,0.306930541992188,34.2131004333496,1,1,3,100.221466064453,0,100.221408843994,,,,,,,,,,,,,,,,,,,,,,,,,,,,,,,,,
,3878552251.2758,100.233871459961,6499.6181640625,-1.10455330573348E-5,1.86235115758477E-8,1,4,13.4005146026611,5.00680882414727,32.5199998915195,-0.0137608292580512,-0.00202027279096003,1,3.00525101978531E-8,,,,,,,,,,,,,,,,,,,,,100.23006439209,100.237678527832,6499.6181640625,6499.6181640625,53.8788262733615,5.6311527972516,4.67389678955078,54,1,0,0,1,0.301055908203125,34.2131004333496,1,1,3,100.23006439209,0,100.233871459961,,,,,,,,,,,,,,,,,,,,,,,,,,,,,,,,,
,3878552317.26881,100.1379737854,8500.1181640625,-1.47955880811836E-5,1.45907331722669E-8,1,4,13.4005146026611,5.00681913819467,32.5199998915195,-0.0184344741711955,-0.00269501723340578,1,4.92200309308724E-8,,,,,,,,,,,,,,,,,,,,,100.134315490723,100.141632080078,8500.1181640625,8500.1181640625,53.8573314890826,5.63112642356294,4.6653037071228,54,1,0,0,1,0.298385620117188,33.7243423461914,1,1,3,100.134315490723,0,100.1379737854,,,,,,,,,,,,,,,,,,,,,,,,,,,,,,,,,
,3878552393.50566,100.175903320312,10000.1103515625,-1.75852549508201E-5,1.39310686568705E-8,1,4,13.4005146026611,5.00690471509022,32.5199998915195,-0.0219019470057122,-0.00326218741331921,1,1.11598502778352E-8,,,,,,,,,,,,,,,,,,,,,100.175392150879,100.176414489746,10000.1103515625,10000.1103515625,53.9612880821403,5.63149352925418,4.66627931594849,54,1,0,0,1,0.298233032226562,33.7243423461914,1,1,3,100.175392150879,0,100.175903320312,,,,,,,,,,,,,,,,,,,,,,,,,,,,,,,,,
,3878552547.28392,100.107719421387,30000.3671875,-5.52927332415304E-5,3.74668972970827E-8,1,4,13.4005146026611,5.00689238686282,32.5199998915195,-0.0688692542949922,-0.0102309038045823,1,5.61667214795774E-8,,,,,,,,,,,,,,,,,,,,,100.102478027344,100.11296081543,30000.3671875,30000.3671875,53.6931895000441,5.63256499278784,4.67217254638672,54,1,0,0,1,0.299835205078125,34.2131004333496,1,1,3,100.102478027344,0,100.107719421387,,,,,,,,,,,,,,,,,,,,,,,,,,,,,,,,,
,3878552704.48272,100.006996154785,50000.26953125,-9.30536317678758E-5,7.75320131866797E-8,1,4,13.4005146026611,5.00684367245506,32.5199998915195,-0.115884749081999,-0.0173219092826747,1,1.07881717257139E-8,,,,,,,,,,,,,,,,,,,,,100.006553649902,100.007438659668,50000.26953125,50000.26953125,53.7307076689672,5.63202744906785,4.66580247879028,54,1,0,0,1,0.299072265625,34.2131004333496,1,1,3,100.006553649902,0,100.006996154785,,,,,,,,,,,,,,,,,,,,,,,,,,,,,,,,,
,3878552862.92289,100.053115844727,70000.21875,-1.30932999837992E-4,1.672907877834E-7,1,4,13.4005146026611,5.00690255297598,32.5199998915195,-0.163059206375976,-0.0243833102501628,1,7.33794752142115E-9,,,,,,,,,,,,,,,,,,,,,100.039863586426,100.066368103027,70000.21875,70000.21875,53.6287051472076,5.63152064281398,4.66914892196655,54,1,0,0,1,0.306015014648438,34.2131004333496,1,1,3,100.066368103027,0,100.053115844727,,,,,,,,,,,,,,,,,,,,,,,,,,,,,,,,,