File: SQUID/22157b_LCOT/LCOT_MH_5K_FC+1T_2.csv
Comment,Time Stamp (sec),Temperature (K),Magnetic Field (Oe),Moment (emu),M. Std. Err. (emu),Transport Action,Averaging Time (sec),Frequency (Hz),Peak Amplitude (mm),Center Position (mm),Lockin Signal' (V),Lockin Signal (V),Range,M. Quad. Signal (emu),AC Moment (emu),AC M. Std Err. (emu),AC Phase (deg),AC Phase Std. Err. (deg),AC Susceptibility (emu/Oe),AC Suscept. Std Err. (emu/Oe),AC X' (emu/Oe),AC X' Std Err. (emu/Oe),AC X'' (emu/Oe),AC X'' Std Err. (emu/Oe),AC Drive (Oe),AC Frequency (Hz),AC Averaging Time (sec),AC Cycles,AC Range,AC Measure Type,AC Signal' (V),AC Signal'' (V),AC Trim Coil Ratio,AC Trim Coil Phase,Min. Temperature (K),Max. Temperature (K),Min. Field (Oe),Max. Field (Oe),Mass (grams),Motor Lag (deg),Pressure (Torr),Measure Count,Measurement Number,SQUID Status (code),Motor Status (code),Measure Status (code),Motor Current (amps),Motor Temp. (C),Temp. Status (code),Field Status (code),Chamber Status (code),Chamber Temp (K),Redirection State,Average Temp (K),Rotation Angle (deg),Rotator state,DC Moment Fixed Ctr (emu),DC Moment Err Fixed Ctr (emu),DC Moment Free Ctr (emu),DC Moment Err Free Ctr (emu),DC Fixed Fit,DC Free Fit,DC Calculated Center (mm),DC Calculated Center Err (mm),DC Scan Length (mm),DC Scan Time (s),DC Number of Points,DC Squid Drift,DC Min V (V),DC Max V (V),DC Scans per Measure,Sample Resistance,He3 Temperature,Sorb Resistance,Sorb Temperature,Map 05,Map 06,Map 07,Map 08,Map 09,Map 10,Map 11,Map 12,Map 13,Map 14,Map 15,Map 16
,3878537977.77239,4.99959087371826,70000.203125,-1.23543461553401E-4,1.72752886831902E-7,1,4,13.4005146026611,5.00750737180338,32.490000128746,-0.15387620430866,-0.0230533159179439,1,-2.70004575658156E-8,,,,,,,,,,,,,,,,,,,,,4.99952554702759,4.99965620040894,70000.203125,70000.203125,54.9039320763327,5.63948100217312,2.77746987342834,54,1,0,0,1,0.298690795898438,32.7468223571777,1,1,3,4.99973773956299,0,4.99959087371826,,,,,,,,,,,,,,,,,,,,,,,,,,,,,,,,,
,3878538135.12825,4.99983549118042,50000.30859375,-8.65032747035214E-5,9.74740472563375E-8,1,4,13.4005146026611,5.00745083158578,32.490000128746,-0.107717969797385,-0.0162892970709996,1,-1.37702063693725E-7,,,,,,,,,,,,,,,,,,,,,4.99972009658814,4.99995088577271,50000.30859375,50000.30859375,54.5420380719289,5.6386481450882,2.78560996055603,54,1,0,0,1,0.300521850585937,33.7243423461914,1,1,3,4.99995088577271,0,4.99983549118042,,,,,,,,,,,,,,,,,,,,,,,,,,,,,,,,,
,3878538289.67513,4.99985098838806,29999.638671875,-5.03561549131009E-5,3.70933470888033E-8,1,4,13.4005146026611,5.00735356118826,32.490000128746,-0.0627087544973295,-0.00945154215558899,1,-5.55203708680441E-8,,,,,,,,,,,,,,,,,,,,,4.99970769882202,4.9999942779541,29999.638671875,29999.638671875,54.1301198422942,5.63803706480677,2.78378105163574,52,1,68,0,0,0.306930541992188,34.2131004333496,1,1,3,4.9999942779541,0,4.99985098838806,,,,,,,,,,,,,,,,,,,,,,,,,,,,,,,,,
,3878538446.16931,5.00023794174194,9999.794921875,-1.52481742269549E-5,2.29993629340888E-8,1,4,13.4005146026611,5.00733130439412,32.490000128746,-0.018978825789535,-0.0029266709739349,1,-6.87586475753793E-8,,,,,,,,,,,,,,,,,,,,,5.00018644332886,5.00028944015503,9999.794921875,9999.794921875,53.9507360971307,5.63695676301043,2.79011011123657,54,1,0,0,1,0.298004150390625,34.2131004333496,1,1,3,5.00018644332886,0,5.00023794174194,,,,,,,,,,,,,,,,,,,,,,,,,,,,,,,,,
,3878538527.63191,4.9998893737793,8499.58984375,-1.26602926116253E-5,2.12196797513683E-8,1,4,13.4005146026611,5.00732120789692,32.490000128746,-0.0157577186791882,-0.00243011948617561,1,-5.72196270857752E-8,,,,,,,,,,,,,,,,,,,,,4.99984550476074,4.99993324279785,8499.58984375,8499.58984375,54.0453131479576,5.63595284386977,2.78984093666077,54,1,0,0,1,0.299758911132812,33.7243423461914,1,1,3,4.99984550476074,0,4.9998893737793,,,,,,,,,,,,,,,,,,,,,,,,,,,,,,,,,
,3878538593.54546,5.00004506111145,6499.56787109375,-9.24679963177564E-6,1.89862754106828E-8,1,4,13.4005146026611,5.00729205656148,32.490000128746,-0.0115087520121117,-0.00177653535502774,1,-4.31118472317169E-8,,,,,,,,,,,,,,,,,,,,,4.99986791610718,5.00022220611572,6499.56787109375,6499.56787109375,53.8526417179672,5.63596177456331,2.79034566879272,52,1,68,0,0,0.298995971679687,34.2131004333496,1,1,3,5.00022220611572,0,5.00004506111145,,,,,,,,,,,,,,,,,,,,,,,,,,,,,,,,,
,3878538661.36818,4.99997973442078,4499.533203125,-5.87699863100094E-6,1.37333984118056E-8,1,4,13.4005146026611,5.00724667595345,32.490000128746,-0.00731179288972555,-0.0011474474916375,1,-4.21318062605959E-8,,,,,,,,,,,,,,,,,,,,,4.9999623298645,4.99999713897705,4499.533203125,4499.533203125,53.8987578006019,5.63720003469221,2.78840684890747,53,1,64,0,0,0.298538208007812,35.6793746948242,1,1,3,4.9999623298645,0,4.99997973442078,,,,,,,,,,,,,,,,,,,,,,,,,,,,,,,,,
,3878538741.83545,4.99996638298035,2999.59228515625,-3.41334298856341E-6,9.88468983263463E-9,1,4,13.4005146026611,5.00725027915735,32.490000128746,-0.00425278999810578,-6.25533400348201E-4,1,8.36991252872304E-9,,,,,,,,,,,,,,,,,,,,,4.99993753433228,4.99999523162842,2999.59228515625,2999.59228515625,53.7666625808518,5.6366178773495,2.78900527954102,54,1,0,0,1,0.299301147460937,34.2131004333496,1,1,3,4.99999523162842,0,4.99996638298035,,,,,,,,,,,,,,,,,,,,,,,,,,,,,,,,,
,3878538815.37314,5.00011944770813,2799.75390625,-3.19832055796994E-6,1.87438009066978E-8,1,4,13.4005146026611,5.00721939454438,32.490000128746,-0.0040205523016333,-3.47478326660726E-4,1,1.99453854739122E-7,,,,,,,,,,,,,,,,,,,,,5.00008964538574,5.00014925003052,2799.75390625,2799.75390625,53.8245030912749,5.63759236950748,2.79003024101257,54,1,0,0,1,0.299072265625,34.2131004333496,1,1,3,5.00008964538574,0,5.00011944770813,,,,,,,,,,,,,,,,,,,,,,,,,,,,,,,,,
,3878538872.62767,5.00001740455627,2599.57543945313,-2.86699974096662E-6,1.91751450551232E-8,1,4,13.4005146026611,5.00728172841212,32.490000128746,-0.003603160964701,-3.17881759902715E-4,1,1.73658239557671E-7,,,,,,,,,,,,,,,,,,,,,4.99999809265137,5.00003671646118,2599.57543945313,2599.57543945313,53.7744788660441,5.6363753883253,2.78033876419067,54,1,0,0,1,0.2996826171875,34.2131004333496,1,1,3,5.00003671646118,0,5.00001740455627,,,,,,,,,,,,,,,,,,,,,,,,,,,,,,,,,
,3878538930.59028,4.99987554550171,2399.91284179687,-2.56952471334358E-6,1.84366200248596E-8,1,4,13.4005146026611,5.00727019767799,32.490000128746,-0.00323991383720846,-2.1389815709741E-4,1,2.12645689404308E-7,,,,,,,,,,,,,,,,,,,,,4.99981641769409,4.99993467330933,2399.91284179687,2399.91284179687,53.8448254327749,5.63614956861182,2.78645968437195,54,1,0,0,1,0.29876708984375,34.2131004333496,1,1,3,4.99993467330933,0,4.99987554550171,,,,,,,,,,,,,,,,,,,,,,,,,,,,,,,,,
,3878538987.76877,5.00008320808411,2199.873046875,-2.2738522636611E-6,1.95902861970111E-8,1,4,13.4005146026611,5.00724691223462,32.490000128746,-0.00287019157693276,-1.6849571025929E-4,1,2.04867774321445E-7,,,,,,,,,,,,,,,,,,,,,4.9998025894165,5.00036382675171,2199.873046875,2199.873046875,53.7662717665922,5.63683859120719,2.77962350845337,54,1,0,0,1,0.298843383789063,34.2131004333496,1,1,3,5.00036382675171,0,5.00008320808411,,,,,,,,,,,,,,,,,,,,,,,,,,,,,,,,,
,3878539045.68594,5.00010108947754,1999.90856933594,-1.93322294257408E-6,1.83879252758473E-8,1,4,13.4005146026611,5.00721626762278,32.490000128746,-0.00244232606860284,-1.29095303708065E-4,1,1.85545732804837E-7,,,,,,,,,,,,,,,,,,,,,5.00004005432129,5.00016212463379,1999.90856933594,1999.90856933594,53.7905022506884,5.63584106675725,2.78577995300293,54,1,0,0,1,0.300064086914063,34.2131004333496,1,1,3,5.00004005432129,0,5.00010108947754,,,,,,,,,,,,,,,,,,,,,,,,,,,,,,,,,
,3878539119.36896,4.99986338615417,1799.60424804687,-1.6436396335595E-6,2.10881173224961E-8,1,4,13.4005146026611,5.00720115139869,32.490000128746,-0.00208642266973361,-4.3252055887854E-5,1,2.11150510013308E-7,,,,,,,,,,,,,,,,,,,,,4.99969673156738,5.00003004074097,1799.60424804687,1799.60424804687,53.7225005695153,5.6370328261243,2.77427530288696,54,1,0,0,1,0.306167602539063,34.2131004333496,1,1,3,4.99969673156738,0,4.99986338615417,,,,,,,,,,,,,,,,,,,,,,,,,,,,,,,,,
,3878539176.04264,5.00014185905457,1599.57690429687,-1.34540254370283E-6,1.78655450136895E-8,1,4,13.4005146026611,5.00721954278525,32.490000128746,-0.0017132426508435,6.32909937551499E-7,1,2.01772107203826E-7,,,,,,,,,,,,,,,,,,,,,5.00004100799561,5.00024271011353,1599.57690429687,1599.57690429687,53.8155143633038,5.63722074299981,2.76646995544434,54,1,0,0,1,0.298843383789063,34.2131004333496,1,1,3,5.00024271011353,0,5.00014185905457,,,,,,,,,,,,,,,,,,,,,,,,,,,,,,,,,
,3878539233.21059,4.99992871284485,1399.78881835938,-1.06062651300792E-6,2.0066319360074E-8,1,4,13.4005146026611,5.00725062626885,32.490000128746,-0.00135838505261775,5.24126588671965E-5,1,2.00745683856949E-7,,,,,,,,,,,,,,,,,,,,,4.9998893737793,4.9999680519104,1399.78881835938,1399.78881835938,53.7951920218038,5.63638035649272,2.76564955711365,54,1,0,0,1,0.298919677734375,34.2131004333496,1,1,3,4.9999680519104,0,4.99992871284485,,,,,,,,,,,,,,,,,,,,,,,,,,,,,,,,,
,3878539316.45368,4.99996471405029,1199.84948730469,-7.99822889119863E-7,2.57119912981678E-8,1,4,13.4005146026611,5.00716726374589,32.490000128746,-0.00104647153583239,1.87467790220772E-4,10,2.70171277738925E-7,,,,,,,,,,,,,,,,,,,,,4.99994802474976,4.99998140335083,1199.84948730469,1199.84948730469,53.8866425585538,5.63760362170693,2.76636743545532,54,1,0,0,1,0.299072265625,34.2131004333496,1,1,3,4.99998140335083,0,4.99996471405029,,,,,,,,,,,,,,,,,,,,,,,,,,,,,,,,,
,3878539400.35701,4.9998767375946,1000.07391357422,-5.0513515326725E-7,2.2296772015149E-8,1,4,13.4005146026611,5.00722125144299,32.490000128746,-6.72543149355636E-4,1.96108597290567E-4,1,2.33023359661535E-7,,,,,,,,,,,,,,,,,,,,,4.99985027313232,4.99990320205688,1000.07391357422,1000.07391357422,53.8944588437461,5.63653003842701,2.76370906829834,53,1,68,0,0,0.299758911132812,33.7243423461914,1,1,3,4.99990320205688,0,4.9998767375946,,,,,,,,,,,,,,,,,,,,,,,,,,,,,,,,,
,3878539458.59996,4.99993371963501,799.996215820312,-2.70475234423584E-7,2.19826435039836E-8,1,4,13.4005146026611,5.00720542798083,32.490000128746,-3.77208214655421E-4,2.19287267113377E-4,1,2.16530927000078E-7,,,,,,,,,,,,,,,,,,,,,4.99953079223633,5.00033664703369,799.996215820312,799.996215820312,53.8245030912749,5.63652871853436,2.76193857192993,54,1,0,0,1,0.30059814453125,34.2131004333496,1,1,3,5.00033664703369,0,4.99993371963501,,,,,,,,,,,,,,,,,,,,,,,,,,,,,,,,,
,3878539524.2147,4.99965476989746,600.069519042969,-3.90295030256907E-8,2.4879083984296E-8,1,4,13.4005146026611,5.00715977026985,32.490000128746,-9.85484953610787E-5,3.26562223819941E-4,10,2.68044310900285E-7,,,,,,,,,,,,,,,,,,,,,4.99952507019043,4.99978446960449,600.069519042969,600.069519042969,53.9034475717172,5.63534595668489,2.76136231422424,54,1,0,0,1,0.299148559570313,34.2131004333496,1,1,3,4.99978446960449,0,4.99965476989746,,,,,,,,,,,,,,,,,,,,,,,,,,,,,,,,,
,3878539614.41746,5.00013947486877,400.130279541016,1.71420332737481E-7,2.3211653697373E-8,1,4,13.4005146026611,5.00716051242117,32.490000128746,1.68791018864304E-4,3.30768100149172E-4,10,2.39939269570517E-7,,,,,,,,,,,,,,,,,,,,,5.00007438659668,5.00020456314087,400.130279541016,400.130279541016,53.7471218678711,5.63643209193154,2.75605058670044,54,1,0,0,1,0.2984619140625,34.2131004333496,1,1,3,5.00020456314087,0,5.00013947486877,,,,,,,,,,,,,,,,,,,,,,,,,,,,,,,,,
,3878539706.48117,4.99989008903503,200.304306030273,3.97769170968781E-7,2.1762132595225E-8,1,4,13.4005146026611,5.00725587574412,32.490000128746,4.48605753367883E-4,3.86999483154062E-4,10,2.51220309918521E-7,,,,,,,,,,,,,,,,,,,,,4.99987888336182,4.99990129470825,200.304306030273,200.304306030273,53.8131694777461,5.63632234228675,2.75412607192993,54,1,0,0,1,0.299224853515625,34.2131004333496,1,1,3,4.99987888336182,0,4.99989008903503,,,,,,,,,,,,,,,,,,,,,,,,,,,,,,,,,
,3878539795.69299,4.99996399879456,0.276941627264023,5.65403446811457E-7,2.61355037305618E-8,1,4,13.4005146026611,5.00718754247441,32.490000128746,6.61000075199127E-4,3.94009645946056E-4,10,2.31777790222194E-7,,,,,,,,,,,,,,,,,,,,,4.999924659729,5.00000333786011,0.276941627264023,0.276941627264023,53.7733064232653,5.63651053750715,2.7316529750824,54,1,0,0,1,0.29937744140625,34.2131004333496,1,1,3,4.999924659729,0,4.99996399879456,,,,,,,,,,,,,,,,,,,,,,,,,,,,,,,,,
,3878539878.2022,4.99996995925903,-199.851135253906,7.08851474706137E-7,1.69045593351012E-8,1,4,13.4005146026611,5.00723245907508,32.490000128746,8.40016346418285E-4,4.18414336012176E-4,1,2.29909676765376E-7,,,,,,,,,,,,,,,,,,,,,4.99993944168091,5.00000047683716,-199.851135253906,-199.851135253906,53.9046200144961,5.63599617598272,2.73178029060364,54,1,0,0,1,0.301437377929687,34.2131004333496,1,1,3,5.00000047683716,0,4.99996995925903,,,,,,,,,,,,,,,,,,,,,,,,,,,,,,,,,
,3878539936.04404,4.9999041557312,-399.828155517578,8.47917117524512E-7,1.94868303258916E-8,1,4,13.4005146026611,5.00721716149739,32.490000128746,0.00102010683212978,3.98244212537409E-4,1,1.92912863713237E-7,,,,,,,,,,,,,,,,,,,,,4.99978542327881,5.00002288818359,-399.828155517578,-399.828155517578,53.8964129150442,5.63538909905506,2.73760724067688,54,1,0,0,1,0.299911499023438,33.7243423461914,1,1,3,4.99978542327881,0,4.9999041557312,,,,,,,,,,,,,,,,,,,,,,,,,,,,,,,,,
,3878540010.23345,4.99998903274536,-599.654113769531,1.02687645204301E-6,1.7925497312646E-8,1,4,13.4005146026611,5.00727492893105,32.490000128746,0.0012401438524861,4.50780310545434E-4,1,2.08317805781747E-7,,,,,,,,,,,,,,,,,,,,,4.99983930587769,5.00013875961304,-599.654113769531,-599.654113769531,53.8495152038903,5.63492021039411,2.73466730117798,54,1,0,0,1,0.298614501953125,34.2131004333496,1,1,3,4.99983930587769,0,4.99998903274536,,,,,,,,,,,,,,,,,,,,,,,,,,,,,,,,,
,3878540067.96445,5.00017714500427,-799.656311035156,1.17579457351572E-6,2.46292427425905E-8,1,4,13.4005146026611,5.00731326117244,32.490000128746,0.00142461399097726,4.85350266918202E-4,1,2.13792672421445E-7,,,,,,,,,,,,,,,,,,,,,5.00016498565674,5.00018930435181,-799.656311035156,-799.656311035156,53.7819043369768,5.6355314274439,2.73201513290405,54,1,0,0,1,0.2984619140625,33.7243423461914,1,1,3,5.00016498565674,0,5.00017714500427,,,,,,,,,,,,,,,,,,,,,,,,,,,,,,,,,
,3878540125.68337,5.00008606910706,-999.63330078125,1.38173844807678E-6,3.25328183356198E-8,1,4,13.4005146026611,5.00719484635851,32.490000128746,0.00168690261691486,4.84652288377917E-4,1,1.82437199299715E-7,,,,,,,,,,,,,,,,,,,,,4.99985694885254,5.00031518936157,-999.63330078125,-999.63330078125,53.8909415154095,5.63585737396488,2.73659753799438,53,1,68,0,0,0.298538208007812,34.2131004333496,1,1,3,5.00031518936157,0,5.00008606910706,,,,,,,,,,,,,,,,,,,,,,,,,,,,,,,,,
,3878540208.56419,4.99975395202637,-1199.62292480469,1.6427314836919E-6,2.02133381270679E-8,1,4,13.4005146026611,5.00725600129044,32.490000128746,0.00200772963966144,5.61780676713037E-4,10,2.05314432547548E-7,,,,,,,,,,,,,,,,,,,,,4.99972343444824,4.99978446960449,-1199.62292480469,-1199.62292480469,53.9054016430153,5.63594800359552,2.73411917686462,54,1,0,0,1,0.299148559570313,33.7243423461914,1,1,3,4.99972343444824,0,4.99975395202637,,,,,,,,,,,,,,,,,,,,,,,,,,,,,,,,,
,3878540291.39008,4.99983310699463,-1399.59997558594,1.89180977571741E-6,1.90843634995996E-8,1,4,13.4005146026611,5.00725559627497,32.490000128746,0.00232778924071259,5.42417774633914E-4,1,1.52507317460336E-7,,,,,,,,,,,,,,,,,,,,,4.99976062774658,4.99990558624268,-1399.59997558594,-1399.59997558594,53.9050108287557,5.63651215514764,2.73044800758362,53,1,68,0,0,0.300216674804687,33.7243423461914,1,1,3,4.99990558624268,0,4.99983310699463,,,,,,,,,,,,,,,,,,,,,,,,,,,,,,,,,
,3878540383.70955,4.99991488456726,-1599.72802734375,2.17714865985151E-6,1.26483820828497E-8,1,4,13.4005146026611,5.00722287417008,32.490000128746,0.00268310646117379,5.95849530364861E-4,1,1.52727417863761E-7,,,,,,,,,,,,,,,,,,,,,4.99977970123291,5.00005006790161,-1599.72802734375,-1599.72802734375,53.7983185358807,5.63494025824119,2.73082065582275,52,1,68,0,0,0.298080444335937,34.2131004333496,1,1,3,4.99977970123291,0,4.99991488456726,,,,,,,,,,,,,,,,,,,,,,,,,,,,,,,,,
,3878540443.71792,4.99992609024048,-1799.8056640625,2.46818015536641E-6,1.08344038019843E-8,1,4,13.4005146026611,5.00721658249561,32.490000128746,0.00304762579089067,6.36332785390807E-4,1,1.4169633547198E-7,,,,,,,,,,,,,,,,,,,,,4.99985361099243,4.99999856948853,-1799.8056640625,-1799.8056640625,53.9526901684288,5.63526639038412,2.72821283340454,54,1,0,0,1,0.2984619140625,33.7243423461914,1,1,3,4.99985361099243,0,4.99992609024048,,,,,,,,,,,,,,,,,,,,,,,,,,,,,,,,,
,3878540502.07493,5.00002861022949,-1999.73229980469,2.75969174809818E-6,8.56580903561535E-9,1,4,13.4005146026611,5.00726575773478,32.490000128746,0.00341444340622584,6.65894142558368E-4,1,1.21815901712454E-7,,,,,,,,,,,,,,,,,,,,,4.99999523162842,5.00006198883057,-1999.73229980469,-1999.73229980469,53.8534233464865,5.634578985496,2.72992539405823,54,1,0,0,1,0.297775268554687,34.2131004333496,1,1,3,4.99999523162842,0,5.00002861022949,,,,,,,,,,,,,,,,,,,,,,,,,,,,,,,,,
,3878540584.91975,4.99983334541321,-2199.72192382813,3.05357864046615E-6,1.1846652537489E-8,1,4,13.4005146026611,5.00723416316998,32.490000128746,0.00378053589784923,7.20003773122521E-4,10,1.2130214779967E-7,,,,,,,,,,,,,,,,,,,,,4.99972200393677,4.99994468688965,-2199.72192382813,-2199.72192382813,53.8788262733615,5.63530479487379,2.72597241401672,54,1,0,0,1,0.299148559570313,33.7243423461914,1,1,3,4.99994468688965,0,4.99983334541321,,,,,,,,,,,,,,,,,,,,,,,,,,,,,,,,,
,3878540650.6496,4.99997115135193,-2399.52270507813,3.19196838876987E-6,1.39984735163972E-7,1,4,13.4005146026611,5.00722279668081,32.490000128746,0.00394386020278071,8.06103631096037E-4,1,1.69732441678536E-7,,,,,,,,,,,,,,,,,,,,,4.99991798400879,5.00002431869507,-2399.52270507813,-2399.52270507813,53.8936772152268,5.63509797520628,2.71867275238037,54,1,0,0,1,0.301055908203125,34.2131004333496,1,1,3,5.00002431869507,0,4.99997115135193,,,,,,,,,,,,,,,,,,,,,,,,,,,,,,,,,
,3878540709.7885,5.00006675720215,-2599.55029296875,3.66835799155139E-6,6.73825044129298E-8,1,4,13.4005146026611,5.0072759726149,32.490000128746,0.00456202701879168,7.29272746180413E-4,1,3.67702656576205E-8,,,,,,,,,,,,,,,,,,,,,4.99988746643066,5.00024604797363,-2599.55029296875,-2599.55029296875,53.9409657406403,5.63593024943118,2.72449374198914,54,1,0,0,1,0.298919677734375,33.7243423461914,1,1,3,5.00024604797363,0,5.00006675720215,,,,,,,,,,,,,,,,,,,,,,,,,,,,,,,,,
,3878540769.45014,5.00025010108948,-2799.53979492187,3.99780776911439E-6,1.30569538045443E-8,1,4,13.4005146026611,5.0072400993395,32.490000128746,0.00496008008126156,8.72343160751809E-4,1,1.02365043136952E-7,,,,,,,,,,,,,,,,,,,,,5.00005578994751,5.00044441223145,-2799.53979492187,-2799.53979492187,54.0163928927461,5.63510414031202,2.7216649055481,54,1,0,0,1,0.299758911132812,34.7018585205078,1,1,3,5.00044441223145,0,5.00025010108948,,,,,,,,,,,,,,,,,,,,,,,,,,,,,,,,,
,3878540830.19658,5.00006365776062,-2999.61743164063,4.30351088744192E-6,1.47807213339815E-8,1,4,13.4005146026611,5.00724950743234,32.490000128746,0.00534429904076536,9.06168802400753E-4,1,8.37907516470203E-8,,,,,,,,,,,,,,,,,,,,,4.99995422363281,5.00017309188843,-2999.61743164063,-2999.61743164063,53.9093097856115,5.63552836793399,2.72516369819641,54,1,0,0,1,0.298690795898438,34.2131004333496,1,1,3,4.99995422363281,0,5.00006365776062,,,,,,,,,,,,,,,,,,,,,,,,,,,,,,,,,
,3878540952.76513,5.00000858306885,-4499.81005859375,6.80875535324306E-6,1.66139659912362E-8,1,4,13.4005146026611,5.00726696429068,32.490000128746,0.00848240479907034,0.00125363173471582,1,-1.20027991801957E-8,,,,,,,,,,,,,,,,,,,,,4.99998664855957,5.00003051757812,-4499.81005859375,-4499.81005859375,53.9093097856115,5.63494119583971,2.70824456214905,54,1,0,0,1,0.299301147460937,34.2131004333496,1,1,3,5.00003051757812,0,5.00000858306885,,,,,,,,,,,,,,,,,,,,,,,,,,,,,,,,,
,3878541018.55716,5.00000500679016,-6499.4794921875,1.01407250330872E-5,1.97217551337149E-8,1,4,13.4005146026611,5.00728429132799,32.490000128746,0.0126341370963185,0.00186261075556364,1,-2.15009056666048E-8,,,,,,,,,,,,,,,,,,,,,4.99994039535522,5.0000696182251,-6499.4794921875,-6499.4794921875,53.882343601698,5.63639476758439,2.70519518852234,54,1,0,0,1,0.299148559570313,33.7243423461914,1,1,3,4.99994039535522,0,5.00000500679016,,,,,,,,,,,,,,,,,,,,,,,,,,,,,,,,,
,3878541084.94479,4.99994707107544,-8499.615234375,1.35580945581417E-5,2.13966875833636E-8,1,4,13.4005146026611,5.00722928512179,32.490000128746,0.0168947656480175,0.00246852316335788,1,-4.6201179322455E-8,,,,,,,,,,,,,,,,,,,,,4.99988651275635,5.00000762939453,-8499.615234375,-8499.615234375,54.0136571929288,5.63623928848002,2.70369124412537,54,1,0,0,1,0.298919677734375,34.2131004333496,1,1,3,5.00000762939453,0,4.99994707107544,,,,,,,,,,,,,,,,,,,,,,,,,,,,,,,,,
,3878541166.63026,5.00001764297485,-9999.4931640625,1.61177291080721E-5,1.76381537416233E-8,1,4,13.4005146026611,5.00725014292741,32.490000128746,0.0200760664602759,0.00299060004369838,1,-9.93906176316027E-9,,,,,,,,,,,,,,,,,,,,,4.99984741210937,5.00018787384033,-9999.4931640625,-9999.4931640625,53.9288504985922,5.6355464973024,2.6994936466217,54,1,0,0,1,0.2984619140625,33.7243423461914,1,1,3,4.99984741210937,0,5.00001764297485,,,,,,,,,,,,,,,,,,,,,,,,,,,,,,,,,
,3878541324.54717,4.99985241889954,-29999.701171875,5.12072467085007E-5,3.87655021193926E-8,1,4,13.4005146026611,5.00726799260324,32.490000128746,0.0637847444301337,0.00949310675725447,1,-3.82440936056806E-8,,,,,,,,,,,,,,,,,,,,,4.99968767166138,5.0000171661377,-29999.701171875,-29999.701171875,54.2645599476019,5.63606056568902,2.70476722717285,54,1,0,0,1,0.305709838867188,33.7243423461914,1,1,3,5.0000171661377,0,4.99985241889954,,,,,,,,,,,,,,,,,,,,,,,,,,,,,,,,,
,3878541482.65509,5.00001573562622,-49999.6796875,8.72493441871477E-5,7.59341369797743E-8,1,4,13.4005146026611,5.00731803362704,32.490000128746,0.108664097493844,0.016288033971019,1,2.55653796623056E-8,,,,,,,,,,,,,,,,,,,,,4.99999380111694,5.0000376701355,-49999.6796875,-49999.6796875,54.6061316105058,5.63725136756066,2.69674062728882,53,1,68,0,0,0.298919677734375,34.2131004333496,1,1,3,5.0000376701355,0,5.00001573562622,,,,,,,,,,,,,,,,,,,,,,,,,,,,,,,,,
,3878541642.79017,5.00002384185791,-69999.6015625,1.23796832900872E-4,1.76036697080278E-7,1,4,13.4005146026611,5.0074051256242,32.490000128746,0.154181324709768,0.02314043466448,1,5.95711875495634E-8,,,,,,,,,,,,,,,,,,,,,4.99996614456177,5.00008153915405,-69999.6015625,-69999.6015625,54.9785775999193,5.6394594628433,2.69679403305054,54,1,0,0,1,0.304183959960937,34.2131004333496,1,1,3,4.99996614456177,0,5.00002384185791,,,,,,,,,,,,,,,,,,,,,,,,,,,,,,,,,
,3878541804.54424,5.00002121925354,-49999.578125,8.67200270939079E-5,9.07376745074845E-8,1,4,13.4005146026611,5.00733688313355,32.490000128746,0.107985074202179,0.0163253880681011,1,1.34670282665405E-7,,,,,,,,,,,,,,,,,,,,,4.99997520446777,5.00006723403931,-49999.578125,-49999.578125,54.5514176141596,5.63721465809558,2.69728875160217,53,1,68,0,0,0.305404663085937,34.2131004333496,1,1,3,5.00006723403931,0,5.00002121925354,,,,,,,,,,,,,,,,,,,,,,,,,,,,,,,,,
,3878541979.89433,5.00001549720764,-29999.712890625,5.04715555836514E-5,4.1930617092261E-8,1,4,13.4005146026611,5.00732582761666,32.490000128746,0.0628487618977419,0.00949462010162227,1,7.29027518179162E-8,,,,,,,,,,,,,,,,,,,,,4.99999237060547,5.00003862380981,-29999.712890625,-29999.712890625,54.2203979362654,5.63804372075628,2.68799090385437,54,1,0,0,1,0.300521850585937,34.2131004333496,1,1,3,5.00013208389282,0,5.00001549720764,,,,,,,,,,,,,,,,,,,,,,,,,,,,,,,,,
,3878542137.69014,5.00005531311035,-10000.1982421875,1.53677239135702E-5,2.53162466083954E-8,1,4,13.4005146026611,5.00731089866331,32.490000128746,0.019127186181713,0.00295180345149245,1,7.10668387995805E-8,,,,,,,,,,,,,,,,,,,,,4.99999237060547,5.00011825561523,-10000.1982421875,-10000.1982421875,53.9163444422846,5.63714634569902,2.69408273696899,54,1,0,0,1,0.299072265625,34.7018585205078,1,1,3,5.00011825561523,0,5.00005531311035,,,,,,,,,,,,,,,,,,,,,,,,,,,,,,,,,
,3878542216.27557,4.99995398521423,-8499.98046875,1.27855625297505E-5,2.28219623939968E-8,1,4,13.4005146026611,5.00726438446188,32.490000128746,0.0159129725033873,0.00245687851806266,1,5.99959018784423E-8,,,,,,,,,,,,,,,,,,,,,4.99989223480225,5.00001573562622,-8499.98046875,-8499.98046875,53.811215406448,5.63519768422969,2.68662214279175,52,1,68,0,0,0.301132202148438,34.2131004333496,1,1,3,5.00001573562622,0,4.99995398521423,,,,,,,,,,,,,,,,,,,,,,,,,,,,,,,,,
,3878542282.58657,5.00012063980103,-6500.02099609375,9.37909913099107E-6,1.7318929479896E-8,1,4,13.4005146026611,5.00722878311457,32.490000128746,0.0116690389390061,0.00182979344816587,1,6.61074086458071E-8,,,,,,,,,,,,,,,,,,,,,5.00005626678467,5.00018501281738,-6500.02099609375,-6500.02099609375,53.9417473691596,5.63556992987122,2.68365836143494,54,1,0,0,1,0.297927856445313,34.7018585205078,1,1,3,5.00005626678467,0,5.00012063980103,,,,,,,,,,,,,,,,,,,,,,,,,,,,,,,,,
,3878542348.49839,4.99989342689514,-4500.28857421875,6.02994930551775E-6,1.87428658904342E-8,1,4,13.4005146026611,5.00733646532432,32.490000128746,0.00750057230909639,0.00118870557484028,1,5.23538423222704E-8,,,,,,,,,,,,,,,,,,,,,4.99983072280884,4.99995613098145,-4500.28857421875,-4500.28857421875,53.8905507011499,5.63605520572373,2.68413305282593,52,1,68,0,0,0.29937744140625,34.2131004333496,1,1,3,4.99995613098145,0,4.99989342689514,,,,,,,,,,,,,,,,,,,,,,,,,,,,,,,,,
,3878542428.11759,4.99991321563721,-3000.15893554687,3.55762004710431E-6,1.19890113085411E-8,1,4,13.4005146026611,5.00725955209129,32.490000128746,0.00442868712183551,6.77869710405529E-4,1,1.20669113977312E-8,,,,,,,,,,,,,,,,,,,,,4.999840259552,4.99998617172241,-3000.15893554687,-3000.15893554687,53.8968037293038,5.63585969701863,2.69124317169189,54,1,0,0,1,0.298309326171875,34.2131004333496,1,1,3,4.999840259552,0,4.99991321563721,,,,,,,,,,,,,,,,,,,,,,,,,,,,,,,,,
,3878542483.22738,5.00001931190491,-2800.3203125,3.32785321988533E-6,1.68745930254443E-8,1,4,13.4005146026611,5.00729798212471,32.490000128746,0.00417978323446627,3.86253229138501E-4,1,-1.87705036346401E-7,,,,,,,,,,,,,,,,,,,,,5.00001192092895,5.00002670288086,-2800.3203125,-2800.3203125,53.7912838792076,5.63692654858021,2.68739724159241,53,1,68,0,0,0.29998779296875,34.2131004333496,1,1,3,5.00001192092895,0,5.00001931190491,,,,,,,,,,,,,,,,,,,,,,,,,,,,,,,,,
,3878542539.08659,4.99993801116943,-2600.33081054687,2.99329932805367E-6,1.79538114170528E-8,1,4,13.4005146026611,5.00733438989509,32.490000128746,0.00376268034721226,3.26980492170731E-4,1,-1.85250367484705E-7,,,,,,,,,,,,,,,,,,,,,4.9998288154602,5.00004720687866,-2600.33081054687,-2600.33081054687,53.9057924572749,5.63731444866569,2.68590188026428,52,1,68,0,0,0.30487060546875,34.7018585205078,1,1,3,4.9998288154602,0,4.99993801116943,,,,,,,,,,,,,,,,,,,,,,,,,,,,,,,,,
,3878542613.04938,4.99992656707764,-2400.31567382813,2.70322101002019E-6,1.76562799335452E-8,1,4,13.4005146026611,5.00726388301063,32.490000128746,0.00340273306501809,2.63480865795313E-4,1,-1.92835374041423E-7,,,,,,,,,,,,,,,,,,,,,4.99988126754761,4.99997186660767,-2400.31567382813,-2400.31567382813,53.9003210576403,5.63458384327233,2.68550705909729,54,1,0,0,1,0.301284790039063,34.7018585205078,1,1,3,4.99997186660767,0,4.99992656707764,,,,,,,,,,,,,,,,,,,,,,,,,,,,,,,,,
,3878542668.99007,4.99986505508423,-2200.4521484375,2.37503858888752E-6,1.94085904455662E-8,1,4,13.4005146026611,5.00726476228569,32.490000128746,0.00299395330445498,2.0257735449958E-4,1,-1.92641017783092E-7,,,,,,,,,,,,,,,,,,,,,4.99982833862305,4.99990177154541,-2200.4521484375,-2200.4521484375,53.8827344159576,5.63557488012735,2.68590092658997,54,1,0,0,1,0.2996826171875,34.2131004333496,1,1,3,4.99982833862305,0,4.99986505508423,,,,,,,,,,,,,,,,,,,,,,,,,,,,,,,,,
,3878542726.272,5.00005984306335,-2000.43725585938,2.08821036953674E-6,1.77696090346434E-8,1,4,13.4005146026611,5.00727230413073,32.490000128746,0.00263450796184981,1.63925745786824E-4,1,-1.80767083383531E-7,,,,,,,,,,,,,,,,,,,,,5.00003671646118,5.00008296966553,-2000.43725585938,-2000.43725585938,53.8502968324095,5.63494921663653,2.68099236488342,54,1,0,0,1,0.298919677734375,36.1681327819824,1,1,3,5.00003671646118,0,5.00005984306335,,,,,,,,,,,,,,,,,,,,,,,,,,,,,,,,,
,3878542783.5249,5.00018048286438,-1800.13305664062,1.79264588406567E-6,2.20623631968653E-8,1,4,13.4005146026611,5.00725159579073,32.490000128746,0.00226902472832176,9.11415174412453E-5,1,-1.94990644305772E-7,,,,,,,,,,,,,,,,,,,,,4.999924659729,5.00043630599976,-1800.13305664062,-1800.13305664062,53.8862517442942,5.63554828355577,2.6828134059906,52,1,68,0,0,0.29998779296875,34.2131004333496,1,1,3,5.00043630599976,0,5.00018048286438,,,,,,,,,,,,,,,,,,,,,,,,,,,,,,,,,
,3878542857.70737,5.00008392333984,-1600.10571289062,1.46593184926562E-6,2.1079384487214E-8,1,4,13.4005146026611,5.00725341283415,32.490000128746,0.00186076218373631,3.92904263303224E-5,1,-1.87747844095586E-7,,,,,,,,,,,,,,,,,,,,,5.00000905990601,5.00015878677368,-1600.10571289062,-1600.10571289062,53.8714008024288,5.63542561171636,2.69040966033936,53,1,68,0,0,0.30059814453125,34.2131004333496,1,1,3,5.00000905990601,0,5.00008392333984,,,,,,,,,,,,,,,,,,,,,,,,,,,,,,,,,
,3878542948.30443,5.00000977516174,-1400.01538085938,1.20018847240474E-6,4.03444978213112E-8,1,4,13.4005146026611,5.00724857843784,32.490000128746,0.0015423999722035,-9.45610644152603E-5,1,-2.55464585632814E-7,,,,,,,,,,,,,,,,,,,,,4.9998083114624,5.00021123886108,-1400.01538085938,-1400.01538085938,53.8350550762845,5.63486497757275,2.69004249572754,52,1,68,0,0,0.297927856445313,34.2131004333496,1,1,3,4.9998083114624,0,5.00000977516174,,,,,,,,,,,,,,,,,,,,,,,,,,,,,,,,,
,3878543004.93192,4.99998426437378,-1200.18933105469,9.10777697011092E-7,2.23166816393226E-8,1,4,13.4005146026611,5.00729981104133,32.490000128746,0.00117452324286352,-9.87490834558115E-5,1,-2.15531973534627E-7,,,,,,,,,,,,,,,,,,,,,4.99983549118042,5.00013303756714,-1200.18933105469,-1200.18933105469,53.8538141607461,5.63441615403223,2.68484711647034,52,1,68,0,0,0.298385620117188,34.2131004333496,1,1,3,5.00013303756714,0,4.99998426437378,,,,,,,,,,,,,,,,,,,,,,,,,,,,,,,,,
,3878543078.64411,4.99989342689514,-1000.17462158203,6.49907812957832E-7,2.32314206620901E-8,1,4,13.4005146026611,5.0073039587006,32.490000128746,8.51419566900879E-4,-1.59430252640944E-4,1,-2.2522796208305E-7,,,,,,,,,,,,,,,,,,,,,4.99978733062744,4.99999952316284,-1000.17462158203,-1000.17462158203,53.7639268810345,5.63584176508898,2.68567609786987,54,1,0,0,1,0.297698974609375,34.2131004333496,1,1,3,4.99999952316284,0,4.99989342689514,,,,,,,,,,,,,,,,,,,,,,,,,,,,,,,,,
,3878543134.92542,5.0000057220459,-800.159851074219,4.11255018076567E-7,2.97034998788997E-8,1,4,13.4005146026611,5.0072399735058,32.490000128746,5.6033660362532E-4,-2.45118795190604E-4,1,-2.58329393261781E-7,,,,,,,,,,,,,,,,,,,,,4.99997711181641,5.00003433227539,-800.159851074219,-800.159851074219,53.9237699132172,5.63508954750151,2.69039535522461,54,1,0,0,1,0.29754638671875,34.7018585205078,1,1,3,4.99997711181641,0,5.0000057220459,,,,,,,,,,,,,,,,,,,,,,,,,,,,,,,,,
,3878543191.75368,5.00013875961304,-600.119873046875,1.59237235473449E-7,2.28802688683974E-8,1,4,13.4005146026611,5.00727696811951,32.490000128746,2.45348070386251E-4,-2.84654066546037E-4,1,-2.52369963982594E-7,,,,,,,,,,,,,,,,,,,,,5.00010108947754,5.00017642974854,-600.119873046875,-600.119873046875,53.8901598868903,5.63599012050907,2.68911218643188,52,1,68,0,0,0.299224853515625,34.2131004333496,1,1,3,5.00017642974854,0,5.00013875961304,,,,,,,,,,,,,,,,,,,,,,,,,,,,,,,,,
,3878543265.88211,5.00011253356934,-400.130279541016,-8.52976863417893E-8,2.32834349193966E-8,1,4,13.4005146026611,5.00721594880588,32.490000128746,-5.90477706610144E-5,-3.31328068573204E-4,1,-2.53268183586197E-7,,,,,,,,,,,,,,,,,,,,,5.00006818771362,5.00015687942505,-400.130279541016,-400.130279541016,53.8256755340538,5.63469278553763,2.69010710716248,53,1,68,0,0,0.300216674804687,34.2131004333496,1,1,3,5.00015687942505,0,5.00011253356934,,,,,,,,,,,,,,,,,,,,,,,,,,,,,,,,,
,3878543330.71292,5.00003409385681,-200.24137878418,-2.18225328826129E-7,3.75304848300313E-8,1,4,13.4005146026611,5.00719342236712,32.490000128746,-2.28752665661164E-4,-3.28350605178087E-4,10,-2.30994035657899E-7,,,,,,,,,,,,,,,,,,,,,5.00000095367432,5.00006723403931,-200.24137878418,-200.24137878418,53.7565014101018,5.63591449532994,2.69028306007385,54,1,0,0,1,0.298690795898438,34.2131004333496,1,1,3,5.00006723403931,0,5.00003409385681,,,,,,,,,,,,,,,,,,,,,,,,,,,,,,,,,
,3878543396.77141,5.00004744529724,-0.201412081718445,-3.90203686627425E-7,2.87200829624997E-8,1,4,13.4005146026611,5.0072348245175,32.490000128746,-4.39716458069802E-4,-3.82005176338965E-4,1,-2.48343904486125E-7,,,,,,,,,,,,,,,,,,,,,4.99999332427978,5.0001015663147,-0.201412081718445,-0.201412081718445,53.9210342133999,5.63665931800312,2.69088840484619,53,1,64,0,0,0.299911499023438,34.2131004333496,1,1,3,4.99999332427978,0,5.00004744529724,,,,,,,,,,,,,,,,,,,,,,,,,,,,,,,,,
,3878543456.47735,4.99994730949402,199.851135253906,-1.93974894662405E-7,8.0211569342159E-7,1,4,13.4005146026611,5.00718697452465,32.490000128746,-3.49137837939712E-4,6.828161214805E-4,1,5.77265017558614E-7,,,,,,,,,,,,,,,,,,,,,4.99993991851807,4.99995470046997,199.851135253906,199.851135253906,53.8370091475826,5.6345555296247,2.68640637397766,54,1,0,0,1,0.301055908203125,34.7018585205078,1,1,3,4.99995470046997,0,4.99994730949402,,,,,,,,,,,,,,,,,,,,,,,,,,,,,,,,,
,3878543514.85852,4.99996304512024,399.740020751953,-7.09106486503895E-7,1.39479157081336E-8,1,4,13.4005146026611,5.00719351411174,32.490000128746,-8.53772014691309E-4,-3.28565924433234E-4,1,-1.57734114854035E-7,,,,,,,,,,,,,,,,,,,,,4.99979305267334,5.00013303756714,399.740020751953,399.740020751953,53.8542049750057,5.63503611556699,2.68723940849304,54,1,0,0,1,0.29937744140625,34.2131004333496,1,1,3,4.99979305267334,0,4.99996304512024,,,,,,,,,,,,,,,,,,,,,,,,,,,,,,,,,
,3878543572.67772,4.99990391731262,599.8681640625,-8.79084427622251E-7,1.43187674255082E-8,1,4,13.4005146026611,5.00725793077313,32.490000128746,-0.00105760463456456,-4.12959622028908E-4,1,-2.00061867415033E-7,,,,,,,,,,,,,,,,,,,,,4.99981927871704,4.9999885559082,599.8681640625,599.8681640625,53.9132179282076,5.63528275696485,2.6881263256073,54,1,0,0,1,0.3082275390625,34.2131004333496,1,1,3,4.9999885559082,0,4.99990391731262,,,,,,,,,,,,,,,,,,,,,,,,,,,,,,,,,
,3878543631.40098,5.00008344650269,799.706665039063,-1.0349992818051E-6,2.21362186281314E-8,1,4,13.4005146026611,5.0072697079001,32.490000128746,-0.00125898922698941,-3.93932694988994E-4,1,-1.61460104234602E-7,,,,,,,,,,,,,,,,,,,,,4.99999761581421,5.00016927719116,799.706665039063,799.706665039063,53.8565498605634,5.63542605992573,2.68199753761291,53,1,68,0,0,0.30029296875,34.2131004333496,1,1,3,5.00016927719116,0,5.00008344650269,,,,,,,,,,,,,,,,,,,,,,,,,,,,,,,,,
,3878543705.38231,4.99983143806458,999.74658203125,-1.20935460667611E-6,5.22597323711124E-8,1,4,13.4005146026611,5.0072647916197,32.490000128746,-0.00146586159287763,-4.95149057994651E-4,1,-2.16645057774233E-7,,,,,,,,,,,,,,,,,,,,,4.9996509552002,5.00001192092895,999.74658203125,999.74658203125,53.7826859654961,5.634522507667,2.68869042396545,53,1,68,0,0,0.298843383789063,32.7468223571777,1,1,3,4.99965906143188,0,4.99983143806458,,,,,,,,,,,,,,,,,,,,,,,,,,,,,,,,,
,3878543780.54459,4.99999618530273,1199.59777832031,-1.46025981480286E-6,1.87418644206228E-8,1,4,13.4005146026611,5.00732377318016,32.490000128746,-0.00178644007672396,-4.88080052438444E-4,1,-1.73428999658276E-7,,,,,,,,,,,,,,,,,,,,,4.99996948242188,5.00002288818359,1199.59777832031,1199.59777832031,53.8006634214384,5.63458339511157,2.68473482131958,54,1,0,0,1,0.300064086914063,33.7243423461914,1,1,3,5.00002288818359,0,4.99999618530273,,,,,,,,,,,,,,,,,,,,,,,,,,,,,,,,,
,3878543855.68468,5.00012040138245,1399.7509765625,-1.7484203818906E-6,1.33295253747357E-8,1,4,13.4005146026611,5.00727734743333,32.490000128746,-0.00215060243715479,-5.06425452276685E-4,1,-1.45056572095576E-7,,,,,,,,,,,,,,,,,,,,,5.00011110305786,5.00012969970703,1399.7509765625,1399.7509765625,53.8764813878038,5.63470057050407,2.68386125564575,53,1,68,0,0,0.300064086914063,34.2131004333496,1,1,3,5.00011110305786,0,5.00012040138245,,,,,,,,,,,,,,,,,,,,,,,,,,,,,,,,,
,3878543913.35551,4.99994778633118,1599.58959960938,-2.02769025998933E-6,1.0556855159517E-8,1,4,13.4005146026611,5.0073199051926,32.490000128746,-0.00250026083517855,-5.46414338202174E-4,1,-1.35381421639706E-7,,,,,,,,,,,,,,,,,,,,,4.99985074996948,5.00004482269287,1599.58959960938,1599.58959960938,53.8643661457557,5.63474607338371,2.68294429779053,52,1,68,0,0,0.306167602539063,33.7243423461914,1,1,3,5.00004482269287,0,4.99994778633118,,,,,,,,,,,,,,,,,,,,,,,,,,,,,,,,,
,3878543971.05546,4.99989247322082,1799.66723632813,-2.29623570685362E-6,4.07081120012253E-8,1,4,13.4005146026611,5.0073491000286,32.490000128746,-0.00282932902891045,-6.32738080507842E-4,1,-1.64513130204501E-7,,,,,,,,,,,,,,,,,,,,,4.99986839294434,4.99991655349731,1799.66723632813,1799.66723632813,53.9311953841499,5.63446434026958,2.68169212341309,54,1,0,0,1,0.299911499023438,34.7018585205078,1,1,3,4.99986839294434,0,4.99989247322082,,,,,,,,,,,,,,,,,,,,,,,,,,,,,,,,,
,3878544028.65662,5.00008034706116,1999.89599609375,-2.58446084863113E-6,3.25505390572411E-8,1,4,13.4005146026611,5.0073460308587,32.490000128746,-0.00319070853649227,-6.70427268033671E-4,1,-1.51656964785555E-7,,,,,,,,,,,,,,,,,,,,,5.00004911422729,5.00011157989502,1999.89599609375,1999.89599609375,53.8612396316788,5.632996750212,2.67916178703308,52,1,68,0,0,0.299224853515625,34.2131004333496,1,1,3,5.00004911422729,0,5.00008034706116,,,,,,,,,,,,,,,,,,,,,,,,,,,,,,,,,
,3878544086.39507,4.9999053478241,2199.83520507813,-2.90973335046446E-6,1.95762634606349E-8,1,4,13.4005146026611,5.00729502781127,32.490000128746,-0.00360302035698817,-6.82666189397541E-4,1,-1.12832459568877E-7,,,,,,,,,,,,,,,,,,,,,4.99988889694214,4.99992179870605,2199.83520507813,2199.83520507813,53.8471703183326,5.63274968148341,2.68592858314514,54,1,0,0,1,0.2996826171875,34.2131004333496,1,1,3,4.99992179870605,0,4.9999053478241,,,,,,,,,,,,,,,,,,,,,,,,,,,,,,,,,
,3878544144.06692,5.0002167224884,2399.96337890625,-3.20141462873125E-6,3.02783058684056E-8,1,4,13.4005146026611,5.00722707608667,32.490000128746,-0.00397097274331355,-7.05301135415021E-4,1,-8.73830102554651E-8,,,,,,,,,,,,,,,,,,,,,5.00014781951904,5.00028562545776,2399.96337890625,2399.96337890625,53.9296321271115,5.63303779739487,2.67955613136291,54,1,0,0,1,0.297698974609375,33.7243423461914,1,1,3,5.00014781951904,0,5.0002167224884,,,,,,,,,,,,,,,,,,,,,,,,,,,,,,,,,
,3878544201.70839,4.99996376037598,2599.8271484375,-3.54913876169688E-6,1.59220906376579E-8,1,4,13.4005146026611,5.00724800747392,32.490000128746,-0.00440129699511381,-7.88675902130885E-4,1,-1.02304542699852E-7,,,,,,,,,,,,,,,,,,,,,4.99989175796509,5.00003576278687,2599.8271484375,2599.8271484375,53.8819527874384,5.6323531640989,2.68704891204834,54,1,0,0,1,0.299301147460937,34.2131004333496,1,1,3,4.99989175796509,0,4.99996376037598,,,,,,,,,,,,,,,,,,,,,,,,,,,,,,,,,
,3878544259.40426,5.00016307830811,2799.98046875,-3.86283637249319E-6,1.69813812157287E-8,1,4,13.4005146026611,5.00719524225629,32.490000128746,-0.00479600358916374,-8.19868552729946E-4,1,-8.0431824264317E-8,,,,,,,,,,,,,,,,,,,,,5.00008773803711,5.0002384185791,2799.98046875,2799.98046875,53.8471703183326,5.63351371889344,2.68283176422119,54,1,0,0,1,0.298233032226562,34.2131004333496,1,1,3,5.00008773803711,0,5.00016307830811,,,,,,,,,,,,,,,,,,,,,,,,,,,,,,,,,
,3878544316.99095,4.99990320205688,2999.71826171875,-4.20704830831264E-6,3.90130508937467E-8,1,4,13.4005146026611,5.00728130858333,32.490000128746,-0.00521775053019444,-9.31342822983895E-4,1,-1.18426723484774E-7,,,,,,,,,,,,,,,,,,,,,4.99981927871704,4.99998712539673,2999.71826171875,2999.71826171875,53.8424805472172,5.63265893741771,2.68081140518188,54,1,0,0,1,0.3009033203125,33.7243423461914,1,1,3,4.99981927871704,0,4.99990320205688,,,,,,,,,,,,,,,,,,,,,,,,,,,,,,,,,
,3878544395.85136,4.99996709823608,4499.7470703125,-6.67837395897594E-6,1.51570494100062E-8,1,4,13.4005146026611,5.0072789966716,32.490000128746,-0.00832100111149591,-0.00122295453758562,1,1.71326671019759E-8,,,,,,,,,,,,,,,,,,,,,4.9999361038208,4.99999809265137,4499.7470703125,4499.7470703125,53.9573799395442,5.63272425464827,2.67735123634338,54,1,0,0,1,0.298385620117188,33.2355842590332,1,1,3,4.99999809265137,0,4.99996709823608,,,,,,,,,,,,,,,,,,,,,,,,,,,,,,,,,
,3878544461.62707,5.0000479221344,6499.6181640625,-1.00512593949439E-5,1.93177228413745E-8,1,4,13.4005146026611,5.00723053468465,32.490000128746,-0.0125274768172186,-0.00181278532734851,1,4.81003612351647E-8,,,,,,,,,,,,,,,,,,,,,4.99987363815308,5.00022220611572,6499.6181640625,6499.6181640625,53.8952404722653,5.63310551221424,2.67906475067139,54,1,0,0,1,0.298385620117188,33.7243423461914,1,1,3,5.00022220611572,0,5.0000479221344,,,,,,,,,,,,,,,,,,,,,,,,,,,,,,,,,
,3878544526.80201,4.99996376037598,8500.04296875,-1.34701446956816E-5,2.36213293045297E-8,1,4,13.4005146026611,5.00729927694959,32.490000128746,-0.0167839174111733,-0.00246313165711865,1,3.74119691578726E-8,,,,,,,,,,,,,,,,,,,,,4.99991083145142,5.00001668930054,8500.04296875,8500.04296875,53.9425289976788,5.63363170695287,2.67734837532043,54,1,0,0,1,0.299758911132812,33.7243423461914,1,1,3,5.00001668930054,0,4.99996376037598,,,,,,,,,,,,,,,,,,,,,,,,,,,,,,,,,
,3878544598.91687,4.99984121322632,10000.09765625,-1.59958972519863E-5,3.03801307320186E-8,1,4,13.4005146026611,5.00724222589489,32.490000128746,-0.0199232371615192,-0.00297489220018337,1,4.32042577945089E-9,,,,,,,,,,,,,,,,,,,,,4.99981832504272,4.99986410140991,10000.09765625,10000.09765625,53.7994909786595,5.63184911058725,2.67631602287292,54,1,0,0,1,0.299911499023438,33.7243423461914,1,1,3,4.99986410140991,0,4.99984121322632,,,,,,,,,,,,,,,,,,,,,,,,,,,,,,,,,
,3878544751.4851,4.99998426437378,30000.205078125,-5.10798356125868E-5,4.05521035924192E-8,1,4,13.4005146026611,5.00730076648181,32.490000128746,-0.0636317474523771,-0.0094353030102287,1,6.56642993272652E-8,,,,,,,,,,,,,,,,,,,,,4.999915599823,5.00005292892456,30000.205078125,30000.205078125,54.1606033545442,5.63436024872149,2.68278121948242,54,1,0,0,1,0.300216674804687,33.7243423461914,1,1,3,4.999915599823,0,4.99998426437378,,,,,,,,,,,,,,,,,,,,,,,,,,,,,,,,,
,3878544908.87957,5.00011730194092,50000.359375,-8.71753426009619E-5,9.19946012483672E-8,1,4,13.4005146026611,5.00730939085764,32.490000128746,-0.108589113760822,-0.0161575774118283,1,6.80756475068896E-8,,,,,,,,,,,,,,,,,,,,,5.0000147819519,5.00021982192993,50000.359375,50000.359375,54.6749149201981,5.63491591287214,2.68752264976501,54,1,0,0,1,0.29754638671875,33.7243423461914,1,1,3,5.0000147819519,0,5.00011730194092,,,,,,,,,,,,,,,,,,,,,,,,,,,,,,,,,
,3878545066.86011,4.99988961219788,70000.40625,-1.238198537539E-4,1.11555856523581E-7,1,4,13.4005146026611,5.00723543370959,32.490000128746,-0.154206605878151,-0.0231174678563323,1,-3.8567283799406E-8,,,,,,,,,,,,,,,,,,,,,4.99970817565918,5.00007104873657,70000.40625,70000.40625,54.9719337575058,5.63539656715304,2.68357300758362,54,1,0,0,1,0.29937744140625,34.2131004333496,1,1,3,5.00007104873657,0,4.99988961219788,,,,,,,,,,,,,,,,,,,,,,,,,,,,,,,,,