File: SQUID/23006_LCOS/23006_LCOS_A1_MH_50K_FC_p0d5T.csv
Comment,Time Stamp (sec),Temperature (K),Magnetic Field (Oe),Moment (emu),M. Std. Err. (emu),Transport Action,Averaging Time (sec),Frequency (Hz),Peak Amplitude (mm),Center Position (mm),Lockin Signal' (V),Lockin Signal (V),Range,M. Quad. Signal (emu),AC Moment (emu),AC M. Std Err. (emu),AC Phase (deg),AC Phase Std. Err. (deg),AC Susceptibility (emu/Oe),AC Suscept. Std Err. (emu/Oe),AC X' (emu/Oe),AC X' Std Err. (emu/Oe),AC X'' (emu/Oe),AC X'' Std Err. (emu/Oe),AC Drive (Oe),AC Frequency (Hz),AC Averaging Time (sec),AC Cycles,AC Range,AC Measure Type,AC Signal' (V),AC Signal'' (V),AC Trim Coil Ratio,AC Trim Coil Phase,Min. Temperature (K),Max. Temperature (K),Min. Field (Oe),Max. Field (Oe),Mass (grams),Motor Lag (deg),Pressure (Torr),Measure Count,Measurement Number,SQUID Status (code),Motor Status (code),Measure Status (code),Motor Current (amps),Motor Temp. (C),Temp. Status (code),Field Status (code),Chamber Status (code),Chamber Temp (K),Redirection State,Average Temp (K),Rotation Angle (deg),Rotator state,DC Moment Fixed Ctr (emu),DC Moment Err Fixed Ctr (emu),DC Moment Free Ctr (emu),DC Moment Err Free Ctr (emu),DC Fixed Fit,DC Free Fit,DC Calculated Center (mm),DC Calculated Center Err (mm),DC Scan Length (mm),DC Scan Time (s),DC Number of Points,DC Squid Drift,DC Min V (V),DC Max V (V),DC Scans per Measure,Map 01,Map 02,Map 03,Map 04,Map 05,Map 06,Map 07,Map 08,Map 09,Map 10,Map 11,Map 12,Map 13,Map 14,Map 15,Map 16
,3883324749.87467,49.9991817474365,70000.15625,-9.44574188412797E-4,1.49122262403204E-7,1,4,13.4005146026611,5.00620657475946,30.4499994963407,-1.17603722391999,-0.176356647507723,1,-3.3678698921316E-7,,,,,,,,,,,,,,,,,,,,,49.9991493225098,49.9992141723633,70000.15625,70000.15625,53.1902115479191,5.64260313693152,4.90113401412964,52,1,68,0,0,0.300750732421875,30.7917900085449,1,1,3,49.9992141723633,0,49.9991817474365,,,,,,,,,,,,,,,,,,,,,,,,,,,,,,,,,
,3883324862.99749,49.8252906799316,60000.47265625,-7.801994203704E-4,1.06920647586429E-7,1,4,13.4005146026611,5.00630531701979,30.4499994963407,-0.971406087842627,-0.145697600940313,1,-2.99473345340638E-7,,,,,,,,,,,,,,,,,,,,,49.8242721557617,49.8263092041016,60000.47265625,60000.47265625,53.2965130265345,5.64238523402439,4.78551435470581,53,1,68,0,0,0.302047729492188,32.7468223571777,1,1,3,49.8242721557617,0,49.8252906799316,,,,,,,,,,,,,,,,,,,,,,,,,,,,,,,,,
,3883324975.70401,49.9818820953369,50000.47265625,-6.16878611090338E-4,9.86920917971566E-8,1,4,13.4005146026611,5.00629138201716,30.4499994963407,-0.768070265698026,-0.115106543160434,1,-1.63362691400143E-7,,,,,,,,,,,,,,,,,,,,,49.9776268005371,49.9861373901367,50000.47265625,50000.47265625,53.3391117808326,5.6420476248067,4.75839185714722,53,1,68,0,0,0.304031372070313,32.7468223571777,1,1,3,49.9861373901367,0,49.9818820953369,,,,,,,,,,,,,,,,,,,,,,,,,,,,,,,,,
,3883325063.51084,50.0216426849365,40000.19921875,-4.5377768538403E-4,7.03326630974123E-8,1,4,13.4005146026611,5.00618832996331,30.4499994963407,-0.564998668798333,-0.0845350566734813,1,-1.15755573305845E-8,,,,,,,,,,,,,,,,,,,,,50.0186462402344,50.0246391296387,40000.19921875,40000.19921875,53.4375969742557,5.64293189845741,4.75053453445435,51,1,100,0,0,0.30059814453125,33.2355842590332,1,1,3,50.0247802734375,0,50.0216426849365,,,,,,,,,,,,,,,,,,,,,,,,,,,,,,,,,
,3883325174.87332,50.0180683135986,30000.12890625,-2.907003214638E-4,4.35226366912467E-8,1,4,13.4005146026611,5.0061320244448,30.4499994963407,-0.361946855386915,-0.0541440011869666,1,8.00786859754643E-10,,,,,,,,,,,,,,,,,,,,,50.016185760498,50.0199508666992,30000.12890625,30000.12890625,53.4696437435441,5.64273713720492,4.75123262405396,54,1,0,0,1,0.303726196289063,33.2355842590332,1,1,3,50.0199508666992,0,50.0180683135986,,,,,,,,,,,,,,,,,,,,,,,,,,,,,,,,,
,3883325260.58542,50.0208549499512,19999.779296875,-1.28169274423682E-4,2.61739302583221E-8,1,4,13.4005146026611,5.00593830293888,30.4499994963407,-0.159569654731892,-0.0238938379986541,1,-1.82266656884959E-8,,,,,,,,,,,,,,,,,,,,,50.0158996582031,50.0258102416992,19999.779296875,19999.779296875,53.4446316309287,5.64355330817435,4.75044727325439,54,1,0,0,1,0.300827026367188,33.2355842590332,1,1,3,50.0258102416992,0,50.0208549499512,,,,,,,,,,,,,,,,,,,,,,,,,,,,,,,,,
,3883325325.53101,50.0144329071045,14499.517578125,-3.94132567510698E-5,1.93444001056905E-8,1,4,13.4005146026611,5.00584247735452,30.4499994963407,-0.0490660620313718,-0.0073593722692445,1,-1.52348116588983E-8,,,,,,,,,,,,,,,,,,,,,50.0140113830566,50.0148544311523,14499.517578125,14499.517578125,53.5306107680441,5.64410901016922,4.74751234054565,54,1,0,0,1,0.300827026367188,33.2355842590332,1,1,3,50.0140113830566,0,50.0144329071045,,,,,,,,,,,,,,,,,,,,,,,,,,,,,,,,,
,3883325364.26929,50.038969039917,13499.794921875,-2.34111893272979E-5,2.14161096611238E-8,1,4,13.4005146026611,5.00586801527167,30.4499994963407,-0.0291407965307277,-0.00440017074752648,1,-3.21223292564716E-8,,,,,,,,,,,,,,,,,,,,,50.0364875793457,50.0414505004883,13499.794921875,13499.794921875,53.4790232857749,5.64312653491574,4.75864458084106,54,1,0,0,1,0.30120849609375,33.7243423461914,1,1,3,50.0364875793457,0,50.038969039917,,,,,,,,,,,,,,,,,,,,,,,,,,,,,,,,,
,3883325404.71451,50.0173969268799,12499.62109375,-7.45036921617215E-6,1.74596561732469E-8,1,4,13.4005146026611,5.00582297584148,30.4499994963407,-0.00926888182438831,-0.00143210437284375,1,-3.5775739131141E-8,,,,,,,,,,,,,,,,,,,,,50.0160980224609,50.0186958312988,12499.62109375,12499.62109375,53.4973915559768,5.64373722251686,4.75950288772583,54,1,0,0,1,0.302352905273438,33.2355842590332,1,1,3,50.0160980224609,0,50.0173969268799,,,,,,,,,,,,,,,,,,,,,,,,,,,,,,,,,
,3883325445.20097,50.0649929046631,11499.685546875,8.42326347401236E-6,1.86102932281188E-8,1,4,13.4005146026611,5.00578778794093,30.4499994963407,0.0104966874986507,0.0015018003545086,1,-5.37696902939658E-8,,,,,,,,,,,,,,,,,,,,,50.0633430480957,50.0666427612305,11499.685546875,11499.685546875,53.4747243289191,5.64382398399605,4.75864362716675,54,1,0,0,1,0.30120849609375,33.2355842590332,1,1,3,50.0666427612305,0,50.0649929046631,,,,,,,,,,,,,,,,,,,,,,,,,,,,,,,,,
,3883325486.06999,50.0647163391113,10499.6240234375,2.42009459927799E-5,1.64578832040013E-8,1,4,13.4005146026611,5.00576927028359,30.4499994963407,0.0301426018134837,0.00441748649025347,1,-7.20142380391325E-8,,,,,,,,,,,,,,,,,,,,,50.063549041748,50.0658836364746,10499.6240234375,10499.6240234375,53.5376454247172,5.64395461858422,4.75689935684204,54,1,0,0,1,0.302658081054687,33.7243423461914,1,1,3,50.0658836364746,0,50.0647163391113,,,,,,,,,,,,,,,,,,,,,,,,,,,,,,,,,
,3883325525.19687,50.0320053100586,9499.7646484375,3.98476071745639E-5,1.28090349279761E-8,1,4,13.4005146026611,5.00573069948018,30.4499994963407,0.0496229356864556,0.00732196210229999,1,-7.96064070275215E-8,,,,,,,,,,,,,,,,,,,,,50.0303039550781,50.0337066650391,9499.7646484375,9499.7646484375,53.384446234948,5.64409354123578,4.7634859085083,52,1,68,0,0,0.302200317382812,33.2355842590332,1,1,3,50.0337066650391,0,50.0320053100586,,,,,,,,,,,,,,,,,,,,,,,,,,,,,,,,,
,3883325565.61292,50.0413246154785,8499.8544921875,5.5296701688016E-5,3.00426097207565E-8,1,4,13.4005146026611,5.00586022093278,30.4499994963407,0.06886223856272,0.0101759361667193,1,-9.85430185053832E-8,,,,,,,,,,,,,,,,,,,,,50.0375785827637,50.0450706481934,8499.8544921875,8499.8544921875,53.4012512481114,5.64383323189761,4.76049518585205,54,1,0,0,1,0.300369262695313,33.2355842590332,1,1,3,50.0450706481934,0,50.0413246154785,,,,,,,,,,,,,,,,,,,,,,,,,,,,,,,,,
,3883325606.76827,50.0147094726562,7499.50341796875,7.04767952776853E-5,2.2262075750562E-8,1,4,13.4005146026611,5.0057976645125,30.4499994963407,0.087759723151541,0.013003288950327,1,-9.8226184220616E-8,,,,,,,,,,,,,,,,,,,,,50.0136947631836,50.0157241821289,7499.50341796875,7499.50341796875,53.3543535369576,5.6436914698999,4.76055145263672,54,1,0,0,1,0.3021240234375,33.7243423461914,1,1,3,50.0136947631836,0,50.0147094726562,,,,,,,,,,,,,,,,,,,,,,,,,,,,,,,,,
,3883325648.09355,50.0488548278809,6499.75634765625,8.54071828633108E-5,8.61002801447668E-9,1,4,13.4005146026611,5.00577212358351,30.4499994963407,0.106349881463006,0.0157634426542478,1,-1.14583863046449E-7,,,,,,,,,,,,,,,,,,,,,50.0457153320313,50.0519943237305,6499.75634765625,6499.75634765625,53.4411143025922,5.64339712033953,4.76566982269287,54,1,0,0,1,0.301971435546875,33.7243423461914,1,1,3,50.0519943237305,0,50.0488548278809,,,,,,,,,,,,,,,,,,,,,,,,,,,,,,,,,
,3883325689.79923,50.0441856384277,5499.80859375,9.95895714124369E-5,1.1722854145729E-8,1,4,13.4005146026611,5.00570639084641,30.4499994963407,0.124005391997689,0.0183958636083308,1,-1.21448563661678E-7,,,,,,,,,,,,,,,,,,,,,50.041675567627,50.0466957092285,5499.80859375,5499.80859375,53.435252088698,5.6442194174307,4.77002716064453,54,1,0,0,1,0.301742553710937,33.2355842590332,1,1,3,50.040657043457,0,50.0441856384277,,,,,,,,,,,,,,,,,,,,,,,,,,,,,,,,,
,3883325730.48537,50.0469799041748,4499.7216796875,1.12777710836388E-4,9.95284223689669E-9,1,4,13.4005146026611,5.00567407652663,30.4499994963407,0.140422538978178,0.0208517172942694,1,-1.21489257134405E-7,,,,,,,,,,,,,,,,,,,,,50.0454750061035,50.0484848022461,4499.7216796875,4499.7216796875,53.4266541749864,5.64375105123463,4.7615442276001,53,1,68,0,0,0.30181884765625,33.2355842590332,1,1,3,50.0454750061035,0,50.0469799041748,,,,,,,,,,,,,,,,,,,,,,,,,,,,,,,,,
,3883325772.07112,50.0174255371094,3499.4970703125,1.23694636997189E-4,1.02473789867328E-8,1,4,13.4005146026611,5.00568733393835,30.4499994963407,0.154016100987629,0.022870019693902,1,-1.33439530008399E-7,,,,,,,,,,,,,,,,,,,,,50.0170097351074,50.0178413391113,3499.4970703125,3499.4970703125,53.4305623175826,5.64428759357861,4.7639741897583,54,1,0,0,1,0.3021240234375,33.7243423461914,1,1,3,50.0170097351074,0,50.0174255371094,,,,,,,,,,,,,,,,,,,,,,,,,,,,,,,,,
,3883325826.95631,50.0115127563477,2709.64721679687,1.29226204258929E-4,7.27256766779824E-9,1,4,13.4005146026611,5.00565685493426,30.4499994963407,0.160900528800114,0.0239041274065115,1,-1.30109602356662E-7,,,,,,,,,,,,,,,,,,,,,50.0088539123535,50.0141716003418,2709.64721679687,2709.64721679687,53.4977823702364,5.64414279597989,4.77660751342773,54,1,0,0,1,0.303802490234375,33.2355842590332,1,1,3,50.0141716003418,0,50.0115127563477,,,,,,,,,,,,,,,,,,,,,,,,,,,,,,,,,
,3883325866.0443,50.0352478027344,2129.64306640625,1.29964282033859E-4,9.87502248746667E-9,1,4,13.4005146026611,5.00567914620948,30.4499994963407,0.161817833129263,0.0240587848757735,1,-1.16410987657746E-7,,,,,,,,,,,,,,,,,,,,,50.0316047668457,50.038890838623,2129.64306640625,2129.64306640625,53.4055502049672,5.64417173972997,4.77554416656494,54,1,0,0,1,0.303192138671875,33.7243423461914,1,1,3,50.038890838623,0,50.0352478027344,,,,,,,,,,,,,,,,,,,,,,,,,,,,,,,,,
,3883325905.39317,50.0292873382568,1549.58898925781,1.25634989382506E-4,9.24594830668459E-9,1,4,13.4005146026611,5.00569263162734,30.4499994963407,0.15643046957655,0.0232412210888327,1,-1.25561594090578E-7,,,,,,,,,,,,,,,,,,,,,50.0269088745117,50.031665802002,1549.58898925781,1549.58898925781,53.4458040737076,5.64406873243904,4.76848745346069,54,1,0,0,1,0.301284790039063,33.7243423461914,1,1,3,50.0269088745117,0,50.0292873382568,,,,,,,,,,,,,,,,,,,,,,,,,,,,,,,,,
,3883325944.81607,50.0293464660645,969.673278808594,1.11864449981584E-4,8.09172905029469E-9,1,4,13.4005146026611,5.0056946053478,30.4499994963407,0.139280437755433,0.0207215821183955,1,-8.94989579819808E-8,,,,,,,,,,,,,,,,,,,,,50.0249137878418,50.0337791442871,969.673278808594,969.673278808594,53.4485397735249,5.6439643505367,4.77095651626587,54,1,0,0,1,0.300064086914063,33.7243423461914,1,1,3,50.0337791442871,0,50.0293464660645,,,,,,,,,,,,,,,,,,,,,,,,,,,,,,,,,
,3883325984.3972,50.0273628234863,389.719787597656,7.71637014708754E-5,8.25132197899633E-9,1,4,13.4005146026611,5.00571932259349,30.4499994963407,0.0960812080867785,0.0142577284370293,1,-9.06885976567667E-8,,,,,,,,,,,,,,,,,,,,,50.0251426696777,50.0295829772949,389.719787597656,389.719787597656,53.391480891621,5.64410778178404,4.7700514793396,54,1,0,0,1,0.301513671875,33.2355842590332,1,1,3,50.0295829772949,0,50.0273628234863,,,,,,,,,,,,,,,,,,,,,,,,,,,,,,,,,
,3883326023.19781,50.0442638397217,-190.284057617187,-2.38989335782384E-5,6.61901128295253E-7,1,4,13.4005146026611,5.00580619718427,30.4499994963407,-0.0298540144355736,-0.00377905056515639,1,5.39683101859739E-7,,,,,,,,,,,,,,,,,,,,,50.0424385070801,50.0460891723633,-190.284057617187,-190.284057617187,53.4227460323903,5.64368079035942,4.77022409439087,54,1,0,0,1,0.302963256835937,33.7243423461914,1,1,3,50.0460891723633,0,50.0442638397217,,,,,,,,,,,,,,,,,,,,,,,,,,,,,,,,,
,3883326060.44914,50.0252647399902,-770.237548828125,-9.20492862206112E-5,2.3378773745459E-8,1,4,13.4005146026611,5.00564181374318,30.4499994963407,-0.114609493107537,-0.0170357388096385,1,8.57462124218096E-8,,,,,,,,,,,,,,,,,,,,,50.024227142334,50.0263023376465,-770.237548828125,-770.237548828125,53.4336888316595,5.64417660737683,4.78352880477905,54,1,0,0,1,0.302963256835937,33.7243423461914,1,1,3,50.0263023376465,0,50.0252647399902,,,,,,,,,,,,,,,,,,,,,,,,,,,,,,,,,
,3883326098.55218,50.0469799041748,-1349.90148925781,-1.1718450130843E-4,2.08445297463172E-8,1,4,13.4005146026611,5.00566305955467,30.4499994963407,-0.145906685878126,-0.0216825858124089,1,1.13260476654828E-7,,,,,,,,,,,,,,,,,,,,,50.0458145141602,50.0481452941895,-1349.90148925781,-1349.90148925781,53.4805865428134,5.64425095298495,4.77865076065063,54,1,0,0,1,0.301742553710937,33.7243423461914,1,1,3,50.0481452941895,0,50.0469799041748,,,,,,,,,,,,,,,,,,,,,,,,,,,,,,,,,
,3883326136.47628,50.0240478515625,-1930.23266601562,-1.26175618687048E-4,1.14164222105964E-7,1,4,13.4005146026611,5.00568587295827,30.4499994963407,-0.157096342333896,-0.0233878362085678,1,8.86314107713088E-8,,,,,,,,,,,,,,,,,,,,,50.0227584838867,50.0253372192383,-1930.23266601562,-1930.23266601562,53.348882137323,5.64323038911978,4.77477741241455,54,1,0,0,1,0.301284790039063,32.7468223571777,1,1,3,50.0253372192383,0,50.0240478515625,,,,,,,,,,,,,,,,,,,,,,,,,,,,,,,,,
,3883326174.88754,50.0280380249023,-2509.87158203125,-1.27894523988372E-4,1.96716667339929E-8,1,4,13.4005146026611,5.00568516516918,30.4499994963407,-0.159236536038603,-0.0237058903981293,1,9.02857542220701E-8,,,,,,,,,,,,,,,,,,,,,50.0273132324219,50.0287628173828,-2509.87158203125,-2509.87158203125,53.5364729819384,5.64348142121237,4.77519702911377,54,1,0,0,1,0.301895141601562,33.2355842590332,1,1,3,50.0287628173828,0,50.0280380249023,,,,,,,,,,,,,,,,,,,,,,,,,,,,,,,,,
,3883326229.75519,50.0510215759277,-3000.03295898438,-1.26060461717537E-4,1.41715700241293E-8,1,4,13.4005146026611,5.00558266125492,30.4499994963407,-0.156947469545481,-0.0233723030040011,1,8.33405210682222E-8,,,,,,,,,,,,,,,,,,,,,50.0504379272461,50.0516052246094,-3000.03295898438,-3000.03295898438,53.4856671281884,5.64459556888161,4.78315925598145,54,1,0,0,1,0.302047729492188,33.7243423461914,1,1,3,50.0504379272461,0,50.0510215759277,,,,,,,,,,,,,,,,,,,,,,,,,,,,,,,,,
,3883326269.92917,50.0343379974365,-3999.88012695313,-1.17356403288559E-4,1.22978573053864E-8,1,4,13.4005146026611,5.00549899366936,30.4499994963407,-0.146104980191499,-0.021773857910421,1,6.48588414783307E-8,,,,,,,,,,,,,,,,,,,,,50.0340957641602,50.0345802307129,-3999.88012695313,-3999.88012695313,53.4833222426306,5.64439507777362,4.78692626953125,54,1,0,0,1,0.304107666015625,33.7243423461914,1,1,3,50.0345802307129,0,50.0343379974365,,,,,,,,,,,,,,,,,,,,,,,,,,,,,,,,,
,3883326311.24562,50.0261688232422,-5000.0048828125,-1.05124355224573E-4,1.57272247833397E-8,1,4,13.4005146026611,5.00561366096887,30.4499994963407,-0.130879995921445,-0.0195094525245299,1,5.45182411385169E-8,,,,,,,,,,,,,,,,,,,,,50.0245094299316,50.0278282165527,-5000.0048828125,-5000.0048828125,53.5110700550634,5.64352424948833,4.77858448028564,54,1,0,0,1,0.3021240234375,33.7243423461914,1,1,3,50.0278282165527,0,50.0261688232422,,,,,,,,,,,,,,,,,,,,,,,,,,,,,,,,,
,3883326351.62569,50.0334339141846,-5999.92724609375,-9.15032046874638E-5,1.00338803619461E-8,1,4,13.4005146026611,5.00548299306762,30.4499994963407,-0.11391733800309,-0.016981925360754,1,4.66771727259513E-8,,,,,,,,,,,,,,,,,,,,,50.0298919677734,50.0369758605957,-5999.92724609375,-5999.92724609375,53.3934349629191,5.64465073799997,4.78796577453613,54,1,0,0,1,0.303421020507812,33.7243423461914,1,1,3,50.0369758605957,0,50.0334339141846,,,,,,,,,,,,,,,,,,,,,,,,,,,,,,,,,
,3883326391.52073,50.0388927459717,-6999.59814453125,-7.69518747325906E-5,1.29329604091036E-8,1,4,13.4005146026611,5.0054854500143,30.4499994963407,-0.0957978810600675,-0.0143066277617336,1,1.89714255795227E-8,,,,,,,,,,,,,,,,,,,,,50.0345077514648,50.0432777404785,-6999.59814453125,-6999.59814453125,53.4340796459191,5.64454683309319,4.79212474822998,52,1,68,0,0,0.302200317382812,33.7243423461914,1,1,3,50.0432777404785,0,50.0388927459717,,,,,,,,,,,,,,,,,,,,,,,,,,,,,,,,,
,3883326432.79898,50.0300750732422,-7999.9365234375,-6.19151265531675E-5,1.24018796224205E-8,1,4,13.4005146026611,5.00554506497688,30.4499994963407,-0.0770761599476546,-0.0115357103858368,1,-4.39329832304868E-9,,,,,,,,,,,,,,,,,,,,,50.028247833252,50.0319023132324,-7999.9365234375,-7999.9365234375,53.4446316309287,5.64456988684957,4.77983665466309,54,1,0,0,1,0.301132202148438,33.7243423461914,1,1,3,50.0319023132324,0,50.0300750732422,,,,,,,,,,,,,,,,,,,,,,,,,,,,,,,,,
,3883326472.88667,50.0576972961426,-8999.7958984375,-4.65743547533559E-5,1.83739594337203E-8,1,4,13.4005146026611,5.00549105897433,30.4499994963407,-0.0579739768746874,-0.00870458829817218,1,-2.51731538393834E-8,,,,,,,,,,,,,,,,,,,,,50.0561790466309,50.0592155456543,-8999.7958984375,-8999.7958984375,53.4114124188614,5.64447501327412,4.78717041015625,54,1,0,0,1,0.303268432617188,32.2580642700195,1,1,3,50.0591354370117,0,50.0576972961426,,,,,,,,,,,,,,,,,,,,,,,,,,,,,,,,,
,3883326513.2427,50.0440101623535,-9999.908203125,-3.10194774256269E-5,1.25820392545626E-8,1,4,13.4005146026611,5.00546392043948,30.4499994963407,-0.0386090334518092,-0.00581432897306898,1,-3.03724473122935E-8,,,,,,,,,,,,,,,,,,,,,50.0439071655273,50.0441131591797,-9999.908203125,-9999.908203125,53.4637815296499,5.64499454706948,4.78509283065796,54,1,0,0,1,0.3021240234375,33.2355842590332,1,1,3,50.0439071655273,0,50.0440101623535,,,,,,,,,,,,,,,,,,,,,,,,,,,,,,,,,
,3883326554.44922,50.0448799133301,-10999.73046875,-1.53195813122972E-5,1.93133599442466E-8,1,4,13.4005146026611,5.00559549753651,30.4499994963407,-0.0190611576472973,-0.00292093765952236,1,-5.4610451932046E-8,,,,,,,,,,,,,,,,,,,,,50.0412445068359,50.0485153198242,-10999.73046875,-10999.73046875,53.488012013746,5.64419540851273,4.78314018249512,54,1,0,0,1,0.3021240234375,33.2355842590332,1,1,3,50.0485153198242,0,50.0448799133301,,,,,,,,,,,,,,,,,,,,,,,,,,,,,,,,,
,3883326594.55039,50.0317516326904,-11999.8173828125,5.81200149660934E-7,2.34615161086513E-8,1,4,13.4005146026611,5.00565945095286,30.4499994963407,7.35778012029251E-4,2.64853795651508E-5,1,-6.5669215834916E-8,,,,,,,,,,,,,,,,,,,,,50.0295944213867,50.0339088439941,-11999.8173828125,-11999.8173828125,53.5704738225249,5.64372200432999,4.78558969497681,54,1,0,0,1,0.302276611328125,33.7243423461914,1,1,3,50.0339088439941,0,50.0317516326904,,,,,,,,,,,,,,,,,,,,,,,,,,,,,,,,,
,3883326634.91337,50.0176734924316,-12999.9287109375,1.63817692709202E-5,1.65823555759933E-8,1,4,13.4005146026611,5.00549303107112,30.4499994963407,0.0204073335516616,0.00295526379478066,1,-7.66449385474539E-8,,,,,,,,,,,,,,,,,,,,,50.0170822143555,50.0182647705078,-12999.9287109375,-12999.9287109375,53.4579193157556,5.64409296349122,4.79497289657593,54,1,0,0,1,0.301437377929687,33.2355842590332,1,1,3,50.0170822143555,0,50.0176734924316,,,,,,,,,,,,,,,,,,,,,,,,,,,,,,,,,
,3883326676.08182,50.012414932251,-13999.73828125,3.23606465617697E-5,1.52285608504272E-8,1,4,13.4005146026611,5.00548525621752,30.4499994963407,0.0403014626074496,0.00591284006740546,1,-9.11517855893402E-8,,,,,,,,,,,,,,,,,,,,,50.0116691589355,50.0131607055664,-13999.73828125,-13999.73828125,53.3383301523133,5.64446889454904,4.79499578475952,54,1,0,0,1,0.30242919921875,33.7243423461914,1,1,3,50.0116691589355,0,50.012414932251,,,,,,,,,,,,,,,,,,,,,,,,,,,,,,,,,
,3883326733.91059,50.0951271057129,-14999.560546875,4.84348121767512E-5,2.66553802382544E-8,1,4,13.4005146026611,5.00549206306151,30.4499994963407,0.060307229802846,0.00893592408882051,1,-6.73094194577337E-8,,,,,,,,,,,,,,,,,,,,,50.0942993164063,50.0959548950195,-14999.560546875,-14999.560546875,53.536863796198,5.64436932430114,4.79178762435913,54,1,0,0,1,0.304107666015625,33.7243423461914,1,1,3,50.0942993164063,0,50.0951271057129,,,,,,,,,,,,,,,,,,,,,,,,,,,,,,,,,
,3883326833.66032,50.0279922485352,-24999.744140625,2.10238586016768E-4,6.00531701412294E-8,1,4,13.4005146026611,5.0055148648089,30.4499994963407,0.261740929135682,0.0390108290189881,1,-1.1314434591904E-7,,,,,,,,,,,,,,,,,,,,,50.0249900817871,50.0309944152832,-24999.744140625,-24999.744140625,53.3324679384191,5.64401341716762,4.7925968170166,48,1,100,0,0,0.302581787109375,33.2355842590332,1,1,3,50.0309944152832,0,50.0279922485352,,,,,,,,,,,,,,,,,,,,,,,,,,,,,,,,,
,3883326947.69075,50.0422325134277,-34999.62890625,3.73186246970984E-4,6.34323896631205E-8,1,4,13.4005146026611,5.00548918465868,30.4499994963407,0.464577314645434,0.0694157739486449,1,-6.45320905868914E-8,,,,,,,,,,,,,,,,,,,,,50.0362014770508,50.0482635498047,-34999.62890625,-34999.62890625,53.3758483212364,5.64453540922513,4.79761219024658,32,1,100,0,0,0.301513671875,33.2355842590332,1,1,3,50.0482635498047,0,50.0422325134277,,,,,,,,,,,,,,,,,,,,,,,,,,,,,,,,,
,3883327061.66581,50.0067234039307,-44999.5625,5.36232656253856E-4,5.15911095972897E-8,1,4,13.4005146026611,5.00539506632919,30.4499994963407,0.667501026165292,0.0999699796782051,1,9.10962252132855E-8,,,,,,,,,,,,,,,,,,,,,50.006664276123,50.0067825317383,-44999.5625,-44999.5625,53.2754090565153,5.64490036423043,4.80306339263916,54,1,0,0,1,0.303573608398438,32.7468223571777,1,1,3,50.006664276123,0,50.0067234039307,,,,,,,,,,,,,,,,,,,,,,,,,,,,,,,,,
,3883327149.26088,50.0303726196289,-54999.671875,6.9953065383518E-4,7.56407125750423E-8,1,4,13.4005146026611,5.00545181261474,30.4499994963407,0.870740394422501,0.13073233389111,1,3.73167968835222E-7,,,,,,,,,,,,,,,,,,,,,50.0286445617676,50.0321006774902,-54999.671875,-54999.671875,53.3918717058807,5.64520158544597,4.79730033874512,54,1,0,0,1,0.303497314453125,33.7243423461914,1,1,3,50.0286445617676,0,50.0303726196289,,,,,,,,,,,,,,,,,,,,,,,,,,,,,,,,,
,3883327250.25382,50.0027503967285,-64999.8046875,8.6295694892861E-4,1.82855159943484E-7,1,4,13.4005146026611,5.00555202586382,30.4499994963407,1.07423563007683,0.161009012002559,1,2.43550791624125E-7,,,,,,,,,,,,,,,,,,,,,50.0022659301758,50.0032348632812,-64999.8046875,-64999.8046875,53.3223067676691,5.64426618172082,4.79699039459229,54,1,0,0,1,0.303878784179687,33.2355842590332,1,1,3,50.0032348632812,0,50.0027503967285,,,,,,,,,,,,,,,,,,,,,,,,,,,,,,,,,
,3883327337.80267,50.0507106781006,-64999.65625,8.62626584043659E-4,1.95672892127354E-7,1,4,13.4005146026611,5.00549906019751,30.4499994963407,1.07374617530909,0.161361573345718,1,5.78097491200355E-7,,,,,,,,,,,,,,,,,,,,,50.0416526794434,50.0597686767578,-64999.65625,-64999.65625,53.3758483212364,5.64473574215871,4.80223178863525,54,1,0,0,1,0.301666259765625,33.2355842590332,1,1,3,50.0597686767578,0,50.0507106781006,,,,,,,,,,,,,,,,,,,,,,,,,,,,,,,,,
,3883327439.01988,50.026481628418,-54999.54296875,6.99165249072052E-4,1.08326851881551E-7,1,4,13.4005146026611,5.0053549849751,30.4499994963407,0.870551921889413,0.128722557167567,100,-1.18384717214538E-6,,,,,,,,,,,,,,,,,,,,,50.0224952697754,50.0304679870605,-54999.54296875,-54999.54296875,53.3926533343999,5.64514179905723,4.79808568954468,54,1,0,0,1,0.300674438476562,33.7243423461914,1,1,3,50.0304679870605,0,50.026481628418,,,,,,,,,,,,,,,,,,,,,,,,,,,,,,,,,
,3883327552.18945,50.0118141174316,-44999.53515625,5.35896692226458E-4,8.27828772707959E-8,1,4,13.4005146026611,5.00531377384892,30.4499994963407,0.667199473011008,0.099024000050944,10,-6.16766353449492E-7,,,,,,,,,,,,,,,,,,,,,50.0100479125977,50.0135803222656,-44999.53515625,-44999.53515625,53.318398625073,5.6450859291504,4.80466270446777,54,1,0,0,1,0.302276611328125,33.7243423461914,1,1,3,50.0135803222656,0,50.0118141174316,,,,,,,,,,,,,,,,,,,,,,,,,,,,,,,,,
,3883327653.05733,50.057674407959,-34999.71875,3.81338207527908E-4,2.05243268434159E-5,1,4,13.4005146026611,5.00529145713295,30.4499994963407,0.472358286964029,0.0865781118771597,10,1.25063675673813E-5,,,,,,,,,,,,,,,,,,,,,50.0507774353027,50.0645713806152,-34999.71875,-34999.71875,53.4688621150249,5.64427712174461,4.8026237487793,54,1,0,0,1,0.302047729492188,33.7243423461914,1,1,3,50.0645713806152,0,50.057674407959,,,,,,,,,,,,,,,,,,,,,,,,,,,,,,,,,
,3883327753.24217,50.0483493804932,-24999.732421875,2.09536414692396E-4,4.49449058789824E-8,1,4,13.4005146026611,5.00545838349605,30.4499994963407,0.260877292288339,0.0387819116378819,10,-1.91500764736616E-7,,,,,,,,,,,,,,,,,,,,,50.039924621582,50.0567741394043,-24999.732421875,-24999.732421875,53.4430683738903,5.64440879735633,4.80591058731079,54,1,0,0,1,0.302352905273438,33.7243423461914,1,1,3,50.0572471618652,0,50.0483493804932,,,,,,,,,,,,,,,,,,,,,,,,,,,,,,,,,
,3883327865.16279,50.009801864624,-14999.673828125,4.75267565810871E-5,2.77988903451506E-8,1,4,13.4005146026611,5.00538672277447,30.4499994963407,0.0591624101600818,0.00885128460285199,10,7.48331938342358E-10,,,,,,,,,,,,,,,,,,,,,50.0093078613281,50.0102958679199,-14999.673828125,-14999.673828125,53.5349097248999,5.64471097788991,4.81303977966309,54,1,0,0,1,0.30242919921875,33.2355842590332,1,1,3,50.0093078613281,0,50.009801864624,,,,,,,,,,,,,,,,,,,,,,,,,,,,,,,,,
,3883327939.75484,50.0473384857178,-13999.939453125,3.14848535487005E-5,2.35066690726329E-8,1,4,13.4005146026611,5.00542310140137,30.4499994963407,0.0391884178118032,0.00589754016140527,1,2.76532571120686E-8,,,,,,,,,,,,,,,,,,,,,50.0403709411621,50.0543060302734,-13999.939453125,-13999.939453125,53.3938257771787,5.64487310121333,4.80598402023315,54,1,0,0,1,0.301132202148438,33.7243423461914,1,1,3,50.0543060302734,0,50.0473384857178,,,,,,,,,,,,,,,,,,,,,,,,,,,,,,,,,
,3883327980.15388,50.0331993103027,-13000.205078125,1.55066306747133E-5,3.72973428258785E-8,1,4,13.4005146026611,5.00528669008341,30.4499994963407,0.0192947762880353,0.00293930271752592,1,4.15849649785172E-8,,,,,,,,,,,,,,,,,,,,,50.0301818847656,50.0362167358398,-13000.205078125,-13000.205078125,53.498173184496,5.64344742830959,4.80784368515015,54,1,0,0,1,0.301742553710937,32.7468223571777,1,1,3,50.0301818847656,0,50.0331993103027,,,,,,,,,,,,,,,,,,,,,,,,,,,,,,,,,
,3883328018.8484,50.0512599945068,-12000.1064453125,-4.02431869785764E-7,2.79103116517621E-8,1,4,13.4005146026611,5.00534125441836,30.4499994963407,-5.08131625317732E-4,-2.69407859601918E-5,1,3.85588469065492E-8,,,,,,,,,,,,,,,,,,,,,50.04541015625,50.0571098327637,-12000.1064453125,-12000.1064453125,53.2871334843037,5.64394002655207,4.81388759613037,53,1,32,0,0,0.3009033203125,33.7243423461914,1,1,3,50.0571098327637,0,50.0512599945068,,,,,,,,,,,,,,,,,,,,,,,,,,,,,,,,,
,3883328059.63771,50.0622539520264,-11000.0703125,-1.62465948029787E-5,2.16014646973476E-8,1,4,13.4005146026611,5.00528441193466,30.4499994963407,-0.0202377222684354,-0.00293097688316462,1,7.57961510160183E-8,,,,,,,,,,,,,,,,,,,,,50.0609817504883,50.0635261535645,-11000.0703125,-11000.0703125,53.3989063625537,5.64468206738775,4.80485391616821,54,1,0,0,1,0.301055908203125,33.7243423461914,1,1,3,50.0635261535645,0,50.0622539520264,,,,,,,,,,,,,,,,,,,,,,,,,,,,,,,,,
,3883328100.55554,50.0411472320557,-10000.2734375,-3.19976892730258E-5,2.68945129134672E-8,1,4,13.4005146026611,5.00540289292222,30.4499994963407,-0.0398451322624749,-0.00586906121089615,1,7.19148131135943E-8,,,,,,,,,,,,,,,,,,,,,50.0375709533691,50.0447235107422,-10000.2734375,-10000.2734375,53.411803233121,5.64386447153568,4.81259918212891,52,1,32,0,0,0.302047729492188,33.7243423461914,1,1,3,50.0375709533691,0,50.0411472320557,,,,,,,,,,,,,,,,,,,,,,,,,,,,,,,,,
,3883328139.98791,50.0697956085205,-9000.3876953125,-4.75340343827955E-5,2.18370600966554E-8,1,4,13.4005146026611,5.00536983912672,30.4499994963407,-0.0591916802192717,-0.0087156301950726,1,1.09281938777863E-7,,,,,,,,,,,,,,,,,,,,,50.0694389343262,50.0701522827148,-9000.3876953125,-9000.3876953125,53.3484913230633,5.64425392347602,4.81693458557129,54,1,0,0,1,0.3045654296875,33.7243423461914,1,1,3,50.0701522827148,0,50.0697956085205,,,,,,,,,,,,,,,,,,,,,,,,,,,,,,,,,
,3883328180.96124,50.0585689544678,-8000.35205078125,-6.29141227342242E-5,2.16202370955168E-8,1,4,13.4005146026611,5.00528319381807,30.4499994963407,-0.0783357522831398,-0.0115758986299298,1,1.12087286113775E-7,,,,,,,,,,,,,,,,,,,,,50.0562210083008,50.0609169006348,-8000.35205078125,-8000.35205078125,53.3875727490249,5.64426350190717,4.80429172515869,54,1,0,0,1,0.302200317382812,34.2131004333496,1,1,3,50.0562210083008,0,50.0585689544678,,,,,,,,,,,,,,,,,,,,,,,,,,,,,,,,,
,3883328220.2983,50.058162689209,-7000.34130859375,-7.79552958247743E-5,2.45633198256961E-8,1,4,13.4005146026611,5.00534907987434,30.4499994963407,-0.0970630175160847,-0.0143611507314524,1,1.24839077902798E-7,,,,,,,,,,,,,,,,,,,,,50.0577583312988,50.0585670471191,-7000.34130859375,-7000.34130859375,53.3176169965537,5.64423592896158,4.81398391723633,54,1,0,0,1,0.303955078125,33.7243423461914,1,1,3,50.0577583312988,0,50.058162689209,,,,,,,,,,,,,,,,,,,,,,,,,,,,,,,,,
,3883328262.37915,50.0293006896973,-6000.3681640625,-9.25152274270534E-5,2.1251616534914E-8,1,4,13.4005146026611,5.00526777572808,30.4499994963407,-0.115188979917502,-0.0170440798690281,1,1.4731738860175E-7,,,,,,,,,,,,,,,,,,,,,50.0292625427246,50.0293388366699,-6000.3681640625,-6000.3681640625,53.4039869479287,5.64331010175227,4.81123447418213,54,1,0,0,1,0.303802490234375,33.7243423461914,1,1,3,50.0292625427246,0,50.0293006896973,,,,,,,,,,,,,,,,,,,,,,,,,,,,,,,,,
,3883328303.369,50.0431518554687,-5000.43212890625,-1.06272633800384E-4,1.69320035921996E-8,1,4,13.4005146026611,5.00534923218235,30.4499994963407,-0.132312980482529,-0.0196331993061787,1,1.25726027758931E-7,,,,,,,,,,,,,,,,,,,,,50.0414810180664,50.0448226928711,-5000.43212890625,-5000.43212890625,53.4254817322076,5.64297697257851,4.80700349807739,52,1,68,0,0,0.303726196289063,34.2131004333496,1,1,3,50.0414810180664,0,50.0431518554687,,,,,,,,,,,,,,,,,,,,,,,,,,,,,,,,,
,3883328343.84356,50.0374507904053,-4000.3583984375,-1.18565061160154E-4,1.64454150913379E-8,1,4,13.4005146026611,5.00533430999828,30.4499994963407,-0.147615281051816,-0.0219145307793073,1,1.31854210295461E-7,,,,,,,,,,,,,,,,,,,,,50.033805847168,50.0410957336426,-4000.3583984375,-4000.3583984375,53.4141481186787,5.64457864825984,4.8099160194397,53,1,68,0,0,0.303497314453125,33.7243423461914,1,1,3,50.0410957336426,0,50.0374507904053,,,,,,,,,,,,,,,,,,,,,,,,,,,,,,,,,
,3883328384.35402,50.0379257202148,-3000.28466796875,-1.27558647956602E-4,2.00769578275784E-8,1,4,13.4005146026611,5.00532419498191,30.4499994963407,-0.158810411697747,-0.0235872629870088,1,1.3341854425071E-7,,,,,,,,,,,,,,,,,,,,,50.0357971191406,50.0400543212891,-3000.28466796875,-3000.28466796875,53.4121940473807,5.64335152667205,4.80739212036133,52,1,68,0,0,0.3021240234375,33.7243423461914,1,1,3,50.0400543212891,0,50.0379257202148,,,,,,,,,,,,,,,,,,,,,,,,,,,,,,,,,
,3883328445.3851,50.0390548706055,-2510.462890625,-1.29808917023444E-4,1.50762065500406E-8,1,4,13.4005146026611,5.00526644795862,30.4499994963407,-0.161606722046748,-0.0240207982612826,1,1.21457800001882E-7,,,,,,,,,,,,,,,,,,,,,50.0388526916504,50.0392570495605,-2510.462890625,-2510.462890625,53.3645147077076,5.64376685764383,4.81732797622681,54,1,0,0,1,0.30364990234375,33.7243423461914,1,1,3,50.0388526916504,0,50.0390548706055,,,,,,,,,,,,,,,,,,,,,,,,,,,,,,,,,
,3883328486.03088,50.0868110656738,-1930.42150878906,-1.29121056824111E-4,1.43795579989939E-8,1,4,13.4005146026611,5.00523607742479,30.4499994963407,-0.160750237881815,-0.0238850382801869,1,1.27458395536939E-7,,,,,,,,,,,,,,,,,,,,,50.0813789367676,50.0922431945801,-1930.42150878906,-1930.42150878906,53.2859610415249,5.64418962218977,4.81703948974609,54,1,0,0,1,0.303802490234375,33.2355842590332,1,1,3,50.0922431945801,0,50.0868110656738,,,,,,,,,,,,,,,,,,,,,,,,,,,,,,,,,
,3883328524.34718,50.1139907836914,-1350.2666015625,-1.2224216271346E-4,1.40822327059651E-8,1,4,13.4005146026611,5.00522423088761,30.4499994963407,-0.152184991803124,-0.0226179153081469,1,1.16312495808758E-7,,,,,,,,,,,,,,,,,,,,,50.113208770752,50.1147727966309,-1350.2666015625,-1350.2666015625,53.4426775596307,5.64453795481909,4.81748533248901,54,1,0,0,1,0.304641723632812,33.2355842590332,1,1,3,50.1147727966309,0,50.1139907836914,,,,,,,,,,,,,,,,,,,,,,,,,,,,,,,,,
,3883328563.64682,50.0834617614746,-770.388610839844,-1.03248872199925E-4,1.14908947514379E-8,1,4,13.4005146026611,5.00536269013606,30.4499994963407,-0.128542632049502,-0.0191157447349816,1,8.91362096437092E-8,,,,,,,,,,,,,,,,,,,,,50.079044342041,50.0878791809082,-770.388610839844,-770.388610839844,53.4837130568903,5.6439253761637,4.81303691864014,54,1,0,0,1,0.303878784179687,33.7243423461914,1,1,3,50.079044342041,0,50.0834617614746,,,,,,,,,,,,,,,,,,,,,,,,,,,,,,,,,
,3883328603.76735,50.0188865661621,-190.321823120117,-5.44421594305229E-5,9.02412694764606E-9,1,4,13.4005146026611,5.00531027771228,30.4499994963407,-0.067782577501862,-0.0100510026302454,1,6.98173935095561E-8,,,,,,,,,,,,,,,,,,,,,50.0182723999023,50.0195007324219,-190.321823120117,-190.321823120117,53.3953890342172,5.64318249512422,4.81863689422607,54,1,0,0,1,0.304107666015625,34.2131004333496,1,1,3,50.0182723999023,0,50.0188865661621,,,,,,,,,,,,,,,,,,,,,,,,,,,,,,,,,
,3883328642.78454,50.0179653167725,389.858245849609,5.59784307343699E-5,1.62224280362616E-8,1,4,13.4005146026611,5.00518070339855,30.4499994963407,0.0696783691308215,0.0104305267995134,1,5.55699366703425E-9,,,,,,,,,,,,,,,,,,,,,50.0168190002441,50.0191116333008,389.858245849609,389.858245849609,53.4559652444576,5.64271507448975,4.81117010116577,54,1,0,0,1,0.3033447265625,33.2355842590332,1,1,3,50.0168190002441,0,50.0179653167725,,,,,,,,,,,,,,,,,,,,,,,,,,,,,,,,,
,3883328682.18161,50.0086479187012,969.534790039063,1.03412983979027E-4,5.17854940884837E-8,1,4,13.4005146026611,5.00522922287306,30.4499994963407,0.128736041556984,0.0191862293540801,1,-5.6489165960349E-8,,,,,,,,,,,,,,,,,,,,,50.008373260498,50.0089225769043,969.534790039063,969.534790039063,53.4262633607268,5.6435621416119,4.80950784683228,54,1,0,0,1,0.301589965820313,33.7243423461914,1,1,3,50.008373260498,0,50.0086479187012,,,,,,,,,,,,,,,,,,,,,,,,,,,,,,,,,
,3883328721.7406,50.0144195556641,1549.58898925781,1.21469078758949E-4,6.21764803984953E-8,1,4,13.4005146026611,5.00530691414731,30.4499994963407,0.151230450385101,0.0224458894684579,1,-1.3927936835408E-7,,,,,,,,,,,,,,,,,,,,,50.0144195556641,50.0144195556641,1549.58898925781,1549.58898925781,53.4966099274576,5.64295936028957,4.81738328933716,54,1,0,0,1,0.302047729492188,33.2355842590332,1,1,3,50.0144195556641,0,50.0144195556641,,,,,,,,,,,,,,,,,,,,,,,,,,,,,,,,,
,3883328762.21757,50.0067481994629,2129.69360351562,1.27549276768348E-4,2.31864464648682E-8,1,4,13.4005146026611,5.00517541760674,30.4499994963407,0.158781577502325,0.0236551856811389,1,-7.66618313726223E-8,,,,,,,,,,,,,,,,,,,,,50.006275177002,50.0072212219238,2129.69360351562,2129.69360351562,53.3746758784576,5.64310192327609,4.8093695640564,54,1,0,0,1,0.3033447265625,33.2355842590332,1,1,3,50.0062599182129,0,50.0067481994629,,,,,,,,,,,,,,,,,,,,,,,,,,,,,,,,,
,3883328802.26032,50.0336112976074,2709.4833984375,1.27473577840191E-4,1.8506492437761E-8,1,4,13.4005146026611,5.00509586937352,30.4499994963407,0.158686487973975,0.0236227583078633,1,-9.09672076768703E-8,,,,,,,,,,,,,,,,,,,,,50.0309753417969,50.036247253418,2709.4833984375,2709.4833984375,53.5016905128326,5.64426665458684,4.81194972991943,54,1,0,0,1,0.3033447265625,33.2355842590332,1,1,3,50.036247253418,0,50.0336112976074,,,,,,,,,,,,,,,,,,,,,,,,,,,,,,,,,
,3883328859.45482,50.0355014801025,3499.4970703125,1.22377550200183E-4,1.46075309665229E-8,1,4,13.4005146026611,5.00510843120724,30.4499994963407,0.152344844383621,0.0226674252824423,1,-9.62020611707292E-8,,,,,,,,,,,,,,,,,,,,,50.0350685119629,50.0359344482422,3499.4970703125,3499.4970703125,53.4172746327557,5.64400115338802,4.81610822677612,54,1,0,0,1,0.303268432617188,33.7243423461914,1,1,3,50.0342903137207,0,50.0355014801025,,,,,,,,,,,,,,,,,,,,,,,,,,,,,,,,,
,3883328913.93058,50.0094661712646,4499.81005859375,1.11553285442696E-4,2.00059474203773E-8,1,4,13.4005146026611,5.00518167013207,30.4499994963407,0.138868990804709,0.0206885258199131,1,-6.71218735215586E-8,,,,,,,,,,,,,,,,,,,,,50.0086517333984,50.0102806091309,4499.81005859375,4499.81005859375,53.4411143025922,5.64349320480487,4.81888675689697,54,1,0,0,1,0.30181884765625,33.2355842590332,1,1,3,50.0086517333984,0,50.0094661712646,,,,,,,,,,,,,,,,,,,,,,,,,,,,,,,,,
,3883328955.16409,50.0137844085693,5499.7080078125,9.84891176699166E-5,2.08740848683218E-8,1,4,13.4005146026611,5.00517958017158,30.4499994963407,0.122605534346287,0.0182672229836603,1,-5.79988535602862E-8,,,,,,,,,,,,,,,,,,,,,50.0126724243164,50.0148963928223,5499.7080078125,5499.7080078125,53.4723794433614,5.64380616184653,4.81054449081421,54,1,0,0,1,0.303955078125,33.7243423461914,1,1,3,50.0149536132812,0,50.0137844085693,,,,,,,,,,,,,,,,,,,,,,,,,,,,,,,,,
,3883328996.72053,50.068286895752,6499.75634765625,8.43075613977405E-5,2.12030575882146E-8,1,4,13.4005146026611,5.00499915170519,30.4499994963407,0.104943896502119,0.0156511023172551,1,-3.76083312866154E-8,,,,,,,,,,,,,,,,,,,,,50.0615921020508,50.0749816894531,6499.75634765625,6499.75634765625,53.4188378897941,5.64394205648634,4.8106803894043,54,1,0,0,1,0.302963256835937,33.7243423461914,1,1,3,50.0749816894531,0,50.068286895752,,,,,,,,,,,,,,,,,,,,,,,,,,,,,,,,,
,3883329037.99902,50.0659675598145,7499.74267578125,6.94914958771508E-5,2.07600646003801E-8,1,4,13.4005146026611,5.00508306923313,30.4499994963407,0.0865008863049195,0.0129168094200788,1,-1.8223253886397E-8,,,,,,,,,,,,,,,,,,,,,50.0628623962402,50.0690727233887,7499.74267578125,7499.74267578125,53.4895752707845,5.6443380451806,4.82270431518555,54,1,0,0,1,0.304336547851562,33.7243423461914,1,1,3,50.0690727233887,0,50.0659675598145,,,,,,,,,,,,,,,,,,,,,,,,,,,,,,,,,
,3883329079.17287,50.088996887207,8499.6025390625,5.42599441598057E-5,2.35436096906615E-8,1,4,13.4005146026611,5.00504974581481,30.4499994963407,0.0675382101082408,0.0101007627783576,1,-1.99402673921494E-9,,,,,,,,,,,,,,,,,,,,,50.0826263427734,50.0953674316406,8499.6025390625,8499.6025390625,53.4790232857749,5.64358621674881,4.82094669342041,54,1,0,0,1,0.302963256835937,33.2355842590332,1,1,3,50.0953674316406,0,50.088996887207,,,,,,,,,,,,,,,,,,,,,,,,,,,,,,,,,
,3883329119.6994,50.0990467071533,9499.701171875,3.88228022874752E-5,2.12144627785442E-8,1,4,13.4005146026611,5.00501687593053,30.4499994963407,0.0483174477230514,0.0072635207427746,1,2.7918803114055E-8,,,,,,,,,,,,,,,,,,,,,50.098087310791,50.1000061035156,9499.701171875,9499.701171875,53.4622182726114,5.64388600769135,4.81303691864014,52,1,68,0,0,0.304336547851562,33.7243423461914,1,1,3,50.098087310791,0,50.0990467071533,,,,,,,,,,,,,,,,,,,,,,,,,,,,,,,,,
,3883329159.61217,50.0551929473877,10499.6240234375,2.3192413604735E-5,2.54095944179031E-8,1,4,13.4005146026611,5.00504376774044,30.4499994963407,0.0288592514420567,0.00437529543083603,1,4.56788533318166E-8,,,,,,,,,,,,,,,,,,,,,50.0539360046387,50.0564498901367,10499.6240234375,10499.6240234375,53.447367330746,5.64367080113163,4.82004642486572,53,1,68,0,0,0.304107666015625,33.2355842590332,1,1,3,50.056453704834,0,50.0551929473877,,,,,,,,,,,,,,,,,,,,,,,,,,,,,,,,,
,3883329199.66896,50.0485153198242,11499.8994140625,7.39357014851045E-6,3.12634671476712E-8,1,4,13.4005146026611,5.00502699337624,30.4499994963407,0.00919391143818019,0.00143599443429206,1,4.76536461231655E-8,,,,,,,,,,,,,,,,,,,,,50.046012878418,50.0510177612305,11499.8994140625,11499.8994140625,53.4508846590826,5.64389238885005,4.81359434127808,52,1,68,0,0,0.3021240234375,33.7243423461914,1,1,3,50.046012878418,0,50.0485153198242,,,,,,,,,,,,,,,,,,,,,,,,,,,,,,,,,
,3883329239.77139,50.0276432037354,12499.708984375,-8.4127371299154E-6,2.17958774147697E-8,1,4,13.4005146026611,5.00505692356461,30.4499994963407,-0.0104841238386614,-0.00148160818684912,1,6.81710601615786E-8,,,,,,,,,,,,,,,,,,,,,50.0262260437012,50.0290603637695,12499.708984375,12499.708984375,53.4024236908903,5.64319653165629,4.81881189346313,54,1,0,0,1,0.302963256835937,33.7243423461914,1,1,3,50.0262260437012,0,50.0276432037354,,,,,,,,,,,,,,,,,,,,,,,,,,,,,,,,,
,3883329279.70078,50.0988426208496,13499.99609375,-2.43622504071433E-5,2.91546748287997E-8,1,4,13.4005146026611,5.00496418014128,30.4499994963407,-0.0303402054349968,-0.00442239421085064,1,9.14032655784047E-8,,,,,,,,,,,,,,,,,,,,,50.0930213928223,50.104663848877,13499.99609375,13499.99609375,53.5153690119191,5.64394288078563,4.81128454208374,52,1,68,0,0,0.302658081054687,33.7243423461914,1,1,3,50.104663848877,0,50.0988426208496,,,,,,,,,,,,,,,,,,,,,,,,,,,,,,,,,
,3883329333.27395,50.1498775482178,14499.8701171875,-4.04239268129293E-5,3.1627034021595E-8,1,4,13.4005146026611,5.00499712338633,30.4499994963407,-0.0503351411666054,-0.00739411770219106,1,1.06644133506227E-7,,,,,,,,,,,,,,,,,,,,,50.1463737487793,50.1533813476562,14499.8701171875,14499.8701171875,53.4211827753518,5.64298545522834,4.82062292098999,46,1,100,0,0,0.304336547851562,33.2355842590332,1,1,3,50.1533813476562,0,50.1498775482178,,,,,,,,,,,,,,,,,,,,,,,,,,,,,,,,,
,3883329411.11566,50.0292015075684,19999.79296875,-1.29042244412592E-4,3.46830994172354E-8,1,4,13.4005146026611,5.00503925821586,30.4499994963407,-0.160643013771704,-0.0238709656238735,1,1.25919378744236E-7,,,,,,,,,,,,,,,,,,,,,50.028881072998,50.0295219421387,19999.79296875,19999.79296875,53.3109731541403,5.64448051902029,4.82253456115723,54,1,0,0,1,0.30181884765625,33.2355842590332,1,1,3,50.028881072998,0,50.0292015075684,,,,,,,,,,,,,,,,,,,,,,,,,,,,,,,,,
,3883329517.76744,50.0575752258301,30000.341796875,-2.93922404132683E-4,5.26659801791324E-6,1,4,13.4005146026611,5.00511002800774,30.4499994963407,-0.365104286272759,-0.0597412537529935,10,-4.02637264979979E-6,,,,,,,,,,,,,,,,,,,,,50.0487289428711,50.0664215087891,30000.341796875,30000.341796875,53.3949982199576,5.64407511074245,4.81336641311646,54,1,0,0,1,0.3033447265625,33.7243423461914,1,1,3,50.0664215087891,0,50.0575752258301,,,,,,,,,,,,,,,,,,,,,,,,,,,,,,,,,
,3883329630.6879,50.0415344238281,40000.44140625,-4.71521804061209E-4,1.62444224619777E-5,1,4,13.4005146026611,5.00499840138941,30.4499994963407,-0.582909274912945,-0.114466832891259,10,-2.14272901061182E-5,,,,,,,,,,,,,,,,,,,,,50.0364265441895,50.0466423034668,40000.44140625,40000.44140625,53.3957798484768,5.64385514077277,4.82267284393311,52,1,68,0,0,0.30303955078125,33.2355842590332,1,1,3,50.0466423034668,0,50.0415344238281,,,,,,,,,,,,,,,,,,,,,,,,,,,,,,,,,
,3883329729.99063,50.0724258422852,50000.23046875,-5.74058967005843E-4,4.67934656357742E-5,1,4,13.4005146026611,5.00502440430667,30.4499994963407,-0.710942064401966,-0.130882564880617,1000,-1.92761971173778E-5,,,,,,,,,,,,,,,,,,,,,50.0720634460449,50.0727882385254,50000.23046875,50000.23046875,53.4645631581691,5.64448052649542,4.81967926025391,54,1,0,0,1,0.305099487304687,33.7243423461914,1,1,3,50.0719795227051,0,50.0724258422852,,,,,,,,,,,,,,,,,,,,,,,,,,,,,,,,,
,3883329835.70467,50.0650196075439,60000.21875,-8.06350922303799E-4,6.17663715942087E-5,1,4,13.4005146026611,5.00496464965909,30.4499994963407,-0.992567747497196,-0.224210907863153,10,-5.95103416958062E-5,,,,,,,,,,,,,,,,,,,,,50.059871673584,50.0701675415039,60000.21875,60000.21875,53.399687991073,5.6446077881828,4.81462240219116,48,1,68,0,0,0.30242919921875,33.7243423461914,1,1,3,50.0701675415039,0,50.0650196075439,,,,,,,,,,,,,,,,,,,,,,,,,,,,,,,,,
,3883329948.73766,50.0645427703857,70000.4453125,-9.54258732084595E-4,3.88111578957665E-5,1,4,13.4005146026611,5.00490177012194,30.4499994963407,-1.18508473334112,-0.195327886591143,10,-1.41818113733611E-5,,,,,,,,,,,,,,,,,,,,,50.0625228881836,50.0665626525879,70000.4453125,70000.4453125,53.3117547826595,5.64481709854243,4.81938362121582,54,1,0,0,1,0.303878784179687,33.2355842590332,1,1,3,50.0665626525879,0,50.0645427703857,,,,,,,,,,,,,,,,,,,,,,,,,,,,,,,,,
,3883329952.81107,50.0665321350098,70000.4453125,-9.36469115670586E-4,1.63646264556931E-5,1,4,13.4005146026611,5.0049103548279,30.4499994963407,-1.16901134300338,-0.151467585175125,10,1.83961154320796E-5,,,,,,,,,,,,,,,,,,,,,50.0664405822754,50.0666236877441,70000.4453125,70000.4453125,53.2840069702268,5.64470144819373,4.82252311706543,54,2,0,0,1,0.303115844726562,33.2355842590332,1,1,3,50.0663642883301,0,50.0665321350098,,,,,,,,,,,,,,,,,,,,,,,,,,,,,,,,,