File: SQUID/Reference/LSAT/A1/LSAT_subs_MT_FC_p0.5T.csv
Comment,Time Stamp (sec),Temperature (K),Magnetic Field (Oe),Moment (emu),M. Std. Err. (emu),Transport Action,Averaging Time (sec),Frequency (Hz),Peak Amplitude (mm),Center Position (mm),Lockin Signal' (V),Lockin Signal (V),Range,M. Quad. Signal (emu),AC Moment (emu),AC M. Std Err. (emu),AC Phase (deg),AC Phase Std. Err. (deg),AC Susceptibility (emu/Oe),AC Suscept. Std Err. (emu/Oe),AC X' (emu/Oe),AC X' Std Err. (emu/Oe),AC X'' (emu/Oe),AC X'' Std Err. (emu/Oe),AC Drive (Oe),AC Frequency (Hz),AC Averaging Time (sec),AC Cycles,AC Range,AC Measure Type,AC Signal' (V),AC Signal'' (V),AC Trim Coil Ratio,AC Trim Coil Phase,Min. Temperature (K),Max. Temperature (K),Min. Field (Oe),Max. Field (Oe),Mass (grams),Motor Lag (deg),Pressure (Torr),Measure Count,Measurement Number,SQUID Status (code),Motor Status (code),Measure Status (code),Motor Current (amps),Motor Temp. (C),Temp. Status (code),Field Status (code),Chamber Status (code),Chamber Temp (K),Redirection State,Average Temp (K),Rotation Angle (deg),Rotator state,DC Moment Fixed Ctr (emu),DC Moment Err Fixed Ctr (emu),DC Moment Free Ctr (emu),DC Moment Err Free Ctr (emu),DC Fixed Fit,DC Free Fit,DC Calculated Center (mm),DC Calculated Center Err (mm),DC Scan Length (mm),DC Scan Time (s),DC Number of Points,DC Squid Drift,DC Min V (V),DC Max V (V),DC Scans per Measure,Map 01,Map 02,Map 03,Map 04,Map 05,Map 06,Map 07,Map 08,Map 09,Map 10,Map 11,Map 12,Map 13,Map 14,Map 15,Map 16
,3883202242.31754,399.987030029297,4999.48876953125,-8.42744497961651E-5,1.26781580876275E-8,1,4,13.4005146026611,5.00894293712212,30.57000041008,-0.105030746407752,-0.0155786949819137,1,1.04602316475001E-7,,,,,,,,,,,,,,,,,,,,,399.986419677734,399.987640380859,4999.48876953125,4999.48876953125,53.4215735896114,5.62152592412548,4.87145853042603,54,1,0,0,1,0.302658081054687,32.7468223571777,1,1,3,399.987640380859,0,399.987030029297,,,,,,,,,,,,,,,,,,,,,,,,,,,,,,,,,
,3883202293.25501,397.457244873047,4999.48876953125,-8.42594476205821E-5,9.62984327908901E-9,1,4,13.4005146026611,5.00889295695947,30.57000041008,-0.105013010709605,-0.0155594884498711,1,1.17597726565201E-7,,,,,,,,,,,,,,,,,,,,,397.308502197266,397.605987548828,4999.48876953125,4999.48876953125,53.5388178674961,5.63691153955033,4.90660285949707,54,1,0,0,1,0.302886962890625,33.2355842590332,2,1,3,397.296173095703,0,397.457244873047,,,,,,,,,,,,,,,,,,,,,,,,,,,,,,,,,
,3883202345.65224,392.789794921875,4999.48876953125,-8.42843778193644E-5,1.75574872957679E-8,1,4,13.4005146026611,5.00876543482993,30.5499993264675,-0.105042855471122,-0.0155467482711337,1,1.31107666571763E-7,,,,,,,,,,,,,,,,,,,,,392.625335693359,392.954254150391,4999.48876953125,4999.48876953125,53.5243577398903,5.63690376119942,4.93556547164917,54,1,0,0,1,0.298385620117188,33.2355842590332,2,1,3,392.625335693359,0,392.789794921875,,,,,,,,,,,,,,,,,,,,,,,,,,,,,,,,,
,3883202398.01692,388.157135009766,4999.48876953125,-8.42733703798946E-5,1.40379338293944E-8,1,4,13.4005146026611,5.00869380229677,30.5499993264675,-0.105027644992134,-0.0155403476837608,1,1.3434863113184E-7,,,,,,,,,,,,,,,,,,,,,387.970886230469,388.343383789063,4999.48876953125,4999.48876953125,53.5313923965634,5.63732036121426,4.96745777130127,54,1,0,0,1,0.297698974609375,33.7243423461914,2,1,3,387.970886230469,0,388.157135009766,,,,,,,,,,,,,,,,,,,,,,,,,,,,,,,,,
,3883202450.39669,383.868423461914,4999.48876953125,-8.42538654132625E-5,1.44328271386348E-8,1,4,13.4005146026611,5.00867347426176,30.5499993264675,-0.105003429544851,-0.0155320591148731,1,1.38012368323885E-7,,,,,,,,,,,,,,,,,,,,,383.7099609375,384.026885986328,4999.48876953125,4999.48876953125,53.518495525996,5.63785203872472,4.99473285675049,54,1,0,0,1,0.301513671875,33.7243423461914,2,1,3,383.7099609375,0,383.868423461914,,,,,,,,,,,,,,,,,,,,,,,,,,,,,,,,,
,3883202502.79277,379.757720947266,4999.48876953125,-8.42701238412463E-5,1.10192222698548E-8,1,4,13.4005146026611,5.00861816451049,30.5300001055002,-0.10502325064888,-0.0155269316590796,1,1.44367432376704E-7,,,,,,,,,,,,,,,,,,,,,379.586669921875,379.928771972656,4999.48876953125,4999.48876953125,53.4243092894287,5.63738384410932,5.00901174545288,54,1,0,0,1,0.304183959960937,32.7468223571777,2,1,3,379.586669921875,0,379.757720947266,,,,,,,,,,,,,,,,,,,,,,,,,,,,,,,,,
,3883202555.19728,375.531036376953,4999.48876953125,-8.42732500838239E-5,1.36136942400284E-8,1,4,13.4005146026611,5.00832928543915,30.5300001055002,-0.10501651499909,-0.0155407316053604,1,1.32753714288509E-7,,,,,,,,,,,,,,,,,,,,,375.407653808594,375.654418945313,4999.48876953125,4999.48876953125,53.5040353983903,5.63888894351783,5.02885913848877,54,1,0,0,1,0.303955078125,33.7243423461914,2,1,3,375.407653808594,0,375.531036376953,,,,,,,,,,,,,,,,,,,,,,,,,,,,,,,,,
,3883202608.13409,371.169738769531,4999.48876953125,-8.42715939204797E-5,1.28896007114546E-8,1,4,13.4005146026611,5.0080117425791,30.5100008845329,-0.105005681445985,-0.0155354626595656,1,1.3563001005298E-7,,,,,,,,,,,,,,,,,,,,,371.022491455078,371.316986083984,4999.48876953125,4999.48876953125,53.5489790382461,5.6395710819692,5.03724527359009,53,1,64,0,0,0.297393798828125,33.7243423461914,2,1,3,371.022491455078,0,371.169738769531,,,,,,,,,,,,,,,,,,,,,,,,,,,,,,,,,
,3883202659.99803,366.902893066406,4999.48876953125,-8.42669709074168E-5,1.31383132226336E-8,1,4,13.4005146026611,5.00793561240154,30.5100008845329,-0.104998116343237,-0.0155314297854933,1,1.37910848518178E-7,,,,,,,,,,,,,,,,,,,,,366.738555908203,367.067230224609,4999.48876953125,4999.48876953125,53.5055986554287,5.64013265827604,5.04043960571289,54,1,0,0,1,0.2978515625,33.7243423461914,2,1,3,366.738555908203,0,366.902893066406,,,,,,,,,,,,,,,,,,,,,,,,,,,,,,,,,
,3883202712.3193,362.542037963867,4999.48876953125,-8.42603046717446E-5,1.12226579305738E-8,1,4,13.4005146026611,5.00790574638445,30.5100008845329,-0.104990250570803,-0.0155212767420826,1,1.4496014646252E-7,,,,,,,,,,,,,,,,,,,,,362.342132568359,362.741943359375,4999.48876953125,4999.48876953125,53.5075527267268,5.6401698301143,5.04462814331055,54,1,0,0,1,0.29754638671875,33.7243423461914,2,1,3,362.342132568359,0,362.542037963867,,,,,,,,,,,,,,,,,,,,,,,,,,,,,,,,,
,3883202764.75113,358.113494873047,4999.48876953125,-8.42546703630946E-5,9.82118860305029E-9,1,4,13.4005146026611,5.00790776480232,30.4899998009205,-0.104981279427837,-0.015533682729523,1,1.34165281309133E-7,,,,,,,,,,,,,,,,,,,,,357.920715332031,358.306274414063,4999.48876953125,4999.48876953125,53.513414940621,5.63990406789117,5.05524826049805,54,1,0,0,1,0.299072265625,34.2131004333496,2,1,3,357.920715332031,0,358.113494873047,,,,,,,,,,,,,,,,,,,,,,,,,,,,,,,,,
,3883202817.15644,353.847229003906,4999.48876953125,-8.42422209872943E-5,1.05455932836046E-8,1,4,13.4005146026611,5.00788047367945,30.4899998009205,-0.10496629786079,-0.0155223790351709,1,1.41282163026564E-7,,,,,,,,,,,,,,,,,,,,,353.714721679687,353.979736328125,4999.48876953125,4999.48876953125,53.5009088843133,5.63979545229876,5.05624866485596,53,1,64,0,0,0.298995971679687,33.7243423461914,2,1,3,353.714721679687,0,353.847229003906,,,,,,,,,,,,,,,,,,,,,,,,,,,,,,,,,
,3883202869.46942,349.524917602539,4999.48876953125,-8.42411607155216E-5,1.24712316682938E-8,1,4,13.4005146026611,5.00786469993919,30.4799992591143,-0.104964484800476,-0.0155223146934072,1,1.41120342603821E-7,,,,,,,,,,,,,,,,,,,,,349.340728759766,349.709106445313,4999.48876953125,4999.48876953125,53.4461948879672,5.63985541778583,5.06083011627197,54,1,0,0,1,0.297927856445313,34.2131004333496,2,1,3,349.340728759766,0,349.524917602539,,,,,,,,,,,,,,,,,,,,,,,,,,,,,,,,,
,3883202921.8582,345.079727172852,4999.48876953125,-8.42310528027794E-5,9.86359989941419E-9,1,4,13.4005146026611,5.0079240083843,30.4799992591143,-0.104952523718131,-0.0155280891409861,1,1.35179062455537E-7,,,,,,,,,,,,,,,,,,,,,344.924285888672,345.235168457031,4999.48876953125,4999.48876953125,53.4418959311114,5.63912131328574,5.06361055374146,54,1,0,0,1,0.29815673828125,34.2131004333496,2,1,3,344.924285888672,0,345.079727172852,,,,,,,,,,,,,,,,,,,,,,,,,,,,,,,,,
,3883202974.27476,340.794067382812,4999.48876953125,-8.42242324414335E-5,1.02439614336196E-8,1,4,13.4005146026611,5.00788147876025,30.460000038147,-0.104942773390832,-0.0155266899921149,1,1.35133995146262E-7,,,,,,,,,,,,,,,,,,,,,340.654907226562,340.933227539063,4999.48876953125,4999.48876953125,53.5720370795634,5.63952329603834,5.06184339523315,54,1,0,0,1,0.298614501953125,33.7243423461914,2,1,3,340.654907226562,0,340.794067382812,,,,,,,,,,,,,,,,,,,,,,,,,,,,,,,,,
,3883203026.62935,336.432647705078,4999.48876953125,-8.42191660476145E-5,1.3248318419876E-8,1,4,13.4005146026611,5.00792339609802,30.460000038147,-0.10493933919966,-0.0155149027119415,1,1.43984234484603E-7,,,,,,,,,,,,,,,,,,,,,336.251220703125,336.614074707031,4999.48876953125,4999.48876953125,53.5231852971114,5.63916140711601,5.05974531173706,54,1,0,0,1,0.304183959960937,33.7243423461914,2,1,3,336.251220703125,0,336.432647705078,,,,,,,,,,,,,,,,,,,,,,,,,,,,,,,,,
,3883203079.02702,332.050674438477,4999.48876953125,-8.42001885536397E-5,9.80078634122278E-9,1,4,13.4005146026611,5.00798972200649,30.460000038147,-0.104916585286006,-0.0155187107279969,1,1.38319027896861E-7,,,,,,,,,,,,,,,,,,,,,331.909851074219,332.191497802734,4999.48876953125,4999.48876953125,53.4106307903422,5.63901829795524,5.060378074646,54,1,0,0,1,0.299072265625,33.7243423461914,2,1,3,331.909851074219,0,332.050674438477,,,,,,,,,,,,,,,,,,,,,,,,,,,,,,,,,
,3883203131.39512,327.648193359375,4999.48876953125,-8.41919678641758E-5,7.9908750826462E-9,1,4,13.4005146026611,5.00795934625568,30.4400008171797,-0.104907115782457,-0.0155059460198681,1,1.47230492525078E-7,,,,,,,,,,,,,,,,,,,,,327.495483398438,327.800903320313,4999.48876953125,4999.48876953125,53.5536688093614,5.63905192700772,5.06188535690308,54,1,0,0,1,0.29876708984375,34.2131004333496,2,1,3,327.495483398438,0,327.648193359375,,,,,,,,,,,,,,,,,,,,,,,,,,,,,,,,,
,3883203183.81418,323.371597290039,4999.48876953125,-8.41785758856628E-5,8.33254636613718E-9,1,4,13.4005146026611,5.0080335538167,30.4400008171797,-0.104892876797103,-0.0155019586468368,1,1.48685729248826E-7,,,,,,,,,,,,,,,,,,,,,323.232025146484,323.511169433594,4999.48876953125,4999.48876953125,53.3719401786402,5.63821193732089,5.05951976776123,54,1,0,0,1,0.305709838867188,34.2131004333496,2,1,3,323.232025146484,0,323.371597290039,,,,,,,,,,,,,,,,,,,,,,,,,,,,,,,,,
,3883203236.15444,318.961318969727,4999.48876953125,-8.41583729541202E-5,9.20562176852686E-9,1,4,13.4005146026611,5.00801252577147,30.4400008171797,-0.104868099096345,-0.0154913812372509,1,1.54081331570957E-7,,,,,,,,,,,,,,,,,,,,,318.789428710937,319.133209228516,4999.48876953125,4999.48876953125,53.5181047117364,5.63805170095708,5.06455087661743,54,1,0,0,1,0.299301147460937,33.7243423461914,2,1,3,318.789428710937,0,318.961318969727,,,,,,,,,,,,,,,,,,,,,,,,,,,,,,,,,
,3883203288.53038,314.412979125977,4999.48876953125,-8.41502616982214E-5,1.37237158809666E-8,1,4,13.4005146026611,5.00797386519222,30.4199997335672,-0.104855744538241,-0.0154971800688467,1,1.4807877049487E-7,,,,,,,,,,,,,,,,,,,,,314.210906982422,314.615051269531,4999.48876953125,4999.48876953125,53.5567953234384,5.63762494517684,5.05992317199707,54,1,0,0,1,0.29815673828125,33.7243423461914,2,1,3,314.210906982422,0,314.412979125977,,,,,,,,,,,,,,,,,,,,,,,,,,,,,,,,,
,3883203340.93481,309.970260620117,4999.48876953125,-8.41260453869807E-5,1.34128144841855E-8,1,4,13.4005146026611,5.00803091395638,30.4199997335672,-0.104825988752129,-0.0155013234960882,1,1.41328177489202E-7,,,,,,,,,,,,,,,,,,,,,309.805358886719,310.135162353516,4999.48876953125,4999.48876953125,53.4841038711499,5.63840575801798,5.06468677520752,54,1,0,0,1,0.304718017578125,34.2131004333496,2,1,3,309.805358886719,0,309.970260620117,,,,,,,,,,,,,,,,,,,,,,,,,,,,,,,,,
,3883203393.33004,305.605758666992,4999.48876953125,-8.41134065720946E-5,1.03928643755304E-8,1,4,13.4005146026611,5.00805997839079,30.4199997335672,-0.104811489532857,-0.0154964513219681,1,1.43449446909613E-7,,,,,,,,,,,,,,,,,,,,,305.432830810547,305.778686523438,4999.48876953125,4999.48876953125,53.5943134923614,5.63810911391288,5.05324840545654,54,1,0,0,1,0.2984619140625,33.7243423461914,2,1,3,305.432830810547,0,305.605758666992,,,,,,,,,,,,,,,,,,,,,,,,,,,,,,,,,
,3883203445.72562,301.109039306641,4999.48876953125,-8.40925064263529E-5,9.75724529407113E-9,1,4,13.4005146026611,5.00806751666133,30.4000005125999,-0.104789198635323,-0.0154690244308784,1,1.62365306601962E-7,,,,,,,,,,,,,,,,,,,,,300.941467285156,301.276611328125,4999.48876953125,4999.48876953125,53.516541454698,5.63853846422475,5.03401803970337,54,1,0,0,1,0.297470092773438,34.2131004333496,2,1,3,300.941467285156,0,301.109039306641,,,,,,,,,,,,,,,,,,,,,,,,,,,,,,,,,
,3883203498.13127,296.756378173828,4999.48876953125,-8.40678963810669E-5,1.18423778111288E-8,1,4,13.4005146026611,5.00807929827745,30.4000005125999,-0.104757792944438,-0.0154717887224524,1,1.5650567075377E-7,,,,,,,,,,,,,,,,,,,,,296.594085693359,296.918670654297,4999.48876953125,4999.48876953125,53.5122424978422,5.63840455554551,5.02148962020874,54,1,0,0,1,0.298233032226562,33.7243423461914,2,1,3,296.594085693359,0,296.756378173828,,,,,,,,,,,,,,,,,,,,,,,,,,,,,,,,,
,3883203551.07271,292.321212768555,4999.48876953125,-8.40207669034764E-5,1.27002226623264E-8,1,4,13.4005146026611,5.0080749371097,30.3899999707937,-0.104698811218457,-0.0154639371985959,1,1.55742867060854E-7,,,,,,,,,,,,,,,,,,,,,292.166778564453,292.475646972656,4999.48876953125,4999.48876953125,53.5196679687749,5.63828785269731,5.00789451599121,52,1,64,0,0,0.298233032226562,34.2131004333496,2,1,3,292.166778564453,0,292.321212768555,,,,,,,,,,,,,,,,,,,,,,,,,,,,,,,,,
,3883203602.84744,288.006286621094,4999.48876953125,-8.40207688788468E-5,1.03116145979203E-8,1,4,13.4005146026611,5.00808819979715,30.3899999707937,-0.104697938647344,-0.0154724348859245,1,1.48967853680445E-7,,,,,,,,,,,,,,,,,,,,,287.853271484375,288.159301757813,4999.48876953125,4999.48876953125,53.5329556536018,5.63849214664875,4.99292278289795,54,1,0,0,1,0.297698974609375,34.2131004333496,2,1,3,287.853271484375,0,288.006286621094,,,,,,,,,,,,,,,,,,,,,,,,,,,,,,,,,
,3883203655.46046,283.590103149414,4999.48876953125,-8.4015551462228E-5,8.19772538588487E-9,1,4,13.4005146026611,5.00807349348802,30.3799994289875,-0.10468332778878,-0.0155227479538623,1,1.07748947042911E-7,,,,,,,,,,,,,,,,,,,,,283.468109130859,283.712097167969,4999.48876953125,4999.48876953125,53.5001272557941,5.63917549020407,4.97427845001221,54,1,0,0,1,0.30487060546875,33.7243423461914,2,1,3,283.468109130859,0,283.590103149414,,,,,,,,,,,,,,,,,,,,,,,,,,,,,,,,,
,3883203707.61617,279.353744506836,4999.48876953125,-8.40135467959583E-5,1.11002578843664E-8,1,4,13.4005146026611,5.00810025827651,30.3799994289875,-0.104685155364692,-0.0154988065599504,1,1.26760293894013E-7,,,,,,,,,,,,,,,,,,,,,279.192779541016,279.514709472656,4999.48876953125,4999.48876953125,53.5958767493999,5.63883450318699,4.95847368240356,54,1,0,0,1,0.298233032226562,33.7243423461914,2,1,3,279.192779541016,0,279.353744506836,,,,,,,,,,,,,,,,,,,,,,,,,,,,,,,,,
,3883203760.03418,274.953674316406,4999.48876953125,-8.39938469727812E-5,1.19652592202963E-8,1,4,13.4005146026611,5.00802434156333,30.3600002080202,-0.104660634542217,-0.0154798453069853,1,1.38770546689885E-7,,,,,,,,,,,,,,,,,,,,,274.801483154297,275.105865478516,4999.48876953125,4999.48876953125,53.4966099274576,5.6392543142454,4.93684434890747,54,1,0,0,1,0.297317504882812,34.2131004333496,2,1,3,274.801483154297,0,274.953674316406,,,,,,,,,,,,,,,,,,,,,,,,,,,,,,,,,
,3883203812.41986,270.560989379883,4999.48876953125,-8.39690743214977E-5,1.11663076359164E-8,1,4,13.4005146026611,5.00798915111044,30.3600002080202,-0.104628099767475,-0.0154794002316277,1,1.35299942623582E-7,,,,,,,,,,,,,,,,,,,,,270.390350341797,270.731628417969,4999.48876953125,4999.48876953125,53.493092599121,5.63889662657797,4.92852067947388,54,1,0,0,1,0.297927856445313,33.2355842590332,2,1,3,270.390350341797,0,270.560989379883,,,,,,,,,,,,,,,,,,,,,,,,,,,,,,,,,
,3883203864.84692,266.217376708984,4999.48876953125,-8.39798032143428E-5,1.17069326735317E-8,1,4,13.4005146026611,5.00799370260659,30.3600002080202,-0.104638581762687,-0.0155015822069674,1,1.19114335418915E-7,,,,,,,,,,,,,,,,,,,,,266.086273193359,266.348480224609,4999.48876953125,4999.48876953125,53.5278750682268,5.63909089130019,4.91141319274902,54,1,0,0,1,0.297317504882812,34.2131004333496,2,1,3,266.086273193359,0,266.217376708984,,,,,,,,,,,,,,,,,,,,,,,,,,,,,,,,,
,3883203917.16525,261.908554077148,4999.48876953125,-8.39683343615334E-5,1.16079970677185E-8,1,4,13.4005146026611,5.00793913723486,30.3399991244078,-0.104627084869779,-0.0154699054572074,1,1.42637745589702E-7,,,,,,,,,,,,,,,,,,,,,261.756927490234,262.060180664062,4999.48876953125,4999.48876953125,53.5181047117364,5.63931973433514,4.90056991577148,54,1,0,0,1,0.297775268554687,34.2131004333496,2,1,3,261.746032714844,0,261.908554077148,,,,,,,,,,,,,,,,,,,,,,,,,,,,,,,,,
,3883203969.56466,257.486679077148,4999.48876953125,-8.39560841065707E-5,1.39031229216528E-8,1,4,13.4005146026611,5.00801266661596,30.3399991244078,-0.104612595840995,-0.0154771359450987,1,1.35255866274529E-7,,,,,,,,,,,,,,,,,,,,,257.326141357422,257.647216796875,4999.48876953125,4999.48876953125,53.5247485541499,5.63890089878033,4.88670015335083,54,1,0,0,1,0.30487060546875,33.7243423461914,2,1,3,257.326141357422,0,257.486679077148,,,,,,,,,,,,,,,,,,,,,,,,,,,,,,,,,
,3883204021.97861,253.134689331055,4999.48876953125,-8.39530743883542E-5,9.09631241886719E-9,1,4,13.4005146026611,5.00794206967087,30.3399991244078,-0.104609463024428,-0.0154583702153356,1,1.49625050498682E-7,,,,,,,,,,,,,,,,,,,,,252.943862915039,253.32551574707,4999.48876953125,4999.48876953125,53.4430683738903,5.63915984137998,4.8685474395752,54,1,0,0,1,0.298538208007812,34.2131004333496,2,1,3,252.943862915039,0,253.134689331055,,,,,,,,,,,,,,,,,,,,,,,,,,,,,,,,,
,3883204074.31179,248.77278137207,4999.48876953125,-8.39359538863382E-5,9.98575887657818E-9,1,4,13.4005146026611,5.00785212255817,30.3399991244078,-0.104584379516106,-0.0154623490922774,1,1.43558251306641E-7,,,,,,,,,,,,,,,,,,,,,248.610244750977,248.935317993164,4999.48876953125,4999.48876953125,53.5208404115537,5.63945298732055,4.85739088058472,54,1,0,0,1,0.2984619140625,34.2131004333496,2,1,3,248.610244750977,0,248.77278137207,,,,,,,,,,,,,,,,,,,,,,,,,,,,,,,,,
,3883204126.83313,244.395317077637,4999.48876953125,-8.39331450153242E-5,1.21853641877289E-8,1,4,13.4005146026611,5.00793663836623,30.3199999034405,-0.104580114947517,-0.0154838000320001,1,1.26211059812134E-7,,,,,,,,,,,,,,,,,,,,,244.224319458008,244.566314697266,4999.48876953125,4999.48876953125,53.5079435409864,5.63947434092297,4.85185146331787,53,1,64,0,0,0.298004150390625,34.2131004333496,2,1,3,244.224319458008,0,244.395317077637,,,,,,,,,,,,,,,,,,,,,,,,,,,,,,,,,
,3883204179.10254,240.036865234375,4999.48876953125,-8.39212613198863E-5,1.06057161443257E-8,1,4,13.4005146026611,5.00792673191703,30.3199999034405,-0.104565761586265,-0.0154765997402818,1,1.3017903737752E-7,,,,,,,,,,,,,,,,,,,,,239.873794555664,240.199935913086,4999.48876953125,4999.48876953125,53.4286082462845,5.63943687976872,4.83940935134888,54,1,0,0,1,0.2972412109375,33.7243423461914,2,1,3,239.873794555664,0,240.036865234375,,,,,,,,,,,,,,,,,,,,,,,,,,,,,,,,,
,3883204231.45241,235.657257080078,4999.48876953125,-8.38998855497542E-5,1.07242618532238E-8,1,4,13.4005146026611,5.0079601741257,30.3199999034405,-0.104543456218984,-0.0154503878798404,1,1.48138836785529E-7,,,,,,,,,,,,,,,,,,,,,235.484252929687,235.830261230469,4999.48876953125,4999.48876953125,53.4692529292845,5.6396475017085,4.82065057754517,54,1,0,0,1,0.297470092773438,35.190616607666,2,1,3,235.484252929687,0,235.657257080078,,,,,,,,,,,,,,,,,,,,,,,,,,,,,,,,,
,3883204283.85515,231.300071716309,4999.48876953125,-8.3911684434992E-5,9.9020383290148E-9,1,4,13.4005146026611,5.00792058666171,30.3000006824732,-0.104554093268052,-0.0154718403585784,1,1.32545710753188E-7,,,,,,,,,,,,,,,,,,,,,231.147613525391,231.452529907227,4999.48876953125,4999.48876953125,53.5145873833999,5.63933555207043,4.81556510925293,54,1,0,0,1,0.298538208007812,33.7243423461914,2,1,3,231.147613525391,0,231.300071716309,,,,,,,,,,,,,,,,,,,,,,,,,,,,,,,,,
,3883204336.21965,226.993141174316,4999.48876953125,-8.38940705866076E-5,1.02846223547147E-8,1,4,13.4005146026611,5.00790520212291,30.3000006824732,-0.104533707141399,-0.0154550924029873,1,1.43302048330035E-7,,,,,,,,,,,,,,,,,,,,,226.822723388672,227.163558959961,4999.48876953125,4999.48876953125,53.4770692144768,5.63960716306624,4.79611778259277,54,1,0,0,1,0.30548095703125,33.7243423461914,2,1,3,226.822723388672,0,226.993141174316,,,,,,,,,,,,,,,,,,,,,,,,,,,,,,,,,
,3883204388.65579,222.616386413574,4999.48876953125,-8.38872358004541E-5,9.35786999861081E-9,1,4,13.4005146026611,5.00784259682972,30.3000006824732,-0.104521767615661,-0.0154642372121527,1,1.34721588182935E-7,,,,,,,,,,,,,,,,,,,,,222.452255249023,222.780517578125,4999.48876953125,4999.48876953125,53.3426291091691,5.63945963765443,4.78754997253418,54,1,0,0,1,0.306243896484375,33.7243423461914,2,1,3,222.452255249023,0,222.616386413574,,,,,,,,,,,,,,,,,,,,,,,,,,,,,,,,,
,3883204441.00566,218.23705291748,4999.48876953125,-8.38728484600474E-5,1.17193843744861E-8,1,4,13.4005146026611,5.00783969184499,30.3000006824732,-0.104505151421617,-0.0154522480396684,1,1.42183872025563E-7,,,,,,,,,,,,,,,,,,,,,218.06608581543,218.408020019531,4999.48876953125,4999.48876953125,53.4610458298326,5.63906752107074,4.77110433578491,54,1,0,0,1,0.305709838867188,33.7243423461914,2,1,3,218.06608581543,0,218.23705291748,,,,,,,,,,,,,,,,,,,,,,,,,,,,,,,,,
,3883204493.38218,213.918083190918,4999.48876953125,-8.38758627326271E-5,1.09486835209448E-8,1,4,13.4005146026611,5.00783997214278,30.2799995988607,-0.104511047044623,-0.0154385548102728,1,1.53628339906244E-7,,,,,,,,,,,,,,,,,,,,,213.779449462891,214.056716918945,4999.48876953125,4999.48876953125,53.5634391658518,5.63954414966591,4.75896120071411,54,1,0,0,1,0.299301147460937,33.7243423461914,2,1,3,213.779449462891,0,213.918083190918,,,,,,,,,,,,,,,,,,,,,,,,,,,,,,,,,
,3883204545.77332,209.605751037598,4999.48876953125,-8.38285437422971E-5,1.09897274760099E-8,1,4,13.4005146026611,5.00784742527792,30.2799995988607,-0.104451572612505,-0.015434765696347,1,1.49617292439976E-7,,,,,,,,,,,,,,,,,,,,,209.403823852539,209.807678222656,4999.48876953125,4999.48876953125,53.5110700550634,5.63890871165894,4.74215364456177,54,1,0,0,1,0.29754638671875,33.7243423461914,2,1,3,209.403823852539,0,209.605751037598,,,,,,,,,,,,,,,,,,,,,,,,,,,,,,,,,
,3883204598.2156,205.230751037598,4999.48876953125,-8.38367560687165E-5,9.52241841899862E-9,1,4,13.4005146026611,5.00780034272406,30.2799995988607,-0.104452263981994,-0.0154906794239341,1,1.05796336388532E-7,,,,,,,,,,,,,,,,,,,,,205.087585449219,205.373916625977,4999.48876953125,4999.48876953125,53.5493698525057,5.63989352654671,4.73088455200195,53,1,64,0,0,0.299758911132812,33.7243423461914,2,1,3,205.087585449219,0,205.230751037598,,,,,,,,,,,,,,,,,,,,,,,,,,,,,,,,,
,3883204650.56758,200.826354980469,4999.48876953125,-8.38427390007279E-5,9.13124731105823E-9,1,4,13.4005146026611,5.00791847912418,30.2600003778934,-0.10446887489353,-0.0154541107131724,1,1.36457194652518E-7,,,,,,,,,,,,,,,,,,,,,200.663558959961,200.989151000977,4999.48876953125,4999.48876953125,53.5282658824864,5.63870270156862,4.71669960021973,54,1,0,0,1,0.297927856445313,33.7243423461914,2,1,3,200.663558959961,0,200.826354980469,,,,,,,,,,,,,,,,,,,,,,,,,,,,,,,,,
,3883204702.96787,196.475799560547,4999.48876953125,-8.38239046638721E-5,1.05854851404895E-8,1,4,13.4005146026611,5.00782977322797,30.2600003778934,-0.104444861330689,-0.0154366184485388,1,1.4737491816341E-7,,,,,,,,,,,,,,,,,,,,,196.303741455078,196.647857666016,4999.48876953125,4999.48876953125,53.452447916121,5.63925072824856,4.70519924163818,54,1,0,0,1,0.305938720703125,33.7243423461914,2,1,3,196.303741455078,0,196.475799560547,,,,,,,,,,,,,,,,,,,,,,,,,,,,,,,,,
,3883204755.30657,192.081619262695,4999.48876953125,-8.38160875333209E-5,9.04949060751755E-9,1,4,13.4005146026611,5.00767009708035,30.2600003778934,-0.104426023012577,-0.0154641949153633,1,1.23514441963058E-7,,,,,,,,,,,,,,,,,,,,,191.911895751953,192.251342773438,4999.48876953125,4999.48876953125,53.5294383252653,5.63940371451401,4.69246768951416,54,1,0,0,1,0.298080444335937,33.7243423461914,2,1,3,191.911895751953,0,192.081619262695,,,,,,,,,,,,,,,,,,,,,,,,,,,,,,,,,
,3883204807.86042,187.765144348145,4999.48876953125,-8.38022667528466E-5,1.14836395239071E-8,1,4,13.4005146026611,5.00757267149587,30.2499998360872,-0.104407163510882,-0.0154532083323395,1,1.29929714388398E-7,,,,,,,,,,,,,,,,,,,,,187.544815063477,187.985473632813,4999.48876953125,4999.48876953125,53.5196679687749,5.64005175156962,4.67636060714722,54,1,0,0,1,0.299224853515625,34.2131004333496,2,1,3,187.535552978516,0,187.765144348145,,,,,,,,,,,,,,,,,,,,,,,,,,,,,,,,,
,3883204860.07255,183.400581359863,4999.48876953125,-8.37964121643747E-5,1.03683666546516E-8,1,4,13.4005146026611,5.00756557103538,30.2499998360872,-0.104399576569203,-0.0154526725120802,1,1.29459489540596E-7,,,,,,,,,,,,,,,,,,,,,183.270660400391,183.530502319336,4999.48876953125,4999.48876953125,53.5274842539672,5.64022835974969,4.64176845550537,54,1,0,0,1,0.298004150390625,33.7243423461914,2,1,3,183.270660400391,0,183.400581359863,,,,,,,,,,,,,,,,,,,,,,,,,,,,,,,,,
,3883204912.52548,178.97566986084,4999.48876953125,-8.37774339515004E-5,1.10088986853379E-8,1,4,13.4005146026611,5.00747662325325,30.239999294281,-0.104375668453682,-0.0154332275248734,1,1.41923952023721E-7,,,,,,,,,,,,,,,,,,,,,178.808547973633,179.142791748047,4999.48876953125,4999.48876953125,53.3746758784576,5.64052624334511,4.63059759140015,54,1,0,0,1,0.297164916992188,33.7243423461914,2,1,3,178.808547973633,0,178.97566986084,,,,,,,,,,,,,,,,,,,,,,,,,,,,,,,,,
,3883204964.89785,174.648880004883,4999.48876953125,-8.37565174186214E-5,9.78432052018739E-9,1,4,13.4005146026611,5.0074343170168,30.239999294281,-0.104350490217497,-0.0154150645638405,1,1.53231050769721E-7,,,,,,,,,,,,,,,,,,,,,174.500396728516,174.79736328125,4999.48876953125,4999.48876953125,53.5270934397076,5.64039895288385,4.62041139602661,54,1,0,0,1,0.29937744140625,34.2131004333496,2,1,3,174.500396728516,0,174.648880004883,,,,,,,,,,,,,,,,,,,,,,,,,,,,,,,,,
,3883205017.23602,170.313301086426,4999.48876953125,-8.37573895563768E-5,9.95827398499442E-9,1,4,13.4005146026611,5.00739656287338,30.2200000733137,-0.104349985845983,-0.0154183457208345,1,1.50596719742154E-7,,,,,,,,,,,,,,,,,,,,,170.141586303711,170.485015869141,4999.48876953125,4999.48876953125,53.4114124188614,5.6400773657589,4.60577583312988,54,1,0,0,1,0.298919677734375,33.7243423461914,2,1,3,170.141586303711,0,170.313301086426,,,,,,,,,,,,,,,,,,,,,,,,,,,,,,,,,
,3883205069.63491,165.919639587402,4999.48876953125,-8.37137072221839E-5,1.1291988798843E-8,1,4,13.4005146026611,5.00750286293965,30.2200000733137,-0.104297311710475,-0.0154197665509485,1,1.43288735502842E-7,,,,,,,,,,,,,,,,,,,,,165.754638671875,166.08464050293,4999.48876953125,4999.48876953125,53.5517147380633,5.64073507993078,4.59092044830322,54,1,0,0,1,0.299072265625,33.7243423461914,2,1,3,165.754638671875,0,165.919639587402,,,,,,,,,,,,,,,,,,,,,,,,,,,,,,,,,
,3883205122.00775,161.580383300781,4999.48876953125,-8.37004267818495E-5,1.09008303470638E-8,1,4,13.4005146026611,5.00746507372502,30.2200000733137,-0.104280766310083,-0.0154098010430022,1,1.49172363961693E-7,,,,,,,,,,,,,,,,,,,,,161.403091430664,161.757675170898,4999.48876953125,4999.48876953125,53.5247485541499,5.64113106838679,4.57935428619385,54,1,0,0,1,0.299072265625,34.2131004333496,2,1,3,161.403091430664,0,161.580383300781,,,,,,,,,,,,,,,,,,,,,,,,,,,,,,,,,
,3883205174.46898,157.208534240723,4999.48876953125,-8.36868624804717E-5,1.27174587329003E-8,1,4,13.4005146026611,5.00741566999914,30.2200000733137,-0.104263211152272,-0.015401861767219,1,1.53346804790043E-7,,,,,,,,,,,,,,,,,,,,,157.05680847168,157.360260009766,4999.48876953125,4999.48876953125,53.5759452221595,5.64106971414868,4.56728506088257,54,1,0,0,1,0.2984619140625,33.7243423461914,2,1,3,157.05680847168,0,157.208534240723,,,,,,,,,,,,,,,,,,,,,,,,,,,,,,,,,
,3883205227.32728,152.808135986328,4999.48876953125,-8.36711299806056E-5,1.39788461715245E-8,1,4,13.4005146026611,5.00739076240982,30.2000008523464,-0.104242902338857,-0.0153987474772298,1,1.53407724077197E-7,,,,,,,,,,,,,,,,,,,,,152.687728881836,152.92854309082,4999.48876953125,4999.48876953125,53.4567468729768,5.64384535826098,4.55581426620483,52,1,64,0,0,0.297393798828125,33.7243423461914,2,1,3,152.687728881836,0,152.808135986328,,,,,,,,,,,,,,,,,,,,,,,,,,,,,,,,,
,3883205279.15481,148.566184997559,4999.48876953125,-8.36581721652728E-5,1.04301154209507E-8,1,4,13.4005146026611,5.00735899041913,30.2000008523464,-0.104227999066133,-0.0153817545325042,1,1.65002996571409E-7,,,,,,,,,,,,,,,,,,,,,148.414306640625,148.718063354492,4999.48876953125,4999.48876953125,53.457528501496,5.64127563817162,4.54838228225708,54,1,0,0,1,0.29815673828125,34.2131004333496,2,1,3,148.414306640625,0,148.566184997559,,,,,,,,,,,,,,,,,,,,,,,,,,,,,,,,,
,3883205331.57134,144.104179382324,4999.48876953125,-8.36582974250069E-5,9.99340956794765E-9,1,4,13.4005146026611,5.00727636570588,30.2000008523464,-0.104224902005123,-0.0153870978377924,1,1.60446718309889E-7,,,,,,,,,,,,,,,,,,,,,143.953903198242,144.254455566406,4999.48876953125,4999.48876953125,53.5138057548807,5.64225038171465,4.53367710113525,54,1,0,0,1,0.299224853515625,34.2131004333496,2,1,3,143.953903198242,0,144.104179382324,,,,,,,,,,,,,,,,,,,,,,,,,,,,,,,,,
,3883205383.92311,139.805267333984,4999.48876953125,-8.36601944309152E-5,8.42544785024288E-9,1,4,13.4005146026611,5.00718134359417,30.2000008523464,-0.104223170881027,-0.0153959261941969,1,1.53314267027336E-7,,,,,,,,,,,,,,,,,,,,,139.648773193359,139.961761474609,4999.48876953125,4999.48876953125,53.3441923662076,5.64251063838949,4.52291393280029,54,1,0,0,1,0.299072265625,33.7243423461914,2,1,3,139.648773193359,0,139.805267333984,,,,,,,,,,,,,,,,,,,,,,,,,,,,,,,,,
,3883205436.31727,135.410171508789,4999.48876953125,-8.36311173491336E-5,1.08010311634226E-8,1,4,13.4005146026611,5.00708207117297,30.2000008523464,-0.104184112865505,-0.0153897904258777,1,1.53548574432629E-7,,,,,,,,,,,,,,,,,,,,,135.257080078125,135.563262939453,4999.48876953125,4999.48876953125,53.4043777621883,5.64272259404439,4.50989055633545,54,1,0,0,1,0.299911499023438,33.7243423461914,2,1,3,135.24560546875,0,135.410171508789,,,,,,,,,,,,,,,,,,,,,,,,,,,,,,,,,
,3883205488.76142,131.05110168457,4999.48876953125,-8.36118323547105E-5,1.10721575682682E-8,1,4,13.4005146026611,5.00712891969852,30.179999768734,-0.104160570924983,-0.0153923248895358,1,1.48790278955522E-7,,,,,,,,,,,,,,,,,,,,,130.866928100586,131.235275268555,4999.48876953125,4999.48876953125,53.4934834133807,5.6424324902323,4.49279499053955,54,1,0,0,1,0.300521850585937,32.7468223571777,2,1,3,130.866928100586,0,131.05110168457,,,,,,,,,,,,,,,,,,,,,,,,,,,,,,,,,
,3883205541.07065,126.800228118896,4999.48876953125,-8.35806739421808E-5,1.03946889251232E-8,1,4,13.4005146026611,5.00702355534551,30.179999768734,-0.104116317105507,-0.0154020115742453,1,1.35987596200252E-7,,,,,,,,,,,,,,,,,,,,,126.637718200684,126.962738037109,4999.48876953125,4999.48876953125,53.5325648393422,5.6428823078161,4.47835826873779,54,1,0,0,1,0.299148559570313,33.7243423461914,2,1,3,126.637718200684,0,126.800228118896,,,,,,,,,,,,,,,,,,,,,,,,,,,,,,,,,
,3883205593.60494,122.293655395508,4999.48876953125,-8.35479417255309E-5,9.52967224444643E-9,1,4,13.4005146026611,5.00698261967387,30.179999768734,-0.104067394085076,-0.0154423233098294,1,9.85807121538323E-8,,,,,,,,,,,,,,,,,,,,,122.100257873535,122.48705291748,4999.48876953125,4999.48876953125,53.5005180700537,5.64280282352589,4.46982479095459,53,1,64,0,0,0.298995971679687,33.7243423461914,2,1,3,122.100257873535,0,122.293655395508,,,,,,,,,,,,,,,,,,,,,,,,,,,,,,,,,
,3883205645.86598,117.935585021973,4999.48876953125,-8.35231481551853E-5,9.93573878516553E-9,1,4,13.4005146026611,5.00701338752463,30.179999768734,-0.1040375965257,-0.0154365924784185,1,9.95798954958003E-8,,,,,,,,,,,,,,,,,,,,,117.778160095215,118.09300994873,4999.48876953125,4999.48876953125,53.4360337172172,5.64270361020281,4.45176792144775,54,1,0,0,1,0.299606323242188,33.7243423461914,2,1,3,117.778160095215,0,117.935585021973,,,,,,,,,,,,,,,,,,,,,,,,,,,,,,,,,
,3883205698.23904,113.615390777588,4999.48876953125,-8.34837914989893E-5,1.17077514442028E-8,1,4,13.4005146026611,5.00702482342068,30.179999768734,-0.10399560544666,-0.0153845793745132,1,1.35496275050112E-7,,,,,,,,,,,,,,,,,,,,,113.425117492676,113.8056640625,4999.48876953125,4999.48876953125,53.4696437435441,5.64280719551104,4.43541431427002,54,1,0,0,1,0.299148559570313,35.190616607666,2,1,3,113.425117492676,0,113.615390777588,,,,,,,,,,,,,,,,,,,,,,,,,,,,,,,,,
,3883205750.67839,109.230266571045,4999.48876953125,-8.34627081660594E-5,9.01561099604615E-9,1,4,13.4005146026611,5.00698001449585,30.1600005477667,-0.103969919325914,-0.0153679470962189,1,1.45542969770477E-7,,,,,,,,,,,,,,,,,,,,,109.045364379883,109.415168762207,4999.48876953125,4999.48876953125,53.4852763139287,5.64244559778059,4.42199182510376,54,1,0,0,1,0.299530029296875,33.7243423461914,2,1,3,109.045364379883,0,109.230266571045,,,,,,,,,,,,,,,,,,,,,,,,,,,,,,,,,
,3883205803.07595,104.923118591309,4999.48876953125,-8.34212252302421E-5,1.1879346244289E-8,1,4,13.4005146026611,5.00703630621968,30.1600005477667,-0.103918631947509,-0.0153688738753527,1,1.38787160331397E-7,,,,,,,,,,,,,,,,,,,,,104.753395080566,105.092842102051,4999.48876953125,4999.48876953125,53.4399418598133,5.64291621037689,4.40713214874268,52,1,64,0,0,0.299072265625,33.7243423461914,2,1,3,104.753395080566,0,104.923118591309,,,,,,,,,,,,,,,,,,,,,,,,,,,,,,,,,
,3883205855.44354,100.565277099609,4999.48876953125,-8.33819524014051E-5,9.73760962783009E-9,1,4,13.4005146026611,5.00700919752273,30.1600005477667,-0.103869331369103,-0.0153587940009141,1,1.40912530511299E-7,,,,,,,,,,,,,,,,,,,,,100.410362243652,100.720191955566,4999.48876953125,4999.48876953125,53.467689672246,5.64316172911121,4.39720487594604,54,1,0,0,1,0.298690795898438,33.7243423461914,2,1,3,100.410362243652,0,100.565277099609,,,,,,,,,,,,,,,,,,,,,,,,,,,,,,,,,
,3883205907.76053,96.1260414123535,4999.48876953125,-8.33395679558564E-5,1.1072339833593E-8,1,4,13.4005146026611,5.00718259282668,30.1600005477667,-0.103822549768953,-0.0153451059619625,1,1.4615952617185E-7,,,,,,,,,,,,,,,,,,,,,95.9615707397461,96.2905120849609,4999.48876953125,4999.48876953125,53.3320771241595,5.64293277866127,4.38050937652588,54,1,0,0,1,0.2984619140625,34.2131004333496,2,1,3,95.9615707397461,0,96.1260414123535,,,,,,,,,,,,,,,,,,,,,,,,,,,,,,,,,
,3883205960.13993,91.7883682250977,4999.48876953125,-8.33003622553261E-5,1.18147849842641E-8,1,4,13.4005146026611,5.00714374069345,30.1600005477667,-0.103770598979941,-0.0153509805030925,1,1.35444097261712E-7,,,,,,,,,,,,,,,,,,,,,91.6424331665039,91.9343032836914,4999.48876953125,4999.48876953125,53.4379877885153,5.64309458914821,4.36001014709473,54,1,0,0,1,0.29876708984375,35.190616607666,2,1,3,91.6424331665039,0,91.7883682250977,,,,,,,,,,,,,,,,,,,,,,,,,,,,,,,,,
,3883206012.58547,87.4241256713867,4999.48876953125,-8.32461138961346E-5,8.40209291430857E-9,1,4,13.4005146026611,5.00714426441162,30.1600005477667,-0.103705650895015,-0.0153234975412572,1,1.49397596012834E-7,,,,,,,,,,,,,,,,,,,,,87.2590408325195,87.5892105102539,4999.48876953125,4999.48876953125,53.4583101300153,5.64293327872819,4.3423752784729,54,1,0,0,1,0.300369262695313,33.7243423461914,2,1,3,87.2590408325195,0,87.4241256713867,,,,,,,,,,,,,,,,,,,,,,,,,,,,,,,,,
,3883206064.93622,83.0599899291992,4999.48876953125,-8.3185485099017E-5,9.37130109663242E-9,1,4,13.4005146026611,5.00716858641234,30.1399994641542,-0.103628729209002,-0.0153264508614066,1,1.38040153051152E-7,,,,,,,,,,,,,,,,,,,,,82.8759002685547,83.2440795898438,4999.48876953125,4999.48876953125,53.4704253720634,5.64230951468005,4.32733392715454,54,1,0,0,1,0.299301147460937,33.7243423461914,2,1,3,82.8759002685547,0,83.0599899291992,,,,,,,,,,,,,,,,,,,,,,,,,,,,,,,,,
,3883206117.41578,78.6318435668945,4999.48876953125,-8.31156999771631E-5,1.08579549700705E-8,1,4,13.4005146026611,5.00725160735821,30.1399994641542,-0.103539055108352,-0.01534830046123,1,1.103427639201E-7,,,,,,,,,,,,,,,,,,,,,78.4843368530273,78.7793502807617,4999.48876953125,4999.48876953125,53.3606065651114,5.64188018202028,4.30657196044922,52,1,64,0,0,0.298538208007812,33.7243423461914,2,1,3,78.4843368530273,0,78.6318435668945,,,,,,,,,,,,,,,,,,,,,,,,,,,,,,,,,
,3883206169.67898,74.2465057373047,4999.48876953125,-8.30595378720694E-5,1.04127746833784E-8,1,4,13.4005146026611,5.00721080744672,30.1399994641542,-0.103473397881016,-0.0153010974295214,1,1.39700953466473E-7,,,,,,,,,,,,,,,,,,,,,74.0631484985352,74.4298629760742,4999.48876953125,4999.48876953125,53.4778508429961,5.64220489954863,4.29228973388672,54,1,0,0,1,0.300064086914063,33.7243423461914,2,1,3,74.0631484985352,0,74.2465057373047,,,,,,,,,,,,,,,,,,,,,,,,,,,,,,,,,
,3883206222.13809,69.788215637207,4999.48876953125,-8.29872063484362E-5,1.1900051015018E-8,1,4,13.4005146026611,5.00719714871582,30.1399994641542,-0.103382309984806,-0.0152916245612734,1,1.3643970004358E-7,,,,,,,,,,,,,,,,,,,,,69.6630554199219,69.9133758544922,4999.48876953125,4999.48876953125,53.4133664901595,5.64223233416814,4.26013994216919,54,1,0,0,1,0.307159423828125,33.7243423461914,2,1,3,69.6630554199219,0,69.788215637207,,,,,,,,,,,,,,,,,,,,,,,,,,,,,,,,,
,3883206274.45561,65.4224472045898,4999.48876953125,-8.28845530751514E-5,1.14448162938792E-8,1,4,13.4005146026611,5.00719962435381,30.1399994641542,-0.103255887240234,-0.0152634450197793,1,1.43717761106076E-7,,,,,,,,,,,,,,,,,,,,,65.2603607177734,65.5845336914062,4999.48876953125,4999.48876953125,53.447367330746,5.64240807109852,4.2436580657959,54,1,0,0,1,0.299224853515625,33.7243423461914,2,1,3,65.2603607177734,0,65.4224472045898,,,,,,,,,,,,,,,,,,,,,,,,,,,,,,,,,
,3883206326.93204,61.0077285766602,4999.48876953125,-8.27789512950965E-5,1.00228560180588E-8,1,4,13.4005146026611,5.00726037481306,30.1399994641542,-0.103124721919234,-0.0152533334119104,1,1.36246897034211E-7,,,,,,,,,,,,,,,,,,,,,60.8745231628418,61.1409339904785,4999.48876953125,4999.48876953125,53.5059894696884,5.64206319696371,4.218825340271,54,1,0,0,1,0.298843383789063,33.7243423461914,2,1,3,60.8745231628418,0,61.0077285766602,,,,,,,,,,,,,,,,,,,,,,,,,,,,,,,,,
,3883206379.2321,56.584005355835,4999.48876953125,-8.26658726114865E-5,1.13258144279659E-8,1,4,13.4005146026611,5.00721073672841,30.1399994641542,-0.102980768154749,-0.0152433488464019,1,1.27178068721787E-7,,,,,,,,,,,,,,,,,,,,,56.406982421875,56.7610282897949,4999.48876953125,4999.48876953125,53.4204011468326,5.64203021381673,4.18519353866577,54,1,0,0,1,0.297698974609375,34.2131004333496,2,1,3,56.406982421875,0,56.584005355835,,,,,,,,,,,,,,,,,,,,,,,,,,,,,,,,,
,3883206443.81177,51.1569423675537,4999.48876953125,-8.24954841285304E-5,1.23228492576197E-8,1,4,13.4005146026611,5.00722292305143,30.120000243187,-0.102764336034527,-0.0152422020125227,1,1.0265144915243E-7,,,,,,,,,,,,,,,,,,,,,51.0229377746582,51.2909469604492,4999.48876953125,4999.48876953125,53.3926533343999,5.64238721450562,4.15361738204956,53,1,68,0,0,0.298843383789063,34.2131004333496,2,1,3,51.0229377746582,0,51.1569423675537,,,,,,,,,,,,,,,,,,,,,,,,,,,,,,,,,
,3883206496.0735,46.7404117584229,4999.48876953125,-8.23255238893196E-5,1.14183192228264E-8,1,4,13.4005146026611,5.00724449225125,30.120000243187,-0.102556963075768,-0.0151859677680861,1,1.22451083013314E-7,,,,,,,,,,,,,,,,,,,,,46.5647354125977,46.916088104248,4999.48876953125,4999.48876953125,53.5247485541499,5.64288746712146,4.10924386978149,54,1,0,0,1,0.299453735351562,34.2131004333496,2,1,3,46.5647354125977,0,46.7404117584229,,,,,,,,,,,,,,,,,,,,,,,,,,,,,,,,,
,3883206560.58674,41.2717571258545,4999.48876953125,-8.20320742238998E-5,1.15898824474811E-8,1,4,13.4005146026611,5.00717596849928,30.120000243187,-0.102182558284635,-0.015177573135479,1,8.50598076305978E-8,,,,,,,,,,,,,,,,,,,,,41.1177291870117,41.4257850646973,4999.48876953125,4999.48876953125,53.411803233121,5.64249855309845,4.06949424743652,54,1,0,0,1,0.299911499023438,33.7243423461914,2,1,3,41.1177291870117,0,41.2717571258545,,,,,,,,,,,,,,,,,,,,,,,,,,,,,,,,,
,3883206612.93172,36.8833103179932,4999.48876953125,-8.17974779354354E-5,1.38668836815747E-8,1,4,13.4005146026611,5.00726597857246,30.120000243187,-0.101896296097779,-0.0151118187060294,1,1.03066343689142E-7,,,,,,,,,,,,,,,,,,,,,36.7078247070313,37.0587959289551,4999.48876953125,4999.48876953125,53.4204011468326,5.64215726578317,4.02010440826416,54,1,0,0,1,0.298843383789063,33.7243423461914,2,1,3,36.7078247070313,0,36.8833103179932,,,,,,,,,,,,,,,,,,,,,,,,,,,,,,,,,
,3883206665.37497,32.4496402740479,4999.48876953125,-8.14837865430094E-5,1.31806331612916E-8,1,4,13.4005146026611,5.00723596553796,30.120000243187,-0.101502524397001,-0.0150681200498488,1,9.1124476515572E-8,,,,,,,,,,,,,,,,,,,,,32.2852096557617,32.614070892334,4999.48876953125,4999.48876953125,53.4884028280057,5.64189991961049,3.95843005180359,54,1,0,0,1,0.298843383789063,33.7243423461914,2,1,3,32.2852096557617,0,32.4496402740479,,,,,,,,,,,,,,,,,,,,,,,,,,,,,,,,,
,3883206717.68943,28.1016960144043,4999.48876953125,-8.10921002968211E-5,1.32556170397216E-8,1,4,13.4005146026611,5.00722228302692,30.120000243187,-0.101017150835754,-0.0149760646848668,1,1.06396890853527E-7,,,,,,,,,,,,,,,,,,,,,27.9077033996582,28.2956886291504,4999.48876953125,4999.48876953125,53.5028629556114,5.64175809776555,3.89244985580444,54,1,0,0,1,0.298919677734375,33.7243423461914,2,1,3,27.9077033996582,0,28.1016960144043,,,,,,,,,,,,,,,,,,,,,,,,,,,,,,,,,
,3883206770.12836,23.7258567810059,4999.48876953125,-8.05200785343856E-5,1.60107929171355E-8,1,4,13.4005146026611,5.00717619657444,30.120000243187,-0.100306689514125,-0.0148474919510889,1,1.23905331772936E-7,,,,,,,,,,,,,,,,,,,,,23.5540733337402,23.8976402282715,4999.48876953125,4999.48876953125,53.4137573044191,5.6423584816695,3.79767489433289,54,1,0,0,1,0.299835205078125,33.7243423461914,2,1,3,23.5540733337402,0,23.7258567810059,,,,,,,,,,,,,,,,,,,,,,,,,,,,,,,,,
,3883206822.45768,19.3288269042969,4999.48876953125,-7.97220885893849E-5,2.15550956419463E-8,1,4,13.4005146026611,5.00721434175218,30.120000243187,-0.099307339491339,-0.0147427748066683,1,8.87368848039772E-8,,,,,,,,,,,,,,,,,,,,,19.1560516357422,19.5016021728516,4999.48876953125,4999.48876953125,53.4817589855922,5.64161526839271,3.65269446372986,54,1,0,0,1,0.298995971679687,33.7243423461914,2,1,3,19.1560516357422,0,19.3288269042969,,,,,,,,,,,,,,,,,,,,,,,,,,,,,,,,,
,3883206874.9391,15.0187120437622,4999.48876953125,-7.85007525589834E-5,1.52365294703557E-8,1,4,13.4005146026611,5.00719919266682,30.120000243187,-0.0977860027847931,-0.0145137978148836,1,8.98323353021128E-8,,,,,,,,,,,,,,,,,,,,,14.8673028945923,15.1701211929321,4999.48876953125,4999.48876953125,53.4450224451884,5.64196958780215,3.41468691825867,54,1,0,0,1,0.30059814453125,33.7243423461914,2,1,3,14.8673028945923,0,15.0187120437622,,,,,,,,,,,,,,,,,,,,,,,,,,,,,,,,,
,3883206927.34851,10.7473540306091,4999.48876953125,-7.63026963286349E-5,2.35112818554388E-8,1,4,13.4005146026611,5.00717244615989,30.120000243187,-0.0950513627787278,-0.0140797476065782,1,1.09439186157285E-7,,,,,,,,,,,,,,,,,,,,,10.5793294906616,10.9153785705566,4999.48876953125,4999.48876953125,53.3633422649287,5.64192409060333,3.067218542099,54,1,0,0,1,0.300750732421875,33.7243423461914,2,1,3,10.5793294906616,0,10.7473540306091,,,,,,,,,,,,,,,,,,,,,,,,,,,,,,,,,
,3883206979.641,6.81466627120972,4999.48876953125,-7.17765175284607E-5,3.0307779965774E-8,1,4,13.4005146026611,5.00716350070564,30.120000243187,-0.0894081123171001,-0.0132759491371247,1,7.77135724501212E-8,,,,,,,,,,,,,,,,,,,,,6.64790058135986,6.98143196105957,4999.48876953125,4999.48876953125,53.4766784002172,5.64205345575554,2.79045224189758,54,1,0,0,1,0.299758911132812,33.7243423461914,6,1,3,6.64790058135986,0,6.81466627120972,,,,,,,,,,,,,,,,,,,,,,,,,,,,,,,,,
,3883207031.99363,2.93709397315979,4999.48876953125,-5.70155302298185E-5,3.01222452342231E-8,1,4,13.4005146026611,5.00711354937033,30.120000243187,-0.0710198433779812,-0.0105477000589569,1,6.00261599989411E-8,,,,,,,,,,,,,,,,,,,,,2.89401078224182,2.98017716407776,4999.48876953125,4999.48876953125,53.4426775596307,5.64209518850876,2.11632680892944,54,1,0,0,1,0.299072265625,33.7243423461914,6,1,3,2.89401078224182,0,2.93709397315979,,,,,,,,,,,,,,,,,,,,,,,,,,,,,,,,,
,3883207084.38189,2.75566136837006,4999.48876953125,-5.56151500340496E-5,1.85048200805735E-8,1,4,13.4005146026611,5.0071996293541,30.120000243187,-0.0692793715798733,-0.0102741160207251,1,7.04070996330446E-8,,,,,,,,,,,,,,,,,,,,,2.754390001297,2.75693273544312,4999.48876953125,4999.48876953125,53.4348612744383,5.64207566717292,2.03204965591431,54,1,0,0,1,0.299148559570313,34.2131004333496,6,1,3,2.75699520111084,0,2.75566136837006,,,,,,,,,,,,,,,,,,,,,,,,,,,,,,,,,
,3883207136.81025,2.7571804523468,4999.48876953125,-5.5573583495861E-5,1.71381587151135E-8,1,4,13.4005146026611,5.00710461233538,30.120000243187,-0.0692284559798904,-0.0102481162928842,1,8.48463773610229E-8,,,,,,,,,,,,,,,,,,,,,2.75715494155884,2.75720596313477,4999.48876953125,4999.48876953125,53.4610458298326,5.64205902911708,2.03492069244385,54,1,0,0,1,0.300445556640625,33.7243423461914,6,1,3,2.75715494155884,0,2.7571804523468,,,,,,,,,,,,,,,,,,,,,,,,,,,,,,,,,
,3883207189.235,2.76022851467133,4999.48876953125,-5.56199184974048E-5,1.76329404589595E-8,1,4,13.4005146026611,5.00707277593674,30.120000243187,-0.0692843264745613,-0.0102648154629013,1,7.82961211936211E-8,,,,,,,,,,,,,,,,,,,,,2.75903511047363,2.76142191886902,4999.48876953125,4999.48876953125,53.4415051168518,5.64242297111503,2.04112887382507,54,1,0,0,1,0.300216674804687,33.7243423461914,6,1,3,2.75903511047363,0,2.76022851467133,,,,,,,,,,,,,,,,,,,,,,,,,,,,,,,,,
,3883207241.6639,2.716836810112,4999.48876953125,-5.52127883098608E-5,2.01002606985628E-8,1,4,13.4005146026611,5.00707348611207,30.120000243187,-0.06877784017188,-0.0101853230200233,1,8.12217799352396E-8,,,,,,,,,,,,,,,,,,,,,2.71475458145142,2.71891903877258,4999.48876953125,4999.48876953125,53.5024721413518,5.64172822671644,2.03610801696777,54,1,0,0,1,0.300064086914063,33.7243423461914,6,1,3,2.71475458145142,0,2.716836810112,,,,,,,,,,,,,,,,,,,,,,,,,,,,,,,,,
,3883207293.93119,2.66553997993469,4999.48876953125,-5.47192734316847E-5,1.91515748774598E-8,1,4,13.4005146026611,5.00703627457459,30.120000243187,-0.0681545914517482,-0.010146155504841,1,3.87597784251087E-8,,,,,,,,,,,,,,,,,,,,,2.66415739059448,2.6669225692749,4999.48876953125,4999.48876953125,53.4985639987557,5.6421355983835,2.03412270545959,54,1,0,0,1,0.300369262695313,33.7243423461914,6,1,3,2.66415739059448,0,2.66553997993469,,,,,,,,,,,,,,,,,,,,,,,,,,,,,,,,,
,3883207346.31833,2.61589992046356,4999.48876953125,-5.42492206102116E-5,2.00311060204488E-8,1,4,13.4005146026611,5.00701971098072,30.120000243187,-0.0675733193517588,-0.0100288287428031,1,6.26136436854039E-8,,,,,,,,,,,,,,,,,,,,,2.61321902275085,2.61858081817627,4999.48876953125,4999.48876953125,53.5294383252653,5.64249255956455,2.02668380737305,54,1,0,0,1,0.298614501953125,33.2355842590332,6,1,3,2.61321902275085,0,2.61589992046356,,,,,,,,,,,,,,,,,,,,,,,,,,,,,,,,,
,3883207398.80925,2.52125883102417,4999.48876953125,-5.32550828091838E-5,2.11205475928028E-8,1,4,13.4005146026611,5.00698761864543,30.120000243187,-0.066331105821429,-0.00986709915622827,1,4.36879438302192E-8,,,,,,,,,,,,,,,,,,,,,2.516361951828,2.52615571022034,4999.48876953125,4999.48876953125,53.4672988579864,5.64243837151951,2.00481605529785,54,1,0,0,1,0.299453735351562,33.7243423461914,6,1,3,2.516361951828,0,2.52125883102417,,,,,,,,,,,,,,,,,,,,,,,,,,,,,,,,,
,3883207451.07593,2.09875655174255,4999.48876953125,-4.8091933139064E-5,2.33174675042842E-8,1,4,13.4005146026611,5.00695510339406,30.120000243187,-0.0598981757525737,-0.00892041145860542,1,3.1405492404222E-8,,,,,,,,,,,,,,,,,,,,,2.08440375328064,2.11310935020447,4999.48876953125,4999.48876953125,53.4587009442749,5.64294565364504,1.82942926883698,54,1,0,0,1,0.298690795898438,33.7243423461914,2,1,3,2.08440375328064,0,2.09875655174255,,,,,,,,,,,,,,,,,,,,,,,,,,,,,,,,,
,3883207503.5011,1.99761265516281,4999.48876953125,-4.67960697003096E-5,1.76483951026467E-8,1,4,13.4005146026611,5.00691807114552,30.120000243187,-0.0582888280092735,-0.00864490139686456,1,5.87077290180688E-8,,,,,,,,,,,,,,,,,,,,,1.99718797206879,1.99803733825684,4999.48876953125,4999.48876953125,53.5278750682268,5.6433182295592,1.77677941322327,54,1,0,0,1,0.299453735351562,33.7243423461914,5,1,3,1.99718797206879,0,1.99761265516281,,,,,,,,,,,,,,,,,,,,,,,,,,,,,,,,,
,3883207535.7006,2.00034844875336,4999.48876953125,-4.68426292189662E-5,1.61383494641069E-8,1,4,13.4005146026611,5.00692929532741,30.120000243187,-0.0583410180115572,-0.00869355165228371,1,2.6629367181065E-8,,,,,,,,,,,,,,,,,,,,,2.00018739700317,2.00050950050354,4999.48876953125,4999.48876953125,53.4966099274576,5.6423429004822,1.76316154003143,54,1,0,0,1,0.298309326171875,33.7243423461914,1,1,3,2.00018739700317,0,2.00034844875336,,,,,,,,,,,,,,,,,,,,,,,,,,,,,,,,,