File: SQUID/Reference/LSAT/A1/LSAT_subs_A1_MH_300K_FC_p0d5T.csv
Moment (emu)
-0.00117539132678691
-0.00117531091048172
-0.00109095011514726
-0.00109097588338253
-0.001007798835229
-0.00100706848869734
-9.23010867672888E-4
-9.23090601329523E-4
-8.3909433614564E-4
-8.39083856660834E-4
-7.55062124119588E-4
-7.55038854422749E-4
-6.71113914890225E-4
-6.71157238660827E-4
-5.87106005595652E-4
-5.87169246144715E-4
-5.03191654103671E-4
-5.03189011502273E-4
-4.19216602578252E-4
-4.19239274510615E-4
-3.35248929637483E-4
-3.35285241583971E-4
-2.51350369035525E-4
-2.5135857947647E-4
-2.42907950783317E-4
-2.42941343290218E-4
-2.34510195534976E-4
-2.34514984654711E-4
-2.26117548104453E-4
-2.26136202954452E-4
-2.17738895313534E-4
-2.17731274182677E-4
-2.09327905445601E-4
-2.09336231310821E-4
-2.00924685389267E-4
-2.00948225752404E-4
-1.92524418488895E-4
-1.92546281802385E-4
-1.84117318943887E-4
-1.84146480841295E-4
-1.75739385684726E-4
-1.75749375099968E-4
-1.67318571949961E-4
-1.67343718059502E-4
-1.58933696349457E-4
-1.58957847846498E-4
-1.50541447578759E-4
-1.50547543085247E-4
-1.42156736922055E-4
-1.42167891388256E-4
-1.33746100005122E-4
-1.33756750233128E-4
-1.25355638392339E-4
-1.2537194909776E-4
-1.16946787439118E-4
-1.16970876273147E-4
-1.08542273566627E-4
-1.0855836935202E-4
-1.00187568824799E-4
-1.00163000732202E-4
-9.17437643091668E-5
-9.17549035934647E-5
-8.33379012387199E-5
-8.3360521256962E-5
-7.49352224057507E-5
-7.4955541547885E-5
-6.65295601055758E-5
-6.65515896749033E-5
-5.81245799340106E-5
-5.81417516628703E-5
-4.97532884891999E-5
-4.97564095674511E-5
-4.48350218916342E-5
-4.48509158205302E-5
-3.9969508925617E-5
-3.99838986065827E-5
-3.50871936868301E-5
-3.51121533845367E-5
-3.02182641359254E-5
-3.02263721286691E-5
-2.53415577046442E-5
-2.53455884130685E-5
-2.04739260039026E-5
-2.04761228025822E-5
-1.55989172998633E-5
-1.5597473069312E-5
-1.07339460618021E-5
-1.07374502579438E-5
-5.86832742109273E-6
-5.87482516168864E-6
-1.01565498840713E-6
-1.00155483141353E-6
3.70703889331316E-6
3.84309276990997E-6
8.6275273902538E-6
8.63405076433459E-6
1.34311676587936E-5
1.34730302574447E-5
1.82226240230246E-5
1.83128934652107E-5
2.31717514129789E-5
2.31800978532382E-5
2.80427680828392E-5
2.80564644768521E-5
3.29123093220342E-5
3.29326926284613E-5
3.77115371614433E-5
3.77110959065833E-5
4.25882251876716E-5
4.26009921034549E-5
4.74481872142738E-5
4.74507419140222E-5
5.08180847486783E-5
5.08147996260386E-5
5.90949146076449E-5
5.90908805577466E-5
6.74932494963925E-5
6.74979944752269E-5
7.58625583577509E-5
7.58548469356154E-5
8.42370689655273E-5
8.42510356252743E-5
9.26162635271128E-5
9.26146133188514E-5
1.00996860351153E-4
1.00988762916867E-4
1.09381950629463E-4
1.09377813291636E-4
1.1775697760753E-4
1.17767448133072E-4
1.26167124183525E-4
1.26160789779317E-4
1.34546820488673E-4
1.34544313565939E-4
1.4294123982503E-4
1.42926919627046E-4
1.51323232586905E-4
1.51314765373538E-4
1.59704192876428E-4
1.59705560326392E-4
1.68101161129122E-4
1.68106269962086E-4
1.76493428593285E-4
1.76481403187544E-4
1.84876827353286E-4
1.84877906516974E-4
1.93273485661843E-4
1.93261274275709E-4
2.01659462556322E-4
2.0164800721681E-4
2.10039846965547E-4
2.10050381089958E-4
2.18442505109492E-4
2.18425776698972E-4
2.26831402350773E-4
2.26819605265038E-4
2.35371009698579E-4
2.35227626781781E-4
2.43608027546891E-4
2.43612950653664E-4
2.52159808544048E-4
2.5198837279549E-4
3.35957235218208E-4
3.36144922729048E-4
4.19900623253852E-4
4.19905381558114E-4
5.0386552862325E-4
5.0389413442886E-4
5.87878222988305E-4
5.87875089775682E-4
6.71919281998673E-4
6.71883370016857E-4
7.55874141624089E-4
7.55872663026895E-4
8.39927665890126E-4
8.39882751831537E-4
9.24697211298849E-4
9.23955183701548E-4
0.00100804893436906
0.00100799818918107
0.00109204957692345
0.00109211329708139
0.00117707229277568
0.0011761694941224
0.00109180887818826
0.00109177334752058
0.00100771781217879
0.00100777528174112
9.23645739177818E-4
9.23633293392248E-4
8.3952797756025E-4
8.3953593870861E-4
7.55489914787102E-4
7.5550587406408E-4
6.71469987780181E-4
6.71441758124792E-4
5.87405177024341E-4
5.87442830961125E-4
5.03390171754136E-4
5.03413001806485E-4
4.19384561027898E-4
4.19418257841106E-4
3.35396818665007E-4
3.35401007569085E-4
2.51391831363754E-4
2.51404854859416E-4
2.43010517328868E-4
2.43018865294965E-4
2.34589829446071E-4
2.34611648559572E-4
2.26194553665243E-4
2.26210574359251E-4
2.17826155558014E-4
2.17838002802292E-4
2.09391891615292E-4
2.09416884638523E-4
2.00994030135374E-4
2.01013237232221E-4
1.92599036237363E-4
1.92615415222466E-4
1.84204480308505E-4
1.84196595927946E-4
1.75782558179203E-4
1.75823196989553E-4
1.67393049043593E-4
1.67405931767746E-4
1.58989686816776E-4
1.5900952093883E-4
1.50585995763325E-4
1.50620475922477E-4
1.42190793224925E-4
1.42203792162771E-4
1.33782116090156E-4
1.33806407301544E-4
1.25382400168705E-4
1.25402643847527E-4
1.16981704372672E-4
1.16995181347248E-4
1.0857140679527E-4
1.08593799374013E-4
1.0016920231219E-4
1.00199338912604E-4
9.1800797867982E-5
9.18037294606263E-5
8.33625253387337E-5
8.33866112041286E-5
7.49563144761651E-5
7.49776709881737E-5
6.65388173269192E-5
6.65753185497859E-5
5.81611146830724E-5
5.81682000482852E-5
4.97409955128041E-5
4.9765838623534E-5
4.6432909146436E-5
4.64274345308877E-5
4.15081543865867E-5
4.15190180405806E-5
3.66180360264518E-5
3.66354439556647E-5
3.17503042421471E-5
3.17672254911942E-5
2.68796751083533E-5
2.68959872577187E-5
2.19908670850249E-5
2.20074174709554E-5
1.71351555295742E-5
1.71288280996637E-5
1.22425252974147E-5
1.22565229006479E-5
7.37264468352124E-6
7.38113837924482E-6
2.5343789044568E-6
2.53512408048852E-6
-2.33512549040858E-6
-2.33579980053969E-6
-7.12787882489832E-6
-7.10366654161566E-6
-1.20135091511762E-5
-1.19544067419062E-5
-1.68345498973112E-5
-1.68331475720445E-5
-2.16516006937859E-5
-2.1676671544899E-5
-2.65307505795721E-5
-2.65326770085127E-5
-3.14291980867134E-5
-3.13711021604498E-5
-3.6371318980387E-5
-3.62375668642392E-5
-4.10979259331914E-5
-4.10931060156327E-5
-4.5943110031985E-5
-4.59302325590062E-5
-5.07725427033776E-5
-5.07728808806436E-5
-5.90975281310504E-5
-5.90963250265395E-5
-6.75068654770106E-5
-6.75049278324409E-5
-7.58600272925862E-5
-7.58564515165891E-5
-8.42442787718051E-5
-8.42348526510338E-5
-9.26205313243824E-5
-9.26271999911468E-5
-1.0101046358807E-4
-1.01001865017542E-4
-1.09390541737229E-4
-1.09382586635893E-4
-1.17778823138903E-4
-1.17768046217906E-4
-1.26170797832186E-4
-1.26157452986477E-4
-1.34550488265889E-4
-1.34550271433935E-4
-1.43000644266603E-4
-1.42925280492577E-4
-1.5132772570138E-4
-1.51315890822657E-4
-1.59715789328709E-4
-1.59713814804889E-4
-1.6810415187896E-4
-1.68099869054138E-4
-1.76505175637902E-4
-1.76502222604461E-4
-1.84896446368624E-4
-1.84895234766813E-4
-1.93274697091087E-4
-1.93270408730135E-4
-2.01664448218126E-4
-2.01677394269724E-4
-2.10082869212076E-4
-2.10067502327831E-4
-2.18453779407898E-4
-2.18452318144875E-4
-2.26855853651851E-4
-2.26835309982308E-4
-2.35234839470144E-4
-2.35229331336577E-4
-2.43622375067596E-4
-2.43627384096714E-4
-2.52014330978009E-4
-2.52017695530031E-4
-3.35915594171765E-4
-3.35914284784454E-4
-4.19943565518749E-4
-4.19914982768268E-4
-5.03900665263763E-4
-5.03898392708881E-4
-5.87889412359347E-4
-5.87906481468812E-4
-6.71909591803554E-4
-6.71907304866545E-4
-7.55913282871346E-4
-7.55793911095472E-4
-8.39984031179361E-4
-8.40523173203146E-4
-9.24118678869996E-4
-9.24063296926815E-4
-0.00100808921160143
-0.00100808642721816
-0.00109215506484397
-0.00109213648634627
-0.00117633951576195
-0.00117727339004628