File: SQUID/22172_LCOL/22172_LCOL_MH_200K_FC_p0d5T.csv
Comment,Time Stamp (sec),Temperature (K),Magnetic Field (Oe),Moment (emu),M. Std. Err. (emu),Transport Action,Averaging Time (sec),Frequency (Hz),Peak Amplitude (mm),Center Position (mm),Lockin Signal' (V),Lockin Signal (V),Range,M. Quad. Signal (emu),AC Moment (emu),AC M. Std Err. (emu),AC Phase (deg),AC Phase Std. Err. (deg),AC Susceptibility (emu/Oe),AC Suscept. Std Err. (emu/Oe),AC X' (emu/Oe),AC X' Std Err. (emu/Oe),AC X'' (emu/Oe),AC X'' Std Err. (emu/Oe),AC Drive (Oe),AC Frequency (Hz),AC Averaging Time (sec),AC Cycles,AC Range,AC Measure Type,AC Signal' (V),AC Signal'' (V),AC Trim Coil Ratio,AC Trim Coil Phase,Min. Temperature (K),Max. Temperature (K),Min. Field (Oe),Max. Field (Oe),Mass (grams),Motor Lag (deg),Pressure (Torr),Measure Count,Measurement Number,SQUID Status (code),Motor Status (code),Measure Status (code),Motor Current (amps),Motor Temp. (C),Temp. Status (code),Field Status (code),Chamber Status (code),Chamber Temp (K),Redirection State,Average Temp (K),Rotation Angle (deg),Rotator state,DC Moment Fixed Ctr (emu),DC Moment Err Fixed Ctr (emu),DC Moment Free Ctr (emu),DC Moment Err Free Ctr (emu),DC Fixed Fit,DC Free Fit,DC Calculated Center (mm),DC Calculated Center Err (mm),DC Scan Length (mm),DC Scan Time (s),DC Number of Points,DC Squid Drift,DC Min V (V),DC Max V (V),DC Scans per Measure,Map 01,Map 02,Map 03,Map 04,Map 05,Map 06,Map 07,Map 08,Map 09,Map 10,Map 11,Map 12,Map 13,Map 14,Map 15,Map 16
,3881443149.56284,200.065673828125,69999.5,-8.92439016035607E-4,5.66081066696852E-7,1,4,14.0008964538574,4.99395038405147,32.5100012123585,-1.10711017781562,-0.16755996310725,100,4.80256827024181E-7,,,,,,,,,,,,,,,,,,,,,200.065658569336,200.065689086914,69999.5,69999.5,53.3625606364095,5.88263778620836,4.28411626815796,56,1,0,0,1,0.329513549804687,32.7468223571777,1,1,3,200.065689086914,0,200.065673828125,,,,,,,,,,,,,,,,,,,,,,,,,,,,,,,,,
,3881443234.97898,200.154121398926,59999.73046875,-7.2712780093185E-4,4.9313697666082E-7,1,4,14.0008964538574,4.99393388904769,32.5100012123585,-0.902042536730796,-0.136439504659145,100,4.57245283651611E-7,,,,,,,,,,,,,,,,,,,,,200.124664306641,200.183578491211,59999.73046875,59999.73046875,53.6228429333134,5.88346987396688,4.29216194152832,56,1,0,0,1,0.328292846679687,33.2355842590332,1,1,3,200.183578491211,0,200.154121398926,,,,,,,,,,,,,,,,,,,,,,,,,,,,,,,,,
,3881443329.3596,200.070320129395,49999.6171875,-5.63309015416048E-4,2.90405529956792E-7,1,4,14.0008964538574,4.99374732806359,32.5100012123585,-0.698659048291464,-0.106488617745904,10,-2.85805207707514E-7,,,,,,,,,,,,,,,,,,,,,200.06721496582,200.073425292969,49999.6171875,49999.6171875,53.7643176952942,5.88356670065441,4.29042530059814,56,1,0,0,1,0.329055786132812,33.7243423461914,1,1,3,200.06721496582,0,200.070320129395,,,,,,,,,,,,,,,,,,,,,,,,,,,,,,,,,
,3881443414.82083,200.036033630371,39999.796875,-3.97683084398804E-4,3.11626887577468E-7,1,4,14.0008964538574,4.99380212259539,32.5100012123585,-0.493256482818253,-0.0751017237254028,10,-1.38950347736702E-7,,,,,,,,,,,,,,,,,,,,,200.027404785156,200.044662475586,39999.796875,39999.796875,53.7650993238134,5.88315610892047,4.28262376785278,56,1,0,0,1,0.32928466796875,34.2131004333496,1,1,3,200.044662475586,0,200.036033630371,,,,,,,,,,,,,,,,,,,,,,,,,,,,,,,,,
,3881443500.8638,200.128372192383,29999.67578125,-2.32424547235994E-4,2.80993023005619E-7,1,4,14.0008964538574,4.99382974846089,32.5100012123585,-0.288284812942659,-0.0438901383171106,10,-7.8667285652077E-8,,,,,,,,,,,,,,,,,,,,,200.116943359375,200.139801025391,29999.67578125,29999.67578125,53.8831252302172,5.88340325440781,4.28765106201172,56,1,0,0,1,0.329437255859375,33.7243423461914,1,1,3,200.139801025391,0,200.128372192383,,,,,,,,,,,,,,,,,,,,,,,,,,,,,,,,,
,3881443592.97237,200.098205566406,19999.603515625,-6.96551216795927E-5,1.03122990791891E-7,1,4,14.0008964538574,4.99389076995021,32.5100012123585,-0.0863735475132393,-0.0133101110725605,1,-1.4973149889251E-7,,,,,,,,,,,,,,,,,,,,,200.071640014648,200.124771118164,19999.603515625,19999.603515625,53.8659294027942,5.88283200293399,4.28071212768555,56,1,0,0,1,0.330581665039063,34.2131004333496,1,1,3,200.124771118164,0,200.098205566406,,,,,,,,,,,,,,,,,,,,,,,,,,,,,,,,,
,3881443656.89565,200.32152557373,14499.6552734375,1.95527022120787E-5,7.31175973256449E-8,1,4,14.0008964538574,4.99383079651617,32.5100012123585,0.0242700571612657,0.00357305896638696,1,-8.94780997465544E-8,,,,,,,,,,,,,,,,,,,,,200.298690795898,200.344360351562,14499.6552734375,14499.6552734375,53.9425289976788,5.88330645503479,4.28845548629761,56,1,0,0,1,0.328750610351562,34.7018585205078,1,1,3,200.344360351562,0,200.32152557373,,,,,,,,,,,,,,,,,,,,,,,,,,,,,,,,,
,3881443695.98937,200.308822631836,13499.568359375,3.55894291320922E-5,5.33583165348737E-8,1,4,14.0008964538574,4.99384521179981,32.5100012123585,0.0441620212946185,0.00659593037678302,1,-8.84590284865999E-8,,,,,,,,,,,,,,,,,,,,,200.300979614258,200.316665649414,13499.568359375,13499.568359375,53.8858609300345,5.88336366032841,4.28641176223755,56,1,0,0,1,0.329742431640625,34.2131004333496,1,1,3,200.300979614258,0,200.308822631836,,,,,,,,,,,,,,,,,,,,,,,,,,,,,,,,,
,3881443739.078,200.270141601562,12499.544921875,5.14742915422876E-5,4.4620523452329E-8,1,4,14.0008964538574,4.99387732600084,32.5100012123585,0.0638597963066919,0.00963168601717337,1,-5.40430176013626E-8,,,,,,,,,,,,,,,,,,,,,200.249313354492,200.290969848633,12499.544921875,12499.544921875,53.9694951815922,5.88347006284707,4.2796196937561,56,1,0,0,1,0.327835083007812,34.2131004333496,1,1,3,200.290969848633,0,200.270141601562,,,,,,,,,,,,,,,,,,,,,,,,,,,,,,,,,
,3881443780.2107,200.219841003418,11499.8115234375,6.74419376465583E-5,4.25127814177345E-8,1,4,14.0008964538574,4.99386142828353,32.5100012123585,0.0836613203734296,0.012670852373511,1,-2.93586969369134E-8,,,,,,,,,,,,,,,,,,,,,200.211410522461,200.228271484375,11499.8115234375,11499.8115234375,53.8827344159576,5.88330117672817,4.28616857528687,56,1,0,0,1,0.328216552734375,34.2131004333496,1,1,3,200.211410522461,0,200.219841003418,,,,,,,,,,,,,,,,,,,,,,,,,,,,,,,,,
,3881443821.86594,200.131538391113,10499.69921875,8.31750867092325E-5,3.60719219974603E-8,1,4,14.0008964538574,4.99384389306365,32.5100012123585,0.103179908727256,0.015612081838117,1,-4.79822502347187E-8,,,,,,,,,,,,,,,,,,,,,200.117538452148,200.145538330078,10499.69921875,10499.69921875,53.7318801117461,5.8839640167047,4.28041315078735,56,1,0,0,1,0.329132080078125,34.2131004333496,1,1,3,200.145538330078,0,200.131538391113,,,,,,,,,,,,,,,,,,,,,,,,,,,,,,,,,
,3881443864.19196,200.165580749512,9499.6259765625,9.89956515728166E-5,4.21964084365391E-8,1,4,14.0008964538574,4.99388941855102,32.5100012123585,0.122800577036312,0.0186249266185173,1,-2.23908254093375E-8,,,,,,,,,,,,,,,,,,,,,200.147674560547,200.183486938477,9499.6259765625,9499.6259765625,53.9136087424672,5.88353551313755,4.27972650527954,56,1,0,0,1,0.328750610351562,34.2131004333496,1,1,3,200.183486938477,0,200.165580749512,,,,,,,,,,,,,,,,,,,,,,,,,,,,,,,,,
,3881443904.67795,200.314811706543,8499.7783203125,1.14248671353918E-4,3.3008576858058E-8,1,4,14.0008964538574,4.99384588387077,32.5100012123585,0.141715540171107,0.0215215616285363,1,-3.90268687715452E-9,,,,,,,,,,,,,,,,,,,,,200.310333251953,200.319290161133,8499.7783203125,8499.7783203125,53.8495152038903,5.88343848876078,4.28111505508423,56,1,0,0,1,0.328750610351562,34.2131004333496,1,1,3,200.310333251953,0,200.314811706543,,,,,,,,,,,,,,,,,,,,,,,,,,,,,,,,,
,3881443946.24587,200.189125061035,7499.591796875,1.29220688555256E-4,3.49145108125677E-8,1,4,14.0008964538574,4.99390686967462,32.5100012123585,0.160284877170058,0.0243745216833592,1,2.15398724802859E-8,,,,,,,,,,,,,,,,,,,,,200.182678222656,200.195571899414,7499.591796875,7499.591796875,53.877263016323,5.88318351845126,4.27825975418091,54,1,68,0,0,0.328140258789063,34.2131004333496,1,1,3,200.182678222656,0,200.189125061035,,,,,,,,,,,,,,,,,,,,,,,,,,,,,,,,,
,3881443987.88515,200.142478942871,6499.8701171875,1.43995876991303E-4,5.0386795481926E-8,1,4,14.0008964538574,4.99394480017307,32.5100012123585,0.178609049030278,0.0271935371016711,1,4.95789135523402E-8,,,,,,,,,,,,,,,,,,,,,200.12174987793,200.163208007813,6499.8701171875,6499.8701171875,53.9210342133999,5.88335041638666,4.2826771736145,55,1,68,0,0,0.3265380859375,34.2131004333496,1,1,3,200.163208007813,0,200.142478942871,,,,,,,,,,,,,,,,,,,,,,,,,,,,,,,,,
,3881444037.64786,200.128524780273,5499.73291015625,1.57781147924181E-4,3.04488921903309E-7,1,4,14.0008964538574,4.99377625492501,32.5100012123585,0.195670208068971,0.0299831540527513,10,2.05637780477265E-7,,,,,,,,,,,,,,,,,,,,,200.123275756836,200.133773803711,5499.73291015625,5499.73291015625,53.8674926598326,5.88262432358222,4.27872562408447,56,1,0,0,1,0.329208374023438,34.7018585205078,1,1,3,200.123275756836,0,200.128524780273,,,,,,,,,,,,,,,,,,,,,,,,,,,,,,,,,
,3881444093.97986,200.198471069336,4499.7470703125,1.69923262034297E-4,4.47833250551148E-8,1,4,14.0008964538574,4.99386346388261,32.5100012123585,0.210790013033061,0.031917594739093,10,-7.98203941770749E-8,,,,,,,,,,,,,,,,,,,,,200.178237915039,200.218704223633,4499.7470703125,4499.7470703125,53.8932864009672,5.88326095874893,4.285231590271,56,1,0,0,1,0.328445434570313,34.2131004333496,1,1,3,200.218704223633,0,200.198471069336,,,,,,,,,,,,,,,,,,,,,,,,,,,,,,,,,
,3881444140.46636,200.3232421875,3499.56005859375,1.79086738634477E-4,5.32430551793164E-8,1,4,14.0008964538574,4.99378770885806,32.5100012123585,0.222116089694744,0.0338784365127706,1,1.0963072841511E-7,,,,,,,,,,,,,,,,,,,,,200.317398071289,200.329086303711,3499.56005859375,3499.56005859375,53.8995394291211,5.88400638765658,4.28261041641235,55,1,68,0,0,0.326690673828125,34.7018585205078,1,1,3,200.317398071289,0,200.3232421875,,,,,,,,,,,,,,,,,,,,,,,,,,,,,,,,,
,3881444212.04033,200.275985717773,2709.79809570313,1.81659945739047E-4,4.38921399357251E-8,1,4,14.0008964538574,4.99380670629694,32.5100012123585,0.225307287858243,0.0343751234440643,1,1.19043481681511E-7,,,,,,,,,,,,,,,,,,,,,200.269104003906,200.282867431641,2709.79809570313,2709.79809570313,53.8835160444769,5.88398667464993,4.28622007369995,56,1,0,0,1,0.329208374023438,34.2131004333496,1,1,3,200.282867431641,0,200.275985717773,,,,,,,,,,,,,,,,,,,,,,,,,,,,,,,,,
,3881444250.91434,200.323654174805,2129.580078125,1.79676575496071E-4,4.87662091465199E-8,1,4,14.0008964538574,4.99375629586637,32.5100012123585,0.22284418621944,0.0339995755615216,1,1.17938722831511E-7,,,,,,,,,,,,,,,,,,,,,200.319213867187,200.328094482422,2129.580078125,2129.580078125,53.8604580031595,5.88365784681702,4.27742624282837,56,1,0,0,1,0.329360961914063,34.7018585205078,1,1,3,200.328094482422,0,200.323654174805,,,,,,,,,,,,,,,,,,,,,,,,,,,,,,,,,
,3881444290.41652,200.262390136719,1549.57641601562,1.70456366594957E-4,5.20103701562326E-8,1,4,14.0008964538574,4.99372264361846,32.5100012123585,0.211407066161646,0.0322528783925299,1,1.10528555397368E-7,,,,,,,,,,,,,,,,,,,,,200.256637573242,200.268142700195,1549.57641601562,1549.57641601562,53.8807803446595,5.88327344935276,4.28441476821899,56,1,0,0,1,0.326766967773438,34.2131004333496,1,1,3,200.268142700195,0,200.262390136719,,,,,,,,,,,,,,,,,,,,,,,,,,,,,,,,,
,3881444329.36216,200.203277587891,969.522216796875,1.47183994770772E-4,2.58660381054145E-8,1,4,14.0008964538574,4.99372629103951,32.5100012123585,0.182553470340568,0.0277863627342668,1,4.4593837569011E-8,,,,,,,,,,,,,,,,,,,,,200.195617675781,200.2109375,969.522216796875,969.522216796875,53.8940680294865,5.88410651048087,4.28542804718018,56,1,0,0,1,0.32745361328125,34.2131004333496,1,1,3,200.2109375,0,200.203277587891,,,,,,,,,,,,,,,,,,,,,,,,,,,,,,,,,
,3881444368.42923,200.313095092773,389.581298828125,9.67643557401551E-5,2.50726455722011E-8,1,4,14.0008964538574,4.99369695407833,32.5100012123585,0.120013407641746,0.0182887196490971,1,4.6295392588084E-8,,,,,,,,,,,,,,,,,,,,,200.289627075195,200.336563110352,389.581298828125,389.581298828125,53.8471703183326,5.88366888587976,4.28134489059448,56,1,0,0,1,0.329742431640625,34.2131004333496,1,1,3,200.336563110352,0,200.313095092773,,,,,,,,,,,,,,,,,,,,,,,,,,,,,,,,,
,3881444407.92735,200.368049621582,-190.145599365234,-3.73527350479957E-5,1.5039313601205E-7,1,4,14.0008964538574,4.99376855275174,32.5100012123585,-0.0463069921483492,-0.00719956840416254,1,-1.30465953049757E-7,,,,,,,,,,,,,,,,,,,,,200.359786987305,200.376312255859,-190.145599365234,-190.145599365234,53.8839068587365,5.883581480427,4.28253698348999,56,1,0,0,1,0.330047607421875,34.2131004333496,1,1,3,200.359786987305,0,200.368049621582,,,,,,,,,,,,,,,,,,,,,,,,,,,,,,,,,
,3881444445.6043,200.249565124512,-770.388610839844,-1.25001462439709E-4,5.23454866518079E-8,1,4,14.0008964538574,4.99369232831862,32.5100012123585,-0.155050062892336,-0.023524379735389,1,2.17824516736907E-8,,,,,,,,,,,,,,,,,,,,,200.236465454102,200.262664794922,-770.388610839844,-770.388610839844,53.999197065323,5.88400779452082,4.28671789169312,56,1,0,0,1,0.326309204101562,34.2131004333496,1,1,3,200.262664794922,0,200.249565124512,,,,,,,,,,,,,,,,,,,,,,,,,,,,,,,,,
,3881444483.14065,200.194450378418,-1349.85119628906,-1.60075558320178E-4,5.24213055887608E-8,1,4,14.0008964538574,4.99376109092966,32.5100012123585,-0.198541450227571,-0.0302432320419485,1,-6.68974540694277E-8,,,,,,,,,,,,,,,,,,,,,200.187652587891,200.201248168945,-1349.85119628906,-1349.85119628906,53.9085281570922,5.88429842195076,4.27987384796143,56,1,0,0,1,0.329208374023438,34.2131004333496,1,1,3,200.187652587891,0,200.194450378418,,,,,,,,,,,,,,,,,,,,,,,,,,,,,,,,,
,3881444521.05001,200.10319519043,-1930.33337402344,-1.74675078340765E-4,8.29701783572571E-8,1,4,14.0008964538574,4.99380138725742,32.5100012123585,-0.216643420534906,-0.0330561481277318,1,-1.1672804927887E-7,,,,,,,,,,,,,,,,,,,,,200.099624633789,200.10676574707,-1930.33337402344,-1930.33337402344,53.9253331702557,5.88302085572048,4.28558969497681,56,1,0,0,1,0.326309204101562,34.2131004333496,1,1,3,200.099624633789,0,200.10319519043,,,,,,,,,,,,,,,,,,,,,,,,,,,,,,,,,
,3881444558.5578,200.099151611328,-2509.83374023438,-1.80063960305755E-4,1.30417284209235E-7,1,4,14.0008964538574,4.99388431706029,32.5100012123585,-0.223342012004339,-0.0340125430803538,1,-6.85649530376217E-8,,,,,,,,,,,,,,,,,,,,,200.096969604492,200.101333618164,-2509.83374023438,-2509.83374023438,53.9706676243711,5.88355460672344,4.27925729751587,56,1,0,0,1,0.327682495117188,34.2131004333496,1,1,3,200.096969604492,0,200.099151611328,,,,,,,,,,,,,,,,,,,,,,,,,,,,,,,,,
,3881444613.44727,200.338050842285,-3000.12109375,-1.78610847501806E-4,3.51241128910985E-8,1,4,14.0008964538574,4.99383325702541,32.5100012123585,-0.221538539369737,-0.0337239759225506,1,-5.70447562984674E-8,,,,,,,,,,,,,,,,,,,,,200.337921142578,200.338180541992,-3000.12109375,-3000.12109375,53.9124362996884,5.88310005095798,4.28259658813477,56,1,0,0,1,0.329132080078125,34.7018585205078,1,1,3,200.338180541992,0,200.338050842285,,,,,,,,,,,,,,,,,,,,,,,,,,,,,,,,,
,3881444652.65587,200.295097351074,-4000.10668945313,-1.73327376116006E-4,5.65408758453531E-8,1,4,14.0008964538574,4.99373747110106,32.5100012123585,-0.214964562148174,-0.0328235299853569,1,-1.34381636639336E-7,,,,,,,,,,,,,,,,,,,,,200.286773681641,200.303421020508,-4000.10668945313,-4000.10668945313,53.912827113948,5.88359004246245,4.2857551574707,56,1,0,0,1,0.326995849609375,34.2131004333496,1,1,3,200.286773681641,0,200.295097351074,,,,,,,,,,,,,,,,,,,,,,,,,,,,,,,,,
,3881444692.31035,200.230567932129,-4999.9921875,-1.62225244402672E-4,7.20233169610567E-8,1,4,14.0008964538574,4.99385706141777,32.5100012123585,-0.201208396324773,-0.0306812916707477,1,-9.28618840859435E-8,,,,,,,,,,,,,,,,,,,,,200.224060058594,200.237075805664,-4999.9921875,-4999.9921875,53.8999302433807,5.88254804933,4.28799438476562,56,1,0,0,1,0.326690673828125,33.2355842590332,1,1,3,200.224060058594,0,200.230567932129,,,,,,,,,,,,,,,,,,,,,,,,,,,,,,,,,
,3881444732.18323,200.272621154785,-5999.96533203125,-1.49014846550832E-4,4.06529927092804E-8,1,4,14.0008964538574,4.99373598383646,32.5100012123585,-0.184814778163863,-0.0281980088899916,1,-9.83016466967947E-8,,,,,,,,,,,,,,,,,,,,,200.269073486328,200.276168823242,-5999.96533203125,-5999.96533203125,53.9147811852461,5.88379805015249,4.27976369857788,56,1,0,0,1,0.325927734375,34.2131004333496,1,1,3,200.269073486328,0,200.272621154785,,,,,,,,,,,,,,,,,,,,,,,,,,,,,,,,,
,3881444772.09093,200.170562744141,-6999.59814453125,-1.35081319029643E-4,5.06941198009931E-8,1,4,14.0008964538574,4.99375998797804,32.5100012123585,-0.167529463108438,-0.0255975467196435,1,-1.18133884023894E-7,,,,,,,,,,,,,,,,,,,,,200.166610717773,200.174514770508,-6999.59814453125,-6999.59814453125,53.9241607274769,5.88396216631764,4.28701210021973,56,1,0,0,1,0.324630737304687,34.2131004333496,1,1,3,200.174514770508,0,200.170562744141,,,,,,,,,,,,,,,,,,,,,,,,,,,,,,,,,
,3881444812.39976,200.22452545166,-8000.08740234375,-1.2003147881812E-4,3.48633544966728E-8,1,4,14.0008964538574,4.99378022372535,32.5100012123585,-0.148869716998026,-0.0227168038102597,1,-8.16183287124399E-8,,,,,,,,,,,,,,,,,,,,,200.222686767578,200.226364135742,-8000.08740234375,-8000.08740234375,53.8639753314961,5.88359999344521,4.28022432327271,54,1,68,0,0,0.3271484375,34.2131004333496,1,1,3,200.226364135742,0,200.22452545166,,,,,,,,,,,,,,,,,,,,,,,,,,,,,,,,,
,3881444852.085,200.192878723145,-8999.80859375,-1.04920769293819E-4,3.68895412573619E-8,1,4,14.0008964538574,4.9937735539833,32.5100012123585,-0.130126516857106,-0.0198689014633615,1,-8.09720376605809E-8,,,,,,,,,,,,,,,,,,,,,200.187622070313,200.198135375977,-8999.80859375,-8999.80859375,53.9054016430153,5.88392481334338,4.28144693374634,56,1,0,0,1,0.32928466796875,34.2131004333496,1,1,3,200.187622070313,0,200.192878723145,,,,,,,,,,,,,,,,,,,,,,,,,,,,,,,,,
,3881444892.35287,200.120712280273,-9999.8583984375,-8.93213992485549E-5,3.25278588185782E-8,1,4,14.0008964538574,4.99375376139884,32.5199998915195,-0.110779225492565,-0.0169132702141085,1,-6.77430271990067E-8,,,,,,,,,,,,,,,,,,,,,200.11376953125,200.127655029297,-9999.8583984375,-9999.8583984375,53.8596763746403,5.88412284024439,4.2873330116272,54,1,68,0,0,0.329437255859375,34.2131004333496,1,1,3,200.127655029297,0,200.120712280273,,,,,,,,,,,,,,,,,,,,,,,,,,,,,,,,,
,3881444931.90141,200.093605041504,-10999.705078125,-7.3987842262664E-5,6.03310611806358E-8,1,4,14.0008964538574,4.99387350695852,32.5100012123585,-0.0917690119792293,-0.0139848316098281,1,-3.55924283779266E-8,,,,,,,,,,,,,,,,,,,,,200.090881347656,200.096328735352,-10999.705078125,-10999.705078125,53.9097005998711,5.88347182817294,4.28481340408325,54,1,68,0,0,0.326690673828125,34.2131004333496,1,1,3,200.090881347656,0,200.093605041504,,,,,,,,,,,,,,,,,,,,,,,,,,,,,,,,,
,3881444971.45388,200.279884338379,-11999.716796875,-5.83908439294245E-5,7.68840735009514E-8,1,4,14.0008964538574,4.99381030692585,32.5100012123585,-0.0724235851351703,-0.0110285807777766,1,-2.16523889984586E-8,,,,,,,,,,,,,,,,,,,,,200.259628295898,200.300140380859,-11999.716796875,-11999.716796875,53.8596763746403,5.88385385705928,4.28475999832153,55,1,68,0,0,0.328445434570313,34.2131004333496,1,1,3,200.300140380859,0,200.279884338379,,,,,,,,,,,,,,,,,,,,,,,,,,,,,,,,,
,3881445011.43346,200.221084594727,-12999.828125,-4.23229139823109E-5,5.75936499003797E-8,1,4,14.0008964538574,4.99382698706091,32.5100012123585,-0.0524944746343666,-0.00799320230565134,1,-1.52242439562321E-8,,,,,,,,,,,,,,,,,,,,,200.211181640625,200.230987548828,-12999.828125,-12999.828125,53.928068870073,5.88453674487615,4.28494882583618,56,1,0,0,1,0.32958984375,34.2131004333496,1,1,3,200.211181640625,0,200.221084594727,,,,,,,,,,,,,,,,,,,,,,,,,,,,,,,,,
,3881445052.06776,200.269561767578,-13999.662109375,-2.61924037658407E-5,6.49988040170548E-8,1,4,14.0008964538574,4.99373658198235,32.5100012123585,-0.0324862753873268,-0.00494783996991686,1,-1.03958664385915E-8,,,,,,,,,,,,,,,,,,,,,200.263809204102,200.275314331055,-13999.662109375,-13999.662109375,53.917907699323,5.8845584030939,4.28228521347046,54,1,68,0,0,0.328445434570313,34.2131004333496,1,1,3,200.263809204102,0,200.269561767578,,,,,,,,,,,,,,,,,,,,,,,,,,,,,,,,,
,3881445116.19887,200.464767456055,-14999.5107421875,-1.04786587032672E-5,9.95594167504681E-8,1,4,14.0008964538574,4.99368909665197,32.5100012123585,-0.0130039479649858,-0.00193001653032211,1,3.56794246612836E-8,,,,,,,,,,,,,,,,,,,,,200.464508056641,200.465026855469,-14999.5107421875,-14999.5107421875,53.9354943410057,5.88423505472371,4.28503942489624,56,1,0,0,1,0.32958984375,34.2131004333496,1,1,3,200.464508056641,0,200.464767456055,,,,,,,,,,,,,,,,,,,,,,,,,,,,,,,,,
,3881445203.7756,200.218215942383,-24999.669921875,1.52291074807854E-4,1.51246024500784E-7,1,4,14.0008964538574,4.99384091802574,32.5100012123585,0.188871506699195,0.028898830020102,1,1.64969016897523E-7,,,,,,,,,,,,,,,,,,,,,200.210021972656,200.226409912109,-24999.669921875,-24999.669921875,53.8749181307653,5.88421984082372,4.29065895080566,56,1,0,0,1,0.32928466796875,33.7243423461914,1,1,3,200.210021972656,0,200.218215942383,,,,,,,,,,,,,,,,,,,,,,,,,,,,,,,,,
,3881445290.54133,200.194816589355,-34999.6796875,3.13603219187228E-4,1.5611965650116E-7,1,4,14.0008964538574,4.99371807955021,32.5100012123585,0.388905884200352,0.0595842439753318,1,4.01620950569313E-7,,,,,,,,,,,,,,,,,,,,,200.188323974609,200.201309204102,-34999.6796875,-34999.6796875,53.8073072638518,5.88463322077877,4.28487396240234,56,1,0,0,1,0.329360961914063,32.7468223571777,1,1,3,200.188323974609,0,200.194816589355,,,,,,,,,,,,,,,,,,,,,,,,,,,,,,,,,
,3881445376.7497,200.180099487305,-44999.57421875,4.78167122631856E-4,3.93307192348489E-7,1,4,14.0008964538574,4.9936578516877,32.5100012123585,0.592955541364593,0.0909776921542483,1,7.15597518146854E-7,,,,,,,,,,,,,,,,,,,,,200.161483764648,200.198715209961,-44999.57421875,-44999.57421875,53.7330525545249,5.88454563055084,4.28656339645386,56,1,0,0,1,0.32989501953125,34.2131004333496,1,1,3,200.198715209961,0,200.180099487305,,,,,,,,,,,,,,,,,,,,,,,,,,,,,,,,,
,3881445464.87948,200.25227355957,-54999.62109375,6.44440176525304E-4,3.7673617616641E-7,1,4,14.0008964538574,4.99372047887784,32.5100012123585,0.799171562939924,0.122526311716439,1,8.92511689557393E-7,,,,,,,,,,,,,,,,,,,,,200.249130249023,200.255416870117,-54999.62109375,-54999.62109375,53.6744304155826,5.88484694616985,4.28770732879639,56,1,0,0,1,0.329132080078125,33.7243423461914,1,1,3,200.255416870117,0,200.25227355957,,,,,,,,,,,,,,,,,,,,,,,,,,,,,,,,,
,3881445552.40526,200.190010070801,-64999.7421875,8.06356181577963E-4,5.0393226289919E-7,1,4,14.0008964538574,4.9936418708021,32.5100012123585,0.999921072122983,0.153444705851044,1,1.22717836818252E-6,,,,,,,,,,,,,,,,,,,,,200.18603515625,200.193984985352,-64999.7421875,-64999.7421875,53.5763360364191,5.88484778382417,4.29126644134521,56,1,0,0,1,0.329513549804687,34.2131004333496,1,1,3,200.18603515625,0,200.190010070801,,,,,,,,,,,,,,,,,,,,,,,,,,,,,,,,,
,3881445639.27719,200.057472229004,-64999.70703125,8.01044207373893E-4,4.22728620876122E-7,1,4,14.0008964538574,4.99375236365492,32.5100012123585,0.99335573213546,0.152497994033567,1,1.26698275783072E-6,,,,,,,,,,,,,,,,,,,,,200.044082641602,200.070861816406,-64999.70703125,-64999.70703125,53.5548412521403,5.88428742951412,4.28569841384888,56,1,0,0,1,0.329971313476562,33.7243423461914,1,1,3,200.070861816406,0,200.057472229004,,,,,,,,,,,,,,,,,,,,,,,,,,,,,,,,,
,3881445727.44476,200.037330627441,-54999.6328125,6.42176364384332E-4,2.8672545538263E-7,1,4,14.0008964538574,4.99371670295839,32.5100012123585,0.796333975573313,0.122289223333478,1,1.04534360809113E-6,,,,,,,,,,,,,,,,,,,,,200.037185668945,200.037475585938,-54999.6328125,-54999.6328125,53.7154659128422,5.88415978555874,4.29385471343994,56,1,0,0,1,0.327224731445313,33.7243423461914,1,1,3,200.037475585938,0,200.037330627441,,,,,,,,,,,,,,,,,,,,,,,,,,,,,,,,,
,3881445815.01183,200.250862121582,-44999.80078125,4.79244521819024E-4,3.51000613580262E-7,1,4,14.0008964538574,4.99363714407871,32.5100012123585,0.594260768188861,0.0913622685710422,1,8.62426028547695E-7,,,,,,,,,,,,,,,,,,,,,200.225021362305,200.276702880859,-44999.80078125,-44999.80078125,53.7893298079095,5.88453505562664,4.28736209869385,56,1,0,0,1,0.329360961914063,34.2131004333496,1,1,3,200.276702880859,0,200.250862121582,,,,,,,,,,,,,,,,,,,,,,,,,,,,,,,,,
,3881445900.93207,200.191230773926,-34999.5546875,3.15150791575868E-4,1.63989342397069E-7,1,4,14.0008964538574,4.99374842772658,32.5100012123585,0.390807897956947,0.0600136844303254,1,5.12355463963545E-7,,,,,,,,,,,,,,,,,,,,,200.182769775391,200.199691772461,-34999.5546875,-34999.5546875,53.7862032938326,5.88411608465858,4.29497957229614,56,1,0,0,1,0.3265380859375,33.7243423461914,1,1,3,200.199691772461,0,200.191230773926,,,,,,,,,,,,,,,,,,,,,,,,,,,,,,,,,
,3881445987.64136,200.202522277832,-24999.732421875,1.51271754604472E-4,9.9184028093633E-8,1,4,14.0008964538574,4.99372524957186,32.5100012123585,0.187579756428404,0.0288460214120962,1,2.77984109209239E-7,,,,,,,,,,,,,,,,,,,,,200.195098876953,200.209945678711,-24999.732421875,-24999.732421875,53.8030083069961,5.88532461721461,4.29632472991943,56,1,0,0,1,0.329513549804687,34.2131004333496,1,1,3,200.209945678711,0,200.202522277832,,,,,,,,,,,,,,,,,,,,,,,,,,,,,,,,,
,3881446072.25088,200.094108581543,-14999.7119140625,-1.12492863354963E-5,5.748284311561E-8,1,4,14.0008964538574,4.9936748313996,32.5100012123585,-0.0139764524562212,-0.00196518898983151,1,1.24374170358244E-7,,,,,,,,,,,,,,,,,,,,,200.067092895508,200.121124267578,-14999.7119140625,-14999.7119140625,53.8733548737269,5.8848349291749,4.29480123519897,56,1,0,0,1,0.326766967773438,34.2131004333496,1,1,3,200.121124267578,0,200.094108581543,,,,,,,,,,,,,,,,,,,,,,,,,,,,,,,,,
,3881446129.4969,200.194747924805,-13999.990234375,-2.73469850142892E-5,4.67817215038479E-8,1,4,14.0008964538574,4.99370279557261,32.5100012123585,-0.033937823580635,-0.00503521880418131,1,9.45000640953736E-8,,,,,,,,,,,,,,,,,,,,,200.186233520508,200.203262329102,-13999.990234375,-13999.990234375,53.8248939055345,5.88431923126018,4.29572868347168,56,1,0,0,1,0.326690673828125,34.7018585205078,1,1,3,200.186233520508,0,200.194747924805,,,,,,,,,,,,,,,,,,,,,,,,,,,,,,,,,
,3881446169.5376,200.181793212891,-13000.205078125,-4.33363252943481E-5,3.98491139675168E-8,1,4,14.0008964538574,4.99369998401134,32.5100012123585,-0.0537695786230739,-0.00805229585557934,1,9.08403827781683E-8,,,,,,,,,,,,,,,,,,,,,200.172302246094,200.191284179687,-13000.205078125,-13000.205078125,53.8397448473999,5.88384611649367,4.29541254043579,56,1,0,0,1,0.330123901367188,34.2131004333496,1,1,3,200.191284179687,0,200.181793212891,,,,,,,,,,,,,,,,,,,,,,,,,,,,,,,,,
,3881446217.64549,200.209892272949,-12000.1318359375,-5.94758917222036E-5,5.25119500812798E-8,1,4,14.0008964538574,4.99366564343356,32.5199998915195,-0.0737828067806195,-0.0111250704023825,1,6.50123180118135E-8,,,,,,,,,,,,,,,,,,,,,200.187973022461,200.231811523438,-12000.1318359375,-12000.1318359375,53.9143903709865,5.88471929351097,4.29189395904541,55,1,68,0,0,0.328216552734375,34.2131004333496,1,1,3,200.231811523438,0,200.209892272949,,,,,,,,,,,,,,,,,,,,,,,,,,,,,,,,,
,3881446256.76297,200.261734008789,-11000.0830078125,-7.51652193921701E-5,3.13516472611455E-8,1,4,14.0008964538574,4.99361850120932,32.5199998915195,-0.0932429037509781,-0.0140731787256335,1,7.1215118180649E-8,,,,,,,,,,,,,,,,,,,,,200.253814697266,200.269653320313,-11000.0830078125,-11000.0830078125,53.8768722020634,5.88528793069946,4.29912900924683,55,1,68,0,0,0.326690673828125,34.2131004333496,1,1,3,200.253814697266,0,200.261734008789,,,,,,,,,,,,,,,,,,,,,,,,,,,,,,,,,
,3881446296.1877,200.162117004395,-10000.3115234375,-9.0862057769002E-5,3.03865089381186E-8,1,4,14.0008964538574,4.99364336946425,32.5199998915195,-0.112706337782965,-0.0170739279676041,1,3.63323012974114E-8,,,,,,,,,,,,,,,,,,,,,200.152282714844,200.171951293945,-10000.3115234375,-10000.3115234375,53.9198617706211,5.88490788750697,4.29955673217773,56,1,0,0,1,0.329132080078125,34.2131004333496,1,1,3,200.171951293945,0,200.162117004395,,,,,,,,,,,,,,,,,,,,,,,,,,,,,,,,,
,3881446335.77166,200.31844329834,-9000.337890625,-1.06177722277458E-4,3.05674158190459E-8,1,4,14.0008964538574,4.99364559302222,32.5199998915195,-0.131699565729877,-0.0199820649099777,1,1.81473699445318E-8,,,,,,,,,,,,,,,,,,,,,200.295944213867,200.340942382813,-9000.337890625,-9000.337890625,53.8944588437461,5.8849953218285,4.30040121078491,55,1,68,0,0,0.330123901367188,34.7018585205078,1,1,3,200.340942382813,0,200.31844329834,,,,,,,,,,,,,,,,,,,,,,,,,,,,,,,,,
,3881446376.24896,200.351005554199,-8000.35205078125,-1.218514310273E-4,3.26961525173478E-8,1,4,14.0008964538574,4.99364749546921,32.5199998915195,-0.15113525543046,-0.0229684848428563,1,-8.76383395460244E-9,,,,,,,,,,,,,,,,,,,,,200.326705932617,200.375305175781,-8000.35205078125,-8000.35205078125,53.9241607274769,5.88483356931238,4.29149198532105,56,1,0,0,1,0.327529907226562,34.2131004333496,1,1,3,200.375305175781,0,200.351005554199,,,,,,,,,,,,,,,,,,,,,,,,,,,,,,,,,
,3881446431.57533,200.394630432129,-7000.17724609375,-1.36566458024327E-4,3.13890888612891E-8,1,4,14.0008964538574,4.99362281871997,32.5199998915195,-0.169384256377175,-0.0257501100851867,1,-1.63385372761625E-8,,,,,,,,,,,,,,,,,,,,,200.392120361328,200.39714050293,-7000.17724609375,-7000.17724609375,53.9495636543519,5.88416767616712,4.29419088363647,54,1,68,0,0,0.32501220703125,34.2131004333496,1,1,3,200.39714050293,0,200.394630432129,,,,,,,,,,,,,,,,,,,,,,,,,,,,,,,,,
,3881446470.43949,200.284965515137,-6000.35546875,-1.505844078511E-4,3.58815407054166E-8,1,4,14.0008964538574,4.99356068499522,32.5199998915195,-0.186763669265347,-0.0284183266939752,1,-3.86357566070191E-8,,,,,,,,,,,,,,,,,,,,,200.278793334961,200.291137695313,-6000.35546875,-6000.35546875,53.821376577198,5.88541543916934,4.29247379302978,54,1,68,0,0,0.330123901367188,34.2131004333496,1,1,3,200.278793334961,0,200.284965515137,,,,,,,,,,,,,,,,,,,,,,,,,,,,,,,,,
,3881446536.74679,200.141380310059,-5000.4072265625,-1.63689072460286E-4,4.63445561130973E-8,1,4,14.0008964538574,4.99365972454191,32.5199998915195,-0.20302174831484,-0.0308971731690686,1,-4.59264938927296E-8,,,,,,,,,,,,,,,,,,,,,200.137191772461,200.145568847656,-5000.4072265625,-5000.4072265625,53.7228913837749,5.88454066574449,4.30068254470825,54,1,68,0,0,0.330123901367188,33.7243423461914,1,1,3,200.137191772461,0,200.141380310059,,,,,,,,,,,,,,,,,,,,,,,,,,,,,,,,,
,3881446603.6262,200.059410095215,-4000.33325195313,-1.74689164304934E-4,3.45552932534101E-8,1,4,14.0008964538574,4.99358152124329,32.5199998915195,-0.216657813694659,-0.0329890598162537,1,-6.214243128516E-8,,,,,,,,,,,,,,,,,,,,,200.056671142578,200.062149047852,-4000.33325195313,-4000.33325195313,53.8745273165057,5.88517353839527,4.29946565628052,55,1,68,0,0,0.328903198242188,34.2131004333496,1,1,3,200.056671142578,0,200.059410095215,,,,,,,,,,,,,,,,,,,,,,,,,,,,,,,,,
,3881446656.93114,200.093276977539,-3000.4609375,-1.81278897651888E-4,3.66505421092717E-8,1,4,14.0008964538574,4.99363703589151,32.5199998915195,-0.224826111133034,-0.0342873841933746,1,-1.07505167439584E-7,,,,,,,,,,,,,,,,,,,,,200.087799072266,200.098754882813,-3000.4609375,-3000.4609375,53.8170776203422,5.88484318905197,4.30112838745117,56,1,0,0,1,0.330047607421875,34.2131004333496,1,1,3,200.098754882813,0,200.093276977539,,,,,,,,,,,,,,,,,,,,,,,,,,,,,,,,,
,3881446713.84128,200.054405212402,-2510.32446289062,-1.81475845296226E-4,2.77082502659957E-8,1,4,14.0008964538574,4.99367551447225,32.5199998915195,-0.225082834184651,-0.0342589444773095,1,-5.43616940095557E-8,,,,,,,,,,,,,,,,,,,,,200.0517578125,200.057052612305,-2510.32446289062,-2510.32446289062,53.8885966298519,5.88501768579377,4.30075597763062,56,1,0,0,1,0.326385498046875,33.7243423461914,1,1,3,200.0517578125,0,200.054405212402,,,,,,,,,,,,,,,,,,,,,,,,,,,,,,,,,
,3881446753.05038,200.069641113281,-1930.43408203125,-1.7723057828286E-4,3.6458474244516E-8,1,4,14.0008964538574,4.99362265434741,32.5199998915195,-0.219810275657619,-0.0334829200559743,1,-7.39648700772075E-8,,,,,,,,,,,,,,,,,,,,,200.069564819336,200.069717407227,-1930.43408203125,-1930.43408203125,53.8753089450249,5.88500320016722,4.30240726470947,56,1,0,0,1,0.330963134765625,34.2131004333496,1,1,3,200.069717407227,0,200.069641113281,,,,,,,,,,,,,,,,,,,,,,,,,,,,,,,,,
,3881446791.99319,200.123420715332,-1350.2666015625,-1.63963628177811E-4,2.96186747885798E-8,1,4,14.0008964538574,4.99362622755234,32.5199998915195,-0.203354671241277,-0.0309861947340736,1,-7.62281875923474E-8,,,,,,,,,,,,,,,,,,,,,200.110473632813,200.136367797852,-1350.2666015625,-1350.2666015625,53.8108245921884,5.8850807884494,4.30188703536987,56,1,0,0,1,0.329513549804687,33.7243423461914,1,1,3,200.136367797852,0,200.123420715332,,,,,,,,,,,,,,,,,,,,,,,,,,,,,,,,,
,3881446830.90071,200.314468383789,-770.539672851562,-1.34312613596122E-4,1.78074849157829E-8,1,4,14.0008964538574,4.9937767772297,32.5299985706806,-0.166581898306484,-0.0254190277707513,1,-9.08801368695057E-8,,,,,,,,,,,,,,,,,,,,,200.308013916016,200.320922851562,-770.539672851562,-770.539672851562,53.7893298079095,5.88407018793816,4.29693269729614,56,1,0,0,1,0.326995849609375,34.2131004333496,1,1,3,200.320922851562,0,200.314468383789,,,,,,,,,,,,,,,,,,,,,,,,,,,,,,,,,
,3881446871.19814,200.306137084961,-190.170776367187,-6.44449589037898E-5,1.43343981139552E-8,1,4,14.0008964538574,4.99369333757724,32.5199998915195,-0.0799323113782124,-0.0121566248173516,1,-1.17809933443628E-8,,,,,,,,,,,,,,,,,,,,,200.296005249023,200.316268920898,-190.170776367187,-190.170776367187,53.7486851249095,5.88470716778774,4.3000693321228,56,1,0,0,1,0.330581665039063,34.2131004333496,1,1,3,200.316268920898,0,200.306137084961,,,,,,,,,,,,,,,,,,,,,,,,,,,,,,,,,
,3881446910.89302,200.338691711426,389.505767822266,7.78908562257441E-5,2.00647413138531E-8,1,4,14.0008964538574,4.99369021487702,32.5199998915195,0.0965993736185578,0.0147591906781717,1,6.76121029839487E-8,,,,,,,,,,,,,,,,,,,,,200.322891235352,200.3544921875,389.505767822266,389.505767822266,53.9206433991403,5.88393260559988,4.29929780960083,56,1,0,0,1,0.328140258789063,33.7243423461914,1,1,3,200.3544921875,0,200.338691711426,,,,,,,,,,,,,,,,,,,,,,,,,,,,,,,,,
,3881446950.33145,200.281387329102,969.459228515625,1.39815156451737E-4,2.55916033008284E-8,1,4,14.0008964538574,4.99368217203229,32.5199998915195,0.173408303573497,0.0264172299533922,1,6.03655631156351E-8,,,,,,,,,,,,,,,,,,,,,200.272659301758,200.290115356445,969.459228515625,969.459228515625,53.9104822283903,5.88442474453665,4.29792928695679,56,1,0,0,1,0.329437255859375,34.2131004333496,1,1,3,200.290115356445,0,200.281387329102,,,,,,,,,,,,,,,,,,,,,,,,,,,,,,,,,
,3881446990.02016,200.261535644531,1549.76525878906,1.66060546343965E-4,2.92752423078369E-8,1,4,14.0008964538574,4.99370625027308,32.5199998915195,0.205957880543383,0.0313970135602498,1,8.83565077318698E-8,,,,,,,,,,,,,,,,,,,,,200.256790161133,200.26628112793,1549.76525878906,1549.76525878906,53.8194225058999,5.8839033323526,4.29644393920898,56,1,0,0,1,0.3265380859375,34.2131004333496,1,1,3,200.26628112793,0,200.261535644531,,,,,,,,,,,,,,,,,,,,,,,,,,,,,,,,,
,3881447028.79828,200.235321044922,2129.71875,1.76956737346669E-4,3.68178557274601E-8,1,4,14.0008964538574,4.9935793441838,32.5199998915195,0.219464209104648,0.0334555892129119,1,9.38537350241073E-8,,,,,,,,,,,,,,,,,,,,,200.218338012695,200.252304077148,2129.71875,2129.71875,53.8542049750057,5.88503792156421,4.30321168899536,56,1,0,0,1,0.329666137695313,33.7243423461914,1,1,3,200.252304077148,0,200.235321044922,,,,,,,,,,,,,,,,,,,,,,,,,,,,,,,,,
,3881447067.64201,200.216651916504,2709.78564453125,1.79442678825432E-4,4.0619146254283E-8,1,4,14.0008964538574,4.9937671114461,32.5199998915195,0.222554595513761,0.0339565724393716,1,1.18715000845021E-7,,,,,,,,,,,,,,,,,,,,,200.215759277344,200.217544555664,2709.78564453125,2709.78564453125,53.8655385885345,5.88358112206684,4.30521202087402,56,1,0,0,1,0.326309204101562,33.7243423461914,1,1,3,200.215759277344,0,200.216651916504,,,,,,,,,,,,,,,,,,,,,,,,,,,,,,,,,
,3881447128.78987,200.438087463379,3499.81176757812,1.76620727226783E-4,2.61066518995202E-8,1,4,14.0008964538574,4.99374255480779,32.5199998915195,0.219060142112591,0.033376291634814,1,7.97279587328569E-8,,,,,,,,,,,,,,,,,,,,,200.437805175781,200.438369750977,3499.81176757812,3499.81176757812,53.7768237516018,5.88415602899508,4.29811382293701,56,1,0,0,1,0.329208374023438,34.2131004333496,1,1,3,200.437805175781,0,200.438087463379,,,,,,,,,,,,,,,,,,,,,,,,,,,,,,,,,
,3881447169.72259,200.32836151123,4499.4951171875,1.67856431203095E-4,3.28898211067913E-8,1,4,14.0008964538574,4.99374525648438,32.5199998915195,0.208182378865413,0.0317707453263406,1,1.16591881812872E-7,,,,,,,,,,,,,,,,,,,,,200.32666015625,200.330062866211,4499.4951171875,4499.4951171875,53.9249423559961,5.88376302387303,4.3011326789856,56,1,0,0,1,0.32958984375,33.7243423461914,1,1,3,200.330062866211,0,200.32836151123,,,,,,,,,,,,,,,,,,,,,,,,,,,,,,,,,
,3881447210.67738,200.282196044922,5499.6826171875,1.55433918468966E-4,2.81095755021557E-8,1,4,14.0008964538574,4.99367513958496,32.5199998915195,0.192769457023738,0.0294335579273449,1,1.19767726449604E-7,,,,,,,,,,,,,,,,,,,,,200.278076171875,200.286315917969,5499.6826171875,5499.6826171875,53.8987578006019,5.88422887121262,4.29827833175659,56,1,0,0,1,0.329513549804687,33.7243423461914,1,1,3,200.278076171875,0,200.282196044922,,,,,,,,,,,,,,,,,,,,,,,,,,,,,,,,,
,3881447250.53479,200.327415466309,6499.60546875,1.42335014519926E-4,3.13125152034027E-8,1,4,14.0008964538574,4.9935961373496,32.5299985706806,0.176521559254676,0.0269439347629876,1,1.0276699717051E-7,,,,,,,,,,,,,,,,,,,,,200.310134887695,200.344696044922,6499.60546875,6499.60546875,53.8049623782942,5.88509300013777,4.29807710647583,56,1,0,0,1,0.327377319335937,33.7243423461914,1,1,3,200.344696044922,0,200.327415466309,,,,,,,,,,,,,,,,,,,,,,,,,,,,,,,,,
,3881447290.82715,200.265716552734,7499.71728515625,1.27509886541854E-4,3.09652460377619E-8,1,4,14.0008964538574,4.9937495841328,32.5199998915195,0.158142970462303,0.0241353909092217,1,8.94873895395153E-8,,,,,,,,,,,,,,,,,,,,,200.254425048828,200.277008056641,7499.71728515625,7499.71728515625,53.8088705208903,5.88413809212487,4.30001306533814,56,1,0,0,1,0.327224731445313,34.2131004333496,1,1,3,200.254425048828,0,200.265716552734,,,,,,,,,,,,,,,,,,,,,,,,,,,,,,,,,
,3881447330.32062,200.35196685791,8499.615234375,1.12615481362541E-4,2.64518745407027E-8,1,4,14.0008964538574,4.99371397773597,32.5199998915195,0.139671575248445,0.0212984840886462,1,6.49710872655652E-8,,,,,,,,,,,,,,,,,,,,,200.348831176758,200.355102539062,8499.615234375,8499.615234375,53.8252847197942,5.88385638269885,4.29831552505493,54,1,68,0,0,0.328521728515625,33.7243423461914,1,1,3,200.348831176758,0,200.35196685791,,,,,,,,,,,,,,,,,,,,,,,,,,,,,,,,,
,3881447370.29324,200.205810546875,9499.865234375,9.72771497132279E-5,3.12788198122467E-8,1,4,14.0008964538574,4.99392945304408,32.5199998915195,0.120652706375272,0.0184169274192782,1,7.07976885331878E-8,,,,,,,,,,,,,,,,,,,,,200.204452514648,200.207168579102,9499.865234375,9499.865234375,53.7783870086403,5.88281583476959,4.29812240600586,56,1,0,0,1,0.3271484375,33.7243423461914,1,1,3,200.204452514648,0,200.205810546875,,,,,,,,,,,,,,,,,,,,,,,,,,,,,,,,,
,3881447410.03152,200.205474853516,10499.7626953125,8.17599695383912E-5,2.96747034060204E-8,1,4,14.0008964538574,4.99378923204718,32.5199998915195,0.101402727552718,0.0154788970495702,1,5.97926906671985E-8,,,,,,,,,,,,,,,,,,,,,200.184295654297,200.226654052734,10499.7626953125,10499.7626953125,53.6877181004095,5.88364227925287,4.30537796020508,56,1,0,0,1,0.330581665039063,34.7018585205078,1,1,3,200.226654052734,0,200.205474853516,,,,,,,,,,,,,,,,,,,,,,,,,,,,,,,,,
,3881447449.56874,200.342407226562,11500.0634765625,6.62963115889023E-5,4.58249578620423E-8,1,4,14.0008964538574,4.99373485121745,32.5299985706806,0.082226714865305,0.0125245810013876,1,2.70982091535685E-8,,,,,,,,,,,,,,,,,,,,,200.341873168945,200.34294128418,11500.0634765625,11500.0634765625,53.8635845172365,5.8836185774954,4.29872417449951,56,1,0,0,1,0.327072143554687,33.7243423461914,1,1,3,200.341873168945,0,200.342407226562,,,,,,,,,,,,,,,,,,,,,,,,,,,,,,,,,
,3881447489.45952,200.426307678223,12499.935546875,5.04731427394848E-5,4.13349014016047E-8,1,4,14.0008964538574,4.99372221154089,32.5299985706806,0.062602825893763,0.00952429440839176,1,1.17880728611296E-8,,,,,,,,,,,,,,,,,,,,,200.418869018555,200.433746337891,12499.935546875,12499.935546875,53.8655385885345,5.88413264682192,4.29889535903931,56,1,0,0,1,0.329742431640625,33.7243423461914,1,1,3,200.433746337891,0,200.426307678223,,,,,,,,,,,,,,,,,,,,,,,,,,,,,,,,,
,3881447612.15444,200.158020019531,13499.8330078125,3.43646969623882E-5,4.24493140646475E-8,1,4,14.0008964538574,4.99369127807745,32.5299985706806,0.0426350425312961,0.00640420947780754,1,-5.67628954415061E-8,,,,,,,,,,,,,,,,,,,,,200.147338867187,200.168701171875,13499.8330078125,13499.8330078125,53.9241607274769,5.8840509741182,4.30630826950073,56,1,0,0,1,0.32745361328125,34.2131004333496,1,1,3,200.147338867187,0,200.158020019531,,,,,,,,,,,,,,,,,,,,,,,,,,,,,,,,,
,3881447652.55208,200.142936706543,14499.7060546875,1.85643773626486E-5,5.16970907487711E-8,1,4,14.0008964538574,4.99369647451537,32.5199998915195,0.0230283973764325,0.00348462183787521,1,-1.05434195000893E-8,,,,,,,,,,,,,,,,,,,,,200.122375488281,200.163497924805,14499.7060546875,14499.7060546875,53.8116062207076,5.88468283295929,4.30773401260376,56,1,0,0,1,0.32684326171875,33.7243423461914,1,1,3,200.163497924805,0,200.142936706543,,,,,,,,,,,,,,,,,,,,,,,,,,,,,,,,,
,3881447827.49473,200.13744354248,19999.767578125,-7.03722605305065E-5,7.38949004708493E-8,1,4,14.0008964538574,4.99368932967643,32.5199998915195,-0.0872704177150248,-0.0133638539228775,1,-8.47335652566222E-8,,,,,,,,,,,,,,,,,,,,,200.135467529297,200.139419555664,19999.767578125,19999.767578125,53.8643661457557,5.88442109292034,4.30895280838013,56,1,0,0,1,0.329208374023438,33.7243423461914,1,1,3,200.135467529297,0,200.13744354248,,,,,,,,,,,,,,,,,,,,,,,,,,,,,,,,,
,3881447912.42283,200.254013061523,30000.115234375,-2.3294710190373E-4,1.3879175998798E-7,1,4,14.0008964538574,4.99362862463925,32.5299985706806,-0.288879602319108,-0.0442302667433898,1,-2.7551186649502E-7,,,,,,,,,,,,,,,,,,,,,200.242980957031,200.265045166016,30000.115234375,30000.115234375,53.7076496276499,5.8852408942775,4.30732727050781,56,1,0,0,1,0.326461791992188,33.7243423461914,1,1,3,200.265045166016,0,200.254013061523,,,,,,,,,,,,,,,,,,,,,,,,,,,,,,,,,
,3881447997.37859,200.126861572266,40000.37890625,-3.95994884715369E-4,2.02672357908976E-7,1,4,14.0008964538574,4.99364065047068,32.5199998915195,-0.49105670739309,-0.0753299552717064,1,-5.82137604790417E-7,,,,,,,,,,,,,,,,,,,,,200.106979370117,200.146743774414,40000.37890625,40000.37890625,53.6490274887076,5.88503210523277,4.30963087081909,56,1,0,0,1,0.32745361328125,34.2131004333496,1,1,3,200.146743774414,0,200.126861572266,,,,,,,,,,,,,,,,,,,,,,,,,,,,,,,,,
,3881448092.40963,200.263572692871,50000.1328125,-5.61005090901349E-4,3.44325146766654E-7,1,4,14.0008964538574,4.99373432483239,32.5199998915195,-0.695824836476697,-0.105882646316723,10,-1.47541528272458E-7,,,,,,,,,,,,,,,,,,,,,200.263397216797,200.263748168945,50000.1328125,50000.1328125,53.6783385581788,5.88382682416424,4.30454111099243,56,1,0,0,1,0.327911376953125,34.2131004333496,1,1,3,200.263748168945,0,200.263572692871,,,,,,,,,,,,,,,,,,,,,,,,,,,,,,,,,
,3881448184.11344,200.164154052734,60000.24609375,-7.2425571623051E-4,3.11193355010743E-7,1,4,14.0008964538574,4.99374013429965,32.5199998915195,-0.898104243847069,-0.138042509504454,1,-1.27736170067798E-6,,,,,,,,,,,,,,,,,,,,,200.130706787109,200.197601318359,60000.24609375,60000.24609375,53.6556713311211,5.88415339118558,4.30976581573486,56,1,0,0,1,0.327987670898438,33.7243423461914,1,1,3,200.197601318359,0,200.164154052734,,,,,,,,,,,,,,,,,,,,,,,,,,,,,,,,,
,3881448270.03305,200.189712524414,70000.390625,-8.87149817886171E-4,4.22801715045727E-7,1,4,14.0008964538574,4.99369959165827,32.5199998915195,-1.10007266131788,-0.169179334773541,1,-1.63824340026199E-6,,,,,,,,,,,,,,,,,,,,,200.162872314453,200.216552734375,70000.390625,70000.390625,53.5548412521403,5.8834822041625,4.30645513534546,56,1,0,0,1,0.328598022460937,33.7243423461914,1,1,3,200.216552734375,0,200.189712524414,,,,,,,,,,,,,,,,,,,,,,,,,,,,,,,,,
,3881448273.90224,200.243850708008,70000.390625,-8.89383874976655E-4,5.28266798439173E-7,1,4,14.0008964538574,4.99368958401299,32.5199998915195,-1.10286399042302,-0.16944572756162,1,-1.51404614647528E-6,,,,,,,,,,,,,,,,,,,,,200.216552734375,200.271148681641,70000.390625,70000.390625,53.6216704905345,5.88439604199126,4.30108165740967,56,2,0,0,1,0.325546264648438,33.7243423461914,1,1,3,200.271148681641,0,200.243850708008,,,,,,,,,,,,,,,,,,,,,,,,,,,,,,,,,