File: SQUID/22172_LCOL/22172_LCOL_MH_50K_FC_p0d5T.csv
Comment,Time Stamp (sec),Temperature (K),Magnetic Field (Oe),Moment (emu),M. Std. Err. (emu),Transport Action,Averaging Time (sec),Frequency (Hz),Peak Amplitude (mm),Center Position (mm),Lockin Signal' (V),Lockin Signal (V),Range,M. Quad. Signal (emu),AC Moment (emu),AC M. Std Err. (emu),AC Phase (deg),AC Phase Std. Err. (deg),AC Susceptibility (emu/Oe),AC Suscept. Std Err. (emu/Oe),AC X' (emu/Oe),AC X' Std Err. (emu/Oe),AC X'' (emu/Oe),AC X'' Std Err. (emu/Oe),AC Drive (Oe),AC Frequency (Hz),AC Averaging Time (sec),AC Cycles,AC Range,AC Measure Type,AC Signal' (V),AC Signal'' (V),AC Trim Coil Ratio,AC Trim Coil Phase,Min. Temperature (K),Max. Temperature (K),Min. Field (Oe),Max. Field (Oe),Mass (grams),Motor Lag (deg),Pressure (Torr),Measure Count,Measurement Number,SQUID Status (code),Motor Status (code),Measure Status (code),Motor Current (amps),Motor Temp. (C),Temp. Status (code),Field Status (code),Chamber Status (code),Chamber Temp (K),Redirection State,Average Temp (K),Rotation Angle (deg),Rotator state,DC Moment Fixed Ctr (emu),DC Moment Err Fixed Ctr (emu),DC Moment Free Ctr (emu),DC Moment Err Free Ctr (emu),DC Fixed Fit,DC Free Fit,DC Calculated Center (mm),DC Calculated Center Err (mm),DC Scan Length (mm),DC Scan Time (s),DC Number of Points,DC Squid Drift,DC Min V (V),DC Max V (V),DC Scans per Measure,Map 01,Map 02,Map 03,Map 04,Map 05,Map 06,Map 07,Map 08,Map 09,Map 10,Map 11,Map 12,Map 13,Map 14,Map 15,Map 16
,3881494516.39503,49.9996662139893,70000.4296875,-7.66642319103882E-4,1.21710676028182E-5,1,4,14.0008964538574,4.98360699747479,32.4000008404255,-0.947138401181925,-0.151126659944527,100,-5.73491148966363E-6,,,,,,,,,,,,,,,,,,,,,49.9996223449707,49.9997100830078,70000.4296875,70000.4296875,52.9971493036691,5.88400566381695,4.16785717010498,56,1,0,0,1,0.326080322265625,31.2805480957031,1,1,3,49.9997100830078,0,49.9996662139893,,,,,,,,,,,,,,,,,,,,,,,,,,,,,,,,,
,3881494602.91065,50.0003643035889,60000.3203125,-6.37257054011931E-4,6.92625464754402E-5,1,4,14.0008964538574,4.98342893657893,32.4000008404255,-0.804749555578259,-0.0104203844742352,100,8.83735924105599E-5,,,,,,,,,,,,,,,,,,,,,50.0002593994141,50.0004692077637,60000.3203125,60000.3203125,53.2171777318326,5.8853182292312,4.14663124084473,56,1,0,0,1,0.325927734375,32.2580642700195,1,1,3,50.0004692077637,0,50.0003643035889,,,,,,,,,,,,,,,,,,,,,,,,,,,,,,,,,
,3881494691.18113,49.9398937225342,50000.21875,-8.61964664214487E-4,3.82606179392102E-4,1,4,14.0008964538574,4.98341703703991,32.4000008404255,-1.09332857548633,0.0175997041171177,100,1.45162272152819E-4,,,,,,,,,,,,,,,,,,,,,49.934741973877,49.9450454711914,50000.21875,50000.21875,53.2992487263518,5.88522072647506,4.11463356018066,55,1,68,0,0,0.327072143554687,32.7468223571777,1,1,3,49.934741973877,0,49.9398937225342,,,,,,,,,,,,,,,,,,,,,,,,,,,,,,,,,
,3881494776.81032,49.9669857025146,40000.15234375,-3.44853190561445E-4,1.37607506706264E-5,1,4,14.0008964538574,4.9833651212204,32.4000008404255,-0.424126917031113,-0.0804082357468204,100,-1.26323033740592E-5,,,,,,,,,,,,,,,,,,,,,49.9647178649902,49.9692535400391,40000.15234375,40000.15234375,53.1820044484672,5.88483031624085,4.09797620773315,56,1,0,0,1,0.32745361328125,33.7243423461914,1,1,3,49.9692535400391,0,49.9669857025146,,,,,,,,,,,,,,,,,,,,,,,,,,,,,,,,,
,3881494870.34716,50.0144481658936,30000.015625,-1.93638622771706E-4,1.28491630465935E-5,1,4,14.0008964538574,4.98338768318359,32.4000008404255,-0.241433542047177,-0.0235545333205366,10,1.03683428548719E-5,,,,,,,,,,,,,,,,,,,,,50.0128593444824,50.0160369873047,30000.015625,30000.015625,53.2980762835729,5.88355042326435,4.09465312957764,56,1,0,0,1,0.327987670898438,33.2355842590332,1,1,3,50.0160369873047,0,50.0144481658936,,,,,,,,,,,,,,,,,,,,,,,,,,,,,,,,,
,3881494955.2814,50.0359725952148,19999.56640625,-5.41663387711886E-5,7.16316301643694E-8,1,4,14.0008964538574,4.9833581878774,32.4000008404255,-0.0669811670386955,-0.010237533918328,10,-4.98941783285372E-8,,,,,,,,,,,,,,,,,,,,,50.0306396484375,50.0413055419922,19999.56640625,19999.56640625,53.355916793996,5.8845381590894,4.0898756980896,56,1,0,0,1,0.325546264648438,33.7243423461914,1,1,3,50.0413055419922,0,50.0359725952148,,,,,,,,,,,,,,,,,,,,,,,,,,,,,,,,,
,3881495016.9406,50.0048542022705,14499.6552734375,2.52576478460146E-5,3.38852037823753E-8,1,4,14.0008964538574,4.98336696237547,32.4000008404255,0.0312587877646464,0.00460564234565508,10,-1.12661990853988E-7,,,,,,,,,,,,,,,,,,,,,50.004810333252,50.0048980712891,14499.6552734375,14499.6552734375,53.5653932371499,5.88423358869142,4.09159851074219,56,1,0,0,1,0.324630737304687,33.7243423461914,1,1,3,50.0048980712891,0,50.0048542022705,,,,,,,,,,,,,,,,,,,,,,,,,,,,,,,,,
,3881495065.79303,50.0007553100586,13499.732421875,3.96936649010835E-5,4.2531717295473E-8,1,4,14.0008964538574,4.98333608028887,32.4000008404255,0.0491031015300096,0.00737769707563145,1,-6.40469566601635E-8,,,,,,,,,,,,,,,,,,,,,50.0006446838379,50.0008659362793,13499.732421875,13499.732421875,53.3379393380537,5.88463876165657,4.09107351303101,56,1,0,0,1,0.32806396484375,33.7243423461914,1,1,3,50.0006446838379,0,50.0007553100586,,,,,,,,,,,,,,,,,,,,,,,,,,,,,,,,,
,3881495105.03125,50.0163822174072,12499.5576171875,5.39665167617847E-5,4.1191709461205E-8,1,4,14.0008964538574,4.98328717833218,32.4000008404255,0.0667552799470103,0.0100511515816989,1,-7.02930748748335E-8,,,,,,,,,,,,,,,,,,,,,50.0161666870117,50.0165977478027,12499.5576171875,12499.5576171875,53.3606065651114,5.88474493847677,4.09534692764282,56,1,0,0,1,0.328521728515625,33.2355842590332,1,1,3,50.0165977478027,0,50.0163822174072,,,,,,,,,,,,,,,,,,,,,,,,,,,,,,,,,
,3881495145.51648,50.0431041717529,11499.6220703125,6.81405751426021E-5,3.34714012177071E-8,1,4,14.0008964538574,4.98336619626356,32.4000008404255,0.0842853654886627,0.0127226478170931,1,-6.3426960860728E-8,,,,,,,,,,,,,,,,,,,,,50.0416984558105,50.0445098876953,11499.6220703125,11499.6220703125,53.2730641709576,5.88409464398991,4.09306716918945,56,1,0,0,1,0.328292846679687,34.2131004333496,1,1,3,50.0445098876953,0,50.0431041717529,,,,,,,,,,,,,,,,,,,,,,,,,,,,,,,,,
,3881495184.91525,50.0409965515137,10499.5361328125,8.2112145748006E-5,3.04488199074196E-8,1,4,14.0008964538574,4.98324465847807,32.4000008404255,0.101555845818304,0.015383109175303,1,-3.41189984035019E-8,,,,,,,,,,,,,,,,,,,,,50.0369911193848,50.0450019836426,10499.5361328125,10499.5361328125,53.470816186323,5.88518871614863,4.09168815612793,56,1,0,0,1,0.327072143554687,33.7243423461914,1,1,3,50.0450019836426,0,50.0409965515137,,,,,,,,,,,,,,,,,,,,,,,,,,,,,,,,,
,3881495225.18842,50.0385303497314,9499.525390625,9.56418159431944E-5,4.38106517970585E-8,1,4,14.0008964538574,4.98334612200012,32.4000008404255,0.118295960564037,0.0178964866148714,1,-5.73830668834571E-8,,,,,,,,,,,,,,,,,,,,,50.0349769592285,50.0420837402344,9499.525390625,9499.525390625,53.3395025950922,5.88367338095501,4.09191179275513,56,1,0,0,1,0.327301025390625,33.7243423461914,1,1,3,50.0349769592285,0,50.0385303497314,,,,,,,,,,,,,,,,,,,,,,,,,,,,,,,,,
,3881495264.70497,50.026195526123,8499.58984375,1.09438460568446E-4,4.29606293410523E-8,1,4,14.0008964538574,4.98325258889493,32.4000008404255,0.135356692769199,0.0204794305361465,1,-6.41595898216041E-8,,,,,,,,,,,,,,,,,,,,,50.0230331420898,50.0293579101562,8499.58984375,8499.58984375,53.4227460323903,5.88505737395339,4.09539413452148,55,1,68,0,0,0.3253173828125,33.7243423461914,1,1,3,50.0293579101562,0,50.026195526123,,,,,,,,,,,,,,,,,,,,,,,,,,,,,,,,,
,3881495305.70057,50.0468864440918,7499.60400390625,1.22578850337864E-4,5.12108988821252E-8,1,4,14.0008964538574,4.98328404424184,32.4099995195866,0.151609465120399,0.0229451332288828,1,-6.65969884318009E-8,,,,,,,,,,,,,,,,,,,,,50.0464706420898,50.0473022460937,7499.60400390625,7499.60400390625,53.3531810941787,5.88370008589168,4.09309720993042,55,1,68,0,0,0.327529907226562,33.7243423461914,1,1,3,50.0464706420898,0,50.0468864440918,,,,,,,,,,,,,,,,,,,,,,,,,,,,,,,,,
,3881495346.45885,50.0095729827881,6499.4921875,1.35787597377508E-4,6.77966283373383E-8,1,4,14.0008964538574,4.98333474271849,32.4000008404255,0.167941627385167,0.0254656510051121,1,-3.52425005456933E-8,,,,,,,,,,,,,,,,,,,,,50.0087203979492,50.010425567627,6499.4921875,6499.4921875,53.4735518861403,5.88379433701017,4.09521198272705,56,1,0,0,1,0.326995849609375,33.7243423461914,1,1,3,50.0087203979492,0,50.0095729827881,,,,,,,,,,,,,,,,,,,,,,,,,,,,,,,,,
,3881495400.92844,50.018196105957,5499.5947265625,1.47515437358233E-4,6.79374199439011E-8,1,4,14.0008964538574,4.98332469933881,32.4000008404255,0.18245020409922,0.0276377541705625,1,-6.03293950349119E-8,,,,,,,,,,,,,,,,,,,,,50.0146179199219,50.0217742919922,5499.5947265625,5499.5947265625,53.2871334843037,5.88401085045128,4.09430551528931,56,1,0,0,1,0.327072143554687,34.2131004333496,1,1,3,50.0217742919922,0,50.018196105957,,,,,,,,,,,,,,,,,,,,,,,,,,,,,,,,,
,3881495440.43638,50.0202121734619,4499.58349609375,1.58655855902065E-4,1.17943680359381E-7,1,4,14.0008964538574,4.98331995849195,32.4000008404255,0.196221914439554,0.0297692485290382,1,-2.90486369707456E-8,,,,,,,,,,,,,,,,,,,,,50.020076751709,50.0203475952148,4499.58349609375,4499.58349609375,53.5274842539672,5.88449803354941,4.0915093421936,56,1,0,0,1,0.3277587890625,34.2131004333496,1,1,3,50.020076751709,0,50.0202121734619,,,,,,,,,,,,,,,,,,,,,,,,,,,,,,,,,
,3881495481.63378,50.0042953491211,3499.623046875,1.66468946657233E-4,8.83989061790844E-8,1,4,14.0008964538574,4.98343894150396,32.4000008404255,0.20589357122854,0.0312250510550285,1,-3.95722132117553E-8,,,,,,,,,,,,,,,,,,,,,50.003978729248,50.0046119689941,3499.623046875,3499.623046875,53.355916793996,5.88365365546352,4.08644580841064,55,1,68,0,0,0.328445434570313,33.7243423461914,1,1,3,50.003978729248,0,50.0042953491211,,,,,,,,,,,,,,,,,,,,,,,,,,,,,,,,,
,3881495551.91733,50.030252456665,2709.79809570313,1.68682930547738E-4,1.02762384187079E-7,1,4,14.0008964538574,4.98327934991392,32.4000008404255,0.208615018150491,0.0316882685272248,1,-1.89998940237948E-10,,,,,,,,,,,,,,,,,,,,,50.0301246643066,50.0303802490234,2709.79809570313,2709.79809570313,53.4231368466499,5.88456682367975,4.09421682357788,56,1,0,0,1,0.324859619140625,33.2355842590332,1,1,3,50.0301246643066,0,50.030252456665,,,,,,,,,,,,,,,,,,,,,,,,,,,,,,,,,
,3881495590.06035,50.0176372528076,2129.56762695313,1.66369169932397E-4,1.43605283442421E-7,1,4,14.0008964538574,4.98337525789598,32.4000008404255,0.205763836248596,0.0312231473145381,1,-2.55027749309177E-8,,,,,,,,,,,,,,,,,,,,,50.015754699707,50.0195198059082,2129.56762695313,2129.56762695313,53.3461464375056,5.88323377119623,4.09227180480957,56,1,0,0,1,0.330047607421875,34.2131004333496,1,1,3,50.015754699707,0,50.0176372528076,,,,,,,,,,,,,,,,,,,,,,,,,,,,,,,,,
,3881495629.18852,50.0272750854492,1549.68969726562,1.57106331983395E-4,8.27682530148578E-8,1,4,14.0008964538574,4.98340518597223,32.4000008404255,0.19430784542485,0.0294944611636914,1,-1.64354565037913E-8,,,,,,,,,,,,,,,,,,,,,50.0271110534668,50.0274391174316,1549.68969726562,1549.68969726562,53.3934349629191,5.88341739169252,4.0918436050415,56,1,0,0,1,0.330047607421875,33.7243423461914,1,1,3,50.0271110534668,0,50.0272750854492,,,,,,,,,,,,,,,,,,,,,,,,,,,,,,,,,
,3881495669.22814,50.0219440460205,969.459228515625,1.36572535096275E-4,8.60454947074307E-8,1,4,14.0008964538574,4.98340541629527,32.4099995195866,0.168916264741333,0.0256102879985236,1,-3.79367111463453E-8,,,,,,,,,,,,,,,,,,,,,50.0198974609375,50.0239906311035,969.459228515625,969.459228515625,53.4461948879672,5.8839779017896,4.08947038650513,56,1,0,0,1,0.326766967773438,33.7243423461914,1,1,3,50.0196113586426,0,50.0219440460205,,,,,,,,,,,,,,,,,,,,,,,,,,,,,,,,,
,3881495708.57999,50.0056667327881,389.518371582031,9.06178731440914E-5,1.15253942291141E-7,1,4,14.0008964538574,4.98336296235305,32.4000008404255,0.112081861970201,0.0169610554028389,1,-5.06752474867081E-8,,,,,,,,,,,,,,,,,,,,,50.0053215026855,50.0060119628906,389.518371582031,389.518371582031,53.3836646064287,5.8838408165388,4.08360195159912,56,1,0,0,1,0.325698852539063,33.7243423461914,1,1,3,50.0053215026855,0,50.0056667327881,,,,,,,,,,,,,,,,,,,,,,,,,,,,,,,,,
,3881495747.16027,50.0068855285645,-190.309234619141,-2.71910003515757E-5,3.54389750719216E-8,1,4,14.0008964538574,4.98339040149208,32.4000008404255,-0.033636202051627,-0.00506038096450767,1,3.86784757099537E-8,,,,,,,,,,,,,,,,,,,,,50.0060234069824,50.0077476501465,-190.309234619141,-190.309234619141,53.4395510455537,5.88454889968879,4.08576345443726,56,1,0,0,1,0.326309204101562,33.7243423461914,1,1,3,50.0077476501465,0,50.0068855285645,,,,,,,,,,,,,,,,,,,,,,,,,,,,,,,,,
,3881495784.08939,50.008659362793,-769.985778808594,-1.09776497148701E-4,6.12628534981899E-8,1,4,14.0008964538574,4.98322295094193,32.4000008404255,-0.13577429642275,-0.0205382821669679,1,6.77816713166384E-8,,,,,,,,,,,,,,,,,,,,,50.007984161377,50.009334564209,-769.985778808594,-769.985778808594,53.4481489592653,5.88512005720393,4.08825826644897,56,1,0,0,1,0.325393676757812,33.7243423461914,1,1,3,50.009334564209,0,50.008659362793,,,,,,,,,,,,,,,,,,,,,,,,,,,,,,,,,
,3881495821.73152,50.0193099975586,-1350.00219726562,-1.44203684641865E-4,1.13817076530383E-7,1,4,14.0008964538574,4.98332388141639,32.4000008404255,-0.178339097790078,-0.0271161532747287,1,-2.09758714741719E-8,,,,,,,,,,,,,,,,,,,,,50.0177955627441,50.020824432373,-1350.00219726562,-1350.00219726562,53.4669080437268,5.88450785248656,4.08691167831421,56,1,0,0,1,0.3265380859375,34.2131004333496,1,1,3,50.0177955627441,0,50.0193099975586,,,,,,,,,,,,,,,,,,,,,,,,,,,,,,,,,
,3881495860.42208,50.0287837982178,-1929.96826171875,-1.59819081402794E-4,1.03287154391313E-7,1,4,14.0008964538574,4.98347265525619,32.4000008404255,-0.197666441997455,-0.0300060553896523,1,1.530878851E-8,,,,,,,,,,,,,,,,,,,,,50.0278167724609,50.0297508239746,-1929.96826171875,-1929.96826171875,53.5102884265441,5.88361784486322,4.08490324020386,56,1,0,0,1,0.325164794921875,33.7243423461914,1,1,3,50.0297508239746,0,50.0287837982178,,,,,,,,,,,,,,,,,,,,,,,,,,,,,,,,,
,3881495898.22625,50.0079536437988,-2509.95971679687,-1.65654816912172E-4,1.11092397133958E-7,1,4,14.0008964538574,4.98336594191552,32.4000008404255,-0.204886850760546,-0.031042541556196,1,6.29582482130235E-8,,,,,,,,,,,,,,,,,,,,,50.0071754455566,50.008731842041,-2509.95971679687,-2509.95971679687,53.5626575373326,5.88411974679833,4.08182525634766,56,1,0,0,1,0.324859619140625,33.7243423461914,1,1,3,50.0071754455566,0,50.0079536437988,,,,,,,,,,,,,,,,,,,,,,,,,,,,,,,,,
,3881495949.79241,50.0008239746094,-2999.91967773438,-1.67124696226388E-4,1.67997009754056E-7,1,4,14.0008964538574,4.98341151778466,32.4099995195866,-0.206704617822889,-0.0313373242879432,1,4.82062118335367E-8,,,,,,,,,,,,,,,,,,,,,50.0007858276367,50.000862121582,-2999.91967773438,-2999.91967773438,53.3821013493903,5.88358900955403,4.08843088150024,56,1,0,0,1,0.32623291015625,34.2131004333496,1,1,3,50.0007858276367,0,50.0008239746094,,,,,,,,,,,,,,,,,,,,,,,,,,,,,,,,,
,3881495989.68408,50.0139675140381,-3999.91796875,-1.60741346358629E-4,8.84163996210904E-8,1,4,14.0008964538574,4.98326460774843,32.4000008404255,-0.198803674383577,-0.0301234078406126,1,5.90892945964357E-8,,,,,,,,,,,,,,,,,,,,,50.012882232666,50.0150527954102,-3999.91796875,-3999.91796875,53.3039384974672,5.88468694620643,4.08068418502808,56,1,0,0,1,0.326156616210937,33.7243423461914,1,1,3,50.012882232666,0,50.0139675140381,,,,,,,,,,,,,,,,,,,,,,,,,,,,,,,,,
,3881496029.36015,50.0199146270752,-4999.853515625,-1.51522439034465E-4,1.06925756435553E-7,1,4,14.0008964538574,4.98318543045669,32.4000008404255,-0.187389679985746,-0.0284474082475182,1,1.34230395358281E-8,,,,,,,,,,,,,,,,,,,,,50.018123626709,50.0217056274414,-4999.853515625,-4999.853515625,53.4297806890633,5.88515901358915,4.08141851425171,56,1,0,0,1,0.326080322265625,33.7243423461914,1,1,3,50.018123626709,0,50.0199146270752,,,,,,,,,,,,,,,,,,,,,,,,,,,,,,,,,
,3881496068.98568,50.0204010009766,-5999.85205078125,-1.39989025874662E-4,6.70919885453571E-8,1,4,14.0008964538574,4.98329384708697,32.4000008404255,-0.173136259121439,-0.0262512236144184,1,3.800054423869E-8,,,,,,,,,,,,,,,,,,,,,50.0186576843262,50.022144317627,-5999.85205078125,-5999.85205078125,53.3523994656595,5.88468674300563,4.08090829849243,56,1,0,0,1,0.325469970703125,34.2131004333496,1,1,3,50.0186576843262,0,50.0204010009766,,,,,,,,,,,,,,,,,,,,,,,,,,,,,,,,,
,3881496108.69649,50.0190181732178,-6999.63623046875,-1.27494100932015E-4,7.09412387547725E-8,1,4,14.0008964538574,4.98321950093442,32.4000008404255,-0.157686613033729,-0.0238603342975376,1,7.28534625619748E-8,,,,,,,,,,,,,,,,,,,,,50.0177574157715,50.0202789306641,-6999.63623046875,-6999.63623046875,53.2554775292749,5.88452131504568,4.08005380630493,56,1,0,0,1,0.327301025390625,33.7243423461914,1,1,3,50.0177574157715,0,50.0190181732178,,,,,,,,,,,,,,,,,,,,,,,,,,,,,,,,,
,3881496148.32113,50.0352535247803,-7999.98681640625,-1.14740098616639E-4,6.16451322866683E-8,1,4,14.0008964538574,4.98331014420447,32.4000008404255,-0.141913385884396,-0.0214905015300353,1,5.22142376543734E-8,,,,,,,,,,,,,,,,,,,,,50.0336265563965,50.0368804931641,-7999.98681640625,-7999.98681640625,53.4035961336691,5.88409836849557,4.08017206192017,56,1,0,0,1,0.327835083007812,33.7243423461914,1,1,3,50.0368804931641,0,50.0352535247803,,,,,,,,,,,,,,,,,,,,,,,,,,,,,,,,,
,3881496187.85435,50.0369472503662,-8999.6455078125,-1.00952179811985E-4,5.07477798390585E-8,1,4,14.0008964538574,4.98333103437073,32.4099995195866,-0.124866350714914,-0.0188721719293402,1,7.5050046800873E-8,,,,,,,,,,,,,,,,,,,,,50.0348701477051,50.0390243530273,-8999.6455078125,-8999.6455078125,53.3832737921691,5.88396889736738,4.08013868331909,56,1,0,0,1,0.327301025390625,34.2131004333496,1,1,3,50.0390243530273,0,50.0369472503662,,,,,,,,,,,,,,,,,,,,,,,,,,,,,,,,,
,3881496227.67037,50.0091438293457,-9999.8076171875,-8.73288272805855E-5,4.02990530875935E-8,1,4,14.0008964538574,4.98330422093787,32.4000008404255,-0.108014465212148,-0.0163287931644168,1,6.20782588882751E-8,,,,,,,,,,,,,,,,,,,,,50.0083427429199,50.0099449157715,-9999.8076171875,-9999.8076171875,53.3801472780922,5.88381190004328,4.08930444717407,56,1,0,0,1,0.3271484375,33.7243423461914,1,1,3,50.0083427429199,0,50.0091438293457,,,,,,,,,,,,,,,,,,,,,,,,,,,,,,,,,
,3881496267.46628,50.0356597900391,-10999.6044921875,-7.34627101493586E-5,3.91847576252272E-8,1,4,14.0008964538574,4.98326008886736,32.4099995195866,-0.0908700689073151,-0.0136876961989996,1,9.12212461613234E-8,,,,,,,,,,,,,,,,,,,,,50.0330848693848,50.0382347106934,-10999.6044921875,-10999.6044921875,53.3574800510345,5.88439674450135,4.07912015914917,56,1,0,0,1,0.329132080078125,33.7243423461914,1,1,3,50.0382347106934,0,50.0356597900391,,,,,,,,,,,,,,,,,,,,,,,,,,,,,,,,,
,3881496307.67103,50.0482044219971,-11999.666015625,-5.92488171616417E-5,4.8796246765474E-8,1,4,14.0008964538574,4.98325979935174,32.4000008404255,-0.0732958792091857,-0.0109882344478151,1,1.14893754025037E-7,,,,,,,,,,,,,,,,,,,,,50.0462532043457,50.0501556396484,-11999.666015625,-11999.666015625,53.4133664901595,5.88431096963791,4.07890272140503,56,1,0,0,1,0.3265380859375,33.7243423461914,1,1,3,50.0501556396484,0,50.0482044219971,,,,,,,,,,,,,,,,,,,,,,,,,,,,,,,,,
,3881496347.28707,50.0284442901611,-12999.94140625,-4.51383669970016E-5,5.3877143579709E-8,1,4,14.0008964538574,4.9833341960191,32.4000008404255,-0.0558539787452352,-0.00828743295450355,1,1.55503748104624E-7,,,,,,,,,,,,,,,,,,,,,50.0258979797363,50.0309906005859,-12999.94140625,-12999.94140625,53.5052078411691,5.88351941182499,4.08822631835937,56,1,0,0,1,0.326919555664063,33.7243423461914,1,1,3,50.0258979797363,0,50.0284442901611,,,,,,,,,,,,,,,,,,,,,,,,,,,,,,,,,
,3881496388.29777,50.0041446685791,-13999.7255859375,-3.08490391792526E-5,5.83405208062285E-8,1,4,14.0008964538574,4.98334901058073,32.4000008404255,-0.0381796824337126,-0.00561729203115527,1,1.43983856894367E-7,,,,,,,,,,,,,,,,,,,,,50.0037002563477,50.0045890808105,-13999.7255859375,-13999.7255859375,53.3817105351306,5.8841026068874,4.08526229858398,51,1,100,0,0,0.326309204101562,34.2131004333496,1,1,3,50.0037002563477,0,50.0041446685791,,,,,,,,,,,,,,,,,,,,,,,,,,,,,,,,,
,3881496445.27018,50.0266666412354,-14999.5859375,-1.66254409501449E-5,8.60982676831111E-8,1,4,14.0008964538574,4.98327332047025,32.4000008404255,-0.0205878360119386,-0.00294735175037048,1,1.42207279623565E-7,,,,,,,,,,,,,,,,,,,,,50.0261917114258,50.0271415710449,-14999.5859375,-14999.5859375,53.420010332573,5.88464286296852,4.07891893386841,54,1,32,0,0,0.3271484375,33.7243423461914,1,1,3,50.0261917114258,0,50.0266666412354,,,,,,,,,,,,,,,,,,,,,,,,,,,,,,,,,
,3881496544.4487,50.0004653930664,-24999.517578125,1.28215018193286E-4,2.62950488769284E-7,1,4,14.0008964538574,4.98337858837401,32.4000008404255,0.15853112044423,0.0243533891820581,1,2.15440983180878E-7,,,,,,,,,,,,,,,,,,,,,50.0003814697266,50.0005493164063,-24999.517578125,-24999.517578125,53.2711100996595,5.88376580990916,4.0879602432251,37,1,100,0,0,0.327529907226562,33.7243423461914,1,1,3,50.0003814697266,0,50.0004653930664,,,,,,,,,,,,,,,,,,,,,,,,,,,,,,,,,
,3881496658.61993,50.0298480987549,-34999.65625,2.22388343778331E-4,5.21391099148202E-5,1,4,14.0008964538574,4.98332903787721,32.4000008404255,0.271416287059011,0.0656199019653313,100,1.92778516969812E-5,,,,,,,,,,,,,,,,,,,,,50.024543762207,50.0351524353027,-34999.65625,-34999.65625,53.2519602009383,5.88449485269706,4.07734441757202,56,1,0,0,1,0.326766967773438,33.2355842590332,1,1,3,50.0351524353027,0,50.0298480987549,,,,,,,,,,,,,,,,,,,,,,,,,,,,,,,,,
,3881496772.52431,50.023416519165,-44999.5234375,-8.9023575315816E-5,4.89154758059358E-4,1,4,14.0008964538574,4.98337047438282,32.4000008404255,-0.158403460687191,0.301266640780372,100,2.57116048019651E-4,,,,,,,,,,,,,,,,,,,,,50.019832611084,50.0270004272461,-44999.5234375,-44999.5234375,53.4032053194095,5.88430452032812,4.07932949066162,53,1,68,0,0,0.327529907226562,33.7243423461914,1,1,3,50.0270004272461,0,50.023416519165,,,,,,,,,,,,,,,,,,,,,,,,,,,,,,,,,
,3881496886.28179,50.0052261352539,-54999.53125,-5.89699045049876E-5,6.97433561872979E-4,1,4,14.0008964538574,4.98333736456615,32.4000008404255,-0.101561461373024,0.177405118203911,1000,1.52402258234524E-4,,,,,,,,,,,,,,,,,,,,,50.0047912597656,50.0056610107422,-54999.53125,-54999.53125,53.3570892367749,5.88494243721432,4.08090019226074,54,1,68,0,0,0.325775146484375,33.7243423461914,1,1,3,50.0047912597656,0,50.0052261352539,,,,,,,,,,,,,,,,,,,,,,,,,,,,,,,,,
,3881497000.41773,50.0164756774902,-64999.73046875,7.34768756979628E-4,6.77306077656242E-5,1,4,14.0008964538574,4.9834615201704,32.4000008404255,0.907522819102065,0.146158293938412,1000,6.56435335112875E-6,,,,,,,,,,,,,,,,,,,,,50.0138816833496,50.0190696716309,-64999.73046875,-64999.73046875,53.2742366137364,5.88317773195814,4.08587265014648,56,1,0,0,1,0.326766967773438,34.2131004333496,1,1,3,50.0192565917969,0,50.0164756774902,,,,,,,,,,,,,,,,,,,,,,,,,,,,,,,,,
,3881497109.67806,50.0195598602295,-64999.54296875,1.89087395607714E-4,4.83453773282449E-4,1,4,14.0008964538574,4.98340738920279,32.4099995195866,0.204788587973317,0.226896937863926,100,1.54736556462163E-4,,,,,,,,,,,,,,,,,,,,,50.0182723999023,50.0208473205566,-64999.54296875,-64999.54296875,53.330513867121,5.88403756716857,4.08568429946899,51,1,68,0,0,0.32440185546875,34.2131004333496,1,1,3,50.0208473205566,0,50.0195598602295,,,,,,,,,,,,,,,,,,,,,,,,,,,,,,,,,
,3881497223.58089,50.0350170135498,-54999.59375,5.98485363997215E-4,8.20788086803322E-5,1,4,14.0008964538574,4.98343392941223,32.4000008404255,0.742479177935976,0.0974052231827988,100,-1.21526370775498E-5,,,,,,,,,,,,,,,,,,,,,50.0301284790039,50.0399055480957,-54999.59375,-54999.59375,53.3137088539576,5.88362928142301,4.0755181312561,51,1,68,0,0,0.327987670898438,34.2131004333496,1,1,3,50.040168762207,0,50.0350170135498,,,,,,,,,,,,,,,,,,,,,,,,,,,,,,,,,
,3881497338.08561,50.007511138916,-44999.76171875,4.15978002596875E-4,4.69645459061993E-5,1,4,14.0008964538574,4.98346195962485,32.4000008404255,0.5276624749309,-0.00864649180228491,100,-7.01778980931814E-5,,,,,,,,,,,,,,,,,,,,,50.0072250366211,50.0077972412109,-44999.76171875,-44999.76171875,53.3113639683999,5.88365462901969,4.08323621749878,55,1,68,0,0,0.328292846679687,34.2131004333496,1,1,3,50.0077972412109,0,50.007511138916,,,,,,,,,,,,,,,,,,,,,,,,,,,,,,,,,
,3881497439.13129,50.010856628418,-34999.65625,2.80650806632967E-4,3.32547178244879E-5,1,4,14.0008964538574,4.98342513373087,32.4000008404255,0.348464952762573,0.0437592184659818,100,-7.24911426414844E-6,,,,,,,,,,,,,,,,,,,,,50.0090293884277,50.0126838684082,-34999.65625,-34999.65625,53.3078466400633,5.88328973147213,4.07640361785889,53,1,68,0,0,0.328445434570313,34.2131004333496,1,1,3,50.0126838684082,0,50.010856628418,,,,,,,,,,,,,,,,,,,,,,,,,,,,,,,,,
,3881497538.65223,50.0002365112305,-24999.80859375,1.3238501335276E-4,2.9147208502935E-5,1,4,14.0008964538574,4.98345987392291,32.4000008404255,0.17150994891862,-0.0263294918257638,100,-4.13977603889431E-5,,,,,,,,,,,,,,,,,,,,,50.000186920166,50.0002861022949,-24999.80859375,-24999.80859375,53.4157113757172,5.88336844485884,4.08434772491455,55,1,68,0,0,0.324935913085937,34.7018585205078,1,1,3,50.000186920166,0,50.0002365112305,,,,,,,,,,,,,,,,,,,,,,,,,,,,,,,,,
,3881497637.37502,50.0134086608887,-14999.837890625,-1.83695218813666E-5,8.12956007516764E-8,1,4,14.0008964538574,4.98350855562377,32.4000008404255,-0.0227435734181929,-0.00329311481720503,100,1.27729312767251E-7,,,,,,,,,,,,,,,,,,,,,50.012264251709,50.0145530700684,-14999.837890625,-14999.837890625,53.3821013493903,5.8830772302664,4.07538938522339,56,1,0,0,1,0.32867431640625,34.2131004333496,1,1,3,50.0145530700684,0,50.0134086608887,,,,,,,,,,,,,,,,,,,,,,,,,,,,,,,,,
,3881497698.96884,50.0088539123535,-14000.103515625,-3.25782600686953E-5,6.97794813505624E-8,1,4,14.0008964538574,4.98347598911987,32.4099995195866,-0.0403167465471378,-0.00596208323373543,10,1.28036426292636E-7,,,,,,,,,,,,,,,,,,,,,50.008186340332,50.009521484375,-14000.103515625,-14000.103515625,53.4520571018614,5.88393630617029,4.08401298522949,55,1,68,0,0,0.326309204101562,34.2131004333496,1,1,3,50.0081253051758,0,50.0088539123535,,,,,,,,,,,,,,,,,,,,,,,,,,,,,,,,,
,3881497751.82135,50.0194187164307,-13000.369140625,-4.66604228940021E-5,3.99188171918315E-8,1,4,14.0008964538574,4.9834105074178,32.4000008404255,-0.057733702994204,-0.00859932780839474,10,1.34663034007703E-7,,,,,,,,,,,,,,,,,,,,,50.0160675048828,50.0227699279785,-13000.369140625,-13000.369140625,53.5950951208807,5.88342279868182,4.07580518722534,56,1,0,0,1,0.325088500976562,34.2131004333496,1,1,3,50.0229454040527,0,50.0194187164307,,,,,,,,,,,,,,,,,,,,,,,,,,,,,,,,,
,3881497791.18615,50.0266647338867,-12000.2705078125,-5.9854867717923E-5,2.24689244956197E-6,1,4,14.0008964538574,4.98342623289867,32.4000008404255,-0.0736653128963953,-0.0136276454815633,10,-1.92673085198345E-6,,,,,,,,,,,,,,,,,,,,,50.0237197875977,50.0296096801758,-12000.2705078125,-12000.2705078125,53.3289506100826,5.8832519165303,4.07524347305298,56,1,0,0,1,0.32867431640625,34.2131004333496,1,1,3,50.0296096801758,0,50.0266647338867,,,,,,,,,,,,,,,,,,,,,,,,,,,,,,,,,
,3881497836.09123,50.0353603363037,-11000.41015625,-7.52969587184536E-5,4.13959117264741E-8,1,4,14.0008964538574,4.98349451356518,32.4000008404255,-0.0931669894123803,-0.0138862764704767,1,2.10013834253873E-7,,,,,,,,,,,,,,,,,,,,,50.0318260192871,50.0388946533203,-11000.41015625,-11000.41015625,53.4082859047845,5.88322200277836,4.07643413543701,56,1,0,0,1,0.32562255859375,33.7243423461914,1,1,3,50.0388946533203,0,50.0353603363037,,,,,,,,,,,,,,,,,,,,,,,,,,,,,,,,,
,3881497874.97572,50.0198764801025,-10000.4365234375,-8.8996274420281E-5,4.47872456332509E-8,1,4,14.0008964538574,4.98347978371979,32.4000008404255,-0.110105620536129,-0.0164880219381233,1,1.87272498474214E-7,,,,,,,,,,,,,,,,,,,,,50.0196380615234,50.0201148986816,-10000.4365234375,-10000.4365234375,53.3453648089864,5.88393181011419,4.08067655563354,56,1,0,0,1,0.327606201171875,33.7243423461914,1,1,3,50.0201148986816,0,50.0198764801025,,,,,,,,,,,,,,,,,,,,,,,,,,,,,,,,,
,3881497914.66248,50.0361633300781,-9000.3125,-1.03010375629055E-4,5.92860880835132E-8,1,4,14.0008964538574,4.98342024031566,32.4000008404255,-0.12743071825804,-0.0191559470189316,1,1.58624996000265E-7,,,,,,,,,,,,,,,,,,,,,50.0358810424805,50.0364456176758,-9000.3125,-9000.3125,53.289869184121,5.8843481996941,4.08236932754517,55,1,68,0,0,0.328521728515625,34.2131004333496,1,1,3,50.0358810424805,0,50.0361633300781,,,,,,,,,,,,,,,,,,,,,,,,,,,,,,,,,
,3881497955.36148,50.0337772369385,-8000.32666015625,-1.16629870367972E-4,8.41959986695806E-8,1,4,14.0008964538574,4.98345903790955,32.4000008404255,-0.14427968380044,-0.0216943846251636,1,1.75149559925841E-7,,,,,,,,,,,,,,,,,,,,,50.0290641784668,50.0384902954102,-8000.32666015625,-8000.32666015625,53.3473188802845,5.88402390472634,4.07957792282105,55,1,68,0,0,0.328140258789063,34.2131004333496,1,1,3,50.0384902954102,0,50.0337772369385,,,,,,,,,,,,,,,,,,,,,,,,,,,,,,,,,
,3881497994.15842,50.035623550415,-7000.22802734375,-1.29835292912969E-4,5.70277101459424E-8,1,4,14.0008964538574,4.98355977577672,32.4000008404255,-0.160606849427656,-0.0242400543163668,1,1.23316007023972E-7,,,,,,,,,,,,,,,,,,,,,50.0335083007812,50.0377388000488,-7000.22802734375,-7000.22802734375,53.5790717362364,5.8826948352487,4.07560157775879,54,1,68,0,0,0.326995849609375,34.2131004333496,1,1,3,50.0377388000488,0,50.035623550415,,,,,,,,,,,,,,,,,,,,,,,,,,,,,,,,,
,3881498048.07572,50.006856918335,-6000.2548828125,-1.42260574412552E-4,1.04228610751354E-7,1,4,14.0008964538574,4.98360179573279,32.4000008404255,-0.17597532106842,-0.0265847723535436,1,1.15209884792993E-7,,,,,,,,,,,,,,,,,,,,,50.0065574645996,50.0071563720703,-6000.2548828125,-6000.2548828125,53.3496637658422,5.88278352716979,4.08379793167114,56,1,0,0,1,0.327911376953125,34.2131004333496,1,1,3,50.0071563720703,0,50.006856918335,,,,,,,,,,,,,,,,,,,,,,,,,,,,,,,,,
,3881498087.28428,50.0198001861572,-5000.306640625,-1.53392414906568E-4,9.0020488528609E-8,1,4,14.0008964538574,4.98359653244831,32.4099995195866,-0.189736043332703,-0.0287242568670437,1,7.62981668354191E-8,,,,,,,,,,,,,,,,,,,,,50.0176429748535,50.0219573974609,-5000.306640625,-5000.306640625,53.2828345274479,5.88315900988931,4.07499885559082,56,1,0,0,1,0.328521728515625,34.2131004333496,1,1,3,50.0219573974609,0,50.0198001861572,,,,,,,,,,,,,,,,,,,,,,,,,,,,,,,,,
,3881498128.06227,50.0173110961914,-4000.3837890625,-1.63013276758516E-4,1.31589902985658E-7,1,4,14.0008964538574,4.98346832847777,32.4000008404255,-0.201633703668895,-0.0304945864280995,1,1.05477971350959E-7,,,,,,,,,,,,,,,,,,,,,50.0141830444336,50.0204391479492,-4000.3837890625,-4000.3837890625,53.440332674073,5.88340251883892,4.08435726165771,56,1,0,0,1,0.324935913085937,34.2131004333496,1,1,3,50.0204391479492,0,50.0173110961914,,,,,,,,,,,,,,,,,,,,,,,,,,,,,,,,,
,3881498181.73751,50.0048866271973,-3000.4736328125,-1.68694538823456E-4,1.17803425075123E-7,1,4,14.0008964538574,4.98352089108254,32.4000008404255,-0.208676508213383,-0.031475719562988,1,1.75547991779033E-7,,,,,,,,,,,,,,,,,,,,,50.0043563842773,50.0054168701172,-3000.4736328125,-3000.4736328125,53.3535719084383,5.8826885410509,4.07421731948853,55,1,68,0,0,0.325393676757812,34.7018585205078,1,1,3,50.0043563842773,0,50.0048866271973,,,,,,,,,,,,,,,,,,,,,,,,,,,,,,,,,
,3881498251.56215,50.0181121826172,-2510.3623046875,-1.68617816429393E-4,1.41314113870134E-7,1,4,14.0008964538574,4.98341551058604,32.4000008404255,-0.208552289940901,-0.0316126996472887,1,5.2383023200912E-8,,,,,,,,,,,,,,,,,,,,,50.0138740539551,50.0223503112793,-2510.3623046875,-2510.3623046875,53.2476612440826,5.88323224033788,4.07995939254761,56,1,0,0,1,0.328292846679687,34.7018585205078,1,1,3,50.0223503112793,0,50.0181121826172,,,,,,,,,,,,,,,,,,,,,,,,,,,,,,,,,
,3881498291.78398,50.0200004577637,-1930.484375,-1.64628202522089E-4,1.56259782721662E-7,1,4,14.0008964538574,4.98344259388241,32.4000008404255,-0.203610256961042,-0.0309248289923842,1,2.73401021528593E-9,,,,,,,,,,,,,,,,,,,,,50.0182037353516,50.0217971801758,-1930.484375,-1930.484375,53.3344220097172,5.88416808312302,4.08004188537598,56,1,0,0,1,0.32562255859375,34.2131004333496,1,1,3,50.0182037353516,0,50.0200004577637,,,,,,,,,,,,,,,,,,,,,,,,,,,,,,,,,
,3881498330.34755,50.0340614318848,-1350.29174804688,-1.52098153552677E-4,1.2833164944382E-7,1,4,14.0008964538574,4.98342710011382,32.4099995195866,-0.18811602118073,-0.0285472492245704,1,2.17124296173149E-8,,,,,,,,,,,,,,,,,,,,,50.0335350036621,50.0345878601074,-1350.29174804688,-1350.29174804688,53.5153690119191,5.88377653457868,4.08456039428711,56,1,0,0,1,0.325088500976562,34.2131004333496,1,1,3,50.0335350036621,0,50.0340614318848,,,,,,,,,,,,,,,,,,,,,,,,,,,,,,,,,
,3881498368.81156,50.0496025085449,-770.451538085938,-1.25036056457882E-4,1.09484806637053E-7,1,4,14.0008964538574,4.98346218281332,32.4000008404255,-0.154653998259512,-0.0234219014741902,1,5.52880520536894E-8,,,,,,,,,,,,,,,,,,,,,50.0485649108887,50.0506401062012,-770.451538085938,-770.451538085938,53.4391602312941,5.88346560199638,4.08250713348389,56,1,0,0,1,0.325927734375,34.2131004333496,1,1,3,50.0506401062012,0,50.0496025085449,,,,,,,,,,,,,,,,,,,,,,,,,,,,,,,,,
,3881498408.47725,50.02663230896,-190.208541870117,-6.25454759675691E-5,4.43810410133088E-8,1,4,14.0008964538574,4.98357819114322,32.4000008404255,-0.0773640556062021,-0.0117126550441754,1,3.0744627133035E-8,,,,,,,,,,,,,,,,,,,,,50.0242080688477,50.0290565490723,-190.208541870117,-190.208541870117,53.3512270228807,5.88271711018754,4.0792670249939,56,1,0,0,1,0.32928466796875,34.2131004333496,1,1,3,50.0242080688477,0,50.02663230896,,,,,,,,,,,,,,,,,,,,,,,,,,,,,,,,,
,3881498446.67609,50.0100936889648,389.606475830078,6.49823679826558E-5,4.58437564615559E-8,1,4,14.0008964538574,4.98352078467389,32.4000008404255,0.0803719580848386,0.0122020567726469,1,-5.05819175256862E-9,,,,,,,,,,,,,,,,,,,,,50.0098533630371,50.0103340148926,389.606475830078,389.606475830078,53.4188378897941,5.88246270618408,4.07540321350098,56,1,0,0,1,0.3253173828125,34.7018585205078,1,1,3,50.0103340148926,0,50.0100936889648,,,,,,,,,,,,,,,,,,,,,,,,,,,,,,,,,
,3881498486.15192,50.0186977386475,969.610290527344,1.25163229498459E-4,1.03136402279724E-7,1,4,14.0008964538574,4.98344291660684,32.4000008404255,0.154807148563719,0.0234673681571613,1,-3.77408593577712E-8,,,,,,,,,,,,,,,,,,,,,50.0160331726074,50.0213623046875,969.610290527344,969.610290527344,53.503253769871,5.88286702510897,4.08549308776855,56,1,0,0,1,0.326156616210937,33.7243423461914,1,1,3,50.0213623046875,0,50.0186977386475,,,,,,,,,,,,,,,,,,,,,,,,,,,,,,,,,
,3881498525.62695,50.0060901641846,1549.50085449219,1.51417163395117E-4,1.0102237093596E-7,1,4,14.0008964538574,4.98347452857625,32.4000008404255,0.187277853209677,0.0284093832257999,1,-3.00488623846147E-8,,,,,,,,,,,,,,,,,,,,,50.005500793457,50.0066795349121,1549.50085449219,1549.50085449219,53.4176654470153,5.8831850549582,4.07994985580444,56,1,0,0,1,0.328140258789063,34.7018585205078,1,1,3,50.005500793457,0,50.0060901641846,,,,,,,,,,,,,,,,,,,,,,,,,,,,,,,,,
,3881498564.86356,50.0216693878174,2129.60546875,1.62932002497882E-4,1.01653885729433E-7,1,4,14.0008964538574,4.98350726332572,32.4000008404255,0.201517695954307,0.0305961592200677,1,-1.12777804892528E-8,,,,,,,,,,,,,,,,,,,,,50.0202331542969,50.0231056213379,2129.60546875,2129.60546875,53.2824437131883,5.88373529067448,4.07690477371216,56,1,0,0,1,0.327606201171875,34.2131004333496,1,1,3,50.0231056213379,0,50.0216693878174,,,,,,,,,,,,,,,,,,,,,,,,,,,,,,,,,
,3881498604.50451,50.0166568756103,2709.53369140625,1.67119457301753E-4,1.08091605897384E-7,1,4,14.0008964538574,4.98375756764718,32.4000008404255,0.206709046854431,0.0314001618245587,1,9.23723948580667E-10,,,,,,,,,,,,,,,,,,,,,50.0154609680176,50.0178527832031,2709.53369140625,2709.53369140625,53.4958282989384,5.88315561583442,4.07656002044678,56,1,0,0,1,0.325698852539063,33.7243423461914,1,1,3,50.0178527832031,0,50.0166568756103,,,,,,,,,,,,,,,,,,,,,,,,,,,,,,,,,
,3881498661.30521,50.0238590240479,3499.74877929687,1.64296817948758E-4,1.21796374737054E-7,1,4,14.0008964538574,4.98357321939585,32.4099995195866,0.203209854815184,0.0308506988315481,1,-1.32520218521531E-8,,,,,,,,,,,,,,,,,,,,,50.0236396789551,50.0240783691406,3499.74877929687,3499.74877929687,53.3883543775441,5.88323209563653,4.07474660873413,56,1,0,0,1,0.325088500976562,33.7243423461914,1,1,3,50.0236396789551,0,50.0238590240479,,,,,,,,,,,,,,,,,,,,,,,,,,,,,,,,,
,3881498715.88555,50.0027923583984,4499.69677734375,1.5677168535758E-4,1.44941847302262E-7,1,4,14.0008964538574,4.98353526442801,32.4099995195866,0.19390692563664,0.0293940888334652,1,-4.76299129778574E-8,,,,,,,,,,,,,,,,,,,,,50.0024108886719,50.003173828125,4499.69677734375,4499.69677734375,53.430171503323,5.88407825695606,4.08028984069824,56,1,0,0,1,0.325241088867188,34.2131004333496,1,1,3,50.0024108886719,0,50.0027923583984,,,,,,,,,,,,,,,,,,,,,,,,,,,,,,,,,
,3881498770.3655,50.0053119659424,5499.63232421875,1.45926125308747E-4,8.84219717479443E-8,1,4,14.0008964538574,4.9834597520851,32.4000008404255,0.180477532162765,0.0274321441377029,1,1.39917694604597E-8,,,,,,,,,,,,,,,,,,,,,50.0048370361328,50.005786895752,5499.63232421875,5499.63232421875,53.391480891621,5.88394314432626,4.08146286010742,54,1,68,0,0,0.324630737304687,33.7243423461914,1,1,3,50.0048370361328,0,50.0053119659424,,,,,,,,,,,,,,,,,,,,,,,,,,,,,,,,,
,3881498824.3759,50.0020198822022,6499.54248046875,1.34002941136847E-4,7.28047176266199E-8,1,4,14.0008964538574,4.98342219284604,32.4000008404255,0.165721828269931,0.0252410114944148,1,5.37060082100129E-8,,,,,,,,,,,,,,,,,,,,,50.0018653869629,50.0021743774414,6499.54248046875,6499.54248046875,53.2574316005729,5.88349644701812,4.07521772384644,56,1,0,0,1,0.327911376953125,34.2131004333496,1,1,3,50.0018653869629,0,50.0020198822022,,,,,,,,,,,,,,,,,,,,,,,,,,,,,,,,,
,3881498878.32067,50.0398788452148,7499.62939453125,1.21108022622743E-4,3.77677639016074E-8,1,4,14.0008964538574,4.9835044762158,32.4000008404255,0.149774709564809,0.0228350501046743,1,6.66635730606237E-8,,,,,,,,,,,,,,,,,,,,,50.0369071960449,50.0428504943848,7499.62939453125,7499.62939453125,53.3555259797364,5.8836917470642,4.0840744972229,55,1,68,0,0,0.326766967773438,34.2131004333496,1,1,3,50.0428504943848,0,50.0398788452148,,,,,,,,,,,,,,,,,,,,,,,,,,,,,,,,,
,3881498930.85216,50.0370597839355,8499.728515625,1.07838634246281E-4,5.12236678015825E-8,1,4,14.0008964538574,4.9835797876293,32.4000008404255,0.133365936663393,0.0203420972897454,1,6.62914804092675E-8,,,,,,,,,,,,,,,,,,,,,50.0347785949707,50.0393409729004,8499.728515625,8499.728515625,53.3309046813806,5.884392686357,4.08407974243164,56,1,0,0,1,0.32806396484375,33.7243423461914,1,1,3,50.0393409729004,0,50.0370597839355,,,,,,,,,,,,,,,,,,,,,,,,,,,,,,,,,
,3881498970.41403,50.0205249786377,9499.8271484375,9.43620984800666E-5,5.86553214225082E-8,1,4,14.0008964538574,4.98353163329161,32.4000008404255,0.116695034547114,0.017817167579188,1,7.21178988689068E-8,,,,,,,,,,,,,,,,,,,,,50.0190162658691,50.0220336914063,9499.8271484375,9499.8271484375,53.4762875859576,5.88420794022535,4.07668781280518,54,1,68,0,0,0.326156616210937,33.7243423461914,1,1,3,50.0190162658691,0,50.0205249786377,,,,,,,,,,,,,,,,,,,,,,,,,,,,,,,,,
,3881499018.5645,50.034517288208,10499.6748046875,8.05485568779818E-5,3.70068765988026E-8,1,4,14.0008964538574,4.98345766568652,32.4000008404255,0.0996333773191629,0.0150555739224948,10,-6.21834571522564E-8,,,,,,,,,,,,,,,,,,,,,50.0317230224609,50.0373115539551,10499.6748046875,10499.6748046875,53.4262633607268,5.88477989391327,4.08499097824097,56,1,0,0,1,0.3265380859375,33.7243423461914,1,1,3,50.0373115539551,0,50.034517288208,,,,,,,,,,,,,,,,,,,,,,,,,,,,,,,,,
,3881499063.61452,50.0307331085205,11499.94921875,6.63461272202278E-5,4.3449879908521E-8,1,4,14.0008964538574,4.98344576219419,32.4000008404255,0.0820434769275431,0.0125466316884462,1,6.66009370466936E-8,,,,,,,,,,,,,,,,,,,,,50.028621673584,50.032844543457,11499.94921875,11499.94921875,53.3992971768133,5.88387980606754,4.08559560775757,54,1,68,0,0,0.327072143554687,33.7243423461914,1,1,3,50.032844543457,0,50.0307331085205,,,,,,,,,,,,,,,,,,,,,,,,,,,,,,,,,
,3881499103.96622,50.0409240722656,12499.7216796875,5.23498936545162E-5,4.48188277042116E-8,1,4,14.0008964538574,4.98346417376747,32.4099995195866,0.0647366307426865,0.00989638207797741,1,4.97283168275973E-8,,,,,,,,,,,,,,,,,,,,,50.0400352478027,50.0418128967285,12499.7216796875,12499.7216796875,53.2929956981979,5.88395512811398,4.08523464202881,56,1,0,0,1,0.328903198242188,33.7243423461914,1,1,3,50.0418128967285,0,50.0409240722656,,,,,,,,,,,,,,,,,,,,,,,,,,,,,,,,,
,3881499157.4482,50.038610458374,13500.072265625,3.80426462321429E-5,4.38887672846195E-8,1,4,14.0008964538574,4.98388992765215,32.4000008404255,0.0470382152323647,0.00726831279891219,1,9.73805034938992E-8,,,,,,,,,,,,,,,,,,,,,50.0361061096191,50.0411148071289,13500.072265625,13500.072265625,53.3957798484768,5.88252006827727,4.08200740814209,56,1,0,0,1,0.326004028320313,33.7243423461914,1,1,3,50.0411148071289,0,50.038610458374,,,,,,,,,,,,,,,,,,,,,,,,,,,,,,,,,
,3881499210.26604,50.0080471038818,14499.78125,2.40385341720916E-5,8.07096663131542E-8,1,4,14.0008964538574,4.98341346657197,32.4000008404255,0.0297074954085713,0.00466589175315291,1,1.21186882411281E-7,,,,,,,,,,,,,,,,,,,,,50.0074348449707,50.008659362793,14499.78125,14499.78125,53.3062833830249,5.88492940991226,4.07667446136475,56,1,0,0,1,0.325851440429687,34.2131004333496,1,1,3,50.0074348449707,0,50.0080471038818,,,,,,,,,,,,,,,,,,,,,,,,,,,,,,,,,
,3881499286.32926,50.0303859710693,19999.603515625,-5.554324785415E-5,2.08786596951436E-7,1,4,14.0008964538574,4.98336133335086,32.4000008404255,-0.0687210121673402,-0.0102533954612543,1,1.46439792690551E-7,,,,,,,,,,,,,,,,,,,,,50.0299301147461,50.0308418273926,19999.603515625,19999.603515625,53.3008119833903,5.8852633197904,4.083740234375,49,1,100,0,0,0.325927734375,33.7243423461914,1,1,3,50.0299301147461,0,50.0303859710693,,,,,,,,,,,,,,,,,,,,,,,,,,,,,,,,,
,3881499395.47041,50.0006847381592,30000.103515625,-2.06960936738515E-4,1.88313013338231E-5,1,4,14.0008964538574,4.98344860352807,32.4000008404255,-0.255874738508239,-0.039486482596764,100,-4.8939830569006E-7,,,,,,,,,,,,,,,,,,,,,50.0006446838379,50.0007247924805,30000.103515625,30000.103515625,53.2773631278133,5.88419678592323,4.07899188995361,56,1,0,0,1,0.325927734375,34.2131004333496,1,1,3,50.0006446838379,0,50.0006847381592,,,,,,,,,,,,,,,,,,,,,,,,,,,,,,,,,
,3881499506.92807,50.0013942718506,40000.37890625,-3.36934917960788E-4,4.52850636111513E-5,1,4,14.0008964538574,4.98339686570307,32.4000008404255,-0.413560380980991,-0.0840382610280167,100,-1.67695902204131E-5,,,,,,,,,,,,,,,,,,,,,50.001148223877,50.0016403198242,40000.37890625,40000.37890625,53.4477581450057,5.88468178027403,4.07683706283569,55,1,68,0,0,0.325698852539063,33.7243423461914,1,1,3,50.0016403198242,0,50.0013942718506,,,,,,,,,,,,,,,,,,,,,,,,,,,,,,,,,
,3881499619.02553,50.0312900543213,50000.296875,-5.52617680217781E-4,7.61163799342661E-5,1,4,14.0008964538574,4.98328704765845,32.4000008404255,-0.693658530171359,-0.0365391253773023,10,5.43974060416215E-5,,,,,,,,,,,,,,,,,,,,,50.0255966186523,50.0369834899902,50000.296875,50000.296875,53.3148812967364,5.88467688825442,4.0868124961853,52,1,68,0,0,0.327835083007812,33.7243423461914,1,1,3,50.0369834899902,0,50.0312900543213,,,,,,,,,,,,,,,,,,,,,,,,,,,,,,,,,
,3881499723.78233,50.016918182373,60000.4453125,-6.27439588937681E-4,8.77851496233137E-5,1,4,14.0008964538574,4.98336035008167,32.4000008404255,-0.760364288623015,-0.220741911900795,100,-8.31767764416903E-5,,,,,,,,,,,,,,,,,,,,,50.0152702331543,50.0185661315918,60000.4453125,60000.4453125,53.3387209665729,5.88419113204696,4.07980155944824,55,1,68,0,0,0.324935913085937,34.2131004333496,1,1,3,50.0185661315918,0,50.016918182373,,,,,,,,,,,,,,,,,,,,,,,,,,,,,,,,,
,3881499832.728,50.0144233703613,70000.15625,-9.87160068680138E-4,8.88445868873852E-5,1,4,14.0008964538574,4.9834860485839,32.4099995195866,-1.25976042110445,0.0702410276294848,1000,2.06741613802113E-4,,,,,,,,,,,,,,,,,,,,,50.0134582519531,50.0153884887695,70000.15625,70000.15625,53.2257756455441,5.88452374067568,4.07654142379761,56,1,0,0,1,0.326690673828125,33.7243423461914,1,1,3,50.0153884887695,0,50.0144233703613,,,,,,,,,,,,,,,,,,,,,,,,,,,,,,,,,
,3881499842.96717,50.0139427185059,70000.15625,-7.72989394321117E-4,7.38249706009632E-5,1,4,14.0008964538574,4.98334598825432,32.4000008404255,-0.972791219849895,-0.0346467899167391,100,8.94023262940391E-5,,,,,,,,,,,,,,,,,,,,,50.0138626098633,50.0140228271484,70000.15625,70000.15625,53.2144420320153,5.88381890383142,4.07685947418213,53,2,68,0,0,0.326004028320313,33.7243423461914,1,1,3,50.0138626098633,0,50.0139427185059,,,,,,,,,,,,,,,,,,,,,,,,,,,,,,,,,