File: SQUID/22172_LCOL/22172_LCOL_MT_FC_p0.5T.csv
Comment,Time Stamp (sec),Temperature (K),Magnetic Field (Oe),Moment (emu),M. Std. Err. (emu),Transport Action,Averaging Time (sec),Frequency (Hz),Peak Amplitude (mm),Center Position (mm),Lockin Signal' (V),Lockin Signal (V),Range,M. Quad. Signal (emu),AC Moment (emu),AC M. Std Err. (emu),AC Phase (deg),AC Phase Std. Err. (deg),AC Susceptibility (emu/Oe),AC Suscept. Std Err. (emu/Oe),AC X' (emu/Oe),AC X' Std Err. (emu/Oe),AC X'' (emu/Oe),AC X'' Std Err. (emu/Oe),AC Drive (Oe),AC Frequency (Hz),AC Averaging Time (sec),AC Cycles,AC Range,AC Measure Type,AC Signal' (V),AC Signal'' (V),AC Trim Coil Ratio,AC Trim Coil Phase,Min. Temperature (K),Max. Temperature (K),Min. Field (Oe),Max. Field (Oe),Mass (grams),Motor Lag (deg),Pressure (Torr),Measure Count,Measurement Number,SQUID Status (code),Motor Status (code),Measure Status (code),Motor Current (amps),Motor Temp. (C),Temp. Status (code),Field Status (code),Chamber Status (code),Chamber Temp (K),Redirection State,Average Temp (K),Rotation Angle (deg),Rotator state,DC Moment Fixed Ctr (emu),DC Moment Err Fixed Ctr (emu),DC Moment Free Ctr (emu),DC Moment Err Free Ctr (emu),DC Fixed Fit,DC Free Fit,DC Calculated Center (mm),DC Calculated Center Err (mm),DC Scan Length (mm),DC Scan Time (s),DC Number of Points,DC Squid Drift,DC Min V (V),DC Max V (V),DC Scans per Measure,Map 01,Map 02,Map 03,Map 04,Map 05,Map 06,Map 07,Map 08,Map 09,Map 10,Map 11,Map 12,Map 13,Map 14,Map 15,Map 16
,3881424187.92683,399.983474731445,4999.56396484375,1.69420720493129E-4,1.64620408570713E-8,1,4,14.0008964538574,4.99623370221144,32.8599996864796,0.210300941516582,0.0318798528502156,1,-5.09867711838993E-8,,,,,,,,,,,,,,,,,,,,,399.983032226562,399.983917236328,4999.56396484375,4999.56396484375,53.2625121859479,5.86030701742598,5.12330722808838,56,1,0,0,1,0.326461791992188,32.2580642700195,1,1,3,399.983917236328,0,399.983474731445,,,,,,,,,,,,,,,,,,,,,,,,,,,,,,,,,
,3881424234.91301,397.877456665039,4999.56396484375,1.71749386773398E-4,2.93436060661562E-8,1,4,14.0008964538574,4.99588723803788,32.8599996864796,0.213161125906955,0.0323785789183223,1,-3.7907197987442E-10,,,,,,,,,,,,,,,,,,,,,397.720642089844,398.034271240234,4999.56396484375,4999.56396484375,53.3492729515826,5.87775288018793,5.13190937042236,56,1,0,0,1,0.326919555664063,32.7468223571777,2,1,3,397.720642089844,0,397.877456665039,,,,,,,,,,,,,,,,,,,,,,,,,,,,,,,,,
,3881424283.00607,393.645889282227,4999.56396484375,1.725849356323E-4,4.03170196573748E-8,1,4,14.0008964538574,4.99579125026806,32.8399986028671,0.214160421409132,0.0327455941840635,1,1.69125139588314E-7,,,,,,,,,,,,,,,,,,,,,393.479156494141,393.812622070313,4999.56396484375,4999.56396484375,53.445413259448,5.87971548965466,5.14462900161743,54,1,64,0,0,0.327529907226562,32.7468223571777,2,1,3,393.479156494141,0,393.645889282227,,,,,,,,,,,,,,,,,,,,,,,,,,,,,,,,,
,3881424330.91582,389.313293457031,4999.56396484375,1.73008350410069E-4,3.72884715044003E-8,1,4,14.0008964538574,4.99583380327272,32.8399986028671,0.214690093749396,0.0328151534485683,1,1.60540479573324E-7,,,,,,,,,,,,,,,,,,,,,389.135101318359,389.491485595703,4999.56396484375,4999.56396484375,53.432125574621,5.87975662957184,5.16542959213257,56,1,0,0,1,0.32684326171875,33.2355842590332,2,1,3,389.135101318359,0,389.313293457031,,,,,,,,,,,,,,,,,,,,,,,,,,,,,,,,,
,3881424378.90591,385.357299804687,4999.56396484375,1.73322485235186E-4,3.84009884117196E-8,1,4,14.0008964538574,4.99584860055002,32.8399986028671,0.21508084623224,0.0328745890623151,1,1.60603229809683E-7,,,,,,,,,,,,,,,,,,,,,385.216979980469,385.497619628906,4999.56396484375,4999.56396484375,53.4895752707845,5.87910898916458,5.17268085479736,56,1,0,0,1,0.326385498046875,33.2355842590332,2,1,3,385.216979980469,0,385.357299804687,,,,,,,,,,,,,,,,,,,,,,,,,,,,,,,,,
,3881424426.88611,381.662734985352,4999.56396484375,1.73500395071491E-4,4.02672500937335E-8,1,4,14.0008964538574,4.99587895029623,32.820001244545,0.215304877553565,0.0328992244426386,1,1.53202886208655E-7,,,,,,,,,,,,,,,,,,,,,381.500946044922,381.824523925781,4999.56396484375,4999.56396484375,53.4106307903422,5.8795528115218,5.18690061569214,56,1,0,0,1,0.326461791992188,33.7243423461914,2,1,3,381.500946044922,0,381.662734985352,,,,,,,,,,,,,,,,,,,,,,,,,,,,,,,,,
,3881424474.91831,377.750473022461,4999.56396484375,1.73830135553041E-4,3.90673958473207E-8,1,4,14.0008964538574,4.99581006172811,32.820001244545,0.21570943905032,0.0329641655639181,1,1.55953246234401E-7,,,,,,,,,,,,,,,,,,,,,377.585571289063,377.915374755859,4999.56396484375,4999.56396484375,53.427044989246,5.88026227955834,5.18544816970825,56,1,0,0,1,0.32806396484375,33.7243423461914,2,1,3,377.585571289063,0,377.750473022461,,,,,,,,,,,,,,,,,,,,,,,,,,,,,,,,,
,3881424522.89047,373.901901245117,4999.56396484375,1.74104020559598E-4,4.09739917960296E-8,1,4,14.0008964538574,4.99575300011903,32.8000001609325,0.216046615444216,0.0330105550893161,1,1.52153768015443E-7,,,,,,,,,,,,,,,,,,,,,373.739227294922,374.064575195313,4999.56396484375,4999.56396484375,53.4633907153903,5.88010015088384,5.19407939910889,56,1,0,0,1,0.325469970703125,32.7468223571777,2,1,3,373.739227294922,0,373.901901245117,,,,,,,,,,,,,,,,,,,,,,,,,,,,,,,,,
,3881424570.87805,369.934677124023,4999.56396484375,1.74435362904389E-4,3.2256472220634E-8,1,4,14.0008964538574,4.99578228946519,32.8000001609325,0.216463967344276,0.0330446164720607,1,1.29049605365627E-7,,,,,,,,,,,,,,,,,,,,,369.780303955078,370.089050292969,4999.56396484375,4999.56396484375,53.5728187080826,5.87946493304678,5.19435596466064,56,1,0,0,1,0.325241088867188,33.2355842590332,2,1,3,369.748626708984,0,369.934677124023,,,,,,,,,,,,,,,,,,,,,,,,,,,,,,,,,
,3881424618.94033,365.906112670898,4999.56396484375,1.74790348040503E-4,3.62355215729837E-8,1,4,14.0008964538574,4.99577643914653,32.8000001609325,0.216900057183092,0.0331386037418929,1,1.50901551309976E-7,,,,,,,,,,,,,,,,,,,,,365.737091064453,366.075134277344,4999.56396484375,4999.56396484375,53.5126333121018,5.88062842043234,5.18991088867188,55,1,64,0,0,0.32745361328125,33.2355842590332,2,1,3,365.722808837891,0,365.906112670898,,,,,,,,,,,,,,,,,,,,,,,,,,,,,,,,,
,3881424666.88509,361.976150512695,4999.56396484375,1.74975024004996E-4,3.32602732678055E-8,1,4,14.0008964538574,4.99577243279241,32.7799990773201,0.217134497897942,0.0331372572970903,1,1.2179445900294E-7,,,,,,,,,,,,,,,,,,,,,361.800933837891,362.1513671875,4999.56396484375,4999.56396484375,53.4383786027749,5.88066270320091,5.19703245162964,56,1,0,0,1,0.325927734375,33.7243423461914,2,1,3,361.800933837891,0,361.976150512695,,,,,,,,,,,,,,,,,,,,,,,,,,,,,,,,,
,3881424715.063,357.941879272461,4999.56396484375,1.75295492373152E-4,3.33161770449923E-8,1,4,14.0008964538574,4.99581375010804,32.7799990773201,0.217536541463826,0.0331862181345314,1,1.12256070105388E-7,,,,,,,,,,,,,,,,,,,,,357.802551269531,358.081207275391,4999.56396484375,4999.56396484375,53.5782901077172,5.88099323509625,5.18800449371338,56,1,0,0,1,0.323486328125,33.7243423461914,2,1,3,357.802551269531,0,357.941879272461,,,,,,,,,,,,,,,,,,,,,,,,,,,,,,,,,
,3881424762.85158,353.808166503906,4999.56396484375,1.75661431787553E-4,3.0693874528477E-8,1,4,14.0008964538574,4.99580932895463,32.770000398159,0.217988617786609,0.0332671308494506,1,1.2189810477687E-7,,,,,,,,,,,,,,,,,,,,,353.632080078125,353.984252929687,4999.56396484375,4999.56396484375,53.3379393380537,5.88018068016868,5.19287729263306,56,1,0,0,1,0.328140258789063,33.7243423461914,2,1,3,353.632080078125,0,353.808166503906,,,,,,,,,,,,,,,,,,,,,,,,,,,,,,,,,
,3881424810.85114,349.741882324219,4999.56396484375,1.76010575569832E-4,3.79908668350149E-8,1,4,14.0008964538574,4.9959841892721,32.770000398159,0.218436358964912,0.0333101208896434,1,1.02186793310228E-7,,,,,,,,,,,,,,,,,,,,,349.564910888672,349.918853759766,4999.56396484375,4999.56396484375,53.3922625201403,5.87990199298342,5.1900053024292,56,1,0,0,1,0.325927734375,33.7243423461914,2,1,3,349.564910888672,0,349.741882324219,,,,,,,,,,,,,,,,,,,,,,,,,,,,,,,,,
,3881424858.91295,345.755569458008,4999.56396484375,1.76252162972788E-4,3.11914328734551E-8,1,4,14.0008964538574,4.99591359427616,32.7499993145466,0.218731472934495,0.0333576672195626,1,1.0432990531402E-7,,,,,,,,,,,,,,,,,,,,,345.610504150391,345.900634765625,4999.56396484375,4999.56396484375,53.4418959311114,5.87967407372922,5.19276714324951,56,1,0,0,1,0.326309204101562,33.7243423461914,2,1,3,345.610504150391,0,345.755569458008,,,,,,,,,,,,,,,,,,,,,,,,,,,,,,,,,
,3881424906.85372,341.734085083008,4999.56396484375,1.76525803985038E-4,3.00401573639512E-8,1,4,14.0008964538574,4.99587018322606,32.7499993145466,0.219067977128,0.0334118315475743,1,1.0673285076636E-7,,,,,,,,,,,,,,,,,,,,,341.550964355469,341.917205810547,4999.56396484375,4999.56396484375,53.5595310232557,5.880284724698,5.19224452972412,56,1,0,0,1,0.325546264648438,33.7243423461914,2,1,3,341.550964355469,0,341.734085083008,,,,,,,,,,,,,,,,,,,,,,,,,,,,,,,,,
,3881424954.91447,337.687484741211,4999.56396484375,1.76932734098466E-4,3.92864682262972E-8,1,4,14.0008964538574,4.99584585389473,32.7499993145466,0.219570518576308,0.0334949453706258,1,1.12071721358651E-7,,,,,,,,,,,,,,,,,,,,,337.545104980469,337.829864501953,4999.56396484375,4999.56396484375,53.3973431055153,5.8805113765993,5.18680715560913,54,1,64,0,0,0.326156616210937,33.2355842590332,2,1,3,337.545104980469,0,337.687484741211,,,,,,,,,,,,,,,,,,,,,,,,,,,,,,,,,
,3881425002.8272,333.719955444336,4999.56396484375,1.77172470646527E-4,3.27432725888263E-8,1,4,14.0008964538574,4.9958400784656,32.7299982309341,0.219870075083457,0.0335244525349612,1,9.94745623847412E-8,,,,,,,,,,,,,,,,,,,,,333.556304931641,333.883605957031,4999.56396484375,4999.56396484375,53.5603126517749,5.88056217977416,5.19237089157105,56,1,0,0,1,0.3240966796875,34.2131004333496,2,1,3,333.556304931641,0,333.719955444336,,,,,,,,,,,,,,,,,,,,,,,,,,,,,,,,,
,3881425050.82978,329.746124267578,4999.56396484375,1.77424134431183E-4,3.66778769607643E-8,1,4,14.0008964538574,4.9958117693804,32.7299982309341,0.220167968558299,0.0336552337226431,1,1.66837345314482E-7,,,,,,,,,,,,,,,,,,,,,329.575286865234,329.916961669922,4999.56396484375,4999.56396484375,53.5634391658518,5.88071931729333,5.19209814071655,56,1,0,0,1,0.325164794921875,33.7243423461914,2,1,3,329.575286865234,0,329.746124267578,,,,,,,,,,,,,,,,,,,,,,,,,,,,,,,,,
,3881425098.83251,325.780838012695,4999.56396484375,1.7781855198884E-4,3.47362380865869E-8,1,4,14.0008964538574,4.99579419683591,32.7299982309341,0.220663857754049,0.0336802579975551,1,1.27222342510957E-7,,,,,,,,,,,,,,,,,,,,,325.604278564453,325.957397460937,4999.56396484375,4999.56396484375,53.5079435409864,5.88111116927245,5.18978023529053,56,1,0,0,1,0.32440185546875,33.7243423461914,2,1,3,325.604278564453,0,325.780838012695,,,,,,,,,,,,,,,,,,,,,,,,,,,,,,,,,
,3881425146.8175,321.724090576172,4999.56396484375,1.78283408702939E-4,3.38684621108114E-8,1,4,14.0008964538574,4.99573108487535,32.7299982309341,0.221231299297102,0.0338039696269193,1,1.56773007009447E-7,,,,,,,,,,,,,,,,,,,,,321.554992675781,321.893188476562,4999.56396484375,4999.56396484375,53.4747243289191,5.88064901008331,5.18788290023804,56,1,0,0,1,0.326461791992188,33.7243423461914,2,1,3,321.554992675781,0,321.724090576172,,,,,,,,,,,,,,,,,,,,,,,,,,,,,,,,,
,3881425195.12634,317.671432495117,4999.56396484375,1.78475430607252E-4,3.29961343237621E-8,1,4,14.0008964538574,4.99579518825019,32.710000872612,0.221471347538658,0.0338555415649299,1,1.68669449987591E-7,,,,,,,,,,,,,,,,,,,,,317.516235351562,317.826629638672,4999.56396484375,4999.56396484375,53.5220128543326,5.88079456837308,5.18090915679932,55,1,64,0,0,0.326080322265625,33.7243423461914,2,1,3,317.516235351562,0,317.671432495117,,,,,,,,,,,,,,,,,,,,,,,,,,,,,,,,,
,3881425242.84343,313.718856811523,4999.56396484375,1.78875139139215E-4,3.8411648981926E-8,1,4,14.0008964538574,4.99572070883058,32.710000872612,0.221966388479852,0.0339064664422922,1,1.49556895255733E-7,,,,,,,,,,,,,,,,,,,,,313.527954101562,313.909759521484,4999.56396484375,4999.56396484375,53.5169322689576,5.88045441384646,5.17859125137329,56,1,0,0,1,0.325241088867188,33.7243423461914,2,1,3,313.527954101562,0,313.718856811523,,,,,,,,,,,,,,,,,,,,,,,,,,,,,,,,,
,3881425290.81626,309.751205444336,4999.56396484375,1.79170015746965E-4,3.29631948614474E-8,1,4,14.0008964538574,4.99572886590889,32.710000872612,0.222330191480438,0.0339796751994239,1,1.63691636639918E-7,,,,,,,,,,,,,,,,,,,,,309.588623046875,309.913787841797,4999.56396484375,4999.56396484375,53.5224036685922,5.88066881180267,5.18429374694824,56,1,0,0,1,0.331268310546875,33.2355842590332,2,1,3,309.588623046875,0,309.751205444336,,,,,,,,,,,,,,,,,,,,,,,,,,,,,,,,,
,3881425338.80751,305.665069580078,4999.56396484375,1.79349710278594E-4,4.10633322933953E-8,1,4,14.0008964538574,4.99572814770051,32.6899997889996,0.222562146354735,0.0339543751781354,1,1.16015854407861E-7,,,,,,,,,,,,,,,,,,,,,305.5078125,305.822326660156,4999.56396484375,4999.56396484375,53.470816186323,5.8817630275156,5.17645406723022,56,1,0,0,1,0.324478149414063,33.7243423461914,2,1,3,305.5078125,0,305.665069580078,,,,,,,,,,,,,,,,,,,,,,,,,,,,,,,,,
,3881425386.786,301.741271972656,4999.56396484375,1.79704090145855E-4,3.03987980246825E-8,1,4,14.0008964538574,4.99567374409642,32.6899997889996,0.223000450300677,0.0340081696186815,1,1.05949168608772E-7,,,,,,,,,,,,,,,,,,,,,301.567657470703,301.914886474609,4999.56396484375,4999.56396484375,53.4532295446403,5.88098957591217,5.17257976531982,56,1,0,0,1,0.326461791992188,33.7243423461914,2,1,3,301.567657470703,0,301.741271972656,,,,,,,,,,,,,,,,,,,,,,,,,,,,,,,,,
,3881425434.79444,297.794799804687,4999.56396484375,1.80006503031756E-4,2.71156449492275E-8,1,4,14.0008964538574,4.99563459713671,32.6899997889996,0.223367028764722,0.0341061309726347,1,1.39249133979971E-7,,,,,,,,,,,,,,,,,,,,,297.618560791016,297.971038818359,4999.56396484375,4999.56396484375,53.3750666927172,5.88031354202219,5.17136430740356,56,1,0,0,1,0.326614379882812,34.2131004333496,2,1,3,297.618560791016,0,297.794799804687,,,,,,,,,,,,,,,,,,,,,,,,,,,,,,,,,
,3881425482.78132,293.717575073242,4999.56396484375,1.80183798713421E-4,3.20462448383734E-8,1,4,14.0008964538574,4.99566207116926,32.6800011098385,0.223589236242789,0.0341368119367314,1,1.368283590288E-7,,,,,,,,,,,,,,,,,,,,,293.522644042969,293.912506103516,4999.56396484375,4999.56396484375,53.4274358035057,5.88107758670666,5.16872835159302,56,1,0,0,1,0.327301025390625,34.2131004333496,2,1,3,293.522644042969,0,293.717575073242,,,,,,,,,,,,,,,,,,,,,,,,,,,,,,,,,
,3881425530.85945,289.729919433594,4999.56396484375,1.80529148452812E-4,3.35454561901408E-8,1,4,14.0008964538574,4.99563538668698,32.6800011098385,0.22402091722588,0.0341702932652932,1,1.11554365311463E-7,,,,,,,,,,,,,,,,,,,,,289.589874267578,289.869964599609,4999.56396484375,4999.56396484375,53.3926533343999,5.88109536696737,5.15942239761353,56,1,0,0,1,0.32562255859375,32.7468223571777,2,1,3,289.589874267578,0,289.729919433594,,,,,,,,,,,,,,,,,,,,,,,,,,,,,,,,,
,3881425578.80637,285.782897949219,4999.56396484375,1.80685343888519E-4,3.27728797123936E-8,1,4,14.0008964538574,4.99568993647778,32.660000026226,0.224215088892918,0.0342206703426303,1,1.2799967675585E-7,,,,,,,,,,,,,,,,,,,,,285.628143310547,285.937652587891,4999.56396484375,4999.56396484375,53.4528387303807,5.88060415593717,5.15063714981079,56,1,0,0,1,0.325851440429687,33.2355842590332,2,1,3,285.628143310547,0,285.782897949219,,,,,,,,,,,,,,,,,,,,,,,,,,,,,,,,,
,3881425626.76265,281.721817016602,4999.56396484375,1.81074849956478E-4,3.46008642163293E-8,1,4,14.0008964538574,4.99558947059486,32.660000026226,0.224696099539915,0.0342671727174856,1,1.07081821737456E-7,,,,,,,,,,,,,,,,,,,,,281.561614990234,281.882019042969,4999.56396484375,4999.56396484375,53.4872303852268,5.88121352592506,5.14692687988281,56,1,0,0,1,0.326614379882812,33.7243423461914,2,1,3,281.561614990234,0,281.721817016602,,,,,,,,,,,,,,,,,,,,,,,,,,,,,,,,,
,3881425674.782,277.842041015625,4999.56396484375,1.81474576456235E-4,3.58048744570377E-8,1,4,14.0008964538574,4.99560809963861,32.660000026226,0.225192145740368,0.0343505761129681,1,1.13424914174065E-7,,,,,,,,,,,,,,,,,,,,,277.694976806641,277.989105224609,4999.56396484375,4999.56396484375,53.4383786027749,5.88077917518951,5.13631725311279,56,1,0,0,1,0.325393676757812,33.7243423461914,2,1,3,277.694976806641,0,277.842041015625,,,,,,,,,,,,,,,,,,,,,,,,,,,,,,,,,
,3881425723.09785,273.726974487305,4999.56396484375,1.81547363326461E-4,3.65600335776907E-8,1,4,14.0008964538574,4.99553384143372,32.6399989426136,0.22526933248965,0.0344192328662108,1,1.58268861034E-7,,,,,,,,,,,,,,,,,,,,,273.606323242187,273.847625732422,4999.56396484375,4999.56396484375,53.442286745371,5.884145763369,5.1278715133667,55,1,64,0,0,0.325546264648438,33.7243423461914,2,1,3,273.606323242187,0,273.726974487305,,,,,,,,,,,,,,,,,,,,,,,,,,,,,,,,,
,3881425770.75166,269.755905151367,4999.56396484375,1.81905932236349E-4,3.25125058455411E-8,1,4,14.0008964538574,4.99556805084793,32.6399989426136,0.225719026526952,0.034470385107862,1,1.44754820250081E-7,,,,,,,,,,,,,,,,,,,,,269.6044921875,269.907318115234,4999.56396484375,4999.56396484375,53.4207919610922,5.88165736271335,5.12067747116089,56,1,0,0,1,0.326385498046875,33.7243423461914,2,1,3,269.6044921875,0,269.755905151367,,,,,,,,,,,,,,,,,,,,,,,,,,,,,,,,,
,3881425818.75131,265.720260620117,4999.56396484375,1.82119844034449E-4,3.33900095971266E-8,1,4,14.0008964538574,4.99552919899612,32.6399989426136,0.225990830642269,0.0344524020614405,1,9.80734098045433E-8,,,,,,,,,,,,,,,,,,,,,265.558441162109,265.882080078125,4999.56396484375,4999.56396484375,53.3961706627364,5.88186820721357,5.12005090713501,56,1,0,0,1,0.327224731445313,33.7243423461914,2,1,3,265.558441162109,0,265.720260620117,,,,,,,,,,,,,,,,,,,,,,,,,,,,,,,,,
,3881425866.75739,261.748611450195,4999.56396484375,1.82421771019094E-4,3.21523908720511E-8,1,4,14.0008964538574,4.99554229060339,32.6399989426136,0.226366216706882,0.0345103245816977,1,9.87831611008595E-8,,,,,,,,,,,,,,,,,,,,,261.579223632813,261.917999267578,4999.56396484375,4999.56396484375,53.516541454698,5.88167130541699,5.11096286773682,56,1,0,0,1,0.325698852539063,33.7243423461914,2,1,3,261.579223632813,0,261.748611450195,,,,,,,,,,,,,,,,,,,,,,,,,,,,,,,,,
,3881425914.7655,257.814788818359,4999.56396484375,1.82545321532766E-4,3.2425636471274E-8,1,4,14.0008964538574,4.99553060787794,32.6200015842915,0.226516185929095,0.034550714778971,1,1.12653666053786E-7,,,,,,,,,,,,,,,,,,,,,257.667327880859,257.962249755859,4999.56396484375,4999.56396484375,53.3606065651114,5.88197169148487,5.10059833526611,56,1,0,0,1,0.3271484375,34.2131004333496,2,1,3,257.667327880859,0,257.814788818359,,,,,,,,,,,,,,,,,,,,,,,,,,,,,,,,,
,3881425962.7493,253.790794372559,4999.56396484375,1.82865950303826E-4,2.83856718165568E-8,1,4,14.0008964538574,4.99551950957053,32.6200015842915,0.226917831930234,0.034581725332334,1,8.90255355230877E-8,,,,,,,,,,,,,,,,,,,,,253.611557006836,253.970031738281,4999.56396484375,4999.56396484375,53.3617790078903,5.88228375903756,5.0934853553772,56,1,0,0,1,0.328826904296875,33.7243423461914,2,1,3,253.611557006836,0,253.790794372559,,,,,,,,,,,,,,,,,,,,,,,,,,,,,,,,,
,3881426010.73183,249.80736541748,4999.56396484375,1.83196569443088E-4,3.32107012714546E-8,1,4,14.0008964538574,4.99551040543977,32.6200015842915,0.227330426428292,0.0346250003260217,1,7.37472578881797E-8,,,,,,,,,,,,,,,,,,,,,249.6455078125,249.969223022461,4999.56396484375,4999.56396484375,53.511460869323,5.88212407876683,5.09045839309692,56,1,0,0,1,0.32623291015625,33.7243423461914,2,1,3,249.6455078125,0,249.80736541748,,,,,,,,,,,,,,,,,,,,,,,,,,,,,,,,,
,3881426058.73597,245.805763244629,4999.56396484375,1.83465064379034E-4,3.88632606851025E-8,1,4,14.0008964538574,4.99545495722541,32.6200015842915,0.227657572801415,0.0346916178459681,1,8.7078716646273E-8,,,,,,,,,,,,,,,,,,,,,245.656127929687,245.95539855957,4999.56396484375,4999.56396484375,53.4966099274576,5.88155457220495,5.08463287353516,56,1,0,0,1,0.32440185546875,33.7243423461914,2,1,3,245.656127929687,0,245.805763244629,,,,,,,,,,,,,,,,,,,,,,,,,,,,,,,,,
,3881426106.7347,241.833404541016,4999.56396484375,1.83579856182118E-4,2.28934212439987E-8,1,4,14.0008964538574,4.99551411152313,32.600000500679,0.227802783833282,0.0347205444186105,1,9.24876239985128E-8,,,,,,,,,,,,,,,,,,,,,241.658020019531,242.0087890625,4999.56396484375,4999.56396484375,53.381319720871,5.88109569687222,5.0842342376709,56,1,0,0,1,0.3277587890625,33.7243423461914,2,1,3,241.658020019531,0,241.833404541016,,,,,,,,,,,,,,,,,,,,,,,,,,,,,,,,,
,3881426154.73257,237.810134887695,4999.56396484375,1.83890264695027E-4,2.54879685601847E-8,1,4,14.0008964538574,4.99557378974032,32.600000500679,0.228191826664906,0.0347795598663611,1,9.24231070194889E-8,,,,,,,,,,,,,,,,,,,,,237.666656494141,237.95361328125,4999.56396484375,4999.56396484375,53.4661264152076,5.88016133075193,5.07171583175659,56,1,0,0,1,0.327072143554687,33.2355842590332,2,1,3,237.666656494141,0,237.810134887695,,,,,,,,,,,,,,,,,,,,,,,,,,,,,,,,,
,3881426202.72525,233.809425354004,4999.56396484375,1.8413586107563E-4,2.95188750921104E-8,1,4,14.0008964538574,4.99546773530918,32.600000500679,0.228485966270927,0.0348501923114028,1,1.1286749660033E-7,,,,,,,,,,,,,,,,,,,,,233.665344238281,233.953506469727,4999.56396484375,4999.56396484375,53.4618274583518,5.88094912156605,5.06458187103271,56,1,0,0,1,0.327224731445313,33.7243423461914,2,1,3,233.665344238281,0,233.809425354004,,,,,,,,,,,,,,,,,,,,,,,,,,,,,,,,,
,3881426250.71971,229.77352142334,4999.56396484375,1.84416960976849E-4,2.28603759497197E-8,1,4,14.0008964538574,4.99548835144361,32.600000500679,0.228842773182662,0.0348596196562527,1,7.76029655027385E-8,,,,,,,,,,,,,,,,,,,,,229.619293212891,229.927749633789,4999.56396484375,4999.56396484375,53.4012512481114,5.8804691171634,5.06274700164795,56,1,0,0,1,0.3271484375,34.2131004333496,2,1,3,229.605834960938,0,229.77352142334,,,,,,,,,,,,,,,,,,,,,,,,,,,,,,,,,
,3881426298.70604,225.829246520996,4999.56396484375,1.84546052608766E-4,2.44558272342116E-8,1,4,14.0008964538574,4.99546613725273,32.5799994170666,0.229002202236481,0.0348794223116267,1,7.41263545346853E-8,,,,,,,,,,,,,,,,,,,,,225.679214477539,225.979278564453,4999.56396484375,4999.56396484375,53.4977823702364,5.88098468506425,5.05280017852783,56,1,0,0,1,0.325927734375,33.7243423461914,2,1,3,225.679214477539,0,225.829246520996,,,,,,,,,,,,,,,,,,,,,,,,,,,,,,,,,
,3881426346.69901,221.836235046387,4999.56396484375,1.8476918561226E-4,2.37756000854136E-8,1,4,14.0008964538574,4.99548867928219,32.5799994170666,0.229282738041085,0.0349073171201366,1,6.25330283237828E-8,,,,,,,,,,,,,,,,,,,,,221.655181884766,222.017288208008,4999.56396484375,4999.56396484375,53.376239135496,5.88157314526034,5.04998016357422,56,1,0,0,1,0.326614379882812,33.2355842590332,2,1,3,221.655181884766,0,221.836235046387,,,,,,,,,,,,,,,,,,,,,,,,,,,,,,,,,
,3881426394.75312,217.777114868164,4999.56396484375,1.85048666484318E-4,1.96399327322626E-8,1,4,14.0008964538574,4.99555030702681,32.5799994170666,0.22963149750869,0.034974018415697,1,7.33420892406436E-8,,,,,,,,,,,,,,,,,,,,,217.594512939453,217.959716796875,4999.56396484375,4999.56396484375,53.4446316309287,5.88122955667237,5.04566431045532,56,1,0,0,1,0.326156616210937,33.7243423461914,2,1,3,217.594512939453,0,217.777114868164,,,,,,,,,,,,,,,,,,,,,,,,,,,,,,,,,
,3881426442.75118,213.738082885742,4999.56396484375,1.85224925567993E-4,2.68672281408157E-8,1,4,14.0008964538574,4.99546563857999,32.5700007379055,0.229847228800168,0.0349902867013261,1,6.03467173389954E-8,,,,,,,,,,,,,,,,,,,,,213.569213867187,213.906951904297,4999.56396484375,4999.56396484375,53.4993456272749,5.88130278656874,5.03914880752563,56,1,0,0,1,0.324630737304687,33.7243423461914,2,1,3,213.569213867187,0,213.738082885742,,,,,,,,,,,,,,,,,,,,,,,,,,,,,,,,,
,3881426490.69137,209.809616088867,4999.56396484375,1.84970498383613E-4,2.22503994984139E-8,1,4,14.0008964538574,4.99562143933496,32.5700007379055,0.229560991683369,0.0348156513531723,1,-4.29561567860874E-8,,,,,,,,,,,,,,,,,,,,,209.669769287109,209.949462890625,4999.56396484375,4999.56396484375,53.5106792408037,5.8795422024963,5.03461599349976,56,1,0,0,1,0.325698852539063,34.2131004333496,2,1,3,209.669769287109,0,209.809616088867,,,,,,,,,,,,,,,,,,,,,,,,,,,,,,,,,
,3881426538.68086,205.79027557373,4999.56396484375,1.84915657193139E-4,2.57679709000195E-8,1,4,14.0008964538574,4.99552827299927,32.5599983334541,0.229498089443878,0.0347309941381751,1,-1.02110450048887E-7,,,,,,,,,,,,,,,,,,,,,205.641662597656,205.938888549805,4999.56396484375,4999.56396484375,53.5298291395249,5.87989690171529,5.03316736221313,56,1,0,0,1,0.32867431640625,33.7243423461914,2,1,3,205.641662597656,0,205.79027557373,,,,,,,,,,,,,,,,,,,,,,,,,,,,,,,,,
,3881426586.69123,201.81192779541,4999.56396484375,1.8511071928702E-4,1.85464914584902E-8,1,4,14.0008964538574,4.99547928458182,32.5599983334541,0.229739489982862,0.0347509258511751,1,-1.15294577101923E-7,,,,,,,,,,,,,,,,,,,,,201.636169433594,201.987686157227,4999.56396484375,4999.56396484375,53.404768576448,5.87913899796154,5.01841735839844,56,1,0,0,1,0.327911376953125,33.7243423461914,2,1,3,201.636169433594,0,201.81192779541,,,,,,,,,,,,,,,,,,,,,,,,,,,,,,,,,
,3881426634.66945,197.865646362305,4999.56396484375,1.85163250299789E-4,1.98170310381179E-8,1,4,14.0008964538574,4.99559116474522,32.540000975132,0.229813587725083,0.0347507261983988,1,-1.24313191725059E-7,,,,,,,,,,,,,,,,,,,,,197.725662231445,198.005630493164,4999.56396484375,4999.56396484375,53.5153690119191,5.8791601197247,5.01412343978882,56,1,0,0,1,0.326766967773438,33.7243423461914,2,1,3,197.705596923828,0,197.865646362305,,,,,,,,,,,,,,,,,,,,,,,,,,,,,,,,,
,3881426682.66664,193.844314575195,4999.56396484375,1.85430368781871E-4,1.65136372647359E-8,1,4,14.0008964538574,4.99555243882399,32.540000975132,0.23014482897453,0.0347859423978252,1,-1.36207072553247E-7,,,,,,,,,,,,,,,,,,,,,193.654144287109,194.034484863281,4999.56396484375,4999.56396484375,53.5071619124672,5.87917149398439,5.00980949401855,56,1,0,0,1,0.326690673828125,33.7243423461914,2,1,3,193.654144287109,0,193.844314575195,,,,,,,,,,,,,,,,,,,,,,,,,,,,,,,,,
,3881426730.66036,189.789207458496,4999.56396484375,1.85582054821471E-4,1.81633065186246E-8,1,4,14.0008964538574,4.99551346597046,32.540000975132,0.230333284705828,0.0347961842784499,1,-1.50688825930631E-7,,,,,,,,,,,,,,,,,,,,,189.612075805664,189.966339111328,4999.56396484375,4999.56396484375,53.4434591881499,5.87942232213392,5.00032186508179,56,1,0,0,1,0.327301025390625,33.7243423461914,2,1,3,189.612075805664,0,189.789207458496,,,,,,,,,,,,,,,,,,,,,,,,,,,,,,,,,
,3881426778.69377,185.813461303711,4999.56396484375,1.85851963749919E-4,1.91441097316376E-8,1,4,14.0008964538574,4.99551720884697,32.540000975132,0.230662984182874,0.0348832817883173,1,-1.21533267402466E-7,,,,,,,,,,,,,,,,,,,,,185.664932250977,185.961990356445,4999.56396484375,4999.56396484375,53.4254817322076,5.8798391840206,5.00374221801758,56,1,0,0,1,0.328292846679687,33.7243423461914,2,1,3,185.664932250977,0,185.813461303711,,,,,,,,,,,,,,,,,,,,,,,,,,,,,,,,,
,3881426826.64835,181.79167175293,4999.56396484375,1.85982833940731E-4,1.75463073682469E-8,1,4,14.0008964538574,4.9955946724274,32.5199998915195,0.230827053579928,0.0349307749903821,1,-1.03753164146825E-7,,,,,,,,,,,,,,,,,,,,,181.607070922852,181.976272583008,4999.56396484375,4999.56396484375,53.4297806890633,5.87912367700245,4.98958396911621,56,1,0,0,1,0.3271484375,33.7243423461914,2,1,3,181.607070922852,0,181.79167175293,,,,,,,,,,,,,,,,,,,,,,,,,,,,,,,,,
,3881426874.66383,177.841148376465,4999.56396484375,1.86216144020089E-4,1.55340645944189E-8,1,4,14.0008964538574,4.99552667390266,32.5199998915195,0.231123522346506,0.0348994797468661,1,-1.63874208100799E-7,,,,,,,,,,,,,,,,,,,,,177.691223144531,177.991073608398,4999.56396484375,4999.56396484375,53.5122424978422,5.87870435781358,4.98282718658447,56,1,0,0,1,0.327529907226562,33.7243423461914,2,1,3,177.691223144531,0,177.841148376465,,,,,,,,,,,,,,,,,,,,,,,,,,,,,,,,,
,3881426922.63727,173.776947021484,4999.56396484375,1.86450465172124E-4,1.94493686427706E-8,1,4,14.0008964538574,4.99553973540857,32.5199998915195,0.231413898213005,0.0349520870676635,1,-1.5717923004514E-7,,,,,,,,,,,,,,,,,,,,,173.61018371582,173.943710327148,4999.56396484375,4999.56396484375,53.4379877885153,5.87813020473381,4.97647905349731,56,1,0,0,1,0.32745361328125,33.2355842590332,2,1,3,173.61018371582,0,173.776947021484,,,,,,,,,,,,,,,,,,,,,,,,,,,,,,,,,
,3881426970.63777,169.861610412598,4999.56396484375,1.86790791702124E-4,2.08204657701767E-8,1,4,14.0008964538574,4.99545457531977,32.5199998915195,0.231823126168055,0.0350653125178105,1,-1.16962474465778E-7,,,,,,,,,,,,,,,,,,,,,169.693969726562,170.029251098633,4999.56396484375,4999.56396484375,53.5681289369672,5.87894963359211,4.97640800476074,56,1,0,0,1,0.324859619140625,33.7243423461914,2,1,3,169.693969726562,0,169.861610412598,,,,,,,,,,,,,,,,,,,,,,,,,,,,,,,,,
,3881427018.63158,165.877731323242,4999.56396484375,1.8712810469563E-4,2.84215837508106E-8,1,4,14.0008964538574,4.99546709526987,32.5199998915195,0.232225946894261,0.035238227175644,1,-2.89610849170393E-8,,,,,,,,,,,,,,,,,,,,,165.689590454102,166.065872192383,4999.56396484375,4999.56396484375,53.4801957285537,5.87890254657373,4.96786689758301,56,1,0,0,1,0.327835083007812,33.7243423461914,2,1,3,165.689590454102,0,165.877731323242,,,,,,,,,,,,,,,,,,,,,,,,,,,,,,,,,
,3881427066.63765,161.795684814453,4999.56396484375,1.87117127904382E-4,2.46002912534933E-8,1,4,14.0008964538574,4.99547628644356,32.4999988079071,0.232220973343921,0.0351832534532111,1,-7.16657414826684E-8,,,,,,,,,,,,,,,,,,,,,161.634826660156,161.95654296875,4999.56396484375,4999.56396484375,53.518495525996,5.87896522782883,4.9679741859436,56,1,0,0,1,0.327224731445313,33.7243423461914,2,1,3,161.634826660156,0,161.795684814453,,,,,,,,,,,,,,,,,,,,,,,,,,,,,,,,,
,3881427114.62314,157.806282043457,4999.56396484375,1.8738001734799E-4,2.92141264128271E-8,1,4,14.0008964538574,4.99549270447429,32.4999988079071,0.232535411113998,0.0353177083201379,1,-3.38324831985379E-9,,,,,,,,,,,,,,,,,,,,,157.636306762695,157.976257324219,4999.56396484375,4999.56396484375,53.450493844823,5.87993960215224,4.95710945129395,56,1,0,0,1,0.327377319335937,33.7243423461914,2,1,3,157.636306762695,0,157.806282043457,,,,,,,,,,,,,,,,,,,,,,,,,,,,,,,,,
,3881427162.63521,153.738998413086,4999.56396484375,1.87685911584754E-4,3.17467176810033E-8,1,4,14.0008964538574,4.99544776371578,32.4999988079071,0.232907787842864,0.035403214903158,1,1.9413512075983E-8,,,,,,,,,,,,,,,,,,,,,153.586624145508,153.891372680664,4999.56396484375,4999.56396484375,53.4520571018614,5.87979269477309,4.95134973526001,56,1,0,0,1,0.326766967773438,33.7243423461914,2,1,3,153.586624145508,0,153.738998413086,,,,,,,,,,,,,,,,,,,,,,,,,,,,,,,,,
,3881427210.62438,149.820335388184,4999.56396484375,1.87941712984893E-4,3.12270008735711E-8,1,4,14.0008964538574,4.99543607902614,32.4999988079071,0.233214319941501,0.0355181001079979,1,7.32285693293308E-8,,,,,,,,,,,,,,,,,,,,,149.649337768555,149.991333007813,4999.56396484375,4999.56396484375,53.3504453943614,5.87955908347531,4.94262599945068,56,1,0,0,1,0.328445434570313,33.7243423461914,2,1,3,149.649337768555,0,149.820335388184,,,,,,,,,,,,,,,,,,,,,,,,,,,,,,,,,
,3881427258.62644,145.859939575195,4999.56396484375,1.87945351186111E-4,2.82112564596044E-8,1,4,14.0008964538574,4.99530125477694,32.4999988079071,0.233235955662107,0.035346696846446,1,-6.43689067372788E-8,,,,,,,,,,,,,,,,,,,,,145.703323364258,146.016555786133,4999.56396484375,4999.56396484375,53.5864972071691,5.87922486872947,4.94382524490356,56,1,0,0,1,0.325088500976562,33.7243423461914,2,1,3,145.703323364258,0,145.859939575195,,,,,,,,,,,,,,,,,,,,,,,,,,,,,,,,,
,3881427306.59951,141.739082336426,4999.56396484375,1.87875975982673E-4,2.37193087747561E-8,1,4,14.0008964538574,4.99522834736944,32.480001449585,0.233153234161193,0.0352793562831078,1,-1.07516646816744E-7,,,,,,,,,,,,,,,,,,,,,141.562927246094,141.915237426758,4999.56396484375,4999.56396484375,53.5806349932749,5.87841888360948,4.92778730392456,56,1,0,0,1,0.325698852539063,33.7243423461914,2,1,3,141.562927246094,0,141.739082336426,,,,,,,,,,,,,,,,,,,,,,,,,,,,,,,,,
,3881427354.60194,137.604553222656,4999.56396484375,1.88174475288909E-4,2.38153012617416E-8,1,4,14.0008964538574,4.99523693040535,32.480001449585,0.23351858454843,0.0353726751536688,1,-7.77238068182543E-8,,,,,,,,,,,,,,,,,,,,,137.432556152344,137.776550292969,4999.56396484375,4999.56396484375,53.3957798484768,5.87969534513401,4.92433643341064,56,1,0,0,1,0.327301025390625,33.7243423461914,2,1,3,137.432556152344,0,137.604553222656,,,,,,,,,,,,,,,,,,,,,,,,,,,,,,,,,
,3881427402.61479,133.657562255859,4999.56396484375,1.88336905487105E-4,2.122467038572E-8,1,4,14.0008964538574,4.99525743680845,32.480001449585,0.233726353951549,0.0353714508826461,1,-1.03547361174553E-7,,,,,,,,,,,,,,,,,,,,,133.494522094727,133.820602416992,4999.56396484375,4999.56396484375,53.5560136949191,5.87738728606772,4.92344903945923,56,1,0,0,1,0.327987670898438,33.2355842590332,2,1,3,133.494522094727,0,133.657562255859,,,,,,,,,,,,,,,,,,,,,,,,,,,,,,,,,
,3881427450.60205,129.605651855469,4999.56396484375,1.88513080918927E-4,2.32845666558805E-8,1,4,14.0008964538574,4.99511897769972,32.480001449585,0.233936634970486,0.0353983650190721,1,-1.07511613827951E-7,,,,,,,,,,,,,,,,,,,,,129.445877075195,129.765426635742,4999.56396484375,4999.56396484375,53.5564045091787,5.87707516351411,4.91166353225708,56,1,0,0,1,0.325164794921875,33.2355842590332,2,1,3,129.445877075195,0,129.605651855469,,,,,,,,,,,,,,,,,,,,,,,,,,,,,,,,,
,3881427498.58932,125.604091644287,4999.56396484375,1.88827701930414E-4,2.49270075337381E-8,1,4,14.0008964538574,4.995183588269,32.480001449585,0.234331859086311,0.0354544789192455,1,-1.10597827090024E-7,,,,,,,,,,,,,,,,,,,,,125.462142944336,125.746040344238,4999.56396484375,4999.56396484375,53.5564045091787,5.87823875066034,4.89942836761475,56,1,0,0,1,0.327301025390625,34.2131004333496,2,1,3,125.462142944336,0,125.604091644287,,,,,,,,,,,,,,,,,,,,,,,,,,,,,,,,,
,3881427546.61286,121.615707397461,4999.56396484375,1.8880685097893E-4,2.70767749486E-8,1,4,14.0008964538574,4.9950211775084,32.4600003659725,0.234286365104118,0.0355078613900296,1,-6.31073338883839E-8,,,,,,,,,,,,,,,,,,,,,121.455154418945,121.776260375977,4999.56396484375,4999.56396484375,53.5739911508614,5.87926357746771,4.89086866378784,56,1,0,0,1,0.328216552734375,33.7243423461914,2,1,3,121.455154418945,0,121.615707397461,,,,,,,,,,,,,,,,,,,,,,,,,,,,,,,,,
,3881427594.57388,117.658416748047,4999.56396484375,1.89162752799189E-4,3.5620501036617E-8,1,4,14.0008964538574,4.99503757590022,32.4600003659725,0.234715348954703,0.0356653222738113,1,9.60033135672838E-9,,,,,,,,,,,,,,,,,,,,,117.507713317871,117.809120178223,4999.56396484375,4999.56396484375,53.2929956981979,5.88002224676445,4.89026784896851,56,1,0,0,1,0.328216552734375,33.7243423461914,2,1,3,117.507713317871,0,117.658416748047,,,,,,,,,,,,,,,,,,,,,,,,,,,,,,,,,
,3881427642.58437,113.64183807373,4999.56396484375,1.89277814158903E-4,2.78289551180826E-8,1,4,14.0008964538574,4.99513412654634,32.4600003659725,0.234879785955576,0.0355871962185327,1,-7.16170342142808E-8,,,,,,,,,,,,,,,,,,,,,113.4443359375,113.839340209961,4999.56396484375,4999.56396484375,53.3316863098999,5.87924357250999,4.87301206588745,56,1,0,0,1,0.328140258789063,33.7243423461914,2,1,3,113.4443359375,0,113.64183807373,,,,,,,,,,,,,,,,,,,,,,,,,,,,,,,,,
,3881427690.57203,109.680908203125,4999.56396484375,1.89561959232617E-4,3.59141337041393E-8,1,4,14.0008964538574,4.99498815830859,32.4600003659725,0.235216270812863,0.035681891239896,1,-3.72872120033471E-8,,,,,,,,,,,,,,,,,,,,,109.493103027344,109.868713378906,4999.56396484375,4999.56396484375,53.4137573044191,5.88001739198969,4.86317300796509,56,1,0,0,1,0.328292846679687,33.2355842590332,2,1,3,109.493103027344,0,109.680908203125,,,,,,,,,,,,,,,,,,,,,,,,,,,,,,,,,
,3881427738.57001,105.693988800049,4999.56396484375,1.89859536000083E-4,3.04357302168175E-8,1,4,14.0008964538574,4.99508598541741,32.4500016868114,0.235580006504003,0.035817701209925,1,2.61724281928792E-8,,,,,,,,,,,,,,,,,,,,,105.516960144043,105.871017456055,4999.56396484375,4999.56396484375,53.5247485541499,5.8792207070889,4.86093282699585,56,1,0,0,1,0.32623291015625,33.7243423461914,2,1,3,105.516960144043,0,105.693988800049,,,,,,,,,,,,,,,,,,,,,,,,,,,,,,,,,
,3881427786.56424,101.676303863525,4999.56396484375,1.89808062353843E-4,2.15294353970239E-8,1,4,14.0008964538574,4.99500700113556,32.4500016868114,0.235532834310965,0.0356629389005939,1,-9.00962419385496E-8,,,,,,,,,,,,,,,,,,,,,101.49471282959,101.857894897461,4999.56396484375,4999.56396484375,53.4637815296499,5.87907275257343,4.84592914581299,56,1,0,0,1,0.328826904296875,33.7243423461914,2,1,3,101.49471282959,0,101.676303863525,,,,,,,,,,,,,,,,,,,,,,,,,,,,,,,,,
,3881427834.56348,97.6882247924805,4999.56396484375,1.89940198823185E-4,1.97248026838418E-8,1,4,14.0008964538574,4.9951281199189,32.4500016868114,0.235714119222281,0.0356276732237636,1,-1.39564292733248E-7,,,,,,,,,,,,,,,,,,,,,97.508544921875,97.8679046630859,4999.56396484375,4999.56396484375,53.4715978148422,5.87894825515283,4.84164667129517,56,1,0,0,1,0.32623291015625,33.7243423461914,2,1,3,97.508544921875,0,97.6882247924805,,,,,,,,,,,,,,,,,,,,,,,,,,,,,,,,,
,3881427882.55371,93.700626373291,4999.56396484375,1.90357802380317E-4,2.68831166405761E-8,1,4,14.0008964538574,4.99504892202469,32.4399992823601,0.236194119840028,0.0359224336598619,1,3.51915014083524E-8,,,,,,,,,,,,,,,,,,,,,93.5467529296875,93.8544998168945,4999.56396484375,4999.56396484375,53.4176654470153,5.87877649406962,4.83007860183716,56,1,0,0,1,0.327911376953125,33.7243423461914,2,1,3,93.5467529296875,0,93.700626373291,,,,,,,,,,,,,,,,,,,,,,,,,,,,,,,,,
,3881427930.53903,89.7057342529297,4999.56396484375,1.90318415227239E-4,2.36894938240237E-8,1,4,14.0008964538574,4.9949714462986,32.4399992823601,0.236161029175944,0.0357765604211505,1,-7.57607122442299E-8,,,,,,,,,,,,,,,,,,,,,89.5630416870117,89.8484268188477,4999.56396484375,4999.56396484375,53.4020328766306,5.87863637235574,4.81961011886597,56,1,0,0,1,0.328292846679687,33.2355842590332,2,1,3,89.5630416870117,0,89.7057342529297,,,,,,,,,,,,,,,,,,,,,,,,,,,,,,,,,
,3881427978.54091,85.6412391662598,4999.56396484375,1.9058157979024E-4,2.07311241771909E-8,1,4,14.0008964538574,4.99501338157654,32.4399992823601,0.236491710822424,0.0358175844563775,1,-8.30120820170503E-8,,,,,,,,,,,,,,,,,,,,,85.4886169433594,85.7938613891602,4999.56396484375,4999.56396484375,53.4891844565249,5.87892912787836,4.79845237731934,56,1,0,0,1,0.327224731445313,33.7243423461914,2,1,3,85.4886169433594,0,85.6412391662598,,,,,,,,,,,,,,,,,,,,,,,,,,,,,,,,,
,3881428026.54035,81.6140747070312,4999.56396484375,1.9077693557998E-4,2.08091471642849E-8,1,4,14.0008964538574,4.99495530873491,32.430000603199,0.236733156622105,0.0358347247883736,1,-9.84024498272947E-8,,,,,,,,,,,,,,,,,,,,,81.4200439453125,81.80810546875,4999.56396484375,4999.56396484375,53.386400306246,5.8787076683957,4.79372930526733,56,1,0,0,1,0.328140258789063,33.7243423461914,2,1,3,81.4200439453125,0,81.6140747070312,,,,,,,,,,,,,,,,,,,,,,,,,,,,,,,,,
,3881428074.75229,77.5643997192383,4999.56396484375,1.90929552225045E-4,1.74696506034978E-8,1,4,14.0008964538574,4.9949995582362,32.430000603199,0.236915927997527,0.0359266988391543,1,-4.78188516792579E-8,,,,,,,,,,,,,,,,,,,,,77.437255859375,77.6915435791016,4999.56396484375,4999.56396484375,53.6040838488518,5.87802994846984,4.77936983108521,55,1,64,0,0,0.326766967773438,33.7243423461914,2,1,3,77.437255859375,0,77.5643997192383,,,,,,,,,,,,,,,,,,,,,,,,,,,,,,,,,
,3881428122.54771,73.6388854980469,4999.56396484375,1.91317833771318E-4,2.83152576798114E-8,1,4,14.0008964538574,4.99508376919991,32.430000603199,0.237398963678227,0.0360293869770253,1,-2.47251473647029E-8,,,,,,,,,,,,,,,,,,,,,73.4851608276367,73.792610168457,4999.56396484375,4999.56396484375,53.4798049142941,5.87897383261859,4.76253604888916,56,1,0,0,1,0.326614379882812,33.7243423461914,2,1,3,73.4851608276367,0,73.6388854980469,,,,,,,,,,,,,,,,,,,,,,,,,,,,,,,,,
,3881428170.51471,69.5578308105469,4999.56396484375,1.91400540509685E-4,2.73279843979712E-8,1,4,14.0008964538574,4.99493955293871,32.4199981987476,0.23750514996148,0.0359568517707689,1,-9.45730852972729E-8,,,,,,,,,,,,,,,,,,,,,69.4121170043945,69.7035446166992,4999.56396484375,4999.56396484375,53.4602642013134,5.87908849796179,4.74080467224121,56,1,0,0,1,0.329208374023438,33.7243423461914,2,1,3,69.4121170043945,0,69.5578308105469,,,,,,,,,,,,,,,,,,,,,,,,,,,,,,,,,
,3881428218.51986,65.5124168395996,4999.56396484375,1.91772912454813E-4,2.58999260989437E-8,1,4,14.0008964538574,4.99509917342386,32.4199981987476,0.237967940831158,0.0360937851046171,1,-4.20780623324121E-8,,,,,,,,,,,,,,,,,,,,,65.3340148925781,65.6908187866211,4999.56396484375,4999.56396484375,53.5384270532364,5.87844703408166,4.72453355789185,56,1,0,0,1,0.325851440429687,34.2131004333496,2,1,3,65.3340148925781,0,65.5124168395996,,,,,,,,,,,,,,,,,,,,,,,,,,,,,,,,,
,3881428266.55106,61.4958801269531,4999.56396484375,1.92047937782516E-4,1.80012143449633E-8,1,4,14.0008964538574,4.99503409016318,32.4199981987476,0.23831392318616,0.0360852655498333,1,-9.01894985910138E-8,,,,,,,,,,,,,,,,,,,,,61.3327941894531,61.6589660644531,4999.56396484375,4999.56396484375,53.5548412521403,5.87861943417067,4.70128107070923,56,1,0,0,1,0.325393676757812,33.7243423461914,2,1,3,61.3161087036133,0,61.4958801269531,,,,,,,,,,,,,,,,,,,,,,,,,,,,,,,,,
,3881428314.5229,57.4484558105469,4999.56396484375,1.92411389175686E-4,2.91574145750305E-8,1,4,14.0008964538574,4.99508844533554,32.4199981987476,0.238741337260134,0.0363334033960127,1,5.41350753347193E-8,,,,,,,,,,,,,,,,,,,,,57.2930679321289,57.6038436889648,4999.56396484375,4999.56396484375,53.4958282989384,5.87896074928102,4.67124080657959,56,1,0,0,1,0.327529907226562,33.2355842590332,2,1,3,57.2930679321289,0,57.4484558105469,,,,,,,,,,,,,,,,,,,,,,,,,,,,,,,,,
,3881428362.50675,53.3960208892822,4999.56396484375,1.92766572321027E-4,2.95183741858099E-8,1,4,14.0008964538574,4.99500031432472,32.4099995195866,0.239185374492959,0.036338734361618,1,5.20290724778712E-9,,,,,,,,,,,,,,,,,,,,,53.224193572998,53.5678482055664,4999.56396484375,4999.56396484375,53.4692529292845,5.87966280900534,4.64379072189331,56,1,0,0,1,0.327987670898438,33.2355842590332,2,1,3,53.2114067077637,0,53.3960208892822,,,,,,,,,,,,,,,,,,,,,,,,,,,,,,,,,
,3881428410.53787,49.4007778167725,4999.56396484375,1.93504061139252E-4,3.10130389105862E-8,1,4,14.0008964538574,4.99486035559138,32.4099995195866,0.240082348053942,0.0365334859197684,1,5.12896899068912E-8,,,,,,,,,,,,,,,,,,,,,49.2409782409668,49.5605773925781,4999.56396484375,4999.56396484375,53.3731126214191,5.87945079282461,4.61693143844604,56,1,0,0,1,0.328445434570313,33.7243423461914,2,1,3,49.2409782409668,0,49.4007778167725,,,,,,,,,,,,,,,,,,,,,,,,,,,,,,,,,
,3881428458.51019,45.3101577758789,4999.56396484375,1.94032484888622E-4,3.9093929728125E-8,1,4,14.0008964538574,4.9949635680195,32.4099995195866,0.240729680895698,0.0367347408580351,1,1.32368565569463E-7,,,,,,,,,,,,,,,,,,,,,45.138355255127,45.4819602966309,4999.56396484375,4999.56396484375,53.5618759088134,5.88058874030924,4.5821270942688,56,1,0,0,1,0.325698852539063,34.2131004333496,2,1,3,45.138355255127,0,45.3101577758789,,,,,,,,,,,,,,,,,,,,,,,,,,,,,,,,,
,3881428518.51468,40.2164325714111,4999.56396484375,1.9571655806063E-4,1.8542656066784E-7,1,4,14.0008964538574,4.99478566863117,32.4099995195866,0.242748013498353,0.037439669504549,1,4.4619041090757E-7,,,,,,,,,,,,,,,,,,,,,40.0361480712891,40.3967170715332,4999.56396484375,4999.56396484375,53.3187894393326,5.88106287017382,4.52651500701904,56,1,0,0,1,0.328521728515625,33.7243423461914,2,1,3,40.0361480712891,0,40.2164325714111,,,,,,,,,,,,,,,,,,,,,,,,,,,,,,,,,
,3881428589.99786,34.25465965271,4999.56396484375,1.96900560510001E-4,1.89878350911557E-7,1,4,14.0008964538574,4.99502417001328,32.4000008404255,0.244239866457384,0.0376226206045302,1,4.11767186680125E-7,,,,,,,,,,,,,,,,,,,,,34.0258941650391,34.4834251403809,4999.56396484375,4999.56396484375,53.6095552484864,5.87927653835388,4.45068502426147,54,1,100,0,0,0.327606201171875,33.7243423461914,2,1,3,34.0258941650391,0,34.25465965271,,,,,,,,,,,,,,,,,,,,,,,,,,,,,,,,,
,3881428682.42206,26.471884727478,4999.56396484375,1.99081554539479E-4,1.83299424071899E-7,1,4,14.0008964538574,4.99499522242917,32.4000008404255,0.246931995367043,0.0381129117221336,1,4.75860546039751E-7,,,,,,,,,,,,,,,,,,,,,26.3140888214111,26.6296806335449,4999.56396484375,4999.56396484375,53.4090675333037,5.87994993744253,4.29201984405518,50,1,100,0,0,0.325393676757812,33.7243423461914,2,1,3,26.3008861541748,0,26.471884727478,,,,,,,,,,,,,,,,,,,,,,,,,,,,,,,,,
,3881428745.20555,21.2352418899536,4999.56396484375,1.99444541648532E-4,6.52367395261476E-7,1,4,14.0008964538574,4.9949925701298,32.4000008404255,0.247557155852328,0.0370295648093614,100,-4.52353812951058E-7,,,,,,,,,,,,,,,,,,,,,21.1835956573486,21.2868881225586,4999.56396484375,4999.56396484375,53.4801957285537,5.87837292463768,4.10936498641968,56,1,0,0,1,0.32562255859375,33.2355842590332,2,1,3,21.1835956573486,0,21.2352418899536,,,,,,,,,,,,,,,,,,,,,,,,,,,,,,,,,
,3881428798.48521,16.8747072219849,4999.56396484375,2.01665564198127E-4,1.91969731938939E-5,1,4,14.0008964538574,4.9950697975089,32.4000008404255,0.249876369356236,0.0403592299964972,10,1.89304026924297E-6,,,,,,,,,,,,,,,,,,,,,16.7285060882568,17.0209083557129,4999.56396484375,4999.56396484375,53.5657840514095,5.88008727927978,3.86705946922302,56,1,0,0,1,0.325546264648438,33.7243423461914,2,1,3,16.7285060882568,0,16.8747072219849,,,,,,,,,,,,,,,,,,,,,,,,,,,,,,,,,
,3881428858.44976,12.0157227516174,4999.56396484375,1.90377082818213E-4,1.29915233999915E-5,1,4,14.0008964538574,4.99505214908696,32.4000008404255,0.238254654126911,0.0225198848142902,10,-1.07690728882226E-5,,,,,,,,,,,,,,,,,,,,,11.8687200546265,12.1627254486084,4999.56396484375,4999.56396484375,53.5016905128326,5.88105799367079,3.46487212181091,51,1,68,0,0,0.324783325195313,33.7243423461914,2,1,3,11.8687200546265,0,12.0157227516174,,,,,,,,,,,,,,,,,,,,,,,,,,,,,,,,,
,3881428925.17279,7.02510476112366,4999.56396484375,2.00307811780379E-4,5.85162411428861E-8,1,4,14.0008964538574,4.99506152135098,32.4000008404255,0.248494091236214,0.0381082145495473,1,2.85236211403016E-7,,,,,,,,,,,,,,,,,,,,,6.99131536483765,7.05889415740967,4999.56396484375,4999.56396484375,53.5106792408037,5.87873824494289,3.06141591072082,56,1,0,0,1,0.32745361328125,33.7243423461914,6,1,3,6.9574761390686,0,7.02510476112366,,,,,,,,,,,,,,,,,,,,,,,,,,,,,,,,,
,3881428986.43449,2.6549836397171,4999.56396484375,2.41604998163095E-4,3.61063386041575E-8,1,4,14.0008964538574,4.99524810640905,32.4000008404255,0.299765078056289,0.0458118354961264,1,2.18728494733841E-7,,,,,,,,,,,,,,,,,,,,,2.64682936668396,2.66313791275024,4999.56396484375,4999.56396484375,53.3930441486595,5.87896461959043,2.20202112197876,56,1,0,0,1,0.327224731445313,33.7243423461914,6,1,3,2.64682936668396,0,2.6549836397171,,,,,,,,,,,,,,,,,,,,,,,,,,,,,,,,,
,3881429034.43633,2.67612910270691,4999.56396484375,2.41224838347878E-4,6.377732833025E-8,1,4,14.0008964538574,4.99511911667072,32.4000008404255,0.299255693427321,0.045915103591271,1,3.61033493714724E-7,,,,,,,,,,,,,,,,,,,,,2.67386913299561,2.67838907241821,4999.56396484375,4999.56396484375,53.5943134923614,5.87938707756445,2.12738704681396,56,1,0,0,1,0.326461791992188,33.2355842590332,6,1,3,2.67838907241821,0,2.67612910270691,,,,,,,,,,,,,,,,,,,,,,,,,,,,,,,,,
,3881429082.51391,2.68930840492249,4999.56396484375,2.41031608213875E-4,4.88031648905253E-8,1,4,14.0008964538574,4.9951756632599,32.4000008404255,0.29903562684437,0.0457809103144974,1,2.81653803700989E-7,,,,,,,,,,,,,,,,,,,,,2.68629932403564,2.69231748580933,4999.56396484375,4999.56396484375,53.5212312258134,5.87874433495662,2.12266898155212,56,1,0,0,1,0.326309204101562,33.7243423461914,6,1,3,2.68629932403564,0,2.68930840492249,,,,,,,,,,,,,,,,,,,,,,,,,,,,,,,,,
,3881429130.45396,2.65624713897705,4999.56396484375,2.41718745493517E-4,3.59734203617228E-8,1,4,14.0008964538574,4.99510578846378,32.4000008404255,0.299892752151762,0.045841369989072,1,2.26725456157587E-7,,,,,,,,,,,,,,,,,,,,,2.65478229522705,2.65771198272705,4999.56396484375,4999.56396484375,53.4129756758999,5.87875675558316,2.12632846832275,56,1,0,0,1,0.328369140625,33.7243423461914,6,1,3,2.65478229522705,0,2.65624713897705,,,,,,,,,,,,,,,,,,,,,,,,,,,,,,,,,
,3881429178.43198,2.61014926433563,4999.56396484375,2.42790423991216E-4,3.41912564787986E-8,1,4,14.0008964538574,4.99499336305378,32.4000008404255,0.301199221992567,0.046132904086625,1,3.00058134059978E-7,,,,,,,,,,,,,,,,,,,,,2.60853147506714,2.61176705360413,4999.56396484375,4999.56396484375,53.5560136949191,5.87931567627282,2.11677932739258,56,1,0,0,1,0.327072143554687,33.7243423461914,6,1,3,2.60853147506714,0,2.61014926433563,,,,,,,,,,,,,,,,,,,,,,,,,,,,,,,,,
,3881429226.42909,2.53778111934662,4999.56396484375,2.44474483407984E-4,3.96064858814819E-8,1,4,14.0008964538574,4.99497064983984,32.4000008404255,0.303293591123812,0.0464058422988446,1,2.64457118720304E-7,,,,,,,,,,,,,,,,,,,,,2.53382658958435,2.54173564910889,4999.56396484375,4999.56396484375,53.4254817322076,5.8795088369947,2.10310626029968,56,1,0,0,1,0.32745361328125,33.2355842590332,6,1,3,2.53382658958435,0,2.53778111934662,,,,,,,,,,,,,,,,,,,,,,,,,,,,,,,,,
,3881429274.40446,2.41672503948212,4999.56396484375,2.47468218519974E-4,4.17520634397023E-8,1,4,14.0008964538574,4.99501235119232,32.4000008404255,0.307005598278734,0.0470114772098124,1,2.97368499166402E-7,,,,,,,,,,,,,,,,,,,,,2.40285515785217,2.43059492111206,4999.56396484375,4999.56396484375,53.467689672246,5.87902794372986,2.05993390083313,56,1,0,0,1,0.32745361328125,33.7243423461914,6,1,3,2.40285515785217,0,2.41672503948212,,,,,,,,,,,,,,,,,,,,,,,,,,,,,,,,,
,3881429334.40605,1.99677121639252,4999.56396484375,2.59680911782336E-4,4.0855980535393E-8,1,4,14.0008964538574,4.99508187141646,32.4000008404255,0.322170058356885,0.0492845261856164,1,2.73396467699967E-7,,,,,,,,,,,,,,,,,,,,,1.99382245540619,1.99971997737885,4999.56396484375,4999.56396484375,53.4778508429961,5.87913621648752,1.87327563762665,56,1,0,0,1,0.327224731445313,33.7243423461914,6,1,3,1.99971997737885,0,1.99677121639252,,,,,,,,,,,,,,,,,,,,,,,,,,,,,,,,,
,3881429382.40405,1.99822670221329,4999.56396484375,2.59361215086089E-4,3.70737989185569E-8,1,4,14.0008964538574,4.99505261610247,32.4000008404255,0.321775837821487,0.0491902223537705,1,2.46283214810958E-7,,,,,,,,,,,,,,,,,,,,,1.99771106243134,1.99874234199524,4999.56396484375,4999.56396484375,53.409849161823,5.87902781052957,1.85629963874817,56,1,0,0,1,0.326385498046875,33.7243423461914,1,1,3,1.99874234199524,0,1.99822670221329,,,,,,,,,,,,,,,,,,,,,,,,,,,,,,,,,