File: SQUID/22172_LCOL/22172_LCOL_MH_300K_FC_p0d5T.csv
Comment,Time Stamp (sec),Temperature (K),Magnetic Field (Oe),Moment (emu),M. Std. Err. (emu),Transport Action,Averaging Time (sec),Frequency (Hz),Peak Amplitude (mm),Center Position (mm),Lockin Signal' (V),Lockin Signal (V),Range,M. Quad. Signal (emu),AC Moment (emu),AC M. Std Err. (emu),AC Phase (deg),AC Phase Std. Err. (deg),AC Susceptibility (emu/Oe),AC Suscept. Std Err. (emu/Oe),AC X' (emu/Oe),AC X' Std Err. (emu/Oe),AC X'' (emu/Oe),AC X'' Std Err. (emu/Oe),AC Drive (Oe),AC Frequency (Hz),AC Averaging Time (sec),AC Cycles,AC Range,AC Measure Type,AC Signal' (V),AC Signal'' (V),AC Trim Coil Ratio,AC Trim Coil Phase,Min. Temperature (K),Max. Temperature (K),Min. Field (Oe),Max. Field (Oe),Mass (grams),Motor Lag (deg),Pressure (Torr),Measure Count,Measurement Number,SQUID Status (code),Motor Status (code),Measure Status (code),Motor Current (amps),Motor Temp. (C),Temp. Status (code),Field Status (code),Chamber Status (code),Chamber Temp (K),Redirection State,Average Temp (K),Rotation Angle (deg),Rotator state,DC Moment Fixed Ctr (emu),DC Moment Err Fixed Ctr (emu),DC Moment Free Ctr (emu),DC Moment Err Free Ctr (emu),DC Fixed Fit,DC Free Fit,DC Calculated Center (mm),DC Calculated Center Err (mm),DC Scan Length (mm),DC Scan Time (s),DC Number of Points,DC Squid Drift,DC Min V (V),DC Max V (V),DC Scans per Measure,Map 01,Map 02,Map 03,Map 04,Map 05,Map 06,Map 07,Map 08,Map 09,Map 10,Map 11,Map 12,Map 13,Map 14,Map 15,Map 16
,3881449066.25494,300.006805419922,69999.640625,-9.02897135085585E-4,3.56898558504529E-7,1,4,14.0008964538574,5.00499261917442,32.6699987053871,-1.12319512240553,-0.172396662502137,1,-1.4013648638623E-6,,,,,,,,,,,,,,,,,,,,,300.006805419922,300.006805419922,69999.640625,69999.640625,53.488012013746,5.8818014121283,4.57562351226807,56,1,0,0,1,0.32806396484375,32.7468223571777,1,1,3,300.006805419922,0,300.006805419922,,,,,,,,,,,,,,,,,,,,,,,,,,,,,,,,,
,3881449165.66497,300.044769287109,60000.4453125,-7.37198459154056E-4,2.85951111505698E-7,1,4,14.0008964538574,5.0048339344469,32.6699987053871,-0.916998866094676,-0.140937231148943,1,-1.29275622135768E-6,,,,,,,,,,,,,,,,,,,,,300.0341796875,300.055358886719,60000.4453125,60000.4453125,53.5169322689576,5.8824920629475,4.71786069869995,54,1,68,0,0,0.330047607421875,33.7243423461914,1,1,3,300.055358886719,0,300.044769287109,,,,,,,,,,,,,,,,,,,,,,,,,,,,,,,,,
,3881449259.51377,299.982238769531,49999.6171875,-5.72239260344644E-4,1.86604674752686E-7,1,4,14.0008964538574,5.00498052967096,32.6699987053871,-0.712004364344028,-0.108295114403006,10,-1.11575854778576E-7,,,,,,,,,,,,,,,,,,,,,299.957489013672,300.006988525391,49999.6171875,49999.6171875,53.638475503698,5.88226908317008,4.89161062240601,56,1,0,0,1,0.327911376953125,33.7243423461914,1,1,3,300.006988525391,0,299.982238769531,,,,,,,,,,,,,,,,,,,,,,,,,,,,,,,,,
,3881449363.25141,300.079925537109,39999.671875,-4.060491042379E-4,9.97582882476967E-8,1,4,14.0008964538574,5.00495472612014,32.6699987053871,-0.505114243005829,-0.0775388468839025,1,-6.38081834016333E-7,,,,,,,,,,,,,,,,,,,,,300.061187744141,300.098663330078,39999.671875,39999.671875,53.7748696803038,5.88195859745814,4.92482423782349,54,1,68,0,0,0.32989501953125,34.2131004333496,1,1,3,300.098663330078,0,300.079925537109,,,,,,,,,,,,,,,,,,,,,,,,,,,,,,,,,
,3881449448.79585,300.091979980469,29999.67578125,-2.40489631443663E-4,6.55953796854631E-8,1,4,14.0008964538574,5.00496836742671,32.6699987053871,-0.29916547008103,-0.0459130403316256,1,-3.69184713998473E-7,,,,,,,,,,,,,,,,,,,,,300.088256835937,300.095703125,29999.67578125,29999.67578125,53.7854216653134,5.88182315362037,4.88075876235962,56,1,0,0,1,0.329742431640625,34.2131004333496,1,1,3,300.088256835937,0,300.091979980469,,,,,,,,,,,,,,,,,,,,,,,,,,,,,,,,,
,3881449533.60363,300.198516845703,19999.58984375,-7.5504428271661E-5,4.38110893345753E-8,1,4,14.0008964538574,5.00505101525926,32.6699987053871,-0.0939216260734089,-0.0144607496535831,1,-1.52476879356918E-7,,,,,,,,,,,,,,,,,,,,,300.178039550781,300.218994140625,19999.58984375,19999.58984375,53.9401841121211,5.88232451170266,4.84510374069214,56,1,0,0,1,0.328216552734375,34.2131004333496,1,1,3,300.218994140625,0,300.198516845703,,,,,,,,,,,,,,,,,,,,,,,,,,,,,,,,,
,3881449598.26964,300.154281616211,14499.6435546875,1.4383163281002E-5,2.9290751735043E-8,1,4,14.0008964538574,5.00505294586986,32.6699987053871,0.0179110048384626,0.00262657631113647,1,-7.39156183983455E-8,,,,,,,,,,,,,,,,,,,,,300.132080078125,300.176483154297,14499.6435546875,14499.6435546875,53.8999302433807,5.88131390205021,4.82505416870117,56,1,0,0,1,0.327987670898438,34.2131004333496,1,1,3,300.176483154297,0,300.154281616211,,,,,,,,,,,,,,,,,,,,,,,,,,,,,,,,,
,3881449639.33222,300.287063598633,13499.4931640625,3.06021095737499E-5,2.97299794124754E-8,1,4,14.0008964538574,5.0051461081323,32.6699987053871,0.0380983435615211,0.00565907345482182,1,-1.00580983384683E-7,,,,,,,,,,,,,,,,,,,,,300.269317626953,300.304809570313,13499.4931640625,13499.4931640625,53.9581615680634,5.88197159821381,4.81279182434082,56,1,0,0,1,0.32745361328125,33.7243423461914,1,1,3,300.304809570313,0,300.287063598633,,,,,,,,,,,,,,,,,,,,,,,,,,,,,,,,,
,3881449680.04247,300.325164794922,12499.734375,4.6768981707349E-5,2.69845861159767E-8,1,4,14.0008964538574,5.0050996207552,32.6699987053871,0.0582114871318548,0.00873536510106284,1,-8.39951362097331E-8,,,,,,,,,,,,,,,,,,,,,300.322998046875,300.327331542969,12499.734375,12499.734375,53.8237214627557,5.88239888523972,4.80059766769409,56,1,0,0,1,0.329971313476562,34.2131004333496,1,1,3,300.322998046875,0,300.325164794922,,,,,,,,,,,,,,,,,,,,,,,,,,,,,,,,,
,3881449721.28773,300.378799438477,11499.7109375,6.27565261017437E-5,3.02526672373886E-8,1,4,14.0008964538574,5.00496675984744,32.6699987053871,0.0780963245821735,0.0117955715189467,1,-5.28035884560873E-8,,,,,,,,,,,,,,,,,,,,,300.361633300781,300.395965576172,11499.7109375,11499.7109375,53.9366667837845,5.8822304475208,4.78337097167969,56,1,0,0,1,0.32806396484375,34.2131004333496,1,1,3,300.395965576172,0,300.378799438477,,,,,,,,,,,,,,,,,,,,,,,,,,,,,,,,,
,3881449773.02384,300.316284179687,10499.5361328125,7.86758029172074E-5,3.42303913559506E-8,1,4,14.0008964538574,5.0049281330577,32.6699987053871,0.0979049865733849,0.0147925854614772,1,-6.2161129466057E-8,,,,,,,,,,,,,,,,,,,,,300.304016113281,300.328552246094,10499.5361328125,10499.5361328125,53.9558166825057,5.88182670281585,4.77853870391846,56,1,0,0,1,0.326995849609375,34.2131004333496,1,1,3,300.304016113281,0,300.316284179687,,,,,,,,,,,,,,,,,,,,,,,,,,,,,,,,,
,3881449814.79314,300.245574951172,9499.77734375,9.44561754427183E-5,3.21453970347479E-8,1,4,14.0008964538574,5.00489955975224,32.6699987053871,0.117533719742423,0.0178094151916848,1,-3.44814762059926E-8,,,,,,,,,,,,,,,,,,,,,300.239105224609,300.252044677734,9499.77734375,9499.77734375,53.8710099881692,5.88206070185487,4.7651538848877,56,1,0,0,1,0.3289794921875,34.2131004333496,1,1,3,300.252044677734,0,300.245574951172,,,,,,,,,,,,,,,,,,,,,,,,,,,,,,,,,
,3881449855.67703,300.363830566406,8499.5771484375,1.09915886526866E-4,3.973505242896E-8,1,4,14.0008964538574,5.00489980155908,32.6699987053871,0.136765943667333,0.0207546778161262,1,-1.57077818362388E-8,,,,,,,,,,,,,,,,,,,,,300.348663330078,300.378997802734,8499.5771484375,8499.5771484375,53.8323193764672,5.88277999112519,4.75699138641357,55,1,68,0,0,0.328521728515625,34.2131004333496,1,1,3,300.378997802734,0,300.363830566406,,,,,,,,,,,,,,,,,,,,,,,,,,,,,,,,,
,3881449896.97105,300.304901123047,7499.5791015625,1.2507285094908E-4,4.40677443249261E-8,1,4,14.0008964538574,5.00483112396407,32.6699987053871,0.155620793591708,0.0236270381151636,1,-9.17299550807796E-9,,,,,,,,,,,,,,,,,,,,,300.299957275391,300.309844970703,7499.5791015625,7499.5791015625,53.8811711589192,5.88186016840539,4.75260591506958,54,1,68,0,0,0.329055786132812,34.2131004333496,1,1,3,300.299957275391,0,300.304901123047,,,,,,,,,,,,,,,,,,,,,,,,,,,,,,,,,
,3881449938.90572,300.224655151367,6499.75634765625,1.39800919167278E-4,3.09414324192512E-8,1,4,14.0008964538574,5.00496048901641,32.6699987053871,0.173945573774672,0.0264548288364876,1,2.56011821212417E-8,,,,,,,,,,,,,,,,,,,,,300.206268310547,300.243041992188,6499.75634765625,6499.75634765625,53.9495636543519,5.88174670082876,4.75052165985107,56,1,0,0,1,0.327224731445313,34.2131004333496,1,1,3,300.243041992188,0,300.224655151367,,,,,,,,,,,,,,,,,,,,,,,,,,,,,,,,,
,3881449980.79326,300.346633911133,5499.64501953125,1.53660405480586E-4,3.47125891657713E-8,1,4,14.0008964538574,5.00478588220546,32.6699987053871,0.191180680100829,0.029076475662371,1,2.84647130013987E-8,,,,,,,,,,,,,,,,,,,,,300.340087890625,300.353179931641,5499.64501953125,5499.64501953125,53.8456070612942,5.88301177695903,4.73716020584106,56,1,0,0,1,0.327911376953125,34.2131004333496,1,1,3,300.340087890625,0,300.346633911133,,,,,,,,,,,,,,,,,,,,,,,,,,,,,,,,,
,3881450034.73902,300.12532043457,4499.67138671875,1.66115463095529E-4,3.58030587146177E-8,1,4,14.0008964538574,5.00477044627715,32.6699987053871,0.206672686799813,0.031455492732287,1,4.87251100628691E-8,,,,,,,,,,,,,,,,,,,,,300.122467041016,300.128173828125,4499.67138671875,4499.67138671875,53.8049623782942,5.8826815075012,4.73156452178955,56,1,0,0,1,0.329971313476562,34.2131004333496,1,1,3,300.128173828125,0,300.12532043457,,,,,,,,,,,,,,,,,,,,,,,,,,,,,,,,,
,3881450089.52093,300.221343994141,3499.78662109375,1.75692938369609E-4,3.80200691528546E-8,1,4,14.0008964538574,5.00473560929275,32.6699987053871,0.218585512338704,0.0332744808186708,1,5.61388037802189E-8,,,,,,,,,,,,,,,,,,,,,300.208648681641,300.234039306641,3499.78662109375,3499.78662109375,53.9308045698903,5.88291193213491,4.72908687591553,56,1,0,0,1,0.328521728515625,34.2131004333496,1,1,3,300.234039306641,0,300.221343994141,,,,,,,,,,,,,,,,,,,,,,,,,,,,,,,,,
,3881450159.62371,300.389663696289,2709.52124023438,1.79179068199494E-4,3.97735816512898E-8,1,4,14.0008964538574,5.00475034702367,32.6699987053871,0.222921905333242,0.0339462922936666,1,6.64423197476417E-8,,,,,,,,,,,,,,,,,,,,,300.377410888672,300.401916503906,2709.52124023438,2709.52124023438,53.8346642620249,5.88252548837005,4.72083520889282,56,1,0,0,1,0.330123901367188,34.2131004333496,1,1,3,300.401916503906,0,300.389663696289,,,,,,,,,,,,,,,,,,,,,,,,,,,,,,,,,
,3881450211.85707,300.225433349609,2129.66821289062,1.77256579549837E-4,3.88498199365717E-8,1,4,14.0008964538574,5.00469842813986,32.6699987053871,0.220523427051964,0.0336043243191179,1,8.40093002724016E-8,,,,,,,,,,,,,,,,,,,,,300.216613769531,300.234252929687,2129.66821289062,2129.66821289062,53.8440438042557,5.88277537650447,4.71170473098755,56,1,0,0,1,0.329742431640625,34.2131004333496,1,1,3,300.216613769531,0,300.225433349609,,,,,,,,,,,,,,,,,,,,,,,,,,,,,,,,,
,3881450251.2193,300.101760864258,1549.828125,1.68385599682701E-4,4.07520621702529E-8,1,4,14.0008964538574,5.00466712971107,32.6699987053871,0.209485693780084,0.0319195801335087,1,7.76320102145359E-8,,,,,,,,,,,,,,,,,,,,,300.097381591797,300.106140136719,1549.828125,1549.828125,53.8667110313134,5.88313265592474,4.71022844314575,56,1,0,0,1,0.328903198242188,34.2131004333496,1,1,3,300.097381591797,0,300.101760864258,,,,,,,,,,,,,,,,,,,,,,,,,,,,,,,,,
,3881450291.17519,300.150253295898,969.610290527344,1.46490037387272E-4,3.35790594717891E-8,1,4,14.0008964538574,5.00466955801797,32.6699987053871,0.18224521104644,0.0277736675307244,1,7.12700434975886E-8,,,,,,,,,,,,,,,,,,,,,300.149597167969,300.150909423828,969.610290527344,969.610290527344,53.7842492225345,5.88302963608288,4.69847726821899,56,1,0,0,1,0.329360961914063,34.2131004333496,1,1,3,300.149597167969,0,300.150253295898,,,,,,,,,,,,,,,,,,,,,,,,,,,,,,,,,
,3881450330.07656,300.050704956055,389.682006835937,9.56928763385108E-5,2.50772016812409E-8,1,4,14.0008964538574,5.00455709958215,32.6699987053871,0.119049396468664,0.0181184238423406,1,2.74069512518375E-8,,,,,,,,,,,,,,,,,,,,,300.044067382812,300.057342529297,389.682006835937,389.682006835937,53.8651477742749,5.88358351184163,4.69400310516357,56,1,0,0,1,0.32928466796875,34.2131004333496,1,1,3,300.044067382812,0,300.050704956055,,,,,,,,,,,,,,,,,,,,,,,,,,,,,,,,,
,3881450367.36532,300.116058349609,-190.460296630859,-3.99529621315624E-5,2.85526799353552E-8,1,4,14.0008964538574,5.00471773153259,32.6699987053871,-0.0497072600121917,-0.00756217489633557,1,-9.16718209663835E-9,,,,,,,,,,,,,,,,,,,,,300.112274169922,300.119842529297,-190.460296630859,-190.460296630859,53.7643176952942,5.8829494848359,4.69976377487183,56,1,0,0,1,0.329208374023438,34.2131004333496,1,1,3,300.112274169922,0,300.116058349609,,,,,,,,,,,,,,,,,,,,,,,,,,,,,,,,,
,3881450404.36036,300.198837280273,-770.162048339844,-1.25828845009828E-4,3.06500679146534E-8,1,4,14.0008964538574,5.00466975238004,32.6699987053871,-0.156551119556538,-0.0237901973941135,1,-7.98711716552598E-9,,,,,,,,,,,,,,,,,,,,,300.197418212891,300.200256347656,-770.162048339844,-770.162048339844,53.8116062207076,5.88331752460442,4.69608688354492,56,1,0,0,1,0.329437255859375,33.7243423461914,1,1,3,300.197418212891,0,300.198837280273,,,,,,,,,,,,,,,,,,,,,,,,,,,,,,,,,
,3881450441.9087,300.107391357422,-1350.10290527344,-1.59592629262778E-4,3.38685369421843E-8,1,4,14.0008964538574,5.00472842990533,32.6699987053871,-0.198554788811881,-0.0302211503632529,1,-4.77530712346235E-8,,,,,,,,,,,,,,,,,,,,,300.103393554687,300.111389160156,-1350.10290527344,-1350.10290527344,53.8913323296692,5.88312619703847,4.68816947937012,56,1,0,0,1,0.32806396484375,34.2131004333496,1,1,3,300.103393554687,0,300.107391357422,,,,,,,,,,,,,,,,,,,,,,,,,,,,,,,,,
,3881450480.47846,300.202758789063,-1930.11938476562,-1.73572314212551E-4,3.44665457273153E-8,1,4,14.0008964538574,5.00464032649878,32.6699987053871,-0.215931896267057,-0.0329346961796925,1,-1.05869107227379E-7,,,,,,,,,,,,,,,,,,,,,300.177398681641,300.228118896484,-1930.11938476562,-1930.11938476562,53.8248939055345,5.88292417573153,4.68305206298828,56,1,0,0,1,0.330276489257812,33.7243423461914,1,1,3,300.228118896484,0,300.202758789063,,,,,,,,,,,,,,,,,,,,,,,,,,,,,,,,,
,3881450518.64909,300.342590332031,-2510.09814453125,-1.77989846434536E-4,3.77684952458918E-8,1,4,14.0008964538574,5.00459576113193,32.6699987053871,-0.221426630390704,-0.0337601123057292,1,-9.86181866213053E-8,,,,,,,,,,,,,,,,,,,,,300.339599609375,300.345581054687,-2510.09814453125,-2510.09814453125,53.9038383859769,5.88377800141943,4.67870187759399,56,1,0,0,1,0.328750610351562,34.7018585205078,1,1,3,300.345855712891,0,300.342590332031,,,,,,,,,,,,,,,,,,,,,,,,,,,,,,,,,
,3881450570.57021,300.342346191406,-3000.03295898438,-1.77551780522469E-4,4.04153595200038E-8,1,4,14.0008964538574,5.00460951304336,32.6699987053871,-0.220883665585563,-0.033669526780789,1,-9.22467364110133E-8,,,,,,,,,,,,,,,,,,,,,300.340881347656,300.343811035156,-3000.03295898438,-3000.03295898438,53.8174684346018,5.88338859069827,4.68193674087524,56,1,0,0,1,0.32928466796875,34.2131004333496,1,1,3,300.340881347656,0,300.342346191406,,,,,,,,,,,,,,,,,,,,,,,,,,,,,,,,,
,3881450609.79649,300.224548339844,-4000.00610351562,-1.70523953691186E-4,3.50674646026231E-8,1,4,14.0008964538574,5.00457259896102,32.6699987053871,-0.212131482198366,-0.032382655710572,1,-1.25701020682235E-7,,,,,,,,,,,,,,,,,,,,,300.217681884766,300.231414794922,-4000.00610351562,-4000.00610351562,53.9120454854288,5.88338823562642,4.67907571792603,56,1,0,0,1,0.329513549804687,34.2131004333496,1,1,3,300.217132568359,0,300.224548339844,,,,,,,,,,,,,,,,,,,,,,,,,,,,,,,,,
,3881450649.30402,300.2919921875,-4999.966796875,-1.59349530204714E-4,3.31169810560031E-8,1,4,14.0008964538574,5.00462938391845,32.6699987053871,-0.198235281791955,-0.0302504631423196,1,-1.08912310537739E-7,,,,,,,,,,,,,,,,,,,,,300.288208007812,300.295776367188,-4999.966796875,-4999.966796875,53.7940195790249,5.88389199692185,4.66946458816528,56,1,0,0,1,0.3302001953125,35.190616607666,1,1,3,300.295776367188,0,300.2919921875,,,,,,,,,,,,,,,,,,,,,,,,,,,,,,,,,
,3881450689.1162,300.343887329102,-5999.85205078125,-1.46104531354804E-4,3.82363713865076E-8,1,4,14.0008964538574,5.0045941143473,32.6699987053871,-0.181758709413556,-0.0277202023941512,1,-8.732541966893E-8,,,,,,,,,,,,,,,,,,,,,300.339385986328,300.348388671875,-5999.85205078125,-5999.85205078125,53.8076980781114,5.88380807057996,4.67653656005859,56,1,0,0,1,0.330581665039063,33.7243423461914,1,1,3,300.348388671875,0,300.343887329102,,,,,,,,,,,,,,,,,,,,,,,,,,,,,,,,,
,3881450728.79299,300.229629516602,-6999.4599609375,-1.3190392002915E-4,3.59241683033132E-8,1,4,14.0008964538574,5.00474740347208,32.6699987053871,-0.164095741707851,-0.025053227755543,1,-9.9907559836803E-8,,,,,,,,,,,,,,,,,,,,,300.221221923828,300.238037109375,-6999.4599609375,-6999.4599609375,53.8041807497749,5.8832636490264,4.66062116622925,56,1,0,0,1,0.330429077148438,34.2131004333496,1,1,3,300.221221923828,0,300.229629516602,,,,,,,,,,,,,,,,,,,,,,,,,,,,,,,,,
,3881450769.11,300.250442504883,-7999.99951171875,-1.16914125345874E-4,3.0809775668789E-8,1,4,14.0008964538574,5.00464211653699,32.6699987053871,-0.145446381915796,-0.0221854054834997,1,-7.24178277176313E-8,,,,,,,,,,,,,,,,,,,,,300.2412109375,300.259674072266,-7999.99951171875,-7999.99951171875,53.8362275190634,5.8831230616496,4.63991165161133,56,1,0,0,1,0.328750610351562,34.2131004333496,1,1,3,300.259674072266,0,300.250442504883,,,,,,,,,,,,,,,,,,,,,,,,,,,,,,,,,
,3881450820.83231,300.438995361328,-8999.6953125,-1.01508914860916E-4,3.2319421140491E-8,1,4,14.0008964538574,5.00467785316168,32.6699987053871,-0.126289279383961,-0.0192201696109428,1,-2.89862617575045E-8,,,,,,,,,,,,,,,,,,,,,300.435638427734,300.442352294922,-8999.6953125,-8999.6953125,53.7471218678711,5.8834719205561,4.63801050186157,56,1,0,0,1,0.330276489257812,34.2131004333496,1,1,3,300.435638427734,0,300.438995361328,,,,,,,,,,,,,,,,,,,,,,,,,,,,,,,,,
,3881450861.24354,300.301910400391,-9999.8076171875,-8.58628001553363E-5,3.68866238246254E-8,1,4,14.0008964538574,5.0046091686723,32.6699987053871,-0.106814973348231,-0.0163008670641263,1,-5.94961791949121E-8,,,,,,,,,,,,,,,,,,,,,300.287841796875,300.315979003906,-9999.8076171875,-9999.8076171875,53.8530325322269,5.88329707252818,4.64442443847656,54,1,68,0,0,0.329360961914063,34.2131004333496,1,1,3,300.315979003906,0,300.301910400391,,,,,,,,,,,,,,,,,,,,,,,,,,,,,,,,,
,3881450913.06436,300.402954101562,-10999.580078125,-6.99905176389645E-5,3.54274472686109E-8,1,4,14.0008964538574,5.0045756992898,32.6699987053871,-0.0870741749291673,-0.0132516086309047,1,-1.97104465189747E-8,,,,,,,,,,,,,,,,,,,,,300.389739990234,300.416168212891,-10999.580078125,-10999.580078125,53.7424320967557,5.88335988172528,4.64723062515259,55,1,68,0,0,0.331497192382812,33.7243423461914,6,1,3,300.416168212891,0,300.402954101562,,,,,,,,,,,,,,,,,,,,,,,,,,,,,,,,,
,3881450979.20961,300.446548461914,-11999.69140625,-5.40415807019026E-5,2.77054875973139E-8,1,4,14.0008964538574,5.00452672768273,32.6699987053871,-0.0672350587388577,-0.0102078104068857,1,4.05303262706437E-9,,,,,,,,,,,,,,,,,,,,,300.436676025391,300.456420898438,-11999.69140625,-11999.69140625,53.7842492225345,5.88340462204673,4.63908386230469,56,1,0,0,1,0.330352783203125,34.2131004333496,1,1,3,300.436676025391,0,300.446548461914,,,,,,,,,,,,,,,,,,,,,,,,,,,,,,,,,
,3881451020.28196,300.279098510742,-12999.7646484375,-3.80379084318533E-5,3.0600123528289E-8,1,4,14.0008964538574,5.00456555141056,32.6699987053871,-0.0473222117215069,-0.00720223877177245,1,-1.10149555768235E-8,,,,,,,,,,,,,,,,,,,,,300.270690917969,300.287506103516,-12999.7646484375,-12999.7646484375,53.8155143633038,5.88281824443901,4.63743257522583,56,1,0,0,1,0.329513549804687,34.2131004333496,1,1,3,300.270690917969,0,300.279098510742,,,,,,,,,,,,,,,,,,,,,,,,,,,,,,,,,
,3881451061.57133,300.142196655273,-13999.5869140625,-2.18108208515892E-5,3.4046397549834E-8,1,4,14.0008964538574,5.00455111120443,32.6699987053871,-0.0271367867396022,-0.00411337119789412,1,6.82891854413874E-9,,,,,,,,,,,,,,,,,,,,,300.12939453125,300.154998779297,-13999.5869140625,-13999.5869140625,53.775651308823,5.88377031196191,4.64068174362183,56,1,0,0,1,0.329132080078125,34.7018585205078,1,1,3,300.155731201172,0,300.142196655273,,,,,,,,,,,,,,,,,,,,,,,,,,,,,,,,,
,3881451119.67862,300.198440551758,-14999.787109375,-5.62671870333565E-6,2.89574350850589E-8,1,4,14.0008964538574,5.00456474828207,32.6699987053871,-0.00700121035474344,-0.00105799609098965,1,4.30846519973325E-9,,,,,,,,,,,,,,,,,,,,,300.198303222656,300.198577880859,-14999.787109375,-14999.787109375,53.8694467311307,5.88368767956202,4.64003849029541,56,1,0,0,1,0.328826904296875,33.7243423461914,1,1,3,300.198303222656,0,300.198440551758,,,,,,,,,,,,,,,,,,,,,,,,,,,,,,,,,
,3881451205.42748,300.15380859375,-24999.6953125,1.58173584232905E-4,5.42003423028575E-8,1,4,14.0008964538574,5.00452788183127,32.6699987053871,0.196761950787607,0.0300582367511073,1,1.33719845350415E-7,,,,,,,,,,,,,,,,,,,,,300.131469726562,300.176147460937,-24999.6953125,-24999.6953125,53.7854216653134,5.88337307578472,4.63471794128418,56,1,0,0,1,0.33050537109375,33.7243423461914,1,1,3,300.176147460937,0,300.15380859375,,,,,,,,,,,,,,,,,,,,,,,,,,,,,,,,,
,3881451293.35,300.221450805664,-34999.62890625,3.23213348767786E-4,7.30235574137873E-8,1,4,14.0008964538574,5.00448620426175,32.6699987053871,0.402044564458752,0.0615253845903459,1,3.57500779841006E-7,,,,,,,,,,,,,,,,,,,,,300.202301025391,300.240600585937,-34999.62890625,-34999.62890625,53.7772145658615,5.88390863425966,4.63826656341553,56,1,0,0,1,0.3289794921875,33.7243423461914,1,1,3,300.240600585937,0,300.221450805664,,,,,,,,,,,,,,,,,,,,,,,,,,,,,,,,,
,3881451380.81775,300.17121887207,-44999.7734375,4.88332293522127E-4,1.27506828695622E-7,1,4,14.0008964538574,5.00466586190756,32.6699987053871,0.607456432738997,0.0930259584667458,1,5.92086530746069E-7,,,,,,,,,,,,,,,,,,,,,300.153747558594,300.188690185547,-44999.7734375,-44999.7734375,53.8245030912749,5.88379064936837,4.6338267326355,54,1,68,0,0,0.32928466796875,33.7243423461914,1,1,3,300.188690185547,0,300.17121887207,,,,,,,,,,,,,,,,,,,,,,,,,,,,,,,,,
,3881451481.67035,300.203033447266,-54999.87109375,6.5353793194032E-4,2.12059825317239E-7,1,4,14.0008964538574,5.0045491383211,32.6699987053871,0.812895082485651,0.124762094494737,1,1.00858989826076E-6,,,,,,,,,,,,,,,,,,,,,300.184387207031,300.2216796875,-54999.87109375,-54999.87109375,53.7662717665922,5.88371089855787,4.6303882598877,56,1,0,0,1,0.3289794921875,34.2131004333496,1,1,3,300.2216796875,0,300.203033447266,,,,,,,,,,,,,,,,,,,,,,,,,,,,,,,,,
,3881451568.84746,300.230178833008,-64999.640625,8.18563057077813E-4,3.33003174047505E-7,1,4,14.0008964538574,5.00452970234921,32.6699987053871,1.01815504415751,0.156258201092465,1,1.25782682068736E-6,,,,,,,,,,,,,,,,,,,,,300.207275390625,300.253082275391,-64999.640625,-64999.640625,53.5450708956499,5.88400137542666,4.62748670578003,54,1,68,0,0,0.330429077148438,33.7243423461914,1,1,3,300.253082275391,0,300.230178833008,,,,,,,,,,,,,,,,,,,,,,,,,,,,,,,,,
,3881451669.42354,300.190093994141,-64999.66796875,8.18195886848592E-4,3.03841232642552E-7,1,4,14.0008964538574,5.00455692120888,32.6699987053871,1.01768190912074,0.156348468466415,1,1.38519896117166E-6,,,,,,,,,,,,,,,,,,,,,300.166046142578,300.214141845703,-64999.66796875,-64999.66796875,53.5696921940057,5.88324414707334,4.6197681427002,56,1,0,0,1,0.327835083007812,33.7243423461914,1,1,3,300.214141845703,0,300.190093994141,,,,,,,,,,,,,,,,,,,,,,,,,,,,,,,,,
,3881451755.92058,300.227722167969,-54999.51953125,6.53322976631321E-4,2.09566465148222E-7,1,4,14.0008964538574,5.00443603884828,32.6699987053871,0.81257819835706,0.12487400488826,1,1.13436462496996E-6,,,,,,,,,,,,,,,,,,,,,300.204345703125,300.251098632812,-54999.51953125,-54999.51953125,53.5341280963807,5.88419352707972,4.6192193031311,56,1,0,0,1,0.330276489257812,34.2131004333496,1,1,3,300.251098632812,0,300.227722167969,,,,,,,,,,,,,,,,,,,,,,,,,,,,,,,,,
,3881451842.99932,300.150772094727,-44999.53515625,4.88110997398194E-4,1.32455672829192E-7,1,4,14.0008964538574,5.00456022604895,32.6699987053871,0.607115799271224,0.0932933108262939,1,8.42798913143145E-7,,,,,,,,,,,,,,,,,,,,,300.145172119141,300.156372070313,-44999.53515625,-44999.53515625,53.6955343856018,5.88286568700974,4.61644792556763,56,1,0,0,1,0.327835083007812,34.2131004333496,1,1,3,300.145172119141,0,300.150772094727,,,,,,,,,,,,,,,,,,,,,,,,,,,,,,,,,
,3881451930.54081,300.060623168945,-34999.66796875,3.22767014278572E-4,9.46893013457008E-8,1,4,14.0008964538574,5.00462889040329,32.6699987053871,0.401481501620242,0.0616000619570326,1,4.83349388050981E-7,,,,,,,,,,,,,,,,,,,,,300.049621582031,300.071624755859,-34999.66796875,-34999.66796875,53.4610458298326,5.88314483832578,4.61717796325684,56,1,0,0,1,0.327224731445313,33.7243423461914,1,1,3,300.071624755859,0,300.060623168945,,,,,,,,,,,,,,,,,,,,,,,,,,,,,,,,,
,3881452016.2937,300.181137084961,-24999.732421875,1.57724395171308E-4,5.53748401695281E-8,1,4,14.0008964538574,5.00461284390537,32.6699987053871,0.196186734041715,0.0301125011964718,1,2.44993439136726E-7,,,,,,,,,,,,,,,,,,,,,300.180755615234,300.181518554687,-24999.732421875,-24999.732421875,53.457528501496,5.88349236359317,4.61905145645142,54,1,68,0,0,0.32867431640625,33.7243423461914,1,1,3,300.180755615234,0,300.181137084961,,,,,,,,,,,,,,,,,,,,,,,,,,,,,,,,,
,3881452101.03274,300.116104125977,-14999.673828125,-6.17630902457217E-6,3.43159178740532E-8,1,4,14.0008964538574,5.00463767893709,32.6699987053871,-0.00770737835779163,-0.00101542463380031,1,1.22025295152777E-7,,,,,,,,,,,,,,,,,,,,,300.111846923828,300.120361328125,-14999.673828125,-14999.673828125,53.4348612744383,5.88374844014988,4.61895799636841,56,1,0,0,1,0.330047607421875,34.7018585205078,1,1,3,300.111846923828,0,300.116104125977,,,,,,,,,,,,,,,,,,,,,,,,,,,,,,,,,
,3881452158.08678,300.236633300781,-14000.1279296875,-2.23809518488287E-5,3.52371675586473E-8,1,4,14.0008964538574,5.00458940008142,32.6699987053871,-0.0278631685064806,-0.00411078064134991,1,9.55490863023403E-8,,,,,,,,,,,,,,,,,,,,,300.231201171875,300.242065429687,-14000.1279296875,-14000.1279296875,53.4813681713326,5.88392339368742,4.60876083374023,56,1,0,0,1,0.327301025390625,34.7018585205078,1,1,3,300.231201171875,0,300.236633300781,,,,,,,,,,,,,,,,,,,,,,,,,,,,,,,,,
,3881452197.89347,300.192642211914,-13000.318359375,-3.85391079658514E-5,3.19095817516149E-8,1,4,14.0008964538574,5.00455148008237,32.6699987053871,-0.0479635092170604,-0.00717891528603653,1,8.38410425199726E-8,,,,,,,,,,,,,,,,,,,,,300.185577392578,300.19970703125,-13000.318359375,-13000.318359375,53.482931428371,5.88386454637184,4.60826587677002,56,1,0,0,1,0.3289794921875,34.2131004333496,1,1,3,300.185577392578,0,300.192642211914,,,,,,,,,,,,,,,,,,,,,,,,,,,,,,,,,
,3881452237.67426,300.163177490234,-12000.3076171875,-5.45913892092639E-5,2.87945036993602E-8,1,4,14.0008964538574,5.00450680719605,32.6699987053871,-0.0679339393851982,-0.0102113919194841,1,8.46442099237072E-8,,,,,,,,,,,,,,,,,,,,,300.157928466797,300.168426513672,-12000.3076171875,-12000.3076171875,53.557186137698,5.88417382508675,4.6160831451416,56,1,0,0,1,0.32806396484375,34.2131004333496,1,1,3,300.168426513672,0,300.163177490234,,,,,,,,,,,,,,,,,,,,,,,,,,,,,,,,,
,3881452276.17971,300.237167358398,-11000.259765625,-7.05205592998291E-5,3.19997910935524E-8,1,4,14.0008964538574,5.00447554717881,32.6699987053871,-0.0877479820985156,-0.0132406908415088,1,6.92801179515131E-8,,,,,,,,,,,,,,,,,,,,,300.210632324219,300.263702392578,-11000.259765625,-11000.259765625,53.3547443512172,5.88341698216833,4.61174726486206,56,1,0,0,1,0.33050537109375,34.2131004333496,1,1,3,300.263702392578,0,300.237167358398,,,,,,,,,,,,,,,,,,,,,,,,,,,,,,,,,
,3881452339.03429,300.447021484375,-10000.474609375,-8.62828712757231E-5,3.73914613497461E-8,1,4,14.0008964538574,5.00447891599587,32.6699987053871,-0.107351150653732,-0.016264762332811,1,3.28561411810616E-8,,,,,,,,,,,,,,,,,,,,,300.443756103516,300.450286865234,-10000.474609375,-10000.474609375,53.3602157508518,5.88427053489404,4.60956811904907,56,1,0,0,1,0.331649780273438,34.2131004333496,1,1,3,300.443756103516,0,300.447021484375,,,,,,,,,,,,,,,,,,,,,,,,,,,,,,,,,
,3881452377.88063,300.301345825195,-9000.060546875,-1.01985064236336E-4,3.6927589709084E-8,1,4,14.0008964538574,5.00449977184423,32.6699987053871,-0.126885161653471,-0.0192447881117615,1,2.27837905199346E-8,,,,,,,,,,,,,,,,,,,,,300.288238525391,300.314453125,-9000.060546875,-9000.060546875,53.4610458298326,5.88376502670867,4.60834407806396,56,1,0,0,1,0.328521728515625,34.2131004333496,1,1,3,300.314453125,0,300.301345825195,,,,,,,,,,,,,,,,,,,,,,,,,,,,,,,,,
,3881452429.75529,300.425201416016,-8000.3896484375,-1.17345297997685E-4,3.6696631675669E-8,1,4,14.0008964538574,5.00448512275651,32.6699987053871,-0.145988415173776,-0.0221869870450219,1,-8.97648770767202E-9,,,,,,,,,,,,,,,,,,,,,300.421936035156,300.428466796875,-8000.3896484375,-8000.3896484375,53.5196679687749,5.88378848460265,4.60579586029053,56,1,0,0,1,0.329513549804687,34.2131004333496,1,1,3,300.421936035156,0,300.425201416016,,,,,,,,,,,,,,,,,,,,,,,,,,,,,,,,,
,3881452471.30754,300.313186645508,-7000.013671875,-1.32313819577956E-4,3.14826412196951E-8,1,4,14.0008964538574,5.00447138636935,32.6699987053871,-0.164614501747097,-0.0249874841070431,1,1.36470465187795E-8,,,,,,,,,,,,,,,,,,,,,300.301391601562,300.324981689453,-7000.013671875,-7000.013671875,53.4196195183133,5.88396659295965,4.60889339447022,56,1,0,0,1,0.33050537109375,34.7018585205078,1,1,3,300.301391601562,0,300.313186645508,,,,,,,,,,,,,,,,,,,,,,,,,,,,,,,,,
,3881452511.45277,300.172485351562,-6000.3681640625,-1.46657311299685E-4,3.24565121683729E-8,1,4,14.0008964538574,5.00462878120309,32.6699987053871,-0.182463375551848,-0.0277251339208081,1,-7.10635544665455E-9,,,,,,,,,,,,,,,,,,,,,300.154388427734,300.190582275391,-6000.3681640625,-6000.3681640625,53.5173230832172,5.88270661309878,4.60595178604126,56,1,0,0,1,0.330657958984375,34.2131004333496,1,1,3,300.190582275391,0,300.172485351562,,,,,,,,,,,,,,,,,,,,,,,,,,,,,,,,,
,3881452565.17832,300.167221069336,-5000.28125,-1.59924731546729E-4,3.93344064908665E-8,1,4,14.0008964538574,5.00459745105609,32.6699987053871,-0.198964162130285,-0.0302600510931929,1,-2.94629504929264E-8,,,,,,,,,,,,,,,,,,,,,300.161437988281,300.173004150391,-5000.28125,-5000.28125,53.4864487567076,5.88332667423603,4.61068105697632,56,1,0,0,1,0.328750610351562,33.7243423461914,1,1,3,300.161437988281,0,300.167221069336,,,,,,,,,,,,,,,,,,,,,,,,,,,,,,,,,
,3881452619.12276,300.072998046875,-4000.30810546875,-1.71205364833261E-4,4.07397734345163E-8,1,4,14.0008964538574,5.00459677632751,32.6699987053871,-0.212998580227366,-0.0323938759730263,1,-3.10376300374633E-8,,,,,,,,,,,,,,,,,,,,,300.061004638672,300.084991455078,-4000.30810546875,-4000.30810546875,53.3531810941787,5.88362451046307,4.60306024551392,55,1,68,0,0,0.331268310546875,34.2131004333496,1,1,3,300.084991455078,0,300.072998046875,,,,,,,,,,,,,,,,,,,,,,,,,,,,,,,,,
,3881452670.48552,300.143707275391,-3000.42309570313,-1.78341877100482E-4,3.66135331442595E-8,1,4,14.0008964538574,5.00460911242756,32.6699987053871,-0.221872650441361,-0.0337792690317195,1,-6.04411183369123E-8,,,,,,,,,,,,,,,,,,,,,300.128753662109,300.158660888672,-3000.42309570313,-3000.42309570313,53.5188863402557,5.88398314253612,4.60793495178223,56,1,0,0,1,0.328292846679687,34.2131004333496,1,1,3,300.158660888672,0,300.143707275391,,,,,,,,,,,,,,,,,,,,,,,,,,,,,,,,,
,3881452731.24867,300.378601074219,-2510.28686523438,-1.78910802280904E-4,3.57851809744804E-8,1,4,14.0008964538574,5.00460817144378,32.6699987053871,-0.222576799741519,-0.0339106138444779,1,-7.95987615226697E-8,,,,,,,,,,,,,,,,,,,,,300.376739501953,300.380462646484,-2510.28686523438,-2510.28686523438,53.4762875859576,5.88387860813068,4.60942554473877,56,1,0,0,1,0.32806396484375,33.7243423461914,1,1,3,300.376739501953,0,300.378601074219,,,,,,,,,,,,,,,,,,,,,,,,,,,,,,,,,
,3881452768.19834,300.291625976562,-1930.42150878906,-1.75371722849243E-4,4.21477310352532E-8,1,4,14.0008964538574,5.00458917783952,32.6699987053871,-0.218177504334553,-0.0332086354099209,1,-5.31012981589645E-8,,,,,,,,,,,,,,,,,,,,,300.276580810547,300.306671142578,-1930.42150878906,-1930.42150878906,53.5149781976595,5.88384545113836,4.58793878555298,56,1,0,0,1,0.329132080078125,34.2131004333496,1,1,3,300.306671142578,0,300.291625976562,,,,,,,,,,,,,,,,,,,,,,,,,,,,,,,,,
,3881452819.52605,300.384078979492,-1350.20361328125,-1.6290745713121E-4,3.05701081549363E-8,1,4,14.0008964538574,5.00459844736851,32.6699987053871,-0.202665782287052,-0.0308855192999299,1,-7.91105361632006E-8,,,,,,,,,,,,,,,,,,,,,300.378570556641,300.389587402344,-1350.20361328125,-1350.20361328125,53.4798049142941,5.88402316609939,4.58397006988525,56,1,0,0,1,0.32989501953125,34.2131004333496,1,1,3,300.389587402344,0,300.384078979492,,,,,,,,,,,,,,,,,,,,,,,,,,,,,,,,,
,3881452858.23033,300.40364074707,-770.388610839844,-1.33726518916786E-4,3.2493976353678E-8,1,4,14.0008964538574,5.00460831959239,32.6699987053871,-0.166367360635677,-0.0253281658939732,1,-4.48231099153674E-8,,,,,,,,,,,,,,,,,,,,,300.390472412109,300.416809082031,-770.388610839844,-770.388610839844,53.3785840210537,5.88421457542835,4.58121252059937,56,1,0,0,1,0.329360961914063,33.7243423461914,1,1,3,300.416809082031,0,300.40364074707,,,,,,,,,,,,,,,,,,,,,,,,,,,,,,,,,
,3881452897.13665,300.393142700195,-190.472885131836,-6.3778706884044E-5,1.74159047180096E-8,1,4,14.0008964538574,5.00460752831991,32.6699987053871,-0.0793438896599804,-0.012095149401732,1,-3.36685940162671E-8,,,,,,,,,,,,,,,,,,,,,300.378265380859,300.408020019531,-190.472885131836,-190.472885131836,53.355916793996,5.88433967590226,4.58967065811157,56,1,0,0,1,0.330123901367188,34.2131004333496,1,1,3,300.408020019531,0,300.393142700195,,,,,,,,,,,,,,,,,,,,,,,,,,,,,,,,,
,3881453015.28488,300.160659790039,389.581298828125,8.00552294147172E-5,2.06858295492448E-8,1,4,14.0008964538574,5.00478911474526,32.6699987053871,0.099597758987542,0.0151825692444902,1,4.22047272054598E-8,,,,,,,,,,,,,,,,,,,,,300.148101806641,300.173217773438,389.581298828125,389.581298828125,53.452447916121,5.8835306794102,4.59296989440918,56,1,0,0,1,0.32989501953125,34.2131004333496,1,1,3,300.173217773438,0,300.160659790039,,,,,,,,,,,,,,,,,,,,,,,,,,,,,,,,,
,3881453054.65749,300.322189331055,969.585144042969,1.40852607202399E-4,8.94066404999248E-8,1,4,14.0008964538574,5.00451852586218,32.6699987053871,0.175220919456035,0.0267266681586916,1,8.69757144825907E-8,,,,,,,,,,,,,,,,,,,,,300.313232421875,300.331146240234,969.585144042969,969.585144042969,53.501299698573,5.88345202916203,4.59453105926514,56,1,0,0,1,0.327835083007812,34.2131004333496,1,1,3,300.331146240234,0,300.322189331055,,,,,,,,,,,,,,,,,,,,,,,,,,,,,,,,,
,3881453117.69083,300.435119628906,1549.63940429687,1.65914637134625E-4,3.65712750302553E-8,1,4,14.0008964538574,5.00451424293714,32.6699987053871,0.206402973157731,0.0314486452530399,1,7.55366240346419E-8,,,,,,,,,,,,,,,,,,,,,300.429534912109,300.440704345703,1549.63940429687,1549.63940429687,53.496219113198,5.88441407581312,4.58738231658936,56,1,0,0,1,0.329742431640625,34.2131004333496,1,1,3,300.429534912109,0,300.435119628906,,,,,,,,,,,,,,,,,,,,,,,,,,,,,,,,,
,3881453157.48682,300.291976928711,2129.60546875,1.75934611541232E-4,4.13646818986239E-8,1,4,14.0008964538574,5.00461527028195,32.6699987053871,0.21887211548937,0.0333633065693359,1,9.17227005249861E-8,,,,,,,,,,,,,,,,,,,,,300.283264160156,300.300689697266,2129.60546875,2129.60546875,53.3770207640153,5.88434769098991,4.5931453704834,56,1,0,0,1,0.3302001953125,34.2131004333496,1,1,3,300.283264160156,0,300.291976928711,,,,,,,,,,,,,,,,,,,,,,,,,,,,,,,,,
,3881453195.83089,300.169296264648,2709.68481445313,1.78170529424578E-4,4.00442141664076E-8,1,4,14.0008964538574,5.00452370119258,32.6699987053871,0.221648588744584,0.0337828754433396,1,9.00155308153445E-8,,,,,,,,,,,,,,,,,,,,,300.168518066406,300.170074462891,2709.68481445313,2709.68481445313,53.386400306246,5.88445299454217,4.58831310272217,56,1,0,0,1,0.330123901367188,33.7243423461914,1,1,3,300.170074462891,0,300.169296264648,,,,,,,,,,,,,,,,,,,,,,,,,,,,,,,,,
,3881453252.63984,300.238021850586,3499.54736328125,1.74843465753181E-4,3.80043856661321E-8,1,4,14.0008964538574,5.00462073154466,32.6699987053871,0.217515880127409,0.0331506664032725,1,8.65148086640527E-8,,,,,,,,,,,,,,,,,,,,,300.237762451172,300.23828125,3499.54736328125,3499.54736328125,53.4102399760826,5.88378284095641,4.59624910354614,56,1,0,0,1,0.329360961914063,33.7243423461914,1,1,3,300.237762451172,0,300.238021850586,,,,,,,,,,,,,,,,,,,,,,,,,,,,,,,,,
,3881453293.40075,300.188659667969,4499.69677734375,1.65260199170285E-4,3.02639089709599E-8,1,4,14.0008964538574,5.00445714677646,32.6699987053871,0.205578301643855,0.0313718277153213,1,1.13603126056687E-7,,,,,,,,,,,,,,,,,,,,,300.184936523438,300.1923828125,4499.69677734375,4499.69677734375,53.4000788053326,5.88446155376523,4.59584856033325,56,1,0,0,1,0.3302001953125,33.7243423461914,1,1,3,300.192535400391,0,300.188659667969,,,,,,,,,,,,,,,,,,,,,,,,,,,,,,,,,
,3881453336.12714,300.163818359375,5499.75830078125,1.52820049537936E-4,3.37890294527898E-8,1,4,14.0008964538574,5.00449427852954,32.6699987053871,0.19010660946213,0.0290008625699662,1,9.72418200673384E-8,,,,,,,,,,,,,,,,,,,,,300.143432617188,300.184204101562,5499.75830078125,5499.75830078125,53.5904053497653,5.88443283122382,4.59725093841553,56,1,0,0,1,0.327682495117188,33.7243423461914,1,1,3,300.184204101562,0,300.163818359375,,,,,,,,,,,,,,,,,,,,,,,,,,,,,,,,,
,3881453376.36767,300.140075683594,6499.630859375,1.39068883631242E-4,2.89464358556546E-8,1,4,14.0008964538574,5.00454151861599,32.6699987053871,0.173006447381933,0.0263661790295227,1,6.80315749123297E-8,,,,,,,,,,,,,,,,,,,,,300.131408691406,300.148742675781,6499.630859375,6499.630859375,53.4379877885153,5.88456848722361,4.58838415145874,56,1,0,0,1,0.33050537109375,33.7243423461914,1,1,3,300.131408691406,0,300.140075683594,,,,,,,,,,,,,,,,,,,,,,,,,,,,,,,,,
,3881453417.38287,300.080932617188,7499.74267578125,1.242367663733E-4,3.58816389766341E-8,1,4,14.0008964538574,5.00448704320754,32.6699987053871,0.154552815203366,0.0235512745507515,1,5.87557708591315E-8,,,,,,,,,,,,,,,,,,,,,300.070007324219,300.091857910156,7499.74267578125,7499.74267578125,53.526702625448,5.88474733439919,4.59456443786621,56,1,0,0,1,0.330047607421875,33.7243423461914,1,1,3,300.091857910156,0,300.080932617188,,,,,,,,,,,,,,,,,,,,,,,,,,,,,,,,,
,3881453457.04362,300.207412719727,8499.615234375,1.09050605959591E-4,3.70359318333614E-8,1,4,14.0008964538574,5.00459046634929,32.6699987053871,0.135661971893923,0.0206921727983554,1,6.69303476401983E-8,,,,,,,,,,,,,,,,,,,,,300.199859619141,300.214965820313,8499.615234375,8499.615234375,53.4649539724287,5.88425484892552,4.59305191040039,56,1,0,0,1,0.3289794921875,34.2131004333496,1,1,3,300.214965820313,0,300.207412719727,,,,,,,,,,,,,,,,,,,,,,,,,,,,,,,,,
,3881453496.75809,300.330963134766,9499.7646484375,9.35158094896248E-5,3.54162654630776E-8,1,4,14.0008964538574,5.00454105103193,32.6699987053871,0.116334042446039,0.0177482167767246,1,6.06036960923575E-8,,,,,,,,,,,,,,,,,,,,,300.329620361328,300.332305908203,9499.7646484375,9499.7646484375,53.3891360060633,5.88430355156665,4.59445333480835,54,1,68,0,0,0.330429077148438,33.7243423461914,1,1,3,300.329620361328,0,300.330963134766,,,,,,,,,,,,,,,,,,,,,,,,,,,,,,,,,
,3881453548.35445,300.42610168457,10499.662109375,7.77642195111077E-5,3.0241830742096E-8,1,4,14.0008964538574,5.00459787389083,32.6699987053871,0.0967478858159336,0.0147106050193148,1,1.15121377006518E-8,,,,,,,,,,,,,,,,,,,,,300.424133300781,300.428070068359,10499.662109375,10499.662109375,53.2914324411595,5.8845452072835,4.58924579620361,56,1,0,0,1,0.330657958984375,33.7243423461914,1,1,3,300.424133300781,0,300.42610168457,,,,,,,,,,,,,,,,,,,,,,,,,,,,,,,,,
,3881453603.04044,300.465835571289,11500.1513671875,6.22384777698521E-5,4.17139395858314E-8,1,4,14.0008964538574,5.00442206454676,32.6699987053871,0.0774335298948671,0.0117380942767065,1,-1.88697357173934E-8,,,,,,,,,,,,,,,,,,,,,300.456268310547,300.475402832031,11500.1513671875,11500.1513671875,53.3242608389672,5.88477118887943,4.59487199783325,56,1,0,0,1,0.330963134765625,33.7243423461914,1,1,3,300.456268310547,0,300.465835571289,,,,,,,,,,,,,,,,,,,,,,,,,,,,,,,,,
,3881453655.55017,300.381500244141,12500.0107421875,4.58797303951648E-5,3.44959383190296E-8,1,4,14.0008964538574,5.00449242865307,32.6699987053871,0.057073204173242,0.00871120122334694,1,3.28501985196982E-8,,,,,,,,,,,,,,,,,,,,,300.373962402344,300.389038085937,12500.0107421875,12500.0107421875,53.4477581450057,5.88454683541831,4.58867788314819,56,1,0,0,1,0.331497192382812,34.2131004333496,1,1,3,300.389038085937,0,300.381500244141,,,,,,,,,,,,,,,,,,,,,,,,,,,,,,,,,
,3881453695.35599,300.340927124023,13499.8203125,2.98177141498744E-5,3.50949704671528E-8,1,4,14.0008964538574,5.00451263696675,32.6699987053871,0.0370954696381952,0.00564315865751607,1,6.58127338355434E-9,,,,,,,,,,,,,,,,,,,,,300.324768066406,300.357086181641,13499.8203125,13499.8203125,53.4387694170345,5.88482140750441,4.58870458602905,56,1,0,0,1,0.3302001953125,33.7243423461914,1,1,3,300.357086181641,0,300.340927124023,,,,,,,,,,,,,,,,,,,,,,,,,,,,,,,,,
,3881453734.83242,300.338638305664,14499.5673828125,1.37661130372198E-5,2.95160529244514E-8,1,4,14.0008964538574,5.00458946803523,32.6699987053871,0.0171260438786482,0.00260799482821858,1,5.15220551420471E-9,,,,,,,,,,,,,,,,,,,,,300.323394775391,300.353881835937,14499.5673828125,14499.5673828125,53.4102399760826,5.88409069917091,4.58874082565308,56,1,0,0,1,0.330352783203125,33.7243423461914,1,1,3,300.355224609375,0,300.338638305664,,,,,,,,,,,,,,,,,,,,,,,,,,,,,,,,,
,3881453797.4581,300.213882446289,19999.75390625,-7.59020981894963E-5,3.68116668820815E-8,1,4,14.0008964538574,5.00447498201662,32.6699987053871,-0.0944224288108013,-0.0143941623885301,1,-4.04194847432232E-8,,,,,,,,,,,,,,,,,,,,,300.212799072266,300.214965820313,19999.75390625,19999.75390625,53.3449739947268,5.88484526206465,4.59607696533203,56,1,0,0,1,0.329360961914063,33.7243423461914,1,1,3,300.212799072266,0,300.213882446289,,,,,,,,,,,,,,,,,,,,,,,,,,,,,,,,,
,3881453881.63327,300.089279174805,30000.103515625,-2.4063688504687E-4,5.80753362466069E-8,1,4,14.0008964538574,5.00447496633079,32.6699987053871,-0.299333772933271,-0.0457610849018214,1,-2.29764176383613E-7,,,,,,,,,,,,,,,,,,,,,300.065338134766,300.113220214844,30000.103515625,30000.103515625,53.4919201563422,5.88420453496703,4.59084129333496,56,1,0,0,1,0.32958984375,33.7243423461914,1,1,3,300.113220214844,0,300.089279174805,,,,,,,,,,,,,,,,,,,,,,,,,,,,,,,,,
,3881453966.62545,300.253997802734,40000.390625,-4.05832155285697E-4,9.97733587707498E-8,1,4,14.0008964538574,5.00447176733817,32.6699987053871,-0.504798210022254,-0.0773423149105776,1,-5.21475788397879E-7,,,,,,,,,,,,,,,,,,,,,300.236022949219,300.27197265625,40000.390625,40000.390625,53.3629514506691,5.88544658281206,4.59036922454834,55,1,68,0,0,0.33111572265625,33.7243423461914,1,1,3,300.27197265625,0,300.253997802734,,,,,,,,,,,,,,,,,,,,,,,,,,,,,,,,,
,3881454053.39291,300.13444519043,50000.359375,-5.7091186573778E-4,2.04512047018996E-7,1,4,14.0008964538574,5.00450640148103,32.6699987053871,-0.710115828426255,-0.108969892452296,1,-8.6711404272593E-7,,,,,,,,,,,,,,,,,,,,,300.112426757812,300.156463623047,50000.359375,50000.359375,53.2488336868614,5.88545990375568,4.5928897857666,56,1,0,0,1,0.330734252929687,33.7243423461914,1,1,3,300.156463623047,0,300.13444519043,,,,,,,,,,,,,,,,,,,,,,,,,,,,,,,,,
,3881454140.23164,300.064834594727,60000.421875,-7.36126553316106E-4,2.55760315007709E-7,1,4,14.0008964538574,5.00455454444187,32.6699987053871,-0.915642041985501,-0.140405319482417,1,-1.03688512323585E-6,,,,,,,,,,,,,,,,,,,,,300.061645507812,300.068023681641,60000.421875,60000.421875,53.1077497391402,5.88511015905573,4.58759021759033,56,1,0,0,1,0.330734252929687,33.7243423461914,1,1,3,300.068389892578,0,300.064834594727,,,,,,,,,,,,,,,,,,,,,,,,,,,,,,,,,
,3881454226.9323,300.159530639648,70000.46875,-9.00610367514011E-4,3.54852606233593E-7,1,4,14.0008964538574,5.00438819088477,32.6699987053871,-1.12015474130234,-0.171973499796814,1,-1.43198356541593E-6,,,,,,,,,,,,,,,,,,,,,300.137908935547,300.18115234375,70000.46875,70000.46875,53.2277297168422,5.88612011938521,4.59560489654541,56,1,0,0,1,0.328369140625,34.7018585205078,1,1,3,300.18115234375,0,300.159530639648,,,,,,,,,,,,,,,,,,,,,,,,,,,,,,,,,
,3881454230.90318,300.196365356445,70000.46875,-9.00748881965446E-4,3.01878340682019E-7,1,4,14.0008964538574,5.00441477258784,32.6699987053871,-1.12031643141513,-0.172125736200696,1,-1.53228482370955E-6,,,,,,,,,,,,,,,,,,,,,300.18115234375,300.211578369141,70000.46875,70000.46875,53.1491760506595,5.88571828604915,4.59150648117065,56,2,0,0,1,0.32928466796875,34.2131004333496,1,1,3,300.211578369141,0,300.196365356445,,,,,,,,,,,,,,,,,,,,,,,,,,,,,,,,,