File: SQUID/22172_LCOL/22172_LCOL_MH_10K_FC_p0d5T_2.csv
Comment,Time Stamp (sec),Temperature (K),Magnetic Field (Oe),Moment (emu),M. Std. Err. (emu),Transport Action,Averaging Time (sec),Frequency (Hz),Peak Amplitude (mm),Center Position (mm),Lockin Signal' (V),Lockin Signal (V),Range,M. Quad. Signal (emu),AC Moment (emu),AC M. Std Err. (emu),AC Phase (deg),AC Phase Std. Err. (deg),AC Susceptibility (emu/Oe),AC Suscept. Std Err. (emu/Oe),AC X' (emu/Oe),AC X' Std Err. (emu/Oe),AC X'' (emu/Oe),AC X'' Std Err. (emu/Oe),AC Drive (Oe),AC Frequency (Hz),AC Averaging Time (sec),AC Cycles,AC Range,AC Measure Type,AC Signal' (V),AC Signal'' (V),AC Trim Coil Ratio,AC Trim Coil Phase,Min. Temperature (K),Max. Temperature (K),Min. Field (Oe),Max. Field (Oe),Mass (grams),Motor Lag (deg),Pressure (Torr),Measure Count,Measurement Number,SQUID Status (code),Motor Status (code),Measure Status (code),Motor Current (amps),Motor Temp. (C),Temp. Status (code),Field Status (code),Chamber Status (code),Chamber Temp (K),Redirection State,Average Temp (K),Rotation Angle (deg),Rotator state,DC Moment Fixed Ctr (emu),DC Moment Err Fixed Ctr (emu),DC Moment Free Ctr (emu),DC Moment Err Free Ctr (emu),DC Fixed Fit,DC Free Fit,DC Calculated Center (mm),DC Calculated Center Err (mm),DC Scan Length (mm),DC Scan Time (s),DC Number of Points,DC Squid Drift,DC Min V (V),DC Max V (V),DC Scans per Measure,Map 01,Map 02,Map 03,Map 04,Map 05,Map 06,Map 07,Map 08,Map 09,Map 10,Map 11,Map 12,Map 13,Map 14,Map 15,Map 16
,3881436153.9071,10.000048160553,70000.328125,-7.37941831668588E-4,3.51931293470406E-5,1,4,14.0008964538574,4.97421407764271,32.4000008404255,-0.919003213763607,-0.0810008075815706,100,4.64292693334002E-5,,,,,,,,,,,,,,,,,,,,,10.0000219345093,10.0000743865967,70000.328125,70000.328125,53.9351035267461,5.88241960509606,3.09747934341431,54,1,68,0,0,0.326309204101562,32.7468223571777,1,1,3,10.0000743865967,0,10.000048160553,,,,,,,,,,,,,,,,,,,,,,,,,,,,,,,,,
,3881436253.73913,9.99981307983398,60000.18359375,-5.76746845409942E-4,9.05313544856179E-5,1,4,14.0008964538574,4.98448821765177,32.4000008404255,-0.744911415752033,0.0982622450342441,100,1.67033871293617E-4,,,,,,,,,,,,,,,,,,,,,9.99975681304932,9.99986934661865,60000.18359375,60000.18359375,53.9714492528903,5.88257878714764,3.13193488121033,48,1,68,0,0,0.331878662109375,32.7468223571777,1,1,3,9.99975681304932,0,9.99981307983398,,,,,,,,,,,,,,,,,,,,,,,,,,,,,,,,,
,3881436366.77591,9.99753761291504,50000.2578125,-3.90347901828704E-4,5.91874572197768E-4,1,4,14.0008964538574,4.98439603397626,32.4000008404255,-0.440559884951395,-0.352131415978757,100,-2.25345024809121E-4,,,,,,,,,,,,,,,,,,,,,9.99665832519531,9.99841690063477,50000.2578125,50000.2578125,53.7471218678711,5.88192066082888,3.13950657844543,49,1,68,0,0,0.3277587890625,33.2355842590332,1,1,3,9.99841690063477,0,9.99753761291504,,,,,,,,,,,,,,,,,,,,,,,,,,,,,,,,,
,3881436479.02259,9.99991035461426,40000.25,--,4.61491053771746E-4,1,4,14.0008964538574,4.98429803293621,32.4000008404255,-1.14024755821214,0.101779814780012,100,2.17270027241216E-4,,,,,,,,,,,,,,,,,,,,,9.99990940093994,9.99991130828857,40000.25,40000.25,53.5950951208807,5.88146915033317,3.12985277175903,47,1,68,0,0,0.32958984375,32.7468223571777,1,1,3,9.99990940093994,0,9.99991035461426,,,,,,,,,,,,,,,,,,,,,,,,,,,,,,,,,
,3881436590.22759,10.0000624656677,30000.140625,-1.54015080417728E-4,5.59213251405834E-5,1,4,14.0008964538574,4.98425779228197,32.4000008404255,-0.187651185215463,-0.0478753872483569,100,-1.53058470027729E-5,,,,,,,,,,,,,,,,,,,,,9.99998283386231,10.0001420974731,30000.140625,30000.140625,53.6763844868807,5.88083006693125,3.1285970211029,55,1,68,0,0,0.3240966796875,33.2355842590332,1,1,3,10.0001420974731,0,10.0000624656677,,,,,,,,,,,,,,,,,,,,,,,,,,,,,,,,,
,3881436688.63585,9.99985408782959,19999.728515625,3.05956934939314E-5,4.19079070200031E-5,1,4,14.0008964538574,4.98419875988878,32.4000008404255,0.0435857386332699,-0.0320217460698595,100,-3.05330695410383E-5,,,,,,,,,,,,,,,,,,,,,9.99972152709961,9.99998664855957,19999.728515625,19999.728515625,53.5524963665826,5.88114311436646,3.13062834739685,54,1,68,0,0,0.326690673828125,33.7243423461914,1,1,3,9.99998664855957,0,9.99985408782959,,,,,,,,,,,,,,,,,,,,,,,,,,,,,,,,,
,3881436777.26122,10.0000987052917,14499.8447265625,7.81978298706543E-5,1.99255035861904E-5,1,4,14.0008964538574,4.98412955522948,32.4000008404255,0.0926597047204592,0.0415069539968506,100,2.16756567830213E-5,,,,,,,,,,,,,,,,,,,,,10.0000648498535,10.00013256073,14499.8447265625,14499.8447265625,53.511460869323,5.88165832965724,3.13369512557983,55,1,68,0,0,0.326995849609375,33.7243423461914,1,1,3,10.0000648498535,0,10.0000987052917,,,,,,,,,,,,,,,,,,,,,,,,,,,,,,,,,
,3881436817.70016,10.0001091957092,13499.8828125,8.09132878403682E-5,4.43630674448644E-6,1,4,14.0008964538574,4.984176023223,32.4000008404255,0.100729324086616,0.0110151665463005,100,-3.38623531873003E-6,,,,,,,,,,,,,,,,,,,,,10.0000772476196,10.0001411437988,13499.8828125,13499.8828125,53.482931428371,5.88181545550159,3.13386583328247,56,1,0,0,1,0.327224731445313,33.7243423461914,1,1,3,10.0001411437988,0,10.0001091957092,,,,,,,,,,,,,,,,,,,,,,,,,,,,,,,,,
,3881436856.12394,10.0000109672546,12499.7587890625,9.3084261042734E-5,3.31203364603345E-5,1,4,14.0008964538574,4.98463417079677,32.4000008404255,0.108161471248693,0.0635922309993876,100,3.72606632067148E-5,,,,,,,,,,,,,,,,,,,,,9.99999237060547,10.0000295639038,12499.7587890625,12499.7587890625,53.3047201259864,5.88003663496083,3.12922525405884,54,1,68,0,0,0.327911376953125,33.7243423461914,1,1,3,10.0000295639038,0,10.0000109672546,,,,,,,,,,,,,,,,,,,,,,,,,,,,,,,,,
,3881436909.03679,9.99996614456177,11499.88671875,1.08871080482831E-4,5.06664249602024E-6,1,4,14.0008964538574,4.98419105055448,32.4000008404255,0.134352613734989,0.0226031879854851,100,1.73444819651444E-6,,,,,,,,,,,,,,,,,,,,,9.9999532699585,9.99997901916504,11499.88671875,11499.88671875,53.3672504075249,5.88119219418075,3.13572430610657,56,1,0,0,1,0.326461791992188,33.2355842590332,1,1,3,9.99997901916504,0,9.99996614456177,,,,,,,,,,,,,,,,,,,,,,,,,,,,,,,,,
,3881436952.45501,10.0000410079956,10499.5859375,9.61614928731048E-5,2.68734125014134E-5,1,4,14.0008964538574,4.98412312462713,32.4000008404255,0.124133627636366,-0.016030610688723,10,-2.75659104111529E-5,,,,,,,,,,,,,,,,,,,,,9.99997520446777,10.0001068115234,10499.5859375,10499.5859375,53.435252088698,5.88190358828984,3.13709139823914,55,1,68,0,0,0.3277587890625,33.7243423461914,1,1,3,10.0001068115234,0,10.0000410079956,,,,,,,,,,,,,,,,,,,,,,,,,,,,,,,,,
,3881437005.62685,10.0000801086426,9499.6259765625,1.34636136795631E-4,2.26475888979079E-6,1,4,14.0008964538574,4.98410049267929,32.4000008404255,0.166296802291237,0.0269444546885112,10,1.33068720542125E-6,,,,,,,,,,,,,,,,,,,,,10.0000734329224,10.0000867843628,9499.6259765625,9499.6259765625,53.4587009442749,5.88119679382483,3.13290786743164,56,1,0,0,1,0.327529907226562,33.7243423461914,1,1,3,10.0000867843628,0,10.0000801086426,,,,,,,,,,,,,,,,,,,,,,,,,,,,,,,,,
,3881437044.00897,10.0001101493835,8499.5390625,1.30901032693777E-4,2.15380870354038E-5,1,4,14.0008964538574,4.98408579919286,32.4000008404255,0.159148942972741,0.0428772860584809,10,1.47782602452451E-5,,,,,,,,,,,,,,,,,,,,,10.0000019073486,10.0002183914185,8499.5390625,8499.5390625,53.4813681713326,5.88180382811942,3.13915657997131,56,1,0,0,1,0.32745361328125,33.7243423461914,1,1,3,10.0002183914185,0,10.0001101493835,,,,,,,,,,,,,,,,,,,,,,,,,,,,,,,,,
,3881437084.66388,9.99999237060547,7499.6669921875,1.77663454531445E-4,1.94561416542319E-5,1,4,14.0008964538574,4.98406853915595,32.4000008404255,0.218776534898287,0.0399250840488348,10,5.28866622357423E-6,,,,,,,,,,,,,,,,,,,,,9.99994564056397,10.000039100647,7499.6669921875,7499.6669921875,53.4637815296499,5.88239186395852,3.13054013252258,56,1,0,0,1,0.326995849609375,33.7243423461914,1,1,3,9.99994564056397,0,9.99999237060547,,,,,,,,,,,,,,,,,,,,,,,,,,,,,,,,,
,3881437125.28524,9.99985313415527,6499.5927734375,1.76815161068945E-4,4.22078263534309E-6,1,4,14.0008964538574,4.98406217314385,32.4000008404255,0.219001118896281,0.0313764117742154,10,-1.4932249245902E-6,,,,,,,,,,,,,,,,,,,,,9.99983406066895,9.9998722076416,6499.5927734375,6499.5927734375,53.3922625201403,5.88226990383381,3.13174891471863,56,1,0,0,1,0.3253173828125,33.7243423461914,1,1,3,9.99983406066895,0,9.99985313415527,,,,,,,,,,,,,,,,,,,,,,,,,,,,,,,,,
,3881437166.59698,9.99993515014648,5499.63232421875,1.81970142247482E-4,4.57822476841704E-8,1,4,14.0008964538574,4.98408365619063,32.4000008404255,0.225106777504783,0.0341386604395935,10,-4.34102377776258E-8,,,,,,,,,,,,,,,,,,,,,9.99977397918701,10.000096321106,5499.63232421875,5499.63232421875,53.4243092894287,5.88220657436616,3.14049983024597,56,1,0,0,1,0.328140258789063,33.7243423461914,1,1,3,9.99977397918701,0,9.99993515014648,,,,,,,,,,,,,,,,,,,,,,,,,,,,,,,,,
,3881437222.86078,9.99986553192139,4499.646484375,1.9075414986236E-4,2.28851820311045E-8,1,4,14.0008964538574,4.98404384016085,32.4099995195866,0.235978041366123,0.0357360097481663,10,-8.60723323088548E-8,,,,,,,,,,,,,,,,,,,,,9.9998083114624,9.99992275238037,4499.646484375,4499.646484375,53.4970007417172,5.88140095731148,3.13619995117188,56,1,0,0,1,0.324783325195313,33.7243423461914,1,1,3,9.9998083114624,0,9.99986553192139,,,,,,,,,,,,,,,,,,,,,,,,,,,,,,,,,
,3881437282.58854,10.0000143051147,3499.68579101562,1.96443753952819E-4,4.99208596919838E-8,1,4,14.0008964538574,4.98407942126618,32.4000008404255,0.242965669853191,0.0371531489258201,1,1.95009822557742E-7,,,,,,,,,,,,,,,,,,,,,9.99994659423828,10.0000820159912,3499.68579101562,3499.68579101562,53.384446234948,5.88184100094493,3.13449883460999,56,1,0,0,1,0.329208374023438,33.7243423461914,1,1,3,10.0000820159912,0,10.0000143051147,,,,,,,,,,,,,,,,,,,,,,,,,,,,,,,,,
,3881437337.05887,10.000020980835,2709.53369140625,1.96901884679784E-4,4.6810543626609E-8,1,4,14.0008964538574,4.98402352589964,32.4000008404255,0.243528558263816,0.0372385852220313,1,1.94960620088384E-7,,,,,,,,,,,,,,,,,,,,,9.99998474121094,10.000057220459,2709.53369140625,2709.53369140625,53.3879635632845,5.88180869457527,3.14129757881165,56,1,0,0,1,0.327301025390625,34.2131004333496,1,1,3,10.000057220459,0,10.000020980835,,,,,,,,,,,,,,,,,,,,,,,,,,,,,,,,,
,3881437375.85682,10.0000205039978,2129.61791992187,1.93082449911643E-4,5.82679835132603E-8,1,4,14.0008964538574,4.98401711978665,32.4000008404255,0.238807510383902,0.0364946794522756,1,1.73798925178207E-7,,,,,,,,,,,,,,,,,,,,,9.99994564056397,10.0000953674316,2129.61791992187,2129.61791992187,53.3113639683999,5.88205668502584,3.13959503173828,56,1,0,0,1,0.326385498046875,33.7243423461914,1,1,3,9.99994564056397,0,10.0000205039978,,,,,,,,,,,,,,,,,,,,,,,,,,,,,,,,,
,3881437414.87046,9.9998607635498,1549.74011230469,1.82382279563004E-4,7.41122521582865E-8,1,4,14.0008964538574,4.98403565545382,32.4000008404255,0.225572048618645,0.0344888314119393,1,1.77441916388127E-7,,,,,,,,,,,,,,,,,,,,,9.99984645843506,9.99987506866455,1549.74011230469,1549.74011230469,53.4536203588999,5.88219936364293,3.14207601547241,56,1,0,0,1,0.328369140625,33.7243423461914,1,1,3,9.99987506866455,0,9.9998607635498,,,,,,,,,,,,,,,,,,,,,,,,,,,,,,,,,
,3881437454.12414,10.0000653266907,969.534790039063,1.585830296566E-4,8.66139126759547E-8,1,4,14.0008964538574,4.98420531008224,32.4000008404255,0.196134403681184,0.030068022454933,1,2.17535924766023E-7,,,,,,,,,,,,,,,,,,,,,10.0000324249268,10.0000982284546,969.534790039063,969.534790039063,53.5282658824864,5.88224847436636,3.13379287719727,56,1,0,0,1,0.326461791992188,32.2580642700195,1,1,3,10.0000982284546,0,10.0000653266907,,,,,,,,,,,,,,,,,,,,,,,,,,,,,,,,,
,3881437492.65119,9.99978303909302,389.845672607422,1.08423987920727E-4,1.42249477808842E-7,1,4,14.0008964538574,4.98405963747237,32.4000008404255,0.134085035773355,0.0206062536377282,1,1.8870088561279E-7,,,,,,,,,,,,,,,,,,,,,9.99959087371826,9.99997520446777,389.845672607422,389.845672607422,53.3621698221499,5.88134505328478,3.1346492767334,56,1,0,0,1,0.326156616210937,33.7243423461914,1,1,3,9.99997520446777,0,9.99978303909302,,,,,,,,,,,,,,,,,,,,,,,,,,,,,,,,,
,3881437530.838,9.99991750717163,-190.233703613281,-1.51499437680978E-5,1.70598006646587E-8,1,4,14.0008964538574,4.98404502141541,32.4000008404255,-0.0187372079388683,-0.00286771183796891,1,-1.70204776205018E-8,,,,,,,,,,,,,,,,,,,,,9.99987983703613,9.99995517730713,-190.233703613281,-190.233703613281,53.3903084488422,5.88190722737457,3.14329075813293,56,1,0,0,1,0.32684326171875,33.7243423461914,1,1,3,9.99995517730713,0,9.99991750717163,,,,,,,,,,,,,,,,,,,,,,,,,,,,,,,,,
,3881437567.66446,9.99996566772461,-769.784362792969,-1.11159034844326E-4,5.06455284694628E-8,1,4,14.0008964538574,4.98403335260227,32.4000008404255,-0.137497804796827,-0.0209190062906771,1,-2.62053915313915E-8,,,,,,,,,,,,,,,,,,,,,9.99992370605469,10.0000076293945,-769.784362792969,-769.784362792969,53.3879635632845,5.88194240074774,3.14423274993897,56,1,0,0,1,0.327377319335937,33.7243423461914,1,1,3,9.99992370605469,0,9.99996566772461,,,,,,,,,,,,,,,,,,,,,,,,,,,,,,,,,
,3881437605.22437,9.99964618682861,-1349.80078125,-1.55329062618927E-4,4.41201184678063E-8,1,4,14.0008964538574,4.98397873509026,32.4000008404255,-0.19212160905611,-0.0292915627838823,1,-8.56520633573389E-8,,,,,,,,,,,,,,,,,,,,,9.99956512451172,9.99972724914551,-1349.80078125,-1349.80078125,53.5052078411691,5.88130377964634,3.1417453289032,56,1,0,0,1,0.324783325195313,33.7243423461914,1,1,3,9.99956512451172,0,9.99964618682861,,,,,,,,,,,,,,,,,,,,,,,,,,,,,,,,,
,3881437643.6803,9.99971437454224,-1929.74169921875,-1.7756270209347E-4,6.26363225831205E-8,1,4,14.0008964538574,4.98398793940814,32.4000008404255,-0.219615732224212,-0.0335274149839992,1,-1.32675879121023E-7,,,,,,,,,,,,,,,,,,,,,9.99966239929199,9.99976634979248,-1929.74169921875,-1929.74169921875,53.4895752707845,5.88200996181745,3.13951206207275,56,1,0,0,1,0.3265380859375,33.7243423461914,1,1,3,9.99976634979248,0,9.99971437454224,,,,,,,,,,,,,,,,,,,,,,,,,,,,,,,,,
,3881437681.79513,9.9998197555542,-2509.98486328125,-1.87466154917932E-4,6.63965008121412E-8,1,4,14.0008964538574,4.98402687029013,32.4000008404255,-0.231866200826748,-0.0354044082440532,1,-1.45438777669699E-7,,,,,,,,,,,,,,,,,,,,,9.99973487854004,9.99990463256836,-2509.98486328125,-2509.98486328125,53.3527902799191,5.88148649246113,3.13989067077637,56,1,0,0,1,0.330123901367188,33.7243423461914,1,1,3,9.99973487854004,0,9.9998197555542,,,,,,,,,,,,,,,,,,,,,,,,,,,,,,,,,
,3881437735.91042,9.99988460540771,-2999.89453125,-1.9090778653962E-4,6.26489758731452E-8,1,4,14.0008964538574,4.98406996644665,32.4000008404255,-0.236121662279749,-0.0360822172678107,1,-1.70253754428428E-7,,,,,,,,,,,,,,,,,,,,,9.99985980987549,9.99990940093994,-2999.89453125,-2999.89453125,53.5231852971114,5.88249763082099,3.1372344493866,56,1,0,0,1,0.325546264648438,33.7243423461914,1,1,3,9.99985980987549,0,9.99988460540771,,,,,,,,,,,,,,,,,,,,,,,,,,,,,,,,,
,3881437775.71311,9.99980592727661,-3999.93041992188,-1.89926619732344E-4,6.7638607350729E-8,1,4,14.0008964538574,4.98401051615159,32.4000008404255,-0.234900464758665,-0.0359206870657064,1,-1.89196610789764E-7,,,,,,,,,,,,,,,,,,,,,9.99967479705811,9.99993705749512,-3999.93041992188,-3999.93041992188,53.455574430198,5.88222913808162,3.1353611946106,56,1,0,0,1,0.327987670898438,33.7243423461914,1,1,3,9.99993705749512,0,9.99980592727661,,,,,,,,,,,,,,,,,,,,,,,,,,,,,,,,,
,3881437829.11384,9.99989604949951,-4999.853515625,-1.83384943261948E-4,5.73678919228736E-8,1,4,14.0008964538574,4.98398512797926,32.4099995195866,-0.226805866769014,-0.0346980842068444,1,-1.94699450026325E-7,,,,,,,,,,,,,,,,,,,,,9.9998950958252,9.99989700317383,-4999.853515625,-4999.853515625,53.3219159534095,5.88196369501759,3.13284826278687,56,1,0,0,1,0.328826904296875,33.2355842590332,1,1,3,9.99989700317383,0,9.99989604949951,,,,,,,,,,,,,,,,,,,,,,,,,,,,,,,,,
,3881437868.82105,10.0000424385071,-5999.82666015625,-1.7414484631973E-4,5.76640588722041E-8,1,4,14.0008964538574,4.98396868990637,32.4000008404255,-0.215387136464857,-0.03288257195119,1,-1.30684030154877E-7,,,,,,,,,,,,,,,,,,,,,10.0000190734863,10.0000658035278,-5999.82666015625,-5999.82666015625,53.5399903102749,5.88226903303775,3.13621783256531,53,1,100,0,0,0.324859619140625,33.2355842590332,1,1,3,10.0000190734863,0,10.0000424385071,,,,,,,,,,,,,,,,,,,,,,,,,,,,,,,,,
,3881437922.8672,9.99982404708862,-6999.74951171875,-1.63771970052295E-4,5.004764974304E-8,1,4,14.0008964538574,4.98398138529996,32.4099995195866,-0.202548497270154,-0.0309892472152049,1,-1.75612056492078E-7,,,,,,,,,,,,,,,,,,,,,9.99974632263184,9.99990177154541,-6999.74951171875,-6999.74951171875,53.4450224451884,5.8825088679175,3.13994646072388,52,1,32,0,0,0.328903198242188,33.7243423461914,1,1,3,9.99990177154541,0,9.99982404708862,,,,,,,,,,,,,,,,,,,,,,,,,,,,,,,,,
,3881437984.51985,9.99967193603516,-8000.1884765625,-1.52335081709926E-4,1.02910658188807E-7,1,4,14.0008964538574,4.9839521646902,32.4099995195866,-0.188431961038073,-0.0286285167489315,10,-4.58578685661425E-9,,,,,,,,,,,,,,,,,,,,,9.99961090087891,9.99973297119141,-8000.1884765625,-8000.1884765625,53.411803233121,5.88144132658668,3.12808442115784,56,1,0,0,1,0.3253173828125,33.7243423461914,1,1,3,9.99961090087891,0,9.99967193603516,,,,,,,,,,,,,,,,,,,,,,,,,,,,,,,,,
,3881438051.26699,9.99979734420776,-8999.607421875,-1.43415376128906E-4,7.52249643412622E-6,1,4,14.0008964538574,4.98391058285835,32.4000008404255,-0.175871224460209,-0.0369938606714081,10,-8.12264419707229E-6,,,,,,,,,,,,,,,,,,,,,9.99977493286133,9.9998197555542,-8999.607421875,-8999.607421875,53.4055502049672,5.88166898197593,3.12749314308167,54,1,68,0,0,0.327682495117188,33.7243423461914,1,1,3,9.99977493286133,0,9.99979734420776,,,,,,,,,,,,,,,,,,,,,,,,,,,,,,,,,
,3881438117.47238,10.000159740448,-9999.7578125,-1.29827902528452E-4,7.86635726667775E-6,1,4,14.0008964538574,4.98394316733575,32.4099995195866,-0.159006603909563,-0.0348301273765003,10,-8.43706460444502E-6,,,,,,,,,,,,,,,,,,,,,10.0001211166382,10.0001983642578,-9999.7578125,-9999.7578125,53.480977357073,5.88198859249046,3.11315226554871,56,1,0,0,1,0.3271484375,33.7243423461914,1,1,3,10.0001983642578,0,10.000159740448,,,,,,,,,,,,,,,,,,,,,,,,,,,,,,,,,
,3881438157.13358,10.0001645088196,-10999.5419921875,-1.424737743333E-4,2.76924956412148E-5,1,4,14.0008964538574,4.98388754026938,32.4000008404255,-0.183797850191073,0.0230417829279231,10,4.02697380103542E-5,,,,,,,,,,,,,,,,,,,,,9.99999618530273,10.0003328323364,-10999.5419921875,-10999.5419921875,53.4950466704191,5.88273506328533,3.11563849449158,55,1,68,0,0,0.324249267578125,33.7243423461914,1,1,3,10.0003328323364,0,10.0001645088196,,,,,,,,,,,,,,,,,,,,,,,,,,,,,,,,,
,3881438196.9079,10.0000758171082,-11999.841796875,-1.17891324606324E-4,3.74672883776519E-5,1,4,14.0008964538574,4.98393674940108,32.4000008404255,-0.141965857547444,-0.0475670451026824,10,-2.05472489523357E-5,,,,,,,,,,,,,,,,,,,,,10.0000371932983,10.000114440918,-11999.841796875,-11999.841796875,53.3133180396979,5.88239572500642,3.11275339126587,55,1,68,0,0,0.327377319335937,33.7243423461914,1,1,3,10.0000371932983,0,10.0000758171082,,,,,,,,,,,,,,,,,,,,,,,,,,,,,,,,,
,3881438236.77621,9.99995374679565,-12999.9541015625,-8.76337215487021E-5,1.30449864184344E-5,1,4,14.0008964538574,4.98392233928964,32.4000008404255,-0.108701991933983,-0.0144693091989473,10,1.6139675533502E-6,,,,,,,,,,,,,,,,,,,,,9.99988555908203,10.0000219345093,-12999.9541015625,-12999.9541015625,53.4442408166691,5.88169707870059,3.10834932327271,54,1,68,0,0,0.3265380859375,36.1681327819824,1,1,3,9.99988555908203,0,9.99995374679565,,,,,,,,,,,,,,,,,,,,,,,,,,,,,,,,,
,3881438277.66238,10.0002069473267,-13999.775390625,-8.81472537691666E-5,3.92931787843289E-5,1,4,14.0008964538574,4.98391922454715,32.4000008404255,-0.122172257661274,0.0699318592602094,10,6.9925181890444E-5,,,,,,,,,,,,,,,,,,,,,10.0001087188721,10.0003051757813,-13999.775390625,-13999.775390625,53.3348128239768,5.88274024171525,3.10982632637024,53,1,68,0,0,0.329437255859375,33.7243423461914,1,1,3,10.0003051757813,0,10.0002069473267,,,,,,,,,,,,,,,,,,,,,,,,,,,,,,,,,
,3881438355.95456,10.0000705718994,-14999.5732421875,-7.18172662834377E-5,6.14527402923775E-5,1,4,14.0008964538574,4.9838645274775,32.4099995195866,-0.105918198278537,0.0989827115267452,100,9.09317476600765E-5,,,,,,,,,,,,,,,,,,,,,10.0000448226929,10.000096321106,-14999.5732421875,-14999.5732421875,53.4184470755345,5.88241376041447,3.11186218261719,54,1,68,0,0,0.32623291015625,33.7243423461914,1,1,3,10.0000448226929,0,10.0000705718994,,,,,,,,,,,,,,,,,,,,,,,,,,,,,,,,,
,3881438458.41282,9.99996995925903,-24999.60546875,1.3175048512297E-4,7.5292106540831E-5,1,4,14.0008964538574,4.98381280661796,32.4000008404255,0.159249091268748,0.0492108456738164,1000,1.97723444584349E-5,,,,,,,,,,,,,,,,,,,,,9.99996948242188,9.99997043609619,-24999.60546875,-24999.60546875,53.4415051168518,5.88348903197947,3.10554671287537,56,1,0,0,1,0.3277587890625,33.7243423461914,1,1,3,9.99997043609619,0,9.99996995925903,,,,,,,,,,,,,,,,,,,,,,,,,,,,,,,,,
,3881438571.26681,10.0001521110535,-34999.69140625,--,5.76044456596983E-4,1,4,14.0008964538574,4.98392359515674,32.4000008404255,-0.297111001270506,0.102295564458128,100,1.16497285081548E-4,,,,,,,,,,,,,,,,,,,,,10.0000295639038,10.0002746582031,-34999.69140625,-34999.69140625,53.8096521494095,5.88269304485802,3.10689926147461,50,1,68,0,0,0.32684326171875,33.7243423461914,1,1,3,10.0002746582031,0,10.0001521110535,,,,,,,,,,,,,,,,,,,,,,,,,,,,,,,,,
,3881438684.97661,9.99991750717163,-44999.625,2.7425598554061E-4,9.1170430526581E-5,1,4,14.0008964538574,4.98392572543285,32.4099995195866,0.362051974306759,-0.0986348397912401,100,-1.21399468837976E-4,,,,,,,,,,,,,,,,,,,,,9.99985980987549,9.99997520446777,-44999.625,-44999.625,53.7307076689672,5.88405375619604,3.09596514701843,48,1,68,0,0,0.32745361328125,33.7243423461914,1,1,3,9.99997520446777,0,9.99991750717163,,,,,,,,,,,,,,,,,,,,,,,,,,,,,,,,,
,3881438799.17517,10.0000295639038,-54999.70703125,--,4.85952214726092E-4,1,4,14.0008964538574,4.98386732466495,32.4000008404255,-0.0637751864293702,0.295946710661801,100,2.41517598452227E-4,,,,,,,,,,,,,,,,,,,,,9.99999618530273,10.0000629425049,-54999.70703125,-54999.70703125,53.9640237819576,5.88416979116717,3.09480404853821,52,1,68,0,0,0.326309204101562,33.7243423461914,1,1,3,10.0000629425049,0,10.0000295639038,,,,,,,,,,,,,,,,,,,,,,,,,,,,,,,,,
,3881438913.33455,9.99996757507324,-64999.62890625,6.55574768729889E-4,1.03016396744298E-4,1,4,14.0008964538574,4.98385386421447,32.4000008404255,0.775743675715968,0.354614130035941,100,1.87107810307685E-4,,,,,,,,,,,,,,,,,,,,,9.9999303817749,10.0000047683716,-64999.62890625,-64999.62890625,54.100808772823,5.88453981407401,3.09428453445435,54,1,68,0,0,0.3253173828125,33.7243423461914,1,1,3,9.9999303817749,0,9.99996757507324,,,,,,,,,,,,,,,,,,,,,,,,,,,,,,,,,
,3881439027.10712,9.99997901916504,-64999.78125,--,3.72526272462163E-4,1,4,14.0008964538574,4.98386417102422,32.4000008404255,0.319828833639148,0.441323927833487,100,3.10352165036792E-4,,,,,,,,,,,,,,,,,,,,,9.99996757507324,9.99999046325684,-64999.78125,-64999.78125,54.0355427914673,5.88451313560107,3.09659004211426,50,1,68,0,0,0.327529907226562,33.7243423461914,1,1,3,9.99996757507324,0,9.99997901916504,,,,,,,,,,,,,,,,,,,,,,,,,,,,,,,,,
,3881439142.00398,10.0000972747803,-54999.64453125,4.10580929072316E-4,7.80547858230908E-5,1,4,14.0008964538574,4.98377457319836,32.4000008404255,0.507365610180331,0.0803170690319988,100,2.56709508069237E-6,,,,,,,,,,,,,,,,,,,,,9.9999942779541,10.0002002716064,-54999.64453125,-54999.64453125,53.9073557143134,5.88435752881243,3.0997359752655,53,1,68,0,0,0.326766967773438,33.7243423461914,1,1,3,9.9999942779541,0,10.0000972747803,,,,,,,,,,,,,,,,,,,,,,,,,,,,,,,,,
,3881439255.97045,9.9998836517334,-44999.80078125,2.91722530899996E-4,8.28223037614064E-5,1,4,14.0008964538574,4.98383910730225,32.4000008404255,0.366055829625545,0.0204633900939288,100,-2.77687140132742E-5,,,,,,,,,,,,,,,,,,,,,9.99969005584717,10.0000772476196,-44999.80078125,-44999.80078125,53.7576738528807,5.88417704681435,3.09760808944702,51,1,68,0,0,0.3271484375,34.2131004333496,1,1,3,9.99969005584717,0,9.9998836517334,,,,,,,,,,,,,,,,,,,,,,,,,,,,,,,,,
,3881439369.92146,9.99997472763062,-34999.6796875,2.0787277035211E-4,6.58190685665429E-5,1,4,14.0008964538574,4.98390175565596,32.4000008404255,0.263790271092653,-0.0048073473236085,100,-3.54622293760264E-5,,,,,,,,,,,,,,,,,,,,,9.99981880187988,10.0001306533813,-34999.6796875,-34999.6796875,53.7135118415441,5.88266311676451,3.09383606910706,54,1,68,0,0,0.327606201171875,33.7243423461914,1,1,3,9.99981880187988,0,9.99997472763062,,,,,,,,,,,,,,,,,,,,,,,,,,,,,,,,,
,3881439482.50185,10.0000085830688,-24999.64453125,6.72952842022135E-5,4.77747888801332E-5,1,4,14.0008964538574,4.98389412300501,32.4000008404255,0.0831697481711704,0.0131092955547967,100,3.76026832029854E-7,,,,,,,,,,,,,,,,,,,,,9.99991130828857,10.0001058578491,-24999.64453125,-24999.64453125,53.4489305877845,5.88368339586467,3.09380865097046,56,1,0,0,1,0.327377319335937,33.7243423461914,1,1,3,10.0001058578491,0,10.0000085830688,,,,,,,,,,,,,,,,,,,,,,,,,,,,,,,,,
,3881439580.11218,10.0002427101135,-14999.8251953125,-4.75938032455355E-5,4.85616915022943E-5,1,4,14.0008964538574,4.98386053961427,32.4000008404255,-0.0570719562925488,-0.0207810264015911,100,-9.57100235467732E-6,,,,,,,,,,,,,,,,,,,,,10.0000581741333,10.0004272460938,-14999.8251953125,-14999.8251953125,53.4438500024095,5.88319896061913,3.08460354804993,55,1,68,0,0,0.324630737304687,33.7243423461914,1,1,3,10.0000581741333,0,10.0002427101135,,,,,,,,,,,,,,,,,,,,,,,,,,,,,,,,,
,3881439637.59894,10.0000987052917,-14000.115234375,-8.21637176395557E-5,2.90498532802678E-5,1,4,14.0008964538574,4.98367080271805,32.4000008404255,-0.0956288130888779,-0.0549142439153233,100,-3.19173119055781E-5,,,,,,,,,,,,,,,,,,,,,10.0000371932983,10.0001602172852,-14000.115234375,-14000.115234375,53.4180562612749,5.88326253546387,3.0931134223938,56,1,0,0,1,0.325241088867188,33.7243423461914,1,1,3,10.0000371932983,0,10.0000987052917,,,,,,,,,,,,,,,,,,,,,,,,,,,,,,,,,
,3881439676.60839,10.0002255439758,-13000.419921875,-8.55625832708435E-5,1.63590501212355E-5,1,4,14.0008964538574,4.98389685006988,32.4000008404255,-0.108851948780199,0.00377792499170799,100,1.60511525005358E-5,,,,,,,,,,,,,,,,,,,,,10.0001182556152,10.0003328323364,-13000.419921875,-13000.419921875,53.5497606667653,5.88286456181856,3.08485913276672,55,1,68,0,0,0.326461791992188,34.2131004333496,1,1,3,10.0001182556152,0,10.0002255439758,,,,,,,,,,,,,,,,,,,,,,,,,,,,,,,,,
,3881439717.37247,10.0001492500305,-12000.1318359375,-1.02864850229502E-4,9.8816189282339E-6,1,4,14.0008964538574,4.98369096035905,32.4000008404255,-0.12986240321373,-0.00200052462324116,100,1.40077087549439E-5,,,,,,,,,,,,,,,,,,,,,10.0000896453857,10.0002088546753,-12000.1318359375,-12000.1318359375,53.4102399760826,5.88246297412672,3.08531498908997,56,1,0,0,1,0.32867431640625,34.2131004333496,1,1,3,10.0000896453857,0,10.0001492500305,,,,,,,,,,,,,,,,,,,,,,,,,,,,,,,,,
,3881439766.08882,10.0003838539124,-11000.2216796875,-1.17526833054978E-4,1.71680497910385E-5,1,4,14.0008964538574,4.9837447520288,32.4000008404255,-0.144696435192357,-0.0265012707554321,1000,-3.57345776676309E-6,,,,,,,,,,,,,,,,,,,,,10.0002288818359,10.0005388259888,-11000.2216796875,-11000.2216796875,53.4942650418999,5.88354416805005,3.09356594085693,56,1,0,0,1,0.328369140625,34.2131004333496,1,1,3,10.0005388259888,0,10.0003838539124,,,,,,,,,,,,,,,,,,,,,,,,,,,,,,,,,
,3881439811.24102,10.0000882148743,-10000.474609375,-1.28042999090836E-4,1.53580601998679E-5,1,4,14.0008964538574,4.9836426490192,32.4000008404255,-0.157551284593613,-0.0294503504221481,100,-4.36101117087115E-6,,,,,,,,,,,,,,,,,,,,,9.99939250946045,10.0007839202881,-10000.474609375,-10000.474609375,53.5067710982076,5.88434644576955,3.09481835365295,56,1,0,0,1,0.3265380859375,34.2131004333496,1,1,3,9.99939250946045,0,10.0000882148743,,,,,,,,,,,,,,,,,,,,,,,,,,,,,,,,,
,3881439858.82974,9.99997520446777,-9000.400390625,-1.45097135066966E-4,3.21841138796298E-6,1,4,14.0008964538574,4.98366475935069,32.4000008404255,-0.179479092517579,-0.027169417806187,10,7.37787294417903E-8,,,,,,,,,,,,,,,,,,,,,9.99953842163086,10.0004119873047,-9000.400390625,-9000.400390625,53.4278266177653,5.882855674446,3.08931159973145,56,1,0,0,1,0.326385498046875,34.2131004333496,1,1,3,10.000485420227,0,9.99997520446777,,,,,,,,,,,,,,,,,,,,,,,,,,,,,,,,,
,3881439899.45053,10.0001859664917,-8000.36474609375,-1.57383912012393E-4,7.60242960262793E-6,1,4,14.0008964538574,4.98370979155578,32.4000008404255,-0.195928558199832,-0.0212494725290088,10,6.72661046345169E-6,,,,,,,,,,,,,,,,,,,,,9.99993991851807,10.0004320144653,-8000.36474609375,-8000.36474609375,53.4434591881499,5.88429651148895,3.08787798881531,55,1,68,0,0,0.328598022460937,34.2131004333496,1,1,3,10.0004320144653,0,10.0001859664917,,,,,,,,,,,,,,,,,,,,,,,,,,,,,,,,,
,3881439938.65474,9.999915599823,-7000.3916015625,-1.6997057785897E-4,4.50518659695017E-6,1,4,14.0008964538574,4.98374095948661,32.4000008404255,-0.21091727047427,-0.0274414698668247,10,3.63256392094029E-6,,,,,,,,,,,,,,,,,,,,,9.99950981140137,10.0003213882446,-7000.3916015625,-7000.3916015625,53.4458040737076,5.88403018566898,3.08773827552795,56,1,0,0,1,0.326461791992188,34.2131004333496,1,1,3,10.0003213882446,0,9.999915599823,,,,,,,,,,,,,,,,,,,,,,,,,,,,,,,,,
,3881439978.22532,10.0002641677856,-6000.38037109375,-1.77687390200746E-4,1.25043154516273E-7,1,4,14.0008964538574,4.98369406910947,32.4000008404255,-0.21979695160721,-0.0332507397641723,10,1.07711049035087E-7,,,,,,,,,,,,,,,,,,,,,9.99987030029297,10.0006580352783,-6000.38037109375,-6000.38037109375,53.4669080437268,5.88323772802369,3.09738039970398,56,1,0,0,1,0.3253173828125,34.2131004333496,1,1,3,9.99987030029297,0,10.0002641677856,,,,,,,,,,,,,,,,,,,,,,,,,,,,,,,,,
,3881440026.74847,10.0004200935364,-5000.5078125,-1.86861746969272E-4,1.20357178854817E-7,1,4,14.0008964538574,4.98364582413533,32.4000008404255,-0.231087140773037,-0.0353306583206822,1,-1.80691513570707E-7,,,,,,,,,,,,,,,,,,,,,9.99972438812256,10.0011157989502,-5000.5078125,-5000.5078125,53.5157598261787,5.88421937225231,3.09205532073975,56,1,0,0,1,0.326309204101562,34.2131004333496,1,1,3,10.0011157989502,0,10.0004200935364,,,,,,,,,,,,,,,,,,,,,,,,,,,,,,,,,
,3881440075.63278,10.0002431869507,-4000.32080078125,-1.9448701873609E-4,4.97100765796633E-8,1,4,14.0008964538574,4.98358970273787,32.4099995195866,-0.240561005844698,-0.0364578795016871,10,6.57574064713725E-8,,,,,,,,,,,,,,,,,,,,,9.99946022033691,10.0010261535645,-4000.32080078125,-4000.32080078125,53.4993456272749,5.88458967383563,3.09795546531677,56,1,0,0,1,0.32501220703125,34.2131004333496,1,1,3,9.99946022033691,0,10.0002431869507,,,,,,,,,,,,,,,,,,,,,,,,,,,,,,,,,
,3881440120.10807,10.0002393722534,-3000.27221679687,-1.97555186357307E-4,5.15848814840506E-8,1,4,14.0008964538574,4.98370572884054,32.4000008404255,-0.244324470705137,-0.0372945019333213,1,-1.43625810279299E-7,,,,,,,,,,,,,,,,,,,,,9.99995994567871,10.0005187988281,-3000.27221679687,-3000.27221679687,53.4004696195922,5.88400372843941,3.09526181221008,56,1,0,0,1,0.326004028320313,34.2131004333496,1,1,3,9.99995994567871,0,10.0002393722534,,,,,,,,,,,,,,,,,,,,,,,,,,,,,,,,,
,3881440176.52442,10.0004630088806,-2510.32446289062,-1.96276916844753E-4,7.95926032858954E-8,1,4,14.0008964538574,4.98367202428853,32.4000008404255,-0.242738037222295,-0.0370741856460388,1,-1.59955638458177E-7,,,,,,,,,,,,,,,,,,,,,9.9990291595459,10.0018968582153,-2510.32446289062,-2510.32446289062,53.3836646064287,5.88425446161822,3.09730315208435,56,1,0,0,1,0.326004028320313,34.2131004333496,1,1,3,10.0018968582153,0,10.0004630088806,,,,,,,,,,,,,,,,,,,,,,,,,,,,,,,,,
,3881440214.93745,9.99893808364868,-1930.40881347656,-1.89875265368941E-4,7.24959061890582E-8,1,4,14.0008964538574,4.98363709008324,32.4000008404255,-0.234822102876104,-0.0358424247987271,1,-1.36774913997712E-7,,,,,,,,,,,,,,,,,,,,,9.99821090698242,9.99966526031494,-1930.40881347656,-1930.40881347656,53.3828829779095,5.88447496634952,3.09323406219482,56,1,0,0,1,0.328292846679687,34.2131004333496,1,1,3,9.99966526031494,0,9.99893808364868,,,,,,,,,,,,,,,,,,,,,,,,,,,,,,,,,
,3881440253.63705,10.0004081726074,-1350.22888183594,-1.75157541887674E-4,5.33935091200109E-8,1,4,14.0008964538574,4.98368640457105,32.4000008404255,-0.216628613073785,-0.0330305964140119,1,-9.86453603664384E-8,,,,,,,,,,,,,,,,,,,,,9.99885654449463,10.0019598007202,-1350.22888183594,-1350.22888183594,53.2883059270826,5.88377311493372,3.09136939048767,56,1,0,0,1,0.328750610351562,33.7243423461914,1,1,3,10.0019598007202,0,10.0004081726074,,,,,,,,,,,,,,,,,,,,,,,,,,,,,,,,,
,3881440292.71736,9.99847459793091,-770.376037597656,-1.44371533414993E-4,3.88223873611539E-8,1,4,14.0008964538574,4.9837338698987,32.4000008404255,-0.178557911653872,-0.0272125917206736,1,-7.09176894117558E-8,,,,,,,,,,,,,,,,,,,,,9.99829292297363,9.99865627288818,-770.376037597656,-770.376037597656,53.3035476832076,5.8837740565861,3.09402585029602,56,1,0,0,1,0.327606201171875,33.7243423461914,1,1,3,9.99865627288818,0,9.99847459793091,,,,,,,,,,,,,,,,,,,,,,,,,,,,,,,,,
,3881440332.4968,10.0008835792542,-190.183364868164,-7.56684477312511E-5,2.61678498814447E-8,1,4,14.0008964538574,4.98369297406677,32.4000008404255,-0.0935871637170826,-0.0142499106322428,1,-2.69247268099277E-8,,,,,,,,,,,,,,,,,,,,,9.99845027923584,10.0033168792725,-190.183364868164,-190.183364868164,53.3348128239768,5.88381079784876,3.09471964836121,56,1,0,0,1,0.328598022460937,33.7243423461914,1,1,3,9.99845027923584,0,10.0008835792542,,,,,,,,,,,,,,,,,,,,,,,,,,,,,,,,,
,3881440371.12365,9.998366355896,389.682006835937,6.23540479622703E-5,3.75884664346981E-8,1,4,14.0008964538574,4.98362618279969,32.4000008404255,0.0771107253364382,0.0117927672486298,1,6.29764270515377E-8,,,,,,,,,,,,,,,,,,,,,9.99751377105713,9.99921894073486,389.682006835937,389.682006835937,53.5935318638422,5.88411382193331,3.10017275810242,56,1,0,0,1,0.326080322265625,33.7243423461914,1,1,3,9.99921894073486,0,9.998366355896,,,,,,,,,,,,,,,,,,,,,,,,,,,,,,,,,
,3881440411.39428,10.0025734901428,969.509582519531,1.34268621984202E-4,7.26337337990389E-8,1,4,14.0008964538574,4.98363677536236,32.4000008404255,0.166049296978382,0.0253658679424154,1,1.13063154357308E-7,,,,,,,,,,,,,,,,,,,,,10.0021123886108,10.0030345916748,969.509582519531,969.509582519531,53.4110216046018,5.88379815928292,3.09991884231567,56,1,0,0,1,0.327606201171875,33.7243423461914,1,1,3,10.0021123886108,0,10.0025734901428,,,,,,,,,,,,,,,,,,,,,,,,,,,,,,,,,
,3881440450.11895,9.99889945983887,1549.6015625,1.68296084757046E-4,1.02998576089346E-7,1,4,14.0008964538574,4.9836763831671,32.4099995195866,0.208161038286948,0.0316113934154968,1,-6.4455336344251E-9,,,,,,,,,,,,,,,,,,,,,9.99722385406494,10.0005750656128,1549.6015625,1549.6015625,53.4786324715153,5.88276199443803,3.10029315948486,56,1,0,0,1,0.3253173828125,33.7243423461914,1,1,3,9.99730587005615,0,9.99889945983887,,,,,,,,,,,,,,,,,,,,,,,,,,,,,,,,,
,3881440489.67046,9.99713945388794,2129.50463867187,1.84335988068441E-4,7.06599990294277E-8,1,4,14.0008964538574,4.98373812049451,32.4000008404255,0.227975097324302,0.03481731128941,1,1.4857963953123E-7,,,,,,,,,,,,,,,,,,,,,9.99687576293945,9.99740314483643,2129.50463867187,2129.50463867187,53.447367330746,5.88376695401124,3.09871602058411,56,1,0,0,1,0.326690673828125,34.2131004333496,1,1,3,9.99740314483643,0,9.99713945388794,,,,,,,,,,,,,,,,,,,,,,,,,,,,,,,,,
,3881440528.94711,9.99914884567261,2709.76049804687,1.91100975036524E-4,4.22229796606418E-8,1,4,14.0008964538574,4.98380764676816,32.4000008404255,0.236346641644448,0.0360930864353438,1,1.5184992590917E-7,,,,,,,,,,,,,,,,,,,,,9.99724006652832,10.0010576248169,2709.76049804687,2709.76049804687,53.4743335146595,5.8831272900817,3.09521794319153,56,1,0,0,1,0.32684326171875,33.7243423461914,1,1,3,10.0010576248169,0,9.99914884567261,,,,,,,,,,,,,,,,,,,,,,,,,,,,,,,,,
,3881440586.02319,9.99754762649536,3499.4970703125,1.93272514228194E-4,8.22637180135988E-8,1,4,14.0008964538574,4.98367413696804,32.4000008404255,0.239016498607094,0.0365468706794189,1,1.89973406392245E-7,,,,,,,,,,,,,,,,,,,,,9.9973030090332,9.99779224395752,3499.4970703125,3499.4970703125,53.5743819651211,5.88416929202988,3.09702801704407,56,1,0,0,1,0.325775146484375,33.7243423461914,1,1,3,9.99779224395752,0,9.99754762649536,,,,,,,,,,,,,,,,,,,,,,,,,,,,,,,,,
,3881440627.07097,10.0009255409241,4499.82275390625,1.87822885919792E-4,3.34559668166951E-8,1,4,14.0008964538574,4.98371969356745,32.4000008404255,0.232274036747975,0.0355562474900959,1,2.16486365388274E-7,,,,,,,,,,,,,,,,,,,,,9.99893856048584,10.0029125213623,4499.82275390625,4499.82275390625,53.4778508429961,5.88390382843665,3.1019332408905,56,1,0,0,1,0.326919555664063,34.7018585205078,1,1,3,10.0029125213623,0,10.0009255409241,,,,,,,,,,,,,,,,,,,,,,,,,,,,,,,,,
,3881440668.51789,10.00244140625,5499.7080078125,1.79642993728865E-4,6.43636568521624E-8,1,4,14.0008964538574,4.98356404593962,32.4000008404255,0.222136341449569,0.0340863755831051,1,2.7184630307606E-7,,,,,,,,,,,,,,,,,,,,,10.0023603439331,10.0025224685669,5499.7080078125,5499.7080078125,53.503253769871,5.88488254798832,3.09717392921448,54,1,32,0,0,0.324935913085937,34.2131004333496,1,1,3,10.0025224685669,0,10.00244140625,,,,,,,,,,,,,,,,,,,,,,,,,,,,,,,,,
,3881440716.93292,10.0017876625061,6499.64306640625,1.6976398132421E-4,5.23161162960707E-8,1,4,14.0008964538574,4.9836479016887,32.4000008404255,0.209965757690834,0.0319474213117005,10,4.24656029300236E-8,,,,,,,,,,,,,,,,,,,,,10.0013179779053,10.0022573471069,6499.64306640625,6499.64306640625,53.4114124188614,5.88402333264192,3.10623073577881,56,1,0,0,1,0.326004028320313,33.7243423461914,1,1,3,10.0013179779053,0,10.0017876625061,,,,,,,,,,,,,,,,,,,,,,,,,,,,,,,,,
,3881440783.75818,9.99983263015747,7499.52880859375,1.58060953683979E-4,2.25631080112645E-6,1,4,14.0008964538574,4.98358906785155,32.4000008404255,0.195050939193108,0.0326225304875296,10,2.36641254771002E-6,,,,,,,,,,,,,,,,,,,,,9.99833011627197,10.001335144043,7499.52880859375,7499.52880859375,53.4583101300153,5.88425148829481,3.09607005119324,56,1,0,0,1,0.326385498046875,33.7243423461914,1,1,3,9.99833011627197,0,9.99983263015747,,,,,,,,,,,,,,,,,,,,,,,,,,,,,,,,,
,3881440842.06854,10.0015392303467,8499.791015625,1.47262785981354E-4,8.39282197780913E-8,1,4,14.0008964538574,4.98350359859024,32.4000008404255,0.182102231264019,0.0278858380520708,1,1.77506818031735E-7,,,,,,,,,,,,,,,,,,,,,10.0011329650879,10.0019454956055,8499.791015625,8499.791015625,53.4868395709672,5.88450294444686,3.10531377792358,41,1,100,0,0,0.324249267578125,33.7243423461914,1,1,3,10.0019454956055,0,10.0015392303467,,,,,,,,,,,,,,,,,,,,,,,,,,,,,,,,,
,3881440901.32042,10.0018529891968,9499.890625,1.33504375394598E-4,6.97837587727601E-6,1,4,14.0008964538574,4.98346201090162,32.4000008404255,0.164534944168715,0.0289140676524361,10,3.09903417911566E-6,,,,,,,,,,,,,,,,,,,,,10.0017347335815,10.001971244812,9499.890625,9499.890625,53.3523994656595,5.88526456424912,3.10747194290161,55,1,68,0,0,0.329055786132812,33.7243423461914,1,1,3,10.0017347335815,0,10.0018529891968,,,,,,,,,,,,,,,,,,,,,,,,,,,,,,,,,
,3881440940.81368,10.0007152557373,10499.8125,1.21131193915001E-4,9.09139218490096E-6,1,4,14.0008964538574,4.98347207640493,32.4000008404255,0.151213820808133,0.0135447619735588,10,-7.44826704369762E-6,,,,,,,,,,,,,,,,,,,,,10.0005178451538,10.0009126663208,10499.8125,10499.8125,53.3121455969191,5.88472974888574,3.10443449020386,56,1,0,0,1,0.328826904296875,34.2131004333496,1,1,3,10.0005178451538,0,10.0007152557373,,,,,,,,,,,,,,,,,,,,,,,,,,,,,,,,,
,3881441001.70789,10.0000386238098,11499.59765625,1.03716732868089E-4,6.82872634079211E-6,1,4,14.0008964538574,4.98338577499831,32.4000008404255,0.12912939128458,0.0138486033402176,100,-4.55707948798213E-6,,,,,,,,,,,,,,,,,,,,,9.99991035461426,10.0001668930054,11499.59765625,11499.59765625,53.5614850945537,5.88387234542694,3.10303068161011,56,1,0,0,1,0.325927734375,33.7243423461914,1,1,3,10.0001668930054,0,10.0000386238098,,,,,,,,,,,,,,,,,,,,,,,,,,,,,,,,,
,3881441054.6457,9.99999856948852,12500.0234375,8.32450837223174E-5,2.11385496804405E-5,1,4,14.0008964538574,4.9833475351775,32.4000008404255,0.100749361716132,0.0301493684587416,100,1.1732973495421E-5,,,,,,,,,,,,,,,,,,,,,9.99977493286133,10.0002222061157,12500.0234375,12500.0234375,53.3144904824768,5.88527485026454,3.10078072547913,55,1,68,0,0,0.327377319335937,33.7243423461914,1,1,3,10.0002222061157,0,9.99999856948852,,,,,,,,,,,,,,,,,,,,,,,,,,,,,,,,,
,3881441112.40008,10.0001444816589,13499.845703125,9.40172982326114E-5,6.79015830014765E-5,1,4,14.0008964538574,4.98336300487468,32.4099995195866,0.126710439372043,-0.0510267059181446,10,-5.55396304630614E-5,,,,,,,,,,,,,,,,,,,,,10.0001268386841,10.0001621246338,13499.845703125,13499.845703125,53.5759452221595,5.88496854344533,3.10118103027344,55,1,68,0,0,0.32684326171875,33.7243423461914,1,1,3,10.0001621246338,0,10.0001444816589,,,,,,,,,,,,,,,,,,,,,,,,,,,,,,,,,
,3881441173.71546,10.0000333786011,14499.78125,9.23680167591009E-5,3.23195406848163E-5,1,4,14.0008964538574,4.98348377890737,32.4000008404255,0.118898628343838,-0.013311235647161,100,-2.47932970136162E-5,,,,,,,,,,,,,,,,,,,,,9.99995708465576,10.0001096725464,14499.78125,14499.78125,53.445413259448,5.88491222146979,3.1039125919342,56,1,0,0,1,0.325469970703125,33.7243423461914,1,1,3,9.99995708465576,0,10.0000333786011,,,,,,,,,,,,,,,,,,,,,,,,,,,,,,,,,
,3881441254.25195,10.0001058578491,19999.4765625,2.24489848517287E-5,3.28352578713113E-5,1,4,14.0008964538574,4.98335295379417,32.4000008404255,0.0227111688983353,0.0374808005362708,10,2.68957936061544E-5,,,,,,,,,,,,,,,,,,,,,10.0000972747803,10.000114440918,19999.4765625,19999.4765625,53.4387694170345,5.88486333661123,3.10438537597656,54,1,68,0,0,0.328750610351562,33.7243423461914,1,1,3,10.0000972747803,0,10.0001058578491,,,,,,,,,,,,,,,,,,,,,,,,,,,,,,,,,
,3881441356.32914,10.0005602836609,30000.166015625,-1.63706983616094E-4,3.94644841766257E-5,1,4,14.0008964538574,4.9832402867116,32.4000008404255,-0.199165672338154,-0.0524334422940151,100,-1.75303548303861E-5,,,,,,,,,,,,,,,,,,,,,10.0004186630249,10.0007019042969,30000.166015625,30000.166015625,53.4837130568903,5.8853427100515,3.11345815658569,54,1,68,0,0,0.328369140625,33.7243423461914,1,1,3,10.0004186630249,0,10.0005602836609,,,,,,,,,,,,,,,,,,,,,,,,,,,,,,,,,
,3881441468.99873,9.99998331069946,40000.4765625,-2.79223611261649E-4,1.34992232884766E-4,1,4,14.0008964538574,4.98342720325566,32.4000008404255,-0.382403696843947,0.191556897739979,100,1.97297488542716E-4,,,,,,,,,,,,,,,,,,,,,9.99933242797852,10.0006341934204,40000.4765625,40000.4765625,53.569301379746,5.88517836565155,3.11643171310425,53,1,68,0,0,0.328903198242188,34.2131004333496,1,1,3,10.0006341934204,0,9.99998331069946,,,,,,,,,,,,,,,,,,,,,,,,,,,,,,,,,
,3881441581.26183,9.99988126754761,50000.39453125,-5.0827286962755E-4,1.31791049707958E-4,1,4,14.0008964538574,4.98337684748587,32.4000008404255,-0.64969676792107,0.0433162826526082,100,1.12230306998909E-4,,,,,,,,,,,,,,,,,,,,,9.99976444244385,9.99999809265137,50000.39453125,50000.39453125,53.7709615377076,5.88608473761956,3.11233878135681,53,1,68,0,0,0.327377319335937,33.7243423461914,1,1,3,9.99976444244385,0,9.99988126754761,,,,,,,,,,,,,,,,,,,,,,,,,,,,,,,,,
,3881441695.19871,9.99962997436523,60000.546875,--,5.11053882282585E-4,1,4,14.0008964538574,4.9833944102503,32.4000008404255,-1.51722331550763,0.111086975925576,100,2.69936787885299E-4,,,,,,,,,,,,,,,,,,,,,9.99930953979492,9.99995040893555,60000.546875,60000.546875,53.7318801117461,5.88686720975462,3.1135790348053,50,1,68,0,0,0.3302001953125,33.2355842590332,1,1,3,9.99995040893555,0,9.99962997436523,,,,,,,,,,,,,,,,,,,,,,,,,,,,,,,,,
,3881441809.02033,10.0000586509705,70000.3828125,-7.57291838979439E-4,1.00732136681238E-4,1,4,14.0008964538574,4.98345752047041,32.4000008404255,-0.925074321764707,-0.218222579114277,100,-6.14104141071901E-5,,,,,,,,,,,,,,,,,,,,,9.99986267089844,10.0002546310425,70000.3828125,70000.3828125,53.9632421534384,5.88732975260678,3.12566184997559,52,1,68,0,0,0.32928466796875,34.2131004333496,1,1,3,9.99986267089844,0,10.0000586509705,,,,,,,,,,,,,,,,,,,,,,,,,,,,,,,,,
,3881441819.80552,9.99969625473022,70000.3828125,-6.80328607530418E-4,6.84745610518992E-5,1,4,14.0008964538574,4.98344352059102,32.4000008404255,-0.824797990179897,-0.23724333539108,1000,-8.84809689445215E-5,,,,,,,,,,,,,,,,,,,,,9.99966430664062,9.99972820281982,70000.3828125,70000.3828125,54.105889358198,5.88641010623002,3.11851620674133,56,2,0,0,1,0.327224731445313,33.7243423461914,1,1,3,9.99966430664062,0,9.99969625473022,,,,,,,,,,,,,,,,,,,,,,,,,,,,,,,,,