File: SQUID/Reference/STO/B1/STOsubs_MH_50K_FC_0d5T.csv
Comment,Time Stamp (sec),Temperature (K),Magnetic Field (Oe),Moment (emu),M. Std. Err. (emu),Transport Action,Averaging Time (sec),Frequency (Hz),Peak Amplitude (mm),Center Position (mm),Lockin Signal' (V),Lockin Signal (V),Range,M. Quad. Signal (emu),AC Moment (emu),AC M. Std Err. (emu),AC Phase (deg),AC Phase Std. Err. (deg),AC Susceptibility (emu/Oe),AC Suscept. Std Err. (emu/Oe),AC X' (emu/Oe),AC X' Std Err. (emu/Oe),AC X'' (emu/Oe),AC X'' Std Err. (emu/Oe),AC Drive (Oe),AC Frequency (Hz),AC Averaging Time (sec),AC Cycles,AC Range,AC Measure Type,AC Signal' (V),AC Signal'' (V),AC Trim Coil Ratio,AC Trim Coil Phase,Min. Temperature (K),Max. Temperature (K),Min. Field (Oe),Max. Field (Oe),Mass (grams),Motor Lag (deg),Pressure (Torr),Measure Count,Measurement Number,SQUID Status (code),Motor Status (code),Measure Status (code),Motor Current (amps),Motor Temp. (C),Temp. Status (code),Field Status (code),Chamber Status (code),Chamber Temp (K),Redirection State,Average Temp (K),Rotation Angle (deg),Rotator state,DC Moment Fixed Ctr (emu),DC Moment Err Fixed Ctr (emu),DC Moment Free Ctr (emu),DC Moment Err Free Ctr (emu),DC Fixed Fit,DC Free Fit,DC Calculated Center (mm),DC Calculated Center Err (mm),DC Scan Length (mm),DC Scan Time (s),DC Number of Points,DC Squid Drift,DC Min V (V),DC Max V (V),DC Scans per Measure,Sample Resistance,He3 Temperature,Sorb Resistance,Sorb Temperature,Map 05,Map 06,Map 07,Map 08,Map 09,Map 10,Map 11,Map 12,Map 13,Map 14,Map 15,Map 16
,3879778145.93469,50.007963180542,69999.671875,-4.31066195935228E-4,1.70521913840382E-7,1,4,13.4005146026611,4.99641906851132,33.2800000905991,-0.535324113944326,-0.07962718969802,1,3.57623653080868E-7,,,,,,,,,,,,,,,,,,,,,50.0079078674316,50.0080184936523,69999.671875,69999.671875,53.379365649573,5.63907439974077,4.60748958587646,54,1,0,0,1,0.298233032226562,32.7468223571777,1,1,3,50.0079078674316,0,50.007963180542,,,,,,,,,,,,,,,,,,,,,,,,,,,,,,,,,
,3879778383.03577,50.010570526123,54999.64453125,-3.3784945274375E-4,8.77844660772492E-8,1,4,13.4005146026611,4.99622988040557,33.2800000905991,-0.419526712217451,-0.0624913615839575,1,2.10528890594784E-7,,,,,,,,,,,,,,,,,,,,,50.0104103088379,50.0107307434082,54999.64453125,54999.64453125,53.2773631278133,5.63941740807938,4.63966274261475,54,2,0,0,1,0.298385620117188,33.7243423461914,1,1,3,50.0107307434082,0,50.010570526123,,,,,,,,,,,,,,,,,,,,,,,,,,,,,,,,,
,3879778615.94403,50.0246467590332,39999.59765625,-2.45453283664406E-4,4.44483565306759E-8,1,4,13.4005146026611,4.99600202102,33.2800000905991,-0.3047856708871,-0.0453181956102653,1,2.17327577174559E-7,,,,,,,,,,,,,,,,,,,,,50.0239334106445,50.0253601074219,39999.59765625,39999.59765625,53.3633422649287,5.640110591627,4.65347003936768,54,3,0,0,1,0.2984619140625,34.7018585205078,1,1,3,50.0239334106445,0,50.0246467590332,,,,,,,,,,,,,,,,,,,,,,,,,,,,,,,,,
,3879778897.15677,50.0182209014893,19999.615234375,-1.22382970201544E-4,1.99849500115339E-8,1,4,13.4005146026611,4.99619235809069,33.2800000905991,-0.151966201925858,-0.0226502970801442,1,6.53143223800774E-8,,,,,,,,,,,,,,,,,,,,,50.0158157348633,50.0206260681152,19999.615234375,19999.615234375,53.4418959311114,5.63912196149265,4.66670513153076,54,1,0,0,1,0.2984619140625,33.7243423461914,1,1,3,50.0206260681152,0,50.0182209014893,,,,,,,,,,,,,,,,,,,,,,,,,,,,,,,,,
,3879779084.55527,50.0159397125244,9999.783203125,-6.08621421908437E-5,1.1674081238531E-8,1,4,13.4005146026611,4.99612373716979,33.2899987697601,-0.0755846747397695,-0.0111838864731336,1,9.69879333501447E-8,,,,,,,,,,,,,,,,,,,,,50.0138969421387,50.0179824829102,9999.783203125,9999.783203125,53.4501030305633,5.63866493454572,4.67097902297974,54,2,0,0,1,0.29876708984375,34.2131004333496,1,1,3,50.0138969421387,0,50.0159397125244,,,,,,,,,,,,,,,,,,,,,,,,,,,,,,,,,
,3879779171.55018,50.0028915405273,8499.765625,-5.16236683263968E-5,1.35422903433389E-8,1,4,13.4005146026611,4.99618377166884,33.2800000905991,-0.0641083872952357,-0.00951387013121459,1,6.01458936078374E-8,,,,,,,,,,,,,,,,,,,,,50.0026435852051,50.0031394958496,8499.765625,8499.765625,53.5028629556114,5.6384029212976,4.68262720108032,54,3,0,0,1,0.298690795898438,34.2131004333496,1,1,3,50.0026435852051,0,50.0028915405273,,,,,,,,,,,,,,,,,,,,,,,,,,,,,,,,,
,3879779272.70513,50.0111446380615,6499.5927734375,-3.92584504922941E-5,3.62389785994314E-8,1,4,13.4005146026611,4.99619258845038,33.2800000905991,-0.0487402855790388,-0.00731921435347724,1,-2.20320648074021E-8,,,,,,,,,,,,,,,,,,,,,50.0108489990234,50.0114402770996,6499.5927734375,6499.5927734375,53.4051593907076,5.63842522150624,4.67418384552002,54,1,0,0,1,0.2978515625,33.7243423461914,1,1,3,50.0114402770996,0,50.0111446380615,,,,,,,,,,,,,,,,,,,,,,,,,,,,,,,,,
,3879779359.25075,50.0029354095459,4999.765625,-3.00886600791112E-5,9.51865301770468E-9,1,4,13.4005146026611,4.99615342481961,33.2800000905991,-0.0373610817302701,-0.00557135940359658,1,1.38871502543804E-8,,,,,,,,,,,,,,,,,,,,,50.002571105957,50.0032997131348,4999.765625,4999.765625,53.3926533343999,5.63855130029044,4.67560529708862,54,2,0,0,1,0.299453735351562,34.2131004333496,1,1,3,50.002571105957,0,50.0029354095459,,,,,,,,,,,,,,,,,,,,,,,,,,,,,,,,,
,3879779445.88255,50.0094242095947,3499.54736328125,-2.08683339658723E-5,7.11597387642138E-9,1,4,13.4005146026611,4.99615017941227,33.2800000905991,-0.0259125352092457,-0.00386171212137745,1,1.15358339969046E-8,,,,,,,,,,,,,,,,,,,,,50.0090141296387,50.0098342895508,3499.54736328125,3499.54736328125,53.437206159996,5.63850826779499,4.68840551376343,53,3,68,0,0,0.298919677734375,34.2131004333496,1,1,3,50.0090141296387,0,50.0094242095947,,,,,,,,,,,,,,,,,,,,,,,,,,,,,,,,,
,3879779553.66114,50.0225372314453,2899.72973632812,-1.72642092785352E-5,1.31131873874985E-8,1,4,13.4005146026611,4.99617462401787,33.2800000905991,-0.021471591135373,-0.0029661216605942,1,1.93709488670128E-7,,,,,,,,,,,,,,,,,,,,,50.0214729309082,50.0236015319824,2899.72973632812,2899.72973632812,53.4547928016787,5.63834218774564,4.68944215774536,54,1,0,0,1,0.298538208007812,34.7018585205078,1,1,3,50.0236015319824,0,50.0225372314453,,,,,,,,,,,,,,,,,,,,,,,,,,,,,,,,,
,3879779629.24425,50.0081634521484,2749.62744140625,-1.63365855387851E-5,9.57187908127672E-9,1,4,13.4005146026611,4.99614701240162,33.2800000905991,-0.0203153725722351,-0.00282257422183705,1,1.70537986504399E-7,,,,,,,,,,,,,,,,,,,,,50.0075378417969,50.0087890625,2749.62744140625,2749.62744140625,53.4977823702364,5.63869696480424,4.68794775009155,54,2,0,0,1,0.299301147460937,33.7243423461914,1,1,3,50.0075378417969,0,50.0081634521484,,,,,,,,,,,,,,,,,,,,,,,,,,,,,,,,,
,3879779703.59772,50.0156536102295,2599.62573242187,-1.53987048310418E-5,9.02454223878573E-9,1,4,13.4005146026611,4.99615946392961,33.2800000905991,-0.0191449067509859,-0.00268881942193408,1,1.3797111361936E-7,,,,,,,,,,,,,,,,,,,,,50.0148506164551,50.0164566040039,2599.62573242187,2599.62573242187,53.5005180700537,5.63886316913441,4.68972158432007,54,3,0,0,1,0.29876708984375,34.2131004333496,1,1,3,50.0148506164551,0,50.0156536102295,,,,,,,,,,,,,,,,,,,,,,,,,,,,,,,,,
,3879779784.7618,50.0159854888916,2399.53540039062,-1.42069974136867E-5,1.73730694378379E-8,1,4,13.4005146026611,4.9962000802216,33.2800000905991,-0.0176818413792391,-0.00235802776909242,1,2.26140872058166E-7,,,,,,,,,,,,,,,,,,,,,50.0154495239258,50.0165214538574,2399.53540039062,2399.53540039062,53.4211827753518,5.6387945133292,4.68881320953369,54,1,0,0,1,0.298690795898438,34.2131004333496,1,1,3,50.0165214538574,0,50.0159854888916,,,,,,,,,,,,,,,,,,,,,,,,,,,,,,,,,
,3879779856.24099,50.0143184661865,2249.49584960938,-1.32702448663186E-5,1.43492820473692E-8,1,4,13.4005146026611,4.99623797248342,33.2800000905991,-0.0165068173618595,-0.00226493828200585,1,1.61001430399489E-7,,,,,,,,,,,,,,,,,,,,,50.0141754150391,50.014461517334,2249.49584960938,2249.49584960938,53.4614366440922,5.63868773153284,4.68669080734253,53,2,68,0,0,0.298843383789063,34.2131004333496,1,1,3,50.0144195556641,0,50.0143184661865,,,,,,,,,,,,,,,,,,,,,,,,,,,,,,,,,
,3879779927.58736,50.0154323577881,2099.60766601562,-1.23420447572777E-5,1.16989281458835E-8,1,4,13.4005146026611,4.9962403568457,33.2800000905991,-0.0153484043623955,-0.00213217224199849,1,1.29077227173479E-7,,,,,,,,,,,,,,,,,,,,,50.0145874023438,50.0162773132324,2099.60766601562,2099.60766601562,53.4872303852268,5.63868640556602,4.69417333602905,54,3,0,0,1,0.298995971679687,34.2131004333496,1,1,3,50.0145874023438,0,50.0154323577881,,,,,,,,,,,,,,,,,,,,,,,,,,,,,,,,,
,3879780009.48509,50.033805847168,1899.73132324219,-1.11468936147982E-5,2.33823750527965E-8,1,4,13.4005146026611,4.99617928223341,33.2800000905991,-0.0138837443449686,-0.00177959660329275,1,2.34224096226344E-7,,,,,,,,,,,,,,,,,,,,,50.0316467285156,50.0359649658203,1899.73132324219,1899.73132324219,53.5036445841307,5.6391058589423,4.68497323989868,54,1,0,0,1,0.299301147460937,34.2131004333496,1,1,3,50.0359649658203,0,50.033805847168,,,,,,,,,,,,,,,,,,,,,,,,,,,,,,,,,
,3879780081.9417,50.0352668762207,1749.76745605469,-1.02201896059812E-5,1.50882501682825E-8,1,4,13.4005146026611,4.99620948150412,33.2800000905991,-0.0127174538190102,-0.00171297910281234,1,1.49260125199697E-7,,,,,,,,,,,,,,,,,,,,,50.0347442626953,50.0357894897461,1749.76745605469,1749.76745605469,53.3903084488422,5.63944119462365,4.68951845169067,54,2,0,0,1,0.298995971679687,33.7243423461914,1,1,3,50.0347442626953,0,50.0352668762207,,,,,,,,,,,,,,,,,,,,,,,,,,,,,,,,,
,3879780153.17203,50.0046043395996,1599.89172363281,-9.26947573103643E-6,1.16679750164029E-8,1,4,13.4005146026611,4.99622514664606,33.2800000905991,-0.0115336104894646,-0.00155950048662329,1,1.306549367228E-7,,,,,,,,,,,,,,,,,,,,,50.0042839050293,50.0049247741699,1599.89172363281,1599.89172363281,53.4235276609095,5.6395354135084,4.6937689781189,53,3,68,0,0,0.2978515625,34.2131004333496,1,1,3,50.0042839050293,0,50.0046043395996,,,,,,,,,,,,,,,,,,,,,,,,,,,,,,,,,
,3879780260.47943,50.014030456543,1399.70068359375,-8.10940349525948E-6,2.78122289904562E-8,1,4,13.4005146026611,4.99608051792283,33.2800000905991,-0.0101044448702614,-0.00126619887071682,1,1.93295267038633E-7,,,,,,,,,,,,,,,,,,,,,50.0131034851074,50.0149574279785,1399.70068359375,1399.70068359375,53.5200587830345,5.6395999444475,4.68644571304321,53,1,68,0,0,0.298385620117188,34.2131004333496,1,1,3,50.0131034851074,0,50.014030456543,,,,,,,,,,,,,,,,,,,,,,,,,,,,,,,,,
,3879780353.68447,50.0340595245361,1249.64868164062,-7.18320410590945E-6,1.34994025375056E-8,1,4,13.4005146026611,4.9961897159055,33.2800000905991,-0.00895304464586372,-0.00110567431963972,1,1.84058439222487E-7,,,,,,,,,,,,,,,,,,,,,50.0339126586914,50.0342063903809,1249.64868164062,1249.64868164062,53.5055986554287,5.63914899358876,4.69015169143677,54,2,0,0,1,0.299301147460937,34.2131004333496,1,1,3,50.0342063903809,0,50.0340595245361,,,,,,,,,,,,,,,,,,,,,,,,,,,,,,,,,
,3879780453.23031,50.0021743774414,1099.81066894531,-6.22137714413588E-6,1.20813749372151E-8,1,4,13.4005146026611,4.99595802451142,33.2899987697601,-0.00774713805144462,-0.00100165186955615,10,1.23901826689274E-7,,,,,,,,,,,,,,,,,,,,,50.0021553039551,50.0021934509277,1099.81066894531,1099.81066894531,53.3992971768133,5.64034313649132,4.69026231765747,54,3,0,0,1,0.299224853515625,33.7243423461914,1,1,3,50.0021362304687,0,50.0021743774414,,,,,,,,,,,,,,,,,,,,,,,,,,,,,,,,,
,3879780567.72072,50.013219833374,899.934326171875,-5.07109256342838E-6,2.908594053724E-8,1,4,13.4005146026611,4.99605941381115,33.2800000905991,-0.00633685214852306,-6.69943139477625E-4,1,2.19015602057554E-7,,,,,,,,,,,,,,,,,,,,,50.0109901428223,50.0154495239258,899.934326171875,899.934326171875,53.2672019570633,5.63920793707769,4.69759941101074,53,1,68,0,0,0.298614501953125,34.2131004333496,1,1,3,50.0154495239258,0,50.013219833374,,,,,,,,,,,,,,,,,,,,,,,,,,,,,,,,,
,3879780676.1172,50.0106792449951,749.794250488281,-4.12953803267908E-6,1.34456381226466E-8,1,4,13.4005146026611,4.99586379252734,33.2800000905991,-0.00515549821416459,-5.75616931746485E-4,1,1.54112058550901E-7,,,,,,,,,,,,,,,,,,,,,50.0105628967285,50.0107955932617,749.794250488281,749.794250488281,53.447367330746,5.64064014382884,4.68942165374756,54,2,0,0,1,0.300140380859375,33.7243423461914,1,1,3,50.0104866027832,0,50.0106792449951,,,,,,,,,,,,,,,,,,,,,,,,,,,,,,,,,
,3879780766.36411,50.0207500457764,600.019165039063,-3.21409166583165E-6,1.64167126064107E-8,1,4,13.4005146026611,4.99604900219008,33.2800000905991,-0.0040203721282288,-3.97570071548472E-4,1,1.60594710459688E-7,,,,,,,,,,,,,,,,,,,,,50.0200805664063,50.0214195251465,600.019165039063,600.019165039063,53.3633422649287,5.64022463829468,4.69513177871704,54,3,0,0,1,0.298995971679687,33.2355842590332,1,1,3,50.0200805664063,0,50.0207500457764,,,,,,,,,,,,,,,,,,,,,,,,,,,,,,,,,
,3879780883.35625,50.0094127655029,399.916259765625,-2.09260288174462E-6,2.23398932327618E-8,1,4,13.4005146026611,4.99594858489118,33.2800000905991,-0.00264427985541611,-7.96568749830876E-5,1,2.48880912477049E-7,,,,,,,,,,,,,,,,,,,,,50.0083236694336,50.0105018615723,399.916259765625,399.916259765625,53.3578708652941,5.6393025310626,4.69022226333618,54,1,0,0,1,0.298004150390625,33.7243423461914,1,1,3,50.0083236694336,0,50.0094127655029,,,,,,,,,,,,,,,,,,,,,,,,,,,,,,,,,
,3879780996.08747,50.0103740692139,249.952377319336,-1.10381958568103E-6,1.63837052104345E-8,1,4,13.4005146026611,4.99591665017277,33.2800000905991,-0.00139429837301786,-4.54323510188503E-5,10,1.28530819464082E-7,,,,,,,,,,,,,,,,,,,,,50.0101280212402,50.0106201171875,249.952377319336,249.952377319336,53.4688621150249,5.63976732206088,4.69557857513428,54,2,0,0,1,0.298690795898438,33.7243423461914,1,1,3,50.0101280212402,0,50.0103740692139,,,,,,,,,,,,,,,,,,,,,,,,,,,,,,,,,
,3879781101.48228,50.0139789581299,100.126983642578,-2.43234508987908E-7,1.29839711374091E-8,1,4,13.4005146026611,4.99585591082591,33.2800000905991,-3.22757808885254E-4,9.37328110303533E-5,10,1.11885393279355E-7,,,,,,,,,,,,,,,,,,,,,50.0138244628906,50.0141334533691,100.126983642578,100.126983642578,53.4833222426306,5.63955791363648,4.69431400299072,54,3,0,0,1,0.29876708984375,33.7243423461914,1,1,3,50.0138244628906,0,50.0139789581299,,,,,,,,,,,,,,,,,,,,,,,,,,,,,,,,,
,3879781223.98631,50.0079116821289,-99.9255676269531,7.71181967972463E-7,2.71068675691195E-8,1,4,13.4005146026611,4.99598647091578,33.2800000905991,9.11460445417941E-4,4.50764298451578E-4,1,2.47699957884786E-7,,,,,,,,,,,,,,,,,,,,,50.0066261291504,50.0091972351074,-99.9255676269531,-99.9255676269531,53.4153205614576,5.63824886730256,4.70087051391602,52,1,68,0,0,0.299072265625,33.7243423461914,1,1,3,50.0091972351074,0,50.0079116821289,,,,,,,,,,,,,,,,,,,,,,,,,,,,,,,,,
,3879781336.89681,50.0154838562012,-249.8642578125,1.68671781512428E-6,2.01234580952135E-8,1,4,13.4005146026611,4.99606187635628,33.2800000905991,0.0020710577330793,4.67971600175869E-4,10,1.24592932471499E-7,,,,,,,,,,,,,,,,,,,,,50.0153121948242,50.0156555175781,-249.8642578125,-249.8642578125,53.3860094919864,5.63843652858449,4.68987941741943,54,2,0,0,1,0.2984619140625,33.7243423461914,1,1,3,50.0148773193359,0,50.0154838562012,,,,,,,,,,,,,,,,,,,,,,,,,,,,,,,,,
,3879781415.26427,50.0131225585937,-399.865905761719,2.51198083184384E-6,7.57654772495475E-9,1,4,13.4005146026611,4.99605658607438,33.2899987697601,0.00310648520676316,5.49052333330357E-4,1,6.64436867962618E-8,,,,,,,,,,,,,,,,,,,,,50.0122222900391,50.0140228271484,-399.865905761719,-399.865905761719,53.2574316005729,5.63848991324159,4.70099925994873,53,3,68,0,0,0.298843383789063,33.7243423461914,1,1,3,50.0122222900391,0,50.0131225585937,,,,,,,,,,,,,,,,,,,,,,,,,,,,,,,,,
,3879781538.6026,50.0003528594971,-599.742248535156,3.59004649826234E-6,1.57545627331337E-8,1,4,13.4005146026611,4.99602620846461,33.2800000905991,0.004417646163442,9.31814437465975E-4,10,2.13464311908796E-7,,,,,,,,,,,,,,,,,,,,,50.000301361084,50.0004043579102,-599.742248535156,-599.742248535156,53.4286082462845,5.63924691250499,4.69970321655273,54,1,0,0,1,0.2984619140625,33.2355842590332,1,1,3,50.0004043579102,0,50.0003528594971,,,,,,,,,,,,,,,,,,,,,,,,,,,,,,,,,
,3879781645.00241,50.0000476837158,-749.743896484375,4.50532529468899E-6,2.16294223417346E-8,1,4,13.4005146026611,4.99592987900129,33.2800000905991,0.00557151346547319,9.83895985860852E-4,1,1.18513783906944E-7,,,,,,,,,,,,,,,,,,,,,49.9999771118164,50.0001182556152,-749.743896484375,-749.743896484375,53.4884028280057,5.63935599862574,4.69571256637573,54,2,0,0,1,0.299530029296875,33.7243423461914,1,1,3,49.9999961853027,0,50.0000476837158,,,,,,,,,,,,,,,,,,,,,,,,,,,,,,,,,
,3879781741.57769,50.0060214996338,-899.669982910156,5.37327042370347E-6,8.93434001162645E-9,1,4,13.4005146026611,4.99602973284011,33.2800000905991,0.00665473563025342,0.00110869126980655,1,8.91663718505356E-8,,,,,,,,,,,,,,,,,,,,,50.005313873291,50.0067291259766,-899.669982910156,-899.669982910156,53.4235276609095,5.6380422459949,4.69316625595093,54,3,0,0,1,0.299301147460937,33.7243423461914,1,1,3,50.005313873291,0,50.0060214996338,,,,,,,,,,,,,,,,,,,,,,,,,,,,,,,,,
,3879781848.67021,50.0199871063232,-1099.68469238281,6.50538745919707E-6,5.84186834268362E-8,1,4,13.4005146026611,4.99601933960541,33.2800000905991,0.00804406653759434,0.00142757964979483,10,1.76654634626489E-7,,,,,,,,,,,,,,,,,,,,,50.0183715820313,50.0216026306152,-1099.68469238281,-1099.68469238281,53.498173184496,5.63817078347203,4.70171546936035,54,1,0,0,1,0.300521850585937,33.7243423461914,1,1,3,50.0216026306152,0,50.0199871063232,,,,,,,,,,,,,,,,,,,,,,,,,,,,,,,,,
,3879781944.19147,50.0022315979004,-1249.64868164062,7.46759771360166E-6,1.02993906908998E-8,1,4,13.4005146026611,4.99592982649963,33.2800000905991,0.00925248705787831,0.00151264146983561,1,1.01256118847367E-7,,,,,,,,,,,,,,,,,,,,,50.0021514892578,50.002311706543,-1249.64868164062,-1249.64868164062,53.4493214020441,5.63923859821483,4.69554805755615,54,2,0,0,1,0.298919677734375,33.2355842590332,1,1,3,50.0021514892578,0,50.0022315979004,,,,,,,,,,,,,,,,,,,,,,,,,,,,,,,,,
,3879782030.35808,50.0015850067139,-1399.56225585938,8.37731282962761E-6,5.91951628042457E-9,1,4,13.4005146026611,4.995896055735,33.2800000905991,0.0103886383491406,0.00163609153527629,1,6.46141330855137E-8,,,,,,,,,,,,,,,,,,,,,50.0015449523926,50.0016250610352,-1399.56225585938,-1399.56225585938,53.328559795823,5.63932320740317,4.69748830795288,54,3,0,0,1,0.29815673828125,33.7243423461914,1,1,3,50.0014343261719,0,50.0015850067139,,,,,,,,,,,,,,,,,,,,,,,,,,,,,,,,,
,3879782122.41408,50.0034294128418,-1599.5517578125,9.54828394044617E-6,8.72234120222254E-9,1,4,13.4005146026611,4.99581694689015,33.2800000905991,0.0118268825839808,0.00195568784077638,1,1.46901478580959E-7,,,,,,,,,,,,,,,,,,,,,50.0031661987305,50.0036926269531,-1599.5517578125,-1599.5517578125,53.340675037871,5.63948457833781,4.70112180709839,54,1,0,0,1,0.298080444335937,33.2355842590332,1,1,3,50.0036926269531,0,50.0034294128418,,,,,,,,,,,,,,,,,,,,,,,,,,,,,,,,,
,3879782205.62631,49.9999618530273,-1749.69189453125,1.04941567050288E-5,8.17931305236334E-9,1,4,13.4005146026611,4.99559836743744,33.2800000905991,0.0130090736911245,0.0020731370955081,1,1.00109998176124E-7,,,,,,,,,,,,,,,,,,,,,49.9999237060547,50,-1749.69189453125,-1749.69189453125,53.4692529292845,5.63992001038072,4.70155715942383,54,2,0,0,1,0.299530029296875,33.7243423461914,1,1,3,49.9999237060547,0,49.9999618530273,,,,,,,,,,,,,,,,,,,,,,,,,,,,,,,,,
,3879782278.82325,50.000020980835,-1899.8193359375,1.14068669979536E-5,7.57606564917944E-9,1,4,13.4005146026611,4.99552431150935,33.2800000905991,0.0141458529284585,0.00221574797012961,1,7.84883529236922E-8,,,,,,,,,,,,,,,,,,,,,50.0000038146973,50.0000381469727,-1899.8193359375,-1899.8193359375,53.3144904824768,5.64089075161244,4.69959449768066,54,3,0,0,1,0.298614501953125,33.7243423461914,1,1,3,50.0000381469727,0,50.000020980835,,,,,,,,,,,,,,,,,,,,,,,,,,,,,,,,,
,3879782361.04776,50.0215644836426,-2099.79638671875,1.25831791634706E-5,4.83317342423496E-8,1,4,13.4005146026611,4.99535872680391,33.2800000905991,0.0155879349818369,0.00255080895608417,1,1.72521498102341E-7,,,,,,,,,,,,,,,,,,,,,50.0202751159668,50.0228538513184,-2099.79638671875,-2099.79638671875,53.3930441486595,5.64230528910669,4.69665908813477,52,1,68,0,0,0.299301147460937,33.7243423461914,1,1,3,50.0202751159668,0,50.0215644836426,,,,,,,,,,,,,,,,,,,,,,,,,,,,,,,,,
,3879782440.00447,50.0075359344482,-2249.76025390625,1.35563704461961E-5,3.88868011375275E-9,1,4,13.4005146026611,4.99524930417563,33.2800000905991,0.01681552619692,0.00259742910271384,10,6.45586549616281E-8,,,,,,,,,,,,,,,,,,,,,50.0074729919434,50.0075988769531,-2249.76025390625,-2249.76025390625,53.3957798484768,5.64234066420016,4.69662380218506,54,2,0,0,1,0.299758911132812,33.2355842590332,1,1,3,50.0074729919434,0,50.0075359344482,,,,,,,,,,,,,,,,,,,,,,,,,,,,,,,,,
,3879782516.12475,50.0008945465088,-2399.673828125,1.44605103783844E-5,7.53319657313956E-9,1,4,13.4005146026611,4.99523257677832,33.2800000905991,0.017936844855635,0.00277135990250229,1,6.94353050862668E-8,,,,,,,,,,,,,,,,,,,,,50.0007171630859,50.0010719299316,-2399.673828125,-2399.673828125,53.4989548130153,5.64151117633979,4.69587564468384,54,3,0,0,1,0.299224853515625,33.7243423461914,1,1,3,50.0007019042969,0,50.0008945465088,,,,,,,,,,,,,,,,,,,,,,,,,,,,,,,,,
,3879782598.4505,50.028392791748,-2599.7265625,1.5662239504133E-5,7.68557673500963E-9,1,4,13.4005146026611,4.99553789134488,33.2800000905991,0.0194271577169947,0.00301514628369819,1,8.58531558571921E-8,,,,,,,,,,,,,,,,,,,,,50.0280799865723,50.0287055969238,-2599.7265625,-2599.7265625,53.6021297775537,5.64107664573296,4.70073556900024,54,1,0,0,1,0.299148559570313,33.7243423461914,1,1,3,50.0287055969238,0,50.028392791748,,,,,,,,,,,,,,,,,,,,,,,,,,,,,,,,,
,3879782669.82147,50.0155506134033,-2749.61474609375,1.65922483840778E-5,7.87686806154081E-9,1,4,13.4005146026611,4.99561378684883,33.2800000905991,0.0205859474246586,0.00316225968746309,1,6.51814187989508E-8,,,,,,,,,,,,,,,,,,,,,50.0153579711914,50.0157432556152,-2749.61474609375,-2749.61474609375,53.467689672246,5.63976309620619,4.70091009140015,53,2,68,0,0,0.299301147460937,33.2355842590332,1,1,3,50.0153579711914,0,50.0155506134033,,,,,,,,,,,,,,,,,,,,,,,,,,,,,,,,,
,3879782741.72617,50.0052318572998,-2899.56616210937,1.75143091543408E-5,8.0819980546783E-9,1,4,13.4005146026611,4.99561126737338,33.2800000905991,0.0217345656230568,0.00330700039517794,1,4.38409626011026E-8,,,,,,,,,,,,,,,,,,,,,50.0046272277832,50.0058364868164,-2899.56616210937,-2899.56616210937,53.4602642013134,5.6401939161434,4.69196128845215,54,3,0,0,1,0.299911499023438,33.7243423461914,1,1,3,50.0046272277832,0,50.0052318572998,,,,,,,,,,,,,,,,,,,,,,,,,,,,,,,,,
,3879782841.96203,50.000244140625,-3499.736328125,2.12173398392621E-5,6.34168507895242E-9,1,4,13.4005146026611,4.99528882591489,33.2800000905991,0.0263441593570284,0.00389447175603057,1,-3.66027515481241E-8,,,,,,,,,,,,,,,,,,,,,50.0001487731934,50.0003395080566,-3499.736328125,-3499.736328125,53.3164445537749,5.64147732845498,4.6933970451355,54,1,0,0,1,0.2984619140625,33.2355842590332,1,1,3,50.0003395080566,0,50.000244140625,,,,,,,,,,,,,,,,,,,,,,,,,,,,,,,,,
,3879782924.93933,50.0106353759766,-4999.70263671875,3.04033796082704E-5,8.60054690818953E-9,1,4,13.4005146026611,4.99538416744713,33.2800000905991,0.0377509668760575,0.00558003614874966,1,-5.30097355009874E-8,,,,,,,,,,,,,,,,,,,,,50.0096664428711,50.011604309082,-4999.70263671875,-4999.70263671875,53.4915293420826,5.64025193885112,4.6929087638855,54,2,0,0,1,0.2996826171875,33.7243423461914,1,1,3,50.0096664428711,0,50.0106353759766,,,,,,,,,,,,,,,,,,,,,,,,,,,,,,,,,
,3879783008.80671,50.0101165771484,-6499.744140625,3.96086965199942E-5,9.81043333510834E-9,1,4,13.4005146026611,4.99536078109578,33.2800000905991,0.0491805916768497,0.0072696010848538,1,-6.89554545815964E-8,,,,,,,,,,,,,,,,,,,,,50.0093116760254,50.0109214782715,-6499.744140625,-6499.744140625,53.379365649573,5.63987311236759,4.69730186462402,54,3,0,0,1,0.300445556640625,33.7243423461914,1,1,3,50.0093116760254,0,50.0101165771484,,,,,,,,,,,,,,,,,,,,,,,,,,,,,,,,,
,3879783108.09161,50.0295791625977,-8499.75390625,5.1898773223526E-5,1.79280247946515E-8,1,4,13.4005146026611,4.99520799479463,33.2800000905991,0.0644372944645702,0.00952921201395785,1,-8.68439297421129E-8,,,,,,,,,,,,,,,,,,,,,50.0258407592773,50.033317565918,-8499.75390625,-8499.75390625,53.5868880214287,5.64132743243261,4.7036247253418,54,1,0,0,1,0.300216674804687,33.2355842590332,1,1,3,50.033317565918,0,50.0295791625977,,,,,,,,,,,,,,,,,,,,,,,,,,,,,,,,,
,3879783192.42501,50.0283699035645,-9999.7197265625,6.10912738816511E-5,1.30893759504964E-8,1,4,13.4005146026611,4.99525987130602,33.2800000905991,0.0758500381301502,0.0112287822077915,1,-9.29147551126653E-8,,,,,,,,,,,,,,,,,,,,,50.0265998840332,50.0301399230957,-9999.7197265625,-9999.7197265625,53.4375969742557,5.64173169068139,4.70538806915283,54,2,0,0,1,0.298995971679687,33.7243423461914,1,1,3,50.0265998840332,0,50.0283699035645,,,,,,,,,,,,,,,,,,,,,,,,,,,,,,,,,
,3879783381.15257,50.036470413208,-19999.62890625,1.22561634407369E-4,2.6282454572537E-8,1,4,13.4005146026611,4.99525428743607,33.2899987697601,0.152162155970988,0.0225830278550762,1,-1.41436075119899E-7,,,,,,,,,,,,,,,,,,,,,50.0355453491211,50.0373954772949,-19999.62890625,-19999.62890625,53.4493214020441,5.64258542734398,4.69529962539673,54,3,0,0,1,0.299606323242188,33.2355842590332,1,1,3,50.0352973937988,0,50.036470413208,,,,,,,,,,,,,,,,,,,,,,,,,,,,,,,,,
,3879783664.95916,50.0087127685547,-39999.62109375,2.45582330594606E-4,3.84992821779213E-8,1,4,13.4005146026611,4.99526128132846,33.2800000905991,0.30488215831455,0.0453355185363922,1,-2.15096261802272E-7,,,,,,,,,,,,,,,,,,,,,50.0075416564941,50.0098838806152,-39999.62109375,-39999.62109375,53.1358883658326,5.64222919481497,4.70460987091064,54,1,0,0,1,0.300369262695313,33.7243423461914,1,1,3,50.0098838806152,0,50.0087127685547,,,,,,,,,,,,,,,,,,,,,,,,,,,,,,,,,
,3879783918.75369,50.0005626678467,-54999.87109375,3.38114347351687E-4,9.12930619294708E-8,1,4,13.4005146026611,4.99547942353082,33.2800000905991,0.419851768795613,0.0619627695826282,10,-6.65376924223395E-7,,,,,,,,,,,,,,,,,,,,,50.0005569458008,50.0005683898926,-54999.87109375,-54999.87109375,53.4078950905249,5.64213245625051,4.70400094985962,54,2,0,0,1,0.300216674804687,33.7243423461914,1,1,3,50.0005569458008,0,50.0005626678467,,,,,,,,,,,,,,,,,,,,,,,,,,,,,,,,,
,3879784167.98849,50.0011501312256,-69999.5234375,4.30295152356564E-4,1.39450923168668E-7,1,4,13.4005146026611,4.99483880527131,33.2800000905991,0.534103397273045,0.0796267761144979,1,-2.14198235139376E-7,,,,,,,,,,,,,,,,,,,,,50.0010757446289,50.0012245178223,-69999.5234375,-69999.5234375,53.1370608086114,5.64491548596053,4.70300722122192,54,3,0,0,1,0.299453735351562,34.2131004333496,1,1,3,50.0010757446289,0,50.0011501312256,,,,,,,,,,,,,,,,,,,,,,,,,,,,,,,,,
,3879784451.5245,50.0004367828369,-49999.6015625,3.06996490246483E-4,5.96720940730842E-8,1,4,13.4005146026611,4.99479414572108,33.2800000905991,0.381056814294098,0.0567926028123757,1,-1.66401846617754E-7,,,,,,,,,,,,,,,,,,,,,50.0003433227539,50.0005302429199,-49999.6015625,-49999.6015625,53.4739427003999,5.64473733049879,4.70125770568848,54,1,0,0,1,0.298919677734375,33.7243423461914,1,1,3,50.0005302429199,0,50.0004367828369,,,,,,,,,,,,,,,,,,,,,,,,,,,,,,,,,
,3879784673.33378,50.0323143005371,-34999.56640625,2.14685300201028E-4,4.15912489463819E-8,1,4,13.4005146026611,4.99503654497271,33.2899987697601,0.266507933926293,0.0396280444066336,1,-1.8904719526855E-7,,,,,,,,,,,,,,,,,,,,,50.0314750671387,50.0331535339355,-34999.56640625,-34999.56640625,53.4907477135634,5.64428594654555,4.7042179107666,54,2,0,0,1,0.30029296875,34.2131004333496,1,1,3,50.0331535339355,0,50.0323143005371,,,,,,,,,,,,,,,,,,,,,,,,,,,,,,,,,
,3879784894.21903,50.0415935516357,-19999.81640625,1.22357035636873E-4,2.45078574385957E-8,1,4,13.4005146026611,4.99513643212694,33.2800000905991,0.151897068529226,0.0225850618226701,1,-1.08589537192837E-7,,,,,,,,,,,,,,,,,,,,,50.0405883789063,50.0425987243652,-19999.81640625,-19999.81640625,53.5919686068037,5.64275437183008,4.70517730712891,54,3,0,0,1,0.299911499023438,34.2131004333496,1,1,3,50.0405883789063,0,50.0415935516357,,,,,,,,,,,,,,,,,,,,,,,,,,,,,,,,,
,3879785096.12204,50.0332469940186,-9500.318359375,5.77417464150986E-5,1.16014593968282E-8,1,4,13.4005146026611,4.99516760012766,33.2800000905991,0.071679258948194,0.0106810367151853,1,-3.28899905142206E-8,,,,,,,,,,,,,,,,,,,,,50.0321197509766,50.0343742370605,-9500.318359375,-9500.318359375,53.3715493643806,5.64225634869657,4.69844102859497,54,1,0,0,1,0.298919677734375,34.2131004333496,1,1,3,50.0343742370605,0,50.0332469940186,,,,,,,,,,,,,,,,,,,,,,,,,,,,,,,,,
,3879785180.26192,50.0257396697998,-8000.33935546875,4.85278395908615E-5,1.24362173377321E-8,1,4,13.4005146026611,4.99500464451202,33.2800000905991,0.0602418123118076,0.00895461703466609,1,-4.50650282463073E-8,,,,,,,,,,,,,,,,,,,,,50.0257263183594,50.0257530212402,-8000.33935546875,-8000.33935546875,53.3758483212364,5.64258529390292,4.70551490783691,54,2,0,0,1,0.29998779296875,34.2131004333496,1,1,3,50.0257530212402,0,50.0257396697998,,,,,,,,,,,,,,,,,,,,,,,,,,,,,,,,,
,3879785265.23957,50.0387763977051,-6500.26025390625,3.93083818188455E-5,1.04015572475616E-8,1,4,13.4005146026611,4.99496301710909,33.2800000905991,0.0487970589327844,0.00724844201014011,1,-4.04243310715042E-8,,,,,,,,,,,,,,,,,,,,,50.0374374389648,50.0401153564453,-6500.26025390625,-6500.26025390625,53.4958282989384,5.64320408595114,4.70258045196533,54,3,0,0,1,0.302200317382812,34.2131004333496,1,1,3,50.0374374389648,0,50.0387763977051,,,,,,,,,,,,,,,,,,,,,,,,,,,,,,,,,
,3879785363.84124,50.0200881958008,-4500.38916015625,2.6988889473775E-5,8.1917166989111E-9,1,4,13.4005146026611,4.99481187995855,33.2800000905991,0.0334938994932259,0.00503292042188778,1,1.76837728891071E-8,,,,,,,,,,,,,,,,,,,,,50.0162239074707,50.0239524841309,-4500.38916015625,-4500.38916015625,53.5395994960153,5.64323626771853,4.69750261306763,54,1,0,0,1,0.299835205078125,33.7243423461914,1,1,3,50.0239524841309,0,50.0200881958008,,,,,,,,,,,,,,,,,,,,,,,,,,,,,,,,,
,3879785449.14472,50.0030994415283,-3000.41064453125,1.77794073940028E-5,6.3911507074942E-9,1,4,13.4005146026611,4.99509579326233,33.2800000905991,0.0220677450859132,0.00330716018826126,1,4.69765007920953E-9,,,,,,,,,,,,,,,,,,,,,50.0029258728027,50.0032730102539,-3000.41064453125,-3000.41064453125,53.516541454698,5.64193032042866,4.70390844345093,52,2,68,0,0,0.300674438476562,38.1231689453125,1,1,3,50.0032730102539,0,50.0030994415283,,,,,,,,,,,,,,,,,,,,,,,,,,,,,,,,,
,3879785536.80806,50.011302947998,-2900.40942382812,1.72428704862218E-5,8.69195275922409E-9,1,4,13.4005146026611,4.99502111096168,33.2800000905991,0.0214248740324549,0.00305003194618814,1,-1.22141614959086E-7,,,,,,,,,,,,,,,,,,,,,50.0099601745605,50.0126457214355,-2900.40942382812,-2900.40942382812,53.5255301826691,5.64204930000703,4.70055532455444,54,3,0,0,1,0.299911499023438,34.2131004333496,1,1,3,50.0099601745605,0,50.011302947998,,,,,,,,,,,,,,,,,,,,,,,,,,,,,,,,,
,3879785618.36334,50.0084629058838,-2700.419921875,1.60587273210029E-5,1.54006895445735E-8,1,4,13.4005146026611,4.99508899830755,33.2800000905991,0.0199732335736581,0.00271148189869546,1,-2.17798558137124E-7,,,,,,,,,,,,,,,,,,,,,50.0078392028809,50.0090866088867,-2700.419921875,-2700.419921875,53.4489305877845,5.64225404882446,4.70161581039429,54,1,0,0,1,0.29998779296875,34.2131004333496,1,1,3,50.0078392028809,0,50.0084629058838,,,,,,,,,,,,,,,,,,,,,,,,,,,,,,,,,
,3879785689.75226,50.0309009552002,-2550.46850585938,1.51103353345737E-5,1.2574715230903E-8,1,4,13.4005146026611,4.99517274248059,33.2800000905991,0.0187821010262956,0.00263162507669323,1,-1.40310881064655E-7,,,,,,,,,,,,,,,,,,,,,50.0301170349121,50.0316848754883,-2550.46850585938,-2550.46850585938,53.5618759088134,5.64279772300479,4.70228910446167,53,2,68,0,0,0.300445556640625,34.2131004333496,1,1,3,50.0301170349121,0,50.0309009552002,,,,,,,,,,,,,,,,,,,,,,,,,,,,,,,,,
,3879785768.13088,50.0068283081055,-2400.39135742187,1.41883689817446E-5,7.08948209843866E-9,1,4,13.4005146026611,4.99501047312517,33.2800000905991,0.0176319294254121,0.00249345545366442,10,-1.1361185680648E-7,,,,,,,,,,,,,,,,,,,,,50.006721496582,50.0069351196289,-2400.39135742187,-2400.39135742187,53.4997364415345,5.64242754166813,4.70411396026611,54,3,0,0,1,0.299224853515625,33.2355842590332,1,1,3,50.006721496582,0,50.0068283081055,,,,,,,,,,,,,,,,,,,,,,,,,,,,,,,,,
,3879785856.02795,50.0147933959961,-2200.41430664062,1.29941716469555E-5,1.98501612984789E-8,1,4,13.4005146026611,4.99516942191249,33.2800000905991,0.0161676337205377,0.00215656369049754,1,-2.06465406757401E-7,,,,,,,,,,,,,,,,,,,,,50.0133857727051,50.0162010192871,-2200.41430664062,-2200.41430664062,53.5415535673134,5.64218970549916,4.70359659194946,52,1,68,0,0,0.301132202148438,34.2131004333496,1,1,3,50.0133857727051,0,50.0147933959961,,,,,,,,,,,,,,,,,,,,,,,,,,,,,,,,,
,3879785926.54635,50.0010795593262,-2050.40014648438,1.20326077356453E-5,1.30849343209923E-8,1,4,13.4005146026611,4.99500231968674,33.2899987697601,0.0149629395805358,0.00204764768501971,1,-1.5028958151071E-7,,,,,,,,,,,,,,,,,,,,,50.0010719299316,50.0010871887207,-2050.40014648438,-2050.40014648438,53.5247485541499,5.64287167263153,4.69693946838379,52,2,68,0,0,0.299835205078125,34.2131004333496,1,1,3,50.0010871887207,0,50.0010795593262,,,,,,,,,,,,,,,,,,,,,,,,,,,,,,,,,
,3879785998.63742,50.0104389190674,-1900.46142578125,1.11122364199257E-5,1.17212788108129E-8,1,4,13.4005146026611,4.99496411768381,33.2800000905991,0.0138169466399118,0.00189991556864302,1,-1.31613636929468E-7,,,,,,,,,,,,,,,,,,,,,50.0097236633301,50.0111541748047,-1900.46142578125,-1900.46142578125,53.4379877885153,5.64299810144992,4.70338153839111,54,3,0,0,1,0.30059814453125,34.2131004333496,1,1,3,50.0097236633301,0,50.0104389190674,,,,,,,,,,,,,,,,,,,,,,,,,,,,,,,,,
,3879786079.7131,50.0098667144775,-1700.11938476562,9.95671887923463E-6,1.96006180002521E-8,1,4,13.4005146026611,4.99489747456801,33.2899987697601,0.0124044068618378,0.00153880137029418,1,-2.49671706338896E-7,,,,,,,,,,,,,,,,,,,,,50.0090255737305,50.0107078552246,-1700.11938476562,-1700.11938476562,53.533737282121,5.64265969085715,4.70708656311035,54,1,0,0,1,0.300140380859375,33.7243423461914,1,1,3,50.0090255737305,0,50.0098667144775,,,,,,,,,,,,,,,,,,,,,,,,,,,,,,,,,
,3879786150.94734,50.0134334564209,-1550.16809082031,9.00256403986108E-6,1.72206847512194E-8,1,4,13.4005146026611,4.99487695034116,33.2800000905991,0.0112034131284789,0.00147296267567982,1,-1.59974562778311E-7,,,,,,,,,,,,,,,,,,,,,50.0120582580566,50.0148086547852,-1550.16809082031,-1550.16809082031,53.4844946854095,5.6428358204462,4.70448732376099,54,2,0,0,1,0.300521850585937,34.2131004333496,1,1,3,50.0120582580566,0,50.0134334564209,,,,,,,,,,,,,,,,,,,,,,,,,,,,,,,,,
,3879786221.30779,50.0062580108643,-1400.19165039062,8.05845754209127E-6,1.23227001807915E-8,1,4,13.4005146026611,4.99484262659462,33.2800000905991,0.0100243983673708,0.00134526391485099,1,-1.21617424807345E-7,,,,,,,,,,,,,,,,,,,,,50.0058326721191,50.0066833496094,-1400.19165039062,-1400.19165039062,53.452447916121,5.64296747519494,4.70430421829224,54,3,0,0,1,0.299530029296875,33.7243423461914,1,1,3,50.0058326721191,0,50.0062580108643,,,,,,,,,,,,,,,,,,,,,,,,,,,,,,,,,
,3879786314.81224,50.0109710693359,-1200.15161132812,6.87225950443499E-6,2.14107399278451E-8,1,4,13.4005146026611,4.99479766761874,33.2800000905991,0.00856813721288042,0.00101734631486243,1,-2.08362150612561E-7,,,,,,,,,,,,,,,,,,,,,50.0100364685059,50.011905670166,-1200.15161132812,-1200.15161132812,53.3735034356787,5.64325512551102,4.7049560546875,54,1,0,0,1,0.300369262695313,34.7018585205078,1,1,3,50.0100364685059,0,50.0109710693359,,,,,,,,,,,,,,,,,,,,,,,,,,,,,,,,,
,3879786386.33472,50.0286045074463,-1050.16259765625,5.93837576749225E-6,1.59378610278635E-8,1,4,13.4005146026611,4.99473698865275,33.2800000905991,0.00739759556695077,9.19699294995885E-4,1,-1.47321413289059E-7,,,,,,,,,,,,,,,,,,,,,50.027229309082,50.0299797058105,-1050.16259765625,-1050.16259765625,53.4891844565249,5.64372034433862,4.70934772491455,53,2,68,0,0,0.300827026367188,33.7243423461914,1,1,3,50.027229309082,0,50.0286045074463,,,,,,,,,,,,,,,,,,,,,,,,,,,,,,,,,
,3879786457.48569,50.0162467956543,-900.211303710937,5.00195973381893E-6,1.69038760279831E-8,1,4,13.4005146026611,4.99495462655332,33.2800000905991,0.00623033230943019,7.82238729581794E-4,1,-1.18032967603691E-7,,,,,,,,,,,,,,,,,,,,,50.0157165527344,50.0167770385742,-900.211303710937,-900.211303710937,53.5544504378807,5.64284190847608,4.70271492004395,53,3,68,0,0,0.30120849609375,33.7243423461914,1,1,3,50.0157165527344,0,50.0162467956543,,,,,,,,,,,,,,,,,,,,,,,,,,,,,,,,,
,3879786563.41623,50.0320377349854,-700.196533203125,3.85152924341598E-6,2.3538391593729E-8,1,4,13.4005146026611,4.99475049015379,33.2800000905991,0.00482650326993381,4.0578187656942E-4,1,-2.49218433849674E-7,,,,,,,,,,,,,,,,,,,,,50.0306663513184,50.0334091186523,-700.196533203125,-700.196533203125,53.4735518861403,5.64389707436797,4.70680093765259,52,1,68,0,0,0.300521850585937,33.7243423461914,1,1,3,50.0334091186523,0,50.0320377349854,,,,,,,,,,,,,,,,,,,,,,,,,,,,,,,,,
,3879786635.7192,50.0161609649658,-550.19482421875,2.92557487412892E-6,1.71220218229692E-8,1,4,13.4005146026611,4.99483472777657,33.2800000905991,0.0036629815944581,3.3001539483709E-4,1,-1.71754222304744E-7,,,,,,,,,,,,,,,,,,,,,50.0145950317383,50.0177268981934,-550.19482421875,-550.19482421875,53.3520086513999,5.64327426624974,4.69803285598755,54,2,0,0,1,0.300369262695313,33.7243423461914,1,1,3,50.0145950317383,0,50.0161609649658,,,,,,,,,,,,,,,,,,,,,,,,,,,,,,,,,
,3879786705.90245,50.0044708251953,-400.256164550781,2.02483315120207E-6,1.53160251546041E-8,1,4,13.4005146026611,4.99485033903554,33.2800000905991,0.00253938164347971,2.00551250203946E-4,1,-1.4131891696535E-7,,,,,,,,,,,,,,,,,,,,,50.0040245056152,50.0049171447754,-400.256164550781,-400.256164550781,53.3277781673037,5.64364029030088,4.70683717727661,53,3,68,0,0,0.301589965820313,33.7243423461914,1,1,3,50.0040245056152,0,50.0044708251953,,,,,,,,,,,,,,,,,,,,,,,,,,,,,,,,,
,3879786798.07732,50.0063934326172,-200.153259277344,8.6814316168282E-7,2.90908253527353E-8,1,4,13.4005146026611,4.99482371657887,33.2800000905991,0.00112102232613631,-1.29769940356871E-4,1,-2.34424975299454E-7,,,,,,,,,,,,,,,,,,,,,50.0063896179199,50.0063972473145,-200.153259277344,-200.153259277344,53.3992971768133,5.64383158353121,4.70196485519409,54,1,0,0,1,0.300521850585937,33.7243423461914,1,1,3,50.0063972473145,0,50.0063934326172,,,,,,,,,,,,,,,,,,,,,,,,,,,,,,,,,
,3879786869.12571,50.0181903839111,-50.2397232055664,-1.44721099558531E-8,2.12722560963173E-8,1,4,13.4005146026611,4.99475934577392,33.2800000905991,1.72935341137266E-5,-2.38360354440642E-4,1,-1.89886317557398E-7,,,,,,,,,,,,,,,,,,,,,50.017162322998,50.0192184448242,-50.2397232055664,-50.2397232055664,53.4872303852268,5.64342326584118,4.70517730712891,52,2,68,0,0,0.299835205078125,33.7243423461914,1,1,3,50.0170860290527,0,50.0181903839111,,,,,,,,,,,,,,,,,,,,,,,,,,,,,,,,,
,3879786941.05856,50.0219764709473,99.7745132446289,-8.21944175030004E-7,5.70517548682083E-9,1,4,13.4005146026611,4.99495705167386,33.2800000905991,-0.00102402347050365,-1.27023726555991E-4,1,2.06181427247509E-8,,,,,,,,,,,,,,,,,,,,,50.0213088989258,50.0226440429687,99.7745132446289,99.7745132446289,53.4223552181307,5.64351280083392,4.70691776275635,54,3,0,0,1,0.300674438476562,33.2355842590332,1,1,3,50.0213088989258,0,50.0219764709473,,,,,,,,,,,,,,,,,,,,,,,,,,,,,,,,,
,3879787023.17607,50.0183334350586,299.587890625,-1.89877285673632E-6,1.64313427210581E-8,1,4,13.4005146026611,4.99491251404658,33.2800000905991,-0.00231597076889123,-6.2497037151966E-4,1,-2.19483597726905E-7,,,,,,,,,,,,,,,,,,,,,50.0164031982422,50.020263671875,299.587890625,299.587890625,53.496219113198,5.64295937311361,4.7009654045105,53,1,68,0,0,0.29998779296875,33.7243423461914,1,1,3,50.020263671875,0,50.0183334350586,,,,,,,,,,,,,,,,,,,,,,,,,,,,,,,,,
,3879787095.00319,50.0043087005615,449.753173828125,-2.74856826299518E-6,2.18442495970252E-8,1,4,13.4005146026611,4.99505425992004,33.2800000905991,-0.00338310561411312,-7.00897503282886E-4,1,-1.5351023228393E-7,,,,,,,,,,,,,,,,,,,,,50.0040473937988,50.0045700073242,449.753173828125,449.753173828125,53.4852763139287,5.64283822563067,4.70450735092163,54,2,0,0,1,0.300827026367188,33.7243423461914,1,1,3,50.0040473937988,0,50.0043087005615,,,,,,,,,,,,,,,,,,,,,,,,,,,,,,,,,
,3879787166.46778,50.0145683288574,599.742248535156,-3.62231636874566E-6,7.68382830090729E-9,1,4,13.4005146026611,4.9950831698128,33.2800000905991,-0.00447734348634398,-7.9844743648576E-4,1,-1.01388931113584E-7,,,,,,,,,,,,,,,,,,,,,50.0143814086914,50.0147552490234,599.742248535156,599.742248535156,53.5415535673134,5.64246744681168,4.69985198974609,52,3,68,0,0,0.301895141601562,33.7243423461914,1,1,3,50.0143814086914,0,50.0145683288574,,,,,,,,,,,,,,,,,,,,,,,,,,,,,,,,,
,3879787248.75703,50.0067043304443,799.593383789063,-4.72276097154665E-6,2.28889653438487E-8,1,4,13.4005146026611,4.99518763029994,33.2800000905991,-0.00582400305543798,-0.00113268899145289,1,-2.06022491730657E-7,,,,,,,,,,,,,,,,,,,,,50.0060615539551,50.0073471069336,799.593383789063,799.593383789063,53.3586524938133,5.64324664068955,4.70148086547852,54,1,0,0,1,0.300827026367188,33.7243423461914,1,1,3,50.0060615539551,0,50.0067043304443,,,,,,,,,,,,,,,,,,,,,,,,,,,,,,,,,
,3879787330.92858,50.0001220703125,949.733459472656,-5.66663863231954E-6,2.17135102492664E-8,1,4,13.4005146026611,4.99514988042191,33.2800000905991,-0.00701182383513018,-0.00119911120845806,1,-1.1834558841732E-7,,,,,,,,,,,,,,,,,,,,,50.0000991821289,50.0001449584961,949.733459472656,949.733459472656,53.2687652141018,5.64286931932545,4.70011568069458,54,2,0,0,1,0.299606323242188,33.7243423461914,1,1,3,50.0000991821289,0,50.0001220703125,,,,,,,,,,,,,,,,,,,,,,,,,,,,,,,,,
,3879787402.66172,50.0017528533936,1099.7099609375,-6.53955604213299E-6,2.40924861975381E-8,1,4,13.4005146026611,4.99514809826286,33.2800000905991,-0.00809589745924459,-0.00135748168803516,1,-1.1535105812936E-7,,,,,,,,,,,,,,,,,,,,,50.0016593933105,50.0018463134766,1099.7099609375,1099.7099609375,53.4004696195922,5.64249554392425,4.70028400421143,52,3,68,0,0,0.299530029296875,34.2131004333496,1,1,3,50.0016593933105,0,50.0017528533936,,,,,,,,,,,,,,,,,,,,,,,,,,,,,,,,,
,3879787498.18306,50.0287857055664,1299.59887695312,-7.78353604346666E-6,1.08474454709137E-7,1,4,13.4005146026611,4.99500191766819,33.2800000905991,-0.00964599472017263,-0.00154572603053586,1,-8.09656985160082E-8,,,,,,,,,,,,,,,,,,,,,50.026237487793,50.0313339233398,1299.59887695312,1299.59887695312,53.4344704601787,5.64265811795078,4.70306205749512,54,1,0,0,1,0.300216674804687,34.2131004333496,1,1,3,50.0313339233398,0,50.0287857055664,,,,,,,,,,,,,,,,,,,,,,,,,,,,,,,,,
,3879787583.74624,50.0120124816895,1449.65087890625,-8.65587929736574E-6,8.41860098053692E-9,1,4,13.4005146026611,4.99511249611231,33.2800000905991,-0.0107222802151369,-0.0017532850308544,1,-1.17647395273816E-7,,,,,,,,,,,,,,,,,,,,,50.0116119384766,50.0124130249023,1449.65087890625,1449.65087890625,53.4000788053326,5.64220062702155,4.69887256622314,54,2,0,0,1,0.300369262695313,34.7018585205078,1,1,3,50.0124130249023,0,50.0120124816895,,,,,,,,,,,,,,,,,,,,,,,,,,,,,,,,,
,3879787655.98417,50.021915435791,1599.82873535156,-9.60960312031833E-6,5.28105540573392E-8,1,4,13.4005146026611,4.99508287747146,33.2800000905991,-0.0119223937335699,-0.00182072287260814,1,-2.93188772312134E-8,,,,,,,,,,,,,,,,,,,,,50.0207214355469,50.0231094360352,1599.82873535156,1599.82873535156,53.3695952930826,5.64265602163129,4.71070289611816,54,3,0,0,1,0.300674438476562,33.7243423461914,1,1,3,50.0207214355469,0,50.021915435791,,,,,,,,,,,,,,,,,,,,,,,,,,,,,,,,,
,3879787738.99963,50.0009746551514,1799.52880859375,-1.07875650374592E-5,8.84890191665E-9,1,4,13.4005146026611,4.99516788187837,33.2800000905991,-0.013367930953594,-0.00215258380142156,1,-1.20423801619269E-7,,,,,,,,,,,,,,,,,,,,,50.000919342041,50.0010299682617,1799.52880859375,1799.52880859375,53.411803233121,5.64245594880137,4.70334815979004,54,1,0,0,1,0.299758911132812,33.7243423461914,1,1,3,50.0009002685547,0,50.0009746551514,,,,,,,,,,,,,,,,,,,,,,,,,,,,,,,,,
,3879787810.73367,50.0135936737061,1949.8955078125,-1.17049231836298E-5,6.20545029320134E-9,1,4,13.4005146026611,4.99515289697109,33.2800000905991,-0.014511926537881,-0.0022870416773441,1,-9.15231507783356E-8,,,,,,,,,,,,,,,,,,,,,50.0131416320801,50.014045715332,1949.8955078125,1949.8955078125,53.3594341223326,5.64271888025558,4.70504713058472,54,2,0,0,1,0.300216674804687,33.7243423461914,1,1,3,50.014045715332,0,50.0135936737061,,,,,,,,,,,,,,,,,,,,,,,,,,,,,,,,,
,3879787882.44687,50.0016632080078,2099.78369140625,-1.26256318244963E-5,7.37154641022246E-9,1,4,13.4005146026611,4.99516169009523,33.2800000905991,-0.0156580523971635,-0.00243633084347864,1,-7.4057681722812E-8,,,,,,,,,,,,,,,,,,,,,50.0015029907227,50.001823425293,2099.78369140625,2099.78369140625,53.554059623621,5.6426271608579,4.69998788833618,53,3,68,0,0,0.300216674804687,33.7243423461914,1,1,3,50.0015029907227,0,50.0016632080078,,,,,,,,,,,,,,,,,,,,,,,,,,,,,,,,,
,3879787964.73195,50.0252494812012,2299.82373046875,-1.38306285279752E-5,6.78914199784461E-9,1,4,13.4005146026611,4.99512228698453,33.2800000905991,-0.017146198153507,-0.00270945069110321,1,-1.13854495925917E-7,,,,,,,,,,,,,,,,,,,,,50.0246086120605,50.0258903503418,2299.82373046875,2299.82373046875,53.4196195183133,5.64272540331583,4.70001602172852,54,1,0,0,1,0.298995971679687,33.2355842590332,1,1,3,50.0246086120605,0,50.0252494812012,,,,,,,,,,,,,,,,,,,,,,,,,,,,,,,,,
,3879788037.15974,50.0021991729736,2449.837890625,-1.47492198118786E-5,7.23768361162892E-9,1,4,13.4005146026611,4.9952202295913,33.2800000905991,-0.0182932876541717,-0.00283744115805021,1,-7.94898655293814E-8,,,,,,,,,,,,,,,,,,,,,50.0021286010742,50.002269744873,2449.837890625,2449.837890625,53.4207919610922,5.64252543915958,4.70588445663452,54,2,0,0,1,0.299072265625,33.7243423461914,1,1,3,50.0021286010742,0,50.0021991729736,,,,,,,,,,,,,,,,,,,,,,,,,,,,,,,,,
,3879788108.8467,50.0263576507568,2599.70141601562,-1.56743625173801E-5,7.26991896471559E-9,1,4,13.4005146026611,4.9951981182155,33.2800000905991,-0.0194454272887098,-0.00298320468031955,1,-5.85382478897976E-8,,,,,,,,,,,,,,,,,,,,,50.0256767272949,50.0270385742188,2599.70141601562,2599.70141601562,53.4000788053326,5.64285106145521,4.7025408744812,54,3,0,0,1,0.300521850585937,33.7243423461914,1,1,3,50.0256767272949,0,50.0263576507568,,,,,,,,,,,,,,,,,,,,,,,,,,,,,,,,,
,3879788191.53829,50.0118179321289,2799.80419921875,-1.68873914637492E-5,7.73735317774762E-9,1,4,13.4005146026611,4.99508395550188,33.2800000905991,-0.0209453398300978,-0.00324262172230948,1,-8.615150526324E-8,,,,,,,,,,,,,,,,,,,,,50.0105972290039,50.0130386352539,2799.80419921875,2799.80419921875,53.4938742276403,5.64344865215943,4.70548868179321,54,1,0,0,1,0.300979614257812,33.7243423461914,1,1,3,50.0105972290039,0,50.0118179321289,,,,,,,,,,,,,,,,,,,,,,,,,,,,,,,,,
,3879788263.18559,50.0217132568359,2949.79321289063,-1.77919394454792E-5,1.50459575964258E-8,1,4,13.4005146026611,4.99519329443546,33.2800000905991,-0.0220706690794309,-0.00339805113601575,1,-7.59736668874438E-8,,,,,,,,,,,,,,,,,,,,,50.0202751159668,50.0231513977051,2949.79321289063,2949.79321289063,53.4817589855922,5.64301419609317,4.7076416015625,54,2,0,0,1,0.29937744140625,33.7243423461914,1,1,3,50.0202751159668,0,50.0217132568359,,,,,,,,,,,,,,,,,,,,,,,,,,,,,,,,,
,3879788355.19563,50.0010032653809,3499.64819335937,-2.11988528630292E-5,6.42490880860426E-9,1,4,13.4005146026611,4.99505390573636,33.2800000905991,-0.0263209950582413,-0.00388063845350175,1,4.47753756736723E-8,,,,,,,,,,,,,,,,,,,,,50.0009384155273,50.0010681152344,3499.64819335937,3499.64819335937,53.4864487567076,5.64290836003134,4.70826482772827,54,3,0,0,1,0.300140380859375,33.7243423461914,1,1,3,50.0009384155273,0,50.0010032653809,,,,,,,,,,,,,,,,,,,,,,,,,,,,,,,,,
,3879788453.22815,50.0078239440918,5499.65771484375,-3.34726915327634E-5,8.72804957064864E-9,1,4,13.4005146026611,4.99554072108982,33.2800000905991,-0.0415675315088897,-0.00611910995314902,1,7.81108057256458E-8,,,,,,,,,,,,,,,,,,,,,50.0069847106934,50.0086631774902,5499.65771484375,5499.65771484375,53.3570892367749,5.64262905256723,4.70209217071533,54,1,0,0,1,0.300216674804687,33.2355842590332,1,1,3,50.0086631774902,0,50.0078239440918,,,,,,,,,,,,,,,,,,,,,,,,,,,,,,,,,
,3879788536.44158,50.0244235992432,6999.76220703125,-4.26567440741084E-5,1.03253233685307E-8,1,4,13.4005146026611,4.99540296021874,33.2800000905991,-0.0529650258766739,-0.00783470231743098,1,6.97637097703985E-8,,,,,,,,,,,,,,,,,,,,,50.0240211486816,50.0248260498047,6999.76220703125,6999.76220703125,53.5829798788326,5.64221154239603,4.70888757705688,54,2,0,0,1,0.299911499023438,33.7243423461914,1,1,3,50.0248260498047,0,50.0244235992432,,,,,,,,,,,,,,,,,,,,,,,,,,,,,,,,,
,3879788620.47079,50.0215358734131,8500.130859375,-5.18881337215958E-5,2.50168422056331E-8,1,4,13.4005146026611,4.99538878741549,33.2800000905991,-0.0644301174083482,-0.00950924323490493,1,1.01727819305187E-7,,,,,,,,,,,,,,,,,,,,,50.0200042724609,50.0230674743652,8500.130859375,8500.130859375,53.6095552484864,5.64273562250628,4.70068311691284,54,3,0,0,1,0.300521850585937,33.7243423461914,1,1,3,50.0200042724609,0,50.0215358734131,,,,,,,,,,,,,,,,,,,,,,,,,,,,,,,,,
,3879788726.64802,50.004789352417,9999.984375,-6.10597225804282E-5,1.16250150457872E-8,1,4,13.4005146026611,4.99537402900874,33.2800000905991,-0.0758123324334385,-0.0112297497581404,1,8.77049606227948E-8,,,,,,,,,,,,,,,,,,,,,50.0047416687012,50.0048370361328,9999.984375,9999.984375,53.4305623175826,5.64385907394979,4.70982646942139,54,1,0,0,1,0.299301147460937,33.7243423461914,1,1,3,50.0046691894531,0,50.004789352417,,,,,,,,,,,,,,,,,,,,,,,,,,,,,,,,,
,3879788944.79853,50.0345993041992,25000.236328125,-1.53294885677056E-4,2.89068468243117E-8,1,4,13.4005146026611,4.9952065815974,33.2800000905991,-0.190314077572316,-0.028254454084206,1,1.69700003643409E-7,,,,,,,,,,,,,,,,,,,,,50.0332489013672,50.0359497070313,25000.236328125,25000.236328125,53.2945589552364,5.64311043165227,4.70829391479492,54,2,0,0,1,0.300827026367188,33.7243423461914,1,1,3,50.0359497070313,0,50.0345993041992,,,,,,,,,,,,,,,,,,,,,,,,,,,,,,,,,
,3879789165.61279,50.0313625335693,40000.37890625,-2.45548876081662E-4,4.70577385615003E-8,1,4,13.4005146026611,4.99515251471192,33.2800000905991,-0.304825156755511,-0.0453692227165409,1,1.81824785868368E-7,,,,,,,,,,,,,,,,,,,,,50.0305252075195,50.0321998596191,40000.37890625,40000.37890625,53.5126333121018,5.64378692915544,4.70827150344849,53,3,64,0,0,0.299530029296875,34.2131004333496,1,1,3,50.0305252075195,0,50.0313625335693,,,,,,,,,,,,,,,,,,,,,,,,,,,,,,,,,
,3879789447.50314,50.0015258789063,60000.3828125,-3.6859062582505E-4,7.15160018073636E-8,1,4,13.4005146026611,4.99513981168551,33.2800000905991,-0.457555953509783,-0.0681831553172321,1,2.08344732499639E-7,,,,,,,,,,,,,,,,,,,,,50.0014038085937,50.0016479492188,60000.3828125,60000.3828125,53.333640381198,5.64448147237981,4.71091413497925,54,1,0,0,1,0.300369262695313,33.7243423461914,1,1,3,50.0013694763184,0,50.0015258789063,,,,,,,,,,,,,,,,,,,,,,,,,,,,,,,,,
,3879789610.96308,50.0008869171143,70000.4296875,-4.30143631782171E-4,1.77055754633797E-7,1,4,13.4005146026611,4.99511686024076,33.2800000905991,-0.533943909894038,-0.0796921290684134,1,1.43882761517126E-7,,,,,,,,,,,,,,,,,,,,,50.0006942749023,50.0010795593262,70000.4296875,70000.4296875,53.3312954956403,5.64426463100819,4.70283460617065,54,3,0,0,1,0.300369262695313,33.7243423461914,1,1,3,50.0006942749023,0,50.0008869171143,,,,,,,,,,,,,,,,,,,,,,,,,,,,,,,,,