File: SQUID/Reference/STO/B1/STOsubs_MH_350K_FC_0d5T.csv
Comment,Time Stamp (sec),Temperature (K),Magnetic Field (Oe),Moment (emu),M. Std. Err. (emu),Transport Action,Averaging Time (sec),Frequency (Hz),Peak Amplitude (mm),Center Position (mm),Lockin Signal' (V),Lockin Signal (V),Range,M. Quad. Signal (emu),AC Moment (emu),AC M. Std Err. (emu),AC Phase (deg),AC Phase Std. Err. (deg),AC Susceptibility (emu/Oe),AC Suscept. Std Err. (emu/Oe),AC X' (emu/Oe),AC X' Std Err. (emu/Oe),AC X'' (emu/Oe),AC X'' Std Err. (emu/Oe),AC Drive (Oe),AC Frequency (Hz),AC Averaging Time (sec),AC Cycles,AC Range,AC Measure Type,AC Signal' (V),AC Signal'' (V),AC Trim Coil Ratio,AC Trim Coil Phase,Min. Temperature (K),Max. Temperature (K),Min. Field (Oe),Max. Field (Oe),Mass (grams),Motor Lag (deg),Pressure (Torr),Measure Count,Measurement Number,SQUID Status (code),Motor Status (code),Measure Status (code),Motor Current (amps),Motor Temp. (C),Temp. Status (code),Field Status (code),Chamber Status (code),Chamber Temp (K),Redirection State,Average Temp (K),Rotation Angle (deg),Rotator state,DC Moment Fixed Ctr (emu),DC Moment Err Fixed Ctr (emu),DC Moment Free Ctr (emu),DC Moment Err Free Ctr (emu),DC Fixed Fit,DC Free Fit,DC Calculated Center (mm),DC Calculated Center Err (mm),DC Scan Length (mm),DC Scan Time (s),DC Number of Points,DC Squid Drift,DC Min V (V),DC Max V (V),DC Scans per Measure,Sample Resistance,He3 Temperature,Sorb Resistance,Sorb Temperature,Map 05,Map 06,Map 07,Map 08,Map 09,Map 10,Map 11,Map 12,Map 13,Map 14,Map 15,Map 16
,3879815655.68258,349.983337402344,70000.1171875,-4.33100629045017E-4,2.07786553582604E-7,1,4,13.4005146026611,4.98424206644111,33.6400009691715,-0.535982726663782,-0.0799403117576571,1,1.89227823269831E-7,,,,,,,,,,,,,,,,,,,,,349.983245849609,349.983428955078,70000.1171875,70000.1171875,53.1609004784479,5.64741126621354,7.00603437423706,54,1,0,0,1,0.300979614257812,33.2355842590332,1,1,3,349.983734130859,0,349.983337402344,,,,,,,,,,,,,,,,,,,,,,,,,,,,,,,,,
,3879815877.24631,349.956314086914,54999.76953125,-3.39986369179465E-4,7.06754964748489E-8,1,4,13.4005146026611,4.98391087310432,33.6400009691715,-0.420701167327124,-0.0628078181535303,1,9.99853658617364E-8,,,,,,,,,,,,,,,,,,,,,349.953521728516,349.959106445313,54999.76953125,54999.76953125,53.3887451918037,5.64901583044099,6.87074756622314,54,2,0,0,1,0.3021240234375,33.7243423461914,1,1,3,349.959106445313,0,349.956314086914,,,,,,,,,,,,,,,,,,,,,,,,,,,,,,,,,
,3879816099.53209,350.082855224609,39999.609375,-2.47005208291036E-4,3.62784784027097E-8,1,4,13.4005146026611,4.98388767180811,33.6400009691715,-0.305661819748885,-0.045509575146843,1,1.70391344110907E-7,,,,,,,,,,,,,,,,,,,,,350.079376220703,350.086334228516,39999.609375,39999.609375,53.4059410192268,5.64993907814789,6.74122810363769,54,3,0,0,1,0.301437377929687,34.2131004333496,1,1,3,350.086334228516,0,350.082855224609,,,,,,,,,,,,,,,,,,,,,,,,,,,,,,,,,
,3879816381.89994,349.995513916016,19999.56640625,-1.23139954035426E-4,2.42609965331819E-8,1,4,13.4005146026611,4.98392637827025,33.6400009691715,-0.152377441303911,-0.0227307328814045,1,5.05862142289611E-8,,,,,,,,,,,,,,,,,,,,,349.97802734375,350.013000488281,19999.56640625,19999.56640625,53.5345189106403,5.64909149964848,6.62023544311523,54,1,0,0,1,0.30181884765625,34.7018585205078,1,1,3,350.013000488281,0,349.995513916016,,,,,,,,,,,,,,,,,,,,,,,,,,,,,,,,,
,3879816566.13752,350.100845336914,9999.8837890625,-6.13076267141252E-5,1.1360397965029E-8,1,4,13.4005146026611,4.98385942309949,33.6400009691715,-0.0758723837639179,-0.0112516558958252,1,7.7773650121892E-8,,,,,,,,,,,,,,,,,,,,,350.09912109375,350.102569580078,9999.8837890625,9999.8837890625,53.5614850945537,5.64932910958596,6.56655740737915,54,2,0,0,1,0.30181884765625,34.7018585205078,1,1,3,350.09912109375,0,350.100845336914,,,,,,,,,,,,,,,,,,,,,,,,,,,,,,,,,
,3879816651.02191,350.054214477539,8499.728515625,-5.20186760621966E-5,1.05203606426803E-8,1,4,13.4005146026611,4.98393020717174,33.6400009691715,-0.0643761538917481,-0.00955910146629808,1,5.62624384310974E-8,,,,,,,,,,,,,,,,,,,,,350.052307128906,350.056121826172,8499.728515625,8499.728515625,53.5864972071691,5.64842268053125,6.54197692871094,54,3,0,0,1,0.3021240234375,34.7018585205078,1,1,3,350.052307128906,0,350.054214477539,,,,,,,,,,,,,,,,,,,,,,,,,,,,,,,,,
,3879816753.0306,350.17204284668,6499.78173828125,-3.963208895891E-5,8.23335800788479E-9,1,4,13.4005146026611,4.98393468973473,33.6400009691715,-0.04904108705725,-0.00732304290353527,1,1.04357189076003E-8,,,,,,,,,,,,,,,,,,,,,350.169219970703,350.174865722656,6499.78173828125,6499.78173828125,53.5399903102749,5.64799687145192,6.52294731140137,54,1,0,0,1,0.303192138671875,34.2131004333496,1,1,3,350.169219970703,0,350.17204284668,,,,,,,,,,,,,,,,,,,,,,,,,,,,,,,,,
,3879816839.23823,350.095794677734,4999.626953125,-3.03583863011991E-5,8.41736236077303E-9,1,4,13.4005146026611,4.98395217758705,33.6400009691715,-0.0375677088905156,-0.00559750961925077,1,1.76974548462155E-8,,,,,,,,,,,,,,,,,,,,,350.089782714844,350.101806640625,4999.626953125,4999.626953125,53.457528501496,5.64830302281332,6.50106954574585,54,2,0,0,1,0.301742553710937,34.2131004333496,1,1,3,350.089782714844,0,350.095794677734,,,,,,,,,,,,,,,,,,,,,,,,,,,,,,,,,
,3879816925.77448,350.02961730957,3499.7236328125,-2.10919136627817E-5,7.9384156967037E-9,1,4,13.4005146026611,4.98373015572129,33.6499996483326,-0.0260984255010424,-0.00389294705047915,1,8.86710133923371E-9,,,,,,,,,,,,,,,,,,,,,350.029083251953,350.030151367188,3499.7236328125,3499.7236328125,53.5661748656691,5.64845045901789,6.48663568496704,52,3,68,0,0,0.302734375,34.7018585205078,1,1,3,350.030151367188,0,350.02961730957,,,,,,,,,,,,,,,,,,,,,,,,,,,,,,,,,
,3879817029.92818,350.257568359375,2899.61645507812,-1.74697888334909E-5,1.43658244092668E-8,1,4,13.4005146026611,4.98377815059566,33.6400009691715,-0.0216562356242279,-0.0029609818790664,1,2.20283712191188E-7,,,,,,,,,,,,,,,,,,,,,350.253143310547,350.261993408203,2899.61645507812,2899.61645507812,53.4825406141114,5.64795829041575,6.47046852111816,54,1,0,0,1,0.301055908203125,34.2131004333496,1,1,3,350.253143310547,0,350.257568359375,,,,,,,,,,,,,,,,,,,,,,,,,,,,,,,,,
,3879817102.69241,350.150131225586,2749.74072265625,-1.65289322409926E-5,1.19775272278082E-8,1,4,13.4005146026611,4.98381911131441,33.6400009691715,-0.0204801371255764,-0.00286847503529318,1,1.5432886057786E-7,,,,,,,,,,,,,,,,,,,,,350.144927978516,350.155334472656,2749.74072265625,2749.74072265625,53.5810258075345,5.64837513436123,6.4528169631958,53,2,68,0,0,0.301437377929687,34.2131004333496,1,1,3,350.155334472656,0,350.150131225586,,,,,,,,,,,,,,,,,,,,,,,,,,,,,,,,,
,3879817176.36204,350.186172485352,2599.587890625,-1.55869299007799E-5,1.03665368534599E-8,1,4,13.4005146026611,4.98378655048701,33.6400009691715,-0.019308835066744,-0.00273130459306534,1,1.2425184120522E-7,,,,,,,,,,,,,,,,,,,,,350.1826171875,350.189727783203,2599.587890625,2599.587890625,53.4254817322076,5.64731937494297,6.44154739379883,52,3,68,0,0,0.301361083984375,34.7018585205078,1,1,3,350.1826171875,0,350.186172485352,,,,,,,,,,,,,,,,,,,,,,,,,,,,,,,,,
,3879817261.6932,350.275115966797,2399.81225585938,-1.43949379779853E-5,1.75993599245892E-8,1,4,13.4005146026611,4.98391066921947,33.6499996483326,-0.0178508630654226,-0.00240202591144779,1,2.1213004331719E-7,,,,,,,,,,,,,,,,,,,,,350.263519287109,350.286712646484,2399.81225585938,2399.81225585938,53.5087251695057,5.64609550903508,6.43698024749756,54,1,0,0,1,0.301132202148438,33.7243423461914,1,1,3,350.286712646484,0,350.275115966797,,,,,,,,,,,,,,,,,,,,,,,,,,,,,,,,,
,3879817333.71731,350.271560668945,2249.77294921875,-1.34652663491825E-5,1.32980154423162E-8,1,4,13.4005146026611,4.98383362515041,33.6499996483326,-0.0166914696285009,-0.00228805705423998,1,1.65123886756445E-7,,,,,,,,,,,,,,,,,,,,,350.267822265625,350.275299072266,2249.77294921875,2249.77294921875,53.4700345578037,5.64566147906898,6.42960786819458,54,2,0,0,1,0.300979614257812,34.7018585205078,1,1,3,350.275299072266,0,350.271560668945,,,,,,,,,,,,,,,,,,,,,,,,,,,,,,,,,
,3879817427.9444,350.069381713867,2099.53198242187,-1.25188662323394E-5,1.36193619228988E-8,1,4,13.4005146026611,4.98398875694032,33.6400009691715,-0.0155159843477476,-0.00214746044788591,1,1.37253571872214E-7,,,,,,,,,,,,,,,,,,,,,350.061584472656,350.077178955078,2099.53198242187,2099.53198242187,53.5059894696884,5.64899027017432,6.41303443908691,54,3,0,0,1,0.302581787109375,34.7018585205078,1,1,3,350.061584472656,0,350.069381713867,,,,,,,,,,,,,,,,,,,,,,,,,,,,,,,,,
,3879817522.79936,350.182815551758,1899.65576171875,-1.13321768242937E-5,5.12792660160282E-8,1,4,13.4005146026611,4.98402468957526,33.6499996483326,-0.014063614599986,-0.00182171590468904,1,2.23000759199136E-7,,,,,,,,,,,,,,,,,,,,,350.177490234375,350.188140869141,1899.65576171875,1899.65576171875,53.5153690119191,5.64854419821962,6.40616703033447,52,1,68,0,0,0.300674438476562,33.7243423461914,1,1,3,350.177490234375,0,350.182815551758,,,,,,,,,,,,,,,,,,,,,,,,,,,,,,,,,
,3879817609.01899,350.097412109375,1749.72961425781,-1.03629306103676E-5,1.35159328413733E-8,1,4,13.4005146026611,4.98391951750766,33.6400009691715,-0.0128521800751342,-0.00172057887480411,1,1.59700405727682E-7,,,,,,,,,,,,,,,,,,,,,350.094329833984,350.100494384766,1749.72961425781,1749.72961425781,53.5329556536018,5.64634435237546,6.39263677597046,54,2,0,0,1,0.3009033203125,34.2131004333496,1,1,3,350.100494384766,0,350.097412109375,,,,,,,,,,,,,,,,,,,,,,,,,,,,,,,,,
,3879817693.49736,350.179870605469,1599.81616210938,-9.42838825377354E-6,1.31879783287925E-8,1,4,13.4005146026611,4.98388068840503,33.6400009691715,-0.0116914910208544,-0.00157566005366479,1,1.37004587895735E-7,,,,,,,,,,,,,,,,,,,,,350.172973632812,350.186767578125,1599.81616210938,1599.81616210938,53.470816186323,5.64728947874275,6.38646650314331,54,3,0,0,1,0.302200317382812,34.2131004333496,1,1,3,350.172546386719,0,350.179870605469,,,,,,,,,,,,,,,,,,,,,,,,,,,,,,,,,
,3879817800.75528,350.238906860352,1399.71325683594,-8.25485176032686E-6,2.60242026775249E-8,1,4,13.4005146026611,4.98400677214701,33.6400009691715,-0.0102637251608352,-0.00119848469066835,1,2.66312463667377E-7,,,,,,,,,,,,,,,,,,,,,350.223205566406,350.254608154297,1399.71325683594,1399.71325683594,53.4876211994864,5.64857799749812,6.3715238571167,54,1,0,0,1,0.29998779296875,33.7243423461914,1,1,3,350.254608154297,0,350.238906860352,,,,,,,,,,,,,,,,,,,,,,,,,,,,,,,,,
,3879817894.27731,350.292831420898,1249.59838867188,-7.28036860856063E-6,1.66094408157603E-8,1,4,13.4005146026611,4.98401505608492,33.6400009691715,-0.00903910662361113,-0.00114397182241743,1,1.64592839666163E-7,,,,,,,,,,,,,,,,,,,,,350.292633056641,350.293029785156,1249.59838867188,1249.59838867188,53.503253769871,5.64859405491261,6.36781549453735,53,2,68,0,0,0.302734375,33.7243423461914,1,1,3,350.292633056641,0,350.292831420898,,,,,,,,,,,,,,,,,,,,,,,,,,,,,,,,,
,3879817985.00515,350.288696289063,1099.78540039062,-6.36356112453745E-6,1.23388887635783E-8,1,4,13.4005146026611,4.9839412949079,33.6400009691715,-0.0078970815922325,-0.00102380939642364,10,1.24536657775094E-7,,,,,,,,,,,,,,,,,,,,,350.287628173828,350.289764404297,1099.78540039062,1099.78540039062,53.5188863402557,5.64848615986846,6.35912990570068,54,3,0,0,1,0.3021240234375,34.2131004333496,1,1,3,350.287628173828,0,350.288696289063,,,,,,,,,,,,,,,,,,,,,,,,,,,,,,,,,
,3879818106.42093,350.028625488281,899.73291015625,-5.20853915203402E-6,2.49305695388463E-8,1,4,13.4005146026611,4.98383202839673,33.6400009691715,-0.00649134882046113,-6.51915582378645E-4,1,2.52290012341658E-7,,,,,,,,,,,,,,,,,,,,,350.011108398438,350.046142578125,899.73291015625,899.73291015625,53.4360337172172,5.6475372529493,6.35058212280273,54,1,0,0,1,0.301284790039063,34.2131004333496,1,1,3,350.046142578125,0,350.028625488281,,,,,,,,,,,,,,,,,,,,,,,,,,,,,,,,,
,3879818197.87628,350.218109130859,749.756469726563,-4.21891438738444E-6,1.35123300801524E-8,1,4,13.4005146026611,4.98367626881776,33.6499996483326,-0.00524406668979642,-6.19558648955044E-4,10,1.30377018858017E-7,,,,,,,,,,,,,,,,,,,,,350.218048095703,350.218170166016,749.756469726563,749.756469726563,53.4583101300153,5.64753357756361,6.34628057479858,54,2,0,0,1,0.301437377929687,33.7243423461914,1,1,3,350.218170166016,0,350.218109130859,,,,,,,,,,,,,,,,,,,,,,,,,,,,,,,,,
,3879818295.37771,350.242752075195,599.943603515625,-3.3382759980528E-6,1.51631175025966E-8,1,4,13.4005146026611,4.98373316553314,33.6400009691715,-0.00415550470448965,-4.50161227970448E-4,1,1.3555703737719E-7,,,,,,,,,,,,,,,,,,,,,350.242736816406,350.242767333984,599.943603515625,599.943603515625,53.4731610718807,5.64857752481587,6.33527660369873,53,3,68,0,0,0.301361083984375,34.2131004333496,1,1,3,350.242736816406,0,350.242752075195,,,,,,,,,,,,,,,,,,,,,,,,,,,,,,,,,
,3879818405.45153,350.097518920898,399.828155517578,-2.15668378919256E-6,2.8603700191772E-8,1,4,13.4005146026611,4.98372532280064,33.6400009691715,-0.00272551173619053,-1.76478969868321E-5,1,3.08363230235705E-7,,,,,,,,,,,,,,,,,,,,,350.093139648438,350.101898193359,399.828155517578,399.828155517578,53.4661264152076,5.64822286574438,6.32759666442871,52,1,68,0,0,0.301742553710937,34.2131004333496,1,1,3,350.093139648438,0,350.097518920898,,,,,,,,,,,,,,,,,,,,,,,,,,,,,,,,,
,3879818493.83174,350.040588378906,249.876846313477,-1.20208304637738E-6,1.38616892992348E-8,1,4,13.4005146026611,4.98397716547089,33.6400009691715,-0.0015108090043606,-6.62071802061412E-5,10,1.26318048857099E-7,,,,,,,,,,,,,,,,,,,,,350.040130615234,350.041046142578,249.876846313477,249.876846313477,53.5306107680441,5.64742011254354,6.32970333099365,54,2,0,0,1,0.302886962890625,34.2131004333496,1,1,3,350.039886474609,0,350.040588378906,,,,,,,,,,,,,,,,,,,,,,,,,,,,,,,,,
,3879818589.82261,350.134170532227,100.013687133789,-3.26792594350291E-7,1.58870461459825E-8,1,4,13.4005146026611,4.9839270309808,33.6499996483326,-4.32718257877342E-4,1.29084315268559E-4,1,1.53208757626197E-7,,,,,,,,,,,,,,,,,,,,,350.131164550781,350.137176513672,100.013687133789,100.013687133789,53.5696921940057,5.64783068356542,6.32358741760254,53,3,68,0,0,0.299835205078125,34.2131004333496,1,1,3,350.137176513672,0,350.134170532227,,,,,,,,,,,,,,,,,,,,,,,,,,,,,,,,,
,3879818709.96193,350.233276367188,-99.9633331298828,7.24399298219293E-7,3.51151332265291E-8,1,4,13.4005146026611,4.98404126429879,33.6400009691715,8.43142731468525E-4,4.89899870493302E-4,1,2.87545972791681E-7,,,,,,,,,,,,,,,,,,,,,350.215270996094,350.251281738281,-99.9633331298828,-99.9633331298828,53.4637815296499,5.64790875704,6.31129598617554,53,1,68,0,0,0.301284790039063,33.2355842590332,1,1,3,350.251281738281,0,350.233276367188,,,,,,,,,,,,,,,,,,,,,,,,,,,,,,,,,
,3879818810.0657,350.209045410156,-249.952377319336,1.61818749180299E-6,1.1346705827665E-8,1,4,13.4005146026611,4.98390342183917,33.6400009691715,0.00198634994475257,4.05898529397566E-4,10,8.59679684301766E-8,,,,,,,,,,,,,,,,,,,,,350.208343505859,350.209747314453,-249.952377319336,-249.952377319336,53.5556228806595,5.64859532531325,6.30514430999756,54,2,0,0,1,0.30059814453125,34.2131004333496,1,1,3,350.208343505859,0,350.209045410156,,,,,,,,,,,,,,,,,,,,,,,,,,,,,,,,,
,3879818918.65604,350.127029418945,-399.916259765625,2.46534555737585E-6,7.96999147785842E-9,1,4,13.4005146026611,4.98391014392959,33.6400009691715,0.00303496630733853,5.60164978274694E-4,10,8.39124566514501E-8,,,,,,,,,,,,,,,,,,,,,350.126800537109,350.127258300781,-399.916259765625,-399.916259765625,53.4438500024095,5.64831845214122,6.30949211120605,54,3,0,0,1,0.300979614257812,34.2131004333496,1,1,3,350.126800537109,0,350.127029418945,,,,,,,,,,,,,,,,,,,,,,,,,,,,,,,,,
,3879819039.17989,350.111373901367,-599.842956542969,2.61966883148407E-6,1.06956045269445E-6,1,4,13.4005146026611,4.98385973666752,33.6499996483326,0.00309051410994539,0.00149356209608672,10,8.15194719279265E-7,,,,,,,,,,,,,,,,,,,,,350.094665527344,350.128082275391,-599.842956542969,-599.842956542969,53.4329072031403,5.6476389917282,6.30126523971558,54,1,0,0,1,0.300216674804687,33.2355842590332,1,1,3,350.128082275391,0,350.111373901367,,,,,,,,,,,,,,,,,,,,,,,,,,,,,,,,,
,3879819134.20889,350.230712890625,-749.857177734375,4.52876825117578E-6,1.59562649093281E-8,1,4,13.4005146026611,4.98384732882262,33.6400009691715,0.0055813226166248,9.87033924013456E-4,1,1.20237293751663E-7,,,,,,,,,,,,,,,,,,,,,350.230438232422,350.230987548828,-749.857177734375,-749.857177734375,53.4559652444576,5.64792336362183,6.30079174041748,54,2,0,0,1,0.301589965820313,33.7243423461914,1,1,3,350.230224609375,0,350.230712890625,,,,,,,,,,,,,,,,,,,,,,,,,,,,,,,,,
,3879819234.0682,350.090057373047,-899.808471679688,5.44122281110524E-6,1.3246949415624E-8,1,4,13.4005146026611,4.98370072594978,33.6499996483326,0.0067083589345114,0.00116720001987772,1,1.2938748111523E-7,,,,,,,,,,,,,,,,,,,,,350.089874267578,350.090240478516,-899.808471679688,-899.808471679688,53.5591402089961,5.64792581576763,6.29283618927002,53,3,68,0,0,0.30181884765625,34.2131004333496,1,1,3,350.090240478516,0,350.090057373047,,,,,,,,,,,,,,,,,,,,,,,,,,,,,,,,,
,3879819343.92582,350.181900024414,-1099.76025390625,6.54091901585648E-6,7.27069688894566E-8,1,4,13.4005146026611,4.98371916574637,33.6400009691715,0.0080478137853998,0.00151258203003394,1,2.44019927676186E-7,,,,,,,,,,,,,,,,,,,,,350.171203613281,350.192596435547,-1099.76025390625,-1099.76025390625,53.3969522912557,5.64823124362808,6.2892575263977,53,1,68,0,0,0.301666259765625,33.7243423461914,1,1,3,350.192596435547,0,350.181900024414,,,,,,,,,,,,,,,,,,,,,,,,,,,,,,,,,
,3879819443.50566,350.136047363281,-1249.69909667969,7.57486424554136E-6,1.25579320287248E-8,1,4,13.4005146026611,4.98377073192009,33.6400009691715,0.00935382500104206,0.00152622440183304,1,1.00356237878509E-7,,,,,,,,,,,,,,,,,,,,,350.131042480469,350.141052246094,-1249.69909667969,-1249.69909667969,53.4497122163037,5.64804281386998,6.28739976882935,54,2,0,0,1,0.301284790039063,34.2131004333496,1,1,3,350.131042480469,0,350.136047363281,,,,,,,,,,,,,,,,,,,,,,,,,,,,,,,,,
,3879819540.20434,350.232345581055,-1399.6376953125,8.50065465152271E-6,7.21400713335647E-9,1,4,13.4005146026611,4.98358926380715,33.6499996483326,0.0105060766801617,0.00164866216684409,1,6.08871538469709E-8,,,,,,,,,,,,,,,,,,,,,350.227630615234,350.237060546875,-1399.6376953125,-1399.6376953125,53.5685197512268,5.64861548698883,6.28059244155884,54,3,0,0,1,0.3033447265625,33.7243423461914,1,1,3,350.227630615234,0,350.232345581055,,,,,,,,,,,,,,,,,,,,,,,,,,,,,,,,,
,3879819645.82207,350.214691162109,-1599.67761230469,9.6838263263386E-6,1.28711145730698E-8,1,4,13.4005146026611,4.9834653255222,33.6499996483326,0.0119546205228151,0.00196722044175496,1,1.41422465645223E-7,,,,,,,,,,,,,,,,,,,,,350.197509765625,350.231872558594,-1599.67761230469,-1599.67761230469,53.5044262126499,5.64896886652752,6.2845139503479,53,1,68,0,0,0.30029296875,33.7243423461914,1,1,3,350.231872558594,0,350.214691162109,,,,,,,,,,,,,,,,,,,,,,,,,,,,,,,,,
,3879819717.5998,350.342376708984,-1749.61633300781,1.06357482438228E-5,7.99870274966088E-9,1,4,13.4005146026611,4.98351905570167,33.6400009691715,0.0131395926813921,0.00209624275320655,1,1.032812202484E-7,,,,,,,,,,,,,,,,,,,,,350.336578369141,350.348175048828,-1749.61633300781,-1749.61633300781,53.4813681713326,5.64897628151882,6.28083610534668,54,2,0,0,1,0.303421020507812,33.7243423461914,1,1,3,350.348175048828,0,350.342376708984,,,,,,,,,,,,,,,,,,,,,,,,,,,,,,,,,
,3879819789.07327,350.253356933594,-1899.86975097656,1.15795476056469E-5,1.40849797625383E-8,1,4,13.4005146026611,4.98354442616998,33.6400009691715,0.0143135975382112,0.00222935873940454,1,6.96750240641023E-8,,,,,,,,,,,,,,,,,,,,,350.252075195313,350.254638671875,-1899.86975097656,-1899.86975097656,53.4669080437268,5.64880626314004,6.28092575073242,54,3,0,0,1,0.301361083984375,33.7243423461914,1,1,3,350.254638671875,0,350.253356933594,,,,,,,,,,,,,,,,,,,,,,,,,,,,,,,,,
,3879819881.5593,350.238693237305,-2099.82153320313,1.27634056417554E-5,9.54737505845607E-9,1,4,13.4005146026611,4.98359656282032,33.6400009691715,0.0157628576060239,0.00255324801466407,1,1.54333974691291E-7,,,,,,,,,,,,,,,,,,,,,350.231719970703,350.245666503906,-2099.82153320313,-2099.82153320313,53.5290475110057,5.6485727565385,6.26959419250488,53,1,68,0,0,0.30120849609375,33.7243423461914,1,1,3,350.231719970703,0,350.238693237305,,,,,,,,,,,,,,,,,,,,,,,,,,,,,,,,,
,3879819953.29114,349.983200073242,-2249.73510742187,1.37072045155824E-5,7.98453940429114E-9,1,4,13.4005146026611,4.9836441811261,33.6400009691715,0.016942513076423,0.00264961548525632,1,9.10077031833946E-8,,,,,,,,,,,,,,,,,,,,,349.981140136719,349.985260009766,-2249.73510742187,-2249.73510742187,53.5040353983903,5.64915074826636,6.26949882507324,52,2,68,0,0,0.30242919921875,35.6793746948242,1,1,3,349.981140136719,0,349.983200073242,,,,,,,,,,,,,,,,,,,,,,,,,,,,,,,,,
,3879820024.88311,349.985809326172,-2399.73681640625,1.46337030263625E-5,7.75566728628589E-9,1,4,13.4005146026611,4.98368679272767,33.6499996483326,0.0180931889688398,0.00279345262158792,1,6.86368485405119E-8,,,,,,,,,,,,,,,,,,,,,349.985656738281,349.985961914063,-2399.73681640625,-2399.73681640625,53.4188378897941,5.64942524265359,6.26938247680664,54,3,0,0,1,0.302886962890625,33.7243423461914,1,1,3,349.985961914063,0,349.985809326172,,,,,,,,,,,,,,,,,,,,,,,,,,,,,,,,,
,3879820106.90368,350.076095581055,-2599.6005859375,1.58458531373277E-5,7.63487053639957E-9,1,4,13.4005146026611,4.98369968413193,33.6400009691715,0.0195868930051621,0.00305878471009208,1,1.01746704729927E-7,,,,,,,,,,,,,,,,,,,,,350.072845458984,350.079345703125,-2599.6005859375,-2599.6005859375,53.4000788053326,5.64774899831046,6.2730827331543,54,1,0,0,1,0.30181884765625,33.7243423461914,1,1,3,350.072845458984,0,350.076095581055,,,,,,,,,,,,,,,,,,,,,,,,,,,,,,,,,
,3879820179.22477,350.270278930664,-2749.63989257813,1.67897606703544E-5,2.29061841672405E-8,1,4,13.4005146026611,4.98384585533559,33.6400009691715,0.020763851867128,0.00317861751148641,1,5.72901973650071E-8,,,,,,,,,,,,,,,,,,,,,350.259948730469,350.280609130859,-2749.63989257813,-2749.63989257813,53.5231852971114,5.64842046917753,6.26511526107788,52,2,68,0,0,0.300140380859375,33.7243423461914,1,1,3,350.281158447266,0,350.270278930664,,,,,,,,,,,,,,,,,,,,,,,,,,,,,,,,,
,3879820251.00118,350.383834838867,-2899.57861328125,1.77143056681145E-5,1.41779651100322E-8,1,4,13.4005146026611,4.98368747201738,33.6400009691715,0.0219107551240303,0.00332343535025301,1,3.61444258458617E-8,,,,,,,,,,,,,,,,,,,,,350.381378173828,350.386291503906,-2899.57861328125,-2899.57861328125,53.5818074360538,5.64872450946163,6.26520967483521,52,3,68,0,0,0.301589965820313,33.7243423461914,1,1,3,350.381378173828,0,350.383834838867,,,,,,,,,,,,,,,,,,,,,,,,,,,,,,,,,
,3879820355.63756,349.997650146484,-3499.8369140625,2.14283718344708E-5,6.82750655626454E-9,1,4,13.4005146026611,4.9836908442319,33.6400009691715,0.0265214572193589,0.00390818929029408,1,-4.68451472220433E-8,,,,,,,,,,,,,,,,,,,,,349.992431640625,350.002868652344,-3499.8369140625,-3499.8369140625,53.3637330791883,5.64878230433443,6.26576089859009,54,1,0,0,1,0.30242919921875,32.7468223571777,1,1,3,350.002868652344,0,349.997650146484,,,,,,,,,,,,,,,,,,,,,,,,,,,,,,,,,
,3879820438.50972,350.16471862793,-4999.626953125,3.0669786501219E-5,7.08194369353686E-9,1,4,13.4005146026611,4.98360133535526,33.6499996483326,0.0379563035531786,0.00560761721550722,1,-5.56647252783496E-8,,,,,,,,,,,,,,,,,,,,,350.154022216797,350.175415039063,-4999.626953125,-4999.626953125,53.5349097248999,5.64840344042736,6.25852298736572,54,2,0,0,1,0.302810668945313,33.7243423461914,1,1,3,350.175415039063,0,350.16471862793,,,,,,,,,,,,,,,,,,,,,,,,,,,,,,,,,
,3879820523.75127,350.21891784668,-6499.630859375,3.99233649369548E-5,9.86907445644249E-9,1,4,13.4005146026611,4.98365981328685,33.6400009691715,0.0494075673873433,0.00731027614391432,1,-6.38693531414523E-8,,,,,,,,,,,,,,,,,,,,,350.215606689453,350.222229003906,-6499.630859375,-6499.630859375,53.4977823702364,5.64885133260676,6.25820732116699,52,3,68,0,0,0.301437377929687,33.7243423461914,1,1,3,350.222229003906,0,350.21891784668,,,,,,,,,,,,,,,,,,,,,,,,,,,,,,,,,
,3879820624.14833,350.039947509766,-8499.6025390625,5.22685491868995E-5,1.04708492890649E-8,1,4,13.4005146026611,4.98376871103481,33.6400009691715,0.0646896924510058,0.00955613936773338,1,-9.56846803215083E-8,,,,,,,,,,,,,,,,,,,,,350.032958984375,350.046936035156,-8499.6025390625,-8499.6025390625,53.5102884265441,5.64725082777743,6.26233291625977,54,1,0,0,1,0.302505493164063,33.7243423461914,1,1,3,350.032501220703,0,350.039947509766,,,,,,,,,,,,,,,,,,,,,,,,,,,,,,,,,
,3879820707.95087,350.001388549805,-9999.70703125,6.15374903645578E-5,1.1490817961918E-8,1,4,13.4005146026611,4.98368388170963,33.6400009691715,0.0761564512756107,0.0112708296860193,1,-9.62136102344988E-8,,,,,,,,,,,,,,,,,,,,,349.995300292969,350.007476806641,-9999.70703125,-9999.70703125,53.5399903102749,5.64752733264258,6.26080799102783,54,2,0,0,1,0.301742553710937,33.7243423461914,1,1,3,350.007720947266,0,350.001388549805,,,,,,,,,,,,,,,,,,,,,,,,,,,,,,,,,
,3879820896.76041,350.157791137695,-19999.75390625,1.23320010616996E-4,2.44772368214282E-8,1,4,13.4005146026611,4.9835698392977,33.6400009691715,0.152596855189335,0.0226819858042519,1,-1.15077620864125E-7,,,,,,,,,,,,,,,,,,,,,350.152099609375,350.163482666016,-19999.75390625,-19999.75390625,53.3860094919864,5.64802849604786,6.25235891342163,54,3,0,0,1,0.3021240234375,33.2355842590332,1,1,3,350.163482666016,0,350.157791137695,,,,,,,,,,,,,,,,,,,,,,,,,,,,,,,,,
,3879821179.17619,350.022155761719,-39999.55859375,2.47016636063548E-4,4.85308864980227E-8,1,4,13.4005146026611,4.9837244806784,33.6400009691715,0.305666481286268,0.0454790870171748,1,-1.95052202394137E-7,,,,,,,,,,,,,,,,,,,,,350.003875732422,350.040435791016,-39999.55859375,-39999.55859375,53.425090917948,5.647567939125,6.24977779388428,53,1,68,0,0,0.301971435546875,34.2131004333496,1,1,3,350.040435791016,0,350.022155761719,,,,,,,,,,,,,,,,,,,,,,,,,,,,,,,,,
,3879821432.16258,350.054946899414,-54999.78515625,3.39975808520286E-4,7.26869171743119E-8,1,4,13.4005146026611,4.98360230682954,33.6400009691715,0.420748343713576,0.0621534080141548,10,-6.22921526034064E-7,,,,,,,,,,,,,,,,,,,,,350.054779052734,350.055114746094,-54999.78515625,-54999.78515625,53.2484428726018,5.64695660142621,6.24281883239746,54,2,0,0,1,0.302047729492188,33.7243423461914,1,1,3,350.054412841797,0,350.054946899414,,,,,,,,,,,,,,,,,,,,,,,,,,,,,,,,,
,3879821667.92571,350.132308959961,-69999.5390625,4.32553054913091E-4,1.12402505136371E-7,1,4,13.4005146026611,4.98374558677432,33.6499996483326,0.535225312048214,0.0798612144373464,1,-1.62212600517915E-7,,,,,,,,,,,,,,,,,,,,,350.126525878906,350.138092041016,-69999.5390625,-69999.5390625,53.2191318031306,5.64617778517018,6.24722146987915,54,3,0,0,1,0.3009033203125,33.2355842590332,1,1,3,350.138092041016,0,350.132308959961,,,,,,,,,,,,,,,,,,,,,,,,,,,,,,,,,
,3879821951.62047,350.031219482422,-49999.6015625,3.08680470705443E-4,7.35387776294698E-8,1,4,13.4005146026611,4.98382984348349,33.6400009691715,0.381965352582792,0.0569496212765173,1,-1.50230265316299E-7,,,,,,,,,,,,,,,,,,,,,350.029693603516,350.032745361328,-49999.6015625,-49999.6015625,53.3105823398806,5.64756177135513,6.23888111114502,54,1,0,0,1,0.301361083984375,34.2131004333496,1,1,3,350.029541015625,0,350.031219482422,,,,,,,,,,,,,,,,,,,,,,,,,,,,,,,,,
,3879822173.80158,350.040466308594,-34999.59375,2.15904705871024E-4,3.35437796893433E-8,1,4,13.4005146026611,4.9839088471218,33.6400009691715,0.267182496240273,0.0397458734171177,1,-1.76265162786878E-7,,,,,,,,,,,,,,,,,,,,,350.03857421875,350.042358398438,-34999.59375,-34999.59375,53.498173184496,5.6473321776684,6.23695230484009,54,2,0,0,1,0.301513671875,33.7243423461914,1,1,3,350.03857421875,0,350.040466308594,,,,,,,,,,,,,,,,,,,,,,,,,,,,,,,,,
,3879822394.96682,350.025985717773,-19999.666015625,1.23116340244609E-4,1.82011509649179E-8,1,4,13.4005146026611,4.98379321098347,33.6400009691715,0.152357017716569,0.0226285383682166,1,-1.28959106902596E-7,,,,,,,,,,,,,,,,,,,,,350.024597167969,350.027374267578,-19999.666015625,-19999.666015625,53.4837130568903,5.64697956240002,6.23531770706177,54,3,0,0,1,0.300827026367188,34.7018585205078,1,1,3,350.024597167969,0,350.025985717773,,,,,,,,,,,,,,,,,,,,,,,,,,,,,,,,,
,3879822599.43417,350.127334594727,-9500.494140625,5.8162762096805E-5,1.06847342486136E-8,1,4,13.4005146026611,4.98385271744087,33.6400009691715,0.0719724419499514,0.010726745405796,1,-3.15320329177062E-8,,,,,,,,,,,,,,,,,,,,,350.123413085937,350.131256103516,-9500.494140625,-9500.494140625,53.6103368770057,5.64782565673329,6.23341941833496,54,1,0,0,1,0.301589965820313,33.7243423461914,1,1,3,350.123413085937,0,350.127334594727,,,,,,,,,,,,,,,,,,,,,,,,,,,,,,,,,
,3879822683.83147,350.114379882812,-8000.2890625,4.89050186958681E-5,1.01637576972872E-8,1,4,13.4005146026611,4.98382157077692,33.6400009691715,0.0605186657478081,0.00900205452327919,1,-4.0446470894421E-8,,,,,,,,,,,,,,,,,,,,,350.111083984375,350.11767578125,-8000.2890625,-8000.2890625,53.4884028280057,5.64776983121065,6.23863649368286,54,2,0,0,1,0.3009033203125,34.2131004333496,1,1,3,350.110778808594,0,350.114379882812,,,,,,,,,,,,,,,,,,,,,,,,,,,,,,,,,
,3879822769.15512,350.227569580078,-6500.38623046875,3.96209854135523E-5,8.22817874750484E-9,1,4,13.4005146026611,4.98386879012574,33.6400009691715,0.0490307590409791,0.00729196965845822,1,-3.37779054489393E-8,,,,,,,,,,,,,,,,,,,,,350.226531982422,350.228607177734,-6500.38623046875,-6500.38623046875,53.5329556536018,5.64757740052874,6.23431205749512,54,3,0,0,1,0.303421020507812,33.7243423461914,1,1,3,350.226379394531,0,350.227569580078,,,,,,,,,,,,,,,,,,,,,,,,,,,,,,,,,
,3879822869.81507,350.147979736328,-4500.2001953125,2.72421316594581E-5,7.54003425561003E-9,1,4,13.4005146026611,4.9839374990722,33.6400009691715,0.0337050499282238,0.00506459734575759,1,1.78091226179587E-8,,,,,,,,,,,,,,,,,,,,,350.130065917969,350.165893554687,-4500.2001953125,-4500.2001953125,53.5016905128326,5.64626228850511,6.23335075378418,54,1,0,0,1,0.301895141601562,34.2131004333496,1,1,3,350.167541503906,0,350.147979736328,,,,,,,,,,,,,,,,,,,,,,,,,,,,,,,,,
,3879822953.59576,350.14958190918,-3000.25952148438,1.79910569793092E-5,6.26633825830348E-9,1,4,13.4005146026611,4.9839574639773,33.6400009691715,0.022261170273773,0.00333275766101089,1,2.07396150540637E-9,,,,,,,,,,,,,,,,,,,,,350.147705078125,350.151458740234,-3000.25952148438,-3000.25952148438,53.4329072031403,5.64685654540437,6.22959804534912,54,2,0,0,1,0.30181884765625,34.2131004333496,1,1,3,350.147705078125,0,350.14958190918,,,,,,,,,,,,,,,,,,,,,,,,,,,,,,,,,
,3879823042.51072,350.199630737305,-2900.4345703125,1.74497825543004E-5,8.93764699639832E-9,1,4,13.4005146026611,4.98405252926924,33.6400009691715,0.0216162217960076,0.00307068606640838,1,-1.28818784106701E-7,,,,,,,,,,,,,,,,,,,,,350.194396972656,350.204864501953,-2900.4345703125,-2900.4345703125,53.3770207640153,5.64637736182944,6.23583078384399,54,3,0,0,1,0.3021240234375,34.2131004333496,1,1,3,350.193969726562,0,350.199630737305,,,,,,,,,,,,,,,,,,,,,,,,,,,,,,,,,
,3879823124.39616,350.235717773438,-2700.419921875,1.62353970466811E-5,1.77019046637851E-8,1,4,13.4005146026611,4.98416777059515,33.6400009691715,0.0201323592299171,0.00272454657794884,1,-2.26956696834212E-7,,,,,,,,,,,,,,,,,,,,,350.2314453125,350.239990234375,-2700.419921875,-2700.419921875,53.4985639987557,5.64618269604267,6.22848510742188,54,1,0,0,1,0.300521850585937,34.2131004333496,1,1,3,350.2314453125,0,350.235717773438,,,,,,,,,,,,,,,,,,,,,,,,,,,,,,,,,
,3879823195.6271,350.287094116211,-2550.48095703125,1.52977907115399E-5,1.23524524654057E-8,1,4,13.4005146026611,4.98434939897097,33.6400009691715,0.01896090951971,0.00263258141189612,1,-1.61124151287554E-7,,,,,,,,,,,,,,,,,,,,,350.278289794922,350.2958984375,-2550.48095703125,-2550.48095703125,53.4977823702364,5.64373383003595,6.22954177856445,53,2,68,0,0,0.301284790039063,33.7243423461914,1,1,3,350.2958984375,0,350.287094116211,,,,,,,,,,,,,,,,,,,,,,,,,,,,,,,,,
,3879823266.64039,350.21842956543,-2400.4794921875,1.43541109983269E-5,1.05960480505449E-8,1,4,13.4005146026611,4.98428453761136,33.6400009691715,0.017785204764613,0.00250845820685516,1,-1.20219702343778E-7,,,,,,,,,,,,,,,,,,,,,350.209014892578,350.227844238281,-2400.4794921875,-2400.4794921875,53.6122909483037,5.64365776047025,6.22866344451904,54,3,0,0,1,0.29937744140625,34.2131004333496,1,1,3,350.209014892578,0,350.21842956543,,,,,,,,,,,,,,,,,,,,,,,,,,,,,,,,,
,3879823347.57962,350.219635009766,-2200.439453125,1.31560829063359E-5,1.84796876387656E-8,1,4,13.4005146026611,4.98437418302175,33.6400009691715,0.0163215999774597,0.00216292415381392,1,-2.20269744664302E-7,,,,,,,,,,,,,,,,,,,,,350.21484375,350.224426269531,-2200.439453125,-2200.439453125,53.5583585804768,5.64377418181349,6.22905921936035,54,1,0,0,1,0.299911499023438,33.7243423461914,1,1,3,350.224426269531,0,350.219635009766,,,,,,,,,,,,,,,,,,,,,,,,,,,,,,,,,
,3879823431.49223,350.24739074707,-2050.43774414062,1.22252248770347E-5,1.35739880382834E-8,1,4,13.4005146026611,4.98434074710522,33.6400009691715,0.0151569393833144,0.002074601706101,1,-1.5237426821652E-7,,,,,,,,,,,,,,,,,,,,,350.240478515625,350.254302978516,-2050.43774414062,-2050.43774414062,53.3824921636499,5.64445522574013,6.23033714294434,52,2,68,0,0,0.300521850585937,34.2131004333496,1,1,3,350.254302978516,0,350.24739074707,,,,,,,,,,,,,,,,,,,,,,,,,,,,,,,,,
,3879823502.99423,350.264083862305,-1900.49914550781,1.12689287900442E-5,1.1738247904865E-8,1,4,13.4005146026611,4.98433929523061,33.6499996483326,0.0139673031703089,0.00193910051850105,1,-1.18813418198263E-7,,,,,,,,,,,,,,,,,,,,,350.262756347656,350.265411376953,-1900.49914550781,-1900.49914550781,53.4778508429961,5.64462073903155,6.22926998138428,54,3,0,0,1,0.301055908203125,34.2131004333496,1,1,3,350.262756347656,0,350.264083862305,,,,,,,,,,,,,,,,,,,,,,,,,,,,,,,,,
,3879823598.46064,350.165298461914,-1700.16967773438,1.0101971595487E-5,1.99531859003252E-8,1,4,13.4005146026611,4.98442550754025,33.6400009691715,0.0125401186897434,0.00161199765865807,1,-2.08600794550383E-7,,,,,,,,,,,,,,,,,,,,,350.156494140625,350.174102783203,-1700.16967773438,-1700.16967773438,53.5157598261787,5.64690084488154,6.22643947601318,54,1,0,0,1,0.300064086914063,33.7243423461914,1,1,3,350.156494140625,0,350.165298461914,,,,,,,,,,,,,,,,,,,,,,,,,,,,,,,,,
,3879823670.70842,350.19612121582,-1550.15551757813,9.13068079384951E-6,1.50851238506687E-8,1,4,13.4005146026611,4.98441397163707,33.6499996483326,0.0113256179700443,0.0015154838774769,1,-1.41286688895299E-7,,,,,,,,,,,,,,,,,,,,,350.189117431641,350.203125,-1550.15551757813,-1550.15551757813,53.425090917948,5.64617244697494,6.22915458679199,52,2,68,0,0,0.300140380859375,33.7243423461914,1,1,3,350.203125,0,350.19612121582,,,,,,,,,,,,,,,,,,,,,,,,,,,,,,,,,
,3879823741.33311,350.235473632812,-1400.17907714844,8.20520304194269E-6,1.23624807351125E-8,1,4,13.4005146026611,4.98438253285368,33.6400009691715,0.0101814125700887,0.00133619883423331,1,-1.47705028787536E-7,,,,,,,,,,,,,,,,,,,,,350.235290527344,350.235656738281,-1400.17907714844,-1400.17907714844,53.4497122163037,5.64619406146366,6.2303786277771,52,3,68,0,0,0.300064086914063,33.7243423461914,1,1,3,350.235656738281,0,350.235473632812,,,,,,,,,,,,,,,,,,,,,,,,,,,,,,,,,
,3879823823.23543,350.321914672852,-1200.18933105469,7.02040708463562E-6,2.28998113556187E-8,1,4,13.4005146026611,4.9842757406004,33.6400009691715,0.00873605208460845,9.75746589639529E-4,1,-2.61713962569273E-7,,,,,,,,,,,,,,,,,,,,,350.318389892578,350.325439453125,-1200.18933105469,-1200.18933105469,53.6036930345922,5.64620113565358,6.22774839401245,52,1,68,0,0,0.301971435546875,34.2131004333496,1,1,3,350.325439453125,0,350.321914672852,,,,,,,,,,,,,,,,,,,,,,,,,,,,,,,,,
,3879823904.2098,350.204620361328,-1050.14990234375,6.05694746502315E-6,1.64303517838552E-8,1,4,13.4005146026611,4.98418550087376,33.6400009691715,0.00752298659801754,9.35165733816407E-4,1,-1.50360318069586E-7,,,,,,,,,,,,,,,,,,,,,350.196441650391,350.212799072266,-1050.14990234375,-1050.14990234375,53.5005180700537,5.64740843562482,6.2267255783081,54,2,0,0,1,0.29998779296875,33.7243423461914,1,1,3,350.196441650391,0,350.204620361328,,,,,,,,,,,,,,,,,,,,,,,,,,,,,,,,,
,3879823975.25874,350.237289428711,-900.2490234375,5.147132732449E-6,1.38331440332305E-8,1,4,13.4005146026611,4.98419092533586,33.6400009691715,0.00639469383527817,7.83156992405771E-4,1,-1.3709919050059E-7,,,,,,,,,,,,,,,,,,,,,350.237243652344,350.237335205078,-900.2490234375,-900.2490234375,53.5087251695057,5.64737059712728,6.22576379776001,54,3,0,0,1,0.302276611328125,33.7243423461914,1,1,3,350.237335205078,0,350.237289428711,,,,,,,,,,,,,,,,,,,,,,,,,,,,,,,,,
,3879824057.09529,350.233444213867,-700.171325683594,3.97061184206753E-6,2.52552733695274E-8,1,4,13.4005146026611,4.98436281886816,33.6400009691715,0.00496203014010386,4.11763280458455E-4,1,-2.61243486512687E-7,,,,,,,,,,,,,,,,,,,,,350.220428466797,350.246459960937,-700.171325683594,-700.171325683594,53.4438500024095,5.64646467072483,6.22586584091187,52,1,68,0,0,0.3009033203125,34.2131004333496,1,1,3,350.246459960937,0,350.233444213867,,,,,,,,,,,,,,,,,,,,,,,,,,,,,,,,,
,3879824128.97018,350.239624023438,-550.220031738281,3.10049664989086E-6,7.06687109519973E-8,1,4,13.4005146026611,4.98429434561769,33.6499996483326,0.0038688614665373,3.59764440376505E-4,1,-1.73092969322252E-7,,,,,,,,,,,,,,,,,,,,,350.235748291016,350.243499755859,-550.220031738281,-550.220031738281,53.5669564941884,5.64702720544218,6.23038053512573,54,2,0,0,1,0.300369262695313,34.2131004333496,1,1,3,350.243499755859,0,350.239624023438,,,,,,,,,,,,,,,,,,,,,,,,,,,,,,,,,
,3879824201.10546,350.254730224609,-400.281341552734,2.11632493859407E-6,1.56569123468286E-8,1,4,13.4005146026611,4.98434038752088,33.6499996483326,0.00264740236972717,2.01612496934064E-4,1,-1.53670140551179E-7,,,,,,,,,,,,,,,,,,,,,350.253997802734,350.255462646484,-400.281341552734,-400.281341552734,53.4153205614576,5.64502640360849,6.22573804855347,54,3,0,0,1,0.301361083984375,33.7243423461914,1,1,3,350.253997802734,0,350.254730224609,,,,,,,,,,,,,,,,,,,,,,,,,,,,,,,,,
,3879824282.87161,350.246383666992,-200.20361328125,9.71377551010498E-7,2.53577167036659E-8,1,4,13.4005146026611,4.98429147725154,33.6400009691715,0.00125085729611259,-1.4634843595086E-4,1,-2.63574979350418E-7,,,,,,,,,,,,,,,,,,,,,350.223541259766,350.269226074219,-200.20361328125,-200.20361328125,53.5106792408037,5.64374041620681,6.2216591835022,53,1,68,0,0,0.300750732421875,33.7243423461914,1,1,3,350.269226074219,0,350.246383666992,,,,,,,,,,,,,,,,,,,,,,,,,,,,,,,,,
,3879824352.82386,350.268768310547,-50.2900772094727,9.5585070164003E-8,3.6332445666334E-8,1,4,13.4005146026611,4.9842348326622,33.6400009691715,1.48559323575972E-4,-1.84694941008381E-4,1,-1.63551669801398E-7,,,,,,,,,,,,,,,,,,,,,350.268005371094,350.26953125,-50.2900772094727,-50.2900772094727,53.4438500024095,5.64696024567788,6.22381401062012,54,2,0,0,1,0.299911499023438,33.7243423461914,1,1,3,350.269439697266,0,350.268768310547,,,,,,,,,,,,,,,,,,,,,,,,,,,,,,,,,
,3879824444.53712,350.221633911133,99.8752136230469,-8.04769756181707E-7,7.5132560210461E-9,1,4,13.4005146026611,4.98445931413641,33.6499996483326,-9.83238611574895E-4,-2.33870729550165E-4,10,-6.85913460222568E-8,,,,,,,,,,,,,,,,,,,,,350.220581054687,350.222686767578,99.8752136230469,99.8752136230469,53.472770257621,5.64565033632459,6.22111034393311,54,3,0,0,1,0.300445556640625,33.7243423461914,1,1,3,350.220581054687,0,350.221633911133,,,,,,,,,,,,,,,,,,,,,,,,,,,,,,,,,
,3879824534.0382,350.20491027832,299.638244628906,-1.90887386979593E-6,5.50486576631543E-8,1,4,13.4005146026611,4.98440077000329,33.6400009691715,-0.00231881305976718,-6.43906345655319E-4,1,-2.34763254943235E-7,,,,,,,,,,,,,,,,,,,,,350.201141357422,350.208679199219,299.638244628906,299.638244628906,53.3832737921691,5.64619743317049,6.22840213775635,54,1,0,0,1,0.299453735351562,33.7243423461914,1,1,3,350.208679199219,0,350.20491027832,,,,,,,,,,,,,,,,,,,,,,,,,,,,,,,,,
,3879824605.47115,350.061401367188,449.853881835937,-2.75272837578865E-6,1.25498887168411E-8,1,4,13.4005146026611,4.98435123871695,33.6400009691715,-0.00338114160904995,-6.79208572963672E-4,1,-1.37062010205553E-7,,,,,,,,,,,,,,,,,,,,,350.058349609375,350.064453125,449.853881835937,449.853881835937,53.447367330746,5.64634391778934,6.2250862121582,53,2,68,0,0,0.301513671875,34.2131004333496,1,1,3,350.058197021484,0,350.061401367188,,,,,,,,,,,,,,,,,,,,,,,,,,,,,,,,,
,3879824677.16687,350.273880004883,599.842956542969,-3.6316992639893E-6,1.08470542082982E-8,1,4,13.4005146026611,4.98439231899425,33.6400009691715,-0.00447639004637317,-7.92027994397168E-4,1,-9.67328236050349E-8,,,,,,,,,,,,,,,,,,,,,350.272430419922,350.275329589844,599.842956542969,599.842956542969,53.3684228503037,5.64616194075884,6.22906351089478,53,3,68,0,0,0.300140380859375,33.7243423461914,1,1,3,350.275360107422,0,350.273880004883,,,,,,,,,,,,,,,,,,,,,,,,,,,,,,,,,
,3879824775.35092,350.125198364258,799.568176269531,-4.7887514594046E-6,2.23000471953268E-8,1,4,13.4005146026611,4.98419292399025,33.6400009691715,-0.00587864710544579,-0.00120193927941697,1,-2.54935744027892E-7,,,,,,,,,,,,,,,,,,,,,350.113189697266,350.13720703125,799.568176269531,799.568176269531,53.5411627530537,5.64687878274681,6.22497701644897,54,1,0,0,1,0.301437377929687,34.2131004333496,1,1,3,350.113189697266,0,350.125198364258,,,,,,,,,,,,,,,,,,,,,,,,,,,,,,,,,
,3879824862.40584,350.065246582031,949.859313964844,-5.76057183998817E-6,1.17142088006602E-8,1,4,13.4005146026611,4.98424269647837,33.6400009691715,-0.00710900228438337,-0.00119684246363123,1,-1.05425043661391E-7,,,,,,,,,,,,,,,,,,,,,350.064453125,350.066040039063,949.859313964844,949.859313964844,53.4594825727941,5.64715028949125,6.22655773162842,54,2,0,0,1,0.301742553710937,33.7243423461914,1,1,3,350.064453125,0,350.065246582031,,,,,,,,,,,,,,,,,,,,,,,,,,,,,,,,,
,3879824946.51876,350.126922607422,1099.78540039062,-6.62088686615779E-6,1.91099700531561E-8,1,4,13.4005146026611,4.98420607736777,33.6400009691715,-0.00816790081096715,-0.00139371496981162,1,-1.35831942703619E-7,,,,,,,,,,,,,,,,,,,,,350.1240234375,350.129821777344,1099.78540039062,1099.78540039062,53.4231368466499,5.64701530753974,6.22638273239136,53,3,68,0,0,0.302276611328125,33.2355842590332,1,1,3,350.129821777344,0,350.126922607422,,,,,,,,,,,,,,,,,,,,,,,,,,,,,,,,,
,3879825029.19234,350.313278198242,1299.58630371094,-7.85262745310479E-6,1.43058305225891E-8,1,4,13.4005146026611,4.9840636025093,33.6499996483326,-0.00968781709366726,-0.00164785384274735,1,-1.56996861198405E-7,,,,,,,,,,,,,,,,,,,,,350.305816650391,350.320739746094,1299.58630371094,1299.58630371094,53.4997364415345,5.64738623165356,6.21933031082153,53,1,68,0,0,0.300827026367188,34.2131004333496,1,1,3,350.305816650391,0,350.313278198242,,,,,,,,,,,,,,,,,,,,,,,,,,,,,,,,,
,3879825100.92076,350.077194213867,1449.80187988281,-8.77802281423762E-6,9.44148165184307E-9,1,4,13.4005146026611,4.98402450182423,33.6400009691715,-0.0108381468106438,-0.00178329940732664,1,-1.28038663354021E-7,,,,,,,,,,,,,,,,,,,,,350.064788818359,350.089599609375,1449.80187988281,1449.80187988281,53.4508846590826,5.6480211127304,6.22572708129883,54,2,0,0,1,0.301589965820313,33.7243423461914,1,1,3,350.089599609375,0,350.077194213867,,,,,,,,,,,,,,,,,,,,,,,,,,,,,,,,,
,3879825172.32246,350.248504638672,1599.61474609375,-9.73069444197356E-6,9.33726700566335E-9,1,4,13.4005146026611,4.98404145812809,33.6400009691715,-0.0120282363670553,-0.00188475275571124,1,-6.75073014573623E-8,,,,,,,,,,,,,,,,,,,,,350.244903564453,350.252105712891,1599.61474609375,1599.61474609375,53.450493844823,5.64820977671817,6.22586584091187,54,3,0,0,1,0.301284790039063,33.7243423461914,1,1,3,350.244903564453,0,350.248504638672,,,,,,,,,,,,,,,,,,,,,,,,,,,,,,,,,
,3879825267.66589,350.189987182617,1799.79309082031,-1.09310366616656E-5,8.34016561088605E-9,1,4,13.4005146026611,4.98408172065209,33.6400009691715,-0.013500998477635,-0.00219180441193891,1,-1.3606661941126E-7,,,,,,,,,,,,,,,,,,,,,350.177520751953,350.202453613281,1799.79309082031,1799.79309082031,53.4344704601787,5.64776567872394,6.22426605224609,54,1,0,0,1,0.300979614257812,33.7243423461914,1,1,3,350.202453613281,0,350.189987182617,,,,,,,,,,,,,,,,,,,,,,,,,,,,,,,,,
,3879825339.42845,350.075958251953,1949.81994628906,-1.18375506038351E-5,2.77086240601754E-8,1,4,13.4005146026611,4.98414946119562,33.6400009691715,-0.0146337580268321,-0.00228778985439512,1,-7.79920310653832E-8,,,,,,,,,,,,,,,,,,,,,350.073364257812,350.078552246094,1949.81994628906,1949.81994628906,53.4923109706018,5.64750792930379,6.22592496871948,54,2,0,0,1,0.301437377929687,33.7243423461914,1,1,3,350.073364257812,0,350.075958251953,,,,,,,,,,,,,,,,,,,,,,,,,,,,,,,,,
,3879825411.28186,350.202041625977,2099.92236328125,-1.27954695156717E-5,6.56297703969358E-9,1,4,13.4005146026611,4.98412365692999,33.6499996483326,-0.0158204675866074,-0.00245531896661098,1,-7.00918829870898E-8,,,,,,,,,,,,,,,,,,,,,350.19970703125,350.204376220703,2099.92236328125,2099.92236328125,53.3129272254383,5.6476832329603,6.22236490249634,54,3,0,0,1,0.301361083984375,33.7243423461914,1,1,3,350.204376220703,0,350.202041625977,,,,,,,,,,,,,,,,,,,,,,,,,,,,,,,,,
,3879825493.56824,350.249755859375,2299.79858398438,-1.40092517318759E-5,9.43360880081882E-9,1,4,13.4005146026611,4.98418021660337,33.6400009691715,-0.0173149386392355,-0.00273198705954655,1,-1.12065995004793E-7,,,,,,,,,,,,,,,,,,,,,350.248748779297,350.250762939453,2299.79858398438,2299.79858398438,53.3719401786402,5.64740686870492,6.2206597328186,54,1,0,0,1,0.3009033203125,33.7243423461914,1,1,3,350.248748779297,0,350.249755859375,,,,,,,,,,,,,,,,,,,,,,,,,,,,,,,,,
,3879825565.08152,350.14501953125,2449.7626953125,-1.49413187071581E-5,8.10199772636393E-9,1,4,13.4005146026611,4.9842099783827,33.6400009691715,-0.0184758036372689,-0.00285556211785005,1,-7.24782253502475E-8,,,,,,,,,,,,,,,,,,,,,350.136444091797,350.153594970703,2449.7626953125,2449.7626953125,53.4731610718807,5.64752451262974,6.21990394592285,54,2,0,0,1,0.300521850585937,33.7243423461914,1,1,3,350.153594970703,0,350.14501953125,,,,,,,,,,,,,,,,,,,,,,,,,,,,,,,,,
,3879825636.86329,350.143127441406,2599.80200195313,-1.58716500716432E-5,1.05362463944329E-8,1,4,13.4005146026611,4.98430584051887,33.6400009691715,-0.0196325495555647,-0.00299462325165817,1,-4.56177382413198E-8,,,,,,,,,,,,,,,,,,,,,350.140777587891,350.145477294922,2599.80200195313,2599.80200195313,53.3422382949095,5.64680379978607,6.22771596908569,53,3,68,0,0,0.301666259765625,33.7243423461914,1,1,3,350.145477294922,0,350.143127441406,,,,,,,,,,,,,,,,,,,,,,,,,,,,,,,,,
,3879825719.18998,350.286834716797,2799.75390625,-1.7085929502656E-5,8.54687126952836E-9,1,4,13.4005146026611,4.98430194740627,33.6400009691715,-0.0211246274417485,-0.00328997607926219,1,-1.0264297587361E-7,,,,,,,,,,,,,,,,,,,,,350.280578613281,350.293090820313,2799.75390625,2799.75390625,53.4680804865057,5.64646259218365,6.2214822769165,54,1,0,0,1,0.300521850585937,33.7243423461914,1,1,3,350.280578613281,0,350.286834716797,,,,,,,,,,,,,,,,,,,,,,,,,,,,,,,,,
,3879825790.96559,350.182083129883,2949.75537109375,-1.80102096085271E-5,9.02829016472426E-9,1,4,13.4005146026611,4.98426825230712,33.6400009691715,-0.0222753339662251,-0.00341336806977924,1,-6.41142098656021E-8,,,,,,,,,,,,,,,,,,,,,350.178436279297,350.185729980469,2949.75537109375,2949.75537109375,53.486057942448,5.6463890042115,6.22353839874268,54,2,0,0,1,0.300750732421875,33.7243423461914,1,1,3,350.185729980469,0,350.182083129883,,,,,,,,,,,,,,,,,,,,,,,,,,,,,,,,,
,3879825884.2747,350.292221069336,3499.56005859375,-2.14281920247475E-5,7.92433729311766E-9,1,4,13.4005146026611,4.98427083617496,33.6400009691715,-0.0265237871387158,-0.00392068031732706,1,3.72399833090089E-8,,,,,,,,,,,,,,,,,,,,,350.291625976562,350.292816162109,3499.56005859375,3499.56005859375,53.4145389329383,5.64674512826257,6.22416496276855,54,3,0,0,1,0.3009033203125,33.7243423461914,1,1,3,350.291625976562,0,350.292221069336,,,,,,,,,,,,,,,,,,,,,,,,,,,,,,,,,
,3879825982.67174,350.103179931641,5499.74560546875,-3.37605704527315E-5,9.27460853028968E-9,1,4,13.4005146026611,4.98424129829532,33.6400009691715,-0.0417938982495254,-0.00614058346058088,1,8.81520249655411E-8,,,,,,,,,,,,,,,,,,,,,350.093231201172,350.113128662109,5499.74560546875,5499.74560546875,53.4700345578037,5.64643065455711,6.22004175186157,54,1,0,0,1,0.300979614257812,33.7243423461914,1,1,3,350.093231201172,0,350.103179931641,,,,,,,,,,,,,,,,,,,,,,,,,,,,,,,,,
,3879826066.99615,349.938873291016,6999.9384765625,-4.30081093642882E-5,1.10731972219626E-8,1,4,13.4005146026611,4.98424511257919,33.6499996483326,-0.0532375684916805,-0.00785185612475718,1,8.86498349171071E-8,,,,,,,,,,,,,,,,,,,,,349.928802490234,349.948944091797,6999.9384765625,6999.9384765625,53.4629999011307,5.64614987933383,6.22454166412354,54,2,0,0,1,0.301666259765625,33.7243423461914,1,1,3,349.949523925781,0,349.938873291016,,,,,,,,,,,,,,,,,,,,,,,,,,,,,,,,,
,3879826150.71762,350.003631591797,8500.0556640625,-5.22584698680083E-5,1.1235659322892E-8,1,4,13.4005146026611,4.98440235757186,33.6400009691715,-0.0646887956687478,-0.00955573071063071,1,9.58845768523103E-8,,,,,,,,,,,,,,,,,,,,,350.003234863281,350.004028320313,8500.0556640625,8500.0556640625,53.4712070005826,5.64459900757256,6.22657346725464,54,3,0,0,1,0.29998779296875,33.7243423461914,1,1,3,350.004028320313,0,350.003631591797,,,,,,,,,,,,,,,,,,,,,,,,,,,,,,,,,
,3879826254.79952,350.087600708008,9999.984375,-6.15225571022072E-5,1.2006542183686E-8,1,4,13.4005146026611,4.98427022035741,33.6400009691715,-0.076153304688933,-0.0112514640783355,1,1.11132409272715E-7,,,,,,,,,,,,,,,,,,,,,350.087158203125,350.088043212891,9999.984375,9999.984375,53.435252088698,5.64600498599482,6.22074127197266,54,1,0,0,1,0.30120849609375,34.2131004333496,1,1,3,350.087158203125,0,350.087600708008,,,,,,,,,,,,,,,,,,,,,,,,,,,,,,,,,
,3879826473.06109,350.069763183594,25000.375,-1.5422823684916E-4,2.35652083363187E-8,1,4,13.4005146026611,4.98420664866455,33.6400009691715,-0.190880400963082,-0.028349748375425,1,1.61865880090536E-7,,,,,,,,,,,,,,,,,,,,,350.055816650391,350.083709716797,25000.375,25000.375,53.4712070005826,5.64702601882291,6.21888494491577,54,2,0,0,1,0.302734375,33.7243423461914,1,1,3,350.083709716797,0,350.069763183594,,,,,,,,,,,,,,,,,,,,,,,,,,,,,,,,,
,3879826693.4644,350.060684204102,40000.50390625,-2.46971645849478E-4,5.25947331943217E-8,1,4,13.4005146026611,4.98423673982987,33.6499996483326,-0.305661009410775,-0.0454364025374482,1,2.28115548284483E-7,,,,,,,,,,,,,,,,,,,,,350.058929443359,350.062438964844,40000.50390625,40000.50390625,53.3578708652941,5.64668060425713,6.22237300872803,54,3,0,0,1,0.301513671875,33.7243423461914,1,1,3,350.058929443359,0,350.060684204102,,,,,,,,,,,,,,,,,,,,,,,,,,,,,,,,,
,3879826974.44424,350.049728393555,60000.37109375,-3.7067649720991E-4,1.20095879687263E-7,1,4,13.4005146026611,4.98420124624455,33.6400009691715,-0.458730219437087,-0.0683799796895732,1,1.92259484677062E-7,,,,,,,,,,,,,,,,,,,,,350.033142089844,350.066314697266,60000.37109375,60000.37109375,53.2070165610826,5.64628648708832,6.22371578216553,54,1,0,0,1,0.302276611328125,33.7243423461914,1,1,3,350.066314697266,0,350.049728393555,,,,,,,,,,,,,,,,,,,,,,,,,,,,,,,,,
,3879827150.07769,349.994018554687,70000.390625,-4.32543755287036E-4,2.09621101871529E-7,1,4,13.4005146026611,4.98409321476774,33.6400009691715,-0.535286854142775,-0.0797291393945987,1,2.73872210580921E-7,,,,,,,,,,,,,,,,,,,,,349.993713378906,349.994323730469,70000.390625,70000.390625,53.1820044484672,5.64720797593311,6.21628618240356,54,3,0,0,1,0.3009033203125,33.7243423461914,1,1,3,349.994323730469,0,349.994018554687,,,,,,,,,,,,,,,,,,,,,,,,,,,,,,,,,