File: SQUID/Reference/STO/B1/STOsubs_MH_200K_FC_0d5T.csv
Comment,Time Stamp (sec),Temperature (K),Magnetic Field (Oe),Moment (emu),M. Std. Err. (emu),Transport Action,Averaging Time (sec),Frequency (Hz),Peak Amplitude (mm),Center Position (mm),Lockin Signal' (V),Lockin Signal (V),Range,M. Quad. Signal (emu),AC Moment (emu),AC M. Std Err. (emu),AC Phase (deg),AC Phase Std. Err. (deg),AC Susceptibility (emu/Oe),AC Suscept. Std Err. (emu/Oe),AC X' (emu/Oe),AC X' Std Err. (emu/Oe),AC X'' (emu/Oe),AC X'' Std Err. (emu/Oe),AC Drive (Oe),AC Frequency (Hz),AC Averaging Time (sec),AC Cycles,AC Range,AC Measure Type,AC Signal' (V),AC Signal'' (V),AC Trim Coil Ratio,AC Trim Coil Phase,Min. Temperature (K),Max. Temperature (K),Min. Field (Oe),Max. Field (Oe),Mass (grams),Motor Lag (deg),Pressure (Torr),Measure Count,Measurement Number,SQUID Status (code),Motor Status (code),Measure Status (code),Motor Current (amps),Motor Temp. (C),Temp. Status (code),Field Status (code),Chamber Status (code),Chamber Temp (K),Redirection State,Average Temp (K),Rotation Angle (deg),Rotator state,DC Moment Fixed Ctr (emu),DC Moment Err Fixed Ctr (emu),DC Moment Free Ctr (emu),DC Moment Err Free Ctr (emu),DC Fixed Fit,DC Free Fit,DC Calculated Center (mm),DC Calculated Center Err (mm),DC Scan Length (mm),DC Scan Time (s),DC Number of Points,DC Squid Drift,DC Min V (V),DC Max V (V),DC Scans per Measure,Sample Resistance,He3 Temperature,Sorb Resistance,Sorb Temperature,Map 05,Map 06,Map 07,Map 08,Map 09,Map 10,Map 11,Map 12,Map 13,Map 14,Map 15,Map 16
,3879802388.5986,200.124877929687,69999.734375,-4.3477408917571E-4,2.24286501883721E-7,1,4,13.4005146026611,4.98385582289353,33.390000462532,-0.537988574641636,-0.0802848638511388,1,1.54079368836482E-7,,,,,,,,,,,,,,,,,,,,,200.124664306641,200.125091552734,69999.734375,69999.734375,53.1073589248806,5.64813095164993,5.06672430038452,54,1,0,0,1,0.301361083984375,32.7468223571777,1,1,3,200.124664306641,0,200.124877929687,,,,,,,,,,,,,,,,,,,,,,,,,,,,,,,,,
,3879802623.49152,200.007766723633,54999.55859375,-3.41356957282748E-4,7.56161008174846E-8,1,4,13.4005146026611,4.98354844519423,33.390000462532,-0.422379763396968,-0.0628826560680771,1,2.39348879174223E-7,,,,,,,,,,,,,,,,,,,,,200.007675170898,200.007858276367,54999.55859375,54999.55859375,53.3918717058807,5.64905062813346,5.06114625930786,54,2,0,0,1,0.30426025390625,34.2131004333496,1,1,3,200.007675170898,0,200.007766723633,,,,,,,,,,,,,,,,,,,,,,,,,,,,,,,,,
,3879802856.19907,200.001892089844,39999.6484375,-2.48040327538178E-4,5.58910182686304E-8,1,4,13.4005146026611,4.98364939020713,33.390000462532,-0.306922777748704,-0.0456930970583171,1,1.74442180899176E-7,,,,,,,,,,,,,,,,,,,,,200.001800537109,200.001983642578,39999.6484375,39999.6484375,53.5310015823037,5.64853093412381,5.06657123565674,54,3,0,0,1,0.303573608398438,34.7018585205078,1,1,3,200.001800537109,0,200.001892089844,,,,,,,,,,,,,,,,,,,,,,,,,,,,,,,,,
,3879803138.34718,200.149566650391,19999.56640625,-1.23663891829276E-4,2.46388112384408E-8,1,4,13.4005146026611,4.9836795511285,33.390000462532,-0.153015749836598,-0.0228218266950076,1,5.40627367835495E-8,,,,,,,,,,,,,,,,,,,,,200.117462158203,200.181671142578,19999.56640625,19999.56640625,53.396561476996,5.64869495498261,5.07561635971069,54,1,0,0,1,0.301055908203125,34.2131004333496,1,1,3,200.185775756836,0,200.149566650391,,,,,,,,,,,,,,,,,,,,,,,,,,,,,,,,,
,3879803332.60888,200.0947265625,9999.6943359375,-6.15300301445908E-5,1.2401385220159E-8,1,4,13.4005146026611,4.98366707931999,33.390000462532,-0.0761433121594694,-0.0112931170077379,1,7.70411613605992E-8,,,,,,,,,,,,,,,,,,,,,200.093963623047,200.095489501953,9999.6943359375,9999.6943359375,53.6193256049768,5.64874907589438,5.07620763778687,54,2,0,0,1,0.303497314453125,34.2131004333496,1,1,3,200.093963623047,0,200.0947265625,,,,,,,,,,,,,,,,,,,,,,,,,,,,,,,,,
,3879803418.34041,200.202095031738,8499.6904296875,-5.21967954223127E-5,1.08395413192359E-8,1,4,13.4005146026611,4.98361745465636,33.390000462532,-0.0645917727900173,-0.00958515212450957,1,6.11724601170798E-8,,,,,,,,,,,,,,,,,,,,,200.195785522461,200.208404541016,8499.6904296875,8499.6904296875,53.5224036685922,5.64910746134286,5.07474327087402,54,3,0,0,1,0.304107666015625,34.7018585205078,1,1,3,200.195785522461,0,200.202095031738,,,,,,,,,,,,,,,,,,,,,,,,,,,,,,,,,
,3879803520.44361,200.137496948242,6499.71875,-3.97440210241258E-5,1.11855104838081E-8,1,4,13.4005146026611,4.98369075213605,33.390000462532,-0.0491737752826531,-0.00735953336314855,1,-2.71898335234752E-9,,,,,,,,,,,,,,,,,,,,,200.132919311523,200.142074584961,6499.71875,6499.71875,53.6060379201499,5.64843742157758,5.07697772979736,54,1,0,0,1,0.303421020507812,34.2131004333496,1,1,3,200.132919311523,0,200.137496948242,,,,,,,,,,,,,,,,,,,,,,,,,,,,,,,,,
,3879803607.13812,200.089309692383,4999.87890625,-3.04412070588306E-5,7.78920797399405E-9,1,4,13.4005146026611,4.98378060763922,33.390000462532,-0.037669542149978,-0.00560472699393816,1,2.40352942087862E-8,,,,,,,,,,,,,,,,,,,,,200.087890625,200.090728759766,4999.87890625,4999.87890625,53.6337857325826,5.64790970600048,5.07150363922119,54,2,0,0,1,0.3057861328125,34.2131004333496,1,1,3,200.090774536133,0,200.089309692383,,,,,,,,,,,,,,,,,,,,,,,,,,,,,,,,,
,3879803693.17359,200.039878845215,3499.79907226562,-2.11325120517728E-5,1.36894365832994E-8,1,4,13.4005146026611,4.98380188934564,33.390000462532,-0.0261513849898181,-0.00388583713012637,1,2.07501657912315E-8,,,,,,,,,,,,,,,,,,,,,200.037979125977,200.041778564453,3499.79907226562,3499.79907226562,53.521622040073,5.64826698432288,5.07944297790527,54,3,0,0,1,0.3021240234375,34.7018585205078,1,1,3,200.037979125977,0,200.039878845215,,,,,,,,,,,,,,,,,,,,,,,,,,,,,,,,,
,3879803804.10549,200.318572998047,2899.71704101562,-1.75006921312221E-5,1.51945819272893E-8,1,4,13.4005146026611,4.98369562606756,33.390000462532,-0.0216946534656415,-0.00296205354388597,1,2.23984907585591E-7,,,,,,,,,,,,,,,,,,,,,200.314392089844,200.32275390625,2899.71704101562,2899.71704101562,53.4493214020441,5.64816849133095,5.07929420471191,54,1,0,0,1,0.302581787109375,34.2131004333496,1,1,3,200.32275390625,0,200.318572998047,,,,,,,,,,,,,,,,,,,,,,,,,,,,,,,,,
,3879803899.16832,200.348999023438,2749.76586914062,-1.65513093429736E-5,1.17308950467188E-8,1,4,13.4005146026611,4.98378623574714,33.390000462532,-0.0205082346321983,-0.00286858160132863,1,1.57568753448572E-7,,,,,,,,,,,,,,,,,,,,,200.339813232422,200.358184814453,2749.76586914062,2749.76586914062,53.5986124492172,5.64689281141635,5.08036088943481,54,2,0,0,1,0.302352905273438,34.2131004333496,1,1,3,200.358184814453,0,200.348999023438,,,,,,,,,,,,,,,,,,,,,,,,,,,,,,,,,
,3879804064.22365,200.119750976562,2599.7265625,-1.55915196678004E-5,9.13114072349644E-9,1,4,13.4005146026611,4.98365742120606,33.390000462532,-0.0193060998906762,-0.00278360765074281,1,8.25850068846358E-8,,,,,,,,,,,,,,,,,,,,,200.119201660156,200.120300292969,2599.7265625,2599.7265625,53.4704253720634,5.64846189370465,5.07330656051636,54,3,0,0,1,0.30487060546875,34.2131004333496,1,1,3,200.119201660156,0,200.119750976562,,,,,,,,,,,,,,,,,,,,,,,,,,,,,,,,,
,3879804145.98511,200.29305267334,2399.61083984375,-1.44318223870877E-5,1.94919838567788E-8,1,4,13.4005146026611,4.98364642848109,33.390000462532,-0.017895721400439,-0.0024049931599096,1,2.1510506418886E-7,,,,,,,,,,,,,,,,,,,,,200.278533935547,200.307571411133,2399.61083984375,2399.61083984375,53.5517147380633,5.64874363749537,5.0791802406311,54,1,0,0,1,0.302047729492188,33.7243423461914,1,1,3,200.307571411133,0,200.29305267334,,,,,,,,,,,,,,,,,,,,,,,,,,,,,,,,,
,3879804234.21124,200.357597351074,2249.57153320313,-1.34650064290498E-5,1.32465724354118E-8,1,4,13.4005146026611,4.9836576027282,33.390000462532,-0.0166937850035137,-0.00226473889233238,1,1.83839928034249E-7,,,,,,,,,,,,,,,,,,,,,200.357162475586,200.358032226562,2249.57153320313,2249.57153320313,53.4532295446403,5.64892855976107,5.08141756057739,53,2,68,0,0,0.3021240234375,34.2131004333496,1,1,3,200.357162475586,0,200.357597351074,,,,,,,,,,,,,,,,,,,,,,,,,,,,,,,,,
,3879804325.69607,200.174446105957,2099.70825195313,-1.25218468422247E-5,9.65830012930324E-9,1,4,13.4005146026611,4.98365854218621,33.390000462532,-0.0155176583289207,-0.00215163273951174,10,1.34165917147406E-7,,,,,,,,,,,,,,,,,,,,,200.173889160156,200.175003051758,2099.70825195313,2099.70825195313,53.5427260100922,5.64909344468062,5.08732414245605,54,3,0,0,1,0.301132202148438,34.2131004333496,1,1,3,200.173355102539,0,200.174446105957,,,,,,,,,,,,,,,,,,,,,,,,,,,,,,,,,
,3879804426.47341,200.242004394531,1899.79418945313,-1.13286707226822E-5,1.62718527630367E-8,1,4,13.4005146026611,4.98357522812527,33.390000462532,-0.0140634315390172,-0.00178116762079014,1,2.55063288192155E-7,,,,,,,,,,,,,,,,,,,,,200.23649597168,200.247512817383,1899.79418945313,1899.79418945313,53.6158082766403,5.64915617134564,5.07965993881226,53,1,68,0,0,0.302200317382812,34.2131004333496,1,1,3,200.23649597168,0,200.242004394531,,,,,,,,,,,,,,,,,,,,,,,,,,,,,,,,,
,3879804509.99503,200.308807373047,1749.515625,-1.0354693905998E-5,1.63196811511407E-8,1,4,13.4005146026611,4.98354476794871,33.390000462532,-0.0128387606041635,-0.00173139312091542,1,1.49580798329624E-7,,,,,,,,,,,,,,,,,,,,,200.303604125977,200.314010620117,1749.515625,1749.515625,53.4489305877845,5.64962567499309,5.07866764068604,53,2,68,0,0,0.302352905273438,34.2131004333496,1,1,3,200.303604125977,0,200.308807373047,,,,,,,,,,,,,,,,,,,,,,,,,,,,,,,,,
,3879804619.45311,200.384986877441,1599.51403808594,-9.41403535401172E-6,1.54758806980636E-8,1,4,13.4005146026611,4.9836220488095,33.390000462532,-0.0116699739977851,-0.00159232550129344,1,1.21295016341329E-7,,,,,,,,,,,,,,,,,,,,,200.384918212891,200.385055541992,1599.51403808594,1599.51403808594,53.4633907153903,5.64941865216401,5.08018398284912,52,3,68,0,0,0.302886962890625,34.2131004333496,1,1,3,200.385055541992,0,200.384986877441,,,,,,,,,,,,,,,,,,,,,,,,,,,,,,,,,
,3879804739.56764,200.246734619141,1399.90209960938,-8.27848395088252E-6,2.25305403645532E-8,1,4,13.4005146026611,4.9836933920307,33.390000462532,-0.0102868181163442,-0.00123778877612162,1,2.37995608837796E-7,,,,,,,,,,,,,,,,,,,,,200.242599487305,200.250869750977,1399.90209960938,1399.90209960938,53.668959015948,5.64896705000942,5.08804559707642,53,1,68,0,0,0.303878784179687,34.2131004333496,1,1,3,200.250869750977,0,200.246734619141,,,,,,,,,,,,,,,,,,,,,,,,,,,,,,,,,
,3879804835.43983,200.192077636719,1249.673828125,-7.2832217394216E-6,1.40625879095258E-8,1,4,13.4005146026611,4.98362964552343,33.390000462532,-0.00904617049230247,-0.00111419725137088,1,1.88984386485674E-7,,,,,,,,,,,,,,,,,,,,,200.187728881836,200.196426391602,1249.673828125,1249.673828125,53.5110700550634,5.64929914680607,5.08370733261108,53,2,68,0,0,0.305252075195313,34.2131004333496,1,1,3,200.187728881836,0,200.192077636719,,,,,,,,,,,,,,,,,,,,,,,,,,,,,,,,,
,3879804951.27141,200.20295715332,1099.87353515625,-6.34204322158017E-6,1.14437507924705E-8,1,4,13.4005146026611,4.98362353857594,33.390000462532,-0.00786804148943384,-0.00103117035841069,10,1.15294244404619E-7,,,,,,,,,,,,,,,,,,,,,200.202911376953,200.203002929687,1099.87353515625,1099.87353515625,53.3981247340345,5.64975885185665,5.08927345275879,54,3,0,0,1,0.3045654296875,34.2131004333496,1,1,3,200.202911376953,0,200.20295715332,,,,,,,,,,,,,,,,,,,,,,,,,,,,,,,,,
,3879805071.54201,200.138481140137,899.808471679688,-5.15910667869415E-6,2.40121132822279E-8,1,4,13.4005146026611,4.98355749852093,33.390000462532,-0.00642630055477141,-6.65359528406806E-4,1,2.33988316170529E-7,,,,,,,,,,,,,,,,,,,,,200.134140014648,200.142822265625,899.808471679688,899.808471679688,53.5669564941884,5.64943456565457,5.09048175811768,54,1,0,0,1,0.304336547851562,34.2131004333496,1,1,3,200.134140014648,0,200.138481140137,,,,,,,,,,,,,,,,,,,,,,,,,,,,,,,,,
,3879805186.66695,200.081718444824,749.844604492188,-4.21936108693668E-6,1.35533380532883E-8,1,4,13.4005146026611,4.98345334807735,33.390000462532,-0.00524565424428014,-6.10484268162121E-4,10,1.37747070662777E-7,,,,,,,,,,,,,,,,,,,,,200.081390380859,200.082046508789,749.844604492188,749.844604492188,53.4805865428134,5.64896905936015,5.08994436264038,54,2,0,0,1,0.30364990234375,33.7243423461914,1,1,3,200.081390380859,0,200.081718444824,,,,,,,,,,,,,,,,,,,,,,,,,,,,,,,,,
,3879805297.23905,200.11247253418,600.056884765625,-3.29681488512494E-6,1.04612948216278E-8,1,4,13.4005146026611,4.98349708452917,33.390000462532,-0.00409907541618366,-4.7492631880033E-4,1,1.0931359963341E-7,,,,,,,,,,,,,,,,,,,,,200.111694335938,200.113250732422,600.056884765625,600.056884765625,53.4966099274576,5.65009824831646,5.0938925743103,54,3,0,0,1,0.302810668945313,33.7243423461914,1,1,3,200.111694335938,0,200.11247253418,,,,,,,,,,,,,,,,,,,,,,,,,,,,,,,,,
,3879805411.07095,200.150169372559,399.916259765625,-2.13674575602889E-6,2.28256319995501E-8,1,4,13.4005146026611,4.98349890929767,33.390000462532,-0.00268959803033398,-8.79736100984919E-5,1,2.4853744457821E-7,,,,,,,,,,,,,,,,,,,,,200.148178100586,200.152160644531,399.916259765625,399.916259765625,53.4020328766306,5.64830540347062,5.09571552276611,54,1,0,0,1,0.301895141601562,33.7243423461914,1,1,3,200.148178100586,0,200.150169372559,,,,,,,,,,,,,,,,,,,,,,,,,,,,,,,,,
,3879805512.81926,200.338668823242,249.939788818359,-1.20000076501469E-6,1.34054287125554E-8,1,4,13.4005146026611,4.98368881474578,33.390000462532,-0.00150929209854168,-5.79144412718419E-5,10,1.32704634922001E-7,,,,,,,,,,,,,,,,,,,,,200.338043212891,200.339294433594,249.939788818359,249.939788818359,53.6076011771884,5.64904765673526,5.095703125,54,2,0,0,1,0.301589965820313,33.7243423461914,1,1,3,200.340301513672,0,200.338668823242,,,,,,,,,,,,,,,,,,,,,,,,,,,,,,,,,
,3879805621.92425,200.07398223877,100.064041137695,-2.76457248378534E-7,1.26765090634747E-8,1,4,13.4005146026611,4.98375529341922,33.390000462532,-3.58540866880402E-4,5.90019050351988E-5,1,8.90424177195392E-8,,,,,,,,,,,,,,,,,,,,,200.073043823242,200.074920654297,100.064041137695,100.064041137695,53.5513239238037,5.64864325727545,5.10021018981934,54,3,0,0,1,0.302276611328125,33.7243423461914,1,1,3,200.073043823242,0,200.07398223877,,,,,,,,,,,,,,,,,,,,,,,,,,,,,,,,,
,3879805723.58508,200.147521972656,-99.9381561279297,8.05474893528805E-7,1.04639889070911E-8,1,4,13.4005146026611,4.98365974794488,33.390000462532,9.69015658669108E-4,3.33378610811176E-4,1,1.48954143514329E-7,,,,,,,,,,,,,,,,,,,,,200.147079467773,200.147964477539,-99.9381561279297,-99.9381561279297,53.4309531318422,5.64901081837498,5.09418678283691,52,1,68,0,0,0.302734375,34.2131004333496,1,1,3,200.147964477539,0,200.147521972656,,,,,,,,,,,,,,,,,,,,,,,,,,,,,,,,,
,3879805830.57772,200.245941162109,-249.889434814453,1.63754761875521E-6,2.28273319485462E-8,1,4,13.4005146026611,4.98401844366488,33.390000462532,0.0019924483795482,5.29299016226166E-4,1,1.82787700010888E-7,,,,,,,,,,,,,,,,,,,,,200.244445800781,200.247436523438,-249.889434814453,-249.889434814453,53.5325648393422,5.64742827200956,5.09396409988403,52,2,68,0,0,0.300827026367188,33.7243423461914,1,1,3,200.244445800781,0,200.245941162109,,,,,,,,,,,,,,,,,,,,,,,,,,,,,,,,,
,3879805946.16709,200.148246765137,-399.891082763672,2.49743156392917E-6,1.34030816618091E-8,1,4,13.4005146026611,4.98379435181315,33.390000462532,0.00307515493262734,5.62160430212342E-4,10,8.07400780165427E-8,,,,,,,,,,,,,,,,,,,,,200.147354125977,200.149139404297,-399.891082763672,-399.891082763672,53.4032053194095,5.64794778914682,5.09765672683716,54,3,0,0,1,0.3033447265625,33.7243423461914,1,1,3,200.147354125977,0,200.148246765137,,,,,,,,,,,,,,,,,,,,,,,,,,,,,,,,,
,3879806068.50794,200.092353820801,-599.780029296875,3.59131514061938E-6,1.78807470538092E-8,1,4,13.4005146026611,4.98361502412402,33.3999991416931,0.00440625012466247,9.12696680306352E-4,1,2.00443967563157E-7,,,,,,,,,,,,,,,,,,,,,200.088577270508,200.096130371094,-599.780029296875,-599.780029296875,53.6709130872461,5.64938188164776,5.10202550888062,54,1,0,0,1,0.3033447265625,33.7243423461914,1,1,3,200.088577270508,0,200.092353820801,,,,,,,,,,,,,,,,,,,,,,,,,,,,,,,,,
,3879806169.41254,200.169227600098,-749.781616210937,4.50452654648775E-6,1.63168121114157E-8,1,4,13.4005146026611,4.98351338341711,33.4100015461445,0.00554135801542951,0.00104561036683091,1,1.71284182071383E-7,,,,,,,,,,,,,,,,,,,,,200.166122436523,200.172332763672,-749.781616210937,-749.781616210937,53.5872788356884,5.64909669922643,5.09981489181519,52,2,68,0,0,0.302352905273438,33.2355842590332,1,1,3,200.166122436523,0,200.169227600098,,,,,,,,,,,,,,,,,,,,,,,,,,,,,,,,,
,3879806281.29437,200.276412963867,-899.720336914062,5.43459660465742E-6,1.68081743660981E-8,1,4,13.4005146026611,4.98352540339019,33.3999991416931,0.00670660889236628,0.00112059908579857,1,9.27593610335067E-8,,,,,,,,,,,,,,,,,,,,,200.270645141602,200.282180786133,-899.720336914062,-899.720336914062,53.6857640291115,5.64921283471814,5.0997052192688,52,3,68,0,0,0.30303955078125,33.7243423461914,1,1,3,200.282180786133,0,200.276412963867,,,,,,,,,,,,,,,,,,,,,,,,,,,,,,,,,
,3879806392.23687,200.062492370605,-1099.697265625,6.48970355833547E-6,1.72245430073115E-7,1,4,13.4005146026611,4.98347482985245,33.4100015461445,0.00796488424875827,0.00163009122308494,1,3.46745520225152E-7,,,,,,,,,,,,,,,,,,,,,200.060668945313,200.064315795898,-1099.697265625,-1099.697265625,53.394607405698,5.64934954310405,5.09781932830811,54,1,0,0,1,0.30181884765625,33.2355842590332,1,1,3,200.064315795898,0,200.062492370605,,,,,,,,,,,,,,,,,,,,,,,,,,,,,,,,,
,3879806507.84493,200.198554992676,-1249.68640136719,7.5777556713101E-6,7.02606498516174E-9,1,4,13.4005146026611,4.98342630480007,33.3999991416931,0.00935578782435354,0.00153134028892081,10,1.04178429228323E-7,,,,,,,,,,,,,,,,,,,,,200.197555541992,200.199554443359,-1249.68640136719,-1249.68640136719,53.4837130568903,5.64888894382928,5.10681390762329,54,2,0,0,1,0.3021240234375,33.7243423461914,1,1,3,200.197555541992,0,200.198554992676,,,,,,,,,,,,,,,,,,,,,,,,,,,,,,,,,
,3879806593.56387,200.099945068359,-1399.59997558594,8.49209726242198E-6,8.22773188302638E-9,1,4,13.4005146026611,4.98341158625592,33.3999991416931,0.0104863482751013,0.0017045907888038,1,1.07440571529926E-7,,,,,,,,,,,,,,,,,,,,,200.097579956055,200.102310180664,-1399.59997558594,-1399.59997558594,53.5071619124672,5.65001852010522,5.098219871521,53,3,68,0,0,0.304641723632812,33.2355842590332,1,1,3,200.097579956055,0,200.099945068359,,,,,,,,,,,,,,,,,,,,,,,,,,,,,,,,,
,3879806687.34302,200.215522766113,-1599.56433105469,9.70268327520562E-6,1.15577172486796E-8,1,4,13.4005146026611,4.98341545847014,33.3999991416931,0.0119763431056205,0.00198030207162335,1,1.49197664700819E-7,,,,,,,,,,,,,,,,,,,,,200.212997436523,200.218048095703,-1599.56433105469,-1599.56433105469,53.4966099274576,5.64980029374336,5.10358572006226,53,1,68,0,0,0.300674438476562,33.7243423461914,1,1,3,200.218048095703,0,200.215522766113,,,,,,,,,,,,,,,,,,,,,,,,,,,,,,,,,
,3879806766.72431,200.323844909668,-1749.59118652344,1.06703148780134E-5,2.5768910636943E-8,1,4,13.4005146026611,4.98364383169243,33.3999991416931,0.0131877166128328,0.0020699958401849,10,7.68369779168512E-8,,,,,,,,,,,,,,,,,,,,,200.322479248047,200.325210571289,-1749.59118652344,-1749.59118652344,53.4587009442749,5.64994545194398,5.10086631774902,54,2,0,0,1,0.301895141601562,33.2355842590332,1,1,3,200.322021484375,0,200.323844909668,,,,,,,,,,,,,,,,,,,,,,,,,,,,,,,,,
,3879806844.24697,200.161636352539,-1900.00817871094,1.15541797903676E-5,1.10854422858915E-7,1,4,13.4005146026611,4.98352020432455,33.4100015461445,0.0143037648389689,0.00207992079893086,1,-4.73035222938166E-8,,,,,,,,,,,,,,,,,,,,,200.156188964844,200.167083740234,-1900.00817871094,-1900.00817871094,53.4297806890633,5.65027922638322,5.10833358764648,54,3,0,0,1,0.301132202148438,33.7243423461914,1,1,3,200.156188964844,0,200.161636352539,,,,,,,,,,,,,,,,,,,,,,,,,,,,,,,,,
,3879806937.11573,200.277755737305,-2099.83422851562,1.27602090060772E-5,3.0495777803115E-8,1,4,13.4005146026611,4.98364197879607,33.3999991416931,0.0157636167179163,0.002522523181277,1,1.29952778163118E-7,,,,,,,,,,,,,,,,,,,,,200.269439697266,200.286071777344,-2099.83422851562,-2099.83422851562,53.498173184496,5.64961875008538,5.10346555709839,53,1,68,0,0,0.301284790039063,33.2355842590332,1,1,3,200.269439697266,0,200.277755737305,,,,,,,,,,,,,,,,,,,,,,,,,,,,,,,,,
,3879807019.90885,200.311019897461,-2249.79809570313,1.37093166638453E-5,9.26815278525822E-9,1,4,13.4005146026611,4.98358578241393,33.3999991416931,0.0169406893318074,0.00267776087736378,1,1.13475511083457E-7,,,,,,,,,,,,,,,,,,,,,200.298202514648,200.323837280273,-2249.79809570313,-2249.79809570313,53.5642207943711,5.65043841799486,5.10013198852539,54,2,0,0,1,0.304107666015625,33.7243423461914,1,1,3,200.323837280273,0,200.311019897461,,,,,,,,,,,,,,,,,,,,,,,,,,,,,,,,,
,3879807091.75696,200.242668151855,-2399.72412109375,1.46514627835074E-5,3.58202152334947E-8,1,4,13.4005146026611,4.98367994787778,33.3999991416931,0.0181233017358856,0.00274209307661094,1,2.44741086029682E-8,,,,,,,,,,,,,,,,,,,,,200.234649658203,200.250686645508,-2399.72412109375,-2399.72412109375,53.5052078411691,5.64968780926233,5.10176515579224,54,3,0,0,1,0.303726196289063,33.7243423461914,1,1,3,200.234649658203,0,200.242668151855,,,,,,,,,,,,,,,,,,,,,,,,,,,,,,,,,
,3879807173.98916,200.213394165039,-2599.57543945313,1.58713449430858E-5,8.40196499471511E-9,1,4,13.4005146026611,4.98361317758431,33.3999991416931,0.0196198087212856,0.00305104105599407,1,9.17347245217545E-8,,,,,,,,,,,,,,,,,,,,,200.194717407227,200.232070922852,-2599.57543945313,-2599.57543945313,53.4563560587172,5.65033667358021,5.1085033416748,54,1,0,0,1,0.30303955078125,33.2355842590332,1,1,3,200.232070922852,0,200.213394165039,,,,,,,,,,,,,,,,,,,,,,,,,,,,,,,,,
,3879807245.42715,200.239936828613,-2749.677734375,1.67586459226912E-5,5.94587148529255E-8,1,4,13.4005146026611,4.98355785579915,33.3999991416931,0.0207132342283992,0.0032423772301198,1,1.13687381097825E-7,,,,,,,,,,,,,,,,,,,,,200.231674194336,200.248199462891,-2749.677734375,-2749.677734375,53.5610942802941,5.64964315465244,5.10934686660767,53,2,68,0,0,0.303115844726562,33.2355842590332,1,1,3,200.231674194336,0,200.239936828613,,,,,,,,,,,,,,,,,,,,,,,,,,,,,,,,,
,3879807317.32663,200.096969604492,-2899.61645507812,1.77204442788628E-5,7.78014843278111E-9,1,4,13.4005146026611,4.98362498797095,33.3999991416931,0.0219134423807478,0.00335474363961989,1,6.05780802814944E-8,,,,,,,,,,,,,,,,,,,,,200.094085693359,200.099853515625,-2899.61645507812,-2899.61645507812,53.5743819651211,5.64992728963807,5.1005392074585,53,3,68,0,0,0.302734375,33.2355842590332,1,1,3,200.094085693359,0,200.096969604492,,,,,,,,,,,,,,,,,,,,,,,,,,,,,,,,,
,3879807422.24944,200.158706665039,-3499.74877929687,2.14803103461235E-5,3.70680829389333E-8,1,4,13.4005146026611,4.98378756143456,33.3999991416931,0.0265870733417979,0.00391369779267235,1,-5.02488314157118E-8,,,,,,,,,,,,,,,,,,,,,200.153930664062,200.163482666016,-3499.74877929687,-3499.74877929687,53.420010332573,5.64888509808976,5.10077428817749,54,1,0,0,1,0.301895141601562,33.7243423461914,1,1,3,200.163482666016,0,200.158706665039,,,,,,,,,,,,,,,,,,,,,,,,,,,,,,,,,
,3879807506.93846,200.236572265625,-4999.740234375,3.07505421023638E-5,9.01490241796115E-9,1,4,13.4005146026611,4.98364792302178,33.3999991416931,0.0380566724606675,0.00562293577163588,1,-5.54236803538777E-8,,,,,,,,,,,,,,,,,,,,,200.217010498047,200.256134033203,-4999.740234375,-4999.740234375,53.501299698573,5.64925150505917,5.11016511917114,54,2,0,0,1,0.302047729492188,33.7243423461914,1,1,3,200.256134033203,0,200.236572265625,,,,,,,,,,,,,,,,,,,,,,,,,,,,,,,,,
,3879807591.77625,200.416191101074,-6499.6181640625,4.00470269478964E-5,1.28412819148838E-8,1,4,13.4005146026611,4.98362557630392,33.3999991416931,0.0495588233976917,0.00734157561265007,1,-5.7013910379441E-8,,,,,,,,,,,,,,,,,,,,,200.408157348633,200.424224853516,-6499.6181640625,-6499.6181640625,53.547024966948,5.65049678846254,5.10712671279907,54,3,0,0,1,0.303268432617188,33.7243423461914,6,1,3,200.424224853516,0,200.416191101074,,,,,,,,,,,,,,,,,,,,,,,,,,,,,,,,,
,3879807706.37767,200.448188781738,-8499.765625,5.24634532649574E-5,1.04452722411817E-8,1,4,13.4005146026611,4.98380485250597,33.4100015461445,0.0649311823240762,0.00959449149172051,1,-9.3923453981003E-8,,,,,,,,,,,,,,,,,,,,,200.4404296875,200.455947875977,-8499.765625,-8499.765625,53.3961706627364,5.6481658366023,5.10304403305054,54,1,0,0,1,0.301666259765625,33.7243423461914,1,1,3,200.455947875977,0,200.448188781738,,,,,,,,,,,,,,,,,,,,,,,,,,,,,,,,,
,3879807791.63015,200.301612854004,-9999.5439453125,6.1749543571851E-5,1.22888586195098E-8,1,4,13.4005146026611,4.98355294622433,33.3999991416931,0.0764139698900722,0.0113232444604357,1,-8.52349271374838E-8,,,,,,,,,,,,,,,,,,,,,200.286651611328,200.31657409668,-9999.5439453125,-9999.5439453125,53.5122424978422,5.65063174163384,5.11010694503784,54,2,0,0,1,0.3021240234375,33.2355842590332,1,1,3,200.31657409668,0,200.301612854004,,,,,,,,,,,,,,,,,,,,,,,,,,,,,,,,,
,3879808060.77966,200.060760498047,-19999.640625,1.23825946789317E-4,2.22923123260156E-8,1,4,13.4005146026611,4.98362597075803,33.3999991416931,0.153226039053819,0.0227706271498108,1,-1.19408565937048E-7,,,,,,,,,,,,,,,,,,,,,200.057647705078,200.063873291016,-19999.640625,-19999.640625,53.5896237212461,5.6504312662266,5.11116409301758,54,3,0,0,1,0.303115844726562,33.2355842590332,1,1,3,200.063873291016,0,200.060760498047,,,,,,,,,,,,,,,,,,,,,,,,,,,,,,,,,
,3879808344.09376,200.131355285645,-39999.5703125,2.48060924588104E-4,4.33457495929018E-8,1,4,13.4005146026611,4.98351891328317,33.3999991416931,0.306931742119793,0.0457302854371056,1,-1.46108552060752E-7,,,,,,,,,,,,,,,,,,,,,200.124130249023,200.138580322266,-39999.5703125,-39999.5703125,53.457528501496,5.65012919777042,5.10202407836914,54,1,0,0,1,0.302658081054687,33.7243423461914,1,1,3,200.138580322266,0,200.131355285645,,,,,,,,,,,,,,,,,,,,,,,,,,,,,,,,,
,3879808595.64578,200.027526855469,-54999.48046875,3.41493082611661E-4,5.75029938515363E-8,1,4,13.4005146026611,4.98349342600006,33.3999991416931,0.422613472079794,0.0624266655443335,10,-6.27489772453928E-7,,,,,,,,,,,,,,,,,,,,,200.027008056641,200.028045654297,-54999.48046875,-54999.48046875,53.3496637658422,5.64989582171153,5.11013841629028,54,2,0,0,1,0.30181884765625,33.7243423461914,1,1,3,200.026718139648,0,200.027526855469,,,,,,,,,,,,,,,,,,,,,,,,,,,,,,,,,
,3879808855.84148,200.208625793457,-69999.7890625,4.34397561601755E-4,1.50788819475774E-7,1,4,13.4005146026611,4.98358540650608,33.3999991416931,0.537480435335814,0.0802179482966456,1,-1.46897824868034E-7,,,,,,,,,,,,,,,,,,,,,200.208526611328,200.208724975586,-69999.7890625,-69999.7890625,53.2257756455441,5.64933671913091,5.10313558578491,54,3,0,0,1,0.302886962890625,33.7243423461914,1,1,3,200.208526611328,0,200.208625793457,,,,,,,,,,,,,,,,,,,,,,,,,,,,,,,,,
,3879809136.25162,200.106117248535,-49999.515625,3.10066165938534E-4,6.51717459319524E-8,1,4,13.4005146026611,4.98351016887958,33.3999991416931,0.383635672238485,0.0572658269156777,1,-9.77999777514927E-8,,,,,,,,,,,,,,,,,,,,,200.088455200195,200.123779296875,-49999.515625,-49999.515625,53.3645147077076,5.64944707688183,5.10544347763062,54,1,0,0,1,0.300750732421875,33.7243423461914,1,1,3,200.123779296875,0,200.106117248535,,,,,,,,,,,,,,,,,,,,,,,,,,,,,,,,,
,3879809359.37008,200.093223571777,-34999.50390625,2.16828646355352E-4,4.04497575514049E-8,1,4,13.4005146026611,4.98344848175211,33.3999991416931,0.268281250050724,0.0399766275633865,1,-1.23802782080445E-7,,,,,,,,,,,,,,,,,,,,,200.077392578125,200.10905456543,-34999.50390625,-34999.50390625,53.5743819651211,5.65057532005937,5.10719633102417,54,2,0,0,1,0.302658081054687,34.2131004333496,1,1,3,200.10905456543,0,200.093223571777,,,,,,,,,,,,,,,,,,,,,,,,,,,,,,,,,
,3879809580.78549,200.257804870605,-19999.640625,1.23621330541492E-4,1.74779594268812E-8,1,4,13.4005146026611,4.98343751721755,33.3999991416931,0.152963946621364,0.0227369917558709,1,-1.15009700114868E-7,,,,,,,,,,,,,,,,,,,,,200.241165161133,200.274444580078,-19999.640625,-19999.640625,53.4563560587172,5.64930107961203,5.10979318618774,54,3,0,0,1,0.304107666015625,34.2131004333496,1,1,3,200.274444580078,0,200.257804870605,,,,,,,,,,,,,,,,,,,,,,,,,,,,,,,,,
,3879809783.66055,200.316528320313,-9500.3935546875,5.83765298019334E-5,1.07803514956169E-8,1,4,13.4005146026611,4.98345349648431,33.3999991416931,0.0722284128065614,0.0107678569146953,1,-2.93062364940553E-8,,,,,,,,,,,,,,,,,,,,,200.290740966797,200.342315673828,-9500.3935546875,-9500.3935546875,53.5544504378807,5.65037851991822,5.10821294784546,54,1,0,0,1,0.303268432617188,34.2131004333496,1,1,3,200.344635009766,0,200.316528320313,,,,,,,,,,,,,,,,,,,,,,,,,,,,,,,,,
,3879809955.43446,200.164291381836,-8000.31396484375,4.90685993936728E-5,1.07058206859443E-8,1,4,13.4005146026611,4.9832971228022,33.3999991416931,0.0607119462090001,0.0090320422165938,1,-3.96032126319497E-8,,,,,,,,,,,,,,,,,,,,,200.163421630859,200.165161132813,-8000.31396484375,-8000.31396484375,53.4645631581691,5.65063766462369,5.10968637466431,54,2,0,0,1,0.302810668945313,34.2131004333496,1,1,3,200.163208007813,0,200.164291381836,,,,,,,,,,,,,,,,,,,,,,,,,,,,,,,,,
,3879810039.73302,200.294960021973,-6500.4111328125,3.9752760685704E-5,8.9734094346857E-9,1,4,13.4005146026611,4.9833631213351,33.4100015461445,0.0491875976359431,0.00731003011297946,1,-3.80532993893402E-8,,,,,,,,,,,,,,,,,,,,,200.286514282227,200.303405761719,-6500.4111328125,-6500.4111328125,53.5548412521403,5.6505116255342,5.10627508163452,54,3,0,0,1,0.30303955078125,34.2131004333496,1,1,3,200.303405761719,0,200.294960021973,,,,,,,,,,,,,,,,,,,,,,,,,,,,,,,,,
,3879810223.80917,200.146133422852,-4500.47705078125,2.73109058593455E-5,9.45699165303519E-9,1,4,13.4005146026611,4.98343762650671,33.3999991416931,0.0337860008591076,0.00507255256192365,1,1.45270740139893E-8,,,,,,,,,,,,,,,,,,,,,200.132629394531,200.159637451172,-4500.47705078125,-4500.47705078125,53.4704253720634,5.65020478757994,5.1090521812439,54,1,0,0,1,0.302276611328125,34.2131004333496,1,1,3,200.159637451172,0,200.146133422852,,,,,,,,,,,,,,,,,,,,,,,,,,,,,,,,,
,3879810307.11345,200.172386169434,-3000.15893554687,1.80037528110411E-5,7.87645429933293E-9,1,4,13.4005146026611,4.98347383428924,33.3999991416931,0.0222729560411409,0.00334060774166053,1,6.88653816606825E-9,,,,,,,,,,,,,,,,,,,,,200.16926574707,200.175506591797,-3000.15893554687,-3000.15893554687,53.4692529292845,5.65079300981071,5.10894870758057,52,2,68,0,0,0.302963256835937,34.2131004333496,1,1,3,200.175582885742,0,200.172386169434,,,,,,,,,,,,,,,,,,,,,,,,,,,,,,,,,
,3879810394.08763,200.289268493652,-2900.38427734375,1.74585019118271E-5,9.70305147121935E-9,1,4,13.4005146026611,4.98334731955342,33.3999991416931,0.0216207448170945,0.00308487869570768,1,-1.18158421175585E-7,,,,,,,,,,,,,,,,,,,,,200.282623291016,200.295913696289,-2900.38427734375,-2900.38427734375,53.6302684042461,5.64978896123206,5.10165452957153,54,3,0,0,1,0.30181884765625,34.2131004333496,1,1,3,200.295913696289,0,200.289268493652,,,,,,,,,,,,,,,,,,,,,,,,,,,,,,,,,
,3879810487.54983,200.132179260254,-2700.35693359375,1.62544333932575E-5,1.72223644620067E-8,1,4,13.4005146026611,4.98345145436661,33.4100015461445,0.0201473664591908,0.0027575010142566,1,-2.0272388069428E-7,,,,,,,,,,,,,,,,,,,,,200.126983642578,200.13737487793,-2700.35693359375,-2700.35693359375,53.5524963665826,5.65092073134197,5.10302352905273,54,1,0,0,1,0.302658081054687,34.2131004333496,1,1,3,200.126983642578,0,200.132179260254,,,,,,,,,,,,,,,,,,,,,,,,,,,,,,,,,
,3879810558.81322,200.065948486328,-2550.40576171875,1.52885041090054E-5,1.22551831995662E-8,1,4,13.4005146026611,4.98395560430728,33.3999991416931,0.0189474487657121,0.00262968923794142,1,-1.61836469735973E-7,,,,,,,,,,,,,,,,,,,,,200.064559936523,200.067337036133,-2550.40576171875,-2550.40576171875,53.5915777925441,5.64747595283049,5.10418939590454,53,2,68,0,0,0.301589965820313,34.2131004333496,1,1,3,200.064559936523,0,200.065948486328,,,,,,,,,,,,,,,,,,,,,,,,,,,,,,,,,
,3879810642.27775,200.22233581543,-2400.42895507813,1.43799387190958E-5,9.96924698055494E-9,1,4,13.4005146026611,4.98364559627844,33.3999991416931,0.0178152198094494,0.00250437711556827,1,-1.27017230358489E-7,,,,,,,,,,,,,,,,,,,,,200.219177246094,200.225494384766,-2400.42895507813,-2400.42895507813,53.5372546104576,5.65042891207567,5.10765695571899,54,3,0,0,1,0.30029296875,34.2131004333496,1,1,3,200.225494384766,0,200.22233581543,,,,,,,,,,,,,,,,,,,,,,,,,,,,,,,,,
,3879810724.02624,200.20418548584,-2200.41430664062,1.31761149679916E-5,1.7371909183982E-8,1,4,13.4005146026611,4.98364906650671,33.3999991416931,0.0163388923465957,0.00219400738430535,1,-1.97786990538143E-7,,,,,,,,,,,,,,,,,,,,,200.194244384766,200.214126586914,-2200.41430664062,-2200.41430664062,53.582589064573,5.64955146909236,5.10755014419556,54,1,0,0,1,0.302658081054687,34.2131004333496,1,1,3,200.194244384766,0,200.20418548584,,,,,,,,,,,,,,,,,,,,,,,,,,,,,,,,,
,3879810796.25019,200.25666809082,-2050.3623046875,1.22042245607162E-5,1.41727764541608E-8,1,4,13.4005146026611,4.98345924564933,33.3999991416931,0.0151238193418788,0.0020927799578476,1,-1.34123555212694E-7,,,,,,,,,,,,,,,,,,,,,200.242080688477,200.271255493164,-2050.3623046875,-2050.3623046875,53.5821982503134,5.65032274297223,5.10173034667969,53,2,68,0,0,0.303192138671875,34.2131004333496,1,1,3,200.271255493164,0,200.25666809082,,,,,,,,,,,,,,,,,,,,,,,,,,,,,,,,,
,3879810866.89342,200.277137756348,-1900.38586425781,1.12725346485549E-5,1.13703086292289E-8,1,4,13.4005146026611,4.98348734929446,33.3999991416931,0.0139701463975203,0.0019277284762191,1,-1.28168709258078E-7,,,,,,,,,,,,,,,,,,,,,200.268814086914,200.285461425781,-1900.38586425781,-1900.38586425781,53.4688621150249,5.64935665215112,5.10906267166138,54,3,0,0,1,0.301742553710937,34.2131004333496,1,1,3,200.268814086914,0,200.277137756348,,,,,,,,,,,,,,,,,,,,,,,,,,,,,,,,,
,3879810948.80018,200.314933776855,-1700.13195800781,1.00710898057623E-5,1.8599508587248E-8,1,4,13.4005146026611,4.98346370937987,33.3999991416931,0.0125020351556461,0.00158232795217902,1,-2.27609754479647E-7,,,,,,,,,,,,,,,,,,,,,200.302993774414,200.326873779297,-1700.13195800781,-1700.13195800781,53.4571376872364,5.64989484607425,5.10142755508423,54,1,0,0,1,0.303955078125,33.7243423461914,1,1,3,200.326873779297,0,200.314933776855,,,,,,,,,,,,,,,,,,,,,,,,,,,,,,,,,
,3879811019.34459,200.252311706543,-1550.14294433594,9.12572144927845E-6,1.47519102496781E-8,1,4,13.4005146026611,4.98354905982435,33.3999991416931,0.0113203341762651,0.00149007023131123,1,-1.60787437523296E-7,,,,,,,,,,,,,,,,,,,,,200.246704101562,200.257919311523,-1550.14294433594,-1550.14294433594,53.427044989246,5.64945621384602,5.10214853286743,52,2,68,0,0,0.303268432617188,34.2131004333496,1,1,3,200.246047973633,0,200.252311706543,,,,,,,,,,,,,,,,,,,,,,,,,,,,,,,,,
,3879811090.94426,200.203712463379,-1400.12866210938,8.2018092006724E-6,1.34626950655981E-8,1,4,13.4005146026611,4.98346200754849,33.3999991416931,0.0101696652650693,0.00136804947106369,1,-1.21173263189745E-7,,,,,,,,,,,,,,,,,,,,,200.198333740234,200.209091186523,-1400.12866210938,-1400.12866210938,53.4415051168518,5.64947430686044,5.10904979705811,54,3,0,0,1,0.301284790039063,34.2131004333496,1,1,3,200.198333740234,0,200.203712463379,,,,,,,,,,,,,,,,,,,,,,,,,,,,,,,,,
,3879811174.25537,200.271133422852,-1200.16418457031,6.98690811064429E-6,2.38961239319409E-8,1,4,13.4005146026611,4.98346371428398,33.3999991416931,0.00868532146833536,0.00101804899082845,1,-2.2233028889192E-7,,,,,,,,,,,,,,,,,,,,,200.266387939453,200.27587890625,-1200.16418457031,-1200.16418457031,53.488012013746,5.64961697808799,5.10690784454346,53,1,68,0,0,0.304946899414063,33.7243423461914,1,1,3,200.265716552734,0,200.271133422852,,,,,,,,,,,,,,,,,,,,,,,,,,,,,,,,,
,3879811245.45107,200.232780456543,-1050.17517089844,6.05591398447012E-6,1.50377524260635E-8,1,4,13.4005146026611,4.98357647100218,33.3999991416931,0.00752430711877423,9.0881779434451E-4,1,-1.71371958824356E-7,,,,,,,,,,,,,,,,,,,,,200.228240966797,200.237319946289,-1050.17517089844,-1050.17517089844,53.4997364415345,5.65047001252481,5.10659980773926,54,2,0,0,1,0.304107666015625,33.7243423461914,1,1,3,200.228240966797,0,200.232780456543,,,,,,,,,,,,,,,,,,,,,,,,,,,,,,,,,
,3879811316.1768,200.283226013184,-900.160949707031,5.11993690756195E-6,1.26445497034312E-8,1,4,13.4005146026611,4.98359180409318,33.3999991416931,0.0063593371548968,7.82205912698555E-4,1,-1.33692821919757E-7,,,,,,,,,,,,,,,,,,,,,200.275741577148,200.290710449219,-900.160949707031,-900.160949707031,53.5435076386114,5.65019158655143,5.10833024978638,53,3,68,0,0,0.303268432617188,34.2131004333496,1,1,3,200.290710449219,0,200.283226013184,,,,,,,,,,,,,,,,,,,,,,,,,,,,,,,,,
,3879811396.99637,200.343444824219,-700.183959960937,3.94261236546437E-6,2.84287440825524E-8,1,4,13.4005146026611,4.98364496148049,33.3999991416931,0.00492779899956632,3.97044957211244E-4,1,-2.68883603659693E-7,,,,,,,,,,,,,,,,,,,,,200.338424682617,200.34846496582,-700.183959960937,-700.183959960937,53.4172746327557,5.64924144526501,5.10493564605713,52,1,68,0,0,0.303421020507812,34.2131004333496,1,1,3,200.338424682617,0,200.343444824219,,,,,,,,,,,,,,,,,,,,,,,,,,,,,,,,,
,3879811467.65342,200.301750183105,-550.182250976562,2.98818734278543E-6,1.92857560677231E-8,1,4,13.4005146026611,4.98362569469079,33.3999991416931,0.00372988011149085,3.34218887355313E-4,1,-1.76884466212847E-7,,,,,,,,,,,,,,,,,,,,,200.297958374023,200.305541992187,-550.182250976562,-550.182250976562,53.4919201563422,5.64956393365474,5.10136604309082,54,2,0,0,1,0.303192138671875,33.7243423461914,1,1,3,200.305541992187,0,200.301750183105,,,,,,,,,,,,,,,,,,,,,,,,,,,,,,,,,
,3879811538.0027,200.230606079102,-400.230987548828,2.08192821476809E-6,1.5141237540036E-8,1,4,13.4005146026611,4.98370114092875,33.3999991416931,0.00259962559725278,2.26909542264143E-4,1,-1.28049566264113E-7,,,,,,,,,,,,,,,,,,,,,200.228485107422,200.232727050781,-400.230987548828,-400.230987548828,53.4915293420826,5.6499233073005,5.10459566116333,54,3,0,0,1,0.301589965820313,34.2131004333496,1,1,3,200.232727050781,0,200.230606079102,,,,,,,,,,,,,,,,,,,,,,,,,,,,,,,,,
,3879811639.43884,200.445663452148,-200.191024780273,9.62848876001367E-7,2.90835327859805E-8,1,4,13.4005146026611,4.98369551024799,33.4100015461445,0.00124017558787335,-1.48440278799475E-4,1,-2.64009667718552E-7,,,,,,,,,,,,,,,,,,,,,200.445175170898,200.446151733398,-200.191024780273,-200.191024780273,53.4164930042364,5.6496587479525,5.10126733779907,54,1,0,0,1,0.3021240234375,34.2131004333496,1,1,3,200.446151733398,0,200.445663452148,,,,,,,,,,,,,,,,,,,,,,,,,,,,,,,,,
,3879811712.29441,200.259185791016,-50.2900772094727,2.25358581939254E-8,2.10086848772539E-8,1,4,13.4005146026611,4.9836495702367,33.3999991416931,5.83019750212827E-5,-1.99174500656177E-4,1,-1.643514688773E-7,,,,,,,,,,,,,,,,,,,,,200.258514404297,200.259857177734,-50.2900772094727,-50.2900772094727,53.5333464678614,5.65016685332068,5.10156297683716,54,2,0,0,1,0.301895141601562,34.2131004333496,1,1,3,200.258514404297,0,200.259185791016,,,,,,,,,,,,,,,,,,,,,,,,,,,,,,,,,
,3879811798.8805,200.28050994873,99.7619247436523,-8.18000890107873E-7,1.68567019095739E-8,1,4,13.4005146026611,4.98382209799444,33.3999991416931,-9.88018325239917E-4,-3.12585055264222E-4,1,-1.30262707283013E-7,,,,,,,,,,,,,,,,,,,,,200.275451660156,200.285568237305,99.7619247436523,99.7619247436523,53.4876211994864,5.6492235116917,5.10776233673096,54,3,0,0,1,0.30059814453125,34.2131004333496,1,1,3,200.275451660156,0,200.28050994873,,,,,,,,,,,,,,,,,,,,,,,,,,,,,,,,,
,3879811894.81034,200.232345581055,299.701171875,-1.87859403201123E-6,2.67246910700483E-8,1,4,13.4005146026611,4.98366442252651,33.3999991416931,-0.00228160668776163,-6.33232241140407E-4,1,-2.30773623541055E-7,,,,,,,,,,,,,,,,,,,,,200.213821411133,200.250869750977,299.701171875,299.701171875,53.5231852971114,5.65005527698984,5.10765027999878,54,1,0,0,1,0.302200317382812,34.2131004333496,1,1,3,200.250869750977,0,200.232345581055,,,,,,,,,,,,,,,,,,,,,,,,,,,,,,,,,
,3879811972.95446,200.274627685547,449.803527832031,-2.74225172647392E-6,1.58495074288272E-8,1,4,13.4005146026611,4.98374534668021,33.3999991416931,-0.00340440217874134,-4.31154878305293E-4,10,6.17579494754416E-8,,,,,,,,,,,,,,,,,,,,,200.273361206055,200.275894165039,449.803527832031,449.803527832031,53.5247485541499,5.64960344589217,5.10399293899536,54,2,0,0,1,0.3009033203125,33.7243423461914,1,1,3,200.273361206055,0,200.274627685547,,,,,,,,,,,,,,,,,,,,,,,,,,,,,,,,,
,3879812048.5179,200.235771179199,599.780029296875,-3.64313996654642E-6,9.11850479057976E-9,1,4,13.4005146026611,4.98362501081936,33.3999991416931,-0.00448911778015726,-7.97052824468764E-4,1,-9.92209046478057E-8,,,,,,,,,,,,,,,,,,,,,200.227890014648,200.24365234375,599.780029296875,599.780029296875,53.4395510455537,5.65048675826185,5.10146999359131,54,3,0,0,1,0.300445556640625,33.7243423461914,1,1,3,200.244400024414,0,200.235771179199,,,,,,,,,,,,,,,,,,,,,,,,,,,,,,,,,
,3879812130.59441,200.087699890137,799.656311035156,-4.79338456699665E-6,2.51319477529849E-8,1,4,13.4005146026611,4.9837465992473,33.3999991416931,-0.00588749092199252,-0.00117691037906152,1,-2.34135968848412E-7,,,,,,,,,,,,,,,,,,,,,200.084091186523,200.09130859375,799.656311035156,799.656311035156,53.5681289369672,5.64930351713258,5.10659313201904,54,1,0,0,1,0.302276611328125,34.2131004333496,1,1,3,200.084091186523,0,200.087699890137,,,,,,,,,,,,,,,,,,,,,,,,,,,,,,,,,
,3879812202.67253,200.285362243652,949.720886230469,-5.72364116637326E-6,1.86596913621171E-8,1,4,13.4005146026611,4.98376849939794,33.3999991416931,-0.00705373994284645,-0.00124746342850132,1,-1.51991136692119E-7,,,,,,,,,,,,,,,,,,,,,200.271102905273,200.299621582031,949.720886230469,949.720886230469,53.521622040073,5.64984394254275,5.10390758514404,54,2,0,0,1,0.302734375,33.7243423461914,1,1,3,200.299621582031,0,200.285362243652,,,,,,,,,,,,,,,,,,,,,,,,,,,,,,,,,
,3879812358.84904,200.131912231445,1099.67211914062,-6.6765563289466E-6,7.17834863588119E-9,1,4,13.4005146026611,4.98365849488854,33.3999991416931,-0.00825808765352956,-0.00125294185404769,1,-1.3899977671558E-8,,,,,,,,,,,,,,,,,,,,,200.126251220703,200.137573242187,1099.67211914062,1099.67211914062,53.4563560587172,5.64992326543861,5.09902477264404,54,3,0,0,1,0.302658081054687,33.7243423461914,1,1,3,200.126251220703,0,200.131912231445,,,,,,,,,,,,,,,,,,,,,,,,,,,,,,,,,
,3879812449.6289,200.207878112793,1299.66186523438,-7.86810255651732E-6,7.04850666396047E-8,1,4,13.4005146026611,4.9836731324731,33.3999991416931,-0.0097013319017123,-0.00168106758218716,10,-1.81672676675421E-7,,,,,,,,,,,,,,,,,,,,,200.189437866211,200.226318359375,1299.66186523438,1299.66186523438,53.4747243289191,5.64995378622995,5.10619163513184,54,1,0,0,1,0.301971435546875,33.7243423461914,1,1,3,200.226318359375,0,200.207878112793,,,,,,,,,,,,,,,,,,,,,,,,,,,,,,,,,
,3879812536.97583,200.243339538574,1449.68859863281,-8.8046703231775E-6,8.03505497086888E-9,1,4,13.4005146026611,4.98368051676422,33.3999991416931,-0.0108797463972571,-0.00172335779672123,10,-7.57453092449014E-8,,,,,,,,,,,,,,,,,,,,,200.242172241211,200.244506835938,1449.68859863281,1449.68859863281,53.4923109706018,5.65014370454105,5.10491704940796,54,2,0,0,1,0.301895141601562,33.2355842590332,1,1,3,200.244506835938,0,200.243339538574,,,,,,,,,,,,,,,,,,,,,,,,,,,,,,,,,
,3879812612.74017,200.110244750977,1599.48889160156,-9.71867681694458E-6,1.08472163368206E-8,1,4,13.4005146026611,4.98348746011365,33.3999991416931,-0.0120120125936435,-0.00187875639956221,1,-6.46959431108181E-8,,,,,,,,,,,,,,,,,,,,,200.106536865234,200.113952636719,1599.48889160156,1599.48889160156,53.5372546104576,5.64886828995784,5.10082578659058,53,3,68,0,0,0.302886962890625,33.7243423461914,1,1,3,200.106536865234,0,200.110244750977,,,,,,,,,,,,,,,,,,,,,,,,,,,,,,,,,
,3879812695.64708,200.216613769531,1799.52880859375,-1.09369642744704E-5,9.6381988499092E-9,1,4,13.4005146026611,4.9836814644458,33.3999991416931,-0.0135063385701155,-0.00219581510602087,1,-1.38621044073134E-7,,,,,,,,,,,,,,,,,,,,,200.211013793945,200.222213745117,1799.52880859375,1799.52880859375,53.4493214020441,5.6494185632628,5.09770822525024,54,1,0,0,1,0.302581787109375,33.7243423461914,1,1,3,200.211013793945,0,200.216613769531,,,,,,,,,,,,,,,,,,,,,,,,,,,,,,,,,
,3879812767.25226,200.205207824707,1949.90808105469,-1.1837421229726E-5,4.22669769515881E-8,1,4,13.4005146026611,4.98375123664757,33.3999991416931,-0.0146365868789411,-0.00225656347343851,1,-5.29810541293488E-8,,,,,,,,,,,,,,,,,,,,,200.187316894531,200.223098754883,1949.90808105469,1949.90808105469,53.5188863402557,5.64911852130958,5.09854412078857,54,2,0,0,1,0.30303955078125,33.2355842590332,1,1,3,200.223937988281,0,200.205207824707,,,,,,,,,,,,,,,,,,,,,,,,,,,,,,,,,
,3879812839.05178,200.349449157715,2099.74609375,-1.27995753024857E-5,3.42823266790787E-8,1,4,13.4005146026611,4.98377159171501,33.3999991416931,-0.0158303287850685,-0.00241339417844591,1,-3.57903365296602E-8,,,,,,,,,,,,,,,,,,,,,200.341369628906,200.357528686523,2099.74609375,2099.74609375,53.5388178674961,5.64791995661123,5.10562133789063,54,3,0,0,1,0.302886962890625,33.2355842590332,1,1,3,200.357528686523,0,200.349449157715,,,,,,,,,,,,,,,,,,,,,,,,,,,,,,,,,
,3879812920.98929,200.397811889648,2299.81103515625,-1.40313869935676E-5,8.71882495408451E-9,1,4,13.4005146026611,4.98380143034397,33.3999991416931,-0.0173418574128047,-0.00272658990976702,1,-1.04628131371467E-7,,,,,,,,,,,,,,,,,,,,,200.390884399414,200.404739379883,2299.81103515625,2299.81103515625,53.5587493947364,5.64949456076254,5.09845685958862,54,1,0,0,1,0.301742553710937,33.7243423461914,1,1,3,200.404739379883,0,200.397811889648,,,,,,,,,,,,,,,,,,,,,,,,,,,,,,,,,
,3879812992.8975,200.303344726562,2449.77514648438,-1.49573312443604E-5,6.81853612420179E-9,1,4,13.4005146026611,4.98366580303175,33.3999991416931,-0.0184905377801392,-0.00287311263524561,1,-8.46212951855E-8,,,,,,,,,,,,,,,,,,,,,200.299819946289,200.306869506836,2449.77514648438,2449.77514648438,53.4215735896114,5.64904628158196,5.09984588623047,54,2,0,0,1,0.30242919921875,33.7243423461914,1,1,3,200.306869506836,0,200.303344726562,,,,,,,,,,,,,,,,,,,,,,,,,,,,,,,,,
,3879813064.85932,200.325996398926,2599.65087890625,-1.58854949835675E-5,6.89811797934474E-9,1,4,13.4005146026611,4.98368855954451,33.3999991416931,-0.019643685752277,-0.00301392933863071,1,-5.95708889786205E-8,,,,,,,,,,,,,,,,,,,,,200.324584960938,200.327407836914,2599.65087890625,2599.65087890625,53.5450708956499,5.64946351634909,5.09766578674316,54,3,0,0,1,0.30364990234375,33.7243423461914,1,1,3,200.324264526367,0,200.325996398926,,,,,,,,,,,,,,,,,,,,,,,,,,,,,,,,,
,3879813146.82333,200.262435913086,2799.76635742187,-1.71167353216607E-5,9.06965659172894E-9,1,4,13.4005146026611,4.98363610329934,33.3999991416931,-0.0211634288264541,-0.00326400431335995,1,-7.75415589589734E-8,,,,,,,,,,,,,,,,,,,,,200.25764465332,200.267227172852,2799.76635742187,2799.76635742187,53.4258725464672,5.64943709856389,5.09645986557007,54,1,0,0,1,0.303115844726562,35.6793746948242,1,1,3,200.25764465332,0,200.262435913086,,,,,,,,,,,,,,,,,,,,,,,,,,,,,,,,,
,3879813218.60628,200.176734924316,2949.76806640625,-1.8035835025894E-5,7.35085114807356E-9,1,4,13.4005146026611,4.98365295027681,33.3999991416931,-0.0223022764183849,-0.00342356871480196,1,-6.90031550895744E-8,,,,,,,,,,,,,,,,,,,,,200.155563354492,200.197906494141,2949.76806640625,2949.76806640625,53.4927017848614,5.64994713118645,5.09753322601318,54,2,0,0,1,0.302505493164063,33.7243423461914,1,1,3,200.197906494141,0,200.176734924316,,,,,,,,,,,,,,,,,,,,,,,,,,,,,,,,,
,3879813310.59345,200.207168579102,3499.58520507812,-2.14749100298813E-5,7.00389291545807E-9,1,4,13.4005146026611,4.98363916920403,33.3999991416931,-0.0265771048576243,-0.00392708214293062,1,3.84910688752328E-8,,,,,,,,,,,,,,,,,,,,,200.199401855469,200.214935302734,3499.58520507812,3499.58520507812,53.5255301826691,5.6497934084394,5.10054588317871,54,3,0,0,1,0.30120849609375,33.7243423461914,1,1,3,200.199401855469,0,200.207168579102,,,,,,,,,,,,,,,,,,,,,,,,,,,,,,,,,
,3879813408.39536,200.083206176758,5499.61962890625,-3.38673216167055E-5,1.00508301633828E-8,1,4,13.4005146026611,4.98364513495851,33.3999991416931,-0.0419191680870197,-0.00615794428046582,1,8.92568079835234E-8,,,,,,,,,,,,,,,,,,,,,200.081497192383,200.084915161133,5499.61962890625,5499.61962890625,53.4450224451884,5.64992985321101,5.09812879562378,52,1,68,0,0,0.30303955078125,33.7243423461914,1,1,3,200.084915161133,0,200.083206176758,,,,,,,,,,,,,,,,,,,,,,,,,,,,,,,,,
,3879813492.57388,200.31908416748,6999.787109375,-4.31601785038667E-5,9.04433988728786E-9,1,4,13.4005146026611,4.98364276931499,33.3999991416931,-0.0534128382874881,-0.00790442403267925,1,6.78350242454388E-8,,,,,,,,,,,,,,,,,,,,,200.309539794922,200.328628540039,6999.787109375,6999.787109375,53.5028629556114,5.64937649479997,5.10489416122437,54,2,0,0,1,0.303192138671875,33.7243423461914,1,1,3,200.309539794922,0,200.31908416748,,,,,,,,,,,,,,,,,,,,,,,,,,,,,,,,,
,3879813576.41637,200.321067810059,8500.0810546875,-5.2464474113685E-5,1.50070761943943E-8,1,4,13.4005146026611,4.98361981702305,33.3999991416931,-0.0649286073296292,-0.00959722650654385,1,9.14616498935296E-8,,,,,,,,,,,,,,,,,,,,,200.313278198242,200.328857421875,8500.0810546875,8500.0810546875,53.4985639987557,5.64899218738342,5.09422206878662,54,3,0,0,1,0.302581787109375,33.2355842590332,1,1,3,200.328857421875,0,200.321067810059,,,,,,,,,,,,,,,,,,,,,,,,,,,,,,,,,
,3879813680.36558,200.178649902344,9999.958984375,-6.17593084866086E-5,1.20010798872073E-8,1,4,13.4005146026611,4.9835637714925,33.4100015461445,-0.0764274606342854,-0.0113172223510085,1,9.15910027686668E-8,,,,,,,,,,,,,,,,,,,,,200.17741394043,200.179885864258,9999.958984375,9999.958984375,53.4450224451884,5.64955103803162,5.10440015792847,54,1,0,0,1,0.302505493164063,33.7243423461914,1,1,3,200.17741394043,0,200.178649902344,,,,,,,,,,,,,,,,,,,,,,,,,,,,,,,,,
,3879813899.14004,200.117630004883,25000.248046875,-1.54870523285511E-4,2.5185861274446E-8,1,4,13.4005146026611,4.98354499464467,33.4100015461445,-0.191633596028443,-0.0285028236455824,1,1.29955506027201E-7,,,,,,,,,,,,,,,,,,,,,200.105743408203,200.129516601562,25000.248046875,25000.248046875,53.4418959311114,5.6503202342677,5.10435914993286,54,2,0,0,1,0.302200317382812,33.7243423461914,1,1,3,200.129516601562,0,200.117630004883,,,,,,,,,,,,,,,,,,,,,,,,,,,,,,,,,
,3879814125.57867,200.268623352051,40000.453125,-2.48190969858602E-4,4.89015821663788E-8,1,4,13.4005146026611,4.9835529584622,33.3999991416931,-0.307147036130252,-0.0454108185179715,10,4.2412889600955E-7,,,,,,,,,,,,,,,,,,,,,200.267211914062,200.270034790039,40000.453125,40000.453125,53.4196195183133,5.65007635658348,5.09540319442749,54,3,0,0,1,0.301513671875,33.7243423461914,1,1,3,200.270034790039,0,200.268623352051,,,,,,,,,,,,,,,,,,,,,,,,,,,,,,,,,
,3879814413.01799,200.168045043945,60000.45703125,-3.72346159102705E-4,9.65319485628573E-8,1,4,13.4005146026611,4.98368982341836,33.3999991416931,-0.46072077887249,-0.0687408860616497,1,1.42379812719138E-7,,,,,,,,,,,,,,,,,,,,,200.136947631836,200.199142456055,60000.45703125,60000.45703125,53.2707192853999,5.64977745735971,5.09611225128174,54,1,0,0,1,0.303497314453125,33.7243423461914,1,1,3,200.199142456055,0,200.168045043945,,,,,,,,,,,,,,,,,,,,,,,,,,,,,,,,,
,3879814579.81036,200.081008911133,70000.1875,-4.34476479259967E-4,1.28183130838799E-7,1,4,13.4005146026611,4.98364853544547,33.3999991416931,-0.537572108679427,-0.0803377367686268,1,6.3038243556782E-8,,,,,,,,,,,,,,,,,,,,,200.080856323242,200.081161499023,70000.1875,70000.1875,53.0506908572364,5.64904422731072,5.09612512588501,54,3,0,0,1,0.301971435546875,34.2131004333496,1,1,3,200.081161499023,0,200.081008911133,,,,,,,,,,,,,,,,,,,,,,,,,,,,,,,,,