File: SQUID/Reference/STO/B1/STOsubs_MT_FC_0d5T.csv
Comment,Time Stamp (sec),Temperature (K),Magnetic Field (Oe),Moment (emu),M. Std. Err. (emu),Transport Action,Averaging Time (sec),Frequency (Hz),Peak Amplitude (mm),Center Position (mm),Lockin Signal' (V),Lockin Signal (V),Range,M. Quad. Signal (emu),AC Moment (emu),AC M. Std Err. (emu),AC Phase (deg),AC Phase Std. Err. (deg),AC Susceptibility (emu/Oe),AC Suscept. Std Err. (emu/Oe),AC X' (emu/Oe),AC X' Std Err. (emu/Oe),AC X'' (emu/Oe),AC X'' Std Err. (emu/Oe),AC Drive (Oe),AC Frequency (Hz),AC Averaging Time (sec),AC Cycles,AC Range,AC Measure Type,AC Signal' (V),AC Signal'' (V),AC Trim Coil Ratio,AC Trim Coil Phase,Min. Temperature (K),Max. Temperature (K),Min. Field (Oe),Max. Field (Oe),Mass (grams),Motor Lag (deg),Pressure (Torr),Measure Count,Measurement Number,SQUID Status (code),Motor Status (code),Measure Status (code),Motor Current (amps),Motor Temp. (C),Temp. Status (code),Field Status (code),Chamber Status (code),Chamber Temp (K),Redirection State,Average Temp (K),Rotation Angle (deg),Rotator state,DC Moment Fixed Ctr (emu),DC Moment Err Fixed Ctr (emu),DC Moment Free Ctr (emu),DC Moment Err Free Ctr (emu),DC Fixed Fit,DC Free Fit,DC Calculated Center (mm),DC Calculated Center Err (mm),DC Scan Length (mm),DC Scan Time (s),DC Number of Points,DC Squid Drift,DC Min V (V),DC Max V (V),DC Scans per Measure,Sample Resistance,He3 Temperature,Sorb Resistance,Sorb Temperature,Map 05,Map 06,Map 07,Map 08,Map 09,Map 10,Map 11,Map 12,Map 13,Map 14,Map 15,Map 16
,3879746629.08653,349.997589111328,4999.66455078125,-3.05951803482802E-5,8.0151767864871E-9,1,6,13.4005146026611,5.00884384442885,33.6400009691715,-0.0381350451473249,-0.00561874889556729,1,6.7523494109387E-8,,,,,,,,,,,,,,,,,,,,,349.99755859375,349.997619628906,4999.66455078125,4999.66455078125,53.4680804865057,5.63227286719826,5.54652976989746,80,1,0,0,1,0.30517578125,32.2580642700195,1,1,3,349.997619628906,0,349.997589111328,,,,,,,,,,,,,,,,,,,,,,,,,,,,,,,,,
,3879746651.52094,349.774307250977,4999.66455078125,-3.05632260754667E-5,1.43412576815528E-8,1,6,13.4005146026611,5.00865285275493,33.6400009691715,-0.0380919139464851,-0.00562108439635381,1,6.06285554920115E-8,,,,,,,,,,,,,,,,,,,,,349.666137695313,349.882476806641,4999.66455078125,4999.66455078125,53.4153205614576,5.63273943987836,5.55221366882324,80,1,0,0,1,0.304489135742188,32.7468223571777,2,1,3,349.660217285156,0,349.774307250977,,,,,,,,,,,,,,,,,,,,,,,,,,,,,,,,,
,3879746675.50945,348.58528137207,4999.66455078125,-3.05663681794078E-5,9.14047423301382E-9,1,6,13.4005146026611,5.00856799626978,33.6400009691715,-0.0380943153213201,-0.00562562477670161,1,5.73476054856249E-8,,,,,,,,,,,,,,,,,,,,,348.401428222656,348.769134521484,4999.66455078125,4999.66455078125,53.4157113757172,5.6325672828106,5.55429458618164,80,1,0,0,1,0.303802490234375,33.2355842590332,2,1,3,348.401428222656,0,348.58528137207,,,,,,,,,,,,,,,,,,,,,,,,,,,,,,,,,
,3879746699.33815,346.524444580078,4999.66455078125,-3.05726291618021E-5,3.40649475896914E-8,1,6,13.4005146026611,5.00852317058938,33.6400009691715,-0.0381020371210252,-0.00562406319168614,1,5.94810927897815E-8,,,,,,,,,,,,,,,,,,,,,346.182312011719,346.866577148438,4999.66455078125,4999.66455078125,53.4399418598133,5.6330923334493,5.56211376190186,80,1,0,0,1,0.311126708984375,32.7468223571777,2,1,3,346.182312011719,0,346.524444580078,,,,,,,,,,,,,,,,,,,,,,,,,,,,,,,,,
,3879746722.9105,343.321563720703,4999.66455078125,-3.05627712823086E-5,9.41123835601836E-9,1,6,13.4005146026611,5.00849142132674,33.6400009691715,-0.038090215551225,-0.00561684165612947,1,6.37626350181524E-8,,,,,,,,,,,,,,,,,,,,,342.90771484375,343.735412597656,4999.66455078125,4999.66455078125,53.4770692144768,5.63257762399004,5.56609630584717,80,1,0,0,1,0.296630859375,33.2355842590332,2,1,3,342.90771484375,0,343.321563720703,,,,,,,,,,,,,,,,,,,,,,,,,,,,,,,,,
,3879746746.65569,339.036682128906,4999.66455078125,-3.05751636288683E-5,2.29264870871475E-8,1,6,13.4005146026611,5.00846637988097,33.6199998855591,-0.0381059065251161,-0.00561565230354818,1,6.65395655024311E-8,,,,,,,,,,,,,,,,,,,,,338.431121826172,339.642242431641,4999.66455078125,4999.66455078125,53.3496637658422,5.63256305367317,5.56228923797607,80,1,0,0,1,0.304946899414063,32.7468223571777,2,1,3,338.431121826172,0,339.036682128906,,,,,,,,,,,,,,,,,,,,,,,,,,,,,,,,,
,3879746770.59611,333.468353271484,4999.66455078125,-3.05712008974809E-5,3.18422637081111E-8,1,6,13.4005146026611,5.00844997110725,33.6199998855591,-0.0380989909331779,-0.00562694715553138,1,5.6860446040144E-8,,,,,,,,,,,,,,,,,,,,,332.724395751953,334.212310791016,4999.66455078125,4999.66455078125,53.2859610415249,5.63327188083836,5.55353355407715,80,1,0,0,1,0.304794311523438,32.7468223571777,2,1,3,332.724395751953,0,333.468353271484,,,,,,,,,,,,,,,,,,,,,,,,,,,,,,,,,
,3879746794.50359,327.01838684082,4999.66455078125,-3.05712434267261E-5,1.13573220664291E-8,1,6,13.4005146026611,5.00841632261691,33.5999988019466,-0.0380998478963993,-0.00561913637930992,1,6.30936853346761E-8,,,,,,,,,,,,,,,,,,,,,326.283447265625,327.753326416016,4999.66455078125,4999.66455078125,53.3148812967364,5.63309264768514,5.54472923278809,79,1,64,0,0,0.312652587890625,33.2355842590332,2,1,3,326.283447265625,0,327.01838684082,,,,,,,,,,,,,,,,,,,,,,,,,,,,,,,,,
,3879746819.02174,320.1884765625,4999.66455078125,-3.05746841531713E-5,1.70875902513026E-8,1,6,13.4005146026611,5.00839014258206,33.5900001227856,-0.0381060004440425,-0.00560540309798355,1,7.4598486367765E-8,,,,,,,,,,,,,,,,,,,,,319.531677246094,320.845275878906,4999.66455078125,4999.66455078125,53.4833222426306,5.6330015961314,5.54301166534424,79,1,64,0,0,0.297622680664063,33.2355842590332,2,1,3,319.472778320313,0,320.1884765625,,,,,,,,,,,,,,,,,,,,,,,,,,,,,,,,,
,3879746842.50687,313.653625488281,4999.66455078125,-3.05689401151315E-5,1.25062246175091E-8,1,6,13.4005146026611,5.00829838592024,33.5900001227856,-0.0380965483801547,-0.00561301404874853,1,6.751490463997E-8,,,,,,,,,,,,,,,,,,,,,312.773712158203,314.533538818359,4999.66455078125,4999.66455078125,53.4899660850441,5.6340853056153,5.54094219207764,80,1,0,0,1,0.302658081054687,33.2355842590332,2,1,3,312.724426269531,0,313.653625488281,,,,,,,,,,,,,,,,,,,,,,,,,,,,,,,,,
,3879746866.50049,307.660308837891,4999.66455078125,-3.0581501870334E-5,1.14238979323323E-8,1,6,13.4005146026611,5.0082523243838,33.5699990391731,-0.038110313344936,-0.00562460847899043,1,6.00295031617943E-8,,,,,,,,,,,,,,,,,,,,,307.070434570313,308.250183105469,4999.66455078125,4999.66455078125,53.4516662876018,5.6335223207442,5.53782796859741,79,1,64,0,0,0.303802490234375,33.2355842590332,2,1,3,307.070434570313,0,307.660308837891,,,,,,,,,,,,,,,,,,,,,,,,,,,,,,,,,
,3879746890.22316,301.86735534668,4999.66455078125,-3.05753502089901E-5,8.221400229738E-9,1,6,13.4005146026611,5.00806464198565,33.5699990391731,-0.0381016322099796,-0.00561662630645152,1,6.52802473534635E-8,,,,,,,,,,,,,,,,,,,,,301.090545654297,302.644165039063,4999.66455078125,4999.66455078125,53.3973431055153,5.63415040250696,5.52855348587036,80,1,0,0,1,0.304336547851562,33.7243423461914,2,1,3,301.066192626953,0,301.86735534668,,,,,,,,,,,,,,,,,,,,,,,,,,,,,,,,,
,3879746914.15408,296.955276489258,4999.66455078125,-3.05708880244829E-5,7.61019108436439E-9,1,6,13.4005146026611,5.0081065708501,33.550001680851,-0.0380969837307252,-0.00561275532907103,1,6.77727846049485E-8,,,,,,,,,,,,,,,,,,,,,296.236877441406,297.673675537109,4999.66455078125,4999.66455078125,53.5102884265441,5.63506753258291,5.5267391204834,80,1,0,0,1,0.304336547851562,33.2355842590332,2,1,3,296.236877441406,0,296.955276489258,,,,,,,,,,,,,,,,,,,,,,,,,,,,,,,,,
,3879746938.15982,292.41291809082,4999.66455078125,-3.05751379720017E-5,1.41745355548066E-8,1,6,13.4005146026611,5.00805581725133,33.550001680851,-0.0381032995481607,-0.0056030324124484,1,7.61495727814191E-8,,,,,,,,,,,,,,,,,,,,,291.964721679687,292.861114501953,4999.66455078125,4999.66455078125,53.4223552181307,5.63501621620108,5.52093124389648,80,1,0,0,1,0.303726196289063,33.2355842590332,2,1,3,291.964721679687,0,292.41291809082,,,,,,,,,,,,,,,,,,,,,,,,,,,,,,,,,
,3879746962.06482,288.430374145508,4999.66455078125,-3.05747565979348E-5,7.67659907177617E-9,1,6,13.4005146026611,5.00797143090952,33.550001680851,-0.0381014591795432,-0.0056059569226051,1,7.36389506795548E-8,,,,,,,,,,,,,,,,,,,,,287.99560546875,288.865142822266,4999.66455078125,4999.66455078125,53.4286082462845,5.63567645915406,5.51546192169189,80,1,0,0,1,0.296783447265625,33.7243423461914,2,1,3,287.961273193359,0,288.430374145508,,,,,,,,,,,,,,,,,,,,,,,,,,,,,,,,,
,3879746985.7507,284.604858398438,4999.66455078125,-3.05667007009894E-5,9.63318233082905E-9,1,6,13.4005146026611,5.00790173746425,33.550001680851,-0.038090060427093,-0.00560850702321386,1,7.02991776086685E-8,,,,,,,,,,,,,,,,,,,,,284.103668212891,285.106048583984,4999.66455078125,4999.66455078125,53.4254817322076,5.63598470304476,5.51689100265503,80,1,0,0,1,0.304412841796875,33.2355842590332,2,1,3,284.103668212891,0,284.604858398438,,,,,,,,,,,,,,,,,,,,,,,,,,,,,,,,,
,3879747009.72441,280.64176940918,4999.66455078125,-3.05713225172662E-5,1.09045844298272E-8,1,6,13.4005146026611,5.00786801258057,33.5300005972385,-0.0380969664980434,-0.0055992397275732,1,7.83876858067844E-8,,,,,,,,,,,,,,,,,,,,,280.250732421875,281.032806396484,4999.66455078125,4999.66455078125,53.420010332573,5.63535225579538,5.50743961334229,80,1,0,0,1,0.304794311523438,33.7243423461914,2,1,3,280.250732421875,0,280.64176940918,,,,,,,,,,,,,,,,,,,,,,,,,,,,,,,,,
,3879747033.25281,276.772644042969,4999.66455078125,-3.05723051833446E-5,7.34378147820628E-9,1,6,13.4005146026611,5.0078619807667,33.5300005972385,-0.0380959622777194,-0.00561388042251808,1,6.67740089081911E-8,,,,,,,,,,,,,,,,,,,,,276.351135253906,277.194152832031,4999.66455078125,4999.66455078125,53.5181047117364,5.6354306748906,5.50924777984619,80,1,0,0,1,0.29815673828125,33.7243423461914,2,1,3,276.351135253906,0,276.772644042969,,,,,,,,,,,,,,,,,,,,,,,,,,,,,,,,,
,3879747057.40098,272.856857299805,4999.66455078125,-3.05714831746079E-5,8.90932555576516E-9,1,6,13.4005146026611,5.00790296535465,33.5300005972385,-0.038095021856426,-0.00561614614011808,1,6.48837658170955E-8,,,,,,,,,,,,,,,,,,,,,272.374694824219,273.339019775391,4999.66455078125,4999.66455078125,53.3586524938133,5.63590485514644,5.50300788879395,80,1,0,0,1,0.304183959960937,33.7243423461914,2,1,3,272.374694824219,0,272.856857299805,,,,,,,,,,,,,,,,,,,,,,,,,,,,,,,,,
,3879747081.37654,268.8564453125,4999.66455078125,-3.05804369418424E-5,1.56913491226601E-8,1,6,13.4005146026611,5.00794701215534,33.5099995136261,-0.0381096049717249,-0.00559809069871705,1,8.07726425786176E-8,,,,,,,,,,,,,,,,,,,,,268.406921386719,269.305969238281,4999.66455078125,4999.66455078125,53.557186137698,5.63506743332725,5.49690389633179,80,1,0,0,1,0.298309326171875,33.7243423461914,2,1,3,268.406921386719,0,268.8564453125,,,,,,,,,,,,,,,,,,,,,,,,,,,,,,,,,
,3879747105.24862,264.819564819336,4999.66455078125,-3.05809706267485E-5,8.93341455552316E-9,1,6,13.4005146026611,5.00798580340348,33.5099995136261,-0.0381103313572107,-0.00560059748982167,1,7.88888262912005E-8,,,,,,,,,,,,,,,,,,,,,264.434539794922,265.20458984375,4999.66455078125,4999.66455078125,53.4274358035057,5.63506510059241,5.49474811553955,80,1,0,0,1,0.30517578125,32.7468223571777,2,1,3,264.434539794922,0,264.819564819336,,,,,,,,,,,,,,,,,,,,,,,,,,,,,,,,,
,3879747129.05302,260.996078491211,4999.66455078125,-3.05763425095209E-5,1.10940778367922E-8,1,6,13.4005146026611,5.00809040727157,33.5099995136261,-0.0381043485836222,-0.00560878839998391,1,7.17527455301399E-8,,,,,,,,,,,,,,,,,,,,,260.536834716797,261.455322265625,4999.66455078125,4999.66455078125,53.4715978148422,5.63547121885937,5.48759317398071,80,1,0,0,1,0.297775268554687,33.7243423461914,2,1,3,260.536834716797,0,260.996078491211,,,,,,,,,,,,,,,,,,,,,,,,,,,,,,,,,
,3879747152.98147,256.927429199219,4999.66455078125,-3.05839166731012E-5,1.13904513303192E-8,1,6,13.4005146026611,5.00806349558699,33.5099995136261,-0.0381143101828368,-0.00560472818858202,1,7.61112094802926E-8,,,,,,,,,,,,,,,,,,,,,256.517700195313,257.337158203125,4999.66455078125,4999.66455078125,53.4872303852268,5.63490647717095,5.47902631759644,80,1,0,0,1,0.2984619140625,33.7243423461914,2,1,3,256.517700195313,0,256.927429199219,,,,,,,,,,,,,,,,,,,,,,,,,,,,,,,,,
,3879747176.9973,252.914535522461,4999.66455078125,-3.05826572280686E-5,2.9803598173109E-8,1,6,13.4005146026611,5.00809637785266,33.4899984300137,-0.0381120304014364,-0.00561163474562136,1,7.04200796801047E-8,,,,,,,,,,,,,,,,,,,,,252.471450805664,253.357620239258,4999.66455078125,4999.66455078125,53.5720370795634,5.63466344930809,5.47913408279419,80,1,0,0,1,0.303115844726562,33.7243423461914,2,1,3,252.433563232422,0,252.914535522461,,,,,,,,,,,,,,,,,,,,,,,,,,,,,,,,,
,3879747200.67311,249.182319641113,4999.66455078125,-3.05847491406922E-5,8.97873733524289E-9,1,6,13.4005146026611,5.00806394868939,33.500000834465,-0.0381145849009658,-0.00561001228141472,1,7.19946385731307E-8,,,,,,,,,,,,,,,,,,,,,248.65022277832,249.714416503906,4999.66455078125,4999.66455078125,53.3391117808326,5.63501457472081,5.4669508934021,80,1,0,0,1,0.303726196289063,33.2355842590332,2,1,3,248.629425048828,0,249.182319641113,,,,,,,,,,,,,,,,,,,,,,,,,,,,,,,,,
,3879747224.6863,245.310165405273,4999.66455078125,-3.05852679573E-5,8.41398154098342E-9,1,6,13.4005146026611,5.00812176755797,33.4899984300137,-0.0381157042661748,-0.00561114890626241,1,7.12325374162686E-8,,,,,,,,,,,,,,,,,,,,,244.859161376953,245.761169433594,4999.66455078125,4999.66455078125,53.5024721413518,5.6347183878727,5.46855354309082,80,1,0,0,1,0.297012329101562,33.7243423461914,2,1,3,244.839019775391,0,245.310165405273,,,,,,,,,,,,,,,,,,,,,,,,,,,,,,,,,
,3879747248.10179,241.464248657227,4999.66455078125,-3.05706337317209E-5,1.32265938060012E-8,1,6,13.4005146026611,5.00808261759206,33.4899984300137,-0.038096716744793,-0.0056106349717605,1,6.94066781560704E-8,,,,,,,,,,,,,,,,,,,,,240.941711425781,241.986785888672,4999.66455078125,4999.66455078125,53.523576111371,5.6342346114121,5.46043252944946,80,1,0,0,1,0.305709838867188,33.7243423461914,2,1,3,240.941711425781,0,241.464248657227,,,,,,,,,,,,,,,,,,,,,,,,,,,,,,,,,
,3879747271.99126,237.559196472168,4999.66455078125,-3.05733173558076E-5,1.25374733265123E-8,1,6,13.4005146026611,5.00804543601484,33.4700010716915,-0.0381029805020843,-0.00558891036274933,1,8.7200364933051E-8,,,,,,,,,,,,,,,,,,,,,237.112075805664,238.006317138672,4999.66455078125,4999.66455078125,53.5274842539672,5.63470142147029,5.45355367660522,80,1,0,0,1,0.30426025390625,33.2355842590332,2,1,3,237.112075805664,0,237.559196472168,,,,,,,,,,,,,,,,,,,,,,,,,,,,,,,,,
,3879747295.94722,233.543579101562,4999.66455078125,-3.05804673221472E-5,1.05035505761755E-8,1,6,13.4005146026611,5.0080059167704,33.4700010716915,-0.0381089142166905,-0.00560724729962109,1,7.35007203867277E-8,,,,,,,,,,,,,,,,,,,,,233.103790283203,233.983367919922,4999.66455078125,4999.66455078125,53.4790232857749,5.63523049352635,5.4524655342102,78,1,64,0,0,0.29693603515625,33.7243423461914,2,1,3,233.103790283203,0,233.543579101562,,,,,,,,,,,,,,,,,,,,,,,,,,,,,,,,,
,3879747319.77356,229.54158782959,4999.66455078125,-3.05701261091558E-5,1.00637939337337E-8,1,6,13.4005146026611,5.00799235769653,33.4700010716915,-0.038095684253186,-0.0056066583816737,1,7.24094528093476E-8,,,,,,,,,,,,,,,,,,,,,229.059722900391,230.023452758789,4999.66455078125,4999.66455078125,53.3953890342172,5.6352139365441,5.44385957717895,80,1,0,0,1,0.3045654296875,33.7243423461914,2,1,3,229.059722900391,0,229.54158782959,,,,,,,,,,,,,,,,,,,,,,,,,,,,,,,,,
,3879747343.91214,225.571441650391,4999.66455078125,-3.05741769130343E-5,1.58256044388675E-8,1,6,13.4005146026611,5.00800167855738,33.4700010716915,-0.0380996979310093,-0.00561499272521892,1,6.6336836908806E-8,,,,,,,,,,,,,,,,,,,,,225.075576782227,226.067306518555,4999.66455078125,4999.66455078125,53.6341765468422,5.6345168051077,5.43606376647949,80,1,0,0,1,0.297470092773438,33.2355842590332,2,1,3,225.075576782227,0,225.571441650391,,,,,,,,,,,,,,,,,,,,,,,,,,,,,,,,,
,3879747367.93659,221.489181518555,4999.66455078125,-3.05661358348395E-5,8.49242944796925E-9,1,6,13.4005146026611,5.00802467117253,33.4499999880791,-0.0380901373146365,-0.00561211305653877,1,6.74744728889481E-8,,,,,,,,,,,,,,,,,,,,,221.102996826172,221.875366210938,4999.66455078125,4999.66455078125,53.482931428371,5.63468271834336,5.43627166748047,80,1,0,0,1,0.297622680664063,33.7243423461914,2,1,3,221.102996826172,0,221.489181518555,,,,,,,,,,,,,,,,,,,,,,,,,,,,,,,,,
,3879747391.42017,217.609741210938,4999.66455078125,-3.0567971830495E-5,7.03543905830939E-9,1,6,13.4005146026611,5.00800066457938,33.4499999880791,-0.0380930216562192,-0.00560671954807492,1,7.20485201790952E-8,,,,,,,,,,,,,,,,,,,,,217.076553344727,218.142929077148,4999.66455078125,4999.66455078125,53.4571376872364,5.6348992849907,5.42702150344849,80,1,0,0,1,0.29754638671875,33.7243423461914,2,1,3,217.076553344727,0,217.609741210938,,,,,,,,,,,,,,,,,,,,,,,,,,,,,,,,,
,3879747415.43545,213.454551696777,4999.66455078125,-3.05728015850569E-5,9.27264581529408E-9,1,6,13.4005146026611,5.00792931294248,33.4499999880791,-0.0380973902294592,-0.00561345262577028,1,6.72763783687067E-8,,,,,,,,,,,,,,,,,,,,,212.931945800781,213.977157592773,4999.66455078125,4999.66455078125,53.5138057548807,5.63484860424705,5.42412185668945,78,1,64,0,0,0.296783447265625,33.7243423461914,2,1,3,212.931945800781,0,213.454551696777,,,,,,,,,,,,,,,,,,,,,,,,,,,,,,,,,
,3879747439.22615,209.543495178223,4999.66455078125,-3.05702240872569E-5,9.32900780216911E-9,1,6,13.4005146026611,5.00792740224786,33.4499999880791,-0.0380954221120416,-0.00560452636187859,1,7.4054003077841E-8,,,,,,,,,,,,,,,,,,,,,209.03141784668,210.055572509766,4999.66455078125,4999.66455078125,53.4438500024095,5.63568265389685,5.41002035140991,80,1,0,0,1,0.304489135742188,33.7243423461914,2,1,3,209.03141784668,0,209.543495178223,,,,,,,,,,,,,,,,,,,,,,,,,,,,,,,,,
,3879747463.04946,205.626861572266,4999.66455078125,-3.05739484704859E-5,8.76544487252539E-9,1,6,13.4005146026611,5.00784581330854,33.440001308918,-0.0380996450959571,-0.00560207712213766,1,7.64748752474581E-8,,,,,,,,,,,,,,,,,,,,,205.096313476562,206.157409667969,4999.66455078125,4999.66455078125,53.5435076386114,5.63522279133438,5.40882921218872,80,1,0,0,1,0.298309326171875,33.7243423461914,2,1,3,205.096313476562,0,205.626861572266,,,,,,,,,,,,,,,,,,,,,,,,,,,,,,,,,
,3879747487.0099,201.625610351562,4999.66455078125,-3.05678013932514E-5,1.03855542394878E-8,1,6,13.4005146026611,5.00788584993498,33.440001308918,-0.0380908701127182,-0.00561131125515761,1,6.81927309333674E-8,,,,,,,,,,,,,,,,,,,,,201.110595703125,202.140625,4999.66455078125,4999.66455078125,53.4536203588999,5.63553152781626,5.40640783309937,80,1,0,0,1,0.298080444335937,33.2355842590332,2,1,3,201.110595703125,0,201.625610351562,,,,,,,,,,,,,,,,,,,,,,,,,,,,,,,,,
,3879747510.77861,197.697334289551,4999.66455078125,-3.05709621818318E-5,2.57370963335028E-8,1,6,13.4005146026611,5.00789676574963,33.4200002253056,-0.0380967295980215,-0.00559984440733052,1,7.78844414449896E-8,,,,,,,,,,,,,,,,,,,,,197.209197998047,198.185470581055,4999.66455078125,4999.66455078125,53.3453648089864,5.63496380613171,5.39207601547241,80,1,0,0,1,0.313720703125,33.7243423461914,2,1,3,197.184173583984,0,197.697334289551,,,,,,,,,,,,,,,,,,,,,,,,,,,,,,,,,
,3879747535.0318,193.632019042969,4999.66455078125,-3.05698734966507E-5,1.28697859105618E-8,1,6,13.4005146026611,5.0079575716477,33.4200002253056,-0.0380946117160372,-0.00560915043536299,1,7.03274733504001E-8,,,,,,,,,,,,,,,,,,,,,193.181991577148,194.082046508789,4999.66455078125,4999.66455078125,53.582589064573,5.63412495105544,5.38717699050903,78,1,64,0,0,0.306015014648438,33.7243423461914,2,1,3,193.107162475586,0,193.632019042969,,,,,,,,,,,,,,,,,,,,,,,,,,,,,,,,,
,3879747559.00762,189.689170837402,4999.66455078125,-3.05695962283548E-5,1.33399808873468E-8,1,6,13.4005146026611,5.00790688240601,33.4200002253056,-0.0380940862968865,-0.00560662002701997,1,7.22536009678759E-8,,,,,,,,,,,,,,,,,,,,,189.239059448242,190.139282226562,4999.66455078125,4999.66455078125,53.404768576448,5.63541458845697,5.37746477127075,80,1,0,0,1,0.305099487304687,33.7243423461914,2,1,3,189.239059448242,0,189.689170837402,,,,,,,,,,,,,,,,,,,,,,,,,,,,,,,,,
,3879747582.77732,185.669448852539,4999.66455078125,-3.05647272491098E-5,9.27472231148964E-9,1,6,13.4005146026611,5.00796853540373,33.4200002253056,-0.0380883553687755,-0.00560795534072007,1,7.05307626914414E-8,,,,,,,,,,,,,,,,,,,,,185.252059936523,186.086837768555,4999.66455078125,4999.66455078125,53.5556228806595,5.6344517716735,5.37308216094971,80,1,0,0,1,0.297470092773438,33.7243423461914,2,1,3,185.252059936523,0,185.669448852539,,,,,,,,,,,,,,,,,,,,,,,,,,,,,,,,,
,3879747606.68085,181.756240844727,4999.66455078125,-3.05596555527874E-5,1.15266883044258E-8,1,6,13.4005146026611,5.00792874818212,33.4200002253056,-0.038082858846208,-0.00559863002356067,1,7.72080206298356E-8,,,,,,,,,,,,,,,,,,,,,181.309219360352,182.203262329102,4999.66455078125,4999.66455078125,53.4395510455537,5.63478311526319,5.36144065856934,80,1,0,0,1,0.305557250976562,33.7243423461914,2,1,3,181.309219360352,0,181.756240844727,,,,,,,,,,,,,,,,,,,,,,,,,,,,,,,,,
,3879747630.20596,177.820190429687,4999.66455078125,-3.05658120715589E-5,1.16308156295312E-8,1,6,13.4005146026611,5.00797571476295,33.3999991416931,-0.0380898867672189,-0.00560747563282651,1,7.10871490181054E-8,,,,,,,,,,,,,,,,,,,,,177.377838134766,178.262542724609,4999.66455078125,4999.66455078125,53.4254817322076,5.63478423336547,5.35503530502319,80,1,0,0,1,0.304031372070313,33.7243423461914,2,1,3,177.377838134766,0,177.820190429687,,,,,,,,,,,,,,,,,,,,,,,,,,,,,,,,,
,3879747654.42577,173.977905273438,4999.66455078125,-3.05692792692276E-5,9.28930846071249E-9,1,6,13.4005146026611,5.00793462780625,33.3999991416931,-0.0380953011804915,-0.00559781579949139,1,7.93086662364152E-8,,,,,,,,,,,,,,,,,,,,,173.566818237305,174.38899230957,4999.66455078125,4999.66455078125,53.4848854996691,5.63407581275451,5.34962272644043,79,1,64,0,0,0.304412841796875,33.7243423461914,2,1,3,173.566818237305,0,173.977905273438,,,,,,,,,,,,,,,,,,,,,,,,,,,,,,,,,
,3879747677.93497,170.190399169922,4999.66455078125,-3.05667143488206E-5,8.61232816550012E-9,1,6,13.4005146026611,5.00793772663058,33.3999991416931,-0.0380914431154183,-0.00560199432224957,1,7.55745349570495E-8,,,,,,,,,,,,,,,,,,,,,169.66911315918,170.711685180664,4999.66455078125,4999.66455078125,53.4340796459191,5.63410178081132,5.34931039810181,80,1,0,0,1,0.30548095703125,33.7243423461914,2,1,3,169.66911315918,0,170.190399169922,,,,,,,,,,,,,,,,,,,,,,,,,,,,,,,,,
,3879747701.84724,166.172912597656,4999.66455078125,-3.05523292514669E-5,7.32145077821384E-9,1,6,13.4005146026611,5.00790294154249,33.3999991416931,-0.0380719569474024,-0.00560725967024579,1,6.91521364249893E-8,,,,,,,,,,,,,,,,,,,,,165.663681030273,166.682144165039,4999.66455078125,4999.66455078125,53.4997364415345,5.63451313378424,5.34199857711792,80,1,0,0,1,0.3045654296875,33.7243423461914,2,1,3,165.663681030273,0,166.172912597656,,,,,,,,,,,,,,,,,,,,,,,,,,,,,,,,,
,3879747726.07744,162.179328918457,4999.66455078125,-3.05503628588828E-5,7.41649139729373E-9,1,6,13.4005146026611,5.00797519083439,33.3999991416931,-0.0380706691042433,-0.00560437255830955,1,7.12663599951204E-8,,,,,,,,,,,,,,,,,,,,,161.652252197266,162.706405639648,4999.66455078125,4999.66455078125,53.3957798484768,5.6341122598303,5.33025646209717,80,1,0,0,1,0.305557250976562,33.7243423461914,2,1,3,161.652252197266,0,162.179328918457,,,,,,,,,,,,,,,,,,,,,,,,,,,,,,,,,
,3879747749.90421,158.183120727539,4999.66455078125,-3.05521442503793E-5,1.20118641201247E-8,1,6,13.4005146026611,5.00805396161404,33.380001783371,-0.0380732229940194,-0.00560818541942704,1,6.85710666733265E-8,,,,,,,,,,,,,,,,,,,,,157.620071411133,158.746170043945,4999.66455078125,4999.66455078125,53.2425806587076,5.63335628351009,5.32375335693359,80,1,0,0,1,0.3057861328125,33.7243423461914,2,1,3,157.574142456055,0,158.183120727539,,,,,,,,,,,,,,,,,,,,,,,,,,,,,,,,,
,3879747773.89596,154.10277557373,4999.66455078125,-3.05467784634827E-5,9.5635100926023E-9,1,6,13.4005146026611,5.00798865727519,33.380001783371,-0.0380657944279856,-0.00560741949979865,1,6.83011592681388E-8,,,,,,,,,,,,,,,,,,,,,153.675857543945,154.529693603516,4999.66455078125,4999.66455078125,53.3899176345826,5.6334512227013,5.31003284454346,78,1,64,0,0,0.310745239257812,33.7243423461914,2,1,3,153.675857543945,0,154.10277557373,,,,,,,,,,,,,,,,,,,,,,,,,,,,,,,,,
,3879747797.3402,150.310401916504,4999.66455078125,-3.05339622592949E-5,8.37869147857767E-9,1,6,13.4005146026611,5.00795873566322,33.380001783371,-0.0380496649826823,-0.00560395580518481,1,6.91268167352617E-8,,,,,,,,,,,,,,,,,,,,,149.821166992187,150.79963684082,4999.66455078125,4999.66455078125,53.4813681713326,5.63292617496957,5.30282020568848,80,1,0,0,1,0.296630859375,33.7243423461914,2,1,3,149.821166992187,0,150.310401916504,,,,,,,,,,,,,,,,,,,,,,,,,,,,,,,,,
,3879747821.55555,146.350204467773,4999.66455078125,-3.05458230213692E-5,7.89477198505758E-9,1,6,13.4005146026611,5.00789459461056,33.380001783371,-0.0380649646562463,-0.00559800439380246,1,7.55981478245228E-8,,,,,,,,,,,,,,,,,,,,,145.743072509766,146.957336425781,4999.66455078125,4999.66455078125,53.5079435409864,5.63437865240723,5.29453945159912,80,1,0,0,1,0.297317504882812,33.7243423461914,2,1,3,145.743072509766,0,146.350204467773,,,,,,,,,,,,,,,,,,,,,,,,,,,,,,,,,
,3879747845.44006,142.311080932617,4999.66455078125,-3.05157475959594E-5,8.64449889011146E-9,1,6,13.4005146026611,5.00798390729328,33.3699993789196,-0.0380275381906477,-0.00559861928584369,1,7.07174719687137E-8,,,,,,,,,,,,,,,,,,,,,141.719589233398,142.902572631836,4999.66455078125,4999.66455078125,53.5505422952845,5.63334488917503,5.29077816009521,80,1,0,0,1,0.3045654296875,33.7243423461914,2,1,3,141.719589233398,0,142.311080932617,,,,,,,,,,,,,,,,,,,,,,,,,,,,,,,,,
,3879747869.32712,138.342796325684,4999.66455078125,-3.05286044459914E-5,9.02606267362934E-9,1,6,13.4005146026611,5.00799776070592,33.3699993789196,-0.0380436355714159,-0.00560147720018599,1,7.03639940376194E-8,,,,,,,,,,,,,,,,,,,,,137.768081665039,138.917510986328,4999.66455078125,4999.66455078125,53.5552320663999,5.6332288681951,5.2849497795105,80,1,0,0,1,0.304946899414063,33.7243423461914,2,1,3,137.768081665039,0,138.342796325684,,,,,,,,,,,,,,,,,,,,,,,,,,,,,,,,,
,3879747909.61263,131.62947845459,4999.66455078125,-3.05099841327839E-5,8.89194100041045E-9,1,6,13.4005146026611,5.00806487994346,33.3499982953072,-0.0380192309143908,-0.005610953179557,1,6.00561422929463E-8,,,,,,,,,,,,,,,,,,,,,130.839782714844,132.419174194336,4999.66455078125,4999.66455078125,53.5251393684095,5.63351115796449,5.26676368713379,78,1,68,0,0,0.29693603515625,33.7243423461914,2,1,3,130.839782714844,0,131.62947845459,,,,,,,,,,,,,,,,,,,,,,,,,,,,,,,,,
,3879747934.9406,127.384616851807,4999.66455078125,-3.05119034765551E-5,7.60631661009855E-9,1,6,13.4005146026611,5.00810634700081,33.3499982953072,-0.0380215102343955,-0.00561506416565859,1,5.7095439759748E-8,,,,,,,,,,,,,,,,,,,,,126.966133117676,127.803100585938,4999.66455078125,4999.66455078125,53.3062833830249,5.63337459748509,5.26300621032715,80,1,0,0,1,0.304641723632812,33.7243423461914,2,1,3,126.966133117676,0,127.384616851807,,,,,,,,,,,,,,,,,,,,,,,,,,,,,,,,,
,3879747958.60763,123.495811462402,4999.66455078125,-3.04979286116549E-5,7.24272068028637E-9,1,6,13.4005146026611,5.00807118989564,33.3499982953072,-0.0380064312742975,-0.0055943329019324,1,7.16021232111628E-8,,,,,,,,,,,,,,,,,,,,,122.992111206055,123.99951171875,4999.66455078125,4999.66455078125,53.5243577398903,5.63374283891652,5.2521710395813,80,1,0,0,1,0.302352905273438,33.7243423461914,2,1,3,122.992111206055,0,123.495811462402,,,,,,,,,,,,,,,,,,,,,,,,,,,,,,,,,
,3879747982.38446,119.32014465332,4999.66455078125,-3.04906529083564E-5,8.28932451652108E-9,1,6,13.4005146026611,5.00812871795613,33.3499982953072,-0.0379974009058644,-0.00559692175480193,1,6.85077254974384E-8,,,,,,,,,,,,,,,,,,,,,118.772789001465,119.867500305176,4999.66455078125,4999.66455078125,53.4786324715153,5.63385744277055,5.24381732940674,80,1,0,0,1,0.304031372070313,34.2131004333496,2,1,3,118.772789001465,0,119.32014465332,,,,,,,,,,,,,,,,,,,,,,,,,,,,,,,,,
,3879748006.26114,115.385444641113,4999.66455078125,-3.04930518946031E-5,7.79226271633686E-9,1,6,13.4005146026611,5.00807049476833,33.3499982953072,-0.0379996537248617,-0.00559806864679562,1,6.78729559056345E-8,,,,,,,,,,,,,,,,,,,,,114.904113769531,115.866775512695,4999.66455078125,4999.66455078125,53.4063318334864,5.63355107436742,5.23895597457886,80,1,0,0,1,0.297088623046875,33.7243423461914,2,1,3,114.904113769531,0,115.385444641113,,,,,,,,,,,,,,,,,,,,,,,,,,,,,,,,,
,3879748030.47177,111.486324310303,4999.66455078125,-3.0481991565345E-5,7.44573695392346E-9,1,6,13.4005146026611,5.008049237316,33.3499982953072,-0.0379846752697542,-0.00560248909941836,1,6.26433167010232E-8,,,,,,,,,,,,,,,,,,,,,110.909576416016,112.06307220459,4999.66455078125,4999.66455078125,53.5009088843133,5.63386423167233,5.22810220718384,80,1,0,0,1,0.297470092773438,33.7243423461914,2,1,3,110.909576416016,0,111.486324310303,,,,,,,,,,,,,,,,,,,,,,,,,,,,,,,,,
,3879748054.41114,107.478874206543,4999.66455078125,-3.04880645396735E-5,7.92711640305788E-9,1,6,13.4005146026611,5.0080791748296,33.330000936985,-0.0379933929489407,-0.0055980871321122,1,6.71229261320627E-8,,,,,,,,,,,,,,,,,,,,,106.902145385742,108.055603027344,4999.66455078125,4999.66455078125,53.5200587830345,5.63294615962461,5.21836757659912,80,1,0,0,1,0.305328369140625,33.7243423461914,2,1,3,106.881927490234,0,107.478874206543,,,,,,,,,,,,,,,,,,,,,,,,,,,,,,,,,
,3879748077.9652,103.589698791504,4999.66455078125,-3.04814051197168E-5,7.11430095819259E-9,1,6,13.4005146026611,5.00804206836447,33.330000936985,-0.0379848658143727,-0.00559570314737898,1,6.79938742632354E-8,,,,,,,,,,,,,,,,,,,,,103.107154846191,104.072242736816,4999.66455078125,4999.66455078125,53.315272110996,5.63369964411204,5.20780086517334,80,1,0,0,1,0.312042236328125,34.2131004333496,2,1,3,103.071975708008,0,103.589698791504,,,,,,,,,,,,,,,,,,,,,,,,,,,,,,,,,
,3879748102.16318,99.7694778442383,4999.66455078125,-3.04706898509755E-5,7.96989466148873E-9,1,6,13.4005146026611,5.00812789785257,33.330000936985,-0.0379724076712608,-0.00559396871048101,1,6.78907860785113E-8,,,,,,,,,,,,,,,,,,,,,99.3457717895508,100.193183898926,4999.66455078125,4999.66455078125,53.3840554206883,5.63303987321436,5.1904091835022,80,1,0,0,1,0.312728881835937,33.7243423461914,2,1,3,99.3277206420898,0,99.7694778442383,,,,,,,,,,,,,,,,,,,,,,,,,,,,,,,,,
,3879748125.76018,95.8989791870117,4999.66455078125,-3.0473431587068E-5,8.09483231896997E-9,1,6,13.4005146026611,5.00790146072871,33.330000936985,-0.0379739899917407,-0.00559033785301559,1,7.09318481247693E-8,,,,,,,,,,,,,,,,,,,,,95.4475784301758,96.3503799438477,4999.66455078125,4999.66455078125,53.4383786027749,5.63322995902829,5.18584489822388,79,1,64,0,0,0.297393798828125,33.7243423461914,2,1,3,95.4475784301758,0,95.8989791870117,,,,,,,,,,,,,,,,,,,,,,,,,,,,,,,,,
,3879748149.54795,92.0101776123047,4999.66455078125,-3.04586121669912E-5,7.83136414349028E-9,1,6,13.4005146026611,5.00777675961402,33.330000936985,-0.0379495433131862,-0.00561856644042911,1,4.58971478872584E-8,,,,,,,,,,,,,,,,,,,,,91.5544128417969,92.4659423828125,4999.66455078125,4999.66455078125,53.5251393684095,5.63499409032162,5.16510581970215,80,1,0,0,1,0.29876708984375,33.7243423461914,2,1,3,91.5544128417969,0,92.0101776123047,,,,,,,,,,,,,,,,,,,,,,,,,,,,,,,,,
,3879748190.3505,85.1531257629395,4999.66455078125,-3.0459569122199E-5,8.01795338173767E-9,1,6,13.4005146026611,5.00758535566235,33.3199985325336,-0.0379509802420818,-0.00560325366131005,1,5.80928963214497E-8,,,,,,,,,,,,,,,,,,,,,84.5286483764648,85.7776031494141,4999.66455078125,4999.66455078125,53.5204495972941,5.63602396254349,5.14303159713745,80,1,0,0,1,0.30517578125,33.7243423461914,2,1,3,84.5286483764648,0,85.1531257629395,,,,,,,,,,,,,,,,,,,,,,,,,,,,,,,,,
,3879748215.29883,80.9648628234863,4999.66455078125,-3.04373157897928E-5,7.81465058858E-9,1,6,13.4005146026611,5.00769676840618,33.3199985325336,-0.0379252416424327,-0.00559393000410019,1,6.23889316785539E-8,,,,,,,,,,,,,,,,,,,,,80.496208190918,81.4335174560547,4999.66455078125,4999.66455078125,53.5411627530537,5.63510837793451,5.13135862350464,78,1,64,0,0,0.299224853515625,33.7243423461914,2,1,3,80.4408264160156,0,80.9648628234863,,,,,,,,,,,,,,,,,,,,,,,,,,,,,,,,,
,3879748239.38869,76.8172760009766,4999.66455078125,-3.04407694593089E-5,7.70003249134801E-9,1,6,13.4005146026611,5.00777277089486,33.3199985325336,-0.0379311746740647,-0.00558916817731553,1,6.68235970544872E-8,,,,,,,,,,,,,,,,,,,,,76.1679611206055,77.4665908813477,4999.66455078125,4999.66455078125,53.3715493643806,5.63425370484704,5.11343622207642,80,1,0,0,1,0.304718017578125,33.7243423461914,2,1,3,76.1679611206055,0,76.8172760009766,,,,,,,,,,,,,,,,,,,,,,,,,,,,,,,,,
,3879748262.99001,72.8838043212891,4999.66455078125,-3.04235418444942E-5,1.06749969997489E-8,1,6,13.4005146026611,5.00782375882835,33.3000011742115,-0.0379103855817229,-0.00558516139774427,1,6.75268662174199E-8,,,,,,,,,,,,,,,,,,,,,72.4504089355469,73.3171997070312,4999.66455078125,4999.66455078125,53.4344704601787,5.63399879767226,5.10404109954834,80,1,0,0,1,0.298004150390625,33.7243423461914,2,1,3,72.4504089355469,0,72.8838043212891,,,,,,,,,,,,,,,,,,,,,,,,,,,,,,,,,
,3879748287.18606,68.8009033203125,4999.66455078125,-3.04053941835147E-5,1.29147514105252E-8,1,6,13.4005146026611,5.00790819945217,33.3000011742115,-0.0378884466096612,-0.00558342129293778,1,6.63146474129824E-8,,,,,,,,,,,,,,,,,,,,,68.2283172607422,69.3734893798828,4999.66455078125,4999.66455078125,53.4086767190441,5.63362254027171,5.08345317840576,80,1,0,0,1,0.297698974609375,33.7243423461914,2,1,3,68.2283172607422,0,68.8009033203125,,,,,,,,,,,,,,,,,,,,,,,,,,,,,,,,,
,3879748310.7347,64.7225799560547,4999.66455078125,-3.03906043988269E-5,1.03188266150071E-8,1,6,13.4005146026611,5.0078904793852,33.3000011742115,-0.0378690328637015,-0.00558600392067341,1,6.20067787363188E-8,,,,,,,,,,,,,,,,,,,,,64.257080078125,65.1880798339844,4999.66455078125,4999.66455078125,53.4735518861403,5.6329566015263,5.0685567855835,80,1,0,0,1,0.298004150390625,33.7243423461914,2,1,3,64.257080078125,0,64.7225799560547,,,,,,,,,,,,,,,,,,,,,,,,,,,,,,,,,
,3879748334.94484,60.6907558441162,4999.66455078125,-3.03705203155247E-5,8.51327597066501E-9,1,6,13.4005146026611,5.00788286136671,33.3000011742115,-0.0378426957533058,-0.00559052491388431,1,5.53634922448988E-8,,,,,,,,,,,,,,,,,,,,,60.1332702636719,61.2482414245606,4999.66455078125,4999.66455078125,53.4798049142941,5.63340684372724,5.03818464279175,80,1,0,0,1,0.305252075195313,34.2131004333496,2,1,3,60.1332702636719,0,60.6907558441162,,,,,,,,,,,,,,,,,,,,,,,,,,,,,,,,,
,3879748358.50715,56.5825176239014,4999.66455078125,-3.03395501910252E-5,6.87032968614772E-9,1,6,13.4005146026611,5.0078893694156,33.3000011742115,-0.0378047557605176,-0.0055809492501067,1,5.84257010717426E-8,,,,,,,,,,,,,,,,,,,,,56.0361976623535,57.1288375854492,4999.66455078125,4999.66455078125,53.3449739947268,5.63432835950883,5.02197790145874,80,1,0,0,1,0.2972412109375,33.7243423461914,2,1,3,56.0361976623535,0,56.5825176239014,,,,,,,,,,,,,,,,,,,,,,,,,,,,,,,,,
,3879748382.81854,52.4651317596436,4999.66455078125,-3.03144537274039E-5,8.79593152839325E-9,1,6,13.4005146026611,5.00791852806956,33.3000011742115,-0.0377730444955167,-0.00558137240452094,1,5.43681967299899E-8,,,,,,,,,,,,,,,,,,,,,51.9977645874023,52.9324989318848,4999.66455078125,4999.66455078125,53.4774600287364,5.63387573225579,4.99173545837402,80,1,0,0,1,0.298919677734375,33.7243423461914,2,1,3,51.9740791320801,0,52.4651317596436,,,,,,,,,,,,,,,,,,,,,,,,,,,,,,,,,
,3879748406.55861,48.335765838623,4999.66455078125,-3.0266376778596E-5,8.03688584702716E-9,1,6,13.4005146026611,5.00801109970639,33.3000011742115,-0.0377154301074756,-0.00556386068033482,1,6.1349245727033E-8,,,,,,,,,,,,,,,,,,,,,47.8535957336426,48.8179359436035,4999.66455078125,4999.66455078125,53.3664687790057,5.633275486576,4.95816564559937,80,1,0,0,1,0.298538208007812,33.2355842590332,2,1,3,47.8535957336426,0,48.335765838623,,,,,,,,,,,,,,,,,,,,,,,,,,,,,,,,,
,3879748430.46129,44.1985321044922,4999.66455078125,-3.02248629985866E-5,1.04033413049407E-8,1,6,13.4005146026611,5.00804255668667,33.3000011742115,-0.0376635026383722,-0.00555980182481881,1,5.84364158224993E-8,,,,,,,,,,,,,,,,,,,,,43.7679901123047,44.6290740966797,4999.66455078125,4999.66455078125,53.4927017848614,5.63297822957743,4.92266130447388,80,1,0,0,1,0.29693603515625,34.2131004333496,2,1,3,43.7679901123047,0,44.1985321044922,,,,,,,,,,,,,,,,,,,,,,,,,,,,,,,,,
,3879748470.79689,37.3418579101562,4999.66455078125,-3.01436775854735E-5,9.72196473443212E-9,1,6,13.4005146026611,5.00815856544424,33.2800000905991,-0.0375626580920665,-0.00555102892536564,1,5.34781142330746E-8,,,,,,,,,,,,,,,,,,,,,36.6353492736816,38.0483665466309,4999.66455078125,4999.66455078125,53.4254817322076,5.63287336367923,4.85571813583374,80,1,0,0,1,0.303192138671875,34.2131004333496,2,1,3,36.6353492736816,0,37.3418579101562,,,,,,,,,,,,,,,,,,,,,,,,,,,,,,,,,
,3879748496.11545,33.0558166503906,4999.66455078125,-3.00804559605867E-5,8.26000616575222E-9,1,6,13.4005146026611,5.00813875282537,33.2800000905991,-0.037482944470276,-0.00554419956354957,1,4.94778928715617E-8,,,,,,,,,,,,,,,,,,,,,32.4454460144043,33.666187286377,4999.66455078125,4999.66455078125,53.5122424978422,5.6333541307042,4.79092216491699,80,1,0,0,1,0.298309326171875,33.7243423461914,2,1,3,32.4454460144043,0,33.0558166503906,,,,,,,,,,,,,,,,,,,,,,,,,,,,,,,,,
,3879748544.01456,25.01145362854,4999.66455078125,-2.99732003198751E-5,9.85945830300022E-9,1,6,13.4005146026611,5.00817168340763,33.2800000905991,-0.0373502428715901,-0.00552043564145152,10,5.25493248303105E-8,,,,,,,,,,,,,,,,,,,,,24.957836151123,25.065071105957,4999.66455078125,4999.66455078125,53.5196679687749,5.63278318826535,4.65683889389038,80,1,0,0,1,0.305404663085937,33.7243423461914,2,1,3,24.9274406433105,0,25.01145362854,,,,,,,,,,,,,,,,,,,,,,,,,,,,,,,,,
,3879748573.40213,20.0283088684082,4999.66455078125,-2.97880048222096E-5,1.02576771619306E-8,1,6,13.4005146026611,5.00817366963672,33.2800000905991,-0.0371180133307732,-0.00549618333943796,1,4.43150012267394E-8,,,,,,,,,,,,,,,,,,,,,19.5268993377686,20.5297183990479,4999.66455078125,4999.66455078125,53.4364245314768,5.63301357688465,4.49903202056885,80,1,0,0,1,0.305709838867188,33.7243423461914,2,1,3,19.5268993377686,0,20.0283088684082,,,,,,,,,,,,,,,,,,,,,,,,,,,,,,,,,
,3879748597.32373,16.0326218605042,4999.66455078125,-2.96293955677752E-5,1.09419273546161E-8,1,6,13.4005146026611,5.00814840563718,33.2800000905991,-0.0369210815184101,-0.00546041471686159,1,4.92686066893466E-8,,,,,,,,,,,,,,,,,,,,,15.557333946228,16.5079097747803,4999.66455078125,4999.66455078125,53.4266541749864,5.63325107606618,4.32439994812012,80,1,0,0,1,0.30426025390625,33.2355842590332,2,1,3,15.557333946228,0,16.0326218605042,,,,,,,,,,,,,,,,,,,,,,,,,,,,,,,,,
,3879748630.68221,10.6748604774475,4999.66455078125,-2.92186713403256E-5,1.14129759184448E-8,1,6,13.4005146026611,5.00818087937122,33.2800000905991,-0.036407875074996,-0.00539636546609071,10,3.92787542408529E-8,,,,,,,,,,,,,,,,,,,,,10.6077432632446,10.7419776916504,4999.66455078125,4999.66455078125,53.4794141000345,5.63318291137283,3.94919753074646,80,1,0,0,1,0.302810668945313,33.7243423461914,2,1,3,10.6077432632446,0,10.6748604774475,,,,,,,,,,,,,,,,,,,,,,,,,,,,,,,,,
,3879748663.29888,9.55084466934204,4999.66455078125,-2.89968814347138E-5,1.73266805731171E-8,1,6,13.4005146026611,5.0081731650294,33.2800000905991,-0.036132625118325,-0.00534744518720294,1,4.53593439500302E-8,,,,,,,,,,,,,,,,,,,,,9.45962429046631,9.64206504821777,4999.66455078125,4999.66455078125,53.5231852971114,5.63334407650681,3.6453218460083,78,1,32,0,0,0.296630859375,33.7243423461914,6,1,3,9.45962429046631,0,9.55084466934204,,,,,,,,,,,,,,,,,,,,,,,,,,,,,,,,,
,3879748686.90335,8.72445869445801,4999.66455078125,-2.88624887760133E-5,1.37586137265218E-8,1,6,13.4005146026611,5.00812879809185,33.2800000905991,-0.0359652726326501,-0.00531886699184023,1,4.81418878036372E-8,,,,,,,,,,,,,,,,,,,,,8.62571334838867,8.82320404052734,4999.66455078125,4999.66455078125,53.5739911508614,5.63375559713878,3.46299195289612,79,1,64,0,0,0.297012329101562,33.7243423461914,6,1,3,8.62571334838867,0,8.72445869445801,,,,,,,,,,,,,,,,,,,,,,,,,,,,,,,,,
,3879748710.7216,7.34676361083984,4999.66455078125,-2.85303761359574E-5,1.46443174219323E-8,1,6,13.4005146026611,5.00816310789154,33.2800000905991,-0.0355539278679399,-0.00524329416729305,1,5.91632596389277E-8,,,,,,,,,,,,,,,,,,,,,7.01849317550659,7.6750340461731,4999.66455078125,4999.66455078125,53.5478065954672,5.63373366445544,3.16394591331482,80,1,0,0,1,0.304641723632812,33.7243423461914,6,1,3,7.01849317550659,0,7.34676361083984,,,,,,,,,,,,,,,,,,,,,,,,,,,,,,,,,
,3879748734.60493,5.68099188804626,4999.66455078125,-2.79923841467011E-5,1.2763058586681E-8,1,6,13.4005146026611,5.00820864736285,33.2800000905991,-0.0348817414007131,-0.00515916764192547,1,4.62641761022017E-8,,,,,,,,,,,,,,,,,,,,,5.53681516647339,5.82516860961914,4999.66455078125,4999.66455078125,53.3867911205057,5.6335137099665,2.89190077781677,80,1,0,0,1,0.305099487304687,33.7243423461914,6,1,3,5.53681516647339,0,5.68099188804626,,,,,,,,,,,,,,,,,,,,,,,,,,,,,,,,,
,3879748758.48304,3.13455128669739,4999.66455078125,-2.60848945429614E-5,2.23069088807517E-8,1,6,13.4005146026611,5.00824518940427,33.2800000905991,-0.0325048771197342,-0.00480928290893742,1,4.18046259231137E-8,,,,,,,,,,,,,,,,,,,,,2.91248440742493,3.35661816596985,4999.66455078125,4999.66455078125,53.4493214020441,5.63375066558125,2.40428352355957,79,1,68,0,0,0.305328369140625,33.7243423461914,6,1,3,2.91248440742493,0,3.13455128669739,,,,,,,,,,,,,,,,,,,,,,,,,,,,,,,,,
,3879748782.33198,2.49756348133087,4999.66455078125,-2.52112885316658E-5,1.32297815583346E-8,1,6,13.4005146026611,5.00821618021314,33.2800000905991,-0.031418725344483,-0.00462999941170338,1,5.49964723525207E-8,,,,,,,,,,,,,,,,,,,,,2.49019074440002,2.50493621826172,4999.66455078125,4999.66455078125,53.3543535369576,5.63360936079647,2.21989846229553,80,1,0,0,1,0.304412841796875,33.2355842590332,6,1,3,2.49019074440002,0,2.49756348133087,,,,,,,,,,,,,,,,,,,,,,,,,,,,,,,,,
,3879748806.26151,2.45794832706451,4999.66455078125,-2.51573988004731E-5,1.10225596343497E-8,1,6,13.4005146026611,5.00824237673614,33.2800000905991,-0.0313521659797034,-0.00461766510413723,1,5.68626317574285E-8,,,,,,,,,,,,,,,,,,,,,2.45773863792419,2.45815801620483,4999.66455078125,4999.66455078125,53.5263118111883,5.63381345257463,2.19325828552246,80,1,0,0,1,0.298080444335937,33.7243423461914,6,1,3,2.45737791061401,0,2.45794832706451,,,,,,,,,,,,,,,,,,,,,,,,,,,,,,,,,
,3879748830.20157,2.4577294588089,4999.66455078125,-2.51473708869211E-5,1.73126075021801E-8,1,6,13.4005146026611,5.00822923843426,33.2800000905991,-0.0313381914254884,-0.00462491521884118,1,4.9529349276843E-8,,,,,,,,,,,,,,,,,,,,,2.45722150802612,2.45823740959167,4999.66455078125,4999.66455078125,53.6220613047941,5.63390125430472,2.19947290420532,80,1,0,0,1,0.305938720703125,33.7243423461914,6,1,3,2.45823740959167,0,2.4577294588089,,,,,,,,,,,,,,,,,,,,,,,,,,,,,,,,,
,3879748854.29332,2.46448290348053,4999.66455078125,-2.51731303110599E-5,1.04556706485961E-8,1,6,13.4005146026611,5.00820100827516,33.2800000905991,-0.0313708966929471,-0.00462392415028102,1,5.41490770018732E-8,,,,,,,,,,,,,,,,,,,,,2.46312689781189,2.46583890914917,4999.66455078125,4999.66455078125,53.5560136949191,5.63501711804462,2.20617461204529,80,1,0,0,1,0.305709838867188,33.7243423461914,6,1,3,2.46583890914917,0,2.46448290348053,,,,,,,,,,,,,,,,,,,,,,,,,,,,,,,,,
,3879748878.19046,2.46466135978699,4999.66455078125,-2.51496128431373E-5,1.05162090368747E-8,1,6,13.4005146026611,5.00819275511353,33.2800000905991,-0.0313413587544491,-0.00462065088391586,1,5.32498968893406E-8,,,,,,,,,,,,,,,,,,,,,2.46361637115479,2.46570634841919,4999.66455078125,4999.66455078125,53.5708646367845,5.63422679139677,2.21266984939575,80,1,0,0,1,0.3045654296875,33.7243423461914,6,1,3,2.46361637115479,0,2.46466135978699,,,,,,,,,,,,,,,,,,,,,,,,,,,,,,,,,
,3879748902.04816,2.44836699962616,4999.66455078125,-2.51411373629649E-5,1.19901417511283E-8,1,6,13.4005146026611,5.00819035934656,33.2800000905991,-0.0313300703760998,-0.00462380550023558,1,4.9447338201493E-8,,,,,,,,,,,,,,,,,,,,,2.44809865951538,2.44863533973694,4999.66455078125,4999.66455078125,53.6474642316691,5.63450460813531,2.20655131340027,80,1,0,0,1,0.29815673828125,33.7243423461914,6,1,3,2.44863533973694,0,2.44836699962616,,,,,,,,,,,,,,,,,,,,,,,,,,,,,,,,,
,3879748926.10516,2.40616250038147,4999.66455078125,-2.50437093627097E-5,1.00053692186268E-8,1,6,13.4005146026611,5.00816979263912,33.2800000905991,-0.0312103650842329,-0.00459325684764161,1,5.93728394557675E-8,,,,,,,,,,,,,,,,,,,,,2.40424203872681,2.40808296203613,4999.66455078125,4999.66455078125,53.3871819347653,5.63428662608279,2.19308423995972,80,1,0,0,1,0.304641723632812,33.7243423461914,6,1,3,2.40424203872681,0,2.40616250038147,,,,,,,,,,,,,,,,,,,,,,,,,,,,,,,,,
,3879748949.93476,2.40640234947205,4999.66455078125,-2.50361371787123E-5,9.5904088999724E-9,1,6,13.4005146026611,5.00820797309388,33.2800000905991,-0.031200941463812,-0.00459405182870687,1,5.76412493789447E-8,,,,,,,,,,,,,,,,,,,,,2.40432119369507,2.40848350524902,4999.66455078125,4999.66455078125,53.4286082462845,5.63476908985692,2.19905710220337,80,1,0,0,1,0.305023193359375,33.7243423461914,6,1,3,2.40848350524902,0,2.40640234947205,,,,,,,,,,,,,,,,,,,,,,,,,,,,,,,,,
,3879748973.4377,2.41442930698395,4999.66455078125,-2.50681881831862E-5,1.13071763862438E-8,1,6,13.4005146026611,5.00820292992442,33.2800000905991,-0.0312400339111806,-0.00460531924912089,1,5.33864060920382E-8,,,,,,,,,,,,,,,,,,,,,2.41389679908752,2.41496181488037,4999.66455078125,4999.66455078125,53.467689672246,5.63435097939073,2.20135045051575,80,1,0,0,1,0.296173095703125,33.7243423461914,6,1,3,2.41496181488037,0,2.41442930698395,,,,,,,,,,,,,,,,,,,,,,,,,,,,,,,,,
,3879748997.28703,2.3847382068634,4999.66455078125,-2.50155893828323E-5,1.10216518285565E-8,1,6,13.4005146026611,5.00822474782197,33.2800000905991,-0.0311746675051702,-0.00459573423747572,1,5.32342388884138E-8,,,,,,,,,,,,,,,,,,,,,2.38031220436096,2.38916420936584,4999.66455078125,4999.66455078125,53.5278750682268,5.63421398035919,2.19332671165466,80,1,0,0,1,0.305557250976562,33.7243423461914,6,1,3,2.38031220436096,0,2.3847382068634,,,,,,,,,,,,,,,,,,,,,,,,,,,,,,,,,
,3879749021.11922,2.33295822143555,4999.66455078125,-2.4901118279102E-5,1.04767720170992E-8,1,6,13.4005146026611,5.00817460020471,33.2800000905991,-0.0310311264016032,-0.00457766042774509,1,5.05662834780347E-8,,,,,,,,,,,,,,,,,,,,,2.32557463645935,2.34034180641174,4999.66455078125,4999.66455078125,53.374285064198,5.63484410391993,2.17461442947388,80,1,0,0,1,0.304107666015625,33.7243423461914,6,1,3,2.32557463645935,0,2.33295822143555,,,,,,,,,,,,,,,,,,,,,,,,,,,,,,,,,
,3879749045.34166,2.14315295219421,4999.66455078125,-2.44789079889371E-5,1.145637492246E-8,1,6,13.4005146026611,5.00814579660505,33.2800000905991,-0.0305040529174382,-0.00450455864975651,1,4.60559487549165E-8,,,,,,,,,,,,,,,,,,,,,2.09797501564026,2.18833088874817,4999.66455078125,4999.66455078125,53.4368153457364,5.63461554835872,2.07520389556885,80,1,0,0,1,0.304641723632812,33.2355842590332,2,1,3,2.09572958946228,0,2.14315295219421,,,,,,,,,,,,,,,,,,,,,,,,,,,,,,,,,
,3879749068.95522,1.99812537431717,4999.66455078125,-2.41635357516144E-5,9.3408801536788E-9,1,6,13.4005146026611,5.00808867345972,33.2800000905991,-0.0301100312771099,-0.004450095713126,1,4.2539000826383E-8,,,,,,,,,,,,,,,,,,,,,1.99796032905579,1.99829041957855,4999.66455078125,4999.66455078125,53.5841523216114,5.63543685912652,2.01156616210938,80,1,0,0,1,0.305938720703125,33.7243423461914,5,1,3,1.99829041957855,0,1.99812537431717,,,,,,,,,,,,,,,,,,,,,,,,,,,,,,,,,
,3879749093.24156,1.99525934457779,4999.66455078125,-2.41806682292057E-5,1.02738916895031E-8,1,6,13.4005146026611,5.00809359307649,33.2800000905991,-0.0301314283022301,-0.00445321038518759,1,4.2606615188717E-8,,,,,,,,,,,,,,,,,,,,,1.9903701543808,2.00014853477478,4999.66455078125,4999.66455078125,53.5794625504961,5.63489614338031,1.9930694103241,80,1,0,0,1,0.299148559570313,33.7243423461914,5,1,3,1.9903701543808,0,1.99525934457779,,,,,,,,,,,,,,,,,,,,,,,,,,,,,,,,,
,3879749116.97627,2.00018411874771,4999.66455078125,-2.41816958052402E-5,1.06298880534887E-8,1,6,13.4005146026611,5.00804960755648,33.2800000905991,-0.0301327552184,-0.00445056159765563,1,4.48427059893168E-8,,,,,,,,,,,,,,,,,,,,,1.99959909915924,2.00076913833618,4999.66455078125,4999.66455078125,53.6615335450153,5.63535179495198,1.99182450771332,80,1,0,0,1,0.298538208007812,33.7243423461914,5,1,3,2.00076913833618,0,2.00018411874771,,,,,,,,,,,,,,,,,,,,,,,,,,,,,,,,,
,3879749140.85643,1.99986886978149,4999.66455078125,-2.4187512940135E-5,1.19209917772026E-8,1,6,13.4005146026611,5.00816519356719,33.2800000905991,-0.0301403104576877,-0.00445622651297173,1,4.12809224465875E-8,,,,,,,,,,,,,,,,,,,,,1.999675989151,2.00006175041199,4999.66455078125,4999.66455078125,53.5618759088134,5.63569788127717,1.98930156230927,80,1,0,0,1,0.306396484375,34.7018585205078,5,1,3,1.999675989151,0,1.99986886978149,,,,,,,,,,,,,,,,,,,,,,,,,,,,,,,,,
,3879749164.74362,2.00014173984528,4999.66455078125,-2.41804343071073E-5,8.8827171894331E-9,1,6,13.4005146026611,5.00813192197838,33.2800000905991,-0.0301318195081247,-0.0044508059564709,1,4.45399190121701E-8,,,,,,,,,,,,,,,,,,,,,2.00008487701416,2.00019860267639,4999.66455078125,4999.66455078125,53.5220128543326,5.63484020147642,1.98208296298981,80,1,0,0,1,0.303192138671875,33.7243423461914,1,1,3,2.00019860267639,0,2.00014173984528,,,,,,,,,,,,,,,,,,,,,,,,,,,,,,,,,