File: SQUID/Reference/STO/B1/STOsubs_MH_10K_FC_0d5T.csv
Comment,Time Stamp (sec),Temperature (K),Magnetic Field (Oe),Moment (emu),M. Std. Err. (emu),Transport Action,Averaging Time (sec),Frequency (Hz),Peak Amplitude (mm),Center Position (mm),Lockin Signal' (V),Lockin Signal (V),Range,M. Quad. Signal (emu),AC Moment (emu),AC M. Std Err. (emu),AC Phase (deg),AC Phase Std. Err. (deg),AC Susceptibility (emu/Oe),AC Suscept. Std Err. (emu/Oe),AC X' (emu/Oe),AC X' Std Err. (emu/Oe),AC X'' (emu/Oe),AC X'' Std Err. (emu/Oe),AC Drive (Oe),AC Frequency (Hz),AC Averaging Time (sec),AC Cycles,AC Range,AC Measure Type,AC Signal' (V),AC Signal'' (V),AC Trim Coil Ratio,AC Trim Coil Phase,Min. Temperature (K),Max. Temperature (K),Min. Field (Oe),Max. Field (Oe),Mass (grams),Motor Lag (deg),Pressure (Torr),Measure Count,Measurement Number,SQUID Status (code),Motor Status (code),Measure Status (code),Motor Current (amps),Motor Temp. (C),Temp. Status (code),Field Status (code),Chamber Status (code),Chamber Temp (K),Redirection State,Average Temp (K),Rotation Angle (deg),Rotator state,DC Moment Fixed Ctr (emu),DC Moment Err Fixed Ctr (emu),DC Moment Free Ctr (emu),DC Moment Err Free Ctr (emu),DC Fixed Fit,DC Free Fit,DC Calculated Center (mm),DC Calculated Center Err (mm),DC Scan Length (mm),DC Scan Time (s),DC Number of Points,DC Squid Drift,DC Min V (V),DC Max V (V),DC Scans per Measure,Sample Resistance,He3 Temperature,Sorb Resistance,Sorb Temperature,Map 05,Map 06,Map 07,Map 08,Map 09,Map 10,Map 11,Map 12,Map 13,Map 14,Map 15,Map 16
,3879766121.0169,10.0001168251038,69999.6484375,-4.2076061627284E-4,1.67018137072391E-7,1,4,13.4005146026611,5.00718801557143,33.2800000905991,-0.524059014652978,-0.0782480986525349,1,1.16154730767179E-7,,,,,,,,,,,,,,,,,,,,,10.0000953674316,10.0001382827759,69999.6484375,69999.6484375,53.9913807801307,5.63884260372507,3.54660964012146,54,1,0,0,1,0.299301147460937,32.7468223571777,1,1,3,10.0000953674316,0,10.0001168251038,,,,,,,,,,,,,,,,,,,,,,,,,,,,,,,,,
,3879766344.11168,10.0003895759583,54999.671875,-3.28990064105801E-4,6.04916978201003E-8,1,4,13.4005146026611,5.00697514616237,33.2800000905991,-0.409729510129777,-0.0612085796916148,1,6.63120936565671E-8,,,,,,,,,,,,,,,,,,,,,10.0003032684326,10.0004758834839,54999.671875,54999.671875,53.8940680294865,5.63866160260396,3.56791496276855,54,2,0,0,1,0.298614501953125,33.7243423461914,1,1,3,10.0004758834839,0,10.0003895759583,,,,,,,,,,,,,,,,,,,,,,,,,,,,,,,,,
,3879766578.72526,10.0002856254578,39999.66015625,-2.38078561261889E-4,6.88245314580938E-8,1,4,13.4005146026611,5.00683370670514,33.2800000905991,-0.296509623456054,-0.0441960320979278,1,1.25653338389486E-7,,,,,,,,,,,,,,,,,,,,,10.0002269744873,10.0003442764282,39999.66015625,39999.66015625,53.7338341830442,5.63892901534118,3.57058525085449,54,3,0,0,1,0.301055908203125,34.2131004333496,1,1,3,10.0002269744873,0,10.0002856254578,,,,,,,,,,,,,,,,,,,,,,,,,,,,,,,,,
,3879766860.75948,10.0001354217529,19999.501953125,-1.1808879710602E-4,2.66758776839913E-8,1,4,13.4005146026611,5.0068011994816,33.2800000905991,-0.147059811026345,-0.021987600875992,1,9.14335922189487E-9,,,,,,,,,,,,,,,,,,,,,10.0000848770142,10.0001859664917,19999.501953125,19999.501953125,53.5720370795634,5.63716038371002,3.58039712905884,54,1,0,0,1,0.307235717773438,34.2131004333496,1,1,3,10.0000848770142,0,10.0001354217529,,,,,,,,,,,,,,,,,,,,,,,,,,,,,,,,,
,3879767049.65745,10.0000386238098,9999.70703125,-5.86063687497287E-5,1.9012224130629E-8,1,4,13.4005146026611,5.00678813216879,33.2800000905991,-0.0729963094371154,-0.0108308949504915,1,6.98277500981194E-8,,,,,,,,,,,,,,,,,,,,,10.0000104904175,10.0000667572021,9999.70703125,9999.70703125,53.491138527823,5.63720084668649,3.58094692230225,54,2,0,0,1,0.299606323242188,34.7018585205078,1,1,3,10.0000104904175,0,10.0000386238098,,,,,,,,,,,,,,,,,,,,,,,,,,,,,,,,,
,3879767135.97424,9.99990510940552,8499.7158203125,-4.97189995260862E-5,1.77891213835136E-8,1,4,13.4005146026611,5.00677434121249,33.2800000905991,-0.0619220393910651,-0.00921847686403301,1,3.50924508881413E-8,,,,,,,,,,,,,,,,,,,,,9.99969959259033,10.0001106262207,8499.7158203125,8499.7158203125,53.5595310232557,5.63726851555212,3.58063268661499,54,3,0,0,1,0.2996826171875,34.2131004333496,1,1,3,10.0001106262207,0,9.99990510940552,,,,,,,,,,,,,,,,,,,,,,,,,,,,,,,,,
,3879767237.88333,10.0000901222229,6499.65576171875,-3.78228737809445E-5,1.32954852659949E-8,1,4,13.4005146026611,5.00663362774962,33.2800000905991,-0.047096380029099,-0.0070653023762944,1,-1.56889058426472E-8,,,,,,,,,,,,,,,,,,,,,9.99989318847656,10.0002870559692,6499.65576171875,6499.65576171875,53.4719886291018,5.63750903258154,3.58885359764099,54,1,0,0,1,0.301055908203125,34.2131004333496,1,1,3,10.0002870559692,0,10.0000901222229,,,,,,,,,,,,,,,,,,,,,,,,,,,,,,,,,
,3879767323.84915,10.0000042915344,4999.7783203125,-2.89344426892637E-5,1.16686172400034E-8,1,4,13.4005146026611,5.00667723883343,33.2800000905991,-0.0360319710605749,-0.00538581973080711,1,3.40986298428052E-9,,,,,,,,,,,,,,,,,,,,,10.0000038146973,10.0000047683716,4999.7783203125,4999.7783203125,53.5310015823037,5.63723220706964,3.59294486045837,54,2,0,0,1,0.300064086914063,34.2131004333496,1,1,3,9.99999237060547,0,10.0000042915344,,,,,,,,,,,,,,,,,,,,,,,,,,,,,,,,,
,3879767409.94891,10.0001745223999,3499.89990234375,-2.00532517339104E-5,8.99396948060211E-9,1,4,13.4005146026611,5.00679279522873,33.2800000905991,-0.0249728369786986,-0.00373428097715662,1,1.17943892714213E-9,,,,,,,,,,,,,,,,,,,,,10.0000820159912,10.0002670288086,3499.89990234375,3499.89990234375,53.4923109706018,5.63724150176166,3.59021687507629,54,3,0,0,1,0.298919677734375,34.2131004333496,1,1,3,10.0002670288086,0,10.0001745223999,,,,,,,,,,,,,,,,,,,,,,,,,,,,,,,,,
,3879767516.373,10.0000324249268,2899.59130859375,-1.65821699718725E-5,1.34666827965456E-8,1,4,13.4005146026611,5.00676062119948,33.2800000905991,-0.020687969084083,-0.00283421304033176,1,2.04669743304805E-7,,,,,,,,,,,,,,,,,,,,,10.0000095367432,10.0000553131104,2899.59130859375,2899.59130859375,53.3543535369576,5.63784433755724,3.58704423904419,54,1,0,0,1,0.300521850585937,34.2131004333496,1,1,3,10.0000095367432,0,10.0000324249268,,,,,,,,,,,,,,,,,,,,,,,,,,,,,,,,,
,3879767590.77314,9.99974822998047,2749.677734375,-1.56951320128686E-5,1.39903681717663E-8,1,4,13.4005146026611,5.00678697120078,33.2800000905991,-0.0195727073900605,-0.00274100782317816,1,1.46835879857854E-7,,,,,,,,,,,,,,,,,,,,,9.99969005584717,9.99980640411377,2749.677734375,2749.677734375,53.4645631581691,5.63684403260503,3.59372234344482,52,2,68,0,0,0.299606323242188,33.7243423461914,1,1,3,9.99969005584717,0,9.99974822998047,,,,,,,,,,,,,,,,,,,,,,,,,,,,,,,,,
,3879767673.39849,9.99991083145142,2599.7265625,-1.47910797187334E-5,1.11694403550759E-8,1,4,13.4005146026611,5.00671565330731,33.2800000905991,-0.0184409323635919,-0.00260983750896622,1,1.16884683893811E-7,,,,,,,,,,,,,,,,,,,,,9.99988079071045,9.99994087219238,2599.7265625,2599.7265625,53.5079435409864,5.6370195166875,3.59072780609131,54,3,0,0,1,0.306167602539063,33.7243423461914,1,1,3,9.99994087219238,0,9.99991083145142,,,,,,,,,,,,,,,,,,,,,,,,,,,,,,,,,
,3879767756.41281,9.99992609024048,2399.62329101562,-1.36608385540404E-5,1.85389711129856E-8,1,4,13.4005146026611,5.00678133488418,33.2800000905991,-0.0170515349275148,-0.0022805685943241,1,2.12252952771857E-7,,,,,,,,,,,,,,,,,,,,,9.99985027313232,10.0000019073486,2399.62329101562,2399.62329101562,53.3985155482941,5.63752381265958,3.58914303779602,53,1,68,0,0,0.307388305664063,33.7243423461914,1,1,3,9.99994373321533,0,9.99992609024048,,,,,,,,,,,,,,,,,,,,,,,,,,,,,,,,,
,3879767829.76516,10.0000171661377,2249.63427734375,-1.27380871338558E-5,1.31592691361911E-8,1,4,13.4005146026611,5.00674888052287,33.2800000905991,-0.015890918604764,-0.00218458566218337,1,1.51274589496303E-7,,,,,,,,,,,,,,,,,,,,,9.99986171722412,10.0001726150513,2249.63427734375,2249.63427734375,53.480977357073,5.63676093994834,3.59303951263428,54,2,0,0,1,0.299224853515625,33.7243423461914,1,1,3,9.99986171722412,0,10.0000171661377,,,,,,,,,,,,,,,,,,,,,,,,,,,,,,,,,
,3879767907.66512,10.0000534057617,2099.70825195313,-1.18442882955411E-5,1.13210814841147E-8,1,4,13.4005146026611,5.00680955869421,33.2800000905991,-0.0147709897755688,-0.00206578833760174,10,1.1299245706617E-7,,,,,,,,,,,,,,,,,,,,,10.0000486373901,10.0000581741333,2099.70825195313,2099.70825195313,53.526702625448,5.63729624739997,3.59205675125122,54,3,0,0,1,0.30548095703125,33.7243423461914,1,1,3,10.0000143051147,0,10.0000534057617,,,,,,,,,,,,,,,,,,,,,,,,,,,,,,,,,
,3879768007.43999,10.0000319480896,1899.78161621094,-1.07141484525756E-5,2.10320350550614E-8,1,4,13.4005146026611,5.00684566902944,33.2800000905991,-0.0133878789047478,-0.00169389241716228,1,2.42578812541668E-7,,,,,,,,,,,,,,,,,,,,,10.000018119812,10.0000457763672,1899.78161621094,1899.78161621094,53.5665656799287,5.63687197735636,3.59797859191895,54,1,0,0,1,0.300445556640625,34.2131004333496,1,1,3,10.0000534057617,0,10.0000319480896,,,,,,,,,,,,,,,,,,,,,,,,,,,,,,,,,
,3879768090.80305,10.0000386238098,1749.57861328125,-9.79726927774827E-6,1.50291181429397E-8,1,4,13.4005146026611,5.00685278638519,33.2800000905991,-0.0122284086513769,-0.00164123438748313,1,1.47706233384086E-7,,,,,,,,,,,,,,,,,,,,,9.99995613098145,10.0001211166382,1749.57861328125,1749.57861328125,53.4551836159384,5.63697497301045,3.59073615074158,53,2,68,0,0,0.300827026367188,34.2131004333496,1,1,3,9.99995613098145,0,10.0000386238098,,,,,,,,,,,,,,,,,,,,,,,,,,,,,,,,,
,3879768195.96573,9.99984884262085,1599.69030761719,-8.90572363812997E-6,9.25104655690864E-9,1,4,13.4005146026611,5.00694174781965,33.2800000905991,-0.0111114833026268,-0.00152149076950962,10,1.10520509093279E-7,,,,,,,,,,,,,,,,,,,,,9.99984550476074,9.99985218048096,1599.69030761719,1599.69030761719,53.4903568993037,5.63662295630144,3.59546113014221,54,3,0,0,1,0.306396484375,33.7243423461914,1,1,3,9.99984550476074,0,9.99984884262085,,,,,,,,,,,,,,,,,,,,,,,,,,,,,,,,,
,3879768298.87636,10.0000605583191,1399.73840332031,-7.76579651391127E-6,2.26430822010738E-8,1,4,13.4005146026611,5.0069308437046,33.2800000905991,-0.00971006771628536,-0.00118717955826124,1,2.08435480798287E-7,,,,,,,,,,,,,,,,,,,,,10.0000009536743,10.0001201629639,1399.73840332031,1399.73840332031,53.5696921940057,5.63691422426997,3.59060788154602,54,1,0,0,1,0.29876708984375,33.7243423461914,1,1,3,10.0001201629639,0,10.0000605583191,,,,,,,,,,,,,,,,,,,,,,,,,,,,,,,,,
,3879768402.49277,9.99988269805908,1249.71166992188,-6.8398974674802E-6,1.17005699551574E-8,1,4,13.4005146026611,5.00684765876867,33.2800000905991,-0.00854588285358539,-0.00108756366596803,10,1.49895837611696E-7,,,,,,,,,,,,,,,,,,,,,9.99985694885254,9.99990844726563,1249.71166992188,1249.71166992188,53.4997364415345,5.63726931779851,3.59953999519348,54,2,0,0,1,0.299835205078125,33.7243423461914,1,1,3,9.99990844726563,0,9.99988269805908,,,,,,,,,,,,,,,,,,,,,,,,,,,,,,,,,
,3879768515.29086,10.0001125335693,1099.92395019531,-5.95211435879148E-6,1.03385580861349E-8,1,4,13.4005146026611,5.00681122234306,33.2800000905991,-0.00743138218509396,-9.81247454272818E-4,1,1.02452567706541E-7,,,,,,,,,,,,,,,,,,,,,10.0001049041748,10.0001201629639,1099.92395019531,1099.92395019531,53.4340796459191,5.63732246977626,3.60114002227783,54,3,0,0,1,0.3009033203125,33.7243423461914,1,1,3,9.99992084503174,0,10.0001125335693,,,,,,,,,,,,,,,,,,,,,,,,,,,,,,,,,
,3879768631.32425,10.0000123977661,899.9091796875,-4.84073348422076E-6,2.53471847566675E-8,1,4,13.4005146026611,5.00664569252228,33.2800000905991,-0.00607424637643238,-5.9254329250441E-4,1,2.48306412629754E-7,,,,,,,,,,,,,,,,,,,,,9.99999141693115,10.0000333786011,899.9091796875,899.9091796875,53.5474157812076,5.63763009009117,3.59779024124146,52,1,68,0,0,0.30029296875,34.2131004333496,1,1,3,9.99999141693115,0,10.0000123977661,,,,,,,,,,,,,,,,,,,,,,,,,,,,,,,,,
,3879768741.99514,10.0000658035278,749.894958496094,-3.94394533906357E-6,1.36180581594556E-8,1,4,13.4005146026611,5.00674765275912,33.2800000905991,-0.00493608867278719,-5.69627885939498E-4,10,1.32567499948149E-7,,,,,,,,,,,,,,,,,,,,,10.0000486373901,10.0000829696655,749.894958496094,749.894958496094,53.4344704601787,5.63739633373858,3.59424328804016,54,2,0,0,1,0.300064086914063,33.7243423461914,1,1,3,10.0000829696655,0,10.0000658035278,,,,,,,,,,,,,,,,,,,,,,,,,,,,,,,,,
,3879768853.69027,10.0000548362732,600.119873046875,-3.04852449808791E-6,1.21634474413724E-8,1,4,13.4005146026611,5.00670981549184,33.2800000905991,-0.00381466197947944,-4.45059391422357E-4,1,9.86452400403336E-8,,,,,,,,,,,,,,,,,,,,,10.0000457763672,10.0000638961792,600.119873046875,600.119873046875,53.4868395709672,5.6370093179881,3.59600949287415,54,3,0,0,1,0.300979614257812,33.7243423461914,1,1,3,10.0000457763672,0,10.0000548362732,,,,,,,,,,,,,,,,,,,,,,,,,,,,,,,,,
,3879768964.59301,10.0000748634338,399.991790771484,-1.94590860296829E-6,2.3898206733107E-8,1,4,13.4005146026611,5.00680937172418,33.2800000905991,-0.00247302563681552,-2.99737950023258E-5,1,2.67026809158108E-7,,,,,,,,,,,,,,,,,,,,,10.000036239624,10.0001134872437,399.991790771484,399.991790771484,53.3852278634672,5.63783004651071,3.60235047340393,52,1,68,0,0,0.308151245117188,33.7243423461914,1,1,3,10.0001134872437,0,10.0000748634338,,,,,,,,,,,,,,,,,,,,,,,,,,,,,,,,,
,3879769075.03291,10.0000104904175,250.002731323242,-1.03780656927726E-6,1.48578531602843E-8,1,4,13.4005146026611,5.00672989653111,33.2800000905991,-0.0013207081004316,-3.92088929839835E-6,10,1.52100904422732E-7,,,,,,,,,,,,,,,,,,,,,9.99996376037598,10.000057220459,250.002731323242,250.002731323242,53.4798049142941,5.63794861703611,3.60290479660034,54,2,0,0,1,0.301361083984375,33.2355842590332,1,1,3,9.99996376037598,0,10.0000104904175,,,,,,,,,,,,,,,,,,,,,,,,,,,,,,,,,
,3879769183.4229,9.99987983703613,100.17733001709,-1.75229728286125E-7,1.1781741344449E-8,1,4,13.4005146026611,5.00668159076192,33.2800000905991,-2.3558500499147E-4,8.35087404357072E-5,1,9.32736919074676E-8,,,,,,,,,,,,,,,,,,,,,9.99982452392578,9.99993515014648,100.17733001709,100.17733001709,53.3977339197749,5.63740344472447,3.5938982963562,54,3,0,0,1,0.29998779296875,33.7243423461914,1,1,3,9.99993515014648,0,9.99987983703613,,,,,,,,,,,,,,,,,,,,,,,,,,,,,,,,,
,3879769287.92401,9.99988317489624,-99.8500366210937,8.86270160733143E-7,2.77100066796009E-8,1,4,13.4005146026611,5.00660787160034,33.2800000905991,0.00105263386409203,5.05984164675708E-4,1,2.73750571720042E-7,,,,,,,,,,,,,,,,,,,,,9.99983882904053,9.99992752075195,-99.8500366210937,-99.8500366210937,53.557186137698,5.63746718603225,3.60467195510864,53,1,68,0,0,0.30029296875,33.7243423461914,1,1,3,9.99983882904053,0,9.99988317489624,,,,,,,,,,,,,,,,,,,,,,,,,,,,,,,,,
,3879769383.43767,9.99988842010498,-249.952377319336,1.63022963595995E-6,1.26736278997426E-7,1,4,13.4005146026611,5.0066181710711,33.2800000905991,0.00203426485901884,2.75511714438001E-4,1,-2.26229704918628E-8,,,,,,,,,,,,,,,,,,,,,9.9998025894165,9.99997425079346,-249.952377319336,-249.952377319336,53.5665656799287,5.63805016310187,3.60494160652161,52,2,68,0,0,0.300369262695313,33.2355842590332,1,1,3,9.99997425079346,0,9.99988842010498,,,,,,,,,,,,,,,,,,,,,,,,,,,,,,,,,
,3879769497.8763,10.0000066757202,-399.941436767578,2.49045701879619E-6,7.41317657957546E-9,1,4,13.4005146026611,5.00653002672876,33.2800000905991,0.00308694377030777,5.59057221416349E-4,1,7.64042319398031E-8,,,,,,,,,,,,,,,,,,,,,9.99993991851807,10.0000734329224,-399.941436767578,-399.941436767578,53.399687991073,5.63721925794318,3.59857702255249,54,3,0,0,1,0.299148559570313,33.7243423461914,1,1,3,9.99993991851807,0,10.0000066757202,,,,,,,,,,,,,,,,,,,,,,,,,,,,,,,,,
,3879769618.20055,9.99988794326782,-599.654113769531,3.52122844096794E-6,1.35818947412536E-8,1,4,13.4005146026611,5.00660831850784,33.2800000905991,0.00434253223438993,9.38578661099389E-4,10,2.26972423518713E-7,,,,,,,,,,,,,,,,,,,,,9.99981880187988,9.99995708465576,-599.654113769531,-599.654113769531,53.5755544078999,5.63713013388914,3.60295534133911,54,1,0,0,1,0.30670166015625,33.2355842590332,1,1,3,9.99995708465576,0,9.99988794326782,,,,,,,,,,,,,,,,,,,,,,,,,,,,,,,,,
,3879769745.45124,9.99994707107544,-749.706115722656,4.3606791775137E-6,1.09703624332977E-8,1,4,13.4005146026611,5.00652485781546,33.2800000905991,0.00540376924328999,9.87732371241293E-4,1,1.40887184804016E-7,,,,,,,,,,,,,,,,,,,,,9.99993896484375,9.99995517730713,-749.706115722656,-749.706115722656,53.4114124188614,5.63700883941096,3.60355281829834,54,2,0,0,1,0.299758911132812,33.2355842590332,1,1,3,9.99993896484375,0,9.99994707107544,,,,,,,,,,,,,,,,,,,,,,,,,,,,,,,,,
,3879769860.03577,9.99995279312134,-899.783264160156,5.21559284194336E-6,1.27266206561315E-8,1,4,13.4005146026611,5.00657792664766,33.2800000905991,0.0064778921538927,0.00108369712952741,1,9.00508577198336E-8,,,,,,,,,,,,,,,,,,,,,9.99990844726563,9.99999713897705,-899.783264160156,-899.783264160156,53.3645147077076,5.63743966705681,3.60636401176453,54,3,0,0,1,0.306167602539063,33.2355842590332,1,1,3,9.99990844726563,0,9.99995279312134,,,,,,,,,,,,,,,,,,,,,,,,,,,,,,,,,
,3879769963.29833,10.0000190734863,-1099.59655761719,6.2698681563945E-6,3.35638170096969E-8,1,4,13.4005146026611,5.00660818736528,33.2800000905991,0.00775657813407716,0.00150875817186166,10,2.73676108313519E-7,,,,,,,,,,,,,,,,,,,,,10.0000028610229,10.0000352859497,-1099.59655761719,-1099.59655761719,53.3422382949095,5.63700381980101,3.60489201545715,54,1,0,0,1,0.299606323242188,33.2355842590332,1,1,3,10.0000457763672,0,10.0000190734863,,,,,,,,,,,,,,,,,,,,,,,,,,,,,,,,,
,3879770058.08557,9.99997520446777,-1249.58569335938,7.21724492986601E-6,1.33556469635816E-8,1,4,13.4005146026611,5.00651385113547,33.2800000905991,0.00896880087903199,0.00146635792513445,1,9.79358376215711E-8,,,,,,,,,,,,,,,,,,,,,9.99995803833008,9.99999237060547,-1249.58569335938,-1249.58569335938,53.4731610718807,5.63734377430726,3.60452103614807,54,2,0,0,1,0.300445556640625,34.2131004333496,1,1,3,9.99999237060547,0,9.99997520446777,,,,,,,,,,,,,,,,,,,,,,,,,,,,,,,,,
,3879770131.02579,9.99997711181641,-1399.65026855469,8.06829949404776E-6,8.86602545089586E-9,1,4,13.4005146026611,5.00642017480211,33.2800000905991,0.0100311578045102,0.00160565721971952,1,8.25244344419845E-8,,,,,,,,,,,,,,,,,,,,,9.99997138977051,9.99998283386231,-1399.65026855469,-1399.65026855469,53.4680804865057,5.63753802184154,3.60416436195374,53,3,68,0,0,0.300827026367188,33.2355842590332,1,1,3,9.99998283386231,0,9.99997711181641,,,,,,,,,,,,,,,,,,,,,,,,,,,,,,,,,
,3879770235.99066,10.000075340271,-1599.47619628906,9.20378612230465E-6,3.65887901959642E-8,1,4,13.4005146026611,5.00648590001885,33.2800000905991,0.0114233716866379,0.00196351427371541,1,2.00026242021996E-7,,,,,,,,,,,,,,,,,,,,,10.0000534057617,10.0000972747803,-1599.47619628906,-1599.47619628906,53.5567953234384,5.63693631938853,3.60415554046631,53,1,68,0,0,0.29998779296875,33.2355842590332,1,1,3,10.0000972747803,0,10.000075340271,,,,,,,,,,,,,,,,,,,,,,,,,,,,,,,,,
,3879770335.00842,10.0001659393311,-1749.61633300781,1.01053810410314E-5,8.14395539339528E-9,1,4,13.4005146026611,5.00653719009177,33.2800000905991,0.012568932052014,0.00197969808959119,10,7.81272968616382E-8,,,,,,,,,,,,,,,,,,,,,10.000114440918,10.0002174377441,-1749.61633300781,-1749.61633300781,53.4477581450057,5.63643867344851,3.60581278800964,54,2,0,0,1,0.299758911132812,33.2355842590332,1,1,3,10.000114440918,0,10.0001659393311,,,,,,,,,,,,,,,,,,,,,,,,,,,,,,,,,
,3879770432.63537,10.0000386238098,-1899.85717773438,1.09760939964324E-5,6.13400239611911E-9,1,4,13.4005146026611,5.00647353996855,33.2800000905991,0.0136533525212583,0.00213899013678523,1,7.58267088564408E-8,,,,,,,,,,,,,,,,,,,,,10.0000143051147,10.0000629425049,-1899.85717773438,-1899.85717773438,53.4329072031403,5.63728101092589,3.60538983345032,54,3,0,0,1,0.3076171875,33.2355842590332,1,1,3,10.0000143051147,0,10.0000386238098,,,,,,,,,,,,,,,,,,,,,,,,,,,,,,,,,
,3879770514.91056,9.99993085861206,-2099.68310546875,1.21224020762766E-5,3.26495996729977E-8,1,4,13.4005146026611,5.0063457067013,33.2800000905991,0.0150683276741268,0.00243180942981622,1,1.3957346974118E-7,,,,,,,,,,,,,,,,,,,,,9.99982643127441,10.0000352859497,-2099.68310546875,-2099.68310546875,53.3043293117268,5.63740382869651,3.59586644172668,52,1,68,0,0,0.301055908203125,33.2355842590332,1,1,3,10.0000352859497,0,9.99993085861206,,,,,,,,,,,,,,,,,,,,,,,,,,,,,,,,,
,3879770587.0317,9.99997472763062,-2249.64697265625,1.30278863752632E-5,3.78773384592647E-8,1,4,13.4005146026611,5.00642182599616,33.2800000905991,0.0162077840555668,0.00252271968271351,1,7.7086448941531E-8,,,,,,,,,,,,,,,,,,,,,9.99994945526123,10,-2249.64697265625,-2249.64697265625,53.3949982199576,5.63711836986082,3.60690355300903,54,2,0,0,1,0.298843383789063,33.7243423461914,1,1,3,9.99994945526123,0,9.99997472763062,,,,,,,,,,,,,,,,,,,,,,,,,,,,,,,,,
,3879770658.69031,10.0000290870667,-2399.76196289062,1.39053184488005E-5,1.93451680810734E-8,1,4,13.4005146026611,5.00643229648602,33.2800000905991,0.0173055529462937,0.0026517282838461,1,4.94276664270132E-8,,,,,,,,,,,,,,,,,,,,,9.99994850158691,10.0001096725464,-2399.76196289062,-2399.76196289062,53.3891360060633,5.63738792201639,3.60527420043945,54,3,0,0,1,0.30548095703125,33.2355842590332,1,1,3,9.99994850158691,0,10.0000290870667,,,,,,,,,,,,,,,,,,,,,,,,,,,,,,,,,
,3879770741.09441,10.0000290870667,-2599.57543945313,1.5060607096386E-5,7.85356885229777E-9,1,4,13.4005146026611,5.00642371927345,33.2800000905991,0.0187339811140406,0.00293430606507853,1,1.03544762682789E-7,,,,,,,,,,,,,,,,,,,,,9.99997043609619,10.0000877380371,-2599.57543945313,-2599.57543945313,53.5454617099095,5.63750454293078,3.6054265499115,54,1,0,0,1,0.301361083984375,33.2355842590332,1,1,3,10.0000877380371,0,10.0000290870667,,,,,,,,,,,,,,,,,,,,,,,,,,,,,,,,,
,3879770812.52206,10.0000576972961,-2749.50146484375,1.59549651997155E-5,9.40004193412126E-9,1,4,13.4005146026611,5.00648895276364,33.2800000905991,0.0198519897591828,0.00307418950460887,1,8.20486474202822E-8,,,,,,,,,,,,,,,,,,,,,10.0000114440918,10.0001039505005,-2749.50146484375,-2749.50146484375,53.4332980173999,5.63740137517835,3.60635232925415,52,2,68,0,0,0.30731201171875,33.2355842590332,1,1,3,10.0000114440918,0,10.0000576972961,,,,,,,,,,,,,,,,,,,,,,,,,,,,,,,,,
,3879770884.70484,9.99993181228638,-2899.74243164063,1.68492907767386E-5,8.91497558384443E-9,1,4,13.4005146026611,5.0063270365936,33.2800000905991,0.0209682294889937,0.00321680247303965,1,6.29091647599391E-8,,,,,,,,,,,,,,,,,,,,,9.99991416931152,9.99994945526123,-2899.74243164063,-2899.74243164063,53.4528387303807,5.63729468090571,3.60061097145081,54,3,0,0,1,0.300827026367188,33.2355842590332,1,1,3,9.99991416931152,0,9.99993181228638,,,,,,,,,,,,,,,,,,,,,,,,,,,,,,,,,
,3879770987.88112,9.99992227554321,-3499.78662109375,2.04186815101954E-5,1.24143485484444E-8,1,4,13.4005146026611,5.0065318842058,33.2800000905991,0.0254299904356399,0.00377580421923813,1,-2.22810111732629E-8,,,,,,,,,,,,,,,,,,,,,9.99984264373779,10.0000019073486,-3499.78662109375,-3499.78662109375,53.3985155482941,5.63776791319961,3.59716987609863,54,1,0,0,1,0.301895141601562,33.2355842590332,1,1,3,10.0000019073486,0,9.99992227554321,,,,,,,,,,,,,,,,,,,,,,,,,,,,,,,,,
,3879771071.58932,10.0000557899475,-4999.58935546875,2.92475064748252E-5,1.03037060049405E-8,1,4,13.4005146026611,5.0063400123302,33.2800000905991,0.0364246714865064,0.0054016480202351,1,-3.71230888782053E-8,,,,,,,,,,,,,,,,,,,,,10.0000343322754,10.0000772476196,-4999.58935546875,-4999.58935546875,53.4247001036883,5.63741026163194,3.59919404983521,54,2,0,0,1,0.300369262695313,33.2355842590332,1,1,3,10.0000772476196,0,10.0000557899475,,,,,,,,,,,,,,,,,,,,,,,,,,,,,,,,,
,3879771155.68208,10.0000948905945,-6499.6181640625,3.81211027342239E-5,1.27278121199542E-8,1,4,13.4005146026611,5.00624843644454,33.2800000905991,0.0474729871771362,0.00705096826334881,1,-3.98261373739939E-8,,,,,,,,,,,,,,,,,,,,,10.0000600814819,10.000129699707,-6499.6181640625,-6499.6181640625,53.3906992631018,5.63829242495653,3.60654640197754,53,3,68,0,0,0.309219360351562,33.2355842590332,1,1,3,10.000129699707,0,10.0000948905945,,,,,,,,,,,,,,,,,,,,,,,,,,,,,,,,,
,3879771254.13478,10.000102519989,-8499.65234375,4.99890762788033E-5,1.71224991114509E-8,1,4,13.4005146026611,5.00633233632447,33.2800000905991,0.0622579516289631,0.00921906499145784,1,-7.410818515512E-8,,,,,,,,,,,,,,,,,,,,,9.99999523162842,10.0002098083496,-8499.65234375,-8499.65234375,53.4418959311114,5.6371313785269,3.60329055786133,54,1,0,0,1,0.300445556640625,33.2355842590332,1,1,3,10.0002098083496,0,10.000102519989,,,,,,,,,,,,,,,,,,,,,,,,,,,,,,,,,
,3879771337.90942,9.99994993209839,-9999.6318359375,5.88785204962324E-5,2.0148110372904E-8,1,4,13.4005146026611,5.00620740113552,33.2800000905991,0.0733214669599133,0.0108922953632946,1,-5.9816215760856E-8,,,,,,,,,,,,,,,,,,,,,9.99987411499023,10.0000257492065,-9999.6318359375,-9999.6318359375,53.4704253720634,5.63703465077602,3.59693765640259,54,2,0,0,1,0.29998779296875,33.2355842590332,1,1,3,10.0000257492065,0,9.99994993209839,,,,,,,,,,,,,,,,,,,,,,,,,,,,,,,,,
,3879771527.70887,10.0000681877136,-19999.767578125,1.18340156724705E-4,2.42340358081994E-8,1,4,13.4005146026611,5.00636977206996,33.2800000905991,0.147363245932812,0.0219771859830884,1,-5.29822060264613E-8,,,,,,,,,,,,,,,,,,,,,10.0000400543213,10.000096321106,-19999.767578125,-19999.767578125,53.4356429029576,5.63758296723122,3.5962336063385,54,3,0,0,1,0.302810668945313,33.2355842590332,1,1,3,10.000096321106,0,10.0000681877136,,,,,,,,,,,,,,,,,,,,,,,,,,,,,,,,,
,3879771811.20705,10.0000514984131,-39999.72265625,2.38297555470029E-4,4.10775693405903E-8,1,4,13.4005146026611,5.00635945994761,33.2800000905991,0.296729653599129,0.044320474776685,1,-5.37725471909182E-8,,,,,,,,,,,,,,,,,,,,,10.0000276565552,10.000075340271,-39999.72265625,-39999.72265625,53.6607519164961,5.63877602038556,3.59508442878723,54,1,0,0,1,0.30181884765625,33.2355842590332,1,1,3,10.0000276565552,0,10.0000514984131,,,,,,,,,,,,,,,,,,,,,,,,,,,,,,,,,
,3879772034.72605,9.99990463256836,-54999.609375,3.29195817015661E-4,7.81862954712837E-8,1,4,13.4005146026611,5.00635320419466,33.2800000905991,0.409915232002592,0.0612317455823372,1,-6.99503669426866E-8,,,,,,,,,,,,,,,,,,,,,9.99987506866455,9.99993419647217,-54999.609375,-54999.609375,53.8272387910922,5.63977256464439,3.60012459754944,54,2,0,0,1,0.308151245117188,33.2355842590332,1,1,3,9.99993419647217,0,9.99990463256836,,,,,,,,,,,,,,,,,,,,,,,,,,,,,,,,,
,3879772268.22817,10.0000252723694,-69999.828125,4.20728761734083E-4,2.29177867371007E-7,1,4,13.4005146026611,5.00628769545379,33.2800000905991,0.523868110536887,0.0783529180959238,1,-1.14100570006937E-8,,,,,,,,,,,,,,,,,,,,,9.99983406066895,10.0002164840698,-69999.828125,-69999.828125,54.0316346488711,5.64084328971823,3.60127997398376,54,3,0,0,1,0.308456420898438,33.2355842590332,1,1,3,10.0002164840698,0,10.0000252723694,,,,,,,,,,,,,,,,,,,,,,,,,,,,,,,,,
,3879772552.79078,10.0001087188721,-49999.62890625,2.98645304218704E-4,7.77984970771829E-8,1,4,13.4005146026611,5.00645861823189,33.2800000905991,0.371895101724955,0.0554808297833222,1,-1.19701058146758E-7,,,,,,,,,,,,,,,,,,,,,10.0000638961792,10.0001535415649,-49999.62890625,-49999.62890625,53.7310984832268,5.6380508377127,3.59626770019531,52,1,68,0,0,0.299148559570313,33.7243423461914,1,1,3,10.0000085830688,0,10.0001087188721,,,,,,,,,,,,,,,,,,,,,,,,,,,,,,,,,
,3879772775.03966,9.99994230270386,-34999.515625,2.07984295297386E-4,3.97682839873238E-8,1,4,13.4005146026611,5.00635994236397,33.2800000905991,0.258989341977674,0.0386430006539912,1,-7.87177043609802E-8,,,,,,,,,,,,,,,,,,,,,9.99989032745361,9.9999942779541,-34999.515625,-34999.515625,53.6884997289287,5.63744326950921,3.60526490211487,54,2,0,0,1,0.302276611328125,34.2131004333496,1,1,3,9.99989032745361,0,9.99994230270386,,,,,,,,,,,,,,,,,,,,,,,,,,,,,,,,,
,3879772996.51322,10.0001764297485,-19999.6796875,1.18147051254785E-4,3.12539594536084E-8,1,4,13.4005146026611,5.00634620604231,33.2800000905991,0.147122657010879,0.0219355364018241,1,-5.74278428216551E-8,,,,,,,,,,,,,,,,,,,,,10.0000782012939,10.0002746582031,-19999.6796875,-19999.6796875,53.5614850945537,5.63712839183664,3.59906029701233,54,3,0,0,1,0.298995971679687,34.2131004333496,1,1,3,10.0000782012939,0,10.0001764297485,,,,,,,,,,,,,,,,,,,,,,,,,,,,,,,,,
,3879773199.83808,10.0001411437988,-9500.4189453125,5.56229106200729E-5,1.6531037569882E-8,1,4,13.4005146026611,5.00644134748677,33.2800000905991,0.0692615637470616,0.0103589803875464,1,-1.66764377440709E-9,,,,,,,,,,,,,,,,,,,,,10.0000095367432,10.0002727508545,-9500.4189453125,-9500.4189453125,53.4532295446403,5.63593721475871,3.6041407585144,54,1,0,0,1,0.299758911132812,34.2131004333496,1,1,3,10.0002384185791,0,10.0001411437988,,,,,,,,,,,,,,,,,,,,,,,,,,,,,,,,,
,3879773284.17397,9.99998188018799,-8000.32666015625,4.67284554510827E-5,1.14442334672765E-8,1,4,13.4005146026611,5.00643257570162,33.2800000905991,0.0581862364059463,0.00870130773447778,1,-2.35252732228565E-9,,,,,,,,,,,,,,,,,,,,,9.99996471405029,9.99999904632568,-8000.32666015625,-8000.32666015625,53.3887451918037,5.63719807789222,3.5980372428894,54,2,0,0,1,0.300979614257812,33.7243423461914,1,1,3,9.99999904632568,0,9.99998188018799,,,,,,,,,,,,,,,,,,,,,,,,,,,,,,,,,
,3879773369.33176,9.99988794326782,-6500.49951171875,3.78347889768969E-5,1.27651659936135E-8,1,4,13.4005146026611,5.00636020387892,33.2800000905991,0.0471145034538673,0.00702097143633263,1,-2.12627692579464E-8,,,,,,,,,,,,,,,,,,,,,9.99985694885254,9.99991893768311,-6500.49951171875,-6500.49951171875,53.5052078411691,5.63880671129593,3.59781074523926,54,3,0,0,1,0.3082275390625,33.2355842590332,1,1,3,9.99991893768311,0,9.99988794326782,,,,,,,,,,,,,,,,,,,,,,,,,,,,,,,,,
,3879773468.74001,10.0000290870667,-4500.46484375,2.59635044591256E-5,8.94337737090639E-9,1,4,13.4005146026611,5.00629028123649,33.2800000905991,0.0323205954423404,0.00488698486041774,1,4.08661756002042E-8,,,,,,,,,,,,,,,,,,,,,10.0000066757202,10.0000514984131,-4500.46484375,-4500.46484375,53.5079435409864,5.63881066372093,3.60347557067871,54,1,0,0,1,0.301361083984375,33.7243423461914,1,1,3,10.0000066757202,0,10.0000290870667,,,,,,,,,,,,,,,,,,,,,,,,,,,,,,,,,
,3879773552.7415,10.0000414848328,-3000.49877929687,1.70842677699562E-5,6.74196973757687E-9,1,4,13.4005146026611,5.00626407919286,33.2800000905991,0.0212702076053193,0.00319520624212777,1,1.0458935881677E-8,,,,,,,,,,,,,,,,,,,,,10.0000171661377,10.0000658035278,-3000.49877929687,-3000.49877929687,53.5435076386114,5.63899484813276,3.60113930702209,54,2,0,0,1,0.301284790039063,33.7243423461914,1,1,3,10.0000171661377,0,10.0000414848328,,,,,,,,,,,,,,,,,,,,,,,,,,,,,,,,,
,3879773639.26989,10.000030040741,-2900.3212890625,1.65699643762601E-5,1.04345396329044E-8,1,4,13.4005146026611,5.00623606464292,33.2800000905991,0.0206541885190647,0.00293549170555826,1,-1.21170061967831E-7,,,,,,,,,,,,,,,,,,,,,9.99992656707764,10.0001335144043,-2900.3212890625,-2900.3212890625,53.4102399760826,5.63891340076321,3.6036422252655,54,3,0,0,1,0.299224853515625,34.2131004333496,1,1,3,10.0001335144043,0,10.000030040741,,,,,,,,,,,,,,,,,,,,,,,,,,,,,,,,,
,3879773722.28701,9.99990367889404,-2700.34448242187,1.54458332857897E-5,2.20141059510469E-8,1,4,13.4005146026611,5.00622648568251,33.2800000905991,0.0192708863670784,0.00261627582548274,1,-2.09374627899003E-7,,,,,,,,,,,,,,,,,,,,,9.99990081787109,9.99990653991699,-2700.34448242187,-2700.34448242187,53.4094583475633,5.63913604067216,3.60142016410828,52,1,68,0,0,0.308609008789063,34.2131004333496,1,1,3,9.99990653991699,0,9.99990367889404,,,,,,,,,,,,,,,,,,,,,,,,,,,,,,,,,
,3879773795.53877,9.99997472763062,-2550.2294921875,1.45003612425982E-5,1.39090524375181E-8,1,4,13.4005146026611,5.00625487773174,33.2800000905991,0.0180822856098194,0.00251719682519176,1,-1.47527836061623E-7,,,,,,,,,,,,,,,,,,,,,9.99982261657715,10.0001268386841,-2550.2294921875,-2550.2294921875,53.4293898748037,5.63942784644503,3.59820628166199,54,2,0,0,1,0.301589965820313,33.7243423461914,1,1,3,9.99982261657715,0,9.99997472763062,,,,,,,,,,,,,,,,,,,,,,,,,,,,,,,,,
,3879773867.02618,9.99988555908203,-2400.39135742187,1.36046805541362E-5,1.05585996199451E-8,1,4,13.4005146026611,5.00623033158515,33.2800000905991,0.0169613547114848,0.00238763194810606,1,-1.17583847161186E-7,,,,,,,,,,,,,,,,,,,,,9.99985694885254,9.99991416931152,-2400.39135742187,-2400.39135742187,53.4391602312941,5.63919304553996,3.59932470321655,54,3,0,0,1,0.300979614257812,34.2131004333496,1,1,3,9.99991416931152,0,9.99988555908203,,,,,,,,,,,,,,,,,,,,,,,,,,,,,,,,,
,3879773951.31575,9.99999809265137,-2200.18774414062,1.24672287696868E-5,1.49904721810658E-8,1,4,13.4005146026611,5.00615319677654,33.2800000905991,0.0155605513336868,0.0020701354458129,1,-2.02385040121144E-7,,,,,,,,,,,,,,,,,,,,,9.99991035461426,10.0000858306885,-2200.18774414062,-2200.18774414062,53.4559652444576,5.63947181233731,3.6027135848999,54,1,0,0,1,0.300979614257812,33.7243423461914,1,1,3,9.99991035461426,0,9.99999809265137,,,,,,,,,,,,,,,,,,,,,,,,,,,,,,,,,
,3879774022.7206,10.0000157356262,-2050.17358398438,1.15500960477001E-5,1.28946987333094E-8,1,4,13.4005146026611,5.00625876135816,33.2800000905991,0.0144097020297412,0.00196193173075496,1,-1.52138233017472E-7,,,,,,,,,,,,,,,,,,,,,9.99990940093994,10.0001220703125,-2050.17358398438,-2050.17358398438,53.3410658521306,5.63843396396442,3.598956823349,53,2,68,0,0,0.30731201171875,33.7243423461914,1,1,3,10.0001220703125,0,10.0000157356262,,,,,,,,,,,,,,,,,,,,,,,,,,,,,,,,,
,3879774093.23587,10.0001635551453,-1900.38586425781,1.06662640699755E-5,1.21622911475937E-8,1,4,13.4005146026611,5.00629659319167,33.2800000905991,0.0133020989840965,0.00184584618007422,1,-1.13169790822953E-7,,,,,,,,,,,,,,,,,,,,,10.000129699707,10.0001974105835,-1900.38586425781,-1900.38586425781,53.3500545801018,5.63898689632723,3.60057234764099,54,3,0,0,1,0.30029296875,33.7243423461914,1,1,3,10.0001974105835,0,10.0001635551453,,,,,,,,,,,,,,,,,,,,,,,,,,,,,,,,,
,3879774174.01371,10.0000534057617,-1700.23266601562,9.51788767424585E-6,2.06614257164411E-8,1,4,13.4005146026611,5.00625728337213,33.2800000905991,0.0118930964421299,0.00149141058182219,1,-2.26021237556558E-7,,,,,,,,,,,,,,,,,,,,,9.9998950958252,10.0002117156982,-1700.23266601562,-1700.23266601562,53.5360821676787,5.63904022921995,3.60166144371033,54,1,0,0,1,0.301132202148438,33.7243423461914,1,1,3,10.0001792907715,0,10.0000534057617,,,,,,,,,,,,,,,,,,,,,,,,,,,,,,,,,
,3879774246.68339,10.0000195503235,-1550.24365234375,8.61007627740503E-6,1.58920647256234E-8,1,4,13.4005146026611,5.00621798199382,33.2800000905991,0.0107502977909438,0.00140478264725216,1,-1.59779327387236E-7,,,,,,,,,,,,,,,,,,,,,9.99995803833008,10.0000810623169,-1550.24365234375,-1550.24365234375,53.5016905128326,5.63926115523948,3.60853695869446,54,2,0,0,1,0.30242919921875,33.7243423461914,1,1,3,10.0000810623169,0,10.0000195503235,,,,,,,,,,,,,,,,,,,,,,,,,,,,,,,,,
,3879774330.4607,10.0001158714294,-1400.12866210938,7.70162947228754E-6,1.01801616000033E-8,1,4,13.4005146026611,5.00609466844244,33.2800000905991,0.00960530719918718,0.00132603218965129,1,-8.70921271464319E-8,,,,,,,,,,,,,,,,,,,,,10.0001106262207,10.0001211166382,-1400.12866210938,-1400.12866210938,53.4442408166691,5.63963015997462,3.60341238975525,54,3,0,0,1,0.30029296875,33.7243423461914,1,1,3,10.0001020431519,0,10.0001158714294,,,,,,,,,,,,,,,,,,,,,,,,,,,,,,,,,
,3879774421.6057,9.99997663497925,-1200.2900390625,6.61703027368486E-6,2.41693378783314E-8,1,4,13.4005146026611,5.00613198016523,33.2800000905991,0.00828878116833587,8.98137325297033E-4,1,-2.68520968429113E-7,,,,,,,,,,,,,,,,,,,,,9.99996662139893,9.99998664855957,-1200.2900390625,-1200.2900390625,53.526702625448,5.63984505305413,3.60057616233826,54,1,0,0,1,0.299530029296875,34.2131004333496,1,1,3,9.99996662139893,0,9.99997663497925,,,,,,,,,,,,,,,,,,,,,,,,,,,,,,,,,
,3879774506.73778,10.0000638961792,-1050.30102539062,5.6793992807474E-6,1.69284672172489E-8,1,4,13.4005146026611,5.00606189672513,33.2800000905991,0.00709778687417768,8.80068869931162E-4,1,-1.427551316343E-7,,,,,,,,,,,,,,,,,,,,,9.99993419647217,10.0001935958862,-1050.30102539062,-1050.30102539062,53.4774600287364,5.63960824512781,3.60742974281311,53,2,68,0,0,0.302200317382812,33.7243423461914,1,1,3,10.0001935958862,0,10.0000638961792,,,,,,,,,,,,,,,,,,,,,,,,,,,,,,,,,
,3879774604.0029,10.000120639801,-900.123168945313,4.8108123492891E-6,1.39040706384568E-8,1,4,13.4005146026611,5.0061151493407,33.2800000905991,0.00601389464649382,7.35268478407381E-4,1,-1.29128501324033E-7,,,,,,,,,,,,,,,,,,,,,10.0000114440918,10.0002298355103,-900.123168945313,-900.123168945313,53.4344704601787,5.63961592398636,3.60080075263977,52,3,68,0,0,0.3021240234375,33.7243423461914,1,1,3,10.0000114440918,0,10.000120639801,,,,,,,,,,,,,,,,,,,,,,,,,,,,,,,,,
,3879774685.54566,9.9999361038208,-700.259460449219,3.69666557016293E-6,4.86675566755673E-8,1,4,13.4005146026611,5.00611313231235,33.2800000905991,0.00464575230721547,4.00329447419092E-4,1,-2.31468987620799E-7,,,,,,,,,,,,,,,,,,,,,9.99982738494873,10.0000448226929,-700.259460449219,-700.259460449219,53.498173184496,5.63899336806327,3.60894846916199,54,1,0,0,1,0.2996826171875,33.2355842590332,1,1,3,10.0000448226929,0,9.9999361038208,,,,,,,,,,,,,,,,,,,,,,,,,,,,,,,,,
,3879774770.94325,10.0000567436218,-550.270385742188,2.78443214739322E-6,1.71614817400837E-8,1,4,13.4005146026611,5.00609261360279,33.2800000905991,0.00349884030699581,3.04549295163801E-4,1,-1.71930066300743E-7,,,,,,,,,,,,,,,,,,,,,10.0000305175781,10.0000829696655,-550.270385742188,-550.270385742188,53.4125848616403,5.63889213664429,3.6095404624939,52,2,68,0,0,0.301589965820313,33.2355842590332,1,1,3,10.0000305175781,0,10.0000567436218,,,,,,,,,,,,,,,,,,,,,,,,,,,,,,,,,
,3879774841.92295,10.0000519752502,-400.218383789063,1.89563942390727E-6,1.55485894510704E-8,1,4,13.4005146026611,5.00631689035224,33.2800000905991,0.00238327483179403,1.99878801001824E-4,1,-1.23050053088381E-7,,,,,,,,,,,,,,,,,,,,,10.0000133514404,10.0000905990601,-400.218383789063,-400.218383789063,53.4583101300153,5.63867366175694,3.60419034957886,54,3,0,0,1,0.30181884765625,33.2355842590332,1,1,3,10.0000905990601,0,10.0000519752502,,,,,,,,,,,,,,,,,,,,,,,,,,,,,,,,,
,3879774925.07883,10.0001044273376,-200.304306030273,8.43124050334121E-7,2.85545928154886E-8,1,4,13.4005146026611,5.006290788771,33.2800000905991,0.00109936479199152,-1.74231243143598E-4,1,-2.66055143494911E-7,,,,,,,,,,,,,,,,,,,,,9.99998760223389,10.0002212524414,-200.304306030273,-200.304306030273,53.5411627530537,5.63853624196147,3.60539245605469,54,1,0,0,1,0.300827026367188,33.2355842590332,1,1,3,10.0002212524414,0,10.0001044273376,,,,,,,,,,,,,,,,,,,,,,,,,,,,,,,,,
,3879775010.49865,10.0000052452087,-50.3907814025879,-5.49058160814585E-8,1.87130570869078E-8,1,4,13.4005146026611,5.00640050825703,33.2800000905991,-3.67610207981859E-5,-2.21509669097654E-4,1,-1.69680307999341E-7,,,,,,,,,,,,,,,,,,,,,9.99995517730713,10.0000553131104,-50.3907814025879,-50.3907814025879,53.493092599121,5.63825769653445,3.60554504394531,52,2,68,0,0,0.301437377929687,33.2355842590332,1,1,3,9.99995517730713,0,10.0000052452087,,,,,,,,,,,,,,,,,,,,,,,,,,,,,,,,,
,3879775080.84343,9.99990797042847,99.8122787475586,-9.29533300694019E-7,1.1330024999259E-8,1,4,13.4005146026611,5.0064160872608,33.2800000905991,-0.00114124818917597,-2.81385043792386E-4,1,-8.69262081853775E-8,,,,,,,,,,,,,,,,,,,,,9.99988651275635,9.99992942810059,99.8122787475586,99.8122787475586,53.4481489592653,5.63784184250029,3.60132670402527,52,3,68,0,0,0.300216674804687,33.2355842590332,1,1,3,9.99988651275635,0,9.99990797042847,,,,,,,,,,,,,,,,,,,,,,,,,,,,,,,,,
,3879775163.04131,10.0000867843628,299.713775634766,-1.90492683028899E-6,1.64109514067226E-8,1,4,13.4005146026611,5.00645514785594,33.2800000905991,-0.00233636449912583,-5.93123353406554E-4,1,-1.91363341056778E-7,,,,,,,,,,,,,,,,,,,,,10.000036239624,10.0001373291016,299.713775634766,299.713775634766,53.4680804865057,5.63787071412972,3.6071994304657,54,1,0,0,1,0.299530029296875,33.2355842590332,1,1,3,10.0001373291016,0,10.0000867843628,,,,,,,,,,,,,,,,,,,,,,,,,,,,,,,,,
,3879775234.63227,10.0000696182251,449.828704833984,-2.72833742414036E-6,1.1210341665993E-8,1,4,13.4005146026611,5.00635928268927,33.2800000905991,-0.00337025114227569,-6.88541940975755E-4,1,-1.44830258747942E-7,,,,,,,,,,,,,,,,,,,,,10.0000629425049,10.0000762939453,449.828704833984,449.828704833984,53.3821013493903,5.63831113068895,3.60559344291687,53,2,68,0,0,0.30242919921875,33.2355842590332,1,1,3,10.0000629425049,0,10.0000696182251,,,,,,,,,,,,,,,,,,,,,,,,,,,,,,,,,
,3879775306.44445,10.0000419616699,599.817810058594,-3.56400505262192E-6,1.36979260828775E-8,1,4,13.4005146026611,5.00646450063404,33.2800000905991,-0.00442037747499583,-7.81033348426694E-4,1,-9.4081578259285E-8,,,,,,,,,,,,,,,,,,,,,10.0000066757202,10.0000772476196,599.817810058594,599.817810058594,53.4446316309287,5.63789956120407,3.60371422767639,54,3,0,0,1,0.300064086914063,33.2355842590332,1,1,3,10.0000066757202,0,10.0000419616699,,,,,,,,,,,,,,,,,,,,,,,,,,,,,,,,,
,3879775388.87043,10.0000996589661,799.706665039063,-4.58937016012456E-6,2.16975810926565E-8,1,4,13.4005146026611,5.00649759392696,33.2800000905991,-0.00567391363682605,-0.00112781064710926,1,-2.19175936256483E-7,,,,,,,,,,,,,,,,,,,,,10.0000200271606,10.0001792907715,799.706665039063,799.706665039063,53.4817589855922,5.63806986439449,3.60365080833435,52,1,68,0,0,0.301589965820313,33.2355842590332,1,1,3,10.0000200271606,0,10.0000996589661,,,,,,,,,,,,,,,,,,,,,,,,,,,,,,,,,
,3879775460.566,10.000138759613,949.771240234375,-5.47596230295806E-6,1.6330195340617E-8,1,4,13.4005146026611,5.00642597477907,33.2800000905991,-0.00678977405898254,-0.00121271582732187,1,-1.54751986566545E-7,,,,,,,,,,,,,,,,,,,,,10.000057220459,10.0002202987671,949.771240234375,949.771240234375,53.4934834133807,5.63821041571656,3.60664105415344,53,2,68,0,0,0.30059814453125,33.2355842590332,1,1,3,10.0002202987671,0,10.000138759613,,,,,,,,,,,,,,,,,,,,,,,,,,,,,,,,,
,3879775532.31562,9.99994802474976,1099.79797363281,-6.29093505125143E-6,7.673829064902E-8,1,4,13.4005146026611,5.00647092452563,33.2800000905991,-0.00783284974029747,-0.00117613778106328,1,-3.44969422148524E-9,,,,,,,,,,,,,,,,,,,,,9.99993324279785,9.99996280670166,1099.79797363281,1099.79797363281,53.4383786027749,5.63869976655259,3.60417914390564,54,3,0,0,1,0.299301147460937,33.7243423461914,1,1,3,9.99993324279785,0,9.99994802474976,,,,,,,,,,,,,,,,,,,,,,,,,,,,,,,,,
,3879775614.32585,10.0000014305115,1299.68701171875,-7.45746078387242E-6,1.41317912409385E-8,1,4,13.4005146026611,5.00646945944972,33.2800000905991,-0.00925539034821429,-0.00159408909852219,1,-1.64594244921393E-7,,,,,,,,,,,,,,,,,,,,,9.99994564056397,10.000057220459,1299.68701171875,1299.68701171875,53.4751151431787,5.63797449950055,3.60106229782105,53,1,68,0,0,0.300979614257812,33.7243423461914,1,1,3,9.99994564056397,0,10.0000014305115,,,,,,,,,,,,,,,,,,,,,,,,,,,,,,,,,
,3879775696.63509,10.0000357627869,1449.71374511719,-8.35147834371434E-6,8.56084919585705E-9,1,4,13.4005146026611,5.00648994916746,33.2800000905991,-0.0103766145819876,-0.00170760939513457,1,-1.22012997421468E-7,,,,,,,,,,,,,,,,,,,,,10.0000190734863,10.0000524520874,1449.71374511719,1449.71374511719,53.4043777621883,5.63796128960168,3.61128163337708,54,2,0,0,1,0.30120849609375,33.7243423461914,1,1,3,10.0000524520874,0,10.0000357627869,,,,,,,,,,,,,,,,,,,,,,,,,,,,,,,,,
,3879775768.53845,9.99994277954102,1599.57690429687,-9.21716091916085E-6,2.26238195176369E-8,1,4,13.4005146026611,5.00648323736325,33.2800000905991,-0.0114633881725928,-0.0018097773023765,1,-7.45636895048952E-8,,,,,,,,,,,,,,,,,,,,,9.99987983703613,10.0000057220459,1599.57690429687,1599.57690429687,53.4055502049672,5.63823859721945,3.61133217811584,54,3,0,0,1,0.300064086914063,33.7243423461914,1,1,3,9.99987983703613,0,9.99994277954102,,,,,,,,,,,,,,,,,,,,,,,,,,,,,,,,,
,3879775850.73693,10.0000004768372,1799.61694335938,-1.03718215923202E-5,1.53574850972584E-8,1,4,13.4005146026611,5.00653395395439,33.2800000905991,-0.012896503594068,-0.00205737466277351,1,-1.00650411506644E-7,,,,,,,,,,,,,,,,,,,,,9.99996089935303,10.0000400543213,1799.61694335938,1799.61694335938,53.4567468729768,5.63806340004535,3.60334348678589,54,1,0,0,1,0.29998779296875,33.2355842590332,1,1,3,9.99996852874756,0,10.0000004768372,,,,,,,,,,,,,,,,,,,,,,,,,,,,,,,,,
,3879775922.35488,9.99995088577271,1949.93322753906,-1.1271672568545E-5,1.5919989787714E-8,1,4,13.4005146026611,5.00657672610442,33.2800000905991,-0.0140189899825739,-0.00221297808470519,1,-9.0977095853697E-8,,,,,,,,,,,,,,,,,,,,,9.99990844726563,9.99999332427978,1949.93322753906,1949.93322753906,53.3953890342172,5.63802261672448,3.60648727416992,54,2,0,0,1,0.3070068359375,33.7243423461914,1,1,3,9.9999942779541,0,9.99995088577271,,,,,,,,,,,,,,,,,,,,,,,,,,,,,,,,,
,3879775994.09981,9.9999566078186,2099.82153320313,-1.21687609382287E-5,2.79363730713242E-8,1,4,13.4005146026611,5.00648651477173,33.2800000905991,-0.0151386188735192,-0.00236050914355972,1,-7.53019614641332E-8,,,,,,,,,,,,,,,,,,,,,9.99993705749512,9.99997615814209,2099.82153320313,2099.82153320313,53.4637815296499,5.63834079634298,3.60189270973206,54,3,0,0,1,0.30059814453125,33.7243423461914,1,1,3,9.99993705749512,0,9.9999566078186,,,,,,,,,,,,,,,,,,,,,,,,,,,,,,,,,
,3879776076.85274,9.99995470046997,2299.94970703125,-1.32439034825277E-5,5.89133127826703E-8,1,4,13.4005146026611,5.00644311896758,33.2800000905991,-0.0164733812885599,-0.0025862508892762,1,-9.57807242943833E-8,,,,,,,,,,,,,,,,,,,,,9.99990844726563,10.0000009536743,2299.94970703125,2299.94970703125,53.3484913230633,5.63830928670274,3.60758638381958,54,1,0,0,1,0.299758911132812,33.2355842590332,1,1,3,9.99990844726563,0,9.99995470046997,,,,,,,,,,,,,,,,,,,,,,,,,,,,,,,,,
,3879776148.83248,9.9999995231628,2449.837890625,-1.41843631983976E-5,7.27863048556831E-9,1,4,13.4005146026611,5.00639591833364,33.2800000905991,-0.0176462462012728,-0.00274773900127522,1,-8.48119990095082E-8,,,,,,,,,,,,,,,,,,,,,9.99991798400879,10.0000810623169,2449.837890625,2449.837890625,53.4512754733422,5.63822552479723,3.60642123222351,54,2,0,0,1,0.301361083984375,33.2355842590332,1,1,3,9.99991798400879,0,9.9999995231628,,,,,,,,,,,,,,,,,,,,,,,,,,,,,,,,,
,3879776221.06788,10.0000066757202,2599.75170898438,-1.50770449515569E-5,7.44060265451409E-9,1,4,13.4005146026611,5.00641258435028,33.2800000905991,-0.0187623354418144,-0.00288425207423164,1,-6.08949850305694E-8,,,,,,,,,,,,,,,,,,,,,9.9999303817749,10.0000829696655,2599.75170898438,2599.75170898438,53.475896771698,5.63854668307471,3.6129846572876,54,3,0,0,1,0.300750732421875,33.7243423461914,1,1,3,10.0000829696655,0,10.0000066757202,,,,,,,,,,,,,,,,,,,,,,,,,,,,,,,,,
,3879776302.89871,10.0001111030579,2799.8544921875,-1.62439753166077E-5,1.15302402793957E-8,1,4,13.4005146026611,5.00645298578326,33.2800000905991,-0.0202077624103637,-0.00315408073615632,1,-1.0299882552227E-7,,,,,,,,,,,,,,,,,,,,,10.0000200271606,10.0002021789551,2799.8544921875,2799.8544921875,53.3977339197749,5.63795335493357,3.60646867752075,54,1,0,0,1,0.300216674804687,33.2355842590332,1,1,3,10.0002021789551,0,10.0001111030579,,,,,,,,,,,,,,,,,,,,,,,,,,,,,,,,,
,3879776374.58497,10.0005450248718,2949.78051757812,-1.71210317452088E-5,8.93248089206397E-9,1,4,13.4005146026611,5.00642214401647,33.2800000905991,-0.0213053186689345,-0.00327977799827246,1,-7.27649591492765E-8,,,,,,,,,,,,,,,,,,,,,10.0002660751343,10.0008239746094,2949.78051757812,2949.78051757812,53.4622182726114,5.63804406463339,3.60500383377075,54,2,0,0,1,0.301666259765625,33.2355842590332,1,1,3,10.0002660751343,0,10.0005450248718,,,,,,,,,,,,,,,,,,,,,,,,,,,,,,,,,
,3879776466.96789,10.0000238418579,3499.69848632812,-2.04053051638208E-5,8.28378090059476E-9,1,4,13.4005146026611,5.00640201130002,33.2800000905991,-0.0254139419270975,-0.00376294983477639,1,3.04933378960074E-8,,,,,,,,,,,,,,,,,,,,,9.99996471405029,10.0000829696655,3499.69848632812,3499.69848632812,53.5059894696884,5.63815420724766,3.60451436042786,54,3,0,0,1,0.301513671875,32.7468223571777,1,1,3,9.99994087219238,0,10.0000238418579,,,,,,,,,,,,,,,,,,,,,,,,,,,,,,,,,
,3879776564.71479,10.0001225471497,5499.720703125,-3.21961737150798E-5,2.21364667207023E-8,1,4,13.4005146026611,5.00636351039149,33.2800000905991,-0.0401052655721138,-0.00589226788340975,1,8.42343192688793E-8,,,,,,,,,,,,,,,,,,,,,10.0000095367432,10.0002355575562,5499.720703125,5499.720703125,53.3910900773614,5.63902335290336,3.60487842559814,54,1,0,0,1,0.299530029296875,33.2355842590332,1,1,3,10.0002374649048,0,10.0001225471497,,,,,,,,,,,,,,,,,,,,,,,,,,,,,,,,,
,3879776649.24449,9.99999904632568,6999.8125,-4.108284104352E-5,1.55382691240586E-8,1,4,13.4005146026611,5.006401991635,33.2800000905991,-0.051168215370714,-0.0075675453611043,1,6.82651407965116E-8,,,,,,,,,,,,,,,,,,,,,9.99992084503174,10.0000772476196,6999.8125,6999.8125,53.3809289066114,5.63881844216281,3.61131620407105,53,2,68,0,0,0.302734375,33.7243423461914,1,1,3,10.0000772476196,0,9.99999904632568,,,,,,,,,,,,,,,,,,,,,,,,,,,,,,,,,
,3879776733.62969,9.99994421005249,8500.1943359375,-4.99762533083445E-5,1.30914336053057E-8,1,4,13.4005146026611,5.00637152468377,33.2800000905991,-0.0622402368239193,-0.00923301737415206,1,6.10657614453002E-8,,,,,,,,,,,,,,,,,,,,,9.99990558624268,9.99998283386231,8500.1943359375,8500.1943359375,53.3387209665729,5.63900812738916,3.60942268371582,54,3,0,0,1,0.306625366210937,33.7243423461914,1,1,3,9.99998283386231,0,9.99994421005249,,,,,,,,,,,,,,,,,,,,,,,,,,,,,,,,,
,3879776839.38837,10.0000967979431,10000.0849609375,-5.88543735154193E-5,1.82121476123022E-8,1,4,13.4005146026611,5.00647090125899,33.2800000905991,-0.0732985299623119,-0.0108770000247505,1,6.91311107186184E-8,,,,,,,,,,,,,,,,,,,,,10.0000267028809,10.0001668930054,10000.0849609375,10000.0849609375,53.447367330746,5.63864152935412,3.60231137275696,54,1,0,0,1,0.29876708984375,33.2355842590332,1,1,3,10.0001668930054,0,10.0000967979431,,,,,,,,,,,,,,,,,,,,,,,,,,,,,,,,,
,3879777058.20446,10.0000133514404,25000.375,-1.48180048777483E-4,3.10165729443854E-8,1,4,13.4005146026611,5.00635628330472,33.2800000905991,-0.184528141568425,-0.0274690847152435,1,1.06194730415454E-7,,,,,,,,,,,,,,,,,,,,,9.99997997283935,10.0000467300415,25000.375,25000.375,53.5653932371499,5.63940749950845,3.6108763217926,54,2,0,0,1,0.300750732421875,33.2355842590332,1,1,3,9.99997997283935,0,10.0000133514404,,,,,,,,,,,,,,,,,,,,,,,,,,,,,,,,,
,3879777296.17271,9.99992895126343,40000.4921875,-2.38289580437131E-4,6.53987944379576E-8,1,4,13.4005146026611,5.00631548809761,33.2800000905991,-0.296730439230503,-0.0442224546431004,1,1.30864032852338E-7,,,,,,,,,,,,,,,,,,,,,9.99989032745361,9.99996757507324,40000.4921875,40000.4921875,53.7303168547076,5.639677410232,3.60700821876526,54,3,0,0,1,0.301132202148438,33.7243423461914,1,1,3,9.99989032745361,0,9.99992895126343,,,,,,,,,,,,,,,,,,,,,,,,,,,,,,,,,
,3879777576.87143,10.0000863075256,60000.41015625,-3.5960385441024E-4,1.17863285354022E-7,1,4,13.4005146026611,5.00630892651131,33.2800000905991,-0.447785694636668,-0.0668076813178002,1,1.40062364378404E-7,,,,,,,,,,,,,,,,,,,,,9.99999809265137,10.0001745223999,60000.41015625,60000.41015625,53.8358367048038,5.64124908466242,3.60031843185425,54,1,0,0,1,0.301666259765625,33.7243423461914,1,1,3,10.0001745223999,0,10.0000863075256,,,,,,,,,,,,,,,,,,,,,,,,,,,,,,,,,
,3879777754.97358,10.0000414848328,70000.46875,-4.20714317017122E-4,1.39986568565214E-7,1,4,13.4005146026611,5.00636930167872,33.2800000905991,-0.523888412668743,-0.0781758764581271,1,1.52866277489828E-7,,,,,,,,,,,,,,,,,,,,,10.0000333786011,10.0000495910645,70000.46875,70000.46875,53.9011026861596,5.64219292923153,3.61185956001282,54,3,0,0,1,0.299911499023438,33.7243423461914,1,1,3,9.99998378753662,0,10.0000414848328,,,,,,,,,,,,,,,,,,,,,,,,,,,,,,,,,