File: SQUID/Reference/STO/B1/STOsubs_MH_5K_FC_0d5T.csv
Comment,Time Stamp (sec),Temperature (K),Magnetic Field (Oe),Moment (emu),M. Std. Err. (emu),Transport Action,Averaging Time (sec),Frequency (Hz),Peak Amplitude (mm),Center Position (mm),Lockin Signal' (V),Lockin Signal (V),Range,M. Quad. Signal (emu),AC Moment (emu),AC M. Std Err. (emu),AC Phase (deg),AC Phase Std. Err. (deg),AC Susceptibility (emu/Oe),AC Suscept. Std Err. (emu/Oe),AC X' (emu/Oe),AC X' Std Err. (emu/Oe),AC X'' (emu/Oe),AC X'' Std Err. (emu/Oe),AC Drive (Oe),AC Frequency (Hz),AC Averaging Time (sec),AC Cycles,AC Range,AC Measure Type,AC Signal' (V),AC Signal'' (V),AC Trim Coil Ratio,AC Trim Coil Phase,Min. Temperature (K),Max. Temperature (K),Min. Field (Oe),Max. Field (Oe),Mass (grams),Motor Lag (deg),Pressure (Torr),Measure Count,Measurement Number,SQUID Status (code),Motor Status (code),Measure Status (code),Motor Current (amps),Motor Temp. (C),Temp. Status (code),Field Status (code),Chamber Status (code),Chamber Temp (K),Redirection State,Average Temp (K),Rotation Angle (deg),Rotator state,DC Moment Fixed Ctr (emu),DC Moment Err Fixed Ctr (emu),DC Moment Free Ctr (emu),DC Moment Err Free Ctr (emu),DC Fixed Fit,DC Free Fit,DC Calculated Center (mm),DC Calculated Center Err (mm),DC Scan Length (mm),DC Scan Time (s),DC Number of Points,DC Squid Drift,DC Min V (V),DC Max V (V),DC Scans per Measure,Sample Resistance,He3 Temperature,Sorb Resistance,Sorb Temperature,Map 05,Map 06,Map 07,Map 08,Map 09,Map 10,Map 11,Map 12,Map 13,Map 14,Map 15,Map 16
,3879749678.85104,4.99999380111694,70000.4296875,-4.17440320720252E-4,1.31134405732375E-7,1,4,13.4005146026611,4.99804657848508,33.2800000905991,-0.518606226064939,-0.0773652499965293,1,1.69319139191316E-7,,,,,,,,,,,,,,,,,,,,,4.99996185302734,5.00002574920654,70000.4296875,70000.4296875,54.5439921432269,5.63877500999581,2.93719935417175,48,1,32,0,0,0.296401977539063,32.2580642700195,1,1,3,5.00002574920654,0,4.99999380111694,,,,,,,,,,,,,,,,,,,,,,,,,,,,,,,,,
,3879749938.93818,5.0003170967102,55000.40234375,-3.24935679696751E-4,1.07201190333469E-7,1,4,13.4005146026611,4.99797184805838,33.2800000905991,-0.40365436013158,-0.060356531081246,1,2.17908007145936E-8,,,,,,,,,,,,,,,,,,,,,5.00024604797363,5.00038814544678,55000.40234375,55000.40234375,54.3485850134192,5.63816508073723,2.95099687576294,49,2,100,0,0,0.29754638671875,33.2355842590332,1,1,3,5.00038814544678,0,5.0003170967102,,,,,,,,,,,,,,,,,,,,,,,,,,,,,,,,,
,3879750164.95873,4.9998300075531,40000.01171875,-2.41279848472535E-4,3.82597913622847E-5,1,4,13.4005146026611,4.99783716523223,33.2800000905991,-0.296992256720382,-0.0630556549609989,10,-1.46672972236583E-5,,,,,,,,,,,,,,,,,,,,,4.99975872039795,4.99990129470825,40000.01171875,40000.01171875,53.9820012378999,5.63721443112954,2.94887495040894,54,3,0,0,1,0.296173095703125,33.7243423461914,1,1,3,4.99975872039795,0,4.9998300075531,,,,,,,,,,,,,,,,,,,,,,,,,,,,,,,,,
,3879750461.58396,4.99968385696411,19999.515625,-1.1420665599221E-4,6.2295545965307E-6,1,4,13.4005146026611,4.99777420176144,33.2800000905991,-0.142353939487721,-0.0179536795729812,10,2.63122562468508E-6,,,,,,,,,,,,,,,,,,,,,4.99960279464722,4.99976491928101,19999.515625,19999.515625,53.7385239541595,5.6363013772776,2.95037531852722,54,1,0,0,1,0.297088623046875,33.7243423461914,1,1,3,4.99976491928101,0,4.99968385696411,,,,,,,,,,,,,,,,,,,,,,,,,,,,,,,,,
,3879750656.026,4.99974918365479,9999.5185546875,-5.60046108460289E-5,2.48341775852771E-8,1,4,13.4005146026611,4.99763481311978,33.2800000905991,-0.0695719542000398,-0.0103598786529592,1,3.75275655304328E-8,,,,,,,,,,,,,,,,,,,,,4.99972343444824,4.99977493286133,9999.5185546875,9999.5185546875,53.5833706930922,5.63591696851562,2.93817925453186,54,2,0,0,1,0.296630859375,33.7243423461914,1,1,3,4.99972343444824,0,4.99974918365479,,,,,,,,,,,,,,,,,,,,,,,,,,,,,,,,,
,3879750742.00921,5.00002789497375,8499.75390625,-4.74334485787746E-5,1.89893316381517E-8,1,4,13.4005146026611,4.99764811387653,33.2800000905991,-0.0589249697579701,-0.00877200915544218,1,3.37053232774363E-8,,,,,,,,,,,,,,,,,,,,,5.00002241134644,5.00003337860107,8499.75390625,8499.75390625,53.5341280963807,5.63601487602144,2.93378162384033,54,3,0,0,1,0.29541015625,33.7243423461914,1,1,3,5.00002241134644,0,5.00002789497375,,,,,,,,,,,,,,,,,,,,,,,,,,,,,,,,,
,3879750844.00764,5.00011515617371,6499.60546875,-3.60157451759529E-5,1.39104376114797E-8,1,4,13.4005146026611,4.99762589519289,33.2800000905991,-0.0447346196852968,-0.00670220151314554,1,-8.01458161134994E-9,,,,,,,,,,,,,,,,,,,,,5.00002002716064,5.00021028518677,6499.60546875,6499.60546875,53.3852278634672,5.63571590925033,2.92509841918945,54,1,0,0,1,0.297317504882812,33.7243423461914,1,1,3,5.00021028518677,0,5.00011515617371,,,,,,,,,,,,,,,,,,,,,,,,,,,,,,,,,
,3879750930.00175,5.00009441375732,4999.5390625,-2.75312741014279E-5,1.13556886069922E-8,1,4,13.4005146026611,4.99766503553689,33.2800000905991,-0.0341977822288594,-0.00511520282405376,1,4.52615562257345E-10,,,,,,,,,,,,,,,,,,,,,4.99992799758911,5.00026082992554,4999.5390625,4999.5390625,53.6290959614672,5.63564278937744,2.92978382110596,54,2,0,0,1,0.297164916992188,33.7243423461914,1,1,3,5.00026082992554,0,5.00009441375732,,,,,,,,,,,,,,,,,,,,,,,,,,,,,,,,,
,3879751015.33325,4.99991846084595,3499.736328125,-1.9069744968693E-5,9.3441516467071E-9,1,4,13.4005146026611,4.99757058701073,33.2800000905991,-0.0236872827771064,-0.00353926451381311,1,3.31293968589888E-9,,,,,,,,,,,,,,,,,,,,,4.99978303909302,5.00005388259888,3499.736328125,3499.736328125,53.6447285318518,5.63647133229405,2.92215418815613,54,3,0,0,1,0.296478271484375,33.7243423461914,1,1,3,4.99978303909302,0,4.99991846084595,,,,,,,,,,,,,,,,,,,,,,,,,,,,,,,,,
,3879751121.95811,5.00008988380432,2899.59130859375,-1.57938354510662E-5,1.68510046820568E-8,1,4,13.4005146026611,4.99762219060746,33.2800000905991,-0.0196507780504059,-0.0027150719774555,1,1.76832462866893E-7,,,,,,,,,,,,,,,,,,,,,4.99995946884155,5.00022029876709,2899.59130859375,2899.59130859375,53.4536203588999,5.63600918554014,2.92043662071228,54,1,0,0,1,0.296707153320313,34.2131004333496,1,1,3,4.99995946884155,0,5.00008988380432,,,,,,,,,,,,,,,,,,,,,,,,,,,,,,,,,
,3879751193.05018,4.99994993209839,2749.6650390625,-1.49103599328008E-5,1.29297701920084E-8,1,4,13.4005146026611,4.9975715996963,33.2800000905991,-0.0185467831511879,-0.00259328696957584,1,1.42686059691568E-7,,,,,,,,,,,,,,,,,,,,,4.99991655349731,4.99998331069946,2749.6650390625,2749.6650390625,53.5392086817557,5.63614367457132,2.92316198348999,52,2,68,0,0,0.303115844726562,33.7243423461914,1,1,3,4.99991655349731,0,4.99994993209839,,,,,,,,,,,,,,,,,,,,,,,,,,,,,,,,,
,3879751265.14015,4.9998505115509,2599.63842773438,-1.40695684588773E-5,1.18883630624169E-8,1,4,13.4005146026611,4.99753910221766,33.2800000905991,-0.0174958324554902,-0.00248007199256402,1,1.08038139574842E-7,,,,,,,,,,,,,,,,,,,,,4.99984359741211,4.9998574256897,2599.63842773438,2599.63842773438,53.511460869323,5.63587521645336,2.9147047996521,54,3,0,0,1,0.302963256835937,34.2131004333496,1,1,3,4.99984359741211,0,4.9998505115509,,,,,,,,,,,,,,,,,,,,,,,,,,,,,,,,,
,3879751345.93365,5.00018000602722,2399.76196289062,-1.29615429725104E-5,1.7114972093376E-8,1,4,13.4005146026611,4.99754554705986,33.2800000905991,-0.0161379567056482,-0.00215139863462321,1,2.06899309652473E-7,,,,,,,,,,,,,,,,,,,,,5.00015020370483,5.00020980834961,2399.76196289062,2399.76196289062,53.5712554510441,5.63539927029806,2.91069889068604,53,1,68,0,0,0.296707153320313,33.7243423461914,1,1,3,5.00020980834961,0,5.00018000602722,,,,,,,,,,,,,,,,,,,,,,,,,,,,,,,,,
,3879751441.74989,4.99988794326782,2249.77294921875,-1.21022171922865E-5,1.51787233960628E-8,1,4,13.4005146026611,4.99767023098025,33.2800000905991,-0.0150630184911234,-0.00204592580733904,1,1.63322026419798E-7,,,,,,,,,,,,,,,,,,,,,4.99975681304932,5.00001907348633,2249.77294921875,2249.77294921875,53.554059623621,5.63619070028961,2.91379547119141,52,2,68,0,0,0.2984619140625,33.7243423461914,1,1,3,4.99975681304932,0,4.99988794326782,,,,,,,,,,,,,,,,,,,,,,,,,,,,,,,,,
,3879751523.19019,4.99940347671509,2099.79638671875,-1.12644164308792E-5,1.1343227901133E-8,1,4,13.4005146026611,4.99754050320178,33.2800000905991,-0.0140129429419508,-0.00194966450502258,1,1.15431371447294E-7,,,,,,,,,,,,,,,,,,,,,4.9991717338562,4.99963521957397,2099.79638671875,2099.79638671875,53.5188863402557,5.63575964347234,2.91244411468506,54,3,0,0,1,0.3033447265625,32.7468223571777,1,1,3,4.99963521957397,0,4.99940347671509,,,,,,,,,,,,,,,,,,,,,,,,,,,,,,,,,
,3879751603.86645,5.00001001358032,1900.04602050781,-1.01585253392254E-5,2.56394936167297E-8,1,4,13.4005146026611,4.9975844804231,33.2800000905991,-0.012661995372823,-0.00159365669009018,1,2.36631115506648E-7,,,,,,,,,,,,,,,,,,,,,4.99991035461426,5.00010967254639,1900.04602050781,1900.04602050781,53.4536203588999,5.63558045301548,2.9106342792511,54,1,0,0,1,0.296707153320313,33.7243423461914,1,1,3,5.00010967254639,0,5.00001001358032,,,,,,,,,,,,,,,,,,,,,,,,,,,,,,,,,
,3879751692.43444,5.00001358985901,1749.7421875,-9.28984225513093E-6,1.14138356505498E-8,1,4,13.4005146026611,4.99752118883587,33.2800000905991,-0.011565217600217,-0.0015496753196368,10,1.42067892196631E-7,,,,,,,,,,,,,,,,,,,,,4.99997568130493,5.00005149841309,1749.7421875,1749.7421875,53.5380362389768,5.63607642282345,2.9102246761322,54,2,0,0,1,0.2960205078125,33.7243423461914,1,1,3,4.99997568130493,0,5.00001358985901,,,,,,,,,,,,,,,,,,,,,,,,,,,,,,,,,
,3879751794.74326,4.99998378753662,1599.71545410156,-8.43922374859298E-6,1.16954947347538E-8,1,4,13.4005146026611,4.99734952227111,33.2800000905991,-0.0105031331639574,-0.00142520899972065,1,1.14972583898752E-7,,,,,,,,,,,,,,,,,,,,,4.99996185302734,5.0000057220459,1599.71545410156,1599.71545410156,53.4887936422653,5.63734156888049,2.90117311477661,52,3,68,0,0,0.296249389648438,33.7243423461914,1,1,3,4.9999737739563,0,4.99998378753662,,,,,,,,,,,,,,,,,,,,,,,,,,,,,,,,,
,3879751913.63884,5.00014710426331,1399.876953125,-7.37119454160974E-6,1.98563189082852E-8,1,4,13.4005146026611,4.99730230564929,33.2800000905991,-0.00920109836770724,-0.00106223279629781,1,2.47434929947809E-7,,,,,,,,,,,,,,,,,,,,,5.00013971328735,5.00015449523926,1399.876953125,1399.876953125,53.6056471058903,5.6369774865496,2.90308499336243,54,1,0,0,1,0.297088623046875,33.7243423461914,1,1,3,5.00013971328735,0,5.00014710426331,,,,,,,,,,,,,,,,,,,,,,,,,,,,,,,,,
,3879752050.90142,4.99997425079346,1249.82495117188,-6.46918186550366E-6,8.57224052795182E-9,1,4,13.4005146026611,4.99718721421519,33.2800000905991,-0.00804529020121128,-0.0011301524564811,1,5.77849383599531E-8,,,,,,,,,,,,,,,,,,,,,4.99991130828857,5.00003719329834,1249.82495117188,1249.82495117188,53.5263118111883,5.63852479115038,2.88303422927856,54,2,0,0,1,0.296096801757812,33.7243423461914,1,1,3,4.99991130828857,0,4.99997425079346,,,,,,,,,,,,,,,,,,,,,,,,,,,,,,,,,
,3879752155.01196,5.00012755393982,1100.02465820312,-5.6556384000133E-6,1.31577683595234E-8,1,4,13.4005146026611,4.99705679184477,33.2800000905991,-0.00704297474259515,-9.23207704542659E-4,10,1.02682383110343E-7,,,,,,,,,,,,,,,,,,,,,5.00006818771362,5.00018692016602,1100.02465820312,1100.02465820312,53.4286082462845,5.63862539070654,2.88436627388001,54,3,0,0,1,0.297012329101562,33.7243423461914,1,1,3,5.00018692016602,0,5.00012755393982,,,,,,,,,,,,,,,,,,,,,,,,,,,,,,,,,
,3879752270.84675,5.00030636787415,899.946899414062,-4.61484883696496E-6,2.30072291389571E-8,1,4,13.4005146026611,4.99685485717076,33.2800000905991,-0.00577899389693392,-5.36408948928667E-4,1,2.58412360880783E-7,,,,,,,,,,,,,,,,,,,,,5.00025033950806,5.00036239624023,899.946899414062,899.946899414062,53.5028629556114,5.63976946734444,2.87288641929626,52,1,68,0,0,0.297470092773438,33.7243423461914,1,1,3,5.00025033950806,0,5.00030636787415,,,,,,,,,,,,,,,,,,,,,,,,,,,,,,,,,
,3879752378.52649,4.99997353553772,749.970458984375,-3.71649142887758E-6,1.37286705411868E-8,1,4,13.4005146026611,4.99694423105692,33.2800000905991,-0.00464097127718358,-5.19980275594231E-4,1,1.37263217496635E-7,,,,,,,,,,,,,,,,,,,,,4.99994993209839,4.99999713897705,749.970458984375,749.970458984375,53.4035961336691,5.63896399626426,2.86835122108459,54,2,0,0,1,0.297164916992188,33.2355842590332,1,1,3,4.99998140335083,0,4.99997353553772,,,,,,,,,,,,,,,,,,,,,,,,,,,,,,,,,
,3879752484.20108,5.00014138221741,600.14501953125,-2.85965781093979E-6,1.21287719860666E-8,1,4,13.4005146026611,4.9970057150772,33.2800000905991,-0.00356890033327728,-4.14551215822984E-4,10,9.39860291984263E-8,,,,,,,,,,,,,,,,,,,,,5.00004053115845,5.00024223327637,600.14501953125,600.14501953125,53.3973431055153,5.63881472543217,2.87331986427307,54,3,0,0,1,0.29815673828125,33.7243423461914,1,1,3,5.00004053115845,0,5.00014138221741,,,,,,,,,,,,,,,,,,,,,,,,,,,,,,,,,
,3879752608.96764,4.99988627433777,400.029571533203,-1.84111518910774E-6,2.31645377784979E-8,1,4,13.4005146026611,4.99710736915351,33.2800000905991,-0.00233724615314452,-3.26865925460355E-6,1,2.72787608760667E-7,,,,,,,,,,,,,,,,,,,,,4.99984121322632,4.99993133544922,400.029571533203,400.029571533203,53.5771176649383,5.63804415528155,2.8646092414856,53,1,68,0,0,0.298309326171875,34.2131004333496,1,1,3,4.99984216690063,0,4.99988627433777,,,,,,,,,,,,,,,,,,,,,,,,,,,,,,,,,
,3879752709.9671,4.99978637695313,250.090850830078,-9.67685874148482E-7,1.34805846853868E-8,1,4,13.4005146026611,4.99708408049813,33.2800000905991,-0.00122619861510466,-1.67221308860577E-5,10,1.31295300522112E-7,,,,,,,,,,,,,,,,,,,,,4.99975776672363,4.99981498718262,250.090850830078,250.090850830078,53.5778992934576,5.6385114032859,2.86307621002197,54,2,0,0,1,0.297622680664063,33.2355842590332,1,1,3,4.99975776672363,0,4.99978637695313,,,,,,,,,,,,,,,,,,,,,,,,,,,,,,,,,
,3879752821.52186,4.99988842010498,100.252861022949,-1.44968489897383E-7,1.06882595026929E-8,1,4,13.4005146026611,4.99710011409999,33.2800000905991,-1.99348423577168E-4,1.02121198152771E-4,1,1.03913322883082E-7,,,,,,,,,,,,,,,,,,,,,4.99977779388428,4.99999904632568,100.252861022949,100.252861022949,53.6052562916307,5.63725712597771,2.8657968044281,54,3,0,0,1,0.2978515625,33.2355842590332,1,1,3,4.99977779388428,0,4.99988842010498,,,,,,,,,,,,,,,,,,,,,,,,,,,,,,,,,
,3879752937.81758,5.000084400177,-99.7871017456055,8.21226504253522E-7,2.7779256577068E-8,1,4,13.4005146026611,4.99681220738064,33.2800000905991,9.73156617221864E-4,4.64592536255914E-4,1,2.51264843856621E-7,,,,,,,,,,,,,,,,,,,,,5.00005197525024,5.00011682510376,-99.7871017456055,-99.7871017456055,53.5372546104576,5.63871170438739,2.86062693595886,53,1,68,0,0,0.298309326171875,33.7243423461914,1,1,3,5.00011682510376,0,5.000084400177,,,,,,,,,,,,,,,,,,,,,,,,,,,,,,,,,
,3879753050.809,4.99994349479675,-249.725784301758,1.64942460217883E-6,1.74315891036738E-8,1,4,13.4005146026611,4.99679171390747,33.2800000905991,0.00202483524765999,4.63372651576865E-4,10,1.26391333863795E-7,,,,,,,,,,,,,,,,,,,,,4.9999303817749,4.9999566078186,-249.725784301758,-249.725784301758,53.5759452221595,5.63905837931533,2.85282135009766,54,2,0,0,1,0.299301147460937,33.2355842590332,1,1,3,5.00004434585571,0,4.99994349479675,,,,,,,,,,,,,,,,,,,,,,,,,,,,,,,,,
,3879753154.37267,4.99996566772461,-399.689666748047,2.41419051470277E-6,1.44504546582259E-8,1,4,13.4005146026611,4.99681436904194,33.2800000905991,0.00297989905157439,5.6981160267699E-4,10,9.76950960812083E-8,,,,,,,,,,,,,,,,,,,,,4.9999475479126,4.99998378753662,-399.689666748047,-399.689666748047,53.6447285318518,5.63874016211915,2.85259914398193,54,3,0,0,1,0.297317504882812,33.7243423461914,1,1,3,4.99998378753662,0,4.99996566772461,,,,,,,,,,,,,,,,,,,,,,,,,,,,,,,,,
,3879753278.17767,5.00003051757812,-599.641540527344,3.41077116113331E-6,1.90408496514568E-8,1,4,13.4005146026611,4.99682959976596,33.2800000905991,0.00420647111084071,8.28776189550508E-4,1,1.57142215842125E-7,,,,,,,,,,,,,,,,,,,,,4.99997520446777,5.00008583068848,-599.641540527344,-599.641540527344,53.3992971768133,5.63917344395734,2.85048770904541,53,1,68,0,0,0.297164916992188,33.7243423461914,1,1,3,5.00008583068848,0,5.00003051757812,,,,,,,,,,,,,,,,,,,,,,,,,,,,,,,,,
,3879753388.93556,4.99986886978149,-749.65576171875,4.19689260120244E-6,1.52621543006884E-8,1,4,13.4005146026611,4.9967392421642,33.2800000905991,0.0051869023847089,9.45926069809097E-4,10,1.33897595428201E-7,,,,,,,,,,,,,,,,,,,,,4.99984455108643,4.99989318847656,-749.65576171875,-749.65576171875,53.5474157812076,5.6397534110661,2.85626029968262,54,2,0,0,1,0.296859741210937,33.7243423461914,1,1,3,4.99989318847656,0,4.99986886978149,,,,,,,,,,,,,,,,,,,,,,,,,,,,,,,,,
,3879753487.9374,4.99987483024597,-899.594421386719,5.00868660928317E-6,1.15484154093565E-8,1,4,13.4005146026611,4.99693716947522,33.2800000905991,0.0062030933148529,0.00104500556916821,10,9.21973925606216E-8,,,,,,,,,,,,,,,,,,,,,4.99985027313232,4.99989938735962,-899.594421386719,-899.594421386719,53.4973915559768,5.63870037708615,2.85195803642273,54,3,0,0,1,0.297622680664063,34.2131004333496,1,1,3,5.0000786781311,0,4.99987483024597,,,,,,,,,,,,,,,,,,,,,,,,,,,,,,,,,
,3879753598.79429,5.00020146369934,-1099.55883789062,6.01522837926649E-6,5.52543578867703E-8,1,4,13.4005146026611,4.99657560848901,33.2800000905991,0.00742779683031821,0.00139600100024938,1,2.24369625042038E-7,,,,,,,,,,,,,,,,,,,,,5.00005388259888,5.0003490447998,-1099.55883789062,-1099.55883789062,53.5778992934576,5.64050429691224,2.85340237617493,54,1,0,0,1,0.298385620117188,33.7243423461914,1,1,3,5.0003490447998,0,5.00020146369934,,,,,,,,,,,,,,,,,,,,,,,,,,,,,,,,,
,3879753699.28444,5.0002076625824,-1249.560546875,6.88276678309942E-6,1.75997681725571E-8,1,4,13.4005146026611,4.99681566445616,33.2800000905991,0.00852571509460087,0.00142309097186457,10,1.16329900492649E-7,,,,,,,,,,,,,,,,,,,,,5.00001955032349,5.00039577484131,-1249.560546875,-1249.560546875,53.5986124492172,5.63994776836596,2.8541784286499,54,2,0,0,1,0.298919677734375,33.7243423461914,1,1,3,5.00001955032349,0,5.0002076625824,,,,,,,,,,,,,,,,,,,,,,,,,,,,,,,,,
,3879753792.23048,4.99991703033447,-1399.78881835938,7.69739677819112E-6,1.19726266570403E-8,1,4,13.4005146026611,4.99704505595691,33.2800000905991,0.00954032266715795,0.00155881364808498,1,1.03676790670849E-7,,,,,,,,,,,,,,,,,,,,,4.99990081787109,4.99993324279785,-1399.78881835938,-1399.78881835938,53.4520571018614,5.63926567549016,2.84831047058105,54,3,0,0,1,0.298309326171875,33.2355842590332,1,1,3,4.99990081787109,0,4.99991703033447,,,,,,,,,,,,,,,,,,,,,,,,,,,,,,,,,
,3879753896.96994,5.00009608268738,-1599.47619628906,8.77550468074782E-6,1.20811665381005E-8,1,4,13.4005146026611,4.99700963893591,33.2800000905991,0.0108704920585008,0.00181692194404057,1,1.50242335424481E-7,,,,,,,,,,,,,,,,,,,,,5.00006484985352,5.00012731552124,-1599.47619628906,-1599.47619628906,53.5403811245345,5.63938166019202,2.85093808174133,54,1,0,0,1,0.298385620117188,33.2355842590332,1,1,3,5.00012731552124,0,5.00009608268738,,,,,,,,,,,,,,,,,,,,,,,,,,,,,,,,,
,3879753980.37791,5.00001335144043,-1749.7548828125,9.62567382299794E-6,1.15016000632344E-8,1,4,13.4005146026611,4.99703597558154,33.2800000905991,0.01193323079687,0.00192932306925947,1,1.13557317921135E-7,,,,,,,,,,,,,,,,,,,,,4.9999828338623,5.00004386901855,-1749.7548828125,-1749.7548828125,53.582589064573,5.63921277532591,2.85152626037598,54,2,0,0,1,0.298004150390625,33.2355842590332,1,1,3,4.9999828338623,0,5.00001335144043,,,,,,,,,,,,,,,,,,,,,,,,,,,,,,,,,
,3879754051.65662,4.99997019767761,-1899.69348144531,1.04198913635097E-5,4.48881931803492E-8,1,4,13.4005146026611,4.99697867273741,33.2800000905991,0.0129295556013392,0.00200881368396441,1,5.87794051625836E-8,,,,,,,,,,,,,,,,,,,,,4.9999475479126,4.99999284744263,-1899.69348144531,-1899.69348144531,53.2992487263518,5.6388460268818,2.84331202507019,54,3,0,0,1,0.304718017578125,33.2355842590332,1,1,3,4.9999475479126,0,4.99997019767761,,,,,,,,,,,,,,,,,,,,,,,,,,,,,,,,,
,3879754145.30684,5.00007343292236,-2099.69555664062,1.14044812233175E-5,1.29719441110099E-7,1,4,13.4005146026611,4.99670436979349,33.2800000905991,0.0141112550550525,0.00245879409602893,1,2.73974902684452E-7,,,,,,,,,,,,,,,,,,,,,4.999671459198,5.00047540664673,-2099.69555664062,-2099.69555664062,53.6404295749961,5.6402108131857,2.8507776260376,54,1,0,0,1,0.297622680664063,33.2355842590332,1,1,3,4.999671459198,0,5.00007343292236,,,,,,,,,,,,,,,,,,,,,,,,,,,,,,,,,
,3879754217.2262,5.00020170211792,-2249.68481445313,1.2392740503816E-5,6.32968930798501E-9,1,4,13.4005146026611,4.9967560138931,33.2800000905991,0.0153720260810575,0.00241966142575034,1,9.45964870038022E-8,,,,,,,,,,,,,,,,,,,,,5.00010633468628,5.00029706954956,-2249.68481445313,-2249.68481445313,53.4907477135634,5.63869634248969,2.84266018867493,53,2,64,0,0,0.298538208007812,33.7243423461914,1,1,3,5.00029706954956,0,5.00020170211792,,,,,,,,,,,,,,,,,,,,,,,,,,,,,,,,,
,3879754289.31764,5.00028252601624,-2399.58569335938,1.32188203601626E-5,1.59055654453702E-8,1,4,13.4005146026611,4.99692677066076,33.2800000905991,0.016402150019271,0.00254988995676924,1,7.57905529708575E-8,,,,,,,,,,,,,,,,,,,,,5.00023746490479,5.00032758712769,-2399.58569335938,-2399.58569335938,53.4493214020441,5.63877258455451,2.84535002708435,54,3,0,0,1,0.298538208007812,33.7243423461914,1,1,3,5.00023746490479,0,5.00028252601624,,,,,,,,,,,,,,,,,,,,,,,,,,,,,,,,,
,3879754384.89809,5.00013446807861,-2599.63842773438,1.43044370890721E-5,1.57929491681026E-7,1,4,13.4005146026611,4.99697300017725,33.2800000905991,0.0177755433114102,0.00258479613504401,1,-5.853052744921E-8,,,,,,,,,,,,,,,,,,,,,5.00009536743164,5.00017356872559,-2599.63842773438,-2599.63842773438,53.4915293420826,5.63840983484798,2.85060954093933,54,1,0,0,1,0.297622680664063,33.7243423461914,1,1,3,5.00009536743164,0,5.00013446807861,,,,,,,,,,,,,,,,,,,,,,,,,,,,,,,,,
,3879754457.36864,5.00007796287537,-2749.53930664062,1.51824602216452E-5,1.13227858866215E-8,1,4,13.4005146026611,4.99692165211945,33.2800000905991,0.018839671393389,0.00292179194672561,1,8.15116670394788E-8,,,,,,,,,,,,,,,,,,,,,5.0000467300415,5.00010919570923,-2749.53930664062,-2749.53930664062,53.613072576823,5.63823377660607,2.84565377235413,54,2,0,0,1,0.297698974609375,33.2355842590332,1,1,3,5.00013113021851,0,5.00007796287537,,,,,,,,,,,,,,,,,,,,,,,,,,,,,,,,,
,3879754530.08804,4.99989724159241,-2899.7548828125,1.61511791410506E-5,1.32895245569315E-7,1,4,13.4005146026611,4.9968423724805,33.2800000905991,0.020060857334051,0.00297737146999903,1,-1.85951629777058E-8,,,,,,,,,,,,,,,,,,,,,4.99978113174438,5.00001335144043,-2899.7548828125,-2899.7548828125,53.4325163888806,5.63859788837239,2.84898781776428,54,3,0,0,1,0.298309326171875,33.2355842590332,1,1,3,4.99978113174438,0,4.99989724159241,,,,,,,,,,,,,,,,,,,,,,,,,,,,,,,,,
,3879754634.45009,5.00005435943604,-3499.52221679687,1.94547845085529E-5,9.94467278478509E-9,1,4,13.4005146026611,4.99662956800918,33.2800000905991,0.0241647878064136,0.00357231943957657,1,-3.35421002937034E-8,,,,,,,,,,,,,,,,,,,,,5.00005340576172,5.00005531311035,-3499.52221679687,-3499.52221679687,53.719764869698,5.63942568586664,2.84293293952942,54,1,0,0,1,0.297470092773438,33.2355842590332,1,1,3,5.00005531311035,0,5.00005435943604,,,,,,,,,,,,,,,,,,,,,,,,,,,,,,,,,
,3879754717.28886,5.00014615058899,-4999.60205078125,2.78742825898079E-5,1.21374513071221E-8,1,4,13.4005146026611,4.99635075044805,33.2800000905991,0.0346181382631303,0.00512997289904177,1,-3.8352550899411E-8,,,,,,,,,,,,,,,,,,,,,5.00012302398682,5.00016927719116,-4999.60205078125,-4999.60205078125,53.4446316309287,5.64171265124718,2.84667110443115,54,2,0,0,1,0.298233032226562,33.2355842590332,1,1,3,5.00020265579224,0,5.00014615058899,,,,,,,,,,,,,,,,,,,,,,,,,,,,,,,,,
,3879754801.76456,5.00005221366882,-6499.7314453125,3.63695283123868E-5,1.59407220560405E-8,1,4,13.4005146026611,4.99631928463464,33.2800000905991,0.0451645928376216,0.00671822882289697,1,-3.00255031889896E-8,,,,,,,,,,,,,,,,,,,,,5.00001335144043,5.00009107589722,-6499.7314453125,-6499.7314453125,53.6447285318518,5.64139731708064,2.84605550765991,54,3,0,0,1,0.298995971679687,33.7243423461914,1,1,3,5.00001335144043,0,5.00005221366882,,,,,,,,,,,,,,,,,,,,,,,,,,,,,,,,,
,3879754901.00065,5.00012254714966,-8499.615234375,4.77385050122494E-5,1.96547841171329E-8,1,4,13.4005146026611,4.99662713660913,33.2800000905991,0.0592930009884961,0.00878557415757918,1,-6.63955398397467E-8,,,,,,,,,,,,,,,,,,,,,5.0001072883606,5.00013780593872,-8499.615234375,-8499.615234375,53.5579677662172,5.63953283318618,2.84560298919678,54,1,0,0,1,0.297317504882812,33.2355842590332,1,1,3,5.00013780593872,0,5.00012254714966,,,,,,,,,,,,,,,,,,,,,,,,,,,,,,,,,
,3879754986.02339,4.99981164932251,-9999.6318359375,5.62668857090181E-5,1.87817507058063E-8,1,4,13.4005146026611,4.99683003600084,33.2800000905991,0.0698835227182273,0.0103959182453366,1,-4.58605448795424E-8,,,,,,,,,,,,,,,,,,,,,4.99968433380127,4.99993896484375,-9999.6318359375,-9999.6318359375,53.4887936422653,5.63927974371189,2.84563279151917,54,2,0,0,1,0.297393798828125,33.7243423461914,1,1,3,4.99968433380127,0,4.99981164932251,,,,,,,,,,,,,,,,,,,,,,,,,,,,,,,,,
,3879755175.54719,4.99996852874756,-19999.75390625,1.14090096438547E-4,3.09737448125641E-8,1,4,13.4005146026611,4.99662961696293,33.2800000905991,0.141679066453398,0.0211649551596234,1,-2.31264868343637E-8,,,,,,,,,,,,,,,,,,,,,4.99990606307983,5.00003099441528,-19999.75390625,-19999.75390625,53.7635360667749,5.64015467307812,2.84127449989319,54,3,0,0,1,0.299301147460937,33.7243423461914,1,1,3,5.00003099441528,0,4.99996852874756,,,,,,,,,,,,,,,,,,,,,,,,,,,,,,,,,
,3879755459.29312,5.00015687942505,-39999.84765625,2.33775441227961E-4,8.80108218543258E-8,1,4,13.4005146026611,4.99688592746451,33.2800000905991,0.290325065314243,0.0433856867353826,1,-3.55647166466762E-8,,,,,,,,,,,,,,,,,,,,,4.99999523162842,5.00031852722168,-39999.84765625,-39999.84765625,53.9139995567269,5.63948258520533,2.84890961647034,49,1,100,0,0,0.298385620117188,33.2355842590332,1,1,3,4.99999523162842,0,5.00015687942505,,,,,,,,,,,,,,,,,,,,,,,,,,,,,,,,,
,3879755730.36868,4.9997992515564,-54999.48046875,3.24983550729118E-4,1.02721563486923E-7,1,4,13.4005146026611,4.99718707193003,33.2800000905991,0.403639021891688,0.0602589642832152,1,-9.68269094967099E-8,,,,,,,,,,,,,,,,,,,,,4.99966335296631,4.99993515014648,-54999.48046875,-54999.48046875,54.3184923154288,5.6391759688979,2.84593963623047,54,2,0,0,1,0.297012329101562,33.2355842590332,1,1,3,4.99971485137939,0,4.9997992515564,,,,,,,,,,,,,,,,,,,,,,,,,,,,,,,,,
,3879755995.59354,4.99983739852905,-69999.734375,4.18248170228663E-4,2.33222536803715E-6,1,4,13.4005146026611,4.99726308299302,33.2800000905991,0.519999743988562,0.0741293574290188,10,-2.88188615188303E-6,,,,,,,,,,,,,,,,,,,,,4.99976682662964,4.99990797042847,-69999.734375,-69999.734375,54.7104790178231,5.64021269818651,2.83917284011841,54,3,0,0,1,0.297393798828125,33.7243423461914,1,1,3,4.99979734420776,0,4.99983739852905,,,,,,,,,,,,,,,,,,,,,,,,,,,,,,,,,
,3879756306.12756,4.99991035461426,-49999.62890625,2.85098613653846E-4,2.34108723758522E-5,1,4,13.4005146026611,4.99724919687909,33.2800000905991,0.349336523553851,0.0847534368699209,10,2.55907409910735E-5,,,,,,,,,,,,,,,,,,,,,4.99967288970947,5.00014781951904,-49999.62890625,-49999.62890625,54.2008572232846,5.63926804526239,2.83827304840088,54,1,0,0,1,0.297622680664063,34.2131004333496,1,1,3,5.00014781951904,0,4.99991035461426,,,,,,,,,,,,,,,,,,,,,,,,,,,,,,,,,
,3879756545.0325,5.00013375282288,-34999.60546875,2.0146911826823E-4,4.69327453098102E-6,1,4,13.4005146026611,4.99719433602653,33.2800000905991,0.251141741666748,0.0312687946790976,10,-4.96189486840169E-6,,,,,,,,,,,,,,,,,,,,,5.0001015663147,5.00016593933105,-34999.60546875,-34999.60546875,53.9014935004192,5.63751548501766,2.84366011619568,54,2,0,0,1,0.304336547851562,33.7243423461914,1,1,3,5.0001015663147,0,5.00013375282288,,,,,,,,,,,,,,,,,,,,,,,,,,,,,,,,,
,3879756781.88262,4.99983739852905,-19999.779296875,1.13798520341809E-4,6.96079975024368E-8,1,4,13.4005146026611,4.99716886090291,33.2800000905991,0.141350686320719,0.0210315036543006,1,-8.9535404758706E-8,,,,,,,,,,,,,,,,,,,,,4.9998345375061,4.999840259552,-19999.779296875,-19999.779296875,53.6799018152172,5.63822967204141,2.84266662597656,54,3,0,0,1,0.297088623046875,34.2131004333496,1,1,3,4.999840259552,0,4.99983739852905,,,,,,,,,,,,,,,,,,,,,,,,,,,,,,,,,
,3879756983.49208,5.00002789497375,-9500.29296875,5.31393226943934E-5,1.69928046184421E-8,1,4,13.4005146026611,4.99723401965517,33.2800000905991,0.0659957183586872,0.00989163811555469,1,1.50301802324145E-8,,,,,,,,,,,,,,,,,,,,,4.99992036819458,5.00013542175293,-9500.29296875,-9500.29296875,53.5149781976595,5.63572424961294,2.84043407440186,54,1,0,0,1,0.297317504882812,34.2131004333496,1,1,3,5.00013542175293,0,5.00002789497375,,,,,,,,,,,,,,,,,,,,,,,,,,,,,,,,,
,3879757068.57982,4.99998116493225,-8000.25146484375,4.45871375401535E-5,1.9208864391953E-8,1,4,13.4005146026611,4.99721680731361,33.2800000905991,0.0553802822588148,0.0082588011345369,1,-2.02775957493569E-8,,,,,,,,,,,,,,,,,,,,,4.9999532699585,5.00000905990601,-8000.25146484375,-8000.25146484375,53.5653932371499,5.63667491536423,2.84447860717773,54,2,0,0,1,0.29693603515625,34.2131004333496,1,1,3,4.9999532699585,0,4.99998116493225,,,,,,,,,,,,,,,,,,,,,,,,,,,,,,,,,
,3879757152.78173,5.00000619888306,-6500.36083984375,3.60738773022618E-5,1.6586445071343E-8,1,4,13.4005146026611,4.99714294278822,33.2800000905991,0.0448055842905486,0.00667987870960459,1,-1.79253753931334E-8,,,,,,,,,,,,,,,,,,,,,4.99983692169189,5.00017547607422,-6500.36083984375,-6500.36083984375,53.4973915559768,5.63705585706538,2.84238219261169,54,3,0,0,1,0.297088623046875,34.2131004333496,1,1,3,4.99983692169189,0,5.00000619888306,,,,,,,,,,,,,,,,,,,,,,,,,,,,,,,,,
,3879757253.09279,4.9999577999115,-4500.28857421875,2.47136393988752E-5,9.84842199570657E-9,1,4,13.4005146026611,4.99715598437221,33.2800000905991,0.0306871121332763,0.00463373731851088,1,3.3970565198645E-8,,,,,,,,,,,,,,,,,,,,,4.99980974197388,5.00010585784912,-4500.28857421875,-4500.28857421875,53.5188863402557,5.6369010052028,2.84349465370178,54,1,0,0,1,0.29754638671875,34.2131004333496,1,1,3,4.9997935295105,0,4.9999577999115,,,,,,,,,,,,,,,,,,,,,,,,,,,,,,,,,
,3879757337.82092,4.99983954429626,-3000.30981445313,1.62410420095573E-5,7.79104598620212E-9,1,4,13.4005146026611,4.99713454819243,33.2800000905991,0.0201679024767412,0.00303577608809416,1,1.47919705868363E-8,,,,,,,,,,,,,,,,,,,,,4.99969005584717,4.99998903274536,-3000.30981445313,-3000.30981445313,53.6005665205153,5.63697127510983,2.83942079544067,54,2,0,0,1,0.29754638671875,34.2131004333496,1,1,3,4.99969005584717,0,4.99983954429626,,,,,,,,,,,,,,,,,,,,,,,,,,,,,,,,,
,3879757427.85003,5.00028991699219,-2900.30883789063,1.57581500892473E-5,9.23419539643911E-9,1,4,13.4005146026611,4.99711013701694,33.2800000905991,0.0195935989938926,0.00277517325033818,1,-1.22787765881997E-7,,,,,,,,,,,,,,,,,,,,,5.00018262863159,5.00039720535278,-2900.30883789063,-2900.30883789063,53.5567953234384,5.63636195502335,2.84673047065735,54,3,0,0,1,0.298080444335937,34.2131004333496,1,1,3,5.00018262863159,0,5.00028991699219,,,,,,,,,,,,,,,,,,,,,,,,,,,,,,,,,
,3879757508.74379,5.00006818771362,-2700.35693359375,1.46823755460395E-5,1.70040200271769E-8,1,4,13.4005146026611,4.99707454062957,33.2800000905991,0.0182735533664127,0.00246704630550872,1,-2.0993863016284E-7,,,,,,,,,,,,,,,,,,,,,5.00004720687866,5.00008916854858,-2700.35693359375,-2700.35693359375,53.5239669256307,5.63701377678329,2.84681868553162,54,1,0,0,1,0.29754638671875,33.7243423461914,1,1,3,5.00008916854858,0,5.00006818771362,,,,,,,,,,,,,,,,,,,,,,,,,,,,,,,,,
,3879757579.27968,5.00010538101196,-2550.38061523438,1.37965260425718E-5,1.28310386094317E-8,1,4,13.4005146026611,4.99707320873854,33.2800000905991,0.0171614979349463,0.0023818949585937,1,-1.45983756789603E-7,,,,,,,,,,,,,,,,,,,,,5.00004005432129,5.00017070770264,-2550.38061523438,-2550.38061523438,53.4512754733422,5.63741565362607,2.84398603439331,52,2,68,0,0,0.29754638671875,34.2131004333496,1,1,3,5.00017070770264,0,5.00010538101196,,,,,,,,,,,,,,,,,,,,,,,,,,,,,,,,,
,3879757651.55059,4.99981999397278,-2400.40380859375,1.29396539075149E-5,1.0273610313519E-8,1,4,13.4005146026611,4.99713673411935,33.2800000905991,0.0160914138543008,0.00226413117745056,1,-1.12656301378426E-7,,,,,,,,,,,,,,,,,,,,,4.99971485137939,4.99992513656616,-2400.40380859375,-2400.40380859375,53.450493844823,5.63683557548211,2.84728860855103,54,3,0,0,1,0.297470092773438,33.7243423461914,1,1,3,4.99992513656616,0,4.99981999397278,,,,,,,,,,,,,,,,,,,,,,,,,,,,,,,,,
,3879757734.73746,5.00002551078796,-2200.36401367187,1.18668671889116E-5,1.98212082950121E-8,1,4,13.4005146026611,4.99712784297987,33.2800000905991,0.0147763313535728,0.00194911146117087,1,-2.05818110911234E-7,,,,,,,,,,,,,,,,,,,,,5.00000905990601,5.00004196166992,-2200.36401367187,-2200.36401367187,53.5306107680441,5.63702727800678,2.8464937210083,54,1,0,0,1,0.297088623046875,33.2355842590332,1,1,3,5.00000905990601,0,5.00002551078796,,,,,,,,,,,,,,,,,,,,,,,,,,,,,,,,,
,3879757807.49462,5.00008797645569,-2050.3623046875,1.09844757942731E-5,1.4536978928277E-8,1,4,13.4005146026611,4.99710735647013,33.2800000905991,0.0136707303574599,0.0018495622149494,1,-1.53964641768378E-7,,,,,,,,,,,,,,,,,,,,,5.00008010864258,5.0000958442688,-2050.3623046875,-2050.3623046875,53.5360821676787,5.63698522298627,2.843581199646,53,2,68,0,0,0.297622680664063,33.7243423461914,1,1,3,5.0000958442688,0,5.00008797645569,,,,,,,,,,,,,,,,,,,,,,,,,,,,,,,,,
,3879757878.58839,4.9998984336853,-1900.41101074219,1.01457410670282E-5,1.28713051144095E-8,1,4,13.4005146026611,4.99706521628046,33.2800000905991,0.0126239464287536,0.00172694968379079,1,-1.27204811356359E-7,,,,,,,,,,,,,,,,,,,,,4.99984741210937,4.99994945526123,-1900.41101074219,-1900.41101074219,53.4528387303807,5.63715515350722,2.83871579170227,54,3,0,0,1,0.298843383789063,34.2131004333496,1,1,3,4.99994945526123,0,4.9998984336853,,,,,,,,,,,,,,,,,,,,,,,,,,,,,,,,,
,3879757960.53619,4.99976944923401,-1700.11938476562,9.04337841959857E-6,1.8376127472745E-8,1,4,13.4005146026611,4.99711129205142,33.2800000905991,0.0112726962100722,0.00140409232626627,1,-2.22276681451382E-7,,,,,,,,,,,,,,,,,,,,,4.99966144561768,4.99987745285034,-1700.11938476562,-1700.11938476562,53.488012013746,5.63621780737453,2.8452000617981,52,1,68,0,0,0.2978515625,33.7243423461914,1,1,3,4.99966144561768,0,4.99976944923401,,,,,,,,,,,,,,,,,,,,,,,,,,,,,,,,,
,3879758031.64302,4.99999666213989,-1550.0673828125,8.19701168786524E-6,1.66049802317949E-8,1,4,13.4005146026611,4.99707562649376,33.2800000905991,0.0102124679151347,0.00130688610597842,1,-1.73924110083866E-7,,,,,,,,,,,,,,,,,,,,,4.99995899200439,5.00003433227539,-1550.0673828125,-1550.0673828125,53.4598733870537,5.63780779289195,2.84920072555542,53,2,64,0,0,0.295791625976562,33.7243423461914,1,1,3,5.00003433227539,0,4.99999666213989,,,,,,,,,,,,,,,,,,,,,,,,,,,,,,,,,
,3879758104.07452,4.99984788894653,-1400.07836914062,7.31548194117381E-6,1.29705709766758E-8,1,4,13.4005146026611,4.99703469322513,33.2800000905991,0.0091060355860479,0.00122014025306307,1,-1.11888760945008E-7,,,,,,,,,,,,,,,,,,,,,4.99979448318481,4.99990129470825,-1400.07836914062,-1400.07836914062,53.6161990908999,5.63733872188267,2.84605383872986,54,3,0,0,1,0.29815673828125,33.7243423461914,1,1,3,4.99979448318481,0,4.99984788894653,,,,,,,,,,,,,,,,,,,,,,,,,,,,,,,,,
,3879758184.97675,4.99991345405579,-1200.05090332031,6.27039574568874E-6,2.12356999815072E-8,1,4,13.4005146026611,4.99700209865445,33.2800000905991,0.00783295065221105,8.59516463830349E-4,1,-2.45919838804221E-7,,,,,,,,,,,,,,,,,,,,,4.99988460540771,4.99994230270386,-1200.05090332031,-1200.05090332031,53.4344704601787,5.63705902065148,2.84392237663269,54,1,0,0,1,0.29815673828125,33.7243423461914,1,1,3,4.99994230270386,0,4.99991345405579,,,,,,,,,,,,,,,,,,,,,,,,,,,,,,,,,
,3879758269.50064,4.99994587898254,-1050.11218261719,5.40292694317006E-6,1.47062084139498E-8,1,4,13.4005146026611,4.99697219498527,33.2800000905991,0.00673907708773694,8.0864472377297E-4,1,-1.57108914690575E-7,,,,,,,,,,,,,,,,,,,,,4.99982738494873,5.00006437301636,-1050.11218261719,-1050.11218261719,53.5091159837653,5.63647959318292,2.84590411186218,53,2,68,0,0,0.297012329101562,33.7243423461914,1,1,3,4.99982738494873,0,4.99994587898254,,,,,,,,,,,,,,,,,,,,,,,,,,,,,,,,,
,3879758364.57492,5.00004434585571,-900.123168945313,4.52366614923052E-6,9.12369782491116E-9,1,4,13.4005146026611,4.99700023880475,33.2800000905991,0.00563467112702345,7.28841712250781E-4,1,-8.98403867650709E-8,,,,,,,,,,,,,,,,,,,,,4.99996900558472,5.00011968612671,-900.123168945313,-900.123168945313,53.4895752707845,5.6360636219817,2.8468132019043,54,3,0,0,1,0.29754638671875,33.7243423461914,1,1,3,4.99996900558472,0,5.00004434585571,,,,,,,,,,,,,,,,,,,,,,,,,,,,,,,,,
,3879758443.70471,4.99988913536072,-700.058044433594,3.48844466910856E-6,2.72399006909908E-8,1,4,13.4005146026611,4.99701041602971,33.2800000905991,0.00437851488225122,3.39437994318031E-4,1,-2.48531017511577E-7,,,,,,,,,,,,,,,,,,,,,4.99975395202637,5.00002431869507,-700.058044433594,-700.058044433594,53.4985639987557,5.63735727099882,2.84930610656738,53,1,68,0,0,0.297775268554687,33.7243423461914,1,1,3,4.99975395202637,0,4.99988913536072,,,,,,,,,,,,,,,,,,,,,,,,,,,,,,,,,
,3879758514.71019,4.99999976158142,-550.131896972656,2.64624274121183E-6,1.86588927967065E-8,1,4,13.4005146026611,4.99702162201477,33.2800000905991,0.0033164726532068,2.90675865392203E-4,1,-1.61807277907029E-7,,,,,,,,,,,,,,,,,,,,,4.99994039535522,5.00005912780762,-550.131896972656,-550.131896972656,53.5224036685922,5.63604285982665,2.8442747592926,52,2,68,0,0,0.2978515625,33.7243423461914,1,1,3,5.00005912780762,0,4.99999976158142,,,,,,,,,,,,,,,,,,,,,,,,,,,,,,,,,
,3879758608.16142,5.00008893013001,-400.142852783203,1.77557125403762E-6,1.03254236467213E-8,1,4,13.4005146026611,4.99700252694912,33.2800000905991,0.00222240275033717,2.14196501948547E-4,1,-9.314100715029E-8,,,,,,,,,,,,,,,,,,,,,5.00002193450928,5.00015592575073,-400.142852783203,-400.142852783203,53.5677381227076,5.63694178849542,2.84373188018799,54,3,0,0,1,0.298004150390625,33.7243423461914,1,1,3,5.00002193450928,0,5.00008893013001,,,,,,,,,,,,,,,,,,,,,,,,,,,,,,,,,
,3879758697.29163,4.9998574256897,-200.065139770508,7.92794454675852E-7,2.61479405419742E-8,1,4,13.4005146026611,4.99703997374987,33.2800000905991,0.00103628472299333,-1.98283344875582E-4,10,-2.78255551184993E-7,,,,,,,,,,,,,,,,,,,,,4.9998459815979,4.99986886978149,-200.065139770508,-200.065139770508,53.5982216349576,5.63750683528928,2.84096622467041,54,1,0,0,1,0.297622680664063,32.7468223571777,1,1,3,4.9998459815979,0,4.9998574256897,,,,,,,,,,,,,,,,,,,,,,,,,,,,,,,,,
,3879758777.9309,4.99991226196289,-50.1516075134277,-8.27084026270796E-8,2.02434234675749E-8,1,4,13.4005146026611,4.99701221252564,33.2800000905991,-7.05390821258648E-5,-2.30465194500901E-4,1,-1.73200087137931E-7,,,,,,,,,,,,,,,,,,,,,4.99990463256836,4.99991989135742,-50.1516075134277,-50.1516075134277,53.5399903102749,5.63717633971095,2.84297490119934,54,2,0,0,1,0.296859741210937,33.7243423461914,1,1,3,4.99990463256836,0,4.99991226196289,,,,,,,,,,,,,,,,,,,,,,,,,,,,,,,,,
,3879758848.46928,5.00022578239441,99.8626251220703,-9.00258576110534E-7,8.09723284794748E-9,1,4,13.4005146026611,4.99699175655962,33.2800000905991,-0.00110080427177288,-2.82443531658077E-4,1,-9.27543683584572E-8,,,,,,,,,,,,,,,,,,,,,4.99993944168091,5.00051212310791,99.8626251220703,99.8626251220703,53.5122424978422,5.63747178809582,2.84476590156555,53,3,68,0,0,0.29754638671875,33.7243423461914,1,1,3,5.00051212310791,0,5.00022578239441,,,,,,,,,,,,,,,,,,,,,,,,,,,,,,,,,
,3879758947.17042,4.99998021125793,299.764129638672,-1.84318025769868E-6,1.83618265503729E-8,1,4,13.4005146026611,4.99721623257658,33.2800000905991,-0.00225530202263419,-5.69051406148701E-4,1,-1.82450967627001E-7,,,,,,,,,,,,,,,,,,,,,4.99974822998047,5.0002121925354,299.764129638672,299.764129638672,53.4919201563422,5.63733172695862,2.84304189682007,54,1,0,0,1,0.298004150390625,33.7243423461914,1,1,3,4.99974822998047,0,4.99998021125793,,,,,,,,,,,,,,,,,,,,,,,,,,,,,,,,,
,3879759019.48344,4.99998903274536,449.879058837891,-2.65772847208936E-6,5.92609568781742E-8,1,4,13.4005146026611,4.99720198334129,33.2800000905991,-0.00326684658787401,-7.21042045594601E-4,1,-1.82979193756044E-7,,,,,,,,,,,,,,,,,,,,,4.99986362457275,5.00011444091797,449.879058837891,449.879058837891,53.4344704601787,5.63656705045439,2.84920644760132,54,2,0,0,1,0.297393798828125,33.2355842590332,1,1,3,4.99986362457275,0,4.99998903274536,,,,,,,,,,,,,,,,,,,,,,,,,,,,,,,,,
,3879759091.47402,5.00001096725464,599.8681640625,-3.39738922550326E-6,9.36133833818932E-9,1,4,13.4005146026611,4.99716228995942,33.2800000905991,-0.00419902427137905,-7.67668883264999E-4,1,-1.09879748925185E-7,,,,,,,,,,,,,,,,,,,,,4.99999904632568,5.00002288818359,599.8681640625,599.8681640625,53.3707677358614,5.63707688225428,2.84121513366699,52,3,68,0,0,0.29632568359375,33.7243423461914,1,1,3,5.00002288818359,0,5.00001096725464,,,,,,,,,,,,,,,,,,,,,,,,,,,,,,,,,
,3879759173.90618,5.00006818771362,799.744445800781,-4.16389250167187E-6,2.04420604764918E-7,1,4,13.4005146026611,4.99713469074857,33.2800000905991,-0.00512897976827567,-0.00105696845336239,1,-2.28159115621902E-7,,,,,,,,,,,,,,,,,,,,,5.00002717971802,5.00010919570923,799.744445800781,799.744445800781,53.5298291395249,5.6371548144669,2.84117388725281,54,1,0,0,1,0.297317504882812,33.2355842590332,1,1,3,5.0001163482666,0,5.00006818771362,,,,,,,,,,,,,,,,,,,,,,,,,,,,,,,,,
,3879759259.49649,5.00000286102295,949.834167480469,-5.21242629550843E-6,1.50418389095856E-8,1,4,13.4005146026611,4.99709207416451,33.2800000905991,-0.00644810424339188,-0.00113832592710261,1,-1.36823421253103E-7,,,,,,,,,,,,,,,,,,,,,4.99990653991699,5.00009918212891,949.834167480469,949.834167480469,53.4825406141114,5.63660146361733,2.83929371833801,53,2,68,0,0,0.29815673828125,33.7243423461914,1,1,3,4.99990653991699,0,5.00000286102295,,,,,,,,,,,,,,,,,,,,,,,,,,,,,,,,,
,3879759331.01959,5.0000786781311,1099.81066894531,-6.00069589372049E-6,3.92369895286305E-8,1,4,13.4005146026611,4.99709407097257,33.2800000905991,-0.00741993178335774,-0.0013326441752055,1,-1.75365933907359E-7,,,,,,,,,,,,,,,,,,,,,4.9999213218689,5.00023603439331,1099.81066894531,1099.81066894531,53.6025205918134,5.63627678123972,2.84283328056335,54,3,0,0,1,0.296707153320313,33.2355842590332,1,1,3,4.9999213218689,0,5.0000786781311,,,,,,,,,,,,,,,,,,,,,,,,,,,,,,,,,
,3879759424.30131,4.99989151954651,1299.71215820312,-7.08851156097563E-6,1.56349686521147E-8,1,4,13.4005146026611,4.99696398610363,33.2800000905991,-0.00877098827949987,-0.00153219717311385,1,-1.73358654772046E-7,,,,,,,,,,,,,,,,,,,,,4.9998025894165,4.99998044967651,1299.71215820312,1299.71215820312,53.6115093197845,5.63669490896311,2.8441333770752,53,1,68,0,0,0.296859741210937,33.7243423461914,1,1,3,4.9998025894165,0,4.99989151954651,,,,,,,,,,,,,,,,,,,,,,,,,,,,,,,,,
,3879759512.43495,5.00007581710815,1449.814453125,-7.93053492152877E-6,8.27323221166244E-9,1,4,13.4005146026611,4.99698604223092,33.2800000905991,-0.00982626529973238,-0.00162506107015413,1,-1.22164957403849E-7,,,,,,,,,,,,,,,,,,,,,5.00002098083496,5.00013065338135,1449.814453125,1449.814453125,53.3594341223326,5.63680798572568,2.84655857086182,54,2,0,0,1,0.305252075195313,33.2355842590332,1,1,3,5.00013065338135,0,5.00007581710815,,,,,,,,,,,,,,,,,,,,,,,,,,,,,,,,,
,3879759594.95863,4.99998474121094,1599.63989257813,-8.77718149248452E-6,8.04727720226667E-9,1,4,13.4005146026611,4.99697921281738,33.2800000905991,-0.0108837576326765,-0.00174184177474831,1,-8.95481459972556E-8,,,,,,,,,,,,,,,,,,,,,4.99993371963501,5.00003576278687,1599.63989257813,1599.63989257813,53.6142450196018,5.63768445725816,2.84188723564148,54,3,0,0,1,0.296249389648438,33.2355842590332,1,1,3,5.00003576278687,0,4.99998474121094,,,,,,,,,,,,,,,,,,,,,,,,,,,,,,,,,
,3879759677.15459,5.00010418891907,1799.67980957031,-9.87494313723428E-6,7.51314205268603E-8,1,4,13.4005146026611,4.99704606202745,33.2800000905991,-0.0122478198639893,-0.0019423377849785,1,-8.67432459409508E-8,,,,,,,,,,,,,,,,,,,,,4.9999828338623,5.00022554397583,1799.67980957031,1799.67980957031,53.5181047117364,5.63621024019345,2.84132194519043,53,1,68,0,0,0.297317504882812,33.2355842590332,1,1,3,5.00022554397583,0,5.00010418891907,,,,,,,,,,,,,,,,,,,,,,,,,,,,,,,,,
,3879759749.55279,4.9999577999115,1950.03393554687,-1.07110244661834E-5,2.50936768304474E-8,1,4,13.4005146026611,4.99702485819562,33.2800000905991,-0.0132887684569816,-0.00207975756155015,1,-7.23312321232986E-8,,,,,,,,,,,,,,,,,,,,,4.9999475479126,4.9999680519104,1950.03393554687,1950.03393554687,53.4274358035057,5.63658584759989,2.84833812713623,54,2,0,0,1,0.297470092773438,33.7243423461914,1,1,3,4.9999680519104,0,4.9999577999115,,,,,,,,,,,,,,,,,,,,,,,,,,,,,,,,,
,3879759821.08554,5.00015616416931,2099.89697265625,-1.15469427023226E-5,7.04915167818718E-9,1,4,13.4005146026611,4.99704155793034,33.2899987697601,-0.0143277063706266,-0.00223019055147152,1,-6.84042465064537E-8,,,,,,,,,,,,,,,,,,,,,5.00007057189941,5.00024175643921,2099.89697265625,2099.89697265625,53.4461948879672,5.63702294758303,2.84836983680725,54,3,0,0,1,0.302352905273438,33.7243423461914,1,1,3,5.00007057189941,0,5.00015616416931,,,,,,,,,,,,,,,,,,,,,,,,,,,,,,,,,
,3879759903.13574,5.00013470649719,2299.96215820313,-1.26257812602339E-5,1.05592061389759E-8,1,4,13.4005146026611,4.99711164085826,33.2800000905991,-0.015660129782453,-0.0024822674572266,1,-1.0995043402144E-7,,,,,,,,,,,,,,,,,,,,,5.0001163482666,5.00015306472778,2299.96215820313,2299.96215820313,53.3961706627364,5.63664799487752,2.83908176422119,53,1,68,0,0,0.296096801757812,33.7243423461914,1,1,3,5.0001163482666,0,5.00013470649719,,,,,,,,,,,,,,,,,,,,,,,,,,,,,,,,,
,3879759974.87988,4.99989295005798,2449.97631835938,-1.34910330181001E-5,8.11794683898123E-9,1,4,13.4005146026611,4.99714113532854,33.2800000905991,-0.0167409803128717,-0.00260216512399222,1,-7.70368305561048E-8,,,,,,,,,,,,,,,,,,,,,4.9997730255127,5.00001287460327,2449.97631835938,2449.97631835938,53.3985155482941,5.63656757710952,2.83964705467224,53,2,68,0,0,0.298309326171875,33.2355842590332,1,1,3,4.9997730255127,0,4.99989295005798,,,,,,,,,,,,,,,,,,,,,,,,,,,,,,,,,
,3879760060.66317,4.9997935295105,2599.78930664062,-1.43343571325823E-5,8.53319267343281E-9,1,4,13.4005146026611,4.99710287529202,33.2800000905991,-0.0177897674777797,-0.00274808742285157,1,-6.83982281916101E-8,,,,,,,,,,,,,,,,,,,,,4.99969577789307,4.99989128112793,2599.78930664062,2599.78930664062,53.4665172294672,5.63596362520236,2.84393906593323,52,3,68,0,0,0.29815673828125,33.7243423461914,1,1,3,4.99989128112793,0,4.9997935295105,,,,,,,,,,,,,,,,,,,,,,,,,,,,,,,,,
,3879760143.10455,4.9999041557312,2799.89233398438,-1.54345548966998E-5,1.00631932146506E-8,1,4,13.4005146026611,4.99706766907525,33.2800000905991,-0.0191504959909927,-0.00298900666145983,1,-9.78246815324612E-8,,,,,,,,,,,,,,,,,,,,,4.99987030029297,4.99993801116943,2799.89233398438,2799.89233398438,53.3977339197749,5.63560309225923,2.84780955314636,54,1,0,0,1,0.2978515625,33.2355842590332,1,1,3,4.99987030029297,0,4.9999041557312,,,,,,,,,,,,,,,,,,,,,,,,,,,,,,,,,
,3879760214.28783,5.00001907348633,2949.85620117188,-1.6284119245605E-5,9.26256264469269E-9,1,4,13.4005146026611,4.9969906585921,33.2800000905991,-0.0202109719081322,-0.00310793282922378,1,-6.65480744264678E-8,,,,,,,,,,,,,,,,,,,,,5.00000619888306,5.0000319480896,2949.85620117188,2949.85620117188,53.6158082766403,5.63589693751971,2.84169769287109,54,2,0,0,1,0.298385620117188,32.7468223571777,1,1,3,5.00000619888306,0,5.00001907348633,,,,,,,,,,,,,,,,,,,,,,,,,,,,,,,,,
,3879760301.63257,5.00010085105896,3499.71118164063,-1.94156176491432E-5,8.03815770902874E-9,1,4,13.4005146026611,4.99699312082445,33.2800000905991,-0.0241194669796302,-0.00355966587337185,1,3.81648618550779E-8,,,,,,,,,,,,,,,,,,,,,5.00006437301636,5.00013732910156,3499.71118164063,3499.71118164063,53.4243092894287,5.63607167628297,2.8462085723877,54,3,0,0,1,0.29754638671875,33.2355842590332,1,1,3,5.00006437301636,0,5.00010085105896,,,,,,,,,,,,,,,,,,,,,,,,,,,,,,,,,
,3879760398.99651,5.00006127357483,5499.75830078125,-3.07087438866283E-5,1.24724917130409E-8,1,4,13.4005146026611,4.99696963498766,33.2800000905991,-0.0381523241301955,-0.0056035077464214,1,8.17876914751669E-8,,,,,,,,,,,,,,,,,,,,,5.00002288818359,5.00009965896606,5499.75830078125,5499.75830078125,53.4012512481114,5.63601515456528,2.83770060539246,54,1,0,0,1,0.298385620117188,33.2355842590332,1,1,3,5.00009965896606,0,5.00006127357483,,,,,,,,,,,,,,,,,,,,,,,,,,,,,,,,,
,3879760483.03427,5.00003933906555,6999.95068359375,-3.91883340394867E-5,1.43645781653112E-8,1,4,13.4005146026611,4.99704159786021,33.2800000905991,-0.0486829211269942,-0.00718682293361207,1,7.54832683572131E-8,,,,,,,,,,,,,,,,,,,,,5.0000147819519,5.0000638961792,6999.95068359375,6999.95068359375,53.4360337172172,5.63669360860137,2.8462610244751,54,2,0,0,1,0.29754638671875,33.2355842590332,1,1,3,5.0000147819519,0,5.00003933906555,,,,,,,,,,,,,,,,,,,,,,,,,,,,,,,,,
,3879760567.16523,5.00002193450928,8500.20703125,-4.77003307050382E-5,1.63426073133509E-8,1,4,13.4005146026611,4.99702946462455,33.2800000905991,-0.0592511753653112,-0.00878683451315313,1,6.04676433408762E-8,,,,,,,,,,,,,,,,,,,,,4.99988269805908,5.00016117095947,8500.20703125,8500.20703125,53.4805865428134,5.63678700181768,2.84123277664185,54,3,0,0,1,0.298385620117188,33.7243423461914,1,1,3,4.99988269805908,0,5.00002193450928,,,,,,,,,,,,,,,,,,,,,,,,,,,,,,,,,
,3879760679.37294,4.99993824958801,10000.1474609375,-5.62334680151988E-5,1.60697422987562E-8,1,4,13.4005146026611,4.99691299398308,33.2800000905991,-0.0698464552632456,-0.0103711760266518,1,6.09792841394E-8,,,,,,,,,,,,,,,,,,,,,4.99981641769409,5.00006008148193,10000.1474609375,10000.1474609375,53.6970976426403,5.63683846138772,2.84681129455566,54,1,0,0,1,0.29693603515625,33.7243423461914,1,1,3,5.00006008148193,0,4.99993824958801,,,,,,,,,,,,,,,,,,,,,,,,,,,,,,,,,
,3879760897.23889,5.00005435943604,25000.4375,-1.43462141371252E-4,5.44925697856189E-8,1,4,13.4005146026611,4.99692345028532,33.2800000905991,-0.178184814631914,-0.0265066034767115,1,1.17154125749695E-7,,,,,,,,,,,,,,,,,,,,,4.99989414215088,5.00021457672119,25000.4375,25000.4375,53.8245030912749,5.63649457932335,2.83795237541199,54,2,0,0,1,0.298309326171875,33.7243423461914,1,1,3,4.99989414215088,0,5.00005435943604,,,,,,,,,,,,,,,,,,,,,,,,,,,,,,,,,
,3879761117.922,5.00003719329834,40000.4921875,-2.33394127687386E-4,4.5529594229814E-8,1,4,13.4005146026611,4.99678073699244,33.2800000905991,-0.289861011367902,-0.0431930371802466,1,1.32626070427337E-7,,,,,,,,,,,,,,,,,,,,,5.00001192092895,5.00006246566772,40000.4921875,40000.4921875,53.9542534254672,5.63767217633652,2.84093952178955,54,3,0,0,1,0.298080444335937,33.2355842590332,1,1,3,5.00001192092895,0,5.00003719329834,,,,,,,,,,,,,,,,,,,,,,,,,,,,,,,,,
,3879761398.66701,4.9998345375061,60000.484375,-3.55564112727876E-4,9.98999926340162E-8,1,4,13.4005146026611,4.99682196679806,33.2800000905991,-0.441586787154068,-0.0658490188790573,1,1.65121988061318E-7,,,,,,,,,,,,,,,,,,,,,4.99954080581665,5.00012826919556,60000.484375,60000.484375,54.2774568181692,5.6389547629305,2.84096908569336,54,1,0,0,1,0.298309326171875,33.7243423461914,1,1,3,4.99954080581665,0,4.9998345375061,,,,,,,,,,,,,,,,,,,,,,,,,,,,,,,,,
,3879761565.01644,5.00012254714966,70000.4140625,-4.17114035377812E-4,1.79193007932769E-7,1,4,13.4005146026611,4.99701340483476,33.2800000905991,-0.518037893604597,-0.0773693396427993,1,9.91875483801309E-8,,,,,,,,,,,,,,,,,,,,,4.99969625473022,5.00054883956909,70000.4140625,70000.4140625,54.6944556331789,5.6405977541243,2.83935785293579,54,3,0,0,1,0.298004150390625,33.2355842590332,1,1,3,4.99969625473022,0,5.00012254714966,,,,,,,,,,,,,,,,,,,,,,,,,,,,,,,,,