File: SQUID/Reference/STO/B1/STOsubs_MH_100K_FC_0d5T.csv
Comment,Time Stamp (sec),Temperature (K),Magnetic Field (Oe),Moment (emu),M. Std. Err. (emu),Transport Action,Averaging Time (sec),Frequency (Hz),Peak Amplitude (mm),Center Position (mm),Lockin Signal' (V),Lockin Signal (V),Range,M. Quad. Signal (emu),AC Moment (emu),AC M. Std Err. (emu),AC Phase (deg),AC Phase Std. Err. (deg),AC Susceptibility (emu/Oe),AC Suscept. Std Err. (emu/Oe),AC X' (emu/Oe),AC X' Std Err. (emu/Oe),AC X'' (emu/Oe),AC X'' Std Err. (emu/Oe),AC Drive (Oe),AC Frequency (Hz),AC Averaging Time (sec),AC Cycles,AC Range,AC Measure Type,AC Signal' (V),AC Signal'' (V),AC Trim Coil Ratio,AC Trim Coil Phase,Min. Temperature (K),Max. Temperature (K),Min. Field (Oe),Max. Field (Oe),Mass (grams),Motor Lag (deg),Pressure (Torr),Measure Count,Measurement Number,SQUID Status (code),Motor Status (code),Measure Status (code),Motor Current (amps),Motor Temp. (C),Temp. Status (code),Field Status (code),Chamber Status (code),Chamber Temp (K),Redirection State,Average Temp (K),Rotation Angle (deg),Rotator state,DC Moment Fixed Ctr (emu),DC Moment Err Fixed Ctr (emu),DC Moment Free Ctr (emu),DC Moment Err Free Ctr (emu),DC Fixed Fit,DC Free Fit,DC Calculated Center (mm),DC Calculated Center Err (mm),DC Scan Length (mm),DC Scan Time (s),DC Number of Points,DC Squid Drift,DC Min V (V),DC Max V (V),DC Scans per Measure,Sample Resistance,He3 Temperature,Sorb Resistance,Sorb Temperature,Map 05,Map 06,Map 07,Map 08,Map 09,Map 10,Map 11,Map 12,Map 13,Map 14,Map 15,Map 16
,3879790082.61182,100.00626373291,69999.75,-4.34059059478134E-4,1.04533558166549E-7,1,4,13.4005146026611,4.99540148005964,33.3000011742115,-0.538867589555984,-0.0802875807665857,1,2.55050014199345E-7,,,,,,,,,,,,,,,,,,,,,100.006240844727,100.006286621094,69999.75,69999.75,53.1620729212268,5.64287409083244,4.87491941452026,54,1,0,0,1,0.2984619140625,32.2580642700195,1,1,3,100.006240844727,0,100.00626373291,,,,,,,,,,,,,,,,,,,,,,,,,,,,,,,,,
,3879790325.4268,100.061473846436,54999.64453125,-3.40744360054376E-4,8.35411218242219E-8,1,4,13.4005146026611,4.99492162513129,33.3000011742115,-0.422966239930919,-0.0630042864788229,1,2.11872721192931E-7,,,,,,,,,,,,,,,,,,,,,100.056411743164,100.066535949707,54999.64453125,54999.64453125,53.425090917948,5.64329394212859,4.8880181312561,54,2,0,0,1,0.29998779296875,33.7243423461914,1,1,3,100.066535949707,0,100.061473846436,,,,,,,,,,,,,,,,,,,,,,,,,,,,,,,,,
,3879790569.84039,100.056491851807,39999.55859375,-2.47647804505325E-4,4.78410778238597E-8,1,4,13.4005146026611,4.99473829074151,33.3000011742115,-0.307414434779466,-0.0456222491082854,1,2.87696727115641E-7,,,,,,,,,,,,,,,,,,,,,100.056449890137,100.056533813477,39999.55859375,39999.55859375,53.467689672246,5.64453888560829,4.8842658996582,54,3,0,0,1,0.300979614257812,34.2131004333496,1,1,3,100.056449890137,0,100.056491851807,,,,,,,,,,,,,,,,,,,,,,,,,,,,,,,,,
,3879790851.04921,100.064212799072,19999.666015625,-1.23428175618324E-4,2.20168342472673E-8,1,4,13.4005146026611,4.99471935714181,33.3000011742115,-0.153197004802478,-0.0228595569384253,1,4.55292225085052E-8,,,,,,,,,,,,,,,,,,,,,100.053062438965,100.07536315918,19999.666015625,19999.666015625,53.4477581450057,5.64356478477616,4.90128040313721,54,1,0,0,1,0.3009033203125,34.2131004333496,1,1,3,100.07536315918,0,100.064212799072,,,,,,,,,,,,,,,,,,,,,,,,,,,,,,,,,
,3879791040.71272,100.104816436768,9999.7197265625,-6.13932780309835E-5,1.26623205499101E-8,1,4,13.4005146026611,4.99491733589655,33.3000011742115,-0.0762159955038744,-0.0112944779929334,1,8.42939192528073E-8,,,,,,,,,,,,,,,,,,,,,100.103630065918,100.106002807617,9999.7197265625,9999.7197265625,53.4653447866883,5.64212842596989,4.90294122695923,54,2,0,0,1,0.29937744140625,34.2131004333496,1,1,3,100.103630065918,0,100.104816436768,,,,,,,,,,,,,,,,,,,,,,,,,,,,,,,,,
,3879791126.50352,100.049892425537,8499.703125,-5.20800903384531E-5,1.17858915730579E-8,1,4,13.4005146026611,4.9949610599538,33.3000011742115,-0.0646515222243459,-0.00960474329098178,1,5.25828191163848E-8,,,,,,,,,,,,,,,,,,,,,100.047813415527,100.051971435547,8499.703125,8499.703125,53.503253769871,5.64308813381777,4.89847421646118,54,3,0,0,1,0.30120849609375,34.7018585205078,1,1,3,100.047813415527,0,100.049892425537,,,,,,,,,,,,,,,,,,,,,,,,,,,,,,,,,
,3879791228.10284,100.030002593994,6499.76904296875,-3.96661532352039E-5,2.35869105995365E-8,1,4,13.4005146026611,4.99498924413756,33.3000011742115,-0.0492345915365305,-0.00736101887174994,1,3.28830916550591E-9,,,,,,,,,,,,,,,,,,,,,100.028594970703,100.031410217285,6499.76904296875,6499.76904296875,53.5091159837653,5.64296687502324,4.90831613540649,54,1,0,0,1,0.29998779296875,34.7018585205078,1,1,3,100.028594970703,0,100.030002593994,,,,,,,,,,,,,,,,,,,,,,,,,,,,,,,,,
,3879791314.32605,100.044033050537,4999.765625,-3.03564343790017E-5,8.57884511500344E-9,1,4,13.4005146026611,4.99497082122823,33.3099998533726,-0.0376807219872218,-0.00562148667006286,1,1.20705638770657E-8,,,,,,,,,,,,,,,,,,,,,100.041885375977,100.046180725098,4999.765625,4999.765625,53.6052562916307,5.64338692357374,4.90395784378052,53,2,68,0,0,0.300216674804687,34.2131004333496,1,1,3,100.041885375977,0,100.044033050537,,,,,,,,,,,,,,,,,,,,,,,,,,,,,,,,,
,3879791400.31825,100.10835647583,3499.509765625,-2.10646179930675E-5,6.64918670993241E-9,1,4,13.4005146026611,4.99494931716761,33.3000011742115,-0.0261487671100877,-0.00388798428015155,1,1.86846254942895E-8,,,,,,,,,,,,,,,,,,,,,100.107902526855,100.108810424805,3499.509765625,3499.509765625,53.4348612744383,5.64317117787589,4.90661382675171,54,3,0,0,1,0.300979614257812,34.2131004333496,1,1,3,100.108810424805,0,100.10835647583,,,,,,,,,,,,,,,,,,,,,,,,,,,,,,,,,
,3879791506.72322,100.0612449646,2899.7548828125,-1.74419137387355E-5,1.47436539124755E-8,1,4,13.4005146026611,4.99497111405393,33.3000011742115,-0.0216904262868681,-0.00296127571300889,1,2.23391068810489E-7,,,,,,,,,,,,,,,,,,,,,100.053802490234,100.068687438965,2899.7548828125,2899.7548828125,53.5052078411691,5.64336529353048,4.89314603805542,54,1,0,0,1,0.298919677734375,34.2131004333496,1,1,3,100.068687438965,0,100.0612449646,,,,,,,,,,,,,,,,,,,,,,,,,,,,,,,,,
,3879791578.83914,100.072784423828,2749.63989257813,-1.64996744753379E-5,1.1016361158044E-8,1,4,13.4005146026611,4.99490445923349,33.3099998533726,-0.0205072749349332,-0.00287489900829338,1,1.51985729110358E-7,,,,,,,,,,,,,,,,,,,,,100.07007598877,100.075492858887,2749.63989257813,2749.63989257813,53.607991991448,5.64430480689791,4.88857650756836,54,2,0,0,1,0.300140380859375,34.2131004333496,1,1,3,100.075492858887,0,100.072784423828,,,,,,,,,,,,,,,,,,,,,,,,,,,,,,,,,
,3879791652.99297,100.099876403809,2599.7265625,-1.55551693873219E-5,9.96931367148521E-9,1,4,13.4005146026611,4.99495723233238,33.3099998533726,-0.0193303446978536,-0.00273243333633457,1,1.25508664120555E-7,,,,,,,,,,,,,,,,,,,,,100.098114013672,100.101638793945,2599.7265625,2599.7265625,53.452447916121,5.64392310173228,4.89533472061157,53,3,68,0,0,0.3009033203125,34.2131004333496,1,1,3,100.098114013672,0,100.099876403809,,,,,,,,,,,,,,,,,,,,,,,,,,,,,,,,,
,3879791736.9712,100.080772399902,2399.52270507813,-1.43596915089993E-5,1.58089661366317E-8,1,4,13.4005146026611,4.99496449619963,33.3000011742115,-0.0178632207591106,-0.00239907162429739,1,2.15257139672352E-7,,,,,,,,,,,,,,,,,,,,,100.078895568848,100.082649230957,2399.52270507813,2399.52270507813,53.4731610718807,5.64382074327297,4.89953899383545,54,1,0,0,1,0.29998779296875,34.2131004333496,1,1,3,100.082649230957,0,100.080772399902,,,,,,,,,,,,,,,,,,,,,,,,,,,,,,,,,
,3879791823.21467,100.020156860352,2249.53369140625,-1.34190687299346E-5,1.25854142655156E-8,1,4,13.4005146026611,4.99492667833473,33.3000011742115,-0.0166878493562642,-0.00227582380375974,1,1.73823610147429E-7,,,,,,,,,,,,,,,,,,,,,100.019248962402,100.021064758301,2249.53369140625,2249.53369140625,53.4602642013134,5.64399174638905,4.90398168563843,52,2,68,0,0,0.300521850585937,34.2131004333496,1,1,3,100.019248962402,0,100.020156860352,,,,,,,,,,,,,,,,,,,,,,,,,,,,,,,,,
,3879791894.91046,100.16227722168,2099.60766601562,-1.24640126798746E-5,1.07161937919677E-8,1,4,13.4005146026611,4.9948771943887,33.3000011742115,-0.0154933431203049,-0.0021578791344366,1,1.25954680407854E-7,,,,,,,,,,,,,,,,,,,,,100.159675598145,100.164878845215,2099.60766601562,2099.60766601562,53.4411143025922,5.64431029586857,4.91750288009644,52,3,68,0,0,0.2996826171875,33.7243423461914,1,1,3,100.164878845215,0,100.16227722168,,,,,,,,,,,,,,,,,,,,,,,,,,,,,,,,,
,3879791987.42259,100.140480041504,1899.73132324219,-1.12302768622985E-5,9.780468639921E-9,1,4,13.4005146026611,4.99492546411113,33.3000011742115,-0.0139573920466138,-0.00196135279341218,1,9.97563898504917E-8,,,,,,,,,,,,,,,,,,,,,100.133949279785,100.147010803223,1899.73132324219,1899.73132324219,53.5431168243518,5.64368395336426,4.9196310043335,54,1,0,0,1,0.302276611328125,34.2131004333496,1,1,3,100.133949279785,0,100.140480041504,,,,,,,,,,,,,,,,,,,,,,,,,,,,,,,,,
,3879792061.37416,100.097278594971,1749.7421875,-1.0319259374349E-5,1.51344078758956E-8,1,4,13.4005146026611,4.99495003238231,33.3099998533726,-0.0128362635592748,-0.00172853452536122,1,1.51060536834763E-7,,,,,,,,,,,,,,,,,,,,,100.096305847168,100.098251342773,1749.7421875,1749.7421875,53.6513723742653,5.64392164499739,4.92441606521606,54,2,0,0,1,0.300521850585937,34.2131004333496,1,1,3,100.098251342773,0,100.097278594971,,,,,,,,,,,,,,,,,,,,,,,,,,,,,,,,,
,3879792146.75453,100.098274230957,1599.85388183594,-9.38665563719353E-6,1.15841208462427E-8,1,4,13.4005146026611,4.9949643989087,33.3099998533726,-0.0116741427495301,-0.001586293549363,1,1.26153913036489E-7,,,,,,,,,,,,,,,,,,,,,100.093925476074,100.10262298584,1599.85388183594,1599.85388183594,53.6584070309384,5.64425437465229,4.92838478088379,53,3,68,0,0,0.3009033203125,34.2131004333496,1,1,3,100.093925476074,0,100.098274230957,,,,,,,,,,,,,,,,,,,,,,,,,,,,,,,,,
,3879792241.7352,100.114025115967,1399.763671875,-8.21181776673745E-6,2.46742844632882E-8,1,4,13.4005146026611,4.99495105763781,33.3000011742115,-0.0102404252020449,-0.0012041740832224,1,2.58264647647059E-7,,,,,,,,,,,,,,,,,,,,,100.102554321289,100.125495910645,1399.763671875,1399.763671875,53.4895752707845,5.6439294142922,4.92481136322022,54,1,0,0,1,0.298995971679687,34.2131004333496,1,1,3,100.125495910645,0,100.114025115967,,,,,,,,,,,,,,,,,,,,,,,,,,,,,,,,,
,3879792330.08458,100.057445526123,1249.560546875,-7.23135764371868E-6,1.15152516980689E-8,1,4,13.4005146026611,4.99490576263293,33.3099998533726,-0.00900410095939792,-0.0011509085028673,10,1.54496810034098E-7,,,,,,,,,,,,,,,,,,,,,100.056838989258,100.058052062988,1249.560546875,1249.560546875,53.536863796198,5.64373308089092,4.92889642715454,54,2,0,0,1,0.299530029296875,33.7243423461914,1,1,3,100.056709289551,0,100.057445526123,,,,,,,,,,,,,,,,,,,,,,,,,,,,,,,,,
,3879792442.56827,100.024421691895,1099.78540039062,-6.28787856544743E-6,1.09644359021986E-8,1,4,13.4005146026611,4.99499663013773,33.3000011742115,-0.00782144591123694,-0.00105481869081019,1,9.07979278806781E-8,,,,,,,,,,,,,,,,,,,,,100.024078369141,100.024765014648,1099.78540039062,1099.78540039062,53.4672988579864,5.64449161878337,4.93059015274048,54,3,0,0,1,0.300521850585937,33.7243423461914,1,1,3,100.023719787598,0,100.024421691895,,,,,,,,,,,,,,,,,,,,,,,,,,,,,,,,,
,3879792557.56074,100.045585632324,899.934326171875,-5.12698637308709E-6,2.33411560682455E-8,1,4,13.4005146026611,4.99493703177798,33.3099998533726,-0.00641126948897099,-6.3307560560898E-4,1,2.56910516821267E-7,,,,,,,,,,,,,,,,,,,,,100.044509887695,100.046661376953,899.934326171875,899.934326171875,53.4325163888806,5.64374744597704,4.94444751739502,53,1,68,0,0,0.300979614257812,33.7243423461914,1,1,3,100.046661376953,0,100.045585632324,,,,,,,,,,,,,,,,,,,,,,,,,,,,,,,,,
,3879792655.80949,100.048393249512,749.76904296875,-4.17898142947845E-6,1.63356343970407E-8,1,4,13.4005146026611,4.99489802413605,33.3000011742115,-0.00521891954781743,-5.61585149784532E-4,1,1.72688151916658E-7,,,,,,,,,,,,,,,,,,,,,100.048034667969,100.048751831055,749.76904296875,749.76904296875,53.6091644342268,5.64483700689572,4.94330072402954,53,2,68,0,0,0.300674438476562,34.2131004333496,1,1,3,100.048034667969,0,100.048393249512,,,,,,,,,,,,,,,,,,,,,,,,,,,,,,,,,
,3879792752.69643,100.165412902832,600.019165039063,-3.24253335928745E-6,1.04946091125822E-8,1,4,13.4005146026611,4.99489197501959,33.3000011742115,-0.00404193476918794,-4.85844152455763E-4,1,9.36241443321298E-8,,,,,,,,,,,,,,,,,,,,,100.164756774902,100.166069030762,600.019165039063,600.019165039063,53.5661748656691,5.64430178385329,4.95019245147705,54,3,0,0,1,0.300064086914063,34.2131004333496,1,1,3,100.164756774902,0,100.165412902832,,,,,,,,,,,,,,,,,,,,,,,,,,,,,,,,,
,3879792866.67257,100.117153167725,400.029571533203,-2.08713499037823E-6,2.58750589084147E-8,1,4,13.4005146026611,4.99493891167908,33.3000011742115,-0.00263851078984649,-6.68134939694262E-5,1,2.58392409125025E-7,,,,,,,,,,,,,,,,,,,,,100.108589172363,100.125717163086,400.029571533203,400.029571533203,53.4055502049672,5.64418811330698,4.9526834487915,52,1,68,0,0,0.300369262695313,34.2131004333496,1,1,3,100.125717163086,0,100.117153167725,,,,,,,,,,,,,,,,,,,,,,,,,,,,,,,,,
,3879792979.84036,100.132476806641,249.927200317383,-1.1680725552335E-6,1.58215058761733E-8,1,4,13.4005146026611,4.99487250203068,33.3000011742115,-0.0014752176580402,-4.67960826332912E-5,10,1.370332055726E-7,,,,,,,,,,,,,,,,,,,,,100.130989074707,100.133964538574,249.927200317383,249.927200317383,53.4653447866883,5.64482231599701,4.95599365234375,54,2,0,0,1,0.30120849609375,33.7243423461914,1,1,3,100.130989074707,0,100.132476806641,,,,,,,,,,,,,,,,,,,,,,,,,,,,,,,,,
,3879793091.6597,100.085983276367,100.089218139648,-2.48018416941543E-7,1.34926277482013E-8,1,4,13.4005146026611,4.99507194097475,33.3000011742115,-3.2574669588976E-4,7.35841766968029E-5,1,9.63849354370492E-8,,,,,,,,,,,,,,,,,,,,,100.085304260254,100.08666229248,100.089218139648,100.089218139648,53.5259209969287,5.64366700308293,4.94875812530518,54,3,0,0,1,0.30029296875,33.7243423461914,1,1,3,100.085304260254,0,100.085983276367,,,,,,,,,,,,,,,,,,,,,,,,,,,,,,,,,
,3879793206.1692,100.099987030029,-99.9381561279297,7.65993256067919E-7,4.04848546726201E-8,1,4,13.4005146026611,4.99494550813737,33.3000011742115,9.00916098432917E-4,4.75326755362589E-4,10,2.68371512588447E-7,,,,,,,,,,,,,,,,,,,,,100.097518920898,100.10245513916,-99.9381561279297,-99.9381561279297,53.4172746327557,5.64417513890895,4.95514965057373,54,1,0,0,1,0.29998779296875,33.7243423461914,1,1,3,100.10245513916,0,100.099987030029,,,,,,,,,,,,,,,,,,,,,,,,,,,,,,,,,
,3879793310.05729,100.073390960693,-249.90202331543,1.61633748827513E-6,2.29486487240371E-8,1,4,13.4005146026611,4.9949700634171,33.3000011742115,0.00197139429208687,5.32794335141763E-4,1,1.87462549709227E-7,,,,,,,,,,,,,,,,,,,,,100.067733764648,100.079048156738,-249.90202331543,-249.90202331543,53.4731610718807,5.64357706116224,4.95646572113037,54,2,0,0,1,0.299224853515625,33.2355842590332,1,1,3,100.079048156738,0,100.073390960693,,,,,,,,,,,,,,,,,,,,,,,,,,,,,,,,,
,3879793411.08198,100.112056732178,-399.840728759766,2.50223442169635E-6,7.55976009397539E-9,1,4,13.4005146026611,4.99498345832581,33.3000011742115,0.00309379872304416,5.4476939480941E-4,1,6.45841281047756E-8,,,,,,,,,,,,,,,,,,,,,100.111358642578,100.112754821777,-399.840728759766,-399.840728759766,53.4059410192268,5.64351893811745,4.95445394515991,54,3,0,0,1,0.300674438476562,34.2131004333496,1,1,3,100.111358642578,0,100.112056732178,,,,,,,,,,,,,,,,,,,,,,,,,,,,,,,,,
,3879793528.81055,100.017570495605,-599.792602539063,3.61060166231386E-6,1.59514498713103E-8,1,4,13.4005146026611,4.99517699726003,33.3000011742115,0.00444246599313911,9.33024220922895E-4,1,2.11542711780341E-7,,,,,,,,,,,,,,,,,,,,,100.016532897949,100.018608093262,-599.792602539063,-599.792602539063,53.3926533343999,5.64440393574424,4.95674657821655,54,1,0,0,1,0.299072265625,33.7243423461914,1,1,3,100.016532897949,0,100.017570495605,,,,,,,,,,,,,,,,,,,,,,,,,,,,,,,,,
,3879793635.26754,100.082637786865,-749.76904296875,4.50096691055721E-6,1.29315719731408E-8,1,4,13.4005146026611,4.99512497961915,33.3099998533726,0.00556636803846313,9.72693631129043E-4,10,1.10319602758003E-7,,,,,,,,,,,,,,,,,,,,,100.082405090332,100.082870483398,-749.76904296875,-749.76904296875,53.4278266177653,5.64420596151015,4.9557614326477,54,2,0,0,1,0.299606323242188,33.7243423461914,1,1,3,100.082405090332,0,100.082637786865,,,,,,,,,,,,,,,,,,,,,,,,,,,,,,,,,
,3879793725.6524,100.154838562012,-899.695129394531,5.41776903627511E-6,1.62396564952075E-8,1,4,13.4005146026611,4.99505610951849,33.3099998533726,0.00671134931445435,0.00109528163340477,1,7.19499389303052E-8,,,,,,,,,,,,,,,,,,,,,100.151344299316,100.158332824707,-899.695129394531,-899.695129394531,53.531783210823,5.64383162822598,4.95847034454346,54,3,0,0,1,0.300445556640625,35.190616607666,1,1,3,100.151344299316,0,100.154838562012,,,,,,,,,,,,,,,,,,,,,,,,,,,,,,,,,
,3879793834.24618,100.041233062744,-1099.7099609375,6.42051888028104E-6,2.22751795577189E-7,1,4,13.4005146026611,4.99504361920312,33.3099998533726,0.00795135185081599,0.00131231815193122,1,9.68041442184233E-8,,,,,,,,,,,,,,,,,,,,,100.03849029541,100.043975830078,-1099.7099609375,-1099.7099609375,53.4442408166691,5.64432842339534,4.95946502685547,54,1,0,0,1,0.299835205078125,33.7243423461914,1,1,3,100.03849029541,0,100.041233062744,,,,,,,,,,,,,,,,,,,,,,,,,,,,,,,,,
,3879793936.9838,100.122898101807,-1249.64868164062,7.50256292687041E-6,3.56792068594616E-8,1,4,13.4005146026611,4.99501059051219,33.3099998533726,0.00929423968301903,0.00151381458724056,10,9.72847012742156E-8,,,,,,,,,,,,,,,,,,,,,100.122337341309,100.123458862305,-1249.64868164062,-1249.64868164062,53.6310500327653,5.64394299862279,4.95971918106079,54,2,0,0,1,0.29998779296875,33.7243423461914,1,1,3,100.123458862305,0,100.122898101807,,,,,,,,,,,,,,,,,,,,,,,,,,,,,,,,,
,3879794034.85535,100.088836669922,-1399.61254882812,8.46495311171747E-6,6.08945763704951E-9,1,4,13.4005146026611,4.99501172342091,33.3099998533726,0.0104956662029235,0.00164646001692148,1,6.01839316169083E-8,,,,,,,,,,,,,,,,,,,,,100.088623046875,100.089050292969,-1399.61254882812,-1399.61254882812,53.618153162198,5.64435255939297,4.96116304397583,54,3,0,0,1,0.30029296875,34.2131004333496,1,1,3,100.088478088379,0,100.088836669922,,,,,,,,,,,,,,,,,,,,,,,,,,,,,,,,,
,3879794148.71948,100.03572845459,-1599.70288085938,9.64320904331916E-6,1.61894890728459E-8,1,4,13.4005146026611,4.99501201487274,33.3099998533726,0.0119450979959601,0.00195240689981105,1,1.30413473746271E-7,,,,,,,,,,,,,,,,,,,,,100.033279418945,100.038177490234,-1599.70288085938,-1599.70288085938,53.4665172294672,5.6434965312515,4.96001958847046,53,1,68,0,0,0.300674438476562,33.7243423461914,1,1,3,100.033279418945,0,100.03572845459,,,,,,,,,,,,,,,,,,,,,,,,,,,,,,,,,
,3879794221.22814,100.009750366211,-1749.54077148438,1.05607504276859E-5,2.95728813500695E-8,1,4,13.4005146026611,4.99499144553611,33.3199985325336,0.0130929920651594,0.00206191909687494,1,8.13942243996216E-8,,,,,,,,,,,,,,,,,,,,,100.009483337402,100.01001739502,-1749.54077148438,-1749.54077148438,53.488012013746,5.64450161877765,4.96494054794312,54,2,0,0,1,0.300521850585937,33.2355842590332,1,1,3,100.009452819824,0,100.009750366211,,,,,,,,,,,,,,,,,,,,,,,,,,,,,,,,,
,3879794294.75848,100.061393737793,-1899.83203125,1.15504369554767E-5,3.62723314946693E-8,1,4,13.4005146026611,4.99495121249911,33.3099998533726,0.0143276631687082,0.00220271167611409,1,4.67949846928524E-8,,,,,,,,,,,,,,,,,,,,,100.060401916504,100.062385559082,-1899.83203125,-1899.83203125,53.5388178674961,5.64439230379794,4.96701335906982,54,3,0,0,1,0.299835205078125,33.2355842590332,1,1,3,100.062385559082,0,100.061393737793,,,,,,,,,,,,,,,,,,,,,,,,,,,,,,,,,
,3879794376.80116,100.115863800049,-2099.64526367187,1.27808374853613E-5,7.0100168429485E-8,1,4,13.4005146026611,4.99488807891527,33.3099998533726,0.0158297990848082,0.00259657927509468,1,1.8010086514766E-7,,,,,,,,,,,,,,,,,,,,,100.115142822266,100.116584777832,-2099.64526367187,-2099.64526367187,53.4106307903422,5.64473938536507,4.96463823318481,53,1,68,0,0,0.300674438476562,33.7243423461914,1,1,3,100.116584777832,0,100.115863800049,,,,,,,,,,,,,,,,,,,,,,,,,,,,,,,,,
,3879794448.76018,100.075836181641,-2249.77294921875,1.36719210126153E-5,6.74886260459262E-9,1,4,13.4005146026611,4.99490367271177,33.3099998533726,0.0169528478691076,0.00264849756760345,1,8.86209252592893E-8,,,,,,,,,,,,,,,,,,,,,100.07292175293,100.078750610352,-2249.77294921875,-2249.77294921875,53.2726733566979,5.64454719558288,4.96177101135254,53,2,68,0,0,0.300521850585937,33.7243423461914,1,1,3,100.07292175293,0,100.075836181641,,,,,,,,,,,,,,,,,,,,,,,,,,,,,,,,,
,3879794534.41471,100.105937957764,-2399.68627929687,1.45962833206367E-5,5.5527239394486E-9,1,4,13.4005146026611,4.99500677430738,33.3099998533726,0.0181055057245889,0.00278788442389678,1,6.2579050592918E-8,,,,,,,,,,,,,,,,,,,,,100.10285949707,100.109016418457,-2399.68627929687,-2399.68627929687,53.3574800510345,5.64455672254204,4.96484708786011,54,3,0,0,1,0.302505493164063,33.7243423461914,1,1,3,100.109016418457,0,100.105937957764,,,,,,,,,,,,,,,,,,,,,,,,,,,,,,,,,
,3879794616.80659,100.053844451904,-2599.61328125,1.5794863398113E-5,9.61008576593749E-9,1,4,13.4005146026611,4.99488935636057,33.3099998533726,0.019584386200328,0.00306494967969372,1,1.06581163659703E-7,,,,,,,,,,,,,,,,,,,,,100.051986694336,100.055702209473,-2599.61328125,-2599.61328125,53.3918717058807,5.64522127643972,4.96900653839111,54,1,0,0,1,0.2996826171875,33.7243423461914,1,1,3,100.051986694336,0,100.053844451904,,,,,,,,,,,,,,,,,,,,,,,,,,,,,,,,,
,3879794688.58097,100.064655303955,-2749.71557617187,1.6755989839989E-5,8.74698511498208E-9,1,4,13.4005146026611,4.99494551482096,33.3099998533726,0.0207838947047369,0.00320163466698985,1,7.28875022110709E-8,,,,,,,,,,,,,,,,,,,,,100.06201171875,100.06729888916,-2749.71557617187,-2749.71557617187,53.5212312258134,5.64523248830756,4.96618127822876,52,2,68,0,0,0.300064086914063,33.7243423461914,1,1,3,100.067390441895,0,100.064655303955,,,,,,,,,,,,,,,,,,,,,,,,,,,,,,,,,
,3879794760.48436,100.034976959229,-2899.61645507812,1.76637070529597E-5,8.48273478578522E-9,1,4,13.4005146026611,4.99501488527371,33.3099998533726,0.0219116698718765,0.00336558708657459,1,6.91383917445291E-8,,,,,,,,,,,,,,,,,,,,,100.034141540527,100.03581237793,-2899.61645507812,-2899.61645507812,53.4848854996691,5.64405217732695,4.9700083732605,53,3,64,0,0,0.300216674804687,32.7468223571777,1,1,3,100.034141540527,0,100.034976959229,,,,,,,,,,,,,,,,,,,,,,,,,,,,,,,,,
,3879794864.11447,100.129627227783,-3499.8369140625,2.14104230581712E-5,8.30676237278994E-9,1,4,13.4005146026611,4.99496755908951,33.3199985325336,0.0265820941901477,0.00392560904119556,1,-4.01177748188199E-8,,,,,,,,,,,,,,,,,,,,,100.125289916992,100.133964538574,-3499.8369140625,-3499.8369140625,53.4485397735249,5.64467675580573,4.96594905853271,54,1,0,0,1,0.30303955078125,33.2355842590332,1,1,3,100.133964538574,0,100.129627227783,,,,,,,,,,,,,,,,,,,,,,,,,,,,,,,,,
,3879794948.02092,100.136516571045,-4999.7529296875,3.0671938876539E-5,7.57444604958992E-9,1,4,13.4005146026611,4.99491205725824,33.3099998533726,0.0380791422147747,0.00563022259870692,1,-5.21550691396916E-8,,,,,,,,,,,,,,,,,,,,,100.132331848145,100.140701293945,-4999.7529296875,-4999.7529296875,53.5294383252653,5.64474174246556,4.96535062789917,54,2,0,0,1,0.300750732421875,33.7243423461914,1,1,3,100.140701293945,0,100.136516571045,,,,,,,,,,,,,,,,,,,,,,,,,,,,,,,,,
,3879795031.89217,100.130947113037,-6499.76904296875,3.99535442446985E-5,9.19919121373488E-9,1,4,13.4005146026611,4.99497507789263,33.3099998533726,0.0495981888566788,0.00736700958015893,1,-4.14301463197577E-8,,,,,,,,,,,,,,,,,,,,,100.130615234375,100.131278991699,-6499.76904296875,-6499.76904296875,53.552105552323,5.64410348690954,4.96633338928223,52,3,68,0,0,0.29998779296875,33.2355842590332,1,1,3,100.131278991699,0,100.130947113037,,,,,,,,,,,,,,,,,,,,,,,,,,,,,,,,,
,3879795131.5729,100.139961242676,-8499.615234375,5.23345295983771E-5,1.15552853100677E-8,1,4,13.4005146026611,4.99490628991868,33.3099998533726,0.0649752901598715,0.00959196996913098,1,-1.00817792926391E-7,,,,,,,,,,,,,,,,,,,,,100.134254455566,100.145668029785,-8499.615234375,-8499.615234375,53.4864487567076,5.64429483044883,4.96609926223755,54,1,0,0,1,0.30120849609375,32.7468223571777,1,1,3,100.132690429688,0,100.139961242676,,,,,,,,,,,,,,,,,,,,,,,,,,,,,,,,,
,3879795215.74199,100.182300567627,-9999.53125,6.16181368241845E-5,1.1000105352322E-8,1,4,13.4005146026611,4.99491308551932,33.3199985325336,0.0764961608421169,0.0113284243020511,1,-9.05705872241521E-8,,,,,,,,,,,,,,,,,,,,,100.173515319824,100.19108581543,-9999.53125,-9999.53125,53.4594825727941,5.645194714288,4.96145629882812,54,2,0,0,1,0.300979614257812,33.7243423461914,1,1,3,100.19108581543,0,100.182300567627,,,,,,,,,,,,,,,,,,,,,,,,,,,,,,,,,
,3879795403.87006,100.082824707031,-19999.62890625,1.23592295410671E-4,1.95470039514178E-8,1,4,13.4005146026611,4.99490279435348,33.3099998533726,0.153420434053279,0.0228120133260508,1,-1.09333161342315E-7,,,,,,,,,,,,,,,,,,,,,100.078308105469,100.087341308594,-19999.62890625,-19999.62890625,53.3477096945441,5.64461208680426,4.96646165847778,54,3,0,0,1,0.301132202148438,33.7243423461914,1,1,3,100.087341308594,0,100.082824707031,,,,,,,,,,,,,,,,,,,,,,,,,,,,,,,,,
,3879795686.16936,100.073951721191,-39999.5859375,2.47640896983296E-4,8.04239196167826E-8,1,4,13.4005146026611,4.99473040615624,33.3099998533726,0.307391867850729,0.0457098678290544,1,-2.15985564381771E-7,,,,,,,,,,,,,,,,,,,,,100.07088470459,100.077018737793,-39999.5859375,-39999.5859375,53.2910416268999,5.64623733489331,4.96173286437988,54,1,0,0,1,0.30029296875,33.7243423461914,1,1,3,100.077018737793,0,100.073951721191,,,,,,,,,,,,,,,,,,,,,,,,,,,,,,,,,
,3879795909.06847,100.134346008301,-54999.48046875,3.40685317035284E-4,1.04982628321084E-7,1,4,13.4005146026611,4.99489999142765,33.3099998533726,0.422877720008279,0.0630776455941495,1,-1.43627875906492E-7,,,,,,,,,,,,,,,,,,,,,100.123123168945,100.145568847656,-54999.48046875,-54999.48046875,53.3566984225153,5.64551014496259,4.97014856338501,52,2,68,0,0,0.300064086914063,33.7243423461914,1,1,3,100.146057128906,0,100.134346008301,,,,,,,,,,,,,,,,,,,,,,,,,,,,,,,,,
,3879796154.7353,100.141841888428,-69999.5390625,4.33704693413365E-4,1.21737450224006E-7,1,4,13.4005146026611,4.99488095563658,33.3099998533726,0.538327368893966,0.0803554645176267,1,-1.37905440722562E-7,,,,,,,,,,,,,,,,,,,,,100.132446289062,100.151237487793,-69999.5390625,-69999.5390625,53.162854549746,5.64524729101862,4.96251726150513,54,3,0,0,1,0.301742553710937,33.7243423461914,1,1,3,100.151237487793,0,100.141841888428,,,,,,,,,,,,,,,,,,,,,,,,,,,,,,,,,
,3879796438.3763,100.089542388916,-49999.6015625,3.09478711522961E-4,4.79953451271319E-8,1,4,13.4005146026611,4.99485347932952,33.3099998533726,0.384138608801357,0.0572904091876001,1,-1.37407170584303E-7,,,,,,,,,,,,,,,,,,,,,100.071556091309,100.107528686523,-49999.6015625,-49999.6015625,53.3187894393326,5.64517263952728,4.96366786956787,54,1,0,0,1,0.2996826171875,32.7468223571777,1,1,3,100.108581542969,0,100.089542388916,,,,,,,,,,,,,,,,,,,,,,,,,,,,,,,,,
,3879796660.39818,100.024169921875,-34999.54296875,2.16450413944968E-4,3.52473040784177E-8,1,4,13.4005146026611,4.9949139414199,33.3199985325336,0.268683832384986,0.0399929749227424,1,-1.57981350564177E-7,,,,,,,,,,,,,,,,,,,,,100.023056030273,100.025283813477,-34999.54296875,-34999.54296875,53.533737282121,5.64484919010273,4.97031545639038,54,2,0,0,1,0.3009033203125,34.2131004333496,1,1,3,100.025283813477,0,100.024169921875,,,,,,,,,,,,,,,,,,,,,,,,,,,,,,,,,
,3879796881.46361,100.032459259033,-19999.703125,1.23368133995505E-4,2.14213015856503E-8,1,4,13.4005146026611,4.99488910424314,33.3099998533726,0.153141939926333,0.0227681784546368,1,-1.11046703041242E-7,,,,,,,,,,,,,,,,,,,,,100.03099822998,100.033920288086,-19999.703125,-19999.703125,53.4493214020441,5.6451920191616,4.96771574020386,54,3,0,0,1,0.300369262695313,34.7018585205078,1,1,3,100.033920288086,0,100.032459259033,,,,,,,,,,,,,,,,,,,,,,,,,,,,,,,,,
,3879797084.41183,100.120613098145,-9500.45703125,5.82484013986253E-5,1.12869951295731E-8,1,4,13.4005146026611,4.99493998130003,33.3199985325336,0.0723023740083883,0.0107822239972838,1,-2.66089449815143E-8,,,,,,,,,,,,,,,,,,,,,100.109336853027,100.131889343262,-9500.45703125,-9500.45703125,53.4891844565249,5.64475714563698,4.97036647796631,54,1,0,0,1,0.300216674804687,34.2131004333496,1,1,3,100.131889343262,0,100.120613098145,,,,,,,,,,,,,,,,,,,,,,,,,,,,,,,,,
,3879797168.93833,100.182739257813,-8000.4150390625,4.89459732442034E-5,1.07743039413158E-8,1,4,13.4005146026611,4.99454091572729,33.3099998533726,0.0607530922326917,0.00902982827806853,1,-4.60742452521907E-8,,,,,,,,,,,,,,,,,,,,,100.182502746582,100.182975769043,-8000.4150390625,-8000.4150390625,53.5263118111883,5.64704555708605,4.97036075592041,54,2,0,0,1,0.302276611328125,34.2131004333496,1,1,3,100.182502746582,0,100.182739257813,,,,,,,,,,,,,,,,,,,,,,,,,,,,,,,,,
,3879797253.24299,100.175407409668,-6500.34814453125,3.96571984908416E-5,9.08939310245992E-9,1,4,13.4005146026611,4.99448660180334,33.3099998533726,0.0492237236090381,0.00731029160293554,1,-4.19877441215753E-8,,,,,,,,,,,,,,,,,,,,,100.173072814941,100.177742004395,-6500.34814453125,-6500.34814453125,53.4790232857749,5.6475263028231,4.96895980834961,54,3,0,0,1,0.301132202148438,34.2131004333496,1,1,3,100.172790527344,0,100.175407409668,,,,,,,,,,,,,,,,,,,,,,,,,,,,,,,,,
,3879797352.66811,100.074836730957,-4500.27587890625,2.72269838152534E-5,9.39617451133243E-9,1,4,13.4005146026611,4.99439260994463,33.3099998533726,0.0337823973989253,0.00509684800106199,1,3.40560569296931E-8,,,,,,,,,,,,,,,,,,,,,100.071365356445,100.078308105469,-4500.27587890625,-4500.27587890625,53.5091159837653,5.64751749553972,4.97273683547974,54,1,0,0,1,0.304107666015625,34.2131004333496,1,1,3,100.071365356445,0,100.074836730957,,,,,,,,,,,,,,,,,,,,,,,,,,,,,,,,,
,3879797437.99275,100.179893493652,-3000.3603515625,1.79604341151777E-5,7.34755626050415E-9,1,4,13.4005146026611,4.99433429203358,33.3099998533726,0.0222882951350188,0.00333597354375966,1,1.40441327619523E-9,,,,,,,,,,,,,,,,,,,,,100.172431945801,100.187355041504,-3000.3603515625,-3000.3603515625,53.5036445841307,5.64686663621457,4.96285676956177,54,2,0,0,1,0.3009033203125,34.2131004333496,1,1,3,100.187355041504,0,100.179893493652,,,,,,,,,,,,,,,,,,,,,,,,,,,,,,,,,
,3879797526.3828,100.409801483154,-2900.35913085937,1.73938804193867E-5,1.02337585640549E-8,1,4,13.4005146026611,4.99426164170948,33.3099998533726,0.0216058444178779,0.00308987334034358,1,-1.12102938868417E-7,,,,,,,,,,,,,,,,,,,,,100.409713745117,100.409889221191,-2900.35913085937,-2900.35913085937,53.493092599121,5.64766607610304,4.9643726348877,54,3,0,0,1,0.300979614257812,34.2131004333496,1,1,3,100.409889221191,0,100.409801483154,,,,,,,,,,,,,,,,,,,,,,,,,,,,,,,,,
,3879797607.17721,100.30685043335,-2700.39477539062,1.62933969599686E-5,1.2143004657777E-7,1,4,13.4005146026611,4.99436338663115,33.3099998533726,0.0202383617182073,0.0029017673263698,1,-9.91256973761285E-8,,,,,,,,,,,,,,,,,,,,,100.302337646484,100.311363220215,-2700.39477539062,-2700.39477539062,53.5224036685922,5.64735138184042,4.96613931655884,54,1,0,0,1,0.303192138671875,33.7243423461914,1,1,3,100.302337646484,0,100.30685043335,,,,,,,,,,,,,,,,,,,,,,,,,,,,,,,,,
,3879797677.98747,100.276546478271,-2550.41821289062,1.52595402571174E-5,1.47599224789505E-8,1,4,13.4005146026611,4.99471585822099,33.3099998533726,0.0189715498500537,0.00261437136341199,1,-1.76261185798799E-7,,,,,,,,,,,,,,,,,,,,,100.26961517334,100.283477783203,-2550.41821289062,-2550.41821289062,53.4919201563422,5.64605045977244,4.96366310119629,53,2,68,0,0,0.30181884765625,34.2131004333496,1,1,3,100.26961517334,0,100.276546478271,,,,,,,,,,,,,,,,,,,,,,,,,,,,,,,,,
,3879797748.35919,100.1637840271,-2400.40380859375,1.43238412979659E-5,9.74410248999702E-9,1,4,13.4005146026611,4.99447023965173,33.3099998533726,0.0177992058337471,0.00250604577787529,1,-1.23428244639606E-7,,,,,,,,,,,,,,,,,,,,,100.15909576416,100.168472290039,-2400.40380859375,-2400.40380859375,53.5259209969287,5.64635066807344,4.96519184112549,54,3,0,0,1,0.299224853515625,34.2131004333496,1,1,3,100.15909576416,0,100.1637840271,,,,,,,,,,,,,,,,,,,,,,,,,,,,,,,,,
,3879797829.51762,100.122344970703,-2200.36401367187,1.31342010022187E-5,1.83099399441564E-8,1,4,13.4005146026611,4.99450336199121,33.3099998533726,0.0163377429829278,0.00218652480945847,1,-2.0294645588739E-7,,,,,,,,,,,,,,,,,,,,,100.120834350586,100.12385559082,-2200.36401367187,-2200.36401367187,53.5857155786499,5.64624645203777,4.96501159667969,54,1,0,0,1,0.301895141601562,33.7243423461914,1,1,3,100.12385559082,0,100.122344970703,,,,,,,,,,,,,,,,,,,,,,,,,,,,,,,,,
,3879797901.00992,100.200981140137,-2050.375,1.2168800486739E-5,1.4430182552555E-8,1,4,13.4005146026611,4.99473600320277,33.3099998533726,0.0151323142815882,0.00206301821308755,1,-1.58155580464843E-7,,,,,,,,,,,,,,,,,,,,,100.194801330566,100.207160949707,-2050.375,-2050.375,53.3918717058807,5.64616399768487,4.96897220611572,52,2,68,0,0,0.302200317382812,34.2131004333496,1,1,3,100.194801330566,0,100.200981140137,,,,,,,,,,,,,,,,,,,,,,,,,,,,,,,,,
,3879797973.09726,100.192352294922,-1900.44885253906,1.12260184092493E-5,1.05676215209835E-8,1,4,13.4005146026611,4.99455790777513,33.3199985325336,0.0139559938804659,0.00192476111067375,1,-1.28440711942323E-7,,,,,,,,,,,,,,,,,,,,,100.191917419434,100.19278717041,-1900.44885253906,-1900.44885253906,53.4407234883326,5.64640411617131,4.96237087249756,54,3,0,0,1,0.300369262695313,34.2131004333496,1,1,3,100.19278717041,0,100.192352294922,,,,,,,,,,,,,,,,,,,,,,,,,,,,,,,,,
,3879798066.19419,100.189552307129,-1700.08154296875,1.00323044635025E-5,2.09180926194258E-8,1,4,13.4005146026611,4.99431596839512,33.3099998533726,0.0124885190798879,0.00160381999934149,1,-2.08383442742598E-7,,,,,,,,,,,,,,,,,,,,,100.186279296875,100.192825317383,-1700.08154296875,-1700.08154296875,53.541944381573,5.64729798211259,4.97207641601562,52,1,68,0,0,0.30181884765625,34.2131004333496,1,1,3,100.186279296875,0,100.189552307129,,,,,,,,,,,,,,,,,,,,,,,,,,,,,,,,,
,3879798137.77703,100.064640045166,-1550.09252929687,9.08065135440615E-6,1.6196344828408E-8,1,4,13.4005146026611,4.99438447953492,33.3099998533726,0.0112966045047575,0.00150174627763148,1,-1.48298124895385E-7,,,,,,,,,,,,,,,,,,,,,100.061836242676,100.067443847656,-1550.09252929687,-1550.09252929687,53.396561476996,5.64674099549985,4.96226644515991,54,2,0,0,1,0.300979614257812,34.2131004333496,1,1,3,100.061836242676,0,100.064640045166,,,,,,,,,,,,,,,,,,,,,,,,,,,,,,,,,
,3879798209.36846,100.113048553467,-1400.103515625,8.15758183990117E-6,1.2518626541526E-8,1,4,13.4005146026611,4.9943217358139,33.3099998533726,0.0101452945831989,0.00136781719292592,1,-1.18113649188474E-7,,,,,,,,,,,,,,,,,,,,,100.111038208008,100.115058898926,-1400.103515625,-1400.103515625,53.5759452221595,5.64602128019951,4.9650764465332,54,3,0,0,1,0.30181884765625,33.7243423461914,1,1,3,100.111038208008,0,100.113048553467,,,,,,,,,,,,,,,,,,,,,,,,,,,,,,,,,
,3879798290.22138,100.143573760986,-1200.12646484375,6.97690974913537E-6,1.03384318129702E-7,1,4,13.4005146026611,4.99450490482255,33.3099998533726,0.00869067929652722,0.00108100904356885,1,-1.72652008424409E-7,,,,,,,,,,,,,,,,,,,,,100.143348693848,100.143798828125,-1200.12646484375,-1200.12646484375,53.3719401786402,5.64614747700299,4.96633386611938,53,1,68,0,0,0.301284790039063,34.2131004333496,1,1,3,100.143165588379,0,100.143573760986,,,,,,,,,,,,,,,,,,,,,,,,,,,,,,,,,
,3879798372.12502,100.068187713623,-1050.16259765625,6.01266061693806E-6,1.50467627229681E-8,1,4,13.4005146026611,4.99445619062535,33.3099998533726,0.00749169039082283,9.16785362725951E-4,1,-1.60723620811883E-7,,,,,,,,,,,,,,,,,,,,,100.067749023438,100.068626403809,-1050.16259765625,-1050.16259765625,53.4180562612749,5.64627727804195,4.96253108978271,53,2,68,0,0,0.30303955078125,33.7243423461914,1,1,3,100.067573547363,0,100.068187713623,,,,,,,,,,,,,,,,,,,,,,,,,,,,,,,,,
,3879798443.88899,100.092544555664,-900.186096191406,5.07819559437754E-6,1.25658521326996E-8,1,4,13.4005146026611,4.99433468391634,33.3099998533726,0.00632663443354227,7.77685476757924E-4,1,-1.32996879934177E-7,,,,,,,,,,,,,,,,,,,,,100.090911865234,100.094177246094,-900.186096191406,-900.186096191406,53.3582616795537,5.64680091451871,4.96600818634033,53,3,68,0,0,0.3021240234375,33.7243423461914,1,1,3,100.090911865234,0,100.092544555664,,,,,,,,,,,,,,,,,,,,,,,,,,,,,,,,,
,3879798526.08728,100.110366821289,-700.196533203125,3.92595593729156E-6,2.59401546818019E-8,1,4,13.4005146026611,4.99442786454332,33.3199985325336,0.00491717807977264,4.27938657750549E-4,1,-2.42468846394021E-7,,,,,,,,,,,,,,,,,,,,,100.108406066895,100.112327575684,-700.196533203125,-700.196533203125,53.6169807194191,5.64682680276575,4.97087907791138,54,1,0,0,1,0.300750732421875,33.7243423461914,1,1,3,100.112327575684,0,100.110366821289,,,,,,,,,,,,,,,,,,,,,,,,,,,,,,,,,
,3879798597.52219,100.088806152344,-550.182250976562,2.96791193923338E-6,1.85127319237387E-8,1,4,13.4005146026611,4.99443855456989,33.3099998533726,0.00371439800515208,3.42636020605587E-4,1,-1.6788846182458E-7,,,,,,,,,,,,,,,,,,,,,100.085273742676,100.092338562012,-550.182250976562,-550.182250976562,53.401642062371,5.64634366076593,4.97160482406616,54,2,0,0,1,0.303115844726562,34.2131004333496,1,1,3,100.085273742676,0,100.088806152344,,,,,,,,,,,,,,,,,,,,,,,,,,,,,,,,,
,3879798669.91596,100.24658203125,-400.243560791016,2.06673627642588E-6,1.52527221770541E-8,1,4,13.4005146026611,4.99451838351881,33.3099998533726,0.00258941684377687,2.19890556068577E-4,1,-1.31989241577744E-7,,,,,,,,,,,,,,,,,,,,,100.242614746094,100.250549316406,-400.243560791016,-400.243560791016,53.526702625448,5.64632148687913,4.97322130203247,54,3,0,0,1,0.300674438476562,33.7243423461914,1,1,3,100.250549316406,0,100.24658203125,,,,,,,,,,,,,,,,,,,,,,,,,,,,,,,,,
,3879798752.27997,100.171207427979,-200.16584777832,9.14082711129047E-7,2.56808259392957E-8,1,4,13.4005146026611,4.99467992450864,33.3199985325336,0.00118966446778435,-1.99258208515659E-4,1,-2.97290668695048E-7,,,,,,,,,,,,,,,,,,,,,100.17098236084,100.171432495117,-200.16584777832,-200.16584777832,53.401642062371,5.64510559663874,4.96996307373047,52,1,68,0,0,0.30059814453125,33.7243423461914,1,1,3,100.171432495117,0,100.171207427979,,,,,,,,,,,,,,,,,,,,,,,,,,,,,,,,,
,3879798823.80027,100.229690551758,-50.2900772094727,-3.5593402788575E-9,1.83420717563002E-8,1,4,13.4005146026611,4.99470262912187,33.3099998533726,2.65037834561214E-5,-2.07362613665929E-4,1,-1.66546016709605E-7,,,,,,,,,,,,,,,,,,,,,100.225807189941,100.233573913574,-50.2900772094727,-50.2900772094727,53.5278750682268,5.64473768864606,4.96198034286499,52,2,68,0,0,0.2996826171875,33.2355842590332,1,1,3,100.233573913574,0,100.229690551758,,,,,,,,,,,,,,,,,,,,,,,,,,,,,,,,,
,3879798907.32963,100.215812683105,99.8122787475586,-8.51480968973849E-7,1.53502998016253E-8,1,4,13.4005146026611,4.99480175777721,33.3099998533726,-0.00103554798792081,-3.00224988952371E-4,1,-1.14517526815526E-7,,,,,,,,,,,,,,,,,,,,,100.214248657227,100.217376708984,99.8122787475586,99.8122787475586,53.5028629556114,5.64545389373579,4.96730756759644,53,3,64,0,0,0.300140380859375,34.2131004333496,1,1,3,100.214248657227,0,100.215812683105,,,,,,,,,,,,,,,,,,,,,,,,,,,,,,,,,
,3879798999.41467,100.114036560059,299.638244628906,-1.90052325057706E-6,1.54124125437592E-8,1,4,13.4005146026611,4.99484457134496,33.3099998533726,-0.00232566398228272,-5.74714393702665E-4,1,-1.78740158819E-7,,,,,,,,,,,,,,,,,,,,,100.105712890625,100.122360229492,299.638244628906,299.638244628906,53.6290959614672,5.64552901637363,4.96996212005615,54,1,0,0,1,0.299835205078125,33.7243423461914,1,1,3,100.122360229492,0,100.114036560059,,,,,,,,,,,,,,,,,,,,,,,,,,,,,,,,,
,3879799070.82327,100.168663024902,449.753173828125,-2.75986691882418E-6,1.08368005568495E-8,1,4,13.4005146026611,4.99481271857532,33.3099998533726,-0.00340088251786491,-6.76324161860242E-4,1,-1.32059380059201E-7,,,,,,,,,,,,,,,,,,,,,100.165054321289,100.172271728516,449.753173828125,449.753173828125,53.3778023925345,5.64455721843994,4.97170066833496,52,2,68,0,0,0.301589965820313,33.7243423461914,1,1,3,100.172271728516,0,100.168663024902,,,,,,,,,,,,,,,,,,,,,,,,,,,,,,,,,
,3879799142.31531,100.183200836182,599.780029296875,-3.63134490928753E-6,1.16046795813701E-8,1,4,13.4005146026611,4.99473174412184,33.3099998533726,-0.00448725889243714,-8.05719710429513E-4,1,-1.0596115813168E-7,,,,,,,,,,,,,,,,,,,,,100.182426452637,100.183975219727,599.780029296875,599.780029296875,53.4739427003999,5.64455764462932,4.96261310577393,52,3,68,0,0,0.299911499023438,33.7243423461914,1,1,3,100.183975219727,0,100.183200836182,,,,,,,,,,,,,,,,,,,,,,,,,,,,,,,,,
,3879799234.87755,100.084621429443,799.60595703125,-4.88724221908361E-6,1.21093493589089E-7,1,4,13.4005146026611,4.99490196508735,33.3099998533726,-0.00603443343862562,-0.00111804062552666,1,-1.69688223712983E-7,,,,,,,,,,,,,,,,,,,,,100.078926086426,100.090316772461,799.60595703125,799.60595703125,53.3824921636499,5.64501632397518,4.97157287597656,54,1,0,0,1,0.302734375,33.7243423461914,1,1,3,100.090316772461,0,100.084621429443,,,,,,,,,,,,,,,,,,,,,,,,,,,,,,,,,
,3879799322.58187,100.05029296875,949.720886230469,-5.69224255115035E-6,1.99379395039868E-8,1,4,13.4005146026611,4.9948125394994,33.3199985325336,-0.00704119820921949,-0.0012153873448268,1,-1.27720565844577E-7,,,,,,,,,,,,,,,,,,,,,100.048538208008,100.052047729492,949.720886230469,949.720886230469,53.3899176345826,5.64537055717772,4.97296333312988,52,2,68,0,0,0.301055908203125,33.7243423461914,1,1,3,100.052047729492,0,100.05029296875,,,,,,,,,,,,,,,,,,,,,,,,,,,,,,,,,
,3879799421.65371,100.0771484375,1099.65954589844,-6.57006197862024E-6,2.96749962334236E-8,1,4,13.4005146026611,4.99478712626462,33.3099998533726,-0.00813380249469219,-0.00135724358507297,1,-1.10706416470119E-7,,,,,,,,,,,,,,,,,,,,,100.07364654541,100.08065032959,1099.65954589844,1099.65954589844,53.5024721413518,5.64542410817454,4.96686553955078,54,3,0,0,1,0.2996826171875,33.7243423461914,1,1,3,100.07364654541,0,100.0771484375,,,,,,,,,,,,,,,,,,,,,,,,,,,,,,,,,
,3879799504.20057,100.145179748535,1299.58630371094,-7.79907353608625E-6,1.32619930289009E-8,1,4,13.4005146026611,4.99475324207349,33.3099998533726,-0.00964831436366315,-0.00165740951098207,1,-1.68713785878829E-7,,,,,,,,,,,,,,,,,,,,,100.140731811523,100.149627685547,1299.58630371094,1299.58630371094,53.516541454698,5.64588473491474,4.97198295593262,52,1,68,0,0,0.300445556640625,33.2355842590332,1,1,3,100.149627685547,0,100.145179748535,,,,,,,,,,,,,,,,,,,,,,,,,,,,,,,,,
,3879799576.6972,100.121257781982,1449.62573242187,-8.74220202439589E-6,8.25863877471106E-9,1,4,13.4005146026611,4.99470354552073,33.3199985325336,-0.010830695556424,-0.00175233951513857,1,-1.04134204172876E-7,,,,,,,,,,,,,,,,,,,,,100.118049621582,100.124465942383,1449.62573242187,1449.62573242187,53.4278266177653,5.64656770709902,4.96915245056152,54,2,0,0,1,0.301742553710937,33.7243423461914,1,1,3,100.118049621582,0,100.121257781982,,,,,,,,,,,,,,,,,,,,,,,,,,,,,,,,,
,3879799649.04818,100.145000457764,1599.76574707031,-9.66991029275759E-6,1.17353157621674E-8,1,4,13.4005146026611,4.99499009031366,33.3099998533726,-0.0119862717790515,-0.00190317011833503,1,-8.67604013811458E-8,,,,,,,,,,,,,,,,,,,,,100.142486572266,100.147514343262,1599.76574707031,1599.76574707031,53.506380283948,5.64623483000632,4.9719934463501,54,3,0,0,1,0.3009033203125,33.7243423461914,1,1,3,100.147514343262,0,100.145000457764,,,,,,,,,,,,,,,,,,,,,,,,,,,,,,,,,
,3879799731.91919,100.131053924561,1799.78051757813,-1.08866215519118E-5,9.81156242567496E-9,1,4,13.4005146026611,4.99491399795328,33.3099998533726,-0.0134868826666516,-0.00219117052709063,1,-1.36817690681758E-7,,,,,,,,,,,,,,,,,,,,,100.113594055176,100.148513793945,1799.78051757813,1799.78051757813,53.552105552323,5.64613459064084,4.96614265441895,54,1,0,0,1,0.300445556640625,33.7243423461914,1,1,3,100.148513793945,0,100.131053924561,,,,,,,,,,,,,,,,,,,,,,,,,,,,,,,,,
,3879799803.47181,100.221569061279,1949.88293457031,-1.18305429512246E-5,1.38452398718742E-8,1,4,13.4005146026611,4.99492949597487,33.3199985325336,-0.0146685828315336,-0.0022992092511292,1,-8.26497944865584E-8,,,,,,,,,,,,,,,,,,,,,100.220985412598,100.222152709961,1949.88293457031,1949.88293457031,53.457528501496,5.64609812141508,4.96470165252686,54,2,0,0,1,0.300521850585937,34.2131004333496,1,1,3,100.222152709961,0,100.221569061279,,,,,,,,,,,,,,,,,,,,,,,,,,,,,,,,,
,3879799875.13521,100.259090423584,2099.77124023438,-1.27487759137615E-5,7.54200502119148E-9,1,4,13.4005146026611,4.99488657819795,33.3099998533726,-0.0158102687650078,-0.00245512299543154,1,-7.09281381573028E-8,,,,,,,,,,,,,,,,,,,,,100.254417419434,100.263763427734,2099.77124023438,2099.77124023438,53.5075527267268,5.64617770958513,4.96480321884155,52,3,68,0,0,0.302200317382812,33.7243423461914,1,1,3,100.254417419434,0,100.259090423584,,,,,,,,,,,,,,,,,,,,,,,,,,,,,,,,,
,3879799957.21757,100.111511230469,2299.86157226562,-1.39783630311835E-5,2.02358372695397E-8,1,4,13.4005146026611,4.99482885107295,33.3099998533726,-0.0173315923420083,-0.00271363643037359,1,-9.53063966231344E-8,,,,,,,,,,,,,,,,,,,,,100.11100769043,100.112014770508,2299.86157226562,2299.86157226562,53.5196679687749,5.64665163363477,4.97343683242798,53,1,68,0,0,0.29937744140625,33.7243423461914,1,1,3,100.112014770508,0,100.111511230469,,,,,,,,,,,,,,,,,,,,,,,,,,,,,,,,,
,3879800029.34009,100.12610244751,2449.8505859375,-1.48941929289611E-5,7.29484541036053E-9,1,4,13.4005146026611,4.99485189495199,33.3099998533726,-0.0184711470382953,-0.00286531107704996,1,-8.04935950264765E-8,,,,,,,,,,,,,,,,,,,,,100.122650146484,100.129554748535,2449.8505859375,2449.8505859375,53.4114124188614,5.64632319311109,4.96905422210693,54,2,0,0,1,0.300750732421875,33.2355842590332,1,1,3,100.129554748535,0,100.12610244751,,,,,,,,,,,,,,,,,,,,,,,,,,,,,,,,,
,3879800101.02537,100.192615509033,2599.73901367187,-1.5832934147349E-5,8.75469704057439E-9,1,4,13.4005146026611,4.99467007324355,33.3099998533726,-0.0196409880186536,-0.00300126139438084,1,-4.97217773481654E-8,,,,,,,,,,,,,,,,,,,,,100.188598632813,100.196632385254,2599.73901367187,2599.73901367187,53.4907477135634,5.6471316324098,4.96649026870728,53,3,68,0,0,0.30059814453125,33.7243423461914,1,1,3,100.188598632813,0,100.192615509033,,,,,,,,,,,,,,,,,,,,,,,,,,,,,,,,,
,3879800183.7772,100.126499176025,2799.84204101562,-1.70532855740803E-5,8.56607572846434E-9,1,4,13.4005146026611,4.99472983913154,33.3099998533726,-0.0211492078374236,-0.00327274278726903,1,-8.58634762589675E-8,,,,,,,,,,,,,,,,,,,,,100.115898132324,100.137100219727,2799.84204101562,2799.84204101562,53.4559652444576,5.64700543907376,4.96250152587891,54,1,0,0,1,0.30059814453125,33.2355842590332,1,1,3,100.137100219727,0,100.126499176025,,,,,,,,,,,,,,,,,,,,,,,,,,,,,,,,,
,3879800255.35371,100.21773147583,2949.74291992188,-1.79726581532654E-5,8.82784035891643E-9,1,4,13.4005146026611,4.99469511390464,33.3099998533726,-0.0222940720996204,-0.00341645750718928,1,-6.415231824125E-8,,,,,,,,,,,,,,,,,,,,,100.211097717285,100.224365234375,2949.74291992188,2949.74291992188,53.5059894696884,5.64703486441505,4.96207237243652,54,2,0,0,1,0.299758911132812,33.7243423461914,1,1,3,100.211097717285,0,100.21773147583,,,,,,,,,,,,,,,,,,,,,,,,,,,,,,,,,
,3879800347.3842,100.106826782227,3499.63549804687,-2.14096622551194E-5,6.92177705407012E-9,1,4,13.4005146026611,4.99464428339572,33.3099998533726,-0.0265780946013259,-0.00392942840092201,1,3.66398096969423E-8,,,,,,,,,,,,,,,,,,,,,100.102310180664,100.111343383789,3499.63549804687,3499.63549804687,53.518495525996,5.64669675981279,4.97168493270874,54,3,0,0,1,0.300521850585937,33.2355842590332,1,1,3,100.102035522461,0,100.106826782227,,,,,,,,,,,,,,,,,,,,,,,,,,,,,,,,,
,3879800445.69343,100.177268981934,5499.64501953125,-3.37710406433501E-5,1.09629115045314E-8,1,4,13.4005146026611,4.9945906971826,33.3099998533726,-0.0419274481382543,-0.0061680853936613,1,8.19665031367701E-8,,,,,,,,,,,,,,,,,,,,,100.175178527832,100.179359436035,5499.64501953125,5499.64501953125,53.4125848616403,5.6478733790847,4.96138620376587,54,1,0,0,1,0.302734375,33.7243423461914,1,1,3,100.175178527832,0,100.177268981934,,,,,,,,,,,,,,,,,,,,,,,,,,,,,,,,,
,3879800528.89319,100.070705413818,6999.74951171875,-4.30526883071037E-5,8.85184662595593E-9,1,4,13.4005146026611,4.99451957028362,33.3199985325336,-0.0534450416962614,-0.00789457649968851,1,7.9185989634826E-8,,,,,,,,,,,,,,,,,,,,,100.06778717041,100.073623657227,6999.74951171875,6999.74951171875,53.4934834133807,5.6475710115607,4.96413469314575,54,2,0,0,1,0.300979614257812,33.7243423461914,1,1,3,100.06778717041,0,100.070705413818,,,,,,,,,,,,,,,,,,,,,,,,,,,,,,,,,
,3879800613.1852,100.186901092529,8500.09375,-5.23300012669128E-5,1.20781340359917E-8,1,4,13.4005146026611,4.99448624388692,33.3099998533726,-0.0649577862500416,-0.00961828149407441,1,7.80287045320121E-8,,,,,,,,,,,,,,,,,,,,,100.18465423584,100.189147949219,8500.09375,8500.09375,53.6466826031499,5.64826294564378,4.9706392288208,54,3,0,0,1,0.300979614257812,33.7243423461914,1,1,3,100.189224243164,0,100.186901092529,,,,,,,,,,,,,,,,,,,,,,,,,,,,,,,,,
,3879800717.48282,100.100105285645,9999.984375,-6.16265590481379E-5,1.08147144277388E-8,1,4,13.4005146026611,4.99453110141854,33.3199985325336,-0.0764975808120714,-0.0113343804557876,1,8.60534647999214E-8,,,,,,,,,,,,,,,,,,,,,100.099174499512,100.101036071777,9999.984375,9999.984375,53.4297806890633,5.64718552118389,4.97187423706055,54,1,0,0,1,0.301361083984375,33.2355842590332,1,1,3,100.099174499512,0,100.100105285645,,,,,,,,,,,,,,,,,,,,,,,,,,,,,,,,,
,3879800936.82224,100.053272247314,25000.248046875,-1.54647849294682E-4,2.43188174824002E-8,1,4,13.4005146026611,4.99461724687668,33.3099998533726,-0.191953501457321,-0.0285562129349525,1,1.25190858477415E-7,,,,,,,,,,,,,,,,,,,,,100.046951293945,100.059593200684,25000.248046875,25000.248046875,53.325433281746,5.64756258290381,4.96588134765625,54,2,0,0,1,0.300216674804687,33.7243423461914,1,1,3,100.059997558594,0,100.053272247314,,,,,,,,,,,,,,,,,,,,,,,,,,,,,,,,,
,3879801157.45271,100.12678527832,40000.37890625,-2.47614111754558E-4,4.14792258284237E-8,1,4,13.4005146026611,4.99430905583777,33.3099998533726,-0.307323000069023,-0.0456948578446366,1,2.19721681025359E-7,,,,,,,,,,,,,,,,,,,,,100.118309020996,100.135261535645,40000.37890625,40000.37890625,53.4602642013134,5.64760781855818,4.96812057495117,54,3,0,0,1,0.300521850585937,33.7243423461914,1,1,3,100.135261535645,0,100.12678527832,,,,,,,,,,,,,,,,,,,,,,,,,,,,,,,,,
,3879801441.02928,100.056037902832,60000.43359375,-3.71699779065776E-4,6.80460262593879E-8,1,4,13.4005146026611,4.99435968495705,33.3099998533726,-0.461309103844152,-0.0687801251062836,1,1.80393229677389E-7,,,,,,,,,,,,,,,,,,,,,100.039680480957,100.072395324707,60000.43359375,60000.43359375,53.371158550121,5.64714429010854,4.96883726119995,54,1,0,0,1,0.301589965820313,33.7243423461914,1,1,3,100.072395324707,0,100.056037902832,,,,,,,,,,,,,,,,,,,,,,,,,,,,,,,,,
,3879801616.06852,100.075138092041,70000.453125,-4.33682398542638E-4,2.24621644391842E-7,1,4,13.4005146026611,4.99430495938162,33.3199985325336,-0.53821592183153,-0.0803171470161982,1,1.5498848868549E-7,,,,,,,,,,,,,,,,,,,,,100.074897766113,100.075378417969,70000.453125,70000.453125,53.386400306246,5.64774405194142,4.97187376022339,54,3,0,0,1,0.302200317382812,33.7243423461914,1,1,3,100.074897766113,0,100.075138092041,,,,,,,,,,,,,,,,,,,,,,,,,,,,,,,,,