File: SQUID/22169_LCOT/22169_LCOT_MT_FC_0d5T.csv
Comment,Time Stamp (sec),Temperature (K),Magnetic Field (Oe),Moment (emu),M. Std. Err. (emu),Transport Action,Averaging Time (sec),Frequency (Hz),Peak Amplitude (mm),Center Position (mm),Lockin Signal' (V),Lockin Signal (V),Range,M. Quad. Signal (emu),AC Moment (emu),AC M. Std Err. (emu),AC Phase (deg),AC Phase Std. Err. (deg),AC Susceptibility (emu/Oe),AC Suscept. Std Err. (emu/Oe),AC X' (emu/Oe),AC X' Std Err. (emu/Oe),AC X'' (emu/Oe),AC X'' Std Err. (emu/Oe),AC Drive (Oe),AC Frequency (Hz),AC Averaging Time (sec),AC Cycles,AC Range,AC Measure Type,AC Signal' (V),AC Signal'' (V),AC Trim Coil Ratio,AC Trim Coil Phase,Min. Temperature (K),Max. Temperature (K),Min. Field (Oe),Max. Field (Oe),Mass (grams),Motor Lag (deg),Pressure (Torr),Measure Count,Measurement Number,SQUID Status (code),Motor Status (code),Measure Status (code),Motor Current (amps),Motor Temp. (C),Temp. Status (code),Field Status (code),Chamber Status (code),Chamber Temp (K),Redirection State,Average Temp (K),Rotation Angle (deg),Rotator state,DC Moment Fixed Ctr (emu),DC Moment Err Fixed Ctr (emu),DC Moment Free Ctr (emu),DC Moment Err Free Ctr (emu),DC Fixed Fit,DC Free Fit,DC Calculated Center (mm),DC Calculated Center Err (mm),DC Scan Length (mm),DC Scan Time (s),DC Number of Points,DC Squid Drift,DC Min V (V),DC Max V (V),DC Scans per Measure,Sample Resistance,He3 Temperature,Sorb Resistance,Sorb Temperature,Map 05,Map 06,Map 07,Map 08,Map 09,Map 10,Map 11,Map 12,Map 13,Map 14,Map 15,Map 16
,3879858693.15284,350.003494262695,4999.7529296875,1.41638794657435E-5,7.23912610508965E-9,1,6,13.4005146026611,5.00785538197031,33.4899984300137,0.0176503478273846,0.00259512856609078,1,-3.55340453164735E-8,,,,,,,,,,,,,,,,,,,,,350.003479003906,350.003509521484,4999.7529296875,4999.7529296875,53.3809289066114,5.62799385596001,5.63084316253662,80,1,0,0,1,0.304946899414063,32.7468223571777,1,1,3,350.003479003906,0,350.003494262695,,,,,,,,,,,,,,,,,,,,,,,,,,,,,,,,,
,3879858715.45974,349.793518066406,4999.7529296875,1.42293531868345E-5,7.19084658255742E-9,1,6,13.4005146026611,5.00807296148525,33.4899984300137,0.0177325285220216,0.00261053445911227,1,-3.30883622073103E-8,,,,,,,,,,,,,,,,,,,,,349.681488037109,349.905548095703,4999.7529296875,4999.7529296875,53.4415051168518,5.63439283408316,5.63510417938232,80,1,0,0,1,0.30487060546875,33.2355842590332,2,1,3,349.678955078125,0,349.793518066406,,,,,,,,,,,,,,,,,,,,,,,,,,,,,,,,,
,3879858739.52677,348.662979125977,4999.7529296875,1.42491067292449E-5,7.63641459340852E-9,1,6,13.4005146026611,5.00792954801219,33.4899984300137,0.0177560096018784,0.00261689418051266,1,-3.08541928553433E-8,,,,,,,,,,,,,,,,,,,,,348.481842041016,348.844116210937,4999.7529296875,4999.7529296875,53.4375969742557,5.63476473856591,5.64293432235718,80,1,0,0,1,0.298690795898438,33.2355842590332,2,1,3,348.481842041016,0,348.662979125977,,,,,,,,,,,,,,,,,,,,,,,,,,,,,,,,,
,3879858763.36592,346.607391357422,4999.7529296875,1.42781992755039E-5,6.66038317849684E-9,1,6,13.4005146026611,5.00784235586694,33.4899984300137,0.0177925082387719,0.0026176342628444,1,-3.45610139843229E-8,,,,,,,,,,,,,,,,,,,,,346.303497314453,346.911285400391,4999.7529296875,4999.7529296875,53.4547928016787,5.63465518710898,5.64735269546509,80,1,0,0,1,0.2984619140625,33.2355842590332,2,1,3,346.288208007812,0,346.607391357422,,,,,,,,,,,,,,,,,,,,,,,,,,,,,,,,,
,3879858787.32122,342.812423706055,4999.7529296875,1.4339928189772E-5,6.61393593222931E-9,1,6,13.4005146026611,5.00766186385953,33.4899984300137,0.0178697506720192,0.0026206607707259,1,-4.12596828320314E-8,,,,,,,,,,,,,,,,,,,,,342.337005615234,343.287841796875,4999.7529296875,4999.7529296875,53.442286745371,5.63417227979876,5.64838457107544,80,1,0,0,1,0.298614501953125,33.2355842590332,2,1,3,342.337005615234,0,342.812423706055,,,,,,,,,,,,,,,,,,,,,,,,,,,,,,,,,
,3879858811.55956,338.308181762695,4999.7529296875,1.4416101873829E-5,7.29937347156919E-9,1,6,13.4005146026611,5.00753728913211,33.4700010716915,0.0179638290817372,0.00263596735064256,1,-4.02928571633244E-8,,,,,,,,,,,,,,,,,,,,,337.825469970703,338.790893554687,4999.7529296875,4999.7529296875,53.4332980173999,5.63472853277861,5.64380645751953,79,1,64,0,0,0.30670166015625,32.2580642700195,2,1,3,337.825469970703,0,338.308181762695,,,,,,,,,,,,,,,,,,,,,,,,,,,,,,,,,
,3879858834.60654,333.34912109375,4999.7529296875,1.45033659892397E-5,7.03355400418394E-9,1,6,13.4005146026611,5.00731591776251,33.4700010716915,0.0180710265937708,0.0026546007770252,1,-3.82556097937054E-8,,,,,,,,,,,,,,,,,,,,,332.776947021484,333.921295166016,4999.7529296875,4999.7529296875,53.4114124188614,5.63639503263388,5.63582181930542,80,1,0,0,1,0.29876708984375,33.7243423461914,2,1,3,332.776947021484,0,333.34912109375,,,,,,,,,,,,,,,,,,,,,,,,,,,,,,,,,
,3879858858.46246,327.746215820313,4999.7529296875,1.45851298600774E-5,6.86705933223533E-9,1,6,13.4005146026611,5.00728886388301,33.4700010716915,0.0181720985545217,0.00267400904234424,1,-3.48880184155906E-8,,,,,,,,,,,,,,,,,,,,,327.080810546875,328.41162109375,4999.7529296875,4999.7529296875,53.5392086817557,5.63686934076915,5.62891101837158,80,1,0,0,1,0.299530029296875,33.2355842590332,2,1,3,327.080810546875,0,327.746215820313,,,,,,,,,,,,,,,,,,,,,,,,,,,,,,,,,
,3879858882.3912,322.066177368164,4999.7529296875,1.46529874441542E-5,6.19528426590621E-9,1,6,13.4005146026611,5.00723579836061,33.4499999880791,0.0182559537610305,0.00268922005597382,1,-3.27942087072393E-8,,,,,,,,,,,,,,,,,,,,,321.381042480469,322.751312255859,4999.7529296875,4999.7529296875,53.5224036685922,5.63599446124688,5.62884712219238,79,1,64,0,0,0.29998779296875,33.7243423461914,2,1,3,321.381042480469,0,322.066177368164,,,,,,,,,,,,,,,,,,,,,,,,,,,,,,,,,
,3879858906.22054,316.715545654297,4999.7529296875,1.4728424565181E-5,7.06196601640587E-9,1,6,13.4005146026611,5.00722970300123,33.4499999880791,0.0183509200621787,0.00269629880304938,1,-3.83918545045859E-8,,,,,,,,,,,,,,,,,,,,,316.140075683594,317.291015625,4999.7529296875,4999.7529296875,53.4774600287364,5.63595439803945,5.62254238128662,80,1,0,0,1,0.300369262695313,33.7243423461914,2,1,3,316.140075683594,0,316.715545654297,,,,,,,,,,,,,,,,,,,,,,,,,,,,,,,,,
,3879858930.16668,311.625076293945,4999.7529296875,1.47820925546154E-5,5.84743626303353E-9,1,6,13.4005146026611,5.00704403624442,33.4299989044666,0.0184161796722333,0.00271035173686459,1,-3.50241825272398E-8,,,,,,,,,,,,,,,,,,,,,311.045166015625,312.204986572266,4999.7529296875,4999.7529296875,53.4966099274576,5.6364272448631,5.62045335769653,80,1,0,0,1,0.306777954101562,33.7243423461914,2,1,3,311.045166015625,0,311.625076293945,,,,,,,,,,,,,,,,,,,,,,,,,,,,,,,,,
,3879858953.95064,307.359146118164,4999.7529296875,1.48362295287967E-5,6.07330140386641E-9,1,6,13.4005146026611,5.00705695468282,33.4299989044666,0.0184840842386159,0.00271766947086774,1,-3.72548125791266E-8,,,,,,,,,,,,,,,,,,,,,306.92138671875,307.796905517578,4999.7529296875,4999.7529296875,53.4442408166691,5.63631396226914,5.61632585525513,80,1,0,0,1,0.298614501953125,34.2131004333496,2,1,3,306.92138671875,0,307.359146118164,,,,,,,,,,,,,,,,,,,,,,,,,,,,,,,,,
,3879858977.83103,303.469223022461,4999.7529296875,1.48909906091205E-5,6.84036940689658E-9,1,6,13.4005146026611,5.00696305131856,33.4299989044666,0.018551323938719,0.00273096699699076,1,-3.4711986371385E-8,,,,,,,,,,,,,,,,,,,,,302.951385498047,303.987060546875,4999.7529296875,4999.7529296875,53.5231852971114,5.63670410236946,5.61449098587036,80,1,0,0,1,0.30609130859375,33.7243423461914,2,1,3,302.951385498047,0,303.469223022461,,,,,,,,,,,,,,,,,,,,,,,,,,,,,,,,,
,3879859001.83598,299.587615966797,4999.7529296875,1.49192448180773E-5,6.16369745924497E-9,1,6,13.4005146026611,5.00699509043704,33.4100015461445,0.0185874780675913,0.00273090210933071,1,-3.90103610025996E-8,,,,,,,,,,,,,,,,,,,,,299.117095947266,300.058135986328,4999.7529296875,4999.7529296875,53.5638299801114,5.63730771835749,5.60616445541382,80,1,0,0,1,0.300979614257812,33.7243423461914,2,1,3,299.117095947266,0,299.587615966797,,,,,,,,,,,,,,,,,,,,,,,,,,,,,,,,,
,3879859025.5991,295.701156616211,4999.7529296875,1.49775866696094E-5,6.42247241465481E-9,1,6,13.4005146026611,5.00698326272498,33.4100015461445,0.0186588957860755,0.00274964193923247,1,-3.2683237899782E-8,,,,,,,,,,,,,,,,,,,,,295.230590820313,296.171722412109,4999.7529296875,4999.7529296875,53.4719886291018,5.63788069209793,5.60662984848022,80,1,0,0,1,0.300064086914063,34.2131004333496,2,1,3,295.230590820313,0,295.701156616211,,,,,,,,,,,,,,,,,,,,,,,,,,,,,,,,,
,3879859049.76298,291.650772094727,4999.7529296875,1.50159111146631E-5,6.73757653953183E-9,1,6,13.4005146026611,5.0069269967671,33.4100015461445,0.0187069276945376,0.00275274612727526,1,-3.58890535225519E-8,,,,,,,,,,,,,,,,,,,,,291.078155517578,292.223388671875,4999.7529296875,4999.7529296875,53.5536688093614,5.63769031700042,5.60059928894043,80,1,0,0,1,0.300521850585937,33.7243423461914,2,1,3,291.078155517578,0,291.650772094727,,,,,,,,,,,,,,,,,,,,,,,,,,,,,,,,,
,3879859073.46821,287.962326049805,4999.7529296875,1.5047633129387E-5,6.68030593083137E-9,1,6,13.4005146026611,5.0068930044759,33.4100015461445,0.0187481516514866,0.00274595206991227,1,-4.60690330327818E-8,,,,,,,,,,,,,,,,,,,,,287.514129638672,288.410522460937,4999.7529296875,4999.7529296875,53.618153162198,5.63819341309429,5.5944652557373,80,1,0,0,1,0.30029296875,33.7243423461914,2,1,3,287.475189208984,0,287.962326049805,,,,,,,,,,,,,,,,,,,,,,,,,,,,,,,,,
,3879859097.65138,283.912033081055,4999.7529296875,1.50812712008687E-5,6.46247859611547E-9,1,6,13.4005146026611,5.00688840110786,33.390000462532,0.0187875918198732,0.0027684381257386,1,-3.30422102700065E-8,,,,,,,,,,,,,,,,,,,,,283.466247558594,284.357818603516,4999.7529296875,4999.7529296875,53.5634391658518,5.63721541526467,5.58534479141235,80,1,0,0,1,0.2996826171875,33.7243423461914,2,1,3,283.466247558594,0,283.912033081055,,,,,,,,,,,,,,,,,,,,,,,,,,,,,,,,,
,3879859121.62098,279.921173095703,4999.7529296875,1.51263230912366E-5,5.98544470835142E-9,1,6,13.4005146026611,5.0067700096615,33.390000462532,0.0188438067328184,0.00277184254137812,1,-3.69744109570686E-8,,,,,,,,,,,,,,,,,,,,,279.457641601562,280.384704589844,4999.7529296875,4999.7529296875,53.4762875859576,5.63854381757141,5.58148050308228,80,1,0,0,1,0.301055908203125,34.7018585205078,2,1,3,279.457641601562,0,279.921173095703,,,,,,,,,,,,,,,,,,,,,,,,,,,,,,,,,
,3879859145.15126,276.041229248047,4999.7529296875,1.52234794734762E-5,6.63325067349602E-9,1,6,13.4005146026611,5.00682591185226,33.390000462532,0.0189646163119167,0.00279316726797559,1,-3.441934865969E-8,,,,,,,,,,,,,,,,,,,,,275.615600585938,276.466857910156,4999.7529296875,4999.7529296875,53.5642207943711,5.63808106772336,5.578688621521,80,1,0,0,1,0.300521850585937,33.7243423461914,2,1,3,275.574035644531,0,276.041229248047,,,,,,,,,,,,,,,,,,,,,,,,,,,,,,,,,
,3879859169.26182,271.929351806641,4999.7529296875,1.53818104993566E-5,7.4679570405071E-9,1,6,13.4005146026611,5.00691025588512,33.3699993789196,0.0191625126100232,0.00282091693258436,1,-3.58749994130113E-8,,,,,,,,,,,,,,,,,,,,,271.464080810547,272.394622802734,4999.7529296875,4999.7529296875,53.5821982503134,5.63719381380797,5.57751035690308,80,1,0,0,1,0.29937744140625,33.7243423461914,2,1,3,271.464080810547,0,271.929351806641,,,,,,,,,,,,,,,,,,,,,,,,,,,,,,,,,
,3879859192.85346,268.027267456055,4999.7529296875,1.54221900740876E-5,6.91107954819706E-9,1,6,13.4005146026611,5.00690147170047,33.3699993789196,0.0192126994762261,0.00282878660247232,1,-3.55907506304582E-8,,,,,,,,,,,,,,,,,,,,,267.615142822266,268.439392089844,4999.7529296875,4999.7529296875,53.5841523216114,5.63850838119825,5.57282495498657,80,1,0,0,1,0.300445556640625,33.2355842590332,2,1,3,267.615142822266,0,268.027267456055,,,,,,,,,,,,,,,,,,,,,,,,,,,,,,,,,
,3879859216.69333,264.155075073242,4999.7529296875,1.54705566163423E-5,6.33478672559425E-9,1,6,13.4005146026611,5.00691685035003,33.3699993789196,0.0192719205601441,0.00284512973229686,1,-2.97126052437094E-8,,,,,,,,,,,,,,,,,,,,,263.700042724609,264.610107421875,4999.7529296875,4999.7529296875,53.4356429029576,5.6376250149384,5.57190656661987,80,1,0,0,1,0.299072265625,33.7243423461914,2,1,3,263.700042724609,0,264.155075073242,,,,,,,,,,,,,,,,,,,,,,,,,,,,,,,,,
,3879859240.56978,260.044845581055,4999.7529296875,1.55203859141501E-5,7.14802119710059E-9,1,6,13.4005146026611,5.0069972221335,33.3699993789196,0.0193364481759957,0.00284085052316957,1,-4.06540780708859E-8,,,,,,,,,,,,,,,,,,,,,259.554138183594,260.535552978516,4999.7529296875,4999.7529296875,53.4094583475633,5.63816580468047,5.5641074180603,80,1,0,0,1,0.29937744140625,34.2131004333496,2,1,3,259.554138183594,0,260.044845581055,,,,,,,,,,,,,,,,,,,,,,,,,,,,,,,,,
,3879859264.40533,256.089309692383,4999.7529296875,1.55765269207859E-5,6.53911635665405E-9,1,6,13.4005146026611,5.00688923146087,33.3499982953072,0.0194051210539016,0.00285563048210548,1,-3.71155162985503E-8,,,,,,,,,,,,,,,,,,,,,255.641235351562,256.537384033203,4999.7529296875,4999.7529296875,53.4653447866883,5.6382559341812,5.56037187576294,80,1,0,0,1,0.300979614257812,33.7243423461914,2,1,3,255.641235351562,0,256.089309692383,,,,,,,,,,,,,,,,,,,,,,,,,,,,,,,,,
,3879859288.34606,252.119750976562,4999.7529296875,1.55995772476389E-5,7.05958947133918E-9,1,6,13.4005146026611,5.00682029282036,33.3499982953072,0.0194327850629183,0.00286433241636034,1,-3.35318809204985E-8,,,,,,,,,,,,,,,,,,,,,251.672836303711,252.566665649414,4999.7529296875,4999.7529296875,53.5106792408037,5.63831839699509,5.55844688415527,80,1,0,0,1,0.300827026367188,33.7243423461914,2,1,3,251.672836303711,0,252.119750976562,,,,,,,,,,,,,,,,,,,,,,,,,,,,,,,,,
,3879859312.1614,248.179328918457,4999.7529296875,1.56511364950456E-5,6.72776598925581E-9,1,6,13.4005146026611,5.00683540971535,33.3499982953072,0.0194980025601226,0.00286775156436504,1,-3.85089592649113E-8,,,,,,,,,,,,,,,,,,,,,247.71257019043,248.646087646484,4999.7529296875,4999.7529296875,53.4989548130153,5.63851550663843,5.55644130706787,80,1,0,0,1,0.299072265625,33.7243423461914,2,1,3,247.71257019043,0,248.179328918457,,,,,,,,,,,,,,,,,,,,,,,,,,,,,,,,,
,3879859336.02339,244.146751403809,4999.7529296875,1.5691532833011E-5,6.24805777557917E-9,1,6,13.4005146026611,5.00683162317724,33.3499982953072,0.0195471732507456,0.00288273036115367,1,-3.25215805137547E-8,,,,,,,,,,,,,,,,,,,,,243.619613647461,244.673889160156,4999.7529296875,4999.7529296875,53.5732095223422,5.63824322458087,5.54939746856689,80,1,0,0,1,0.299148559570313,33.7243423461914,2,1,3,243.619613647461,0,244.146751403809,,,,,,,,,,,,,,,,,,,,,,,,,,,,,,,,,
,3879859359.92115,240.030464172363,4999.7529296875,1.57205997316819E-5,7.34613008658774E-9,1,6,13.4005146026611,5.00674886040833,33.330000936985,0.0195836372027894,0.00288327446112851,1,-3.63793913688372E-8,,,,,,,,,,,,,,,,,,,,,239.551544189453,240.509384155273,4999.7529296875,4999.7529296875,53.498173184496,5.63786961843348,5.5389347076416,80,1,0,0,1,0.307998657226562,34.2131004333496,2,1,3,239.551544189453,0,240.030464172363,,,,,,,,,,,,,,,,,,,,,,,,,,,,,,,,,
,3879859384.12555,236.028671264648,4999.7529296875,1.57712315471403E-5,6.6760996912676E-9,1,6,13.4005146026611,5.00677632586263,33.330000936985,0.0196468093462686,0.00289293149632319,1,-3.62166278770895E-8,,,,,,,,,,,,,,,,,,,,,235.42610168457,236.631240844727,4999.7529296875,4999.7529296875,53.4715978148422,5.63827622526691,5.53520393371582,80,1,0,0,1,0.29998779296875,34.2131004333496,2,1,3,235.409164428711,0,236.028671264648,,,,,,,,,,,,,,,,,,,,,,,,,,,,,,,,,
,3879859407.66592,232.236114501953,4999.7529296875,1.58199719906855E-5,6.9913968489874E-9,1,6,13.4005146026611,5.00685817349187,33.330000936985,0.019707928839639,0.00290226376746484,1,-3.60672215160039E-8,,,,,,,,,,,,,,,,,,,,,231.738403320313,232.733825683594,4999.7529296875,4999.7529296875,53.4418959311114,5.63748842003297,5.52779531478882,80,1,0,0,1,0.30029296875,33.7243423461914,2,1,3,231.738403320313,0,232.236114501953,,,,,,,,,,,,,,,,,,,,,,,,,,,,,,,,,
,3879859432.2192,228.093475341797,4999.7529296875,1.58496081389892E-5,9.3776339478282E-9,1,6,13.4005146026611,5.00689662220316,33.3099998533726,0.0197442189866103,0.00291335666565765,1,-3.16181802122355E-8,,,,,,,,,,,,,,,,,,,,,227.706924438477,228.480026245117,4999.7529296875,4999.7529296875,53.455574430198,5.63744635945487,5.53070592880249,79,1,64,0,0,0.301055908203125,33.7243423461914,2,1,3,227.706924438477,0,228.093475341797,,,,,,,,,,,,,,,,,,,,,,,,,,,,,,,,,
,3879859455.84846,224.053482055664,4999.7529296875,1.58824256395208E-5,6.82069760840509E-9,1,6,13.4005146026611,5.00684355405075,33.3099998533726,0.0197865303723161,0.00290782755059726,1,-4.09326815240003E-8,,,,,,,,,,,,,,,,,,,,,223.597351074219,224.509613037109,4999.7529296875,4999.7529296875,53.5411627530537,5.63746004049046,5.52079391479492,79,1,64,0,0,0.301132202148438,33.7243423461914,2,1,3,223.597351074219,0,224.053482055664,,,,,,,,,,,,,,,,,,,,,,,,,,,,,,,,,
,3879859479.31935,220.270347595215,4999.7529296875,1.59182967055435E-5,6.12774582753789E-9,1,6,13.4005146026611,5.00682698113007,33.3099998533726,0.0198300656241442,0.00292147815375117,1,-3.5326505984311E-8,,,,,,,,,,,,,,,,,,,,,219.798263549805,220.742431640625,4999.7529296875,4999.7529296875,53.501299698573,5.63737183849592,5.51371288299561,80,1,0,0,1,0.299224853515625,34.2131004333496,2,1,3,219.798263549805,0,220.270347595215,,,,,,,,,,,,,,,,,,,,,,,,,,,,,,,,,
,3879859503.50103,216.320571899414,4999.7529296875,1.59634704045049E-5,7.55847658657692E-9,1,6,13.4005146026611,5.00691818561273,33.3099998533726,0.0198867844522843,0.00293025996521744,1,-3.50923220483908E-8,,,,,,,,,,,,,,,,,,,,,215.89892578125,216.742218017578,4999.7529296875,4999.7529296875,53.5407719387941,5.63711323372784,5.51111650466919,80,1,0,0,1,0.299606323242188,33.7243423461914,2,1,3,215.89892578125,0,216.320571899414,,,,,,,,,,,,,,,,,,,,,,,,,,,,,,,,,
,3879859527.3897,212.374397277832,4999.7529296875,1.59950054604176E-5,6.68603283873488E-9,1,6,13.4005146026611,5.0068584603978,33.3099998533726,0.0199258654280305,0.00293514464878109,1,-3.58481576686098E-8,,,,,,,,,,,,,,,,,,,,,211.902389526367,212.846405029297,4999.7529296875,4999.7529296875,53.5739911508614,5.63752168046382,5.5012903213501,80,1,0,0,1,0.300369262695313,34.2131004333496,2,1,3,211.902389526367,0,212.374397277832,,,,,,,,,,,,,,,,,,,,,,,,,,,,,,,,,
,3879859550.98076,208.321105957031,4999.7529296875,1.60129535251995E-5,5.46859332111024E-9,1,6,13.4005146026611,5.00694482399795,33.2899987697601,0.0199490289097918,0.00293634622324248,1,-3.76250764711497E-8,,,,,,,,,,,,,,,,,,,,,207.865814208984,208.776397705078,4999.7529296875,4999.7529296875,53.5415535673134,5.63653517963429,5.49380016326904,80,1,0,0,1,0.298995971679687,34.2131004333496,2,1,3,207.865814208984,0,208.321105957031,,,,,,,,,,,,,,,,,,,,,,,,,,,,,,,,,
,3879859575.00674,204.413352966309,4999.7529296875,1.60446161500502E-5,7.43863100491505E-9,1,6,13.4005146026611,5.00681502606475,33.2899987697601,0.0199882215329541,0.00293889347652192,1,-4.02307010556724E-8,,,,,,,,,,,,,,,,,,,,,203.991683959961,204.835021972656,4999.7529296875,4999.7529296875,53.5102884265441,5.63759679000979,5.49145650863647,79,1,64,0,0,0.300140380859375,33.7243423461914,2,1,3,203.991683959961,0,204.413352966309,,,,,,,,,,,,,,,,,,,,,,,,,,,,,,,,,
,3879859598.73062,200.60294342041,4999.7529296875,1.60756702909451E-5,6.67744286238551E-9,1,6,13.4005146026611,5.00674932686737,33.2899987697601,0.0200265054807882,0.0029447656200648,1,-4.01174708277663E-8,,,,,,,,,,,,,,,,,,,,,200.145156860352,201.060729980469,4999.7529296875,4999.7529296875,53.3906992631018,5.63709046198987,5.48476076126099,80,1,0,0,1,0.30181884765625,33.7243423461914,2,1,3,200.145156860352,0,200.60294342041,,,,,,,,,,,,,,,,,,,,,,,,,,,,,,,,,
,3879859622.56643,196.683601379395,4999.7529296875,1.60978028999744E-5,6.85911907204739E-9,1,6,13.4005146026611,5.00681074167944,33.2899987697601,0.0200541417752487,0.00295073977651563,1,-3.86716429801767E-8,,,,,,,,,,,,,,,,,,,,,196.161437988281,197.205764770508,4999.7529296875,4999.7529296875,53.5755544078999,5.63682232481667,5.47709131240845,80,1,0,0,1,0.299911499023438,34.2131004333496,2,1,3,196.161437988281,0,196.683601379395,,,,,,,,,,,,,,,,,,,,,,,,,,,,,,,,,
,3879859646.44854,192.691184997559,4999.7529296875,1.61239829793809E-5,7.82779470069107E-9,1,6,13.4005146026611,5.00679774884346,33.270001411438,0.0200864822781564,0.00295687120128164,1,-3.76558391871823E-8,,,,,,,,,,,,,,,,,,,,,192.186096191406,193.196273803711,4999.7529296875,4999.7529296875,53.4743335146595,5.63576022831314,5.47357130050659,80,1,0,0,1,0.299835205078125,33.7243423461914,2,1,3,192.186096191406,0,192.691184997559,,,,,,,,,,,,,,,,,,,,,,,,,,,,,,,,,
,3879859670.36861,188.727333068848,4999.7529296875,1.61415648888949E-5,8.10124100526989E-9,1,6,13.4005146026611,5.00678296909106,33.270001411438,0.0201094136759324,0.00295265185631013,1,-4.36643695701719E-8,,,,,,,,,,,,,,,,,,,,,188.279159545898,189.175506591797,4999.7529296875,4999.7529296875,53.506380283948,5.63649111281572,5.45807075500488,80,1,0,0,1,0.299224853515625,33.2355842590332,2,1,3,188.279159545898,0,188.727333068848,,,,,,,,,,,,,,,,,,,,,,,,,,,,,,,,,
,3879859694.29845,184.762077331543,4999.7529296875,1.61886689888154E-5,7.17374477905937E-9,1,6,13.4005146026611,5.00676960119866,33.270001411438,0.0201669961712617,0.0029681107312609,1,-3.82882969828299E-8,,,,,,,,,,,,,,,,,,,,,184.272171020508,185.251983642578,4999.7529296875,4999.7529296875,53.430171503323,5.63683006678737,5.45556545257568,78,1,64,0,0,0.30792236328125,33.7243423461914,2,1,3,184.272171020508,0,184.762077331543,,,,,,,,,,,,,,,,,,,,,,,,,,,,,,,,,
,3879859718.48414,180.744522094727,4999.7529296875,1.62245681323414E-5,6.34458315852966E-9,1,6,13.4005146026611,5.00675693674467,33.270001411438,0.020210527243867,0.00298216056538497,1,-3.23678944298122E-8,,,,,,,,,,,,,,,,,,,,,180.128326416016,181.360717773438,4999.7529296875,4999.7529296875,53.5075527267268,5.63613942588888,5.44880104064941,80,1,0,0,1,0.306015014648438,34.2131004333496,2,1,3,180.072235107422,0,180.744522094727,,,,,,,,,,,,,,,,,,,,,,,,,,,,,,,,,
,3879859742.27547,176.809524536133,4999.7529296875,1.62609013068866E-5,6.37925795591124E-9,1,6,13.4005146026611,5.00676962507188,33.270001411438,0.0202580148074906,0.00297443369992194,1,-4.40163853475672E-8,,,,,,,,,,,,,,,,,,,,,176.207550048828,177.411499023438,4999.7529296875,4999.7529296875,53.4032053194095,5.63627725713721,5.43845319747925,80,1,0,0,1,0.301132202148438,33.7243423461914,2,1,3,176.207550048828,0,176.809524536133,,,,,,,,,,,,,,,,,,,,,,,,,,,,,,,,,
,3879859766.16963,172.810935974121,4999.7529296875,1.6271581302477E-5,6.40816194947881E-9,1,6,13.4005146026611,5.00669418001542,33.2500003278255,0.0202701301308037,0.00298142432977776,1,-3.99500308382373E-8,,,,,,,,,,,,,,,,,,,,,172.26042175293,173.361450195313,4999.7529296875,4999.7529296875,53.4598733870537,5.63641866871339,5.43076944351196,80,1,0,0,1,0.30059814453125,34.2131004333496,2,1,3,172.26042175293,0,172.810935974121,,,,,,,,,,,,,,,,,,,,,,,,,,,,,,,,,
,3879859790.09609,168.868026733398,4999.7529296875,1.63085303787026E-5,6.14879506016277E-9,1,6,13.4005146026611,5.00671142278383,33.2500003278255,0.0203180509460036,0.00297621556824859,1,-4.96716931210644E-8,,,,,,,,,,,,,,,,,,,,,168.256103515625,169.479949951172,4999.7529296875,4999.7529296875,53.5224036685922,5.63664011860856,5.42750644683838,80,1,0,0,1,0.298843383789063,33.7243423461914,2,1,3,168.256103515625,0,168.868026733398,,,,,,,,,,,,,,,,,,,,,,,,,,,,,,,,,
,3879859814.0904,164.831771850586,4999.7529296875,1.63417044523816E-5,6.73553867326007E-9,1,6,13.4005146026611,5.0067561594559,33.2500003278255,0.0203574137437094,0.00299715771565983,1,-3.78472677363241E-8,,,,,,,,,,,,,,,,,,,,,164.366714477539,165.296829223633,4999.7529296875,4999.7529296875,53.4801957285537,5.63732709366721,5.41501045227051,78,1,64,0,0,0.30029296875,33.7243423461914,2,1,3,164.366714477539,0,164.831771850586,,,,,,,,,,,,,,,,,,,,,,,,,,,,,,,,,
,3879859837.88912,160.813789367676,4999.7529296875,1.63628534367448E-5,6.04949544958161E-9,1,6,13.4005146026611,5.00678352824228,33.2500003278255,0.0203851310919263,0.0029929337037011,1,-4.44213493229038E-8,,,,,,,,,,,,,,,,,,,,,160.431045532227,161.196533203125,4999.7529296875,4999.7529296875,53.4938742276403,5.63705594270434,5.40640354156494,80,1,0,0,1,0.298385620117188,33.7243423461914,2,1,3,160.431045532227,0,160.813789367676,,,,,,,,,,,,,,,,,,,,,,,,,,,,,,,,,
,3879859861.35945,156.937850952148,4999.7529296875,1.63964086315916E-5,6.48678520684756E-9,1,6,13.4005146026611,5.00679419011762,33.2500003278255,0.0204259192023734,0.00300627540417141,1,-3.87346452285529E-8,,,,,,,,,,,,,,,,,,,,,156.485397338867,157.39030456543,4999.7529296875,4999.7529296875,53.4172746327557,5.63712546321005,5.40541887283325,80,1,0,0,1,0.298690795898438,33.7243423461914,2,1,3,156.463943481445,0,156.937850952148,,,,,,,,,,,,,,,,,,,,,,,,,,,,,,,,,
,3879859885.65277,152.78311920166,4999.7529296875,1.64089847619193E-5,6.48730373834682E-9,1,6,13.4005146026611,5.00687447956497,33.2299992442131,0.0204415489671851,0.00301195962393793,1,-3.61056971090129E-8,,,,,,,,,,,,,,,,,,,,,152.335311889648,153.230926513672,4999.7529296875,4999.7529296875,53.4508846590826,5.63704574068649,5.39864158630371,80,1,0,0,1,0.2996826171875,33.7243423461914,2,1,3,152.335311889648,0,152.78311920166,,,,,,,,,,,,,,,,,,,,,,,,,,,,,,,,,
,3879859909.20896,148.956672668457,4999.7529296875,1.64341159483991E-5,6.36545102119104E-9,1,6,13.4005146026611,5.00678021298664,33.2299992442131,0.0204725845986516,0.00301470678703853,1,-3.7595500729074E-8,,,,,,,,,,,,,,,,,,,,,148.446166992187,149.467178344727,4999.7529296875,4999.7529296875,53.4594825727941,5.63600484458357,5.38959217071533,80,1,0,0,1,0.30029296875,33.7243423461914,2,1,3,148.395751953125,0,148.956672668457,,,,,,,,,,,,,,,,,,,,,,,,,,,,,,,,,
,3879859933.02391,145.094902038574,4999.7529296875,1.64646860531414E-5,7.01039543931078E-9,1,6,13.4005146026611,5.00675833388629,33.2299992442131,0.020509886352793,0.00302467636101945,1,-3.41480697310708E-8,,,,,,,,,,,,,,,,,,,,,144.618743896484,145.571060180664,4999.7529296875,4999.7529296875,53.4977823702364,5.6371347783958,5.37849140167236,80,1,0,0,1,0.298919677734375,33.7243423461914,2,1,3,144.618743896484,0,145.094902038574,,,,,,,,,,,,,,,,,,,,,,,,,,,,,,,,,
,3879859956.91471,141.029235839844,4999.7529296875,1.65017047685544E-5,6.65040082418783E-9,1,6,13.4005146026611,5.00680242372329,33.2299992442131,0.0205562715228303,0.00303139209415412,1,-3.43229595732473E-8,,,,,,,,,,,,,,,,,,,,,140.600784301758,141.45768737793,4999.7529296875,4999.7529296875,53.5360821676787,5.63719121493661,5.37433576583862,80,1,0,0,1,0.300445556640625,33.7243423461914,2,1,3,140.600784301758,0,141.029235839844,,,,,,,,,,,,,,,,,,,,,,,,,,,,,,,,,
,3879859980.76289,137.371459960938,4999.7529296875,1.65237896303374E-5,6.57310713501982E-9,1,6,13.4005146026611,5.00683112343233,33.220000565052,0.0205835760224202,0.00303795814234662,1,-3.23736824258118E-8,,,,,,,,,,,,,,,,,,,,,136.915969848633,137.826950073242,4999.7529296875,4999.7529296875,53.4899660850441,5.6367410450784,5.3563551902771,80,1,0,0,1,0.300064086914063,33.7243423461914,2,1,3,136.915969848633,0,137.371459960938,,,,,,,,,,,,,,,,,,,,,,,,,,,,,,,,,
,3879860004.62483,133.432014465332,4999.7529296875,1.65497365381464E-5,6.70134028951077E-9,1,6,13.4005146026611,5.00688017387787,33.220000565052,0.020617198931846,0.00303596072088546,1,-3.78925000740743E-8,,,,,,,,,,,,,,,,,,,,,132.931167602539,133.932861328125,4999.7529296875,4999.7529296875,53.4770692144768,5.63653931359754,5.35790824890137,80,1,0,0,1,0.300750732421875,33.7243423461914,2,1,3,132.913970947266,0,133.432014465332,,,,,,,,,,,,,,,,,,,,,,,,,,,,,,,,,
,3879860028.84355,129.375785827637,4999.7529296875,1.65801632028828E-5,6.46101516952244E-9,1,6,13.4005146026611,5.00687080686477,33.220000565052,0.0206538034418259,0.00304986463797831,1,-3.12730298157105E-8,,,,,,,,,,,,,,,,,,,,,128.821929931641,129.929641723633,4999.7529296875,4999.7529296875,53.4293898748037,5.6369532481859,5.3394341468811,80,1,0,0,1,0.2984619140625,33.7243423461914,2,1,3,128.821929931641,0,129.375785827637,,,,,,,,,,,,,,,,,,,,,,,,,,,,,,,,,
,3879860052.72248,125.421447753906,4999.7529296875,1.65829380326849E-5,6.67581682933393E-9,1,6,13.4005146026611,5.00676940671555,33.1999994814396,0.020657680570852,0.00304356778227924,1,-3.6675255351142E-8,,,,,,,,,,,,,,,,,,,,,124.846336364746,125.996559143066,4999.7529296875,4999.7529296875,53.5196679687749,5.63652973435084,5.34050273895264,80,1,0,0,1,0.300445556640625,34.7018585205078,2,1,3,124.814788818359,0,125.421447753906,,,,,,,,,,,,,,,,,,,,,,,,,,,,,,,,,
,3879860076.81613,121.359039306641,4999.7529296875,1.66115367326767E-5,6.37062083375405E-9,1,6,13.4005146026611,5.0067753866375,33.1999994814396,0.0206931159345037,0.00305032672505532,1,-3.55300032769729E-8,,,,,,,,,,,,,,,,,,,,,120.906433105469,121.811645507813,4999.7529296875,4999.7529296875,53.4540111731595,5.63677863792696,5.32745313644409,80,1,0,0,1,0.300827026367188,33.7243423461914,2,1,3,120.906433105469,0,121.359039306641,,,,,,,,,,,,,,,,,,,,,,,,,,,,,,,,,
,3879860100.54807,117.319519042969,4999.7529296875,1.6632591787118E-5,5.93029967571495E-9,1,6,13.4005146026611,5.00675927610784,33.1999994814396,0.0207198648010797,0.00305007726642166,1,-3.88690103878093E-8,,,,,,,,,,,,,,,,,,,,,116.881820678711,117.757217407227,4999.7529296875,4999.7529296875,53.3910900773614,5.63629956890261,5.32069969177246,80,1,0,0,1,0.298995971679687,33.2355842590332,2,1,3,116.881820678711,0,117.319519042969,,,,,,,,,,,,,,,,,,,,,,,,,,,,,,,,,
,3879860124.09983,113.584217071533,4999.7529296875,1.66671958943654E-5,5.59400034786936E-9,1,6,13.4005146026611,5.00666578307934,33.1999994814396,0.0207620408785501,0.00305894729254866,1,-3.68586605637616E-8,,,,,,,,,,,,,,,,,,,,,113.064765930176,114.103668212891,4999.7529296875,4999.7529296875,53.3926533343999,5.63618171236386,5.30674695968628,80,1,0,0,1,0.29998779296875,35.190616607666,2,1,3,113.036842346191,0,113.584217071533,,,,,,,,,,,,,,,,,,,,,,,,,,,,,,,,,
,3879860147.91732,109.519393920898,4999.7529296875,1.6691904069797E-5,7.2020707474474E-9,1,6,13.4005146026611,5.00673809382204,33.1999994814396,0.0207931981627689,0.0030638186986381,1,-3.6692605111204E-8,,,,,,,,,,,,,,,,,,,,,108.925422668457,110.11336517334,4999.7529296875,4999.7529296875,53.3910900773614,5.63651026712292,5.30181646347046,80,1,0,0,1,0.301437377929687,34.2131004333496,2,1,3,108.925422668457,0,109.519393920898,,,,,,,,,,,,,,,,,,,,,,,,,,,,,,,,,
,3879860171.90168,105.538272857666,4999.7529296875,1.67313657185272E-5,6.0666317391725E-9,1,6,13.4005146026611,5.00679819310046,33.1999994814396,0.0208407760344286,0.00308401166995913,1,-2.64219862514448E-8,,,,,,,,,,,,,,,,,,,,,104.981536865234,106.095008850098,4999.7529296875,4999.7529296875,53.445413259448,5.63681182357792,5.28570222854614,80,1,0,0,1,0.30059814453125,33.2355842590332,2,1,3,104.981536865234,0,105.538272857666,,,,,,,,,,,,,,,,,,,,,,,,,,,,,,,,,
,3879860195.6593,101.493087768555,4999.7529296875,1.67424881614071E-5,6.21949711438384E-9,1,6,13.4005146026611,5.00673064543288,33.1799983978271,0.020853930088867,0.0030880547931645,1,-2.47924020312453E-8,,,,,,,,,,,,,,,,,,,,,101.027061462402,101.959114074707,4999.7529296875,4999.7529296875,53.437206159996,5.63642443506145,5.27401781082153,80,1,0,0,1,0.299758911132812,33.7243423461914,2,1,3,101.027061462402,0,101.493087768555,,,,,,,,,,,,,,,,,,,,,,,,,,,,,,,,,
,3879860219.58746,97.574951171875,4999.7529296875,1.67518090843036E-5,6.06417138462026E-9,1,6,13.4005146026611,5.00673847075175,33.1799983978271,0.0208670906691937,0.00307971928010902,1,-3.28857718457203E-8,,,,,,,,,,,,,,,,,,,,,97.1227188110352,98.0271835327148,4999.7529296875,4999.7529296875,53.4184470755345,5.63666508761238,5.26005363464355,80,1,0,0,1,0.30059814453125,33.7243423461914,2,1,3,97.1227188110352,0,97.574951171875,,,,,,,,,,,,,,,,,,,,,,,,,,,,,,,,,
,3879860243.45265,93.5983505249023,4999.7529296875,1.67915341766086E-5,6.5892169275231E-9,1,6,13.4005146026611,5.00667798189272,33.1799983978271,0.0209161515822965,0.00308743717053299,1,-3.25888900561233E-8,,,,,,,,,,,,,,,,,,,,,93.1528396606445,94.0438613891602,4999.7529296875,4999.7529296875,53.4770692144768,5.63637390448829,5.25451755523682,79,1,68,0,0,0.301132202148438,33.7243423461914,2,1,3,93.1528396606445,0,93.5983505249023,,,,,,,,,,,,,,,,,,,,,,,,,,,,,,,,,
,3879860285.22116,86.6123695373535,4999.7529296875,1.6839018247218E-5,6.94543287002296E-9,1,6,13.4005146026611,5.00674910111449,33.1799983978271,0.0209744344577997,0.00310479653047258,1,-2.58015476264792E-8,,,,,,,,,,,,,,,,,,,,,86.1206359863281,87.1041030883789,4999.7529296875,4999.7529296875,53.345755623246,5.63573085948742,5.22171306610107,80,1,0,0,1,0.300445556640625,33.7243423461914,2,1,3,86.1206359863281,0,86.6123695373535,,,,,,,,,,,,,,,,,,,,,,,,,,,,,,,,,
,3879860309.21564,82.8855934143066,4999.7529296875,1.68588534869423E-5,6.56345775848223E-9,1,6,13.4005146026611,5.00667342678884,33.1799983978271,0.0209979872428624,0.0031131341045718,1,-2.20207178427528E-8,,,,,,,,,,,,,,,,,,,,,82.421272277832,83.3499145507812,4999.7529296875,4999.7529296875,53.4141481186787,5.63690134118389,5.21785879135132,78,1,68,0,0,0.300674438476562,34.7018585205078,2,1,3,82.421272277832,0,82.8855934143066,,,,,,,,,,,,,,,,,,,,,,,,,,,,,,,,,
,3879860350.91983,75.9230117797852,4999.7529296875,1.68845133720165E-5,6.6718609481882E-9,1,6,13.4005146026611,5.00666586796028,33.160001039505,0.0210303460080946,0.00311490227138616,1,-2.44340966531101E-8,,,,,,,,,,,,,,,,,,,,,75.4209365844727,76.4250869750977,4999.7529296875,4999.7529296875,53.470816186323,5.63619155513702,5.18289947509766,80,1,0,0,1,0.302200317382812,33.7243423461914,2,1,3,75.4209365844727,0,75.9230117797852,,,,,,,,,,,,,,,,,,,,,,,,,,,,,,,,,
,3879860374.79855,71.7607765197754,4999.7529296875,1.69156366272076E-5,6.52633121405942E-9,1,6,13.4005146026611,5.00655498814781,33.160001039505,0.0210687099532798,0.00311886940462852,1,-2.58266359561933E-8,,,,,,,,,,,,,,,,,,,,,71.2889633178711,72.2325897216797,4999.7529296875,4999.7529296875,53.4899660850441,5.63744673015533,5.17098569869995,80,1,0,0,1,0.300216674804687,33.2355842590332,2,1,3,71.2657089233398,0,71.7607765197754,,,,,,,,,,,,,,,,,,,,,,,,,,,,,,,,,
,3879860398.95819,67.5753746032715,4999.7529296875,1.69509322760718E-5,6.36694622371355E-9,1,6,13.4005146026611,5.00654315844422,33.160001039505,0.0211121908119491,0.00312811239368174,1,-2.36756472104391E-8,,,,,,,,,,,,,,,,,,,,,67.008918762207,68.1418304443359,4999.7529296875,4999.7529296875,53.3664687790057,5.63718625993418,5.14937925338745,80,1,0,0,1,0.300674438476562,33.7243423461914,2,1,3,67.008918762207,0,67.5753746032715,,,,,,,,,,,,,,,,,,,,,,,,,,,,,,,,,
,3879860422.94202,63.553201675415,4999.7529296875,1.69869261349927E-5,5.49171722716612E-9,1,6,13.4005146026611,5.00645843490057,33.160001039505,0.021157463786374,0.00312837279249159,1,-2.87915494590625E-8,,,,,,,,,,,,,,,,,,,,,63.0909996032715,64.0154037475586,4999.7529296875,4999.7529296875,53.4485397735249,5.63775184434455,5.1308913230896,80,1,0,0,1,0.3009033203125,33.7243423461914,2,1,3,63.0909996032715,0,63.553201675415,,,,,,,,,,,,,,,,,,,,,,,,,,,,,,,,,
,3879860446.81799,59.5145092010498,4999.7529296875,1.7015424342055E-5,6.98656435871531E-9,1,6,13.4005146026611,5.00641351991699,33.160001039505,0.0211926601545909,0.00313380068985441,1,-2.86640777157445E-8,,,,,,,,,,,,,,,,,,,,,59.0690803527832,59.9599380493164,4999.7529296875,4999.7529296875,53.4035961336691,5.63748864681855,5.0975775718689,80,1,0,0,1,0.300064086914063,33.7243423461914,2,1,3,59.0690803527832,0,59.5145092010498,,,,,,,,,,,,,,,,,,,,,,,,,,,,,,,,,
,3879860470.72442,55.4036426544189,4999.7529296875,1.70585765415253E-5,6.61619214897887E-9,1,6,13.4005146026611,5.0064797971104,33.160001039505,0.0212459837129564,0.00314725859677389,1,-2.43581886035557E-8,,,,,,,,,,,,,,,,,,,,,54.9767036437988,55.8305816650391,4999.7529296875,4999.7529296875,53.4841038711499,5.63867294758352,5.08218193054199,78,1,32,0,0,0.301361083984375,33.7243423461914,2,1,3,54.9767036437988,0,55.4036426544189,,,,,,,,,,,,,,,,,,,,,,,,,,,,,,,,,
,3879860494.62252,51.4975833892822,4999.7529296875,1.71131214289114E-5,7.23698926817301E-9,1,6,13.4005146026611,5.00651007408479,33.160001039505,0.0213133291085787,0.00316248897328983,1,-2.03080334474309E-8,,,,,,,,,,,,,,,,,,,,,51.0728797912598,51.9222869873047,4999.7529296875,4999.7529296875,53.4938742276403,5.63762804576198,5.05205535888672,80,1,0,0,1,0.307769775390625,33.7243423461914,2,1,3,51.0728797912598,0,51.4975833892822,,,,,,,,,,,,,,,,,,,,,,,,,,,,,,,,,
,3879860518.43663,47.316520690918,4999.7529296875,1.71521931337631E-5,6.37822071708074E-9,1,6,13.4005146026611,5.00648780093522,33.1399999558926,0.021363830694771,0.00315650012640968,1,-3.09466343347539E-8,,,,,,,,,,,,,,,,,,,,,46.8127822875977,47.8202590942383,4999.7529296875,4999.7529296875,53.4024236908903,5.63826771363219,5.01697731018066,80,1,0,0,1,0.299530029296875,33.7243423461914,2,1,3,46.8127822875977,0,47.316520690918,,,,,,,,,,,,,,,,,,,,,,,,,,,,,,,,,
,3879860542.20956,43.229663848877,4999.7529296875,1.72311454530518E-5,7.68742286376017E-9,1,6,13.4005146026611,5.00656578220899,33.1399999558926,0.0214620069400848,0.00317530880242741,1,-2.77081107927729E-8,,,,,,,,,,,,,,,,,,,,,42.6572113037109,43.802116394043,4999.7529296875,4999.7529296875,53.4481489592653,5.63814259480256,4.97858381271362,80,1,0,0,1,0.298614501953125,33.7243423461914,2,1,3,42.6572113037109,0,43.229663848877,,,,,,,,,,,,,,,,,,,,,,,,,,,,,,,,,
,3879860566.19722,39.111686706543,4999.7529296875,1.72852015119954E-5,9.78543480212455E-9,1,6,13.4005146026611,5.00654983685457,33.1399999558926,0.021523813657243,0.00322152860963179,1,1.33425760551444E-9,,,,,,,,,,,,,,,,,,,,,38.528694152832,39.6946792602539,4999.7529296875,4999.7529296875,53.4364245314768,5.63784941959393,4.92911005020142,79,1,68,0,0,0.300674438476562,33.7243423461914,2,1,3,38.4902763366699,0,39.111686706543,,,,,,,,,,,,,,,,,,,,,,,,,,,,,,,,,
,3879860590.10908,35.0816802978516,4999.7529296875,1.73544708181694E-5,7.32371215388194E-9,1,6,13.4005146026611,5.00656526279742,33.1399999558926,0.0216136905180819,0.00321086536307,1,-1.76023819084497E-8,,,,,,,,,,,,,,,,,,,,,34.482967376709,35.6803932189941,4999.7529296875,4999.7529296875,53.4266541749864,5.63841564380313,4.87472248077393,80,1,0,0,1,0.299606323242188,33.7243423461914,2,1,3,34.482967376709,0,35.0816802978516,,,,,,,,,,,,,,,,,,,,,,,,,,,,,,,,,
,3879860613.88872,30.9807462692261,4999.7529296875,1.74370780579015E-5,9.82054254357984E-9,1,6,13.4005146026611,5.00654708248851,33.1399999558926,0.0217165277585886,0.00322568898554409,1,-1.80424973796895E-8,,,,,,,,,,,,,,,,,,,,,30.4049739837646,31.5565185546875,4999.7529296875,4999.7529296875,53.4340796459191,5.63808558144708,4.81927871704102,80,1,0,0,1,0.299758911132812,33.7243423461914,2,1,3,30.4049739837646,0,30.9807462692261,,,,,,,,,,,,,,,,,,,,,,,,,,,,,,,,,
,3879860637.6951,26.9977283477783,4999.7529296875,1.75293215714903E-5,8.43157908469049E-9,1,6,13.4005146026611,5.00653163804003,33.1399999558926,0.021830955575919,0.003245146771629,1,-1.62044579177449E-8,,,,,,,,,,,,,,,,,,,,,26.4032669067383,27.5921897888184,4999.7529296875,4999.7529296875,53.4477581450057,5.63779492359473,4.73795938491821,80,1,0,0,1,0.299530029296875,33.7243423461914,2,1,3,26.4032669067383,0,26.9977283477783,,,,,,,,,,,,,,,,,,,,,,,,,,,,,,,,,
,3879860661.68726,22.9337215423584,4999.7529296875,1.76500365207853E-5,9.07233897750444E-9,1,6,13.4005146026611,5.00651768424513,33.1399999558926,0.0219815576703562,0.0032651434579745,1,-1.81937510055917E-8,,,,,,,,,,,,,,,,,,,,,22.3591632843018,23.508279800415,4999.7529296875,4999.7529296875,53.4387694170345,5.63834362177782,4.63425731658936,80,1,0,0,1,0.3009033203125,33.7243423461914,2,1,3,22.3591632843018,0,22.9337215423584,,,,,,,,,,,,,,,,,,,,,,,,,,,,,,,,,
,3879860701.60074,16.302797794342,4999.7529296875,1.79679852072211E-5,1.71234010261654E-8,1,6,13.4005146026611,5.00650922936344,33.1399999558926,0.0223765521386522,0.00333016845936837,1,-1.35308894166217E-8,,,,,,,,,,,,,,,,,,,,,15.5158376693726,17.0897579193115,4999.7529296875,4999.7529296875,53.4766784002172,5.63875210493974,4.34829521179199,80,1,0,0,1,0.298995971679687,33.7243423461914,2,1,3,15.4993953704834,0,16.302797794342,,,,,,,,,,,,,,,,,,,,,,,,,,,,,,,,,
,3879860727.35247,12.1299648284912,4999.7529296875,1.82398822223051E-5,8.15758233960453E-9,1,6,13.4005146026611,5.00649218552394,33.1399999558926,0.0227107695630034,0.00340917803145278,1,9.25849239508483E-9,,,,,,,,,,,,,,,,,,,,,11.7350282669067,12.5249013900757,4999.7529296875,4999.7529296875,53.4516662876018,5.63838716882621,4.05373811721802,78,1,32,0,0,0.30120849609375,33.7243423461914,2,1,3,11.7350282669067,0,12.1299648284912,,,,,,,,,,,,,,,,,,,,,,,,,,,,,,,,,
,3879860751.15063,9.37447071075439,4999.7529296875,1.85048214177286E-5,7.90750721592245E-9,1,6,13.4005146026611,5.00642096174469,33.1399999558926,0.023042444432058,0.00344356699274884,1,-2.70278995126465E-9,,,,,,,,,,,,,,,,,,,,,9.13354778289795,9.61539363861084,4999.7529296875,4999.7529296875,53.4751151431787,5.63857354670161,3.72959542274475,80,1,0,0,1,0.301132202148438,33.7243423461914,6,1,3,9.61539363861084,0,9.37447071075439,,,,,,,,,,,,,,,,,,,,,,,,,,,,,,,,,
,3879860775.38946,9.17438697814941,4999.7529296875,1.85415478898321E-5,8.86482876724679E-9,1,6,13.4005146026611,5.00641540355493,33.1199988722801,0.0230872429170456,0.00345639872018293,1,2.11253503461497E-9,,,,,,,,,,,,,,,,,,,,,9.09010791778564,9.25866603851318,4999.7529296875,4999.7529296875,53.5149781976595,5.63815141448425,3.57660508155823,79,1,64,0,0,0.299835205078125,33.7243423461914,6,1,3,9.09010791778564,0,9.17438697814941,,,,,,,,,,,,,,,,,,,,,,,,,,,,,,,,,
,3879860798.66265,7.99149060249329,4999.7529296875,1.87310471388605E-5,9.33049054220733E-9,1,6,13.4005146026611,5.00647256912015,33.1199988722801,0.02332529553667,0.00348026256120118,1,-7.11509116759841E-9,,,,,,,,,,,,,,,,,,,,,7.60899686813354,8.37398433685303,4999.7529296875,4999.7529296875,53.4876211994864,5.63827943960701,3.29915332794189,80,1,0,0,1,0.299301147460937,33.7243423461914,6,1,3,7.60899686813354,0,7.99149060249329,,,,,,,,,,,,,,,,,,,,,,,,,,,,,,,,,
,3879860822.49498,6.07377028465271,4999.7529296875,1.91771919870128E-5,7.50910480126155E-9,1,6,13.4005146026611,5.00648094402633,33.1199988722801,0.023881485050956,0.00355941622620905,1,-1.02954603564128E-8,,,,,,,,,,,,,,,,,,,,,5.9150276184082,6.23251295089722,4999.7529296875,4999.7529296875,53.4442408166691,5.63747279834426,2.99416399002075,80,1,0,0,1,0.300979614257812,33.7243423461914,6,1,3,5.9150276184082,0,6.07377028465271,,,,,,,,,,,,,,,,,,,,,,,,,,,,,,,,,
,3879860846.3975,3.64043474197388,4999.7529296875,2.03873093501849E-5,1.73964507065373E-8,1,6,13.4005146026611,5.00656758281542,33.1199988722801,0.0253855211350007,0.00380781386526635,1,8.08751315125423E-9,,,,,,,,,,,,,,,,,,,,,3.24873781204224,4.03213167190552,4999.7529296875,4999.7529296875,53.5513239238037,5.63762922325662,2.54594922065735,80,1,0,0,1,0.3009033203125,33.7243423461914,6,1,3,3.24873781204224,0,3.64043474197388,,,,,,,,,,,,,,,,,,,,,,,,,,,,,,,,,
,3879860870.32868,2.53408098220825,4999.7529296875,2.14395006523701E-5,8.52094867949486E-9,1,6,13.4005146026611,5.00656462722301,33.1199988722801,0.0266988380776041,0.00398301180999702,1,-8.61670433511639E-9,,,,,,,,,,,,,,,,,,,,,2.52074003219604,2.54742193222046,4999.7529296875,4999.7529296875,53.3953890342172,5.6383975123189,2.27807545661926,80,1,0,0,1,0.300064086914063,35.6793746948242,6,1,3,2.52074003219604,0,2.53408098220825,,,,,,,,,,,,,,,,,,,,,,,,,,,,,,,,,
,3879860894.23682,2.50703990459442,4999.7529296875,2.14720439435213E-5,7.45593624714092E-9,1,6,13.4005146026611,5.00650727953528,33.1199988722801,0.0267396723608503,0.0039840738806599,1,-1.25808352180452E-8,,,,,,,,,,,,,,,,,,,,,2.50502729415894,2.50905251502991,4999.7529296875,4999.7529296875,53.503253769871,5.63841501149723,2.24469780921936,80,1,0,0,1,0.30242919921875,33.7243423461914,6,1,3,2.50502729415894,0,2.50703990459442,,,,,,,,,,,,,,,,,,,,,,,,,,,,,,,,,
,3879860918.07363,2.50417482852936,4999.7529296875,2.14869663563888E-5,7.36662306504348E-9,1,6,13.4005146026611,5.00648959052794,33.1199988722801,0.0267569158823736,0.00399489520800332,1,-6.10696587296066E-9,,,,,,,,,,,,,,,,,,,,,2.50296306610107,2.50538659095764,4999.7529296875,4999.7529296875,53.4450224451884,5.63830853228843,2.24434733390808,80,1,0,0,1,0.300750732421875,33.7243423461914,6,1,3,2.50538659095764,0,2.50417482852936,,,,,,,,,,,,,,,,,,,,,,,,,,,,,,,,,
,3879860941.8737,2.51991701126099,4999.7529296875,2.14751502698939E-5,7.87094692386139E-9,1,6,13.4005146026611,5.00647602462304,33.1199988722801,0.0267446460461541,0.00397566644691925,1,-1.97694440967617E-8,,,,,,,,,,,,,,,,,,,,,2.51826167106628,2.52157235145569,4999.7529296875,4999.7529296875,53.4235276609095,5.63856890879217,2.25173592567444,80,1,0,0,1,0.300979614257812,33.7243423461914,6,1,3,2.52157235145569,0,2.51991701126099,,,,,,,,,,,,,,,,,,,,,,,,,,,,,,,,,
,3879860965.78046,2.52182590961456,4999.7529296875,2.14730474746345E-5,7.17036197846723E-9,1,6,13.4005146026611,5.00643601839654,33.1199988722801,0.0267413282638469,0.00397790830928134,1,-1.76187922065453E-8,,,,,,,,,,,,,,,,,,,,,2.52154064178467,2.52211117744446,4999.7529296875,4999.7529296875,53.4747243289191,5.63837488777062,2.25964379310608,80,1,0,0,1,0.30029296875,33.2355842590332,6,1,3,2.52154064178467,0,2.52182590961456,,,,,,,,,,,,,,,,,,,,,,,,,,,,,,,,,
,3879860989.90479,2.51007175445557,4999.7529296875,2.14936048593379E-5,6.22500461663214E-9,1,6,13.4005146026611,5.00639130441005,33.1199988722801,0.0267662168332841,0.00398419510199154,1,-1.56052379888021E-8,,,,,,,,,,,,,,,,,,,,,2.50807213783264,2.51207137107849,4999.7529296875,4999.7529296875,53.5778992934576,5.63835720583216,2.25996518135071,80,1,0,0,1,0.301361083984375,33.7243423461914,6,1,3,2.50807213783264,0,2.51007175445557,,,,,,,,,,,,,,,,,,,,,,,,,,,,,,,,,
,3879861013.9224,2.46324491500854,4999.7529296875,2.1567059451695E-5,7.77677727491082E-9,1,6,13.4005146026611,5.00636477904669,33.1199988722801,0.0268587752015364,0.00398920142690769,1,-2.25492826760367E-8,,,,,,,,,,,,,,,,,,,,,2.45394945144653,2.47254037857056,4999.7529296875,4999.7529296875,53.4821497998518,5.63889270863934,2.24398636817932,80,1,0,0,1,0.300369262695313,33.7243423461914,6,1,3,2.45394945144653,0,2.46324491500854,,,,,,,,,,,,,,,,,,,,,,,,,,,,,,,,,
,3879861037.54293,2.43911623954773,4999.7529296875,2.16071452994222E-5,6.93928037299636E-9,1,6,13.4005146026611,5.00631674686985,33.1199988722801,0.0269056421514524,0.00401456748992385,1,-8.13100287796526E-9,,,,,,,,,,,,,,,,,,,,,2.4375319480896,2.44070053100586,4999.7529296875,4999.7529296875,53.3860094919864,5.63865702977599,2.241375207901,80,1,0,0,1,0.301895141601562,33.7243423461914,6,1,3,2.4375319480896,0,2.43911623954773,,,,,,,,,,,,,,,,,,,,,,,,,,,,,,,,,
,3879861061.38807,2.43660950660706,4999.7529296875,2.1620725675268E-5,6.74893062405988E-9,1,6,13.4005146026611,5.00622660306734,33.1199988722801,0.0269232413365645,0.00400785547333461,1,-1.54720397691163E-8,,,,,,,,,,,,,,,,,,,,,2.43470406532288,2.43851494789124,4999.7529296875,4999.7529296875,53.5282658824864,5.63903856890079,2.24576020240784,80,1,0,0,1,0.300216674804687,34.2131004333496,6,1,3,2.43851494789124,0,2.43660950660706,,,,,,,,,,,,,,,,,,,,,,,,,,,,,,,,,
,3879861085.18431,2.42350029945374,4999.7529296875,2.16404096168157E-5,7.03961532246194E-9,1,6,13.4005146026611,5.00620833737179,33.1199988722801,0.0269481436091946,0.00400795239403767,1,-1.83223748663388E-8,,,,,,,,,,,,,,,,,,,,,2.41842889785767,2.4285717010498,4999.7529296875,4999.7529296875,53.5423351958326,5.63875416761776,2.23646855354309,80,1,0,0,1,0.300064086914063,34.2131004333496,6,1,3,2.41842889785767,0,2.42350029945374,,,,,,,,,,,,,,,,,,,,,,,,,,,,,,,,,
,3879861109.08022,2.37223243713379,4999.7529296875,2.17224477038982E-5,6.10870391234275E-9,1,6,13.4005146026611,5.00618507886397,33.1199988722801,0.027049986601856,0.00402406168938737,1,-1.76357433525275E-8,,,,,,,,,,,,,,,,,,,,,2.36432766914368,2.3801372051239,4999.7529296875,4999.7529296875,53.4497122163037,5.63905738878166,2.21013331413269,80,1,0,0,1,0.300521850585937,33.7243423461914,6,1,3,2.36432766914368,0,2.37223243713379,,,,,,,,,,,,,,,,,,,,,,,,,,,,,,,,,
,3879861132.90886,2.20935940742493,4999.7529296875,2.2010318120305E-5,7.47644969245398E-9,1,6,13.4005146026611,5.00611744848644,33.1199988722801,0.0274062989633652,0.00408828887023332,1,-9.05356701597618E-9,,,,,,,,,,,,,,,,,,,,,2.17138075828552,2.24733805656433,4999.7529296875,4999.7529296875,53.4282174320249,5.63982685950778,2.12695384025574,80,1,0,0,1,0.300369262695313,33.7243423461914,6,1,3,2.17138075828552,0,2.20935940742493,,,,,,,,,,,,,,,,,,,,,,,,,,,,,,,,,
,3879861156.78848,1.99765110015869,4999.7529296875,2.23908547875769E-5,6.29024889636489E-9,1,6,13.4005146026611,5.00614202712161,33.1199988722801,0.027880335784461,0.00415888233763757,1,-9.30451336224575E-9,,,,,,,,,,,,,,,,,,,,,1.99671053886414,1.99859166145325,4999.7529296875,4999.7529296875,53.4715978148422,5.64000987092677,2.03862977027893,80,1,0,0,1,0.301361083984375,34.2131004333496,6,1,3,1.99671053886414,0,1.99765110015869,,,,,,,,,,,,,,,,,,,,,,,,,,,,,,,,,
,3879861180.70047,1.99934601783752,4999.7529296875,2.23681655141969E-5,7.34419328975332E-9,1,6,13.4005146026611,5.00605950598097,33.1199988722801,0.0278530850921435,0.00414358824190434,1,-1.81171734211437E-8,,,,,,,,,,,,,,,,,,,,,1.99883592128754,1.99985611438751,4999.7529296875,4999.7529296875,53.5071619124672,5.64010862781784,2.02117896080017,80,1,0,0,1,0.301895141601562,33.7243423461914,5,1,3,1.99883592128754,0,1.99934601783752,,,,,,,,,,,,,,,,,,,,,,,,,,,,,,,,,
,3879861204.5391,1.99858695268631,4999.7529296875,2.23610860709206E-5,7.72625566288563E-9,1,6,13.4005146026611,5.0061116221779,33.1199988722801,0.027845320029875,0.00413802517521579,1,-2.15746200202155E-8,,,,,,,,,,,,,,,,,,,,,1.9980936050415,1.99908030033112,4999.7529296875,4999.7529296875,53.5208404115537,5.63998459815355,2.01623630523682,80,1,0,0,1,0.303878784179687,33.7243423461914,5,1,3,1.99908030033112,0,1.99858695268631,,,,,,,,,,,,,,,,,,,,,,,,,,,,,,,,,
,3879861216.88176,2.00004649162292,4999.7529296875,2.23755413375741E-5,6.74609323803032E-9,1,6,13.4005146026611,5.00606730940704,33.1199988722801,0.0278650774338588,0.00412659948358695,1,-3.28727049692718E-8,,,,,,,,,,,,,,,,,,,,,2.00002670288086,2.00006628036499,4999.7529296875,4999.7529296875,53.4157113757172,5.64001343332156,2.01032972335815,80,1,0,0,1,0.301895141601562,33.7243423461914,1,1,3,2.00006628036499,0,2.00004649162292,,,,,,,,,,,,,,,,,,,,,,,,,,,,,,,,,