File: SQUID/22169_LCOT/22169_LCOT_MH_275K_FC_0d5T.csv
Comment,Time Stamp (sec),Temperature (K),Magnetic Field (Oe),Moment (emu),M. Std. Err. (emu),Transport Action,Averaging Time (sec),Frequency (Hz),Peak Amplitude (mm),Center Position (mm),Lockin Signal' (V),Lockin Signal (V),Range,M. Quad. Signal (emu),AC Moment (emu),AC M. Std Err. (emu),AC Phase (deg),AC Phase Std. Err. (deg),AC Susceptibility (emu/Oe),AC Suscept. Std Err. (emu/Oe),AC X' (emu/Oe),AC X' Std Err. (emu/Oe),AC X'' (emu/Oe),AC X'' Std Err. (emu/Oe),AC Drive (Oe),AC Frequency (Hz),AC Averaging Time (sec),AC Cycles,AC Range,AC Measure Type,AC Signal' (V),AC Signal'' (V),AC Trim Coil Ratio,AC Trim Coil Phase,Min. Temperature (K),Max. Temperature (K),Min. Field (Oe),Max. Field (Oe),Mass (grams),Motor Lag (deg),Pressure (Torr),Measure Count,Measurement Number,SQUID Status (code),Motor Status (code),Measure Status (code),Motor Current (amps),Motor Temp. (C),Temp. Status (code),Field Status (code),Chamber Status (code),Chamber Temp (K),Redirection State,Average Temp (K),Rotation Angle (deg),Rotator state,DC Moment Fixed Ctr (emu),DC Moment Err Fixed Ctr (emu),DC Moment Free Ctr (emu),DC Moment Err Free Ctr (emu),DC Fixed Fit,DC Free Fit,DC Calculated Center (mm),DC Calculated Center Err (mm),DC Scan Length (mm),DC Scan Time (s),DC Number of Points,DC Squid Drift,DC Min V (V),DC Max V (V),DC Scans per Measure,Sample Resistance,He3 Temperature,Sorb Resistance,Sorb Temperature,Map 05,Map 06,Map 07,Map 08,Map 09,Map 10,Map 11,Map 12,Map 13,Map 14,Map 15,Map 16
,3880035415.90815,270.077743530273,69999.4609375,-3.79446448819055E-4,5.7823083617226E-7,1,4,13.4005146026611,4.98159732762773,33.4200002253056,-0.469340882412571,-0.0692670578790437,1,7.46270162849613E-7,,,,,,,,,,,,,,,,,,,,,270.077178955078,270.078308105469,69999.4609375,69999.4609375,53.1237731237845,5.65395601042054,5.70463514328003,54,1,0,0,1,0.30364990234375,32.7468223571777,1,1,3,270.078308105469,0,270.077743530273,,,,,,,,,,,,,,,,,,,,,,,,,,,,,,,,,
,3880035658.99725,270.044845581055,55000.36328125,-2.87381608050398E-4,1.25952523240303E-7,1,4,13.4005146026611,4.98173393198132,33.4200002253056,-0.355379896082814,-0.0531233082053279,1,3.11134443954305E-8,,,,,,,,,,,,,,,,,,,,,270.042541503906,270.047149658203,55000.36328125,55000.36328125,53.3133180396979,5.65446178767468,5.77331924438477,54,2,0,0,1,0.296783447265625,33.2355842590332,1,1,3,270.042541503906,0,270.044845581055,,,,,,,,,,,,,,,,,,,,,,,,,,,,,,,,,
,3880035879.90593,270.194107055664,39999.74609375,-1.95711020501074E-4,6.56423010655781E-8,1,4,13.4005146026611,4.98167552498589,33.4100015461445,-0.242029937862343,-0.0360763056089842,1,1.02735266781867E-7,,,,,,,,,,,,,,,,,,,,,270.187225341797,270.200988769531,39999.74609375,39999.74609375,53.3223067676691,5.65379980503225,5.84045839309692,54,3,0,0,1,0.297775268554687,33.2355842590332,1,1,3,270.200988769531,0,270.194107055664,,,,,,,,,,,,,,,,,,,,,,,,,,,,,,,,,
,3880036161.09555,270.150741577148,19999.6796875,-7.36801362341744E-5,2.1099909079577E-8,1,4,13.4005146026611,4.98154385151526,33.4200002253056,-0.0911017943419133,-0.0136670961659253,1,-3.07141474328909E-8,,,,,,,,,,,,,,,,,,,,,270.131011962891,270.170471191406,19999.6796875,19999.6796875,53.4587009442749,5.65447915529236,5.91742467880249,54,1,0,0,1,0.304641723632812,34.2131004333496,1,1,3,270.170471191406,0,270.150741577148,,,,,,,,,,,,,,,,,,,,,,,,,,,,,,,,,
,3880036431.30574,270.147964477539,9999.7197265625,-1.35345933641191E-5,1.31056151958566E-8,1,4,13.4005146026611,4.98128537485469,33.4200002253056,-0.0167377835535957,-0.00248259658299692,1,1.68282987339368E-8,,,,,,,,,,,,,,,,,,,,,270.138488769531,270.157440185547,9999.7197265625,9999.7197265625,53.5708646367845,5.65595814947779,5.9817590713501,54,2,0,0,1,0.295333862304687,34.2131004333496,1,1,3,270.138488769531,0,270.147964477539,,,,,,,,,,,,,,,,,,,,,,,,,,,,,,,,,
,3880036519.21484,270.132720947266,8499.58984375,-4.70555707517823E-6,1.22942766115391E-8,1,4,13.4005146026611,4.98126987738046,33.4200002253056,-0.00581618477542513,-8.83148548770762E-4,1,-1.03497482721156E-8,,,,,,,,,,,,,,,,,,,,,270.128936767578,270.136505126953,8499.58984375,8499.58984375,53.5052078411691,5.65599474927242,5.99265336990356,54,3,0,0,1,0.29754638671875,33.7243423461914,1,1,3,270.128936767578,0,270.132720947266,,,,,,,,,,,,,,,,,,,,,,,,,,,,,,,,,
,3880036621.14136,270.294982910156,6499.5927734375,6.79451290163885E-6,1.06316907315963E-8,1,4,13.4005146026611,4.98126764848466,33.4200002253056,0.00841628496275405,0.00115418312693335,1,-8.29374842557715E-8,,,,,,,,,,,,,,,,,,,,,270.286682128906,270.303283691406,6499.5927734375,6499.5927734375,53.4610458298326,5.65562457108648,6.00841808319092,54,1,0,0,1,0.304718017578125,33.7243423461914,1,1,3,270.286682128906,0,270.294982910156,,,,,,,,,,,,,,,,,,,,,,,,,,,,,,,,,
,3880036719.84673,270.378448486328,4999.5390625,1.49733018459373E-5,9.37248863118112E-9,1,4,13.4005146026611,4.98135972724861,33.4200002253056,0.0185271761784452,0.00268102973823513,1,-7.16077625162894E-8,,,,,,,,,,,,,,,,,,,,,270.367645263672,270.389251708984,4999.5390625,4999.5390625,53.541944381573,5.65535537854973,6.01847410202026,54,2,0,0,1,0.297088623046875,33.2355842590332,6,1,3,270.389251708984,0,270.378448486328,,,,,,,,,,,,,,,,,,,,,,,,,,,,,,,,,
,3880036818.64045,270.283401489258,3499.849609375,2.2241973154103E-5,1.20129134391335E-8,1,4,13.4005146026611,4.98124122831349,33.4200002253056,0.0275148551288768,0.00401763509142904,1,-7.7856595128994E-8,,,,,,,,,,,,,,,,,,,,,270.272308349609,270.294494628906,3499.849609375,3499.849609375,53.6064287344095,5.65567257851387,6.03179931640625,54,3,0,0,1,0.305557250976562,33.2355842590332,1,1,3,270.270812988281,0,270.283401489258,,,,,,,,,,,,,,,,,,,,,,,,,,,,,,,,,
,3880037013.09806,270.385269165039,2899.59130859375,2.44765869734419E-5,1.08912347644158E-8,1,4,13.4005146026611,4.98137662193159,33.4100015461445,0.0302537963658618,0.00459916599725543,1,5.80508852004681E-8,,,,,,,,,,,,,,,,,,,,,270.382843017578,270.3876953125,2899.59130859375,2899.59130859375,53.4813681713326,5.65570367744827,6.0472526550293,54,1,0,0,1,0.305709838867188,33.2355842590332,1,1,3,270.3876953125,0,270.385269165039,,,,,,,,,,,,,,,,,,,,,,,,,,,,,,,,,
,3880037098.86806,270.283569335938,2749.76586914062,2.49514680181259E-5,1.27673399134486E-8,1,4,13.4005146026611,4.98116869042213,33.4100015461445,0.0308327627812894,0.00472952652883103,1,9.26654263634493E-8,,,,,,,,,,,,,,,,,,,,,270.277557373047,270.289581298828,2749.76586914062,2749.76586914062,53.6267510759095,5.65631911724701,6.0590615272522,54,2,0,0,1,0.304641723632812,33.2355842590332,1,1,3,270.289581298828,0,270.283569335938,,,,,,,,,,,,,,,,,,,,,,,,,,,,,,,,,
,3880037171.26313,270.173614501953,2599.76416015625,2.54129876831909E-5,1.10896291444233E-8,1,4,13.4005146026611,4.98124074981267,33.4100015461445,0.0314044112944698,0.00481238089024886,1,9.05586829154106E-8,,,,,,,,,,,,,,,,,,,,,270.167510986328,270.179718017578,2599.76416015625,2599.76416015625,53.569301379746,5.65661870116468,6.06195545196533,53,3,68,0,0,0.305099487304687,33.2355842590332,1,1,3,270.167510986328,0,270.173614501953,,,,,,,,,,,,,,,,,,,,,,,,,,,,,,,,,
,3880037253.98445,270.295776367187,2399.64868164062,2.58523305720593E-5,2.17934754075166E-8,1,4,13.4005146026611,4.98103639282316,33.4200002253056,0.0319291906995368,0.00500428647889417,1,1.80279278845581E-7,,,,,,,,,,,,,,,,,,,,,270.279724121094,270.311828613281,2399.64868164062,2399.64868164062,53.5579677662172,5.65664759584921,6.07202768325806,54,1,0,0,1,0.3045654296875,32.7468223571777,1,1,3,270.311828613281,0,270.295776367187,,,,,,,,,,,,,,,,,,,,,,,,,,,,,,,,,
,3880037325.41227,270.282989501953,2249.57153320313,2.62166983346088E-5,1.49147599759253E-8,1,4,13.4005146026611,4.98122423943717,33.4200002253056,0.0323931568898578,0.00499329173005446,1,1.16665418529379E-7,,,,,,,,,,,,,,,,,,,,,270.2724609375,270.293518066406,2249.57153320313,2249.57153320313,53.4481489592653,5.65631508359308,6.07566452026367,52,2,68,0,0,0.296173095703125,33.2355842590332,1,1,3,270.293518066406,0,270.282989501953,,,,,,,,,,,,,,,,,,,,,,,,,,,,,,,,,
,3880037397.68596,270.241638183594,2099.68310546875,2.6476969579303E-5,1.11703547452576E-8,1,4,13.4005146026611,4.98124057724351,33.4200002253056,0.0327201562666019,0.00500772786299432,1,8.93875904959232E-8,,,,,,,,,,,,,,,,,,,,,270.233978271484,270.249298095703,2099.68310546875,2099.68310546875,53.5278750682268,5.65626477963017,6.07952785491943,54,3,0,0,1,0.297622680664063,33.7243423461914,1,1,3,270.233978271484,0,270.241638183594,,,,,,,,,,,,,,,,,,,,,,,,,,,,,,,,,
,3880037479.96437,270.336563110352,1899.78161621094,2.66333389960563E-5,2.49172169156927E-8,1,4,13.4005146026611,4.9812585252905,33.4100015461445,0.032895498626213,0.00515808817560639,1,1.87583876120358E-7,,,,,,,,,,,,,,,,,,,,,270.3203125,270.352813720703,1899.78161621094,1899.78161621094,53.4864487567076,5.65567802205729,6.08747529983521,54,1,0,0,1,0.297088623046875,33.7243423461914,1,1,3,270.352813720703,0,270.336563110352,,,,,,,,,,,,,,,,,,,,,,,,,,,,,,,,,
,3880037553.80204,270.286956787109,1749.81774902344,2.66842866275276E-5,1.46972363191741E-8,1,4,13.4005146026611,4.98125421112965,33.4100015461445,0.0329728167821394,0.00507147748055161,1,1.09918264429816E-7,,,,,,,,,,,,,,,,,,,,,270.281646728516,270.292266845703,1749.81774902344,1749.81774902344,53.6263602616499,5.65656822873821,6.09601926803589,54,2,0,0,1,0.303878784179687,33.2355842590332,1,1,3,270.281646728516,0,270.286956787109,,,,,,,,,,,,,,,,,,,,,,,,,,,,,,,,,
,3880037626.08544,270.306381225586,1599.50146484375,2.65999457027815E-5,1.1538205927061E-8,1,4,13.4005146026611,4.98113062568063,33.4100015461445,0.0328698595245424,0.00503919909140602,1,9.65708785871485E-8,,,,,,,,,,,,,,,,,,,,,270.302673339844,270.310089111328,1599.50146484375,1599.50146484375,53.5036445841307,5.65668422744228,6.10040855407715,54,3,0,0,1,0.305099487304687,33.2355842590332,1,1,3,270.302673339844,0,270.306381225586,,,,,,,,,,,,,,,,,,,,,,,,,,,,,,,,,
,3880037706.89334,270.213150024414,1399.78881835938,2.62193079363995E-5,2.21790836861699E-8,1,4,13.4005146026611,4.98111802118859,33.4100015461445,0.0323801080386853,0.00509594041441652,1,1.99419581943265E-7,,,,,,,,,,,,,,,,,,,,,270.206756591797,270.219543457031,1399.78881835938,1399.78881835938,53.5333464678614,5.65655597277808,6.10423564910889,53,1,68,0,0,0.297164916992188,33.2355842590332,1,1,3,270.206756591797,0,270.213150024414,,,,,,,,,,,,,,,,,,,,,,,,,,,,,,,,,
,3880037777.39475,270.17561340332,1249.54797363281,2.58026701400958E-5,1.70322049872001E-8,1,4,13.4005146026611,4.98116303631873,33.4200002253056,0.0318806603353364,0.00491686756498712,1,1.16859005970026E-7,,,,,,,,,,,,,,,,,,,,,270.163604736328,270.187622070313,1249.54797363281,1249.54797363281,53.5048170269095,5.65527283425921,6.11010026931763,53,2,68,0,0,0.296630859375,33.2355842590332,1,1,3,270.187622070313,0,270.17561340332,,,,,,,,,,,,,,,,,,,,,,,,,,,,,,,,,
,3880037848.63679,270.272155761719,1099.74768066406,2.5182748114144E-5,1.40016802069187E-8,1,4,13.4005146026611,4.98108511537815,33.4100015461445,0.0311170165358102,0.00477865680562769,1,9.78950477196248E-8,,,,,,,,,,,,,,,,,,,,,270.2666015625,270.277709960938,1099.74768066406,1099.74768066406,53.5243577398903,5.65546114578646,6.11688566207886,53,3,68,0,0,0.300369262695313,33.2355842590332,1,1,3,270.2666015625,0,270.272155761719,,,,,,,,,,,,,,,,,,,,,,,,,,,,,,,,,
,3880037930.32296,270.253021240234,899.833618164062,2.38535928797043E-5,2.47800890161238E-8,1,4,13.4005146026611,4.98088878337593,33.4200002253056,0.0294480752330572,0.00469292091016957,1,2.27593486644691E-7,,,,,,,,,,,,,,,,,,,,,270.250335693359,270.255706787109,899.833618164062,899.833618164062,53.5036445841307,5.65681164435625,6.11981773376465,53,1,68,0,0,0.29815673828125,33.2355842590332,1,1,3,270.255706787109,0,270.253021240234,,,,,,,,,,,,,,,,,,,,,,,,,,,,,,,,,
,3880037999.75889,270.271423339844,749.743896484375,2.25887268713972E-5,1.55557298331051E-8,1,4,13.4005146026611,4.98101743339384,33.4200002253056,0.0279027808696503,0.00434252612075516,1,1.33259883387472E-7,,,,,,,,,,,,,,,,,,,,,270.265319824219,270.277526855469,749.743896484375,749.743896484375,53.5962675636595,5.65583691364661,6.12569665908813,54,2,0,0,1,0.298614501953125,33.7243423461914,1,1,3,270.265319824219,0,270.271423339844,,,,,,,,,,,,,,,,,,,,,,,,,,,,,,,,,
,3880038072.30204,270.377700805664,599.855529785156,2.09175554594683E-5,1.47481314477846E-8,1,4,13.4005146026611,4.9809623083014,33.4200002253056,0.0258402646457647,0.0040064607070745,1,1.11485150078441E-7,,,,,,,,,,,,,,,,,,,,,270.373382568359,270.382019042969,599.855529785156,599.855529785156,53.4313439461018,5.65605714457563,6.12721109390259,52,3,68,0,0,0.29754638671875,33.2355842590332,1,1,3,270.373382568359,0,270.377700805664,,,,,,,,,,,,,,,,,,,,,,,,,,,,,,,,,
,3880038153.99194,270.266418457031,399.928863525391,1.76982380890862E-5,2.67563080049986E-8,1,4,13.4005146026611,4.98091121450403,33.4100015461445,0.021838905888662,0.00355087881805589,1,2.24619501418932E-7,,,,,,,,,,,,,,,,,,,,,270.244689941406,270.288146972656,399.928863525391,399.928863525391,53.6544988883422,5.65702378847657,6.13175916671753,53,1,68,0,0,0.303573608398438,33.2355842590332,1,1,3,270.288146972656,0,270.266418457031,,,,,,,,,,,,,,,,,,,,,,,,,,,,,,,,,
,3880038247.56764,270.412399291992,249.813903808594,1.45564628469174E-5,1.09019545598302E-8,1,4,13.4005146026611,4.98099988389135,33.4100015461445,0.0179812805615294,0.00279527240010072,1,8.33727691330249E-8,,,,,,,,,,,,,,,,,,,,,270.408294677734,270.41650390625,249.813903808594,249.813903808594,53.4735518861403,5.65630301945551,6.1365966796875,54,2,0,0,1,0.29693603515625,33.2355842590332,1,1,3,270.408294677734,0,270.412399291992,,,,,,,,,,,,,,,,,,,,,,,,,,,,,,,,,
,3880038345.18561,270.349655151367,100.001098632813,1.02056543531088E-5,1.70672992058236E-8,1,4,13.4005146026611,4.98107865193003,33.4100015461445,0.0125922380327254,0.00205919190629723,1,1.38818125359978E-7,,,,,,,,,,,,,,,,,,,,,270.346588134766,270.352722167969,100.001098632813,100.001098632813,53.5610942802941,5.65699216084585,6.14929580688477,53,3,68,0,0,0.29754638671875,33.2355842590332,1,1,3,270.346588134766,0,270.349655151367,,,,,,,,,,,,,,,,,,,,,,,,,,,,,,,,,
,3880038475.14373,270.312805175781,-99.9255676269531,1.95854108572594E-6,2.42614544560649E-8,1,4,13.4005146026611,4.98093647852247,33.4200002253056,0.00237227455480397,6.90443973291541E-4,10,2.6548345116831E-7,,,,,,,,,,,,,,,,,,,,,270.311126708984,270.314483642578,-99.9255676269531,-99.9255676269531,53.6142450196018,5.65689716528421,6.14504861831665,54,1,0,0,1,0.3045654296875,33.2355842590332,1,1,3,270.311126708984,0,270.312805175781,,,,,,,,,,,,,,,,,,,,,,,,,,,,,,,,,
,3880038585.08255,270.28630065918,-249.889434814453,-4.63164689025037E-6,1.74769440096067E-8,1,4,13.4005146026611,4.98093673490564,33.4200002253056,-0.00574918450696792,-7.02798425107413E-4,10,1.24403794683082E-7,,,,,,,,,,,,,,,,,,,,,270.285064697266,270.287536621094,-249.889434814453,-249.889434814453,53.5853247643903,5.65648175781537,6.13983488082886,54,2,0,0,1,0.297164916992188,33.2355842590332,1,1,3,270.283752441406,0,270.28630065918,,,,,,,,,,,,,,,,,,,,,,,,,,,,,,,,,
,3880038686.93484,270.288009643555,-399.802978515625,-9.86422832602648E-6,9.13004117782278E-7,1,4,13.4005146026611,4.98083379501883,33.4200002253056,-0.0123827274204741,-5.69000994250508E-4,1,1.01537512916978E-6,,,,,,,,,,,,,,,,,,,,,270.286346435547,270.289672851562,-399.802978515625,-399.802978515625,53.4743335146595,5.65721466659099,6.13343143463135,54,3,0,0,1,0.30029296875,32.7468223571777,1,1,3,270.286346435547,0,270.288009643555,,,,,,,,,,,,,,,,,,,,,,,,,,,,,,,,,
,3880038794.37226,270.450393676758,-599.729675292969,-1.57634521500393E-5,8.92519579623874E-9,1,4,13.4005146026611,4.98101773284911,33.4100015461445,-0.0195073548886336,-0.00279303924450932,1,9.90030276267748E-8,,,,,,,,,,,,,,,,,,,,,270.442352294922,270.458435058594,-599.729675292969,-599.729675292969,53.5509331095441,5.65648386573349,6.12846899032593,54,1,0,0,1,0.296173095703125,33.7243423461914,1,1,3,270.442352294922,0,270.450393676758,,,,,,,,,,,,,,,,,,,,,,,,,,,,,,,,,
,3880038866.55533,270.152465820313,-749.76904296875,-1.88330507674521E-5,1.60592640816423E-8,1,4,13.4005146026611,4.98123271844653,33.4200002253056,-0.023319810546056,-0.00325424031271626,1,1.85319231546363E-7,,,,,,,,,,,,,,,,,,,,,270.149871826172,270.155059814453,-749.76904296875,-749.76904296875,53.516541454698,5.65551899191406,6.12230396270752,53,2,68,0,0,0.2972412109375,33.2355842590332,1,1,3,270.149871826172,0,270.152465820313,,,,,,,,,,,,,,,,,,,,,,,,,,,,,,,,,
,3880038938.39111,270.214996337891,-899.632202148438,-2.10940346735229E-5,1.63577149037218E-8,1,4,13.4005146026611,4.98113013837541,33.4200002253056,-0.026106470774405,-0.00372652320511469,1,1.41484835486746E-7,,,,,,,,,,,,,,,,,,,,,270.208068847656,270.221923828125,-899.632202148438,-899.632202148438,53.5200587830345,5.6559041899446,6.11770439147949,54,3,0,0,1,0.305557250976562,33.2355842590332,1,1,3,270.221923828125,0,270.214996337891,,,,,,,,,,,,,,,,,,,,,,,,,,,,,,,,,
,3880039020.61169,270.267013549805,-1099.62182617188,-2.35831356763449E-5,2.92419914916526E-7,1,4,13.4005146026611,4.98098419508942,33.4200002253056,-0.0292017260561721,-0.00405988832904401,1,2.44074598255473E-7,,,,,,,,,,,,,,,,,,,,,270.256408691406,270.277618408203,-1099.62182617188,-1099.62182617188,53.5806349932749,5.65592782984627,6.11755323410034,53,1,68,0,0,0.2960205078125,33.2355842590332,1,1,3,270.277618408203,0,270.267013549805,,,,,,,,,,,,,,,,,,,,,,,,,,,,,,,,,
,3880039092.27144,270.357879638672,-1249.62353515625,-2.43409926335952E-5,1.1329463553397E-8,1,4,13.4005146026611,4.98095704618897,33.4100015461445,-0.0301218541192417,-0.00431101496037947,1,1.54296326399265E-7,,,,,,,,,,,,,,,,,,,,,270.353973388672,270.361785888672,-1249.62353515625,-1249.62353515625,53.4633907153903,5.65661467178756,6.11275911331177,54,2,0,0,1,0.296554565429687,33.2355842590332,1,1,3,270.361785888672,0,270.357879638672,,,,,,,,,,,,,,,,,,,,,,,,,,,,,,,,,
,3880039165.52869,270.288925170898,-1399.56225585938,-2.51331329384282E-5,8.16493680828693E-9,1,4,13.4005146026611,4.98083008128277,33.4100015461445,-0.0310968989510497,-0.00447863829508774,1,1.37083813526058E-7,,,,,,,,,,,,,,,,,,,,,270.286163330078,270.291687011719,-1399.56225585938,-1399.56225585938,53.4579193157556,5.6571172703964,6.10703134536743,52,3,68,0,0,0.297470092773438,33.2355842590332,1,1,3,270.291687011719,0,270.288925170898,,,,,,,,,,,,,,,,,,,,,,,,,,,,,,,,,
,3880039249.6952,270.141128540039,-1599.52661132813,-2.5770894220554E-5,2.00411906567128E-8,1,4,13.4005146026611,4.98076405757372,33.4100015461445,-0.031895826464732,-0.00452249724025703,1,1.96944309853746E-7,,,,,,,,,,,,,,,,,,,,,270.136199951172,270.146057128906,-1599.52661132813,-1599.52661132813,53.4966099274576,5.65724039068591,6.10003995895386,54,1,0,0,1,0.297470092773438,33.2355842590332,1,1,3,270.136199951172,0,270.141128540039,,,,,,,,,,,,,,,,,,,,,,,,,,,,,,,,,
,3880039323.2692,270.148315429687,-1749.64147949219,-2.60305430450861E-5,1.01612506120552E-8,1,4,13.4005146026611,4.9807362357668,33.4100015461445,-0.032206620786352,-0.00463696188400954,1,1.43166953772888E-7,,,,,,,,,,,,,,,,,,,,,270.144165039062,270.152465820313,-1749.64147949219,-1749.64147949219,53.5224036685922,5.65768205945309,6.10064458847046,52,2,68,0,0,0.305557250976562,33.7243423461914,1,1,3,270.152465820313,0,270.148315429687,,,,,,,,,,,,,,,,,,,,,,,,,,,,,,,,,
,3880039395.65218,270.079956054687,-1899.73132324219,-2.6155407922854E-5,5.10239958502302E-8,1,4,13.4005146026611,4.98095705206397,33.4200002253056,-0.0323502261000844,-0.00474572317865478,1,7.41077603361259E-8,,,,,,,,,,,,,,,,,,,,,270.078430175781,270.081481933594,-1899.73132324219,-1899.73132324219,53.491138527823,5.65661535407908,6.07296276092529,54,3,0,0,1,0.297698974609375,33.2355842590332,1,1,3,270.078216552734,0,270.079956054687,,,,,,,,,,,,,,,,,,,,,,,,,,,,,,,,,
,3880039477.6398,270.246185302734,-2099.7333984375,-2.61270544479386E-5,5.22837370865754E-8,1,4,13.4005146026611,4.98077295290222,33.4100015461445,-0.0323245174032569,-0.00466655462173057,1,1.33705938310774E-7,,,,,,,,,,,,,,,,,,,,,270.224822998047,270.267547607422,-2099.7333984375,-2099.7333984375,53.4755059574383,5.6572161295361,6.07377862930298,54,1,0,0,1,0.297622680664063,33.2355842590332,1,1,3,270.267547607422,0,270.246185302734,,,,,,,,,,,,,,,,,,,,,,,,,,,,,,,,,
,3880039565.84027,270.348739624023,-2249.72241210938,-2.58718073691962E-5,1.0616675954077E-8,1,4,13.4005146026611,4.98089283289709,33.4100015461445,-0.0320091000427399,-0.00462583962036822,1,1.28583015406E-7,,,,,,,,,,,,,,,,,,,,,270.341400146484,270.356079101562,-2249.72241210938,-2249.72241210938,53.5079435409864,5.657448828881,6.07200908660889,54,2,0,0,1,0.2960205078125,33.2355842590332,1,1,3,270.341400146484,0,270.348739624023,,,,,,,,,,,,,,,,,,,,,,,,,,,,,,,,,
,3880039637.78261,270.202484130859,-2399.6611328125,-2.55794288543076E-5,1.43084107206087E-8,1,4,13.4005146026611,4.98069384094912,33.4200002253056,-0.0316399788472951,-0.0046108084243317,1,9.67940388699914E-8,,,,,,,,,,,,,,,,,,,,,270.200500488281,270.204467773438,-2399.6611328125,-2399.6611328125,53.5818074360538,5.65765561482855,6.07328510284424,52,3,68,0,0,0.304489135742188,32.7468223571777,1,1,3,270.204467773438,0,270.202484130859,,,,,,,,,,,,,,,,,,,,,,,,,,,,,,,,,
,3880039720.2803,270.096496582031,-2599.7265625,-2.52041165579399E-5,8.25583023565526E-8,1,4,13.4005146026611,4.9809523329565,33.4100015461445,-0.0311874364719207,-0.00448050575682573,1,1.46316834204342E-7,,,,,,,,,,,,,,,,,,,,,270.084838867187,270.108154296875,-2599.7265625,-2599.7265625,53.4692529292845,5.65684637373064,6.06981945037842,54,1,0,0,1,0.297775268554687,32.2580642700195,1,1,3,270.108154296875,0,270.096496582031,,,,,,,,,,,,,,,,,,,,,,,,,,,,,,,,,
,3880039792.29859,270.201736450195,-2749.62744140625,-2.47029205780933E-5,8.74881227672763E-9,1,4,13.4005146026611,4.98077077128711,33.4100015461445,-0.0305600408237319,-0.00442898286739728,1,1.1283206247578E-7,,,,,,,,,,,,,,,,,,,,,270.196411132813,270.207061767578,-2749.62744140625,-2749.62744140625,53.4497122163037,5.6572410084042,6.07060241699219,54,2,0,0,1,0.297698974609375,33.7243423461914,1,1,3,270.196411132813,0,270.201736450195,,,,,,,,,,,,,,,,,,,,,,,,,,,,,,,,,
,3880039864.20198,270.375869750977,-2899.57861328125,-2.42323216529985E-5,7.68750384459395E-9,1,4,13.4005146026611,4.980798878527,33.4100015461445,-0.0299769982178214,-0.0043520038737687,1,1.04729007006799E-7,,,,,,,,,,,,,,,,,,,,,270.372406005859,270.379333496094,-2899.57861328125,-2899.57861328125,53.5607034660345,5.6567211624482,6.07245826721191,53,3,68,0,0,0.305709838867188,33.2355842590332,6,1,3,270.379333496094,0,270.375869750977,,,,,,,,,,,,,,,,,,,,,,,,,,,,,,,,,
,3880040041.09316,270.111953735352,-3499.81176757812,-2.19239736901623E-5,8.69962803813151E-9,1,4,13.4005146026611,4.981035224646,33.4100015461445,-0.0271084026076495,-0.00403677797877807,1,1.46138095441498E-8,,,,,,,,,,,,,,,,,,,,,270.111145019531,270.112762451172,-3499.81176757812,-3499.81176757812,53.5915777925441,5.65679016658061,6.07510089874268,54,1,0,0,1,0.305328369140625,33.2355842590332,1,1,3,270.112762451172,0,270.111953735352,,,,,,,,,,,,,,,,,,,,,,,,,,,,,,,,,
,3880040123.95799,270.247909545898,-4999.740234375,-1.46822308408096E-5,3.96371320271041E-8,1,4,13.4005146026611,4.9808986042496,33.4200002253056,-0.0181538520212265,-0.0027008178866362,1,1.17776482840675E-8,,,,,,,,,,,,,,,,,,,,,270.236297607422,270.259521484375,-4999.740234375,-4999.740234375,53.5560136949191,5.65678357405683,6.07085514068604,54,2,0,0,1,0.30487060546875,33.7243423461914,1,1,3,270.259521484375,0,270.247909545898,,,,,,,,,,,,,,,,,,,,,,,,,,,,,,,,,
,3880040208.66604,270.217422485352,-6499.857421875,-6.49718024035061E-6,9.85588462532742E-9,1,4,13.4005146026611,4.98089860700827,33.4200002253056,-0.00802878382541511,-0.00122630411506828,1,-1.99747847584303E-8,,,,,,,,,,,,,,,,,,,,,270.20947265625,270.225372314453,-6499.857421875,-6499.857421875,53.5509331095441,5.65689518787237,6.07139730453491,54,3,0,0,1,0.296401977539063,33.2355842590332,1,1,3,270.20947265625,0,270.217422485352,,,,,,,,,,,,,,,,,,,,,,,,,,,,,,,,,
,3880040305.7811,270.172149658203,-8499.841796875,4.99742762714015E-6,1.20220161373699E-8,1,4,13.4005146026611,4.98100650948368,33.4200002253056,0.0061918928964298,8.34863518257812E-4,1,-7.23141004752147E-8,,,,,,,,,,,,,,,,,,,,,270.146545410156,270.19775390625,-8499.841796875,-8499.841796875,53.5427260100922,5.65629340413134,6.06895256042481,54,1,0,0,1,0.298004150390625,33.2355842590332,1,1,3,270.19775390625,0,270.172149658203,,,,,,,,,,,,,,,,,,,,,,,,,,,,,,,,,
,3880040390.1497,270.241775512695,-9999.7578125,1.3795183140145E-5,1.2013025944713E-8,1,4,13.4005146026611,4.98086277831872,33.4200002253056,0.0170641758447011,0.0024889091115554,1,-5.04657742709432E-8,,,,,,,,,,,,,,,,,,,,,270.230072021484,270.253479003906,-9999.7578125,-9999.7578125,53.569301379746,5.65646267030884,6.07009983062744,54,2,0,0,1,0.30426025390625,33.2355842590332,1,1,3,270.253479003906,0,270.241775512695,,,,,,,,,,,,,,,,,,,,,,,,,,,,,,,,,
,3880040661.69633,270.086853027344,-19999.716796875,7.39167995041974E-5,1.96512188302544E-8,1,4,13.4005146026611,4.98097410002709,33.4100015461445,0.0913981110204492,0.0135860218903056,1,-6.84912693292753E-8,,,,,,,,,,,,,,,,,,,,,270.084320068359,270.089385986328,-19999.716796875,-19999.716796875,53.4774600287364,5.65709268734876,6.06229829788208,54,3,0,0,1,0.297164916992188,33.7243423461914,1,1,3,270.084320068359,0,270.086853027344,,,,,,,,,,,,,,,,,,,,,,,,,,,,,,,,,
,3880040944.13669,270.136413574219,-39999.62109375,1.95932245757669E-4,5.04133770495464E-8,1,4,13.4005146026611,4.9809920534564,33.4100015461445,0.24226342350947,0.0360662658791654,1,-1.38330749908963E-7,,,,,,,,,,,,,,,,,,,,,270.128601074219,270.144226074219,-39999.62109375,-39999.62109375,53.3594341223326,5.65639530711037,6.05945491790771,54,1,0,0,1,0.297317504882812,32.7468223571777,1,1,3,270.144226074219,0,270.136413574219,,,,,,,,,,,,,,,,,,,,,,,,,,,,,,,,,
,3880041176.87302,269.999740600586,-54999.74609375,2.87627438200116E-4,1.03756534383344E-7,1,4,13.4005146026611,4.98100511798721,33.4100015461445,0.355628724420043,0.0530384051339306,1,-1.27738214922906E-7,,,,,,,,,,,,,,,,,,,,,269.999481201172,270,-54999.74609375,-54999.74609375,53.3598249365922,5.65641004879949,6.05153656005859,54,2,0,0,1,0.297012329101562,33.2355842590332,1,1,3,270,0,269.999740600586,,,,,,,,,,,,,,,,,,,,,,,,,,,,,,,,,
,3880041422.02429,270.183166503906,-69999.5234375,3.79501556267137E-4,1.39028315912786E-7,1,4,13.4005146026611,4.9809137954419,33.4200002253056,0.469215814165518,0.0699511675664638,1,-1.90374658320968E-7,,,,,,,,,,,,,,,,,,,,,270.182678222656,270.183654785156,-69999.5234375,-69999.5234375,53.228902159621,5.65582096985951,6.05078363418579,54,3,0,0,1,0.29815673828125,33.7243423461914,1,1,3,270.182678222656,0,270.183166503906,,,,,,,,,,,,,,,,,,,,,,,,,,,,,,,,,
,3880041706.05822,270.065887451172,-49999.6171875,2.56870507795758E-4,1.18949558833451E-7,1,4,13.4005146026611,4.98083357903244,33.4200002253056,0.317584056050277,0.0473698148148134,1,-1.09818161118248E-7,,,,,,,,,,,,,,,,,,,,,270.064086914062,270.067687988281,-49999.6171875,-49999.6171875,53.3824921636499,5.65724522884142,6.05003118515015,54,1,0,0,1,0.298004150390625,33.7243423461914,1,1,3,270.064086914062,0,270.065887451172,,,,,,,,,,,,,,,,,,,,,,,,,,,,,,,,,
,3880041929.71902,270.090835571289,-34999.70703125,1.65187341800042E-4,4.13197259857344E-8,1,4,13.4005146026611,4.98103809073931,33.4200002253056,0.204245868748805,0.0304420310378079,1,-8.85217435193268E-8,,,,,,,,,,,,,,,,,,,,,270.089782714844,270.091888427734,-34999.70703125,-34999.70703125,53.4024236908903,5.65684477487888,6.05145597457886,54,2,0,0,1,0.297698974609375,34.2131004333496,1,1,3,270.091888427734,0,270.090835571289,,,,,,,,,,,,,,,,,,,,,,,,,,,,,,,,,
,3880042150.60644,270.132568359375,-19999.703125,7.37195650950667E-5,2.73730141409865E-8,1,4,13.4005146026611,4.98110766164937,33.4200002253056,0.0911533231301792,0.0135792815465964,1,-4.48515073233356E-8,,,,,,,,,,,,,,,,,,,,,270.122924804687,270.142211914062,-19999.703125,-19999.703125,53.5016905128326,5.65635454104117,6.04442977905273,54,3,0,0,1,0.307159423828125,33.7243423461914,1,1,3,270.142211914062,0,270.132568359375,,,,,,,,,,,,,,,,,,,,,,,,,,,,,,,,,
,3880042353.85501,270.134231567383,-9500.29296875,1.05624570008393E-5,1.3433374628311E-8,1,4,13.4005146026611,4.98094572931894,33.4100015461445,0.0130503545437342,0.00200834481147778,1,4.43772095099954E-8,,,,,,,,,,,,,,,,,,,,,270.131896972656,270.136566162109,-9500.29296875,-9500.29296875,53.6685682016884,5.65691418429948,6.04741764068604,54,1,0,0,1,0.2978515625,34.2131004333496,1,1,3,270.131896972656,0,270.134231567383,,,,,,,,,,,,,,,,,,,,,,,,,,,,,,,,,
,3880042448.48869,270.038009643555,-8000.5029296875,1.79876099228956E-6,1.12393919298996E-8,1,4,13.4005146026611,4.98103447306931,33.4100015461445,0.00221639605690177,3.82825157675602E-4,1,4.0557967168276E-8,,,,,,,,,,,,,,,,,,,,,270.037353515625,270.038665771484,-8000.5029296875,-8000.5029296875,53.5517147380633,5.65648029538867,6.04245662689209,52,2,68,0,0,0.29754638671875,33.7243423461914,1,1,3,270.038665771484,0,270.038009643555,,,,,,,,,,,,,,,,,,,,,,,,,,,,,,,,,
,3880042557.38503,270.253692626953,-6500.423828125,-6.77179726042746E-6,9.8392360627068E-9,1,4,13.4005146026611,4.98098420927813,33.4100015461445,-0.00838069131593506,-0.00119559606839919,1,4.59681847955871E-8,,,,,,,,,,,,,,,,,,,,,270.250915527344,270.256469726562,-6500.423828125,-6500.423828125,53.5270934397076,5.65676423679141,6.04361629486084,54,3,0,0,1,0.296096801757812,33.7243423461914,1,1,3,270.256469726562,0,270.253692626953,,,,,,,,,,,,,,,,,,,,,,,,,,,,,,,,,
,3880042656.0425,270.171691894531,-4500.50244140625,-1.75563592234826E-5,1.08925720639363E-8,1,4,13.4005146026611,4.98100166765335,33.4100015461445,-0.0217241025587461,-0.00312330727967064,1,1.0006657636149E-7,,,,,,,,,,,,,,,,,,,,,270.153472900391,270.189910888672,-4500.50244140625,-4500.50244140625,53.4227460323903,5.65689971003207,6.04527044296265,52,1,68,0,0,0.300369262695313,33.7243423461914,1,1,3,270.189910888672,0,270.171691894531,,,,,,,,,,,,,,,,,,,,,,,,,,,,,,,,,
,3880042740.96958,270.176223754883,-3000.37280273438,-2.41980056457928E-5,8.79267014880939E-9,1,4,13.4005146026611,4.98100528182165,33.4100015461445,-0.0299332250889229,-0.00436657046882365,1,8.80182662601233E-8,,,,,,,,,,,,,,,,,,,,,270.164703369141,270.187744140625,-3000.37280273438,-3000.37280273438,53.4313439461018,5.65676296363223,6.04333591461182,54,2,0,0,1,0.2972412109375,33.7243423461914,1,1,3,270.187744140625,0,270.176223754883,,,,,,,,,,,,,,,,,,,,,,,,,,,,,,,,,
,3880042828.40196,270.239303588867,-2900.37182617188,-2.44636093519673E-5,1.11585768595834E-8,1,4,13.4005146026611,4.98097316981252,33.4100015461445,-0.0302324142617952,-0.00460893220128167,1,-6.83145148633855E-8,,,,,,,,,,,,,,,,,,,,,270.236602783203,270.242004394531,-2900.37182617188,-2900.37182617188,53.607991991448,5.65737416365519,6.03679418563843,54,3,0,0,1,0.30487060546875,33.7243423461914,1,1,3,270.242004394531,0,270.239303588867,,,,,,,,,,,,,,,,,,,,,,,,,,,,,,,,,
,3880042923.28209,270.343307495117,-2700.419921875,-2.5056436262267E-5,1.8671933653506E-8,1,4,13.4005146026611,4.98086078490888,33.4100015461445,-0.030945632602405,-0.00484362706928817,1,-1.69587523234485E-7,,,,,,,,,,,,,,,,,,,,,270.335784912109,270.350830078125,-2700.419921875,-2700.419921875,53.5907961640249,5.657344104061,6.03852128982544,54,1,0,0,1,0.305557250976562,33.7243423461914,1,1,3,270.335784912109,0,270.343307495117,,,,,,,,,,,,,,,,,,,,,,,,,,,,,,,,,
,3880042994.33419,270.157073974609,-2550.443359375,-2.55258720944768E-5,1.55807709148879E-8,1,4,13.4005146026611,4.98094891597061,33.4200002253056,-0.0315405301120368,-0.00483861088612295,1,-9.52081573540379E-8,,,,,,,,,,,,,,,,,,,,,270.151275634766,270.162872314453,-2550.443359375,-2550.443359375,53.5950951208807,5.65678343534931,6.0406060218811,53,2,68,0,0,0.297622680664063,34.2131004333496,1,1,3,270.151275634766,0,270.157073974609,,,,,,,,,,,,,,,,,,,,,,,,,,,,,,,,,
,3880043065.05176,270.278610229492,-2400.4794921875,-2.59209116218004E-5,1.20797928770598E-8,1,4,13.4005146026611,4.98097884499442,33.4100015461445,-0.0320342885090598,-0.00487766697863073,1,-6.76700106600388E-8,,,,,,,,,,,,,,,,,,,,,270.270874023438,270.286346435547,-2400.4794921875,-2400.4794921875,53.4415051168518,5.65636384926809,6.04161500930786,54,3,0,0,1,0.29754638671875,33.2355842590332,1,1,3,270.269989013672,0,270.278610229492,,,,,,,,,,,,,,,,,,,,,,,,,,,,,,,,,
,3880043147.66229,270.205184936523,-2200.38916015625,-2.62855458707281E-5,1.9924220350826E-8,1,4,13.4005146026611,4.9809738334085,33.4200002253056,-0.0324641266696555,-0.00508497199619689,1,-1.80806502177306E-7,,,,,,,,,,,,,,,,,,,,,270.198486328125,270.211883544922,-2200.38916015625,-2200.38916015625,53.562266723073,5.65661655927342,6.04014921188354,54,1,0,0,1,0.297698974609375,33.7243423461914,1,1,3,270.198486328125,0,270.205184936523,,,,,,,,,,,,,,,,,,,,,,,,,,,,,,,,,
,3880043219.99776,270.213500976562,-2050.3623046875,-2.65201031606024E-5,1.72619394971704E-8,1,4,13.4005146026611,4.98106252663322,33.4100015461445,-0.0327652513044871,-0.00505951989885151,1,-1.25029050537304E-7,,,,,,,,,,,,,,,,,,,,,270.206146240234,270.220855712891,-2050.3623046875,-2050.3623046875,53.4258725464672,5.65651068576591,6.04071807861328,54,2,0,0,1,0.297698974609375,33.7243423461914,1,1,3,270.220855712891,0,270.213500976562,,,,,,,,,,,,,,,,,,,,,,,,,,,,,,,,,
,3880043291.07831,270.147659301758,-1900.42358398438,-2.66473468541713E-5,1.4659463892921E-8,1,4,13.4005146026611,4.98088669750571,33.4200002253056,-0.0329277536243696,-0.0050372475381616,1,-8.81815883778453E-8,,,,,,,,,,,,,,,,,,,,,270.141174316406,270.154144287109,-1900.42358398438,-1900.42358398438,53.4266541749864,5.65668070046026,6.04123306274414,54,3,0,0,1,0.298233032226562,33.7243423461914,1,1,3,270.141174316406,0,270.147659301758,,,,,,,,,,,,,,,,,,,,,,,,,,,,,,,,,
,3880043385.17167,270.334411621094,-1700.11938476562,-2.66120373007363E-5,2.12663955310261E-8,1,4,13.4005146026611,4.98089095548928,33.4100015461445,-0.0328621897321875,-0.00517745545144696,1,-2.06868132980678E-7,,,,,,,,,,,,,,,,,,,,,270.332336425781,270.336486816406,-1700.11938476562,-1700.11938476562,53.6154174623807,5.6573421069992,6.03935432434082,54,1,0,0,1,0.295257568359375,33.7243423461914,1,1,3,270.336486816406,0,270.334411621094,,,,,,,,,,,,,,,,,,,,,,,,,,,,,,,,,
,3880043456.04421,270.419311523438,-1550.11767578125,-2.65054868284558E-5,1.91166802692891E-8,1,4,13.4005146026611,4.98070263633095,33.4100015461445,-0.0327449906340895,-0.00504873986751886,1,-1.1891057631724E-7,,,,,,,,,,,,,,,,,,,,,270.415710449219,270.422912597656,-1550.11767578125,-1550.11767578125,53.4211827753518,5.65806486124338,6.04162216186523,54,2,0,0,1,0.296783447265625,33.7243423461914,6,1,3,270.422912597656,0,270.419311523438,,,,,,,,,,,,,,,,,,,,,,,,,,,,,,,,,
,3880043527.09932,270.308029174805,-1400.14123535156,-2.62766461270781E-5,1.34435565160498E-8,1,4,13.4005146026611,4.98082400192859,33.4200002253056,-0.0324710771271943,-0.00495393657477208,1,-7.63194910586756E-8,,,,,,,,,,,,,,,,,,,,,270.305541992187,270.310516357422,-1400.14123535156,-1400.14123535156,53.4125848616403,5.6574128905723,6.04275035858154,53,3,68,0,0,0.296173095703125,33.7243423461914,1,1,3,270.305541992187,0,270.308029174805,,,,,,,,,,,,,,,,,,,,,,,,,,,,,,,,,
,3880043609.6008,270.23649597168,-1200.12646484375,-2.55792005422004E-5,2.22418967961983E-8,1,4,13.4005146026611,4.98081695952011,33.4100015461445,-0.0315859953439041,-0.00497724554978898,1,-1.99515227004433E-7,,,,,,,,,,,,,,,,,,,,,270.230926513672,270.242065429687,-1200.12646484375,-1200.12646484375,53.5536688093614,5.65704024027549,6.03275918960571,54,1,0,0,1,0.298233032226562,33.2355842590332,1,1,3,270.242065429687,0,270.23649597168,,,,,,,,,,,,,,,,,,,,,,,,,,,,,,,,,
,3880043680.06978,270.157623291016,-1050.14990234375,-2.48855884779634E-5,1.65317568335959E-8,1,4,13.4005146026611,4.98077447693701,33.4100015461445,-0.0307413777819307,-0.0047603738459444,1,-1.27897727635639E-7,,,,,,,,,,,,,,,,,,,,,270.156707763672,270.158538818359,-1050.14990234375,-1050.14990234375,53.5435076386114,5.65678100499769,6.03505992889404,54,2,0,0,1,0.297622680664063,33.2355842590332,1,1,3,270.156707763672,0,270.157623291016,,,,,,,,,,,,,,,,,,,,,,,,,,,,,,,,,
,3880043751.26174,270.135986328125,-900.173522949219,-2.3902092999997E-5,1.45408028187369E-8,1,4,13.4005146026611,4.98104982609993,33.4100015461445,-0.0295339488347364,-0.00453783410422152,1,-9.47271513434556E-8,,,,,,,,,,,,,,,,,,,,,270.134368896484,270.137603759766,-900.173522949219,-900.173522949219,53.498173184496,5.65603736344097,6.03789520263672,52,3,68,0,0,0.3057861328125,33.2355842590332,1,1,3,270.137603759766,0,270.135986328125,,,,,,,,,,,,,,,,,,,,,,,,,,,,,,,,,
,3880043833.76162,270.359024047852,-700.133605957031,-2.18654755595825E-5,1.60788017146021E-7,1,4,13.4005146026611,4.98094338130731,33.4100015461445,-0.0269896993662998,-0.00433121038473486,1,-2.32374350962137E-7,,,,,,,,,,,,,,,,,,,,,270.344482421875,270.373565673828,-700.133605957031,-700.133605957031,53.4684713007653,5.65636325849338,6.04151964187622,53,1,68,0,0,0.298385620117188,33.2355842590332,1,1,3,270.373565673828,0,270.359024047852,,,,,,,,,,,,,,,,,,,,,,,,,,,,,,,,,
,3880043917.75445,270.377792358398,-550.157104492188,-2.01704467538119E-5,1.73971349561981E-8,1,4,13.4005146026611,4.98082518456374,33.4100015461445,-0.0249049226407467,-0.00393973304309247,1,-1.69398537894912E-7,,,,,,,,,,,,,,,,,,,,,270.372894287109,270.382690429687,-550.157104492188,-550.157104492188,53.5939226781018,5.65738329372703,6.03446769714355,54,2,0,0,1,0.298004150390625,33.7243423461914,1,1,3,270.382690429687,0,270.377792358398,,,,,,,,,,,,,,,,,,,,,,,,,,,,,,,,,
,3880044001.25612,270.205123901367,-400.180633544922,-1.77417083687237E-5,1.4546182051036E-8,1,4,13.4005146026611,4.98087543454968,33.4100015461445,-0.0219144476492731,-0.00341168446865911,1,-1.05555578713636E-7,,,,,,,,,,,,,,,,,,,,,270.197692871094,270.212554931641,-400.180633544922,-400.180633544922,53.447367330746,5.65642999215505,6.03137826919556,54,3,0,0,1,0.299453735351562,33.2355842590332,1,1,3,270.197692871094,0,270.205123901367,,,,,,,,,,,,,,,,,,,,,,,,,,,,,,,,,
,3880044095.06149,270.363693237305,-200.153259277344,-1.31263021310386E-5,2.76414843710202E-8,1,4,13.4005146026611,4.98094731029511,33.4100015461445,-0.0161817559554111,-0.00273877982513359,1,-2.51655333485476E-7,,,,,,,,,,,,,,,,,,,,,270.356323242187,270.371063232422,-200.153259277344,-200.153259277344,53.5575769519576,5.65676390624836,6.03383731842041,52,1,68,0,0,0.29754638671875,33.7243423461914,1,1,3,270.371063232422,0,270.363693237305,,,,,,,,,,,,,,,,,,,,,,,,,,,,,,,,,
,3880044165.54987,270.228210449219,-50.1767845153809,-8.4089537221444E-6,2.25344212852498E-8,1,4,13.4005146026611,4.98075972205886,33.4200002253056,-0.0103649893020256,-0.00175974879816274,1,-1.65525022195948E-7,,,,,,,,,,,,,,,,,,,,,270.224090576172,270.232330322266,-50.1767845153809,-50.1767845153809,53.6177623479384,5.65757157898499,6.03794860839844,52,2,68,0,0,0.295257568359375,33.2355842590332,1,1,3,270.224090576172,0,270.228210449219,,,,,,,,,,,,,,,,,,,,,,,,,,,,,,,,,
,3880044235.94627,270.175186157227,99.799690246582,-1.97902663728543E-6,1.66880948517197E-8,1,4,13.4005146026611,4.98067825832979,33.4100015461445,-0.00242421822042234,-5.15086974720697E-4,1,-1.20610854757742E-7,,,,,,,,,,,,,,,,,,,,,270.174041748047,270.176330566406,99.799690246582,99.799690246582,53.5907961640249,5.65790488566666,6.02929019927978,54,3,0,0,1,0.304718017578125,33.7243423461914,1,1,3,270.176330566406,0,270.175186157227,,,,,,,,,,,,,,,,,,,,,,,,,,,,,,,,,
,3880044334.97735,270.368927001953,299.688598632812,6.65872311138118E-6,1.88945468417434E-8,1,4,13.4005146026611,4.98068157571075,33.4100015461445,0.00826462512554895,0.00101124868695589,1,-1.78091540333922E-7,,,,,,,,,,,,,,,,,,,,,270.354766845703,270.383087158203,299.688598632812,299.688598632812,53.5204495972941,5.65739983955573,6.03511571884155,54,1,0,0,1,0.30059814453125,33.2355842590332,1,1,3,270.383087158203,0,270.368927001953,,,,,,,,,,,,,,,,,,,,,,,,,,,,,,,,,
,3880044406.61629,270.202850341797,449.790924072266,1.1822623559349E-5,1.43548191314972E-8,1,4,13.4005146026611,4.98079018832287,33.4100015461445,0.0146433868973042,0.00200262697584186,1,-1.48689830112991E-7,,,,,,,,,,,,,,,,,,,,,270.196105957031,270.209594726562,449.790924072266,449.790924072266,53.4938742276403,5.65710312884951,6.0333685874939,54,2,0,0,1,0.298614501953125,33.2355842590332,1,1,3,270.196105957031,0,270.202850341797,,,,,,,,,,,,,,,,,,,,,,,,,,,,,,,,,
,3880044494.81707,270.312789916992,599.792602539063,1.58009956207986E-5,1.54016013678918E-8,1,4,13.4005146026611,4.98082925717537,33.4100015461445,0.0195578144980833,0.00276586525484857,1,-1.26479789111888E-7,,,,,,,,,,,,,,,,,,,,,270.305572509766,270.320007324219,599.792602539063,599.792602539063,53.4645631581691,5.65707721374644,6.03097486495972,54,3,0,0,1,0.297775268554687,33.2355842590332,1,1,3,270.320007324219,0,270.312789916992,,,,,,,,,,,,,,,,,,,,,,,,,,,,,,,,,
,3880044592.93792,270.19059753418,799.681457519531,1.96983913522083E-5,1.79521333600504E-8,1,4,13.4005146026611,4.98091285458963,33.4100015461445,0.0243950212530858,0.00336394538153211,1,-2.2579550850333E-7,,,,,,,,,,,,,,,,,,,,,270.181793212891,270.199401855469,799.681457519531,799.681457519531,53.5274842539672,5.6566577876268,6.03504371643066,54,1,0,0,1,0.29754638671875,33.7243423461914,1,1,3,270.199401855469,0,270.19059753418,,,,,,,,,,,,,,,,,,,,,,,,,,,,,,,,,
,3880044665.14483,270.314758300781,949.771240234375,2.17149095632291E-5,1.81862528344193E-8,1,4,13.4005146026611,4.98077663626864,33.4100015461445,0.026871980195769,0.00383731519470967,1,-1.44444916827915E-7,,,,,,,,,,,,,,,,,,,,,270.306884765625,270.322631835938,949.771240234375,949.771240234375,53.5954859351403,5.65692048075048,6.03567171096802,53,2,68,0,0,0.298080444335937,33.7243423461914,1,1,3,270.322631835938,0,270.314758300781,,,,,,,,,,,,,,,,,,,,,,,,,,,,,,,,,
,3880044736.26219,270.273208618164,1099.76025390625,2.32378664446884E-5,4.06724995027049E-8,1,4,13.4005146026611,4.98106385911824,33.4100015461445,0.0287537785559381,0.0041413551660969,1,-1.26605664433483E-7,,,,,,,,,,,,,,,,,,,,,270.267120361328,270.279296875,1099.76025390625,1099.76025390625,53.516541454698,5.65649848861681,6.0295557975769,54,3,0,0,1,0.305557250976562,33.2355842590332,1,1,3,270.279296875,0,270.273208618164,,,,,,,,,,,,,,,,,,,,,,,,,,,,,,,,,
,3880044818.59931,270.369140625,1299.68701171875,2.4691287895149E-5,1.32483649424243E-8,1,4,13.4005146026611,4.98108894042073,33.4100015461445,0.0305635686335035,0.00432582160169381,1,-1.94852028493244E-7,,,,,,,,,,,,,,,,,,,,,270.360870361328,270.377410888672,1299.68701171875,1299.68701171875,53.5513239238037,5.65668452672519,6.02769231796265,53,1,68,0,0,0.29693603515625,33.7243423461914,1,1,3,270.360870361328,0,270.369140625,,,,,,,,,,,,,,,,,,,,,,,,,,,,,,,,,
,3880044890.85763,270.361099243164,1449.68859863281,2.53350238702986E-5,9.65092890993841E-9,1,4,13.4005146026611,4.9809899543107,33.4200002253056,0.0313484527826279,0.00451251528138454,1,-1.40047506563152E-7,,,,,,,,,,,,,,,,,,,,,270.359191894531,270.363006591797,1449.68859863281,1449.68859863281,53.638475503698,5.65715316618171,6.0286111831665,54,2,0,0,1,0.305862426757812,33.2355842590332,1,1,3,270.363006591797,0,270.361099243164,,,,,,,,,,,,,,,,,,,,,,,,,,,,,,,,,
,3880044962.57188,270.291442871094,1599.56433105469,2.57816188864859E-5,8.34962839588359E-9,1,4,13.4005146026611,4.98094586151425,33.4200002253056,0.0318959259901022,0.00462360572251156,1,-1.16954184355705E-7,,,,,,,,,,,,,,,,,,,,,270.283721923828,270.299163818359,1599.56433105469,1599.56433105469,53.5642207943711,5.65570520702617,6.03296041488647,54,3,0,0,1,0.297470092773438,33.2355842590332,1,1,3,270.283721923828,0,270.291442871094,,,,,,,,,,,,,,,,,,,,,,,,,,,,,,,,,
,3880045044.62652,270.29069519043,1799.60424804687,2.6086777421473E-5,1.5709690106727E-8,1,4,13.4005146026611,4.98115476490762,33.4100015461445,0.0322824380128627,0.00463126013619329,1,-1.56633242951176E-7,,,,,,,,,,,,,,,,,,,,,270.273254394531,270.308135986328,1799.60424804687,1799.60424804687,53.567347308448,5.65581481914096,6.03651475906372,52,1,68,0,0,0.30548095703125,32.7468223571777,1,1,3,270.308135986328,0,270.29069519043,,,,,,,,,,,,,,,,,,,,,,,,,,,,,,,,,
,3880045116.95782,270.328964233398,1949.90808105469,2.61158033155365E-5,7.57473044940003E-9,1,4,13.4005146026611,4.98100800058884,33.4200002253056,0.0323114152090631,0.00467369506493623,1,-1.26497400930069E-7,,,,,,,,,,,,,,,,,,,,,270.324279785156,270.333648681641,1949.90808105469,1949.90808105469,53.6287051472076,5.65629962859639,6.02928590774536,53,2,68,0,0,0.298004150390625,33.2355842590332,1,1,3,270.333648681641,0,270.328964233398,,,,,,,,,,,,,,,,,,,,,,,,,,,,,,,,,
,3880045188.87813,270.282318115234,2099.82153320313,2.6044112929987E-5,8.48393969969892E-9,1,4,13.4005146026611,4.98094818789652,33.4100015461445,0.0322189401739875,0.00468240511529781,1,-1.08664096134079E-7,,,,,,,,,,,,,,,,,,,,,270.274139404297,270.290496826172,2099.82153320313,2099.82153320313,53.5642207943711,5.65647628795858,6.03169345855713,54,3,0,0,1,0.296630859375,33.7243423461914,1,1,3,270.274139404297,0,270.282318115234,,,,,,,,,,,,,,,,,,,,,,,,,,,,,,,,,
,3880045271.04266,270.208786010742,2299.89916992187,2.57926117534167E-5,8.21578126447148E-9,1,4,13.4005146026611,4.98097226456856,33.4200002253056,0.0319133511403444,0.00460162786537634,1,-1.36403198680747E-7,,,,,,,,,,,,,,,,,,,,,270.195922851562,270.221649169922,2299.89916992187,2299.89916992187,53.5403811245345,5.65654565901527,6.03177690505981,54,1,0,0,1,0.29754638671875,33.2355842590332,1,1,3,270.221649169922,0,270.208786010742,,,,,,,,,,,,,,,,,,,,,,,,,,,,,,,,,
,3880045342.55035,270.331588745117,2449.92602539062,2.54939373852942E-5,8.11194493049422E-9,1,4,13.4005146026611,4.98085839801173,33.4200002253056,0.0315408865026479,0.00456090274414505,1,-1.24545362220215E-7,,,,,,,,,,,,,,,,,,,,,270.324157714844,270.339019775391,2449.92602539062,2449.92602539062,53.5618759088134,5.65701128120894,6.02409982681274,52,2,68,0,0,0.298538208007812,33.7243423461914,1,1,3,270.339019775391,0,270.331588745117,,,,,,,,,,,,,,,,,,,,,,,,,,,,,,,,,
,3880045414.41461,270.232421875,2599.73901367187,2.51319429109322E-5,8.51103186118341E-9,1,4,13.4005146026611,4.98098873934946,33.4200002253056,0.031090478308512,0.00452099857051657,1,-1.02804945322573E-7,,,,,,,,,,,,,,,,,,,,,270.227844238281,270.236999511719,2599.73901367187,2599.73901367187,53.5333464678614,5.65717900941749,6.02825832366943,52,3,68,0,0,0.298919677734375,33.2355842590332,1,1,3,270.227844238281,0,270.232421875,,,,,,,,,,,,,,,,,,,,,,,,,,,,,,,,,
,3880045496.73214,270.162155151367,2799.91748046875,2.45570171095652E-5,8.68085735789592E-9,1,4,13.4005146026611,4.98096310701239,33.4100015461445,0.030379127531452,0.00441684979835059,1,-1.01013806190766E-7,,,,,,,,,,,,,,,,,,,,,270.134887695313,270.189422607422,2799.91748046875,2799.91748046875,53.5728187080826,5.65698464095875,6.02898788452148,54,1,0,0,1,0.296478271484375,33.2355842590332,1,1,3,270.189422607422,0,270.162155151367,,,,,,,,,,,,,,,,,,,,,,,,,,,,,,,,,
,3880045568.68825,270.175979614258,2949.818359375,2.40767724722738E-5,8.78921220647226E-9,1,4,13.4005146026611,4.98094233802905,33.4100015461445,0.029787032199119,0.00431585680656509,1,-1.1083981875397E-7,,,,,,,,,,,,,,,,,,,,,270.169250488281,270.182708740234,2949.818359375,2949.818359375,53.3949982199576,5.65646469471625,6.02994155883789,54,2,0,0,1,0.299758911132812,33.2355842590332,1,1,3,270.182891845703,0,270.175979614258,,,,,,,,,,,,,,,,,,,,,,,,,,,,,,,,,
,3880045681.71127,270.414077758789,3499.53491210937,2.19176903914403E-5,8.15945558368389E-9,1,4,13.4005146026611,4.9809892555209,33.4200002253056,0.0271007554280243,0.0040324067838808,1,-1.71671806784086E-8,,,,,,,,,,,,,,,,,,,,,270.406341552734,270.421813964844,3499.53491210937,3499.53491210937,53.5798533647557,5.65612600307257,6.0258297920227,54,3,0,0,1,0.306472778320313,33.2355842590332,1,1,3,270.406341552734,0,270.414077758789,,,,,,,,,,,,,,,,,,,,,,,,,,,,,,,,,
,3880045779.76282,270.168930053711,5499.720703125,1.19758228592227E-5,2.34247542893868E-8,1,4,13.4005146026611,4.9809994100168,33.4100015461445,0.0147967523134761,0.002277773780608,1,5.08469409657212E-8,,,,,,,,,,,,,,,,,,,,,270.163635253906,270.174224853516,5499.720703125,5499.720703125,53.6267510759095,5.65669317708164,6.02860021591187,54,1,0,0,1,0.297775268554687,33.2355842590332,1,1,3,270.163635253906,0,270.168930053711,,,,,,,,,,,,,,,,,,,,,,,,,,,,,,,,,
,3880045862.83128,270.205596923828,6999.900390625,3.66811247221334E-6,1.2317291892134E-8,1,4,13.4005146026611,4.98095885505218,33.4200002253056,0.00452914823507643,7.17337153235203E-4,1,3.14911272092236E-8,,,,,,,,,,,,,,,,,,,,,270.19970703125,270.211486816406,6999.900390625,6999.900390625,53.5657840514095,5.65738117409908,6.02235555648804,54,2,0,0,1,0.298004150390625,33.7243423461914,1,1,3,270.211486816406,0,270.205596923828,,,,,,,,,,,,,,,,,,,,,,,,,,,,,,,,,
,3880045978.03433,270.177734375,8500.09375,-4.98491649849787E-6,1.27492530230427E-8,1,4,13.4005146026611,4.98094959516852,33.4100015461445,-0.00616918134750078,-8.8029544181282E-4,10,3.36839743675592E-8,,,,,,,,,,,,,,,,,,,,,270.176666259766,270.178802490234,8500.09375,8500.09375,53.3801472780922,5.65652842553424,6.02556371688843,54,3,0,0,1,0.299835205078125,33.2355842590332,1,1,3,270.176666259766,0,270.177734375,,,,,,,,,,,,,,,,,,,,,,,,,,,,,,,,,
,3880046101.22067,270.437973022461,10000.1728515625,-1.378331362453E-5,1.18612977168202E-8,1,4,13.4005146026611,4.98100448191525,33.4200002253056,-0.0170461110384159,-0.00251403033351934,1,2.84515214739297E-8,,,,,,,,,,,,,,,,,,,,,270.437835693359,270.438110351562,10000.1728515625,10000.1728515625,53.4919201563422,5.65639182657008,6.02360153198242,54,1,0,0,1,0.30120849609375,33.2355842590332,1,1,3,270.438110351562,0,270.437973022461,,,,,,,,,,,,,,,,,,,,,,,,,,,,,,,,,
,3880046319.20422,270.172409057617,25000.310546875,-1.04353090928901E-4,3.28215837959892E-8,1,4,13.4005146026611,4.98104629972508,33.4200002253056,-0.129037523166555,-0.0191651593724327,1,1.09222403300091E-7,,,,,,,,,,,,,,,,,,,,,270.166229248047,270.178588867187,25000.310546875,25000.310546875,53.516541454698,5.65701903310745,6.03083896636963,54,2,0,0,1,0.297622680664063,33.7243423461914,1,1,3,270.178588867187,0,270.172409057617,,,,,,,,,,,,,,,,,,,,,,,,,,,,,,,,,
,3880046540.51707,270.185745239258,40000.17578125,-1.95834785925599E-4,5.41647255881858E-8,1,4,13.4005146026611,4.98089602741849,33.4200002253056,-0.242135488412058,-0.0360532119420127,1,1.33520789660688E-7,,,,,,,,,,,,,,,,,,,,,270.179962158203,270.191528320313,40000.17578125,40000.17578125,53.4340796459191,5.65681820381819,6.0262565612793,54,3,0,0,1,0.299758911132812,33.7243423461914,1,1,3,270.191528320313,0,270.185745239258,,,,,,,,,,,,,,,,,,,,,,,,,,,,,,,,,
,3880046835.08645,270.160980224609,60000.34375,-3.18317778448139E-4,8.82520410356976E-8,1,4,13.4005146026611,4.98127879794929,33.4100015461445,-0.393606431945681,-0.0586944675018439,1,1.47638748342908E-7,,,,,,,,,,,,,,,,,,,,,270.136505126953,270.185455322266,60000.34375,60000.34375,53.3047201259864,5.65447064378069,6.02176809310913,53,1,68,0,0,0.303955078125,33.7243423461914,1,1,3,270.187286376953,0,270.160980224609,,,,,,,,,,,,,,,,,,,,,,,,,,,,,,,,,
,3880047011.19566,270.249923706055,70000.46875,-3.79507184364546E-4,1.27392406322587E-7,1,4,13.4005146026611,4.98104800661774,33.4200002253056,-0.469215375805155,-0.0701229323705658,1,5.44280407410926E-8,,,,,,,,,,,,,,,,,,,,,270.248870849609,270.2509765625,70000.46875,70000.46875,53.1859125910633,5.65538077940776,6.02223920822144,54,3,0,0,1,0.298919677734375,33.7243423461914,1,1,3,270.248870849609,0,270.249923706055,,,,,,,,,,,,,,,,,,,,,,,,,,,,,,,,,