File: SQUID/22169_LCOT/22169_LCOT_MH_350K_FC_0d5T.csv
Comment,Time Stamp (sec),Temperature (K),Magnetic Field (Oe),Moment (emu),M. Std. Err. (emu),Transport Action,Averaging Time (sec),Frequency (Hz),Peak Amplitude (mm),Center Position (mm),Lockin Signal' (V),Lockin Signal (V),Range,M. Quad. Signal (emu),AC Moment (emu),AC M. Std Err. (emu),AC Phase (deg),AC Phase Std. Err. (deg),AC Susceptibility (emu/Oe),AC Suscept. Std Err. (emu/Oe),AC X' (emu/Oe),AC X' Std Err. (emu/Oe),AC X'' (emu/Oe),AC X'' Std Err. (emu/Oe),AC Drive (Oe),AC Frequency (Hz),AC Averaging Time (sec),AC Cycles,AC Range,AC Measure Type,AC Signal' (V),AC Signal'' (V),AC Trim Coil Ratio,AC Trim Coil Phase,Min. Temperature (K),Max. Temperature (K),Min. Field (Oe),Max. Field (Oe),Mass (grams),Motor Lag (deg),Pressure (Torr),Measure Count,Measurement Number,SQUID Status (code),Motor Status (code),Measure Status (code),Motor Current (amps),Motor Temp. (C),Temp. Status (code),Field Status (code),Chamber Status (code),Chamber Temp (K),Redirection State,Average Temp (K),Rotation Angle (deg),Rotator state,DC Moment Fixed Ctr (emu),DC Moment Err Fixed Ctr (emu),DC Moment Free Ctr (emu),DC Moment Err Free Ctr (emu),DC Fixed Fit,DC Free Fit,DC Calculated Center (mm),DC Calculated Center Err (mm),DC Scan Length (mm),DC Scan Time (s),DC Number of Points,DC Squid Drift,DC Min V (V),DC Max V (V),DC Scans per Measure,Sample Resistance,He3 Temperature,Sorb Resistance,Sorb Temperature,Map 05,Map 06,Map 07,Map 08,Map 09,Map 10,Map 11,Map 12,Map 13,Map 14,Map 15,Map 16
,3879919474.77881,349.98860168457,69999.546875,-3.81596599922076E-4,9.8398003842807E-8,1,4,13.4005146026611,5.00337063956889,33.4899984300137,-0.474768698942282,-0.0709210770046505,1,7.97163623103621E-8,,,,,,,,,,,,,,,,,,,,,349.988433837891,349.98876953125,69999.546875,69999.546875,53.157773964371,5.64923196157696,7.07652235031128,54,1,0,0,1,0.305557250976562,32.7468223571777,1,1,3,349.98876953125,0,349.98860168457,,,,,,,,,,,,,,,,,,,,,,,,,,,,,,,,,
,3879919694.34356,349.954940795898,54999.64453125,-2.89416058165689E-4,5.85857602888991E-8,1,4,13.4005146026611,5.00330952493002,33.4899984300137,-0.360076266032369,-0.0537785993881867,1,6.80788349585453E-8,,,,,,,,,,,,,,,,,,,,,349.944549560547,349.96533203125,54999.64453125,54999.64453125,53.2023267899672,5.65103205796161,6.91057586669922,54,2,0,0,1,0.305938720703125,32.7468223571777,1,1,3,349.96533203125,0,349.954940795898,,,,,,,,,,,,,,,,,,,,,,,,,,,,,,,,,
,3879919925.70861,350.000030517578,39999.6484375,-1.9743757139223E-4,4.67123747393578E-8,1,4,13.4005146026611,5.00321993986303,33.4899984300137,-0.245653797109474,-0.0365628705797,1,1.45784072395348E-7,,,,,,,,,,,,,,,,,,,,,349.994903564453,350.005157470703,39999.6484375,39999.6484375,53.3023752404287,5.65092333952761,6.77366542816162,54,3,0,0,1,0.306015014648438,34.2131004333496,1,1,3,350.005310058594,0,350.000030517578,,,,,,,,,,,,,,,,,,,,,,,,,,,,,,,,,
,3879920206.78434,350.01220703125,19999.62890625,-7.49172375726313E-5,1.63696852523274E-8,1,4,13.4005146026611,5.00312383985228,33.4899984300137,-0.0932004843383481,-0.0139387426748402,1,2.73281967848848E-9,,,,,,,,,,,,,,,,,,,,,349.999206542969,350.025207519531,19999.62890625,19999.62890625,53.4567468729768,5.65000506253702,6.66181087493896,54,1,0,0,1,0.305633544921875,34.2131004333496,1,1,3,350.025207519531,0,350.01220703125,,,,,,,,,,,,,,,,,,,,,,,,,,,,,,,,,
,3879920411.40555,350.021942138672,9999.7451171875,-1.44512253517323E-5,1.04697653965216E-8,1,4,13.4005146026611,5.0036457849068,33.4899984300137,-0.0179830321975189,-0.00267293672388372,1,1.35324500838469E-8,,,,,,,,,,,,,,,,,,,,,350.02099609375,350.022888183594,9999.7451171875,9999.7451171875,53.5806349932749,5.64907770866755,6.60079050064087,54,2,0,0,1,0.306396484375,34.7018585205078,1,1,3,350.02099609375,0,350.021942138672,,,,,,,,,,,,,,,,,,,,,,,,,,,,,,,,,
,3879920499.3548,349.919235229492,8499.7783203125,-5.5654416825625E-6,9.3154483190444E-9,1,4,13.4005146026611,5.00359671565987,33.4899984300137,-0.00692365704328743,-0.00104178901462735,1,-4.75812660044176E-9,,,,,,,,,,,,,,,,,,,,,349.914825439453,349.923645019531,8499.7783203125,8499.7783203125,53.3496637658422,5.64888877957623,6.57664728164673,54,3,0,0,1,0.30609130859375,34.2131004333496,1,1,3,349.923645019531,0,349.919235229492,,,,,,,,,,,,,,,,,,,,,,,,,,,,,,,,,
,3879920602.14833,349.908020019531,6499.78173828125,6.01955441422336E-6,8.80546329416606E-9,1,4,13.4005146026611,5.00363265951103,33.4899984300137,0.00750135472675057,0.00104200226058795,1,-6.30113647745581E-8,,,,,,,,,,,,,,,,,,,,,349.906921386719,349.909118652344,6499.78173828125,6499.78173828125,53.4426775596307,5.64789096051709,6.55106925964355,54,1,0,0,1,0.306320190429687,34.2131004333496,1,1,3,349.909118652344,0,349.908020019531,,,,,,,,,,,,,,,,,,,,,,,,,,,,,,,,,
,3879920688.93085,349.931060791016,4999.626953125,1.42769959245519E-5,7.97634054729503E-9,1,4,13.4005146026611,5.00369774595182,33.4899984300137,0.0177732221421677,0.00259567969929437,1,-4.95918050060242E-8,,,,,,,,,,,,,,,,,,,,,349.929107666016,349.933013916016,4999.626953125,4999.626953125,53.4688621150249,5.64788172504128,6.53517770767212,52,2,68,0,0,0.30517578125,34.2131004333496,1,1,3,349.933013916016,0,349.931060791016,,,,,,,,,,,,,,,,,,,,,,,,,,,,,,,,,
,3879920774.26228,350.083709716797,3499.57250976562,2.1637478555365E-5,6.37308863678473E-9,1,4,13.4005146026611,5.00368221092776,33.4899984300137,0.0269306772450889,0.00396985492293619,1,-4.62303252913485E-8,,,,,,,,,,,,,,,,,,,,,350.080047607422,350.087371826172,3499.57250976562,3499.57250976562,53.3891360060633,5.64746997786644,6.5166597366333,54,3,0,0,1,0.30517578125,34.2131004333496,1,1,3,350.087371826172,0,350.083709716797,,,,,,,,,,,,,,,,,,,,,,,,,,,,,,,,,
,3879920886.12563,350.069641113281,2899.6416015625,2.38966666920804E-5,1.40398628484735E-8,1,4,13.4005146026611,5.00360203479239,33.4899984300137,0.0297041635290239,0.00463628701932019,1,1.51509205371379E-7,,,,,,,,,,,,,,,,,,,,,350.060333251953,350.078948974609,2899.6416015625,2899.6416015625,53.4434591881499,5.64761837728368,6.49585437774658,53,1,68,0,0,0.306243896484375,33.7243423461914,1,1,3,350.078948974609,0,350.069641113281,,,,,,,,,,,,,,,,,,,,,,,,,,,,,,,,,
,3879920959.05228,350.075210571289,2749.70288085938,2.44218903022074E-5,1.0574287205225E-8,1,4,13.4005146026611,5.00352027069077,33.4899984300137,0.0303676255702756,0.00466261096880505,1,9.41818810525316E-8,,,,,,,,,,,,,,,,,,,,,350.071746826172,350.078674316406,2749.70288085938,2749.70288085938,53.5196679687749,5.64824868740035,6.48424196243286,54,2,0,0,1,0.3045654296875,34.2131004333496,1,1,3,350.071746826172,0,350.075210571289,,,,,,,,,,,,,,,,,,,,,,,,,,,,,,,,,
,3879921032.48619,350.063598632812,2599.55029296875,2.48881138353544E-5,1.19933231929471E-8,1,4,13.4005146026611,5.00349639019742,33.4899984300137,0.0309497293312208,0.00473434101121957,1,8.21157164139665E-8,,,,,,,,,,,,,,,,,,,,,350.062774658203,350.064422607422,2599.55029296875,2599.55029296875,53.3543535369576,5.64859054798605,6.4718279838562,54,3,0,0,1,0.304794311523438,34.2131004333496,1,1,3,350.062774658203,0,350.063598632812,,,,,,,,,,,,,,,,,,,,,,,,,,,,,,,,,
,3879921116.12961,350.002563476562,2399.560546875,2.53745697926508E-5,1.82835928703122E-8,1,4,13.4005146026611,5.00336143452258,33.4899984300137,0.0315367628180375,0.00493840139920254,1,1.73508093595311E-7,,,,,,,,,,,,,,,,,,,,,350.000427246094,350.004699707031,2399.560546875,2399.560546875,53.4418959311114,5.64888744004948,6.46166515350342,54,1,0,0,1,0.305709838867188,34.2131004333496,1,1,3,350.000427246094,0,350.002563476562,,,,,,,,,,,,,,,,,,,,,,,,,,,,,,,,,
,3879921189.13388,349.939361572266,2249.55883789062,2.57464845524893E-5,1.31512179438046E-8,1,4,13.4005146026611,5.00335166385201,33.4899984300137,0.0320130454084082,0.00491627359940293,1,1.00096850707962E-7,,,,,,,,,,,,,,,,,,,,,349.934906005859,349.943817138672,2249.55883789062,2249.55883789062,53.521622040073,5.64919858515056,6.44747066497803,53,2,68,0,0,0.305862426757812,34.2131004333496,1,1,3,349.934906005859,0,349.939361572266,,,,,,,,,,,,,,,,,,,,,,,,,,,,,,,,,
,3879921260.47092,350.123138427734,2099.6328125,2.6012265288685E-5,1.23689466530179E-8,1,4,13.4005146026611,5.00328915976432,33.500000834465,0.0323453800561536,0.00495069724177686,1,8.80763305905769E-8,,,,,,,,,,,,,,,,,,,,,350.118225097656,350.128051757812,2099.6328125,2099.6328125,53.4872303852268,5.65017237760098,6.43857526779175,54,3,0,0,1,0.305252075195313,34.2131004333496,1,1,3,350.128051757812,0,350.123138427734,,,,,,,,,,,,,,,,,,,,,,,,,,,,,,,,,
,3879921342.13765,350.079513549805,1899.78161621094,2.61863417408321E-5,2.10041448596314E-8,1,4,13.4005146026611,5.00319104976281,33.4899984300137,0.0325449640181532,0.0050905211736593,1,1.7453772951584E-7,,,,,,,,,,,,,,,,,,,,,350.077362060547,350.081665039063,1899.78161621094,1899.78161621094,53.4610458298326,5.65018613509544,6.43391990661621,54,1,0,0,1,0.306015014648438,34.2131004333496,1,1,3,350.081665039063,0,350.079513549805,,,,,,,,,,,,,,,,,,,,,,,,,,,,,,,,,
,3879921414.14105,349.988494873047,1749.49047851562,2.62664234914478E-5,1.60689163484144E-8,1,4,13.4005146026611,5.00340606119019,33.4899984300137,0.0326556264813828,0.00504507816495588,1,1.25786314182115E-7,,,,,,,,,,,,,,,,,,,,,349.983825683594,349.9931640625,1749.49047851562,1749.49047851562,53.4395510455537,5.65000426922468,6.42403030395508,52,2,68,0,0,0.306625366210937,33.7243423461914,1,1,3,349.983825683594,0,349.988494873047,,,,,,,,,,,,,,,,,,,,,,,,,,,,,,,,,
,3879921487.62654,349.894515991211,1599.52661132813,2.61982563654444E-5,1.98641304579679E-8,1,4,13.4005146026611,5.0031714401185,33.4899984300137,0.0325783500256066,0.00496742483756631,1,7.38302003654164E-8,,,,,,,,,,,,,,,,,,,,,349.891571044922,349.8974609375,1599.52661132813,1599.52661132813,53.4852763139287,5.65046762999263,6.40911340713501,54,3,0,0,1,0.3057861328125,33.7243423461914,1,1,3,349.8974609375,0,349.894515991211,,,,,,,,,,,,,,,,,,,,,,,,,,,,,,,,,
,3879921568.41821,349.928207397461,1399.71325683594,2.5830137369674E-5,1.95632270911313E-8,1,4,13.4005146026611,5.00322341260183,33.4899984300137,0.0320993602889829,0.00504268328217852,1,1.89334070148425E-7,,,,,,,,,,,,,,,,,,,,,349.919555664063,349.936859130859,1399.71325683594,1399.71325683594,53.5427260100922,5.64943955075272,6.40063095092773,52,1,68,0,0,0.307159423828125,33.7243423461914,1,1,3,349.919555664063,0,349.928207397461,,,,,,,,,,,,,,,,,,,,,,,,,,,,,,,,,
,3879921640.41772,349.884414672852,1249.673828125,2.54544860226557E-5,1.49537713311335E-8,1,4,13.4005146026611,5.003152257756,33.4899984300137,0.0316413551157863,0.00490607921460879,1,1.3580381944787E-7,,,,,,,,,,,,,,,,,,,,,349.880615234375,349.888214111328,1249.673828125,1249.673828125,53.394607405698,5.65013302862039,6.40028190612793,53,2,68,0,0,0.305252075195313,33.7243423461914,1,1,3,349.880523681641,0,349.884414672852,,,,,,,,,,,,,,,,,,,,,,,,,,,,,,,,,
,3879921711.30421,349.844039916992,1099.86096191406,2.48189207978672E-5,1.43741747838304E-8,1,4,13.4005146026611,5.00325019464461,33.500000834465,0.030859425830836,0.00473511889559807,1,9.33537508174946E-8,,,,,,,,,,,,,,,,,,,,,349.843658447266,349.844421386719,1099.86096191406,1099.86096191406,53.486057942448,5.65009923391916,6.39235782623291,54,3,0,0,1,0.305252075195313,33.7243423461914,1,1,3,349.843658447266,0,349.844039916992,,,,,,,,,,,,,,,,,,,,,,,,,,,,,,,,,
,3879921792.22876,349.752136230469,899.770690917969,2.35207153640538E-5,2.46265311181047E-8,1,4,13.4005146026611,5.00328244182808,33.4899984300137,0.0292218390162938,0.00464579994241924,1,2.15728615676999E-7,,,,,,,,,,,,,,,,,,,,,349.748992919922,349.755279541016,899.770690917969,899.770690917969,53.5712554510441,5.65028218840035,6.38195610046387,52,1,68,0,0,0.30517578125,33.7243423461914,1,1,3,349.755279541016,0,349.752136230469,,,,,,,,,,,,,,,,,,,,,,,,,,,,,,,,,
,3879921863.54621,350.08659362793,749.819396972656,2.23052170331501E-5,1.63411134529469E-8,1,4,13.4005146026611,5.00318593535086,33.4899984300137,0.0277219781047751,0.00433202045520139,1,1.4543843769244E-7,,,,,,,,,,,,,,,,,,,,,350.08447265625,350.088714599609,749.819396972656,749.819396972656,53.5231852971114,5.65131340422621,6.3811616897583,54,2,0,0,1,0.307464599609375,33.7243423461914,1,1,3,350.088714599609,0,350.08659362793,,,,,,,,,,,,,,,,,,,,,,,,,,,,,,,,,
,3879921934.11465,349.995498657227,599.943603515625,2.06344950360037E-5,1.51733045829693E-8,1,4,13.4005146026611,5.00320519018629,33.4899984300137,0.0256477003804964,0.00399394833910782,1,1.23601993541837E-7,,,,,,,,,,,,,,,,,,,,,349.9931640625,349.997833251953,599.943603515625,599.943603515625,53.4438500024095,5.65026991462967,6.37561273574829,52,3,68,0,0,0.306320190429687,33.7243423461914,1,1,3,349.9931640625,0,349.995498657227,,,,,,,,,,,,,,,,,,,,,,,,,,,,,,,,,
,3879922015.7226,350.037063598633,399.891082763672,1.74421889556504E-5,2.49569797640367E-8,1,4,13.4005146026611,5.00314332706424,33.500000834465,0.0216595770529351,0.00350877695118914,1,2.11212092218346E-7,,,,,,,,,,,,,,,,,,,,,350.030395507812,350.043731689453,399.891082763672,399.891082763672,53.4966099274576,5.65092955743498,6.36415529251099,54,1,0,0,1,0.305938720703125,33.7243423461914,1,1,3,350.043731689453,0,350.037063598633,,,,,,,,,,,,,,,,,,,,,,,,,,,,,,,,,
,3879922101.25138,349.951614379883,249.952377319336,1.42340937150718E-5,2.05760210165083E-8,1,4,13.4005146026611,5.00325329304228,33.4899984300137,0.0176729134814238,0.00288635919186707,1,1.90734700479681E-7,,,,,,,,,,,,,,,,,,,,,349.947174072266,349.9560546875,249.952377319336,249.952377319336,53.503253769871,5.64984776818184,6.36229181289673,54,2,0,0,1,0.306396484375,33.7243423461914,1,1,3,349.947174072266,0,349.951614379883,,,,,,,,,,,,,,,,,,,,,,,,,,,,,,,,,
,3879922193.42542,349.874206542969,100.13956451416,9.89092370051789E-6,1.65073476951975E-8,1,4,13.4005146026611,5.00314474064395,33.4899984300137,0.012280554530031,0.00200257969787661,1,1.30109427428067E-7,,,,,,,,,,,,,,,,,,,,,349.872955322266,349.875457763672,100.13956451416,100.13956451416,53.4215735896114,5.64987300701391,6.35331869125366,53,3,68,0,0,0.306243896484375,33.7243423461914,1,1,3,349.872863769531,0,349.874206542969,,,,,,,,,,,,,,,,,,,,,,,,,,,,,,,,,
,3879922312.11101,350.144332885742,-99.9255676269531,1.47444483929835E-6,2.83884539438547E-8,1,4,13.4005146026611,5.00323933055273,33.4899984300137,0.00178562185544759,5.99981909691403E-4,1,2.61701956327164E-7,,,,,,,,,,,,,,,,,,,,,350.138092041016,350.150573730469,-99.9255676269531,-99.9255676269531,53.5001272557941,5.65011737276162,6.3418025970459,54,1,0,0,1,0.306167602539063,33.7243423461914,1,1,3,350.150573730469,0,350.144332885742,,,,,,,,,,,,,,,,,,,,,,,,,,,,,,,,,
,3879922419.86807,350.011764526367,-249.851669311523,-5.18149345581919E-6,2.13798147606447E-8,1,4,13.4005146026611,5.00313402859487,33.500000834465,-0.00647812443704308,-7.4953083922534E-4,1,1.72623431867392E-7,,,,,,,,,,,,,,,,,,,,,350.005187988281,350.018341064453,-249.851669311523,-249.851669311523,53.4672988579864,5.65085160978562,6.33970260620117,52,2,68,0,0,0.304946899414063,33.7243423461914,1,1,3,350.018341064453,0,350.011764526367,,,,,,,,,,,,,,,,,,,,,,,,,,,,,,,,,
,3879922518.28177,350.188003540039,-399.777801513672,-1.04882819472033E-5,9.32941576363189E-9,1,4,13.4005146026611,5.0030903282136,33.4899984300137,-0.0130511060445644,-0.00192916209723063,1,1.82432580847615E-8,,,,,,,,,,,,,,,,,,,,,350.184661865234,350.191345214844,-399.777801513672,-399.777801513672,53.4501030305633,5.65067408588899,6.33423662185669,54,3,0,0,1,0.306320190429687,33.7243423461914,1,1,3,350.191345214844,0,350.188003540039,,,,,,,,,,,,,,,,,,,,,,,,,,,,,,,,,
,3879922600.23395,350.189361572266,-599.729675292969,-1.6146415620379E-5,1.59624478440778E-8,1,4,13.4005146026611,5.00321814115891,33.4899984300137,-0.0201298547083514,-0.00272048579577531,1,2.28645110921388E-7,,,,,,,,,,,,,,,,,,,,,350.179168701172,350.199554443359,-599.729675292969,-599.729675292969,53.569301379746,5.64993869277914,6.32140731811523,54,1,0,0,1,0.305938720703125,33.7243423461914,1,1,3,350.179168701172,0,350.189361572266,,,,,,,,,,,,,,,,,,,,,,,,,,,,,,,,,
,3879922672.26171,350.061126708984,-749.781616210937,-1.9003917860422E-5,1.67283808877048E-8,1,4,13.4005146026611,5.00325826202547,33.500000834465,-0.0236755139499372,-0.00331612383010094,1,1.77358725715316E-7,,,,,,,,,,,,,,,,,,,,,350.050048828125,350.072204589844,-749.781616210937,-749.781616210937,53.421964403871,5.649923761619,6.32379055023193,52,2,68,0,0,0.304489135742188,33.7243423461914,1,1,3,350.072204589844,0,350.061126708984,,,,,,,,,,,,,,,,,,,,,,,,,,,,,,,,,
,3879922743.80175,350.194213867188,-899.657409667969,-2.11312931803219E-5,1.94236933700293E-8,1,4,13.4005146026611,5.0033436669532,33.4899984300137,-0.0263147640202968,-0.00376571862903103,1,1.34287586959831E-7,,,,,,,,,,,,,,,,,,,,,350.193572998047,350.194854736328,-899.657409667969,-899.657409667969,53.6115093197845,5.6498259771962,6.31785535812378,54,3,0,0,1,0.305557250976562,33.7243423461914,1,1,3,350.193572998047,0,350.194213867188,,,,,,,,,,,,,,,,,,,,,,,,,,,,,,,,,
,3879922825.70423,350.041748046875,-1099.64697265625,-2.312186037625E-5,9.75123475966688E-8,1,4,13.4005146026611,5.00329477021576,33.4899984300137,-0.0288152894254723,-0.0039728666346582,1,2.65518310137746E-7,,,,,,,,,,,,,,,,,,,,,350.041107177734,350.042388916016,-1099.64697265625,-1099.64697265625,53.5638299801114,5.65082174339191,6.30902767181396,52,1,68,0,0,0.305099487304687,33.7243423461914,1,1,3,350.041107177734,0,350.041748046875,,,,,,,,,,,,,,,,,,,,,,,,,,,,,,,,,
,3879922897.78358,350.101837158203,-1249.62353515625,-2.41855026745622E-5,3.29571261893123E-8,1,4,13.4005146026611,5.00322973696451,33.4899984300137,-0.0301231671030623,-0.00427001511890882,1,1.85723831687172E-7,,,,,,,,,,,,,,,,,,,,,350.099975585937,350.103698730469,-1249.62353515625,-1249.62353515625,53.4590917585345,5.65028257186076,6.30654048919678,52,2,68,0,0,0.30487060546875,33.7243423461914,1,1,3,350.099975585937,0,350.101837158203,,,,,,,,,,,,,,,,,,,,,,,,,,,,,,,,,
,3879922970.95791,350.063415527344,-1399.56225585938,-2.48649821169742E-5,1.06829281577292E-8,1,4,13.4005146026611,5.00402742648116,33.4899984300137,-0.0309646143669938,-0.0044695334927872,1,1.27796046017317E-7,,,,,,,,,,,,,,,,,,,,,350.058471679687,350.068359375,-1399.56225585938,-1399.56225585938,53.475896771698,5.64738428622099,6.30485105514526,52,3,68,0,0,0.305404663085937,33.2355842590332,1,1,3,350.068359375,0,350.063415527344,,,,,,,,,,,,,,,,,,,,,,,,,,,,,,,,,
,3879923055.90067,350.052093505859,-1599.52661132813,-2.54470590168983E-5,1.03750776884373E-8,1,4,13.4005146026611,5.00394992970588,33.4899984300137,-0.0316984789381438,-0.00450932391060119,1,1.82815888022873E-7,,,,,,,,,,,,,,,,,,,,,350.049011230469,350.05517578125,-1599.52661132813,-1599.52661132813,53.3543535369576,5.64745454417031,6.30280065536499,53,1,68,0,0,0.305023193359375,33.7243423461914,1,1,3,350.049011230469,0,350.052093505859,,,,,,,,,,,,,,,,,,,,,,,,,,,,,,,,,
,3879923130.57235,350.088302612305,-1749.83032226562,-2.56227127371429E-5,8.45553183068135E-9,1,4,13.4005146026611,5.00390798910505,33.4899984300137,-0.031909014307892,-0.00459317978509697,1,1.41658756079673E-7,,,,,,,,,,,,,,,,,,,,,350.077667236328,350.098937988281,-1749.83032226562,-1749.83032226562,53.4485397735249,5.64820190653273,6.29837989807129,53,2,68,0,0,0.30517578125,33.7243423461914,1,1,3,350.098937988281,0,350.088302612305,,,,,,,,,,,,,,,,,,,,,,,,,,,,,,,,,
,3879923203.65499,350.051544189453,-1899.78161621094,-2.56703581666342E-5,8.61606176805638E-9,1,4,13.4005146026611,5.00405810215867,33.4899984300137,-0.0319654702362256,-0.00463012504023902,1,1.19251026159144E-7,,,,,,,,,,,,,,,,,,,,,350.049560546875,350.053527832031,-1899.78161621094,-1899.78161621094,53.4833222426306,5.64721891064341,6.29285573959351,54,3,0,0,1,0.304946899414063,33.7243423461914,1,1,3,350.049560546875,0,350.051544189453,,,,,,,,,,,,,,,,,,,,,,,,,,,,,,,,,
,3879923286.03705,350.178283691406,-2099.70825195313,-2.55536437871425E-5,8.11457987461288E-9,1,4,13.4005146026611,5.00399865675986,33.4899984300137,-0.0318306634555785,-0.00453507657634366,1,1.78113882152573E-7,,,,,,,,,,,,,,,,,,,,,350.175567626953,350.180999755859,-2099.70825195313,-2099.70825195313,53.3781932067941,5.64799224853993,6.28843021392822,54,1,0,0,1,0.306015014648438,33.7243423461914,1,1,3,350.175567626953,0,350.178283691406,,,,,,,,,,,,,,,,,,,,,,,,,,,,,,,,,
,3879923357.6732,350.10758972168,-2249.72241210938,-2.53273382609959E-5,1.08720193273748E-8,1,4,13.4005146026611,5.00390086348281,33.4899984300137,-0.0315425213595906,-0.00453078366734884,1,1.476103806344E-7,,,,,,,,,,,,,,,,,,,,,350.103240966797,350.111938476562,-2249.72241210938,-2249.72241210938,53.4461948879672,5.6480426366906,6.29157161712647,54,2,0,0,1,0.304641723632812,33.2355842590332,1,1,3,350.103240966797,0,350.10758972168,,,,,,,,,,,,,,,,,,,,,,,,,,,,,,,,,
,3879923429.48904,350.027603149414,-2399.63598632813,-2.50157030252625E-5,9.39851006074894E-9,1,4,13.4005146026611,5.00398451201674,33.4899984300137,-0.03114764186787,-0.0045252704239968,1,1.05507463004854E-7,,,,,,,,,,,,,,,,,,,,,350.026184082031,350.029022216797,-2399.63598632813,-2399.63598632813,53.3387209665729,5.64801889558044,6.28733921051025,54,3,0,0,1,0.306015014648438,33.2355842590332,1,1,3,350.026184082031,0,350.027603149414,,,,,,,,,,,,,,,,,,,,,,,,,,,,,,,,,
,3879923513.14839,350.113403320313,-2599.67602539062,-2.45612222263116E-5,4.33935863316457E-8,1,4,13.4005146026611,5.00424899554743,33.4899984300137,-0.0305880466133087,-0.00441645306310124,1,1.25232255914607E-7,,,,,,,,,,,,,,,,,,,,,350.099670410156,350.127136230469,-2599.67602539062,-2599.67602539062,53.5579677662172,5.64674117005162,6.28131246566772,54,1,0,0,1,0.304641723632812,33.2355842590332,1,1,3,350.127136230469,0,350.113403320313,,,,,,,,,,,,,,,,,,,,,,,,,,,,,,,,,
,3879923584.88765,350.207366943359,-2749.5517578125,-2.40934190226204E-5,2.32970587825048E-8,1,4,13.4005146026611,5.00433977912947,33.4899984300137,-0.0300073433230226,-0.00432490493180473,1,1.2890624182362E-7,,,,,,,,,,,,,,,,,,,,,350.202239990234,350.212493896484,-2749.5517578125,-2749.5517578125,53.4485397735249,5.64754359590009,6.27905797958374,54,2,0,0,1,0.303726196289063,33.7243423461914,1,1,3,350.202239990234,0,350.207366943359,,,,,,,,,,,,,,,,,,,,,,,,,,,,,,,,,
,3879923658.2842,350.121398925781,-2899.61645507812,-2.35735785808405E-5,8.98767635306298E-9,1,4,13.4005146026611,5.0041841650593,33.4899984300137,-0.0293550822480205,-0.00425510239203211,1,1.07083138349094E-7,,,,,,,,,,,,,,,,,,,,,350.115875244141,350.126922607422,-2899.61645507812,-2899.61645507812,53.4477581450057,5.64772321627211,6.27665567398071,54,3,0,0,1,0.304718017578125,33.2355842590332,1,1,3,350.115875244141,0,350.121398925781,,,,,,,,,,,,,,,,,,,,,,,,,,,,,,,,,
,3879923768.8581,350.225921630859,-3499.87475585937,-2.11756229074422E-5,8.56178128017824E-9,1,4,13.4005146026611,5.00401513528903,33.4899984300137,-0.0263532700108652,-0.00391903756164221,1,1.82749712147537E-8,,,,,,,,,,,,,,,,,,,,,350.213592529297,350.238250732422,-3499.87475585937,-3499.87475585937,53.3250424674864,5.6484022141576,6.27252292633057,54,1,0,0,1,0.3045654296875,33.7243423461914,1,1,3,350.238250732422,0,350.225921630859,,,,,,,,,,,,,,,,,,,,,,,,,,,,,,,,,
,3879923853.03082,350.059478759766,-4999.6396484375,-1.38262597948171E-5,7.82954018356172E-9,1,4,13.4005146026611,5.00397605663141,33.4899984300137,-0.0172066439568191,-0.00255940038313528,1,1.14823121000392E-8,,,,,,,,,,,,,,,,,,,,,350.056732177734,350.062225341797,-4999.6396484375,-4999.6396484375,53.5505422952845,5.64837137317073,6.26563119888306,54,2,0,0,1,0.306854248046875,33.2355842590332,1,1,3,350.056732177734,0,350.059478759766,,,,,,,,,,,,,,,,,,,,,,,,,,,,,,,,,
,3879923937.16844,350.062927246094,-6499.744140625,-5.56306723047081E-6,8.97482959928967E-9,1,4,13.4005146026611,5.00384674682029,33.4899984300137,-0.00692314987909914,-0.00102829483554579,1,5.79006682438057E-9,,,,,,,,,,,,,,,,,,,,,350.062042236328,350.063812255859,-6499.744140625,-6499.744140625,53.4305623175826,5.64854524651859,6.26681709289551,54,3,0,0,1,0.30487060546875,33.7243423461914,1,1,3,350.063812255859,0,350.062927246094,,,,,,,,,,,,,,,,,,,,,,,,,,,,,,,,,
,3879924036.52135,350.080657958984,-8499.564453125,6.0206614930729E-6,9.92118233197732E-9,1,4,13.4005146026611,5.00379130094201,33.4899984300137,0.00750085853035722,0.00105700354613476,1,-5.11578324308607E-8,,,,,,,,,,,,,,,,,,,,,350.062133789063,350.099182128906,-8499.564453125,-8499.564453125,53.4387694170345,5.64883847981106,6.26156234741211,54,1,0,0,1,0.306015014648438,33.2355842590332,1,1,3,350.101104736328,0,350.080657958984,,,,,,,,,,,,,,,,,,,,,,,,,,,,,,,,,
,3879924120.28038,350.176467895508,-9999.619140625,1.48541584370462E-5,1.16597085540613E-8,1,4,13.4005146026611,5.00373038617416,33.500000834465,0.0184888919794068,0.00272069171744698,1,-3.54790202250729E-8,,,,,,,,,,,,,,,,,,,,,350.166900634766,350.18603515625,-9999.619140625,-9999.619140625,53.355916793996,5.64888689651841,6.26593351364136,54,2,0,0,1,0.305099487304687,33.2355842590332,1,1,3,350.18603515625,0,350.176467895508,,,,,,,,,,,,,,,,,,,,,,,,,,,,,,,,,
,3879924315.26906,350.127304077148,-19999.654296875,7.52915111629616E-5,2.41657582483496E-8,1,4,13.4005146026611,5.00412937392684,33.4899984300137,0.0937066883227033,0.0139170027603695,1,-7.93411851622336E-8,,,,,,,,,,,,,,,,,,,,,350.121246337891,350.133361816406,-19999.654296875,-19999.654296875,53.3809289066114,5.64792584109805,6.25935411453247,54,3,0,0,1,0.306396484375,33.7243423461914,1,1,3,350.133880615234,0,350.127304077148,,,,,,,,,,,,,,,,,,,,,,,,,,,,,,,,,
,3879924598.40027,350.009918212891,-39999.5859375,1.97664506853398E-4,3.77646113286312E-8,1,4,13.4005146026611,5.00406783991752,33.4899984300137,0.245991927928895,0.0366304428235693,1,-1.32394889338288E-7,,,,,,,,,,,,,,,,,,,,,349.98974609375,350.030090332031,-39999.5859375,-39999.5859375,53.4700345578037,5.64862370506324,6.24930572509766,52,1,68,0,0,0.305862426757812,33.2355842590332,1,1,3,350.030090332031,0,350.009918212891,,,,,,,,,,,,,,,,,,,,,,,,,,,,,,,,,
,3879924821.21835,349.991439819336,-54999.76953125,2.89657100777661E-4,5.42044398040183E-8,1,4,13.4005146026611,5.00413259252563,33.4899984300137,0.36045937686784,0.0538337970181278,1,-6.97243351230256E-8,,,,,,,,,,,,,,,,,,,,,349.983856201172,349.9990234375,-54999.76953125,-54999.76953125,53.2480520583422,5.64813204656104,6.24015665054321,54,2,0,0,1,0.30487060546875,33.7243423461914,1,1,3,349.9990234375,0,349.991439819336,,,,,,,,,,,,,,,,,,,,,,,,,,,,,,,,,
,3879925055.36138,350.089904785156,-69999.4609375,3.81784097717516E-4,1.12248088472935E-7,1,4,13.4005146026611,5.0039781930127,33.4899984300137,0.475076879200862,0.0710065849578579,1,-4.87276416811226E-8,,,,,,,,,,,,,,,,,,,,,350.089630126953,350.090179443359,-69999.4609375,-69999.4609375,52.9940227895922,5.64795301280678,6.24159383773804,54,3,0,0,1,0.30426025390625,33.7243423461914,1,1,3,350.090637207031,0,350.089904785156,,,,,,,,,,,,,,,,,,,,,,,,,,,,,,,,,
,3879925339.19348,349.960311889648,-49999.65234375,2.58864101607122E-4,6.60315936559122E-8,1,4,13.4005146026611,5.00411875212227,33.4899984300137,0.322145024573372,0.048065342770775,1,-9.86997347088388E-8,,,,,,,,,,,,,,,,,,,,,349.951354980469,349.969268798828,-49999.65234375,-49999.65234375,53.1569923358518,5.64641851164643,6.23460674285889,54,1,0,0,1,0.303726196289063,34.2131004333496,1,1,3,349.969268798828,0,349.960311889648,,,,,,,,,,,,,,,,,,,,,,,,,,,,,,,,,
,3879925560.01723,350.087326049805,-34999.52734375,1.66872622276679E-4,3.32405998216496E-8,1,4,13.4005146026611,5.00452364201185,33.4899984300137,0.207696598816346,0.0309383489946228,1,-1.03572423443749E-7,,,,,,,,,,,,,,,,,,,,,350.074096679687,350.100555419922,-34999.52734375,-34999.52734375,53.3899176345826,5.64608535034468,6.22796773910522,54,2,0,0,1,0.304946899414063,33.7243423461914,1,1,3,350.100555419922,0,350.087326049805,,,,,,,,,,,,,,,,,,,,,,,,,,,,,,,,,
,3879925781.58622,350.070297241211,-19999.666015625,7.51203764436125E-5,1.68032824759066E-8,1,4,13.4005146026611,5.00418306231499,33.4899984300137,0.0934898436027097,0.0139207128879241,1,-5.09268589593342E-8,,,,,,,,,,,,,,,,,,,,,350.067047119141,350.073547363281,-19999.666015625,-19999.666015625,53.4192287040537,5.64837218151022,6.23105430603027,54,3,0,0,1,0.305938720703125,33.7243423461914,1,1,3,350.066772460937,0,350.070297241211,,,,,,,,,,,,,,,,,,,,,,,,,,,,,,,,,
,3879925989.87482,350.153091430664,-9500.3056640625,1.16874224728101E-5,1.07623459636099E-8,1,4,13.4005146026611,5.00410216053435,33.4899984300137,0.0145381223794963,0.00221216665945144,1,2.93604028068038E-8,,,,,,,,,,,,,,,,,,,,,350.143402099609,350.162780761719,-9500.3056640625,-9500.3056640625,53.5102884265441,5.64832560981367,6.22780418395996,54,1,0,0,1,0.305404663085937,33.7243423461914,1,1,3,350.162780761719,0,350.153091430664,,,,,,,,,,,,,,,,,,,,,,,,,,,,,,,,,
,3879926074.1507,350.167861938477,-8000.17578125,2.8667579610475E-6,9.52977118257172E-9,1,4,13.4005146026611,5.00414414093061,33.4899984300137,0.00356409672405306,5.5558162855397E-4,1,1.76182813131832E-8,,,,,,,,,,,,,,,,,,,,,350.156066894531,350.179656982422,-8000.17578125,-8000.17578125,53.4446316309287,5.64874783266245,6.22547435760498,54,2,0,0,1,0.30426025390625,33.7243423461914,1,1,3,350.179656982422,0,350.167861938477,,,,,,,,,,,,,,,,,,,,,,,,,,,,,,,,,
,3879926159.14839,350.185287475586,-6500.310546875,-5.77394714829338E-6,8.33094447573735E-9,1,4,13.4005146026611,5.00413114027505,33.4899984300137,-0.00719179064143473,-0.00102970533916404,1,3.62686016203046E-8,,,,,,,,,,,,,,,,,,,,,350.183929443359,350.186645507812,-6500.310546875,-6500.310546875,53.4141481186787,5.64890691356502,6.22092199325561,54,3,0,0,1,0.305862426757812,33.7243423461914,1,1,3,350.183929443359,0,350.185287475586,,,,,,,,,,,,,,,,,,,,,,,,,,,,,,,,,
,3879926258.2464,350.207382202148,-4500.40185546875,-1.66569225783753E-5,9.51549184665526E-9,1,4,13.4005146026611,5.00399636810493,33.4899984300137,-0.0207437239669885,-0.00298827929751785,1,9.02806641126143E-8,,,,,,,,,,,,,,,,,,,,,350.196075439453,350.218688964844,-4500.40185546875,-4500.40185546875,53.4821497998518,5.64911407137846,6.22304677963257,52,1,68,0,0,0.304107666015625,33.7243423461914,1,1,3,350.218688964844,0,350.207382202148,,,,,,,,,,,,,,,,,,,,,,,,,,,,,,,,,
,3879926342.43024,350.312042236328,-3000.42309570313,-2.3438340557495E-5,7.62080660785383E-9,1,4,13.4005146026611,5.00385125280803,33.4899984300137,-0.0291742359949899,-0.00429530684207171,1,5.42230743070729E-8,,,,,,,,,,,,,,,,,,,,,350.307098388672,350.316986083984,-3000.42309570313,-3000.42309570313,53.4024236908903,5.64973244852295,6.22349739074707,54,2,0,0,1,0.306777954101562,33.7243423461914,1,1,3,350.316986083984,0,350.312042236328,,,,,,,,,,,,,,,,,,,,,,,,,,,,,,,,,
,3879926496.88429,350.235626220703,-2900.24584960937,-2.37109800458336E-5,1.09322820236864E-8,1,4,13.4005146026611,5.00393545423443,33.4899984300137,-0.0294897895812951,-0.00450916058541158,1,-7.67742405994836E-8,,,,,,,,,,,,,,,,,,,,,350.233337402344,350.237915039063,-2900.24584960937,-2900.24584960937,53.5587493947364,5.64877431870379,6.21871328353882,54,3,0,0,1,0.305709838867188,33.7243423461914,1,1,3,350.233337402344,0,350.235626220703,,,,,,,,,,,,,,,,,,,,,,,,,,,,,,,,,
,3879926578.08061,349.950241088867,-2700.26879882813,-2.43546161012691E-5,1.80978467291641E-8,1,4,13.4005146026611,5.00398023672553,33.4899984300137,-0.0302738470427588,-0.00474408381540949,1,-1.69238786864258E-7,,,,,,,,,,,,,,,,,,,,,349.9326171875,349.967864990234,-2700.26879882813,-2700.26879882813,53.5157598261787,5.64813415143761,6.21767997741699,54,1,0,0,1,0.30426025390625,33.7243423461914,1,1,3,349.969757080078,0,349.950241088867,,,,,,,,,,,,,,,,,,,,,,,,,,,,,,,,,
,3879926649.37887,350.162933349609,-2550.26733398438,-2.48248308229384E-5,1.30929955777124E-8,1,4,13.4005146026611,5.00394748198962,33.4899984300137,-0.0308697494713396,-0.00475750476956566,1,-1.0971819020886E-7,,,,,,,,,,,,,,,,,,,,,350.150909423828,350.174957275391,-2550.26733398438,-2550.26733398438,53.5384270532364,5.6483361803625,6.21627759933472,53,2,68,0,0,0.30517578125,33.7243423461914,1,1,3,350.174957275391,0,350.162933349609,,,,,,,,,,,,,,,,,,,,,,,,,,,,,,,,,
,3879926721.08111,350.167541503906,-2400.32836914062,-2.52283134259931E-5,1.02045866093802E-8,1,4,13.4005146026611,5.00378722305811,33.4899984300137,-0.0313754229905373,-0.00479886946863853,1,-8.27751030741897E-8,,,,,,,,,,,,,,,,,,,,,350.167144775391,350.167938232422,-2400.32836914062,-2400.32836914062,53.4848854996691,5.64903204523425,6.21708965301514,54,3,0,0,1,0.304641723632812,33.7243423461914,1,1,3,350.167938232422,0,350.167541503906,,,,,,,,,,,,,,,,,,,,,,,,,,,,,,,,,
,3879926802.7225,350.183578491211,-2200.30102539062,-2.55320910829866E-5,1.74333122430993E-8,1,4,13.4005146026611,5.00392262739103,33.4899984300137,-0.0317384335062072,-0.00496370763552806,1,-1.696586793554E-7,,,,,,,,,,,,,,,,,,,,,350.170501708984,350.196655273438,-2200.30102539062,-2200.30102539062,53.5212312258134,5.64945271380902,6.21627330780029,54,1,0,0,1,0.305099487304687,34.2131004333496,1,1,3,350.196655273438,0,350.183578491211,,,,,,,,,,,,,,,,,,,,,,,,,,,,,,,,,
,3879926873.16374,350.375930786133,-2050.21118164062,-2.58029024645127E-5,1.52839567167223E-8,1,4,13.4005146026611,5.00406183383056,33.4899984300137,-0.0320866583770957,-0.0049474535603767,1,-1.1592961588401E-7,,,,,,,,,,,,,,,,,,,,,350.372009277344,350.379852294922,-2050.21118164062,-2050.21118164062,53.3778023925345,5.64776194865289,6.21696996688843,53,2,68,0,0,0.30670166015625,33.7243423461914,1,1,3,350.379852294922,0,350.375930786133,,,,,,,,,,,,,,,,,,,,,,,,,,,,,,,,,
,3879926957.13996,350.416442871094,-1900.32287597656,-2.5996584985028E-5,1.06436471140882E-8,1,4,13.4005146026611,5.00376565777802,33.4899984300137,-0.0323415698690454,-0.00487228954122916,1,-2.68765639025442E-8,,,,,,,,,,,,,,,,,,,,,350.408996582031,350.423889160156,-1900.32287597656,-1900.32287597656,53.4629999011307,5.64875436015211,6.21247005462647,54,3,0,0,1,0.305862426757812,33.7243423461914,1,1,3,350.408996582031,0,350.416442871094,,,,,,,,,,,,,,,,,,,,,,,,,,,,,,,,,
,3879927039.48933,350.288192749023,-1700.01867675781,-2.59616689072598E-5,2.40642123598365E-8,1,4,13.4005146026611,5.00382891271521,33.4899984300137,-0.0322669667684605,-0.00507798026387294,1,-1.97339009580284E-7,,,,,,,,,,,,,,,,,,,,,350.274322509766,350.302062988281,-1700.01867675781,-1700.01867675781,53.5087251695057,5.64936511808731,6.21061849594116,52,1,68,0,0,0.305328369140625,33.2355842590332,1,1,3,350.274322509766,0,350.288192749023,,,,,,,,,,,,,,,,,,,,,,,,,,,,,,,,,
,3879927108.96795,350.297286987305,-1549.97924804687,-2.59233817343621E-5,1.4635810364305E-8,1,4,13.4005146026611,5.00366075501085,33.4899984300137,-0.0322280424067802,-0.00500222871900584,1,-1.42375899141664E-7,,,,,,,,,,,,,,,,,,,,,350.290954589844,350.303619384766,-1549.97924804687,-1549.97924804687,53.4743335146595,5.64986765575986,6.20943689346313,54,2,0,0,1,0.30487060546875,33.7243423461914,1,1,3,350.290954589844,0,350.297286987305,,,,,,,,,,,,,,,,,,,,,,,,,,,,,,,,,
,3879927180.92977,350.24821472168,-1400.00280761719,-2.56683453871501E-5,1.51934153099716E-8,1,4,13.4005146026611,5.00390667258009,33.4899984300137,-0.0319221161541882,-0.00489358021656867,1,-9.29352495268545E-8,,,,,,,,,,,,,,,,,,,,,350.24755859375,350.248870849609,-1400.00280761719,-1400.00280761719,53.5087251695057,5.64926984123116,6.21365213394165,53,3,68,0,0,0.306167602539063,33.7243423461914,1,1,3,350.24755859375,0,350.24821472168,,,,,,,,,,,,,,,,,,,,,,,,,,,,,,,,,
,3879927275.9066,350.053482055664,-1200.0634765625,-2.50067631731503E-5,2.21101692993444E-8,1,4,13.4005146026611,5.00388748036904,33.4899984300137,-0.0310730710246893,-0.00494196468225791,1,-2.30809711196355E-7,,,,,,,,,,,,,,,,,,,,,350.042205810547,350.064758300781,-1200.0634765625,-1200.0634765625,53.4571376872364,5.64832388911131,6.2115159034729,52,1,68,0,0,0.305557250976562,33.2355842590332,1,1,3,350.042205810547,0,350.053482055664,,,,,,,,,,,,,,,,,,,,,,,,,,,,,,,,,
,3879927347.25768,350.298080444336,-1050.04919433594,-2.43504927899744E-5,1.64418457468424E-8,1,4,13.4005146026611,5.00367076366648,33.4899984300137,-0.0302703849240575,-0.00471424884974912,1,-1.46206753888196E-7,,,,,,,,,,,,,,,,,,,,,350.290802001953,350.305358886719,-1050.04919433594,-1050.04919433594,53.379365649573,5.64941771709809,6.21310186386108,54,2,0,0,1,0.30609130859375,33.7243423461914,1,1,3,350.305358886719,0,350.298080444336,,,,,,,,,,,,,,,,,,,,,,,,,,,,,,,,,
,3879927418.19489,350.251449584961,-900.097961425781,-2.34138496636508E-5,1.42567708026028E-8,1,4,13.4005146026611,5.00360584536477,33.4899984300137,-0.0291130726055293,-0.00448224245573079,1,-9.99222357619376E-8,,,,,,,,,,,,,,,,,,,,,350.242065429687,350.260833740234,-900.097961425781,-900.097961425781,53.5036445841307,5.64972375876669,6.21201133728027,54,3,0,0,1,0.30548095703125,33.7243423461914,1,1,3,350.242065429687,0,350.251449584961,,,,,,,,,,,,,,,,,,,,,,,,,,,,,,,,,
,3879927499.0395,350.183822631836,-700.032897949219,-2.15447484124395E-5,2.22907062027817E-8,1,4,13.4005146026611,5.00359799396267,33.4899984300137,-0.0267638062690065,-0.00429250107898429,1,-2.27035971721857E-7,,,,,,,,,,,,,,,,,,,,,350.183502197266,350.184143066406,-700.032897949219,-700.032897949219,53.5716462653038,5.64942504499945,6.21323680877686,52,1,68,0,0,0.305328369140625,33.7243423461914,1,1,3,350.184143066406,0,350.183822631836,,,,,,,,,,,,,,,,,,,,,,,,,,,,,,,,,
,3879927570.46901,350.256713867188,-550.056396484375,-1.97736989945916E-5,1.97418026217155E-8,1,4,13.4005146026611,5.00354279121473,33.4899984300137,-0.0245731930812043,-0.00387381065660809,1,-1.55509440385786E-7,,,,,,,,,,,,,,,,,,,,,350.249481201172,350.263946533203,-550.056396484375,-550.056396484375,53.5407719387941,5.65030101488934,6.20877122879028,53,2,68,0,0,0.30487060546875,33.7243423461914,1,1,3,350.263946533203,0,350.256713867188,,,,,,,,,,,,,,,,,,,,,,,,,,,,,,,,,
,3879927655.49569,350.362854003906,-400.155456542969,-1.73794240522318E-5,1.32350972606219E-8,1,4,13.4005146026611,5.0035423982573,33.4899984300137,-0.0215998833924523,-0.00339065841623634,1,-1.2535018625838E-7,,,,,,,,,,,,,,,,,,,,,350.359954833984,350.365753173828,-400.155456542969,-400.155456542969,53.3828829779095,5.65103190969777,6.20805215835571,54,3,0,0,1,0.304794311523438,33.7243423461914,1,1,3,350.359954833984,0,350.362854003906,,,,,,,,,,,,,,,,,,,,,,,,,,,,,,,,,
,3879927747.74546,350.016754150391,-200.039962768555,-1.27868728090679E-5,2.99953782901993E-8,1,4,13.4005146026611,5.00339821877397,33.4899984300137,-0.0158571956243589,-0.00272339028100911,1,-2.76146257673249E-7,,,,,,,,,,,,,,,,,,,,,350.00732421875,350.026184082031,-200.039962768555,-200.039962768555,53.4665172294672,5.65109308431891,6.20804738998413,52,1,68,0,0,0.304794311523438,33.2355842590332,1,1,3,350.00732421875,0,350.016754150391,,,,,,,,,,,,,,,,,,,,,,,,,,,,,,,,,
,3879927818.91845,350.259353637695,-50.1390190124512,-7.99546510833866E-6,2.17041483804559E-8,1,4,13.4005146026611,5.00344316551546,33.4899984300137,-0.0099154336968623,-0.00170284761146565,1,-1.72610959908078E-7,,,,,,,,,,,,,,,,,,,,,350.248504638672,350.270202636719,-50.1390190124512,-50.1390190124512,53.5392086817557,5.65080483917831,6.20203638076782,54,2,0,0,1,0.30364990234375,34.2131004333496,1,1,3,350.270202636719,0,350.259353637695,,,,,,,,,,,,,,,,,,,,,,,,,,,,,,,,,
,3879927903.24107,350.392105102539,99.8248596191406,-1.55893183456421E-6,1.20848429251267E-8,1,4,13.4005146026611,5.00324528410811,33.4899984300137,-0.00192580199167244,-3.81281989678014E-4,1,-7.32701252040435E-8,,,,,,,,,,,,,,,,,,,,,350.384582519531,350.399627685547,99.8248596191406,99.8248596191406,53.4938742276403,5.65169370600001,6.20766592025757,54,3,0,0,1,0.3057861328125,33.7243423461914,1,1,3,350.384582519531,0,350.392105102539,,,,,,,,,,,,,,,,,,,,,,,,,,,,,,,,,
,3879927984.8654,350.294189453125,299.801879882812,7.13001230668729E-6,3.47445268870806E-8,1,4,13.4005146026611,5.00320574628471,33.4899984300137,0.00892281429704129,9.7533256750145E-4,1,-2.82619156703805E-7,,,,,,,,,,,,,,,,,,,,,350.281616210937,350.306762695313,299.801879882812,299.801879882812,53.3527902799191,5.65205334926759,6.20404624938965,52,1,68,0,0,0.3057861328125,32.7468223571777,1,1,3,350.281616210937,0,350.294189453125,,,,,,,,,,,,,,,,,,,,,,,,,,,,,,,,,
,3879928056.35479,350.265213012695,449.853881835937,1.21770725536671E-5,2.17646611377297E-8,1,4,13.4005146026611,5.00322286809858,33.4899984300137,0.0151749953652259,0.00209361529556817,1,-1.38744110832882E-7,,,,,,,,,,,,,,,,,,,,,350.255920410156,350.274505615234,449.853881835937,449.853881835937,53.5712554510441,5.65209396151147,6.2053484916687,53,2,68,0,0,0.306167602539063,33.2355842590332,1,1,3,350.274505615234,0,350.265213012695,,,,,,,,,,,,,,,,,,,,,,,,,,,,,,,,,
,3879928144.13066,350.078491210937,599.817810058594,1.5980212443476E-5,8.84566186632005E-9,1,4,13.4005146026611,5.00337081156243,33.4899984300137,0.0199020051100992,0.00283627476252298,1,-1.10806881252684E-7,,,,,,,,,,,,,,,,,,,,,350.075317382812,350.081665039063,599.817810058594,599.817810058594,53.5407719387941,5.65041664294246,6.20733261108398,54,3,0,0,1,0.305938720703125,33.7243423461914,1,1,3,350.075317382812,0,350.078491210937,,,,,,,,,,,,,,,,,,,,,,,,,,,,,,,,,
,3879928236.29392,350.202941894531,799.71923828125,1.96501602235098E-5,3.72372693808735E-8,1,4,13.4005146026611,5.0032258180279,33.4899984300137,0.0245002668232838,0.00329602386962699,1,-2.90164980823443E-7,,,,,,,,,,,,,,,,,,,,,350.197357177734,350.208526611328,799.71923828125,799.71923828125,53.3758483212364,5.65176995379043,6.20302486419678,54,1,0,0,1,0.305557250976562,33.7243423461914,1,1,3,350.208526611328,0,350.202941894531,,,,,,,,,,,,,,,,,,,,,,,,,,,,,,,,,
,3879928307.8142,350.289337158203,949.808959960937,2.1601911162267E-5,1.77547440739456E-8,1,4,13.4005146026611,5.00314435849878,33.4899984300137,0.0269044237971613,0.00381528580564503,1,-1.64676956824382E-7,,,,,,,,,,,,,,,,,,,,,350.289184570313,350.289489746094,949.808959960937,949.808959960937,53.5712554510441,5.65149256065237,6.20566558837891,53,2,64,0,0,0.305862426757812,33.2355842590332,1,1,3,350.289184570313,0,350.289337158203,,,,,,,,,,,,,,,,,,,,,,,,,,,,,,,,,
,3879928379.42234,350.203521728516,1099.79797363281,2.29848911805075E-5,3.70835113539714E-8,1,4,13.4005146026611,5.00319430178746,33.4899984300137,0.0286228468041738,0.00408921449574287,1,-1.51416427981218E-7,,,,,,,,,,,,,,,,,,,,,350.196105957031,350.2109375,1099.79797363281,1099.79797363281,53.5118516835826,5.65061800697772,6.20221138000488,54,3,0,0,1,0.306396484375,33.7243423461914,1,1,3,350.195404052734,0,350.203521728516,,,,,,,,,,,,,,,,,,,,,,,,,,,,,,,,,
,3879928462.10767,350.202514648438,1299.56115722656,2.43004389776574E-5,3.86819684836255E-8,1,4,13.4005146026611,5.00307180818772,33.4899984300137,0.0302647294228918,0.00429182295144506,1,-1.85235923494322E-7,,,,,,,,,,,,,,,,,,,,,350.183929443359,350.221099853516,1299.56115722656,1299.56115722656,53.5321740250826,5.65130349389589,6.19773435592651,52,1,68,0,0,0.305557250976562,33.2355842590332,1,1,3,350.221099853516,0,350.202514648438,,,,,,,,,,,,,,,,,,,,,,,,,,,,,,,,,
,3879928533.54381,350.302734375,1449.76416015625,2.48897151764543E-5,4.616899541087E-8,1,4,13.4005146026611,5.00309048106162,33.4899984300137,0.0309924473809349,0.00443838127867503,1,-1.55596473117246E-7,,,,,,,,,,,,,,,,,,,,,350.296112060547,350.309356689453,1449.76416015625,1449.76416015625,53.528656696746,5.65107998348181,6.19532489776611,54,2,0,0,1,0.306777954101562,33.7243423461914,1,1,3,350.309356689453,0,350.302734375,,,,,,,,,,,,,,,,,,,,,,,,,,,,,,,,,
,3879928605.07695,350.140823364258,1599.5517578125,2.52268222858673E-5,7.37726284491352E-9,1,4,13.4005146026611,5.00315798162396,33.4899984300137,0.0314059608671871,0.00454431733778611,1,-1.20938840863652E-7,,,,,,,,,,,,,,,,,,,,,350.13720703125,350.144439697266,1599.5517578125,1599.5517578125,53.554059623621,5.65146100290944,6.19778728485107,54,3,0,0,1,0.306015014648438,33.2355842590332,1,1,3,350.13720703125,0,350.140823364258,,,,,,,,,,,,,,,,,,,,,,,,,,,,,,,,,
,3879928689.38803,349.93327331543,1799.79309082031,2.55045614253915E-5,1.88520259042618E-8,1,4,13.4005146026611,5.00306708797373,33.4899984300137,0.0317619303161077,0.00452065349778413,1,-1.81416157128547E-7,,,,,,,,,,,,,,,,,,,,,349.929473876953,349.937072753906,1799.79309082031,1799.79309082031,53.533737282121,5.6519217255002,6.19959688186646,54,1,0,0,1,0.306320190429687,33.7243423461914,1,1,3,349.929473876953,0,349.93327331543,,,,,,,,,,,,,,,,,,,,,,,,,,,,,,,,,
,3879928760.94536,350.079010009766,1949.94580078125,2.54240840066547E-5,3.51311544100532E-8,1,4,13.4005146026611,5.00297142224117,33.4899984300137,0.031650853299228,0.00457317046065601,1,-1.27063349780703E-7,,,,,,,,,,,,,,,,,,,,,350.073944091797,350.084075927734,1949.94580078125,1949.94580078125,53.5270934397076,5.65266191076962,6.19407224655151,54,2,0,0,1,0.306243896484375,33.7243423461914,1,1,3,350.084075927734,0,350.079010009766,,,,,,,,,,,,,,,,,,,,,,,,,,,,,,,,,
,3879928832.84566,350.115493774414,2099.88452148438,2.53398267338358E-5,7.38560775326004E-9,1,4,13.4005146026611,5.00320161301695,33.4899984300137,0.0315465504401485,0.00456793397456904,1,-1.18904745342509E-7,,,,,,,,,,,,,,,,,,,,,350.112060546875,350.118927001953,2099.88452148438,2099.88452148438,53.3887451918037,5.65135325495044,6.20340156555176,54,3,0,0,1,0.305862426757812,33.7243423461914,1,1,3,350.118927001953,0,350.115493774414,,,,,,,,,,,,,,,,,,,,,,,,,,,,,,,,,
,3879928915.12202,350.185623168945,2299.91186523438,2.49953445011025E-5,6.08704560958759E-8,1,4,13.4005146026611,5.00322956089868,33.500000834465,0.0311169355678403,0.00451254508704898,1,-1.11923127299929E-7,,,,,,,,,,,,,,,,,,,,,350.177062988281,350.194183349609,2299.91186523438,2299.91186523438,53.462609086871,5.65120497889582,6.20071077346802,54,1,0,0,1,0.304641723632812,33.7243423461914,1,1,3,350.194183349609,0,350.185623168945,,,,,,,,,,,,,,,,,,,,,,,,,,,,,,,,,
,3879928986.99969,350.259460449219,2449.91357421875,2.47101125805763E-5,8.03499740663924E-9,1,4,13.4005146026611,5.0030574510192,33.500000834465,0.0307630485148728,0.00444291390249825,1,-1.25052540967457E-7,,,,,,,,,,,,,,,,,,,,,350.255828857422,350.263092041016,2449.91357421875,2449.91357421875,53.4954374846787,5.65158282041884,6.19613981246948,52,2,68,0,0,0.3057861328125,33.2355842590332,1,1,3,350.255462646484,0,350.259460449219,,,,,,,,,,,,,,,,,,,,,,,,,,,,,,,,,
,3879929058.76061,350.02555847168,2599.80200195313,2.43201939960496E-5,8.14990054840269E-9,1,4,13.4005146026611,5.00310921071493,33.4899984300137,0.0302753738125838,0.00439078894967636,1,-1.08674747065817E-7,,,,,,,,,,,,,,,,,,,,,350.021148681641,350.029968261719,2599.80200195313,2599.80200195313,53.5528871808422,5.65163939758593,6.19730520248413,54,3,0,0,1,0.306015014648438,33.7243423461914,1,1,3,350.021148681641,0,350.02555847168,,,,,,,,,,,,,,,,,,,,,,,,,,,,,,,,,
,3879929140.83276,350.134033203125,2799.71606445313,2.37130649062241E-5,1.03906460371786E-8,1,4,13.4005146026611,5.00280901850192,33.4899984300137,0.0295211813333874,0.00425354873990574,1,-1.27883664020935E-7,,,,,,,,,,,,,,,,,,,,,350.112213134766,350.155853271484,2799.71606445313,2799.71606445313,53.5907961640249,5.65277672497662,6.19654226303101,54,1,0,0,1,0.306015014648438,33.7243423461914,1,1,3,350.155853271484,0,350.134033203125,,,,,,,,,,,,,,,,,,,,,,,,,,,,,,,,,
,3879929212.54011,350.344802856445,2949.84350585937,2.32023786333299E-5,4.83456809133977E-8,1,4,13.4005146026611,5.00296041828768,33.4899984300137,0.0288750056377494,0.00423985241242332,1,-6.26429633528855E-8,,,,,,,,,,,,,,,,,,,,,350.333953857422,350.355651855469,2949.84350585937,2949.84350585937,53.6228429333134,5.65155491434907,6.19657897949219,53,2,68,0,0,0.305938720703125,33.2355842590332,1,1,3,350.355499267578,0,350.344802856445,,,,,,,,,,,,,,,,,,,,,,,,,,,,,,,,,
,3879929310.4666,350.26643371582,3499.509765625,2.0978896016501E-5,7.29792988416751E-9,1,4,13.4005146026611,5.00301872000385,33.4899984300137,0.026103372150308,0.00386682635839939,1,-2.99387675804628E-8,,,,,,,,,,,,,,,,,,,,,350.265441894531,350.267425537109,3499.509765625,3499.509765625,53.3989063625537,5.65114861400794,6.1980504989624,54,3,0,0,1,0.30609130859375,33.2355842590332,1,1,3,350.267425537109,0,350.26643371582,,,,,,,,,,,,,,,,,,,,,,,,,,,,,,,,,
,3879929407.81502,350.193359375,5499.74560546875,1.09009041670339E-5,8.77302715635696E-9,1,4,13.4005146026611,5.00281555920257,33.500000834465,0.0135572237368982,0.00204693193970523,1,1.48256164848329E-8,,,,,,,,,,,,,,,,,,,,,350.185455322266,350.201263427734,5499.74560546875,5499.74560546875,53.5634391658518,5.65292365378412,6.19667291641235,54,1,0,0,1,0.3057861328125,33.2355842590332,1,1,3,350.201263427734,0,350.193359375,,,,,,,,,,,,,,,,,,,,,,,,,,,,,,,,,
,3879929492.684,350.199920654297,6999.92578125,2.48702408036508E-6,1.17346766411496E-8,1,4,13.4005146026611,5.00287029958188,33.500000834465,0.00309064688492228,4.83453673020287E-4,1,1.66001916491059E-8,,,,,,,,,,,,,,,,,,,,,350.188720703125,350.211120605469,6999.92578125,6999.92578125,53.5333464678614,5.65210532554724,6.19528007507324,54,2,0,0,1,0.306243896484375,33.7243423461914,1,1,3,350.211120605469,0,350.199920654297,,,,,,,,,,,,,,,,,,,,,,,,,,,,,,,,,
,3879929575.86484,350.197860717773,8500.068359375,-6.22087526236201E-6,1.18978024816857E-8,1,4,13.4005146026611,5.00285438216365,33.500000834465,-0.00774198678709541,-0.00113384012272445,1,1.91175897897929E-8,,,,,,,,,,,,,,,,,,,,,350.197692871094,350.198028564453,8500.068359375,8500.068359375,53.506380283948,5.65209318480248,6.19673824310303,54,3,0,0,1,0.305099487304687,33.2355842590332,1,1,3,350.197631835937,0,350.197860717773,,,,,,,,,,,,,,,,,,,,,,,,,,,,,,,,,
,3879929687.38761,350.14030456543,10000.0341796875,-1.50674834306335E-5,1.72113434944715E-8,1,4,13.4005146026611,5.00288104149164,33.500000834465,-0.018747804735271,-0.00277354121376906,1,2.4386779081928E-8,,,,,,,,,,,,,,,,,,,,,350.139465332031,350.141143798828,10000.0341796875,10000.0341796875,53.4755059574383,5.65162944099969,6.1985011100769,54,1,0,0,1,0.306167602539063,33.2355842590332,1,1,3,350.139465332031,0,350.14030456543,,,,,,,,,,,,,,,,,,,,,,,,,,,,,,,,,
,3879929906.08904,350.002059936523,25000.173828125,-1.05977475418449E-4,2.04454583567083E-8,1,4,13.4005146026611,5.00290103666873,33.4899984300137,-0.131848580229353,-0.0196098355140675,1,8.95582346113453E-8,,,,,,,,,,,,,,,,,,,,,350.001098632812,350.003021240234,25000.173828125,25000.173828125,53.5153690119191,5.65216892171109,6.19045925140381,54,2,0,0,1,0.306320190429687,34.2131004333496,1,1,3,350.001098632812,0,350.002059936523,,,,,,,,,,,,,,,,,,,,,,,,,,,,,,,,,
,3879930127.56776,350.030166625977,40000.328125,-1.97803552150708E-4,4.00266568346959E-8,1,4,13.4005146026611,5.00267514648467,33.4899984300137,-0.246070835111931,-0.0366306291000535,1,1.41581917875861E-7,,,,,,,,,,,,,,,,,,,,,350.028747558594,350.031585693359,40000.328125,40000.328125,53.4141481186787,5.6528108392764,6.19029951095581,54,3,0,0,1,0.308303833007812,33.2355842590332,1,1,3,350.028656005859,0,350.030166625977,,,,,,,,,,,,,,,,,,,,,,,,,,,,,,,,,
,3879930410.01649,350.033615112305,60000.1953125,-3.20489508632254E-4,7.73338565277461E-8,1,4,13.4005146026611,5.00278451252014,33.4899984300137,-0.398693227681934,-0.0594400166833401,1,1.58862664098696E-7,,,,,,,,,,,,,,,,,,,,,350.032409667969,350.034820556641,60000.1953125,60000.1953125,53.2691560283614,5.65243613686568,6.18791580200195,52,1,68,0,0,0.3057861328125,33.7243423461914,1,1,3,350.032257080078,0,350.033615112305,,,,,,,,,,,,,,,,,,,,,,,,,,,,,,,,,
,3879930573.71688,350.133377075195,70000.390625,-3.81827204696704E-4,9.23183779443735E-8,1,4,13.4005146026611,5.00268867475307,33.4899984300137,-0.474962698899028,-0.0709660232676425,1,6.7209141148784E-8,,,,,,,,,,,,,,,,,,,,,350.128112792969,350.138641357422,70000.390625,70000.390625,53.2367184448133,5.65287919366755,6.19232368469238,54,3,0,0,1,0.306396484375,33.7243423461914,1,1,3,350.138641357422,0,350.133377075195,,,,,,,,,,,,,,,,,,,,,,,,,,,,,,,,,