File: SQUID/22169_LCOT/22169_LCOT_MH_5K_FC_0d5T.csv
Comment,Time Stamp (sec),Temperature (K),Magnetic Field (Oe),Moment (emu),M. Std. Err. (emu),Transport Action,Averaging Time (sec),Frequency (Hz),Peak Amplitude (mm),Center Position (mm),Lockin Signal' (V),Lockin Signal (V),Range,M. Quad. Signal (emu),AC Moment (emu),AC M. Std Err. (emu),AC Phase (deg),AC Phase Std. Err. (deg),AC Susceptibility (emu/Oe),AC Suscept. Std Err. (emu/Oe),AC X' (emu/Oe),AC X' Std Err. (emu/Oe),AC X'' (emu/Oe),AC X'' Std Err. (emu/Oe),AC Drive (Oe),AC Frequency (Hz),AC Averaging Time (sec),AC Cycles,AC Range,AC Measure Type,AC Signal' (V),AC Signal'' (V),AC Trim Coil Ratio,AC Trim Coil Phase,Min. Temperature (K),Max. Temperature (K),Min. Field (Oe),Max. Field (Oe),Mass (grams),Motor Lag (deg),Pressure (Torr),Measure Count,Measurement Number,SQUID Status (code),Motor Status (code),Measure Status (code),Motor Current (amps),Motor Temp. (C),Temp. Status (code),Field Status (code),Chamber Status (code),Chamber Temp (K),Redirection State,Average Temp (K),Rotation Angle (deg),Rotator state,DC Moment Fixed Ctr (emu),DC Moment Err Fixed Ctr (emu),DC Moment Free Ctr (emu),DC Moment Err Free Ctr (emu),DC Fixed Fit,DC Free Fit,DC Calculated Center (mm),DC Calculated Center Err (mm),DC Scan Length (mm),DC Scan Time (s),DC Number of Points,DC Squid Drift,DC Min V (V),DC Max V (V),DC Scans per Measure,Sample Resistance,He3 Temperature,Sorb Resistance,Sorb Temperature,Map 05,Map 06,Map 07,Map 08,Map 09,Map 10,Map 11,Map 12,Map 13,Map 14,Map 15,Map 16
,3879861729.42628,5.00008320808411,70000.3515625,-3.54007237609992E-4,1.31510183398305E-7,1,4,13.4005146026611,5.00607090722335,33.1199988722801,-0.440785748463368,-0.0657744447589062,1,1.29142309183645E-7,,,,,,,,,,,,,,,,,,,,,5.00004053115845,5.00012588500977,70000.3515625,70000.3515625,54.464656848525,5.64281756179555,2.96171522140503,54,1,0,0,1,0.301132202148438,31.7693061828613,1,1,3,5.00012588500977,0,5.00008320808411,,,,,,,,,,,,,,,,,,,,,,,,,,,,,,,,,
,3879861980.37397,4.99998235702515,55000.19921875,-2.6394371044349E-4,8.17072656327663E-8,1,4,13.4005146026611,5.00578026474366,33.1199988722801,-0.328695025503258,-0.0485223784244422,10,5.09397658489287E-7,,,,,,,,,,,,,,,,,,,,,4.99996948242188,4.99999523162842,55000.19921875,55000.19921875,54.2032021088423,5.64289705669113,2.97518539428711,54,2,0,0,1,0.302352905273438,33.2355842590332,1,1,3,4.99999523162842,0,4.99998235702515,,,,,,,,,,,,,,,,,,,,,,,,,,,,,,,,,
,3879862216.15524,4.99998927116394,40000.40234375,-1.75487487038387E-4,4.85630188111853E-8,1,4,13.4005146026611,5.00569203097849,33.1199988722801,-0.218503424926318,-0.0324586382695594,1,1.79234704317308E-7,,,,,,,,,,,,,,,,,,,,,4.99986791610718,5.0001106262207,40000.40234375,40000.40234375,53.9038383859769,5.64266708866267,2.97145843505859,54,3,0,0,1,0.302810668945313,33.7243423461914,1,1,3,4.99986791610718,0,4.99998927116394,,,,,,,,,,,,,,,,,,,,,,,,,,,,,,,,,
,3879862496.83466,4.99963212013245,19999.7421875,-6.00667283995417E-5,2.46865218225509E-8,1,4,13.4005146026611,5.00545358262797,33.1199988722801,-0.0747760121072866,-0.0111724913345859,1,1.06384066358974E-8,,,,,,,,,,,,,,,,,,,,,4.9995436668396,4.99972057342529,19999.7421875,19999.7421875,53.6525448170441,5.64240954091496,2.97512435913086,54,1,0,0,1,0.301971435546875,33.7243423461914,1,1,3,4.9995436668396,0,4.99963212013245,,,,,,,,,,,,,,,,,,,,,,,,,,,,,,,,,
,3879862684.51813,5.00003433227539,9999.6064453125,-4.30240776177426E-6,1.50731100980812E-8,1,4,13.4005146026611,5.00531200090625,33.1199988722801,-0.00536051629196608,-7.68559522479141E-4,1,2.61977189318303E-8,,,,,,,,,,,,,,,,,,,,,4.99995374679565,5.00011491775513,9999.6064453125,9999.6064453125,53.554059623621,5.64338211740756,2.96580767631531,54,2,0,0,1,0.303192138671875,33.7243423461914,1,1,3,4.99997663497925,0,5.00003433227539,,,,,,,,,,,,,,,,,,,,,,,,,,,,,,,,,
,3879862769.6519,4.99963855743408,8499.728515625,3.75157916921017E-6,1.51731185879919E-8,1,4,13.4005146026611,5.00531706654669,33.1199988722801,0.0046674154343952,7.15695819798197E-4,1,1.37344108244741E-8,,,,,,,,,,,,,,,,,,,,,4.99957323074341,4.99970388412476,8499.728515625,8499.728515625,53.5786809219768,5.6429142822174,2.9552571773529,54,3,0,0,1,0.30242919921875,33.7243423461914,1,1,3,4.99970388412476,0,4.99963855743408,,,,,,,,,,,,,,,,,,,,,,,,,,,,,,,,,
,3879862871.57889,5.00020980834961,6499.4921875,1.42372894970244E-5,1.10977934126211E-8,1,4,13.4005146026611,5.00536259488209,33.1199988722801,0.0177298453981642,0.00260433564847173,1,-3.76687269746018E-8,,,,,,,,,,,,,,,,,,,,,5.0000696182251,5.00034999847412,6499.4921875,6499.4921875,53.4204011468326,5.64186042789885,2.9533519744873,54,1,0,0,1,0.303115844726562,34.2131004333496,1,1,3,5.0000696182251,0,5.00020980834961,,,,,,,,,,,,,,,,,,,,,,,,,,,,,,,,,
,3879862956.83988,4.99988174438477,4999.6142578125,2.16131561646809E-5,9.14726490990761E-9,1,4,13.4005146026611,5.0054221256839,33.1199988722801,0.0269079604611099,0.00400426766989583,1,-1.64984467031095E-8,,,,,,,,,,,,,,,,,,,,,4.99973011016846,5.00003337860107,4999.6142578125,4999.6142578125,53.3930441486595,5.64226240352519,2.95154333114624,52,2,68,0,0,0.302886962890625,33.2355842590332,1,1,3,5.00003337860107,0,4.99988174438477,,,,,,,,,,,,,,,,,,,,,,,,,,,,,,,,,
,3879863043.31524,5.00004649162292,3499.64819335937,2.80807883104116E-5,7.59396888297639E-9,1,4,13.4005146026611,5.0052540805461,33.1199988722801,0.0349581763843597,0.00520374841792841,1,-2.02567584783541E-8,,,,,,,,,,,,,,,,,,,,,4.999915599823,5.00017738342285,3499.64819335937,3499.64819335937,53.4028145051499,5.64300026394026,2.95083427429199,54,3,0,0,1,0.304031372070313,34.2131004333496,1,1,3,5.00007343292236,0,5.00004649162292,,,,,,,,,,,,,,,,,,,,,,,,,,,,,,,,,
,3879863147.12342,5.000239610672,2899.66674804687,2.99497165071139E-5,1.19337286663111E-8,1,4,13.4005146026611,5.00525127713902,33.1199988722801,0.0372414580681014,0.00583983053517004,1,2.11166385764848E-7,,,,,,,,,,,,,,,,,,,,,5.00021171569824,5.00026750564575,2899.66674804687,2899.66674804687,53.4567468729768,5.64295304137397,2.94287323951721,54,1,0,0,1,0.302200317382812,33.7243423461914,1,1,3,5.00021171569824,0,5.000239610672,,,,,,,,,,,,,,,,,,,,,,,,,,,,,,,,,
,3879863219.46465,4.99993562698364,2749.564453125,3.03506789487801E-5,1.33404903810481E-8,1,4,13.4005146026611,5.00529846109628,33.1199988722801,0.0377577077020186,0.0058033211013277,1,1.21793365838453E-7,,,,,,,,,,,,,,,,,,,,,4.99978637695313,5.00008487701416,2749.564453125,2749.564453125,53.4778508429961,5.64220205744749,2.94514870643616,53,2,68,0,0,0.304641723632812,33.7243423461914,1,1,3,5.00008487701416,0,4.99993562698364,,,,,,,,,,,,,,,,,,,,,,,,,,,,,,,,,
,3879863290.79377,4.99985504150391,2599.53759765625,3.07367770238141E-5,1.00081631774358E-8,1,4,13.4005146026611,5.00527181419398,33.1199988722801,0.038242620416071,0.00584452949732196,1,9.71749769238948E-8,,,,,,,,,,,,,,,,,,,,,4.99978160858154,4.99992847442627,2599.53759765625,2599.53759765625,53.5759452221595,5.64216808711173,2.94092130661011,54,3,0,0,1,0.3021240234375,34.2131004333496,1,1,3,4.99992847442627,0,4.99985504150391,,,,,,,,,,,,,,,,,,,,,,,,,,,,,,,,,
,3879863372.03688,5.00001311302185,2399.86254882813,3.10943938479578E-5,1.79376874996573E-8,1,4,13.4005146026611,5.00530050681014,33.1199988722801,0.0386735067586834,0.00600863522611995,1,1.75473479715156E-7,,,,,,,,,,,,,,,,,,,,,4.99990701675415,5.00011920928955,2399.86254882813,2399.86254882813,53.4696437435441,5.6426056294988,2.93507504463196,53,1,68,0,0,0.305023193359375,33.7243423461914,1,1,3,5.00011920928955,0,5.00001311302185,,,,,,,,,,,,,,,,,,,,,,,,,,,,,,,,,
,3879863444.19235,5.00001955032349,2249.68481445313,3.13208325132801E-5,1.45529266361586E-8,1,4,13.4005146026611,5.00527349866807,33.1199988722801,0.0389635263280812,0.00599431262154775,1,1.30130001138486E-7,,,,,,,,,,,,,,,,,,,,,4.99993467330933,5.00010442733765,2249.68481445313,2249.68481445313,53.4086767190441,5.64314045027157,2.93374037742615,53,2,68,0,0,0.302963256835937,34.2131004333496,1,1,3,4.99993467330933,0,5.00001955032349,,,,,,,,,,,,,,,,,,,,,,,,,,,,,,,,,
,3879863515.27403,4.99986791610718,2099.78369140625,3.14915325717871E-5,1.17754932610901E-8,1,4,13.4005146026611,5.00525199833063,33.1199988722801,0.0391817827655169,0.00598591030642546,1,9.78732052185924E-8,,,,,,,,,,,,,,,,,,,,,4.9997615814209,4.99997425079346,2099.78369140625,2099.78369140625,53.4215735896114,5.64220386668597,2.93845748901367,53,3,68,0,0,0.303115844726562,33.7243423461914,1,1,3,4.9997615814209,0,4.99986791610718,,,,,,,,,,,,,,,,,,,,,,,,,,,,,,,,,
,3879863597.93743,4.99981927871704,1900.00817871094,3.15197036858269E-5,2.10096301042946E-8,1,4,13.4005146026611,5.00528774389826,33.1199988722801,0.0391949099734704,0.00614049514211411,1,2.17796258013312E-7,,,,,,,,,,,,,,,,,,,,,4.99979209899902,4.99984645843506,1900.00817871094,1900.00817871094,53.5442892671307,5.64245928644475,2.93307614326477,54,1,0,0,1,0.303802490234375,33.7243423461914,1,1,3,4.99984645843506,0,4.99981927871704,,,,,,,,,,,,,,,,,,,,,,,,,,,,,,,,,
,3879863669.50407,4.99990844726562,1749.72961425781,3.15068477672693E-5,1.40808261201474E-8,1,4,13.4005146026611,5.00526056839832,33.1199988722801,0.0391943622758912,0.00603275148935245,1,1.33200653261502E-7,,,,,,,,,,,,,,,,,,,,,4.99985551834106,4.99996137619019,1749.72961425781,1749.72961425781,53.5509331095441,5.64291922116418,2.92450523376465,54,2,0,0,1,0.303802490234375,33.7243423461914,1,1,3,4.99985551834106,0,4.99990844726562,,,,,,,,,,,,,,,,,,,,,,,,,,,,,,,,,
,3879863740.35476,4.99997735023499,1599.58959960938,3.13750754468574E-5,1.30506119437663E-8,1,4,13.4005146026611,5.00519383307502,33.1199988722801,0.0390364150695415,0.00596258973268853,1,9.66376092460351E-8,,,,,,,,,,,,,,,,,,,,,4.99987983703613,5.00007486343384,1599.58959960938,1599.58959960938,53.5435076386114,5.64301492980263,2.9229679107666,54,3,0,0,1,0.304946899414063,33.7243423461914,1,1,3,5.00007486343384,0,4.99997735023499,,,,,,,,,,,,,,,,,,,,,,,,,,,,,,,,,
,3879863823.2481,5.00003504753113,1399.92724609375,3.09125098351549E-5,2.36815531837337E-8,1,4,13.4005146026611,5.00523192314988,33.1199988722801,0.0384335503864493,0.006060291194324,1,2.4427302435732E-7,,,,,,,,,,,,,,,,,,,,,5.00000619888306,5.0000638961792,1399.92724609375,1399.92724609375,53.4637815296499,5.64270925147756,2.92273473739624,53,1,68,0,0,0.304336547851562,33.7243423461914,1,1,3,5.0000638961792,0,5.00003504753113,,,,,,,,,,,,,,,,,,,,,,,,,,,,,,,,,
,3879863894.62134,5.00004720687866,1249.85009765625,3.0476512363531E-5,1.68681995259848E-8,1,4,13.4005146026611,5.00514258526168,33.1199988722801,0.0379107093421092,0.00583976271348948,1,1.32448950222917E-7,,,,,,,,,,,,,,,,,,,,,4.99999809265137,5.00009632110596,1249.85009765625,1249.85009765625,53.4798049142941,5.64251787111472,2.92448830604553,54,2,0,0,1,0.303421020507812,33.7243423461914,1,1,3,4.99999809265137,0,5.00004720687866,,,,,,,,,,,,,,,,,,,,,,,,,,,,,,,,,
,3879863965.18517,5.00003576278687,1099.8232421875,2.98272475441968E-5,1.17761776864702E-8,1,4,13.4005146026611,5.00509627230167,33.1199988722801,0.0371030869037172,0.00571194442036475,1,1.26947709405887E-7,,,,,,,,,,,,,,,,,,,,,4.99996900558472,5.00010251998901,1099.8232421875,1099.8232421875,53.3942165914383,5.64342525246578,2.92517232894897,54,3,0,0,1,0.30303955078125,33.7243423461914,1,1,3,5.00007724761963,0,5.00003576278687,,,,,,,,,,,,,,,,,,,,,,,,,,,,,,,,,
,3879864045.72513,5.00003862380981,899.984680175781,2.85213791658912E-5,2.57814275116949E-8,1,4,13.4005146026611,5.004992957784,33.1199988722801,0.0354560981193409,0.00560578434919093,1,2.37139618302258E-7,,,,,,,,,,,,,,,,,,,,,4.99998235702515,5.00009489059448,899.984680175781,899.984680175781,53.4141481186787,5.64361308980337,2.9236888885498,54,1,0,0,1,0.304336547851562,33.7243423461914,1,1,3,4.99998235702515,0,5.00003862380981,,,,,,,,,,,,,,,,,,,,,,,,,,,,,,,,,
,3879864166.1863,5.00001287460327,750.008239746094,2.73291099411636E-5,1.68107489312693E-8,1,4,13.4005146026611,5.00500613183497,33.1199988722801,0.0339877371795435,0.00528006760671163,1,1.53794939926463E-7,,,,,,,,,,,,,,,,,,,,,4.99999856948853,5.00002717971802,750.008239746094,750.008239746094,53.5349097248999,5.64391804671845,2.90195083618164,54,2,0,0,1,0.302505493164063,33.7243423461914,1,1,3,4.99999856948853,0,5.00001287460327,,,,,,,,,,,,,,,,,,,,,,,,,,,,,,,,,
,3879864237.01438,5.00007367134094,599.956176757812,2.57225524937406E-5,1.91062018890172E-8,1,4,13.4005146026611,5.00503437454259,33.1199988722801,0.0319958951332955,0.00493031366407986,1,1.13098811423756E-7,,,,,,,,,,,,,,,,,,,,,5.00003528594971,5.00011205673218,599.956176757812,599.956176757812,53.4590917585345,5.64435885527074,2.89818167686462,53,3,68,0,0,0.304718017578125,33.7243423461914,1,1,3,5.00003528594971,0,5.00007367134094,,,,,,,,,,,,,,,,,,,,,,,,,,,,,,,,,
,3879864317.93315,5.00013947486877,400.067321777344,2.28103345217111E-5,2.74638052701302E-8,1,4,13.4005146026611,5.00499557065661,33.1199988722801,0.0283398822300757,0.00459428340915532,1,2.78820616400313E-7,,,,,,,,,,,,,,,,,,,,,5.00008678436279,5.00019216537476,400.067321777344,400.067321777344,53.3461464375056,5.64419328868589,2.89382266998291,53,1,68,0,0,0.305252075195313,33.2355842590332,1,1,3,5.00008678436279,0,5.00013947486877,,,,,,,,,,,,,,,,,,,,,,,,,,,,,,,,,
,3879864389.355,5.00009918212891,250.128616333008,1.99822730167474E-5,1.90208725880958E-8,1,4,13.4005146026611,5.00499653287854,33.1199988722801,0.0248403127078948,0.00393077423126886,1,1.68808573048708E-7,,,,,,,,,,,,,,,,,,,,,5.0000958442688,5.00010251998901,250.128616333008,250.128616333008,53.3387209665729,5.64391622146591,2.89544773101807,54,2,0,0,1,0.30364990234375,33.7243423461914,1,1,3,5.00006151199341,0,5.00009918212891,,,,,,,,,,,,,,,,,,,,,,,,,,,,,,,,,
,3879864460.61991,5.00001239776611,100.076629638672,1.63033017852673E-5,1.41945690487342E-8,1,4,13.4005146026611,5.00503631920624,33.1199988722801,0.0202686109217563,0.00319730607305771,1,1.29853895227246E-7,,,,,,,,,,,,,,,,,,,,,4.99984931945801,5.00017547607422,100.076629638672,100.076629638672,53.4360337172172,5.64375156398315,2.88828921318054,54,3,0,0,1,0.30487060546875,33.7243423461914,1,1,3,5.00017547607422,0,5.00001239776611,,,,,,,,,,,,,,,,,,,,,,,,,,,,,,,,,
,3879864562.78336,5.00006127357483,-99.9255676269531,9.63336286274934E-6,2.58226052261289E-8,1,4,13.4005146026611,5.00500354203748,33.1199988722801,0.0119466813380463,0.00208715767687838,1,2.35753740260561E-7,,,,,,,,,,,,,,,,,,,,,4.99997138977051,5.00015115737915,-99.9255676269531,-99.9255676269531,53.3676412217845,5.64384006872886,2.88666725158691,54,1,0,0,1,0.3033447265625,33.7243423461914,1,1,3,4.99997138977051,0,5.00006127357483,,,,,,,,,,,,,,,,,,,,,,,,,,,,,,,,,
,3879864663.41945,5.0001757144928,-249.889434814453,3.9908145139976E-6,9.82494232462483E-9,1,4,13.4005146026611,5.0049232402472,33.1199988722801,0.00496117246187776,7.83539870567368E-4,1,3.25174243236405E-8,,,,,,,,,,,,,,,,,,,,,5.00005483627319,5.0002965927124,-249.889434814453,-249.889434814453,53.4966099274576,5.64419592757873,2.89220333099365,54,2,0,0,1,0.304336547851562,33.7243423461914,1,1,3,5.0002965927124,0,5.0001757144928,,,,,,,,,,,,,,,,,,,,,,,,,,,,,,,,,
,3879864759.38575,4.99993371963501,-399.765197753906,-1.38785002685429E-6,7.98609054960347E-9,1,4,13.4005146026611,5.00485488318455,33.1199988722801,-0.00174632085626275,-1.31758181558525E-4,1,1.01753443721242E-7,,,,,,,,,,,,,,,,,,,,,4.99973630905151,5.00013113021851,-399.765197753906,-399.765197753906,53.3938257771787,5.64443680207976,2.88645124435425,53,3,68,0,0,0.305404663085937,33.7243423461914,1,1,3,4.99973630905151,0,4.99993371963501,,,,,,,,,,,,,,,,,,,,,,,,,,,,,,,,,
,3879864886.01851,4.99993705749512,-599.767456054687,-7.63002117478642E-6,1.51443908975878E-8,1,4,13.4005146026611,5.00495020231023,33.1199988722801,-0.00953601057627407,-0.00115917527293924,1,2.10096099689444E-7,,,,,,,,,,,,,,,,,,,,,4.9998631477356,5.00001096725464,-599.767456054687,-599.767456054687,53.4465857022268,5.6433782772812,2.88194608688354,54,1,0,0,1,0.303115844726562,33.7243423461914,1,1,3,5.00001096725464,0,4.99993705749512,,,,,,,,,,,,,,,,,,,,,,,,,,,,,,,,,
,3879864971.65938,5.00004744529724,-749.819396972656,-1.14125466348204E-5,3.2618602051954E-8,1,4,13.4005146026611,5.00492503533963,33.1199988722801,-0.014234489864294,-0.00192650888245661,1,1.5943425695597E-7,,,,,,,,,,,,,,,,,,,,,4.99991035461426,5.00018453598022,-749.819396972656,-749.819396972656,53.4653447866883,5.6435157683597,2.87614345550537,53,2,68,0,0,0.30487060546875,33.7243423461914,1,1,3,4.99991035461426,0,5.00004744529724,,,,,,,,,,,,,,,,,,,,,,,,,,,,,,,,,
,3879865043.82392,5.00010442733765,-899.707763671875,-1.45338338781153E-5,4.07481134840459E-8,1,4,13.4005146026611,5.00490290186378,33.1199988722801,-0.0181027667581935,-0.00261842510299408,1,7.04412790984522E-8,,,,,,,,,,,,,,,,,,,,,5.000084400177,5.00012445449829,-899.707763671875,-899.707763671875,53.4696437435441,5.64400466521489,2.88033080101013,54,3,0,0,1,0.305099487304687,33.7243423461914,1,1,3,5.00012445449829,0,5.00010442733765,,,,,,,,,,,,,,,,,,,,,,,,,,,,,,,,,
,3879865125.82101,5.00000929832458,-1099.68469238281,-1.79104465990194E-5,5.38550692829565E-8,1,4,13.4005146026611,5.00484118417385,33.1199988722801,-0.022344610985665,-0.0029830149487764,1,2.82596676744061E-7,,,,,,,,,,,,,,,,,,,,,4.99995756149292,5.00006103515625,-1099.68469238281,-1099.68469238281,53.5489790382461,5.64346046255591,2.87896132469177,54,1,0,0,1,0.305099487304687,33.7243423461914,1,1,3,4.99995756149292,0,5.00000929832458,,,,,,,,,,,,,,,,,,,,,,,,,,,,,,,,,
,3879865214.25571,5.00015902519226,-1249.673828125,-1.98145034438831E-5,1.33051656668005E-8,1,4,13.4005146026611,5.00479950345509,33.1199988722801,-0.0246917729620835,-0.00348728927955883,1,1.62241283954704E-7,,,,,,,,,,,,,,,,,,,,,5.00006294250488,5.00025510787964,-1249.673828125,-1249.673828125,53.5864972071691,5.64434929665915,2.87581276893616,54,2,0,0,1,0.303726196289063,33.7243423461914,1,1,3,5.00025510787964,0,5.00015902519226,,,,,,,,,,,,,,,,,,,,,,,,,,,,,,,,,
,3879865285.88484,5.0000536441803,-1399.56225585938,-2.131955879176E-5,7.4980410051328E-9,1,4,13.4005146026611,5.00489689514265,33.1199988722801,-0.0265552038400759,-0.00383791806173547,1,1.05757117115627E-7,,,,,,,,,,,,,,,,,,,,,5.00003433227539,5.00007295608521,-1399.56225585938,-1399.56225585938,53.5227944828518,5.6429202107324,2.87726163864136,53,3,68,0,0,0.305023193359375,33.7243423461914,1,1,3,5.00003433227539,0,5.0000536441803,,,,,,,,,,,,,,,,,,,,,,,,,,,,,,,,,
,3879865368.96172,5.00000834465027,-1599.57690429687,-2.28770140466925E-5,1.59874836983501E-8,1,4,13.4005146026611,5.00489211427669,33.1199988722801,-0.0285073626138271,-0.00403631082666625,1,1.79342814594691E-7,,,,,,,,,,,,,,,,,,,,,4.99980449676514,5.0002121925354,-1599.57690429687,-1599.57690429687,53.3680320360441,5.64353209758429,2.8758237361908,53,1,68,0,0,0.3045654296875,33.2355842590332,1,1,3,4.9999794960022,0,5.00000834465027,,,,,,,,,,,,,,,,,,,,,,,,,,,,,,,,,
,3879865441.24159,5.00019025802612,-1749.54077148438,-2.36827026905452E-5,1.44418728188222E-8,1,4,13.4005146026611,5.00492305444523,33.1199988722801,-0.0295009292676401,-0.00424981324999083,1,1.28362849840883E-7,,,,,,,,,,,,,,,,,,,,,4.99965953826904,5.0007209777832,-1749.54077148438,-1749.54077148438,53.3867911205057,5.64334179195728,2.87563133239746,54,2,0,0,1,0.302581787109375,33.7243423461914,1,1,3,4.99965953826904,0,5.00019025802612,,,,,,,,,,,,,,,,,,,,,,,,,,,,,,,,,
,3879865514.07128,4.99974513053894,-1899.80676269531,-2.42977416794104E-5,7.29006245534993E-9,1,4,13.4005146026611,5.0048075272704,33.1199988722801,-0.0302596975847194,-0.00440277442013482,1,9.73612524147961E-8,,,,,,,,,,,,,,,,,,,,,4.9997353553772,4.99975490570068,-1899.80676269531,-1899.80676269531,53.5431168243518,5.64333602992111,2.86792302131653,54,3,0,0,1,0.30487060546875,33.2355842590332,1,1,3,4.9997353553772,0,4.99974513053894,,,,,,,,,,,,,,,,,,,,,,,,,,,,,,,,,
,3879865596.38012,4.99972414970398,-2099.78369140625,-2.48345682045138E-5,1.98594476881288E-8,1,4,13.4005146026611,5.00478361951255,33.1199988722801,-0.030934502950339,-0.00445680812368479,1,1.34229621891583E-7,,,,,,,,,,,,,,,,,,,,,4.9996223449707,4.99982595443726,-2099.78369140625,-2099.78369140625,53.4794141000345,5.64400796682325,2.86721682548523,52,1,68,0,0,0.305633544921875,33.7243423461914,1,1,3,4.99982595443726,0,4.99972414970398,,,,,,,,,,,,,,,,,,,,,,,,,,,,,,,,,
,3879865668.1783,5.00004768371582,-2249.76025390625,-2.50357639378729E-5,1.18761617374589E-7,1,4,13.4005146026611,5.004897295713,33.1199988722801,-0.0312009625667985,-0.00439375468394591,1,2.15100336163099E-7,,,,,,,,,,,,,,,,,,,,,4.99959945678711,5.00049591064453,-2249.76025390625,-2249.76025390625,53.491138527823,5.64346623954119,2.87400484085083,54,2,0,0,1,0.303726196289063,33.7243423461914,1,1,3,5.00049591064453,0,5.00004768371582,,,,,,,,,,,,,,,,,,,,,,,,,,,,,,,,,
,3879865739.82071,5.00018739700317,-2399.68627929687,-2.5129086445443E-5,7.23166903594455E-9,1,4,13.4005146026611,5.00481237419483,33.1199988722801,-0.0312918622265182,-0.00457488067230126,1,8.34506532930308E-8,,,,,,,,,,,,,,,,,,,,,4.99999189376831,5.00038290023804,-2399.68627929687,-2399.68627929687,53.4864487567076,5.64312038431892,2.87244510650635,54,3,0,0,1,0.30426025390625,33.7243423461914,1,1,3,5.00038290023804,0,5.00018739700317,,,,,,,,,,,,,,,,,,,,,,,,,,,,,,,,,
,3879865821.97526,4.99992680549622,-2599.77685546875,-2.50877669298812E-5,7.837081312797E-9,1,4,13.4005146026611,5.00486970287048,33.1199988722801,-0.0312489001042039,-0.00451401778088036,1,1.2622813496575E-7,,,,,,,,,,,,,,,,,,,,,4.99987602233887,4.99997758865356,-2599.77685546875,-2599.77685546875,53.452447916121,5.64348922597056,2.865562915802,54,1,0,0,1,0.303573608398438,33.2355842590332,1,1,3,4.99997758865356,0,4.99992680549622,,,,,,,,,,,,,,,,,,,,,,,,,,,,,,,,,
,3879865894.43564,5.00010633468628,-2749.71557617187,-2.49361355706548E-5,7.96549864297667E-9,1,4,13.4005146026611,5.00483682094551,33.1199988722801,-0.0310546038543937,-0.00452106279354743,1,9.78513907986233E-8,,,,,,,,,,,,,,,,,,,,,5.00010585784912,5.00010681152344,-2749.71557617187,-2749.71557617187,53.5759452221595,5.64428718929422,2.87201046943665,52,2,68,0,0,0.30487060546875,33.7243423461914,1,1,3,5.00010585784912,0,5.00010633468628,,,,,,,,,,,,,,,,,,,,,,,,,,,,,,,,,
,3879865966.00059,4.99985361099243,-2899.57861328125,-2.47188984232576E-5,7.08168091247759E-9,1,4,13.4005146026611,5.00475894478566,33.1199988722801,-0.0307787618586169,-0.00451254592811146,1,7.21180181187949E-8,,,,,,,,,,,,,,,,,,,,,4.99984502792358,4.99986219406128,-2899.57861328125,-2899.57861328125,53.4309531318422,5.64414696594185,2.86182427406311,54,3,0,0,1,0.305252075195313,33.7243423461914,1,1,3,4.99984502792358,0,4.99985361099243,,,,,,,,,,,,,,,,,,,,,,,,,,,,,,,,,
,3879866071.03817,5.00005674362183,-3499.71118164063,-2.31566431745863E-5,9.35569111260277E-9,1,4,13.4005146026611,5.00468085717059,33.1199988722801,-0.0288182993167491,-0.00432478547131111,1,-1.08024361057577E-8,,,,,,,,,,,,,,,,,,,,,4.99997854232788,5.00013494491577,-3499.71118164063,-3499.71118164063,53.3441923662076,5.64442628582,2.86996245384216,54,1,0,0,1,0.305633544921875,33.2355842590332,1,1,3,5.00023794174194,0,5.00005674362183,,,,,,,,,,,,,,,,,,,,,,,,,,,,,,,,,
,3879866153.9715,5.00013446807861,-4999.740234375,-1.7202746931868E-5,9.35836506564101E-9,1,4,13.4005146026611,5.00490380266498,33.1199988722801,-0.0214100187872599,-0.00321320460688878,1,-8.17096549234314E-9,,,,,,,,,,,,,,,,,,,,,4.99997282028198,5.00029611587524,-4999.740234375,-4999.740234375,53.4086767190441,5.64305433158468,2.86753463745117,54,2,0,0,1,0.303955078125,33.2355842590332,1,1,3,5.00030136108398,0,5.00013446807861,,,,,,,,,,,,,,,,,,,,,,,,,,,,,,,,,
,3879866237.18042,5.0000684261322,-6499.7314453125,-9.98048269060276E-6,1.16013973809342E-8,1,4,13.4005146026611,5.00438232339948,33.1199988722801,-0.012418944520151,-0.00186828910975147,1,-8.24591287771035E-9,,,,,,,,,,,,,,,,,,,,,5.0000147819519,5.0001220703125,-6499.7314453125,-6499.7314453125,53.6767753011403,5.6460893005036,2.86032867431641,54,3,0,0,1,0.304641723632812,33.2355842590332,1,1,3,5.0001220703125,0,5.0000684261322,,,,,,,,,,,,,,,,,,,,,,,,,,,,,,,,,
,3879866335.59331,4.99964165687561,-8499.58984375,4.11415047248329E-7,1.31640309711781E-8,1,4,13.4005146026611,5.00416177094813,33.1199988722801,5.19966869125162E-4,2.3095787181164E-5,1,-4.29853819529956E-8,,,,,,,,,,,,,,,,,,,,,4.99935340881348,4.99992990493774,-8499.58984375,-8499.58984375,53.503253769871,5.64740499696474,2.86066746711731,54,1,0,0,1,0.308685302734375,33.7243423461914,1,1,3,4.99992990493774,0,4.99964165687561,,,,,,,,,,,,,,,,,,,,,,,,,,,,,,,,,
,3879866418.83028,5.00005722045898,-9999.70703125,8.43192897493205E-6,1.40618568259582E-8,1,4,13.4005146026611,5.00428844504176,33.1199988722801,0.0104986081751506,0.00153264362882441,1,-2.97757721055792E-8,,,,,,,,,,,,,,,,,,,,,5.00003290176392,5.00008153915405,-9999.70703125,-9999.70703125,53.4204011468326,5.64753622656889,2.86096119880676,54,2,0,0,1,0.304489135742188,33.2355842590332,1,1,3,5.00003290176392,0,5.00005722045898,,,,,,,,,,,,,,,,,,,,,,,,,,,,,,,,,
,3879866606.6713,5.00006008148193,-19999.666015625,6.41023223494594E-5,2.08125826903142E-8,1,4,13.4005146026611,5.00438120578583,33.1199988722801,0.0797796022694662,0.0118950947943248,1,-3.10002288518404E-8,,,,,,,,,,,,,,,,,,,,,4.99991321563721,5.00020694732666,-19999.666015625,-19999.666015625,53.6752120441018,5.64718056268316,2.8636314868927,54,3,0,0,1,0.306549072265625,33.2355842590332,1,1,3,5.00020694732666,0,5.00006008148193,,,,,,,,,,,,,,,,,,,,,,,,,,,,,,,,,
,3879866890.8496,4.99987721443176,-39999.859375,1.7886750432444E-4,3.83409520617472E-8,1,4,13.4005146026611,5.00438225240846,33.1199988722801,0.222621322248731,0.0331328843223935,1,-1.3353061692975E-7,,,,,,,,,,,,,,,,,,,,,4.99981784820557,4.99993658065796,-39999.859375,-39999.859375,53.9870818232749,5.64807839535371,2.8623034954071,54,1,0,0,1,0.306549072265625,33.7243423461914,1,1,3,4.99993658065796,0,4.99987721443176,,,,,,,,,,,,,,,,,,,,,,,,,,,,,,,,,
,3879867112.34619,4.99987363815308,-54999.59375,2.65741349687333E-4,5.54606258932426E-8,1,4,13.4005146026611,5.00450609973708,33.1199988722801,0.330734896372071,0.0493768065359789,1,-7.78839069011782E-8,,,,,,,,,,,,,,,,,,,,,4.99980211257935,4.99994516372681,-54999.59375,-54999.59375,54.3044230020827,5.64843703781579,2.85929441452026,54,2,0,0,1,0.305328369140625,33.7243423461914,1,1,3,4.99992942810059,0,4.99987363815308,,,,,,,,,,,,,,,,,,,,,,,,,,,,,,,,,
,3879867344.71824,4.99988746643066,-69999.5078125,3.53373598926034E-4,1.26455013894948E-7,1,4,13.4005146026611,5.00440055405279,33.1199988722801,0.43976216434309,0.0658221958279065,1,2.86751113661485E-8,,,,,,,,,,,,,,,,,,,,,4.99981021881103,4.99996471405029,-69999.5078125,-69999.5078125,54.5869817117846,5.6503076143905,2.86585140228271,54,3,0,0,1,0.306243896484375,34.2131004333496,1,1,3,4.99996471405029,0,4.99988746643066,,,,,,,,,,,,,,,,,,,,,,,,,,,,,,,,,
,3879867629.68869,4.99995350837708,-49999.890625,2.34311392149337E-4,6.25631419999952E-8,1,4,13.4005146026611,5.00414623574672,33.1199988722801,0.291580220311012,0.0435888281792192,1,-2.34052191940698E-8,,,,,,,,,,,,,,,,,,,,,4.9999098777771,4.99999713897705,-49999.890625,-49999.890625,54.1844430243807,5.64987768939262,2.8627781867981,54,1,0,0,1,0.304031372070313,33.7243423461914,1,1,3,4.99999713897705,0,4.99995350837708,,,,,,,,,,,,,,,,,,,,,,,,,,,,,,,,,
,3879867851.96873,5.00009250640869,-34999.640625,1.46515523798732E-4,3.94086116374989E-8,1,4,13.4005146026611,5.00423818106243,33.1199988722801,0.182336928003222,0.027214316560292,1,-4.88612665830021E-8,,,,,,,,,,,,,,,,,,,,,5.0000524520874,5.00013256072998,-34999.640625,-34999.640625,53.831537747948,5.64931681984205,2.85737895965576,54,2,0,0,1,0.306015014648438,32.7468223571777,1,1,3,5.00013256072998,0,5.00009250640869,,,,,,,,,,,,,,,,,,,,,,,,,,,,,,,,,
,3879868072.73149,5.00002694129944,-19999.716796875,6.0298174553081E-5,2.74033433714316E-8,1,4,13.4005146026611,5.00430963400691,33.1199988722801,0.0750424846754768,0.0111963219097542,1,-2.32426692208602E-8,,,,,,,,,,,,,,,,,,,,,4.9999852180481,5.00006866455078,-19999.716796875,-19999.716796875,53.5763360364191,5.64688270965758,2.86223220825195,54,3,0,0,1,0.305404663085937,34.2131004333496,1,1,3,4.9999852180481,0,5.00002694129944,,,,,,,,,,,,,,,,,,,,,,,,,,,,,,,,,
,3879868273.5282,5.0000581741333,-9500.45703125,1.70449532943002E-6,1.72551771033629E-8,1,4,13.4005146026611,5.00424246927401,33.1199988722801,0.00211937078458273,3.29013710860348E-4,1,9.4074631075985E-9,,,,,,,,,,,,,,,,,,,,,4.99940633773804,5.00071001052856,-9500.45703125,-9500.45703125,53.4719886291018,5.64703966659054,2.85422110557556,54,1,0,0,1,0.307769775390625,34.2131004333496,1,1,3,5.00071001052856,0,5.0000581741333,,,,,,,,,,,,,,,,,,,,,,,,,,,,,,,,,
,3879868358.07995,5.00025939941406,-8000.3017578125,-6.29899242461153E-6,1.28300071606325E-8,1,4,13.4005146026611,5.00422219077357,33.1199988722801,-0.00784398658601454,-0.0011365942745778,1,2.89386963080442E-8,,,,,,,,,,,,,,,,,,,,,4.99967241287231,5.00084638595581,-8000.3017578125,-8000.3017578125,53.5192771545153,5.64735476276223,2.86284875869751,54,2,0,0,1,0.305862426757812,33.7243423461914,1,1,3,4.99967241287231,0,5.00025939941406,,,,,,,,,,,,,,,,,,,,,,,,,,,,,,,,,
,3879868443.50806,5.00022602081299,-6500.23486328125,-1.41048122234591E-5,1.20241599788175E-8,1,4,13.4005146026611,5.00428077726464,33.1199988722801,-0.0175557674944509,-0.00260468330775401,1,1.69390572012492E-8,,,,,,,,,,,,,,,,,,,,,5.00012302398682,5.00032901763916,-6500.23486328125,-6500.23486328125,53.5169322689576,5.64642642926416,2.8618495464325,54,3,0,0,1,0.305557250976562,33.7243423461914,1,1,3,5.00037050247192,0,5.00022602081299,,,,,,,,,,,,,,,,,,,,,,,,,,,,,,,,,
,3879868542.95406,5.00001883506775,-4500.38916015625,-2.38061141024417E-5,9.45461209307167E-9,1,4,13.4005146026611,5.00426836303125,33.1199988722801,-0.0296361845643177,-0.00435841579320444,1,5.89293035501406E-8,,,,,,,,,,,,,,,,,,,,,5.0000114440918,5.0000262260437,-4500.38916015625,-4500.38916015625,53.2922140696787,5.64670895858307,2.86095237731934,54,1,0,0,1,0.304718017578125,34.7018585205078,1,1,3,5.00007295608521,0,5.00001883506775,,,,,,,,,,,,,,,,,,,,,,,,,,,,,,,,,
,3879868627.27911,4.999915599823,-3000.3603515625,-2.9615426001089E-5,8.14323899893543E-9,1,4,13.4005146026611,5.0044107578187,33.1199988722801,-0.0368626901416891,-0.00546874167166768,1,3.59101280194965E-8,,,,,,,,,,,,,,,,,,,,,4.99986505508423,4.99996614456177,-3000.3603515625,-3000.3603515625,53.5341280963807,5.64583082052307,2.86465120315552,54,2,0,0,1,0.30548095703125,34.2131004333496,1,1,3,4.99986505508423,0,4.999915599823,,,,,,,,,,,,,,,,,,,,,,,,,,,,,,,,,
,3879868717.24593,5.00006604194641,-2900.35913085937,-2.97774748998295E-5,1.02771649972329E-8,1,4,13.4005146026611,5.00441197751312,33.1199988722801,-0.0370386681877484,-0.00567072563531512,1,-1.02149827964198E-7,,,,,,,,,,,,,,,,,,,,,5.00005531311035,5.00007677078247,-2900.35913085937,-2900.35913085937,53.4501030305633,5.64597207464782,2.86222338676453,54,3,0,0,1,0.306777954101562,33.7243423461914,1,1,3,5.00007677078247,0,5.00006604194641,,,,,,,,,,,,,,,,,,,,,,,,,,,,,,,,,
,3879868799.88138,4.99995636940002,-2700.34448242187,-3.02230737958141E-5,2.48666478508766E-8,1,4,13.4005146026611,5.00446998999321,33.1199988722801,-0.0375829589765674,-0.0058263768379798,1,-1.60487642798045E-7,,,,,,,,,,,,,,,,,,,,,4.99994468688965,4.9999680519104,-2700.34448242187,-2700.34448242187,53.4672988579864,5.64519907747244,2.856693983078,54,1,0,0,1,0.3045654296875,34.2131004333496,1,1,3,4.99994468688965,0,4.99995636940002,,,,,,,,,,,,,,,,,,,,,,,,,,,,,,,,,
,3879868871.3052,5.00004291534424,-2550.39306640625,-3.05885093580162E-5,1.35661534852577E-8,1,4,13.4005146026611,5.0044652086647,33.1199988722801,-0.0380409066239815,-0.00587293597747169,1,-1.4323874225207E-7,,,,,,,,,,,,,,,,,,,,,4.99994993209839,5.00013589859009,-2550.39306640625,-2550.39306640625,53.3621698221499,5.64547775404591,2.85793495178223,53,2,68,0,0,0.30609130859375,33.7243423461914,1,1,3,4.99994993209839,0,5.00004291534424,,,,,,,,,,,,,,,,,,,,,,,,,,,,,,,,,
,3879868941.766,5.00001072883606,-2400.41650390625,-3.08417801516604E-5,1.14965643950198E-8,1,4,13.4005146026611,5.00448476105529,33.1199988722801,-0.0383616262397706,-0.00588460303479733,1,-1.14700007463683E-7,,,,,,,,,,,,,,,,,,,,,4.99999856948853,5.00002288818359,-2400.41650390625,-2400.41650390625,53.3969522912557,5.64463446113439,2.85772705078125,54,3,0,0,1,0.305023193359375,33.2355842590332,1,1,3,4.99999856948853,0,5.00001072883606,,,,,,,,,,,,,,,,,,,,,,,,,,,,,,,,,
,3879869023.20188,4.99988698959351,-2200.38916015625,-3.10604543440537E-5,1.88389589327027E-8,1,4,13.4005146026611,5.00443147579432,33.1199988722801,-0.0386241711566415,-0.00598553934167038,1,-1.63164413053727E-7,,,,,,,,,,,,,,,,,,,,,4.99983882904053,4.99993515014648,-2200.38916015625,-2200.38916015625,53.4895752707845,5.64456755361554,2.86442399024963,54,1,0,0,1,0.30487060546875,33.7243423461914,1,1,3,4.99983882904053,0,4.99988698959351,,,,,,,,,,,,,,,,,,,,,,,,,,,,,,,,,
,3879869094.66614,4.99995350837708,-2050.31201171875,-3.12101291610889E-5,1.62074105859466E-8,1,4,13.4005146026611,5.00450140636094,33.1199988722801,-0.0388165959514615,-0.00597744441471434,1,-1.34175524448791E-7,,,,,,,,,,,,,,,,,,,,,4.99975728988647,5.00014972686768,-2050.31201171875,-2050.31201171875,53.5364729819384,5.64606285982811,2.86444330215454,54,2,0,0,1,0.302734375,34.2131004333496,1,1,3,4.99975728988647,0,4.99995350837708,,,,,,,,,,,,,,,,,,,,,,,,,,,,,,,,,
,3879869166.10359,4.99993133544922,-1900.41101074219,-3.12557720008227E-5,1.33613993548712E-8,1,4,13.4005146026611,5.00437864896468,33.1199988722801,-0.0388782334446065,-0.0059445068259944,1,-1.01045367565879E-7,,,,,,,,,,,,,,,,,,,,,4.99987983703613,4.9999828338623,-1900.41101074219,-1900.41101074219,53.4798049142941,5.64594122351104,2.86470365524292,54,3,0,0,1,0.305099487304687,33.7243423461914,1,1,3,4.99987983703613,0,4.99993133544922,,,,,,,,,,,,,,,,,,,,,,,,,,,,,,,,,
,3879869248.21994,4.99988055229187,-1700.03125,-3.10902491808527E-5,2.17745927166814E-8,1,4,13.4005146026611,5.00443676033449,33.1199988722801,-0.0386577672924454,-0.00601476216301292,1,-1.82181841665697E-7,,,,,,,,,,,,,,,,,,,,,4.99978971481323,4.99997138977051,-1700.03125,-1700.03125,53.4610458298326,5.64584562029895,2.86173963546753,54,1,0,0,1,0.304794311523438,33.7243423461914,1,1,3,4.99997138977051,0,4.99988055229187,,,,,,,,,,,,,,,,,,,,,,,,,,,,,,,,,
,3879869319.11049,4.9999897480011,-1550.07995605469,-3.09241798841621E-5,1.70807379811106E-8,1,4,13.4005146026611,5.00439372933353,33.1199988722801,-0.0384546628142844,-0.00595683062305658,1,-1.60532136792724E-7,,,,,,,,,,,,,,,,,,,,,4.99982261657715,5.00015687942505,-1550.07995605469,-1550.07995605469,53.4336888316595,5.64530149766998,2.86317300796509,54,2,0,0,1,0.305862426757812,33.7243423461914,1,1,3,4.99982261657715,0,4.9999897480011,,,,,,,,,,,,,,,,,,,,,,,,,,,,,,,,,
,3879869390.47,5.00005412101746,-1400.12866210938,-3.06047444396074E-5,1.37800213044969E-8,1,4,13.4005146026611,5.00444688193977,33.1199988722801,-0.0380667021554477,-0.00583725156911449,1,-1.1216053611979E-7,,,,,,,,,,,,,,,,,,,,,5.0000433921814,5.00006484985352,-1400.12866210938,-1400.12866210938,53.4903568993037,5.64524202945569,2.86302065849304,53,3,68,0,0,0.306396484375,32.7468223571777,1,1,3,5.00006484985352,0,5.00005412101746,,,,,,,,,,,,,,,,,,,,,,,,,,,,,,,,,
,3879869471.27779,4.99997711181641,-1200.12646484375,-2.97944470641913E-5,2.84178082892164E-8,1,4,13.4005146026611,5.00428123916202,33.1199988722801,-0.0370364925180913,-0.00582036363812564,1,-2.20022478394653E-7,,,,,,,,,,,,,,,,,,,,,4.99997711181641,4.99997711181641,-1200.12646484375,-1200.12646484375,53.4778508429961,5.64598050422094,2.86575889587402,53,1,68,0,0,0.3082275390625,34.2131004333496,1,1,3,4.99997711181641,0,4.99997711181641,,,,,,,,,,,,,,,,,,,,,,,,,,,,,,,,,
,3879869543.16186,4.99993181228638,-1050.12475585938,-2.90969402600815E-5,2.04681407234351E-8,1,4,13.4005146026611,5.00427215577176,33.1199988722801,-0.0361791862898522,-0.00561835784655351,1,-1.6205022020656E-7,,,,,,,,,,,,,,,,,,,,,4.99992227554321,4.99994134902954,-1050.12475585938,-1050.12475585938,53.4485397735249,5.64598289942373,2.86605453491211,54,2,0,0,1,0.305404663085937,33.7243423461914,1,1,3,4.99998426437378,0,4.99993181228638,,,,,,,,,,,,,,,,,,,,,,,,,,,,,,,,,
,3879869615.62998,5.00004076957703,-900.123168945313,-2.81096419198791E-5,1.27770220594951E-8,1,4,13.4005146026611,5.00438139258814,33.1199988722801,-0.03495994710657,-0.00537907120979603,1,-1.17327196277029E-7,,,,,,,,,,,,,,,,,,,,,4.99999809265137,5.00008344650269,-900.123168945313,-900.123168945313,53.5575769519576,5.64581502641762,2.86703491210938,52,3,68,0,0,0.303268432617188,33.7243423461914,1,1,3,4.99999809265137,0,5.00004076957703,,,,,,,,,,,,,,,,,,,,,,,,,,,,,,,,,
,3879869696.48787,5.00004887580872,-700.133605957031,-2.62596106245645E-5,2.23448694278279E-8,1,4,13.4005146026611,5.0042809024514,33.1199988722801,-0.0326348155654147,-0.00518087234549329,1,-2.34934563888604E-7,,,,,,,,,,,,,,,,,,,,,4.99991035461426,5.00018739700317,-700.133605957031,-700.133605957031,53.2734549852172,5.64666287547376,2.86526155471802,53,1,68,0,0,0.306167602539063,33.7243423461914,1,1,3,5.00021982192993,0,5.00004887580872,,,,,,,,,,,,,,,,,,,,,,,,,,,,,,,,,
,3879869767.91048,5.00009512901306,-550.157104492188,-2.45113018055336E-5,1.65469929458378E-8,1,4,13.4005146026611,5.00417981464063,33.1199988722801,-0.0304759591799906,-0.00473713329600552,1,-1.40001498877387E-7,,,,,,,,,,,,,,,,,,,,,5.00005769729614,5.00013256072998,-550.157104492188,-550.157104492188,53.4544019874191,5.64710854262975,2.86222052574158,54,2,0,0,1,0.305633544921875,33.7243423461914,1,1,3,5.00005769729614,0,5.00009512901306,,,,,,,,,,,,,,,,,,,,,,,,,,,,,,,,,
,3879869840.25617,4.99997687339783,-400.193206787109,-2.22427760076007E-5,1.32822592478289E-8,1,4,13.4005146026611,5.00415008926411,33.1199988722801,-0.0276589054162906,-0.00427372739729163,1,-1.06996400226183E-7,,,,,,,,,,,,,,,,,,,,,4.99986219406128,5.00009155273438,-400.193206787109,-400.193206787109,53.3926533343999,5.64616324516821,2.86632132530212,54,3,0,0,1,0.304946899414063,33.7243423461914,1,1,3,4.99986219406128,0,4.99997687339783,,,,,,,,,,,,,,,,,,,,,,,,,,,,,,,,,
,3879869919.85013,4.99997878074646,-200.16584777832,-1.80912958774709E-5,2.8081470531223E-8,1,4,13.4005146026611,5.00426432326641,33.1199988722801,-0.0224684970069057,-0.00366841747792537,1,-2.41509482793698E-7,,,,,,,,,,,,,,,,,,,,,4.99989414215088,5.00006341934204,-200.16584777832,-200.16584777832,53.5380362389768,5.64524222579762,2.85752463340759,53,1,68,0,0,0.305862426757812,33.2355842590332,1,1,3,5.00006341934204,0,4.99997878074646,,,,,,,,,,,,,,,,,,,,,,,,,,,,,,,,,
,3879869991.22828,5.00013899803162,-50.2145500183105,-1.39510411319906E-5,2.01321073212563E-8,1,4,13.4005146026611,5.00429834787435,33.1199988722801,-0.0173297736298235,-0.00280816493373373,1,-1.69565473945685E-7,,,,,,,,,,,,,,,,,,,,,5.00004911422729,5.00022888183594,-50.2145500183105,-50.2145500183105,53.3613881936306,5.64657455075596,2.85814261436462,54,2,0,0,1,0.3057861328125,33.7243423461914,1,1,3,5.00022888183594,0,5.00013899803162,,,,,,,,,,,,,,,,,,,,,,,,,,,,,,,,,
,3879870062.3145,5.00012397766113,99.8122787475586,-8.58651345638219E-6,8.48043293379474E-9,1,4,13.4005146026611,5.0043142016731,33.1199988722801,-0.010666468840683,-0.0017257979053924,1,-1.02302647702045E-7,,,,,,,,,,,,,,,,,,,,,5.00002098083496,5.0002269744873,99.8122787475586,99.8122787475586,53.4516662876018,5.64602445651718,2.85634088516235,53,3,68,0,0,0.3057861328125,33.7243423461914,1,1,3,5.00019645690918,0,5.00012397766113,,,,,,,,,,,,,,,,,,,,,,,,,,,,,,,,,
,3879870158.70529,4.99997067451477,299.738952636719,-7.53123879081132E-7,1.80427748032071E-8,1,4,13.4005146026611,5.00443576266287,33.1199988722801,-8.96956955394902E-4,-4.09619514046864E-4,1,-2.16482357919616E-7,,,,,,,,,,,,,,,,,,,,,4.99994707107544,4.9999942779541,299.738952636719,299.738952636719,53.4653447866883,5.64523061240042,2.86064076423645,54,1,0,0,1,0.304946899414063,33.7243423461914,1,1,3,4.9999942779541,0,4.99997067451477,,,,,,,,,,,,,,,,,,,,,,,,,,,,,,,,,
,3879870230.92458,4.99995923042297,449.803527832031,4.57310989254332E-6,1.13560080610884E-8,1,4,13.4005146026611,5.00448417807222,33.1199988722801,0.00571599221228823,6.86262803508934E-4,1,-1.32677950193032E-7,,,,,,,,,,,,,,,,,,,,,4.999915599823,5.00000286102295,449.803527832031,449.803527832031,53.4864487567076,5.64462243478425,2.86441493034363,52,2,68,0,0,0.306396484375,33.7243423461914,1,1,3,4.999915599823,0,4.99995923042297,,,,,,,,,,,,,,,,,,,,,,,,,,,,,,,,,
,3879870303.125,5.00002527236938,599.792602539063,9.17449274749318E-6,1.75156070368102E-8,1,4,13.4005146026611,5.00440693900489,33.1199988722801,0.0114354397654377,0.00158821727481829,1,-9.62435991993111E-8,,,,,,,,,,,,,,,,,,,,,4.9999418258667,5.00010871887207,599.792602539063,599.792602539063,53.4594825727941,5.64516654281027,2.86787629127502,54,3,0,0,1,0.306015014648438,33.7243423461914,1,1,3,4.9999418258667,0,5.00002527236938,,,,,,,,,,,,,,,,,,,,,,,,,,,,,,,,,
,3879870385.56602,4.99992704391479,799.656311035156,1.4077372819121E-5,1.9031335935894E-8,1,4,13.4005146026611,5.00442232646405,33.1199988722801,0.017555388073651,0.00237858488295467,1,-1.94596560472522E-7,,,,,,,,,,,,,,,,,,,,,4.999924659729,4.99992942810059,799.656311035156,799.656311035156,53.4196195183133,5.64522833192061,2.86000347137451,54,1,0,0,1,0.3057861328125,33.7243423461914,1,1,3,4.999924659729,0,4.99992704391479,,,,,,,,,,,,,,,,,,,,,,,,,,,,,,,,,
,3879870457.68688,4.99990820884705,949.758605957031,1.70545729060159E-5,4.21523767012608E-8,1,4,13.4005146026611,5.00438508488564,33.1199988722801,0.0212536657022164,0.00297692763465428,1,-1.5914921663133E-7,,,,,,,,,,,,,,,,,,,,,4.99986600875854,4.99995040893555,949.758605957031,949.758605957031,53.4426775596307,5.64524373488822,2.85788750648499,53,2,68,0,0,0.306472778320313,33.7243423461914,1,1,3,4.99986600875854,0,4.99990820884705,,,,,,,,,,,,,,,,,,,,,,,,,,,,,,,,,
,3879870534.04422,5.00000500679016,1099.7099609375,1.93636601383407E-5,2.13202192975456E-8,1,4,13.4005146026611,5.00453936094116,33.1199988722801,0.0241237834120292,0.00343723283767901,1,-1.34815329718446E-7,,,,,,,,,,,,,,,,,,,,,4.99992752075195,5.00008249282837,1099.7099609375,1099.7099609375,53.552105552323,5.64546412007725,2.86527347564697,54,3,0,0,1,0.305938720703125,33.2355842590332,1,1,3,5.00008249282837,0,5.00000500679016,,,,,,,,,,,,,,,,,,,,,,,,,,,,,,,,,
,3879870616.17904,5.00054001808167,1299.63659667969,2.17171711455316E-5,1.15999325070642E-8,1,4,13.4005146026611,5.00449457430813,33.1199988722801,0.0270554644550693,0.00385528560301736,1,-1.50935542104472E-7,,,,,,,,,,,,,,,,,,,,,5.00030565261841,5.00077438354492,1299.63659667969,1299.63659667969,53.5040353983903,5.6455490936486,2.8585364818573,53,1,68,0,0,0.305633544921875,33.7243423461914,1,1,3,5.00030565261841,0,5.00054001808167,,,,,,,,,,,,,,,,,,,,,,,,,,,,,,,,,
,3879870687.72995,4.99972581863403,1449.67602539062,2.30472403871693E-5,1.29725929905369E-8,1,4,13.4005146026611,5.00454850800768,33.1199988722801,0.0287080125626552,0.00412420595767398,1,-1.33871347437412E-7,,,,,,,,,,,,,,,,,,,,,4.9997181892395,4.99973344802856,1449.67602539062,1449.67602539062,53.5001272557941,5.64535810954669,2.86660480499268,54,2,0,0,1,0.308303833007812,33.2355842590332,1,1,3,4.99973344802856,0,4.99972581863403,,,,,,,,,,,,,,,,,,,,,,,,,,,,,,,,,
,3879870759.36131,4.9997227191925,1599.47619628906,2.40779041617283E-5,1.08056852540025E-8,1,4,13.4005146026611,5.00458389971559,33.1199988722801,0.0299830593819657,0.00436925313438901,1,-9.11883840985714E-8,,,,,,,,,,,,,,,,,,,,,4.99961566925049,4.99982976913452,1599.47619628906,1599.47619628906,53.369204478823,5.64468445256242,2.85790801048279,54,3,0,0,1,0.304946899414063,33.2355842590332,1,1,3,4.99961566925049,0,4.9997227191925,,,,,,,,,,,,,,,,,,,,,,,,,,,,,,,,,
,3879870841.95944,4.99998140335083,1799.52880859375,2.50791327360475E-5,5.11037135496923E-8,1,4,13.4005146026611,5.00460533576789,33.1199988722801,0.03124452422485,0.00445406520024437,1,-1.72840511351797E-7,,,,,,,,,,,,,,,,,,,,,4.99972724914551,5.00023555755615,1799.52880859375,1799.52880859375,53.4563560587172,5.64472533932197,2.8572473526001,52,1,68,0,0,0.304031372070313,33.7243423461914,1,1,3,4.99972724914551,0,4.99998140335083,,,,,,,,,,,,,,,,,,,,,,,,,,,,,,,,,
,3879870913.98956,5.00005960464478,1949.85766601562,2.55005118388189E-5,2.45920200596531E-8,1,4,13.4005146026611,5.00454877358277,33.1199988722801,0.0317600529906006,0.0045885857193541,1,-1.27730658881998E-7,,,,,,,,,,,,,,,,,,,,,4.99988031387329,5.00023889541626,1949.85766601562,1949.85766601562,53.4856671281884,5.64522237852346,2.86057686805725,54,2,0,0,1,0.304336547851562,33.7243423461914,1,1,3,5.00023889541626,0,5.00005960464478,,,,,,,,,,,,,,,,,,,,,,,,,,,,,,,,,
,3879870985.68538,4.99982237815857,2099.7333984375,2.57870671859481E-5,7.75803382045594E-9,1,4,13.4005146026611,5.00455921751883,33.1199988722801,0.0321096538773272,0.00468955039528751,1,-8.94821287903029E-8,,,,,,,,,,,,,,,,,,,,,4.99965810775757,4.99998664855957,2099.7333984375,2099.7333984375,53.411803233121,5.64454506614928,2.85765862464905,54,3,0,0,1,0.305557250976562,33.7243423461914,1,1,3,4.99965810775757,0,4.99982237815857,,,,,,,,,,,,,,,,,,,,,,,,,,,,,,,,,
,3879871067.53725,5.00006294250488,2299.83642578125,2.59551521092543E-5,1.27917594835985E-8,1,4,13.4005146026611,5.00451316000284,33.1199988722801,0.0323284945903432,0.00465347702463821,1,-1.43563814786857E-7,,,,,,,,,,,,,,,,,,,,,4.99976062774658,5.00036525726318,2299.83642578125,2299.83642578125,53.4157113757172,5.64514885112194,2.86242127418518,53,1,68,0,0,0.306243896484375,33.7243423461914,1,1,3,4.99976062774658,0,5.00006294250488,,,,,,,,,,,,,,,,,,,,,,,,,,,,,,,,,
,3879871139.83324,4.99998116493225,2449.8505859375,2.59407937920101E-5,6.81803192796307E-9,1,4,13.4005146026611,5.00452983485939,33.1199988722801,0.0323019902610311,0.00470955555599395,1,-9.63732480729647E-8,,,,,,,,,,,,,,,,,,,,,4.99968814849854,5.00027418136597,2449.8505859375,2449.8505859375,53.5161506404384,5.64541524286364,2.86492538452148,53,2,68,0,0,0.306549072265625,33.2355842590332,1,1,3,5.00027418136597,0,4.99998116493225,,,,,,,,,,,,,,,,,,,,,,,,,,,,,,,,,
,3879871211.70619,5.00025057792664,2599.70141601562,2.58356969747348E-5,6.98065858510721E-9,1,4,13.4005146026611,5.00454113488877,33.1199988722801,0.0321673390425677,0.00471645479397653,1,-7.51197210571385E-8,,,,,,,,,,,,,,,,,,,,,5.00018167495728,5.000319480896,2599.70141601562,2599.70141601562,53.4970007417172,5.64605800789929,2.86169767379761,53,3,68,0,0,0.3033447265625,33.2355842590332,1,1,3,5.000319480896,0,5.00025057792664,,,,,,,,,,,,,,,,,,,,,,,,,,,,,,,,,
,3879871293.56113,4.99989175796509,2799.81665039062,2.55644033888714E-5,3.1542430156009E-8,1,4,13.4005146026611,5.00449526705183,33.1199988722801,0.0318406221048125,0.00459018464218907,1,-1.35948536500413E-7,,,,,,,,,,,,,,,,,,,,,4.9996452331543,5.00013828277588,2799.81665039062,2799.81665039062,53.5423351958326,5.64535184757794,2.86659288406372,54,1,0,0,1,0.30548095703125,33.2355842590332,1,1,3,5.00013828277588,0,4.99989175796509,,,,,,,,,,,,,,,,,,,,,,,,,,,,,,,,,
,3879871365.53036,5.00023317337036,2949.76806640625,2.52733269314181E-5,7.445567602604E-9,1,4,13.4005146026611,5.00450845202553,33.1199988722801,0.0314704060533427,0.00459004199200734,1,-9.25335035782131E-8,,,,,,,,,,,,,,,,,,,,,5.00011253356934,5.00035381317139,2949.76806640625,2949.76806640625,53.5310015823037,5.64582447976947,2.86434292793274,52,2,68,0,0,0.302352905273438,33.2355842590332,1,1,3,5.00035381317139,0,5.00023317337036,,,,,,,,,,,,,,,,,,,,,,,,,,,,,,,,,
,3879871457.5798,4.9997353553772,3499.64819335937,2.36872036654645E-5,6.90190728619459E-9,1,4,13.4005146026611,5.00447930713868,33.1199988722801,0.0294787174413169,0.00441159819941674,1,1.3860947201671E-9,,,,,,,,,,,,,,,,,,,,,4.99940252304077,5.00006818771362,3499.64819335937,3499.64819335937,53.4114124188614,5.64588969603448,2.85670685768127,54,3,0,0,1,0.304946899414063,33.7243423461914,1,1,3,5.00006818771362,0,4.9997353553772,,,,,,,,,,,,,,,,,,,,,,,,,,,,,,,,,
,3879871556.12764,5.00000309944153,5499.63232421875,1.51532790088522E-5,1.0585272102658E-8,1,4,13.4005146026611,5.00442511454291,33.1199988722801,0.0188510284121841,0.002868535279381,1,3.81481911085325E-8,,,,,,,,,,,,,,,,,,,,,4.99980401992798,5.00020217895508,5499.63232421875,5499.63232421875,53.467689672246,5.64627264657967,2.85973596572876,54,1,0,0,1,0.306854248046875,33.2355842590332,1,1,3,4.99980401992798,0,5.00000309944153,,,,,,,,,,,,,,,,,,,,,,,,,,,,,,,,,
,3879871640.5263,4.99964642524719,6999.8251953125,7.65555103755956E-6,1.22198759486193E-8,1,4,13.4005146026611,5.00447443087317,33.1199988722801,0.00951998676846019,0.00147480465679475,1,3.9826234904748E-8,,,,,,,,,,,,,,,,,,,,,4.99953985214233,4.99975299835205,6999.8251953125,6999.8251953125,53.4536203588999,5.64599087517023,2.86156439781189,54,2,0,0,1,0.3057861328125,33.7243423461914,1,1,3,4.99941396713257,0,4.99964642524719,,,,,,,,,,,,,,,,,,,,,,,,,,,,,,,,,
,3879871723.87676,4.9998779296875,8500.15625,-1.93676209525961E-7,1.33237800545133E-8,1,4,13.4005146026611,5.00453037718646,33.1199988722801,-2.48689171440597E-4,1.51053721795546E-5,1,4.11101954697388E-8,,,,,,,,,,,,,,,,,,,,,4.99959802627563,5.00015783309937,8500.15625,8500.15625,53.4583101300153,5.6461994436807,2.85731959342957,54,3,0,0,1,0.305938720703125,33.2355842590332,1,1,3,4.99959802627563,0,4.9998779296875,,,,,,,,,,,,,,,,,,,,,,,,,,,,,,,,,
,3879871829.99782,4.99990701675415,10000.0849609375,-8.20727332519882E-6,1.58498219933407E-8,1,4,13.4005146026611,5.00439557533734,33.1199988722801,-0.0102203259393183,-0.00148429347417598,1,3.50571905923355E-8,,,,,,,,,,,,,,,,,,,,,4.99985265731812,4.99996137619019,10000.0849609375,10000.0849609375,53.6224521190538,5.64645866139506,2.85938501358032,54,1,0,0,1,0.303573608398438,33.7243423461914,1,1,3,4.99996137619019,0,4.99990701675415,,,,,,,,,,,,,,,,,,,,,,,,,,,,,,,,,
,3879872048.02337,5.00006818771362,25000.298828125,-9.23627574856644E-5,3.00444523280439E-8,1,4,13.4005146026611,5.0045545253002,33.1199988722801,-0.114967811117325,-0.0170688536097704,1,1.01873781968089E-7,,,,,,,,,,,,,,,,,,,,,5.00005006790161,5.00008630752563,25000.298828125,25000.298828125,53.5911869782845,5.64683177795892,2.86444926261902,54,2,0,0,1,0.306472778320313,33.7243423461914,1,1,3,5.00008630752563,0,5.00006818771362,,,,,,,,,,,,,,,,,,,,,,,,,,,,,,,,,
,3879872268.97409,4.99990844726562,40000.125,-1.78611268567522E-4,3.94866416336142E-8,1,4,13.4005146026611,5.00452021593967,33.1199988722801,-0.222309287715411,-0.0330979963735335,1,1.24258944276416E-7,,,,,,,,,,,,,,,,,,,,,4.99983310699463,4.99998378753662,40000.125,40000.125,53.8479519468519,5.64685381625412,2.8672297000885,54,3,0,0,1,0.30426025390625,33.2355842590332,1,1,3,4.99998378753662,0,4.99990844726562,,,,,,,,,,,,,,,,,,,,,,,,,,,,,,,,,
,3879872550.20174,4.9997181892395,60000.45703125,-2.94800498610605E-4,8.25820507355043E-8,1,4,13.4005146026611,5.00458580931174,33.1199988722801,-0.366917531103284,-0.0547227109695291,1,1.30377435691927E-7,,,,,,,,,,,,,,,,,,,,,4.99965238571167,4.99978399276733,60000.45703125,60000.45703125,54.3509298989769,5.64823466523908,2.85821628570557,54,1,0,0,1,0.306243896484375,33.2355842590332,1,1,3,4.99978399276733,0,4.9997181892395,,,,,,,,,,,,,,,,,,,,,,,,,,,,,,,,,
,3879872713.80164,4.9999783039093,70000.390625,-3.53288293653286E-4,1.44727131358353E-7,1,4,13.4005146026611,5.00452510947991,33.1199988722801,-0.439707447345267,-0.0655670167364275,1,1.65445854353153E-7,,,,,,,,,,,,,,,,,,,,,4.99987697601318,5.00007963180542,70000.390625,70000.390625,54.5162443307942,5.64908444320475,2.86225509643555,54,3,0,0,1,0.30609130859375,33.2355842590332,1,1,3,5.00007963180542,0,4.9999783039093,,,,,,,,,,,,,,,,,,,,,,,,,,,,,,,,,