File: SQUID/22169_LCOT/22169_LCOT_MH_10K_FC_0d5T.csv
Comment,Time Stamp (sec),Temperature (K),Magnetic Field (Oe),Moment (emu),M. Std. Err. (emu),Transport Action,Averaging Time (sec),Frequency (Hz),Peak Amplitude (mm),Center Position (mm),Lockin Signal' (V),Lockin Signal (V),Range,M. Quad. Signal (emu),AC Moment (emu),AC M. Std Err. (emu),AC Phase (deg),AC Phase Std. Err. (deg),AC Susceptibility (emu/Oe),AC Suscept. Std Err. (emu/Oe),AC X' (emu/Oe),AC X' Std Err. (emu/Oe),AC X'' (emu/Oe),AC X'' Std Err. (emu/Oe),AC Drive (Oe),AC Frequency (Hz),AC Averaging Time (sec),AC Cycles,AC Range,AC Measure Type,AC Signal' (V),AC Signal'' (V),AC Trim Coil Ratio,AC Trim Coil Phase,Min. Temperature (K),Max. Temperature (K),Min. Field (Oe),Max. Field (Oe),Mass (grams),Motor Lag (deg),Pressure (Torr),Measure Count,Measurement Number,SQUID Status (code),Motor Status (code),Measure Status (code),Motor Current (amps),Motor Temp. (C),Temp. Status (code),Field Status (code),Chamber Status (code),Chamber Temp (K),Redirection State,Average Temp (K),Rotation Angle (deg),Rotator state,DC Moment Fixed Ctr (emu),DC Moment Err Fixed Ctr (emu),DC Moment Free Ctr (emu),DC Moment Err Free Ctr (emu),DC Fixed Fit,DC Free Fit,DC Calculated Center (mm),DC Calculated Center Err (mm),DC Scan Length (mm),DC Scan Time (s),DC Number of Points,DC Squid Drift,DC Min V (V),DC Max V (V),DC Scans per Measure,Sample Resistance,He3 Temperature,Sorb Resistance,Sorb Temperature,Map 05,Map 06,Map 07,Map 08,Map 09,Map 10,Map 11,Map 12,Map 13,Map 14,Map 15,Map 16
,3879872873.46764,10.0001654624939,69999.828125,-3.58488086598305E-4,1.09059019543208E-7,1,4,13.4005146026611,4.98367485013308,33.1199988722801,-0.44357536131905,-0.0661576348114106,1,1.56928233835445E-7,,,,,,,,,,,,,,,,,,,,,10.0001497268677,10.0001811981201,69999.828125,69999.828125,53.9995878795826,5.64798140257615,3.58078551292419,54,1,0,0,1,0.302352905273438,32.7468223571777,1,1,3,10.0001497268677,0,10.0001654624939,,,,,,,,,,,,,,,,,,,,,,,,,,,,,,,,,
,3879873095.92365,10.0003061294556,55000.38671875,-2.69186834304952E-4,7.73669520826976E-8,1,4,13.4005146026611,4.98373490992993,33.1300012767315,-0.333083074833031,-0.0496848288903266,1,1.12529829929327E-7,,,,,,,,,,,,,,,,,,,,,10.0002956390381,10.000316619873,55000.38671875,55000.38671875,53.7760421230826,5.64683065272454,3.59149217605591,54,2,0,0,1,0.301437377929687,33.7243423461914,1,1,3,10.0002937316895,0,10.0003061294556,,,,,,,,,,,,,,,,,,,,,,,,,,,,,,,,,
,3879873316.10096,10.0000667572021,39999.734375,-1.80729932136236E-4,4.72490880180842E-8,1,4,13.4005146026611,4.98352683464966,33.1199988722801,-0.223624734652465,-0.0332994491971437,1,1.21300792149288E-7,,,,,,,,,,,,,,,,,,,,,10.000039100647,10.0000944137573,39999.734375,39999.734375,53.6670049446499,5.64737396872474,3.5988118648529,54,3,0,0,1,0.3033447265625,33.7243423461914,1,1,3,10.0000944137573,0,10.0000667572021,,,,,,,,,,,,,,,,,,,,,,,,,,,,,,,,,
,3879873597.42693,10.0001964569092,19999.62890625,-6.38440905321138E-5,2.46547381081603E-8,1,4,13.4005146026611,4.98330095769832,33.1199988722801,-0.0789873636044741,-0.0117931727370751,1,1.80660850420461E-8,,,,,,,,,,,,,,,,,,,,,10.0000944137573,10.000298500061,19999.62890625,19999.62890625,53.4579193157556,5.64662741533936,3.60830450057983,54,1,0,0,1,0.304031372070313,34.2131004333496,1,1,3,10.0000944137573,0,10.0001964569092,,,,,,,,,,,,,,,,,,,,,,,,,,,,,,,,,
,3879873785.45273,10.0000729560852,9999.70703125,-6.62495585494632E-6,1.58153747959264E-8,1,4,13.4005146026611,4.98343148827799,33.1199988722801,-0.00819918161236365,-0.00120680593363683,1,1.56072411912971E-8,,,,,,,,,,,,,,,,,,,,,10.0000200271606,10.0001258850098,9999.70703125,9999.70703125,53.5650024228903,5.64631617182202,3.60860371589661,54,2,0,0,1,0.3033447265625,34.2131004333496,1,1,3,10.0001258850098,0,10.0000729560852,,,,,,,,,,,,,,,,,,,,,,,,,,,,,,,,,
,3879873872.52498,10.0000686645508,8499.52734375,1.67800078400877E-6,1.20153490519581E-8,1,4,13.4005146026611,4.98342331909715,33.1199988722801,0.00207387107407198,3.24732747744841E-4,1,1.14592270250868E-8,,,,,,,,,,,,,,,,,,,,,10.000054359436,10.0000829696655,8499.52734375,8499.52734375,53.567347308448,5.64564474540313,3.61286616325378,54,3,0,0,1,0.304183959960937,33.7243423461914,1,1,3,10.000054359436,0,10.0000686645508,,,,,,,,,,,,,,,,,,,,,,,,,,,,,,,,,
,3879873973.23657,10.000009059906,6499.7314453125,1.25185580367562E-5,1.08211891631817E-8,1,4,13.4005146026611,4.98335858029206,33.1199988722801,0.0154936347959071,0.0022754749672956,1,-3.34249586593062E-8,,,,,,,,,,,,,,,,,,,,,9.9999532699585,10.0000648498535,6499.7314453125,6499.7314453125,53.5048170269095,5.64658601360486,3.61965990066528,54,1,0,0,1,0.303115844726562,33.7243423461914,1,1,3,9.9999532699585,0,10.000009059906,,,,,,,,,,,,,,,,,,,,,,,,,,,,,,,,,
,3879874061.10127,10.0001783370972,4999.5390625,2.01726260318742E-5,8.27303978852897E-9,1,4,13.4005146026611,4.98333920248509,33.1300012767315,0.0249615960312386,0.00370004510191808,1,-2.69251444123111E-8,,,,,,,,,,,,,,,,,,,,,10.0001659393311,10.0001907348633,4999.5390625,4999.5390625,53.4000788053326,5.64644999805259,3.6192421913147,54,2,0,0,1,0.30181884765625,34.2131004333496,1,1,3,10.0001659393311,0,10.0001783370972,,,,,,,,,,,,,,,,,,,,,,,,,,,,,,,,,
,3879874147.9556,10.0000295639038,3499.849609375,2.68838427004987E-5,8.15343910825609E-9,1,4,13.4005146026611,4.98326921721679,33.1199988722801,0.033263494944375,0.00494362280146174,1,-2.56094734527787E-8,,,,,,,,,,,,,,,,,,,,,9.99997520446777,10.0000839233398,3499.849609375,3499.849609375,53.4927017848614,5.6456108916834,3.62281250953674,54,3,0,0,1,0.300827026367188,33.7243423461914,1,1,3,10.0000839233398,0,10.0000295639038,,,,,,,,,,,,,,,,,,,,,,,,,,,,,,,,,
,3879874252.49779,10.0000748634338,2899.6416015625,2.88206018527906E-5,1.23843101514253E-8,1,4,13.4005146026611,4.98354938272351,33.1199988722801,0.0356254032001393,0.00554929819695754,1,1.73891274765269E-7,,,,,,,,,,,,,,,,,,,,,10.0000524520874,10.0000972747803,2899.6416015625,2899.6416015625,53.2304654166595,5.64637428787214,3.61801981925964,54,1,0,0,1,0.301361083984375,33.7243423461914,1,1,3,10.0000524520874,0,10.0000748634338,,,,,,,,,,,,,,,,,,,,,,,,,,,,,,,,,
,3879874324.93377,9.99988794326782,2749.6904296875,2.92407862043632E-5,1.29345260703383E-8,1,4,13.4005146026611,4.98337491834037,33.1199988722801,0.0361508707119444,0.0055774555878713,1,1.34014224083275E-7,,,,,,,,,,,,,,,,,,,,,9.99981689453125,9.99995899200439,2749.6904296875,2749.6904296875,53.5040353983903,5.64614564982093,3.62027144432068,54,2,0,0,1,0.302810668945313,33.2355842590332,1,1,3,9.99995899200439,0,9.99988794326782,,,,,,,,,,,,,,,,,,,,,,,,,,,,,,,,,
,3879874397.72171,10.000198841095,2599.77685546875,2.96255557298879E-5,1.15433312804499E-8,1,4,13.4005146026611,4.98347686720078,33.1300012767315,0.0366346725722277,0.00560385850152693,1,9.76665210041757E-8,,,,,,,,,,,,,,,,,,,,,10.0001268386841,10.0002708435059,2599.77685546875,2599.77685546875,53.3695952930826,5.64596538279871,3.61759543418884,53,3,68,0,0,0.3009033203125,33.7243423461914,1,1,3,10.0000820159912,0,10.000198841095,,,,,,,,,,,,,,,,,,,,,,,,,,,,,,,,,
,3879874479.55737,10.0000267028809,2399.58569335938,2.99596007635991E-5,2.11277125035244E-8,1,4,13.4005146026611,4.98344738808377,33.1199988722801,0.0370374689039943,0.00573366530871147,1,1.52653700490235E-7,,,,,,,,,,,,,,,,,,,,,9.99999332427978,10.0000600814819,2399.58569335938,2399.58569335938,53.4106307903422,5.64666066167171,3.62683415412903,54,1,0,0,1,0.302734375,33.7243423461914,1,1,3,10.0000600814819,0,10.0000267028809,,,,,,,,,,,,,,,,,,,,,,,,,,,,,,,,,
,3879874549.85533,10.0002861022949,2249.57153320313,3.02381596016489E-5,1.45006869832243E-8,1,4,13.4005146026611,4.98348037158147,33.1199988722801,0.0373824396032157,0.00578531835844671,1,1.5268988111419E-7,,,,,,,,,,,,,,,,,,,,,10.0002470016479,10.0003252029419,2249.57153320313,2249.57153320313,53.543898452871,5.6460943040459,3.61986875534058,53,2,68,0,0,0.30242919921875,33.7243423461914,1,1,3,10.0002470016479,0,10.0002861022949,,,,,,,,,,,,,,,,,,,,,,,,,,,,,,,,,
,3879874620.73012,9.99995040893555,2099.67041015625,3.04320737386234E-5,1.11757020147183E-8,1,4,13.4005146026611,4.98339315063704,33.1199988722801,0.0376298355719562,0.00576485235755085,1,1.07253779975304E-7,,,,,,,,,,,,,,,,,,,,,9.99988842010498,10.0000123977661,2099.67041015625,2099.67041015625,53.4262633607268,5.64659423122647,3.62817287445068,54,3,0,0,1,0.302276611328125,33.7243423461914,1,1,3,10.0000123977661,0,9.99995040893555,,,,,,,,,,,,,,,,,,,,,,,,,,,,,,,,,
,3879874702.31193,10.0000343322754,1899.74389648438,3.04781166840999E-5,2.03944449565654E-8,1,4,13.4005146026611,4.98335850107467,33.1199988722801,0.0376626551363451,0.00593225281154634,1,2.35721864534091E-7,,,,,,,,,,,,,,,,,,,,,10.0000276565552,10.0000410079956,1899.74389648438,1899.74389648438,53.5493698525057,5.64624247176266,3.62450385093689,53,1,68,0,0,0.303497314453125,33.2355842590332,1,1,3,10.0000410079956,0,10.0000343322754,,,,,,,,,,,,,,,,,,,,,,,,,,,,,,,,,
,3879874774.9795,10.0000424385071,1749.46533203125,3.04902199922707E-5,1.36058127855119E-8,1,4,13.4005146026611,4.9833282563302,33.1199988722801,0.0376994482158437,0.00578644002284185,1,1.16090134860187E-7,,,,,,,,,,,,,,,,,,,,,10.000018119812,10.0000667572021,1749.46533203125,1749.46533203125,53.4723794433614,5.64539986236403,3.6314115524292,54,2,0,0,1,0.30303955078125,33.7243423461914,1,1,3,10.0000038146973,0,10.0000424385071,,,,,,,,,,,,,,,,,,,,,,,,,,,,,,,,,
,3879874847.22035,9.99994945526123,1599.47619628906,3.03407429791867E-5,1.9278394327131E-8,1,4,13.4005146026611,4.98338445776706,33.1199988722801,0.0375170809559794,0.00574573615185567,1,1.05476122132145E-7,,,,,,,,,,,,,,,,,,,,,9.99994659423828,9.99995231628418,1599.47619628906,1599.47619628906,53.3625606364095,5.64669776772901,3.6230640411377,54,3,0,0,1,0.302734375,33.7243423461914,1,1,3,9.99995231628418,0,9.99994945526123,,,,,,,,,,,,,,,,,,,,,,,,,,,,,,,,,
,3879874929.55888,10.0001726150513,1399.73840332031,2.99238765856419E-5,2.46905665773797E-8,1,4,13.4005146026611,4.98335839355724,33.1300012767315,0.0369782787270817,0.00582093556637603,1,2.28654798963265E-7,,,,,,,,,,,,,,,,,,,,,10.0001277923584,10.0002174377441,1399.73840332031,1399.73840332031,53.404768576448,5.6463414139528,3.62123537063599,54,1,0,0,1,0.301284790039063,33.7243423461914,1,1,3,10.0002174377441,0,10.0001726150513,,,,,,,,,,,,,,,,,,,,,,,,,,,,,,,,,
,3879875000.25462,10.0000529289246,1249.62353515625,2.95007752027985E-5,1.73464778652756E-8,1,4,13.4005146026611,4.9832848689315,33.1300012767315,0.0364693772089761,0.00564025649365231,1,1.45999021701005E-7,,,,,,,,,,,,,,,,,,,,,9.99993515014648,10.0001707077026,1249.62353515625,1249.62353515625,53.3535719084383,5.64676243143464,3.62292337417603,54,2,0,0,1,0.301971435546875,33.2355842590332,1,1,3,10.0001707077026,0,10.0000529289246,,,,,,,,,,,,,,,,,,,,,,,,,,,,,,,,,
,3879875082.12658,9.99998617172241,1099.81066894531,2.88601587651085E-5,1.37727060436427E-8,1,4,13.4005146026611,4.98319932121201,33.1199988722801,0.035684176739221,0.00546683820390559,1,1.01760234230161E-7,,,,,,,,,,,,,,,,,,,,,9.99993515014648,10.0000371932983,1099.81066894531,1099.81066894531,53.4790232857749,5.6466768456268,3.62279415130615,53,3,68,0,0,0.303802490234375,32.7468223571777,1,1,3,10.0000371932983,0,9.99998617172241,,,,,,,,,,,,,,,,,,,,,,,,,,,,,,,,,
,3879875164.59601,9.99999475479126,899.795837402344,2.75557339835993E-5,2.18083489913995E-8,1,4,13.4005146026611,4.98327499432212,33.1199988722801,0.0340457430525514,0.00539568241754162,1,2.39283167892456E-7,,,,,,,,,,,,,,,,,,,,,9.9998779296875,10.000111579895,899.795837402344,899.795837402344,53.3500545801018,5.64672855037426,3.62590885162354,52,1,68,0,0,0.30181884765625,33.7243423461914,1,1,3,9.9998779296875,0,9.99999475479126,,,,,,,,,,,,,,,,,,,,,,,,,,,,,,,,,
,3879875236.79183,10.0000405311584,749.781616210937,2.63225261029365E-5,1.56176853086586E-8,1,4,13.4005146026611,4.98320793034094,33.1300012767315,0.0325310897250173,0.00508982013235724,1,1.76605811001426E-7,,,,,,,,,,,,,,,,,,,,,10.0000352859497,10.0000457763672,749.781616210937,749.781616210937,53.3496637658422,5.64700932376762,3.62626695632935,54,2,0,0,1,0.301513671875,33.7243423461914,1,1,3,10.0000352859497,0,10.0000405311584,,,,,,,,,,,,,,,,,,,,,,,,,,,,,,,,,
,3879875309.1351,10.0002021789551,599.91845703125,2.46791511737094E-5,5.18306102737739E-8,1,4,13.4005146026611,4.98314637296123,33.1199988722801,0.0305096152435274,0.00470482787122734,1,1.11306734556397E-7,,,,,,,,,,,,,,,,,,,,,10.0000848770142,10.000319480896,599.91845703125,599.91845703125,53.4801957285537,5.64664888935655,3.6329288482666,53,3,68,0,0,0.302200317382812,33.7243423461914,1,1,3,10.0000848770142,0,10.0002021789551,,,,,,,,,,,,,,,,,,,,,,,,,,,,,,,,,
,3879875389.99534,10.0000224113464,399.865905761719,2.18013331149633E-5,2.6778489069463E-8,1,4,13.4005146026611,4.98321519079506,33.1199988722801,0.0269193956338091,0.00437713056834385,1,2.76847346446574E-7,,,,,,,,,,,,,,,,,,,,,9.99996471405029,10.0000801086426,399.865905761719,399.865905761719,53.3629514506691,5.64690637847462,3.63380336761475,52,1,68,0,0,0.303726196289063,33.7243423461914,1,1,3,9.99996471405029,0,10.0000224113464,,,,,,,,,,,,,,,,,,,,,,,,,,,,,,,,,
,3879875460.60732,9.99998378753662,249.8642578125,1.89160752783643E-5,1.95532295309638E-8,1,4,13.4005146026611,4.98318613615881,33.1199988722801,0.0233729095460362,0.003688830827711,1,1.52111038497245E-7,,,,,,,,,,,,,,,,,,,,,9.99989128112793,10.0000762939453,249.8642578125,249.8642578125,53.427044989246,5.64659232265986,3.62748527526855,54,2,0,0,1,0.302963256835937,33.7243423461914,1,1,3,10.0000762939453,0,9.99998378753662,,,,,,,,,,,,,,,,,,,,,,,,,,,,,,,,,
,3879875532.8052,9.99988603591919,100.051452636719,1.51136225453599E-5,1.510745166899E-8,1,4,13.4005146026611,4.98315201152717,33.1300012767315,0.0186721944540749,0.00296188068110405,1,1.33332724803415E-7,,,,,,,,,,,,,,,,,,,,,9.99983882904053,9.99993324279785,100.051452636719,100.051452636719,53.4133664901595,5.64663593689651,3.63545703887939,52,3,68,0,0,0.302276611328125,33.7243423461914,1,1,3,9.99993324279785,0,9.99988603591919,,,,,,,,,,,,,,,,,,,,,,,,,,,,,,,,,
,3879875615.22662,10.0000619888306,-99.9381561279297,8.30042164686969E-6,1.34202737174541E-8,1,4,13.4005146026611,4.98312032321025,33.1199988722801,0.010237432079531,0.00174210356550085,1,1.66550806150665E-7,,,,,,,,,,,,,,,,,,,,,9.99994277954102,10.0001811981201,-99.9381561279297,-99.9381561279297,53.3942165914383,5.64690714362138,3.62773990631103,53,1,68,0,0,0.302658081054687,33.7243423461914,1,1,3,9.99994277954102,0,10.0000619888306,,,,,,,,,,,,,,,,,,,,,,,,,,,,,,,,,
,3879875700.00236,10.0001811981201,-249.914611816406,2.4161739873847E-6,1.18790114312219E-8,1,4,13.4005146026611,4.98297058181751,33.1199988722801,0.00296215301799385,6.25680699678811E-4,1,1.44350366931818E-7,,,,,,,,,,,,,,,,,,,,,10.0000896453857,10.0002727508545,-249.914611816406,-249.914611816406,53.4336888316595,5.64676747545293,3.6255476474762,52,2,68,0,0,0.302886962890625,33.7243423461914,1,1,3,10.0000896453857,0,10.0001811981201,,,,,,,,,,,,,,,,,,,,,,,,,,,,,,,,,
,3879875822.32999,10.0000262260437,-399.840728759766,-3.11447540490179E-6,8.71562263805629E-9,1,4,13.4005146026611,4.98304664336694,33.1199988722801,-0.00386436396201149,-4.98802354084543E-4,1,6.26872691973683E-8,,,,,,,,,,,,,,,,,,,,,9.99997043609619,10.0000820159912,-399.840728759766,-399.840728759766,53.3836646064287,5.64669718676521,3.6290135383606,54,3,0,0,1,0.3021240234375,32.7468223571777,1,1,3,9.99995040893555,0,10.0000262260437,,,,,,,,,,,,,,,,,,,,,,,,,,,,,,,,,
,3879875913.84481,10.0001435279846,-599.792602539063,-9.30030663699838E-6,2.07733012210832E-8,1,4,13.4005146026611,4.98307078458586,33.1199988722801,-0.0115401830896341,-0.00148607227574519,1,1.89973928073688E-7,,,,,,,,,,,,,,,,,,,,,10.0001249313354,10.0001621246338,-599.792602539063,-599.792602539063,53.4274358035057,5.64688564317356,3.62747359275818,52,1,68,0,0,0.304107666015625,33.7243423461914,1,1,3,10.0001621246338,0,10.0001435279846,,,,,,,,,,,,,,,,,,,,,,,,,,,,,,,,,
,3879875995.71153,10.0000147819519,-749.819396972656,-1.30807496658471E-5,1.24474711250565E-8,1,4,13.4005146026611,4.98307001717125,33.1300012767315,-0.0162120548134574,-0.00221745642258783,1,1.6427630908185E-7,,,,,,,,,,,,,,,,,,,,,9.99997997283935,10.0000495910645,-749.819396972656,-749.819396972656,53.3535719084383,5.64718643651593,3.63569569587708,52,2,68,0,0,0.302581787109375,33.2355842590332,1,1,3,9.99997997283935,0,10.0000147819519,,,,,,,,,,,,,,,,,,,,,,,,,,,,,,,,,
,3879876067.3726,10.0000381469727,-899.745483398438,-1.61155815871537E-5,1.23937043533782E-8,1,4,13.4005146026611,4.9829126353385,33.1199988722801,-0.0199597448078727,-0.00281698578913545,1,1.33526527005775E-7,,,,,,,,,,,,,,,,,,,,,9.99990940093994,10.0001668930054,-899.745483398438,-899.745483398438,53.3387209665729,5.64693838261027,3.63308572769165,54,3,0,0,1,0.303268432617188,33.2355842590332,1,1,3,9.99990940093994,0,10.0000381469727,,,,,,,,,,,,,,,,,,,,,,,,,,,,,,,,,
,3879876149.64769,10.0000987052917,-1099.68469238281,-1.93055900205353E-5,7.16398079437942E-8,1,4,13.4005146026611,4.98308247307065,33.1199988722801,-0.0239446313354604,-0.00315550140624881,1,3.37196445430993E-7,,,,,,,,,,,,,,,,,,,,,10.000096321106,10.0001010894775,-1099.68469238281,-1099.68469238281,53.366077964746,5.64668468939178,3.63278007507324,54,1,0,0,1,0.304031372070313,33.2355842590332,1,1,3,10.000096321106,0,10.0000987052917,,,,,,,,,,,,,,,,,,,,,,,,,,,,,,,,,
,3879876222.39893,9.9998836517334,-1249.64868164062,-2.10206858039218E-5,3.11809455604499E-8,1,4,13.4005146026611,4.98290356074922,33.1199988722801,-0.0260274331667353,-0.00372383971651604,1,1.3418702101439E-7,,,,,,,,,,,,,,,,,,,,,9.99984550476074,9.99992179870605,-1249.64868164062,-1249.64868164062,53.4516662876018,5.64694181288532,3.63621973991394,54,2,0,0,1,0.303497314453125,33.2355842590332,1,1,3,9.9998950958252,0,9.9998836517334,,,,,,,,,,,,,,,,,,,,,,,,,,,,,,,,,
,3879876293.67185,9.99994230270386,-1399.58740234375,-2.24358287725271E-5,7.50365750505482E-9,1,4,13.4005146026611,4.98287242276716,33.1199988722801,-0.0277731718573015,-0.00401609279893316,1,1.09595784739945E-7,,,,,,,,,,,,,,,,,,,,,9.99985313415527,10.0000314712524,-1399.58740234375,-1399.58740234375,53.3039384974672,5.64716557726203,3.63627362251282,54,3,0,0,1,0.302352905273438,33.2355842590332,1,1,3,9.99987316131592,0,9.99994230270386,,,,,,,,,,,,,,,,,,,,,,,,,,,,,,,,,
,3879876376.19007,10.0000967979431,-1599.56433105469,-2.38441997714745E-5,6.92514365061855E-8,1,4,13.4005146026611,4.98293151972196,33.1300012767315,-0.0295245192086711,-0.00421851596113526,1,1.56694430614971E-7,,,,,,,,,,,,,,,,,,,,,10.0000009536743,10.0001926422119,-1599.56433105469,-1599.56433105469,53.3090190828422,5.64629260537403,3.62978839874268,52,1,68,0,0,0.303268432617188,33.2355842590332,1,1,3,10.0002202987671,0,10.0000967979431,,,,,,,,,,,,,,,,,,,,,,,,,,,,,,,,,
,3879876459.3444,10.0000143051147,-1749.57861328125,-2.45034056663837E-5,9.08293426116843E-9,1,4,13.4005146026611,4.98298996871832,33.1199988722801,-0.0303361627900074,-0.00436931975489283,1,1.33455826773026E-7,,,,,,,,,,,,,,,,,,,,,9.99996471405029,10.0000638961792,-1749.57861328125,-1749.57861328125,53.4184470755345,5.64629158653146,3.63329386711121,54,2,0,0,1,0.302886962890625,33.7243423461914,1,1,3,9.99996471405029,0,10.0000143051147,,,,,,,,,,,,,,,,,,,,,,,,,,,,,,,,,
,3879876531.40067,9.99997425079346,-1899.8193359375,-2.49946437920284E-5,7.42817574901274E-9,1,4,13.4005146026611,4.9829397788601,33.1300012767315,-0.0309366278728741,-0.00450544560151644,1,9.68481368122989E-8,,,,,,,,,,,,,,,,,,,,,9.99995231628418,9.99999618530273,-1899.8193359375,-1899.8193359375,53.320352696371,5.64680731633687,3.63492012023926,54,3,0,0,1,0.303573608398438,33.2355842590332,1,1,3,9.99995231628418,0,9.99997425079346,,,,,,,,,,,,,,,,,,,,,,,,,,,,,,,,,
,3879876613.64414,9.99996662139893,-2099.78369140625,-2.53678172969429E-5,1.32753746676361E-8,1,4,13.4005146026611,4.98299101551057,33.1199988722801,-0.0314109141811486,-0.00449292819008743,1,1.62844060261569E-7,,,,,,,,,,,,,,,,,,,,,9.99995803833008,9.99997520446777,-2099.78369140625,-2099.78369140625,53.3606065651114,5.64641332802612,3.63830971717834,52,1,68,0,0,0.303268432617188,33.7243423461914,1,1,3,9.99995803833008,0,9.99996662139893,,,,,,,,,,,,,,,,,,,,,,,,,,,,,,,,,
,3879876685.75713,9.99992656707764,-2249.74755859375,-2.54696904025206E-5,6.69755141167083E-9,1,4,13.4005146026611,4.98291642441785,33.1199988722801,-0.0315256029162449,-0.00458300522550548,1,1.05188713539003E-7,,,,,,,,,,,,,,,,,,,,,9.99971675872803,10.0001363754272,-2249.74755859375,-2249.74755859375,53.3887451918037,5.6461530862114,3.63228869438171,52,2,68,0,0,0.30364990234375,33.7243423461914,1,1,3,9.99971675872803,0,9.99992656707764,,,,,,,,,,,,,,,,,,,,,,,,,,,,,,,,,
,3879876757.00919,10.000020980835,-2399.72412109375,-2.54620186090775E-5,7.98324583058061E-9,1,4,13.4005146026611,4.9829413600115,33.1199988722801,-0.0315122576317601,-0.00460886851525233,1,8.31592346916584E-8,,,,,,,,,,,,,,,,,,,,,10.0000095367432,10.0000324249268,-2399.72412109375,-2399.72412109375,53.2851794130056,5.64704690782267,3.63818073272705,54,3,0,0,1,0.30364990234375,33.2355842590332,1,1,3,10.0000324249268,0,10.000020980835,,,,,,,,,,,,,,,,,,,,,,,,,,,,,,,,,
,3879876839.23294,10.0001068115234,-2599.7138671875,-2.52972063909431E-5,8.36049288333283E-9,1,4,13.4005146026611,4.9830568640755,33.1199988722801,-0.0313188448821386,-0.00451538885712963,1,1.34191874869959E-7,,,,,,,,,,,,,,,,,,,,,9.9999885559082,10.0002250671387,-2599.7138671875,-2599.7138671875,53.4274358035057,5.64576824209147,3.63771033287048,54,1,0,0,1,0.3021240234375,33.7243423461914,1,1,3,10.0002250671387,0,10.0001068115234,,,,,,,,,,,,,,,,,,,,,,,,,,,,,,,,,
,3879876910.91922,10.0000352859497,-2749.65258789062,-2.50443395244555E-5,9.22626833752238E-9,1,4,13.4005146026611,4.98300644021165,33.1300012767315,-0.0310007213674193,-0.00450110761827663,1,1.07857438315565E-7,,,,,,,,,,,,,,,,,,,,,9.9998950958252,10.0001754760742,-2749.65258789062,-2749.65258789062,53.2777539420729,5.64636824538536,3.63724565505981,54,2,0,0,1,0.301361083984375,33.7243423461914,1,1,3,9.9998950958252,0,10.0000352859497,,,,,,,,,,,,,,,,,,,,,,,,,,,,,,,,,
,3879876982.60841,10.0000791549683,-2899.57861328125,-2.47532398548771E-5,8.47598677932236E-9,1,4,13.4005146026611,4.9830385200798,33.1300012767315,-0.0306365332589458,-0.00447645119310865,1,8.42752599689345E-8,,,,,,,,,,,,,,,,,,,,,10.0000190734863,10.0001392364502,-2899.57861328125,-2899.57861328125,53.3903084488422,5.64558524272488,3.63423323631287,54,3,0,0,1,0.303115844726562,33.2355842590332,1,1,3,10.0000190734863,0,10.0000791549683,,,,,,,,,,,,,,,,,,,,,,,,,,,,,,,,,
,3879877086.69096,10.0001034736633,-3499.82446289063,-2.29191088381174E-5,8.43713271924258E-9,1,4,13.4005146026611,4.98306673229682,33.1199988722801,-0.0283520066359202,-0.00424298617735868,1,-1.34461391244935E-9,,,,,,,,,,,,,,,,,,,,,10.0000247955322,10.0001821517944,-3499.82446289063,-3499.82446289063,53.381319720871,5.64535552450407,3.63065886497498,54,1,0,0,1,0.30364990234375,33.2355842590332,1,1,3,10.0001821517944,0,10.0001034736633,,,,,,,,,,,,,,,,,,,,,,,,,,,,,,,,,
,3879877171.18508,10.0001816749573,-4999.71533203125,-1.64987911579512E-5,1.10710759317452E-8,1,4,13.4005146026611,4.98313572142981,33.1199988722801,-0.0204100329900194,-0.00305538068364364,1,-1.71212929060044E-9,,,,,,,,,,,,,,,,,,,,,10.0001420974731,10.0002212524414,-4999.71533203125,-4999.71533203125,53.3367668952749,5.64585594120189,3.63163375854492,54,2,0,0,1,0.302276611328125,33.2355842590332,1,1,3,10.0002212524414,0,10.0001816749573,,,,,,,,,,,,,,,,,,,,,,,,,,,,,,,,,
,3879877255.9853,10.0002150535584,-6499.76904296875,-8.89675427508795E-6,1.26110934753363E-8,1,4,13.4005146026611,4.98300582702685,33.1300012767315,-0.0110037014957489,-0.00165911460643224,1,-1.03015984295802E-8,,,,,,,,,,,,,,,,,,,,,9.99997997283935,10.0004501342773,-6499.76904296875,-6499.76904296875,53.4032053194095,5.64590683181665,3.63187980651855,54,3,0,0,1,0.303497314453125,33.7243423461914,1,1,3,10.0004501342773,0,10.0002150535584,,,,,,,,,,,,,,,,,,,,,,,,,,,,,,,,,
,3879877354.78863,9.99993658065796,-8499.5771484375,1.9195850185943E-6,1.2765575576476E-8,1,4,13.4005146026611,4.98305303934988,33.1199988722801,0.00238586461006146,2.80114826672529E-4,1,-6.07208402790454E-8,,,,,,,,,,,,,,,,,,,,,9.9998607635498,10.0000123977661,-8499.5771484375,-8499.5771484375,53.3477096945441,5.64654942396706,3.63948822021484,54,1,0,0,1,0.303192138671875,33.2355842590332,1,1,3,9.9998607635498,0,9.99993658065796,,,,,,,,,,,,,,,,,,,,,,,,,,,,,,,,,
,3879877439.23621,10.0001001358032,-9999.70703125,1.02213260978941E-5,1.86292483820958E-8,1,4,13.4005146026611,4.98301966218369,33.1199988722801,0.0126508267156536,0.0018471998406674,1,-3.58069641548325E-8,,,,,,,,,,,,,,,,,,,,,10.0000610351562,10.0001392364502,-9999.70703125,-9999.70703125,53.3668595932653,5.64695857150536,3.63138437271118,54,2,0,0,1,0.303955078125,33.7243423461914,1,1,3,10.0001392364502,0,10.0001001358032,,,,,,,,,,,,,,,,,,,,,,,,,,,,,,,,,
,3879877627.29003,10.0000629425049,-19999.515625,6.74364231850786E-5,3.14233071397208E-8,1,4,13.4005146026611,4.98309258919249,33.1199988722801,0.0834357268500717,0.0123968177340277,1,-6.69327319565712E-8,,,,,,,,,,,,,,,,,,,,,10.0000238418579,10.0001020431519,-19999.515625,-19999.515625,53.486057942448,5.64685809896731,3.63129878044128,54,3,0,0,1,0.302581787109375,33.2355842590332,1,1,3,10.0000238418579,0,10.0000629425049,,,,,,,,,,,,,,,,,,,,,,,,,,,,,,,,,
,3879877909.88682,10.0000557899475,-39999.53515625,1.83677199490278E-4,4.84234935638263E-8,1,4,13.4005146026611,4.98296177789888,33.1199988722801,0.227229685589137,0.0338749935876957,1,-9.26446495281098E-8,,,,,,,,,,,,,,,,,,,,,10.0000410079956,10.0000705718994,-39999.53515625,-39999.53515625,53.6877181004095,5.64719242430069,3.63815522193909,54,1,0,0,1,0.303497314453125,33.7243423461914,1,1,3,10.0000371932983,0,10.0000557899475,,,,,,,,,,,,,,,,,,,,,,,,,,,,,,,,,
,3879878150.52027,10.0000023841858,-54999.8828125,2.71061642336807E-4,6.95492216666236E-8,1,4,13.4005146026611,4.9830191672526,33.1300012767315,0.335391590188267,0.0496446024286372,10,-4.17414436991264E-7,,,,,,,,,,,,,,,,,,,,,9.99999237060547,10.0000123977661,-54999.8828125,-54999.8828125,53.6552805168614,5.64857238952687,3.63766765594482,54,2,0,0,1,0.302505493164063,33.2355842590332,1,1,3,9.99999237060547,0,10.0000023841858,,,,,,,,,,,,,,,,,,,,,,,,,,,,,,,,,
,3879878388.27691,10.0000767707825,-69999.875,3.58784352680417E-4,1.55738032058588E-7,1,4,13.4005146026611,4.98307961596511,33.1300012767315,0.443841183144276,0.0663774630799853,1,-1.45836159565171E-8,,,,,,,,,,,,,,,,,,,,,10.0000066757202,10.0001468658447,-69999.875,-69999.875,53.9034475717172,5.64919370487348,3.63590455055237,54,3,0,0,1,0.302810668945313,34.2131004333496,1,1,3,10.0000066757202,0,10.0000767707825,,,,,,,,,,,,,,,,,,,,,,,,,,,,,,,,,
,3879878669.70551,9.99993753433228,-49999.6796875,2.39884613917897E-4,6.98796488457045E-8,1,4,13.4005146026611,4.98313217587799,33.1199988722801,0.296767275427898,0.0443211140684853,1,-5.80683159139454E-8,,,,,,,,,,,,,,,,,,,,,9.99987506866455,10,-49999.6796875,-49999.6796875,53.6724763442845,5.64861948536886,3.62862849235535,54,1,0,0,1,0.303421020507812,34.2131004333496,1,1,3,9.99987506866455,0,9.99993753433228,,,,,,,,,,,,,,,,,,,,,,,,,,,,,,,,,
,3879878892.19042,9.99994421005249,-34999.5546875,1.51648587004322E-4,3.57561803968518E-8,1,4,13.4005146026611,4.98312269851046,33.1199988722801,0.187609717187396,0.0280055337927921,1,-4.72219924516474E-8,,,,,,,,,,,,,,,,,,,,,9.99992847442627,9.99995994567871,-34999.5546875,-34999.5546875,53.5868880214287,5.64746192523168,3.62834715843201,54,2,0,0,1,0.303573608398438,33.7243423461914,1,1,3,9.99992847442627,0,9.99994421005249,,,,,,,,,,,,,,,,,,,,,,,,,,,,,,,,,
,3879879113.40628,10.0000705718994,-19999.728515625,6.41265509202724E-5,2.65273558160928E-8,1,4,13.4005146026611,4.98312094516875,33.1199988722801,0.0793323214601069,0.0118479457775932,1,-1.55610158529642E-8,,,,,,,,,,,,,,,,,,,,,9.99997615814209,10.0001649856567,-19999.728515625,-19999.728515625,53.5141965691403,5.64670086722559,3.63097238540649,53,3,68,0,0,0.3033447265625,33.7243423461914,1,1,3,9.9999885559082,0,10.0000705718994,,,,,,,,,,,,,,,,,,,,,,,,,,,,,,,,,
,3879879316.19733,10.0001764297485,-9500.431640625,4.02952019700266E-6,1.73939656624714E-8,1,4,13.4005146026611,4.98299822921987,33.1300012767315,0.0049805840843617,7.72866454133813E-4,1,2.19825949345059E-8,,,,,,,,,,,,,,,,,,,,,10.0001745223999,10.0001783370972,-9500.431640625,-9500.431640625,53.3770207640153,5.64663928228528,3.63926720619202,54,1,0,0,1,0.302505493164063,34.7018585205078,1,1,3,10.0001745223999,0,10.0001764297485,,,,,,,,,,,,,,,,,,,,,,,,,,,,,,,,,
,3879879399.39172,10.0000433921814,-8000.2890625,-4.23224607687467E-6,1.72010713802188E-8,1,4,13.4005146026611,4.98302298075106,33.1300012767315,-0.00523887483588378,-7.60414705005342E-4,1,1.84140456755273E-8,,,,,,,,,,,,,,,,,,,,,10.0000028610229,10.0000839233398,-8000.2890625,-8000.2890625,53.3387209665729,5.64723302860087,3.63758945465088,54,2,0,0,1,0.302047729492188,33.7243423461914,1,1,3,10.0000839233398,0,10.0000433921814,,,,,,,,,,,,,,,,,,,,,,,,,,,,,,,,,
,3879879484.34349,10.0001468658447,-6500.2099609375,-1.22879567157496E-5,1.17723726614992E-8,1,4,13.4005146026611,4.98296580006459,33.1199988722801,-0.0152038181369094,-0.00225156276359252,1,1.80554370912791E-8,,,,,,,,,,,,,,,,,,,,,10.0001382827759,10.0001554489136,-6500.2099609375,-6500.2099609375,53.4196195183133,5.64693578838768,3.63250064849854,54,3,0,0,1,0.303497314453125,33.7243423461914,1,1,3,10.0001554489136,0,10.0001468658447,,,,,,,,,,,,,,,,,,,,,,,,,,,,,,,,,
,3879879583.57077,10.0000996589661,-4500.37646484375,-2.23685176251123E-5,1.13457434192486E-8,1,4,13.4005146026611,4.98295890607651,33.1300012767315,-0.027681558515277,-0.00406406150381333,1,6.0827889503695E-8,,,,,,,,,,,,,,,,,,,,,10.0000915527344,10.0001077651978,-4500.37646484375,-4500.37646484375,53.371158550121,5.64735994383108,3.63684964179993,53,1,68,0,0,0.301284790039063,34.2131004333496,1,1,3,10.0000915527344,0,10.0000996589661,,,,,,,,,,,,,,,,,,,,,,,,,,,,,,,,,
,3879879668.58687,10.0001654624939,-3000.2216796875,-2.84496264970375E-5,7.7041378079603E-9,1,4,13.4005146026611,4.98301456320922,33.1199988722801,-0.035202241636393,-0.00520497458778061,1,4.82825175119758E-8,,,,,,,,,,,,,,,,,,,,,10.0000553131104,10.0002756118774,-3000.2216796875,-3000.2216796875,53.3371577095345,5.64703427062094,3.63065481185913,52,2,68,0,0,0.30303955078125,34.2131004333496,1,1,3,10.0000553131104,0,10.0001654624939,,,,,,,,,,,,,,,,,,,,,,,,,,,,,,,,,
,3879879757.20652,9.999840259552,-2900.37182617188,-2.86229113021688E-5,1.07750673788645E-8,1,4,13.4005146026611,4.98302551523091,33.1300012767315,-0.0353892691139026,-0.00542050020227074,1,-1.00008599551171E-7,,,,,,,,,,,,,,,,,,,,,9.99978446960449,9.99989604949951,-2900.37182617188,-2900.37182617188,53.2523510151979,5.64730486961169,3.63375496864319,54,3,0,0,1,0.3021240234375,34.2131004333496,1,1,3,9.99989604949951,0,9.999840259552,,,,,,,,,,,,,,,,,,,,,,,,,,,,,,,,,
,3879879840.59163,9.99982690811157,-2700.36962890625,-2.90888213917326E-5,1.91226874012281E-8,1,4,13.4005146026611,4.98293705635227,33.1300012767315,-0.0359457269290601,-0.00563357313614072,1,-2.02668502040271E-7,,,,,,,,,,,,,,,,,,,,,9.99955654144287,10.0000972747803,-2700.36962890625,-2700.36962890625,53.4946558561595,5.64727080757813,3.63859295845032,54,1,0,0,1,0.303878784179687,33.7243423461914,1,1,3,10.0000972747803,0,9.99982690811157,,,,,,,,,,,,,,,,,,,,,,,,,,,,,,,,,
,3879879912.62541,10.0000696182251,-2550.45581054687,-2.94666396469103E-5,1.35547254222641E-8,1,4,13.4005146026611,4.98299614116684,33.1199988722801,-0.0364274185670844,-0.00561186855842385,1,-1.28527767713388E-7,,,,,,,,,,,,,,,,,,,,,9.99999713897705,10.0001420974731,-2550.45581054687,-2550.45581054687,53.3727218071595,5.64728799337533,3.63732504844666,53,2,68,0,0,0.302505493164063,34.2131004333496,1,1,3,9.99999713897705,0,10.0000696182251,,,,,,,,,,,,,,,,,,,,,,,,,,,,,,,,,
,3879879984.10037,9.99999475479126,-2400.42895507813,-2.97624160122885E-5,1.17557936642527E-8,1,4,13.4005146026611,4.98311455878295,33.1199988722801,-0.0368013333317387,-0.00562131699681243,1,-9.17679008847345E-8,,,,,,,,,,,,,,,,,,,,,9.99992561340332,10.0000638961792,-2400.42895507813,-2400.42895507813,53.3703769216018,5.64629251229574,3.63991189002991,54,3,0,0,1,0.30181884765625,33.7243423461914,1,1,3,9.99992561340332,0,9.99999475479126,,,,,,,,,,,,,,,,,,,,,,,,,,,,,,,,,
,3879880065.94733,9.99996662139893,-2200.38916015625,-2.99902088282115E-5,2.08408186190937E-8,1,4,13.4005146026611,4.9830336083772,33.1300012767315,-0.0370579162857717,-0.00582623962000916,1,-2.23449900235953E-7,,,,,,,,,,,,,,,,,,,,,9.9999475479126,9.99998569488525,-2200.38916015625,-2200.38916015625,53.404768576448,5.64668583574515,3.64299535751343,54,1,0,0,1,0.302200317382812,34.2131004333496,1,1,3,9.9999475479126,0,9.99996662139893,,,,,,,,,,,,,,,,,,,,,,,,,,,,,,,,,
,3879880138.0161,9.99989414215088,-2050.42529296875,-3.016353670966E-5,1.55117254302006E-8,1,4,13.4005146026611,4.98291213149044,33.1199988722801,-0.0372858001127316,-0.00575955220647554,1,-1.43771792839204E-7,,,,,,,,,,,,,,,,,,,,,9.99979114532471,9.99999713897705,-2050.42529296875,-2050.42529296875,53.3484913230633,5.64693551194058,3.63238334655762,53,2,68,0,0,0.302658081054687,33.7243423461914,1,1,3,9.99999713897705,0,9.99989414215088,,,,,,,,,,,,,,,,,,,,,,,,,,,,,,,,,
,3879880209.45311,9.99992799758911,-1900.44885253906,-3.02568573120751E-5,1.26436653775247E-8,1,4,13.4005146026611,4.98284755688437,33.1199988722801,-0.0374056668056658,-0.00574256408046664,1,-1.16162740703713E-7,,,,,,,,,,,,,,,,,,,,,9.99975204467773,10.0001039505005,-1900.44885253906,-1900.44885253906,53.3848370492076,5.64745005104661,3.63768410682678,54,3,0,0,1,0.302200317382812,33.7243423461914,1,1,3,10.0001039505005,0,9.99992799758911,,,,,,,,,,,,,,,,,,,,,,,,,,,,,,,,,
,3879880290.36918,9.99989557266235,-1700.16967773438,-3.01261872965205E-5,2.37136744352253E-8,1,4,13.4005146026611,4.98296668992331,33.1300012767315,-0.0372279314508747,-0.00583454710268566,1,-2.09912821063778E-7,,,,,,,,,,,,,,,,,,,,,9.99986267089844,9.99992847442627,-1700.16967773438,-1700.16967773438,53.294949769496,5.64687210536161,3.63527750968933,53,1,68,0,0,0.30303955078125,33.2355842590332,1,1,3,9.99992847442627,0,9.99989557266235,,,,,,,,,,,,,,,,,,,,,,,,,,,,,,,,,
,3879880361.05317,9.99992561340332,-1550.15551757813,-2.9995806115965E-5,1.54416445314072E-8,1,4,13.4005146026611,4.98304646390904,33.1300012767315,-0.0370768875516894,-0.00574766098928954,1,-1.59074571083011E-7,,,,,,,,,,,,,,,,,,,,,9.99979114532471,10.0000600814819,-1550.15551757813,-1550.15551757813,53.5329556536018,5.64628624626626,3.63425993919373,53,2,68,0,0,0.3033447265625,33.7243423461914,1,1,3,9.99979114532471,0,9.99992561340332,,,,,,,,,,,,,,,,,,,,,,,,,,,,,,,,,
,3879880431.201,10.0000691413879,-1400.12866210938,-2.97036171818593E-5,1.41513575814946E-8,1,4,13.4005146026611,4.98313530057729,33.1199988722801,-0.0367289110868533,-0.00560978837287778,1,-9.12180913138351E-8,,,,,,,,,,,,,,,,,,,,,9.99998283386231,10.0001554489136,-1400.12866210938,-1400.12866210938,53.3484913230633,5.64664288267831,3.63307523727417,54,3,0,0,1,0.302963256835937,33.7243423461914,1,1,3,9.99998283386231,0,10.0000691413879,,,,,,,,,,,,,,,,,,,,,,,,,,,,,,,,,
,3879880523.79225,9.99996614456177,-1200.15161132812,-2.89693307236205E-5,2.48775774980209E-8,1,4,13.4005146026611,4.9830361011148,33.1300012767315,-0.0357901685371104,-0.00567007915242273,1,-2.49927167122097E-7,,,,,,,,,,,,,,,,,,,,,9.99993896484375,9.99999332427978,-1200.15161132812,-1200.15161132812,53.2902599983806,5.64636276296353,3.63630652427673,54,1,0,0,1,0.30242919921875,33.7243423461914,1,1,3,9.99993896484375,0,9.99996614456177,,,,,,,,,,,,,,,,,,,,,,,,,,,,,,,,,
,3879880595.2682,9.99999284744263,-1050.17517089844,-2.82634428304236E-5,1.75311400292401E-8,1,4,13.4005146026611,4.98306123426174,33.1199988722801,-0.034935318929283,-0.00541836493706899,1,-1.52012708406352E-7,,,,,,,,,,,,,,,,,,,,,9.99986934661865,10.0001163482666,-1050.17517089844,-1050.17517089844,53.3469280660249,5.64644369221899,3.63540625572205,54,2,0,0,1,0.302963256835937,33.7243423461914,1,1,3,9.99986934661865,0,9.99999284744263,,,,,,,,,,,,,,,,,,,,,,,,,,,,,,,,,
,3879880666.62833,10.000063419342,-900.160949707031,-2.7290703510918E-5,1.5268281975002E-8,1,4,13.4005146026611,4.98300361725197,33.1300012767315,-0.0337365305619644,-0.0052042330718444,1,-1.24498763872072E-7,,,,,,,,,,,,,,,,,,,,,10.0000095367432,10.0001173019409,-900.160949707031,-900.160949707031,53.2726733566979,5.64576127547289,3.63826942443848,53,3,68,0,0,0.302886962890625,33.2355842590332,1,1,3,10.0001173019409,0,10.000063419342,,,,,,,,,,,,,,,,,,,,,,,,,,,,,,,,,
,3879880748.53446,9.99992895126343,-700.158752441406,-2.54643964436223E-5,2.30618912411186E-8,1,4,13.4005146026611,4.98304325719155,33.1199988722801,-0.0314532360279304,-0.00502969438648589,1,-2.56563347086502E-7,,,,,,,,,,,,,,,,,,,,,9.99986839294434,9.99998950958252,-700.158752441406,-700.158752441406,53.3168353680345,5.64669346085667,3.63404870033264,52,1,68,0,0,0.30181884765625,33.7243423461914,1,1,3,9.99998950958252,0,9.99992895126343,,,,,,,,,,,,,,,,,,,,,,,,,,,,,,,,,
,3879880818.89192,10.0000286102295,-550.232604980469,-2.37195726599931E-5,1.91978709985376E-8,1,4,13.4005146026611,4.98296226807767,33.1199988722801,-0.0293128570837524,-0.00458154488767494,1,-1.55389764751891E-7,,,,,,,,,,,,,,,,,,,,,9.99999237060547,10.0000648498535,-550.232604980469,-550.232604980469,53.4684713007653,5.64669221769558,3.63757538795471,54,2,0,0,1,0.30426025390625,33.7243423461914,1,1,3,10.0000648498535,0,10.0000286102295,,,,,,,,,,,,,,,,,,,,,,,,,,,,,,,,,
,3879880889.97874,10.0000381469727,-400.230987548828,-2.14856257461833E-5,1.51412409343927E-8,1,4,13.4005146026611,4.98306803350224,33.1199988722801,-0.0265549523128242,-0.00413656320076043,1,-1.29754504330257E-7,,,,,,,,,,,,,,,,,,,,,10.0000028610229,10.0000734329224,-400.230987548828,-400.230987548828,53.2793171991114,5.64650999602225,3.63611364364624,52,3,68,0,0,0.302886962890625,32.7468223571777,1,1,3,10.0000734329224,0,10.0000381469727,,,,,,,,,,,,,,,,,,,,,,,,,,,,,,,,,
,3879880971.73655,10.0001473426819,-200.178436279297,-1.73133494272713E-5,2.34439478253446E-8,1,4,13.4005146026611,4.98300933479505,33.1199988722801,-0.0213687717748058,-0.00352804028967692,1,-2.62037087538001E-7,,,,,,,,,,,,,,,,,,,,,10.0001201629639,10.0001745223999,-200.178436279297,-200.178436279297,53.2812712704095,5.64609188957412,3.6367666721344,52,1,68,0,0,0.301589965820313,33.7243423461914,1,1,3,10.0001201629639,0,10.0001473426819,,,,,,,,,,,,,,,,,,,,,,,,,,,,,,,,,
,3879881043.07617,10.0001893043518,-50.2774887084961,-1.31759374004126E-5,2.01510527810182E-8,1,4,13.4005146026611,4.9829628026179,33.1199988722801,-0.0162664188226904,-0.0026554476951495,1,-1.75607619224317E-7,,,,,,,,,,,,,,,,,,,,,10.000114440918,10.0002641677856,-50.2774887084961,-50.2774887084961,53.4692529292845,5.64619712640761,3.64389181137085,53,2,68,0,0,0.30303955078125,33.7243423461914,1,1,3,10.000114440918,0,10.0001893043518,,,,,,,,,,,,,,,,,,,,,,,,,,,,,,,,,
,3879881114.87906,10.0000200271606,99.7745132446289,-7.78167788422509E-6,1.6446166634958E-8,1,4,13.4005146026611,4.98291292826686,33.1199988722801,-0.0096021235373946,-0.00159936692676824,1,-1.288449314917E-7,,,,,,,,,,,,,,,,,,,,,10.0000028610229,10.0000371932983,99.7745132446289,99.7745132446289,53.391480891621,5.64630375420119,3.63869094848633,54,3,0,0,1,0.30181884765625,33.7243423461914,1,1,3,10.0000028610229,0,10.0000200271606,,,,,,,,,,,,,,,,,,,,,,,,,,,,,,,,,
,3879881197.01957,10.0001721382141,299.650817871094,8.93296909011914E-8,3.06779964340776E-8,1,4,13.4005146026611,4.98310994456809,33.1199988722801,1.45825751862381E-4,-2.19564356130699E-4,1,-1.90850220163722E-7,,,,,,,,,,,,,,,,,,,,,10.0001230239868,10.0002212524414,299.650817871094,299.650817871094,53.411803233121,5.64547720157217,3.64717054367065,54,1,0,0,1,0.302734375,33.7243423461914,1,1,3,10.0002212524414,0,10.0001721382141,,,,,,,,,,,,,,,,,,,,,,,,,,,,,,,,,
,3879881282.3593,9.99999332427978,449.778350830078,5.4058316712695E-6,1.17941894353066E-8,1,4,13.4005146026611,4.98295148812596,33.1300012767315,0.00671441728108642,8.17791176134951E-4,1,-1.47579932136577E-7,,,,,,,,,,,,,,,,,,,,,9.99986362457275,10.0001230239868,449.778350830078,449.778350830078,53.3641238934479,5.64694310705615,3.64461803436279,53,2,68,0,0,0.30364990234375,33.2355842590332,1,1,3,9.99986362457275,0,9.99999332427978,,,,,,,,,,,,,,,,,,,,,,,,,,,,,,,,,
,3879881354.24259,10.0000886917114,599.767456054687,9.95993189331648E-6,7.48117774285283E-9,1,4,13.4005146026611,4.98295993201861,33.1199988722801,0.0123414735762391,0.00170380984270842,1,-1.12594522997115E-7,,,,,,,,,,,,,,,,,,,,,10.0000839233398,10.000093460083,599.767456054687,599.767456054687,53.3754575069768,5.64619763487314,3.64257454872131,54,3,0,0,1,0.303115844726562,33.7243423461914,1,1,3,10.0000772476196,0,10.0000886917114,,,,,,,,,,,,,,,,,,,,,,,,,,,,,,,,,
,3879881436.4577,10.0000739097595,799.60595703125,1.48224653113666E-5,2.36447630809823E-8,1,4,13.4005146026611,4.98307264590227,33.1300012767315,0.0183805074400825,0.00244729252426895,1,-2.39035301931237E-7,,,,,,,,,,,,,,,,,,,,,9.99999904632568,10.0001487731934,799.60595703125,799.60595703125,53.2480520583422,5.64671204547188,3.64819431304932,54,1,0,0,1,0.302810668945313,33.2355842590332,1,1,3,9.99999904632568,0,10.0000739097595,,,,,,,,,,,,,,,,,,,,,,,,,,,,,,,,,
,3879881508.02261,10.0001401901245,949.783813476563,1.76507620172078E-5,2.59514665185509E-8,1,4,13.4005146026611,4.98312925339571,33.1199988722801,0.0218653235204043,0.00306635452876085,1,-1.61740349065224E-7,,,,,,,,,,,,,,,,,,,,,10.0001049041748,10.0001754760742,949.783813476563,949.783813476563,53.3578708652941,5.64616252136082,3.64430069923401,52,2,68,0,0,0.302810668945313,33.2355842590332,1,1,3,10.0001049041748,0,10.0001401901245,,,,,,,,,,,,,,,,,,,,,,,,,,,,,,,,,
,3879881579.68892,9.99999332427978,1099.68469238281,1.98942728583196E-5,2.0852725868875E-8,1,4,13.4005146026611,4.98311898686721,33.1199988722801,0.024634439555309,0.00352306314503889,1,-1.28164539881317E-7,,,,,,,,,,,,,,,,,,,,,9.99996852874756,10.000018119812,1099.68469238281,1099.68469238281,53.406722647746,5.64619450761376,3.63722133636475,54,3,0,0,1,0.303573608398438,33.2355842590332,1,1,3,9.99996852874756,0,9.99999332427978,,,,,,,,,,,,,,,,,,,,,,,,,,,,,,,,,
,3879881662.25924,10.0000834465027,1299.67443847656,2.21505311764294E-5,1.33121435153594E-8,1,4,13.4005146026611,4.98308935588109,33.1199988722801,0.0274332574220556,0.00388786586291718,1,-1.70769482683747E-7,,,,,,,,,,,,,,,,,,,,,10.0000267028809,10.0001401901245,1299.67443847656,1299.67443847656,53.4043777621883,5.64592482813307,3.64692950248718,53,1,68,0,0,0.301971435546875,33.2355842590332,1,1,3,10.0001401901245,0,10.0000834465027,,,,,,,,,,,,,,,,,,,,,,,,,,,,,,,,,
,3879881734.42695,10.0000333786011,1449.68859863281,2.34079597164668E-5,1.50626834321267E-8,1,4,13.4005146026611,4.98301711976052,33.1199988722801,0.0289786809557538,0.00418403796133366,1,-1.19389174976693E-7,,,,,,,,,,,,,,,,,,,,,9.99999618530273,10.0000705718994,1449.68859863281,1449.68859863281,53.3957798484768,5.64599419929713,3.64642858505249,54,2,0,0,1,0.303878784179687,33.7243423461914,1,1,3,10.0000705718994,0,10.0000333786011,,,,,,,,,,,,,,,,,,,,,,,,,,,,,,,,,
,3879881806.20465,10.0000534057617,1599.52661132813,2.43537571673623E-5,7.33688266477617E-9,1,4,13.4005146026611,4.98300979853838,33.1199988722801,0.0301452741356986,0.00438134019277188,1,-1.01371941128638E-7,,,,,,,,,,,,,,,,,,,,,9.99991321563721,10.0001935958862,1599.52661132813,1599.52661132813,53.4071134620056,5.64620155264442,3.64512062072754,54,3,0,0,1,0.303573608398438,33.2355842590332,1,1,3,9.99991989135742,0,10.0000534057617,,,,,,,,,,,,,,,,,,,,,,,,,,,,,,,,,
,3879881889.76711,10.0000796318054,1799.59167480469,2.53079640268333E-5,9.94032920701095E-8,1,4,13.4005146026611,4.98307145135604,33.1199988722801,0.0313422711816014,0.00445061856795126,1,-1.88174424758936E-7,,,,,,,,,,,,,,,,,,,,,9.99999713897705,10.0001621246338,1799.59167480469,1799.59167480469,53.3688136645633,5.64707461685329,3.63895678520203,52,1,68,0,0,0.301895141601562,33.2355842590332,1,1,3,10.0001621246338,0,10.0000796318054,,,,,,,,,,,,,,,,,,,,,,,,,,,,,,,,,
,3879881961.27624,10.0000801086426,1949.92065429687,2.56112228021687E-5,7.01358346706583E-9,1,4,13.4005146026611,4.98318056108577,33.1300012767315,0.0317045862393282,0.00459918358221206,1,-1.13558975555805E-7,,,,,,,,,,,,,,,,,,,,,9.99997329711914,10.000186920166,1949.92065429687,1949.92065429687,53.3516178371403,5.64650121426147,3.64436602592468,54,2,0,0,1,0.30364990234375,33.2355842590332,1,1,3,10.000186920166,0,10.0000801086426,,,,,,,,,,,,,,,,,,,,,,,,,,,,,,,,,
,3879882033.15089,10.0000839233398,2099.78369140625,2.58327778023854E-5,6.89595900924159E-9,1,4,13.4005146026611,4.98302741552316,33.1199988722801,0.0319719447071795,0.00467573205108163,1,-8.46617497447534E-8,,,,,,,,,,,,,,,,,,,,,9.99999237060547,10.0001754760742,2099.78369140625,2099.78369140625,53.3058925687653,5.64629998030596,3.64001989364624,54,3,0,0,1,0.301589965820313,33.7243423461914,1,1,3,9.99999237060547,0,10.0000839233398,,,,,,,,,,,,,,,,,,,,,,,,,,,,,,,,,
,3879882115.8717,10.000072479248,2299.8740234375,2.59276141537623E-5,8.59764494833304E-9,1,4,13.4005146026611,4.98298985047782,33.1300012767315,0.0320970991119438,0.00463857001628052,1,-1.2885001911902E-7,,,,,,,,,,,,,,,,,,,,,10.0000247955322,10.0001201629639,2299.8740234375,2299.8740234375,53.3723309928999,5.64650073896754,3.63713932037354,53,1,68,0,0,0.302658081054687,32.7468223571777,1,1,3,10.0001201629639,0,10.000072479248,,,,,,,,,,,,,,,,,,,,,,,,,,,,,,,,,
,3879882187.61456,10.0000596046448,2449.87573242187,2.58942844771015E-5,2.72362652313323E-8,1,4,13.4005146026611,4.98300397183312,33.1199988722801,0.0320529640674288,0.00465269350209836,1,-1.12461814051005E-7,,,,,,,,,,,,,,,,,,,,,10.000020980835,10.0000982284546,2449.87573242187,2449.87573242187,53.300030354871,5.64613689689986,3.64567494392395,54,2,0,0,1,0.30242919921875,33.7243423461914,1,1,3,10.0000982284546,0,10.0000596046448,,,,,,,,,,,,,,,,,,,,,,,,,,,,,,,,,
,3879882259.06776,10.0000100135803,2599.76416015625,2.56962871042762E-5,7.83305586693344E-9,1,4,13.4005146026611,4.98308551852544,33.1199988722801,0.0318029768665376,0.00465484977798964,1,-8.11859355032436E-8,,,,,,,,,,,,,,,,,,,,,9.99992179870605,10.0000982284546,2599.76416015625,2599.76416015625,53.3344220097172,5.6462587226745,3.64182496070862,54,3,0,0,1,0.304641723632812,33.2355842590332,1,1,3,10.0000982284546,0,10.0000100135803,,,,,,,,,,,,,,,,,,,,,,,,,,,,,,,,,
,3879882340.92947,10.0001730918884,2799.84204101562,2.53505809949142E-5,8.37749278578973E-9,1,4,13.4005146026611,4.98303089944373,33.1199988722801,0.0313814767265261,0.00454639670269311,1,-1.1708363784003E-7,,,,,,,,,,,,,,,,,,,,,10.0001125335693,10.0002336502075,2799.84204101562,2799.84204101562,53.3770207640153,5.64642652587761,3.64611959457397,54,1,0,0,1,0.302276611328125,33.7243423461914,1,1,3,10.0002336502075,0,10.0001730918884,,,,,,,,,,,,,,,,,,,,,,,,,,,,,,,,,
,3879882412.8616,10.0001354217529,2949.76806640625,2.50058768579569E-5,1.01503860607568E-8,1,4,13.4005146026611,4.98305835075116,33.1199988722801,0.0309498083110394,0.00451936294215851,1,-8.73997608131646E-8,,,,,,,,,,,,,,,,,,,,,10.0000953674316,10.0001754760742,2949.76806640625,2949.76806640625,53.3359852667556,5.64694419926749,3.64630460739136,54,2,0,0,1,0.302352905273438,33.2355842590332,1,1,3,10.0000953674316,0,10.0001354217529,,,,,,,,,,,,,,,,,,,,,,,,,,,,,,,,,
,3879882505.75136,10.000114440918,3499.64819335937,2.32782210225051E-5,8.9978618977107E-9,1,4,13.4005146026611,4.9830017195992,33.1199988722801,0.0287947138004301,0.00431610193884595,1,6.7920965176052E-9,,,,,,,,,,,,,,,,,,,,,10.0000410079956,10.0001878738403,3499.64819335937,3499.64819335937,53.2906508126403,5.64682229374002,3.64405488967895,54,3,0,0,1,0.302352905273438,33.7243423461914,1,1,3,10.0001878738403,0,10.000114440918,,,,,,,,,,,,,,,,,,,,,,,,,,,,,,,,,
,3879882605.77519,10.0000123977661,5499.65771484375,1.43002309063427E-5,1.04350056909339E-8,1,4,13.4005146026611,4.98301857356064,33.1199988722801,0.0176820670398807,0.00269912621868498,1,4.26954019474166E-8,,,,,,,,,,,,,,,,,,,,,9.99991607666016,10.0001087188721,5499.65771484375,5499.65771484375,53.4235276609095,5.64644191551914,3.64105081558228,54,1,0,0,1,0.303573608398438,33.7243423461914,1,1,3,10.0001087188721,0,10.0000123977661,,,,,,,,,,,,,,,,,,,,,,,,,,,,,,,,,
,3879882688.65823,10.0002074241638,6999.8125,6.47793520554967E-6,1.17135531950146E-8,1,4,13.4005146026611,4.9831279730082,33.1199988722801,0.00800914129489028,0.00122938696189675,1,2.47230179020016E-8,,,,,,,,,,,,,,,,,,,,,10.0001153945923,10.0002994537354,6999.8125,6999.8125,53.3426291091691,5.64645941745976,3.64085292816162,54,2,0,0,1,0.30242919921875,33.2355842590332,1,1,3,10.0001153945923,0,10.0002074241638,,,,,,,,,,,,,,,,,,,,,,,,,,,,,,,,,
,3879882771.54104,9.99997806549072,8499.9931640625,-1.66289907253961E-6,1.44881171183123E-8,1,4,13.4005146026611,4.98302886745105,33.1199988722801,-0.00206293778712789,-2.68567422967067E-4,1,3.16553348844927E-8,,,,,,,,,,,,,,,,,,,,,9.99993801116943,10.000018119812,8499.9931640625,8499.9931640625,53.2812712704095,5.64619020600284,3.64064240455627,54,3,0,0,1,0.30364990234375,33.7243423461914,1,1,3,10.000018119812,0,9.99997806549072,,,,,,,,,,,,,,,,,,,,,,,,,,,,,,,,,
,3879882875.78813,10.0000009536743,10000.046875,-9.96941803855764E-6,1.46597400418268E-8,1,4,13.4005146026611,4.98303403982426,33.1199988722801,-0.0123390087317973,-0.00180224387412759,1,3.44704986112824E-8,,,,,,,,,,,,,,,,,,,,,9.99997329711914,10.0000286102295,10000.046875,10000.046875,53.3387209665729,5.64612303321202,3.64191746711731,54,1,0,0,1,0.301666259765625,33.2355842590332,1,1,3,10.0000286102295,0,10.0000009536743,,,,,,,,,,,,,,,,,,,,,,,,,,,,,,,,,
,3879883109.77796,10.000036239624,25000.400390625,-9.61039134206125E-5,2.88745189663253E-8,1,4,13.4005146026611,4.9831361596721,33.1199988722801,-0.118908620419135,-0.0176497427514733,1,1.09312418523903E-7,,,,,,,,,,,,,,,,,,,,,10.0000133514404,10.0000591278076,25000.400390625,25000.400390625,53.6267510759095,5.64607409618926,3.6425940990448,54,2,0,0,1,0.303268432617188,33.2355842590332,1,1,3,10.0000276565552,0,10.000036239624,,,,,,,,,,,,,,,,,,,,,,,,,,,,,,,,,
,3879883328.67511,10.0001091957092,40000.23828125,-1.83256270974729E-4,9.06975756329169E-8,1,4,13.4005146026611,4.98302597669427,33.1300012767315,-0.226727228306709,-0.0337031789767358,1,1.69062749979379E-7,,,,,,,,,,,,,,,,,,,,,9.99997520446777,10.0002431869507,40000.23828125,40000.23828125,53.4258725464672,5.64824991444003,3.64322447776794,54,3,0,0,1,0.303421020507812,33.2355842590332,1,1,3,10.0002136230469,0,10.0001091957092,,,,,,,,,,,,,,,,,,,,,,,,,,,,,,,,,
,3879883611.65263,9.99999141693115,60000.5234375,-2.9996452019098E-4,6.99346956194862E-8,1,4,13.4005146026611,4.98317188773298,33.1300012767315,-0.371108484386758,-0.0553505814630192,1,1.30427895934689E-7,,,,,,,,,,,,,,,,,,,,,9.99982643127441,10.0001564025879,60000.5234375,60000.5234375,53.8588947461211,5.64794419184443,3.64922666549683,54,1,0,0,1,0.302352905273438,33.7243423461914,1,1,3,9.99982643127441,0,9.99999141693115,,,,,,,,,,,,,,,,,,,,,,,,,,,,,,,,,
,3879883781.62245,9.99989080429077,70000.4140625,-3.58833243448203E-4,7.9165333439158E-8,1,4,13.4005146026611,4.98298086641875,33.1199988722801,-0.443984275015088,-0.0657499141456406,10,5.27709166961038E-7,,,,,,,,,,,,,,,,,,,,,9.99984264373779,9.99993896484375,70000.4140625,70000.4140625,53.9683227388134,5.64935595171823,3.64118409156799,54,3,0,0,1,0.303573608398438,33.7243423461914,1,1,3,9.99990749359131,0,9.99989080429077,,,,,,,,,,,,,,,,,,,,,,,,,,,,,,,,,