File: SQUID/22169_LCOT/22169_LCOT_MH_100K_FC_0d5T.csv
Comment,Time Stamp (sec),Temperature (K),Magnetic Field (Oe),Moment (emu),M. Std. Err. (emu),Transport Action,Averaging Time (sec),Frequency (Hz),Peak Amplitude (mm),Center Position (mm),Lockin Signal' (V),Lockin Signal (V),Range,M. Quad. Signal (emu),AC Moment (emu),AC M. Std Err. (emu),AC Phase (deg),AC Phase Std. Err. (deg),AC Susceptibility (emu/Oe),AC Suscept. Std Err. (emu/Oe),AC X' (emu/Oe),AC X' Std Err. (emu/Oe),AC X'' (emu/Oe),AC X'' Std Err. (emu/Oe),AC Drive (Oe),AC Frequency (Hz),AC Averaging Time (sec),AC Cycles,AC Range,AC Measure Type,AC Signal' (V),AC Signal'' (V),AC Trim Coil Ratio,AC Trim Coil Phase,Min. Temperature (K),Max. Temperature (K),Min. Field (Oe),Max. Field (Oe),Mass (grams),Motor Lag (deg),Pressure (Torr),Measure Count,Measurement Number,SQUID Status (code),Motor Status (code),Measure Status (code),Motor Current (amps),Motor Temp. (C),Temp. Status (code),Field Status (code),Chamber Status (code),Chamber Temp (K),Redirection State,Average Temp (K),Rotation Angle (deg),Rotator state,DC Moment Fixed Ctr (emu),DC Moment Err Fixed Ctr (emu),DC Moment Free Ctr (emu),DC Moment Err Free Ctr (emu),DC Fixed Fit,DC Free Fit,DC Calculated Center (mm),DC Calculated Center Err (mm),DC Scan Length (mm),DC Scan Time (s),DC Number of Points,DC Squid Drift,DC Min V (V),DC Max V (V),DC Scans per Measure,Sample Resistance,He3 Temperature,Sorb Resistance,Sorb Temperature,Map 05,Map 06,Map 07,Map 08,Map 09,Map 10,Map 11,Map 12,Map 13,Map 14,Map 15,Map 16
,3879895600.12739,100.036994934082,69999.484375,-3.73808521667897E-4,1.17379926848754E-7,1,4,13.4005146026611,4.99342153424601,33.1499986350536,-0.463796655861016,-0.0692022237445875,1,1.41040593889781E-7,,,,,,,,,,,,,,,,,,,,,100.036674499512,100.037315368652,69999.484375,69999.484375,53.1429230225056,5.64965160495161,4.89953994750977,54,1,0,0,1,0.302886962890625,33.2355842590332,1,1,3,100.036674499512,0,100.036994934082,,,,,,,,,,,,,,,,,,,,,,,,,,,,,,,,,
,3879895830.6771,100.072113037109,54999.68359375,-2.82813038808324E-4,7.35387036375069E-8,1,4,13.4005146026611,4.99334580593119,33.1499986350536,-0.350889664296276,-0.0523447637515331,1,1.15238945718722E-7,,,,,,,,,,,,,,,,,,,,,100.065101623535,100.079124450684,54999.68359375,54999.68359375,53.1507393076979,5.64964925159724,4.90844106674194,54,2,0,0,1,0.302276611328125,33.7243423461914,1,1,3,100.079124450684,0,100.072113037109,,,,,,,,,,,,,,,,,,,,,,,,,,,,,,,,,
,3879896052.08338,100.009494781494,39999.609375,-1.9193430147829E-4,4.42526401298706E-8,1,4,13.4005146026611,4.99331586364672,33.1499986350536,-0.238140586163952,-0.0354752403533731,1,1.17570164092877E-7,,,,,,,,,,,,,,,,,,,,,100.009239196777,100.009750366211,39999.609375,39999.609375,53.2859610415249,5.64851041182104,4.918297290802,54,3,0,0,1,0.305023193359375,33.7243423461914,1,1,3,100.009239196777,0,100.009494781494,,,,,,,,,,,,,,,,,,,,,,,,,,,,,,,,,
,3879896334.57262,100.026794433594,19999.578125,-7.10200701989924E-5,2.08776088090922E-8,1,4,13.4005146026611,4.99311787225049,33.1499986350536,-0.0881019012502147,-0.0131971344979141,1,-1.39023680496009E-8,,,,,,,,,,,,,,,,,,,,,100.018966674805,100.034622192383,19999.578125,19999.578125,53.3594341223326,5.65033343321089,4.92231369018555,54,1,0,0,1,0.303497314453125,34.7018585205078,1,1,3,100.034934997559,0,100.026794433594,,,,,,,,,,,,,,,,,,,,,,,,,,,,,,,,,
,3879896523.97309,100.001613616943,9999.794921875,-1.13403003910587E-5,1.22154429893938E-8,1,4,13.4005146026611,4.9932222909467,33.1499986350536,-0.01407071065521,-0.00209119773549037,1,1.07965921934019E-8,,,,,,,,,,,,,,,,,,,,,100.001304626465,100.001922607422,9999.794921875,9999.794921875,53.3930441486595,5.64943963121617,4.92650318145752,54,2,0,0,1,0.30303955078125,34.2131004333496,1,1,3,100.001922607422,0,100.001613616943,,,,,,,,,,,,,,,,,,,,,,,,,,,,,,,,,
,3879896611.7593,100.146957397461,8499.791015625,-2.60820505065073E-6,1.03740972994095E-8,1,4,13.4005146026611,4.99314599080582,33.160001039505,-0.00323462776167312,-4.90893285707855E-4,1,-5.52923741879892E-9,,,,,,,,,,,,,,,,,,,,,100.144920349121,100.148994445801,8499.791015625,8499.791015625,53.4696437435441,5.64981559225701,4.93610572814941,54,3,0,0,1,0.302581787109375,34.2131004333496,1,1,3,100.144920349121,0,100.146957397461,,,,,,,,,,,,,,,,,,,,,,,,,,,,,,,,,
,3879896714.6641,100.075843811035,6499.65576171875,8.77700620715591E-6,1.05587942760687E-8,1,4,13.4005146026611,4.99294563622851,33.160001039505,0.0109004408602512,0.00154462064550127,1,-6.78238901089297E-8,,,,,,,,,,,,,,,,,,,,,100.073684692383,100.078002929688,6499.65576171875,6499.65576171875,53.3520086513999,5.65091972440003,4.93917751312256,54,1,0,0,1,0.29632568359375,34.2131004333496,1,1,3,100.073684692383,0,100.075843811035,,,,,,,,,,,,,,,,,,,,,,,,,,,,,,,,,
,3879896801.12383,100.033317565918,4999.6142578125,1.68563451466284E-5,6.86011903333584E-9,1,4,13.4005146026611,4.99297931915987,33.160001039505,0.020919072770503,0.00307045077406847,1,-4.64520125035452E-8,,,,,,,,,,,,,,,,,,,,,100.031509399414,100.035125732422,4999.6142578125,4999.6142578125,53.2726733566979,5.64910201155486,4.94272041320801,52,2,68,0,0,0.30242919921875,34.2131004333496,1,1,3,100.035125732422,0,100.033317565918,,,,,,,,,,,,,,,,,,,,,,,,,,,,,,,,,
,3879896888.47062,100.092170715332,3499.91259765625,2.39293772627276E-5,7.76495735560729E-9,1,4,13.4005146026611,4.99291548321364,33.160001039505,0.0296919485737514,0.00438797502660649,1,-4.23873438799486E-8,,,,,,,,,,,,,,,,,,,,,100.089553833008,100.094787597656,3499.91259765625,3499.91259765625,53.4950466704191,5.64931193725868,4.93399000167847,53,3,64,0,0,0.303802490234375,34.2131004333496,1,1,3,100.094787597656,0,100.092170715332,,,,,,,,,,,,,,,,,,,,,,,,,,,,,,,,,
,3879896994.92588,100.066192626953,2899.59130859375,2.60114024817113E-5,1.35670922265875E-8,1,4,13.4005146026611,4.99270947930683,33.160001039505,0.0322307812088331,0.0050549994918692,1,1.84101833285488E-7,,,,,,,,,,,,,,,,,,,,,100.063018798828,100.069366455078,2899.59130859375,2899.59130859375,53.3543535369576,5.65014997693876,4.9439525604248,52,1,68,0,0,0.302886962890625,34.2131004333496,1,1,3,100.062843322754,0,100.066192626953,,,,,,,,,,,,,,,,,,,,,,,,,,,,,,,,,
,3879897069.45686,100.078090667725,2749.74072265625,2.65247411124641E-5,1.257651404068E-8,1,4,13.4005146026611,4.99299723753487,33.1499986350536,0.0328830603324522,0.00506462437636838,1,1.14739251671091E-7,,,,,,,,,,,,,,,,,,,,,100.077919006348,100.078262329102,2749.74072265625,2749.74072265625,53.4000788053326,5.64979098202486,4.94082689285278,54,2,0,0,1,0.302352905273438,33.7243423461914,1,1,3,100.077919006348,0,100.078090667725,,,,,,,,,,,,,,,,,,,,,,,,,,,,,,,,,
,3879897143.37361,100.061290740967,2599.7138671875,2.69477326451389E-5,9.22534385394694E-9,1,4,13.4005146026611,4.9930336354298,33.1499986350536,0.0334135438268684,0.0051069767002271,1,8.55611836167798E-8,,,,,,,,,,,,,,,,,,,,,100.060111999512,100.062469482422,2599.7138671875,2599.7138671875,53.3770207640153,5.64956649428094,4.93768692016602,54,3,0,0,1,0.303802490234375,33.7243423461914,1,1,3,100.060111999512,0,100.061290740967,,,,,,,,,,,,,,,,,,,,,,,,,,,,,,,,,
,3879897226.95299,100.02738571167,2399.58569335938,2.73883341448868E-5,1.6336043119801E-8,1,4,13.4005146026611,4.99290090824953,33.160001039505,0.0339431173369325,0.0052937683770989,1,1.7038315960447E-7,,,,,,,,,,,,,,,,,,,,,100.027145385742,100.027626037598,2399.58569335938,2399.58569335938,53.1921656192172,5.64978899223812,4.94383239746094,54,1,0,0,1,0.303421020507812,32.7468223571777,1,1,3,100.027145385742,0,100.02738571167,,,,,,,,,,,,,,,,,,,,,,,,,,,,,,,,,
,3879897298.9294,100.087230682373,2249.53369140625,2.76445953388578E-5,1.37897180508635E-8,1,4,13.4005146026611,4.99288819405715,33.1499986350536,0.0342723442013214,0.00526468448846404,1,1.08617569322288E-7,,,,,,,,,,,,,,,,,,,,,100.085525512695,100.088935852051,2249.53369140625,2249.53369140625,53.152693378996,5.6500927923179,4.94533252716064,53,2,68,0,0,0.302658081054687,33.7243423461914,1,1,3,100.088935852051,0,100.087230682373,,,,,,,,,,,,,,,,,,,,,,,,,,,,,,,,,
,3879897369.35724,100.04415512085,2099.58227539062,2.78669540419214E-5,1.14641104764769E-8,1,4,13.4005146026611,4.99286637092272,33.1499986350536,0.0345514940471121,0.00528231448902886,1,8.95924229201121E-8,,,,,,,,,,,,,,,,,,,,,100.043830871582,100.044479370117,2099.58227539062,2099.58227539062,53.3148812967364,5.64984022922369,4.94317674636841,54,3,0,0,1,0.304031372070313,34.2131004333496,1,1,3,100.043830871582,0,100.04415512085,,,,,,,,,,,,,,,,,,,,,,,,,,,,,,,,,
,3879897452.84571,100.048400878906,1899.76904296875,2.7990839383855E-5,1.8690970277457E-8,1,4,13.4005146026611,4.99285680621619,33.1499986350536,0.0346867242686338,0.00542797259908656,1,1.88493398027028E-7,,,,,,,,,,,,,,,,,,,,,100.04663848877,100.050163269043,1899.76904296875,1899.76904296875,53.2777539420729,5.64956446905406,4.9510326385498,54,1,0,0,1,0.302200317382812,34.2131004333496,1,1,3,100.04663848877,0,100.048400878906,,,,,,,,,,,,,,,,,,,,,,,,,,,,,,,,,
,3879897525.51002,100.051261901855,1749.50305175781,2.77785233611294E-5,2.13320005719634E-7,1,4,13.4005146026611,4.99282491396627,33.1499986350536,0.0344255224321069,0.00537196635347275,1,1.75143987856806E-7,,,,,,,,,,,,,,,,,,,,,100.049934387207,100.052589416504,1749.50305175781,1749.50305175781,53.3367668952749,5.65003369756516,4.94534397125244,52,2,68,0,0,0.304031372070313,34.2131004333496,1,1,3,100.052589416504,0,100.051261901855,,,,,,,,,,,,,,,,,,,,,,,,,,,,,,,,,
,3879897597.98289,100.087032318115,1599.53918457031,2.78719613401144E-5,1.0881415291717E-8,1,4,13.4005146026611,4.99276915929277,33.1499986350536,0.0345576035323643,0.0052774790845061,1,8.50613797067294E-8,,,,,,,,,,,,,,,,,,,,,100.086692810059,100.087371826172,1599.53918457031,1599.53918457031,53.4692529292845,5.64979147142394,4.9473557472229,54,3,0,0,1,0.303573608398438,33.7243423461914,1,1,3,100.086692810059,0,100.087032318115,,,,,,,,,,,,,,,,,,,,,,,,,,,,,,,,,
,3879897679.0312,100.060340881348,1399.73840332031,2.74203000918309E-5,2.57423508533802E-8,1,4,13.4005146026611,4.99288006357247,33.1499986350536,0.0339737511949956,0.00535863256528259,1,2.17916023023982E-7,,,,,,,,,,,,,,,,,,,,,100.048973083496,100.071708679199,1399.73840332031,1399.73840332031,53.3281689815633,5.65092819683801,4.94577836990356,53,1,68,0,0,0.3033447265625,33.7243423461914,1,1,3,100.071708679199,0,100.060340881348,,,,,,,,,,,,,,,,,,,,,,,,,,,,,,,,,
,3879897751.56959,100.042869567871,1249.64868164062,2.69618606386277E-5,1.64231833123913E-8,1,4,13.4005146026611,4.99285402954166,33.1499986350536,0.0334213479703187,0.00516306773175548,1,1.2887293035546E-7,,,,,,,,,,,,,,,,,,,,,100.041435241699,100.044303894043,1249.64868164062,1249.64868164062,53.3086282685826,5.65096531885626,4.95473480224609,53,2,64,0,0,0.304107666015625,33.2355842590332,1,1,3,100.044303894043,0,100.042869567871,,,,,,,,,,,,,,,,,,,,,,,,,,,,,,,,,
,3879897822.39352,100.10474395752,1099.87353515625,2.62905258994876E-5,1.32511059346141E-8,1,4,13.4005146026611,4.99281973707387,33.1499986350536,0.0325953954595628,0.004990788061473,1,9.04561276620222E-8,,,,,,,,,,,,,,,,,,,,,100.103996276855,100.105491638184,1099.87353515625,1099.87353515625,53.4028145051499,5.64954434640491,4.95700359344482,53,3,68,0,0,0.30517578125,34.2131004333496,1,1,3,100.105491638184,0,100.10474395752,,,,,,,,,,,,,,,,,,,,,,,,,,,,,,,,,
,3879897905.13104,100.133354187012,899.770690917969,2.49192448748514E-5,2.14902401958179E-8,1,4,13.4005146026611,4.99276648168421,33.1499986350536,0.0308733750261352,0.00487361562704808,1,2.01190705436172E-7,,,,,,,,,,,,,,,,,,,,,100.124588012695,100.142120361328,899.770690917969,899.770690917969,53.3023752404287,5.65075920421505,4.9533109664917,52,1,68,0,0,0.305328369140625,33.7243423461914,1,1,3,100.142120361328,0,100.133354187012,,,,,,,,,,,,,,,,,,,,,,,,,,,,,,,,,
,3879897974.59364,100.146148681641,749.743896484375,2.36375118305555E-5,1.81180303873175E-8,1,4,13.4005146026611,4.9927928561244,33.1499986350536,0.029296313136069,0.00455139345590059,1,1.3313749644124E-7,,,,,,,,,,,,,,,,,,,,,100.143943786621,100.14835357666,749.743896484375,749.743896484375,53.366077964746,5.65076156212,4.95208072662354,54,2,0,0,1,0.304031372070313,33.7243423461914,1,1,3,100.143943786621,0,100.146148681641,,,,,,,,,,,,,,,,,,,,,,,,,,,,,,,,,
,3879898046.75808,100.111877441406,599.993957519531,2.1866034091087E-5,1.46075468690093E-8,1,4,13.4005146026611,4.99281015768889,33.1499986350536,0.02710479530935,0.0041841211175013,1,1.0204201507535E-7,,,,,,,,,,,,,,,,,,,,,100.109535217285,100.114219665527,599.993957519531,599.993957519531,53.2937773267172,5.65010062655938,4.95366621017456,52,3,68,0,0,0.304183959960937,33.7243423461914,1,1,3,100.109535217285,0,100.111877441406,,,,,,,,,,,,,,,,,,,,,,,,,,,,,,,,,
,3879898141.24106,100.073337554932,399.878509521484,1.85927507632851E-5,2.44116559448229E-8,1,4,13.4005146026611,4.99277409168192,33.1499986350536,0.0230131330030704,0.00378446806058132,1,2.69552092241947E-7,,,,,,,,,,,,,,,,,,,,,100.069862365723,100.076812744141,399.878509521484,399.878509521484,53.3926533343999,5.65130834608331,4.96030569076538,52,1,68,0,0,0.3045654296875,33.7243423461914,1,1,3,100.069862365723,0,100.073337554932,,,,,,,,,,,,,,,,,,,,,,,,,,,,,,,,,
,3879898232.08438,100.059837341309,249.927200317383,1.55361573589545E-5,1.44135285958799E-8,1,4,13.4005146026611,4.99277755153184,33.160001039505,0.0192515031361356,0.00301763950783704,10,1.08605438010773E-7,,,,,,,,,,,,,,,,,,,,,100.059478759766,100.060195922852,249.927200317383,249.927200317383,53.3860094919864,5.65059816778189,4.96061611175537,54,2,0,0,1,0.304183959960937,33.2355842590332,1,1,3,100.059478759766,0,100.059837341309,,,,,,,,,,,,,,,,,,,,,,,,,,,,,,,,,
,3879898319.45277,100.063499450684,100.101806640625,1.13077043516322E-5,1.07265403613323E-8,1,4,13.4005146026611,4.99269102365234,33.160001039505,0.0140097046664122,0.00220834605474019,1,8.87741894199327E-8,,,,,,,,,,,,,,,,,,,,,100.062133789062,100.064865112305,100.101806640625,100.101806640625,53.3754575069768,5.65117722429823,4.95249795913696,54,3,0,0,1,0.303497314453125,33.7243423461914,1,1,3,100.061950683594,0,100.063499450684,,,,,,,,,,,,,,,,,,,,,,,,,,,,,,,,,
,3879898429.23967,100.097225189209,-99.7619247436523,3.247615452666E-6,2.81655808419334E-8,1,4,13.4005146026611,4.99274191717134,33.1699997186661,0.0039836094002987,9.02234867944018E-4,10,2.41535234754013E-7,,,,,,,,,,,,,,,,,,,,,100.095710754395,100.098739624023,-99.7619247436523,-99.7619247436523,53.2371092590729,5.6514668882423,4.95287609100342,54,1,0,0,1,0.295333862304687,33.7243423461914,1,1,3,100.098739624023,0,100.097225189209,,,,,,,,,,,,,,,,,,,,,,,,,,,,,,,,,
,3879898542.20115,100.067596435547,-249.889434814453,-3.27670074428763E-6,2.12736138286808E-8,1,4,13.4005146026611,4.99263582656772,33.1699997186661,-0.00409873859159264,-3.78367254423337E-4,1,1.85135237756163E-7,,,,,,,,,,,,,,,,,,,,,100.065849304199,100.069343566895,-249.889434814453,-249.889434814453,53.3543535369576,5.65138872042242,4.95515155792236,52,2,68,0,0,0.30364990234375,33.7243423461914,1,1,3,100.065849304199,0,100.067596435547,,,,,,,,,,,,,,,,,,,,,,,,,,,,,,,,,
,3879898629.59083,100.045417785645,-399.828155517578,-9.01746314398265E-6,1.09004512819653E-8,1,4,13.4005146026611,4.99250780704337,33.1699997186661,-0.0112070260190316,-0.00152437343190602,1,1.19965621883696E-7,,,,,,,,,,,,,,,,,,,,,100.043815612793,100.047019958496,-399.828155517578,-399.828155517578,53.1820044484672,5.65160147074445,4.9576849937439,53,3,68,0,0,0.305709838867188,33.7243423461914,1,1,3,100.043815612793,0,100.045417785645,,,,,,,,,,,,,,,,,,,,,,,,,,,,,,,,,
,3879898711.95617,100.042304992676,-599.553405761719,-1.50744423310615E-5,1.87159216757567E-8,1,4,13.4005146026611,4.9924223288823,33.1699997186661,-0.0187366887336771,-0.002532075483662,1,2.13566624099122E-7,,,,,,,,,,,,,,,,,,,,,100.035858154297,100.048751831055,-599.553405761719,-599.553405761719,53.2863518557845,5.65219107038985,4.95651149749756,54,1,0,0,1,0.305099487304687,33.7243423461914,1,1,3,100.048751831055,0,100.042304992676,,,,,,,,,,,,,,,,,,,,,,,,,,,,,,,,,
,3879898783.95534,100.073184967041,-749.806823730469,-1.84057173938525E-5,1.54340166242221E-8,1,4,13.4005146026611,4.99253607019372,33.160001039505,-0.0228566400225038,-0.00323457062001912,1,1.4560382725209E-7,,,,,,,,,,,,,,,,,,,,,100.072731018066,100.073638916016,-749.806823730469,-749.806823730469,53.4622182726114,5.65121159055294,4.96584939956665,53,2,68,0,0,0.305099487304687,33.7243423461914,1,1,3,100.072731018066,0,100.073184967041,,,,,,,,,,,,,,,,,,,,,,,,,,,,,,,,,
,3879898855.52285,100.029983520508,-899.682556152344,-2.09605739289065E-5,1.11465853361701E-8,1,4,13.4005146026611,4.99240401754435,33.1699997186661,-0.026022052512459,-0.00372554514518853,1,1.31849432134693E-7,,,,,,,,,,,,,,,,,,,,,100.029220581055,100.030746459961,-899.682556152344,-899.682556152344,53.4661264152076,5.65262362212031,4.95753765106201,54,3,0,0,1,0.304794311523438,33.7243423461914,1,1,3,100.029220581055,0,100.029983520508,,,,,,,,,,,,,,,,,,,,,,,,,,,,,,,,,
,3879898939.09157,100.079025268555,-1099.52111816406,-2.35199040911226E-5,5.41348447354188E-8,1,4,13.4005146026611,4.99243365635393,33.1699997186661,-0.0292214447737931,-0.00403473536164344,1,2.65451697448664E-7,,,,,,,,,,,,,,,,,,,,,100.076026916504,100.082023620605,-1099.52111816406,-1099.52111816406,53.416883818496,5.65117082608733,4.95919322967529,54,1,0,0,1,0.30548095703125,33.7243423461914,1,1,3,100.076026916504,0,100.079025268555,,,,,,,,,,,,,,,,,,,,,,,,,,,,,,,,,
,3879899010.67044,100.020980834961,-1249.64868164062,-2.47809692928969E-5,1.10157795023908E-8,1,4,13.4005146026611,4.99242054351288,33.1699997186661,-0.0307678049469356,-0.00438668957425328,1,1.7032530310056E-7,,,,,,,,,,,,,,,,,,,,,100.020790100098,100.021171569824,-1249.64868164062,-1249.64868164062,53.4516662876018,5.65159506239178,4.96767616271973,53,2,68,0,0,0.30487060546875,32.7468223571777,1,1,3,100.020820617676,0,100.020980834961,,,,,,,,,,,,,,,,,,,,,,,,,,,,,,,,,
,3879899083.31676,100.086330413818,-1399.56225585938,-2.57392023802827E-5,7.71507286231605E-9,1,4,13.4005146026611,4.99229831325995,33.1699997186661,-0.0319479973204315,-0.00461260429406602,1,1.31400435652123E-7,,,,,,,,,,,,,,,,,,,,,100.08504486084,100.087615966797,-1399.56225585938,-1399.56225585938,53.4055502049672,5.65253472337167,4.96158504486084,54,3,0,0,1,0.305328369140625,33.2355842590332,1,1,3,100.087615966797,0,100.086330413818,,,,,,,,,,,,,,,,,,,,,,,,,,,,,,,,,
,3879899166.97661,100.035415649414,-1599.69030761719,-2.66093710806024E-5,2.48438032156064E-8,1,4,13.4005146026611,4.99230977593033,33.1699997186661,-0.0330333514209268,-0.0047339477282079,1,1.63748464094257E-7,,,,,,,,,,,,,,,,,,,,,100.035087585449,100.035743713379,-1599.69030761719,-1599.69030761719,53.4915293420826,5.65208588246708,4.96207427978516,53,1,68,0,0,0.305557250976562,33.2355842590332,1,1,3,100.035743713379,0,100.035415649414,,,,,,,,,,,,,,,,,,,,,,,,,,,,,,,,,
,3879899240.9207,100.058151245117,-1749.81774902344,-2.69616087360168E-5,1.08004306066034E-8,1,4,13.4005146026611,4.99221718831271,33.1699997186661,-0.0334660563335569,-0.00482121798119981,1,1.45976466679841E-7,,,,,,,,,,,,,,,,,,,,,100.056709289551,100.059593200684,-1749.81774902344,-1749.81774902344,53.427044989246,5.65146203489487,4.96540260314941,54,2,0,0,1,0.304489135742188,33.7243423461914,1,1,3,100.056564331055,0,100.058151245117,,,,,,,,,,,,,,,,,,,,,,,,,,,,,,,,,
,3879899313.09817,100.117420196533,-1899.78161621094,-2.72000603995583E-5,6.40465395510409E-8,1,4,13.4005146026611,4.9922184289918,33.1699997186661,-0.0337583105117662,-0.00488882902974764,1,1.27134426679936E-7,,,,,,,,,,,,,,,,,,,,,100.116912841797,100.11792755127,-1899.78161621094,-1899.78161621094,53.3735034356787,5.65138363422299,4.96254014968872,53,3,68,0,0,0.305023193359375,33.2355842590332,1,1,3,100.11792755127,0,100.117420196533,,,,,,,,,,,,,,,,,,,,,,,,,,,,,,,,,
,3879899395.13027,100.098773956299,-2099.60766601562,-2.72193964174428E-5,1.1443669662568E-8,1,4,13.4005146026611,4.99238698851166,33.1699997186661,-0.0337957378670282,-0.00481344889103112,1,1.909890381243E-7,,,,,,,,,,,,,,,,,,,,,100.096755981445,100.100791931152,-2099.60766601562,-2099.60766601562,53.2961222122749,5.65187135656704,4.96212720870972,54,1,0,0,1,0.305633544921875,33.2355842590332,1,1,3,100.100791931152,0,100.098773956299,,,,,,,,,,,,,,,,,,,,,,,,,,,,,,,,,
,3879899466.63289,100.094959259033,-2249.5966796875,-2.70943873346565E-5,8.84630032724686E-9,1,4,13.4005146026611,4.99223195497207,33.160001039505,-0.0336284034492024,-0.0048623851123264,1,1.32662808238043E-7,,,,,,,,,,,,,,,,,,,,,100.092735290527,100.097183227539,-2249.5966796875,-2249.5966796875,53.384446234948,5.65167417576534,4.96314811706543,54,2,0,0,1,0.30609130859375,34.2131004333496,1,1,3,100.097183227539,0,100.094959259033,,,,,,,,,,,,,,,,,,,,,,,,,,,,,,,,,
,3879899538.68925,100.083442687988,-2399.69897460938,-2.68788656073913E-5,7.30963961990796E-9,1,4,13.4005146026611,4.99233113663993,33.1699997186661,-0.0333590047653017,-0.00484276601835528,1,1.16349452603951E-7,,,,,,,,,,,,,,,,,,,,,100.082679748535,100.084205627441,-2399.69897460938,-2399.69897460938,53.218740988871,5.65128450352516,4.9640736579895,54,3,0,0,1,0.305709838867188,33.7243423461914,1,1,3,100.082679748535,0,100.083442687988,,,,,,,,,,,,,,,,,,,,,,,,,,,,,,,,,
,3879899621.10345,100.079090118408,-2599.587890625,-2.64908931626111E-5,9.54352085372104E-9,1,4,13.4005146026611,4.99241461444373,33.1699997186661,-0.0328813960058891,-0.00475206415713141,1,1.31530864832274E-7,,,,,,,,,,,,,,,,,,,,,100.077339172363,100.080841064453,-2599.587890625,-2599.587890625,53.3543535369576,5.65257446522395,4.96806716918945,54,1,0,0,1,0.304946899414063,33.7243423461914,1,1,3,100.077339172363,0,100.079090118408,,,,,,,,,,,,,,,,,,,,,,,,,,,,,,,,,
,3879899693.15803,100.048831939697,-2749.61474609375,-2.61161240874493E-5,8.28564600728591E-9,1,4,13.4005146026611,4.99245477761967,33.1699997186661,-0.0324153202999919,-0.00469334536393794,1,1.22852299426295E-7,,,,,,,,,,,,,,,,,,,,,100.046295166016,100.051368713379,-2749.61474609375,-2749.61474609375,53.4247001036883,5.65073062450939,4.96492958068848,53,2,68,0,0,0.304946899414063,33.2355842590332,1,1,3,100.046295166016,0,100.048831939697,,,,,,,,,,,,,,,,,,,,,,,,,,,,,,,,,
,3879899765.67818,100.03014755249,-2899.541015625,-2.56930735659735E-5,6.60910894488308E-9,1,4,13.4005146026611,4.9923877408581,33.1699997186661,-0.0318866832666246,-0.00463693143060213,1,1.0497933314175E-7,,,,,,,,,,,,,,,,,,,,,100.029434204102,100.030860900879,-2899.541015625,-2899.541015625,53.4325163888806,5.652014169114,4.96811676025391,54,3,0,0,1,0.305633544921875,33.2355842590332,1,1,3,100.029434204102,0,100.03014755249,,,,,,,,,,,,,,,,,,,,,,,,,,,,,,,,,
,3879899869.96754,100.100074768066,-3499.6103515625,-2.35015411282765E-5,8.33872929605983E-9,1,4,13.4005146026611,4.99244258562707,33.1699997186661,-0.029150665176194,-0.00435272076453745,1,6.33968814111624E-9,,,,,,,,,,,,,,,,,,,,,100.096206665039,100.103942871094,-3499.6103515625,-3499.6103515625,53.3566984225153,5.65087266785897,4.97291040420532,54,1,0,0,1,0.304641723632812,33.2355842590332,1,1,3,100.096206665039,0,100.100074768066,,,,,,,,,,,,,,,,,,,,,,,,,,,,,,,,,
,3879899952.57935,100.05623626709,-4999.5390625,-1.64550337326435E-5,7.99908814262671E-9,1,4,13.4005146026611,4.99257744709846,33.160001039505,-0.020411964752717,-0.00304226418538426,1,8.86349580601591E-9,,,,,,,,,,,,,,,,,,,,,100.051452636719,100.061019897461,-4999.5390625,-4999.5390625,53.3230883961883,5.65134228912167,4.96806526184082,54,2,0,0,1,0.304794311523438,33.2355842590332,1,1,3,100.061332702637,0,100.05623626709,,,,,,,,,,,,,,,,,,,,,,,,,,,,,,,,,
,3879900037.16423,100.031856536865,-6499.5927734375,-8.38976180657385E-6,1.16050445146788E-8,1,4,13.4005146026611,4.99246045950625,33.1699997186661,-0.0104051541536628,-0.00156275188863647,1,-4.89313086284564E-9,,,,,,,,,,,,,,,,,,,,,100.030975341797,100.032737731934,-6499.5927734375,-6499.5927734375,53.1784871201306,5.65105618231843,4.96585750579834,54,3,0,0,1,0.30548095703125,33.2355842590332,1,1,3,100.030975341797,0,100.031856536865,,,,,,,,,,,,,,,,,,,,,,,,,,,,,,,,,
,3879900136.58144,100.110706329346,-8499.640625,2.96859200443142E-6,1.20718504791749E-8,1,4,13.4005146026611,4.99237890080879,33.1699997186661,0.00369113960088753,4.89335763338368E-4,1,-4.95530040732508E-8,,,,,,,,,,,,,,,,,,,,,100.105094909668,100.116317749023,-8499.640625,-8499.640625,53.254305086496,5.65115567614478,4.97118902206421,54,1,0,0,1,0.306396484375,33.2355842590332,1,1,3,100.116317749023,0,100.110706329346,,,,,,,,,,,,,,,,,,,,,,,,,,,,,,,,,
,3879900221.58847,100.144466400146,-9999.5439453125,1.16962600283531E-5,1.27106341112173E-8,1,4,13.4005146026611,4.9923983114849,33.1699997186661,0.0145136490850648,0.0021253927202365,1,-3.60863784458361E-8,,,,,,,,,,,,,,,,,,,,,100.138359069824,100.150573730469,-9999.5439453125,-9999.5439453125,53.3543535369576,5.65090610339427,4.97442483901978,54,2,0,0,1,0.304336547851562,33.7243423461914,1,1,3,100.150840759277,0,100.144466400146,,,,,,,,,,,,,,,,,,,,,,,,,,,,,,,,,
,3879900410.86748,100.01362991333,-19999.666015625,7.1363122842734E-5,1.99885725254231E-8,1,4,13.4005146026611,4.9924101001002,33.1699997186661,0.0885332104012389,0.0131023151910289,1,-1.11751064703378E-7,,,,,,,,,,,,,,,,,,,,,100.012672424316,100.014587402344,-19999.666015625,-19999.666015625,53.3586524938133,5.65171759441561,4.97614479064941,54,3,0,0,1,0.304794311523438,33.2355842590332,1,1,3,100.012672424316,0,100.01362991333,,,,,,,,,,,,,,,,,,,,,,,,,,,,,,,,,
,3879900693.86542,100.027416229248,-39999.609375,1.92253504791027E-4,4.12767482658979E-8,1,4,13.4005146026611,4.99248229980745,33.160001039505,0.238491974045362,0.0354515356658647,1,-1.77743222115503E-7,,,,,,,,,,,,,,,,,,,,,100.02424621582,100.030586242676,-39999.609375,-39999.609375,53.2058441183037,5.65125512537563,4.97187757492065,53,1,68,0,0,0.304031372070313,33.7243423461914,1,1,3,100.030586242676,0,100.027416229248,,,,,,,,,,,,,,,,,,,,,,,,,,,,,,,,,
,3879900933.80831,100.14750289917,-54999.62109375,2.83286479625828E-4,5.32904350978158E-8,1,4,13.4005146026611,4.99259456283686,33.1699997186661,0.351480400245011,0.0519038284260986,10,-5.32653092162854E-7,,,,,,,,,,,,,,,,,,,,,100.146873474121,100.148132324219,-54999.62109375,-54999.62109375,53.2296837881402,5.65154899771609,4.97335767745972,54,2,0,0,1,0.304336547851562,33.7243423461914,1,1,3,100.148132324219,0,100.14750289917,,,,,,,,,,,,,,,,,,,,,,,,,,,,,,,,,
,3879901182.13072,100.048149108887,-69999.5859375,3.73974530394694E-4,1.30928286225945E-7,1,4,13.4005146026611,4.99264808475123,33.1699997186661,0.463904979122773,0.0691975997087291,1,-1.57495523904757E-7,,,,,,,,,,,,,,,,,,,,,100.047950744629,100.048347473145,-69999.5859375,-69999.5859375,53.1194741669287,5.65003168880098,4.97508907318115,54,3,0,0,1,0.305023193359375,33.7243423461914,1,1,3,100.047950744629,0,100.048149108887,,,,,,,,,,,,,,,,,,,,,,,,,,,,,,,,,
,3879901465.23687,100.013103485107,-49999.62890625,2.52577080473009E-4,5.88873633824646E-8,1,4,13.4005146026611,4.99263752692061,33.1699997186661,0.313317586862558,0.046710280917221,1,-1.26247503469574E-7,,,,,,,,,,,,,,,,,,,,,100.012336730957,100.013870239258,-49999.62890625,-49999.62890625,53.0616336565056,5.65147477244696,4.97789621353149,54,1,0,0,1,0.30303955078125,33.7243423461914,1,1,3,100.013778686523,0,100.013103485107,,,,,,,,,,,,,,,,,,,,,,,,,,,,,,,,,
,3879901687.40629,100.016639709473,-34999.54296875,1.61748076219596E-4,3.36152177220017E-8,1,4,13.4005146026611,4.99277778497193,33.160001039505,0.200661903416461,0.0298588093779202,1,-1.25355508993254E-7,,,,,,,,,,,,,,,,,,,,,100.015937805176,100.01734161377,-34999.54296875,-34999.54296875,53.2503969438999,5.64973597040816,4.97065019607544,54,2,0,0,1,0.305252075195313,34.2131004333496,1,1,3,100.015937805176,0,100.016639709473,,,,,,,,,,,,,,,,,,,,,,,,,,,,,,,,,
,3879901909.23484,100.090953826904,-19999.767578125,7.10912657821008E-5,2.1129277195004E-8,1,4,13.4005146026611,4.99284411809851,33.160001039505,0.0882003164751265,0.0130965788545818,1,-7.69938868696843E-8,,,,,,,,,,,,,,,,,,,,,100.08846282959,100.093444824219,-19999.767578125,-19999.767578125,53.1452679080633,5.65026036733663,4.98025178909302,54,3,0,0,1,0.303115844726562,34.2131004333496,1,1,3,100.093444824219,0,100.090953826904,,,,,,,,,,,,,,,,,,,,,,,,,,,,,,,,,
,3879902111.46088,100.146667480469,-9500.45703125,8.42995782271744E-6,1.21846039467251E-8,1,4,13.4005146026611,4.99277228133381,33.160001039505,0.0104532433403917,0.0015882763054551,1,1.93467532322951E-8,,,,,,,,,,,,,,,,,,,,,100.135772705078,100.157562255859,-9500.45703125,-9500.45703125,53.432125574621,5.65165407621565,4.97432899475098,54,1,0,0,1,0.303955078125,34.2131004333496,1,1,3,100.157562255859,0,100.146667480469,,,,,,,,,,,,,,,,,,,,,,,,,,,,,,,,,
,3879902196.05743,100.168060302734,-8000.263671875,-2.44213609609678E-7,1.01192055486167E-8,1,4,13.4005146026611,4.99282672207113,33.160001039505,-3.05932253069377E-4,-2.52899951374536E-5,1,1.61451946901189E-8,,,,,,,,,,,,,,,,,,,,,100.164474487305,100.171646118164,-8000.263671875,-8000.263671875,53.4129756758999,5.65141044937437,4.96980237960815,54,2,0,0,1,0.303421020507812,34.2131004333496,1,1,3,100.171646118164,0,100.168060302734,,,,,,,,,,,,,,,,,,,,,,,,,,,,,,,,,
,3879902281.03475,100.051155090332,-6500.14697265625,-8.72165384480172E-6,9.31856098272708E-9,1,4,13.4005146026611,4.99287733829694,33.160001039505,-0.0108246889728646,-0.00158030949859162,1,3.07493130955178E-8,,,,,,,,,,,,,,,,,,,,,100.04859161377,100.053718566895,-6500.14697265625,-6500.14697265625,53.350836208621,5.65066769898402,4.97840070724487,54,3,0,0,1,0.305252075195313,33.7243423461914,1,1,3,100.04859161377,0,100.051155090332,,,,,,,,,,,,,,,,,,,,,,,,,,,,,,,,,
,3879902378.64829,100.099613189697,-4500.3388671875,-1.93431873968599E-5,1.12277519954389E-8,1,4,13.4005146026611,4.99282290470046,33.1699997186661,-0.0240093896557711,-0.00348887217473722,1,8.10467697101009E-8,,,,,,,,,,,,,,,,,,,,,100.085693359375,100.11353302002,-4500.3388671875,-4500.3388671875,53.2828345274479,5.65024527377304,4.97269535064697,53,1,68,0,0,0.302734375,33.7243423461914,1,1,3,100.11353302002,0,100.099613189697,,,,,,,,,,,,,,,,,,,,,,,,,,,,,,,,,
,3879902464.06447,100.05908203125,-3000.29736328125,-2.57706115908153E-5,1.07947854191785E-8,1,4,13.4005146026611,4.99282429763596,33.1699997186661,-0.0319792016315801,-0.00470249792913666,1,6.41797473010299E-8,,,,,,,,,,,,,,,,,,,,,100.056083679199,100.062080383301,-3000.29736328125,-3000.29736328125,53.2859610415249,5.65035126102054,4.97412204742432,52,2,68,0,0,0.304031372070313,33.7243423461914,1,1,3,100.056083679199,0,100.05908203125,,,,,,,,,,,,,,,,,,,,,,,,,,,,,,,,,
,3879902553.03325,100.031700134277,-2900.23315429687,-2.60385918641702E-5,1.01143116237051E-8,1,4,13.4005146026611,4.99287751180851,33.1699997186661,-0.0322855578141119,-0.00492973615968841,1,-7.88620818070108E-8,,,,,,,,,,,,,,,,,,,,,100.031677246094,100.031723022461,-2900.23315429687,-2900.23315429687,53.4665172294672,5.65052110001857,4.9744553565979,54,3,0,0,1,0.303573608398438,33.7243423461914,1,1,3,100.031723022461,0,100.031700134277,,,,,,,,,,,,,,,,,,,,,,,,,,,,,,,,,
,3879902636.10815,100.053211212158,-2700.35693359375,-2.66005338866626E-5,1.71620475579626E-8,1,4,13.4005146026611,4.99297453069807,33.1699997186661,-0.0329644110432119,-0.00516195793509644,1,-1.81889818359043E-7,,,,,,,,,,,,,,,,,,,,,100.051277160645,100.055145263672,-2700.35693359375,-2700.35693359375,53.2648570715056,5.65021402993558,4.97010612487793,54,1,0,0,1,0.304107666015625,33.7243423461914,1,1,3,100.051277160645,0,100.053211212158,,,,,,,,,,,,,,,,,,,,,,,,,,,,,,,,,
,3879902707.94308,100.069965362549,-2550.3427734375,-2.7023206728403E-5,1.22303211704838E-8,1,4,13.4005146026611,4.99300540138906,33.1699997186661,-0.0335042304115001,-0.00513882858823359,1,-9.99796137281903E-8,,,,,,,,,,,,,,,,,,,,,100.068878173828,100.07105255127,-2550.3427734375,-2550.3427734375,53.4547928016787,5.65079344213763,4.97723197937012,53,2,68,0,0,0.3045654296875,33.7243423461914,1,1,3,100.07105255127,0,100.069965362549,,,,,,,,,,,,,,,,,,,,,,,,,,,,,,,,,
,3879902778.24634,100.084095001221,-2400.2529296875,-2.73702752791719E-5,1.09542209390904E-8,1,4,13.4005146026611,4.99289993443151,33.160001039505,-0.0339355273241938,-0.00519134114765277,1,-9.05152887967324E-8,,,,,,,,,,,,,,,,,,,,,100.082611083984,100.085578918457,-2400.2529296875,-2400.2529296875,53.4278266177653,5.65106543827827,4.9750919342041,54,3,0,0,1,0.304336547851562,34.2131004333496,1,1,3,100.082611083984,0,100.084095001221,,,,,,,,,,,,,,,,,,,,,,,,,,,,,,,,,
,3879902861.11027,100.056465148926,-2200.37646484375,-2.76731904344676E-5,1.71529679577209E-8,1,4,13.4005146026611,4.9927396951117,33.1699997186661,-0.034294928971403,-0.00534635968571246,1,-1.70361262294969E-7,,,,,,,,,,,,,,,,,,,,,100.05492401123,100.058006286621,-2200.37646484375,-2200.37646484375,53.2347643735152,5.65043116568299,4.97713470458984,54,1,0,0,1,0.304794311523438,33.7243423461914,1,1,3,100.05492401123,0,100.056465148926,,,,,,,,,,,,,,,,,,,,,,,,,,,,,,,,,
,3879902932.07789,100.048248291016,-2050.31201171875,-2.78899179887517E-5,1.60152170369061E-8,1,4,13.4005146026611,4.99311183276488,33.160001039505,-0.0345764954298283,-0.00532615657126316,1,-1.21204555088333E-7,,,,,,,,,,,,,,,,,,,,,100.046195983887,100.050300598145,-2050.31201171875,-2050.31201171875,53.2308562309191,5.64996639850254,4.97681713104248,52,2,68,0,0,0.302886962890625,33.7243423461914,1,1,3,100.046195983887,0,100.048248291016,,,,,,,,,,,,,,,,,,,,,,,,,,,,,,,,,
,3879903003.61708,100.054195404053,-1900.41101074219,-2.79852092256679E-5,1.12718460561618E-8,1,4,13.4005146026611,4.99299150002694,33.160001039505,-0.0346996229407437,-0.00530298410833173,1,-8.84148063582924E-8,,,,,,,,,,,,,,,,,,,,,100.054107666016,100.05428314209,-1900.41101074219,-1900.41101074219,53.4055502049672,5.65101507782918,4.97647953033447,54,3,0,0,1,0.304336547851562,34.7018585205078,1,1,3,100.05428314209,0,100.054195404053,,,,,,,,,,,,,,,,,,,,,,,,,,,,,,,,,
,3879903084.89015,100.075744628906,-1700.01867675781,-2.78864704022749E-5,3.34304051197185E-8,1,4,13.4005146026611,4.9929994129915,33.160001039505,-0.0345626746117342,-0.00538185743997012,1,-1.66757088063651E-7,,,,,,,,,,,,,,,,,,,,,100.071418762207,100.080070495605,-1700.01867675781,-1700.01867675781,53.4278266177653,5.64993216132721,4.97638893127441,53,1,68,0,0,0.302886962890625,33.7243423461914,1,1,3,100.071418762207,0,100.075744628906,,,,,,,,,,,,,,,,,,,,,,,,,,,,,,,,,
,3879903156.36734,100.017810821533,-1550.0673828125,-2.77603251674188E-5,1.54408825885165E-8,1,4,13.4005146026611,4.99301776588775,33.160001039505,-0.034414174325842,-0.00530628286115338,1,-1.24683733839897E-7,,,,,,,,,,,,,,,,,,,,,100.017578125,100.018043518066,-1550.0673828125,-1550.0673828125,53.3617790078903,5.65100484225098,4.97388315200806,54,2,0,0,1,0.303268432617188,33.7243423461914,1,1,3,100.017578125,0,100.017810821533,,,,,,,,,,,,,,,,,,,,,,,,,,,,,,,,,
,3879903239.76675,100.019195556641,-1399.92724609375,-2.74737987720526E-5,9.26963609694548E-9,1,4,13.4005146026611,4.99305809865815,33.160001039505,-0.0340734477966259,-0.00515737423455774,1,-4.7462261161792E-8,,,,,,,,,,,,,,,,,,,,,100.018997192383,100.019393920898,-1399.92724609375,-1399.92724609375,53.2855702272653,5.65068102984727,4.9786639213562,54,3,0,0,1,0.305862426757812,33.7243423461914,1,1,3,100.018997192383,0,100.019195556641,,,,,,,,,,,,,,,,,,,,,,,,,,,,,,,,,
,3879903320.66408,100.089393615723,-1200.10119628906,-2.66805277863882E-5,2.21936928167091E-8,1,4,13.4005146026611,4.99304839797515,33.160001039505,-0.0330550126782093,-0.00523919006472065,1,-2.32094173802031E-7,,,,,,,,,,,,,,,,,,,,,100.086860656738,100.091926574707,-1200.10119628906,-1200.10119628906,53.330513867121,5.64994493875746,4.97631883621216,53,1,68,0,0,0.304336547851562,33.7243423461914,1,1,3,100.086860656738,0,100.089393615723,,,,,,,,,,,,,,,,,,,,,,,,,,,,,,,,,
,3879903392.5724,100.09867477417,-1050.12475585938,-2.59617213865075E-5,1.76398276747326E-8,1,4,13.4005146026611,4.99301945798526,33.1699997186661,-0.0321786014433317,-0.0050017854985653,1,-1.48282940514613E-7,,,,,,,,,,,,,,,,,,,,,100.097579956055,100.099769592285,-1050.12475585938,-1050.12475585938,53.4493214020441,5.65075651889198,4.97358560562134,52,2,68,0,0,0.304412841796875,33.2355842590332,1,1,3,100.097579956055,0,100.09867477417,,,,,,,,,,,,,,,,,,,,,,,,,,,,,,,,,
,3879903463.49705,100.116527557373,-899.946899414062,-2.49261142544586E-5,1.33628515861402E-8,1,4,13.4005146026611,4.99304109092366,33.1699997186661,-0.030909148802725,-0.00470899609472709,1,-6.71594557806422E-8,,,,,,,,,,,,,,,,,,,,,100.115982055664,100.117073059082,-899.946899414062,-899.946899414062,53.4723794433614,5.65043125825252,4.97385597229004,53,3,68,0,0,0.303497314453125,33.7243423461914,1,1,3,100.115768432617,0,100.116527557373,,,,,,,,,,,,,,,,,,,,,,,,,,,,,,,,,
,3879903544.22161,100.097904205322,-700.095825195313,-2.29888718281891E-5,2.60803522578677E-8,1,4,13.4005146026611,4.99305969357247,33.1699997186661,-0.0284741934988746,-0.00456272581815222,1,-2.39030364166921E-7,,,,,,,,,,,,,,,,,,,,,100.094650268555,100.10115814209,-700.095825195313,-700.095825195313,53.4547928016787,5.65114383948942,4.96874094009399,53,1,68,0,0,0.303573608398438,33.2355842590332,1,1,3,100.094306945801,0,100.097904205322,,,,,,,,,,,,,,,,,,,,,,,,,,,,,,,,,
,3879903633.2527,100.058753967285,-550.131896972656,-2.11553614114069E-5,1.43243185243792E-8,1,4,13.4005146026611,4.99310538661406,33.1699997186661,-0.0262252769306506,-0.00405349539940313,10,-1.02778499272919E-7,,,,,,,,,,,,,,,,,,,,,100.058731079102,100.058776855469,-550.131896972656,-550.131896972656,53.2777539420729,5.64983007050793,4.97099304199219,54,2,0,0,1,0.302505493164063,33.2355842590332,1,1,3,100.058731079102,0,100.058753967285,,,,,,,,,,,,,,,,,,,,,,,,,,,,,,,,,
,3879903707.06434,100.066452026367,-400.155456542969,-1.87054679411805E-5,1.411746016348E-8,1,4,13.4005146026611,4.99316059963984,33.1699997186661,-0.0231832419519779,-0.00362010012336346,1,-1.19865794879208E-7,,,,,,,,,,,,,,,,,,,,,100.065979003906,100.066925048828,-400.155456542969,-400.155456542969,53.3750666927172,5.64967598294476,4.97556591033936,54,3,0,0,1,0.302886962890625,33.7243423461914,1,1,3,100.066925048828,0,100.066452026367,,,,,,,,,,,,,,,,,,,,,,,,,,,,,,,,,
,3879903789.75027,100.059993743896,-200.090316772461,-1.40395828081696E-5,4.57541379394967E-8,1,4,13.4005146026611,4.99311570228161,33.160001039505,-0.017365571314049,-0.00294857614208396,1,-2.76581683841474E-7,,,,,,,,,,,,,,,,,,,,,100.057510375977,100.062477111816,-200.090316772461,-200.090316772461,53.384446234948,5.64997059694305,4.97340393066406,53,1,68,0,0,0.303421020507812,33.7243423461914,1,1,3,100.05721282959,0,100.059993743896,,,,,,,,,,,,,,,,,,,,,,,,,,,,,,,,,
,3879903874.04861,100.030838012695,-50.1893730163574,-9.4592821234679E-6,2.22076357565059E-8,1,4,13.4005146026611,4.99300082466064,33.160001039505,-0.0117046121782485,-0.00195450530749263,1,-1.60507000062604E-7,,,,,,,,,,,,,,,,,,,,,100.029266357422,100.032409667969,-50.1893730163574,-50.1893730163574,53.3410658521306,5.6507072256046,4.97327661514282,53,2,68,0,0,0.304412841796875,33.7243423461914,1,1,3,100.029113769531,0,100.030838012695,,,,,,,,,,,,,,,,,,,,,,,,,,,,,,,,,
,3879903945.70618,100.053848266602,99.9129791259766,-3.29769806091083E-6,1.52164557686982E-8,1,4,13.4005146026611,4.99301847618195,33.160001039505,-0.00407080894547769,-7.46072367865975E-4,1,-1.0810232502684E-7,,,,,,,,,,,,,,,,,,,,,100.051643371582,100.056053161621,99.9129791259766,99.9129791259766,53.3852278634672,5.65053150741336,4.97537565231323,54,3,0,0,1,0.3033447265625,33.2355842590332,1,1,3,100.051643371582,0,100.053848266602,,,,,,,,,,,,,,,,,,,,,,,,,,,,,,,,,
,3879904028.16639,100.08617401123,299.688598632812,5.42155681811391E-6,7.7723111112823E-8,1,4,13.4005146026611,4.99307237662325,33.1699997186661,0.00676107586976349,7.69419359112888E-4,1,-1.90802963828084E-7,,,,,,,,,,,,,,,,,,,,,100.085624694824,100.086723327637,299.688598632812,299.688598632812,53.2808804561499,5.65016961478434,4.97421979904175,53,1,68,0,0,0.30487060546875,33.2355842590332,1,1,3,100.085624694824,0,100.08617401123,,,,,,,,,,,,,,,,,,,,,,,,,,,,,,,,,
,3879904114.55584,100.093482971191,449.816101074219,1.07576779633976E-5,1.20853887641234E-8,1,4,13.4005146026611,4.99311957980475,33.160001039505,0.0133624013526119,0.00188359080213783,1,-9.09409107116076E-8,,,,,,,,,,,,,,,,,,,,,100.089736938477,100.097229003906,449.816101074219,449.816101074219,53.3926533343999,5.64992014601473,4.97744178771973,54,2,0,0,1,0.303955078125,33.7243423461914,1,1,3,100.089736938477,0,100.093482971191,,,,,,,,,,,,,,,,,,,,,,,,,,,,,,,,,
,3879904186.5775,100.084896087646,599.8681640625,1.51115349363206E-5,1.31818654225655E-8,1,4,13.4005146026611,4.99314739233656,33.1699997186661,0.0187708827305996,0.00264398830429337,1,-1.29319817983774E-7,,,,,,,,,,,,,,,,,,,,,100.083679199219,100.086112976074,599.8681640625,599.8681640625,53.4141481186787,5.6512562916977,4.96654224395752,54,3,0,0,1,0.303802490234375,33.2355842590332,1,1,3,100.086112976074,0,100.084896087646,,,,,,,,,,,,,,,,,,,,,,,,,,,,,,,,,
,3879904268.97462,100.040756225586,799.71923828125,1.94629797477052E-5,2.87012411071482E-8,1,4,13.4005146026611,4.99310924139863,33.160001039505,0.0241893789054978,0.00331450950807915,1,-2.39745143860311E-7,,,,,,,,,,,,,,,,,,,,,100.035537719727,100.045974731445,799.71923828125,799.71923828125,53.3879635632845,5.65099960465192,4.97310590744019,54,1,0,0,1,0.303726196289063,33.7243423461914,1,1,3,100.046310424805,0,100.040756225586,,,,,,,,,,,,,,,,,,,,,,,,,,,,,,,,,
,3879904340.98322,100.040824890137,949.79638671875,2.17442366990504E-5,1.93060299899408E-8,1,4,13.4005146026611,4.99309431025749,33.1699997186661,0.0270002064666111,0.00386541217743059,1,-1.36916317044904E-7,,,,,,,,,,,,,,,,,,,,,100.039825439453,100.04182434082,949.79638671875,949.79638671875,53.1909931764383,5.64910104570419,4.97208881378174,53,2,68,0,0,0.302276611328125,33.2355842590332,1,1,3,100.039825439453,0,100.040824890137,,,,,,,,,,,,,,,,,,,,,,,,,,,,,,,,,
,3879904412.68484,100.087703704834,1099.76025390625,2.35328742019905E-5,3.7113161159244E-8,1,4,13.4005146026611,4.99294988492809,33.1699997186661,0.0292217510638966,0.00417153414500759,1,-1.57585954514309E-7,,,,,,,,,,,,,,,,,,,,,100.085609436035,100.089797973633,1099.76025390625,1099.76025390625,53.3637330791883,5.64941172552163,4.97124290466309,52,3,68,0,0,0.301971435546875,33.7243423461914,1,1,3,100.085609436035,0,100.087703704834,,,,,,,,,,,,,,,,,,,,,,,,,,,,,,,,,
,3879904495.02551,100.122077941895,1299.71215820312,2.51642645559839E-5,5.57743783728869E-8,1,4,13.4005146026611,4.9930206140352,33.160001039505,0.0312452059804079,0.00448040052305715,1,-1.52718000588843E-7,,,,,,,,,,,,,,,,,,,,,100.116340637207,100.127815246582,1299.71215820312,1299.71215820312,53.3641238934479,5.65050158762732,4.97133684158325,54,1,0,0,1,0.302963256835937,33.2355842590332,1,1,3,100.127815246582,0,100.122077941895,,,,,,,,,,,,,,,,,,,,,,,,,,,,,,,,,
,3879904566.92443,100.134552001953,1449.76416015625,2.60536973323633E-5,8.54246570569775E-9,1,4,13.4005146026611,4.99311371087327,33.160001039505,0.0323471166482508,0.00466093144105937,1,-1.40341820007648E-7,,,,,,,,,,,,,,,,,,,,,100.133087158203,100.136016845703,1449.76416015625,1449.76416015625,53.3363760810153,5.64979519066917,4.96899652481079,54,2,0,0,1,0.303955078125,33.7243423461914,1,1,3,100.136016845703,0,100.134552001953,,,,,,,,,,,,,,,,,,,,,,,,,,,,,,,,,
,3879904638.68518,100.033740997314,1599.57690429687,2.6618822803846E-5,4.40091893028573E-8,1,4,13.4005146026611,4.99310654411722,33.160001039505,0.0330513141316562,0.00474444568280248,1,-1.57553413222219E-7,,,,,,,,,,,,,,,,,,,,,100.032165527344,100.035316467285,1599.57690429687,1599.57690429687,53.3137088539576,5.65046450998595,4.97267436981201,52,3,68,0,0,0.30517578125,33.2355842590332,1,1,3,100.032165527344,0,100.033740997314,,,,,,,,,,,,,,,,,,,,,,,,,,,,,,,,,
,3879904720.7212,100.054100036621,1799.61694335938,2.71033467680457E-5,1.35497306692594E-8,1,4,13.4005146026611,4.99316953478846,33.160001039505,0.0336567862973811,0.00480905029371363,1,-1.78026485118419E-7,,,,,,,,,,,,,,,,,,,,,100.044204711914,100.063995361328,1799.61694335938,1799.61694335938,53.3031568689479,5.64954522039795,4.96957015991211,52,1,68,0,0,0.303192138671875,33.2355842590332,1,1,3,100.063995361328,0,100.054100036621,,,,,,,,,,,,,,,,,,,,,,,,,,,,,,,,,
,3879904792.40288,100.140121459961,1949.97094726562,2.71979381119291E-5,3.30661487985439E-8,1,4,13.4005146026611,4.99316435571715,33.160001039505,0.0337665375832465,0.00487704996674124,1,-1.37358047810006E-7,,,,,,,,,,,,,,,,,,,,,100.138572692871,100.141670227051,1949.97094726562,1949.97094726562,53.4336888316595,5.64994491803312,4.96863508224487,54,2,0,0,1,0.302734375,33.7243423461914,1,1,3,100.138359069824,0,100.140121459961,,,,,,,,,,,,,,,,,,,,,,,,,,,,,,,,,
,3879904864.24123,100.149108886719,2099.88452148438,2.72223625683939E-5,3.3686733856869E-8,1,4,13.4005146026611,4.9931740210647,33.160001039505,0.0337982966852766,0.0048724571472954,1,-1.44724621317338E-7,,,,,,,,,,,,,,,,,,,,,100.145210266113,100.153007507324,2099.88452148438,2099.88452148438,53.2402357731499,5.64945421649352,4.97059011459351,54,3,0,0,1,0.303955078125,33.2355842590332,1,1,3,100.145210266113,0,100.149108886719,,,,,,,,,,,,,,,,,,,,,,,,,,,,,,,,,
,3879904946.46923,100.063526153564,2299.91186523438,2.70876713422661E-5,8.63219345407425E-9,1,4,13.4005146026611,4.99307266140514,33.160001039505,0.033633603542569,0.00482487430870016,1,-1.62820438338706E-7,,,,,,,,,,,,,,,,,,,,,100.060722351074,100.066329956055,2299.91186523438,2299.91186523438,53.2980762835729,5.65098065648859,4.96943807601929,54,1,0,0,1,0.302352905273438,33.7243423461914,1,1,3,100.060722351074,0,100.063526153564,,,,,,,,,,,,,,,,,,,,,,,,,,,,,,,,,
,3879905018.46081,100.054862976074,2449.951171875,2.68505120451823E-5,1.13193090380113E-8,1,4,13.4005146026611,4.99316710350664,33.160001039505,0.0333306654925047,0.00484526713877193,1,-1.110077190483E-7,,,,,,,,,,,,,,,,,,,,,100.053611755371,100.056114196777,2449.951171875,2449.951171875,53.1507393076979,5.64954110731449,4.9675178527832,52,2,68,0,0,0.303878784179687,33.7243423461914,1,1,3,100.053611755371,0,100.054862976074,,,,,,,,,,,,,,,,,,,,,,,,,,,,,,,,,
,3879905090.2378,100.046520233154,2599.81469726562,2.65327528982344E-5,7.42843576304775E-9,1,4,13.4005146026611,4.99316453960592,33.160001039505,0.0329356422418026,0.00479161172042162,1,-1.06720584395781E-7,,,,,,,,,,,,,,,,,,,,,100.046119689941,100.046920776367,2599.81469726562,2599.81469726562,53.2683743998422,5.65124438150174,4.97599840164185,54,3,0,0,1,0.3033447265625,34.2131004333496,1,1,3,100.046119689941,0,100.046520233154,,,,,,,,,,,,,,,,,,,,,,,,,,,,,,,,,
,3879905172.55073,100.114822387695,2799.89233398438,2.60134884141715E-5,1.49758515884661E-8,1,4,13.4005146026611,4.99320027030533,33.160001039505,0.0322976005426026,0.00465638418551461,1,-1.38083472040159E-7,,,,,,,,,,,,,,,,,,,,,100.111480712891,100.1181640625,2799.89233398438,2799.89233398438,53.4344704601787,5.65072030237067,4.97061967849731,54,1,0,0,1,0.304794311523438,33.7243423461914,1,1,3,100.111480712891,0,100.114822387695,,,,,,,,,,,,,,,,,,,,,,,,,,,,,,,,,
,3879905244.34343,100.120494842529,2949.8310546875,2.55592029749156E-5,7.7624195567512E-9,1,4,13.4005146026611,4.99318525579734,33.160001039505,0.0317305879491192,0.00459410758231429,1,-1.20308903415225E-7,,,,,,,,,,,,,,,,,,,,,100.119934082031,100.121055603027,2949.8310546875,2949.8310546875,53.2945589552364,5.65036827428029,4.96599435806274,54,2,0,0,1,0.303268432617188,33.7243423461914,1,1,3,100.119934082031,0,100.120494842529,,,,,,,,,,,,,,,,,,,,,,,,,,,,,,,,,
,3879905337.45956,100.127933502197,3499.71118164063,2.35523160882435E-5,6.57087449486241E-9,1,4,13.4005146026611,4.99313530715192,33.160001039505,0.0292234082842395,0.00433567394902303,1,-2.8358624083638E-8,,,,,,,,,,,,,,,,,,,,,100.126243591309,100.129623413086,3499.71118164063,3499.71118164063,53.3535719084383,5.6507438875853,4.96787118911743,54,3,0,0,1,0.305633544921875,33.2355842590332,1,1,3,100.126243591309,0,100.127933502197,,,,,,,,,,,,,,,,,,,,,,,,,,,,,,,,,
,3879905436.23281,100.117069244385,5499.73291015625,1.38628899136803E-5,9.22554264442983E-9,1,4,13.4005146026611,4.99309412162152,33.160001039505,0.0171929919836488,0.00260344178931334,1,2.48173192122538E-8,,,,,,,,,,,,,,,,,,,,,100.112480163574,100.121658325195,5499.73291015625,5499.73291015625,53.2113155179383,5.65085766155119,4.97158908843994,54,1,0,0,1,0.303878784179687,33.2355842590332,1,1,3,100.112480163574,0,100.117069244385,,,,,,,,,,,,,,,,,,,,,,,,,,,,,,,,,
,3879905520.14556,100.120342254639,6999.9384765625,5.63817761679997E-6,1.03469051574675E-8,1,4,13.4005146026611,4.99322288585523,33.1699997186661,0.0069934797895658,0.00105445024434639,1,6.51925288890213E-9,,,,,,,,,,,,,,,,,,,,,100.117240905762,100.123443603516,6999.9384765625,6999.9384765625,53.1847401482845,5.65028672162835,4.96923637390137,54,2,0,0,1,0.304946899414063,33.2355842590332,1,1,3,100.123443603516,0,100.120342254639,,,,,,,,,,,,,,,,,,,,,,,,,,,,,,,,,
,3879905604.04502,100.111629486084,8500.1064453125,-2.93208668159967E-6,9.16484034470904E-9,1,4,13.4005146026611,4.99322202943601,33.1699997186661,-0.00364306113024327,-5.07167173037392E-4,1,2.98120808969607E-8,,,,,,,,,,,,,,,,,,,,,100.109397888184,100.113861083984,8500.1064453125,8500.1064453125,53.396561476996,5.65040968705872,4.96892070770264,54,3,0,0,1,0.302810668945313,33.2355842590332,1,1,3,100.109397888184,0,100.111629486084,,,,,,,,,,,,,,,,,,,,,,,,,,,,,,,,,
,3879905711.98273,100.102916717529,10000.123046875,-1.1656887801876E-5,1.1626201595879E-8,1,4,13.4005146026611,4.99317784022818,33.1699997186661,-0.0144652508932307,-0.00213679443848578,1,2.13807045161512E-8,,,,,,,,,,,,,,,,,,,,,100.102409362793,100.103424072266,10000.123046875,10000.123046875,53.3695952930826,5.6498416369755,4.97418832778931,54,1,0,0,1,0.302658081054687,33.7243423461914,1,1,3,100.102058410645,0,100.102916717529,,,,,,,,,,,,,,,,,,,,,,,,,,,,,,,,,
,3879905930.70681,100.053295135498,25000.474609375,-1.01457783428223E-4,2.71828853006726E-8,1,4,13.4005146026611,4.99309150679982,33.160001039505,-0.125883921590884,-0.0186904130895929,1,1.11208116993559E-7,,,,,,,,,,,,,,,,,,,,,100.048332214355,100.058258056641,25000.474609375,25000.474609375,53.2562591577941,5.64994308038084,4.97388410568237,54,2,0,0,1,0.303726196289063,34.7018585205078,1,1,3,100.058570861816,0,100.053295135498,,,,,,,,,,,,,,,,,,,,,,,,,,,,,,,,,
,3879906152.44689,100.09351348877,40000.390625,-1.92202434895603E-4,3.70041730306532E-8,1,4,13.4005146026611,4.99314524244589,33.160001039505,-0.23846785774313,-0.0354829649912857,1,1.50085638375273E-7,,,,,,,,,,,,,,,,,,,,,100.091934204102,100.095092773438,40000.390625,40000.390625,53.4121940473807,5.64928413179153,4.96739912033081,54,3,0,0,1,0.30303955078125,33.7243423461914,1,1,3,100.095092773438,0,100.09351348877,,,,,,,,,,,,,,,,,,,,,,,,,,,,,,,,,
,3879906436.30154,100.097900390625,60000.49609375,-3.13372012933824E-4,8.9699121553493E-8,1,4,13.4005146026611,4.993042295709,33.1699997186661,-0.388785593007186,-0.0579013605256077,1,2.03872487228821E-7,,,,,,,,,,,,,,,,,,,,,100.081764221191,100.114036560059,60000.49609375,60000.49609375,53.0772662268902,5.65068213332136,4.97311639785767,54,1,0,0,1,0.304412841796875,33.2355842590332,1,1,3,100.114036560059,0,100.097900390625,,,,,,,,,,,,,,,,,,,,,,,,,,,,,,,,,
,3879906601.92698,100.036125183105,70000.4453125,-3.74015512663282E-4,1.14717132191541E-7,1,4,13.4005146026611,4.99293924391049,33.1699997186661,-0.463983619529583,-0.0692783963573279,1,1.03051568237298E-7,,,,,,,,,,,,,,,,,,,,,100.035255432129,100.036994934082,70000.4453125,70000.4453125,53.0143451310921,5.65067851471997,4.97055196762085,54,3,0,0,1,0.305023193359375,33.7243423461914,1,1,3,100.036994934082,0,100.036125183105,,,,,,,,,,,,,,,,,,,,,,,,,,,,,,,,,