File: SQUID/22169_LCOT/22169_LCOT_MH_50K_FC_0d5T.csv
Comment,Time Stamp (sec),Temperature (K),Magnetic Field (Oe),Moment (emu),M. Std. Err. (emu),Transport Action,Averaging Time (sec),Frequency (Hz),Peak Amplitude (mm),Center Position (mm),Lockin Signal' (V),Lockin Signal (V),Range,M. Quad. Signal (emu),AC Moment (emu),AC M. Std Err. (emu),AC Phase (deg),AC Phase Std. Err. (deg),AC Susceptibility (emu/Oe),AC Suscept. Std Err. (emu/Oe),AC X' (emu/Oe),AC X' Std Err. (emu/Oe),AC X'' (emu/Oe),AC X'' Std Err. (emu/Oe),AC Drive (Oe),AC Frequency (Hz),AC Averaging Time (sec),AC Cycles,AC Range,AC Measure Type,AC Signal' (V),AC Signal'' (V),AC Trim Coil Ratio,AC Trim Coil Phase,Min. Temperature (K),Max. Temperature (K),Min. Field (Oe),Max. Field (Oe),Mass (grams),Motor Lag (deg),Pressure (Torr),Measure Count,Measurement Number,SQUID Status (code),Motor Status (code),Measure Status (code),Motor Current (amps),Motor Temp. (C),Temp. Status (code),Field Status (code),Chamber Status (code),Chamber Temp (K),Redirection State,Average Temp (K),Rotation Angle (deg),Rotator state,DC Moment Fixed Ctr (emu),DC Moment Err Fixed Ctr (emu),DC Moment Free Ctr (emu),DC Moment Err Free Ctr (emu),DC Fixed Fit,DC Free Fit,DC Calculated Center (mm),DC Calculated Center Err (mm),DC Scan Length (mm),DC Scan Time (s),DC Number of Points,DC Squid Drift,DC Min V (V),DC Max V (V),DC Scans per Measure,Sample Resistance,He3 Temperature,Sorb Resistance,Sorb Temperature,Map 05,Map 06,Map 07,Map 08,Map 09,Map 10,Map 11,Map 12,Map 13,Map 14,Map 15,Map 16
,3879884179.92681,50.0234622955322,69999.734375,-3.69860231077022E-4,1.02753219697451E-7,1,4,13.4005146026611,4.99393657229723,33.1300012767315,-0.458987024507457,-0.0683285336675693,1,2.62569623163654E-7,,,,,,,,,,,,,,,,,,,,,50.0231323242188,50.0237922668457,69999.734375,69999.734375,53.1663718780826,5.64580842106124,4.62671375274658,54,1,0,0,1,0.3009033203125,32.7468223571777,1,1,3,50.0231323242188,0,50.0234622955322,,,,,,,,,,,,,,,,,,,,,,,,,,,,,,,,,
,3879884400.21835,50.0010566711426,54999.58203125,-2.79220902690902E-4,5.56378917582038E-8,1,4,13.4005146026611,4.99376572233315,33.1300012767315,-0.346485629175765,-0.0516060568079445,1,1.7820312771038E-7,,,,,,,,,,,,,,,,,,,,,50.0009765625,50.0011367797852,54999.58203125,54999.58203125,53.4207919610922,5.6468893896576,4.67521095275879,54,2,0,0,1,0.302963256835937,33.7243423461914,1,1,3,50.0009765625,0,50.0010566711426,,,,,,,,,,,,,,,,,,,,,,,,,,,,,,,,,
,3879884635.85551,50.0002937316895,39999.68359375,-1.89195600630268E-4,4.46639446560269E-8,1,4,13.4005146026611,4.99386705598666,33.1300012767315,-0.234785310296321,-0.0349314147731702,1,1.50578507124419E-7,,,,,,,,,,,,,,,,,,,,,50.0002174377441,50.0003700256348,39999.68359375,39999.68359375,53.3543535369576,5.64702731954044,4.68607616424561,54,3,0,0,1,0.302886962890625,33.7243423461914,1,1,3,50.0002174377441,0,50.0002937316895,,,,,,,,,,,,,,,,,,,,,,,,,,,,,,,,,
,3879884917.39503,50.0135250091553,19999.603515625,-6.95544356198535E-5,1.98608929306261E-8,1,4,13.4005146026611,4.99385964273978,33.1300012767315,-0.0863067664638588,-0.0128936654505274,1,1.36335570469863E-8,,,,,,,,,,,,,,,,,,,,,50.0116577148438,50.0153923034668,19999.603515625,19999.603515625,53.3156629252556,5.6467787192497,4.69610548019409,54,1,0,0,1,0.300827026367188,34.2131004333496,1,1,3,50.0155067443848,0,50.0135250091553,,,,,,,,,,,,,,,,,,,,,,,,,,,,,,,,,
,3879885106.92394,50.004861831665,9999.794921875,-1.05089794433563E-5,1.29264839521592E-8,1,4,13.4005146026611,4.9939472173677,33.1399999558926,-0.0130453195381429,-0.00191532857570701,1,2.8512125886523E-8,,,,,,,,,,,,,,,,,,,,,50.0042877197266,50.0054359436035,9999.794921875,9999.794921875,53.4786324715153,5.64620968642537,4.70679378509521,54,2,0,0,1,0.301742553710937,33.7243423461914,1,1,3,50.0042877197266,0,50.004861831665,,,,,,,,,,,,,,,,,,,,,,,,,,,,,,,,,
,3879885194.20405,50.0153331756592,8499.791015625,-1.86175226824874E-6,1.18208125749738E-8,1,4,13.4005146026611,4.99379194803145,33.1300012767315,-0.00231054856336231,-3.42219929478655E-4,1,2.69905171197519E-9,,,,,,,,,,,,,,,,,,,,,50.0140838623047,50.0165824890137,8499.791015625,8499.791015625,53.447367330746,5.64665210250233,4.71174573898315,54,3,0,0,1,0.302276611328125,34.2131004333496,1,1,3,50.0140838623047,0,50.0153331756592,,,,,,,,,,,,,,,,,,,,,,,,,,,,,,,,,
,3879885295.49437,50.0231285095215,6499.630859375,9.38194740652059E-6,1.06492775748272E-8,1,4,13.4005146026611,4.99390864362118,33.1300012767315,0.0116520311790669,0.00167060388100171,1,-5.71245439229693E-8,,,,,,,,,,,,,,,,,,,,,50.0220375061035,50.0242195129395,6499.630859375,6499.630859375,53.394607405698,5.64629295357519,4.71075916290283,54,1,0,0,1,0.300216674804687,34.2131004333496,1,1,3,50.0242195129395,0,50.0231285095215,,,,,,,,,,,,,,,,,,,,,,,,,,,,,,,,,
,3879885382.54675,50.0065364837646,4999.60205078125,1.73447973928991E-5,7.64129606154908E-9,1,4,13.4005146026611,4.99380573650737,33.1399999558926,0.0215298776483845,0.00316260303061034,1,-4.58266834778223E-8,,,,,,,,,,,,,,,,,,,,,50.0058708190918,50.0072021484375,4999.60205078125,4999.60205078125,53.4305623175826,5.64641724379625,4.71716737747192,54,2,0,0,1,0.30426025390625,33.7243423461914,1,1,3,50.0058708190918,0,50.0065364837646,,,,,,,,,,,,,,,,,,,,,,,,,,,,,,,,,
,3879885470.35424,50.0264110565186,3499.736328125,2.43165140968185E-5,7.65062490540275E-9,1,4,13.4005146026611,4.99379350913815,33.1300012767315,0.0301784499916764,0.00446873891869878,1,-3.60813563717694E-8,,,,,,,,,,,,,,,,,,,,,50.0259246826172,50.0268974304199,3499.736328125,3499.736328125,53.5145873833999,5.64694445425742,4.71470785140991,54,3,0,0,1,0.302505493164063,34.2131004333496,1,1,3,50.0259246826172,0,50.0264110565186,,,,,,,,,,,,,,,,,,,,,,,,,,,,,,,,,
,3879885575.54242,50.0273418426514,2899.6416015625,2.63891833744009E-5,1.52430512637366E-8,1,4,13.4005146026611,4.99377705543487,33.1300012767315,0.0327132018404761,0.00509976764802194,1,1.62448083539941E-7,,,,,,,,,,,,,,,,,,,,,50.0251426696777,50.029541015625,2899.6416015625,2899.6416015625,53.3613881936306,5.64625839221867,4.70915460586548,53,1,68,0,0,0.303726196289063,33.7243423461914,1,1,3,50.0251426696777,0,50.0273418426514,,,,,,,,,,,,,,,,,,,,,,,,,,,,,,,,,
,3879885648.70735,50.0027103424072,2749.70288085938,2.68671028712151E-5,1.31306748883315E-8,1,4,13.4005146026611,4.99362650176796,33.1300012767315,0.0333138364080093,0.00512779372054132,1,1.13716154949883E-7,,,,,,,,,,,,,,,,,,,,,50.0024223327637,50.0029983520508,2749.70288085938,2749.70288085938,53.4286082462845,5.64697002181414,4.71228694915771,54,2,0,0,1,0.304183959960937,34.2131004333496,1,1,3,50.0024223327637,0,50.0027103424072,,,,,,,,,,,,,,,,,,,,,,,,,,,,,,,,,
,3879885723.97172,50.0156555175781,2599.68872070313,2.72680612475024E-5,1.03034361823493E-8,1,4,13.4005146026611,4.99366489747527,33.1399999558926,0.0338161666825277,0.00517230122136281,1,8.9562244080961E-8,,,,,,,,,,,,,,,,,,,,,50.0147361755371,50.0165748596191,2599.68872070313,2599.68872070313,53.3148812967364,5.64725529683938,4.72075700759888,54,3,0,0,1,0.304031372070313,33.7243423461914,1,1,3,50.0146636962891,0,50.0156555175781,,,,,,,,,,,,,,,,,,,,,,,,,,,,,,,,,
,3879885805.67194,50.0321254730225,2399.61083984375,2.76887787843145E-5,1.85911477327619E-8,1,4,13.4005146026611,4.99367509440361,33.1300012767315,0.0343214800017699,0.00536263755091745,1,1.80017640528017E-7,,,,,,,,,,,,,,,,,,,,,50.0304069519043,50.0338439941406,2399.61083984375,2399.61083984375,53.442286745371,5.64810481434216,4.72217750549316,53,1,68,0,0,0.302047729492188,34.2131004333496,1,1,3,50.0338439941406,0,50.0321254730225,,,,,,,,,,,,,,,,,,,,,,,,,,,,,,,,,
,3879885877.69514,50.0140838623047,2249.53369140625,2.79648217403494E-5,1.16993910361253E-8,1,4,13.4005146026611,4.99369877392526,33.1300012767315,0.0346757766197326,0.00533659586099753,1,1.17706099356346E-7,,,,,,,,,,,,,,,,,,,,,50.0129013061523,50.015266418457,2249.53369140625,2249.53369140625,53.5102884265441,5.6472941740412,4.71648979187012,53,2,68,0,0,0.302505493164063,33.7243423461914,1,1,3,50.0129013061523,0,50.0140838623047,,,,,,,,,,,,,,,,,,,,,,,,,,,,,,,,,
,3879885949.5758,50.0004940032959,2099.56982421875,2.81836920850695E-5,1.13824096367622E-8,1,4,13.4005146026611,4.99377755639685,33.1300012767315,0.0349527058697553,0.00534664695061902,1,9.29699633995377E-8,,,,,,,,,,,,,,,,,,,,,50.0004653930664,50.0005226135254,2099.56982421875,2099.56982421875,53.4102399760826,5.64748414097342,4.71618890762329,54,3,0,0,1,0.304946899414063,34.2131004333496,1,1,3,50.0004653930664,0,50.0004940032959,,,,,,,,,,,,,,,,,,,,,,,,,,,,,,,,,
,3879886030.35344,50.0173816680908,1899.78161621094,2.8247423643611E-5,2.12208287208763E-8,1,4,13.4005146026611,4.9937598731726,33.1399999558926,0.0350115540157955,0.00549251535026809,1,2.01019253948299E-7,,,,,,,,,,,,,,,,,,,,,50.0152130126953,50.0195503234863,1899.78161621094,1899.78161621094,53.5739911508614,5.64693347812229,4.72188329696655,54,1,0,0,1,0.302963256835937,33.7243423461914,1,1,3,50.0195503234863,0,50.0173816680908,,,,,,,,,,,,,,,,,,,,,,,,,,,,,,,,,
,3879886102.88537,50.0113487243652,1749.69189453125,2.82584815774546E-5,1.67975080258672E-8,1,4,13.4005146026611,4.9938761318845,33.1399999558926,0.0350399026039068,0.0054045974817227,1,1.28366122134154E-7,,,,,,,,,,,,,,,,,,,,,50.0102882385254,50.0124092102051,1749.69189453125,1749.69189453125,53.5736003366018,5.64685725125489,4.72189617156982,53,2,68,0,0,0.301437377929687,34.2131004333496,1,1,3,50.0102882385254,0,50.0113487243652,,,,,,,,,,,,,,,,,,,,,,,,,,,,,,,,,
,3879886176.52559,50.0100574493408,1599.53918457031,2.81439182397864E-5,1.23623438524041E-8,1,4,13.4005146026611,4.99400177050646,33.1399999558926,0.0349062534996953,0.00533489951815227,1,8.9181744558689E-8,,,,,,,,,,,,,,,,,,,,,50.0093383789063,50.0107765197754,1599.53918457031,1599.53918457031,53.3598249365922,5.64653503049368,4.72691535949707,53,3,68,0,0,0.3021240234375,34.2131004333496,1,1,3,50.0092735290527,0,50.0100574493408,,,,,,,,,,,,,,,,,,,,,,,,,,,,,,,,,
,3879886258.12525,50.0046844482422,1399.68811035156,2.77081807337149E-5,2.22018256278134E-8,1,4,13.4005146026611,4.99377763090158,33.1300012767315,0.0343383780731108,0.00542095998306319,1,2.23995288459541E-7,,,,,,,,,,,,,,,,,,,,,50.0041885375977,50.0051803588867,1399.68811035156,1399.68811035156,53.5208404115537,5.64760397382146,4.71953105926514,53,1,68,0,0,0.302886962890625,33.7243423461914,1,1,3,50.0041885375977,0,50.0046844482422,,,,,,,,,,,,,,,,,,,,,,,,,,,,,,,,,
,3879886329.19564,50.0009651184082,1249.63610839844,2.72193557180156E-5,1.4750765904371E-8,1,4,13.4005146026611,4.99383609337473,33.1300012767315,0.0337468631857087,0.00523365479595468,1,1.46094583281636E-7,,,,,,,,,,,,,,,,,,,,,50.000919342041,50.0010108947754,1249.63610839844,1249.63610839844,53.2550867150153,5.64749331853712,4.72494506835937,54,2,0,0,1,0.302963256835937,34.2131004333496,1,1,3,50.000919342041,0,50.0009651184082,,,,,,,,,,,,,,,,,,,,,,,,,,,,,,,,,
,3879886400.94927,50.0263385772705,1099.78540039062,2.66039328311887E-5,6.2722857632845E-8,1,4,13.4005146026611,4.99375952290736,33.1399999558926,0.0329793414990661,0.00514064880720558,1,1.63291030959392E-7,,,,,,,,,,,,,,,,,,,,,50.0257987976074,50.0268783569336,1099.78540039062,1099.78540039062,53.3367668952749,5.64705963445363,4.71967697143555,54,3,0,0,1,0.300445556640625,33.7243423461914,1,1,3,50.0257987976074,0,50.0263385772705,,,,,,,,,,,,,,,,,,,,,,,,,,,,,,,,,
,3879886483.25755,50.0046138763428,899.770690917969,2.52288974605519E-5,2.82745000225319E-8,1,4,13.4005146026611,4.99377543248275,33.1399999558926,0.0312611008347657,0.00496741908071612,1,2.29356511878338E-7,,,,,,,,,,,,,,,,,,,,,50.004280090332,50.0049476623535,899.770690917969,899.770690917969,53.5126333121018,5.64746009330235,4.7164831161499,54,1,0,0,1,0.302352905273438,33.7243423461914,1,1,3,50.004280090332,0,50.0046138763428,,,,,,,,,,,,,,,,,,,,,,,,,,,,,,,,,
,3879886554.50207,50.0347118377686,749.756469726563,2.39083419965909E-5,1.97182263274722E-8,1,4,13.4005146026611,4.9936522665719,33.1399999558926,0.0296376923745611,0.00461423493207014,1,1.42386561920987E-7,,,,,,,,,,,,,,,,,,,,,50.0341644287109,50.0352592468262,749.756469726563,749.756469726563,53.3695952930826,5.64751324783886,4.7235894203186,54,2,0,0,1,0.302963256835937,33.2355842590332,1,1,3,50.035213470459,0,50.0347118377686,,,,,,,,,,,,,,,,,,,,,,,,,,,,,,,,,
,3879886625.43774,50.0135650634766,599.993957519531,2.21942098935989E-5,1.48574226826011E-8,1,4,13.4005146026611,4.99357014556606,33.1300012767315,0.0275142008966628,0.00426963791973375,1,1.21155164924282E-7,,,,,,,,,,,,,,,,,,,,,50.0131301879883,50.0139999389648,599.993957519531,599.993957519531,53.2582132290922,5.64793664127549,4.724693775177,53,3,68,0,0,0.301971435546875,33.2355842590332,1,1,3,50.0131301879883,0,50.0135650634766,,,,,,,,,,,,,,,,,,,,,,,,,,,,,,,,,
,3879886707.41167,50.0222682952881,399.853332519531,1.90587527456631E-5,2.81878628062367E-8,1,4,13.4005146026611,4.99361413201064,33.1300012767315,0.023600964404853,0.00384361763403627,1,2.46795241983146E-7,,,,,,,,,,,,,,,,,,,,,50.0211486816406,50.0233879089355,399.853332519531,399.853332519531,53.320352696371,5.64809221080188,4.71803331375122,53,1,68,0,0,0.303573608398438,32.2580642700195,1,1,3,50.0233879089355,0,50.0222682952881,,,,,,,,,,,,,,,,,,,,,,,,,,,,,,,,,
,3879886779.78599,50.0292434692383,249.914611816406,1.59195230079752E-5,1.52835736039253E-8,1,4,13.4005146026611,4.99370462017217,33.1300012767315,0.019723715908923,0.00314614038509475,1,1.54189711947241E-7,,,,,,,,,,,,,,,,,,,,,50.0284042358398,50.0300827026367,249.914611816406,249.914611816406,53.3453648089864,5.64780570173974,4.72803401947022,54,2,0,0,1,0.302276611328125,33.7243423461914,1,1,3,50.0300827026367,0,50.0292434692383,,,,,,,,,,,,,,,,,,,,,,,,,,,,,,,,,
,3879886860.12367,50.0071277618408,100.038864135742,1.18038355292679E-5,1.46362796400703E-8,1,4,13.4005146026611,4.99375553364083,33.1300012767315,0.0146225136498693,0.00234765642156665,1,1.26300842378774E-7,,,,,,,,,,,,,,,,,,,,,50.0065612792969,50.0076942443848,100.038864135742,100.038864135742,53.3402842236114,5.64765309790595,4.72023725509644,54,3,0,0,1,0.303192138671875,33.7243423461914,1,1,3,50.0065612792969,0,50.0071277618408,,,,,,,,,,,,,,,,,,,,,,,,,,,,,,,,,
,3879886965.56974,50.0025825500488,-99.9255676269531,3.81850922422806E-6,3.30790540552597E-7,1,4,13.4005146026611,4.99381519737299,33.1399999558926,0.0047314169745577,7.52830336646612E-4,1,3.55042235060156E-8,,,,,,,,,,,,,,,,,,,,,50.0020599365234,50.0031051635742,-99.9255676269531,-99.9255676269531,53.2777539420729,5.64757062823774,4.72591400146484,52,1,68,0,0,0.301513671875,33.2355842590332,1,1,3,50.0020599365234,0,50.0025825500488,,,,,,,,,,,,,,,,,,,,,,,,,,,,,,,,,
,3879887080.98085,50.0152721405029,-249.889434814453,-2.2640478276744E-6,1.07746461231925E-8,1,4,13.4005146026611,4.99378866933624,33.1399999558926,-0.00283412416403267,-2.53696245327579E-4,10,1.34224293292383E-7,,,,,,,,,,,,,,,,,,,,,50.0151557922363,50.0153884887695,-249.889434814453,-249.889434814453,53.4051593907076,5.64716125994524,4.71923542022705,54,2,0,0,1,0.300674438476562,33.7243423461914,1,1,3,50.0151557922363,0,50.0152721405029,,,,,,,,,,,,,,,,,,,,,,,,,,,,,,,,,
,3879887192.81027,50.0006675720215,-399.853332519531,-8.04303911640743E-6,7.90109439769115E-9,1,4,13.4005146026611,4.99366769921197,33.1300012767315,-0.00999562593920505,-0.00138433457909792,1,8.74641015986093E-8,,,,,,,,,,,,,,,,,,,,,50.0005989074707,50.0007362365723,-399.853332519531,-399.853332519531,53.4368153457364,5.64819189275615,4.71874952316284,54,3,0,0,1,0.303573608398438,33.7243423461914,1,1,3,50.0005989074707,0,50.0006675720215,,,,,,,,,,,,,,,,,,,,,,,,,,,,,,,,,
,3879887290.42229,50.0154304504395,-599.767456054687,-1.42010616250222E-5,1.74168712321937E-8,1,4,13.4005146026611,4.99373119528495,33.1399999558926,-0.0176588511576797,-0.00237794590984565,1,2.07884671875283E-7,,,,,,,,,,,,,,,,,,,,,50.0140533447266,50.0168075561523,-599.767456054687,-599.767456054687,53.2879151128229,5.64794254072391,4.72691297531128,54,1,0,0,1,0.301666259765625,33.7243423461914,1,1,3,50.0168075561523,0,50.0154304504395,,,,,,,,,,,,,,,,,,,,,,,,,,,,,,,,,
,3879887361.96077,50.0207614898682,-749.731262207031,-1.77310303883962E-5,1.86911737901455E-8,1,4,13.4005146026611,4.99371778903532,33.1300012767315,-0.0220293403569728,-0.00309537828895343,1,1.57721894069625E-7,,,,,,,,,,,,,,,,,,,,,50.0205268859863,50.02099609375,-749.731262207031,-749.731262207031,53.4133664901595,5.64799932909326,4.72140073776245,53,2,68,0,0,0.302810668945313,33.7243423461914,1,1,3,50.02099609375,0,50.0207614898682,,,,,,,,,,,,,,,,,,,,,,,,,,,,,,,,,
,3879887433.695,50.028392791748,-899.695129394531,-2.04210900021549E-5,1.7758235255444E-8,1,4,13.4005146026611,4.99367342007996,33.1399999558926,-0.0253684550187803,-0.00358330740939602,1,1.66854102347307E-7,,,,,,,,,,,,,,,,,,,,,50.0270805358887,50.0297050476074,-899.695129394531,-899.695129394531,53.2926048839383,5.64741021656521,4.72069072723389,54,3,0,0,1,0.302581787109375,34.2131004333496,1,1,3,50.0270805358887,0,50.028392791748,,,,,,,,,,,,,,,,,,,,,,,,,,,,,,,,,
,3879887516.11273,50.0070343017578,-1099.63439941406,-2.31469262310506E-5,5.75175813217359E-8,1,4,13.4005146026611,4.99362434071884,33.1399999558926,-0.0287688318178373,-0.00396425876808266,1,2.67545510111489E-7,,,,,,,,,,,,,,,,,,,,,50.0064659118652,50.0076026916504,-1099.63439941406,-1099.63439941406,53.4426775596307,5.6476088452046,4.72774648666382,54,1,0,0,1,0.30242919921875,33.7243423461914,1,1,3,50.0064659118652,0,50.0070343017578,,,,,,,,,,,,,,,,,,,,,,,,,,,,,,,,,
,3879887588.06912,50.0118255615234,-1249.59838867188,-2.45103647212212E-5,1.20646723236942E-8,1,4,13.4005146026611,4.99365767178487,33.1300012767315,-0.0304401383154649,-0.00435535137000109,1,1.56329608827676E-7,,,,,,,,,,,,,,,,,,,,,50.0117950439453,50.0118560791016,-1249.59838867188,-1249.59838867188,53.3887451918037,5.64786240893185,4.73079061508179,54,2,0,0,1,0.30303955078125,33.2355842590332,1,1,3,50.0117950439453,0,50.0118255615234,,,,,,,,,,,,,,,,,,,,,,,,,,,,,,,,,
,3879887660.50312,50.0066165924072,-1399.53698730469,-2.5559788043003E-5,9.45469783028957E-9,1,4,13.4005146026611,4.99360825034688,33.1300012767315,-0.0317361721794907,-0.00458745879142591,1,1.26194661980518E-7,,,,,,,,,,,,,,,,,,,,,50.0060348510742,50.0071983337402,-1399.53698730469,-1399.53698730469,53.3953890342172,5.64757659072807,4.72234964370728,53,3,68,0,0,0.302810668945313,33.7243423461914,1,1,3,50.0060348510742,0,50.0066165924072,,,,,,,,,,,,,,,,,,,,,,,,,,,,,,,,,
,3879887742.65213,50.0263786315918,-1599.57690429687,-2.65383358454714E-5,1.16613451994666E-8,1,4,13.4005146026611,4.99366188199335,33.1399999558926,-0.0329628854816751,-0.00468823051868988,1,1.91416413434086E-7,,,,,,,,,,,,,,,,,,,,,50.0234336853027,50.0293235778809,-1599.57690429687,-1599.57690429687,53.289869184121,5.64768376455843,4.72086334228516,54,1,0,0,1,0.301971435546875,33.7243423461914,1,1,3,50.0293235778809,0,50.0263786315918,,,,,,,,,,,,,,,,,,,,,,,,,,,,,,,,,
,3879887815.17997,50.0044097900391,-1749.55346679687,-2.69829622352393E-5,4.68572963436955E-8,1,4,13.4005146026611,4.99361087986382,33.1399999558926,-0.033511285465324,-0.00478933428052578,1,1.76388341399295E-7,,,,,,,,,,,,,,,,,,,,,50.0040550231934,50.0047645568848,-1749.55346679687,-1749.55346679687,53.4133664901595,5.64749251421074,4.72910642623901,54,2,0,0,1,0.303421020507812,33.7243423461914,1,1,3,50.0040168762207,0,50.0044097900391,,,,,,,,,,,,,,,,,,,,,,,,,,,,,,,,,
,3879887887.62105,50.0304565429687,-1899.8193359375,-2.72038995686038E-5,1.0473566917388E-8,1,4,13.4005146026611,4.99357587628994,33.1399999558926,-0.0337749204193152,-0.00489818890436524,1,1.21666038429919E-7,,,,,,,,,,,,,,,,,,,,,50.0293197631836,50.0315933227539,-1899.8193359375,-1899.8193359375,53.4082859047845,5.6480455938146,4.7209939956665,54,3,0,0,1,0.30181884765625,33.7243423461914,1,1,3,50.029182434082,0,50.0304565429687,,,,,,,,,,,,,,,,,,,,,,,,,,,,,,,,,
,3879887969.66034,50.0046062469482,-2099.80908203125,-2.73455021351173E-5,2.70092477126107E-8,1,4,13.4005146026611,4.99360727945065,33.1399999558926,-0.0339575242995933,-0.00488028731654692,1,1.57311985814468E-7,,,,,,,,,,,,,,,,,,,,,50.0041580200195,50.005054473877,-2099.80908203125,-2099.80908203125,53.3629514506691,5.6482422432625,4.72448873519897,52,1,68,0,0,0.300750732421875,33.7243423461914,1,1,3,50.0041313171387,0,50.0046062469482,,,,,,,,,,,,,,,,,,,,,,,,,,,,,,,,,
,3879888041.43775,50.0092544555664,-2249.78540039062,-2.7241234741604E-5,8.34751887565119E-9,1,4,13.4005146026611,4.99352757415826,33.1300012767315,-0.0338237280780354,-0.00488537479005268,1,1.37525784200011E-7,,,,,,,,,,,,,,,,,,,,,50.0085830688477,50.0099258422852,-2249.78540039062,-2249.78540039062,53.430171503323,5.64855673271868,4.7280421257019,53,2,64,0,0,0.303115844726562,33.2355842590332,1,1,3,50.0085830688477,0,50.0092544555664,,,,,,,,,,,,,,,,,,,,,,,,,,,,,,,,,
,3879888113.41553,50.0291385650635,-2399.69897460938,-2.70721621376969E-5,6.70910586561508E-9,1,4,13.4005146026611,4.99353837995552,33.1300012767315,-0.0336072192520777,-0.00489974882097713,1,1.00660116829894E-7,,,,,,,,,,,,,,,,,,,,,50.0280227661133,50.0302543640137,-2399.69897460938,-2399.69897460938,53.4332980173999,5.64753113564574,4.72856616973877,54,3,0,0,1,0.303573608398438,33.7243423461914,1,1,3,50.0278472900391,0,50.0291385650635,,,,,,,,,,,,,,,,,,,,,,,,,,,,,,,,,
,3879888195.49841,50.0251426696777,-2599.7265625,-2.67120439582274E-5,1.06559822001242E-8,1,4,13.4005146026611,4.99342978278208,33.1300012767315,-0.0331686734209591,-0.00477083212393321,1,1.50577594907384E-7,,,,,,,,,,,,,,,,,,,,,50.0242118835449,50.0260734558105,-2599.7265625,-2599.7265625,53.411803233121,5.64827391702251,4.73351573944092,54,1,0,0,1,0.300979614257812,33.7243423461914,1,1,3,50.0260734558105,0,50.0251426696777,,,,,,,,,,,,,,,,,,,,,,,,,,,,,,,,,
,3879888267.1019,50.0057926177978,-2749.6650390625,-2.63605012376814E-5,1.10750852089858E-8,1,4,13.4005146026611,4.99345211501176,33.1399999558926,-0.0327284940506845,-0.00473394223004479,1,1.27746818185498E-7,,,,,,,,,,,,,,,,,,,,,50.0055046081543,50.0060806274414,-2749.6650390625,-2749.6650390625,53.2242123885056,5.64802968460168,4.72154855728149,52,2,68,0,0,0.304183959960937,33.7243423461914,1,1,3,50.0055046081543,0,50.0057926177978,,,,,,,,,,,,,,,,,,,,,,,,,,,,,,,,,
,3879888339.11674,50.0118713378906,-2899.60375976562,-2.59475584817383E-5,7.47695190581259E-9,1,4,13.4005146026611,4.99345060866541,33.1300012767315,-0.0322111199162131,-0.00469094529253522,1,1.00627643546658E-7,,,,,,,,,,,,,,,,,,,,,50.0118370056152,50.011905670166,-2899.60375976562,-2899.60375976562,53.4055502049672,5.64846642412305,4.72170400619507,53,3,68,0,0,0.30303955078125,33.2355842590332,1,1,3,50.0118370056152,0,50.0118713378906,,,,,,,,,,,,,,,,,,,,,,,,,,,,,,,,,
,3879888442.44543,50.0157470703125,-3499.58520507812,-2.38312881714458E-5,6.72947105075985E-9,1,4,13.4005146026611,4.99356251902229,33.1300012767315,-0.0295713539737812,-0.00439921128132876,1,1.92996436284128E-8,,,,,,,,,,,,,,,,,,,,,50.0145149230957,50.0169792175293,-3499.58520507812,-3499.58520507812,53.4164930042364,5.64749653054318,4.73222398757935,54,1,0,0,1,0.304183959960937,33.2355842590332,1,1,3,50.0145149230957,0,50.0157470703125,,,,,,,,,,,,,,,,,,,,,,,,,,,,,,,,,
,3879888526.43083,50.0335788726807,-4999.7275390625,-1.69154592587741E-5,9.03221292867562E-9,1,4,13.4005146026611,4.99349560384862,33.1300012767315,-0.020988843960217,-0.00312599700391892,1,1.08831693880646E-8,,,,,,,,,,,,,,,,,,,,,50.0332794189453,50.033878326416,-4999.7275390625,-4999.7275390625,53.3238700247076,5.64846106345253,4.72373867034912,54,2,0,0,1,0.302734375,33.2355842590332,1,1,3,50.033878326416,0,50.0335788726807,,,,,,,,,,,,,,,,,,,,,,,,,,,,,,,,,
,3879888611.39158,50.0075092315674,-6499.744140625,-8.96506084592403E-6,1.21429857127873E-8,1,4,13.4005146026611,4.99350843841022,33.1300012767315,-0.0111235467228506,-0.00165954173004881,1,3.52582108975094E-9,,,,,,,,,,,,,,,,,,,,,50.0068664550781,50.0081520080566,-6499.744140625,-6499.744140625,53.1429230225056,5.64811559052144,4.72209072113037,54,3,0,0,1,0.302810668945313,33.2355842590332,1,1,3,50.0068664550781,0,50.0075092315674,,,,,,,,,,,,,,,,,,,,,,,,,,,,,,,,,
,3879888709.85428,50.0349998474121,-8499.7158203125,2.2692489408095E-6,1.38711341555934E-8,1,4,13.4005146026611,4.99345545654918,33.1399999558926,0.00282389089266038,3.64410027167414E-4,1,-4.57465033586951E-8,,,,,,,,,,,,,,,,,,,,,50.03369140625,50.0363082885742,-8499.7158203125,-8499.7158203125,53.3852278634672,5.64847294938208,4.73206615447998,54,1,0,0,1,0.3033447265625,34.2131004333496,1,1,3,50.0363082885742,0,50.0349998474121,,,,,,,,,,,,,,,,,,,,,,,,,,,,,,,,,
,3879888794.55524,50.0124607086182,-9999.64453125,1.08790002456789E-5,1.07077311727223E-8,1,4,13.4005146026611,4.99358350536764,33.1300012767315,0.0135041292727348,0.00197680066176313,1,-3.41619492253337E-8,,,,,,,,,,,,,,,,,,,,,50.011058807373,50.0138626098633,-9999.64453125,-9999.64453125,53.3699861073422,5.64737410103954,4.72244215011597,54,2,0,0,1,0.302505493164063,33.7243423461914,1,1,3,50.011058807373,0,50.0124607086182,,,,,,,,,,,,,,,,,,,,,,,,,,,,,,,,,
,3879888981.55139,50.0364551544189,-19999.666015625,6.99030684863127E-5,2.02666226946053E-8,1,4,13.4005146026611,4.99343582454632,33.1399999558926,0.0867399895212817,0.0128836637950896,1,-7.26128310512283E-8,,,,,,,,,,,,,,,,,,,,,50.0355911254883,50.0373191833496,-19999.666015625,-19999.666015625,53.2656387000249,5.64791862329215,4.72897911071777,54,3,0,0,1,0.304031372070313,33.7243423461914,1,1,3,50.0355911254883,0,50.0364551544189,,,,,,,,,,,,,,,,,,,,,,,,,,,,,,,,,
,3879889265.25203,50.0024147033691,-39999.66015625,1.89559556479161E-4,3.73388929122499E-8,1,4,13.4005146026611,4.99361415815265,33.1300012767315,0.235216762410406,0.0350196362001531,1,-1.31922317716838E-7,,,,,,,,,,,,,,,,,,,,,50.0021476745605,50.0026817321777,-39999.66015625,-39999.66015625,53.3551351654768,5.6472613221611,4.7213888168335,54,1,0,0,1,0.303955078125,33.7243423461914,1,1,3,50.0021476745605,0,50.0024147033691,,,,,,,,,,,,,,,,,,,,,,,,,,,,,,,,,
,3879889494.88717,50.0089588165283,-54999.76953125,2.79637415036367E-4,8.53665845124516E-8,1,4,13.4005146026611,4.99353885981328,33.1300012767315,0.347030620743726,0.0513440093603022,10,-4.49072372248807E-7,,,,,,,,,,,,,,,,,,,,,50.0088043212891,50.0091133117676,-54999.76953125,-54999.76953125,53.2027176042268,5.64775360010014,4.72613430023193,54,2,0,0,1,0.304107666015625,34.2131004333496,1,1,3,50.0087623596191,0,50.0089588165283,,,,,,,,,,,,,,,,,,,,,,,,,,,,,,,,,
,3879889730.00506,50.0079402923584,-69999.546875,3.6940459623947E-4,1.09121181354045E-7,1,4,13.4005146026611,4.99360275715168,33.1300012767315,0.458337496474141,0.0685131855417196,1,-4.04269893946442E-8,,,,,,,,,,,,,,,,,,,,,50.0077819824219,50.0080986022949,-69999.546875,-69999.546875,53.1995910901499,5.64827348980976,4.7236499786377,54,3,0,0,1,0.300445556640625,33.7243423461914,1,1,3,50.0077819824219,0,50.0079402923584,,,,,,,,,,,,,,,,,,,,,,,,,,,,,,,,,
,3879890012.19776,50.0174579620361,-49999.6640625,2.49265292264598E-4,7.50549531728014E-8,1,4,13.4005146026611,4.99360849773311,33.1300012767315,0.309284663525975,0.046170272553716,1,-7.63176095824049E-8,,,,,,,,,,,,,,,,,,,,,50.0138816833496,50.0210342407227,-49999.6640625,-49999.6640625,53.5122424978422,5.64893943021682,4.73257160186768,54,1,0,0,1,0.302963256835937,33.7243423461914,1,1,3,50.0210342407227,0,50.0174579620361,,,,,,,,,,,,,,,,,,,,,,,,,,,,,,,,,
,3879890234.88147,50.0013523101807,-34999.515625,1.59312032590339E-4,3.67252209857387E-8,1,4,13.4005146026611,4.99358166897596,33.1300012767315,0.197676157989046,0.0294706656701327,1,-7.92049261586232E-8,,,,,,,,,,,,,,,,,,,,,50.0011901855469,50.0015144348145,-34999.515625,-34999.515625,53.3543535369576,5.64843967770418,4.72540807723999,54,2,0,0,1,0.303115844726562,33.7243423461914,1,1,3,50.0011901855469,0,50.0013523101807,,,,,,,,,,,,,,,,,,,,,,,,,,,,,,,,,
,3879890456.68458,50.0190868377686,-19999.703125,6.96158799977408E-5,2.3393109956901E-8,1,4,13.4005146026611,4.9935788922432,33.1300012767315,0.0863831647408022,0.0128575263658638,1,-5.11343769055463E-8,,,,,,,,,,,,,,,,,,,,,50.0185928344727,50.0195808410645,-19999.703125,-19999.703125,53.2632938144672,5.64845107560256,4.72190046310425,54,3,0,0,1,0.30242919921875,34.2131004333496,1,1,3,50.0185928344727,0,50.0190868377686,,,,,,,,,,,,,,,,,,,,,,,,,,,,,,,,,
,3879890658.92119,50.0169525146484,-9500.34375,7.62433329227949E-6,1.21637032950709E-8,1,4,13.4005146026611,4.99355850157024,33.1399999558926,0.00945463987197951,0.00144820932965752,1,2.66882723424066E-8,,,,,,,,,,,,,,,,,,,,,50.0161018371582,50.0178031921387,-9500.34375,-9500.34375,53.4329072031403,5.64864258853245,4.7323431968689,54,1,0,0,1,0.303192138671875,34.2131004333496,1,1,3,50.0178642272949,0,50.0169525146484,,,,,,,,,,,,,,,,,,,,,,,,,,,,,,,,,
,3879890743.3787,50.0041732788086,-8000.40234375,-9.39192546750393E-7,1.11233574298796E-8,1,4,13.4005146026611,4.99373126088553,33.1300012767315,-0.00116972039881329,-1.44928805648504E-4,1,2.36919800617527E-8,,,,,,,,,,,,,,,,,,,,,50.0037155151367,50.0046310424805,-8000.40234375,-8000.40234375,53.3449739947268,5.64778337662347,4.73467588424683,54,2,0,0,1,0.302886962890625,33.7243423461914,1,1,3,50.0036582946777,0,50.0041732788086,,,,,,,,,,,,,,,,,,,,,,,,,,,,,,,,,
,3879890827.56739,50.0082168579102,-6500.37353515625,-9.33681746307022E-6,9.92502118982138E-9,1,4,13.4005146026611,4.99373820855342,33.1399999558926,-0.0115894254396899,-0.00170260777002869,1,2.4515511379049E-8,,,,,,,,,,,,,,,,,,,,,50.0076217651367,50.0088119506836,-6500.37353515625,-6500.37353515625,53.457528501496,5.64747758742147,4.72751522064209,54,3,0,0,1,0.301513671875,34.2131004333496,1,1,3,50.0076217651367,0,50.0082168579102,,,,,,,,,,,,,,,,,,,,,,,,,,,,,,,,,
,3879890928.94075,50.0175666809082,-4500.48974609375,-1.97915053547103E-5,1.07573179741196E-8,1,4,13.4005146026611,4.9938317482856,33.1399999558926,-0.0245718296997218,-0.00357730265203456,1,7.76397861691444E-8,,,,,,,,,,,,,,,,,,,,,50.016429901123,50.0187034606934,-4500.48974609375,-4500.48974609375,53.2929956981979,5.64710036077634,4.73219013214111,54,1,0,0,1,0.301513671875,33.7243423461914,1,1,3,50.016429901123,0,50.0175666809082,,,,,,,,,,,,,,,,,,,,,,,,,,,,,,,,,
,3879891012.70282,50.0081481933594,-3000.37280273438,-2.61252250298098E-5,7.75355375952146E-9,1,4,13.4005146026611,4.99379433891649,33.1300012767315,-0.032426444489052,-0.00477938484148286,1,5.62934099754638E-8,,,,,,,,,,,,,,,,,,,,,50.007926940918,50.0083694458008,-3000.37280273438,-3000.37280273438,53.2351551877748,5.64731872564306,4.73498821258545,54,2,0,0,1,0.3033447265625,33.7243423461914,1,1,3,50.0083694458008,0,50.0081481933594,,,,,,,,,,,,,,,,,,,,,,,,,,,,,,,,,
,3879891102.15713,50.0336074829102,-2900.42211914063,-2.63756444967642E-5,1.26700706403494E-8,1,4,13.4005146026611,4.99384738455393,33.1300012767315,-0.0327136204977965,-0.00498657221010918,1,-7.31653835566184E-8,,,,,,,,,,,,,,,,,,,,,50.0325164794922,50.0346984863281,-2900.42211914063,-2900.42211914063,53.4844946854095,5.64741350633838,4.72941160202026,54,3,0,0,1,0.303726196289063,33.7243423461914,1,1,3,50.0325164794922,0,50.0336074829102,,,,,,,,,,,,,,,,,,,,,,,,,,,,,,,,,
,3879891185.15105,50.0141124725342,-2700.35693359375,-2.6935090157925E-5,1.75975707368152E-8,1,4,13.4005146026611,4.99377341885523,33.1399999558926,-0.033393317039731,-0.0051824047577454,1,-1.47388614459612E-7,,,,,,,,,,,,,,,,,,,,,50.0138893127441,50.0143356323242,-2700.35693359375,-2700.35693359375,53.3922625201403,5.64761562489777,4.73538732528687,54,1,0,0,1,0.3009033203125,33.7243423461914,1,1,3,50.0143356323242,0,50.0141124725342,,,,,,,,,,,,,,,,,,,,,,,,,,,,,,,,,
,3879891256.61416,50.0291404724121,-2550.46850585938,-2.73363129590599E-5,1.30477869545364E-8,1,4,13.4005146026611,4.99381925810744,33.1300012767315,-0.0338978316422724,-0.00521518323296255,1,-1.1373162242211E-7,,,,,,,,,,,,,,,,,,,,,50.028018951416,50.0302619934082,-2550.46850585938,-2550.46850585938,53.411803233121,5.64765260816867,4.72849798202515,53,2,68,0,0,0.302505493164063,34.2131004333496,1,1,3,50.028018951416,0,50.0291404724121,,,,,,,,,,,,,,,,,,,,,,,,,,,,,,,,,
,3879891328.09842,50.0095405578613,-2400.40380859375,-2.76793395892866E-5,1.10834837375249E-8,1,4,13.4005146026611,4.99375082360986,33.1300012767315,-0.0343262353365938,-0.00525579368814509,1,-9.52274766427904E-8,,,,,,,,,,,,,,,,,,,,,50.0091781616211,50.0099029541016,-2400.40380859375,-2400.40380859375,53.4039869479287,5.64766256526353,4.73078489303589,54,3,0,0,1,0.302047729492188,33.7243423461914,1,1,3,50.0091438293457,0,50.0095405578613,,,,,,,,,,,,,,,,,,,,,,,,,,,,,,,,,
,3879891408.97858,50.0247802734375,-2200.38916015625,-2.79870010744694E-5,1.60121555425138E-8,1,4,13.4005146026611,4.99366071004988,33.1300012767315,-0.0346925463666095,-0.00541003613655365,1,-1.73624532612146E-7,,,,,,,,,,,,,,,,,,,,,50.0226707458496,50.0268898010254,-2200.38916015625,-2200.38916015625,53.2832253417076,5.64765897987104,4.72717189788818,54,1,0,0,1,0.301361083984375,33.7243423461914,1,1,3,50.0268898010254,0,50.0247802734375,,,,,,,,,,,,,,,,,,,,,,,,,,,,,,,,,
,3879891481.07813,50.0186977386475,-2050.34985351562,-2.81736508862693E-5,1.40486909258497E-8,1,4,13.4005146026611,4.99374492123589,33.1300012767315,-0.0349378349535036,-0.00535871909408511,1,-1.04241027277356E-7,,,,,,,,,,,,,,,,,,,,,50.0171051025391,50.0202903747559,-2050.34985351562,-2050.34985351562,53.4477581450057,5.64792284288426,4.73353338241577,54,2,0,0,1,0.302276611328125,33.7243423461914,1,1,3,50.0171051025391,0,50.0186977386475,,,,,,,,,,,,,,,,,,,,,,,,,,,,,,,,,
,3879891552.24527,50.0194759368897,-1900.38586425781,-2.82579770546562E-5,1.08348510788858E-8,1,4,13.4005146026611,4.99372372365102,33.1300012767315,-0.0350450337913757,-0.005355773169956,1,-8.92777600106762E-8,,,,,,,,,,,,,,,,,,,,,50.0177154541016,50.0212364196777,-1900.38586425781,-1900.38586425781,53.416883818496,5.64718683775628,4.72905445098877,54,3,0,0,1,0.302352905273438,34.2131004333496,1,1,3,50.0177154541016,0,50.0194759368897,,,,,,,,,,,,,,,,,,,,,,,,,,,,,,,,,
,3879891632.61218,50.0108737945557,-1700.13195800781,-2.81718257648745E-5,2.15307989098388E-8,1,4,13.4005146026611,4.99397121268959,33.1300012767315,-0.0349243439489679,-0.00544859157723362,1,-1.76667805428814E-7,,,,,,,,,,,,,,,,,,,,,50.009895324707,50.0118522644043,-1700.13195800781,-1700.13195800781,53.3903084488422,5.64738159476643,4.73311996459961,53,1,68,0,0,0.302505493164063,34.2131004333496,1,1,3,50.009895324707,0,50.0108737945557,,,,,,,,,,,,,,,,,,,,,,,,,,,,,,,,,
,3879891703.96515,50.0387630462646,-1550.14294433594,-2.80094986357079E-5,1.59762242501274E-8,1,4,13.4005146026611,4.9939921914039,33.1300012767315,-0.0347325247996092,-0.00535564896803545,1,-1.26023446849276E-7,,,,,,,,,,,,,,,,,,,,,50.0376739501953,50.039852142334,-1550.14294433594,-1550.14294433594,53.3191802535922,5.64736947616526,4.72857761383057,53,2,68,0,0,0.301513671875,33.7243423461914,1,1,3,50.0376739501953,0,50.0387630462646,,,,,,,,,,,,,,,,,,,,,,,,,,,,,,,,,
,3879891776.09736,50.0194263458252,-1400.103515625,-2.77097496458947E-5,1.30357182310206E-8,1,4,13.4005146026611,4.99394498606684,33.1300012767315,-0.0343656267314858,-0.00526314489791357,1,-9.6371970278311E-8,,,,,,,,,,,,,,,,,,,,,50.0180320739746,50.0208206176758,-1400.103515625,-1400.103515625,53.498173184496,5.64750755500003,4.7282280921936,54,3,0,0,1,0.303421020507812,32.7468223571777,1,1,3,50.0180320739746,0,50.0194263458252,,,,,,,,,,,,,,,,,,,,,,,,,,,,,,,,,
,3879891856.93669,50.0129947662354,-1200.12646484375,-2.69326993189186E-5,1.93057399411396E-8,1,4,13.4005146026611,4.99390263751878,33.1399999558926,-0.0333835604574631,-0.00523562980077111,1,-1.90489560769735E-7,,,,,,,,,,,,,,,,,,,,,50.0120391845703,50.0139503479004,-1200.12646484375,-1200.12646484375,53.3926533343999,5.64709724735594,4.72547817230225,52,1,68,0,0,0.301589965820313,33.7243423461914,1,1,3,50.0120391845703,0,50.0129947662354,,,,,,,,,,,,,,,,,,,,,,,,,,,,,,,,,
,3879891927.7437,50.0017681121826,-1050.16259765625,-2.62060492827765E-5,1.50935325995194E-8,1,4,13.4005146026611,4.99395990690862,33.1300012767315,-0.0324904605214059,-0.00504716586141588,1,-1.47241286878911E-7,,,,,,,,,,,,,,,,,,,,,50.0014572143555,50.0020790100098,-1050.16259765625,-1050.16259765625,53.3160537395153,5.64718173910681,4.72610712051392,54,2,0,0,1,0.302505493164063,33.7243423461914,1,1,3,50.0014572143555,0,50.0017681121826,,,,,,,,,,,,,,,,,,,,,,,,,,,,,,,,,
,3879891999.09499,50.0206184387207,-900.173522949219,-2.52089383582226E-5,1.3218725057527E-8,1,4,13.4005146026611,4.99385850574408,33.1399999558926,-0.0312575340735776,-0.00482699094541033,1,-1.19074892848098E-7,,,,,,,,,,,,,,,,,,,,,50.0194358825684,50.021800994873,-900.173522949219,-900.173522949219,53.4082859047845,5.64786989912147,4.72709465026855,52,3,68,0,0,0.302047729492188,33.7243423461914,1,1,3,50.0194358825684,0,50.0206184387207,,,,,,,,,,,,,,,,,,,,,,,,,,,,,,,,,
,3879892081.73759,50.0286502838135,-700.1083984375,-2.32732712713823E-5,2.52229394026325E-8,1,4,13.4005146026611,4.99384223894825,33.1300012767315,-0.028845907106988,-0.00453245030862998,1,-1.71278741246268E-7,,,,,,,,,,,,,,,,,,,,,50.0286445617676,50.0286560058594,-700.1083984375,-700.1083984375,53.482931428371,5.64803953953689,4.73155069351196,52,1,68,0,0,0.302200317382812,33.7243423461914,1,1,3,50.0286445617676,0,50.0286502838135,,,,,,,,,,,,,,,,,,,,,,,,,,,,,,,,,
,3879892152.91928,50.0147590637207,-550.131896972656,-2.14232792970244E-5,2.19677004677376E-8,1,4,13.4005146026611,4.9936877279099,33.1300012767315,-0.0265499901041215,-0.0041840537379172,1,-1.67390665940006E-7,,,,,,,,,,,,,,,,,,,,,50.0143585205078,50.0151596069336,-550.131896972656,-550.131896972656,53.3383301523133,5.64756922366369,4.72833585739136,54,2,0,0,1,0.304336547851562,33.7243423461914,1,1,3,50.0143585205078,0,50.0147590637207,,,,,,,,,,,,,,,,,,,,,,,,,,,,,,,,,
,3879892234.84164,50.0054111480713,-400.193206787109,-1.90749317020682E-5,1.08937752990396E-8,1,4,13.4005146026611,4.99380741955686,33.1300012767315,-0.0236520508592993,-0.00364807833916636,1,-8.66153759118988E-8,,,,,,,,,,,,,,,,,,,,,50.0051956176758,50.0056266784668,-400.193206787109,-400.193206787109,53.4407234883326,5.64828039889518,4.72584104537964,54,3,0,0,1,0.301742553710937,33.7243423461914,1,1,3,50.0051956176758,0,50.0054111480713,,,,,,,,,,,,,,,,,,,,,,,,,,,,,,,,,
,3879892314.43377,50.0174503326416,-200.153259277344,-1.45524620297992E-5,3.06779898759394E-8,1,4,13.4005146026611,4.99375675013162,33.1300012767315,-0.018014720907552,-0.00297975632247428,1,-2.24560177479185E-7,,,,,,,,,,,,,,,,,,,,,50.014518737793,50.0203819274902,-200.153259277344,-200.153259277344,53.3242608389672,5.64746067368778,4.72589588165283,53,1,68,0,0,0.300750732421875,33.7243423461914,1,1,3,50.0203819274902,0,50.0174503326416,,,,,,,,,,,,,,,,,,,,,,,,,,,,,,,,,
,3879892408.56467,50.0196132659912,-50.252311706543,-1.00420082760948E-5,1.95421074905377E-8,1,4,13.4005146026611,4.99373501682632,33.1300012767315,-0.0124292199604592,-0.00206864373095557,1,-1.65000063368437E-7,,,,,,,,,,,,,,,,,,,,,50.019157409668,50.0200691223145,-50.252311706543,-50.252311706543,53.4977823702364,5.64810794586028,4.73520994186401,54,2,0,0,1,0.30242919921875,33.2355842590332,1,1,3,50.0200691223145,0,50.0196132659912,,,,,,,,,,,,,,,,,,,,,,,,,,,,,,,,,
,3879892478.61918,50.015230178833,99.8122787475586,-4.09084627363608E-6,1.95819345211231E-8,1,4,13.4005146026611,4.99374391214722,33.1300012767315,-0.00504913573100743,-9.37699787885004E-4,1,-1.43771505935944E-7,,,,,,,,,,,,,,,,,,,,,50.0146598815918,50.0158004760742,99.8122787475586,99.8122787475586,53.3871819347653,5.64830607715228,4.73154306411743,52,3,68,0,0,0.301437377929687,33.2355842590332,1,1,3,50.0145797729492,0,50.015230178833,,,,,,,,,,,,,,,,,,,,,,,,,,,,,,,,,
,3879892563.23326,50.0070056915283,299.764129638672,4.37438234157278E-6,1.09933316711724E-8,1,4,13.4005146026611,4.99370365756395,33.1300012767315,0.00542882263300704,8.03521890766734E-4,1,-6.77678787712126E-9,,,,,,,,,,,,,,,,,,,,,50.0066146850586,50.007396697998,299.764129638672,299.764129638672,53.3699861073422,5.6473604472867,4.73191928863525,54,1,0,0,1,0.302963256835937,33.7243423461914,1,1,3,50.007396697998,0,50.0070056915283,,,,,,,,,,,,,,,,,,,,,,,,,,,,,,,,,
,3879892634.77772,50.0060062408447,449.828704833984,9.83438498684871E-6,1.1569117727402E-8,1,4,13.4005146026611,4.99367437968078,33.1300012767315,0.0122262067156055,0.00166369960444793,1,-1.30282532864796E-7,,,,,,,,,,,,,,,,,,,,,50.0053558349609,50.0066566467285,449.828704833984,449.828704833984,53.4055502049672,5.64835543006125,4.73454666137695,53,2,68,0,0,0.303192138671875,33.7243423461914,1,1,3,50.0053558349609,0,50.0060062408447,,,,,,,,,,,,,,,,,,,,,,,,,,,,,,,,,
,3879892706.54533,50.0030841827393,599.792602539063,1.42502729177912E-5,8.354452193584E-9,1,4,13.4005146026611,4.99371595996593,33.1300012767315,0.0177024309529616,0.00250341436330221,1,-1.14116392338984E-7,,,,,,,,,,,,,,,,,,,,,50.0028648376465,50.003303527832,599.792602539063,599.792602539063,53.4782416572557,5.64762034414216,4.73263502120972,54,3,0,0,1,0.303726196289063,33.7243423461914,1,1,3,50.0028381347656,0,50.0030841827393,,,,,,,,,,,,,,,,,,,,,,,,,,,,,,,,,
,3879892789.01739,50.0211410522461,799.656311035156,1.87475831564273E-5,2.14413662970634E-8,1,4,13.4005146026611,4.99379369721456,33.1300012767315,0.0233015384642031,0.00321462538343051,1,-2.13739480503206E-7,,,,,,,,,,,,,,,,,,,,,50.0175247192383,50.0247573852539,799.656311035156,799.656311035156,53.4383786027749,5.64757784211914,4.72758197784424,54,1,0,0,1,0.301895141601562,33.2355842590332,1,1,3,50.0247573852539,0,50.0211410522461,,,,,,,,,,,,,,,,,,,,,,,,,,,,,,,,,
,3879892860.99775,50.0019721984863,949.808959960937,2.12275807763927E-5,1.48552100921149E-8,1,4,13.4005146026611,4.99373160234798,33.1300012767315,0.0263685872576416,0.00373942594369727,1,-1.61723497014271E-7,,,,,,,,,,,,,,,,,,,,,50.0018768310547,50.002067565918,949.808959960937,949.808959960937,53.4094583475633,5.64793417589319,4.73254537582397,53,2,68,0,0,0.30303955078125,33.7243423461914,1,1,3,50.0018768310547,0,50.0019721984863,,,,,,,,,,,,,,,,,,,,,,,,,,,,,,,,,
,3879892932.66512,50.0124416351318,1099.73510742188,2.31068334692003E-5,6.99393327117636E-8,1,4,13.4005146026611,4.9936960718245,33.1300012767315,0.0286965512591038,0.00411140889402202,1,-1.4301528862043E-7,,,,,,,,,,,,,,,,,,,,,50.0112113952637,50.013671875,1099.73510742188,1099.73510742188,53.4532295446403,5.64848165866586,4.72808027267456,53,3,68,0,0,0.302505493164063,33.7243423461914,1,1,3,50.0112113952637,0,50.0124416351318,,,,,,,,,,,,,,,,,,,,,,,,,,,,,,,,,
,3879893016.5813,49.9982624053955,1299.49816894531,2.4981188025194E-5,1.38507294151327E-8,1,4,13.4005146026611,4.99372262678324,33.1399999558926,0.0310305987410901,0.00440456227122968,1,-1.87164193474281E-7,,,,,,,,,,,,,,,,,,,,,49.9980163574219,49.9985084533691,1299.49816894531,1299.49816894531,53.2820528989287,5.64839379823374,4.73450660705566,52,1,68,0,0,0.301666259765625,33.2355842590332,1,1,3,49.9985084533691,0,49.9982624053955,,,,,,,,,,,,,,,,,,,,,,,,,,,,,,,,,
,3879893088.58635,50.0306663513184,1449.71374511719,2.59071600198961E-5,1.070948741367E-8,1,4,13.4005146026611,4.99370735081882,33.1399999558926,0.0321727440502501,0.00462075500893965,1,-1.51426878602023E-7,,,,,,,,,,,,,,,,,,,,,50.0303192138672,50.0310134887695,1449.71374511719,1449.71374511719,53.3860094919864,5.64812250232559,4.72881269454956,54,2,0,0,1,0.3021240234375,33.2355842590332,1,1,3,50.030948638916,0,50.0306663513184,,,,,,,,,,,,,,,,,,,,,,,,,,,,,,,,,
,3879893160.99839,50.0309391021729,1599.50146484375,2.65558317040229E-5,1.22645930347034E-8,1,4,13.4005146026611,4.99369103394026,33.1300012767315,0.0329700582962059,0.00479048336941187,1,-1.11652922989904E-7,,,,,,,,,,,,,,,,,,,,,50.029369354248,50.0325088500977,1599.50146484375,1599.50146484375,53.3309046813806,5.64800838446737,4.73561716079712,54,3,0,0,1,0.30181884765625,33.7243423461914,1,1,3,50.029369354248,0,50.0309391021729,,,,,,,,,,,,,,,,,,,,,,,,,,,,,,,,,
,3879893244.4702,50.0111618041992,1799.56652832031,2.71275278823718E-5,1.26145937439402E-8,1,4,13.4005146026611,4.99365713360062,33.1300012767315,0.0336878636141601,0.00483779286519169,1,-1.59008528116104E-7,,,,,,,,,,,,,,,,,,,,,50.0099563598633,50.0123672485352,1799.56652832031,1799.56652832031,53.2750182422556,5.64818910680491,4.73295783996582,53,1,68,0,0,0.303802490234375,33.2355842590332,1,1,3,50.0123672485352,0,50.0111618041992,,,,,,,,,,,,,,,,,,,,,,,,,,,,,,,,,
,3879893316.63046,50.0001544952393,1949.88293457031,2.73130512825441E-5,9.86573563212092E-9,1,4,13.4005146026611,4.99364620329845,33.1300012767315,0.0339142199553845,0.00489712614991337,1,-1.38928899640895E-7,,,,,,,,,,,,,,,,,,,,,50.0001029968262,50.0002059936523,1949.88293457031,1949.88293457031,53.3926533343999,5.64831077870469,4.72823476791382,54,2,0,0,1,0.302276611328125,33.2355842590332,1,1,3,50.0002059936523,0,50.0001544952393,,,,,,,,,,,,,,,,,,,,,,,,,,,,,,,,,
,3879893388.48151,50.0010643005371,2099.8466796875,2.73862676610019E-5,4.19731474711329E-8,1,4,13.4005146026611,4.99353559795309,33.1300012767315,0.0339917476761846,0.00499251668727222,1,-7.28748756433825E-8,,,,,,,,,,,,,,,,,,,,,50.0007247924805,50.0014038085937,2099.8466796875,2099.8466796875,53.3637330791883,5.6483758168898,4.73292112350464,54,3,0,0,1,0.303115844726562,33.7243423461914,1,1,3,50.0007247924805,0,50.0010643005371,,,,,,,,,,,,,,,,,,,,,,,,,,,,,,,,,
,3879893470.75239,50.0222835540771,2299.73559570313,2.72539224671407E-5,8.62469510018599E-9,1,4,13.4005146026611,4.99351673910018,33.1300012767315,0.0338449733944415,0.00485023652108524,1,-1.67733229642958E-7,,,,,,,,,,,,,,,,,,,,,50.019889831543,50.0246772766113,2299.73559570313,2299.73559570313,53.359043308073,5.64780000485257,4.72982120513916,54,1,0,0,1,0.302581787109375,33.2355842590332,1,1,3,50.0246772766113,0,50.0222835540771,,,,,,,,,,,,,,,,,,,,,,,,,,,,,,,,,
,3879893542.87932,50.0118980407715,2449.92602539062,2.70534982620176E-5,6.93522583526107E-9,1,4,13.4005146026611,4.99345797187519,33.1300012767315,0.0335868961670457,0.00487217025508258,1,-1.20007689740253E-7,,,,,,,,,,,,,,,,,,,,,50.0118789672852,50.0119171142578,2449.92602539062,2449.92602539062,53.284788598746,5.64815327236732,4.73430585861206,52,2,68,0,0,0.303726196289063,33.7243423461914,1,1,3,50.0119171142578,0,50.0118980407715,,,,,,,,,,,,,,,,,,,,,,,,,,,,,,,,,
,3879893614.49106,50.0006408691406,2599.75170898438,2.67648722458731E-5,7.36167698955763E-9,1,4,13.4005146026611,4.99345459776796,33.1399999558926,0.0332250898477403,0.00484322093804472,1,-1.00160824815912E-7,,,,,,,,,,,,,,,,,,,,,50.0004615783691,50.0008201599121,2599.75170898438,2599.75170898438,53.2961222122749,5.64842890902352,4.73649406433105,54,3,0,0,1,0.302734375,33.2355842590332,1,1,3,50.0004615783691,0,50.0006408691406,,,,,,,,,,,,,,,,,,,,,,,,,,,,,,,,,
,3879893697.1503,50.0286865234375,2799.72875976562,2.62890572195088E-5,7.75222017124263E-9,1,4,13.4005146026611,4.99344287125454,33.1300012767315,0.0326399350574065,0.00471957133738759,1,-1.28632502587109E-7,,,,,,,,,,,,,,,,,,,,,50.0277328491211,50.0296401977539,2799.72875976562,2799.72875976562,53.2953405837556,5.64834703233642,4.72799301147461,54,1,0,0,1,0.302810668945313,33.7243423461914,1,1,3,50.0296401977539,0,50.0286865234375,,,,,,,,,,,,,,,,,,,,,,,,,,,,,,,,,
,3879893769.55993,50.0109329223633,2949.84350585937,2.58671805826076E-5,8.00705696117064E-9,1,4,13.4005146026611,4.99348627502351,33.1300012767315,0.0321126842784681,0.00466961831498341,1,-1.05831107684171E-7,,,,,,,,,,,,,,,,,,,,,50.0099716186523,50.0118942260742,2949.84350585937,2949.84350585937,53.4379877885153,5.6482682251998,4.7317533493042,54,2,0,0,1,0.30517578125,33.2355842590332,1,1,3,50.0098724365234,0,50.0109329223633,,,,,,,,,,,,,,,,,,,,,,,,,,,,,,,,,
,3879893862.27236,50.0082626342773,3499.57250976562,2.38948808626151E-5,8.26841047270327E-9,1,4,13.4005146026611,4.99336507134887,33.1399999558926,0.0296494335309391,0.00440527668383867,1,-2.37273818759703E-8,,,,,,,,,,,,,,,,,,,,,50.0075340270996,50.0089912414551,3499.57250976562,3499.57250976562,53.4407234883326,5.64877139542557,4.7370138168335,54,3,0,0,1,0.302734375,33.2355842590332,1,1,3,50.0075340270996,0,50.0082626342773,,,,,,,,,,,,,,,,,,,,,,,,,,,,,,,,,
,3879893961.17587,50.0026454925537,5499.75830078125,1.43923872639693E-5,1.52433360923473E-8,1,4,13.4005146026611,4.99339395551951,33.1300012767315,0.0178533006156264,0.00268896808756452,1,1.43677185748077E-8,,,,,,,,,,,,,,,,,,,,,50.002571105957,50.0027198791504,5499.75830078125,5499.75830078125,53.2507877581595,5.64962071262887,4.73868989944458,54,1,0,0,1,0.304031372070313,32.2580642700195,1,1,3,50.002571105957,0,50.0026454925537,,,,,,,,,,,,,,,,,,,,,,,,,,,,,,,,,
,3879894044.18917,50.0089092254639,6999.8876953125,6.2737556633679E-6,2.13337077225678E-8,1,4,13.4005146026611,4.99336869501979,33.1399999558926,0.00778302388283148,0.00116756302792395,1,2.57849620464E-9,,,,,,,,,,,,,,,,,,,,,50.0082092285156,50.0096092224121,6999.8876953125,6999.8876953125,53.4000788053326,5.64924733644283,4.73200082778931,54,2,0,0,1,0.302581787109375,33.7243423461914,1,1,3,50.0081748962402,0,50.0089092254639,,,,,,,,,,,,,,,,,,,,,,,,,,,,,,,,,
,3879894127.2401,50.0084285736084,8500.0810546875,-2.1759206041979E-6,1.12103256070824E-8,1,4,13.4005146026611,4.99333897627384,33.1399999558926,-0.00270257965353302,-3.83392889797095E-4,1,1.64746289046093E-8,,,,,,,,,,,,,,,,,,,,,50.0075759887695,50.0092811584473,8500.0810546875,8500.0810546875,53.3242608389672,5.6495240176296,4.7324423789978,54,3,0,0,1,0.303802490234375,33.7243423461914,1,1,3,50.0075759887695,0,50.0084285736084,,,,,,,,,,,,,,,,,,,,,,,,,,,,,,,,,
,3879894234.98319,50.0433197021484,10000.1103515625,-1.08109773189683E-5,1.47110076978549E-8,1,4,13.4005146026611,4.99330729403527,33.1399999558926,-0.0134165476474017,-0.00197835761857422,1,2.26076867344169E-8,,,,,,,,,,,,,,,,,,,,,50.0428428649902,50.0437965393066,10000.1103515625,10000.1103515625,53.3066741972845,5.64907270398473,4.72670745849609,54,1,0,0,1,0.302658081054687,33.2355842590332,1,1,3,50.0428428649902,0,50.0433197021484,,,,,,,,,,,,,,,,,,,,,,,,,,,,,,,,,
,3879894454.02505,50.0127429962158,25000.474609375,-9.96370107978688E-5,3.06447536901364E-8,1,4,13.4005146026611,4.9932999965469,33.1399999558926,-0.123630170817443,-0.0183684738342239,1,9.92115661646538E-8,,,,,,,,,,,,,,,,,,,,,50.0125427246094,50.0129432678223,25000.474609375,25000.474609375,53.3695952930826,5.64900435575858,4.73425436019897,54,2,0,0,1,0.30303955078125,33.2355842590332,1,1,3,50.0129432678223,0,50.0127429962158,,,,,,,,,,,,,,,,,,,,,,,,,,,,,,,,,
,3879894673.92507,50.0019664764404,40000.1640625,-1.89440043283638E-4,4.08344386061264E-8,1,4,13.4005146026611,4.99329615272494,33.1300012767315,-0.235048967124287,-0.0349845727655336,1,1.39788416659648E-7,,,,,,,,,,,,,,,,,,,,,50.0017356872559,50.002197265625,40000.1640625,40000.1640625,53.2843977844864,5.64894755113934,4.72904109954834,54,3,0,0,1,0.304336547851562,33.2355842590332,1,1,3,50.0017356872559,0,50.0019664764404,,,,,,,,,,,,,,,,,,,,,,,,,,,,,,,,,
,3879894955.13198,50.0203075408936,60000.49609375,-3.09418271661495E-4,7.4605543153119E-8,1,4,13.4005146026611,4.99332921335546,33.1300012767315,-0.383897334100805,-0.0572686706203324,1,1.26148754626814E-7,,,,,,,,,,,,,,,,,,,,,50.0182075500488,50.0224075317383,60000.49609375,60000.49609375,53.3344220097172,5.64994780506856,4.73085784912109,52,1,68,0,0,0.306015014648438,33.2355842590332,1,1,3,50.0224075317383,0,50.0203075408936,,,,,,,,,,,,,,,,,,,,,,,,,,,,,,,,,
,3879895130.12091,50.0003757476807,70000.328125,-3.69361252685681E-4,1.21535796937612E-7,1,4,13.4005146026611,4.99327950928738,33.1300012767315,-0.458256723964953,-0.0684015666505786,1,1.1890562904644E-7,,,,,,,,,,,,,,,,,,,,,50.0003051757812,50.0004463195801,70000.328125,70000.328125,53.2789263848518,5.65062965123592,4.74014043807983,54,3,0,0,1,0.30487060546875,33.7243423461914,1,1,3,50.0004463195801,0,50.0003757476807,,,,,,,,,,,,,,,,,,,,,,,,,,,,,,,,,