File: SQUID/22169_LCOT/22169_LCOT_MH_300K_FC_0d5T.csv
Comment,Time Stamp (sec),Temperature (K),Magnetic Field (Oe),Moment (emu),M. Std. Err. (emu),Transport Action,Averaging Time (sec),Frequency (Hz),Peak Amplitude (mm),Center Position (mm),Lockin Signal' (V),Lockin Signal (V),Range,M. Quad. Signal (emu),AC Moment (emu),AC M. Std Err. (emu),AC Phase (deg),AC Phase Std. Err. (deg),AC Susceptibility (emu/Oe),AC Suscept. Std Err. (emu/Oe),AC X' (emu/Oe),AC X' Std Err. (emu/Oe),AC X'' (emu/Oe),AC X'' Std Err. (emu/Oe),AC Drive (Oe),AC Frequency (Hz),AC Averaging Time (sec),AC Cycles,AC Range,AC Measure Type,AC Signal' (V),AC Signal'' (V),AC Trim Coil Ratio,AC Trim Coil Phase,Min. Temperature (K),Max. Temperature (K),Min. Field (Oe),Max. Field (Oe),Mass (grams),Motor Lag (deg),Pressure (Torr),Measure Count,Measurement Number,SQUID Status (code),Motor Status (code),Measure Status (code),Motor Current (amps),Motor Temp. (C),Temp. Status (code),Field Status (code),Chamber Status (code),Chamber Temp (K),Redirection State,Average Temp (K),Rotation Angle (deg),Rotator state,DC Moment Fixed Ctr (emu),DC Moment Err Fixed Ctr (emu),DC Moment Free Ctr (emu),DC Moment Err Free Ctr (emu),DC Fixed Fit,DC Free Fit,DC Calculated Center (mm),DC Calculated Center Err (mm),DC Scan Length (mm),DC Scan Time (s),DC Number of Points,DC Squid Drift,DC Min V (V),DC Max V (V),DC Scans per Measure,Sample Resistance,He3 Temperature,Sorb Resistance,Sorb Temperature,Map 05,Map 06,Map 07,Map 08,Map 09,Map 10,Map 11,Map 12,Map 13,Map 14,Map 15,Map 16
,3880070343.32757,300.099060058594,69999.7890625,-3.80668538639711E-4,3.18576597566319E-7,1,4,13.4005146026611,5.00162594014601,33.4200002253056,-0.473372500581578,-0.0707843583043101,1,2.3009125671355E-8,,,,,,,,,,,,,,,,,,,,,300.098571777344,300.099548339844,69999.7890625,69999.7890625,53.0760937841114,5.65682190413255,6.13360738754273,54,1,0,0,1,0.307083129882812,32.7468223571777,1,1,3,300.099670410156,0,300.099060058594,,,,,,,,,,,,,,,,,,,,,,,,,,,,,,,,,
,3880070575.48567,300.095138549805,55000.3125,-2.88587244934697E-4,1.49938216411847E-7,1,4,13.4005146026611,5.001081428013,33.4100015461445,-0.358833873450207,-0.0535079793171544,1,1.34805486737007E-7,,,,,,,,,,,,,,,,,,,,,300.089172363281,300.101104736328,55000.3125,55000.3125,53.4282174320249,5.65635835012441,6.14482975006104,54,2,0,0,1,0.306396484375,33.7243423461914,1,1,3,300.101104736328,0,300.095138549805,,,,,,,,,,,,,,,,,,,,,,,,,,,,,,,,,
,3880070795.55818,300.118576049805,39999.69921875,-1.96742265702661E-4,7.56069115223753E-8,1,4,13.4005146026611,5.00099018914913,33.4100015461445,-0.244630123592775,-0.0364511924017915,1,1.13260409755961E-7,,,,,,,,,,,,,,,,,,,,,300.115447998047,300.121704101562,39999.69921875,39999.69921875,53.4610458298326,5.65716697889879,6.14556264877319,54,3,0,0,1,0.299301147460937,34.2131004333496,1,1,3,300.121704101562,0,300.118576049805,,,,,,,,,,,,,,,,,,,,,,,,,,,,,,,,,
,3880071076.67678,300.156616210937,19999.666015625,-7.44646504468364E-5,2.80943279081639E-8,1,4,13.4005146026611,5.00099165369229,33.4100015461445,-0.0925788422689574,-0.0138688272955313,1,-1.54215379979475E-8,,,,,,,,,,,,,,,,,,,,,300.135101318359,300.178131103516,19999.666015625,19999.666015625,53.5110700550634,5.65850002734031,6.15349578857422,54,1,0,0,1,0.3070068359375,34.2131004333496,1,1,3,300.178131103516,0,300.156616210937,,,,,,,,,,,,,,,,,,,,,,,,,,,,,,,,,
,3880071265.61637,300.372863769531,9999.7197265625,-1.41358633276604E-5,1.06240296100641E-8,1,4,13.4005146026611,5.00113911587994,33.4200002253056,-0.0175751516048033,-0.00263362100507897,1,-3.52946510092951E-9,,,,,,,,,,,,,,,,,,,,,300.372283935547,300.373443603516,9999.7197265625,9999.7197265625,53.4852763139287,5.65843042234195,6.15293836593628,54,2,0,0,1,0.306854248046875,33.7243423461914,1,1,3,300.373443603516,0,300.372863769531,,,,,,,,,,,,,,,,,,,,,,,,,,,,,,,,,
,3880071364.10044,300.360595703125,8499.5517578125,-5.29602483191263E-6,1.15953927386022E-8,1,4,13.4005146026611,5.00105239731983,33.4200002253056,-0.00658251100565943,-9.99295227675515E-4,1,-1.14795352897079E-8,,,,,,,,,,,,,,,,,,,,,300.353851318359,300.367340087891,8499.5517578125,8499.5517578125,53.6091644342268,5.65843176014238,6.15979766845703,54,3,0,0,1,0.307235717773438,34.2131004333496,1,1,3,300.353851318359,0,300.360595703125,,,,,,,,,,,,,,,,,,,,,,,,,,,,,,,,,
,3880071466.08437,300.160614013672,6499.744140625,6.2745331668752E-6,1.01465329512618E-8,1,4,13.4005146026611,5.00098076163677,33.4200002253056,0.00781519448880025,0.0010726917105324,1,-7.58492684978419E-8,,,,,,,,,,,,,,,,,,,,,300.15576171875,300.165466308594,6499.744140625,6499.744140625,53.5821982503134,5.65779459680182,6.15793371200562,54,1,0,0,1,0.307846069335937,34.2131004333496,1,1,3,300.15576171875,0,300.160614013672,,,,,,,,,,,,,,,,,,,,,,,,,,,,,,,,,
,3880071552.29436,300.069900512695,4999.7275390625,1.44957764611075E-5,8.94474003445489E-9,1,4,13.4005146026611,5.00105140256209,33.4200002253056,0.0180364180767912,0.00260549887763513,1,-7.28779468923148E-8,,,,,,,,,,,,,,,,,,,,,300.057312011719,300.082489013672,4999.7275390625,4999.7275390625,53.5751635936403,5.65770721317681,6.15992069244385,54,2,0,0,1,0.305404663085937,34.2131004333496,1,1,3,300.082489013672,0,300.069900512695,,,,,,,,,,,,,,,,,,,,,,,,,,,,,,,,,
,3880071639.03963,300.259414672852,3499.77392578125,2.18332906305942E-5,7.60652721695718E-9,1,4,13.4005146026611,5.00095434911592,33.4200002253056,0.027156419163956,0.00398433140316794,1,-6.14438104012406E-8,,,,,,,,,,,,,,,,,,,,,300.259338378906,300.259490966797,3499.77392578125,3499.77392578125,53.5356913534191,5.65834199479622,6.16041469573975,54,3,0,0,1,0.302886962890625,34.2131004333496,1,1,3,300.259338378906,0,300.259414672852,,,,,,,,,,,,,,,,,,,,,,,,,,,,,,,,,
,3880071748.23267,300.046173095703,2899.654296875,2.40963433483046E-5,1.61295207149766E-8,1,4,13.4005146026611,5.0010331073491,33.4100015461445,0.0299365329761497,0.00463371325321549,1,1.22246864941648E-7,,,,,,,,,,,,,,,,,,,,,300.043762207031,300.048583984375,2899.654296875,2899.654296875,53.6591886594576,5.65891617057603,6.16558933258057,54,1,0,0,1,0.305862426757812,34.2131004333496,1,1,3,300.043762207031,0,300.046173095703,,,,,,,,,,,,,,,,,,,,,,,,,,,,,,,,,
,3880071821.12951,300.138290405273,2749.71557617187,2.46077532174903E-5,1.17592706198794E-8,1,4,13.4005146026611,5.00105669145072,33.4200002253056,0.0305754085479448,0.00470993213765292,1,1.07021210129186E-7,,,,,,,,,,,,,,,,,,,,,300.134735107422,300.141845703125,2749.71557617187,2749.71557617187,53.6048654773711,5.65842963057559,6.16434526443481,54,2,0,0,1,0.307235717773438,34.2131004333496,1,1,3,300.134735107422,0,300.138290405273,,,,,,,,,,,,,,,,,,,,,,,,,,,,,,,,,
,3880071895.59163,300.150985717773,2599.7265625,2.50676013095769E-5,1.08689272521711E-8,1,4,13.4005146026611,5.00115244491752,33.4200002253056,0.0311546415016637,0.004751067878438,1,7.12137915234136E-8,,,,,,,,,,,,,,,,,,,,,300.143737792969,300.158233642578,2599.7265625,2599.7265625,53.6873272861499,5.6584756783659,6.16107082366943,54,3,0,0,1,0.305099487304687,34.2131004333496,1,1,3,300.143737792969,0,300.150985717773,,,,,,,,,,,,,,,,,,,,,,,,,,,,,,,,,
,3880071990.31529,300.304656982422,2399.58569335938,2.55439262134746E-5,1.8241725462283E-8,1,4,13.4005146026611,5.00109458185276,33.4200002253056,0.0317270139157208,0.00496896070990247,1,1.75269318845843E-7,,,,,,,,,,,,,,,,,,,,,300.296264648438,300.313049316406,2399.58569335938,2399.58569335938,53.5657840514095,5.65793509200364,6.16413593292236,54,1,0,0,1,0.308761596679687,33.7243423461914,1,1,3,300.296264648438,0,300.304656982422,,,,,,,,,,,,,,,,,,,,,,,,,,,,,,,,,
,3880072063.15354,300.258193969727,2249.55883789062,2.58857312468546E-5,1.35584605515102E-8,1,4,13.4005146026611,5.00106964595282,33.4200002253056,0.0321581957083055,0.0049895262880472,1,1.40706069936145E-7,,,,,,,,,,,,,,,,,,,,,300.257476806641,300.258911132812,2249.55883789062,2249.55883789062,53.6580162166788,5.65582686573126,6.15862798690796,53,2,68,0,0,0.3070068359375,33.7243423461914,1,1,3,300.258911132812,0,300.258193969727,,,,,,,,,,,,,,,,,,,,,,,,,,,,,,,,,
,3880072134.40207,300.227447509766,2099.6328125,2.61696495199706E-5,1.08998762434684E-8,1,4,13.4005146026611,5.00106833080841,33.4200002253056,0.0325226054540414,0.0049659971587109,1,7.9310748680544E-8,,,,,,,,,,,,,,,,,,,,,300.221893310547,300.233001708984,2099.6328125,2099.6328125,53.5353005391595,5.65805787020861,6.16545629501343,53,3,68,0,0,0.30181884765625,33.7243423461914,1,1,3,300.221893310547,0,300.227447509766,,,,,,,,,,,,,,,,,,,,,,,,,,,,,,,,,
,3880072217.26984,300.35807800293,1899.74389648438,2.6315255338466E-5,2.27544650690188E-8,1,4,13.4005146026611,5.00102195329764,33.4200002253056,0.0326875001623144,0.00509807291371358,1,1.63810157991219E-7,,,,,,,,,,,,,,,,,,,,,300.339080810547,300.377075195313,1899.74389648438,1899.74389648438,53.6083828057076,5.65806968179744,6.16717195510864,54,1,0,0,1,0.306930541992188,33.7243423461914,1,1,3,300.378509521484,0,300.35807800293,,,,,,,,,,,,,,,,,,,,,,,,,,,,,,,,,
,3880072316.74477,300.3896484375,1749.52819824219,2.63578001900544E-5,1.52298596618219E-8,1,4,13.4005146026611,5.00102280682328,33.4200002253056,0.0327448898044067,0.00507600278671945,1,1.3969360108869E-7,,,,,,,,,,,,,,,,,,,,,300.388458251953,300.390838623047,1749.52819824219,1749.52819824219,53.384446234948,5.65650584332829,6.1634521484375,53,2,68,0,0,0.302963256835937,34.2131004333496,1,1,3,300.390838623047,0,300.3896484375,,,,,,,,,,,,,,,,,,,,,,,,,,,,,,,,,
,3880072390.03429,300.261505126953,1599.48889160156,2.6327165721388E-5,1.28285280051278E-8,1,4,13.4005146026611,5.00104845458223,33.4200002253056,0.0327201427809214,0.00498272850931893,1,6.9226532445795E-8,,,,,,,,,,,,,,,,,,,,,300.258117675781,300.264892578125,1599.48889160156,1599.48889160156,53.4129756758999,5.65708918854396,6.16446685791016,54,3,0,0,1,0.308303833007812,33.7243423461914,1,1,3,300.264892578125,0,300.261505126953,,,,,,,,,,,,,,,,,,,,,,,,,,,,,,,,,
,3880072483.35068,300.226119995117,1399.68811035156,2.59664663796287E-5,2.19247359349365E-8,1,4,13.4005146026611,5.00134594306344,33.4200002253056,0.032250463826609,0.00507582562253265,1,1.97723157424233E-7,,,,,,,,,,,,,,,,,,,,,300.201538085937,300.250701904297,1399.68811035156,1399.68811035156,53.597830820698,5.65525127451295,6.16145515441895,54,1,0,0,1,0.300445556640625,33.7243423461914,1,1,3,300.250701904297,0,300.226119995117,,,,,,,,,,,,,,,,,,,,,,,,,,,,,,,,,
,3880072566.87758,300.383346557617,1249.62353515625,2.5583662978644E-5,1.92423840398037E-8,1,4,13.4005146026611,5.00133952729051,33.4200002253056,0.0317918274319892,0.00488825496372664,1,1.04144726067421E-7,,,,,,,,,,,,,,,,,,,,,300.383331298828,300.383361816406,1249.62353515625,1249.62353515625,53.618153162198,5.65572858334076,6.16503715515137,53,2,68,0,0,0.307464599609375,33.7243423461914,1,1,3,300.383331298828,0,300.383346557617,,,,,,,,,,,,,,,,,,,,,,,,,,,,,,,,,
,3880072636.753,300.318481445313,1099.78540039062,2.49607723770201E-5,1.31045951350374E-8,1,4,13.4005146026611,5.00133081987926,33.4200002253056,0.0310165343496127,0.00477708587679426,1,1.07928671183566E-7,,,,,,,,,,,,,,,,,,,,,300.309265136719,300.327697753906,1099.78540039062,1099.78540039062,53.7326617402653,5.65577448649686,6.16568851470947,54,3,0,0,1,0.307235717773438,33.7243423461914,1,1,3,300.309265136719,0,300.318481445313,,,,,,,,,,,,,,,,,,,,,,,,,,,,,,,,,
,3880072734.41656,300.427536010742,899.770690917969,2.37350591372334E-5,9.47117078818111E-9,1,4,13.4005146026611,5.00134343049701,33.4200002253056,0.0294974495975317,0.00451647549991447,1,8.16826487977037E-8,,,,,,,,,,,,,,,,,,,,,300.416229248047,300.438842773438,899.770690917969,899.770690917969,53.6294867757268,5.65629093647489,6.17079734802246,54,1,0,0,1,0.306777954101562,33.2355842590332,1,1,3,300.416229248047,0,300.427536010742,,,,,,,,,,,,,,,,,,,,,,,,,,,,,,,,,
,3880072808.70986,300.248977661133,749.743896484375,2.24033944374745E-5,1.98520405572674E-8,1,4,13.4005146026611,5.00138769716289,33.4200002253056,0.0278321724081733,0.00433436356860379,1,1.34387784303114E-7,,,,,,,,,,,,,,,,,,,,,300.2392578125,300.258697509766,749.743896484375,749.743896484375,53.6365214323999,5.65620125528198,6.16267251968384,53,2,68,0,0,0.307464599609375,33.7243423461914,1,1,3,300.258697509766,0,300.248977661133,,,,,,,,,,,,,,,,,,,,,,,,,,,,,,,,,
,3880072880.19217,300.145233154297,599.981384277344,2.07155321823032E-5,1.5992823383868E-8,1,4,13.4005146026611,5.00143043426227,33.4200002253056,0.025740737291864,0.00397362784165798,1,9.67311775761785E-8,,,,,,,,,,,,,,,,,,,,,300.140960693359,300.149505615234,599.981384277344,599.981384277344,53.493092599121,5.65571293440849,6.16655349731445,53,3,68,0,0,0.307998657226562,33.7243423461914,1,1,3,300.140533447266,0,300.145233154297,,,,,,,,,,,,,,,,,,,,,,,,,,,,,,,,,
,3880072971.29402,300.190414428711,399.840728759766,1.75454811642286E-5,2.67381770510867E-8,1,4,13.4005146026611,5.00141537503862,33.4200002253056,0.0217743306807124,0.0035478184522037,1,2.28521427421419E-7,,,,,,,,,,,,,,,,,,,,,300.185211181641,300.195617675781,399.840728759766,399.840728759766,53.5642207943711,5.65607721927974,6.16227006912231,53,1,68,0,0,0.306625366210937,33.7243423461914,1,1,3,300.185211181641,0,300.190414428711,,,,,,,,,,,,,,,,,,,,,,,,,,,,,,,,,
,3880073053.0281,300.340087890625,249.90202331543,1.43564644720185E-5,2.03714444054401E-8,1,4,13.4005146026611,5.00150111715191,33.4100015461445,0.0178218357685901,0.00287150762827863,1,1.6162235508316E-7,,,,,,,,,,,,,,,,,,,,,300.331573486328,300.348602294922,249.90202331543,249.90202331543,53.554059623621,5.65590755010505,6.16875314712524,53,2,68,0,0,0.306625366210937,33.7243423461914,1,1,3,300.348602294922,0,300.340087890625,,,,,,,,,,,,,,,,,,,,,,,,,,,,,,,,,
,3880073130.14129,300.23828125,100.051452636719,1.00913147532391E-5,1.24362080387148E-8,1,4,13.4005146026611,5.00139276248352,33.4200002253056,0.0125264130674343,0.00202081981227067,10,1.15590210635023E-7,,,,,,,,,,,,,,,,,,,,,300.237487792969,300.239074707031,100.051452636719,100.051452636719,53.4801957285537,5.65623290434168,6.16500377655029,54,3,0,0,1,0.308380126953125,33.2355842590332,1,1,3,300.237487792969,0,300.23828125,,,,,,,,,,,,,,,,,,,,,,,,,,,,,,,,,
,3880073243.41778,300.231781005859,-100.001098632813,1.78916118364162E-6,1.74923451273542E-8,1,4,13.4005146026611,5.00150056569661,33.4200002253056,0.00218822664717366,5.77138725747258E-4,1,1.9648645330437E-7,,,,,,,,,,,,,,,,,,,,,300.229736328125,300.233825683594,-100.001098632813,-100.001098632813,53.5403811245345,5.65523402944567,6.17038440704346,53,1,68,0,0,0.30731201171875,33.7243423461914,1,1,3,300.229736328125,0,300.231781005859,,,,,,,,,,,,,,,,,,,,,,,,,,,,,,,,,
,3880073326.18247,300.078308105469,-249.889434814453,-4.78964143636175E-6,1.34796586675205E-8,1,4,13.4005146026611,5.0012730791138,33.4200002253056,-0.00598979523221765,-6.61089566111381E-4,1,1.84819959664943E-7,,,,,,,,,,,,,,,,,,,,,300.074859619141,300.081756591797,-249.889434814453,-249.889434814453,53.8190316916403,5.65624553232819,6.16467237472534,53,2,68,0,0,0.300521850585937,33.7243423461914,1,1,3,300.074859619141,0,300.078308105469,,,,,,,,,,,,,,,,,,,,,,,,,,,,,,,,,
,3880073424.87589,300.22444152832,-399.865905761719,-1.03381622247836E-5,1.1755281405945E-8,1,4,13.4005146026611,5.00134362704055,33.4200002253056,-0.0128770654598739,-0.00177331636174549,1,1.20364888913376E-7,,,,,,,,,,,,,,,,,,,,,300.219512939453,300.229370117188,-399.865905761719,-399.865905761719,53.5591402089961,5.65642451787803,6.1641206741333,54,3,0,0,1,0.30670166015625,33.7243423461914,1,1,3,300.219512939453,0,300.22444152832,,,,,,,,,,,,,,,,,,,,,,,,,,,,,,,,,
,3880073507.06964,300.234420776367,-599.817810058594,-1.58838546554779E-5,1.51156767001012E-8,1,4,13.4005146026611,5.00138474672575,33.4200002253056,-0.019790184938524,-0.00268946107258039,1,2.13196892889955E-7,,,,,,,,,,,,,,,,,,,,,300.227661132812,300.241180419922,-599.817810058594,-599.817810058594,53.6197164192364,5.6564142280607,6.17150783538818,52,1,68,0,0,0.30731201171875,33.7243423461914,1,1,3,300.227661132812,0,300.234420776367,,,,,,,,,,,,,,,,,,,,,,,,,,,,,,,,,
,3880073579.24227,300.259658813477,-749.806823730469,-1.88442099272443E-5,1.23188482698634E-8,1,4,13.4005146026611,5.00123248660748,33.4100015461445,-0.0234619133357045,-0.00329532084515865,1,1.68687764891642E-7,,,,,,,,,,,,,,,,,,,,,300.255065917969,300.264251708984,-749.806823730469,-749.806823730469,53.6052562916307,5.65720354036769,6.17034864425659,52,2,68,0,0,0.306320190429687,33.7243423461914,1,1,3,300.255065917969,0,300.259658813477,,,,,,,,,,,,,,,,,,,,,,,,,,,,,,,,,
,3880073650.52328,300.214416503906,-899.770690917969,-2.10415823738744E-5,1.77740323166085E-8,1,4,13.4005146026611,5.00115381048338,33.4200002253056,-0.0261835888363056,-0.00377026547757329,1,1.15356117653196E-7,,,,,,,,,,,,,,,,,,,,,300.208282470703,300.220550537109,-899.770690917969,-899.770690917969,53.5939226781018,5.65608442424694,6.17078018188477,54,3,0,0,1,0.306777954101562,33.7243423461914,1,1,3,300.208282470703,0,300.214416503906,,,,,,,,,,,,,,,,,,,,,,,,,,,,,,,,,
,3880073732.35673,300.254501342773,-1099.74768066406,-2.31721846358507E-5,7.64518346678432E-8,1,4,13.4005146026611,5.00112720088661,33.4200002253056,-0.0288559569256986,-0.0040094959549999,1,2.41649692398455E-7,,,,,,,,,,,,,,,,,,,,,300.232879638672,300.276123046875,-1099.74768066406,-1099.74768066406,53.6220613047941,5.65677543345613,6.16558694839478,54,1,0,0,1,0.308914184570313,33.7243423461914,1,1,3,300.276123046875,0,300.254501342773,,,,,,,,,,,,,,,,,,,,,,,,,,,,,,,,,
,3880073803.84507,300.337051391602,-1249.673828125,-2.42029060573581E-5,2.06678933537642E-8,1,4,13.4005146026611,5.00106796509875,33.4200002253056,-0.0301181621787819,-0.00432705929075842,1,1.403710353376E-7,,,,,,,,,,,,,,,,,,,,,300.328369140625,300.345733642578,-1249.673828125,-1249.673828125,53.4891844565249,5.6575168609039,6.17019510269165,54,2,0,0,1,0.29998779296875,33.2355842590332,1,1,3,300.328369140625,0,300.337051391602,,,,,,,,,,,,,,,,,,,,,,,,,,,,,,,,,
,3880073875.519,300.403869628906,-1399.6376953125,-2.4925316654712E-5,1.28906329643928E-8,1,4,13.4005146026611,5.00092017108279,33.4200002253056,-0.0310111509280258,-0.00448743673161603,1,1.19299088659325E-7,,,,,,,,,,,,,,,,,,,,,300.402313232422,300.405426025391,-1399.6376953125,-1399.6376953125,53.5993940777364,5.65721556290129,6.16607666015625,53,3,68,0,0,0.30853271484375,33.7243423461914,6,1,3,300.402313232422,0,300.403869628906,,,,,,,,,,,,,,,,,,,,,,,,,,,,,,,,,
,3880073957.5574,300.20622253418,-1599.62731933594,-2.55495803140838E-5,1.55138987880448E-8,1,4,13.4005146026611,5.00089747256242,33.4100015461445,-0.0317974731300191,-0.0045340289637407,1,1.75186449210385E-7,,,,,,,,,,,,,,,,,,,,,300.199096679687,300.213348388672,-1599.62731933594,-1599.62731933594,53.6279235186884,5.6569733479869,6.16665554046631,53,1,68,0,0,0.306015014648438,33.2355842590332,1,1,3,300.199096679687,0,300.20622253418,,,,,,,,,,,,,,,,,,,,,,,,,,,,,,,,,
,3880074029.94082,300.12809753418,-1749.60375976562,-2.57567065173106E-5,1.82525333637914E-8,1,4,13.4005146026611,5.00089322051465,33.4200002253056,-0.032050081336178,-0.00460507625975168,1,1.49021094514409E-7,,,,,,,,,,,,,,,,,,,,,300.125061035156,300.131134033203,-1749.60375976562,-1749.60375976562,53.5505422952845,5.65747912824727,6.16421747207642,52,2,68,0,0,0.30242919921875,33.2355842590332,1,1,3,300.125061035156,0,300.12809753418,,,,,,,,,,,,,,,,,,,,,,,,,,,,,,,,,
,3880074101.67474,300.274291992188,-1899.86975097656,-2.58756787659551E-5,4.99730510112413E-8,1,4,13.4005146026611,5.0008521800501,33.4200002253056,-0.0321978657572133,-0.00462554341590152,1,1.50313436688868E-7,,,,,,,,,,,,,,,,,,,,,300.269836425781,300.278747558594,-1899.86975097656,-1899.86975097656,53.5259209969287,5.65794191684595,6.16447591781616,54,3,0,0,1,0.308761596679687,33.7243423461914,1,1,3,300.269836425781,0,300.274291992188,,,,,,,,,,,,,,,,,,,,,,,,,,,,,,,,,
,3880074195.37695,300.401290893555,-2099.80908203125,-2.57309815164286E-5,7.9931749812625E-9,1,4,13.4005146026611,5.00126451918031,33.4200002253056,-0.0320151022053144,-0.00464303510625014,1,1.15029121160442E-7,,,,,,,,,,,,,,,,,,,,,300.3974609375,300.405120849609,-2099.80908203125,-2099.80908203125,53.536863796198,5.65608678593795,6.16408538818359,54,1,0,0,1,0.307464599609375,33.7243423461914,1,1,3,300.3974609375,0,300.401290893555,,,,,,,,,,,,,,,,,,,,,,,,,,,,,,,,,
,3880074280.07752,300.33268737793,-2249.76025390625,-2.55340990706533E-5,8.37171020915089E-9,1,4,13.4005146026611,5.0011516387573,33.4200002253056,-0.031775317461836,-0.00456602148648628,1,1.47399049498673E-7,,,,,,,,,,,,,,,,,,,,,300.322418212891,300.342956542969,-2249.76025390625,-2249.76025390625,53.5376454247172,5.65699713669124,6.16962623596191,53,2,68,0,0,0.3070068359375,33.2355842590332,1,1,3,300.320617675781,0,300.33268737793,,,,,,,,,,,,,,,,,,,,,,,,,,,,,,,,,
,3880074351.81233,300.196792602539,-2399.74926757813,-2.52555632739322E-5,7.41958970388814E-9,1,4,13.4005146026611,5.00121098968769,33.4100015461445,-0.0314230818290401,-0.00455733378436822,1,1.12779991030131E-7,,,,,,,,,,,,,,,,,,,,,300.193908691406,300.199676513672,-2399.74926757813,-2399.74926757813,53.5270934397076,5.65626897861533,6.16989421844482,54,3,0,0,1,0.306930541992188,34.2131004333496,1,1,3,300.193908691406,0,300.196792602539,,,,,,,,,,,,,,,,,,,,,,,,,,,,,,,,,
,3880074434.4493,300.290786743164,-2599.77685546875,-2.4769578366409E-5,1.02785368609976E-8,1,4,13.4005146026611,5.00145878685643,33.4200002253056,-0.0308229516754147,-0.00445391963782398,1,1.23500180432404E-7,,,,,,,,,,,,,,,,,,,,,300.289642333984,300.291931152344,-2599.77685546875,-2599.77685546875,53.6115093197845,5.6555006514608,6.16484212875366,54,1,0,0,1,0.30670166015625,33.7243423461914,1,1,3,300.289428710937,0,300.290786743164,,,,,,,,,,,,,,,,,,,,,,,,,,,,,,,,,
,3880074505.7965,300.302124023438,-2749.6904296875,-2.4358094545077E-5,9.7409488509472E-9,1,4,13.4005146026611,5.0015150053913,33.4200002253056,-0.0303106116423074,-0.00438515494351036,1,1.1730129074922E-7,,,,,,,,,,,,,,,,,,,,,300.291809082031,300.312438964844,-2749.6904296875,-2749.6904296875,53.4184470755345,5.6560729377921,6.14429569244385,54,2,0,0,1,0.3082275390625,33.2355842590332,1,1,3,300.312438964844,0,300.302124023438,,,,,,,,,,,,,,,,,,,,,,,,,,,,,,,,,
,3880074577.62967,300.148986816406,-2899.654296875,-2.38578970103055E-5,7.91458199620117E-9,1,4,13.4005146026611,5.00110714546142,33.4200002253056,-0.0296822544594659,-0.00431156927668333,1,1.01256371525199E-7,,,,,,,,,,,,,,,,,,,,,300.145446777344,300.152526855469,-2899.654296875,-2899.654296875,53.5841523216114,5.65783642803478,6.14545345306397,52,3,68,0,0,0.307388305664063,33.7243423461914,1,1,3,300.145446777344,0,300.148986816406,,,,,,,,,,,,,,,,,,,,,,,,,,,,,,,,,
,3880074680.69329,300.37109375,-3499.849609375,-2.1537410813412E-5,9.19303624908289E-9,1,4,13.4005146026611,5.00107260464912,33.4100015461445,-0.0267829326456721,-0.0039729501184842,1,2.64419520165064E-8,,,,,,,,,,,,,,,,,,,,,300.356811523438,300.385375976562,-3499.849609375,-3499.849609375,53.5024721413518,5.65727759596539,6.1526927947998,54,1,0,0,1,0.30670166015625,33.7243423461914,1,1,3,300.386962890625,0,300.37109375,,,,,,,,,,,,,,,,,,,,,,,,,,,,,,,,,
,3880074764.99994,300.302719116211,-4999.7783203125,-1.41904885848554E-5,8.49326062792942E-9,1,4,13.4005146026611,5.00109222622183,33.4200002253056,-0.0176432618673481,-0.00264091560271632,1,-1.25262494295498E-9,,,,,,,,,,,,,,,,,,,,,300.295257568359,300.310180664063,-4999.7783203125,-4999.7783203125,53.4919201563422,5.65688683172693,6.15586566925049,54,2,0,0,1,0.301361083984375,33.7243423461914,1,1,3,300.310180664063,0,300.302719116211,,,,,,,,,,,,,,,,,,,,,,,,,,,,,,,,,
,3880074860.7337,300.410675048828,-6499.79443359375,-5.95002150994354E-6,9.05389736046915E-9,1,4,13.4005146026611,5.00107957974119,33.4200002253056,-0.00739774926718555,-0.00110719997066665,1,-4.26572791185393E-10,,,,,,,,,,,,,,,,,,,,,300.410003662109,300.411346435547,-6499.79443359375,-6499.79443359375,53.745167796573,5.65741927454235,6.15521717071533,54,3,0,0,1,0.307846069335937,33.7243423461914,6,1,3,300.410003662109,0,300.410675048828,,,,,,,,,,,,,,,,,,,,,,,,,,,,,,,,,
,3880074958.98578,300.080001831055,-8499.8544921875,5.59524134606624E-6,1.17065508440326E-8,1,4,13.4005146026611,5.0010437208625,33.4100015461445,0.00696895027439277,9.58452189792892E-4,1,-6.61295589950886E-8,,,,,,,,,,,,,,,,,,,,,300.076782226562,300.083221435547,-8499.8544921875,-8499.8544921875,53.6314408470249,5.6574284060983,6.16155862808228,54,1,0,0,1,0.306472778320313,33.7243423461914,1,1,3,300.076782226562,0,300.080001831055,,,,,,,,,,,,,,,,,,,,,,,,,,,,,,,,,
,3880075042.01299,300.156143188477,-9999.7451171875,1.4408367709886E-5,1.62674626089988E-8,1,4,13.4005146026611,5.00108073141919,33.4200002253056,0.0179223470549867,0.00262630466011855,1,-4.30853935595251E-8,,,,,,,,,,,,,,,,,,,,,300.151306152344,300.160980224609,-9999.7451171875,-9999.7451171875,53.5067710982076,5.65755246538662,6.16373157501221,54,2,0,0,1,0.307388305664063,33.2355842590332,1,1,3,300.151306152344,0,300.156143188477,,,,,,,,,,,,,,,,,,,,,,,,,,,,,,,,,
,3880075229.81195,300.085754394531,-19999.81640625,7.53014268475542E-5,4.12661492290479E-7,1,4,13.4005146026611,5.00103912046736,33.4200002253056,0.093671959682882,0.0136802992235577,1,-2.61536726908427E-7,,,,,,,,,,,,,,,,,,,,,300.085388183594,300.086120605469,-19999.81640625,-19999.81640625,53.6439469033326,5.65678549330627,6.16621017456055,54,3,0,0,1,0.306472778320313,33.2355842590332,1,1,3,300.086120605469,0,300.085754394531,,,,,,,,,,,,,,,,,,,,,,,,,,,,,,,,,
,3880075512.52015,300.072509765625,-39999.68359375,1.96934427010423E-4,6.56986076821465E-8,1,4,13.4005146026611,5.00129124034209,33.4200002253056,0.244888005847034,0.0365010871367929,1,-1.0434833842924E-7,,,,,,,,,,,,,,,,,,,,,300.046447753906,300.098571777344,-39999.68359375,-39999.68359375,53.5759452221595,5.65673887743739,6.14610099792481,54,1,0,0,1,0.307159423828125,33.7243423461914,1,1,3,300.098571777344,0,300.072509765625,,,,,,,,,,,,,,,,,,,,,,,,,,,,,,,,,
,3880075735.47994,300.109298706055,-54999.6328125,2.88805992702099E-4,7.79816669254454E-8,1,4,13.4005146026611,5.00102568480425,33.4200002253056,0.359095276897045,0.0535810603793502,1,-1.08078104124642E-7,,,,,,,,,,,,,,,,,,,,,300.095947265625,300.122650146484,-54999.6328125,-54999.6328125,53.4172746327557,5.65816872269829,6.15581321716309,54,2,0,0,1,0.307464599609375,33.7243423461914,1,1,3,300.122650146484,0,300.109298706055,,,,,,,,,,,,,,,,,,,,,,,,,,,,,,,,,
,3880075978.44502,300.049407958984,-69999.6015625,3.80424138099474E-4,3.17849133445102E-7,1,4,13.4005146026611,5.00115739283665,33.4200002253056,0.473060984451845,0.0703659216631073,1,-3.15524570394523E-7,,,,,,,,,,,,,,,,,,,,,300.047454833984,300.051361083984,-69999.6015625,-69999.6015625,53.2648570715056,5.65727469481753,6.15853023529053,54,3,0,0,1,0.307159423828125,33.7243423461914,1,1,3,300.047454833984,0,300.049407958984,,,,,,,,,,,,,,,,,,,,,,,,,,,,,,,,,
,3880076267.81964,300.049362182617,-49999.765625,2.58130585094162E-4,1.56668640531825E-7,1,4,13.4005146026611,5.00094466356721,33.4100015461445,0.320952991679548,0.047847805162706,1,-1.29639963803552E-7,,,,,,,,,,,,,,,,,,,,,300.040344238281,300.058380126953,-49999.765625,-49999.765625,53.4286082462845,5.65849641215512,6.16488695144653,54,1,0,0,1,0.306396484375,33.7243423461914,1,1,3,300.059387207031,0,300.049362182617,,,,,,,,,,,,,,,,,,,,,,,,,,,,,,,,,
,3880076489.53567,300.157684326172,-34999.62890625,1.66064696898504E-4,7.51627782916833E-8,1,4,13.4005146026611,5.00081932170911,33.4200002253056,0.206477757258555,0.0307518127003787,1,-1.06988111907776E-7,,,,,,,,,,,,,,,,,,,,,300.144470214844,300.1708984375,-34999.62890625,-34999.62890625,53.6021297775537,5.65957234651253,6.16601467132568,54,2,0,0,1,0.302352905273438,33.7243423461914,1,1,3,300.1708984375,0,300.157684326172,,,,,,,,,,,,,,,,,,,,,,,,,,,,,,,,,
,3880076710.15155,300.069061279297,-19999.501953125,7.4528989231063E-5,4.39514931562663E-8,1,4,13.4005146026611,5.00089862986808,33.4200002253056,0.0926637115326095,0.0138317084948928,1,-2.37686974126754E-8,,,,,,,,,,,,,,,,,,,,,300.066741943359,300.071380615234,-19999.501953125,-19999.501953125,53.6763844868807,5.65854798286546,6.17175340652466,54,3,0,0,1,0.300674438476562,34.2131004333496,1,1,3,300.06640625,0,300.069061279297,,,,,,,,,,,,,,,,,,,,,,,,,,,,,,,,,
,3880076911.12801,300.341079711914,-9500.40625,1.11712637961574E-5,1.53676889598083E-8,1,4,13.4005146026611,5.00098532394609,33.4200002253056,0.0138836435151829,0.00211474089498979,1,2.97638166205514E-8,,,,,,,,,,,,,,,,,,,,,300.332275390625,300.349884033203,-9500.40625,-9500.40625,53.6572345881595,5.65893164495943,6.16795921325684,54,1,0,0,1,0.301513671875,34.7018585205078,1,1,3,300.349884033203,0,300.341079711914,,,,,,,,,,,,,,,,,,,,,,,,,,,,,,,,,
,3880077019.39701,300.397491455078,-8000.31396484375,2.39586670463414E-6,1.15259430323544E-8,1,4,13.4005146026611,5.00091414522671,33.4200002253056,0.00297660518954935,4.59669430720326E-4,1,1.13190992747293E-8,,,,,,,,,,,,,,,,,,,,,300.390472412109,300.404510498047,-8000.31396484375,-8000.31396484375,53.4989548130153,5.65884603944599,6.16644477844238,54,2,0,0,1,0.308456420898438,34.2131004333496,1,1,3,300.390472412109,0,300.397491455078,,,,,,,,,,,,,,,,,,,,,,,,,,,,,,,,,
,3880077116.54761,300.2529296875,-6500.23486328125,-6.23443960359372E-6,1.20743420219634E-8,1,4,13.4005146026611,5.001077299809,33.4100015461445,-0.00775923524345049,-0.00110751744884453,1,4.18647087554549E-8,,,,,,,,,,,,,,,,,,,,,300.248718261719,300.257141113281,-6500.23486328125,-6500.23486328125,53.6666141303903,5.6584854951964,6.17338848114014,54,3,0,0,1,0.30792236328125,34.2131004333496,1,1,3,300.257141113281,0,300.2529296875,,,,,,,,,,,,,,,,,,,,,,,,,,,,,,,,,
,3880077216.27841,300.327621459961,-4500.27587890625,-1.71007812373437E-5,1.27546570265505E-8,1,4,13.4005146026611,5.00104038276086,33.4200002253056,-0.0212820226786663,-0.00304440963247124,1,1.09547453048417E-7,,,,,,,,,,,,,,,,,,,,,300.323669433594,300.331573486328,-4500.27587890625,-4500.27587890625,53.4876211994864,5.65920332948256,6.17221164703369,52,1,68,0,0,0.308685302734375,33.7243423461914,1,1,3,300.323669433594,0,300.327621459961,,,,,,,,,,,,,,,,,,,,,,,,,,,,,,,,,
,3880077301.08645,300.199142456055,-3000.3349609375,-2.37542424638414E-5,1.119083765872E-7,1,4,13.4005146026611,5.00105294148663,33.4200002253056,-0.0295298390244173,-0.0044465737088097,1,-2.28862267824561E-8,,,,,,,,,,,,,,,,,,,,,300.187255859375,300.211029052734,-3000.3349609375,-3000.3349609375,53.6025205918134,5.65893791524569,6.17418479919434,53,2,68,0,0,0.307998657226562,33.7243423461914,1,1,3,300.211029052734,0,300.199142456055,,,,,,,,,,,,,,,,,,,,,,,,,,,,,,,,,
,3880077387.37654,300.330810546875,-2900.30883789063,-2.40891671645255E-5,1.05658580274222E-8,1,4,13.4005146026611,5.00096914470063,33.4200002253056,-0.0299372143462889,-0.00456451736443154,1,-6.77315923916952E-8,,,,,,,,,,,,,,,,,,,,,300.322143554687,300.339477539063,-2900.30883789063,-2900.30883789063,53.3207435106306,5.65877845491961,6.17161989212036,54,3,0,0,1,0.303955078125,33.7243423461914,1,1,3,300.322143554687,0,300.330810546875,,,,,,,,,,,,,,,,,,,,,,,,,,,,,,,,,
,3880077468.33806,300.148132324219,-2700.34448242187,-2.47058312654223E-5,1.79142199677654E-8,1,4,13.4005146026611,5.00101963553498,33.4200002253056,-0.0306796424094735,-0.00484437485440574,1,-2.00521760113514E-7,,,,,,,,,,,,,,,,,,,,,300.141693115234,300.154571533203,-2700.34448242187,-2700.34448242187,53.6564529596403,5.65868819805736,6.17813968658447,54,1,0,0,1,0.306472778320313,33.7243423461914,1,1,3,300.154571533203,0,300.148132324219,,,,,,,,,,,,,,,,,,,,,,,,,,,,,,,,,
,3880077540.20252,300.398956298828,-2550.38061523438,-2.51793766394416E-5,1.43168205252882E-8,1,4,13.4005146026611,5.00106782422827,33.4100015461445,-0.0312820767632454,-0.00484394083727661,1,-1.29280675585925E-7,,,,,,,,,,,,,,,,,,,,,300.39697265625,300.400939941406,-2550.38061523438,-2550.38061523438,53.4700345578037,5.65849796692866,6.1765284538269,54,2,0,0,1,0.3076171875,35.190616607666,1,1,3,300.400756835937,0,300.398956298828,,,,,,,,,,,,,,,,,,,,,,,,,,,,,,,,,
,3880077624.48955,300.210632324219,-2400.39135742187,-2.55786581176801E-5,1.20699941673769E-8,1,4,13.4005146026611,5.00123895320653,33.4200002253056,-0.0317888575944628,-0.00485946029157857,1,-8.1845723506108E-8,,,,,,,,,,,,,,,,,,,,,300.204559326172,300.216705322266,-2400.39135742187,-2400.39135742187,53.7209373124768,5.65761889605695,6.17613887786865,54,3,0,0,1,0.306930541992188,33.7243423461914,1,1,3,300.204559326172,0,300.210632324219,,,,,,,,,,,,,,,,,,,,,,,,,,,,,,,,,
,3880077707.3998,300.004379272461,-2200.40161132813,-2.59399733432696E-5,1.8663767207919E-8,1,4,13.4005146026611,5.00104291455078,33.4200002253056,-0.0322248095153874,-0.00500349284005479,1,-1.43855116363441E-7,,,,,,,,,,,,,,,,,,,,,299.999877929687,300.008880615234,-2200.40161132813,-2200.40161132813,53.4520571018614,5.65860961908445,6.17593097686768,54,1,0,0,1,0.300750732421875,33.7243423461914,1,1,3,299.999877929687,0,300.004379272461,,,,,,,,,,,,,,,,,,,,,,,,,,,,,,,,,
,3880077778.97399,300.228378295898,-2050.31201171875,-2.61831368357876E-5,1.50227188860385E-8,1,4,13.4005146026611,5.00115298124679,33.4200002253056,-0.0325374695865205,-0.00498650956164712,1,-9.36961740104073E-8,,,,,,,,,,,,,,,,,,,,,300.225921630859,300.230834960937,-2050.31201171875,-2050.31201171875,53.6204980477557,5.65859309685845,6.17636013031006,53,2,68,0,0,0.309219360351562,33.7243423461914,1,1,3,300.230804443359,0,300.228378295898,,,,,,,,,,,,,,,,,,,,,,,,,,,,,,,,,
,3880077865.891,300.409317016602,-1900.34814453125,-2.6369603207347E-5,9.73799171114157E-9,1,4,13.4005146026611,5.00102844529376,33.4200002253056,-0.03278030700469,-0.00493989335769144,1,-2.84480788209352E-8,,,,,,,,,,,,,,,,,,,,,300.400146484375,300.418487548828,-1900.34814453125,-1900.34814453125,53.5704738225249,5.65832170477715,6.17046308517456,54,3,0,0,1,0.308761596679687,33.7243423461914,1,1,3,300.400146484375,0,300.409317016602,,,,,,,,,,,,,,,,,,,,,,,,,,,,,,,,,
,3880077947.42761,300.333679199219,-1700.06896972656,-2.63425881578326E-5,1.86816421542956E-8,1,4,13.4005146026611,5.00146477031542,33.4200002253056,-0.0327245038702,-0.00511069786068194,1,-1.69366426913505E-7,,,,,,,,,,,,,,,,,,,,,300.326354980469,300.341003417969,-1700.06896972656,-1700.06896972656,53.528656696746,5.65658074007742,6.17315578460693,54,1,0,0,1,0.307083129882812,33.7243423461914,1,1,3,300.341003417969,0,300.333679199219,,,,,,,,,,,,,,,,,,,,,,,,,,,,,,,,,
,3880078016.94837,300.31201171875,-1550.02954101562,-2.62266161591051E-5,1.57518108043815E-8,1,4,13.4005146026611,5.00121758700633,33.4200002253056,-0.0325848883726782,-0.00504302115919641,1,-1.3256956793349E-7,,,,,,,,,,,,,,,,,,,,,300.305480957031,300.318542480469,-1550.02954101562,-1550.02954101562,53.5630483515922,5.65736455018393,6.17648410797119,54,2,0,0,1,0.307388305664063,33.7243423461914,1,1,3,300.305480957031,0,300.31201171875,,,,,,,,,,,,,,,,,,,,,,,,,,,,,,,,,
,3880078088.96503,300.214080810547,-1400.09094238281,-2.60243295699696E-5,1.39416353280853E-8,1,4,13.4005146026611,5.00117878094013,33.4200002253056,-0.0323435559335555,-0.00493490441937262,1,-7.5919312514414E-8,,,,,,,,,,,,,,,,,,,,,300.210723876953,300.217437744141,-1400.09094238281,-1400.09094238281,53.5517147380633,5.65780864599569,6.17611932754517,54,3,0,0,1,0.302276611328125,33.2355842590332,1,1,3,300.210723876953,0,300.214080810547,,,,,,,,,,,,,,,,,,,,,,,,,,,,,,,,,
,3880078187.48815,300.206634521484,-1200.05090332031,-2.53739993374307E-5,2.31621306761653E-8,1,4,13.4005146026611,5.00100160451665,33.4200002253056,-0.0315147809736137,-0.00493814478470529,1,-1.76007729813541E-7,,,,,,,,,,,,,,,,,,,,,300.186553955078,300.226715087891,-1200.05090332031,-1200.05090332031,53.6705222729865,5.65904114362683,6.17522239685059,53,1,68,0,0,0.3057861328125,33.2355842590332,1,1,3,300.226715087891,0,300.206634521484,,,,,,,,,,,,,,,,,,,,,,,,,,,,,,,,,
,3880078259.72964,300.186279296875,-1050.07446289062,-2.46587696255219E-5,1.74771870965259E-8,1,4,13.4005146026611,5.00081616626368,33.4200002253056,-0.0306336717690139,-0.00473985636926618,1,-1.23714050845936E-7,,,,,,,,,,,,,,,,,,,,,300.177703857422,300.194854736328,-1050.07446289062,-1050.07446289062,53.6380846894384,5.65893050902326,6.17448425292969,54,2,0,0,1,0.302505493164063,33.7243423461914,1,1,3,300.194854736328,0,300.186279296875,,,,,,,,,,,,,,,,,,,,,,,,,,,,,,,,,
,3880078331.82035,300.33122253418,-900.085388183594,-2.37142125171193E-5,1.30530588216885E-8,1,4,13.4005146026611,5.00087929072974,33.4200002253056,-0.0294664015772346,-0.00452070155428979,1,-8.86720814852696E-8,,,,,,,,,,,,,,,,,,,,,300.331085205078,300.331359863281,-900.085388183594,-900.085388183594,53.6287051472076,5.65841724772662,6.18018198013306,54,3,0,0,1,0.2996826171875,33.2355842590332,1,1,3,300.331359863281,0,300.33122253418,,,,,,,,,,,,,,,,,,,,,,,,,,,,,,,,,
,3880078415.59815,300.278213500977,-700.083251953125,-2.18441882153121E-5,2.02940523567851E-8,1,4,13.4005146026611,5.00077824109656,33.4200002253056,-0.0271228691006549,-0.00429205683485995,1,-1.84606171552242E-7,,,,,,,,,,,,,,,,,,,,,300.260955810547,300.295471191406,-700.083251953125,-700.083251953125,53.6603611022364,5.65931017484448,6.17426538467407,54,1,0,0,1,0.302734375,33.7243423461914,1,1,3,300.295471191406,0,300.278213500977,,,,,,,,,,,,,,,,,,,,,,,,,,,,,,,,,
,3880078486.55752,300.300567626953,-550.094116210937,-2.00040250455988E-5,1.62144788898789E-8,1,4,13.4005146026611,5.00077877165015,33.4200002253056,-0.0248397986069418,-0.00391867963162836,1,-1.59552801173873E-7,,,,,,,,,,,,,,,,,,,,,300.295074462891,300.306060791016,-550.094116210937,-550.094116210937,53.6337857325826,5.65848503470263,6.17382478713989,54,2,0,0,1,0.29998779296875,33.2355842590332,1,1,3,300.295074462891,0,300.300567626953,,,,,,,,,,,,,,,,,,,,,,,,,,,,,,,,,
,3880078564.13102,300.233993530273,-400.130279541016,-1.76249773598325E-5,1.40721409790806E-8,1,4,13.4005146026611,5.00083116400128,33.4200002253056,-0.0218949701639563,-0.00339246176467491,10,-9.21347254604416E-8,,,,,,,,,,,,,,,,,,,,,300.233459472656,300.234527587891,-400.130279541016,-400.130279541016,53.4786324715153,5.65883627911425,6.17646265029907,54,3,0,0,1,0.300979614257812,33.2355842590332,1,1,3,300.233459472656,0,300.233993530273,,,,,,,,,,,,,,,,,,,,,,,,,,,,,,,,,
,3880078651.86048,300.145706176758,-200.052551269531,-1.30241933069169E-5,2.40097485828808E-8,1,4,13.4005146026611,5.00106806782433,33.4200002253056,-0.0161501395476906,-0.00271088518692722,1,-2.32013799077885E-7,,,,,,,,,,,,,,,,,,,,,300.129791259766,300.16162109375,-200.052551269531,-200.052551269531,53.582589064573,5.65786122467115,6.17549610137939,52,1,68,0,0,0.299911499023438,33.2355842590332,1,1,3,300.16162109375,0,300.145706176758,,,,,,,,,,,,,,,,,,,,,,,,,,,,,,,,,
,3880078732.8785,300.252639770508,-50.113842010498,-8.24149097336549E-6,2.14395394450498E-8,1,4,13.4005146026611,5.00114430154525,33.4200002253056,-0.0102162090072895,-0.00173914525958651,1,-1.65880673640278E-7,,,,,,,,,,,,,,,,,,,,,300.245971679687,300.259307861328,-50.113842010498,-50.113842010498,53.5360821676787,5.65803271234779,6.17495393753052,54,2,0,0,1,0.307388305664063,33.2355842590332,1,1,3,300.259307861328,0,300.252639770508,,,,,,,,,,,,,,,,,,,,,,,,,,,,,,,,,
,3880078820.30706,300.234115600586,99.8500366210937,-1.79495704875275E-6,1.80131893113736E-8,1,4,13.4005146026611,5.00105340940843,33.4200002253056,-0.00220461223697364,-5.14951955524621E-4,1,-1.45660747805002E-7,,,,,,,,,,,,,,,,,,,,,300.230224609375,300.238006591797,99.8500366210937,99.8500366210937,53.5388178674961,5.65827175166287,6.17515277862549,52,3,68,0,0,0.307464599609375,35.190616607666,1,1,3,300.230224609375,0,300.234115600586,,,,,,,,,,,,,,,,,,,,,,,,,,,,,,,,,
,3880078916.4254,300.354309082031,299.776702880859,6.8244819662639E-6,3.50783306829287E-8,1,4,13.4005146026611,5.00101317314046,33.4200002253056,0.00852726319916173,9.86183777896841E-4,1,-2.27705060965503E-7,,,,,,,,,,,,,,,,,,,,,300.346343994141,300.362274169922,299.776702880859,299.776702880859,53.5818074360538,5.6587720482239,6.17438077926636,54,1,0,0,1,0.304946899414063,33.2355842590332,1,1,3,300.346343994141,0,300.354309082031,,,,,,,,,,,,,,,,,,,,,,,,,,,,,,,,,
,3880079000.97021,300.398880004883,449.816101074219,1.19028221439711E-5,8.89364734071737E-9,1,4,13.4005146026611,5.00100773590045,33.4200002253056,0.0148137806505092,0.00211377032337884,1,-8.04641128907945E-8,,,,,,,,,,,,,,,,,,,,,300.393218994141,300.404541015625,449.816101074219,449.816101074219,53.5005180700537,5.65864200495713,6.1730170249939,54,2,0,0,1,0.309066772460937,33.7243423461914,1,1,3,300.393218994141,0,300.398880004883,,,,,,,,,,,,,,,,,,,,,,,,,,,,,,,,,
,3880079072.97425,300.358596801758,599.855529785156,1.58577117529883E-5,1.9995100907651E-8,1,4,13.4005146026611,5.00091434884584,33.4200002253056,0.0197426476457381,0.0027673375418418,1,-1.46362997823075E-7,,,,,,,,,,,,,,,,,,,,,300.357299804687,300.359893798828,599.855529785156,599.855529785156,53.5743819651211,5.65826010418156,6.17442131042481,53,3,68,0,0,0.307846069335937,33.2355842590332,1,1,3,300.359893798828,0,300.358596801758,,,,,,,,,,,,,,,,,,,,,,,,,,,,,,,,,
,3880079154.7459,300.366424560547,799.555603027344,1.96865136251006E-5,2.10759352459207E-8,1,4,13.4005146026611,5.0007643330465,33.4200002253056,0.0245167770926292,0.00337954798091637,1,-2.26594755790302E-7,,,,,,,,,,,,,,,,,,,,,300.358642578125,300.374206542969,799.555603027344,799.555603027344,53.4876211994864,5.65919797844229,6.18037080764771,54,1,0,0,1,0.308380126953125,33.2355842590332,1,1,3,300.358642578125,0,300.366424560547,,,,,,,,,,,,,,,,,,,,,,,,,,,,,,,,,
,3880079226.87426,300.211730957031,949.79638671875,2.16587120703041E-5,1.59612192118603E-8,1,4,13.4005146026611,5.00071339204164,33.4200002253056,0.0269565937396336,0.00382430615050409,1,-1.63832225173714E-7,,,,,,,,,,,,,,,,,,,,,300.199829101562,300.2236328125,949.79638671875,949.79638671875,53.4977823702364,5.65890376092694,6.17409753799438,53,2,68,0,0,0.300445556640625,33.2355842590332,1,1,3,300.2236328125,0,300.211730957031,,,,,,,,,,,,,,,,,,,,,,,,,,,,,,,,,
,3880079298.41797,300.129653930664,1099.81066894531,2.31096657598287E-5,2.24965796021222E-8,1,4,13.4005146026611,5.00079799663948,33.4200002253056,0.0287563646621925,0.004125907194887,1,-1.38364076608625E-7,,,,,,,,,,,,,,,,,,,,,300.124969482422,300.134338378906,1099.81066894531,1099.81066894531,53.6290959614672,5.6589350100103,6.17697620391846,52,3,68,0,0,0.305709838867188,33.2355842590332,1,1,3,300.124969482422,0,300.129653930664,,,,,,,,,,,,,,,,,,,,,,,,,,,,,,,,,
,3880079380.87837,300.142013549805,1299.57373046875,2.45009959051082E-5,1.30440367557475E-8,1,4,13.4005146026611,5.00072103282996,33.4200002253056,0.0304922702884367,0.00433899040393279,1,-1.75028502851651E-7,,,,,,,,,,,,,,,,,,,,,300.123199462891,300.160827636719,1299.57373046875,1299.57373046875,53.6040838488518,5.65895616383116,6.17595052719116,52,1,68,0,0,0.305709838867188,33.7243423461914,1,1,3,300.160827636719,0,300.142013549805,,,,,,,,,,,,,,,,,,,,,,,,,,,,,,,,,
,3880079452.62498,300.093673706055,1449.814453125,2.50610076559272E-5,6.95654589676653E-8,1,4,13.4005146026611,5.00089305042891,33.4100015461445,0.0311803463287937,0.00450775179101038,1,-1.23230124101711E-7,,,,,,,,,,,,,,,,,,,,,300.089233398438,300.098114013672,1449.814453125,1449.814453125,53.592750235323,5.65867852626314,6.17590093612671,54,2,0,0,1,0.307464599609375,33.2355842590332,1,1,3,300.089233398438,0,300.093673706055,,,,,,,,,,,,,,,,,,,,,,,,,,,,,,,,,
,3880079524.31236,300.172210693359,1599.63989257813,2.55269848130491E-5,1.67970330863907E-8,1,4,13.4005146026611,5.00096121999826,33.4200002253056,0.0317623459792517,0.00458072255865308,1,-1.34314777048576E-7,,,,,,,,,,,,,,,,,,,,,300.166809082031,300.177612304687,1599.63989257813,1599.63989257813,53.6025205918134,5.65830537364536,6.17424058914185,54,3,0,0,1,0.300064086914063,32.7468223571777,1,1,3,300.166809082031,0,300.172210693359,,,,,,,,,,,,,,,,,,,,,,,,,,,,,,,,,
,3880079606.56021,300.116897583008,1799.65466308594,2.58353318869797E-5,7.91765405513933E-8,1,4,13.4005146026611,5.00094050876149,33.4200002253056,0.0321658307537269,0.0045022956810031,1,-2.43500889389287E-7,,,,,,,,,,,,,,,,,,,,,300.115447998047,300.118347167969,1799.65466308594,1799.65466308594,53.5263118111883,5.65768348099646,6.17464637756348,52,1,68,0,0,0.3070068359375,33.2355842590332,1,1,3,300.115447998047,0,300.116897583008,,,,,,,,,,,,,,,,,,,,,,,,,,,,,,,,,
,3880079678.482,300.182846069336,1950.02136230469,2.58535113418295E-5,8.54286648971072E-9,1,4,13.4005146026611,5.00084128246833,33.4200002253056,0.0321640295871487,0.00466270804271251,1,-1.17092740327244E-7,,,,,,,,,,,,,,,,,,,,,300.175140380859,300.190551757812,1950.02136230469,1950.02136230469,53.5657840514095,5.65823324617025,6.17665958404541,53,2,68,0,0,0.304031372070313,32.2580642700195,1,1,3,300.190551757812,0,300.182846069336,,,,,,,,,,,,,,,,,,,,,,,,,,,,,,,,,
,3880079750.01334,300.158462524414,2099.89697265625,2.57492667133513E-5,8.54569374106153E-9,1,4,13.4005146026611,5.00091445598999,33.4200002253056,0.0320336382994461,0.00465307882860583,1,-1.09320242441345E-7,,,,,,,,,,,,,,,,,,,,,300.154479980469,300.162445068359,2099.89697265625,2099.89697265625,53.5427260100922,5.65788461071046,6.17562103271484,54,3,0,0,1,0.3076171875,32.7468223571777,1,1,3,300.154479980469,0,300.158462524414,,,,,,,,,,,,,,,,,,,,,,,,,,,,,,,,,
,3880079832.2728,300.072082519531,2300.01245117187,2.54706810550695E-5,9.15148218443699E-9,1,4,13.4005146026611,5.0010785254285,33.4200002253056,0.0316943591866303,0.00456388508561599,1,-1.39555273585348E-7,,,,,,,,,,,,,,,,,,,,,300.070739746094,300.073425292969,2300.01245117187,2300.01245117187,53.404768576448,5.65696482513457,6.16939640045166,54,1,0,0,1,0.300827026367188,33.2355842590332,1,1,3,300.070739746094,0,300.072082519531,,,,,,,,,,,,,,,,,,,,,,,,,,,,,,,,,
,3880079903.97202,300.378005981445,2449.97631835938,2.51712343830659E-5,9.50190658220104E-9,1,4,13.4005146026611,5.00107183521684,33.4200002253056,0.0313181450931964,0.00453388509087342,1,-1.18881861436932E-7,,,,,,,,,,,,,,,,,,,,,300.364044189453,300.391967773438,2449.97631835938,2449.97631835938,53.511460869323,5.65696692774133,6.17597484588623,52,2,68,0,0,0.3076171875,32.7468223571777,6,1,3,300.391967773438,0,300.378005981445,,,,,,,,,,,,,,,,,,,,,,,,,,,,,,,,,
,3880080016.40359,300.40380859375,2599.85229492187,2.47696620541377E-5,7.38829912060636E-9,1,4,13.4005146026611,5.00113265922557,33.4200002253056,0.0308133357299728,0.00449970576272504,1,-8.63609564066629E-8,,,,,,,,,,,,,,,,,,,,,300.395904541016,300.411712646484,2599.85229492187,2599.85229492187,53.5943134923614,5.65740672502395,6.17369794845581,54,3,0,0,1,0.307388305664063,33.2355842590332,1,1,3,300.395111083984,0,300.40380859375,,,,,,,,,,,,,,,,,,,,,,,,,,,,,,,,,
,3880080098.4087,300.236999511719,2799.82934570313,2.41959669090248E-5,8.38073910753074E-9,1,4,13.4005146026611,5.00113257999605,33.4200002253056,0.0301041481236606,0.00436549283816084,1,-1.08484525917962E-7,,,,,,,,,,,,,,,,,,,,,300.225891113281,300.248107910156,2799.82934570313,2799.82934570313,53.5415535673134,5.65728672878944,6.17902231216431,54,1,0,0,1,0.301666259765625,33.2355842590332,1,1,3,300.248107910156,0,300.236999511719,,,,,,,,,,,,,,,,,,,,,,,,,,,,,,,,,
,3880080170.21676,300.178070068359,2949.95678710937,2.36850468488644E-5,8.35662789072419E-9,1,4,13.4005146026611,5.00113603974646,33.4200002253056,0.0294686084848544,0.00427258983579094,1,-1.06777481036397E-7,,,,,,,,,,,,,,,,,,,,,300.175842285156,300.180297851562,2949.95678710937,2949.95678710937,53.5923594210634,5.65635676804071,6.17389392852783,54,2,0,0,1,0.300216674804687,33.2355842590332,1,1,3,300.175476074219,0,300.178070068359,,,,,,,,,,,,,,,,,,,,,,,,,,,,,,,,,
,3880080271.08245,300.269454956055,3499.59765625,2.1509025944276E-5,6.91240318644382E-9,1,4,13.4005146026611,5.00110315138266,33.4200002253056,0.0267468725625867,0.00397436970405029,1,-2.10813057543877E-8,,,,,,,,,,,,,,,,,,,,,300.258758544922,300.280151367188,3499.59765625,3499.59765625,53.521622040073,5.65720827495726,6.17389059066772,54,3,0,0,1,0.300216674804687,32.7468223571777,1,1,3,300.258758544922,0,300.269454956055,,,,,,,,,,,,,,,,,,,,,,,,,,,,,,,,,
,3880080369.33113,300.111145019531,5499.833984375,1.14942308025341E-5,8.99768520943499E-9,1,4,13.4005146026611,5.00119636221572,33.4200002253056,0.0142838708672459,0.00218937361393901,1,4.13741195943041E-8,,,,,,,,,,,,,,,,,,,,,300.110443115234,300.111846923828,5499.833984375,5499.833984375,53.5939226781018,5.65690486873852,6.16940975189209,53,1,68,0,0,0.309219360351562,32.7468223571777,1,1,3,300.111846923828,0,300.111145019531,,,,,,,,,,,,,,,,,,,,,,,,,,,,,,,,,
,3880080464.39816,300.170989990234,7000.0009765625,3.1122881970945E-6,1.02334395355746E-8,1,4,13.4005146026611,5.00123644430477,33.4200002253056,0.00386196082911945,6.3106229949339E-4,1,4.19575452371735E-8,,,,,,,,,,,,,,,,,,,,,300.156494140625,300.185485839844,7000.0009765625,7000.0009765625,53.5091159837653,5.65721791925479,6.17510747909546,53,2,68,0,0,0.308074951171875,33.2355842590332,1,1,3,300.185485839844,0,300.170989990234,,,,,,,,,,,,,,,,,,,,,,,,,,,,,,,,,
,3880080585.84325,300.087478637695,8500.1435546875,-5.57585057474807E-6,1.30619513183467E-8,1,4,13.4005146026611,5.00119315440314,33.4200002253056,-0.00693755289964458,-0.00100554874607007,1,2.5382823903271E-8,,,,,,,,,,,,,,,,,,,,,300.083770751953,300.091186523438,8500.1435546875,8500.1435546875,53.5935318638422,5.65653384511146,6.17870187759399,53,3,68,0,0,0.306396484375,32.7468223571777,1,1,3,300.083770751953,0,300.087478637695,,,,,,,,,,,,,,,,,,,,,,,,,,,,,,,,,
,3880080697.81429,300.419281005859,10000.248046875,-1.44232021528686E-5,1.2301799989106E-8,1,4,13.4005146026611,5.00114721521791,33.4200002253056,-0.0179368594070714,-0.00265762631704335,1,2.01525153923238E-8,,,,,,,,,,,,,,,,,,,,,300.418212890625,300.420349121094,10000.248046875,10000.248046875,53.4817589855922,5.65709513732871,6.16937017440796,54,1,0,0,1,0.299072265625,33.2355842590332,1,1,3,300.418212890625,0,300.419281005859,,,,,,,,,,,,,,,,,,,,,,,,,,,,,,,,,
,3880080916.50387,300.055358886719,25000.197265625,-1.051825671777E-4,2.96682459421812E-8,1,4,13.4005146026611,5.00118463853222,33.4200002253056,-0.130800262423612,-0.0194303445009954,1,1.07434248928146E-7,,,,,,,,,,,,,,,,,,,,,300.053771972656,300.056945800781,25000.197265625,25000.197265625,53.5169322689576,5.65721152292735,6.17585706710815,54,2,0,0,1,0.306320190429687,33.2355842590332,1,1,3,300.053771972656,0,300.055358886719,,,,,,,,,,,,,,,,,,,,,,,,,,,,,,,,,
,3880081138.11451,300.070083618164,40000.27734375,-1.9685188245255E-4,6.20238082763578E-8,1,4,13.4005146026611,5.0010380619203,33.4100015461445,-0.2447749489142,-0.0364369031999505,1,1.41543949088612E-7,,,,,,,,,,,,,,,,,,,,,300.067810058594,300.072357177734,40000.27734375,40000.27734375,53.437206159996,5.65832554247768,6.1721363067627,54,3,0,0,1,0.307846069335937,33.2355842590332,1,1,3,300.067810058594,0,300.070083618164,,,,,,,,,,,,,,,,,,,,,,,,,,,,,,,,,
,3880081420.47837,300.081939697266,60000.26953125,-3.1943090307645E-4,1.01386579160826E-7,1,4,13.4005146026611,5.00093750790253,33.4100015461445,-0.397181445219504,-0.0591436670973789,1,2.14169509169082E-7,,,,,,,,,,,,,,,,,,,,,300.079193115234,300.084686279297,60000.26953125,60000.26953125,53.3199618821114,5.658721728457,6.17046642303467,54,1,0,0,1,0.302505493164063,33.2355842590332,1,1,3,300.079193115234,0,300.081939697266,,,,,,,,,,,,,,,,,,,,,,,,,,,,,,,,,
,3880081586.82749,300.050674438477,70000.46875,-3.80725376752269E-4,2.72157502191489E-7,1,4,13.4005146026611,5.00098502347853,33.4100015461445,-0.473390280605179,-0.0705684147993274,1,1.94990429692176E-7,,,,,,,,,,,,,,,,,,,,,300.048370361328,300.052978515625,70000.46875,70000.46875,53.1507393076979,5.6576779044442,6.17050313949585,54,3,0,0,1,0.306167602539063,33.2355842590332,1,1,3,300.048370361328,0,300.050674438477,,,,,,,,,,,,,,,,,,,,,,,,,,,,,,,,,