File: SQUID/22169_LCOT/22169_LCOT_MH_280K_FC_0d5T.csv
Comment,Time Stamp (sec),Temperature (K),Magnetic Field (Oe),Moment (emu),M. Std. Err. (emu),Transport Action,Averaging Time (sec),Frequency (Hz),Peak Amplitude (mm),Center Position (mm),Lockin Signal' (V),Lockin Signal (V),Range,M. Quad. Signal (emu),AC Moment (emu),AC M. Std Err. (emu),AC Phase (deg),AC Phase Std. Err. (deg),AC Susceptibility (emu/Oe),AC Suscept. Std Err. (emu/Oe),AC X' (emu/Oe),AC X' Std Err. (emu/Oe),AC X'' (emu/Oe),AC X'' Std Err. (emu/Oe),AC Drive (Oe),AC Frequency (Hz),AC Averaging Time (sec),AC Cycles,AC Range,AC Measure Type,AC Signal' (V),AC Signal'' (V),AC Trim Coil Ratio,AC Trim Coil Phase,Min. Temperature (K),Max. Temperature (K),Min. Field (Oe),Max. Field (Oe),Mass (grams),Motor Lag (deg),Pressure (Torr),Measure Count,Measurement Number,SQUID Status (code),Motor Status (code),Measure Status (code),Motor Current (amps),Motor Temp. (C),Temp. Status (code),Field Status (code),Chamber Status (code),Chamber Temp (K),Redirection State,Average Temp (K),Rotation Angle (deg),Rotator state,DC Moment Fixed Ctr (emu),DC Moment Err Fixed Ctr (emu),DC Moment Free Ctr (emu),DC Moment Err Free Ctr (emu),DC Fixed Fit,DC Free Fit,DC Calculated Center (mm),DC Calculated Center Err (mm),DC Scan Length (mm),DC Scan Time (s),DC Number of Points,DC Squid Drift,DC Min V (V),DC Max V (V),DC Scans per Measure,Sample Resistance,He3 Temperature,Sorb Resistance,Sorb Temperature,Map 05,Map 06,Map 07,Map 08,Map 09,Map 10,Map 11,Map 12,Map 13,Map 14,Map 15,Map 16
,3880058687.27246,280.003433227539,69999.671875,-3.80142084964571E-4,1.85889422248426E-7,1,4,13.4005146026611,5.00214814634993,33.4200002253056,-0.472798349118324,-0.0706202184256643,1,8.45459984526821E-8,,,,,,,,,,,,,,,,,,,,,280.0029296875,280.003936767578,69999.671875,69999.671875,53.3445831804672,5.65320868583274,6.05187129974365,54,1,0,0,1,0.306549072265625,32.7468223571777,1,1,3,280.003936767578,0,280.003433227539,,,,,,,,,,,,,,,,,,,,,,,,,,,,,,,,,
,3880058940.25969,280.141525268555,55000.3125,-2.88404809303706E-4,1.62483119239382E-7,1,4,13.4005146026611,5.0015777174301,33.4200002253056,-0.358704117952038,-0.0531654367112741,10,3.88955466226638E-7,,,,,,,,,,,,,,,,,,,,,280.140533447266,280.142517089844,55000.3125,55000.3125,53.4833222426306,5.65684197197569,6.0557713508606,54,2,0,0,1,0.306549072265625,33.7243423461914,1,1,3,280.144195556641,0,280.141525268555,,,,,,,,,,,,,,,,,,,,,,,,,,,,,,,,,
,3880059164.6214,280.208389282227,39999.6328125,-1.96375671854165E-4,4.57680424652224E-8,1,4,13.4005146026611,5.00147041767778,33.4200002253056,-0.244205896194492,-0.0363962640650284,1,1.0653274754049E-7,,,,,,,,,,,,,,,,,,,,,280.201141357422,280.215637207031,39999.6328125,39999.6328125,53.4669080437268,5.65762175532545,6.05910491943359,54,3,0,0,1,0.307846069335937,34.2131004333496,1,1,3,280.215637207031,0,280.208389282227,,,,,,,,,,,,,,,,,,,,,,,,,,,,,,,,,
,3880059445.7231,280.152145385742,19999.767578125,-7.41596544042191E-5,2.56555430478149E-8,1,4,13.4005146026611,5.00137355503436,33.4200002253056,-0.0922053654389875,-0.0138411724722753,1,-3.76144807585786E-8,,,,,,,,,,,,,,,,,,,,,280.128540039062,280.175750732422,19999.767578125,19999.767578125,53.6017389632941,5.65794611460412,6.06603860855103,54,1,0,0,1,0.306777954101562,33.7243423461914,1,1,3,280.180633544922,0,280.152145385742,,,,,,,,,,,,,,,,,,,,,,,,,,,,,,,,,
,3880059635.0346,280.364654541016,9999.8076171875,-1.38728071446612E-5,1.28276858690812E-8,1,4,13.4005146026611,5.00123374818391,33.4100015461445,-0.0172492772701168,-0.00257981787026749,1,4.46647465839499E-10,,,,,,,,,,,,,,,,,,,,,280.363555908203,280.365753173828,9999.8076171875,9999.8076171875,53.5915777925441,5.65784815930062,6.05803394317627,54,2,0,0,1,0.306930541992188,34.2131004333496,1,1,3,280.365692138672,0,280.364654541016,,,,,,,,,,,,,,,,,,,,,,,,,,,,,,,,,
,3880059721.22603,280.296188354492,8499.65234375,-5.02105248751111E-6,1.0398031874264E-8,1,4,13.4005146026611,5.00120834662255,33.4200002253056,-0.00623765260645569,-9.69935766367873E-4,1,-2.89658786184666E-8,,,,,,,,,,,,,,,,,,,,,280.29248046875,280.299896240234,8499.65234375,8499.65234375,53.5993940777364,5.65945421531394,6.0633487701416,54,3,0,0,1,0.307540893554687,35.190616607666,1,1,3,280.292022705078,0,280.296188354492,,,,,,,,,,,,,,,,,,,,,,,,,,,,,,,,,
,3880059822.56925,280.286239624023,6499.66845703125,6.52617915051181E-6,9.02822476098378E-9,1,4,13.4005146026611,5.00151132939808,33.4200002253056,0.0081314016003554,0.00110541858843732,1,-8.73032026148915E-8,,,,,,,,,,,,,,,,,,,,,280.277191162109,280.295288085938,6499.66845703125,6499.66845703125,53.628314332948,5.65692244969095,6.06528043746948,53,1,68,0,0,0.307388305664063,34.2131004333496,1,1,3,280.295288085938,0,280.286239624023,,,,,,,,,,,,,,,,,,,,,,,,,,,,,,,,,
,3880059908.9482,280.096557617187,4999.82861328125,1.47471695687848E-5,8.75347484732769E-9,1,4,13.4005146026611,5.00156385136339,33.4200002253056,0.0183528296553292,0.00264448719114647,1,-7.94314521507008E-8,,,,,,,,,,,,,,,,,,,,,280.092681884766,280.100433349609,4999.82861328125,4999.82861328125,53.523576111371,5.6578982484767,6.06710577011108,53,2,68,0,0,0.3070068359375,34.2131004333496,1,1,3,280.092681884766,0,280.096557617187,,,,,,,,,,,,,,,,,,,,,,,,,,,,,,,,,
,3880059994.44047,280.116806030273,3499.64819335937,2.20465830931214E-5,7.89692793303195E-9,1,4,13.4005146026611,5.00131656934512,33.4200002253056,0.0274268403647212,0.00400797251499074,1,-7.46626933164342E-8,,,,,,,,,,,,,,,,,,,,,280.112457275391,280.121154785156,3499.64819335937,3499.64819335937,53.7013965994961,5.65822728290062,6.06499528884888,54,3,0,0,1,0.303955078125,34.2131004333496,1,1,3,280.112457275391,0,280.116806030273,,,,,,,,,,,,,,,,,,,,,,,,,,,,,,,,,
,3880060100.96642,280.316909790039,2899.72973632812,2.42850933634499E-5,1.63716761511206E-8,1,4,13.4005146026611,5.00121689698764,33.4200002253056,0.0301671340799649,0.00470666481186355,1,1.52491553814508E-7,,,,,,,,,,,,,,,,,,,,,280.291534423828,280.34228515625,2899.72973632812,2899.72973632812,53.5239669256307,5.6588361942245,6.06417942047119,52,1,68,0,0,0.307159423828125,34.2131004333496,1,1,3,280.34228515625,0,280.316909790039,,,,,,,,,,,,,,,,,,,,,,,,,,,,,,,,,
,3880060182.59596,280.195297241211,2749.63989257813,2.47841086925399E-5,1.46577736488627E-8,1,4,13.4005146026611,5.00121564031754,33.4200002253056,0.0307959488567522,0.00474358256181808,1,1.07534820915099E-7,,,,,,,,,,,,,,,,,,,,,280.188598632813,280.201995849609,2749.63989257813,2749.63989257813,53.6369122466595,5.65819225289474,6.0621452331543,53,2,68,0,0,0.307998657226562,34.2131004333496,1,1,3,280.188598632813,0,280.195297241211,,,,,,,,,,,,,,,,,,,,,,,,,,,,,,,,,
,3880060268.53211,280.257080078125,2599.77685546875,2.52504142076946E-5,1.16619080821316E-8,1,4,13.4005146026611,5.00134195797619,33.4200002253056,0.0313818821016378,0.00479685166610427,1,8.04843836408722E-8,,,,,,,,,,,,,,,,,,,,,280.249755859375,280.264404296875,2599.77685546875,2599.77685546875,53.6462917888903,5.65783856523424,6.06247615814209,54,3,0,0,1,0.306396484375,33.7243423461914,1,1,3,280.249755859375,0,280.257080078125,,,,,,,,,,,,,,,,,,,,,,,,,,,,,,,,,
,3880060349.17752,280.182601928711,2399.63598632813,2.57313575121841E-5,1.81497729123228E-8,1,4,13.4005146026611,5.00115621751917,33.4200002253056,0.0319605933459551,0.00500398379789484,1,1.75330051102815E-7,,,,,,,,,,,,,,,,,,,,,280.170196533203,280.195007324219,2399.63598632813,2399.63598632813,53.6521540027845,5.65846865116773,6.06738233566284,54,1,0,0,1,0.308303833007812,33.7243423461914,1,1,3,280.195007324219,0,280.182601928711,,,,,,,,,,,,,,,,,,,,,,,,,,,,,,,,,
,3880060420.57656,280.307037353516,2249.63427734375,2.60702341894825E-5,1.47144972778978E-8,1,4,13.4005146026611,5.00118300670994,33.4200002253056,0.0323920576259616,0.00500102238933296,1,1.22224250867964E-7,,,,,,,,,,,,,,,,,,,,,280.295135498047,280.318939208984,2249.63427734375,2249.63427734375,53.6670049446499,5.65885133538318,6.06361436843872,53,2,68,0,0,0.301437377929687,33.7243423461914,1,1,3,280.318939208984,0,280.307037353516,,,,,,,,,,,,,,,,,,,,,,,,,,,,,,,,,
,3880060535.97977,280.429946899414,2099.64526367187,2.63546266102772E-5,7.95553465430881E-9,1,4,13.4005146026611,5.00136862929078,33.4100015461445,0.0327612929570405,0.00496105347912495,1,4.73279059097452E-8,,,,,,,,,,,,,,,,,,,,,280.421813964844,280.438079833984,2099.64526367187,2099.64526367187,53.5321740250826,5.65754274507262,6.06683111190796,54,3,0,0,1,0.307235717773438,33.7243423461914,1,1,3,280.420257568359,0,280.429946899414,,,,,,,,,,,,,,,,,,,,,,,,,,,,,,,,,
,3880060617.66548,280.400100708008,1899.97045898438,2.64792913834702E-5,2.0680115616005E-8,1,4,13.4005146026611,5.0012905989351,33.4200002253056,0.0328922506196718,0.00514012591112827,1,1.72784118804283E-7,,,,,,,,,,,,,,,,,,,,,280.391754150391,280.408447265625,1899.97045898438,1899.97045898438,53.6169807194191,5.65832709457106,6.07300710678101,52,1,68,0,0,0.306854248046875,33.7243423461914,1,1,3,280.408447265625,0,280.400100708008,,,,,,,,,,,,,,,,,,,,,,,,,,,,,,,,,
,3880060689.90406,280.32731628418,1749.54077148438,2.65133861670341E-5,1.82842803478317E-8,1,4,13.4005146026611,5.00111980632254,33.4200002253056,0.0329433782964009,0.0050773158204112,1,1.17364146910059E-7,,,,,,,,,,,,,,,,,,,,,280.319946289062,280.334686279297,1749.54077148438,1749.54077148438,53.5704738225249,5.65852473623562,6.07001256942749,54,2,0,0,1,0.301437377929687,33.7243423461914,1,1,3,280.319946289062,0,280.32731628418,,,,,,,,,,,,,,,,,,,,,,,,,,,,,,,,,
,3880060775.0588,280.296417236328,1599.53918457031,2.64683117752464E-5,1.34205375419193E-8,1,4,13.4005146026611,5.001223966125,33.4200002253056,0.0328953046544533,0.00502221421842662,1,7.96719533554101E-8,,,,,,,,,,,,,,,,,,,,,280.286285400391,280.306549072266,1599.53918457031,1599.53918457031,53.6799018152172,5.65876709803092,6.07352209091187,54,3,0,0,1,0.307846069335937,33.7243423461914,1,1,3,280.286285400391,0,280.296417236328,,,,,,,,,,,,,,,,,,,,,,,,,,,,,,,,,
,3880060856.6292,280.221405029297,1399.81396484375,2.61111112680755E-5,2.27306206487451E-8,1,4,13.4005146026611,5.00128951612731,33.4200002253056,0.0324253569170567,0.00513239337048318,1,2.21643986238802E-7,,,,,,,,,,,,,,,,,,,,,280.198516845703,280.244293212891,1399.81396484375,1399.81396484375,53.5220128543326,5.65814648430904,6.06825017929077,53,1,68,0,0,0.308303833007812,33.7243423461914,1,1,3,280.244293212891,0,280.221405029297,,,,,,,,,,,,,,,,,,,,,,,,,,,,,,,,,
,3880060944.0772,280.363204956055,1249.76196289062,2.56949494313274E-5,1.87092941791875E-8,1,4,13.4005146026611,5.00121648815015,33.4200002253056,0.0319213474385639,0.00496063652595163,1,1.45846040251753E-7,,,,,,,,,,,,,,,,,,,,,280.35107421875,280.375335693359,1249.76196289062,1249.76196289062,53.5579677662172,5.65845650540338,6.06353616714478,53,2,68,0,0,0.309371948242188,33.7243423461914,6,1,3,280.375335693359,0,280.363204956055,,,,,,,,,,,,,,,,,,,,,,,,,,,,,,,,,
,3880061014.27913,280.105194091797,1099.81066894531,2.51101092291704E-5,1.47726360780903E-8,1,4,13.4005146026611,5.00136756266501,33.4200002253056,0.0312029601003979,0.00480212373394021,1,1.0568545516267E-7,,,,,,,,,,,,,,,,,,,,,280.09716796875,280.113220214844,1099.81066894531,1099.81066894531,53.503253769871,5.6580843183129,6.06863069534302,54,3,0,0,1,0.302505493164063,33.7243423461914,1,1,3,280.09716796875,0,280.105194091797,,,,,,,,,,,,,,,,,,,,,,,,,,,,,,,,,
,3880061096.42509,280.345916748047,899.984680175781,2.37443728610225E-5,2.23492724359013E-8,1,4,13.4005146026611,5.0014275439178,33.4200002253056,0.0294818383527097,0.00470472918874684,1,2.31600277096923E-7,,,,,,,,,,,,,,,,,,,,,280.343902587891,280.347930908203,899.984680175781,899.984680175781,53.445413259448,5.65765085668404,6.0742917060852,53,1,68,0,0,0.308761596679687,34.7018585205078,1,1,3,280.347930908203,0,280.345916748047,,,,,,,,,,,,,,,,,,,,,,,,,,,,,,,,,
,3880061180.34919,280.301544189453,749.806823730469,2.25220263136946E-5,2.33279312252246E-8,1,4,13.4005146026611,5.00135354229381,33.4200002253056,0.0279804966714648,0.00434916536836401,1,1.28578565398383E-7,,,,,,,,,,,,,,,,,,,,,280.300109863281,280.302978515625,749.806823730469,749.806823730469,53.6150266481211,5.65701710182501,6.06677055358887,53,2,68,0,0,0.307464599609375,33.7243423461914,1,1,3,280.300109863281,0,280.301544189453,,,,,,,,,,,,,,,,,,,,,,,,,,,,,,,,,
,3880061270.39875,280.404678344727,599.981384277344,2.08283162599299E-5,1.45780184694111E-8,1,4,13.4005146026611,5.00131416292605,33.4200002253056,0.025874247999179,0.00403384242623333,1,1.28390314529279E-7,,,,,,,,,,,,,,,,,,,,,280.400299072266,280.409057617187,599.981384277344,599.981384277344,53.628314332948,5.6577273856561,6.06978130340576,54,3,0,0,1,0.29937744140625,33.7243423461914,1,1,3,280.400299072266,0,280.404678344727,,,,,,,,,,,,,,,,,,,,,,,,,,,,,,,,,
,3880061352.03751,280.363494873047,400.067321777344,1.76431530552202E-5,2.79558934586677E-8,1,4,13.4005146026611,5.00138353305793,33.4100015461445,0.021890460352691,0.00360021347798478,1,2.56073098364683E-7,,,,,,,,,,,,,,,,,,,,,280.362335205078,280.364654541016,400.067321777344,400.067321777344,53.5915777925441,5.65799174221855,6.06552648544312,52,1,68,0,0,0.306243896484375,32.7468223571777,1,1,3,280.364654541016,0,280.363494873047,,,,,,,,,,,,,,,,,,,,,,,,,,,,,,,,,
,3880061429.38049,280.117736816406,249.952377319336,1.44877829743569E-5,1.50098952360432E-8,1,4,13.4005146026611,5.00129744952875,33.4200002253056,0.0179925196493389,0.00283950171618581,10,1.16368937403022E-7,,,,,,,,,,,,,,,,,,,,,280.117004394531,280.118469238281,249.952377319336,249.952377319336,53.5974400064384,5.65717990943193,6.0653862953186,54,2,0,0,1,0.30731201171875,33.7243423461914,1,1,3,280.117004394531,0,280.117736816406,,,,,,,,,,,,,,,,,,,,,,,,,,,,,,,,,
,3880061516.68708,280.157073974609,100.051452636719,1.01682468684263E-5,1.56514909019557E-8,1,4,13.4005146026611,5.00123685095949,33.4100015461445,0.0126193666135991,0.00204945447806758,1,1.2718217851234E-7,,,,,,,,,,,,,,,,,,,,,280.153137207031,280.161010742187,100.051452636719,100.051452636719,53.5251393684095,5.65820694765956,6.06819200515747,54,3,0,0,1,0.307235717773438,33.7243423461914,1,1,3,280.161010742187,0,280.157073974609,,,,,,,,,,,,,,,,,,,,,,,,,,,,,,,,,
,3880061629.65398,280.090942382813,-99.9507446289063,1.88683938740173E-6,2.79767830816498E-8,1,4,13.4005146026611,5.0012657713113,33.4200002253056,0.00229768207201983,6.74505347924157E-4,1,2.60212094102746E-7,,,,,,,,,,,,,,,,,,,,,280.089782714844,280.092102050781,-99.9507446289063,-99.9507446289063,53.4837130568903,5.65811579560872,6.06909036636353,54,1,0,0,1,0.300750732421875,33.7243423461914,1,1,3,280.092102050781,0,280.090942382813,,,,,,,,,,,,,,,,,,,,,,,,,,,,,,,,,
,3880061735.58522,280.159744262695,-249.90202331543,-4.85343747429339E-6,5.02602604788865E-7,1,4,13.4005146026611,5.00139918322027,33.4200002253056,-0.00615931564091765,-7.14669917682327E-5,1,6.68569097492976E-7,,,,,,,,,,,,,,,,,,,,,280.156829833984,280.162658691406,-249.90202331543,-249.90202331543,53.5282658824864,5.65775131733225,6.07266664505005,51,2,68,0,0,0.306625366210937,33.7243423461914,1,1,3,280.156829833984,0,280.159744262695,,,,,,,,,,,,,,,,,,,,,,,,,,,,,,,,,
,3880061831.32387,280.125228881836,-399.828155517578,-1.02391536135961E-5,1.26448401607502E-8,1,4,13.4005146026611,5.00128015112298,33.4200002253056,-0.0127528085141416,-0.00176102665300329,1,1.15412454948226E-7,,,,,,,,,,,,,,,,,,,,,280.122436523438,280.128021240234,-399.828155517578,-399.828155517578,53.5704738225249,5.65867038221766,6.0702428817749,52,3,68,0,0,0.307464599609375,33.2355842590332,1,1,3,280.122436523438,0,280.125228881836,,,,,,,,,,,,,,,,,,,,,,,,,,,,,,,,,
,3880061913.31434,280.119979858398,-599.767456054687,-1.58573106191929E-5,2.35845997459343E-8,1,4,13.4005146026611,5.00124145206169,33.4200002253056,-0.0197568999737433,-0.00268098775678984,1,2.15954075023528E-7,,,,,,,,,,,,,,,,,,,,,280.115264892578,280.124694824219,-599.767456054687,-599.767456054687,53.5708646367845,5.6579632732634,6.06963586807251,53,1,68,0,0,0.306777954101562,33.2355842590332,1,1,3,280.115264892578,0,280.119979858398,,,,,,,,,,,,,,,,,,,,,,,,,,,,,,,,,
,3880061985.20698,280.205825805664,-749.806823730469,-1.88035930347561E-5,1.68041581619092E-8,1,4,13.4005146026611,5.00128375874535,33.4200002253056,-0.0234078248197086,-0.00331403128742277,1,1.47601928001903E-7,,,,,,,,,,,,,,,,,,,,,280.201904296875,280.209747314453,-749.806823730469,-749.806823730469,53.541944381573,5.65797941388009,6.0667142868042,54,2,0,0,1,0.3070068359375,33.7243423461914,1,1,3,280.201904296875,0,280.205825805664,,,,,,,,,,,,,,,,,,,,,,,,,,,,,,,,,
,3880062056.67667,280.161697387695,-899.73291015625,-2.1062374403195E-5,4.81324227830143E-8,1,4,13.4005146026611,5.00125756938696,33.4200002253056,-0.0261973927436066,-0.00385986624322969,1,4.64928275048302E-8,,,,,,,,,,,,,,,,,,,,,280.155914306641,280.16748046875,-899.73291015625,-899.73291015625,53.5743819651211,5.65799850293597,6.07509279251099,54,3,0,0,1,0.301895141601562,33.7243423461914,1,1,3,280.155914306641,0,280.161697387695,,,,,,,,,,,,,,,,,,,,,,,,,,,,,,,,,
,3880062138.76928,280.082412719727,-1099.73510742188,-2.33172833357436E-5,9.24250698624882E-8,1,4,13.4005146026611,5.00118437272822,33.4200002253056,-0.0290177550444285,-0.00416405389155419,1,1.39100930703675E-7,,,,,,,,,,,,,,,,,,,,,280.080963134766,280.083862304687,-1099.73510742188,-1099.73510742188,53.5560136949191,5.6586768619914,6.07151365280151,53,1,68,0,0,0.3070068359375,33.2355842590332,1,1,3,280.080963134766,0,280.082412719727,,,,,,,,,,,,,,,,,,,,,,,,,,,,,,,,,
,3880062210.62404,280.247024536133,-1249.68640136719,-2.42903750130135E-5,1.07625500654176E-8,1,4,13.4005146026611,5.00121614444867,33.4200002253056,-0.0302261597101659,-0.0043569305215763,1,1.29575833346254E-7,,,,,,,,,,,,,,,,,,,,,280.243408203125,280.250640869141,-1249.68640136719,-1249.68640136719,53.6244061903518,5.65852757377983,6.07150316238403,54,2,0,0,1,0.307464599609375,33.7243423461914,1,1,3,280.243408203125,0,280.247024536133,,,,,,,,,,,,,,,,,,,,,,,,,,,,,,,,,
,3880062282.8451,280.192947387695,-1399.58740234375,-2.50132248862533E-5,1.67932811872235E-8,1,4,13.4005146026611,5.00121377188054,33.4200002253056,-0.0311248411285196,-0.0044918584129371,1,1.29189917255006E-7,,,,,,,,,,,,,,,,,,,,,280.186920166016,280.198974609375,-1399.58740234375,-1399.58740234375,53.523576111371,5.65853026693825,6.06879329681396,54,3,0,0,1,0.307540893554687,33.2355842590332,1,1,3,280.198974609375,0,280.192947387695,,,,,,,,,,,,,,,,,,,,,,,,,,,,,,,,,
,3880062376.00993,280.134201049805,-1599.58959960938,-2.57040573545904E-5,1.24673626297658E-8,1,4,13.4005146026611,5.00122942466971,33.4200002253056,-0.0319952289973895,-0.00454494227419261,1,1.89856834783634E-7,,,,,,,,,,,,,,,,,,,,,280.128875732422,280.139526367187,-1599.58959960938,-1599.58959960938,53.5333464678614,5.65784689067069,6.06536483764648,54,1,0,0,1,0.307083129882812,33.2355842590332,1,1,3,280.139526367187,0,280.134201049805,,,,,,,,,,,,,,,,,,,,,,,,,,,,,,,,,
,3880062448.25521,280.272430419922,-1749.57861328125,-2.59235678117686E-5,1.74805919267107E-8,1,4,13.4005146026611,5.00137732617158,33.4200002253056,-0.032265868628504,-0.00461023089624448,1,1.7033869135445E-7,,,,,,,,,,,,,,,,,,,,,280.259490966797,280.285369873047,-1749.57861328125,-1749.57861328125,53.5845431358711,5.65788350971649,6.0709433555603,53,2,68,0,0,0.306777954101562,33.7243423461914,1,1,3,280.285369873047,0,280.272430419922,,,,,,,,,,,,,,,,,,,,,,,,,,,,,,,,,
,3880062521.46838,280.286392211914,-1899.80676269531,-2.60075888901307E-5,7.70744461371691E-9,1,4,13.4005146026611,5.0012685801759,33.4100015461445,-0.0323582036918473,-0.00470028469404897,1,1.10369117498284E-7,,,,,,,,,,,,,,,,,,,,,280.286346435547,280.286437988281,-1899.80676269531,-1899.80676269531,53.6271418901691,5.65777568884644,6.07017803192139,53,3,64,0,0,0.308456420898438,33.2355842590332,1,1,3,280.286437988281,0,280.286392211914,,,,,,,,,,,,,,,,,,,,,,,,,,,,,,,,,
,3880062603.6864,280.358093261719,-2099.77124023438,-2.59188245950463E-5,2.41641059227319E-8,1,4,13.4005146026611,5.00132069298749,33.4200002253056,-0.0322528766031935,-0.00465328161450687,1,1.34947335868416E-7,,,,,,,,,,,,,,,,,,,,,280.350646972656,280.365539550781,-2099.77124023438,-2099.77124023438,53.6017389632941,5.65798381118242,6.06868743896484,54,1,0,0,1,0.299835205078125,33.2355842590332,1,1,3,280.350646972656,0,280.358093261719,,,,,,,,,,,,,,,,,,,,,,,,,,,,,,,,,
,3880062675.11356,280.25244140625,-2249.73510742187,-2.57208999640703E-5,1.61946027241398E-8,1,4,13.4005146026611,5.00124037100648,33.4200002253056,-0.0320034425504932,-0.00463382955856133,1,1.20899378614739E-7,,,,,,,,,,,,,,,,,,,,,280.246002197266,280.258880615234,-2249.73510742187,-2249.73510742187,53.648636674448,5.65739496074252,6.06914138793945,54,2,0,0,1,0.301895141601562,33.7243423461914,1,1,3,280.246002197266,0,280.25244140625,,,,,,,,,,,,,,,,,,,,,,,,,,,,,,,,,
,3880062746.83929,280.304809570313,-2399.69897460938,-2.54493182315842E-5,1.08436006904327E-8,1,4,13.4005146026611,5.00136950478392,33.4200002253056,-0.0316624740082518,-0.0046131085409249,1,9.70714801784938E-8,,,,,,,,,,,,,,,,,,,,,280.299865722656,280.309753417969,-2399.69897460938,-2399.69897460938,53.6920170572653,5.65775480864864,6.06982469558716,53,3,68,0,0,0.307235717773438,33.7243423461914,1,1,3,280.309753417969,0,280.304809570313,,,,,,,,,,,,,,,,,,,,,,,,,,,,,,,,,
,3880062841.31291,280.318771362305,-2599.76416015625,-2.4976260722772E-5,8.32743852592785E-9,1,4,13.4005146026611,5.00131880971227,33.4200002253056,-0.0310785335993017,-0.00449354134844495,1,1.22412986745842E-7,,,,,,,,,,,,,,,,,,,,,280.304473876953,280.333068847656,-2599.76416015625,-2599.76416015625,53.5880604642076,5.65754439086319,6.07159423828125,54,1,0,0,1,0.307846069335937,33.2355842590332,1,1,3,280.333068847656,0,280.318771362305,,,,,,,,,,,,,,,,,,,,,,,,,,,,,,,,,
,3880062925.04483,280.297500610352,-2749.6904296875,-2.45599265826066E-5,1.66470289222657E-8,1,4,13.4005146026611,5.0014767040145,33.4200002253056,-0.030559066805437,-0.00443730056772431,1,1.05520634739703E-7,,,,,,,,,,,,,,,,,,,,,280.290557861328,280.304443359375,-2749.6904296875,-2749.6904296875,53.5247485541499,5.65740671473026,6.07199430465698,54,2,0,0,1,0.308151245117188,33.7243423461914,1,1,3,280.304443359375,0,280.297500610352,,,,,,,,,,,,,,,,,,,,,,,,,,,,,,,,,
,3880062996.58315,280.329544067383,-2899.60375976562,-2.40332551743947E-5,1.02097862630833E-8,1,4,13.4005146026611,5.00135720269069,33.4100015461445,-0.0299035835744272,-0.00433641530815975,1,1.07749534515958E-7,,,,,,,,,,,,,,,,,,,,,280.320159912109,280.338928222656,-2899.60375976562,-2899.60375976562,53.6806834437364,5.65810534028639,6.07100820541382,54,3,0,0,1,0.305862426757812,33.7243423461914,1,1,3,280.320159912109,0,280.329544067383,,,,,,,,,,,,,,,,,,,,,,,,,,,,,,,,,
,3880063117.92345,280.452346801758,-3499.736328125,-2.17236413595521E-5,8.31853014430364E-9,1,4,13.4005146026611,5.00145925699169,33.4200002253056,-0.0270170117411451,-0.00401061907233766,1,2.43528882583971E-8,,,,,,,,,,,,,,,,,,,,,280.441040039062,280.463653564453,-3499.736328125,-3499.736328125,53.4637815296499,5.65782723300782,6.06955814361572,54,1,0,0,1,0.308685302734375,33.7243423461914,1,1,3,280.440521240234,0,280.452346801758,,,,,,,,,,,,,,,,,,,,,,,,,,,,,,,,,
,3880063215.4355,280.248031616211,-4999.7529296875,-1.44191091947383E-5,1.09730640870223E-8,1,4,13.4005146026611,5.00142513464402,33.4200002253056,-0.0179287472179691,-0.00268660183739462,1,-3.59612823265645E-9,,,,,,,,,,,,,,,,,,,,,280.242462158203,280.253601074219,-4999.7529296875,-4999.7529296875,53.6896721717076,5.657593894456,6.07069826126099,54,2,0,0,1,0.30548095703125,33.7243423461914,1,1,3,280.253601074219,0,280.248031616211,,,,,,,,,,,,,,,,,,,,,,,,,,,,,,,,,
,3880063298.50555,280.144927978516,-6499.83203125,-6.22412082331234E-6,1.01280882652644E-8,1,4,13.4005146026611,5.00161902891816,33.4200002253056,-0.00773758877814573,-0.00117255308559268,1,-1.18437351987985E-8,,,,,,,,,,,,,,,,,,,,,280.138916015625,280.150939941406,-6499.83203125,-6499.83203125,53.5739911508614,5.65735258455141,6.07435321807861,54,3,0,0,1,0.306396484375,33.2355842590332,1,1,3,280.150939941406,0,280.144927978516,,,,,,,,,,,,,,,,,,,,,,,,,,,,,,,,,
,3880063398.14514,280.33137512207,-8499.8291015625,5.30758058205341E-6,1.14098574540105E-8,1,4,13.4005146026611,5.00148384652572,33.4200002253056,0.00661252866974134,9.02270989477829E-4,1,-6.8373232428637E-8,,,,,,,,,,,,,,,,,,,,,280.330841064453,280.331909179687,-8499.8291015625,-8499.8291015625,53.5177138974768,5.65801100589853,6.06881904602051,54,1,0,0,1,0.306777954101562,32.7468223571777,1,1,3,280.331909179687,0,280.33137512207,,,,,,,,,,,,,,,,,,,,,,,,,,,,,,,,,
,3880063482.90418,280.151473999023,-9999.7451171875,1.41265910618285E-5,1.23335807037094E-8,1,4,13.4005146026611,5.00146400571238,33.4200002253056,0.0175746025167186,0.00256941213673239,1,-4.69131709819427E-8,,,,,,,,,,,,,,,,,,,,,280.145721435547,280.1572265625,-9999.7451171875,-9999.7451171875,53.5423351958326,5.65881952350996,6.06515264511108,54,2,0,0,1,0.30853271484375,33.2355842590332,1,1,3,280.145721435547,0,280.151473999023,,,,,,,,,,,,,,,,,,,,,,,,,,,,,,,,,
,3880063670.44406,280.099212646484,-19999.830078125,7.43767444764682E-5,2.25835928299078E-8,1,4,13.4005146026611,5.00210372739173,33.4200002253056,0.0925156604914069,0.013740876210476,1,-7.77786983370928E-8,,,,,,,,,,,,,,,,,,,,,280.095764160156,280.102661132813,-19999.830078125,-19999.830078125,53.4094583475633,5.65433412054936,6.07001447677612,54,3,0,0,1,0.307769775390625,33.2355842590332,1,1,3,280.095764160156,0,280.099212646484,,,,,,,,,,,,,,,,,,,,,,,,,,,,,,,,,
,3880063952.84652,280.16064453125,-39999.69921875,1.96585477506601E-4,6.79363047403635E-8,1,4,13.4005146026611,5.00208741880151,33.4200002253056,0.244527000989954,0.0363211026074375,1,-2.03404478022123E-7,,,,,,,,,,,,,,,,,,,,,280.136535644531,280.184753417969,-39999.69921875,-39999.69921875,53.3004211691306,5.65438760545372,6.06992053985596,52,1,68,0,0,0.305633544921875,33.2355842590332,1,1,3,280.184753417969,0,280.16064453125,,,,,,,,,,,,,,,,,,,,,,,,,,,,,,,,,
,3880064182.72168,280.06477355957,-54999.671875,2.8850937042387E-4,9.21337737154902E-8,1,4,13.4005146026611,5.00181885232945,33.4200002253056,0.358873186636151,0.0530892636931679,10,-4.68733769259222E-7,,,,,,,,,,,,,,,,,,,,,280.064422607422,280.065124511719,-54999.671875,-54999.671875,53.3735034356787,5.65541398778765,6.07017040252686,54,2,0,0,1,0.306625366210937,33.7243423461914,1,1,3,280.064422607422,0,280.06477355957,,,,,,,,,,,,,,,,,,,,,,,,,,,,,,,,,
,3880064419.171,280.120544433594,-69999.5390625,3.80076292985395E-4,2.28343185387342E-7,1,4,13.4005146026611,5.00164213905335,33.4200002253056,0.472647981306622,0.0706089487733826,1,-7.57292157717618E-8,,,,,,,,,,,,,,,,,,,,,280.119720458984,280.121368408203,-69999.5390625,-69999.5390625,53.2464888013037,5.65586900699476,6.07111883163452,54,3,0,0,1,0.306777954101562,33.7243423461914,1,1,3,280.121368408203,0,280.120544433594,,,,,,,,,,,,,,,,,,,,,,,,,,,,,,,,,
,3880064702.61533,280.100082397461,-49999.71484375,2.57579365743118E-4,1.06317266623194E-7,1,4,13.4005146026611,5.00136849546698,33.4200002253056,0.320294162000871,0.0478277525420421,1,-6.78712222232683E-8,,,,,,,,,,,,,,,,,,,,,280.096069335938,280.104095458984,-49999.71484375,-49999.71484375,53.4399418598133,5.65652976125271,6.07209491729736,54,1,0,0,1,0.30731201171875,33.7243423461914,1,1,3,280.096069335938,0,280.100082397461,,,,,,,,,,,,,,,,,,,,,,,,,,,,,,,,,
,3880064924.21626,280.116424560547,-34999.640625,1.65726155968801E-4,4.9003560321238E-8,1,4,13.4005146026611,5.00155445688704,33.4200002253056,0.206089862258013,0.0307579614186044,1,-5.64867686338474E-8,,,,,,,,,,,,,,,,,,,,,280.101593017578,280.131256103516,-34999.640625,-34999.640625,53.5716462653038,5.6563685071508,6.07231283187866,54,2,0,0,1,0.307998657226562,34.2131004333496,1,1,3,280.131256103516,0,280.116424560547,,,,,,,,,,,,,,,,,,,,,,,,,,,,,,,,,
,3880065146.36234,280.083190917969,-19999.578125,7.41985975507144E-5,2.5058410216791E-8,1,4,13.4005146026611,5.00140153711895,33.4200002253056,0.0922701318252969,0.013744101287513,1,-4.63649537865814E-8,,,,,,,,,,,,,,,,,,,,,280.079559326172,280.086822509766,-19999.578125,-19999.578125,53.3836646064287,5.657136925456,6.06457805633545,54,3,0,0,1,0.307540893554687,33.2355842590332,1,1,3,280.079559326172,0,280.083190917969,,,,,,,,,,,,,,,,,,,,,,,,,,,,,,,,,
,3880065350.52383,280.331848144531,-9500.2802734375,1.09049536689281E-5,1.36375725565126E-8,1,4,13.4005146026611,5.00144236662367,33.4200002253056,0.013549163383834,0.00209964078439772,1,5.72410056542382E-8,,,,,,,,,,,,,,,,,,,,,280.314453125,280.349243164062,-9500.2802734375,-9500.2802734375,53.5188863402557,5.65604007670148,6.06775760650635,54,1,0,0,1,0.299835205078125,33.7243423461914,1,1,3,280.349243164062,0,280.331848144531,,,,,,,,,,,,,,,,,,,,,,,,,,,,,,,,,
,3880065463.07775,280.396240234375,-8000.45263671875,2.11056655859344E-6,9.41688467589436E-9,1,4,13.4005146026611,5.00132972548169,33.4200002253056,0.00261614922207238,4.47135231437493E-4,1,4.38747937489679E-8,,,,,,,,,,,,,,,,,,,,,280.388946533203,280.403533935547,-8000.45263671875,-8000.45263671875,53.6267510759095,5.65703349318693,6.07523536682129,54,2,0,0,1,0.307769775390625,33.7243423461914,6,1,3,280.403533935547,0,280.396240234375,,,,,,,,,,,,,,,,,,,,,,,,,,,,,,,,,
,3880065559.06465,280.219528198242,-6500.4365234375,-6.4891802261544E-6,1.01640868324822E-8,1,4,13.4005146026611,5.00132545753258,33.4200002253056,-0.00807529182168692,-0.00116320092447238,1,3.52514343511619E-8,,,,,,,,,,,,,,,,,,,,,280.216857910156,280.222198486328,-6500.4365234375,-6500.4365234375,53.4059410192268,5.65726031563688,6.06994676589966,54,3,0,0,1,0.308990478515625,33.2355842590332,1,1,3,280.216857910156,0,280.219528198242,,,,,,,,,,,,,,,,,,,,,,,,,,,,,,,,,
,3880065665.495,280.318817138672,-4500.51513671875,-1.73353469664305E-5,1.05240294251924E-8,1,4,13.4005146026611,5.00142985774867,33.4200002253056,-0.0215748938050939,-0.00309585226603357,1,1.03532952754055E-7,,,,,,,,,,,,,,,,,,,,,280.296752929687,280.340881347656,-4500.51513671875,-4500.51513671875,53.6247970046114,5.65647763243645,6.06946754455566,54,1,0,0,1,0.305328369140625,33.7243423461914,1,1,3,280.340881347656,0,280.318817138672,,,,,,,,,,,,,,,,,,,,,,,,,,,,,,,,,
,3880065761.69247,280.351150512695,-3000.17138671875,-2.40361487748099E-5,8.53513401129671E-9,1,4,13.4005146026611,5.00143137741575,33.4200002253056,-0.029903630368345,-0.00436493106708639,1,8.53220015206245E-8,,,,,,,,,,,,,,,,,,,,,280.347381591797,280.354919433594,-3000.17138671875,-3000.17138671875,53.6052562916307,5.65621001942366,6.0701961517334,54,2,0,0,1,0.306777954101562,33.7243423461914,1,1,3,280.347381591797,0,280.351150512695,,,,,,,,,,,,,,,,,,,,,,,,,,,,,,,,,
,3880065919.9463,280.047012329102,-2900.29614257812,-2.43019441429187E-5,1.37498814516612E-8,1,4,13.4005146026611,5.00148997913537,33.4200002253056,-0.030205418596777,-0.00460971213378419,1,-7.17121856787996E-8,,,,,,,,,,,,,,,,,,,,,280.044952392578,280.049072265625,-2900.29614257812,-2900.29614257812,53.5579677662172,5.65622655521611,6.07307386398315,53,3,68,0,0,0.307159423828125,34.2131004333496,1,1,3,280.044952392578,0,280.047012329102,,,,,,,,,,,,,,,,,,,,,,,,,,,,,,,,,
,3880066001.56712,280.174987792969,-2700.33178710938,-2.49006605677759E-5,1.59514083968166E-8,1,4,13.4005146026611,5.00130517669998,33.4200002253056,-0.0309298520439712,-0.00484419166338408,1,-1.70917895994635E-7,,,,,,,,,,,,,,,,,,,,,280.173889160156,280.176086425781,-2700.33178710938,-2700.33178710938,53.5407719387941,5.65740855966269,6.06964063644409,54,1,0,0,1,0.306167602539063,33.7243423461914,1,1,3,280.173889160156,0,280.174987792969,,,,,,,,,,,,,,,,,,,,,,,,,,,,,,,,,
,3880066072.95514,280.286727905273,-2550.3427734375,-2.53839266289734E-5,1.52111901237882E-8,1,4,13.4005146026611,5.00126855615861,33.4200002253056,-0.0315411455521135,-0.00486236822596729,1,-1.13282693506237E-7,,,,,,,,,,,,,,,,,,,,,280.271545410156,280.301910400391,-2550.3427734375,-2550.3427734375,53.6884997289287,5.65611033915222,6.07056951522827,53,2,68,0,0,0.308151245117188,34.2131004333496,1,1,3,280.301910400391,0,280.286727905273,,,,,,,,,,,,,,,,,,,,,,,,,,,,,,,,,
,3880066157.46948,280.40299987793,-2400.353515625,-2.57785893150772E-5,1.00739747324028E-8,1,4,13.4005146026611,5.00140698487564,33.4200002253056,-0.0320478894383509,-0.00483715268910843,1,-3.38133192016897E-8,,,,,,,,,,,,,,,,,,,,,280.397186279297,280.408813476562,-2400.353515625,-2400.353515625,53.4317347603614,5.65615981547186,6.06931924819946,54,3,0,0,1,0.307769775390625,33.7243423461914,1,1,3,280.397186279297,0,280.40299987793,,,,,,,,,,,,,,,,,,,,,,,,,,,,,,,,,
,3880066237.65042,280.213928222656,-2200.326171875,-2.61461681467174E-5,1.82186087987044E-8,1,4,13.4005146026611,5.00133333029199,33.4200002253056,-0.0324796157099697,-0.00507031770284608,1,-1.6642561772707E-7,,,,,,,,,,,,,,,,,,,,,280.18603515625,280.241821289062,-2200.326171875,-2200.326171875,53.5872788356884,5.65639743225642,6.06913995742798,54,1,0,0,1,0.306930541992188,33.7243423461914,1,1,3,280.241821289062,0,280.213928222656,,,,,,,,,,,,,,,,,,,,,,,,,,,,,,,,,
,3880066308.33326,280.265258789062,-2050.375,-2.63840630729311E-5,1.52783330563732E-8,1,4,13.4005146026611,5.00128954791194,33.4100015461445,-0.0327839241237481,-0.0050549610682247,1,-1.18537442937284E-7,,,,,,,,,,,,,,,,,,,,,280.257843017578,280.272674560547,-2050.375,-2050.375,53.5888420927268,5.65676481436691,6.07336044311523,52,2,68,0,0,0.306625366210937,33.7243423461914,1,1,3,280.257843017578,0,280.265258789062,,,,,,,,,,,,,,,,,,,,,,,,,,,,,,,,,
,3880066378.93721,280.367584228516,-1900.42358398438,-2.65319208253875E-5,1.29127715550473E-8,1,4,13.4005146026611,5.00134678097281,33.4200002253056,-0.0329739095366134,-0.00504503630186878,1,-8.83719148859535E-8,,,,,,,,,,,,,,,,,,,,,280.365234375,280.369934082031,-1900.42358398438,-1900.42358398438,53.5587493947364,5.65651220063799,6.0720591545105,54,3,0,0,1,0.306549072265625,33.7243423461914,6,1,3,280.369934082031,0,280.367584228516,,,,,,,,,,,,,,,,,,,,,,,,,,,,,,,,,
,3880066472.57975,280.358840942383,-1700.08154296875,-2.65119026655512E-5,2.04046098914724E-8,1,4,13.4005146026611,5.00160297816598,33.4200002253056,-0.0329290505849518,-0.00519094212522538,1,-2.08409560376131E-7,,,,,,,,,,,,,,,,,,,,,280.356140136719,280.361541748047,-1700.08154296875,-1700.08154296875,53.6290959614672,5.65621670908598,6.07076215744019,53,1,68,0,0,0.307235717773438,33.7243423461914,1,1,3,280.361541748047,0,280.358840942383,,,,,,,,,,,,,,,,,,,,,,,,,,,,,,,,,
,3880066544.02236,280.300811767578,-1550.13024902344,-2.64078397518936E-5,1.62881289984035E-8,1,4,13.4005146026611,5.00154298227291,33.4200002253056,-0.0328149553047141,-0.00506548703102554,1,-1.23157224995138E-7,,,,,,,,,,,,,,,,,,,,,280.297912597656,280.3037109375,-1550.13024902344,-1550.13024902344,53.562266723073,5.65620518609678,6.0718150138855,54,2,0,0,1,0.30670166015625,33.7243423461914,1,1,3,280.297912597656,0,280.300811767578,,,,,,,,,,,,,,,,,,,,,,,,,,,,,,,,,
,3880066614.43232,280.266693115234,-1400.103515625,-2.61857148163254E-5,2.86591954145124E-8,1,4,13.4005146026611,5.00153459402381,33.4200002253056,-0.0325391160012512,-0.00502116769792895,1,-1.20754116155409E-7,,,,,,,,,,,,,,,,,,,,,280.260864257813,280.272521972656,-1400.103515625,-1400.103515625,53.5821982503134,5.65612172992367,6.07167863845825,54,3,0,0,1,0.308074951171875,33.7243423461914,1,1,3,280.260864257813,0,280.266693115234,,,,,,,,,,,,,,,,,,,,,,,,,,,,,,,,,
,3880066696.26199,280.23095703125,-1200.08862304688,-2.54565789863378E-5,2.12584341521396E-8,1,4,13.4005146026611,5.00138911699536,33.4200002253056,-0.0316147857523154,-0.00499478259833516,1,-2.08773175415006E-7,,,,,,,,,,,,,,,,,,,,,280.211883544922,280.250030517578,-1200.08862304688,-1200.08862304688,53.4055502049672,5.65653175071071,6.0737190246582,53,1,68,0,0,0.300064086914063,33.7243423461914,1,1,3,280.250030517578,0,280.23095703125,,,,,,,,,,,,,,,,,,,,,,,,,,,,,,,,,
,3880066780.8237,280.351348876953,-1050.16259765625,-2.47791780952561E-5,1.62141607910613E-8,1,4,13.4005146026611,5.00151424566139,33.4200002253056,-0.0307853095456874,-0.00479039658473742,1,-1.45601320665558E-7,,,,,,,,,,,,,,,,,,,,,280.349212646484,280.353485107422,-1050.16259765625,-1050.16259765625,53.5567953234384,5.65615133501335,6.07289409637451,54,2,0,0,1,0.300979614257812,33.7243423461914,1,1,3,280.349212646484,0,280.351348876953,,,,,,,,,,,,,,,,,,,,,,,,,,,,,,,,,
,3880066851.87165,280.365097045898,-900.123168945313,-2.38476770209213E-5,1.39593337793875E-8,1,4,13.4005146026611,5.00142246013669,33.4200002253056,-0.0296357835542594,-0.00455325047029609,1,-9.43304114310036E-8,,,,,,,,,,,,,,,,,,,,,280.362579345703,280.367614746094,-900.123168945313,-900.123168945313,53.5321740250826,5.65689669660477,6.07149505615234,53,3,68,0,0,0.308685302734375,33.7243423461914,6,1,3,280.367614746094,0,280.365097045898,,,,,,,,,,,,,,,,,,,,,,,,,,,,,,,,,
,3880066932.51438,280.129486083984,-700.1083984375,-2.1961989770731E-5,2.56870579972533E-8,1,4,13.4005146026611,5.00139290975411,33.4100015461445,-0.0272656407762881,-0.00437067330065528,1,-2.29615222873775E-7,,,,,,,,,,,,,,,,,,,,,280.128112792969,280.130859375,-700.1083984375,-700.1083984375,53.5595310232557,5.65674873697807,6.0699896812439,52,1,68,0,0,0.306167602539063,33.7243423461914,1,1,3,280.130859375,0,280.129486083984,,,,,,,,,,,,,,,,,,,,,,,,,,,,,,,,,
,3880067003.06032,280.090362548828,-550.169677734375,-2.01217300251108E-5,1.94641863710134E-8,1,4,13.4005146026611,5.00159931585815,33.4200002253056,-0.0249949471966386,-0.00392089827871485,1,-1.43005498638465E-7,,,,,,,,,,,,,,,,,,,,,280.088226318359,280.092498779297,-550.169677734375,-550.169677734375,53.5564045091787,5.65568224362239,6.07479333877564,54,2,0,0,1,0.30670166015625,33.7243423461914,1,1,3,280.088226318359,0,280.090362548828,,,,,,,,,,,,,,,,,,,,,,,,,,,,,,,,,
,3880067075.04392,280.220825195313,-400.205810546875,-1.76659528112002E-5,1.46368481915718E-8,1,4,13.4005146026611,5.00167482604301,33.4200002253056,-0.0219426523522747,-0.0034573103604883,1,-1.37509628956278E-7,,,,,,,,,,,,,,,,,,,,,280.219940185547,280.221710205078,-400.205810546875,-400.205810546875,53.5106792408037,5.65510496948064,6.07627964019775,54,3,0,0,1,0.307693481445313,33.2355842590332,1,1,3,280.219940185547,0,280.220825195313,,,,,,,,,,,,,,,,,,,,,,,,,,,,,,,,,
,3880067155.93971,280.23844909668,-200.153259277344,-1.30916318948233E-5,2.47617942210559E-8,1,4,13.4005146026611,5.00178242954394,33.4200002253056,-0.0162418406387002,-0.00269316669506947,1,-2.07241644705415E-7,,,,,,,,,,,,,,,,,,,,,280.22998046875,280.246917724609,-200.153259277344,-200.153259277344,53.6310500327653,5.65535787621261,6.06760406494141,53,1,68,0,0,0.30609130859375,33.2355842590332,1,1,3,280.22998046875,0,280.23844909668,,,,,,,,,,,,,,,,,,,,,,,,,,,,,,,,,
,3880067227.20665,280.302932739258,-50.2397232055664,-8.35862276517392E-6,6.40121885449908E-8,1,4,13.4005146026611,5.00160301928816,33.4200002253056,-0.0103535943352747,-0.00182520028628413,1,-2.17382300721802E-7,,,,,,,,,,,,,,,,,,,,,280.286712646484,280.319152832031,-50.2397232055664,-50.2397232055664,53.5560136949191,5.65622146541501,6.07062387466431,53,2,68,0,0,0.30853271484375,33.2355842590332,1,1,3,280.319152832031,0,280.302932739258,,,,,,,,,,,,,,,,,,,,,,,,,,,,,,,,,
,3880067311.73973,280.213897705078,99.799690246582,-1.95518062089543E-6,1.70307621509122E-8,1,4,13.4005146026611,5.00132246527698,33.4200002253056,-0.00240615097217961,-5.30429359757318E-4,1,-1.34108632646694E-7,,,,,,,,,,,,,,,,,,,,,280.208618164062,280.219177246094,99.799690246582,99.799690246582,53.5970491921788,5.65575034239963,6.06740808486938,54,3,0,0,1,0.304641723632812,33.7243423461914,1,1,3,280.208618164062,0,280.213897705078,,,,,,,,,,,,,,,,,,,,,,,,,,,,,,,,,
,3880067393.91641,280.293167114258,299.688598632812,6.68785221197787E-6,1.95764221309647E-8,1,4,13.4005146026611,5.00161869822914,33.4200002253056,0.00835071225462645,0.00101504405967646,1,-1.84191833055631E-7,,,,,,,,,,,,,,,,,,,,,280.290130615234,280.296203613281,299.688598632812,299.688598632812,53.3426291091691,5.65421044759055,6.07019281387329,54,1,0,0,1,0.30853271484375,33.7243423461914,1,1,3,280.290130615234,0,280.293167114258,,,,,,,,,,,,,,,,,,,,,,,,,,,,,,,,,
,3880067465.51764,280.263565063477,449.778350830078,1.18457606138384E-5,1.41762626878679E-8,1,4,13.4005146026611,5.00163914188403,33.4200002253056,0.0147579502595338,0.00201990355314217,1,-1.47712923194079E-7,,,,,,,,,,,,,,,,,,,,,280.255340576172,280.271789550781,449.778350830078,449.778350830078,53.5661748656691,5.65480169404216,6.07041120529175,53,2,68,0,0,0.30609130859375,33.7243423461914,1,1,3,280.271789550781,0,280.263565063477,,,,,,,,,,,,,,,,,,,,,,,,,,,,,,,,,
,3880067537.66539,280.263412475586,599.742248535156,1.58132758912194E-5,1.20908643427022E-8,1,4,13.4005146026611,5.00163783219367,33.4200002253056,0.0196864491548043,0.00279264154207409,1,-1.1981751111412E-7,,,,,,,,,,,,,,,,,,,,,280.256561279297,280.270263671875,599.742248535156,599.742248535156,53.3926533343999,5.65465017167289,6.07180261611938,54,3,0,0,1,0.307693481445313,33.2355842590332,1,1,3,280.256561279297,0,280.263412475586,,,,,,,,,,,,,,,,,,,,,,,,,,,,,,,,,
,3880067619.73288,280.284240722656,799.694091796875,1.96770298897812E-5,2.58963828313608E-8,1,4,13.4005146026611,5.00158638995492,33.4200002253056,0.0245018478263791,0.00343722468225853,1,-1.79418815025934E-7,,,,,,,,,,,,,,,,,,,,,280.276153564453,280.292327880859,799.694091796875,799.694091796875,53.6564529596403,5.65424228760362,6.07473516464233,53,1,68,0,0,0.306396484375,33.2355842590332,1,1,3,280.292327880859,0,280.284240722656,,,,,,,,,,,,,,,,,,,,,,,,,,,,,,,,,
,3880067691.16585,280.344345092773,949.758605957031,2.17189032731368E-5,1.54667599818989E-8,1,4,13.4005146026611,5.00154127589443,33.4200002253056,0.027038748707888,0.00382928212044513,1,-1.69547301994772E-7,,,,,,,,,,,,,,,,,,,,,280.3330078125,280.355682373047,949.758605957031,949.758605957031,53.5814166217941,5.65550896576535,6.06818389892578,53,2,68,0,0,0.307083129882812,33.2355842590332,6,1,3,280.355682373047,0,280.344345092773,,,,,,,,,,,,,,,,,,,,,,,,,,,,,,,,,
,3880067763.10257,280.239196777344,1099.73510742188,2.32241805104826E-5,3.16544871246425E-8,1,4,13.4005146026611,5.00138829157599,33.4200002253056,0.0289006042276662,0.00416728846421328,1,-1.22763062508259E-7,,,,,,,,,,,,,,,,,,,,,280.22998046875,280.248413085938,1099.73510742188,1099.73510742188,53.6572345881595,5.65643628034563,6.07083654403687,54,3,0,0,1,0.305099487304687,33.2355842590332,1,1,3,280.22998046875,0,280.239196777344,,,,,,,,,,,,,,,,,,,,,,,,,,,,,,,,,
,3880067845.29347,280.349868774414,1299.69958496094,2.4581961450562E-5,2.08603919972584E-8,1,4,13.4005146026611,5.00143282190999,33.4200002253056,0.0306043561552333,0.00431924608548385,1,-2.03714113168768E-7,,,,,,,,,,,,,,,,,,,,,280.326385498047,280.373352050781,1299.69958496094,1299.69958496094,53.6228429333134,5.65521310039846,6.07236289978027,52,1,68,0,0,0.30670166015625,33.7243423461914,1,1,3,280.373352050781,0,280.349868774414,,,,,,,,,,,,,,,,,,,,,,,,,,,,,,,,,
,3880067916.94649,280.277969360352,1449.67602539062,2.52551043196549E-5,8.75012653995929E-9,1,4,13.4005146026611,5.00139106344131,33.4200002253056,0.0314261812431486,0.0045435271257426,1,-1.23999617129434E-7,,,,,,,,,,,,,,,,,,,,,280.265258789062,280.290679931641,1449.67602539062,1449.67602539062,53.5657840514095,5.65598094933647,6.07295656204224,54,2,0,0,1,0.306930541992188,33.2355842590332,1,1,3,280.290679931641,0,280.277969360352,,,,,,,,,,,,,,,,,,,,,,,,,,,,,,,,,
,3880068005.16945,280.437423706055,1599.56433105469,2.56625832304061E-5,6.71637890041651E-9,1,4,13.4005146026611,5.00124467308782,33.4200002253056,0.0319236984122724,0.0046716028879783,1,-8.180062021938E-8,,,,,,,,,,,,,,,,,,,,,280.427795410156,280.447052001953,1599.56433105469,1599.56433105469,53.5478065954672,5.65617449181855,6.0740795135498,54,3,0,0,1,0.3076171875,33.2355842590332,1,1,3,280.427795410156,0,280.437423706055,,,,,,,,,,,,,,,,,,,,,,,,,,,,,,,,,
,3880068101.017,280.226776123047,1799.59167480469,2.59025303354448E-5,6.18241485164028E-8,1,4,13.4005146026611,5.00171391520705,33.4200002253056,0.0322395115825409,0.00462837151984799,1,-1.52952926100248E-7,,,,,,,,,,,,,,,,,,,,,280.218109130859,280.235443115234,1799.59167480469,1799.59167480469,53.6978792711595,5.65452716863167,6.07160425186157,54,1,0,0,1,0.307159423828125,33.7243423461914,1,1,3,280.218109130859,0,280.226776123047,,,,,,,,,,,,,,,,,,,,,,,,,,,,,,,,,
,3880068173.05587,280.083480834961,1949.92065429687,2.60646148159004E-5,3.73007388048713E-8,1,4,13.4005146026611,5.0016924399344,33.4200002253056,0.0324360213514474,0.00469095216926742,1,-1.26852860473036E-7,,,,,,,,,,,,,,,,,,,,,280.081146240234,280.085815429687,1949.92065429687,1949.92065429687,53.4688621150249,5.65486988881408,6.06978464126587,54,2,0,0,1,0.306015014648438,33.7243423461914,1,1,3,280.085815429687,0,280.083480834961,,,,,,,,,,,,,,,,,,,,,,,,,,,,,,,,,
,3880068245.25314,280.184387207031,2099.79638671875,2.59850096158819E-5,5.50430448193794E-8,1,4,13.4005146026611,5.00139114795267,33.4200002253056,0.0323311844774689,0.00469659971485851,1,-1.10084565649874E-7,,,,,,,,,,,,,,,,,,,,,280.179016113281,280.189758300781,2099.79638671875,2099.79638671875,53.5677381227076,5.65532556195681,6.07269477844238,54,3,0,0,1,0.306243896484375,33.7243423461914,1,1,3,280.189758300781,0,280.184387207031,,,,,,,,,,,,,,,,,,,,,,,,,,,,,,,,,
,3880068327.52938,280.112106323242,2299.84887695313,2.56335158119365E-5,3.10191044216283E-8,1,4,13.4005146026611,5.00133522981097,33.4200002253056,0.0318989847503076,0.00459531925794626,1,-1.38897500264126E-7,,,,,,,,,,,,,,,,,,,,,280.108947753906,280.115264892578,2299.84887695313,2299.84887695313,53.4970007417172,5.655065123077,6.07011461257935,54,1,0,0,1,0.307540893554687,33.7243423461914,1,1,3,280.108947753906,0,280.112106323242,,,,,,,,,,,,,,,,,,,,,,,,,,,,,,,,,
,3880068399.04763,280.262176513672,2449.92602539062,2.53496141450805E-5,8.00851576690828E-9,1,4,13.4005146026611,5.0013532199972,33.4200002253056,0.0315424810999296,0.00456696223129047,1,-1.19251771135471E-7,,,,,,,,,,,,,,,,,,,,,280.253875732422,280.270477294922,2449.92602539062,2449.92602539062,53.4469765164864,5.65592679195499,6.07366752624512,53,2,68,0,0,0.307083129882812,33.2355842590332,1,1,3,280.270477294922,0,280.262176513672,,,,,,,,,,,,,,,,,,,,,,,,,,,,,,,,,
,3880068482.97399,280.379440307617,2599.73901367187,2.49589647197185E-5,8.70862557745598E-9,1,4,13.4005146026611,5.00160442311177,33.4200002253056,0.031051482652561,0.00454433845735691,1,-7.9264598427636E-8,,,,,,,,,,,,,,,,,,,,,280.372650146484,280.38623046875,2599.73901367187,2599.73901367187,53.5290475110057,5.65510901224696,6.06774997711182,54,3,0,0,1,0.306015014648438,33.7243423461914,1,1,3,280.372650146484,0,280.379440307617,,,,,,,,,,,,,,,,,,,,,,,,,,,,,,,,,
,3880068565.36441,280.308349609375,2799.89233398438,2.43977263134973E-5,1.09563523274042E-8,1,4,13.4005146026611,5.00153568481911,33.4200002253056,0.0303605560350839,0.00438929393845295,1,-1.19921820628592E-7,,,,,,,,,,,,,,,,,,,,,280.284332275391,280.332366943359,2799.89233398438,2799.89233398438,53.5224036685922,5.65475128197928,6.0683445930481,54,1,0,0,1,0.306243896484375,33.2355842590332,1,1,3,280.332366943359,0,280.308349609375,,,,,,,,,,,,,,,,,,,,,,,,,,,,,,,,,
,3880068636.80134,280.322647094727,2949.78051757812,2.39023059794493E-5,8.80285932069939E-9,1,4,13.4005146026611,5.00156170448305,33.4200002253056,0.0297431368306958,0.00430777762033878,1,-1.11389841429416E-7,,,,,,,,,,,,,,,,,,,,,280.319671630859,280.325622558594,2949.78051757812,2949.78051757812,53.5712554510441,5.65432449074631,6.07082605361938,54,2,0,0,1,0.30670166015625,33.2355842590332,1,1,3,280.325531005859,0,280.322647094727,,,,,,,,,,,,,,,,,,,,,,,,,,,,,,,,,
,3880068728.87843,280.273696899414,3499.67333984375,2.17422602506418E-5,1.08700450694473E-8,1,4,13.4005146026611,5.00146762183949,33.4200002253056,0.0270429487721218,0.00399589653857684,1,-3.89856523243672E-8,,,,,,,,,,,,,,,,,,,,,280.269775390625,280.277618408203,3499.67333984375,3499.67333984375,53.4938742276403,5.65552493649237,6.07106876373291,54,3,0,0,1,0.306930541992188,33.7243423461914,1,1,3,280.277618408203,0,280.273696899414,,,,,,,,,,,,,,,,,,,,,,,,,,,,,,,,,
,3880068839.63496,280.326965332031,5499.73291015625,1.17445590160297E-5,8.85360244323767E-9,1,4,13.4005146026611,5.00144666826473,33.4200002253056,0.0145966183972195,0.00223291495783785,1,3.88196562245914E-8,,,,,,,,,,,,,,,,,,,,,280.325805664062,280.328125,5499.73291015625,5499.73291015625,53.3613881936306,5.65598339097016,6.06947660446167,54,1,0,0,1,0.308456420898438,33.7243423461914,1,1,3,280.325805664062,0,280.326965332031,,,,,,,,,,,,,,,,,,,,,,,,,,,,,,,,,
,3880068929.54669,280.360626220703,6999.8876953125,3.39018342686864E-6,9.34280938060356E-9,1,4,13.4005146026611,5.00149104939703,33.4200002253056,0.00421257332341187,6.50828959839393E-4,10,1.62463354964758E-8,,,,,,,,,,,,,,,,,,,,,280.360595703125,280.360656738281,6999.8876953125,6999.8876953125,53.4739427003999,5.65513092299169,6.06983375549316,54,2,0,0,1,0.306854248046875,33.2355842590332,1,1,3,280.360656738281,0,280.360626220703,,,,,,,,,,,,,,,,,,,,,,,,,,,,,,,,,
,3880069036.08324,280.227966308594,8500.2568359375,-5.28340276635486E-6,1.2510493613485E-8,1,4,13.4005146026611,5.00142703040638,33.4200002253056,-0.00657406904794087,-9.53180272474084E-4,10,2.38028485769588E-8,,,,,,,,,,,,,,,,,,,,,280.224975585938,280.23095703125,8500.2568359375,8500.2568359375,53.5091159837653,5.65620603142979,6.06656742095947,54,3,0,0,1,0.307388305664063,33.2355842590332,1,1,3,280.224975585938,0,280.227966308594,,,,,,,,,,,,,,,,,,,,,,,,,,,,,,,,,
,3880069150.06359,280.335998535156,10000.09765625,-1.412814835557E-5,1.48265527003096E-8,1,4,13.4005146026611,5.00138008675691,33.4100015461445,-0.0175686125449126,-0.00261986924503553,1,6.51873463454697E-9,,,,,,,,,,,,,,,,,,,,,280.335327148438,280.336669921875,10000.09765625,10000.09765625,53.5548412521403,5.65642946502498,6.06920909881592,54,1,0,0,1,0.30548095703125,33.2355842590332,1,1,3,280.333770751953,0,280.335998535156,,,,,,,,,,,,,,,,,,,,,,,,,,,,,,,,,
,3880069369.22053,280.159652709961,25000.2109375,-1.0483582166272E-4,2.96711899335436E-8,1,4,13.4005146026611,5.00135305835712,33.4200002253056,-0.130371676489868,-0.0193908139796096,1,8.80912782570836E-8,,,,,,,,,,,,,,,,,,,,,280.148803710938,280.170501708984,25000.2109375,25000.2109375,53.3750666927172,5.65651777202686,6.0694055557251,54,2,0,0,1,0.3033447265625,33.2355842590332,1,1,3,280.170806884766,0,280.159652709961,,,,,,,,,,,,,,,,,,,,,,,,,,,,,,,,,
,3880069590.04411,280.057052612305,40000.44140625,-1.9648115434057E-4,6.40156025715096E-8,1,4,13.4005146026611,5.00146127414921,33.4200002253056,-0.244333994062543,-0.0364321083931622,1,9.34111436443077E-8,,,,,,,,,,,,,,,,,,,,,280.05517578125,280.058929443359,40000.44140625,40000.44140625,53.4387694170345,5.65589923306542,6.07364559173584,54,3,0,0,1,0.306549072265625,33.2355842590332,1,1,3,280.05517578125,0,280.057052612305,,,,,,,,,,,,,,,,,,,,,,,,,,,,,,,,,
,3880069884.60184,280.006149291992,60000.33203125,-3.18952965508032E-4,1.04231589424126E-7,1,4,13.4005146026611,5.00121846621925,33.4200002253056,-0.396612220769458,-0.0591008125761894,1,1.80878667556916E-7,,,,,,,,,,,,,,,,,,,,,280.005981445313,280.006317138672,60000.33203125,60000.33203125,53.3832737921691,5.65680121598914,6.06810474395752,54,1,0,0,1,0.304107666015625,33.7243423461914,1,1,3,280.005981445313,0,280.006149291992,,,,,,,,,,,,,,,,,,,,,,,,,,,,,,,,,
,3880070060.81015,280.14128112793,70000.4453125,-3.80250773194912E-4,1.94435744693203E-7,1,4,13.4005146026611,5.00112491146423,33.4200002253056,-0.472801016093184,-0.0706012100678025,1,9.9837519115324E-8,,,,,,,,,,,,,,,,,,,,,280.134155273438,280.148406982422,70000.4453125,70000.4453125,53.2527418294575,5.65634434882878,6.06985330581665,54,3,0,0,1,0.299835205078125,33.7243423461914,1,1,3,280.148406982422,0,280.14128112793,,,,,,,,,,,,,,,,,,,,,,,,,,,,,,,,,