File: SQUID/22169_LCOT/22169_LCOT_MH_250K_FC_0d5T.csv
Comment,Time Stamp (sec),Temperature (K),Magnetic Field (Oe),Moment (emu),M. Std. Err. (emu),Transport Action,Averaging Time (sec),Frequency (Hz),Peak Amplitude (mm),Center Position (mm),Lockin Signal' (V),Lockin Signal (V),Range,M. Quad. Signal (emu),AC Moment (emu),AC M. Std Err. (emu),AC Phase (deg),AC Phase Std. Err. (deg),AC Susceptibility (emu/Oe),AC Suscept. Std Err. (emu/Oe),AC X' (emu/Oe),AC X' Std Err. (emu/Oe),AC X'' (emu/Oe),AC X'' Std Err. (emu/Oe),AC Drive (Oe),AC Frequency (Hz),AC Averaging Time (sec),AC Cycles,AC Range,AC Measure Type,AC Signal' (V),AC Signal'' (V),AC Trim Coil Ratio,AC Trim Coil Phase,Min. Temperature (K),Max. Temperature (K),Min. Field (Oe),Max. Field (Oe),Mass (grams),Motor Lag (deg),Pressure (Torr),Measure Count,Measurement Number,SQUID Status (code),Motor Status (code),Measure Status (code),Motor Current (amps),Motor Temp. (C),Temp. Status (code),Field Status (code),Chamber Status (code),Chamber Temp (K),Redirection State,Average Temp (K),Rotation Angle (deg),Rotator state,DC Moment Fixed Ctr (emu),DC Moment Err Fixed Ctr (emu),DC Moment Free Ctr (emu),DC Moment Err Free Ctr (emu),DC Fixed Fit,DC Free Fit,DC Calculated Center (mm),DC Calculated Center Err (mm),DC Scan Length (mm),DC Scan Time (s),DC Number of Points,DC Squid Drift,DC Min V (V),DC Max V (V),DC Scans per Measure,Sample Resistance,He3 Temperature,Sorb Resistance,Sorb Temperature,Map 05,Map 06,Map 07,Map 08,Map 09,Map 10,Map 11,Map 12,Map 13,Map 14,Map 15,Map 16
,3880023820.36258,250.136070251465,70000.4140625,-3.7834566237535E-4,2.3573230909581E-7,1,4,13.4005146026611,4.99343797077382,33.4200002253056,-0.46943466760259,-0.0699992740131489,1,1.77590211696502E-7,,,,,,,,,,,,,,,,,,,,,250.136016845703,250.136123657227,70000.4140625,70000.4140625,52.9502515925152,5.6470000806106,5.64196634292603,54,1,0,0,1,0.3009033203125,30.7917900085449,1,1,3,250.135604858398,0,250.136070251465,,,,,,,,,,,,,,,,,,,,,,,,,,,,,,,,,
,3880024061.45045,250.182334899902,55000.2734375,-2.86687740045526E-4,1.70716928157662E-7,1,4,13.4005146026611,4.99293186877501,33.4100015461445,-0.355710796673591,-0.0526877410689519,10,4.1348495884358E-7,,,,,,,,,,,,,,,,,,,,,250.181213378906,250.183456420898,55000.2734375,55000.2734375,53.2648570715056,5.64860017137053,5.63727807998657,54,2,0,0,1,0.304412841796875,33.2355842590332,1,1,3,250.183456420898,0,250.182334899902,,,,,,,,,,,,,,,,,,,,,,,,,,,,,,,,,
,3880024298.66103,250.116432189941,40000.27734375,-1.94903389587456E-4,6.3120303260623E-8,1,4,13.4005146026611,4.99247691140465,33.4200002253056,-0.241761042096354,-0.0360589021931512,1,8.44267807667233E-8,,,,,,,,,,,,,,,,,,,,,250.109481811523,250.123382568359,40000.27734375,40000.27734375,53.1609004784479,5.64979642040731,5.63514995574951,54,3,0,0,1,0.296401977539063,33.2355842590332,1,1,3,250.123992919922,0,250.116432189941,,,,,,,,,,,,,,,,,,,,,,,,,,,,,,,,,
,3880024577.6982,250.055046081543,19999.8671875,-7.32040895100346E-5,2.67533528820606E-8,1,4,13.4005146026611,4.99249145618216,33.4100015461445,-0.090793077564815,-0.0136151830521821,1,-2.61003785123312E-8,,,,,,,,,,,,,,,,,,,,,250.026168823242,250.083923339844,19999.8671875,19999.8671875,53.4766784002172,5.6508721634088,5.63311767578125,53,1,68,0,0,0.30548095703125,32.7468223571777,1,1,3,250.083923339844,0,250.055046081543,,,,,,,,,,,,,,,,,,,,,,,,,,,,,,,,,
,3880024769.24817,250.372772216797,9999.6064453125,-1.32347934263346E-5,1.69597047837005E-8,1,4,13.4005146026611,4.99259800188915,33.4200002253056,-0.0164181360742572,-0.00244232347228038,1,1.08258069309433E-8,,,,,,,,,,,,,,,,,,,,,250.365432739258,250.380111694336,9999.6064453125,9999.6064453125,53.3273873530441,5.650058306772,5.63314390182495,54,2,0,0,1,0.304336547851562,33.2355842590332,1,1,3,250.365432739258,0,250.372772216797,,,,,,,,,,,,,,,,,,,,,,,,,,,,,,,,,
,3880024856.35285,250.099082946777,8499.640625,-4.44018906204908E-6,1.34768882392261E-8,1,4,13.4005146026611,4.99232916981445,33.4200002253056,-0.00550737443823446,-8.2193106912983E-4,1,1.52852636491118E-9,,,,,,,,,,,,,,,,,,,,,250.094650268555,250.103515625,8499.640625,8499.640625,53.4790232857749,5.65083407826776,5.63290977478027,54,3,0,0,1,0.30548095703125,33.2355842590332,1,1,3,250.094116210938,0,250.099082946777,,,,,,,,,,,,,,,,,,,,,,,,,,,,,,,,,
,3880024957.68703,250.356330871582,6499.6181640625,7.04849122175375E-6,1.28982095886827E-8,1,4,13.4005146026611,4.99255572130674,33.4200002253056,0.00875966222223244,0.00119432502438115,1,-9.15265012000511E-8,,,,,,,,,,,,,,,,,,,,,250.348327636719,250.364334106445,6499.6181640625,6499.6181640625,53.4977823702364,5.6502118236257,5.63663625717163,53,1,68,0,0,0.30426025390625,32.7468223571777,1,1,3,250.364334106445,0,250.356330871582,,,,,,,,,,,,,,,,,,,,,,,,,,,,,,,,,
,3880025059.3342,250.288307189941,4999.60205078125,1.51934653615705E-5,1.09972132464289E-8,1,4,13.4005146026611,4.99236521609015,33.4200002253056,0.0188559487921676,0.00274171536339628,1,-6.23148741505473E-8,,,,,,,,,,,,,,,,,,,,,250.278259277344,250.298355102539,4999.60205078125,4999.60205078125,53.3973431055153,5.65023531686885,5.63642930984497,53,2,68,0,0,0.303497314453125,33.2355842590332,1,1,3,250.278259277344,0,250.288307189941,,,,,,,,,,,,,,,,,,,,,,,,,,,,,,,,,
,3880025146.3294,250.220832824707,3499.484375,2.24326489858695E-5,7.89657911321514E-9,1,4,13.4005146026611,4.99231977918951,33.4100015461445,0.0278339758998301,0.00408713087922786,1,-6.04561375023303E-8,,,,,,,,,,,,,,,,,,,,,250.217971801758,250.223693847656,3499.484375,3499.484375,53.4915293420826,5.65085642813972,5.6371054649353,54,3,0,0,1,0.304794311523438,33.2355842590332,1,1,3,250.223693847656,0,250.220832824707,,,,,,,,,,,,,,,,,,,,,,,,,,,,,,,,,
,3880025256.1625,250.371536254883,2899.50317382812,2.46092107549929E-5,1.62493114739587E-8,1,4,13.4005146026611,4.99221642894169,33.4200002253056,0.0304938292114664,0.00475024738672909,1,1.48705509271374E-7,,,,,,,,,,,,,,,,,,,,,250.365036010742,250.378036499023,2899.50317382812,2899.50317382812,53.523576111371,5.65087377426939,5.63412809371948,54,1,0,0,1,0.29632568359375,33.2355842590332,1,1,3,250.365036010742,0,250.371536254883,,,,,,,,,,,,,,,,,,,,,,,,,,,,,,,,,
,3880025328.3128,250.265258789062,2749.51416015625,2.51238483076372E-5,1.21236327844455E-8,1,4,13.4005146026611,4.99220368590367,33.4200002253056,0.0311400600272654,0.0047917916998024,1,1.05229614440479E-7,,,,,,,,,,,,,,,,,,,,,250.259735107422,250.270782470703,2749.51416015625,2749.51416015625,53.4821497998518,5.65117421496165,5.63062047958374,53,2,68,0,0,0.304031372070313,33.7243423461914,1,1,3,250.270782470703,0,250.265258789062,,,,,,,,,,,,,,,,,,,,,,,,,,,,,,,,,
,3880025400.42225,250.141738891602,2599.53759765625,2.55808557501902E-5,1.11240665693962E-8,1,4,13.4005146026611,4.99228692105597,33.4200002253056,0.0317118568110462,0.00484823513409278,1,8.22829076627911E-8,,,,,,,,,,,,,,,,,,,,,250.139572143555,250.143905639648,2599.53759765625,2599.53759765625,53.4243092894287,5.65037989956906,5.63599538803101,54,3,0,0,1,0.306472778320313,33.2355842590332,1,1,3,250.139572143555,0,250.141738891602,,,,,,,,,,,,,,,,,,,,,,,,,,,,,,,,,
,3880025493.72802,250.348533630371,2399.673828125,2.60492870101141E-5,1.69447584077989E-8,1,4,13.4005146026611,4.99225741285604,33.4200002253056,0.032276457213472,0.00504281408944449,1,1.69126723728584E-7,,,,,,,,,,,,,,,,,,,,,250.348098754883,250.348968505859,2399.673828125,2399.673828125,53.3930441486595,5.65079217408792,5.63145399093628,54,1,0,0,1,0.304183959960937,33.2355842590332,1,1,3,250.348968505859,0,250.348533630371,,,,,,,,,,,,,,,,,,,,,,,,,,,,,,,,,
,3880025565.50582,250.381469726562,2249.7099609375,2.63631844359334E-5,1.54676212744872E-8,1,4,13.4005146026611,4.99212244238538,33.4200002253056,0.0326703439382726,0.00506201848267489,1,1.37808417541556E-7,,,,,,,,,,,,,,,,,,,,,250.380264282227,250.382675170898,2249.7099609375,2249.7099609375,53.511460869323,5.65064332141396,5.63356018066406,53,2,68,0,0,0.30426025390625,33.2355842590332,1,1,3,250.382675170898,0,250.381469726562,,,,,,,,,,,,,,,,,,,,,,,,,,,,,,,,,
,3880025661.84707,250.336639404297,2099.77124023438,2.66238538146407E-5,1.30442577019296E-8,1,4,13.4005146026611,4.99217636332458,33.4200002253056,0.0330024231358173,0.00505500841542492,1,9.30998772639491E-8,,,,,,,,,,,,,,,,,,,,,250.328048706055,250.345230102539,2099.77124023438,2099.77124023438,53.4614366440922,5.65122861761018,5.64029979705811,54,3,0,0,1,0.304718017578125,33.2355842590332,1,1,3,250.328048706055,0,250.336639404297,,,,,,,,,,,,,,,,,,,,,,,,,,,,,,,,,
,3880025742.85541,250.348686218262,1899.88232421875,2.6772227294955E-5,2.03638344565955E-8,1,4,13.4005146026611,4.99214477002034,33.4200002253056,0.0331699758162511,0.00519058545745421,1,1.80257300186078E-7,,,,,,,,,,,,,,,,,,,,,250.346786499023,250.3505859375,1899.88232421875,1899.88232421875,53.5849339501307,5.65073208041347,5.63207054138184,54,1,0,0,1,0.304641723632812,33.2355842590332,1,1,3,250.346786499023,0,250.348686218262,,,,,,,,,,,,,,,,,,,,,,,,,,,,,,,,,
,3880025825.35212,250.427284240723,1749.55346679687,2.68789964708632E-5,9.55575683486877E-9,1,4,13.4005146026611,4.99208545827766,33.4200002253056,0.0333275185780486,0.00503864236533629,1,4.18397893303219E-8,,,,,,,,,,,,,,,,,,,,,250.418365478516,250.43620300293,1749.55346679687,1749.55346679687,53.4508846590826,5.65118887242926,5.63275814056396,54,2,0,0,1,0.305404663085937,33.2355842590332,1,1,3,250.417541503906,0,250.427284240723,,,,,,,,,,,,,,,,,,,,,,,,,,,,,,,,,
,3880025910.05947,250.260894775391,1599.57690429687,2.67449555676383E-5,1.30292339820648E-8,1,4,13.4005146026611,4.99231081075603,33.4200002253056,0.0331526002107177,0.0050861444547028,1,9.99341052353907E-8,,,,,,,,,,,,,,,,,,,,,250.251815795898,250.269973754883,1599.57690429687,1599.57690429687,53.4583101300153,5.64992726564955,5.63115787506103,54,3,0,0,1,0.3045654296875,32.7468223571777,1,1,3,250.251815795898,0,250.260894775391,,,,,,,,,,,,,,,,,,,,,,,,,,,,,,,,,
,3880026015.66675,250.446113586426,1399.71325683594,2.64208834097552E-5,1.13235531076061E-8,1,4,13.4005146026611,4.99215668257798,33.4200002253056,0.0327550088002284,0.00498726526213425,1,6.88637595683721E-8,,,,,,,,,,,,,,,,,,,,,250.442535400391,250.449691772461,1399.71325683594,1399.71325683594,53.4442408166691,5.65089109802553,5.63552761077881,53,1,68,0,0,0.305404663085937,32.2580642700195,1,1,3,250.442535400391,0,250.446113586426,,,,,,,,,,,,,,,,,,,,,,,,,,,,,,,,,
,3880026099.81735,250.258598327637,1249.64868164062,2.5949581384823E-5,1.75185547173643E-8,1,4,13.4005146026611,4.99236700903063,33.4200002253056,0.0321633939015691,0.00496024027025661,1,1.17341112901938E-7,,,,,,,,,,,,,,,,,,,,,250.24382019043,250.273376464844,1249.64868164062,1249.64868164062,53.4805865428134,5.65083235306673,5.62900352478027,52,2,68,0,0,0.30426025390625,33.2355842590332,1,1,3,250.273376464844,0,250.258598327637,,,,,,,,,,,,,,,,,,,,,,,,,,,,,,,,,
,3880026171.69423,250.134208679199,1099.79797363281,2.53101359856383E-5,1.3900232563091E-8,1,4,13.4005146026611,4.99267494276368,33.4100015461445,0.031375273872541,0.00482683821417634,1,1.05105279102599E-7,,,,,,,,,,,,,,,,,,,,,250.12890625,250.139511108398,1099.79797363281,1099.79797363281,53.308237454323,5.64942312591466,5.63561201095581,54,3,0,0,1,0.304107666015625,32.7468223571777,1,1,3,250.12890625,0,250.134208679199,,,,,,,,,,,,,,,,,,,,,,,,,,,,,,,,,
,3880026252.7579,250.197853088379,899.758117675781,2.39781801223198E-5,2.25551971424736E-8,1,4,13.4005146026611,4.99241411050407,33.4200002253056,0.0296957311324376,0.00474783618862106,1,2.4094728068467E-7,,,,,,,,,,,,,,,,,,,,,250.194885253906,250.200820922852,899.758117675781,899.758117675781,53.5169322689576,5.65045991395613,5.6315188407898,54,1,0,0,1,0.303802490234375,33.2355842590332,1,1,3,250.200820922852,0,250.197853088379,,,,,,,,,,,,,,,,,,,,,,,,,,,,,,,,,
,3880026324.08614,250.199935913086,749.781616210937,2.27202154289387E-5,1.57810225983686E-8,1,4,13.4005146026611,4.99255189870771,33.4100015461445,0.0281521584803949,0.00441026369878632,1,1.56826268307443E-7,,,,,,,,,,,,,,,,,,,,,250.19841003418,250.201461791992,749.781616210937,749.781616210937,53.445413259448,5.64915691608475,5.62983131408691,53,2,68,0,0,0.304794311523438,33.2355842590332,1,1,3,250.201461791992,0,250.199935913086,,,,,,,,,,,,,,,,,,,,,,,,,,,,,,,,,
,3880026394.81897,250.139358520508,599.981384277344,2.09891163644284E-5,1.44118990202048E-8,1,4,13.4005146026611,4.99252579717754,33.4200002253056,0.0260128393158996,0.00403516047517322,1,1.13397177215596E-7,,,,,,,,,,,,,,,,,,,,,250.133728027344,250.144989013672,599.981384277344,599.981384277344,53.345755623246,5.65024236308944,5.63483810424805,53,3,68,0,0,0.305099487304687,33.2355842590332,1,1,3,250.133728027344,0,250.139358520508,,,,,,,,,,,,,,,,,,,,,,,,,,,,,,,,,
,3880026476.77215,250.241722106934,399.802978515625,1.78752338591813E-5,8.70665889137658E-8,1,4,13.4005146026611,4.99238536672489,33.4100015461445,0.0221413490599493,0.00351278843439024,1,1.58178021987763E-7,,,,,,,,,,,,,,,,,,,,,250.241134643555,250.242309570313,399.802978515625,399.802978515625,53.5173230832172,5.64946007747576,5.63061475753784,53,1,68,0,0,0.305252075195313,32.7468223571777,1,1,3,250.242233276367,0,250.241722106934,,,,,,,,,,,,,,,,,,,,,,,,,,,,,,,,,
,3880026547.93788,250.213516235352,249.889434814453,1.46202328402154E-5,9.42660666055073E-9,1,4,13.4005146026611,4.9923348585207,33.4100015461445,0.0181047538656198,0.0029031441973269,1,1.53610650553626E-7,,,,,,,,,,,,,,,,,,,,,250.213439941406,250.213592529297,249.889434814453,249.889434814453,53.4610458298326,5.6502711616512,5.63562345504761,52,2,68,0,0,0.304183959960937,33.2355842590332,1,1,3,250.213439941406,0,250.213516235352,,,,,,,,,,,,,,,,,,,,,,,,,,,,,,,,,
,3880026631.68419,250.260093688965,100.038864135742,1.0359856684799E-5,6.76129335660169E-9,1,4,13.4005146026611,4.99231678019948,33.4200002253056,0.01283630021962,0.00200777158833788,1,6.9036103855849E-8,,,,,,,,,,,,,,,,,,,,,250.259185791016,250.261001586914,100.038864135742,100.038864135742,53.5446800813903,5.65050856704776,5.63615608215332,54,3,0,0,1,0.30609130859375,33.2355842590332,1,1,3,250.259185791016,0,250.260093688965,,,,,,,,,,,,,,,,,,,,,,,,,,,,,,,,,
,3880026736.80188,250.153228759766,-99.8122787475586,2.12981709699179E-6,1.58709327820228E-8,1,4,13.4005146026611,4.99231790195876,33.4200002253056,0.00259657404585951,6.95933004771237E-4,1,2.42502505535407E-7,,,,,,,,,,,,,,,,,,,,,250.152191162109,250.154266357422,-99.8122787475586,-99.8122787475586,53.5302199537845,5.65030519473847,5.62780475616455,54,1,0,0,1,0.304336547851562,32.7468223571777,1,1,3,250.154403686523,0,250.153228759766,,,,,,,,,,,,,,,,,,,,,,,,,,,,,,,,,
,3880026846.28048,250.100830078125,-249.813903808594,-4.47246979255045E-6,1.86708651144164E-8,1,4,13.4005146026611,4.99225858734655,33.4200002253056,-0.00557788932913958,-6.23433361649067E-4,1,1.66389842498924E-7,,,,,,,,,,,,,,,,,,,,,250.099609375,250.10205078125,-249.813903808594,-249.813903808594,53.3121455969191,5.65059492608266,5.63375282287598,53,2,68,0,0,0.297927856445313,32.7468223571777,1,1,3,250.099609375,0,250.100830078125,,,,,,,,,,,,,,,,,,,,,,,,,,,,,,,,,
,3880026959.20945,250.165252685547,-399.790374755859,-1.00540911537698E-5,1.68213676648772E-8,1,4,13.4005146026611,4.99212508660007,33.4200002253056,-0.0124903618830393,-0.00172387832690346,1,1.14043212382923E-7,,,,,,,,,,,,,,,,,,,,,250.164688110352,250.165817260742,-399.790374755859,-399.790374755859,53.430171503323,5.65150580220177,5.62801647186279,52,3,68,0,0,0.30426025390625,32.7468223571777,1,1,3,250.165817260742,0,250.165252685547,,,,,,,,,,,,,,,,,,,,,,,,,,,,,,,,,
,3880027051.82993,250.125480651855,-599.679321289063,-1.57177002099344E-5,1.4309971690593E-8,1,4,13.4005146026611,4.99211517632296,33.4200002253056,-0.0195320384915963,-0.00265660649461696,1,2.09206684302763E-7,,,,,,,,,,,,,,,,,,,,,250.112197875977,250.138763427734,-599.679321289063,-599.679321289063,53.3758483212364,5.65091211185695,5.62775182723999,54,1,0,0,1,0.297622680664063,32.7468223571777,1,1,3,250.138763427734,0,250.125480651855,,,,,,,,,,,,,,,,,,,,,,,,,,,,,,,,,
,3880027123.73688,250.158042907715,-749.718688964844,-1.87729965305998E-5,1.06739244706779E-8,1,4,13.4005146026611,4.99229284593027,33.4200002253056,-0.023316409404835,-0.00326369395821857,1,1.76887058118661E-7,,,,,,,,,,,,,,,,,,,,,250.154403686523,250.161682128906,-749.718688964844,-749.718688964844,53.4876211994864,5.65012226602906,5.63430213928223,54,2,0,0,1,0.303878784179687,32.7468223571777,1,1,3,250.161682128906,0,250.158042907715,,,,,,,,,,,,,,,,,,,,,,,,,,,,,,,,,
,3880027195.36662,250.076240539551,-899.657409667969,-2.10590996462133E-5,1.34159663539533E-8,1,4,13.4005146026611,4.99228407650954,33.4200002253056,-0.0261448281666276,-0.00373398411118651,1,1.39683003786921E-7,,,,,,,,,,,,,,,,,,,,,250.073715209961,250.078765869141,-899.657409667969,-899.657409667969,53.4489305877845,5.65016109470319,5.63111591339111,54,3,0,0,1,0.303115844726562,33.2355842590332,1,1,3,250.073715209961,0,250.076240539551,,,,,,,,,,,,,,,,,,,,,,,,,,,,,,,,,
,3880027278.47317,250.247650146484,-1099.583984375,-2.32004054779729E-5,5.89181589263776E-8,1,4,13.4005146026611,4.9921599684656,33.4200002253056,-0.0288231174811831,-0.00397403133999955,1,2.66352791961627E-7,,,,,,,,,,,,,,,,,,,,,250.242568969727,250.252731323242,-1099.583984375,-1099.583984375,53.3836646064287,5.65027177118183,5.63388824462891,52,1,68,0,0,0.296478271484375,32.7468223571777,1,1,3,250.242568969727,0,250.247650146484,,,,,,,,,,,,,,,,,,,,,,,,,,,,,,,,,
,3880027349.79573,250.134384155273,-1249.62353515625,-2.43561963739708E-5,1.45763267720831E-8,1,4,13.4005146026611,4.99204313041444,33.4200002253056,-0.0302314403120868,-0.0043495949606973,1,1.36317802978924E-7,,,,,,,,,,,,,,,,,,,,,250.130249023438,250.138519287109,-1249.62353515625,-1249.62353515625,53.3664687790057,5.65055877741042,5.63081836700439,54,2,0,0,1,0.30548095703125,33.2355842590332,1,1,3,250.138732910156,0,250.134384155273,,,,,,,,,,,,,,,,,,,,,,,,,,,,,,,,,
,3880027422.08538,250.345321655273,-1399.51184082031,-2.51537987297102E-5,9.1362512808817E-9,1,4,13.4005146026611,4.99212080013234,33.4200002253056,-0.0312171677362287,-0.00452525143947839,1,1.14076249288183E-7,,,,,,,,,,,,,,,,,,,,,250.339385986328,250.351257324219,-1399.51184082031,-1399.51184082031,53.4247001036883,5.65089747592081,5.63815212249756,52,3,68,0,0,0.3045654296875,32.7468223571777,6,1,3,250.351547241211,0,250.345321655273,,,,,,,,,,,,,,,,,,,,,,,,,,,,,,,,,
,3880027507.02634,250.246429443359,-1599.53918457031,-2.58433381454355E-5,9.43355207174072E-9,1,4,13.4005146026611,4.99211697950567,33.4100015461445,-0.0320817404955766,-0.00459011658261052,1,1.64921406509693E-7,,,,,,,,,,,,,,,,,,,,,250.235382080078,250.257476806641,-1599.53918457031,-1599.53918457031,53.4590917585345,5.6504542927146,5.62906885147095,52,1,68,0,0,0.30487060546875,33.2355842590332,1,1,3,250.235382080078,0,250.246429443359,,,,,,,,,,,,,,,,,,,,,,,,,,,,,,,,,
,3880027580.1996,250.173492431641,-1749.78002929687,-2.60924203787159E-5,8.95057155561858E-9,1,4,13.4005146026611,4.99209310303565,33.4200002253056,-0.0323846163872494,-0.00467520971874798,1,1.33545383188242E-7,,,,,,,,,,,,,,,,,,,,,250.172286987305,250.174697875977,-1749.78002929687,-1749.78002929687,53.4262633607268,5.65151978653571,5.63775539398193,53,2,68,0,0,0.303878784179687,32.7468223571777,1,1,3,250.172286987305,0,250.173492431641,,,,,,,,,,,,,,,,,,,,,,,,,,,,,,,,,
,3880027652.54699,250.214218139648,-1899.73132324219,-2.61561330826748E-5,1.46936717066634E-7,1,4,13.4005146026611,4.99216641947739,33.4200002253056,-0.0324324671582437,-0.00489992846506886,1,-3.803773905086E-8,,,,,,,,,,,,,,,,,,,,,250.20915222168,250.219284057617,-1899.73132324219,-1899.73132324219,53.3328587526787,5.65090891256787,5.63254356384277,54,3,0,0,1,0.296554565429687,32.7468223571777,1,1,3,250.20915222168,0,250.214218139648,,,,,,,,,,,,,,,,,,,,,,,,,,,,,,,,,
,3880027743.75857,250.34049987793,-2099.69555664062,-2.61108405169591E-5,3.25929541381325E-8,1,4,13.4005146026611,4.99216294141885,33.4100015461445,-0.0324085464593945,-0.00467570993060977,1,1.35971495597765E-7,,,,,,,,,,,,,,,,,,,,,250.339736938477,250.341262817383,-2099.69555664062,-2099.69555664062,53.528656696746,5.6515614547398,5.63203430175781,54,1,0,0,1,0.305633544921875,32.7468223571777,1,1,3,250.339736938477,0,250.34049987793,,,,,,,,,,,,,,,,,,,,,,,,,,,,,,,,,
,3880027815.16164,250.281707763672,-2249.67211914062,-2.60106294433472E-5,4.44312744280211E-8,1,4,13.4005146026611,4.99214851746709,33.4200002253056,-0.0322855489696643,-0.00464762322375132,1,1.43611823412206E-7,,,,,,,,,,,,,,,,,,,,,250.279190063477,250.284225463867,-2249.67211914062,-2249.67211914062,53.3430199234287,5.65116675133561,5.63308763504028,53,2,68,0,0,0.295944213867188,32.7468223571777,1,1,3,250.284225463867,0,250.281707763672,,,,,,,,,,,,,,,,,,,,,,,,,,,,,,,,,
,3880027886.83271,250.24201965332,-2399.673828125,-2.56876527851133E-5,7.29897452499828E-9,1,4,13.4005146026611,4.9920744258143,33.4200002253056,-0.0318790298320388,-0.00462299469252615,1,1.15077176404153E-7,,,,,,,,,,,,,,,,,,,,,250.237091064453,250.246948242187,-2399.673828125,-2399.673828125,53.4559652444576,5.65129867558331,5.62840604782105,53,3,68,0,0,0.295486450195313,32.7468223571777,1,1,3,250.246948242187,0,250.24201965332,,,,,,,,,,,,,,,,,,,,,,,,,,,,,,,,,
,3880027980.12668,250.442276000977,-2599.68872070313,-2.52383263565357E-5,7.55152437608845E-9,1,4,13.4005146026611,4.99207322577632,33.4200002253056,-0.0313179564088523,-0.00456510603254348,1,9.45365598259831E-8,,,,,,,,,,,,,,,,,,,,,250.435165405273,250.44938659668,-2599.68872070313,-2599.68872070313,53.5853247643903,5.65099275081519,5.63505840301514,54,1,0,0,1,0.30517578125,32.7468223571777,1,1,3,250.4326171875,0,250.442276000977,,,,,,,,,,,,,,,,,,,,,,,,,,,,,,,,,
,3880028052.81506,250.238967895508,-2749.61474609375,-2.48159765399396E-5,9.68183679204693E-9,1,4,13.4005146026611,4.99211150927826,33.4100015461445,-0.0307969510192552,-0.00447035747038911,1,1.07792548874297E-7,,,,,,,,,,,,,,,,,,,,,250.235061645508,250.242874145508,-2749.61474609375,-2749.61474609375,53.3801472780922,5.65182060302112,5.63253879547119,52,2,68,0,0,0.30548095703125,34.2131004333496,1,1,3,250.242935180664,0,250.238967895508,,,,,,,,,,,,,,,,,,,,,,,,,,,,,,,,,
,3880028125.02861,250.431228637695,-2899.70458984375,-2.43408475352501E-5,9.73767493720282E-9,1,4,13.4005146026611,4.99272331294521,33.4200002253056,-0.0302141952039694,-0.00437416864633361,1,1.14880408380042E-7,,,,,,,,,,,,,,,,,,,,,250.4296875,250.432769775391,-2899.70458984375,-2899.70458984375,53.533737282121,5.65008718704987,5.63374328613281,54,3,0,0,1,0.304946899414063,32.7468223571777,6,1,3,250.432647705078,0,250.431228637695,,,,,,,,,,,,,,,,,,,,,,,,,,,,,,,,,
,3880028330.99978,250.113670349121,-3499.7236328125,-2.20544589956215E-5,1.1828696288098E-8,1,4,13.4005146026611,4.9922413693612,33.4200002253056,-0.0273578767477628,-0.00405989399391738,1,2.57694810204704E-8,,,,,,,,,,,,,,,,,,,,,250.106887817383,250.120452880859,-3499.7236328125,-3499.7236328125,53.4215735896114,5.65132114706976,5.63194036483765,54,1,0,0,1,0.305938720703125,33.2355842590332,1,1,3,250.120452880859,0,250.113670349121,,,,,,,,,,,,,,,,,,,,,,,,,,,,,,,,,
,3880028413.68043,250.218101501465,-4999.71533203125,-1.48318724842098E-5,9.05789422889567E-9,1,4,13.4005146026611,4.99228608939292,33.4200002253056,-0.0183927908351884,-0.00276993831565486,1,-1.45818144067587E-8,,,,,,,,,,,,,,,,,,,,,250.205276489258,250.230926513672,-4999.71533203125,-4999.71533203125,53.3649055219672,5.65150614222418,5.63403654098511,54,2,0,0,1,0.305557250976562,32.7468223571777,1,1,3,250.231643676758,0,250.218101501465,,,,,,,,,,,,,,,,,,,,,,,,,,,,,,,,,
,3880028510.86568,250.376083374023,-6499.78173828125,-6.67215219040334E-6,9.77237701320577E-9,1,4,13.4005146026611,4.99217625026458,33.4100015461445,-0.00827093652171796,-0.00126506267451956,1,-2.19099823854105E-8,,,,,,,,,,,,,,,,,,,,,250.373001098633,250.379165649414,-6499.78173828125,-6499.78173828125,53.4176654470153,5.65232691716275,5.62945461273193,54,3,0,0,1,0.30487060546875,32.7468223571777,1,1,3,250.373001098633,0,250.376083374023,,,,,,,,,,,,,,,,,,,,,,,,,,,,,,,,,
,3880028609.61969,250.141212463379,-8499.791015625,4.78648459122806E-6,1.6509666233558E-8,1,4,13.4005146026611,4.9923320255967,33.4200002253056,0.00594942953356093,8.0231662956437E-4,1,-6.91472110396606E-8,,,,,,,,,,,,,,,,,,,,,250.117431640625,250.164993286133,-8499.791015625,-8499.791015625,53.3989063625537,5.65172102997762,5.63242864608765,53,1,68,0,0,0.304489135742188,33.2355842590332,1,1,3,250.164993286133,0,250.141212463379,,,,,,,,,,,,,,,,,,,,,,,,,,,,,,,,,
,3880028693.15489,250.264343261719,-9999.908203125,1.35536029809663E-5,1.38709615407104E-8,1,4,13.4005146026611,4.99219433800987,33.4100015461445,0.0168181015291902,0.00245823761630435,1,-4.54631192095437E-8,,,,,,,,,,,,,,,,,,,,,250.26220703125,250.266479492187,-9999.908203125,-9999.908203125,53.366077964746,5.65147939416846,5.62547540664673,54,2,0,0,1,0.30517578125,32.7468223571777,1,1,3,250.266479492187,0,250.264343261719,,,,,,,,,,,,,,,,,,,,,,,,,,,,,,,,,
,3880028874.11812,249.99779510498,-19999.7421875,7.34608155120041E-5,3.71654680502064E-8,1,4,13.4005146026611,4.99209765328682,33.4200002253056,0.0911247620021062,0.0135053721261559,1,-9.96336500347807E-8,,,,,,,,,,,,,,,,,,,,,249.997741699219,249.997848510742,-19999.7421875,-19999.7421875,53.3797564638326,5.65193636402506,5.62816762924194,54,3,0,0,1,0.296707153320313,32.7468223571777,1,1,3,249.997848510742,0,249.99779510498,,,,,,,,,,,,,,,,,,,,,,,,,,,,,,,,,
,3880029155.69022,250.059295654297,-39999.69921875,1.95074939986976E-4,4.28708936484907E-8,1,4,13.4005146026611,4.99204051338853,33.4200002253056,0.241952937286009,0.0360278071079959,1,-1.31601521348738E-7,,,,,,,,,,,,,,,,,,,,,250.031814575195,250.086776733398,-39999.69921875,-39999.69921875,53.3140996682172,5.65192255486274,5.6325888633728,54,1,0,0,1,0.304107666015625,33.2355842590332,1,1,3,250.086776733398,0,250.059295654297,,,,,,,,,,,,,,,,,,,,,,,,,,,,,,,,,
,3880029384.60237,250.240257263184,-54999.55859375,2.86811953053025E-4,8.71054516959739E-8,1,4,13.4005146026611,4.99189229519017,33.4200002253056,0.355769336041171,0.0526401401197766,10,-4.58056155963839E-7,,,,,,,,,,,,,,,,,,,,,250.239791870117,250.24072265625,-54999.55859375,-54999.55859375,53.2969038407941,5.65218235060613,5.63074207305908,54,2,0,0,1,0.305633544921875,33.2355842590332,1,1,3,250.24072265625,0,250.240257263184,,,,,,,,,,,,,,,,,,,,,,,,,,,,,,,,,
,3880029622.00214,250.060272216797,-69999.546875,3.78381036729266E-4,3.58272452997615E-7,1,4,13.4005146026611,4.99187345168427,33.4200002253056,0.469247570463899,0.0701415638565307,1,-4.33661135839351E-8,,,,,,,,,,,,,,,,,,,,,250.057769775391,250.062774658203,-69999.546875,-69999.546875,53.0585071424287,5.65149737778442,5.62762117385864,54,3,0,0,1,0.304489135742188,32.7468223571777,1,1,3,250.057769775391,0,250.060272216797,,,,,,,,,,,,,,,,,,,,,,,,,,,,,,,,,
,3880029906.69928,250.106643676758,-49999.73046875,2.55904798345847E-4,9.93129832691778E-8,1,4,13.4005146026611,4.99214567276375,33.4200002253056,0.317394532826253,0.0473673752677884,1,-8.90335891148768E-8,,,,,,,,,,,,,,,,,,,,,250.074111938477,250.139175415039,-49999.73046875,-49999.73046875,53.3527902799191,5.65167043463821,5.62909269332886,54,1,0,0,1,0.30364990234375,33.2355842590332,1,1,3,250.139175415039,0,250.106643676758,,,,,,,,,,,,,,,,,,,,,,,,,,,,,,,,,
,3880030129.38779,250.017669677734,-34999.6171875,1.6439708833148E-4,4.50604817125782E-8,1,4,13.4005146026611,4.99218067418521,33.4200002253056,0.203907734742835,0.0303849332568576,1,-9.33828557423582E-8,,,,,,,,,,,,,,,,,,,,,250.016906738281,250.018432617187,-34999.6171875,-34999.6171875,53.5169322689576,5.65117285195635,5.62389039993286,54,2,0,0,1,0.304412841796875,33.7243423461914,1,1,3,250.016906738281,0,250.017669677734,,,,,,,,,,,,,,,,,,,,,,,,,,,,,,,,,
,3880030367.92305,250.161026000977,-19999.56640625,7.32487745681854E-5,3.32785595762502E-8,1,4,13.4005146026611,4.99215488153767,33.4200002253056,0.0908484088143133,0.0135654448837931,1,-1.96514644379938E-8,,,,,,,,,,,,,,,,,,,,,250.150787353516,250.171264648438,-19999.56640625,-19999.56640625,53.4348612744383,5.65146027583657,5.62968063354492,52,3,68,0,0,0.297470092773438,33.7243423461914,1,1,3,250.171264648438,0,250.161026000977,,,,,,,,,,,,,,,,,,,,,,,,,,,,,,,,,
,3880030570.55038,250.209327697754,-9500.1796875,1.02702514368806E-5,1.87137445002674E-8,1,4,13.4005146026611,4.99217288566097,33.4100015461445,0.0127309945144988,0.00194865980793831,1,3.48438731387629E-8,,,,,,,,,,,,,,,,,,,,,250.203125,250.215530395508,-9500.1796875,-9500.1796875,53.4247001036883,5.65171445646183,5.62772178649902,54,1,0,0,1,0.30426025390625,33.7243423461914,1,1,3,250.203125,0,250.209327697754,,,,,,,,,,,,,,,,,,,,,,,,,,,,,,,,,
,3880030674.32363,250.2744140625,-8000.4150390625,1.54982010251108E-6,1.80720189727814E-8,1,4,13.4005146026611,4.99219728070859,33.4100015461445,0.00191873724804148,3.10316370527256E-4,10,1.83637628465832E-8,,,,,,,,,,,,,,,,,,,,,250.273056030273,250.275772094727,-8000.4150390625,-8000.4150390625,53.5087251695057,5.65209851823432,5.62910175323486,54,2,0,0,1,0.30517578125,33.7243423461914,1,1,3,250.275772094727,0,250.2744140625,,,,,,,,,,,,,,,,,,,,,,,,,,,,,,,,,
,3880030772.58765,250.208961486816,-6500.3232421875,-7.00979486919762E-6,1.09453028095262E-8,1,4,13.4005146026611,4.99215257330375,33.4200002253056,-0.00870039301912071,-0.00125577045798315,1,3.60848888918817E-8,,,,,,,,,,,,,,,,,,,,,250.204223632813,250.21369934082,-6500.3232421875,-6500.3232421875,53.4739427003999,5.6524706764954,5.63108777999878,54,3,0,0,1,0.305023193359375,33.7243423461914,1,1,3,250.204223632813,0,250.208961486816,,,,,,,,,,,,,,,,,,,,,,,,,,,,,,,,,
,3880030883.94411,250.340911865234,-4500.37646484375,-1.77699382415622E-5,1.1990199760331E-8,1,4,13.4005146026611,4.99222021024438,33.4200002253056,-0.0220578110174856,-0.00317168179511032,1,1.00970764604777E-7,,,,,,,,,,,,,,,,,,,,,250.331390380859,250.350433349609,-4500.37646484375,-4500.37646484375,53.5739911508614,5.65209034636345,5.62676620483398,54,1,0,0,1,0.2984619140625,33.2355842590332,1,1,3,250.350433349609,0,250.340911865234,,,,,,,,,,,,,,,,,,,,,,,,,,,,,,,,,
,3880030968.43428,250.325355529785,-3000.41064453125,-2.43937807730813E-5,8.52417232487994E-9,1,4,13.4005146026611,4.99219565075916,33.4200002253056,-0.0302712763569329,-0.00441071212205248,1,9.28117063467748E-8,,,,,,,,,,,,,,,,,,,,,250.314437866211,250.336273193359,-3000.41064453125,-3000.41064453125,53.3871819347653,5.65235403093081,5.62888526916504,54,2,0,0,1,0.299224853515625,33.7243423461914,1,1,3,250.336273193359,0,250.325355529785,,,,,,,,,,,,,,,,,,,,,,,,,,,,,,,,,
,3880031057.41878,250.266571044922,-2900.25854492188,-2.46471211649917E-5,1.17830940062408E-8,1,4,13.4005146026611,4.99220625547552,33.4200002253056,-0.030553811085545,-0.0046700249626069,1,-7.83623072308862E-8,,,,,,,,,,,,,,,,,,,,,250.259384155273,250.27375793457,-2900.25854492188,-2900.25854492188,53.498173184496,5.65208351206198,5.62939023971558,54,3,0,0,1,0.296554565429687,33.7243423461914,1,1,3,250.27375793457,0,250.266571044922,,,,,,,,,,,,,,,,,,,,,,,,,,,,,,,,,
,3880031139.53782,250.413566589355,-2700.24365234375,-2.52365464903521E-5,1.72562371282647E-8,1,4,13.4005146026611,4.9922972681995,33.4100015461445,-0.0312710834296045,-0.00487680668517122,1,-1.5681462308318E-7,,,,,,,,,,,,,,,,,,,,,250.40803527832,250.419097900391,-2700.24365234375,-2700.24365234375,53.554059623621,5.65208015432142,5.62735843658447,54,1,0,0,1,0.304336547851562,33.7243423461914,1,1,3,250.419097900391,0,250.413566589355,,,,,,,,,,,,,,,,,,,,,,,,,,,,,,,,,
,3880031210.0489,250.328643798828,-2550.26733398438,-2.57019376938637E-5,1.3719154042005E-8,1,4,13.4005146026611,4.99241345390781,33.4200002253056,-0.0318600151981949,-0.00489191192301496,1,-9.9245321625853E-8,,,,,,,,,,,,,,,,,,,,,250.325164794922,250.332122802734,-2550.26733398438,-2550.26733398438,53.5079435409864,5.65205095432286,5.63252258300781,53,2,68,0,0,0.305252075195313,33.7243423461914,1,1,3,250.325164794922,0,250.328643798828,,,,,,,,,,,,,,,,,,,,,,,,,,,,,,,,,
,3880031282.36472,250.347236633301,-2400.26538085938,-2.60856120094742E-5,1.21356506931364E-8,1,4,13.4005146026611,4.99239480150286,33.4100015461445,-0.0323400411726351,-0.00493420067816233,1,-7.59660804880142E-8,,,,,,,,,,,,,,,,,,,,,250.343185424805,250.351287841797,-2400.26538085938,-2400.26538085938,53.4985639987557,5.65122148154927,5.62508630752563,54,3,0,0,1,0.305633544921875,33.7243423461914,1,1,3,250.351287841797,0,250.347236633301,,,,,,,,,,,,,,,,,,,,,,,,,,,,,,,,,
,3880031391.29502,250.326499938965,-2200.27587890625,-2.64226963886805E-5,1.96078836598355E-8,1,4,13.4005146026611,4.992207050949,33.4200002253056,-0.0327348310777799,-0.00514068199236632,1,-1.92234881382317E-7,,,,,,,,,,,,,,,,,,,,,250.325988769531,250.327011108398,-2200.27587890625,-2200.27587890625,53.5333464678614,5.65234245604904,5.63428068161011,54,1,0,0,1,0.30517578125,33.7243423461914,1,1,3,250.325988769531,0,250.326499938965,,,,,,,,,,,,,,,,,,,,,,,,,,,,,,,,,
,3880031462.02518,250.229347229004,-2050.31201171875,-2.66480575168232E-5,1.57837752898269E-8,1,4,13.4005146026611,4.99215276997314,33.4100015461445,-0.0330277996199707,-0.0050890316138321,1,-1.16939305873383E-7,,,,,,,,,,,,,,,,,,,,,250.22004699707,250.238647460938,-2050.31201171875,-2050.31201171875,53.5935318638422,5.65249348216456,5.62914752960205,53,2,68,0,0,0.305633544921875,33.7243423461914,1,1,3,250.238647460938,0,250.229347229004,,,,,,,,,,,,,,,,,,,,,,,,,,,,,,,,,
,3880031533.01184,250.147933959961,-1900.32287597656,-2.6801948614706E-5,1.40571077141176E-8,1,4,13.4005146026611,4.99199553019823,33.4200002253056,-0.0332237064039575,-0.00507381355029178,1,-8.18282739891252E-8,,,,,,,,,,,,,,,,,,,,,250.143142700195,250.152725219727,-1900.32287597656,-1900.32287597656,53.5712554510441,5.65337400051138,5.62551736831665,54,3,0,0,1,0.30548095703125,33.2355842590332,1,1,3,250.143142700195,0,250.147933959961,,,,,,,,,,,,,,,,,,,,,,,,,,,,,,,,,
,3880031613.95007,250.069633483887,-1700.03125,-2.67436264120033E-5,2.28942338719197E-8,1,4,13.4005146026611,4.99211746966,33.4200002253056,-0.0331329152668708,-0.00519416554324097,1,-1.87454565980175E-7,,,,,,,,,,,,,,,,,,,,,250.064254760742,250.075012207031,-1700.03125,-1700.03125,53.541944381573,5.65245624531316,5.62602949142456,53,1,68,0,0,0.305252075195313,33.2355842590332,1,1,3,250.075012207031,0,250.069633483887,,,,,,,,,,,,,,,,,,,,,,,,,,,,,,,,,
,3880031685.69991,250.334381103516,-1550.02954101562,-2.66452716489074E-5,1.50709585755444E-8,1,4,13.4005146026611,4.9919366531058,33.4200002253056,-0.0330255181375049,-0.00506696909984561,1,-9.98147331902806E-8,,,,,,,,,,,,,,,,,,,,,250.329071044922,250.339691162109,-1550.02954101562,-1550.02954101562,53.4872303852268,5.65304766567784,5.62765550613403,53,2,68,0,0,0.297622680664063,33.2355842590332,1,1,3,250.339691162109,0,250.334381103516,,,,,,,,,,,,,,,,,,,,,,,,,,,,,,,,,
,3880031756.39737,250.341430664062,-1400.00280761719,-2.64056723489092E-5,1.46411538210934E-8,1,4,13.4005146026611,4.99184642246822,33.4200002253056,-0.0327316197612353,-0.00499519301619024,1,-7.78822276886789E-8,,,,,,,,,,,,,,,,,,,,,250.339660644531,250.343200683594,-1400.00280761719,-1400.00280761719,53.5544504378807,5.65408618303303,5.62326955795288,53,3,68,0,0,0.29815673828125,33.2355842590332,1,1,3,250.343200683594,0,250.341430664062,,,,,,,,,,,,,,,,,,,,,,,,,,,,,,,,,
,3880031850.88407,250.24683380127,-1200.05090332031,-2.57329309786237E-5,2.44460080309265E-8,1,4,13.4005146026611,4.99178014358417,33.4100015461445,-0.0318761496438676,-0.00500800624448922,1,-1.88927622250973E-7,,,,,,,,,,,,,,,,,,,,,250.243072509766,250.250595092773,-1200.05090332031,-1200.05090332031,53.5595310232557,5.65379060049919,5.62791681289673,54,1,0,0,1,0.305252075195313,32.7468223571777,1,1,3,250.250595092773,0,250.24683380127,,,,,,,,,,,,,,,,,,,,,,,,,,,,,,,,,
,3880031921.3882,250.16374206543,-1050.07446289062,-2.49939188437341E-5,1.78659045007715E-8,1,4,13.4005146026611,4.99201522400457,33.4200002253056,-0.0309705952307982,-0.00481210398984561,1,-1.41249235429871E-7,,,,,,,,,,,,,,,,,,,,,250.15592956543,250.17155456543,-1050.07446289062,-1050.07446289062,53.508334355246,5.65326844287899,5.62434816360474,54,2,0,0,1,0.305557250976562,33.2355842590332,1,1,3,250.17155456543,0,250.16374206543,,,,,,,,,,,,,,,,,,,,,,,,,,,,,,,,,
,3880031992.73071,250.248878479004,-900.060241699219,-2.40524835602201E-5,1.48138205547978E-8,1,4,13.4005146026611,4.99195158132034,33.4200002253056,-0.0298103306034264,-0.00458514885195294,1,-9.91454999030537E-8,,,,,,,,,,,,,,,,,,,,,250.24462890625,250.253128051758,-900.060241699219,-900.060241699219,53.470816186323,5.65355627150386,5.62812519073486,53,3,68,0,0,0.297393798828125,33.2355842590332,1,1,3,250.253448486328,0,250.248878479004,,,,,,,,,,,,,,,,,,,,,,,,,,,,,,,,,
,3880032075.44448,250.28987121582,-700.032897949219,-2.21244898889593E-5,2.20954916489281E-8,1,4,13.4005146026611,4.99207671798662,33.4200002253056,-0.0273934654612345,-0.00440693010527331,1,-2.4372942457069E-7,,,,,,,,,,,,,,,,,,,,,250.284957885742,250.294784545898,-700.032897949219,-700.032897949219,53.5630483515922,5.65273145757149,5.63034057617188,53,1,68,0,0,0.30487060546875,33.7243423461914,1,1,3,250.284957885742,0,250.28987121582,,,,,,,,,,,,,,,,,,,,,,,,,,,,,,,,,
,3880032146.56696,250.282333374023,-550.106750488281,-2.02822135654187E-5,2.03003957936893E-8,1,4,13.4005146026611,4.99185774454279,33.4200002253056,-0.0251222446126121,-0.00396392091899297,1,-1.62309808453873E-7,,,,,,,,,,,,,,,,,,,,,250.280242919922,250.284423828125,-550.106750488281,-550.106750488281,53.5849339501307,5.65262102241106,5.6243577003479,54,2,0,0,1,0.30517578125,33.2355842590332,1,1,3,250.279769897461,0,250.282333374023,,,,,,,,,,,,,,,,,,,,,,,,,,,,,,,,,
,3880032217.30564,250.196418762207,-400.130279541016,-1.78710762397067E-5,1.32759600987146E-8,1,4,13.4005146026611,4.99187873841731,33.4200002253056,-0.0221422477817151,-0.00344999720276535,1,-1.08569819281034E-7,,,,,,,,,,,,,,,,,,,,,250.192947387695,250.199890136719,-400.130279541016,-400.130279541016,53.325433281746,5.65399961895223,5.62867212295532,53,3,68,0,0,0.3082275390625,32.7468223571777,1,1,3,250.192947387695,0,250.196418762207,,,,,,,,,,,,,,,,,,,,,,,,,,,,,,,,,
,3880032299.54385,250.303321838379,-200.090316772461,-1.32643309243183E-5,2.62465293159742E-8,1,4,13.4005146026611,4.99193103100467,33.4100015461445,-0.0164044528089874,-0.00276313979791819,1,-2.43816930259771E-7,,,,,,,,,,,,,,,,,,,,,250.298187255859,250.308456420898,-200.090316772461,-200.090316772461,53.4970007417172,5.65345140878827,5.63095951080322,53,1,68,0,0,0.306015014648438,33.2355842590332,1,1,3,250.308456420898,0,250.303321838379,,,,,,,,,,,,,,,,,,,,,,,,,,,,,,,,,
,3880032369.67298,250.340621948242,-50.1516075134277,-8.52498409671333E-6,1.92193548885905E-8,1,4,13.4005146026611,4.99191165541501,33.4200002253056,-0.0105468822766893,-0.00175046111714423,1,-1.36220418407247E-7,,,,,,,,,,,,,,,,,,,,,250.330535888672,250.350708007813,-50.1516075134277,-50.1516075134277,53.6290959614672,5.65364941579516,5.6274356842041,54,2,0,0,1,0.305557250976562,33.2355842590332,1,1,3,250.330535888672,0,250.340621948242,,,,,,,,,,,,,,,,,,,,,,,,,,,,,,,,,
,3880032440.34772,250.338249206543,99.9381561279297,-2.18614032831674E-6,9.19521872456651E-9,1,4,13.4005146026611,4.9919504990709,33.4200002253056,-0.00269402949797071,-5.19979787282656E-4,1,-9.22543022831657E-8,,,,,,,,,,,,,,,,,,,,,250.330795288086,250.345703125,99.9381561279297,99.9381561279297,53.5138057548807,5.65348634863345,5.62717151641846,54,3,0,0,1,0.305252075195313,33.2355842590332,1,1,3,250.330795288086,0,250.338249206543,,,,,,,,,,,,,,,,,,,,,,,,,,,,,,,,,
,3880032522.7203,250.296028137207,299.600463867188,6.50825850614529E-6,1.98470503518611E-8,1,4,13.4005146026611,4.99183632050723,33.4200002253056,0.00810654058684665,9.6955569459008E-4,1,-1.91765872148359E-7,,,,,,,,,,,,,,,,,,,,,250.288269042969,250.303787231445,299.600463867188,299.600463867188,53.3125364111787,5.65369273651457,5.63090229034424,54,1,0,0,1,0.29937744140625,33.2355842590332,1,1,3,250.288269042969,0,250.296028137207,,,,,,,,,,,,,,,,,,,,,,,,,,,,,,,,,
,3880032594.48378,250.225769042969,449.6650390625,1.16717250354051E-5,1.13314927850121E-8,1,4,13.4005146026611,4.99181766836784,33.4200002253056,0.0145019376662547,0.00197958120688057,1,-1.49716769951392E-7,,,,,,,,,,,,,,,,,,,,,250.219985961914,250.231552124023,449.6650390625,449.6650390625,53.5388178674961,5.65314125775558,5.62765407562256,53,2,68,0,0,0.304107666015625,33.2355842590332,1,1,3,250.219985961914,0,250.225769042969,,,,,,,,,,,,,,,,,,,,,,,,,,,,,,,,,
,3880032678.2864,250.380592346191,599.855529785156,1.56827716020648E-5,7.38233147253874E-9,1,4,13.4005146026611,4.99184592975563,33.4200002253056,0.019465386215586,0.00279605932808539,1,-9.13681221568231E-8,,,,,,,,,,,,,,,,,,,,,250.373321533203,250.38786315918,599.855529785156,599.855529785156,53.6076011771884,5.65347351170935,5.62965536117554,53,3,68,0,0,0.305557250976562,33.2355842590332,1,1,3,250.373321533203,0,250.380592346191,,,,,,,,,,,,,,,,,,,,,,,,,,,,,,,,,
,3880032760.05872,250.308479309082,799.593383789063,1.96204617396508E-5,2.18969993393032E-8,1,4,13.4005146026611,4.99197311012247,33.4100015461445,0.0243737910956762,0.00336391913738849,1,-2.22610068364042E-7,,,,,,,,,,,,,,,,,,,,,250.300750732422,250.316207885742,799.593383789063,799.593383789063,53.4512754733422,5.65321901533016,5.63007020950317,54,1,0,0,1,0.305633544921875,32.7468223571777,1,1,3,250.316207885742,0,250.308479309082,,,,,,,,,,,,,,,,,,,,,,,,,,,,,,,,,
,3880032831.4095,250.314804077148,949.670532226563,2.16874623417957E-5,1.86536833706304E-8,1,4,13.4005146026611,4.99198606919958,33.4200002253056,0.0269229727241241,0.00384316756543118,1,-1.4539078947535E-7,,,,,,,,,,,,,,,,,,,,,250.313491821289,250.316116333008,949.670532226563,949.670532226563,53.4313439461018,5.65338818720036,5.63039064407349,52,2,68,0,0,0.299148559570313,33.2355842590332,1,1,3,250.316116333008,0,250.314804077148,,,,,,,,,,,,,,,,,,,,,,,,,,,,,,,,,
,3880032903.11398,250.299102783203,1099.67211914062,2.32240890931745E-5,2.33898301070644E-8,1,4,13.4005146026611,4.99183660326964,33.4200002253056,0.0288251802826392,0.00414312042938981,1,-1.33254941751789E-7,,,,,,,,,,,,,,,,,,,,,250.294815063477,250.30339050293,1099.67211914062,1099.67211914062,53.6326132898038,5.65405884224146,5.63115787506103,53,3,64,0,0,0.30426025390625,33.2355842590332,1,1,3,250.294815063477,0,250.299102783203,,,,,,,,,,,,,,,,,,,,,,,,,,,,,,,,,
,3880032985.03882,250.357986450195,1299.54858398438,2.46265338117562E-5,9.25071933379412E-8,1,4,13.4005146026611,4.99211882187787,33.4200002253056,0.0305580067329748,0.00446235178743185,1,-8.59155860614535E-8,,,,,,,,,,,,,,,,,,,,,250.348815917969,250.367156982422,1299.54858398438,1299.54858398438,53.3398934093518,5.65377975095782,5.63094282150269,52,1,68,0,0,0.307083129882812,33.2355842590332,1,1,3,250.367156982422,0,250.357986450195,,,,,,,,,,,,,,,,,,,,,,,,,,,,,,,,,
,3880033056.66445,250.340347290039,1449.66345214844,2.53760802664968E-5,9.17589995892284E-9,1,4,13.4005146026611,4.9919032811937,33.4200002253056,0.0314978980156522,0.0045195709338464,1,-1.51685960826802E-7,,,,,,,,,,,,,,,,,,,,,250.329895019531,250.350799560547,1449.66345214844,1449.66345214844,53.4938742276403,5.65395626228085,5.63110208511353,54,2,0,0,1,0.305099487304687,33.2355842590332,1,1,3,250.350799560547,0,250.340347290039,,,,,,,,,,,,,,,,,,,,,,,,,,,,,,,,,
,3880033129.16447,250.334518432617,1599.791015625,2.58392775582833E-5,9.32639611796364E-9,1,4,13.4005146026611,4.99203295175927,33.4100015461445,0.03206620195217,0.0046544047970179,1,-1.12388856586565E-7,,,,,,,,,,,,,,,,,,,,,250.334106445313,250.334930419922,1599.791015625,1599.791015625,53.5138057548807,5.65343494493496,5.62750434875488,54,3,0,0,1,0.304336547851562,33.2355842590332,1,1,3,250.334930419922,0,250.334518432617,,,,,,,,,,,,,,,,,,,,,,,,,,,,,,,,,
,3880033212.89816,250.344680786133,1799.51623535156,2.61396474073574E-5,2.73804418905182E-8,1,4,13.4005146026611,4.9920254857167,33.4200002253056,0.0324505843999034,0.00463031912610132,1,-1.76735623093368E-7,,,,,,,,,,,,,,,,,,,,,250.336883544922,250.352478027344,1799.51623535156,1799.51623535156,53.521622040073,5.65345820798211,5.63102293014526,52,1,68,0,0,0.304641723632812,33.2355842590332,1,1,3,250.352478027344,0,250.344680786133,,,,,,,,,,,,,,,,,,,,,,,,,,,,,,,,,
,3880033284.37604,250.337158203125,1949.84509277344,2.61970787733638E-5,8.63977091730942E-9,1,4,13.4005146026611,4.99202900756251,33.4200002253056,0.0325132710643911,0.00469827073886583,1,-1.30538891073644E-7,,,,,,,,,,,,,,,,,,,,,250.327133178711,250.347183227539,1949.84509277344,1949.84509277344,53.4157113757172,5.65408872629437,5.63048553466797,53,2,68,0,0,0.305557250976562,33.2355842590332,1,1,3,250.347183227539,0,250.337158203125,,,,,,,,,,,,,,,,,,,,,,,,,,,,,,,,,
,3880033355.93811,250.327865600586,2099.7333984375,2.61352445629589E-5,2.89009735346031E-8,1,4,13.4005146026611,4.99221522883848,33.4100015461445,0.0324405901393089,0.00467160883233711,1,-1.42984208661126E-7,,,,,,,,,,,,,,,,,,,,,250.3212890625,250.334442138672,2099.7333984375,2099.7333984375,53.5478065954672,5.65295735011357,5.63310146331787,54,3,0,0,1,0.305404663085937,33.2355842590332,1,1,3,250.3212890625,0,250.327865600586,,,,,,,,,,,,,,,,,,,,,,,,,,,,,,,,,
,3880033438.4758,250.150192260742,2299.82373046875,2.58688355605934E-5,3.88552628204138E-8,1,4,13.4005146026611,4.99210760534194,33.4200002253056,0.032104731943759,0.00465196419216693,1,-1.18857097758034E-7,,,,,,,,,,,,,,,,,,,,,250.147384643555,250.15299987793,2299.82373046875,2299.82373046875,53.3680320360441,5.65403481924861,5.62723779678345,54,1,0,0,1,0.3057861328125,33.2355842590332,1,1,3,250.153167724609,0,250.150192260742,,,,,,,,,,,,,,,,,,,,,,,,,,,,,,,,,
,3880033510.2204,250.119338989258,2449.80029296875,2.56022408171938E-5,8.28925310478556E-9,1,4,13.4005146026611,4.99201893752084,33.4200002253056,0.0317763527297576,0.00458204100528936,1,-1.35264519691878E-7,,,,,,,,,,,,,,,,,,,,,250.114898681641,250.123779296875,2449.80029296875,2449.80029296875,53.4528387303807,5.65425450283076,5.63043928146362,52,2,68,0,0,0.304336547851562,33.2355842590332,1,1,3,250.114898681641,0,250.119338989258,,,,,,,,,,,,,,,,,,,,,,,,,,,,,,,,,
,3880033582.11712,250.223304748535,2599.67602539062,2.52521184847218E-5,4.1586254428184E-8,1,4,13.4005146026611,4.99191324882773,33.4200002253056,0.031324999402593,0.00462531516931644,1,-4.78841310020195E-8,,,,,,,,,,,,,,,,,,,,,250.218276977539,250.228332519531,2599.67602539062,2599.67602539062,53.4489305877845,5.65450075557783,5.63165330886841,54,3,0,0,1,0.305938720703125,32.7468223571777,1,1,3,250.228775024414,0,250.223304748535,,,,,,,,,,,,,,,,,,,,,,,,,,,,,,,,,
,3880033679.70199,250.442810058594,2799.82934570313,2.46646415222394E-5,7.92096238586621E-9,1,4,13.4005146026611,4.99198992328162,33.4100015461445,0.0306045347024098,0.00446676177545164,1,-8.79301104928869E-8,,,,,,,,,,,,,,,,,,,,,250.432678222656,250.452941894531,2799.82934570313,2799.82934570313,53.4551836159384,5.65422388333814,5.63231515884399,54,1,0,0,1,0.306167602539063,33.2355842590332,1,1,3,250.432678222656,0,250.442810058594,,,,,,,,,,,,,,,,,,,,,,,,,,,,,,,,,
,3880033752.86555,250.255271911621,2949.7177734375,2.41817722919946E-5,9.02211688958783E-9,1,4,13.4005146026611,4.9921062721703,33.4200002253056,0.0300084692467348,0.00436534301882632,1,-9.7589250419099E-8,,,,,,,,,,,,,,,,,,,,,250.253387451172,250.25715637207,2949.7177734375,2949.7177734375,53.4927017848614,5.65415801160696,5.6306848526001,54,2,0,0,1,0.304641723632812,32.7468223571777,1,1,3,250.25715637207,0,250.255271911621,,,,,,,,,,,,,,,,,,,,,,,,,,,,,,,,,
,3880033845.40045,250.288040161133,3499.63549804687,2.2064726797632E-5,7.94591502381272E-9,1,4,13.4005146026611,4.99201045913711,33.4200002253056,0.0273694571573232,0.00405739331439345,1,-2.91097064615285E-8,,,,,,,,,,,,,,,,,,,,,250.28173828125,250.294342041016,3499.63549804687,3499.63549804687,53.5364729819384,5.65404930703002,5.6345386505127,54,3,0,0,1,0.304794311523438,32.7468223571777,1,1,3,250.28173828125,0,250.288040161133,,,,,,,,,,,,,,,,,,,,,,,,,,,,,,,,,
,3880033944.26743,250.169990539551,5499.65771484375,1.2186531097261E-5,2.73004631684362E-8,1,4,13.4005146026611,4.99177985152372,33.4100015461445,0.0151009650987348,0.00233727429133224,1,6.17291862441426E-8,,,,,,,,,,,,,,,,,,,,,250.147476196289,250.192504882813,5499.65771484375,5499.65771484375,53.4993456272749,5.65481219678462,5.63262557983398,53,1,68,0,0,0.30670166015625,32.7468223571777,1,1,3,250.192504882813,0,250.169990539551,,,,,,,,,,,,,,,,,,,,,,,,,,,,,,,,,
,3880034028.41627,250.266830444336,6999.7998046875,3.86347115839964E-6,1.27048524661899E-8,1,4,13.4005146026611,4.99194510340485,33.4200002253056,0.00478145949322477,7.82399977239919E-4,1,5.29402889944671E-8,,,,,,,,,,,,,,,,,,,,,250.265380859375,250.268280029297,6999.7998046875,6999.7998046875,53.4903568993037,5.65502724678083,5.62875556945801,54,2,0,0,1,0.29815673828125,32.7468223571777,1,1,3,250.268280029297,0,250.266830444336,,,,,,,,,,,,,,,,,,,,,,,,,,,,,,,,,
,3880034112.444,250.299468994141,8500.130859375,-4.78164340915698E-6,1.25447907702452E-8,1,4,13.4005146026611,4.99198727230224,33.4200002253056,-0.00593447146128014,-8.57349376246348E-4,1,2.3985019555895E-8,,,,,,,,,,,,,,,,,,,,,250.2900390625,250.308898925781,8500.130859375,8500.130859375,53.4739427003999,5.65436095049955,5.62289333343506,54,3,0,0,1,0.296707153320313,32.7468223571777,1,1,3,250.288681030273,0,250.299468994141,,,,,,,,,,,,,,,,,,,,,,,,,,,,,,,,,
,3880034217.26982,250.118598937988,10000.09765625,-1.35433939806922E-5,1.24602488606383E-8,1,4,13.4005146026611,4.99201177064624,33.4200002253056,-0.0167998727555813,-0.00248767635863155,1,2.00967219001147E-8,,,,,,,,,,,,,,,,,,,,,250.117660522461,250.119537353516,10000.09765625,10000.09765625,53.3312954956403,5.65386804692133,5.6262526512146,54,1,0,0,1,0.29815673828125,33.2355842590332,1,1,3,250.117660522461,0,250.118598937988,,,,,,,,,,,,,,,,,,,,,,,,,,,,,,,,,
,3880034436.98075,250.122734069824,25000.400390625,-1.03747141943021E-4,3.04148974702656E-8,1,4,13.4005146026611,4.99208371345468,33.4100015461445,-0.128691880733404,-0.0190811107447454,1,1.3439168276582E-7,,,,,,,,,,,,,,,,,,,,,250.101638793945,250.143829345703,25000.400390625,25000.400390625,53.4207919610922,5.65382032997842,5.62674474716186,54,2,0,0,1,0.305328369140625,33.2355842590332,1,1,3,250.143829345703,0,250.122734069824,,,,,,,,,,,,,,,,,,,,,,,,,,,,,,,,,
,3880034659.37508,250.077903747559,40000.30078125,-1.95026467020704E-4,7.47534788754732E-8,1,4,13.4005146026611,4.99215215699227,33.4200002253056,-0.241891948272671,-0.0360764568330491,1,8.60339696222492E-8,,,,,,,,,,,,,,,,,,,,,250.077667236328,250.078140258789,40000.30078125,40000.30078125,53.4176654470153,5.65425573399244,5.6317458152771,54,3,0,0,1,0.304718017578125,32.7468223571777,1,1,3,250.078140258789,0,250.077903747559,,,,,,,,,,,,,,,,,,,,,,,,,,,,,,,,,
,3880034968.74729,250.10888671875,60000.26953125,-3.1720150533841E-4,1.85061990848055E-7,1,4,13.4005146026611,4.99217215070178,33.4200002253056,-0.393438575154501,-0.0586079612174864,1,1.95607323659376E-7,,,,,,,,,,,,,,,,,,,,,250.095077514648,250.122695922852,60000.26953125,60000.26953125,53.2402357731499,5.65435159730402,5.62796974182129,54,1,0,0,1,0.305252075195313,33.7243423461914,1,1,3,250.122695922852,0,250.10888671875,,,,,,,,,,,,,,,,,,,,,,,,,,,,,,,,,
,3880035135.20532,250.107215881348,70000.4453125,-3.78453661822091E-4,2.91091926605057E-7,1,4,13.4005146026611,4.99211347562141,33.4200002253056,-0.46939023146148,-0.070019557400799,1,1.5641681888122E-7,,,,,,,,,,,,,,,,,,,,,250.103698730469,250.110733032227,70000.4453125,70000.4453125,53.1194741669287,5.65432649901988,5.6022219657898,54,3,0,0,1,0.306243896484375,32.7468223571777,1,1,3,250.110733032227,0,250.107215881348,,,,,,,,,,,,,,,,,,,,,,,,,,,,,,,,,