File: SQUID/22169_LCOT/22169_LCOT_MH_200K_FC_0d5T.csv
Comment,Time Stamp (sec),Temperature (K),Magnetic Field (Oe),Moment (emu),M. Std. Err. (emu),Transport Action,Averaging Time (sec),Frequency (Hz),Peak Amplitude (mm),Center Position (mm),Lockin Signal' (V),Lockin Signal (V),Range,M. Quad. Signal (emu),AC Moment (emu),AC M. Std Err. (emu),AC Phase (deg),AC Phase Std. Err. (deg),AC Susceptibility (emu/Oe),AC Suscept. Std Err. (emu/Oe),AC X' (emu/Oe),AC X' Std Err. (emu/Oe),AC X'' (emu/Oe),AC X'' Std Err. (emu/Oe),AC Drive (Oe),AC Frequency (Hz),AC Averaging Time (sec),AC Cycles,AC Range,AC Measure Type,AC Signal' (V),AC Signal'' (V),AC Trim Coil Ratio,AC Trim Coil Phase,Min. Temperature (K),Max. Temperature (K),Min. Field (Oe),Max. Field (Oe),Mass (grams),Motor Lag (deg),Pressure (Torr),Measure Count,Measurement Number,SQUID Status (code),Motor Status (code),Measure Status (code),Motor Current (amps),Motor Temp. (C),Temp. Status (code),Field Status (code),Chamber Status (code),Chamber Temp (K),Redirection State,Average Temp (K),Rotation Angle (deg),Rotator state,DC Moment Fixed Ctr (emu),DC Moment Err Fixed Ctr (emu),DC Moment Free Ctr (emu),DC Moment Err Free Ctr (emu),DC Fixed Fit,DC Free Fit,DC Calculated Center (mm),DC Calculated Center Err (mm),DC Scan Length (mm),DC Scan Time (s),DC Number of Points,DC Squid Drift,DC Min V (V),DC Max V (V),DC Scans per Measure,Sample Resistance,He3 Temperature,Sorb Resistance,Sorb Temperature,Map 05,Map 06,Map 07,Map 08,Map 09,Map 10,Map 11,Map 12,Map 13,Map 14,Map 15,Map 16
,3879907375.67711,199.983047485352,69999.890625,-3.76677680110887E-4,7.83267072664468E-8,1,4,13.4005146026611,4.99315588532665,33.2500003278255,-0.467341283216218,-0.0695971667808105,1,2.47735571039041E-7,,,,,,,,,,,,,,,,,,,,,199.982864379883,199.98323059082,69999.890625,69999.890625,52.9623668345633,5.64979611253303,5.10629224777222,54,1,0,0,1,0.304794311523438,32.2580642700195,1,1,3,199.983322143555,0,199.983047485352,,,,,,,,,,,,,,,,,,,,,,,,,,,,,,,,,
,3879907612.13605,200.160850524902,54999.64453125,-2.85112112444112E-4,6.59644702735347E-8,1,4,13.4005146026611,4.99306108816075,33.2599990069866,-0.353715422412929,-0.0527558679179573,1,1.24403601007162E-7,,,,,,,,,,,,,,,,,,,,,200.146026611328,200.175674438477,54999.64453125,54999.64453125,52.9924595325537,5.6498050988076,5.10833883285522,54,2,0,0,1,0.304031372070313,33.7243423461914,1,1,3,200.175674438477,0,200.160850524902,,,,,,,,,,,,,,,,,,,,,,,,,,,,,,,,,
,3879907834.46311,200.074996948242,39999.55859375,-1.93722540470651E-4,4.20156323702175E-8,1,4,13.4005146026611,4.99279234225991,33.2500003278255,-0.240331171174851,-0.0357526989878495,1,1.57202058522089E-7,,,,,,,,,,,,,,,,,,,,,200.072570800781,200.077423095703,39999.55859375,39999.55859375,53.2027176042268,5.65086868408871,5.11631774902344,54,3,0,0,1,0.3070068359375,33.7243423461914,1,1,3,200.072570800781,0,200.074996948242,,,,,,,,,,,,,,,,,,,,,,,,,,,,,,,,,
,3879908116.48994,200.047782897949,19999.62890625,-7.22088271229842E-5,2.12483377944094E-8,1,4,13.4005146026611,4.99273109640686,33.2599990069866,-0.0895743413907014,-0.013366550851619,1,2.61941889519285E-8,,,,,,,,,,,,,,,,,,,,,200.034851074219,200.06071472168,19999.62890625,19999.62890625,53.4813681713326,5.65126781514707,5.10986375808716,54,1,0,0,1,0.304794311523438,34.7018585205078,1,1,3,200.06071472168,0,200.047782897949,,,,,,,,,,,,,,,,,,,,,,,,,,,,,,,,,
,3879908304.1646,200.074729919434,9999.8203125,-1.22382315752156E-5,1.4068634879164E-8,1,4,13.4005146026611,4.99264016110888,33.2599990069866,-0.0151840104920032,-0.00224535785519403,1,2.05627281907164E-8,,,,,,,,,,,,,,,,,,,,,200.073181152344,200.076278686523,9999.8203125,9999.8203125,53.4274358035057,5.65116899592582,5.10580921173096,54,2,0,0,1,0.3057861328125,34.2131004333496,1,1,3,200.073181152344,0,200.074729919434,,,,,,,,,,,,,,,,,,,,,,,,,,,,,,,,,
,3879908390.44391,200.220542907715,8499.5517578125,-3.45503386476493E-6,1.23147030372042E-8,1,4,13.4005146026611,4.99275957016138,33.2599990069866,-0.00428461675040822,-6.48610372776238E-4,1,-6.03859342724518E-9,,,,,,,,,,,,,,,,,,,,,200.21305847168,200.22802734375,8499.5517578125,8499.5517578125,53.3379393380537,5.6515691895723,5.10557556152344,54,3,0,0,1,0.304412841796875,33.7243423461914,1,1,3,200.22802734375,0,200.220542907715,,,,,,,,,,,,,,,,,,,,,,,,,,,,,,,,,
,3879908491.64055,200.106475830078,6499.76904296875,8.01035974845983E-6,1.10665437089603E-8,1,4,13.4005146026611,4.99268455827305,33.2500003278255,0.00994423203588127,0.00143204380352413,1,-4.38050831462809E-8,,,,,,,,,,,,,,,,,,,,,200.102783203125,200.110168457031,6499.76904296875,6499.76904296875,53.3473188802845,5.65131653943903,5.1053671836853,54,1,0,0,1,0.306167602539063,33.7243423461914,1,1,3,200.102783203125,0,200.106475830078,,,,,,,,,,,,,,,,,,,,,,,,,,,,,,,,,
,3879908577.30449,200.28727722168,4999.70263671875,1.61459981902251E-5,7.68794466000477E-9,1,4,13.4005146026611,4.99272707392531,33.2599990069866,0.0200354038932238,0.00294549818565276,1,-4.07472517351902E-8,,,,,,,,,,,,,,,,,,,,,200.285888671875,200.288665771484,4999.70263671875,4999.70263671875,53.3117547826595,5.65157928694403,5.11120653152466,53,2,68,0,0,0.302658081054687,33.7243423461914,1,1,3,200.285888671875,0,200.28727722168,,,,,,,,,,,,,,,,,,,,,,,,,,,,,,,,,
,3879908663.61816,200.202354431152,3499.77392578125,2.33280136938707E-5,6.83995470430288E-9,1,4,13.4005146026611,4.9926191373186,33.2599990069866,0.028944684699753,0.00426849138899054,1,-4.84608252707198E-8,,,,,,,,,,,,,,,,,,,,,200.199813842773,200.204895019531,3499.77392578125,3499.77392578125,53.4825406141114,5.65128703993746,5.10712289810181,54,3,0,0,1,0.305633544921875,34.2131004333496,1,1,3,200.199813842773,0,200.202354431152,,,,,,,,,,,,,,,,,,,,,,,,,,,,,,,,,
,3879908767.09319,200.284400939941,2899.654296875,2.55007942687937E-5,1.5490554564144E-8,1,4,13.4005146026611,4.9926565015971,33.2500003278255,0.031602822548845,0.00492088920545837,1,1.52427416435585E-7,,,,,,,,,,,,,,,,,,,,,200.278259277344,200.290542602539,2899.654296875,2899.654296875,53.4528387303807,5.65245265293869,5.1086802482605,53,1,68,0,0,0.305633544921875,34.2131004333496,1,1,3,200.278259277344,0,200.284400939941,,,,,,,,,,,,,,,,,,,,,,,,,,,,,,,,,
,3879908840.42233,200.355003356934,2749.76586914062,2.59642650104264E-5,1.1959715436027E-8,1,4,13.4005146026611,4.99269637681739,33.2599990069866,0.0321855825991213,0.00495672695365899,1,1.11942492284371E-7,,,,,,,,,,,,,,,,,,,,,200.350891113281,200.359115600586,2749.76586914062,2749.76586914062,53.3144904824768,5.65179801690006,5.11201477050781,54,2,0,0,1,0.305404663085937,34.2131004333496,1,1,3,200.359115600586,0,200.355003356934,,,,,,,,,,,,,,,,,,,,,,,,,,,,,,,,,
,3879908914.18521,200.173149108887,2599.76416015625,2.64317034834134E-5,1.00367940746624E-8,1,4,13.4005146026611,4.99286353931759,33.2500003278255,0.0327727009504072,0.00500515889599528,1,8.08723781575801E-8,,,,,,,,,,,,,,,,,,,,,200.167373657227,200.178924560547,2599.76416015625,2599.76416015625,53.2883059270826,5.65106793093963,5.10551166534424,54,3,0,0,1,0.306472778320313,33.7243423461914,1,1,3,200.166976928711,0,200.173149108887,,,,,,,,,,,,,,,,,,,,,,,,,,,,,,,,,
,3879908997.74933,200.208633422852,2399.6611328125,2.68389350909088E-5,1.98439016842828E-8,1,4,13.4005146026611,4.99276149551002,33.2599990069866,0.0332578962056142,0.00520765939898742,1,1.83318372363538E-7,,,,,,,,,,,,,,,,,,,,,200.182266235352,200.235000610352,2399.6611328125,2399.6611328125,53.3332495669383,5.65245918438476,5.11245059967041,54,1,0,0,1,0.305862426757812,33.7243423461914,1,1,3,200.235000610352,0,200.208633422852,,,,,,,,,,,,,,,,,,,,,,,,,,,,,,,,,
,3879909069.01556,200.314613342285,2249.60913085938,2.7182431122497E-5,1.42286709609318E-8,1,4,13.4005146026611,4.9927477598296,33.2599990069866,0.0336996579930001,0.00516570811806252,1,9.81296776013927E-8,,,,,,,,,,,,,,,,,,,,,200.300964355469,200.328262329102,2249.60913085938,2249.60913085938,53.4774600287364,5.65192215393765,5.10869359970093,52,2,68,0,0,0.303421020507812,33.7243423461914,1,1,3,200.328262329102,0,200.314613342285,,,,,,,,,,,,,,,,,,,,,,,,,,,,,,,,,
,3879909139.60591,200.121101379395,2099.70825195313,2.74103558836011E-5,1.19622386865225E-8,1,4,13.4005146026611,4.99281529251675,33.2500003278255,0.0339862275445104,0.0051867018602532,1,8.0878881635362E-8,,,,,,,,,,,,,,,,,,,,,200.116577148438,200.125625610352,2099.70825195313,2099.70825195313,53.353962722698,5.65141861730577,5.11414480209351,54,3,0,0,1,0.305938720703125,34.2131004333496,1,1,3,200.116073608398,0,200.121101379395,,,,,,,,,,,,,,,,,,,,,,,,,,,,,,,,,
,3879909220.54957,200.227989196777,1899.86975097656,2.75359626062768E-5,1.96583156359885E-8,1,4,13.4005146026611,4.9929099812682,33.2500003278255,0.0341237011983233,0.00533878124925525,1,1.84574492390067E-7,,,,,,,,,,,,,,,,,,,,,200.211853027344,200.244125366211,1899.86975097656,1899.86975097656,53.3949982199576,5.65067462447753,5.11102390289307,54,1,0,0,1,0.30303955078125,33.7243423461914,1,1,3,200.244125366211,0,200.227989196777,,,,,,,,,,,,,,,,,,,,,,,,,,,,,,,,,
,3879909290.36673,200.231254577637,1749.55346679687,2.75470560337046E-5,1.4392239414171E-8,1,4,13.4005146026611,4.99293948497221,33.2500003278255,0.034147980520372,0.00527246236596216,1,1.29417741911616E-7,,,,,,,,,,,,,,,,,,,,,200.230941772461,200.231567382813,1749.55346679687,1749.55346679687,53.2586040433518,5.6501507195535,5.11431837081909,53,2,68,0,0,0.302734375,33.7243423461914,1,1,3,200.231567382813,0,200.231254577637,,,,,,,,,,,,,,,,,,,,,,,,,,,,,,,,,
,3879909361.4819,200.255073547363,1599.53918457031,2.74712360149798E-5,1.14814598001396E-8,1,4,13.4005146026611,4.99300856984476,33.2599990069866,0.0340595340113101,0.00522542001279546,1,1.02756060989577E-7,,,,,,,,,,,,,,,,,,,,,200.249588012695,200.260559082031,1599.53918457031,1599.53918457031,53.3785840210537,5.65110532240919,5.11522388458252,54,3,0,0,1,0.303421020507812,33.7243423461914,1,1,3,200.24919128418,0,200.255073547363,,,,,,,,,,,,,,,,,,,,,,,,,,,,,,,,,
,3879909451.37411,200.242256164551,1399.7509765625,2.70243340116956E-5,2.16514062954923E-8,1,4,13.4005146026611,4.99306922629845,33.2500003278255,0.0334851854604593,0.0052798002453042,10,2.13374071764691E-7,,,,,,,,,,,,,,,,,,,,,200.235778808594,200.248733520508,1399.7509765625,1399.7509765625,53.3981247340345,5.65208253116361,5.11310243606567,54,1,0,0,1,0.304946899414063,33.7243423461914,1,1,3,200.235778808594,0,200.242256164551,,,,,,,,,,,,,,,,,,,,,,,,,,,,,,,,,
,3879909531.24768,200.068183898926,1249.69909667969,2.66199403093413E-5,1.68903610999025E-8,1,4,13.4005146026611,4.99322945995971,33.2599990069866,0.0329956226956722,0.00513398857125915,1,1.56143999158185E-7,,,,,,,,,,,,,,,,,,,,,200.064666748047,200.071701049805,1249.69909667969,1249.69909667969,53.3543535369576,5.65054901738174,5.11337947845459,54,2,0,0,1,0.304107666015625,33.7243423461914,1,1,3,200.064666748047,0,200.068183898926,,,,,,,,,,,,,,,,,,,,,,,,,,,,,,,,,
,3879909614.30279,200.023742675781,1099.88610839844,2.59521356352647E-5,1.41818080590238E-8,1,4,13.4005146026611,4.9931153487973,33.2500003278255,0.0321779396773721,0.00493085972444585,1,9.24358839118987E-8,,,,,,,,,,,,,,,,,,,,,200.023025512695,200.024459838867,1099.88610839844,1099.88610839844,53.384446234948,5.65154113639614,5.11319637298584,54,3,0,0,1,0.303878784179687,33.7243423461914,1,1,3,200.023025512695,0,200.023742675781,,,,,,,,,,,,,,,,,,,,,,,,,,,,,,,,,
,3879909706.23968,200.170097351074,899.821044921875,2.45586795175511E-5,2.40169159699267E-8,1,4,13.4005146026611,4.99327138106924,33.2500003278255,0.0304278209929863,0.00482481677500464,1,2.15237934825582E-7,,,,,,,,,,,,,,,,,,,,,200.164077758789,200.176116943359,899.821044921875,899.821044921875,53.2261664598037,5.64985366378368,5.12027454376221,53,1,68,0,0,0.303573608398438,33.7243423461914,1,1,3,200.164077758789,0,200.170097351074,,,,,,,,,,,,,,,,,,,,,,,,,,,,,,,,,
,3879909777.65305,200.192428588867,749.869750976563,2.3267823478046E-5,1.52709386250313E-8,1,4,13.4005146026611,4.99330965510161,33.2599990069866,0.0288436716721703,0.00447171640400467,1,1.23685208162301E-7,,,,,,,,,,,,,,,,,,,,,200.190353393555,200.19450378418,749.869750976563,749.869750976563,53.374285064198,5.64973564730406,5.12087345123291,54,2,0,0,1,0.302886962890625,33.2355842590332,1,1,3,200.19450378418,0,200.192428588867,,,,,,,,,,,,,,,,,,,,,,,,,,,,,,,,,
,3879909847.83327,200.166160583496,600.069519042969,2.15672326574559E-5,1.84452172471951E-8,1,4,13.4005146026611,4.99321614205731,33.2500003278255,0.0267367854997205,0.00413186658053767,1,1.0423597734319E-7,,,,,,,,,,,,,,,,,,,,,200.160537719727,200.171783447266,600.069519042969,600.069519042969,53.4192287040537,5.64961568301607,5.11641454696655,54,3,0,0,1,0.303497314453125,33.7243423461914,1,1,3,200.160537719727,0,200.166160583496,,,,,,,,,,,,,,,,,,,,,,,,,,,,,,,,,
,3879909929.47528,200.070747375488,399.991790771484,1.82641878259461E-5,2.80468168861191E-8,1,4,13.4005146026611,4.99315110009853,33.2500003278255,0.022615931241897,0.00367062531655276,1,2.26613793028359E-7,,,,,,,,,,,,,,,,,,,,,200.066436767578,200.075057983398,399.991790771484,399.991790771484,53.3836646064287,5.65085276260558,5.11936044692993,52,1,68,0,0,0.304412841796875,33.7243423461914,1,1,3,200.066436767578,0,200.070747375488,,,,,,,,,,,,,,,,,,,,,,,,,,,,,,,,,
,3879910011.75501,200.124694824219,250.015319824219,1.50799856160809E-5,1.87270411271501E-8,1,4,13.4005146026611,4.99310118023037,33.2599990069866,0.0186800206045551,0.00298223208136202,1,1.48083331983214E-7,,,,,,,,,,,,,,,,,,,,,200.123886108398,200.125503540039,250.015319824219,250.015319824219,53.3137088539576,5.65023141869539,5.12281942367554,54,2,0,0,1,0.301971435546875,33.7243423461914,1,1,3,200.125442504883,0,200.124694824219,,,,,,,,,,,,,,,,,,,,,,,,,,,,,,,,,
,3879910100.93576,200.123970031738,100.126983642578,1.07839750596939E-5,1.31532342041985E-8,1,4,13.4005146026611,4.99307125609049,33.2599990069866,0.0133580302928244,0.00213452846663368,10,1.07426578702664E-7,,,,,,,,,,,,,,,,,,,,,200.123458862305,200.124481201172,100.126983642578,100.126983642578,53.3004211691306,5.65120665790191,5.11839151382446,54,3,0,0,1,0.303268432617188,33.2355842590332,1,1,3,200.123458862305,0,200.123970031738,,,,,,,,,,,,,,,,,,,,,,,,,,,,,,,,,
,3879910220.05741,200.198570251465,-99.8500366210937,2.46945840128764E-6,3.11862857602443E-8,1,4,13.4005146026611,4.99299216168221,33.2599990069866,0.00301537952174613,7.79251660663734E-4,1,2.58752731072097E-7,,,,,,,,,,,,,,,,,,,,,200.185928344727,200.211212158203,-99.8500366210937,-99.8500366210937,53.269546842621,5.65042495178971,5.12160539627075,52,1,68,0,0,0.303192138671875,33.2355842590332,1,1,3,200.211212158203,0,200.198570251465,,,,,,,,,,,,,,,,,,,,,,,,,,,,,,,,,
,3879910338.99101,200.238067626953,-249.82649230957,-4.14483736373085E-6,1.55947528884721E-8,1,4,13.4005146026611,4.99291117734273,33.2599990069866,-0.0051587125899906,-6.54832459301973E-4,1,9.21581595594794E-8,,,,,,,,,,,,,,,,,,,,,200.235015869141,200.241119384766,-249.82649230957,-249.82649230957,53.3903084488422,5.65092448507844,5.12134027481079,53,2,68,0,0,0.304412841796875,34.2131004333496,1,1,3,200.235015869141,0,200.238067626953,,,,,,,,,,,,,,,,,,,,,,,,,,,,,,,,,
,3879910437.6614,200.182403564453,-399.802978515625,-9.87287837122444E-6,7.33236503201711E-9,1,4,13.4005146026611,4.99297359951557,33.2500003278255,-0.0122513307957792,-0.00180570584046961,1,2.13029131590732E-8,,,,,,,,,,,,,,,,,,,,,200.179870605469,200.184936523438,-399.802978515625,-399.802978515625,53.4313439461018,5.64982812640286,5.12378931045532,54,3,0,0,1,0.303878784179687,33.2355842590332,1,1,3,200.179870605469,0,200.182403564453,,,,,,,,,,,,,,,,,,,,,,,,,,,,,,,,,
,3879910519.7098,200.152557373047,-599.69189453125,-1.57234092338123E-5,1.41310303842761E-8,1,4,13.4005146026611,4.99300174318131,33.2500003278255,-0.0195498077314331,-0.00261937689545468,1,2.40604978512191E-7,,,,,,,,,,,,,,,,,,,,,200.146514892578,200.158599853516,-599.69189453125,-599.69189453125,53.3586524938133,5.65003570618705,5.12831926345825,54,1,0,0,1,0.30426025390625,33.2355842590332,1,1,3,200.146514892578,0,200.152557373047,,,,,,,,,,,,,,,,,,,,,,,,,,,,,,,,,
,3879910591.43002,200.099922180176,-749.743896484375,-1.88931894801614E-5,1.46603975954409E-8,1,4,13.4005146026611,4.99317324218311,33.2599990069866,-0.0234718170953963,-0.00328321144047556,1,1.79784650203599E-7,,,,,,,,,,,,,,,,,,,,,200.089111328125,200.110733032227,-749.743896484375,-749.743896484375,53.328559795823,5.64947503205618,5.12960767745972,52,2,68,0,0,0.302963256835937,32.7468223571777,1,1,3,200.110733032227,0,200.099922180176,,,,,,,,,,,,,,,,,,,,,,,,,,,,,,,,,
,3879910662.84892,200.273612976074,-899.644775390625,-2.12951864537488E-5,1.99074507305087E-8,1,4,13.4005146026611,4.99315366589877,33.2599990069866,-0.0264445784033259,-0.0037754529436243,1,1.42307497024037E-7,,,,,,,,,,,,,,,,,,,,,200.269546508789,200.277679443359,-899.644775390625,-899.644775390625,53.3187894393326,5.64876047509972,5.12694787979126,54,3,0,0,1,0.30242919921875,33.7243423461914,1,1,3,200.269546508789,0,200.273612976074,,,,,,,,,,,,,,,,,,,,,,,,,,,,,,,,,
,3879910745.65595,200.234718322754,-1099.63439941406,-2.35764660260524E-5,6.44304762394853E-8,1,4,13.4005146026611,4.99307906897873,33.2500003278255,-0.0293002629631214,-0.00402351832123105,1,2.83544173779781E-7,,,,,,,,,,,,,,,,,,,,,200.229461669922,200.239974975586,-1099.63439941406,-1099.63439941406,53.4497122163037,5.65011218746802,5.13052845001221,54,1,0,0,1,0.302810668945313,33.7243423461914,1,1,3,200.239974975586,0,200.234718322754,,,,,,,,,,,,,,,,,,,,,,,,,,,,,,,,,
,3879910817.9192,200.220268249512,-1249.59838867188,-2.4811792061349E-5,1.41156901814335E-8,1,4,13.4005146026611,4.99303208510993,33.2500003278255,-0.0308058974976751,-0.00442942500471442,1,1.41093714871648E-7,,,,,,,,,,,,,,,,,,,,,200.214141845703,200.22639465332,-1249.59838867188,-1249.59838867188,53.4114124188614,5.65033151311467,5.13266134262085,54,2,0,0,1,0.305938720703125,33.7243423461914,1,1,3,200.22639465332,0,200.220268249512,,,,,,,,,,,,,,,,,,,,,,,,,,,,,,,,,
,3879910891.29958,200.178405761719,-1399.53698730469,-2.56598313216976E-5,1.01871678671384E-8,1,4,13.4005146026611,4.99312373433085,33.2500003278255,-0.0318570748243458,-0.00459800208639639,1,1.32159046536823E-7,,,,,,,,,,,,,,,,,,,,,200.172958374023,200.183853149414,-1399.53698730469,-1399.53698730469,53.3277781673037,5.6495683441046,5.12849235534668,54,3,0,0,1,0.303573608398438,33.7243423461914,1,1,3,200.17219543457,0,200.178405761719,,,,,,,,,,,,,,,,,,,,,,,,,,,,,,,,,
,3879910975.91235,200.159996032715,-1599.791015625,-2.64236494696431E-5,1.51594118158253E-8,1,4,13.4005146026611,4.99317029085063,33.2500003278255,-0.0328135518411539,-0.00468308257891569,1,1.77888497609219E-7,,,,,,,,,,,,,,,,,,,,,200.156936645508,200.163055419922,-1599.791015625,-1599.791015625,53.3109731541403,5.65018869837489,5.13090467453003,53,1,68,0,0,0.303497314453125,33.2355842590332,1,1,3,200.156539916992,0,200.159996032715,,,,,,,,,,,,,,,,,,,,,,,,,,,,,,,,,
,3879911049.56798,200.142646789551,-1749.66674804687,-2.67036330356652E-5,1.01058081724969E-8,1,4,13.4005146026611,4.99316325746338,33.2599990069866,-0.0331544547416507,-0.00477763183501548,1,1.43550702139826E-7,,,,,,,,,,,,,,,,,,,,,200.136749267578,200.148544311523,-1749.66674804687,-1749.66674804687,53.3434107376883,5.64953963111206,5.12808561325073,54,2,0,0,1,0.302734375,33.2355842590332,1,1,3,200.148544311523,0,200.142646789551,,,,,,,,,,,,,,,,,,,,,,,,,,,,,,,,,
,3879911123.0226,200.082534790039,-1899.75646972656,-2.68344617782176E-5,8.85656860915857E-9,1,4,13.4005146026611,4.99313347570294,33.2500003278255,-0.0333124860223696,-0.00482856318369897,1,1.2203466452988E-7,,,,,,,,,,,,,,,,,,,,,200.080032348633,200.085037231445,-1899.75646972656,-1899.75646972656,53.3156629252556,5.650698199774,5.13055276870728,54,3,0,0,1,0.303955078125,33.7243423461914,1,1,3,200.080032348633,0,200.082534790039,,,,,,,,,,,,,,,,,,,,,,,,,,,,,,,,,
,3879911205.25355,200.017318725586,-2099.54467773438,-2.68203644580111E-5,3.48664686757028E-8,1,4,13.4005146026611,4.993186408487,33.2500003278255,-0.0333014961010831,-0.00478588209724785,1,1.54387700976565E-7,,,,,,,,,,,,,,,,,,,,,200.016265869141,200.018371582031,-2099.54467773438,-2099.54467773438,53.437206159996,5.64944599731967,5.13897323608398,53,1,68,0,0,0.30364990234375,33.2355842590332,1,1,3,200.016265869141,0,200.017318725586,,,,,,,,,,,,,,,,,,,,,,,,,,,,,,,,,
,3879911276.91427,200.263763427734,-2249.64697265625,-2.66751159541804E-5,1.0277666577641E-8,1,4,13.4005146026611,4.99320233737326,33.2500003278255,-0.0331190743120176,-0.00477483891881996,1,1.41578236888831E-7,,,,,,,,,,,,,,,,,,,,,200.263595581055,200.263931274414,-2249.64697265625,-2249.64697265625,53.3727218071595,5.65007087367703,5.13863611221313,52,2,68,0,0,0.305023193359375,34.2131004333496,1,1,3,200.263595581055,0,200.263763427734,,,,,,,,,,,,,,,,,,,,,,,,,,,,,,,,,
,3879911348.33362,200.239265441895,-2399.62329101562,-2.64053429431556E-5,1.70676925325182E-8,1,4,13.4005146026611,4.99317860973823,33.2599990069866,-0.0327780193233235,-0.00476591909098015,1,1.08386286008966E-7,,,,,,,,,,,,,,,,,,,,,200.23193359375,200.246597290039,-2399.62329101562,-2399.62329101562,53.2480520583422,5.64998646909654,5.1313042640686,54,3,0,0,1,0.302886962890625,33.2355842590332,1,1,3,200.23193359375,0,200.239265441895,,,,,,,,,,,,,,,,,,,,,,,,,,,,,,,,,
,3879911433.30743,200.207084655762,-2599.80200195313,-2.60114625061092E-5,8.97963109042375E-9,1,4,13.4005146026611,4.99310449523233,33.2500003278255,-0.0322977546899633,-0.00463225028579481,1,1.57133690884846E-7,,,,,,,,,,,,,,,,,,,,,200.196533203125,200.217636108398,-2599.80200195313,-2599.80200195313,53.3977339197749,5.64933760052418,5.14142656326294,54,1,0,0,1,0.303955078125,33.2355842590332,1,1,3,200.217636108398,0,200.207084655762,,,,,,,,,,,,,,,,,,,,,,,,,,,,,,,,,
,3879911505.22958,200.333457946777,-2749.5517578125,-2.5603986565096E-5,8.56803891401256E-9,1,4,13.4005146026611,4.99303199462143,33.2500003278255,-0.0317853285129287,-0.00459854555109863,1,1.23271513472663E-7,,,,,,,,,,,,,,,,,,,,,200.330368041992,200.336547851562,-2749.5517578125,-2749.5517578125,53.4020328766306,5.65015428949694,5.13455820083618,53,2,68,0,0,0.303497314453125,32.7468223571777,1,1,3,200.330368041992,0,200.333457946777,,,,,,,,,,,,,,,,,,,,,,,,,,,,,,,,,
,3879911579.2096,200.243263244629,-2899.61645507812,-2.51417134993894E-5,7.81286310632159E-9,1,4,13.4005146026611,4.99306341890825,33.2500003278255,-0.0312081326205571,-0.00453959546127324,1,1.01670752037389E-7,,,,,,,,,,,,,,,,,,,,,200.238555908203,200.247970581055,-2899.61645507812,-2899.61645507812,53.3320771241595,5.6497419699367,5.13474035263062,52,3,68,0,0,0.30364990234375,33.7243423461914,1,1,3,200.238555908203,0,200.243263244629,,,,,,,,,,,,,,,,,,,,,,,,,,,,,,,,,
,3879911687.31218,200.333961486816,-3499.63549804687,-2.29069095690356E-5,2.01086519826673E-8,1,4,13.4005146026611,4.99293632845922,33.2599990069866,-0.0284203961375836,-0.00422072691861757,1,2.42769249047337E-8,,,,,,,,,,,,,,,,,,,,,200.320587158203,200.34733581543,-3499.63549804687,-3499.63549804687,53.2578224148326,5.65022922155454,5.13647413253784,54,1,0,0,1,0.303497314453125,33.7243423461914,1,1,3,200.320587158203,0,200.333961486816,,,,,,,,,,,,,,,,,,,,,,,,,,,,,,,,,
,3879911772.78242,200.206115722656,-4999.626953125,-1.57332716941954E-5,9.29056713483032E-9,1,4,13.4005146026611,4.99285409561729,33.2500003278255,-0.0195189619949419,-0.00290366244281932,1,1.28163873934364E-8,,,,,,,,,,,,,,,,,,,,,200.201522827148,200.210708618164,-4999.626953125,-4999.626953125,53.3707677358614,5.65069512053326,5.14108514785767,54,2,0,0,1,0.304489135742188,33.7243423461914,1,1,3,200.210662841797,0,200.206115722656,,,,,,,,,,,,,,,,,,,,,,,,,,,,,,,,,
,3879911857.49411,200.159934997559,-6499.5048828125,-7.60286905032804E-6,1.20008595242486E-8,1,4,13.4005146026611,4.9928271470734,33.2500003278255,-0.00943197541090678,-0.00140448278644868,1,5.11162994792852E-9,,,,,,,,,,,,,,,,,,,,,200.156311035156,200.163558959961,-6499.5048828125,-6499.5048828125,53.4786324715153,5.64990366084805,5.14076948165894,54,3,0,0,1,0.303802490234375,33.2355842590332,1,1,3,200.156311035156,0,200.159934997559,,,,,,,,,,,,,,,,,,,,,,,,,,,,,,,,,
,3879911956.53379,200.15559387207,-8499.765625,3.82758496524276E-6,1.41768944309915E-8,1,4,13.4005146026611,4.99281670027519,33.2599990069866,0.00475678841774994,6.51099275708642E-4,1,-4.76946924913227E-8,,,,,,,,,,,,,,,,,,,,,200.155563354492,200.155624389648,-8499.765625,-8499.765625,53.3602157508518,5.65041487420566,5.14123868942261,54,1,0,0,1,0.304336547851562,33.2355842590332,1,1,3,200.155563354492,0,200.15559387207,,,,,,,,,,,,,,,,,,,,,,,,,,,,,,,,,
,3879912041.986,200.105995178223,-9999.64453125,1.26071267542008E-5,1.28099690221413E-8,1,4,13.4005146026611,4.9930304442345,33.2599990069866,0.01564333798972,0.00231379427577691,1,-2.07782062746183E-8,,,,,,,,,,,,,,,,,,,,,200.103759765625,200.10823059082,-9999.64453125,-9999.64453125,53.2570407863133,5.64925189199726,5.13681697845459,54,2,0,0,1,0.303955078125,33.2355842590332,1,1,3,200.10823059082,0,200.105995178223,,,,,,,,,,,,,,,,,,,,,,,,,,,,,,,,,
,3879912231.09728,200.017127990723,-19999.654296875,7.25765772443666E-5,2.29931207404634E-8,1,4,13.4005146026611,4.99305122859513,33.2500003278255,0.0900507721451877,0.0133545969450906,1,-9.18114184728412E-8,,,,,,,,,,,,,,,,,,,,,200.016220092773,200.018035888672,-19999.654296875,-19999.654296875,53.3629514506691,5.65021767971674,5.14658403396606,54,3,0,0,1,0.30548095703125,33.2355842590332,1,1,3,200.016220092773,0,200.017127990723,,,,,,,,,,,,,,,,,,,,,,,,,,,,,,,,,
,3879912514.18073,200.113487243652,-39999.6328125,1.94061125995809E-4,3.72897329710407E-8,1,4,13.4005146026611,4.99291497508869,33.2500003278255,0.240763309988229,0.0357909752438494,1,-1.77988380655252E-7,,,,,,,,,,,,,,,,,,,,,200.080749511719,200.146224975586,-39999.6328125,-39999.6328125,53.3551351654768,5.6496420871792,5.13903284072876,53,1,68,0,0,0.304641723632812,33.7243423461914,1,1,3,200.146224975586,0,200.113487243652,,,,,,,,,,,,,,,,,,,,,,,,,,,,,,,,,
,3879912756.31818,200.157707214355,-54999.6328125,2.85568358791052E-4,7.67150503740716E-8,1,4,13.4005146026611,4.99296151082142,33.2599990069866,0.354334832138569,0.0524157946793513,10,-4.65608361895572E-7,,,,,,,,,,,,,,,,,,,,,200.157348632813,200.158065795898,-54999.6328125,-54999.6328125,53.2335919307364,5.65003773640066,5.14676380157471,54,2,0,0,1,0.302886962890625,33.2355842590332,1,1,3,200.158065795898,0,200.157707214355,,,,,,,,,,,,,,,,,,,,,,,,,,,,,,,,,
,3879912995.31885,200.200622558594,-69999.7890625,3.76983687090845E-4,7.8396228117049E-8,1,4,13.4005146026611,4.99296143063294,33.2500003278255,0.467671094607472,0.0698125437135247,1,-1.16830561201502E-7,,,,,,,,,,,,,,,,,,,,,200.200180053711,200.201065063477,-69999.7890625,-69999.7890625,53.0030115175633,5.65036189933739,5.14905548095703,54,3,0,0,1,0.305709838867188,33.7243423461914,1,1,3,200.201065063477,0,200.200622558594,,,,,,,,,,,,,,,,,,,,,,,,,,,,,,,,,
,3879913278.70584,200.140243530273,-49999.703125,2.54770179436269E-4,6.67347836611147E-8,1,4,13.4005146026611,4.99303164384746,33.2500003278255,0.316075419006636,0.0471051931154691,1,-1.40144026499757E-7,,,,,,,,,,,,,,,,,,,,,200.128479003906,200.152008056641,-49999.703125,-49999.703125,53.1499576791787,5.65000244827567,5.139817237854,54,1,0,0,1,0.30487060546875,33.7243423461914,1,1,3,200.152008056641,0,200.140243530273,,,,,,,,,,,,,,,,,,,,,,,,,,,,,,,,,
,3879913501.65359,200.011169433594,-34999.54296875,1.63330488017635E-4,3.32974019755771E-8,1,4,13.4005146026611,4.99287894752899,33.2500003278255,0.202626113494383,0.0301828987644642,1,-1.01495427362822E-7,,,,,,,,,,,,,,,,,,,,,200.007217407227,200.015121459961,-34999.54296875,-34999.54296875,53.2761906850345,5.65035416637873,5.14174270629883,54,2,0,0,1,0.303573608398438,33.7243423461914,1,1,3,200.015121459961,0,200.011169433594,,,,,,,,,,,,,,,,,,,,,,,,,,,,,,,,,
,3879913722.28862,200.011383056641,-19999.69140625,7.22332065525766E-5,2.21077514612324E-8,1,4,13.4005146026611,4.99276975462923,33.2500003278255,0.0896116728062494,0.0133303188001156,1,-5.91672208050467E-8,,,,,,,,,,,,,,,,,,,,,200.010803222656,200.011962890625,-19999.69140625,-19999.69140625,53.3148812967364,5.6511943598362,5.14117527008057,54,3,0,0,1,0.304183959960937,33.7243423461914,1,1,3,200.010803222656,0,200.011383056641,,,,,,,,,,,,,,,,,,,,,,,,,,,,,,,,,
,3879913925.55911,200.205619812012,-9500.4443359375,9.26640959377103E-6,1.30845778382104E-8,1,4,13.4005146026611,4.99268984306429,33.2599990069866,0.0114875525627006,0.00176344255487243,1,3.5464922849373E-8,,,,,,,,,,,,,,,,,,,,,200.201248168945,200.209991455078,-9500.4443359375,-9500.4443359375,53.4129756758999,5.65204051459116,5.1490626335144,54,1,0,0,1,0.30548095703125,34.2131004333496,1,1,3,200.209991455078,0,200.205619812012,,,,,,,,,,,,,,,,,,,,,,,,,,,,,,,,,
,3879914009.23676,200.294937133789,-8000.36474609375,5.27349531316397E-7,1.01001113222492E-8,1,4,13.4005146026611,4.99269578089393,33.2500003278255,6.50134894706266E-4,1.24559744076671E-4,1,2.15299145289616E-8,,,,,,,,,,,,,,,,,,,,,200.28678894043,200.303085327148,-8000.36474609375,-8000.36474609375,53.440332674073,5.64983937854542,5.14879560470581,54,2,0,0,1,0.304031372070313,33.7243423461914,1,1,3,200.28678894043,0,200.294937133789,,,,,,,,,,,,,,,,,,,,,,,,,,,,,,,,,
,3879914093.10624,200.252853393555,-6500.36083984375,-8.01948631252986E-6,9.73980107857232E-9,1,4,13.4005146026611,4.99269532304929,33.2500003278255,-0.00995232216325137,-0.00145553797878497,1,2.62332021169968E-8,,,,,,,,,,,,,,,,,,,,,200.244445800781,200.261260986328,-6500.36083984375,-6500.36083984375,53.3465372517652,5.65095341825017,5.14753675460815,54,3,0,0,1,0.30303955078125,34.2131004333496,1,1,3,200.244445800781,0,200.252853393555,,,,,,,,,,,,,,,,,,,,,,,,,,,,,,,,,
,3879914191.3496,200.194465637207,-4500.48974609375,-1.87356402887578E-5,7.76153609878968E-9,1,4,13.4005146026611,4.99274052104742,33.2500003278255,-0.0232552007629997,-0.00337616535991821,1,8.09578057827742E-8,,,,,,,,,,,,,,,,,,,,,200.187515258789,200.201416015625,-4500.48974609375,-4500.48974609375,53.3055017545056,5.6500267525462,5.14367246627808,53,1,68,0,0,0.306243896484375,33.7243423461914,1,1,3,200.187515258789,0,200.194465637207,,,,,,,,,,,,,,,,,,,,,,,,,,,,,,,,,
,3879914274.90762,200.192420959473,-3000.32250976562,-2.52844514105094E-5,8.0505823350214E-9,1,4,13.4005146026611,4.99282979017993,33.2500003278255,-0.0313738938847929,-0.00462764005390901,1,5.18060236536184E-8,,,,,,,,,,,,,,,,,,,,,200.188110351562,200.196731567383,-3000.32250976562,-3000.32250976562,53.4735518861403,5.64976559809494,5.14903402328491,54,2,0,0,1,0.306396484375,34.2131004333496,1,1,3,200.196731567383,0,200.192420959473,,,,,,,,,,,,,,,,,,,,,,,,,,,,,,,,,
,3879914367.05828,200.356964111328,-2900.13256835937,-2.55393450894006E-5,1.02162803873928E-8,1,4,13.4005146026611,4.9928081527658,33.2500003278255,-0.0316674473842743,-0.00482490903166564,1,-6.91163152076084E-8,,,,,,,,,,,,,,,,,,,,,200.356430053711,200.357498168945,-2900.13256835937,-2900.13256835937,53.3570892367749,5.64959014583841,5.1451563835144,54,3,0,0,1,0.30517578125,33.7243423461914,1,1,3,200.356430053711,0,200.356964111328,,,,,,,,,,,,,,,,,,,,,,,,,,,,,,,,,
,3879914449.53331,200.192306518555,-2700.306640625,-2.61396621719844E-5,1.87980118054687E-8,1,4,13.4005146026611,4.99278931146483,33.2599990069866,-0.0323944183287289,-0.00505340259945243,1,-1.63536320123496E-7,,,,,,,,,,,,,,,,,,,,,200.187103271484,200.197509765625,-2700.306640625,-2700.306640625,53.5075527267268,5.65073946784161,5.14136409759521,54,1,0,0,1,0.303955078125,33.7243423461914,1,1,3,200.186706542969,0,200.192306518555,,,,,,,,,,,,,,,,,,,,,,,,,,,,,,,,,
,3879914520.52623,200.188056945801,-2550.36791992187,-2.65518560907934E-5,1.40526149114242E-8,1,4,13.4005146026611,4.99279481156164,33.2599990069866,-0.0329187158945196,-0.00504337296567176,1,-9.37828481718606E-8,,,,,,,,,,,,,,,,,,,,,200.187072753906,200.189041137695,-2550.36791992187,-2550.36791992187,53.376239135496,5.65048818436291,5.13945770263672,53,2,68,0,0,0.301971435546875,34.2131004333496,1,1,3,200.187072753906,0,200.188056945801,,,,,,,,,,,,,,,,,,,,,,,,,,,,,,,,,
,3879914592.61514,200.221305847168,-2400.2275390625,-2.69395222008403E-5,1.09564676022091E-8,1,4,13.4005146026611,4.99274152423995,33.2500003278255,-0.0334015704476526,-0.00509868485732286,1,-8.04422115880373E-8,,,,,,,,,,,,,,,,,,,,,200.21630859375,200.226303100586,-2400.2275390625,-2400.2275390625,53.399687991073,5.64992079254713,5.14798450469971,54,3,0,0,1,0.305328369140625,34.2131004333496,1,1,3,200.21630859375,0,200.221305847168,,,,,,,,,,,,,,,,,,,,,,,,,,,,,,,,,
,3879914673.78903,200.075035095215,-2200.36401367187,-2.72557387271631E-5,1.60777708159446E-8,1,4,13.4005146026611,4.99277450035534,33.2500003278255,-0.0337764549977065,-0.00527553989082027,1,-1.75674797116835E-7,,,,,,,,,,,,,,,,,,,,,200.072967529297,200.077102661133,-2200.36401367187,-2200.36401367187,53.421964403871,5.65007753011644,5.14580869674683,54,1,0,0,1,0.306549072265625,33.7243423461914,1,1,3,200.072555541992,0,200.075035095215,,,,,,,,,,,,,,,,,,,,,,,,,,,,,,,,,
,3879914743.91618,200.093421936035,-2050.33715820313,-2.74858044487793E-5,1.49247229415529E-8,1,4,13.4005146026611,4.99273659480846,33.2500003278255,-0.0340739762637327,-0.00523460626471961,1,-1.08303938210193E-7,,,,,,,,,,,,,,,,,,,,,200.09196472168,200.094879150391,-2050.33715820313,-2050.33715820313,53.3684228503037,5.65034945412617,5.1460018157959,53,2,68,0,0,0.30426025390625,33.7243423461914,1,1,3,200.091583251953,0,200.093421936035,,,,,,,,,,,,,,,,,,,,,,,,,,,,,,,,,
,3879914815.59939,200.27906036377,-1900.3984375,-2.75872315309029E-5,1.24713907019748E-8,1,4,13.4005146026611,4.99288615646677,33.2500003278255,-0.0342077667534031,-0.00520991297478295,1,-7.30476723447072E-8,,,,,,,,,,,,,,,,,,,,,200.278167724609,200.27995300293,-1900.3984375,-1900.3984375,53.360997379371,5.64996760566714,5.14580011367798,54,3,0,0,1,0.30303955078125,33.7243423461914,1,1,3,200.27995300293,0,200.27906036377,,,,,,,,,,,,,,,,,,,,,,,,,,,,,,,,,
,3879914895.5253,200.260467529297,-1700.09411621094,-2.75059801605369E-5,1.98518708950844E-8,1,4,13.4005146026611,4.99294081835262,33.2500003278255,-0.0340864377406409,-0.00533570778620965,1,-1.86544831955174E-7,,,,,,,,,,,,,,,,,,,,,200.245361328125,200.275573730469,-1700.09411621094,-1700.09411621094,53.4000788053326,5.65058325094607,5.1457462310791,53,1,68,0,0,0.304946899414063,35.190616607666,1,1,3,200.275573730469,0,200.260467529297,,,,,,,,,,,,,,,,,,,,,,,,,,,,,,,,,
,3879914967.37323,200.124809265137,-1550.0673828125,-2.74058020763131E-5,1.5266444031309E-8,1,4,13.4005146026611,4.99287788847251,33.2599990069866,-0.0339740738853795,-0.00523342161053777,1,-1.19149479114485E-7,,,,,,,,,,,,,,,,,,,,,200.119995117187,200.129623413086,-1550.0673828125,-1550.0673828125,53.4387694170345,5.6510093663125,5.14200687408447,54,2,0,0,1,0.303268432617188,33.7243423461914,1,1,3,200.119995117187,0,200.124809265137,,,,,,,,,,,,,,,,,,,,,,,,,,,,,,,,,
,3879915039.58274,200.102333068848,-1400.09094238281,-2.71230595594983E-5,1.31663933887313E-8,1,4,13.4005146026611,4.99289242482529,33.2599990069866,-0.0336282412032307,-0.00514912275871309,1,-9.34721168616046E-8,,,,,,,,,,,,,,,,,,,,,200.098648071289,200.106018066406,-1400.09094238281,-1400.09094238281,53.4231368466499,5.65036120301212,5.1411657333374,54,3,0,0,1,0.304489135742188,33.7243423461914,1,1,3,200.098648071289,0,200.102333068848,,,,,,,,,,,,,,,,,,,,,,,,,,,,,,,,,
,3879915122.35895,200.143775939941,-1200.08862304688,-2.63999785496618E-5,2.25830812855101E-8,1,4,13.4005146026611,4.9929451138574,33.2500003278255,-0.0327128749681083,-0.00514124693938356,1,-1.95230291179068E-7,,,,,,,,,,,,,,,,,,,,,200.140502929687,200.147048950195,-1200.08862304688,-1200.08862304688,53.2750182422556,5.65008109528865,5.14356279373169,53,1,68,0,0,0.304718017578125,34.2131004333496,1,1,3,200.140502929687,0,200.143775939941,,,,,,,,,,,,,,,,,,,,,,,,,,,,,,,,,
,3879915206.18869,200.117210388184,-1050.11218261719,-2.56744344795681E-5,1.47165946562932E-8,1,4,13.4005146026611,4.99288323794776,33.2500003278255,-0.031822372199058,-0.00493910365929926,1,-1.4088293560838E-7,,,,,,,,,,,,,,,,,,,,,200.115325927734,200.119094848633,-1050.11218261719,-1050.11218261719,53.1745789775345,5.65068505699017,5.14815807342529,54,2,0,0,1,0.306320190429687,33.2355842590332,1,1,3,200.119049072266,0,200.117210388184,,,,,,,,,,,,,,,,,,,,,,,,,,,,,,,,,
,3879915276.05823,200.093734741211,-900.1357421875,-2.46577682563092E-5,1.536468458663E-8,1,4,13.4005146026611,4.99285933648466,33.2500003278255,-0.0305716228802856,-0.00467951598968742,1,-8.37306508015213E-8,,,,,,,,,,,,,,,,,,,,,200.093032836914,200.094436645508,-900.1357421875,-900.1357421875,53.3266057245249,5.65163631927001,5.14683055877686,53,3,68,0,0,0.30517578125,33.2355842590332,1,1,3,200.094436645508,0,200.093734741211,,,,,,,,,,,,,,,,,,,,,,,,,,,,,,,,,
,3879915358.29991,200.185577392578,-700.045471191406,-2.27391381165885E-5,2.03807025161989E-8,1,4,13.4005146026611,4.99279741877787,33.2500003278255,-0.0281636901877828,-0.00450686787159994,1,-2.31629153680521E-7,,,,,,,,,,,,,,,,,,,,,200.169876098633,200.201278686523,-700.045471191406,-700.045471191406,53.3039384974672,5.65106843579507,5.141282081604,54,1,0,0,1,0.305328369140625,33.7243423461914,1,1,3,200.201278686523,0,200.185577392578,,,,,,,,,,,,,,,,,,,,,,,,,,,,,,,,,
,3879915429.82431,200.213188171387,-550.056396484375,-2.08791597019212E-5,7.31873666822727E-8,1,4,13.4005146026611,4.9929229933866,33.2599990069866,-0.0258638189426468,-0.00411895291974724,1,-1.97031292417513E-7,,,,,,,,,,,,,,,,,,,,,200.208984375,200.217391967773,-550.056396484375,-550.056396484375,53.3074558258037,5.65090556968651,5.14239406585693,54,2,0,0,1,0.302963256835937,33.2355842590332,1,1,3,200.208984375,0,200.213188171387,,,,,,,,,,,,,,,,,,,,,,,,,,,,,,,,,
,3879915500.78793,200.22322845459,-400.180633544922,-1.83597385826852E-5,1.43033721099838E-8,1,4,13.4005146026611,4.99287411696244,33.2500003278255,-0.0227514076380286,-0.00356302603422062,1,-1.25809410466828E-7,,,,,,,,,,,,,,,,,,,,,200.216110229492,200.230346679687,-400.180633544922,-400.180633544922,53.3821013493903,5.65090539375034,5.14749526977539,53,3,68,0,0,0.306167602539063,33.2355842590332,1,1,3,200.216110229492,0,200.22322845459,,,,,,,,,,,,,,,,,,,,,,,,,,,,,,,,,
,3879915582.2179,200.085388183594,-200.052551269531,-1.37221762412197E-5,2.48966049432499E-8,1,4,13.4005146026611,4.99291297967942,33.2599990069866,-0.0169768406503681,-0.00284942842112351,1,-2.44272456894469E-7,,,,,,,,,,,,,,,,,,,,,200.085327148438,200.08544921875,-200.052551269531,-200.052551269531,53.4274358035057,5.65041106629814,5.14727830886841,53,1,68,0,0,0.304031372070313,33.2355842590332,1,1,3,200.085327148438,0,200.085388183594,,,,,,,,,,,,,,,,,,,,,,,,,,,,,,,,,
,3879915653.92202,200.203971862793,-50.1641960144043,-8.96279007611678E-6,1.85686891113936E-8,1,4,13.4005146026611,4.99286174515839,33.2500003278255,-0.0110873008522729,-0.00186879348924541,1,-1.65744306917101E-7,,,,,,,,,,,,,,,,,,,,,200.191818237305,200.216125488281,-50.1641960144043,-50.1641960144043,53.4755059574383,5.65186006134091,5.14217042922974,54,2,0,0,1,0.30487060546875,33.7243423461914,1,1,3,200.216125488281,0,200.203971862793,,,,,,,,,,,,,,,,,,,,,,,,,,,,,,,,,
,3879915735.74087,200.214385986328,99.8878021240234,-2.55371910646659E-6,3.155160028661E-8,1,4,13.4005146026611,4.99298920855603,33.2599990069866,-0.00314118499837404,-6.52625668371927E-4,1,-1.44072839947624E-7,,,,,,,,,,,,,,,,,,,,,200.212036132813,200.216735839844,99.8878021240234,99.8878021240234,53.493092599121,5.65019358573991,5.14788961410522,54,3,0,0,1,0.30517578125,33.2355842590332,1,1,3,200.212036132813,0,200.214385986328,,,,,,,,,,,,,,,,,,,,,,,,,,,,,,,,,
,3879915828.76931,200.064506530762,299.764129638672,6.20437919606908E-6,1.85527144193065E-8,1,4,13.4005146026611,4.99303375643109,33.2500003278255,0.00773097226503936,9.22328245577124E-4,1,-1.84640539226593E-7,,,,,,,,,,,,,,,,,,,,,200.061798095703,200.06721496582,299.764129638672,299.764129638672,53.4196195183133,5.65024748192598,5.14106273651123,54,1,0,0,1,0.304412841796875,33.7243423461914,1,1,3,200.061798095703,0,200.064506530762,,,,,,,,,,,,,,,,,,,,,,,,,,,,,,,,,
,3879915900.6554,200.100204467773,449.866455078125,1.15408798837311E-5,1.3260676397803E-8,1,4,13.4005146026611,4.99315173571968,33.2500003278255,0.0143426413795,0.00197211363145163,1,-1.36760175957206E-7,,,,,,,,,,,,,,,,,,,,,200.098587036133,200.101821899414,449.866455078125,449.866455078125,53.3527902799191,5.64987058351754,5.13887786865234,53,2,68,0,0,0.303268432617188,33.7243423461914,1,1,3,200.098587036133,0,200.100204467773,,,,,,,,,,,,,,,,,,,,,,,,,,,,,,,,,
,3879915983.51691,200.122772216797,599.893249511719,1.57054457374258E-5,1.40528001162928E-8,1,4,13.4005146026611,4.99319777621138,33.2500003278255,0.0195085744807601,0.00275003882938955,1,-1.3271108011447E-7,,,,,,,,,,,,,,,,,,,,,200.120162963867,200.125381469727,599.893249511719,599.893249511719,53.386400306246,5.6500420308954,5.13977241516113,54,3,0,0,1,0.304718017578125,33.7243423461914,1,1,3,200.120025634766,0,200.122772216797,,,,,,,,,,,,,,,,,,,,,,,,,,,,,,,,,
,3879916066.19244,200.113639831543,799.731811523437,1.97997931956197E-5,2.30617666952322E-8,1,4,13.4005146026611,4.99321558399711,33.2500003278255,0.0246075677363761,0.00337966180711742,1,-2.37692957560518E-7,,,,,,,,,,,,,,,,,,,,,200.102737426758,200.124542236328,799.731811523437,799.731811523437,53.2757998707749,5.64971769110158,5.14410734176636,54,1,0,0,1,0.304107666015625,33.7243423461914,1,1,3,200.124542236328,0,200.113639831543,,,,,,,,,,,,,,,,,,,,,,,,,,,,,,,,,
,3879916137.749,200.198722839355,949.884521484375,2.1961236628236E-5,2.45365615412628E-8,1,4,13.4005146026611,4.99314485184085,33.2500003278255,0.0272684287861796,0.00391485287297297,1,-1.29569048916648E-7,,,,,,,,,,,,,,,,,,,,,200.197387695313,200.200057983398,949.884521484375,949.884521484375,53.1640269925249,5.6498502190336,5.14407682418823,53,2,68,0,0,0.306243896484375,33.7243423461914,1,1,3,200.200057983398,0,200.198722839355,,,,,,,,,,,,,,,,,,,,,,,,,,,,,,,,,
,3879916209.61681,200.186515808105,1099.8232421875,2.35761583482751E-5,1.93111461828447E-8,1,4,13.4005146026611,4.99311711667982,33.2500003278255,0.0292733460479077,0.00420297701457802,1,-1.38873028535432E-7,,,,,,,,,,,,,,,,,,,,,200.185409545898,200.187622070313,1099.8232421875,1099.8232421875,53.379365649573,5.64952327778196,5.14103412628174,54,3,0,0,1,0.305404663085937,33.2355842590332,1,1,3,200.187622070313,0,200.186515808105,,,,,,,,,,,,,,,,,,,,,,,,,,,,,,,,,
,3879916292.06805,200.159706115723,1299.56115722656,2.51611192742786E-5,2.50422547953882E-8,1,4,13.4005146026611,4.99312335946164,33.2500003278255,0.0312475367767755,0.00444430349240334,1,-1.81448990522662E-7,,,,,,,,,,,,,,,,,,,,,200.149749755859,200.169662475586,1299.56115722656,1299.56115722656,53.394607405698,5.64913577201924,5.13808822631836,52,1,68,0,0,0.303497314453125,33.7243423461914,1,1,3,200.169662475586,0,200.159706115723,,,,,,,,,,,,,,,,,,,,,,,,,,,,,,,,,
,3879916364.39515,200.106590270996,1449.80187988281,2.58772343417006E-5,8.78903488927591E-9,1,4,13.4005146026611,4.99309583270643,33.2500003278255,0.0321278896943395,0.00462918676333094,1,-1.39514395693829E-7,,,,,,,,,,,,,,,,,,,,,200.10481262207,200.108367919922,1449.80187988281,1449.80187988281,53.3879635632845,5.65011136967168,5.13885164260864,54,2,0,0,1,0.30517578125,33.2355842590332,1,1,3,200.108367919922,0,200.106590270996,,,,,,,,,,,,,,,,,,,,,,,,,,,,,,,,,
,3879916436.19012,200.316680908203,1599.62731933594,2.63505865998161E-5,6.45352476999586E-8,1,4,13.4005146026611,4.99306954370318,33.2500003278255,0.0327200405718067,0.0046824014557776,1,-1.67401082157854E-7,,,,,,,,,,,,,,,,,,,,,200.313522338867,200.319839477539,1599.62731933594,1599.62731933594,53.360997379371,5.65034122099654,5.13679027557373,54,3,0,0,1,0.305709838867188,33.2355842590332,1,1,3,200.313522338867,0,200.316680908203,,,,,,,,,,,,,,,,,,,,,,,,,,,,,,,,,
,3879916518.32294,200.15071105957,1799.66723632813,2.67946687487329E-5,1.82791230448212E-8,1,4,13.4005146026611,4.9931223799843,33.2500003278255,0.0332757300733812,0.0047361774570501,1,-1.90540796174917E-7,,,,,,,,,,,,,,,,,,,,,200.150085449219,200.151336669922,1799.66723632813,1799.66723632813,53.4434591881499,5.64991146879913,5.1449556350708,52,1,68,0,0,0.304107666015625,33.7243423461914,1,1,3,200.151336669922,0,200.15071105957,,,,,,,,,,,,,,,,,,,,,,,,,,,,,,,,,
,3879916590.10583,200.20198059082,1950.04650878906,2.68644554237987E-5,8.24879334691626E-9,1,4,13.4005146026611,4.99307867653492,33.2500003278255,0.0333507201033552,0.00482377483925312,1,-1.30321556225488E-7,,,,,,,,,,,,,,,,,,,,,200.196716308594,200.207244873047,1950.04650878906,1950.04650878906,53.1433138367652,5.65051126995429,5.14115858078003,54,2,0,0,1,0.305328369140625,33.7243423461914,1,1,3,200.207244873047,0,200.20198059082,,,,,,,,,,,,,,,,,,,,,,,,,,,,,,,,,
,3879916661.50181,200.28685760498,2099.87182617187,2.68709210387887E-5,5.97993074034036E-8,1,4,13.4005146026611,4.99305682135401,33.2500003278255,0.0333528839843568,0.00486273028678103,1,-9.9862823480161E-8,,,,,,,,,,,,,,,,,,,,,200.2841796875,200.289535522461,2099.87182617187,2099.87182617187,53.3641238934479,5.65047731852291,5.13637971878052,54,3,0,0,1,0.303573608398438,33.7243423461914,1,1,3,200.2841796875,0,200.28685760498,,,,,,,,,,,,,,,,,,,,,,,,,,,,,,,,,
,3879916743.67169,200.168601989746,2299.83642578125,2.66103485378767E-5,8.69218908717347E-9,1,4,13.4005146026611,4.99304530838294,33.2500003278255,0.0330411175191915,0.0047368829855423,1,-1.62316333946449E-7,,,,,,,,,,,,,,,,,,,,,200.167526245117,200.169677734375,2299.83642578125,2299.83642578125,53.3047201259864,5.65058695685474,5.14163064956665,54,1,0,0,1,0.305404663085937,33.2355842590332,1,1,3,200.167526245117,0,200.168601989746,,,,,,,,,,,,,,,,,,,,,,,,,,,,,,,,,
,3879916815.51966,200.172348022461,2449.9638671875,2.63473851239272E-5,7.42261964217401E-9,1,4,13.4005146026611,4.99302705821895,33.2500003278255,0.0327072390439753,0.00473817062860504,1,-1.21921090966515E-7,,,,,,,,,,,,,,,,,,,,,200.169845581055,200.174850463867,2449.9638671875,2449.9638671875,53.460655015573,5.65030422929523,5.14023017883301,52,2,68,0,0,0.304336547851562,33.2355842590332,1,1,3,200.174850463867,0,200.172348022461,,,,,,,,,,,,,,,,,,,,,,,,,,,,,,,,,
,3879916886.82098,200.102554321289,2599.85229492187,2.60075125394659E-5,7.86797033627254E-9,1,4,13.4005146026611,4.99307290953842,33.2599990069866,0.0322818025185448,0.00470344325787065,1,-9.91210970154317E-8,,,,,,,,,,,,,,,,,,,,,200.1015625,200.103546142578,2599.85229492187,2599.85229492187,53.1440954652845,5.64995353947077,5.14160919189453,54,3,0,0,1,0.30364990234375,33.7243423461914,1,1,3,200.1015625,0,200.102554321289,,,,,,,,,,,,,,,,,,,,,,,,,,,,,,,,,
,3879916969.86757,200.050048828125,2799.7412109375,2.54797849525958E-5,9.18837691377614E-9,1,4,13.4005146026611,4.99318269791333,33.2500003278255,0.0316346478604994,0.00456193778092232,1,-1.34357056157104E-7,,,,,,,,,,,,,,,,,,,,,200.047348022461,200.052749633789,2799.7412109375,2799.7412109375,53.4637815296499,5.65051619663164,5.13623952865601,54,1,0,0,1,0.305862426757812,33.2355842590332,1,1,3,200.047348022461,0,200.050048828125,,,,,,,,,,,,,,,,,,,,,,,,,,,,,,,,,
,3879917041.49624,200.275802612305,2949.85620117188,2.49983563110353E-5,1.45655573958215E-8,1,4,13.4005146026611,4.99315318794887,33.2599990069866,0.03103219021619,0.00450564447167747,1,-1.0768482673175E-7,,,,,,,,,,,,,,,,,,,,,200.27424621582,200.277359008789,2949.85620117188,2949.85620117188,53.3871819347653,5.65042804913379,5.14318990707397,53,2,68,0,0,0.302505493164063,33.2355842590332,1,1,3,200.277359008789,0,200.275802612305,,,,,,,,,,,,,,,,,,,,,,,,,,,,,,,,,
,3879917133.59051,200.255523681641,3499.63549804687,2.28974141317347E-5,7.24422535679219E-9,1,4,13.4005146026611,4.99314087435134,33.2599990069866,0.0284119882684091,0.00420757148026758,1,-3.36561331362972E-8,,,,,,,,,,,,,,,,,,,,,200.249954223633,200.261093139648,3499.63549804687,3499.63549804687,53.218740988871,5.65066711872911,5.13892364501953,54,3,0,0,1,0.305252075195313,33.2355842590332,1,1,3,200.249954223633,0,200.255523681641,,,,,,,,,,,,,,,,,,,,,,,,,,,,,,,,,
,3879917231.82965,200.264640808105,5499.78369140625,1.30922093058621E-5,1.52871380749413E-8,1,4,13.4005146026611,4.99309569837654,33.2599990069866,0.0162371376346051,0.00245904598579442,1,2.37088425477441E-8,,,,,,,,,,,,,,,,,,,,,200.255783081055,200.273498535156,5499.78369140625,5499.78369140625,53.4274358035057,5.6510960838628,5.13794946670532,54,1,0,0,1,0.302352905273438,33.2355842590332,1,1,3,200.255783081055,0,200.264640808105,,,,,,,,,,,,,,,,,,,,,,,,,,,,,,,,,
,3879917315.96054,200.21166229248,6999.95068359375,4.7894469733781E-6,1.15060973265677E-8,1,4,13.4005146026611,4.99312405600164,33.2599990069866,0.00594083631571152,8.93895649795957E-4,1,4.0866010108711E-9,,,,,,,,,,,,,,,,,,,,,200.204299926758,200.219024658203,6999.95068359375,6999.95068359375,53.3301230528614,5.65110615385323,5.1332311630249,54,2,0,0,1,0.30548095703125,33.7243423461914,1,1,3,200.204299926758,0,200.21166229248,,,,,,,,,,,,,,,,,,,,,,,,,,,,,,,,,
,3879917399.98981,200.360984802246,8500.1435546875,-3.84401820187855E-6,1.10478628624429E-8,1,4,13.4005146026611,4.99309885108724,33.2500003278255,-0.00477257558032973,-6.87462076856436E-4,1,2.08827414862665E-8,,,,,,,,,,,,,,,,,,,,,200.357498168945,200.364471435547,8500.1435546875,8500.1435546875,53.3586524938133,5.65168392881349,5.13334226608276,54,3,0,0,1,0.303497314453125,33.2355842590332,6,1,3,200.36442565918,0,200.360984802246,,,,,,,,,,,,,,,,,,,,,,,,,,,,,,,,,
,3879917511.48798,200.190498352051,10000.185546875,-1.26004525545186E-5,1.48119068853668E-8,1,4,13.4005146026611,4.99299794199383,33.2599990069866,-0.0156357769421055,-0.00230677855902887,1,2.54182601726169E-8,,,,,,,,,,,,,,,,,,,,,200.189636230469,200.191360473633,10000.185546875,10000.185546875,53.3625606364095,5.65087304903153,5.14196348190308,54,1,0,0,1,0.305099487304687,33.7243423461914,1,1,3,200.189636230469,0,200.190498352051,,,,,,,,,,,,,,,,,,,,,,,,,,,,,,,,,
,3879917731.07567,200.00252532959,25000.513671875,-1.02851122049759E-4,2.42074665406074E-8,1,4,13.4005146026611,4.99292604723493,33.2500003278255,-0.127603108045365,-0.0189707868105967,1,9.2925088147656E-8,,,,,,,,,,,,,,,,,,,,,200.002227783203,200.002822875977,25000.513671875,25000.513671875,53.3688136645633,5.65137085921679,5.13698577880859,54,2,0,0,1,0.303726196289063,33.2355842590332,1,1,3,200.002807617187,0,200.00252532959,,,,,,,,,,,,,,,,,,,,,,,,,,,,,,,,,
,3879917951.93302,200.077346801758,40000.1875,-1.94061236054458E-4,4.48787970736314E-8,1,4,13.4005146026611,4.99289564633472,33.2500003278255,-0.240756385487555,-0.0358292734561769,1,1.46974652733038E-7,,,,,,,,,,,,,,,,,,,,,200.074951171875,200.079742431641,40000.1875,40000.1875,53.2886967413422,5.65229066525418,5.13782596588135,52,3,68,0,0,0.306930541992188,33.7243423461914,1,1,3,200.079742431641,0,200.077346801758,,,,,,,,,,,,,,,,,,,,,,,,,,,,,,,,,
,3879918233.59975,200.162719726562,60000.47265625,-3.15891868912193E-4,9.00807745999285E-8,1,4,13.4005146026611,4.99292220567033,33.2599990069866,-0.391885359389213,-0.0584538349659114,1,1.33886440538543E-7,,,,,,,,,,,,,,,,,,,,,200.13346862793,200.191970825195,60000.47265625,60000.47265625,53.1155660243325,5.65214777862189,5.13790941238403,54,1,0,0,1,0.303802490234375,33.2355842590332,1,1,3,200.191970825195,0,200.162719726562,,,,,,,,,,,,,,,,,,,,,,,,,,,,,,,,,
,3879918397.7853,200.169166564941,70000.4921875,-3.76961587167092E-4,1.72037979284739E-7,1,4,13.4005146026611,4.99279581246236,33.2599990069866,-0.467644347837112,-0.0696554502927798,1,2.37551751622136E-7,,,,,,,,,,,,,,,,,,,,,200.169036865234,200.169296264648,70000.4921875,70000.4921875,53.0882090261595,5.65188235842389,5.13947677612305,54,3,0,0,1,0.304107666015625,33.7243423461914,1,1,3,200.169036865234,0,200.169166564941,,,,,,,,,,,,,,,,,,,,,,,,,,,,,,,,,