File: SQUID/Reference/LAO/C3/transfer_115386_files_71fd6f70/LAOsubs_22172_MH_10K_FC_p0d5T.dat
[Header]
; MPMS3 Data File (default extension .dat)
; Copyright (c) 2007, Quantum Design, Inc. All rights reserved.
TITLE,
FILEOPENTIME,3881338643.97406,12/27/2022,9:40 pm
BYAPP,SQUID AC,0.9.1.0
INFO,MPMS3 Measurement Release 1.1.16 Build 347, MultiVu Release 2.3.3.2,APPNAME
INFO,0,MOMENT_UNITS
INFO,LAO,SAMPLE_MATERIAL
INFO,,SAMPLE_COMMENT
INFO,,SAMPLE_MASS
INFO,,SAMPLE_VOLUME
INFO,,SAMPLE_MOLECULAR_WEIGHT
INFO,,SAMPLE_SIZE
INFO,,SAMPLE_SHAPE
INFO,Quartz,SAMPLE_HOLDER
INFO,Standard,SAMPLE_HOLDER_DETAIL
INFO,65.74,SAMPLE_OFFSET
DATATYPE,COMMENT,1
DATATYPE,TIME,2
STARTUPAXIS,X,2
STARTUPAXIS,Y1,5
FIELDGROUP, VSM,2,3,4,5,6,8,9,10,11,14,15
FIELDGROUP, DC, 2,3,4,14,56,57,58,59,60,61,62,63,64,65,66,67,68,69
FIELDGROUP, AC, 2,3,4,11,16,17,18,19,20,21,22,23,24,25,26,27,28,29,30
STARTUPGROUP, All
[Data]
Comment,Time Stamp (sec),Temperature (K),Magnetic Field (Oe),Moment (emu),M. Std. Err. (emu),Transport Action,Averaging Time (sec),Frequency (Hz),Peak Amplitude (mm),Center Position (mm),Lockin Signal' (V),Lockin Signal (V),Range,M. Quad. Signal (emu),AC Moment (emu),AC M. Std Err. (emu),AC Phase (deg),AC Phase Std. Err. (deg),AC Susceptibility (emu/Oe),AC Suscept. Std Err. (emu/Oe),AC X' (emu/Oe),AC X' Std Err. (emu/Oe),AC X'' (emu/Oe),AC X'' Std Err. (emu/Oe),AC Drive (Oe),AC Frequency (Hz),AC Averaging Time (sec),AC Cycles,AC Range,AC Measure Type,AC Signal' (V),AC Signal'' (V),AC Trim Coil Ratio,AC Trim Coil Phase,Min. Temperature (K),Max. Temperature (K),Min. Field (Oe),Max. Field (Oe),Mass (grams),Motor Lag (deg),Pressure (Torr),Measure Count,Measurement Number,SQUID Status (code),Motor Status (code),Measure Status (code),Motor Current (amps),Motor Temp. (C),Temp. Status (code),Field Status (code),Chamber Status (code),Chamber Temp (K),Redirection State,Average Temp (K),Rotation Angle (deg),Rotator state,DC Moment Fixed Ctr (emu),DC Moment Err Fixed Ctr (emu),DC Moment Free Ctr (emu),DC Moment Err Free Ctr (emu),DC Fixed Fit,DC Free Fit,DC Calculated Center (mm),DC Calculated Center Err (mm),DC Scan Length (mm),DC Scan Time (s),DC Number of Points,DC Squid Drift,DC Min V (V),DC Max V (V),DC Scans per Measure,Map 01,Map 02,Map 03,Map 04,Map 05,Map 06,Map 07,Map 08,Map 09,Map 10,Map 11,Map 12,Map 13,Map 14,Map 15,Map 16
,3881338780.4444,10.0002555847168,70000.328125,-0.00118973765949549,6.36652676466542E-7,1,4,14.0008964538574,4.99571334364673,32.9700000584126,-1.47631039467903,-0.225739643081677,1,-1.17263818692762E-6,,,,,,,,,,,,,,,,,,,,,10.0001878738403,10.0003232955933,70000.328125,70000.328125,53.9468279545346,5.87691087850644,3.80657052993774,36,1,100,0,0,0.32684326171875,31.7693061828613,1,1,3,10.0003786087036,0,10.0002555847168,,,,,,,,,,,,,,,,,,,,,,,,,,,,,,,,,
,3881338893.13679,9.99975204467773,60000.34375,-0.000976885477761473,6.01873932767017E-5,1,4,14.0008964538574,4.99553636064354,32.9700000584126,-1.20382142840596,-0.240030431239597,10,-4.50293858930677E-5,,,,,,,,,,,,,,,,,,,,,9.99954128265381,9.99996280670166,60000.34375,60000.34375,54.0433590766596,5.87722015762112,3.82320976257324,45,1,68,0,0,0.325469970703125,32.7468223571777,1,1,3,10.0000553131104,0,9.99975204467773,,,,,,,,,,,,,,,,,,,,,,,,,,,,,,,,,
,3881338999.02474,9.99940776824951,50000.4453125,-0.000825193305464705,1.39517410156136E-5,1,4,14.0008964538574,4.99538421299353,32.9700000584126,-1.02490892387801,-0.149675060235073,10,4.73233576806872E-6,,,,,,,,,,,,,,,,,,,,,9.99905872344971,9.99975681304932,50000.4453125,50000.4453125,53.8483427611115,5.87730563944468,3.84850430488586,46,1,68,0,0,0.326156616210937,33.2355842590332,1,1,3,9.99905872344971,0,9.99940776824951,,,,,,,,,,,,,,,,,,,,,,,,,,,,,,,,,
,3881339112.18766,9.99652433395386,40000.25,-0.000344719148077962,0.000175954041681128,1,4,14.0008964538574,4.99526817377539,32.9700000584126,-0.434015769985431,-0.0238096741415183,1000,3.31752516844953E-5,,,,,,,,,,,,,,,,,,,,,9.99580192565918,9.99724674224854,40000.25,40000.25,53.8284112338711,5.87730175701312,3.84844207763672,56,1,0,0,1,0.325164794921875,33.2355842590332,1,1,3,9.99580192565918,0,9.99652433395386,,,,,,,,,,,,,,,,,,,,,,,,,,,,,,,,,
,3881339223.21401,9.99994659423828,29999.927734375,-0.000495784623243193,1.18024466479929E-7,1,4,14.0008964538574,4.99525430614863,32.9700000584126,-0.615337845413868,-0.0926587167387332,100,6.38639238513342E-7,,,,,,,,,,,,,,,,,,,,,9.99961662292481,10.0002765655518,29999.927734375,29999.927734375,53.6607519164961,5.87607690352696,3.81958723068237,56,1,0,0,1,0.327377319335937,33.2355842590332,1,1,3,9.99961662292481,0,9.99994659423828,,,,,,,,,,,,,,,,,,,,,,,,,,,,,,,,,
,3881339325.56383,10.0004343986511,19999.69140625,-0.000470173092000365,0.00016362439824037,1,4,14.0008964538574,4.99515214013558,32.9700000584126,-0.577921373157115,-0.124816883247327,100,-2.91698861693127E-5,,,,,,,,,,,,,,,,,,,,,10.0003871917725,10.0004816055298,19999.69140625,19999.69140625,53.3523994656595,5.87671091855148,3.8139340877533,48,1,68,0,0,0.328292846679687,33.7243423461914,1,1,3,10.0003871917725,0,10.0004343986511,,,,,,,,,,,,,,,,,,,,,,,,,,,,,,,,,
,3881339415.05969,9.99975728988647,14499.66796875,-0.00023676985341749,7.35701298494594E-8,1,4,14.0008964538574,4.99509907680584,32.9700000584126,-0.293861444069595,-0.0441839912937135,100,3.57159056300883E-7,,,,,,,,,,,,,,,,,,,,,9.99948978424072,10.0000247955322,14499.66796875,14499.66796875,53.5880604642076,5.87581890656519,3.79476499557495,56,1,0,0,1,0.325775146484375,33.7243423461914,1,1,3,9.99948978424072,0,9.99975728988647,,,,,,,,,,,,,,,,,,,,,,,,,,,,,,,,,
,3881339480.75305,9.99998807907105,13499.7822265625,-0.00018558428161815,3.06521687193022E-5,1,4,14.0008964538574,4.99512532127094,32.9700000584126,-0.226638493196611,-0.0589699300499419,100,-1.93335988349693E-5,,,,,,,,,,,,,,,,,,,,,9.99995708465576,10.0000190734863,13499.7822265625,13499.7822265625,53.4731610718807,5.87612607617561,3.79664993286133,54,1,68,0,0,0.326004028320313,33.7243423461914,1,1,3,10.0000190734863,0,9.99998807907105,,,,,,,,,,,,,,,,,,,,,,,,,,,,,,,,,
,3881339541.22957,9.99986553192139,12499.6083984375,-0.000214610855074555,8.37459801776201E-6,1,4,14.0008964538574,4.99510097552443,32.9700000584126,-0.266475295328703,-0.0392862823325224,1000,9.38319112531195E-7,,,,,,,,,,,,,,,,,,,,,9.99971389770508,10.0000171661377,12499.6083984375,12499.6083984375,53.5446800813903,5.87645791628439,3.79728841781616,56,1,0,0,1,0.32562255859375,33.7243423461914,1,1,3,9.99971389770508,0,9.99986553192139,,,,,,,,,,,,,,,,,,,,,,,,,,,,,,,,,
,3881339599.95382,10.0000882148743,11499.7734375,-0.00019144394662268,9.3525391420476E-6,1,4,14.0008964538574,4.99514106680212,32.9700000584126,-0.235895215800653,-0.0470086790258693,100,-8.80380281961469E-6,,,,,,,,,,,,,,,,,,,,,9.99995803833008,10.0002183914185,11499.7734375,11499.7734375,53.5313923965634,5.87654529527058,3.79291415214539,55,1,68,0,0,0.326766967773438,33.7243423461914,1,1,3,9.99995803833008,0,10.0000882148743,,,,,,,,,,,,,,,,,,,,,,,,,,,,,,,,,
,3881339653.94735,10.0001978874207,10499.662109375,-0.000183575457038855,1.31567489561187E-5,1,4,14.0008964538574,4.99506297753986,32.9700000584126,-0.22976155399426,-0.0215945365666488,100,1.04817140784087E-5,,,,,,,,,,,,,,,,,,,,,10.0000371932983,10.000358581543,10499.662109375,10499.662109375,53.6623151735345,5.87601616420514,3.79420375823975,56,1,0,0,1,0.326690673828125,33.7243423461914,1,1,3,10.000358581543,0,10.0001978874207,,,,,,,,,,,,,,,,,,,,,,,,,,,,,,,,,
,3881339698.9696,9.99985122680664,9499.6640625,-0.000151130948538378,6.68856617266205E-6,1,4,14.0008964538574,4.99504187939194,32.9700000584126,-0.186348217005266,-0.0362436136966182,10,-6.25263106632066E-6,,,,,,,,,,,,,,,,,,,,,9.99981307983398,9.9998893737793,9499.6640625,9499.6640625,53.569301379746,5.87654967911118,3.7932858467102,56,1,0,0,1,0.327072143554687,33.7243423461914,1,1,3,9.9998893737793,0,9.99985122680664,,,,,,,,,,,,,,,,,,,,,,,,,,,,,,,,,
,3881339747.73222,9.99964189529419,8499.58984375,-0.000126781309140745,1.69113632784476E-5,1,4,14.0008964538574,4.99494716235102,32.9700000584126,-0.154415838108905,-0.0429413803808669,100,-1.53500906718669E-5,,,,,,,,,,,,,,,,,,,,,9.99940586090088,9.9998779296875,8499.58984375,8499.58984375,53.6228429333134,5.87657146683932,3.80657649040222,56,1,0,0,1,0.32501220703125,33.7243423461914,1,1,3,9.9998779296875,0,9.99964189529419,,,,,,,,,,,,,,,,,,,,,,,,,,,,,,,,,
,3881339800.7327,10.0001220703125,7499.56640625,-0.000119461342181156,2.55585639541851E-5,1,4,14.0008964538574,4.99502993292968,32.9700000584126,-0.147887336852052,-0.0247709094775889,100,-1.81724787992282E-6,,,,,,,,,,,,,,,,,,,,,9.99994564056397,10.000298500061,7499.56640625,7499.56640625,53.5556228806595,5.87666069415715,3.80634164810181,56,1,0,0,1,0.326461791992188,33.2355842590332,1,1,3,9.99994564056397,0,10.0001220703125,,,,,,,,,,,,,,,,,,,,,,,,,,,,,,,,,
,3881339846.22208,9.99993896484375,6499.52978515625,-9.32064813986653E-5,2.02154994919936E-5,1,4,14.0008964538574,4.99493282907277,32.9799987375736,-0.10971498219167,-0.0566336870234374,10,-3.1485426763447E-5,,,,,,,,,,,,,,,,,,,,,9.9998893737793,9.9999885559082,6499.52978515625,6499.52978515625,53.6177623479384,5.87716436712921,3.79679346084595,56,1,0,0,1,0.325088500976562,33.7243423461914,1,1,3,9.9999885559082,0,9.99993896484375,,,,,,,,,,,,,,,,,,,,,,,,,,,,,,,,,
,3881339885.59076,10.0004820823669,5499.67041015625,-6.15874622777765E-5,4.68575293503585E-5,1,4,14.0008964538574,4.99478462036682,32.9700000584126,-0.0676883766334595,-0.0690480310509658,10,-4.62958871169644E-5,,,,,,,,,,,,,,,,,,,,,10.0003280639648,10.000636100769,5499.67041015625,5499.67041015625,53.4344704601787,5.8766204100482,3.7982702255249,56,1,0,0,1,0.327911376953125,33.7243423461914,1,1,3,10.000636100769,0,10.0004820823669,,,,,,,,,,,,,,,,,,,,,,,,,,,,,,,,,
,3881339926.04713,9.99989748001099,4499.58349609375,-7.26876229754029E-5,2.64595926178818E-8,1,4,14.0008964538574,4.99486882513228,32.9700000584126,-0.090195821843841,-0.0136485379505761,10,4.10896353024239E-8,,,,,,,,,,,,,,,,,,,,,9.99985408782959,9.99994087219238,4499.58349609375,4499.58349609375,53.6040838488518,5.87686946937287,3.79898619651794,56,1,0,0,1,0.326309204101562,33.7243423461914,1,1,3,9.99994087219238,0,9.99989748001099,,,,,,,,,,,,,,,,,,,,,,,,,,,,,,,,,
,3881339980.88932,9.99990367889404,3499.6103515625,-5.626534907471E-5,2.57054387112323E-8,1,4,14.0008964538574,4.99494745322984,32.9700000584126,-0.069820126667581,-0.0105608397063647,10,3.52916831721002E-8,,,,,,,,,,,,,,,,,,,,,9.9997673034668,10.0000400543213,3499.6103515625,3499.6103515625,53.5599218375153,5.87692440695669,3.8067467212677,56,1,0,0,1,0.327911376953125,33.7243423461914,1,1,3,10.0000400543213,0,9.99990367889404,,,,,,,,,,,,,,,,,,,,,,,,,,,,,,,,,
,3881340037.60838,10.0001034736633,2709.79809570313,-4.34173354708249E-5,2.17804675911666E-8,1,4,14.0008964538574,4.99487688473844,32.9700000584126,-0.0538644652479227,-0.00822413686374744,1,-3.32076525564463E-8,,,,,,,,,,,,,,,,,,,,,10.0000047683716,10.0002021789551,2709.79809570313,2709.79809570313,53.4790232857749,5.87653896929801,3.80791306495666,56,1,0,0,1,0.327377319335937,33.7243423461914,1,1,3,10.0000047683716,0,10.0001034736633,,,,,,,,,,,,,,,,,,,,,,,,,,,,,,,,,
,3881340075.62635,10.0002951622009,2129.52978515625,-3.39190646890182E-5,1.51593297063672E-8,1,4,14.0008964538574,4.99480428818978,32.9700000584126,-0.0420809905250564,-0.00641734853200245,1,-1.99065409699047E-8,,,,,,,,,,,,,,,,,,,,,10.0002861022949,10.0003042221069,2129.52978515625,2129.52978515625,53.5552320663999,5.8762480190365,3.8109335899353,56,1,0,0,1,0.326309204101562,33.7243423461914,1,1,3,10.0002861022949,0,10.0002951622009,,,,,,,,,,,,,,,,,,,,,,,,,,,,,,,,,
,3881340114.28423,10.0002694129944,1549.70227050781,-2.4490747346838E-5,1.47681793317658E-8,1,4,14.0008964538574,4.9949229653543,32.9700000584126,-0.030382217751105,-0.0046517140686269,1,-2.88886481619258E-8,,,,,,,,,,,,,,,,,,,,,10.0001497268677,10.0003890991211,1549.70227050781,1549.70227050781,53.5966583779191,5.87659934774408,3.81190991401672,56,1,0,0,1,0.326309204101562,33.7243423461914,1,1,3,10.0003890991211,0,10.0002694129944,,,,,,,,,,,,,,,,,,,,,,,,,,,,,,,,,
,3881340154.18453,10.0001215934753,969.773986816406,-1.5079413620648E-5,1.01499003817578E-8,1,4,14.0008964538574,4.99484572829423,32.9700000584126,-0.0187091048232016,-0.00284692143827551,1,-3.95348757543353E-9,,,,,,,,,,,,,,,,,,,,,10.0000991821289,10.0001440048218,969.773986816406,969.773986816406,53.4508846590826,5.87589804183922,3.81171727180481,56,1,0,0,1,0.326080322265625,33.7243423461914,1,1,3,10.0001440048218,0,10.0001215934753,,,,,,,,,,,,,,,,,,,,,,,,,,,,,,,,,
,3881340193.72608,9.99972009658813,389.530944824219,-5.67061029842252E-6,3.04948574271003E-8,1,4,14.0008964538574,4.99480700612572,32.9799987375736,-0.00703340579842246,-0.0010842178798782,1,-1.24844108677101E-8,,,,,,,,,,,,,,,,,,,,,9.9996395111084,9.99980068206787,389.530944824219,389.530944824219,53.4786324715153,5.87681805270299,3.80893325805664,56,1,0,0,1,0.324783325195313,33.7243423461914,1,1,3,9.99980068206787,0,9.99972009658813,,,,,,,,,,,,,,,,,,,,,,,,,,,,,,,,,
,3881340231.73878,9.99977540969849,-190.321823120117,3.65879534093858E-6,1.39675644954549E-8,1,4,14.0008964538574,4.99485929387358,32.9700000584126,0.00454071560544022,0.000682783934849582,1,-5.47375726773356E-9,,,,,,,,,,,,,,,,,,,,,9.99943161010742,10.0001192092896,-190.321823120117,-190.321823120117,53.5626575373326,5.87719620975111,3.81261587142944,56,1,0,0,1,0.330657958984375,33.7243423461914,1,1,3,9.99943161010742,0,9.99977540969849,,,,,,,,,,,,,,,,,,,,,,,,,,,,,,,,,
,3881340269.03466,9.99981546401978,-769.859924316406,1.30349344486689E-5,2.51383556693352E-8,1,4,14.0008964538574,4.99482264788135,32.9700000584126,0.0161666930510783,0.00249851773478427,1,3.37219294250496E-8,,,,,,,,,,,,,,,,,,,,,9.99973106384277,9.99989986419678,-769.859924316406,-769.859924316406,53.3906992631018,5.87663805937087,3.81356000900269,56,1,0,0,1,0.327682495117188,33.7243423461914,1,1,3,9.99972629547119,0,9.99981546401978,,,,,,,,,,,,,,,,,,,,,,,,,,,,,,,,,
,3881340306.6622,10.0003304481506,-1349.97705078125,2.24470997278198E-5,2.40832459048044E-8,1,4,14.0008964538574,4.99474979761548,32.9700000584126,0.0278477901973226,0.00424892313533507,1,1.48570661994681E-8,,,,,,,,,,,,,,,,,,,,,10.0001535415649,10.0005073547363,-1349.97705078125,-1349.97705078125,53.5302199537845,5.87754751913788,3.81299710273743,56,1,0,0,1,0.327072143554687,33.2355842590332,1,1,3,10.0001535415649,0,10.0003304481506,,,,,,,,,,,,,,,,,,,,,,,,,,,,,,,,,
,3881340345.15593,9.99995279312134,-1930.28295898438,3.20141544781796E-5,1.33453575756676E-8,1,4,14.0008964538574,4.99486827690103,32.9700000584126,0.0397269162470264,0.0060010929999309,1,-2.63151283076993E-8,,,,,,,,,,,,,,,,,,,,,9.99989032745361,10.0000152587891,-1930.28295898438,-1930.28295898438,53.4469765164864,5.87664810813205,3.81431007385254,56,1,0,0,1,0.328521728515625,33.7243423461914,1,1,3,10.0000152587891,0,9.99995279312134,,,,,,,,,,,,,,,,,,,,,,,,,,,,,,,,,
,3881340383.28264,9.9999566078186,-2509.98486328125,4.13730349532393E-5,5.33968288933865E-8,1,4,14.0008964538574,4.99471901589696,32.9700000584126,0.0513511681248568,0.00767080564613406,1,-1.01950116043008E-7,,,,,,,,,,,,,,,,,,,,,9.99986839294434,10.0000448226929,-2509.98486328125,-2509.98486328125,53.4583101300153,5.87705529380938,3.80511021614075,56,1,0,0,1,0.32745361328125,33.7243423461914,1,1,3,9.99986839294434,0,9.9999566078186,,,,,,,,,,,,,,,,,,,,,,,,,,,,,,,,,
,3881340437.19413,10.0003042221069,-2999.96997070313,4.931109350713E-5,2.23675096128923E-8,1,4,14.0008964538574,4.9945613679701,32.9700000584126,0.0611896133827693,0.00921699801691697,1,-6.1193118483226E-8,,,,,,,,,,,,,,,,,,,,,10.0002870559692,10.0003213882446,-2999.96997070313,-2999.96997070313,53.4313439461018,5.87887809427112,3.81017756462097,56,1,0,0,1,0.3277587890625,33.7243423461914,1,1,3,10.0003213882446,0,10.0003042221069,,,,,,,,,,,,,,,,,,,,,,,,,,,,,,,,,
,3881340476.24081,10.0001697540283,-3999.96826171875,6.55469571915659E-5,3.00856699877056E-8,1,4,14.0008964538574,4.99468380414331,32.9700000584126,0.0813376836334592,0.0122629054756924,1,-7.26723635531004E-8,,,,,,,,,,,,,,,,,,,,,9.99996757507324,10.0003719329834,-3999.96826171875,-3999.96826171875,53.6095552484864,5.87868673519731,3.81034421920776,54,1,68,0,0,0.329666137695313,33.7243423461914,1,1,3,9.99996757507324,0,10.0001697540283,,,,,,,,,,,,,,,,,,,,,,,,,,,,,,,,,
,3881340529.7249,9.99999856948852,-5000.080078125,8.19679452645571E-5,2.41924074220539E-8,1,4,14.0008964538574,4.99472478627433,32.9700000584126,0.101714061325474,0.0153464844144436,1,-8.17958462231741E-8,,,,,,,,,,,,,,,,,,,,,9.99974822998047,10.0002489089966,-5000.080078125,-5000.080078125,53.6900629859672,5.87721756905059,3.81687116622925,56,1,0,0,1,0.326156616210937,33.7243423461914,1,1,3,9.99974822998047,0,9.99999856948852,,,,,,,,,,,,,,,,,,,,,,,,,,,,,,,,,
,3881340583.04628,9.99987363815308,-6000.0029296875,9.80864414232784E-5,4.3259100953582E-8,1,4,14.0008964538574,4.99462488826313,32.9700000584126,0.121708623433831,0.0183866558125419,1,-7.94281938118332E-8,,,,,,,,,,,,,,,,,,,,,9.99978160858154,9.99996566772461,-6000.0029296875,-6000.0029296875,53.4493214020441,5.87762354085836,3.81894731521606,52,1,68,0,0,0.328140258789063,33.2355842590332,1,1,3,9.99996566772461,0,9.99987363815308,,,,,,,,,,,,,,,,,,,,,,,,,,,,,,,,,
,3881340635.50213,10.0002841949463,-6999.673828125,0.000114317753647648,5.83232958702349E-8,1,4,14.0008964538574,4.99463520928206,32.9700000584126,0.141845545123774,0.0214542998297018,1,-7.24505752523815E-8,,,,,,,,,,,,,,,,,,,,,10.0002822875977,10.0002861022949,-6999.673828125,-6999.673828125,53.4571376872364,5.87727797996964,3.81424880027771,52,1,68,0,0,0.327606201171875,33.7243423461914,1,1,3,10.0002861022949,0,10.0002841949463,,,,,,,,,,,,,,,,,,,,,,,,,,,,,,,,,
,3881340700.87401,10.0002160072327,-7999.99951171875,0.000130592993752442,5.27161757133687E-8,1,4,14.0008964538574,4.99460338731588,32.9700000584126,0.162039465472522,0.0245016654429031,1,-8.82710173165131E-8,,,,,,,,,,,,,,,,,,,,,9.99981307983398,10.0006189346313,-7999.99951171875,-7999.99951171875,53.4501030305633,5.87715058878426,3.80813646316528,48,1,100,0,0,0.329666137695313,32.7468223571777,1,1,3,9.99981307983398,0,10.0002160072327,,,,,,,,,,,,,,,,,,,,,,,,,,,,,,,,,
,3881340754.07647,10.0000147819519,-8999.6953125,0.000147076652537386,6.53729075993697E-8,1,4,14.0008964538574,4.99451380486033,32.9700000584126,0.182490345508453,0.0275766177191869,1,-1.13110754307244E-7,,,,,,,,,,,,,,,,,,,,,9.99992942810059,10.0001001358032,-8999.6953125,-8999.6953125,53.3985155482941,5.87833212810036,3.81553149223328,47,1,100,0,0,0.326156616210937,33.7243423461914,1,1,3,10.0001001358032,0,10.0000147819519,,,,,,,,,,,,,,,,,,,,,,,,,,,,,,,,,
,3881340820.68769,10.0000071525574,-9999.8076171875,0.000163574488580839,5.46308191270137E-8,1,4,14.0008964538574,4.99453507603766,32.9700000584126,0.20296178393228,0.0306702612813634,1,-1.25681779381016E-7,,,,,,,,,,,,,,,,,,,,,9.99998188018799,10.0000324249268,-9999.8076171875,-9999.8076171875,53.5333464678614,5.8779248211563,3.81328177452087,52,1,68,0,0,0.32958984375,33.7243423461914,1,1,3,10.0000228881836,0,10.0000071525574,,,,,,,,,,,,,,,,,,,,,,,,,,,,,,,,,
,3881340868.66045,10.0000567436218,-10999.818359375,0.000166052664572787,1.46822944587755E-5,1,4,14.0008964538574,4.99450335565121,32.9700000584126,0.2067754456262,0.0262590783775203,10,-4.05747921087437E-6,,,,,,,,,,,,,,,,,,,,,10.000054359436,10.0000591278076,-10999.818359375,-10999.818359375,53.3613881936306,5.87882357739604,3.8193838596344,56,1,0,0,1,0.328903198242188,33.7243423461914,1,1,3,10.0000591278076,0,10.0000567436218,,,,,,,,,,,,,,,,,,,,,,,,,,,,,,,,,
,3881340908.38809,9.99987363815308,-11999.8671875,0.000190145477361233,9.64671658402993E-6,1,4,14.0008964538574,4.99443270551199,32.9700000584126,0.233945667599792,0.0486756542953431,10,1.03522386706593E-5,,,,,,,,,,,,,,,,,,,,,9.99967670440674,10.0000705718994,-11999.8671875,-11999.8671875,53.5224036685922,5.87821551148849,3.80980253219604,56,1,0,0,1,0.32867431640625,33.2355842590332,1,1,3,10.0000705718994,0,9.99987363815308,,,,,,,,,,,,,,,,,,,,,,,,,,,,,,,,,
,3881340948.57377,10.0001964569092,-12999.978515625,0.000190754314646667,2.80388884372002E-5,1,4,14.0008964538574,4.99437763502363,32.9700000584126,0.235743796114448,0.0419007141970882,10,4.79930673769572E-6,,,,,,,,,,,,,,,,,,,,,9.99997711181641,10.000415802002,-12999.978515625,-12999.978515625,53.4274358035057,5.87864900378298,3.80944299697876,52,1,68,0,0,0.32958984375,33.7243423461914,1,1,3,10.000415802002,0,10.0001964569092,,,,,,,,,,,,,,,,,,,,,,,,,,,,,,,,,
,3881341010.32485,10.0000042915344,-13999.650390625,0.000261031212330673,2.89616064847973E-5,1,4,14.0008964538574,4.9943105262314,32.9700000584126,0.321814880210301,0.0624357884684183,100,1.06778774896681E-5,,,,,,,,,,,,,,,,,,,,,9.9997444152832,10.0002641677856,-13999.650390625,-13999.650390625,53.4563560587172,5.87827526940314,3.81111407279968,52,1,68,0,0,0.328140258789063,33.7243423461914,1,1,3,10.0002641677856,0,10.0000042915344,,,,,,,,,,,,,,,,,,,,,,,,,,,,,,,,,
,3881341093.08762,10.0003814697266,-14999.673828125,0.000251286538646706,1.9102168019557E-5,1,4,14.0008964538574,4.99441655390627,32.9700000584126,0.313129802017645,0.0382533203771853,100,-7.33588597749179E-6,,,,,,,,,,,,,,,,,,,,,10.0003232955933,10.0004396438599,-14999.673828125,-14999.673828125,53.3985155482941,5.878765946326,3.81945109367371,54,1,68,0,0,0.3265380859375,33.7243423461914,1,1,3,10.0004396438599,0,10.0003814697266,,,,,,,,,,,,,,,,,,,,,,,,,,,,,,,,,
,3881341204.26868,10.0002732276917,-24999.681640625,0.000715876043655329,0.000249782060455203,1,4,14.0008964538574,4.99442375856748,32.9700000584126,0.874895039989944,0.221977624949456,100,7.01853456438739E-5,,,,,,,,,,,,,,,,,,,,,10.0000696182251,10.0004768371582,-24999.681640625,-24999.681640625,53.6033022203326,5.87871413009469,3.82461786270142,54,1,68,0,0,0.325927734375,33.7243423461914,1,1,3,10.0004768371582,0,10.0002732276917,,,,,,,,,,,,,,,,,,,,,,,,,,,,,,,,,
,3881341317.07006,9.9999680519104,-34999.71875,0.000571831937460996,8.47333719389325E-5,1,4,14.0008964538574,4.99452661429923,32.9700000584126,0.708820844502844,0.111836579443196,100,3.28305003427122E-6,,,,,,,,,,,,,,,,,,,,,9.99991893768311,10.0000171661377,-34999.71875,-34999.71875,53.816295991823,5.87943880727095,3.82555794715881,52,1,68,0,0,0.3253173828125,33.2355842590332,1,1,3,9.99991893768311,0,9.9999680519104,,,,,,,,,,,,,,,,,,,,,,,,,,,,,,,,,
,3881341418.04024,10.0002326965332,-44999.80078125,0.000777980088105271,3.90891120811529E-5,1,4,14.0008964538574,4.99445674719835,32.9700000584126,0.960237493814905,0.179128027063762,100,2.62112374042162E-5,,,,,,,,,,,,,,,,,,,,,10.0002145767212,10.0002508163452,-44999.80078125,-44999.80078125,53.8284112338711,5.87966569678956,3.81946420669556,55,1,68,0,0,0.3289794921875,33.2355842590332,1,1,3,10.0002145767212,0,10.0002326965332,,,,,,,,,,,,,,,,,,,,,,,,,,,,,,,,,
,3881341518.68728,10.0002841949463,-54999.70703125,0.000947022170480502,3.97127913726868E-5,1,4,14.0008964538574,4.99455022922785,32.9700000584126,1.17080712092691,0.205577224151846,100,2.18488446962269E-5,,,,,,,,,,,,,,,,,,,,,10.0000114440918,10.0005569458008,-54999.70703125,-54999.70703125,53.8909415154095,5.88062757444599,3.81540942192078,56,1,0,0,1,0.328826904296875,33.2355842590332,1,1,3,10.0000114440918,0,10.0002841949463,,,,,,,,,,,,,,,,,,,,,,,,,,,,,,,,,
,3881341618.77168,10.0001230239868,-64999.578125,0.00111768699438568,9.82760967882667E-5,1,4,14.0008964538574,4.99440181959023,32.9700000584126,1.37048208513956,0.316749820153713,100,8.55438036659113E-5,,,,,,,,,,,,,,,,,,,,,10.000018119812,10.0002279281616,-64999.578125,-64999.578125,54.0972914444865,5.88096928602715,3.81734538078308,54,1,68,0,0,0.327835083007812,33.2355842590332,1,1,3,10.0002279281616,0,10.0001230239868,,,,,,,,,,,,,,,,,,,,,,,,,,,,,,,,,
,3881341732.2208,9.99980592727661,-64999.640625,0.00111643202169153,1.79557444406638E-5,1,4,14.0008964538574,4.9944628064139,32.9700000584126,1.38448296092155,0.214251223901657,100,3.11130040732156E-6,,,,,,,,,,,,,,,,,,,,,9.9997730255127,9.99983882904053,-64999.640625,-64999.640625,54.0257724349769,5.88135502543806,3.82363724708557,56,1,0,0,1,0.328521728515625,33.7243423461914,1,1,3,9.9997730255127,0,9.99980592727661,,,,,,,,,,,,,,,,,,,,,,,,,,,,,,,,,
,3881341819.67218,10.0003137588501,-54999.58203125,0.000867382020641896,8.95024703733245E-5,1,4,14.0008964538574,4.99438440798995,32.9700000584126,1.07555208908808,0.166856622014156,100,2.74250505405387E-6,,,,,,,,,,,,,,,,,,,,,10.0001668930054,10.0004606246948,-54999.58203125,-54999.58203125,53.9284596843326,5.88063172299515,3.8268358707428,54,1,68,0,0,0.3289794921875,33.7243423461914,1,1,3,10.0004606246948,0,10.0003137588501,,,,,,,,,,,,,,,,,,,,,,,,,,,,,,,,,
,3881341928.68072,10.0001788139343,-44999.7734375,0.000604877663505321,0.000122029278563992,1,4,14.0008964538574,4.99432275567822,32.9700000584126,0.736124813666199,0.207926878081739,1000,7.57249902564552E-5,,,,,,,,,,,,,,,,,,,,,10.0001068115234,10.0002508163452,-44999.7734375,-44999.7734375,53.8233306484961,5.88049216176397,3.81760120391846,56,1,0,0,1,0.32623291015625,33.7243423461914,1,1,3,10.0002508163452,0,10.0001788139343,,,,,,,,,,,,,,,,,,,,,,,,,,,,,,,,,
,3881342041.096,10.0000734329224,-34999.578125,0.00060570651416545,3.15398109842624E-5,1,4,14.0008964538574,4.99444949086691,32.9700000584126,0.751542951310125,0.113529983270089,1000,-4.95560658036513E-7,,,,,,,,,,,,,,,,,,,,,10.0000247955322,10.0001220703125,-34999.578125,-34999.578125,53.8104337779288,5.88029911103375,3.82286524772644,56,1,0,0,1,0.327377319335937,33.7243423461914,1,1,3,10.0000247955322,0,10.0000734329224,,,,,,,,,,,,,,,,,,,,,,,,,,,,,,,,,
,3881342131.91217,9.99980449676514,-24999.7578125,0.000385812081438026,2.6337124880734E-5,1,4,14.0008964538574,4.99440601235545,32.9700000584126,0.48121758728641,0.0557296628835221,100,-1.36831608738779E-5,,,,,,,,,,,,,,,,,,,,,9.99948883056641,10.0001201629639,-24999.7578125,-24999.7578125,53.5415535673134,5.87972769714585,3.82794737815857,56,1,0,0,1,0.326766967773438,33.7243423461914,1,1,3,9.99948883056641,0,9.99980449676514,,,,,,,,,,,,,,,,,,,,,,,,,,,,,,,,,
,3881342217.84297,9.99992847442627,-15000.2529296875,0.000261289682168707,1.91145840282863E-5,1,4,14.0008964538574,4.99437150807676,32.9700000584126,0.321238424788868,0.0684277475262397,100,1.54676842515172E-5,,,,,,,,,,,,,,,,,,,,,9.9997091293335,10.000147819519,-15000.2529296875,-15000.2529296875,53.4989548130153,5.87908793063036,3.82697868347168,56,1,0,0,1,0.326156616210937,33.2355842590332,1,1,3,9.9997091293335,0,9.99992847442627,,,,,,,,,,,,,,,,,,,,,,,,,,,,,,,,,
,3881342275.12176,10.00040102005,-14000.392578125,0.000254418987162079,2.17547162481625E-5,1,4,14.0008964538574,4.99433321833517,32.9700000584126,0.315305636427861,0.0500533394437829,100,1.70074232546622E-6,,,,,,,,,,,,,,,,,,,,,10.0003032684326,10.0004987716675,-14000.392578125,-14000.392578125,53.6595794737172,5.87973533340913,3.82709693908691,56,1,0,0,1,0.3277587890625,33.7243423461914,1,1,3,10.0004987716675,0,10.00040102005,,,,,,,,,,,,,,,,,,,,,,,,,,,,,,,,,
,3881342331.71853,10.0000128746033,-13000.306640625,0.000211696580610544,3.81662321207298E-8,1,4,14.0008964538574,4.9944167215281,32.9700000584126,0.262688177486768,0.0395230237980612,100,-2.98739267741608E-7,,,,,,,,,,,,,,,,,,,,,9.99999046325684,10.0000352859497,-13000.306640625,-13000.306640625,53.4629999011307,5.87921186954806,3.83143711090088,56,1,0,0,1,0.328369140625,33.7243423461914,1,1,3,9.99999046325684,0,10.0000128746033,,,,,,,,,,,,,,,,,,,,,,,,,,,,,,,,,
,3881342375.49313,10.0001931190491,-12000.3837890625,0.000195082699708959,5.83801387396714E-8,1,4,14.0008964538574,4.99438871285381,32.9700000584126,0.242055846362546,0.0365180489848994,10,-1.97053060327977E-7,,,,,,,,,,,,,,,,,,,,,10.000036239624,10.0003499984741,-12000.3837890625,-12000.3837890625,53.536863796198,5.87961615377208,3.8297610282898,52,1,68,0,0,0.327377319335937,34.2131004333496,1,1,3,10.000036239624,0,10.0001931190491,,,,,,,,,,,,,,,,,,,,,,,,,,,,,,,,,
,3881342429.57893,10.0000262260437,-11000.5234375,0.000157911584849124,3.44433164674513E-5,1,4,14.0008964538574,4.99433234257562,32.9700000584126,0.19014206725507,0.0676720614874121,10,3.05622261097127E-5,,,,,,,,,,,,,,,,,,,,,9.99995708465576,10.0000953674316,-11000.5234375,-11000.5234375,53.4035961336691,5.87905033289287,3.82297801971436,56,1,0,0,1,0.330276489257812,33.7243423461914,1,1,3,10.0000953674316,0,10.0000262260437,,,,,,,,,,,,,,,,,,,,,,,,,,,,,,,,,
,3881342469.1509,10.0002131462097,-10000.349609375,0.000162289341829046,6.04291503254517E-8,1,4,14.0008964538574,4.99436279645564,32.9700000584126,0.201350265901555,0.0304751604002423,10,-8.65392487440327E-8,,,,,,,,,,,,,,,,,,,,,10.0000610351562,10.0003652572632,-10000.349609375,-10000.349609375,53.3699861073422,5.87934568762161,3.8227686882019,56,1,0,0,1,0.3271484375,33.7243423461914,1,1,3,10.0000610351562,0,10.0002131462097,,,,,,,,,,,,,,,,,,,,,,,,,,,,,,,,,
,3881342509.57042,10.0000061988831,-9000.451171875,0.000146003837355623,5.02875716645364E-8,1,4,14.0008964538574,4.99436065491893,32.9700000584126,0.18114919130183,0.0273890469249285,10,-1.0039131660688E-7,,,,,,,,,,,,,,,,,,,,,9.99988269805908,10.000129699707,-9000.451171875,-9000.451171875,53.7013965994961,5.87932072127711,3.83511829376221,56,1,0,0,1,0.324630737304687,33.7243423461914,1,1,3,9.999924659729,0,10.0000061988831,,,,,,,,,,,,,,,,,,,,,,,,,,,,,,,,,
,3881342572.44159,10.0001535415649,-8000.21337890625,0.000129472340641861,4.92091871255855E-8,1,4,14.0008964538574,4.99440656486474,32.9700000584126,0.160609425006689,0.024491975722342,1,7.52352206038376E-8,,,,,,,,,,,,,,,,,,,,,10.0001211166382,10.0001859664917,-8000.21337890625,-8000.21337890625,53.4790232857749,5.87866776173085,3.83555459976196,56,1,0,0,1,0.326080322265625,33.7243423461914,1,1,3,10.0000524520874,0,10.0001535415649,,,,,,,,,,,,,,,,,,,,,,,,,,,,,,,,,
,3881342629.15374,9.99989080429077,-7000.2783203125,0.000113314022071923,3.93463770910358E-8,1,4,14.0008964538574,4.99434951755183,32.9700000584126,0.140570801286964,0.0213830403392287,1,2.39608919264813E-8,,,,,,,,,,,,,,,,,,,,,9.99973487854004,10.0000467300415,-7000.2783203125,-7000.2783203125,53.5009088843133,5.87925482647357,3.82782125473022,55,1,68,0,0,0.32745361328125,35.6793746948242,1,1,3,9.99973487854004,0,9.99989080429077,,,,,,,,,,,,,,,,,,,,,,,,,,,,,,,,,
,3881342683.5766,10.0001616477966,-6000.30517578125,9.69115217383562E-5,4.6059347467411E-8,1,4,14.0008964538574,4.99420874376538,32.9700000584126,0.120214799680235,0.0183085598882934,1,3.7817683333716E-8,,,,,,,,,,,,,,,,,,,,,10.0000524520874,10.0002708435059,-6000.30517578125,-6000.30517578125,53.5509331095441,5.87868489767413,3.83415913581848,54,1,68,0,0,0.3289794921875,33.7243423461914,1,1,3,10.0002708435059,0,10.0001616477966,,,,,,,,,,,,,,,,,,,,,,,,,,,,,,,,,
,3881342722.09195,10.0001368522644,-5000.2939453125,8.06595040667322E-5,3.39575813921037E-8,1,4,14.0008964538574,4.99436137961956,32.9700000584126,0.100060786739724,0.0152278790801951,1,2.26120506808243E-8,,,,,,,,,,,,,,,,,,,,,10.0001354217529,10.0001382827759,-5000.2939453125,-5000.2939453125,53.5493698525057,5.87865376924119,3.82823133468628,55,1,68,0,0,0.328826904296875,33.7243423461914,1,1,3,10.0001354217529,0,10.0001368522644,,,,,,,,,,,,,,,,,,,,,,,,,,,,,,,,,
,3881342763.34303,10.0003776550293,-4000.21997070313,6.43597552163581E-5,1.04074509457474E-7,1,4,14.0008964538574,4.99431146975883,32.9799987375736,0.0798308981674697,0.0122056956410998,1,6.25792995387204E-8,,,,,,,,,,,,,,,,,,,,,10.0003070831299,10.0004482269287,-4000.21997070313,-4000.21997070313,53.5845431358711,5.87918153885297,3.83376169204712,55,1,68,0,0,0.325393676757812,33.7243423461914,1,1,3,10.0003070831299,0,10.0003776550293,,,,,,,,,,,,,,,,,,,,,,,,,,,,,,,,,
,3881342803.76703,10.0000109672546,-3000.38549804687,4.80026560541164E-5,2.21828163797387E-8,1,4,14.0008964538574,4.99428300671427,32.9700000584126,0.0595481676912057,0.0090584292252301,1,1.03173623509966E-8,,,,,,,,,,,,,,,,,,,,,10.0000085830688,10.0000133514404,-3000.38549804687,-3000.38549804687,53.5896237212461,5.87894775816314,3.83667945861816,56,1,0,0,1,0.327682495117188,34.2131004333496,1,1,3,10.0000257492065,0,10.0000109672546,,,,,,,,,,,,,,,,,,,,,,,,,,,,,,,,,
,3881342860.44901,10.0000958442688,-2510.48828125,4.00964870417754E-5,1.83855971464346E-8,1,4,14.0008964538574,4.99431024173315,32.9700000584126,0.0497391109408895,0.00757766651177406,1,1.75878325346607E-8,,,,,,,,,,,,,,,,,,,,,9.99994087219238,10.0002508163452,-2510.48828125,-2510.48828125,53.5517147380633,5.87936515396366,3.83792614936829,56,1,0,0,1,0.327529907226562,33.7243423461914,1,1,3,9.99994087219238,0,10.0000958442688,,,,,,,,,,,,,,,,,,,,,,,,,,,,,,,,,
,3881342900.09047,10.0000638961792,-1930.484375,3.06721858800529E-5,1.18857383047707E-8,1,4,14.0008964538574,4.99429758431398,32.9700000584126,0.0380467625547649,0.00580649037950718,1,2.14370428789607E-8,,,,,,,,,,,,,,,,,,,,,9.99996280670166,10.0001649856567,-1930.484375,-1930.484375,53.5138057548807,5.87998434489289,3.83239197731018,56,1,0,0,1,0.327072143554687,33.7243423461914,1,1,3,10.0001649856567,0,10.0000638961792,,,,,,,,,,,,,,,,,,,,,,,,,,,,,,,,,
,3881342939.00259,10.0000276565552,-1350.44287109375,2.12239945744269E-5,9.66109199892352E-9,1,4,14.0008964538574,4.9942803697348,32.9700000584126,0.0263293565578198,0.00400099637473003,1,1.24591373246333E-9,,,,,,,,,,,,,,,,,,,,,9.99990272521973,10.0001525878906,-1350.44287109375,-1350.44287109375,53.5091159837653,5.87918803196163,3.84329628944397,56,1,0,0,1,0.329132080078125,33.2355842590332,1,1,3,10.0001525878906,0,10.0000276565552,,,,,,,,,,,,,,,,,,,,,,,,,,,,,,,,,
,3881342978.47579,10.000027179718,-770.451538085938,1.17951751448662E-5,8.85494078540729E-9,1,4,14.0008964538574,4.994169410419,32.9700000584126,0.0146284058048567,0.00224720270018303,1,1.98210531429892E-8,,,,,,,,,,,,,,,,,,,,,9.99976062774658,10.0002937316895,-770.451538085938,-770.451538085938,53.4211827753518,5.87975013504954,3.84174823760986,56,1,0,0,1,0.330810546875,33.7243423461914,1,1,3,10.0002937316895,0,10.000027179718,,,,,,,,,,,,,,,,,,,,,,,,,,,,,,,,,
,3881343018.89946,10.0002555847168,-190.284057617187,2.56231936835614E-6,1.3353569560305E-7,1,4,14.0008964538574,4.99422832136154,32.9700000584126,0.00316998386755454,0.00053994621444574,1,4.603613832637E-8,,,,,,,,,,,,,,,,,,,,,10.0001287460327,10.0003824234009,-190.284057617187,-190.284057617187,53.5329556536018,5.87942412483465,3.8436541557312,56,1,0,0,1,0.327224731445313,34.2131004333496,1,1,3,10.0004253387451,0,10.0002555847168,,,,,,,,,,,,,,,,,,,,,,,,,,,,,,,,,
,3881343057.46951,10.0002312660217,389.757537841797,-6.86033697878223E-6,1.45901959880303E-8,1,4,14.0008964538574,4.99427911169088,32.9799987375736,-0.00851424111209598,-0.0012690633656711,1,1.91030827280441E-8,,,,,,,,,,,,,,,,,,,,,10.0002250671387,10.0002374649048,389.757537841797,389.757537841797,53.594704306621,5.88022270693334,3.84005904197693,56,1,0,0,1,0.325851440429687,33.7243423461914,1,1,3,10.0002374649048,0,10.0002312660217,,,,,,,,,,,,,,,,,,,,,,,,,,,,,,,,,
,3881343097.19648,9.99993133544922,969.786560058594,-1.62956898852649E-5,2.30828560897004E-8,1,4,14.0008964538574,4.99424312974888,32.9700000584126,-0.0202130714457021,-0.00308693725866885,1,-1.30657123953395E-8,,,,,,,,,,,,,,,,,,,,,9.99984264373779,10.0000200271606,969.786560058594,969.786560058594,53.547024966948,5.87925814716373,3.8367326259613,56,1,0,0,1,0.327072143554687,34.2131004333496,1,1,3,9.99984264373779,0,9.99993133544922,,,,,,,,,,,,,,,,,,,,,,,,,,,,,,,,,
,3881343136.47445,9.99986171722412,1549.51342773438,-2.57227275521542E-5,1.86428207459936E-8,1,4,14.0008964538574,4.99425957485055,32.9700000584126,-0.031916228968426,-0.00480841727297238,1,3.12334731465152E-8,,,,,,,,,,,,,,,,,,,,,9.9996919631958,10.0000314712524,1549.51342773438,1549.51342773438,53.5157598261787,5.87911429673274,3.8374171257019,56,1,0,0,1,0.327377319335937,34.2131004333496,1,1,3,9.9996919631958,0,9.99986171722412,,,,,,,,,,,,,,,,,,,,,,,,,,,,,,,,,
,3881343175.24274,9.99994277954102,2129.61791992187,-3.51926400924296E-5,3.97932078802905E-8,1,4,14.0008964538574,4.99431991830006,32.9700000584126,-0.0436648024102132,-0.00659349413448305,1,3.08587848902E-8,,,,,,,,,,,,,,,,,,,,,9.99972248077393,10.0001630783081,2129.61791992187,2129.61791992187,53.5020813270922,5.88006931844251,3.83707880973816,56,1,0,0,1,0.32684326171875,34.2131004333496,1,1,3,9.99976348876953,0,9.99994277954102,,,,,,,,,,,,,,,,,,,,,,,,,,,,,,,,,
,3881343214.46816,10.0000982284546,2709.609375,-4.45864217212171E-5,1.95132569762238E-8,1,4,14.0008964538574,4.99422394182162,32.9700000584126,-0.0553191804723245,-0.0083489101239901,1,4.25821278406641E-8,,,,,,,,,,,,,,,,,,,,,10.0000648498535,10.0001316070557,2709.609375,2709.609375,53.6177623479384,5.87973726526178,3.84223222732544,56,1,0,0,1,0.324478149414063,34.2131004333496,1,1,3,10.0001316070557,0,10.0000982284546,,,,,,,,,,,,,,,,,,,,,,,,,,,,,,,,,
,3881343272.06872,10.0001730918884,3499.59765625,-5.72853273482436E-5,2.31043936598428E-8,1,4,14.0008964538574,4.99430276920641,32.9700000584126,-0.0710758148457634,-0.0107316490454033,1,5.10002239287646E-8,,,,,,,,,,,,,,,,,,,,,10.0000410079956,10.0003051757813,3499.59765625,3499.59765625,53.4712070005826,5.88008133122562,3.84906578063965,56,1,0,0,1,0.328826904296875,33.7243423461914,1,1,3,10.0002326965332,0,10.0001730918884,,,,,,,,,,,,,,,,,,,,,,,,,,,,,,,,,
,3881343313.18393,9.99981641769409,4499.70947265625,-7.37085977703535E-5,2.65798073379777E-8,1,4,14.0008964538574,4.99427033563286,32.9700000584126,-0.0914523874298577,-0.013804878063335,1,6.83043152470816E-8,,,,,,,,,,,,,,,,,,,,,9.99978160858154,9.99985122680664,4499.70947265625,4499.70947265625,53.4989548130153,5.88020626687862,3.8503954410553,56,1,0,0,1,0.327072143554687,33.7243423461914,1,1,3,9.99985122680664,0,9.99981641769409,,,,,,,,,,,,,,,,,,,,,,,,,,,,,,,,,
,3881343355.211,9.99982404708862,5499.65771484375,-8.99355413338221E-5,4.0025870127729E-8,1,4,14.0008964538574,4.99417860710913,32.9700000584126,-0.111583064786925,-0.0168415448132063,1,8.49884004286574E-8,,,,,,,,,,,,,,,,,,,,,9.99982070922852,9.99982738494873,5499.65771484375,5499.65771484375,53.4934834133807,5.88029402698344,3.84810304641724,56,1,0,0,1,0.328826904296875,33.7243423461914,1,1,3,9.99982070922852,0,9.99982404708862,,,,,,,,,,,,,,,,,,,,,,,,,,,,,,,,,
,3881343396.01988,10.0002655982971,6499.54248046875,-0.000106090521062933,4.43188458343986E-8,1,4,14.0008964538574,4.99424012782347,32.9799987375736,-0.131626539557754,-0.0198821624504369,1,8.81192141121611E-8,,,,,,,,,,,,,,,,,,,,,10.0000801086426,10.0004510879517,6499.54248046875,6499.54248046875,53.4442408166691,5.87983156706691,3.8502345085144,54,1,32,0,0,0.3253173828125,33.7243423461914,1,1,3,10.0005483627319,0,10.0002655982971,,,,,,,,,,,,,,,,,,,,,,,,,,,,,,,,,
,3881343436.69133,9.99983024597168,7499.62939453125,-0.000122693482853454,4.8631286799954E-8,1,4,14.0008964538574,4.99434450259546,32.9700000584126,-0.1522294796363,-0.0229997253202088,1,9.75813298714002E-8,,,,,,,,,,,,,,,,,,,,,9.999755859375,9.99990463256836,7499.62939453125,7499.62939453125,53.5853247643903,5.87965738544322,3.85135912895203,56,1,0,0,1,0.329437255859375,33.2355842590332,1,1,3,9.99990463256836,0,9.99983024597168,,,,,,,,,,,,,,,,,,,,,,,,,,,,,,,,,
,3881343484.35112,9.99992847442627,8499.728515625,-0.000139255377902201,3.50507805961318E-8,1,4,14.0008964538574,4.9943204531308,32.9700000584126,-0.172798247464845,-0.0259653212386773,10,2.22691775488781E-7,,,,,,,,,,,,,,,,,,,,,9.99963092803955,10.000226020813,8499.728515625,8499.728515625,53.4008604338518,5.8807162294504,3.84623861312866,56,1,0,0,1,0.32684326171875,33.7243423461914,1,1,3,9.99963092803955,0,9.99992847442627,,,,,,,,,,,,,,,,,,,,,,,,,,,,,,,,,
,3881343537.64879,10.0001230239868,9499.7890625,-0.000159637958143373,7.30783551160021E-6,1,4,14.0008964538574,4.99425170052108,32.9700000584126,-0.199344055413929,-0.0214871881587099,10,6.92819408510659E-6,,,,,,,,,,,,,,,,,,,,,10.0000677108765,10.0001783370972,9499.7890625,9499.7890625,53.5626575373326,5.88015954291453,3.85117983818054,55,1,68,0,0,0.328826904296875,33.7243423461914,1,1,3,10.0001783370972,0,10.0001230239868,,,,,,,,,,,,,,,,,,,,,,,,,,,,,,,,,
,3881343595.78244,10.0001626014709,10499.5361328125,-0.000171486987333746,6.74797347642046E-8,1,4,14.0008964538574,4.99422245077471,32.9700000584126,-0.212753576129882,-0.0321991680171588,1,9.29634843775482E-8,,,,,,,,,,,,,,,,,,,,,9.99993705749512,10.0003881454468,10499.5361328125,10499.5361328125,53.4653447866883,5.8803721461529,3.8440535068512,53,1,100,0,0,0.328140258789063,33.7243423461914,1,1,3,10.0003881454468,0,10.0001626014709,,,,,,,,,,,,,,,,,,,,,,,,,,,,,,,,,
,3881343649.93016,10.0001044273376,11499.521484375,-0.000187736365784906,6.72329419907705E-8,1,4,14.0008964538574,4.99418122172235,32.9700000584126,-0.232899166163414,-0.0353244826204775,1,4.1583312969535E-8,,,,,,,,,,,,,,,,,,,,,10.0000286102295,10.0001802444458,11499.521484375,11499.521484375,53.4653447866883,5.87978430053081,3.84853482246399,53,1,68,0,0,0.327377319335937,33.7243423461914,1,1,3,10.0001802444458,0,10.0001044273376,,,,,,,,,,,,,,,,,,,,,,,,,,,,,,,,,
,3881343708.31497,9.99983882904053,12499.7841796875,-0.000207925978406548,4.98433473723521E-6,1,4,14.0008964538574,4.9942265405078,32.9700000584126,-0.258782304188452,-0.0336377801731279,10,4.46838940428105E-6,,,,,,,,,,,,,,,,,,,,,9.99969863891602,9.99997901916504,12499.7841796875,12499.7841796875,53.2601673003903,5.88045392943481,3.85409665107727,56,1,0,0,1,0.328903198242188,33.7243423461914,1,1,3,9.99997901916504,0,9.99983882904053,,,,,,,,,,,,,,,,,,,,,,,,,,,,,,,,,
,3881343761.5455,10.0000252723694,13499.5810546875,-0.000219765625449776,7.34339875626093E-6,1,4,14.0008964538574,4.99417979978756,32.9700000584126,-0.273275849150278,-0.037121894721621,10,3.45788421735226E-6,,,,,,,,,,,,,,,,,,,,,9.9999303817749,10.0001201629639,13499.5810546875,13499.5810546875,53.5798533647557,5.88064045848566,3.85655641555786,53,1,68,0,0,0.326919555664063,33.2355842590332,1,1,3,10.0001201629639,0,10.0000252723694,,,,,,,,,,,,,,,,,,,,,,,,,,,,,,,,,
,3881343814.99746,9.99997425079346,14499.4541015625,-0.000233896844965951,3.33915150853247E-6,1,4,14.0008964538574,4.9939939509575,32.9700000584126,-0.290750067557196,-0.0400507203264461,10,3.24176503948869E-6,,,,,,,,,,,,,,,,,,,,,9.9996976852417,10.0002508163452,14499.4541015625,14499.4541015625,53.4344704601787,5.88060296577198,3.86028814315796,56,1,0,0,1,0.329513549804687,33.7243423461914,1,1,3,10.0002508163452,0,9.99997425079346,,,,,,,,,,,,,,,,,,,,,,,,,,,,,,,,,
,3881343878.6794,10.0001726150513,19999.7421875,-0.000328748339981059,9.35743964536463E-8,1,4,14.0008964538574,4.99411459901354,32.9700000584126,-0.407894551290139,-0.0614052872141597,10,4.36266320771535E-7,,,,,,,,,,,,,,,,,,,,,10.0001697540283,10.0001754760742,19999.7421875,19999.7421875,53.5661748656691,5.88090655052291,3.85203886032105,56,1,0,0,1,0.32958984375,33.7243423461914,1,1,3,10.0001697540283,0,10.0001726150513,,,,,,,,,,,,,,,,,,,,,,,,,,,,,,,,,
,3881343985.05526,10.0000782012939,30000.25390625,-0.000478766866567856,1.49058264548233E-5,1,4,14.0008964538574,4.99415565248858,32.9700000584126,-0.59568060104926,-0.0786065638173941,100,9.35832441980889E-6,,,,,,,,,,,,,,,,,,,,,9.99988174438477,10.0002746582031,30000.25390625,30000.25390625,53.6591886594576,5.88195518632639,3.8542799949646,55,1,68,0,0,0.329513549804687,33.2355842590332,1,1,3,10.0001811981201,0,10.0000782012939,,,,,,,,,,,,,,,,,,,,,,,,,,,,,,,,,
,3881344092.19754,10.0001001358032,40000.36328125,-0.000673798502301408,1.03357104539876E-5,1,4,14.0008964538574,4.99416484489442,32.9700000584126,-0.835142864936294,-0.131680271061391,100,-3.79983085874074E-6,,,,,,,,,,,,,,,,,,,,,9.99983882904053,10.0003614425659,40000.36328125,40000.36328125,53.7225005695153,5.88249839548144,3.86124897003174,52,1,68,0,0,0.33172607421875,33.7243423461914,1,1,3,9.99983882904053,0,10.0001001358032,,,,,,,,,,,,,,,,,,,,,,,,,,,,,,,,,
,3881344197.745,10.0002703666687,50000.14453125,-0.000760892608011633,5.03221357641614E-5,1,4,14.0008964538574,4.99414880236509,32.9700000584126,-0.945069274032469,-0.1356559940205,1000,6.2243343599319E-6,,,,,,,,,,,,,,,,,,,,,10.0001726150513,10.0003681182861,50000.14453125,50000.14453125,53.8221582057172,5.88204646270966,3.86913657188416,56,1,0,0,1,0.330810546875,33.7243423461914,1,1,3,10.0001726150513,0,10.0002703666687,,,,,,,,,,,,,,,,,,,,,,,,,,,,,,,,,
,3881344303.47387,10.0001511573792,60000.421875,-0.000960959565137913,3.04606135063469E-5,1,4,14.0008964538574,4.99414149920397,32.9700000584126,-1.19264025544541,-0.17738407726543,100,2.97631335549606E-6,,,,,,,,,,,,,,,,,,,,,10.0000925064087,10.0002098083496,60000.421875,60000.421875,53.9069649000538,5.8832615523494,3.87512016296387,56,1,0,0,1,0.328750610351562,33.7243423461914,1,1,3,10.0002098083496,0,10.0001511573792,,,,,,,,,,,,,,,,,,,,,,,,,,,,,,,,,
,3881344411.54632,10.0003519058228,70000.453125,-0.00117239219625194,3.88855023411999E-5,1,4,14.0008964538574,4.99415595077196,32.9799987375736,-1.45652255778096,-0.206743664542702,1000,1.14261288468052E-5,,,,,,,,,,,,,,,,,,,,,10.0002775192261,10.0004262924194,70000.453125,70000.453125,54.0746242174288,5.88374973580713,3.87874937057495,56,1,0,0,1,0.327072143554687,33.2355842590332,1,1,3,10.0002775192261,0,10.0003519058228,,,,,,,,,,,,,,,,,,,,,,,,,,,,,,,,,
,3881344421.97313,10.0004425048828,70000.453125,-0.00117121119573916,4.04903965833526E-5,1,4,14.0008964538574,4.99412598864938,32.9700000584126,-1.45453399410391,-0.209885347334521,100,8.71274922599604E-6,,,,,,,,,,,,,,,,,,,,,10.000415802002,10.0004692077637,70000.453125,70000.453125,54.0507845475923,5.88318914634134,3.87206149101257,54,2,68,0,0,0.330352783203125,33.2355842590332,1,1,3,10.0004692077637,0,10.0004425048828,,,,,,,,,,,,,,,,,,,,,,,,,,,,,,,,,