File: SQUID/Reference/LAO/C3/transfer_115386_files_71fd6f70/LAOsubs_22172_MH_5K_FC_p0d5T.dat
[Header]
; MPMS3 Data File (default extension .dat)
; Copyright (c) 2007, Quantum Design, Inc. All rights reserved.
TITLE,
FILEOPENTIME,3881328558.34957,12/27/2022,6:52 pm
BYAPP,SQUID AC,0.9.1.0
INFO,MPMS3 Measurement Release 1.1.16 Build 347, MultiVu Release 2.3.3.2,APPNAME
INFO,0,MOMENT_UNITS
INFO,LAO,SAMPLE_MATERIAL
INFO,,SAMPLE_COMMENT
INFO,,SAMPLE_MASS
INFO,,SAMPLE_VOLUME
INFO,,SAMPLE_MOLECULAR_WEIGHT
INFO,,SAMPLE_SIZE
INFO,,SAMPLE_SHAPE
INFO,Quartz,SAMPLE_HOLDER
INFO,Standard,SAMPLE_HOLDER_DETAIL
INFO,65.74,SAMPLE_OFFSET
DATATYPE,COMMENT,1
DATATYPE,TIME,2
STARTUPAXIS,X,2
STARTUPAXIS,Y1,5
FIELDGROUP, VSM,2,3,4,5,6,8,9,10,11,14,15
FIELDGROUP, DC, 2,3,4,14,56,57,58,59,60,61,62,63,64,65,66,67,68,69
FIELDGROUP, AC, 2,3,4,11,16,17,18,19,20,21,22,23,24,25,26,27,28,29,30
STARTUPGROUP, All
[Data]
Comment,Time Stamp (sec),Temperature (K),Magnetic Field (Oe),Moment (emu),M. Std. Err. (emu),Transport Action,Averaging Time (sec),Frequency (Hz),Peak Amplitude (mm),Center Position (mm),Lockin Signal' (V),Lockin Signal (V),Range,M. Quad. Signal (emu),AC Moment (emu),AC M. Std Err. (emu),AC Phase (deg),AC Phase Std. Err. (deg),AC Susceptibility (emu/Oe),AC Suscept. Std Err. (emu/Oe),AC X' (emu/Oe),AC X' Std Err. (emu/Oe),AC X'' (emu/Oe),AC X'' Std Err. (emu/Oe),AC Drive (Oe),AC Frequency (Hz),AC Averaging Time (sec),AC Cycles,AC Range,AC Measure Type,AC Signal' (V),AC Signal'' (V),AC Trim Coil Ratio,AC Trim Coil Phase,Min. Temperature (K),Max. Temperature (K),Min. Field (Oe),Max. Field (Oe),Mass (grams),Motor Lag (deg),Pressure (Torr),Measure Count,Measurement Number,SQUID Status (code),Motor Status (code),Measure Status (code),Motor Current (amps),Motor Temp. (C),Temp. Status (code),Field Status (code),Chamber Status (code),Chamber Temp (K),Redirection State,Average Temp (K),Rotation Angle (deg),Rotator state,DC Moment Fixed Ctr (emu),DC Moment Err Fixed Ctr (emu),DC Moment Free Ctr (emu),DC Moment Err Free Ctr (emu),DC Fixed Fit,DC Free Fit,DC Calculated Center (mm),DC Calculated Center Err (mm),DC Scan Length (mm),DC Scan Time (s),DC Number of Points,DC Squid Drift,DC Min V (V),DC Max V (V),DC Scans per Measure,Map 01,Map 02,Map 03,Map 04,Map 05,Map 06,Map 07,Map 08,Map 09,Map 10,Map 11,Map 12,Map 13,Map 14,Map 15,Map 16
,3881328684.01028,5.00071215629578,70000.3046875,-0.0011835548299719,1.23385336908941E-5,1,4,14.0008964538574,5.00690082693426,32.9700000584126,-1.4745391256442,-0.21673266197399,10,5.69144722936212E-6,,,,,,,,,,,,,,,,,,,,,5.00060653686523,5.00081777572632,70000.3046875,70000.3046875,54.6686618920442,5.87395464746456,7.5199294090271,56,1,0,0,1,0.3314208984375,31.7693061828613,1,1,3,5.00060653686523,0,5.00071215629578,,,,,,,,,,,,,,,,,,,,,,,,,,,,,,,,,
,3881328735.37395,5.00011467933655,65000.24609375,-0.00114312536270005,0.000116846365724274,1,4,14.0008964538574,5.00683837231792,32.9700000584126,-1.42703217615706,-0.190318334350192,100,2.07648005732654E-5,,,,,,,,,,,,,,,,,,,,,4.99996566772461,5.00026369094849,65000.24609375,65000.24609375,54.5072556028231,5.87377927206213,7.54188203811646,39,1,68,0,0,0.32989501953125,33.2355842590332,1,1,3,4.99996566772461,0,5.00011467933655,,,,,,,,,,,,,,,,,,,,,,,,,,,,,,,,,
,3881328791.68755,5.00019383430481,60000.421875,-0.00100904684134014,3.2903694513529E-5,1,4,14.0008964538574,5.00679946476088,32.9700000584126,-1.25286552425458,-0.212593618214206,10,-1.74963802381513E-5,,,,,,,,,,,,,,,,,,,,,4.99951457977295,5.00087308883667,60000.421875,60000.421875,54.4498059066596,5.87382370606885,7.54143190383911,44,1,68,0,0,0.326919555664063,32.7468223571777,1,1,3,4.99951457977295,0,5.00019383430481,,,,,,,,,,,,,,,,,,,,,,,,,,,,,,,,,
,3881328847.66313,5.00017809867859,55000.3359375,-0.001559050576831,0.00126857873042225,1,4,14.0008964538574,5.00677060146485,32.9700000584126,-2.13301636143441,0.970177420449061,1000,0.00101613953274662,,,,,,,,,,,,,,,,,,,,,4.99937009811401,5.00098609924316,55000.3359375,55000.3359375,54.1156597146884,5.87333244446575,7.54969787597656,56,1,0,0,1,0.3289794921875,33.2355842590332,1,1,3,4.99937009811401,0,5.00017809867859,,,,,,,,,,,,,,,,,,,,,,,,,,,,,,,,,
,3881328904.03028,4.99994468688965,50000.28125,-0.00274228639023835,0.00251785462484612,1,4,14.0008964538574,5.00674195518066,32.9700000584126,-4.06129068720034,3.74374013282677,1000,0.00342383383800429,,,,,,,,,,,,,,,,,,,,,4.9996452331543,5.000244140625,50000.28125,50000.28125,54.2915261315154,5.87345187953989,7.57003307342529,52,1,68,0,0,0.32958984375,33.2355842590332,1,1,3,4.9996452331543,0,4.99994468688965,,,,,,,,,,,,,,,,,,,,,,,,,,,,,,,,,
,3881328959.37759,4.99983263015747,45000.37890625,-0.000732428324078096,1.13847977120619E-5,1,4,14.0008964538574,5.00672378701434,32.9700000584126,-0.911109875182242,-0.142972804504925,1000,-3.59270761947385E-6,,,,,,,,,,,,,,,,,,,,,4.99963808059692,5.00002717971802,45000.37890625,45000.37890625,53.9429198119384,5.87287053663332,7.59082126617432,56,1,0,0,1,0.327606201171875,33.2355842590332,1,1,3,5.00002717971802,0,4.99983263015747,,,,,,,,,,,,,,,,,,,,,,,,,,,,,,,,,
,3881329015.95129,5.00020599365234,40000.4921875,-0.000437152797664145,0.000275090877910571,1,4,14.0008964538574,5.00661602603983,32.9700000584126,-0.532953641658483,-0.156625832402678,1000,-5.94159849748497E-5,,,,,,,,,,,,,,,,,,,,,4.99933433532715,5.00107765197754,40000.4921875,40000.4921875,54.0374968627653,5.87384081796836,7.58321809768677,56,1,0,0,1,0.329818725585937,33.2355842590332,1,1,3,5.00107765197754,0,5.00020599365234,,,,,,,,,,,,,,,,,,,,,,,,,,,,,,,,,
,3881329071.49924,4.99981760978699,35000.34765625,-0.000547178266244419,2.87473455923254E-7,1,4,14.0008964538574,5.00664959906037,32.9700000584126,-0.681355881775665,-0.102178718886447,1000,1.03556107585837E-6,,,,,,,,,,,,,,,,,,,,,4.99964094161987,4.9999942779541,35000.34765625,35000.34765625,53.8651477742749,5.87234964096815,7.5844144821167,56,1,0,0,1,0.326309204101562,33.7243423461914,1,1,3,4.99993658065796,0,4.99981760978699,,,,,,,,,,,,,,,,,,,,,,,,,,,,,,,,,
,3881329127.35045,4.99971222877502,30000.228515625,-0.000471712863919503,8.7287678159816E-5,1,4,14.0008964538574,5.00667891716644,32.9700000584126,-0.563694896810643,-0.244078315677527,1000,-0.000124414431097405,,,,,,,,,,,,,,,,,,,,,4.99950790405273,4.99991655349731,30000.228515625,30000.228515625,53.7639268810345,5.87209159260911,7.59021854400635,56,1,0,0,1,0.3265380859375,33.2355842590332,1,1,3,4.99950790405273,0,4.99971222877502,,,,,,,,,,,,,,,,,,,,,,,,,,,,,,,,,
,3881329182.7137,4.99981093406677,25000.173828125,-0.000188140999207278,0.000149815293239168,1,4,14.0008964538574,5.006725304061,32.9700000584126,-0.243208080925701,0.0236333536114133,1000,4.7562870922116E-5,,,,,,,,,,,,,,,,,,,,,4.99949789047241,5.00012397766113,25000.173828125,25000.173828125,53.7318801117461,5.87175928869478,7.62595701217651,56,1,0,0,1,0.326309204101562,33.7243423461914,1,1,3,5.00012397766113,0,4.99981093406677,,,,,,,,,,,,,,,,,,,,,,,,,,,,,,,,,
,3881329238.95732,5.00029635429382,19999.8046875,-0.000245486810673667,0.000144725417164579,1,4,14.0008964538574,5.00666925949698,32.9700000584126,-0.312019861729433,-0.00414491291019936,1000,3.3959709570385E-5,,,,,,,,,,,,,,,,,,,,,4.99943494796753,5.00115776062012,19999.8046875,19999.8046875,53.7010057852365,5.8725637548741,7.6328821182251,56,1,0,0,1,0.327529907226562,33.2355842590332,1,1,3,4.99943494796753,0,5.00029635429382,,,,,,,,,,,,,,,,,,,,,,,,,,,,,,,,,
,3881329286.85385,4.99946355819702,14999.5107421875,-0.000235704625495902,1.84785010731785E-5,1,4,14.0008964538574,5.00672643036322,32.9700000584126,-0.295581472628374,-0.0303773374934353,100,1.14017075566431E-5,,,,,,,,,,,,,,,,,,,,,4.99945211410522,4.99947500228882,14999.5107421875,14999.5107421875,53.5864972071691,5.8712978593757,7.61409997940063,54,1,68,0,0,0.330810546875,33.7243423461914,1,1,3,4.99947500228882,0,4.99946355819702,,,,,,,,,,,,,,,,,,,,,,,,,,,,,,,,,
,3881329337.47792,5.00066018104553,9999.6943359375,-0.000165073690622815,4.21302317648831E-5,1,4,14.0008964538574,5.00663359943624,32.9700000584126,-0.194085999979136,-0.106307536106263,1000,-6.03229930843675E-5,,,,,,,,,,,,,,,,,,,,,5.00063753128052,5.00068283081055,9999.6943359375,9999.6943359375,53.5669564941884,5.87110264953286,7.63798046112061,56,1,0,0,1,0.32867431640625,33.2355842590332,1,1,3,5.00068283081055,0,5.00066018104553,,,,,,,,,,,,,,,,,,,,,,,,,,,,,,,,,
,3881329378.64067,4.99993586540222,9999.669921875,-0.00010897850584567,1.9764399529208E-5,1,4,14.0008964538574,5.00664335604763,32.9700000584126,-0.137255116006744,-0.0101236819953598,100,8.42137295828086E-6,,,,,,,,,,,,,,,,,,,,,4.99987888336182,4.99999284744263,9999.669921875,9999.669921875,53.508334355246,5.87170830696784,7.64433526992798,56,1,0,0,1,0.330352783203125,33.7243423461914,1,1,3,4.99987888336182,0,4.99993586540222,,,,,,,,,,,,,,,,,,,,,,,,,,,,,,,,,
,3881329397.34082,4.99978804588318,9499.890625,-0.000131800770982839,4.58551353113864E-6,1,4,14.0008964538574,5.00665321193782,32.9700000584126,-0.164440371172091,-0.0225081775611266,100,1.93958647643292E-6,,,,,,,,,,,,,,,,,,,,,4.99967050552368,4.99990558624268,9499.890625,9499.890625,53.5786809219768,5.87136482454126,7.63551092147827,56,1,0,0,1,0.326690673828125,34.2131004333496,1,1,3,4.99990558624268,0,4.99978804588318,,,,,,,,,,,,,,,,,,,,,,,,,,,,,,,,,
,3881329431.23193,4.99973368644714,8999.833984375,-0.000101102478885292,2.70957602231843E-5,1,4,14.0008964538574,5.00658299257688,32.9700000584126,-0.127483351010522,-0.0084043895394596,100,8.60601096563743E-6,,,,,,,,,,,,,,,,,,,,,4.99964761734009,4.9998197555542,8999.833984375,8999.833984375,53.4719886291018,5.87197889412468,7.63381910324097,52,1,68,0,0,0.328521728515625,33.7243423461914,1,1,3,4.99964761734009,0,4.99973368644714,,,,,,,,,,,,,,,,,,,,,,,,,,,,,,,,,
,3881329464.82585,5.00004100799561,8499.791015625,-9.64673714050285E-5,3.40677189929538E-5,1,4,14.0008964538574,5.00663176192649,32.9700000584126,-0.11473810549628,-0.053459425724034,100,-2.82910161396619E-5,,,,,,,,,,,,,,,,,,,,,4.99993848800659,5.00014352798462,8499.791015625,8499.791015625,53.4970007417172,5.87132492518702,7.64248704910278,54,1,68,0,0,0.328598022460937,33.7243423461914,1,1,3,5.00014352798462,0,5.00004100799561,,,,,,,,,,,,,,,,,,,,,,,,,,,,,,,,,
,3881329484.43539,4.99993133544922,7999.98681640625,-8.77630519802748E-5,2.84742389517198E-5,1,4,14.0008964538574,5.00659168244256,32.9700000584126,-0.112190221773913,0.0027552741620558,100,1.55445175237613E-5,,,,,,,,,,,,,,,,,,,,,4.99959516525269,5.00026750564575,7999.98681640625,7999.98681640625,53.5188863402557,5.87145232125603,7.66332578659058,56,1,0,0,1,0.328292846679687,33.7243423461914,1,1,3,5.00026750564575,0,4.99993133544922,,,,,,,,,,,,,,,,,,,,,,,,,,,,,,,,,
,3881329513.06557,4.99979066848755,7499.90625,-0.000101647812124786,1.66151147159858E-5,1,4,14.0008964538574,5.00659592959987,32.9700000584126,-0.123336727786068,-0.0402781361846225,1000,-1.69158049161E-5,,,,,,,,,,,,,,,,,,,,,4.99963235855103,4.99994897842407,7499.90625,7499.90625,53.3586524938133,5.87155155182402,7.63965797424316,56,1,0,0,1,0.331344604492188,33.7243423461914,1,1,3,4.99963235855103,0,4.99979066848755,,,,,,,,,,,,,,,,,,,,,,,,,,,,,,,,,
,3881329538.06691,4.99949884414673,6999.69921875,-0.000107075139927139,2.48851729670453E-5,1,4,14.0008964538574,5.00655846170223,32.9700000584126,-0.138667695207097,0.0151555492704941,100,2.84394717734878E-5,,,,,,,,,,,,,,,,,,,,,4.99941349029541,4.99958419799805,6999.69921875,6999.69921875,53.427044989246,5.87074261043734,7.64423942565918,54,1,68,0,0,0.33050537109375,33.7243423461914,1,1,3,4.99941349029541,0,4.99949884414673,,,,,,,,,,,,,,,,,,,,,,,,,,,,,,,,,
,3881329557.11315,4.99961256980896,6499.58056640625,-9.13663590159596E-5,2.40876294209198E-6,1,4,14.0008964538574,5.00663884523065,32.9700000584126,-0.11333272418431,-0.0199443805952764,100,-2.14293819366241E-6,,,,,,,,,,,,,,,,,,,,,4.99887895584106,5.00034618377686,6499.58056640625,6499.58056640625,53.4977823702364,5.87125967538491,7.63009214401245,56,1,0,0,1,0.326919555664063,33.7243423461914,1,1,3,5.00034618377686,0,4.99961256980896,,,,,,,,,,,,,,,,,,,,,,,,,,,,,,,,,
,3881329582.63972,4.99978518486023,5999.8017578125,-8.54835962334374E-5,1.64171231121966E-8,1,4,14.0008964538574,5.00653650563938,32.9700000584126,-0.106422679117431,-0.0160916443535517,10,5.80297092962591E-8,,,,,,,,,,,,,,,,,,,,,4.99961471557617,4.99995565414429,5999.8017578125,5999.8017578125,53.3836646064287,5.87091313465986,7.65760803222656,56,1,0,0,1,0.329360961914063,33.2355842590332,1,1,3,4.99995565414429,0,4.99978518486023,,,,,,,,,,,,,,,,,,,,,,,,,,,,,,,,,
,3881329611.42326,5.00032091140747,5499.58203125,-8.025511989643E-5,2.19688098893761E-6,1,4,14.0008964538574,5.00653299631297,32.9700000584126,-0.0997525332325154,-0.0161664240609449,100,-7.96258455969974E-7,,,,,,,,,,,,,,,,,,,,,4.99980163574219,5.00084018707275,5499.58203125,5499.58203125,53.6048654773711,5.87116275371342,7.66150617599487,56,1,0,0,1,0.329132080078125,33.7243423461914,1,1,3,5.00084018707275,0,5.00032091140747,,,,,,,,,,,,,,,,,,,,,,,,,,,,,,,,,
,3881329644.58367,5.00004124641418,4999.80322265625,-6.01710297280744E-5,1.50596373469799E-5,1,4,14.0008964538574,5.00648371236821,32.9700000584126,-0.072038892666673,-0.0302195942432198,100,-1.51366834788515E-5,,,,,,,,,,,,,,,,,,,,,4.99952554702759,5.00055694580078,4999.80322265625,4999.80322265625,53.5141965691403,5.87191951355383,7.65581798553467,54,1,68,0,0,0.329208374023438,33.7243423461914,1,1,3,5.00055694580078,0,5.00004124641418,,,,,,,,,,,,,,,,,,,,,,,,,,,,,,,,,
,3881329669.85929,5.00082635879517,4499.5458984375,-6.366966872379E-5,2.38584116753963E-6,1,4,14.0008964538574,5.00650595916891,32.9700000584126,-0.0787726007643816,-0.0152254353731494,10,-2.55974778171871E-6,,,,,,,,,,,,,,,,,,,,,5.00070238113403,5.0009503364563,4499.5458984375,4499.5458984375,53.452447916121,5.87119457179738,7.66337585449219,56,1,0,0,1,0.3265380859375,33.7243423461914,1,1,3,5.00070238113403,0,5.00082635879517,,,,,,,,,,,,,,,,,,,,,,,,,,,,,,,,,
,3881329689.62089,5.00077056884766,3999.8046875,-6.03934932012004E-5,9.01544343711618E-6,1,4,14.0008964538574,5.00649567982415,32.9700000584126,-0.0749042577894666,-0.0132228547470194,10,-1.44868301055886E-6,,,,,,,,,,,,,,,,,,,,,5.00076389312744,5.00077724456787,3999.8046875,3999.8046875,53.547024966948,5.87085077524487,7.65569591522217,56,1,0,0,1,0.3265380859375,33.7243423461914,1,1,3,5.00077724456787,0,5.00077056884766,,,,,,,,,,,,,,,,,,,,,,,,,,,,,,,,,
,3881329710.64773,4.99989724159241,3499.76147460937,-4.92018102897144E-5,2.25302752606095E-8,1,4,14.0008964538574,5.00647392022826,32.9700000584126,-0.0612454035457703,-0.00930942656845346,10,-4.93337128332317E-9,,,,,,,,,,,,,,,,,,,,,4.99936962127686,5.00042486190796,3499.76147460937,3499.76147460937,53.5829798788326,5.87136325157465,7.66657018661499,56,1,0,0,1,0.328140258789063,32.7468223571777,1,1,3,5.00042486190796,0,4.99989724159241,,,,,,,,,,,,,,,,,,,,,,,,,,,,,,,,,
,3881329730.71709,4.99951553344727,2999.56713867188,-4.21624172350229E-5,6.4356671903942E-8,1,4,14.0008964538574,5.00642046773119,32.9700000584126,-0.0524885713966235,-0.00793497296545191,10,2.98490227194915E-8,,,,,,,,,,,,,,,,,,,,,4.99938297271729,4.99964809417725,2999.56713867188,2999.56713867188,53.4286082462845,5.87122935177874,7.66592931747437,56,1,0,0,1,0.330352783203125,33.2355842590332,1,1,3,4.99938297271729,0,4.99951553344727,,,,,,,,,,,,,,,,,,,,,,,,,,,,,,,,,
,3881329768.80157,4.99957895278931,2999.59228515625,-4.21844809625257E-5,1.89261144803942E-8,1,4,14.0008964538574,5.00643876810771,32.9700000584126,-0.0525182614766079,-0.00792630047693182,10,4.02001192923831E-8,,,,,,,,,,,,,,,,,,,,,4.99928092956543,4.99987697601318,2999.59228515625,2999.59228515625,53.5696921940057,5.87129216057341,7.67784309387207,56,1,0,0,1,0.32928466796875,33.7243423461914,1,1,3,4.99987697601318,0,4.99957895278931,,,,,,,,,,,,,,,,,,,,,,,,,,,,,,,,,
,3881329786.28382,4.99990081787109,2949.65478515625,-4.14155300272147E-5,1.86468998208982E-8,1,4,14.0008964538574,5.00646523335656,32.9700000584126,-0.051571200807253,-0.00771685615381345,10,9.1699967456318E-8,,,,,,,,,,,,,,,,,,,,,4.99938774108887,5.00041389465332,2949.65478515625,2949.65478515625,53.5536688093614,5.87125004282416,7.65912675857544,56,1,0,0,1,0.32684326171875,33.7243423461914,1,1,3,4.99938774108887,0,4.99990081787109,,,,,,,,,,,,,,,,,,,,,,,,,,,,,,,,,
,3881329812.85458,4.99991083145142,2899.78002929687,-4.07443973429454E-5,2.67781365005974E-8,1,4,14.0008964538574,5.00642509953207,32.9700000584126,-0.0507451145348948,-0.00752466159868978,1,1.44086032742738E-7,,,,,,,,,,,,,,,,,,,,,4.9999041557312,4.99991750717163,2899.78002929687,2899.78002929687,53.5427260100922,5.87190484055442,7.68178129196167,56,1,0,0,1,0.326614379882812,33.2355842590332,1,1,3,4.9999041557312,0,4.99991083145142,,,,,,,,,,,,,,,,,,,,,,,,,,,,,,,,,
,3881329832.10166,4.99986028671265,2849.72924804687,-4.00519013137257E-5,2.13236260645813E-8,1,4,14.0008964538574,5.00641379293852,32.9700000584126,-0.049890195322512,-0.00734600715959308,1,1.82400359328934E-7,,,,,,,,,,,,,,,,,,,,,4.99944925308228,5.00027132034302,2849.72924804687,2849.72924804687,53.5665656799287,5.87134006827228,7.66545724868774,54,1,68,0,0,0.32745361328125,34.2131004333496,1,1,3,5.00027132034302,0,4.99986028671265,,,,,,,,,,,,,,,,,,,,,,,,,,,,,,,,,
,3881329863.58934,4.9998722076416,2799.80419921875,-3.94961434260851E-5,1.95897285723318E-8,1,4,14.0008964538574,5.00647696895551,32.9700000584126,-0.0492083768416535,-0.00718108785612276,1,2.30571791454418E-7,,,,,,,,,,,,,,,,,,,,,4.99966716766357,5.00007724761963,2799.80419921875,2799.80419921875,53.445413259448,5.87170252999899,7.69542074203491,55,1,68,0,0,0.3302001953125,34.2131004333496,1,1,3,5.00007724761963,0,4.9998722076416,,,,,,,,,,,,,,,,,,,,,,,,,,,,,,,,,
,3881329882.77117,5.00011610984802,2749.8037109375,-3.86710712156818E-5,2.2631375152809E-8,1,4,14.0008964538574,5.00652679822044,32.9700000584126,-0.0481788774248756,-0.00704571983407603,1,2.14069375330025E-7,,,,,,,,,,,,,,,,,,,,,5.00007390975952,5.00015830993652,2749.8037109375,2749.8037109375,53.4485397735249,5.87084638542102,7.6929235458374,52,1,68,0,0,0.334930419921875,33.2355842590332,1,1,3,5.00007390975952,0,5.00011610984802,,,,,,,,,,,,,,,,,,,,,,,,,,,,,,,,,
,3881329913.92962,4.99992775917053,2699.76538085938,-3.79223846946319E-5,2.7576550854649E-8,1,4,14.0008964538574,5.00645312860046,32.9700000584126,-0.0472474071276838,-0.00689427255869347,1,2.21892655243488E-7,,,,,,,,,,,,,,,,,,,,,4.99954080581665,5.00031471252441,2699.76538085938,2699.76538085938,53.528656696746,5.87112988422316,7.68840217590332,56,1,0,0,1,0.327682495117188,33.7243423461914,1,1,3,5.00031471252441,0,4.99992775917053,,,,,,,,,,,,,,,,,,,,,,,,,,,,,,,,,
,3881329932.13767,4.99935555458069,2649.6640625,-3.73430704150177E-5,2.11256907645411E-8,1,4,14.0008964538574,5.00643843269785,32.9700000584126,-0.046522856708305,-0.00680599760245526,1,2.04788161658835E-7,,,,,,,,,,,,,,,,,,,,,4.99927520751953,4.99943590164185,2649.6640625,2649.6640625,53.5614850945537,5.87098808781617,7.70813465118408,56,1,0,0,1,0.328521728515625,33.2355842590332,1,1,3,4.99943590164185,0,4.99935555458069,,,,,,,,,,,,,,,,,,,,,,,,,,,,,,,,,
,3881329949.96525,5.00045084953308,2599.81469726562,-3.6518457465727E-5,3.58047188257499E-8,1,4,14.0008964538574,5.00635554461276,32.9700000584126,-0.0455005444002859,-0.0066156410850826,1,2.3232995007706E-7,,,,,,,,,,,,,,,,,,,,,5.00020217895508,5.00069952011108,2599.81469726562,2599.81469726562,53.5141965691403,5.87104585946442,7.7104640007019,53,1,100,0,0,0.327072143554687,33.7243423461914,1,1,3,5.00069952011108,0,5.00045084953308,,,,,,,,,,,,,,,,,,,,,,,,,,,,,,,,,
,3881329981.49192,5.00010633468628,2549.7763671875,-3.57845448937772E-5,2.20901847161178E-8,1,4,14.0008964538574,5.00637785443322,32.9700000584126,-0.0445865342703824,-0.00648181867786313,1,2.28390305282564E-7,,,,,,,,,,,,,,,,,,,,,4.99965810775757,5.00055456161499,2549.7763671875,2549.7763671875,53.4766784002172,5.87144819573949,7.68931818008423,55,1,68,0,0,0.330581665039063,33.7243423461914,1,1,3,5.00055456161499,0,5.00010633468628,,,,,,,,,,,,,,,,,,,,,,,,,,,,,,,,,
,3881330000.01993,5.00023889541626,2499.86376953125,-3.51566530053756E-5,2.73374089204048E-8,1,4,14.0008964538574,5.00639984966722,32.9700000584126,-0.0438000302356032,-0.00639733830600419,1,2.00913962759076E-7,,,,,,,,,,,,,,,,,,,,,5.00023794174194,5.00023984909058,2499.86376953125,2499.86376953125,53.5767268506787,5.87165546205,7.7061767578125,56,1,0,0,1,0.326919555664063,33.2355842590332,1,1,3,5.00023794174194,0,5.00023889541626,,,,,,,,,,,,,,,,,,,,,,,,,,,,,,,,,
,3881330017.31575,5.00005769729614,2449.87573242187,-3.45675409134637E-5,1.6364026070785E-8,1,4,14.0008964538574,5.00649634814655,32.9700000584126,-0.043068085127244,-0.00628476891750021,1,2.01997900751991E-7,,,,,,,,,,,,,,,,,,,,,5.00001811981201,5.00009727478027,2449.87573242187,2449.87573242187,53.5704738225249,5.8713519428604,7.71991014480591,54,1,68,0,0,0.327072143554687,33.7243423461914,1,1,3,5.00001811981201,0,5.00005769729614,,,,,,,,,,,,,,,,,,,,,,,,,,,,,,,,,
,3881330035.49557,4.99962186813354,2399.98852539062,-3.37946941794722E-5,2.36126182060831E-8,1,4,14.0008964538574,5.0064433151135,32.9700000584126,-0.0421046224237476,-0.00614377571418514,1,1.97794984754646E-7,,,,,,,,,,,,,,,,,,,,,4.99961423873901,4.99962949752808,2399.98852539062,2399.98852539062,53.5208404115537,5.8712113782651,7.72511768341064,56,1,0,0,1,0.32867431640625,33.2355842590332,1,1,3,4.99962949752808,0,4.99962186813354,,,,,,,,,,,,,,,,,,,,,,,,,,,,,,,,,
,3881330062.0124,5.00012016296387,2349.87451171875,-3.30986217721762E-5,2.08843247537333E-8,1,4,14.0008964538574,5.0065149605384,32.9700000584126,-0.0412476699884245,-0.00595510532169664,10,2.43725993759746E-7,,,,,,,,,,,,,,,,,,,,,4.99984121322632,5.00039911270142,2349.87451171875,2349.87451171875,53.531783210823,5.8709693461289,7.71834230422974,56,1,0,0,1,0.326995849609375,33.7243423461914,1,1,3,5.00045585632324,0,5.00012016296387,,,,,,,,,,,,,,,,,,,,,,,,,,,,,,,,,
,3881330085.63137,4.99985218048096,2299.91186523438,-3.22911891882503E-5,2.75950954407444E-8,1,4,14.0008964538574,5.00640211896267,32.9700000584126,-0.0402267266485129,-0.00589818584733026,1,1.66653439588025E-7,,,,,,,,,,,,,,,,,,,,,4.99971294403076,4.99999141693115,2299.91186523438,2299.91186523438,53.4434591881499,5.87169462153386,7.72373247146606,56,1,0,0,1,0.330352783203125,33.7243423461914,1,1,3,4.99998188018799,0,4.99985218048096,,,,,,,,,,,,,,,,,,,,,,,,,,,,,,,,,
,3881330103.42706,4.99964833259583,2249.94897460938,-3.1654679854759E-5,2.21994554705438E-8,1,4,14.0008964538574,5.00644790619047,32.9700000584126,-0.0394436103021671,-0.0057207036283247,1,2.12608720096763E-7,,,,,,,,,,,,,,,,,,,,,4.99955892562866,4.99973773956299,2249.94897460938,2249.94897460938,53.5282658824864,5.87145558334377,7.72367238998413,56,1,0,0,1,0.326995849609375,33.7243423461914,1,1,3,4.99964284896851,0,4.99964833259583,,,,,,,,,,,,,,,,,,,,,,,,,,,,,,,,,
,3881330123.01536,4.99941682815552,2199.89819335938,-3.08976999045155E-5,2.14112741889065E-8,1,4,14.0008964538574,5.00638061634412,32.9700000584126,-0.0384970648533839,-0.00560078067328545,1,1.93879278591343E-7,,,,,,,,,,,,,,,,,,,,,4.99924516677856,4.99958848953247,2199.89819335938,2199.89819335938,53.506380283948,5.87148883294189,7.73225021362305,56,1,0,0,1,0.328903198242188,33.7243423461914,1,1,3,4.99924516677856,0,4.99941682815552,,,,,,,,,,,,,,,,,,,,,,,,,,,,,,,,,
,3881330141.46846,4.9999566078186,2149.89770507813,-3.02428103476574E-5,2.2214834410293E-8,1,4,14.0008964538574,5.00647951337219,32.9700000584126,-0.0376849691802767,-0.00546362413969847,1,2.04709728935843E-7,,,,,,,,,,,,,,,,,,,,,4.99994325637817,4.99996995925903,2149.89770507813,2149.89770507813,53.4762875859576,5.87102546057232,7.74121046066284,56,1,0,0,1,0.32958984375,33.2355842590332,1,1,3,4.99996995925903,0,4.9999566078186,,,,,,,,,,,,,,,,,,,,,,,,,,,,,,,,,
,3881330159.8361,4.99976849555969,2100.02294921875,-2.94758464108573E-5,2.88252751852945E-8,1,4,14.0008964538574,5.00642336878427,32.9700000584126,-0.036726842029039,-0.00533717861847017,1,1.89720050092047E-7,,,,,,,,,,,,,,,,,,,,,4.9996542930603,4.99988269805908,2100.02294921875,2100.02294921875,53.567347308448,5.8714988621333,7.72804307937622,56,1,0,0,1,0.326156616210937,33.7243423461914,1,1,3,4.99988269805908,0,4.99976849555969,,,,,,,,,,,,,,,,,,,,,,,,,,,,,,,,,
,3881330177.52151,4.99944758415222,2050.123046875,-2.88157480454825E-5,2.00311418177812E-8,1,4,14.0008964538574,5.00641204546895,32.9700000584126,-0.0359105426652445,-0.005176194322234,1,2.18765733778915E-7,,,,,,,,,,,,,,,,,,,,,4.99929857254028,4.99959659576416,2050.123046875,2050.123046875,53.4622182726114,5.8709855394027,7.74081420898438,56,1,0,0,1,0.32806396484375,33.2355842590332,1,1,3,4.99959659576416,0,4.99944758415222,,,,,,,,,,,,,,,,,,,,,,,,,,,,,,,,,
,3881330195.83903,5.00044226646423,2000.02185058594,-2.80381091036484E-5,3.6984945421911E-8,1,4,14.0008964538574,5.00641127116983,32.9700000584126,-0.0349404603487008,-0.0050429008197161,1,2.07724162137664E-7,,,,,,,,,,,,,,,,,,,,,4.99983072280884,5.00105381011963,2000.02185058594,2000.02185058594,53.5372546104576,5.87089936149363,7.76055145263672,56,1,0,0,1,0.329742431640625,33.2355842590332,1,1,3,4.99983072280884,0,5.00044226646423,,,,,,,,,,,,,,,,,,,,,,,,,,,,,,,,,
,3881330213.32887,5.00042295455933,1949.99621582031,-2.7331048538237E-5,2.30804242861193E-8,1,4,14.0008964538574,5.00638154408621,32.9700000584126,-0.0340621897396333,-0.00489504964665165,1,2.19066666881991E-7,,,,,,,,,,,,,,,,,,,,,5.00003480911255,5.0008111000061,1949.99621582031,1949.99621582031,53.3652963362268,5.87084519760435,7.76716661453247,54,1,68,0,0,0.328369140625,33.7243423461914,1,1,3,5.00003480911255,0,5.00042295455933,,,,,,,,,,,,,,,,,,,,,,,,,,,,,,,,,
,3881330231.32306,4.99986863136292,1900.08374023438,-2.66078171956755E-5,2.54286858460928E-8,1,4,14.0008964538574,5.00643124943763,32.9700000584126,-0.033164166598516,-0.00474671146971677,1,2.28430644584141E-7,,,,,,,,,,,,,,,,,,,,,4.99955368041992,5.00018358230591,1900.08374023438,1900.08374023438,53.5407719387941,5.87066875829611,7.76899766921997,55,1,68,0,0,0.326919555664063,33.7243423461914,1,1,3,4.99955368041992,0,4.99986863136292,,,,,,,,,,,,,,,,,,,,,,,,,,,,,,,,,
,3881330249.25856,4.99993443489075,1850.12097167969,-2.58913461743795E-5,2.58975552079787E-8,1,4,14.0008964538574,5.00642565733508,32.9700000584126,-0.0322752395632789,-0.00459164891241716,1,2.44163212676041E-7,,,,,,,,,,,,,,,,,,,,,4.99932098388672,5.00054788589478,1850.12097167969,1850.12097167969,53.5650024228903,5.87106003837307,7.76449775695801,55,1,68,0,0,0.329055786132812,34.2131004333496,1,1,3,5.00054788589478,0,4.99993443489075,,,,,,,,,,,,,,,,,,,,,,,,,,,,,,,,,
,3881330267.60674,4.99950337409973,1799.66723632813,-2.52172665352088E-5,2.10535394835662E-8,1,4,14.0008964538574,5.00636245998283,32.9700000584126,-0.0314328570849903,-0.00448218984056578,1,2.29641683596243E-7,,,,,,,,,,,,,,,,,,,,,4.99936962127686,4.99963712692261,1799.66723632813,1799.66723632813,53.5403811245345,5.87160209197462,7.75304460525513,56,1,0,0,1,0.326995849609375,33.7243423461914,1,1,3,4.99963712692261,0,4.99950337409973,,,,,,,,,,,,,,,,,,,,,,,,,,,,,,,,,
,3881330284.61071,5.00039315223694,1749.84289550781,-2.44227860596186E-5,2.46433939548786E-8,1,4,14.0008964538574,5.00630009485351,32.9700000584126,-0.0304354091723347,-0.0043844328463667,1,1.87434012650411E-7,,,,,,,,,,,,,,,,,,,,,5.00003147125244,5.00075483322144,1749.84289550781,1749.84289550781,53.5474157812076,5.87106311274965,7.75850200653076,54,1,68,0,0,0.327301025390625,33.7243423461914,1,1,3,5.00046491622925,0,5.00039315223694,,,,,,,,,,,,,,,,,,,,,,,,,,,,,,,,,
,3881330304.19503,5.00014019012451,1699.75427246094,-2.37980877301963E-5,2.32502531686491E-8,1,4,14.0008964538574,5.00633033897022,32.9700000584126,-0.0296630338179802,-0.00423370150486522,1,2.13666234097326E-7,,,,,,,,,,,,,,,,,,,,,4.99951028823853,5.0007700920105,1699.75427246094,1699.75427246094,53.4102399760826,5.87112146803806,7.77077865600586,56,1,0,0,1,0.332183837890625,33.2355842590332,1,1,3,5.0007700920105,0,5.00014019012451,,,,,,,,,,,,,,,,,,,,,,,,,,,,,,,,,
,3881330323.15299,5.00010919570923,1649.71594238281,-2.30877245073886E-5,2.05665417300982E-8,1,4,14.0008964538574,5.00637380725112,32.9700000584126,-0.0287785554951999,-0.00410341520320223,1,2.10471234855117E-7,,,,,,,,,,,,,,,,,,,,,4.99949169158936,5.0007266998291,1649.71594238281,1649.71594238281,53.4618274583518,5.87131786682882,7.78718090057373,56,1,0,0,1,0.3314208984375,33.7243423461914,1,1,3,5.0007266998291,0,5.00010919570923,,,,,,,,,,,,,,,,,,,,,,,,,,,,,,,,,
,3881330341.48893,4.99972486495972,1599.65246582031,-2.24316353768945E-5,2.07377834607941E-8,1,4,14.0008964538574,5.00639030198233,32.9700000584126,-0.0279680623532127,-0.00393952596798568,1,2.42489164450867E-7,,,,,,,,,,,,,,,,,,,,,4.9996657371521,4.99978399276733,1599.65246582031,1599.65246582031,53.5696921940057,5.87165984179914,7.77656698226929,55,1,68,0,0,0.3265380859375,33.7243423461914,1,1,3,4.99978399276733,0,4.99972486495972,,,,,,,,,,,,,,,,,,,,,,,,,,,,,,,,,
,3881330358.51773,4.99997568130493,1549.89111328125,-2.16581337003667E-5,2.21419300106115E-8,1,4,14.0008964538574,5.00645614043083,32.9700000584126,-0.0269966222414117,-0.00385328606154325,1,1.94333426804792E-7,,,,,,,,,,,,,,,,,,,,,4.9995322227478,5.00041913986206,1549.89111328125,1549.89111328125,53.5513239238037,5.87093159105128,7.79444599151611,55,1,68,0,0,0.327682495117188,33.7243423461914,1,1,3,4.9995322227478,0,4.99997568130493,,,,,,,,,,,,,,,,,,,,,,,,,,,,,,,,,
,3881330376.87144,4.99942970275879,1499.86535644531,-2.09418332903671E-5,2.12802987837615E-8,1,4,14.0008964538574,5.00637362308996,32.9700000584126,-0.0261085685493197,-0.00369015577054543,1,2.16509680333406E-7,,,,,,,,,,,,,,,,,,,,,4.99905586242676,4.99980354309082,1499.86535644531,1499.86535644531,53.450493844823,5.87124402292895,7.78406095504761,55,1,68,0,0,0.326995849609375,33.7243423461914,1,1,3,4.99980354309082,0,4.99942970275879,,,,,,,,,,,,,,,,,,,,,,,,,,,,,,,,,
,3881330394.89406,4.99976396560669,1449.83972167969,-2.02821925402679E-5,2.05955307735653E-8,1,4,14.0008964538574,5.00637352927953,32.9700000584126,-0.0252853534667407,-0.0035793726233352,1,2.05309879227019E-7,,,,,,,,,,,,,,,,,,,,,4.99902629852295,5.00050163269043,1449.83972167969,1449.83972167969,53.5681289369672,5.87139362611338,7.80003023147583,54,1,68,0,0,0.327072143554687,33.2355842590332,1,1,3,4.99902629852295,0,4.99976396560669,,,,,,,,,,,,,,,,,,,,,,,,,,,,,,,,,
,3881330413.44243,4.99999308586121,1399.95239257812,-1.95227643582719E-5,2.43249479132586E-8,1,4,14.0008964538574,5.00637574231539,32.9700000584126,-0.0243443874529671,-0.00340729396775364,1,2.28196883107798E-7,,,,,,,,,,,,,,,,,,,,,4.99958610534668,5.00040006637573,1399.95239257812,1399.95239257812,53.5001272557941,5.87110643685876,7.82154846191406,56,1,0,0,1,0.328903198242188,33.7243423461914,1,1,3,5.00040006637573,0,4.99999308586121,,,,,,,,,,,,,,,,,,,,,,,,,,,,,,,,,
,3881330431.71185,5.00104713439941,1349.85119628906,-1.87661431925475E-5,2.26230187354705E-8,1,4,14.0008964538574,5.00646972312346,32.9700000584126,-0.0233977012432999,-0.00330043049630716,1,1.99186488343276E-7,,,,,,,,,,,,,,,,,,,,,5.00085353851318,5.00124073028564,1349.85119628906,1349.85119628906,53.5091159837653,5.87132293263811,7.83017349243164,56,1,0,0,1,0.327377319335937,33.2355842590332,1,1,3,5.00085353851318,0,5.00104713439941,,,,,,,,,,,,,,,,,,,,,,,,,,,,,,,,,
,3881330449.14263,5.00089359283447,1299.82543945312,-1.80900057794696E-5,2.07752116972289E-8,1,4,14.0008964538574,5.00642026167026,32.9700000584126,-0.0225616147946677,-0.00313383727055957,1,2.30278449637882E-7,,,,,,,,,,,,,,,,,,,,,5.00073146820068,5.00105571746826,1299.82543945312,1299.82543945312,53.5614850945537,5.87125976685331,7.83293390274048,54,1,68,0,0,0.330047607421875,33.7243423461914,1,1,3,5.00073146820068,0,5.00089359283447,,,,,,,,,,,,,,,,,,,,,,,,,,,,,,,,,
,3881330467.36233,4.99991130828857,1249.88781738281,-1.73665026730244E-5,2.24968745700013E-8,1,4,14.0008964538574,5.00637131743637,32.9700000584126,-0.0216600733702081,-0.00300123050363599,1,2.26876064862675E-7,,,,,,,,,,,,,,,,,,,,,4.99923992156982,5.00058269500732,1249.88781738281,1249.88781738281,53.5900145355057,5.87040052534593,7.83781051635742,54,1,68,0,0,0.3271484375,32.7468223571777,1,1,3,5.00058269500732,0,4.99991130828857,,,,,,,,,,,,,,,,,,,,,,,,,,,,,,,,,
,3881330485.02399,5.00044417381287,1199.8369140625,-1.66874798584344E-5,2.20906523980188E-8,1,4,14.0008964538574,5.0064537431684,32.9700000584126,-0.0208126708411107,-0.00289041505521702,1,2.12811670243294E-7,,,,,,,,,,,,,,,,,,,,,5.00040340423584,5.00048494338989,1199.8369140625,1199.8369140625,53.4434591881499,5.87114493289491,7.83011817932129,55,1,68,0,0,0.327987670898438,33.7243423461914,1,1,3,5.00048494338989,0,5.00044417381287,,,,,,,,,,,,,,,,,,,,,,,,,,,,,,,,,
,3881330516.58081,4.99950337409973,1149.84887695312,-1.59523115723467E-5,2.2470670193409E-8,1,4,14.0008964538574,5.00637354255269,32.9700000584126,-0.0199038651363403,-0.00270676925130966,1,2.48622687744622E-7,,,,,,,,,,,,,,,,,,,,,4.9993109703064,4.99969577789307,1149.84887695312,1149.84887695312,53.4997364415345,5.87091495943634,7.87032175064087,55,1,68,0,0,0.326766967773438,33.7243423461914,1,1,3,4.99969577789307,0,4.99950337409973,,,,,,,,,,,,,,,,,,,,,,,,,,,,,,,,,
,3881330535.78691,5.00062656402588,1100.03723144531,-1.52478944144521E-5,2.19224468504172E-8,1,4,14.0008964538574,5.00633937574066,32.9700000584126,-0.0190258638377403,-0.00258005168638328,1,2.43402834798636E-7,,,,,,,,,,,,,,,,,,,,,5.0005259513855,5.00072717666626,1100.03723144531,1100.03723144531,53.5552320663999,5.87111357603466,7.87452363967896,56,1,0,0,1,0.33050537109375,33.7243423461914,1,1,3,5.00072717666626,0,5.00062656402588,,,,,,,,,,,,,,,,,,,,,,,,,,,,,,,,,
,3881330554.14329,5.00065517425537,1050.02404785156,-1.45435105386739E-5,5.94704557379233E-8,1,4,14.0008964538574,5.00640366726248,32.9700000584126,-0.018126207911493,-0.00259963734967731,1,1.20710205389059E-7,,,,,,,,,,,,,,,,,,,,,5.00063943862915,5.00067090988159,1050.02404785156,1050.02404785156,53.5130241263614,5.87133347001265,7.87630081176758,56,1,0,0,1,0.326614379882812,33.7243423461914,1,1,3,5.00067090988159,0,5.00065517425537,,,,,,,,,,,,,,,,,,,,,,,,,,,,,,,,,
,3881330572.55827,5.00006079673767,999.998352050781,-1.38372362525561E-5,1.99463959993366E-8,1,4,14.0008964538574,5.00636500694457,32.9700000584126,-0.0172702622685728,-0.00231206853731917,1,2.44428367799333E-7,,,,,,,,,,,,,,,,,,,,,4.9995813369751,5.00054025650024,999.998352050781,999.998352050781,53.5790717362364,5.87103198084198,7.88692951202393,55,1,68,0,0,0.326995849609375,33.7243423461914,1,1,3,4.9995813369751,0,5.00006079673767,,,,,,,,,,,,,,,,,,,,,,,,,,,,,,,,,
,3881330603.06347,4.9985716342926,949.97265625,-1.31728070903749E-5,2.21860750374697E-8,1,4,14.0008964538574,5.00638139052583,32.9700000584126,-0.0164431644288749,-0.00218722513182383,1,2.43805090924398E-7,,,,,,,,,,,,,,,,,,,,,4.99782514572144,4.99931812286377,949.97265625,949.97265625,53.5345189106403,5.8713082564096,7.94049501419067,55,1,68,0,0,0.327072143554687,33.2355842590332,1,1,3,4.99782514572144,0,4.9985716342926,,,,,,,,,,,,,,,,,,,,,,,,,,,,,,,,,
,3881330621.1993,4.9994432926178,899.959533691406,-1.24094969190811E-5,2.5913519747112E-8,1,4,14.0008964538574,5.00639668146561,32.9700000584126,-0.0154945472593193,-0.0020332998440613,1,2.51523646558171E-7,,,,,,,,,,,,,,,,,,,,,4.99850416183472,5.00038242340088,899.959533691406,899.959533691406,53.5653932371499,5.8706093178779,7.94732093811035,55,1,68,0,0,0.326461791992188,33.7243423461914,1,1,3,4.99850416183472,0,4.9994432926178,,,,,,,,,,,,,,,,,,,,,,,,,,,,,,,,,
,3881330638.79531,5.00024700164795,849.883422851562,-1.17032786567845E-5,2.44710087806442E-8,1,4,14.0008964538574,5.00636043924245,32.9700000584126,-0.0146081536659793,-0.00194691973379728,1,2.13627988632078E-7,,,,,,,,,,,,,,,,,,,,,5.00004816055298,5.00044584274292,849.883422851562,849.883422851562,53.425090917948,5.87127051069945,7.95113468170166,56,1,0,0,1,0.329055786132812,33.2355842590332,1,1,3,5.00044584274292,0,5.00024700164795,,,,,,,,,,,,,,,,,,,,,,,,,,,,,,,,,
,3881330665.13257,5.00054001808167,799.857727050781,-1.09584107570868E-5,1.09767569957979E-7,1,4,14.0008964538574,5.00640517229464,32.9700000584126,-0.0137141358671913,-0.00158890570639805,10,3.88116048291593E-7,,,,,,,,,,,,,,,,,,,,,5.00044107437134,5.00063896179199,799.857727050781,799.857727050781,53.4516662876018,5.87171434314208,7.93042659759522,56,1,0,0,1,0.326004028320313,33.7243423461914,1,1,3,5.00044107437134,0,5.00054001808167,,,,,,,,,,,,,,,,,,,,,,,,,,,,,,,,,
,3881330688.46529,4.9997341632843,750.020812988281,-1.03116811024063E-5,2.94891795185322E-8,1,4,14.0008964538574,5.00638345374509,32.9700000584126,-0.0128836699279817,-0.00163353265834365,1,2.54018768663875E-7,,,,,,,,,,,,,,,,,,,,,4.99958467483521,4.9998836517334,750.020812988281,750.020812988281,53.6310500327653,5.87137783149828,7.9414496421814,56,1,0,0,1,0.327301025390625,33.7243423461914,1,1,3,4.9998836517334,0,4.9997341632843,,,,,,,,,,,,,,,,,,,,,,,,,,,,,,,,,
,3881330706.25858,4.99999213218689,700.032897949219,-9.57847566676752E-6,2.29505836679412E-8,1,4,14.0008964538574,5.00643539180431,32.9700000584126,-0.0119663464417046,-0.00152669917679151,1,2.2848913567055E-7,,,,,,,,,,,,,,,,,,,,,4.99950933456421,5.00047492980957,700.032897949219,700.032897949219,53.5227944828518,5.87150322702311,7.94496250152588,55,1,68,0,0,0.328140258789063,33.2355842590332,1,1,3,5.00047492980957,0,4.99999213218689,,,,,,,,,,,,,,,,,,,,,,,,,,,,,,,,,
,3881330725.03318,4.99978470802307,650.095275878906,-8.8444936000346E-6,2.27358351443463E-8,1,4,14.0008964538574,5.00638778142158,32.9700000584126,-0.0110537884428241,-0.00137974207004523,1,2.35041138109753E-7,,,,,,,,,,,,,,,,,,,,,4.99950122833252,5.00006818771362,650.095275878906,650.095275878906,53.5188863402557,5.87153937427233,7.96296453475952,55,1,68,0,0,0.326995849609375,33.2355842590332,1,1,3,4.99950122833252,0,4.99978470802307,,,,,,,,,,,,,,,,,,,,,,,,,,,,,,,,,
,3881330743.25811,4.99978709220886,600.220581054687,-8.15371965754235E-6,2.32414624631461E-8,1,4,14.0008964538574,5.00631991131332,32.9700000584126,-0.0101916671763639,-0.00126276359797814,1,2.24069807242534E-7,,,,,,,,,,,,,,,,,,,,,4.99976539611816,4.99980878829956,600.220581054687,600.220581054687,53.506380283948,5.87172143130467,7.96583127975464,55,1,68,0,0,0.329208374023438,33.7243423461914,1,1,3,4.99980878829956,0,4.99978709220886,,,,,,,,,,,,,,,,,,,,,,,,,,,,,,,,,
,3881330774.77637,4.9996383190155,550.131896972656,-7.45844830924618E-6,1.90420868815209E-8,1,4,14.0008964538574,5.00637382091733,32.9700000584126,-0.00933318222503607,-0.00108648849238274,1,2.60087052298219E-7,,,,,,,,,,,,,,,,,,,,,4.99922657012939,5.00005006790161,550.131896972656,550.131896972656,53.4086767190441,5.87163946602222,7.98400449752808,55,1,68,0,0,0.335311889648438,33.2355842590332,1,1,3,4.99922657012939,0,4.9996383190155,,,,,,,,,,,,,,,,,,,,,,,,,,,,,,,,,
,3881330806.31963,5.0004289150238,500.181701660156,-6.74608377365448E-6,2.17205533770964E-8,1,4,14.0008964538574,5.00638807410053,32.9700000584126,-0.00844393706659302,-0.000968608360509194,1,2.46583176025712E-7,,,,,,,,,,,,,,,,,,,,,4.99992179870605,5.00093603134155,500.181701660156,500.181701660156,53.5458525241691,5.8715719455691,7.96502304077148,55,1,68,0,0,0.32684326171875,33.7243423461914,1,1,3,4.99992179870605,0,5.0004289150238,,,,,,,,,,,,,,,,,,,,,,,,,,,,,,,,,
,3881330836.54953,5.0005931854248,450.168579101562,-6.02587674304067E-6,2.42831730887176E-8,1,4,14.0008964538574,5.00642781234485,32.9700000584126,-0.00754847812379487,-0.000826197538788636,1,2.5159894866972E-7,,,,,,,,,,,,,,,,,,,,,5.00000047683716,5.00118589401245,450.168579101562,450.168579101562,53.4852763139287,5.87167329621462,7.99848222732544,56,1,0,0,1,0.330581665039063,33.7243423461914,1,1,3,5.00000047683716,0,5.0005931854248,,,,,,,,,,,,,,,,,,,,,,,,,,,,,,,,,
,3881330854.82407,4.99999141693115,400.067321777344,-5.28900610512118E-6,5.94459559839873E-8,1,4,14.0008964538574,5.00643276261749,32.9700000584126,-0.00663655305931243,-0.000651916469538319,1,2.79678684195723E-7,,,,,,,,,,,,,,,,,,,,,4.99986124038696,5.00012159347534,400.067321777344,400.067321777344,53.5138057548807,5.87089052823112,8.00844383239746,56,1,0,0,1,0.327911376953125,33.2355842590332,1,1,3,5.00019836425781,0,4.99999141693115,,,,,,,,,,,,,,,,,,,,,,,,,,,,,,,,,
,3881330881.61836,5.00009822845459,350.041625976562,-4.57522977255002E-6,2.69751392279992E-8,1,4,14.0008964538574,5.00642762174557,32.9700000584126,-0.0057428581936446,-0.000551115282933432,10,2.52234657650072E-7,,,,,,,,,,,,,,,,,,,,,4.99971532821655,5.00048112869263,350.041625976562,350.041625976562,53.5325648393422,5.87106526973203,7.98904037475586,56,1,0,0,1,0.3265380859375,33.7243423461914,1,1,3,4.99971532821655,0,5.00009822845459,,,,,,,,,,,,,,,,,,,,,,,,,,,,,,,,,
,3881330904.46562,5.00012278556824,300.003265380859,-3.89447220985937E-6,2.40488930813935E-8,1,4,14.0008964538574,5.00641432574608,32.9799987375736,-0.00490167162551225,-0.000381403282888692,1,2.85165508036653E-7,,,,,,,,,,,,,,,,,,,,,4.99990940093994,5.00033617019653,300.003265380859,300.003265380859,53.3977339197749,5.87070581676558,7.9984564781189,54,1,68,0,0,0.326461791992188,33.2355842590332,1,1,3,5.00041151046753,0,5.00012278556824,,,,,,,,,,,,,,,,,,,,,,,,,,,,,,,,,
,3881330923.03521,4.99943280220032,250.090850830078,-3.14719543152839E-6,2.41443347213059E-8,1,4,14.0008964538574,5.00639529762113,32.9700000584126,-0.00395928208352572,-0.000320257527336073,1,2.20775027530788E-7,,,,,,,,,,,,,,,,,,,,,4.99880075454712,5.00006484985352,250.090850830078,250.090850830078,53.4762875859576,5.87152229929954,8.01220989227295,55,1,68,0,0,0.326919555664063,33.2355842590332,1,1,3,5.00006484985352,0,4.99943280220032,,,,,,,,,,,,,,,,,,,,,,,,,,,,,,,,,
,3881330954.80047,4.9999623298645,200.20361328125,-2.46643560312824E-6,2.31072354769132E-8,1,4,14.0008964538574,5.00638640010218,32.9700000584126,-0.00312011009166342,-0.00013738534161959,1,2.64280001942047E-7,,,,,,,,,,,,,,,,,,,,,4.99988269805908,5.00004196166992,200.20361328125,200.20361328125,53.602911406073,5.87175906701271,8.03554821014404,55,1,68,0,0,0.327377319335937,33.2355842590332,1,1,3,5.00004196166992,0,4.9999623298645,,,,,,,,,,,,,,,,,,,,,,,,,,,,,,,,,
,3881330986.43649,5.00026607513428,150.190460205078,-1.72157573692613E-6,2.53485893783542E-8,1,4,14.0008964538574,5.00625477686858,32.9700000584126,-0.00218642762200905,-3.88396502183516E-5,1,2.30302960106342E-7,,,,,,,,,,,,,,,,,,,,,5.00017404556274,5.00035810470581,150.190460205078,150.190460205078,53.5607034660345,5.87082088236112,8.04735279083252,55,1,68,0,0,0.32745361328125,33.2355842590332,1,1,3,5.00017404556274,0,5.00026607513428,,,,,,,,,,,,,,,,,,,,,,,,,,,,,,,,,
,3881331017.95273,4.99996829032898,100.265449523926,-1.03107575902245E-6,2.49813651195749E-8,1,4,14.0008964538574,5.00636134638957,32.9700000584126,-0.00133621084800217,0.00015244489087963,1,2.79089225430139E-7,,,,,,,,,,,,,,,,,,,,,4.99956750869751,5.00036907196045,100.265449523926,100.265449523926,53.5728187080826,5.87105137517217,8.08485221862793,55,1,68,0,0,0.326919555664063,33.2355842590332,1,1,3,5.00036907196045,0,4.99996829032898,,,,,,,,,,,,,,,,,,,,,,,,,,,,,,,,,
,3881331049.71643,5.00071310997009,50.252311706543,-2.78427050537317E-7,2.48416388515257E-8,1,4,14.0008964538574,5.006264571083,32.9700000584126,-0.000389520770144389,0.000230145781395586,1,2.27189711066683E-7,,,,,,,,,,,,,,,,,,,,,5.00070333480835,5.00072288513184,50.252311706543,50.252311706543,53.4887936422653,5.87041710121605,8.12112331390381,54,1,68,0,0,0.3289794921875,33.2355842590332,1,1,3,5.00072288513184,0,5.00071310997009,,,,,,,,,,,,,,,,,,,,,,,,,,,,,,,,,
,3881331081.18079,4.99998497962952,0.214000344276428,3.70597502407466E-7,2.40188049723971E-8,1,4,14.0008964538574,5.00623827412755,32.9700000584126,0.000416461269483593,0.000365182904327177,1,2.37092843784455E-7,,,,,,,,,,,,,,,,,,,,,4.99981021881103,5.000159740448,0.214000344276428,0.214000344276428,53.5036445841307,5.87037124034103,8.1862096786499,54,1,68,0,0,0.32867431640625,33.2355842590332,1,1,3,5.000159740448,0,4.99998497962952,,,,,,,,,,,,,,,,,,,,,,,,,,,,,,,,,
,3881331112.80455,5.00002503395081,-49.8872566223145,1.08003503491484E-6,2.92114551495085E-8,1,4,14.0008964538574,5.00626373198129,32.9700000584126,0.00130295315840486,0.00047671377939853,1,2.1893037617868E-7,,,,,,,,,,,,,,,,,,,,,4.999755859375,5.00029420852661,-49.8872566223145,-49.8872566223145,53.5220128543326,5.87069719326425,8.20683193206787,54,1,68,0,0,0.326690673828125,33.2355842590332,1,1,3,4.999755859375,0,5.00002503395081,,,,,,,,,,,,,,,,,,,,,,,,,,,,,,,,,
,3881331143.94305,5.00003623962402,-99.8878021240234,1.86287315853753E-6,3.15001953402751E-8,1,4,14.0008964538574,5.00630207756535,32.9700000584126,0.00227146316799781,0.000663791854160229,1,2.5030864336839E-7,,,,,,,,,,,,,,,,,,,,,5.00002288818359,5.00004959106445,-99.8878021240234,-99.8878021240234,53.493092599121,5.87080362087737,8.25924587249756,56,1,0,0,1,0.325927734375,32.7468223571777,1,1,3,5.00002288818359,0,5.00003623962402,,,,,,,,,,,,,,,,,,,,,,,,,,,,,,,,,
,3881331170.37297,5.00129580497742,-149.737289428711,2.56875744688873E-6,2.40388071777952E-8,1,4,14.0008964538574,5.00629772317372,32.9700000584126,0.00315086856278464,0.000792201817850957,10,2.46248158918283E-7,,,,,,,,,,,,,,,,,,,,,5.00125217437744,5.00133943557739,-149.737289428711,-149.737289428711,53.5696921940057,5.87106590387853,8.26737308502197,56,1,0,0,1,0.328445434570313,33.2355842590332,1,1,3,5.00133943557739,0,5.00129580497742,,,,,,,,,,,,,,,,,,,,,,,,,,,,,,,,,
,3881331202.2815,5.00128984451294,-199.775604248047,3.22291359633435E-6,2.86843735086855E-8,1,4,14.0008964538574,5.0062535565334,32.9700000584126,0.00396590211852256,0.000910411023048155,10,2.41858413842858E-7,,,,,,,,,,,,,,,,,,,,,5.00064039230347,5.00193929672241,-199.775604248047,-199.775604248047,53.4907477135634,5.87036491505805,8.31153964996338,56,1,0,0,1,0.32562255859375,33.2355842590332,1,1,3,5.00193929672241,0,5.00128984451294,,,,,,,,,,,,,,,,,,,,,,,,,,,,,,,,,
,3881331226.05578,5.00133466720581,-249.839080810547,3.98189379326698E-6,3.28689485859176E-8,1,4,14.0008964538574,5.00634508289402,32.9700000584126,0.00491186894712698,0.00104655326312673,1,2.35923874101258E-7,,,,,,,,,,,,,,,,,,,,,5.00080490112305,5.00186443328857,-249.839080810547,-249.839080810547,53.5489790382461,5.87014818138644,8.32110023498535,54,1,68,0,0,0.329818725585937,32.7468223571777,1,1,3,5.00080490112305,0,5.00133466720581,,,,,,,,,,,,,,,,,,,,,,,,,,,,,,,,,
,3881331259.16078,5.00024461746216,-299.751525878906,4.78207422621035E-6,1.04990217174303E-8,1,4,14.0008964538574,5.0062653238112,32.9700000584126,0.00594991395624561,0.00092034244013511,1,1.2999148359056E-8,,,,,,,,,,,,,,,,,,,,,4.99982690811157,5.00066232681274,-299.751525878906,-299.751525878906,53.4966099274576,5.87007402111348,8.3636474609375,56,1,0,0,1,0.32806396484375,33.2355842590332,1,1,3,5.00066232681274,0,5.00024461746216,,,,,,,,,,,,,,,,,,,,,,,,,,,,,,,,,
,3881331277.43375,5.00200510025024,-349.789855957031,5.41796458999946E-6,1.51712626152082E-8,1,4,14.0008964538574,5.00626656972365,32.9700000584126,0.00672501277566176,0.00114862268137896,1,9.98054207903707E-8,,,,,,,,,,,,,,,,,,,,,5.00134754180908,5.00266265869141,-349.789855957031,-349.789855957031,53.6337857325826,5.87031942868169,8.36427783966065,55,1,68,0,0,0.3277587890625,33.2355842590332,1,1,3,5.00134754180908,0,5.00200510025024,,,,,,,,,,,,,,,,,,,,,,,,,,,,,,,,,
,3881331308.93333,5.0010232925415,-399.828155517578,6.1399006961464E-6,2.22621884868194E-8,1,4,14.0008964538574,5.00624728797188,32.9700000584126,0.00761002219861293,0.00137440009262718,1,1.71536847350357E-7,,,,,,,,,,,,,,,,,,,,,5.00066232681274,5.00138425827026,-399.828155517578,-399.828155517578,53.4927017848614,5.87014736128902,8.39274501800537,56,1,0,0,1,0.330734252929687,33.2355842590332,1,1,3,5.00066232681274,0,5.0010232925415,,,,,,,,,,,,,,,,,,,,,,,,,,,,,,,,,
,3881331327.39973,5.00120735168457,-449.677642822266,6.82362204507299E-6,1.99432272516422E-8,1,4,14.0008964538574,5.00632608092208,32.9700000584126,0.00845635579892754,0.00153592449190421,1,1.97420484355098E-7,,,,,,,,,,,,,,,,,,,,,5.0009241104126,5.00149059295654,-449.677642822266,-449.677642822266,53.5036445841307,5.8696870855605,8.43023586273193,56,1,0,0,1,0.327606201171875,33.2355842590332,1,1,3,5.0009241104126,0,5.00120735168457,,,,,,,,,,,,,,,,,,,,,,,,,,,,,,,,,
,3881331345.41351,5.03676152229309,-499.715942382812,7.5527047145976E-6,2.34454726272804E-8,1,4,14.0008964538574,5.0062026684626,32.9700000584126,0.00936276415391534,0.00167893580780235,1,2.01611579231847E-7,,,,,,,,,,,,,,,,,,,,,5.02262783050537,5.05089521408081,-499.715942382812,-499.715942382812,53.6572345881595,5.86955592837404,8.46652412414551,56,1,0,0,1,0.329437255859375,33.2355842590332,6,1,3,5.05089521408081,0,5.03676152229309,,,,,,,,,,,,,,,,,,,,,,,,,,,,,,,,,
,3881331349.6275,5.0700671672821,-499.715942382812,7.5613491865175E-6,1.23545109364156E-8,1,4,14.0008964538574,5.0062791603712,32.9700000584126,0.00938788925949785,0.00158735331150998,1,1.26693522718014E-7,,,,,,,,,,,,,,,,,,,,,5.05454349517822,5.08559083938599,-499.715942382812,-499.715942382812,53.547024966948,5.86985338428861,8.46555423736572,54,2,68,0,0,0.327224731445313,33.2355842590332,6,1,3,5.08559083938599,0,5.0700671672821,,,,,,,,,,,,,,,,,,,,,,,,,,,,,,,,,