File: SQUID/Reference/LAO/C3/transfer_115386_files_71fd6f70/LAOsubs_22172_MH_200K_FC_p0d5T.dat
[Header]
; MPMS3 Data File (default extension .dat)
; Copyright (c) 2007, Quantum Design, Inc. All rights reserved.
TITLE,
FILEOPENTIME,3881345701.71737,12/27/2022,11:38 pm
BYAPP,SQUID AC,0.9.1.0
INFO,MPMS3 Measurement Release 1.1.16 Build 347, MultiVu Release 2.3.3.2,APPNAME
INFO,0,MOMENT_UNITS
INFO,LAO,SAMPLE_MATERIAL
INFO,,SAMPLE_COMMENT
INFO,,SAMPLE_MASS
INFO,,SAMPLE_VOLUME
INFO,,SAMPLE_MOLECULAR_WEIGHT
INFO,,SAMPLE_SIZE
INFO,,SAMPLE_SHAPE
INFO,Quartz,SAMPLE_HOLDER
INFO,Standard,SAMPLE_HOLDER_DETAIL
INFO,65.74,SAMPLE_OFFSET
DATATYPE,COMMENT,1
DATATYPE,TIME,2
STARTUPAXIS,X,2
STARTUPAXIS,Y1,5
FIELDGROUP, VSM,2,3,4,5,6,8,9,10,11,14,15
FIELDGROUP, DC, 2,3,4,14,56,57,58,59,60,61,62,63,64,65,66,67,68,69
FIELDGROUP, AC, 2,3,4,11,16,17,18,19,20,21,22,23,24,25,26,27,28,29,30
STARTUPGROUP, All
[Data]
Comment,Time Stamp (sec),Temperature (K),Magnetic Field (Oe),Moment (emu),M. Std. Err. (emu),Transport Action,Averaging Time (sec),Frequency (Hz),Peak Amplitude (mm),Center Position (mm),Lockin Signal' (V),Lockin Signal (V),Range,M. Quad. Signal (emu),AC Moment (emu),AC M. Std Err. (emu),AC Phase (deg),AC Phase Std. Err. (deg),AC Susceptibility (emu/Oe),AC Suscept. Std Err. (emu/Oe),AC X' (emu/Oe),AC X' Std Err. (emu/Oe),AC X'' (emu/Oe),AC X'' Std Err. (emu/Oe),AC Drive (Oe),AC Frequency (Hz),AC Averaging Time (sec),AC Cycles,AC Range,AC Measure Type,AC Signal' (V),AC Signal'' (V),AC Trim Coil Ratio,AC Trim Coil Phase,Min. Temperature (K),Max. Temperature (K),Min. Field (Oe),Max. Field (Oe),Mass (grams),Motor Lag (deg),Pressure (Torr),Measure Count,Measurement Number,SQUID Status (code),Motor Status (code),Measure Status (code),Motor Current (amps),Motor Temp. (C),Temp. Status (code),Field Status (code),Chamber Status (code),Chamber Temp (K),Redirection State,Average Temp (K),Rotation Angle (deg),Rotator state,DC Moment Fixed Ctr (emu),DC Moment Err Fixed Ctr (emu),DC Moment Free Ctr (emu),DC Moment Err Free Ctr (emu),DC Fixed Fit,DC Free Fit,DC Calculated Center (mm),DC Calculated Center Err (mm),DC Scan Length (mm),DC Scan Time (s),DC Number of Points,DC Squid Drift,DC Min V (V),DC Max V (V),DC Scans per Measure,Map 01,Map 02,Map 03,Map 04,Map 05,Map 06,Map 07,Map 08,Map 09,Map 10,Map 11,Map 12,Map 13,Map 14,Map 15,Map 16
,3881345742.72139,199.982246398926,69999.578125,-0.00128422741581631,4.33619841222729E-7,1,4,14.0008964538574,4.9941232326169,33.0899991095066,-1.59371764766734,-0.237844598953364,100,3.34108222912064E-6,,,,,,,,,,,,,,,,,,,,,199.982086181641,199.982406616211,69999.578125,69999.578125,53.1937288762556,5.8811740741194,5.27485799789429,56,1,0,0,1,0.327682495117188,32.7468223571777,1,1,3,199.982406616211,0,199.982246398926,,,,,,,,,,,,,,,,,,,,,,,,,,,,,,,,,
,3881345835.1355,200.137413024902,59999.65234375,-0.00110148233837922,3.14521291701074E-7,1,4,14.0008964538574,4.99425231096263,33.100001513958,-1.36672721759967,-0.205682228798702,10,1.51508230969747E-6,,,,,,,,,,,,,,,,,,,,,200.133987426758,200.140838623047,59999.65234375,59999.65234375,53.3078466400633,5.88150891999918,5.2660231590271,56,1,0,0,1,0.3265380859375,33.2355842590332,1,1,3,200.133987426758,0,200.137413024902,,,,,,,,,,,,,,,,,,,,,,,,,,,,,,,,,
,3881345921.41383,200.074600219727,49999.56640625,-0.000917028974367534,2.21844270752287E-7,1,4,14.0008964538574,4.99412275215217,33.0899991095066,-1.13780946802941,-0.171267774860744,10,1.23303057037753E-6,,,,,,,,,,,,,,,,,,,,,200.051727294922,200.097473144531,49999.56640625,49999.56640625,53.3449739947268,5.88101378074014,5.26846361160278,56,1,0,0,1,0.3289794921875,33.7243423461914,1,1,3,200.097473144531,0,200.074600219727,,,,,,,,,,,,,,,,,,,,,,,,,,,,,,,,,
,3881346005.85238,200.174674987793,39999.6484375,-0.000733058036327147,1.61160769501934E-7,1,4,14.0008964538574,4.99415132790665,33.0899991095066,-0.909578213332988,-0.136748124460296,10,1.11596914967608E-6,,,,,,,,,,,,,,,,,,,,,200.170989990234,200.178359985352,39999.6484375,39999.6484375,53.5310015823037,5.88067272763027,5.26444387435913,56,1,0,0,1,0.323944091796875,33.7243423461914,1,1,3,200.170989990234,0,200.174674987793,,,,,,,,,,,,,,,,,,,,,,,,,,,,,,,,,
,3881346100.73179,200.054054260254,29999.587890625,-0.000548752714298549,1.49282317148071E-7,1,4,14.0008964538574,4.99410752905779,33.0899991095066,-0.680714952679277,-0.103477611672467,1,-6.09689292746854E-8,,,,,,,,,,,,,,,,,,,,,200.042449951172,200.065658569336,29999.587890625,29999.587890625,53.5747727793807,5.88049281551874,5.26051568984985,56,1,0,0,1,0.327529907226562,33.7243423461914,1,1,3,200.065658569336,0,200.054054260254,,,,,,,,,,,,,,,,,,,,,,,,,,,,,,,,,
,3881346185.54751,200.126251220703,19999.56640625,-0.000365956808478138,8.6569110453213E-8,1,4,14.0008964538574,4.99423152080338,33.100001513958,-0.453995805128422,-0.0688845084968398,1,6.0835182543201E-8,,,,,,,,,,,,,,,,,,,,,200.115829467773,200.136672973633,19999.56640625,19999.56640625,53.5243577398903,5.87978055527641,5.25993204116821,56,1,0,0,1,0.3271484375,34.2131004333496,1,1,3,200.136672973633,0,200.126251220703,,,,,,,,,,,,,,,,,,,,,,,,,,,,,,,,,
,3881346251.84678,200.136474609375,14499.6181640625,-0.000265515856528929,2.85706184176673E-8,1,4,14.0008964538574,4.99425322928682,33.100001513958,-0.329406391914969,-0.0498942652893852,1,1.12189887945808E-7,,,,,,,,,,,,,,,,,,,,,200.11051940918,200.16242980957,14499.6181640625,14499.6181640625,53.4629999011307,5.88022304169912,5.26793956756592,56,1,0,0,1,0.326995849609375,34.2131004333496,1,1,3,200.16242980957,0,200.136474609375,,,,,,,,,,,,,,,,,,,,,,,,,,,,,,,,,
,3881346292.93798,200.234970092773,13499.5185546875,-0.000247141618207428,3.09559374049968E-8,1,4,14.0008964538574,4.9943217363877,33.100001513958,-0.306620843031543,-0.0464150302240817,1,1.26466419618955E-7,,,,,,,,,,,,,,,,,,,,,200.221435546875,200.248504638672,13499.5185546875,13499.5185546875,53.4934834133807,5.87904361442731,5.26005125045776,56,1,0,0,1,0.328445434570313,34.2131004333496,1,1,3,200.248504638672,0,200.234970092773,,,,,,,,,,,,,,,,,,,,,,,,,,,,,,,,,
,3881346333.93568,200.252510070801,12499.7841796875,-0.000228826698015935,2.69409280270318E-8,1,4,14.0008964538574,4.99441060795176,33.0899991095066,-0.283904260592101,-0.0429824309252254,1,1.12251998335438E-7,,,,,,,,,,,,,,,,,,,,,200.222946166992,200.282073974609,12499.7841796875,12499.7841796875,53.5028629556114,5.87863755231101,5.26186418533325,56,1,0,0,1,0.327529907226562,34.2131004333496,1,1,3,200.282073974609,0,200.252510070801,,,,,,,,,,,,,,,,,,,,,,,,,,,,,,,,,
,3881346375.59852,200.319725036621,11499.7734375,-0.000210472958973512,2.34587303907104E-8,1,4,14.0008964538574,4.99426287918469,33.0899991095066,-0.26112465900781,-0.0395160110395106,1,1.17150118430284E-7,,,,,,,,,,,,,,,,,,,,,200.319107055664,200.320343017578,11499.7734375,11499.7734375,53.6416020177749,5.87900178102601,5.27012062072754,56,1,0,0,1,0.325393676757812,34.2131004333496,1,1,3,200.319107055664,0,200.319725036621,,,,,,,,,,,,,,,,,,,,,,,,,,,,,,,,,
,3881346416.23356,200.223220825195,10499.69921875,-0.000192133805637188,2.43548655738003E-8,1,4,14.0008964538574,4.99427342153963,33.0899991095066,-0.238373131638042,-0.0360706042900322,1,1.08846762602947E-7,,,,,,,,,,,,,,,,,,,,,200.216430664062,200.230010986328,10499.69921875,10499.69921875,53.5599218375153,5.87926841898623,5.26816892623901,56,1,0,0,1,0.3289794921875,34.2131004333496,1,1,3,200.216430664062,0,200.223220825195,,,,,,,,,,,,,,,,,,,,,,,,,,,,,,,,,
,3881346459.43455,200.125854492187,9499.7890625,-0.000173734051417975,2.73211387046898E-8,1,4,14.0008964538574,4.99422504152266,33.0899991095066,-0.215544629864929,-0.0326007020204212,1,1.10632994023747E-7,,,,,,,,,,,,,,,,,,,,,200.119430541992,200.132278442383,9499.7890625,9499.7890625,53.5665656799287,5.87953936244542,5.27084016799927,56,1,0,0,1,0.328140258789063,34.2131004333496,1,1,3,200.132278442383,0,200.125854492187,,,,,,,,,,,,,,,,,,,,,,,,,,,,,,,,,
,3881346499.27278,200.203453063965,8499.6025390625,-0.000155381187225475,2.47654807975009E-8,1,4,14.0008964538574,4.99421444017185,33.0899991095066,-0.192775916918406,-0.0291468942184743,1,1.06892706241687E-7,,,,,,,,,,,,,,,,,,,,,200.200469970703,200.206436157227,8499.6025390625,8499.6025390625,53.5696921940057,5.88033417889773,5.27033948898315,56,1,0,0,1,0.32867431640625,33.7243423461914,1,1,3,200.200469970703,0,200.203453063965,,,,,,,,,,,,,,,,,,,,,,,,,,,,,,,,,
,3881346541.84804,200.225784301758,7499.76806640625,-0.000136873411472711,3.99909130881056E-8,1,4,14.0008964538574,4.99419614829101,33.0899991095066,-0.169809430350809,-0.0256992137240242,1,7.46540450940978E-8,,,,,,,,,,,,,,,,,,,,,200.224639892578,200.226928710938,7499.76806640625,7499.76806640625,53.496219113198,5.87952469015747,5.26021766662598,56,1,0,0,1,0.329666137695313,34.2131004333496,1,1,3,200.226928710938,0,200.225784301758,,,,,,,,,,,,,,,,,,,,,,,,,,,,,,,,,
,3881346581.21468,200.318618774414,6499.79443359375,-0.000118717974805155,2.11407472172233E-8,1,4,14.0008964538574,4.99427553180581,33.0899991095066,-0.147290653379292,-0.0222767385124352,1,7.61376845464136E-8,,,,,,,,,,,,,,,,,,,,,200.302047729492,200.335189819336,6499.79443359375,6499.79443359375,53.521622040073,5.8796103223703,5.26074409484863,56,1,0,0,1,0.329055786132812,34.2131004333496,1,1,3,200.335189819336,0,200.318618774414,,,,,,,,,,,,,,,,,,,,,,,,,,,,,,,,,
,3881346622.12855,200.355125427246,5499.6826171875,-0.000100210077037819,2.59187318031774E-8,1,4,14.0008964538574,4.99424079206289,33.0899991095066,-0.124323883820809,-0.0188249609278394,1,4.70939219810224E-8,,,,,,,,,,,,,,,,,,,,,200.343246459961,200.367004394531,5499.6826171875,5499.6826171875,53.5974400064384,5.87953175330583,5.26095485687256,56,1,0,0,1,0.32989501953125,34.2131004333496,1,1,3,200.367004394531,0,200.355125427246,,,,,,,,,,,,,,,,,,,,,,,,,,,,,,,,,
,3881346663.3247,200.274909973145,4499.7216796875,-8.20104174661385E-5,1.3759498587432E-8,1,4,14.0008964538574,4.99425769798981,33.0899991095066,-0.10174547098836,-0.0154048546538538,1,3.95750445169845E-8,,,,,,,,,,,,,,,,,,,,,200.264541625977,200.285278320313,4499.7216796875,4499.7216796875,53.4993456272749,5.88002665862914,5.26364660263062,54,1,68,0,0,0.326995849609375,33.7243423461914,1,1,3,200.264541625977,0,200.274909973145,,,,,,,,,,,,,,,,,,,,,,,,,,,,,,,,,
,3881346703.5189,200.341514587402,3499.68579101562,-6.36393258063154E-5,8.07054065893258E-9,1,4,14.0008964538574,4.99427288285641,33.0899991095066,-0.0789521857456153,-0.0119652371248822,1,2.17127577908584E-8,,,,,,,,,,,,,,,,,,,,,200.321990966797,200.361038208008,3499.68579101562,3499.68579101562,53.5513239238037,5.87984923646899,5.27149868011475,56,1,0,0,1,0.326461791992188,34.2131004333496,1,1,3,200.361038208008,0,200.341514587402,,,,,,,,,,,,,,,,,,,,,,,,,,,,,,,,,
,3881346822.9658,200.138465881348,2709.78564453125,-4.91340924785246E-5,8.47697735939467E-9,1,4,14.0008964538574,4.9942700188599,33.0899991095066,-0.0609569670296634,-0.00923600049381645,1,1.83819563247444E-8,,,,,,,,,,,,,,,,,,,,,200.131744384766,200.14518737793,2709.78564453125,2709.78564453125,53.5767268506787,5.87969038930199,5.2733907699585,56,1,0,0,1,0.3277587890625,34.2131004333496,1,1,3,200.14518737793,0,200.138465881348,,,,,,,,,,,,,,,,,,,,,,,,,,,,,,,,,
,3881346861.67313,200.145751953125,2129.73120117187,-3.85244061709153E-5,1.18191250913903E-7,1,4,14.0008964538574,4.99429268863817,33.0899991095066,-0.0478170382980342,-0.0070941817301065,1,1.33314287203191E-7,,,,,,,,,,,,,,,,,,,,,200.13981628418,200.15168762207,2129.73120117187,2129.73120117187,53.577508479198,5.8798127757455,5.26604557037354,56,1,0,0,1,0.328369140625,33.7243423461914,1,1,3,200.15168762207,0,200.145751953125,,,,,,,,,,,,,,,,,,,,,,,,,,,,,,,,,
,3881346900.82327,200.118064880371,1549.55126953125,-2.7817006503558E-5,7.223372463513E-9,1,4,14.0008964538574,4.99434091781907,33.0899991095066,-0.0345127933421332,-0.00521820229706541,1,1.912414543766E-8,,,,,,,,,,,,,,,,,,,,,200.113693237305,200.122436523438,1549.55126953125,1549.55126953125,53.5747727793807,5.87957844404843,5.26793622970581,56,1,0,0,1,0.32806396484375,33.7243423461914,1,1,3,200.122436523438,0,200.118064880371,,,,,,,,,,,,,,,,,,,,,,,,,,,,,,,,,
,3881346940.51643,200.255104064941,969.685852050781,-1.71538083460479E-5,1.43014548639887E-8,1,4,14.0008964538574,4.99430128180816,33.0899991095066,-0.0212823901639576,-0.00321948053972202,1,1.04815475262797E-8,,,,,,,,,,,,,,,,,,,,,200.240646362305,200.269561767578,969.685852050781,969.685852050781,53.5110700550634,5.87964864241789,5.26783609390259,56,1,0,0,1,0.328521728515625,33.7243423461914,1,1,3,200.269561767578,0,200.255104064941,,,,,,,,,,,,,,,,,,,,,,,,,,,,,,,,,
,3881346980.08253,200.34977722168,389.744964599609,-6.49948007913984E-6,9.02306792154452E-9,1,4,14.0008964538574,4.99427946850065,33.0899991095066,-0.00806503882796399,-0.00121119807735327,1,1.09338019075365E-8,,,,,,,,,,,,,,,,,,,,,200.343872070313,200.355682373047,389.744964599609,389.744964599609,53.5110700550634,5.87983526898574,5.27450799942017,56,1,0,0,1,0.327224731445313,34.2131004333496,1,1,3,200.343521118164,0,200.34977722168,,,,,,,,,,,,,,,,,,,,,,,,,,,,,,,,,
,3881347018.79771,200.40234375,-190.372177124023,4.16213632854068E-6,1.29915163305329E-8,1,4,14.0008964538574,4.99436694947732,33.0899991095066,0.00516333888594118,0.000785366163960401,1,8.33404505297199E-10,,,,,,,,,,,,,,,,,,,,,200.395751953125,200.408935546875,-190.372177124023,-190.372177124023,53.5966583779191,5.87863344201347,5.26550579071045,56,1,0,0,1,0.327301025390625,34.2131004333496,1,1,3,200.408935546875,0,200.40234375,,,,,,,,,,,,,,,,,,,,,,,,,,,,,,,,,
,3881347055.94969,200.273986816406,-770.187194824219,1.47887410565184E-5,3.22071253928422E-8,1,4,14.0008964538574,4.99434603661508,33.0899991095066,0.0183490380805245,0.00277095973917117,1,-1.28027102910203E-8,,,,,,,,,,,,,,,,,,,,,200.263885498047,200.284088134766,-770.187194824219,-770.187194824219,53.5122424978422,5.87918744819216,5.27192354202271,56,1,0,0,1,0.328903198242188,33.7243423461914,1,1,3,200.263885498047,0,200.273986816406,,,,,,,,,,,,,,,,,,,,,,,,,,,,,,,,,
,3881347093.78838,200.14591217041,-1350.17846679688,2.54234314827655E-5,1.38189708729938E-8,1,4,14.0008964538574,4.99432885236603,33.100001513958,0.0315488391084354,0.00473045739569777,1,-4.86876199437389E-8,,,,,,,,,,,,,,,,,,,,,200.142013549805,200.149810791016,-1350.17846679688,-1350.17846679688,53.6064287344095,5.87940915955405,5.26936340332031,56,1,0,0,1,0.325546264648438,34.7018585205078,1,1,3,200.149810791016,0,200.14591217041,,,,,,,,,,,,,,,,,,,,,,,,,,,,,,,,,
,3881347132.21451,200.24365234375,-1930.47180175781,3.60641412271386E-5,2.50275146822889E-8,1,4,14.0008964538574,4.99434295442217,33.0899991095066,0.044743920626617,0.00677310691502153,1,-1.84923270894467E-8,,,,,,,,,,,,,,,,,,,,,200.238159179687,200.249145507813,-1930.47180175781,-1930.47180175781,53.5638299801114,5.87921789816652,5.26581764221191,56,1,0,0,1,0.329360961914063,33.2355842590332,1,1,3,200.249145507813,0,200.24365234375,,,,,,,,,,,,,,,,,,,,,,,,,,,,,,,,,
,3881347169.61918,200.16870880127,-2510.12329101562,4.66081321282242E-5,4.85988897246019E-8,1,4,14.0008964538574,4.99427541131325,33.0899991095066,0.0578269372692522,0.00873715642376466,1,-3.68144879993667E-8,,,,,,,,,,,,,,,,,,,,,200.16242980957,200.174987792969,-2510.12329101562,-2510.12329101562,53.6021297775537,5.87981050342292,5.27240037918091,56,1,0,0,1,0.326766967773438,34.2131004333496,1,1,3,200.16242980957,0,200.16870880127,,,,,,,,,,,,,,,,,,,,,,,,,,,,,,,,,
,3881347220.91922,200.083396911621,-3000.27221679687,5.56600102799207E-5,8.43339853675967E-9,1,4,14.0008964538574,4.99426664553987,33.0899991095066,0.069069009824226,0.0103580706063843,1,-1.05166429332754E-7,,,,,,,,,,,,,,,,,,,,,200.083114624023,200.083679199219,-3000.27221679687,-3000.27221679687,53.5646116086307,5.87974180661161,5.27873420715332,56,1,0,0,1,0.328750610351562,34.2131004333496,1,1,3,200.083114624023,0,200.083396911621,,,,,,,,,,,,,,,,,,,,,,,,,,,,,,,,,
,3881347260.71133,200.083824157715,-4000.09423828125,7.38798960867396E-5,8.40021170269317E-9,1,4,14.0008964538574,4.99425570322838,33.100001513958,0.091669312838221,0.0138055222530267,1,-9.37594900530481E-8,,,,,,,,,,,,,,,,,,,,,200.064926147461,200.102722167969,-4000.09423828125,-4000.09423828125,53.5786809219768,5.87985784757483,5.27386665344238,56,1,0,0,1,0.324172973632812,34.2131004333496,1,1,3,200.102722167969,0,200.083824157715,,,,,,,,,,,,,,,,,,,,,,,,,,,,,,,,,
,3881347300.4565,200.200881958008,-5000.14306640625,9.20757138844195E-5,2.40159254855274E-8,1,4,14.0008964538574,4.99420961789588,33.0899991095066,0.114248194686552,0.0171843824643199,1,-1.33834390765447E-7,,,,,,,,,,,,,,,,,,,,,200.198440551758,200.203323364258,-5000.14306640625,-5000.14306640625,53.5732095223422,5.8800105988743,5.27576541900635,56,1,0,0,1,0.329208374023438,33.7243423461914,1,1,3,200.198440551758,0,200.200881958008,,,,,,,,,,,,,,,,,,,,,,,,,,,,,,,,,
,3881347339.92562,200.291023254395,-6000.1162109375,0.0001104751724838,1.69197259576768E-8,1,4,14.0008964538574,4.99419334027648,33.0899991095066,0.13707484971106,0.0206373097207184,1,-1.45204297977114E-7,,,,,,,,,,,,,,,,,,,,,200.279541015625,200.302505493164,-6000.1162109375,-6000.1162109375,53.5536688093614,5.87990609384283,5.26973390579224,56,1,0,0,1,0.3289794921875,34.2131004333496,1,1,3,200.302505493164,0,200.291023254395,,,,,,,,,,,,,,,,,,,,,,,,,,,,,,,,,
,3881347380.19492,200.439407348633,-6999.72412109375,0.000128730133295673,2.71615315679182E-8,1,4,14.0008964538574,4.99414757492817,33.0899991095066,0.159725903353762,0.0240286716552615,1,-1.84068015701285E-7,,,,,,,,,,,,,,,,,,,,,200.432037353516,200.44677734375,-6999.72412109375,-6999.72412109375,53.5388178674961,5.87982749090507,5.27014923095703,56,1,0,0,1,0.327072143554687,33.7243423461914,1,1,3,200.432037353516,0,200.439407348633,,,,,,,,,,,,,,,,,,,,,,,,,,,,,,,,,
,3881347419.82565,200.347137451172,-8000.0751953125,0.000147156108365988,2.18792279670912E-8,1,4,14.0008964538574,4.99419754622549,33.0899991095066,0.182585527849309,0.027504870486699,1,-1.81044380107573E-7,,,,,,,,,,,,,,,,,,,,,200.346206665039,200.348068237305,-8000.0751953125,-8000.0751953125,53.5415535673134,5.87984063075851,5.27505683898926,56,1,0,0,1,0.329055786132812,33.7243423461914,1,1,3,200.346206665039,0,200.347137451172,,,,,,,,,,,,,,,,,,,,,,,,,,,,,,,,,
,3881347459.67622,200.197578430176,-8999.7841796875,0.000165552573036224,1.80621262105979E-8,1,4,14.0008964538574,4.99418073845436,33.0899991095066,0.205406641686376,0.0309664349505568,1,-1.84945839802972E-7,,,,,,,,,,,,,,,,,,,,,200.189987182617,200.205169677734,-8999.7841796875,-8999.7841796875,53.4919201563422,5.88037125074069,5.2563419342041,56,1,0,0,1,0.326995849609375,33.7243423461914,1,1,3,200.189987182617,0,200.197578430176,,,,,,,,,,,,,,,,,,,,,,,,,,,,,,,,,
,3881347499.22426,200.086578369141,-9999.8583984375,0.000183833748022227,2.40249856376064E-8,1,4,14.0008964538574,4.99415323857133,33.0899991095066,0.228084862579554,0.0343993906021172,1,-1.94287389481253E-7,,,,,,,,,,,,,,,,,,,,,200.083206176758,200.089950561523,-9999.8583984375,-9999.8583984375,53.4989548130153,5.87971080973617,5.24884080886841,56,1,0,0,1,0.32867431640625,33.7243423461914,1,1,3,200.083206176758,0,200.086578369141,,,,,,,,,,,,,,,,,,,,,,,,,,,,,,,,,
,3881347538.91714,200.22770690918,-10999.818359375,0.000202216311317887,2.04392126600532E-8,1,4,14.0008964538574,4.99419655261526,33.100001513958,0.250894252776927,0.037847124564667,1,-2.07679900784694E-7,,,,,,,,,,,,,,,,,,,,,200.216506958008,200.238906860352,-10999.818359375,-10999.818359375,53.5353005391595,5.87994354422967,5.24972867965698,56,1,0,0,1,0.326461791992188,33.7243423461914,1,1,3,200.238906860352,0,200.22770690918,,,,,,,,,,,,,,,,,,,,,,,,,,,,,,,,,
,3881347578.69557,200.285568237305,-11999.91796875,0.000220487517236688,3.41003635451673E-8,1,4,14.0008964538574,4.99417988156028,33.0899991095066,0.273562329275238,0.0412674808646213,1,-2.25734204866239E-7,,,,,,,,,,,,,,,,,,,,,200.284881591797,200.286254882813,-11999.91796875,-11999.91796875,53.3883543775441,5.88022240304842,5.26074171066284,54,1,68,0,0,0.32745361328125,33.7243423461914,1,1,3,200.286254882813,0,200.285568237305,,,,,,,,,,,,,,,,,,,,,,,,,,,,,,,,,
,3881347618.33027,200.168075561523,-13000.0166015625,0.000238642481611246,4.85834907108436E-8,1,4,14.0008964538574,4.9940312482158,33.0899991095066,0.296066885280184,0.0447179001924243,1,-2.00537119876209E-7,,,,,,,,,,,,,,,,,,,,,200.161499023438,200.174652099609,-13000.0166015625,-13000.0166015625,53.4450224451884,5.88011204821881,5.26483154296875,56,1,0,0,1,0.327606201171875,34.2131004333496,1,1,3,200.161499023438,0,200.168075561523,,,,,,,,,,,,,,,,,,,,,,,,,,,,,,,,,
,3881347670.83316,200.263046264648,-13999.6123046875,0.000257149766306292,2.72504008572562E-8,1,4,14.0008964538574,4.99405493354186,33.100001513958,0.319032554947416,0.0481673165723096,1,-2.31310692211431E-7,,,,,,,,,,,,,,,,,,,,,200.235794067383,200.290298461914,-13999.6123046875,-13999.6123046875,53.5341280963807,5.88072132787486,5.2621283531189,56,1,0,0,1,0.329666137695313,33.7243423461914,1,1,3,200.290298461914,0,200.263046264648,,,,,,,,,,,,,,,,,,,,,,,,,,,,,,,,,
,3881347736.09644,200.318550109863,-14999.6611328125,0.000275594878107537,3.34371739919742E-8,1,4,14.0008964538574,4.99412644091295,33.0899991095066,0.341967168647527,0.0513346738964167,10,-4.80609840595891E-7,,,,,,,,,,,,,,,,,,,,,200.316818237305,200.320281982422,-14999.6611328125,-14999.6611328125,53.5739911508614,5.8809441147603,5.26154804229736,56,1,0,0,1,0.32958984375,33.7243423461914,1,1,3,200.316818237305,0,200.318550109863,,,,,,,,,,,,,,,,,,,,,,,,,,,,,,,,,
,3881347839.14664,200.051361083984,-24999.76953125,0.000458992712620556,5.07822506874196E-8,1,4,14.0008964538574,4.99406772822976,33.0899991095066,0.569406340168594,0.0862680677445255,1,-1.76855771819315E-7,,,,,,,,,,,,,,,,,,,,,200.047180175781,200.055541992187,-24999.76953125,-24999.76953125,53.4583101300153,5.88134553550817,5.2747917175293,56,1,0,0,1,0.328216552734375,33.7243423461914,1,1,3,200.055541992187,0,200.051361083984,,,,,,,,,,,,,,,,,,,,,,,,,,,,,,,,,
,3881347938.15651,200.139854431152,-34999.78125,0.000642677390024472,6.30746514388233E-8,1,4,14.0008964538574,4.99410956673062,33.0899991095066,0.797286588169163,0.120795201009166,1,-2.45998961704579E-7,,,,,,,,,,,,,,,,,,,,,200.138595581055,200.14111328125,-34999.78125,-34999.78125,53.4801957285537,5.88066639290905,5.27085542678833,56,1,0,0,1,0.329208374023438,34.2131004333496,1,1,3,200.14111328125,0,200.139854431152,,,,,,,,,,,,,,,,,,,,,,,,,,,,,,,,,
,3881348039.46343,200.172462463379,-44999.8359375,0.00082542124766847,2.12232016940471E-7,1,4,14.0008964538574,4.99408129201064,33.0899991095066,1.02390864251993,0.155645151105587,1,8.98106275713042E-8,,,,,,,,,,,,,,,,,,,,,200.156692504883,200.188232421875,-44999.8359375,-44999.8359375,53.475896771698,5.87943902974443,5.27293968200684,56,1,0,0,1,0.328521728515625,33.7243423461914,1,1,3,200.188232421875,0,200.172462463379,,,,,,,,,,,,,,,,,,,,,,,,,,,,,,,,,
,3881348140.03062,200.052307128906,-54999.54296875,0.00100987103903998,2.06022139851337E-7,1,4,14.0008964538574,4.99416082948662,33.100001513958,1.25273970267458,0.190436342176799,1,1.14925058269958E-7,,,,,,,,,,,,,,,,,,,,,200.049728393555,200.054885864258,-54999.54296875,-54999.54296875,53.2875242985633,5.87991563332533,5.28716850280762,56,1,0,0,1,0.327987670898438,34.2131004333496,1,1,3,200.049728393555,0,200.052307128906,,,,,,,,,,,,,,,,,,,,,,,,,,,,,,,,,
,3881348228.31746,200.103996276855,-64999.79296875,0.00119361114872273,3.40199877576053E-7,1,4,14.0008964538574,4.99416933626197,33.0899991095066,1.48059259817949,0.225607547289351,1,5.5654037383393E-7,,,,,,,,,,,,,,,,,,,,,200.072189331055,200.135803222656,-64999.79296875,-64999.79296875,53.3805380923518,5.88038266125831,5.27987384796143,56,1,0,0,1,0.325927734375,34.2131004333496,1,1,3,200.135803222656,0,200.103996276855,,,,,,,,,,,,,,,,,,,,,,,,,,,,,,,,,
,3881348328.84227,200.173355102539,-64999.8671875,0.00119321897585895,3.43387798643935E-7,1,4,14.0008964538574,4.99418266828859,33.100001513958,1.48008228737512,0.225727695819393,1,7.12284220474676E-7,,,,,,,,,,,,,,,,,,,,,200.145309448242,200.201400756836,-64999.8671875,-64999.8671875,53.2816620846691,5.88042602729848,5.28085470199585,56,1,0,0,1,0.325546264648438,33.7243423461914,1,1,3,200.201400756836,0,200.173355102539,,,,,,,,,,,,,,,,,,,,,,,,,,,,,,,,,
,3881348424.88718,200.224945068359,-54999.68359375,0.00101053822504373,1.93625398565574E-7,1,4,14.0008964538574,4.99418179280158,33.0899991095066,1.25389200952182,0.188474426335353,10,-1.56884532242409E-6,,,,,,,,,,,,,,,,,,,,,200.194290161133,200.255599975586,-54999.68359375,-54999.68359375,53.4196195183133,5.88059548264209,5.28655004501343,56,1,0,0,1,0.32958984375,34.2131004333496,1,1,3,200.255599975586,0,200.224945068359,,,,,,,,,,,,,,,,,,,,,,,,,,,,,,,,,
,3881348529.73583,200.215606689453,-44999.546875,0.00082557647675368,1.36408371644855E-7,1,4,14.0008964538574,4.99422473469295,33.0899991095066,1.02413308346359,0.155742039729753,1,1.39285465616246E-7,,,,,,,,,,,,,,,,,,,,,200.188049316406,200.2431640625,-44999.546875,-44999.546875,53.465735600948,5.88062654489183,5.28718042373657,56,1,0,0,1,0.327682495117188,33.7243423461914,1,1,3,200.2431640625,0,200.215606689453,,,,,,,,,,,,,,,,,,,,,,,,,,,,,,,,,
,3881348617.59778,200.127342224121,-34999.6796875,0.00064215401181021,5.97003895091975E-8,1,4,14.0008964538574,4.99424062356039,33.100001513958,0.796624747988837,0.120976690193875,1,-2.37794246670443E-8,,,,,,,,,,,,,,,,,,,,,200.12336730957,200.131317138672,-34999.6796875,-34999.6796875,53.411803233121,5.88090130024335,5.29371404647827,56,1,0,0,1,0.326156616210937,33.7243423461914,1,1,3,200.131317138672,0,200.127342224121,,,,,,,,,,,,,,,,,,,,,,,,,,,,,,,,,
,3881348703.91627,200.230026245117,-24999.681640625,0.000458418073773806,6.7071956893485E-8,1,4,14.0008964538574,4.99419661289232,33.0899991095066,0.568697059878797,0.0862748793528264,1,-8.65915435563E-8,,,,,,,,,,,,,,,,,,,,,200.222381591797,200.237670898438,-24999.681640625,-24999.681640625,53.699442528198,5.88107154571595,5.30125379562378,55,1,68,0,0,0.327529907226562,34.2131004333496,1,1,3,200.222381591797,0,200.230026245117,,,,,,,,,,,,,,,,,,,,,,,,,,,,,,,,,
,3881348817.26257,200.096656799316,-14999.724609375,0.00027493664975839,3.19015786711183E-8,1,4,14.0008964538574,4.99412427321392,33.0899991095066,0.341074469888823,0.0517106547559779,1,-7.75128345409771E-8,,,,,,,,,,,,,,,,,,,,,200.082977294922,200.110336303711,-14999.724609375,-14999.724609375,53.5802441790153,5.88166367733634,5.30144309997559,56,1,0,0,1,0.328445434570313,33.7243423461914,1,1,3,200.110336303711,0,200.096656799316,,,,,,,,,,,,,,,,,,,,,,,,,,,,,,,,,
,3881348948.12553,200.185760498047,-14000.216796875,0.000256507418089141,3.48723236739776E-8,1,4,14.0008964538574,4.99416263872555,33.0899991095066,0.318225056517682,0.0481813253853586,1,-1.23618649161579E-7,,,,,,,,,,,,,,,,,,,,,200.152969360352,200.218551635742,-14000.216796875,-14000.216796875,53.5270934397076,5.881612147671,5.30736875534058,55,1,68,0,0,0.329666137695313,34.2131004333496,1,1,3,200.218551635742,0,200.185760498047,,,,,,,,,,,,,,,,,,,,,,,,,,,,,,,,,
,3881349100.88805,200.146614074707,-13000.34375,0.000238425290471013,1.61655810416066E-8,1,4,14.0008964538574,4.99419560743654,33.0899991095066,0.295874082066482,0.044264423589772,10,-5.34758962226172E-7,,,,,,,,,,,,,,,,,,,,,200.136856079102,200.156372070313,-13000.34375,-13000.34375,53.5192771545153,5.88149344175654,5.31276893615723,56,1,0,0,1,0.329513549804687,34.2131004333496,1,1,3,200.136856079102,0,200.146614074707,,,,,,,,,,,,,,,,,,,,,,,,,,,,,,,,,
,3881349146.86535,200.276374816895,-12000.3203125,0.000219688498865689,4.23808467517168E-8,1,4,14.0008964538574,4.99422501762187,33.0899991095066,0.272552999129291,0.0412595084485576,1,-1.11211460197766E-7,,,,,,,,,,,,,,,,,,,,,200.27424621582,200.278503417969,-12000.3203125,-12000.3203125,53.518495525996,5.88071145143793,5.30745220184326,56,1,0,0,1,0.32745361328125,33.7243423461914,1,1,3,200.278503417969,0,200.276374816895,,,,,,,,,,,,,,,,,,,,,,,,,,,,,,,,,
,3881349186.01573,200.331352233887,-11000.4609375,0.000201528712407293,2.27615589122971E-8,1,4,14.0008964538574,4.99426333082718,33.0899991095066,0.250027076694378,0.0378425109588172,1,-1.07524409035283E-7,,,,,,,,,,,,,,,,,,,,,200.30891418457,200.353790283203,-11000.4609375,-11000.4609375,53.5900145355057,5.88006674797217,5.30710411071777,56,1,0,0,1,0.329513549804687,34.2131004333496,1,1,3,200.353790283203,0,200.331352233887,,,,,,,,,,,,,,,,,,,,,,,,,,,,,,,,,
,3881349327.09975,200.131553649902,-10000.2861328125,0.000183063211407429,1.63428287030819E-8,1,4,14.0008964538574,4.99424290767143,33.0899991095066,0.227115513351054,0.0343814605665085,1,-9.23940597268579E-8,,,,,,,,,,,,,,,,,,,,,200.116333007813,200.146774291992,-10000.2861328125,-10000.2861328125,53.5259209969287,5.88083535811618,5.31740093231201,55,1,68,0,0,0.329055786132812,34.2131004333496,1,1,3,200.146774291992,0,200.131553649902,,,,,,,,,,,,,,,,,,,,,,,,,,,,,,,,,
,3881349367.20519,200.313629150391,-9000.3505859375,0.000164698051429957,1.79046500381154E-8,1,4,14.0008964538574,4.99416774405573,33.100001513958,0.204327117251567,0.0309285790655213,1,-8.55696646972668E-8,,,,,,,,,,,,,,,,,,,,,200.30305480957,200.324203491211,-9000.3505859375,-9000.3505859375,53.5509331095441,5.8810596030786,5.3188099861145,56,1,0,0,1,0.327987670898438,33.7243423461914,1,1,3,200.324203491211,0,200.313629150391,,,,,,,,,,,,,,,,,,,,,,,,,,,,,,,,,
,3881349408.79534,200.477783203125,-8000.515625,0.00014638986302975,1.36724172263583E-8,1,4,14.0008964538574,4.99419099258081,33.0899991095066,0.181612392202061,0.0275069255061062,1,-6.29548003089517E-8,,,,,,,,,,,,,,,,,,,,,200.476409912109,200.479156494141,-8000.515625,-8000.515625,53.6466826031499,5.88167350345605,5.31588792800903,56,1,0,0,1,0.327301025390625,34.2131004333496,1,1,3,200.476409912109,0,200.477783203125,,,,,,,,,,,,,,,,,,,,,,,,,,,,,,,,,
,3881349529.10364,200.165390014648,-7000.40380859375,0.000128010196563554,1.54326674552574E-8,1,4,14.0008964538574,4.99413424597216,33.100001513958,0.15880841000984,0.0240496688709774,1,-5.77112785935208E-8,,,,,,,,,,,,,,,,,,,,,200.145645141602,200.185134887695,-7000.40380859375,-7000.40380859375,53.5016905128326,5.88117274534061,5.3148078918457,56,1,0,0,1,0.32684326171875,33.7243423461914,1,1,3,200.185134887695,0,200.165390014648,,,,,,,,,,,,,,,,,,,,,,,,,,,,,,,,,
,3881349568.58866,200.346527099609,-6000.330078125,0.000109626408389808,1.37390964381651E-8,1,4,14.0008964538574,4.99408907529505,33.0899991095066,0.136002065000508,0.0205813930987814,1,-6.08671611913704E-8,,,,,,,,,,,,,,,,,,,,,200.343856811523,200.349197387695,-6000.330078125,-6000.330078125,53.5567953234384,5.8816942778942,5.32211446762085,55,1,68,0,0,0.326461791992188,34.2131004333496,1,1,3,200.343856811523,0,200.346527099609,,,,,,,,,,,,,,,,,,,,,,,,,,,,,,,,,
,3881349607.34799,200.335800170898,-5000.369140625,9.12756115365993E-5,8.68387760590497E-9,1,4,14.0008964538574,4.99411820662026,33.0899991095066,0.113236931070607,0.0171372354828746,1,-4.99504964193688E-8,,,,,,,,,,,,,,,,,,,,,200.328277587891,200.343322753906,-5000.369140625,-5000.369140625,53.518495525996,5.88157529280895,5.31326580047607,55,1,68,0,0,0.33050537109375,33.7243423461914,1,1,3,200.328277587891,0,200.335800170898,,,,,,,,,,,,,,,,,,,,,,,,,,,,,,,,,
,3881349648.14335,200.252182006836,-4000.40893554687,7.29022701093995E-5,1.38951438169762E-8,1,4,14.0008964538574,4.99407147442879,33.0899991095066,0.0904387811430529,0.0137066035765806,1,-2.44254997865896E-8,,,,,,,,,,,,,,,,,,,,,200.236480712891,200.267883300781,-4000.40893554687,-4000.40893554687,53.5544504378807,5.88181613515656,5.31892204284668,56,1,0,0,1,0.329360961914063,33.7243423461914,1,1,3,200.267883300781,0,200.252182006836,,,,,,,,,,,,,,,,,,,,,,,,,,,,,,,,,
,3881349688.93936,200.282112121582,-3000.08325195313,5.45145471958771E-5,7.00537506414277E-9,1,4,14.0008964538574,4.99407112703363,33.0899991095066,0.0676283270198049,0.0102467695728368,1,-2.04371117953655E-8,,,,,,,,,,,,,,,,,,,,,200.275497436523,200.288726806641,-3000.08325195313,-3000.08325195313,53.5677381227076,5.88225788813996,5.32620763778687,54,1,68,0,0,0.327529907226562,33.7243423461914,1,1,3,200.275497436523,0,200.282112121582,,,,,,,,,,,,,,,,,,,,,,,,,,,,,,,,,
,3881349740.98803,200.133499145508,-2510.37475585938,4.5505319251535E-5,7.59924684420649E-9,1,4,14.0008964538574,4.99402863709766,33.100001513958,0.0564520608193682,0.00854763007137899,1,-2.15962023848526E-8,,,,,,,,,,,,,,,,,,,,,200.128173828125,200.138824462891,-2510.37475585938,-2510.37475585938,53.521622040073,5.88227717635016,5.32704973220825,56,1,0,0,1,0.327377319335937,33.7243423461914,1,1,3,200.128173828125,0,200.133499145508,,,,,,,,,,,,,,,,,,,,,,,,,,,,,,,,,
,3881349780.02592,200.132423400879,-1930.52221679687,3.48301267867542E-5,7.21630457412093E-9,1,4,14.0008964538574,4.99411160917603,33.100001513958,0.0432074243142822,0.00655856977563049,1,-3.63614650512951E-9,,,,,,,,,,,,,,,,,,,,,200.129806518555,200.135040283203,-1930.52221679687,-1930.52221679687,53.4989548130153,5.88190825070918,5.32701635360718,56,1,0,0,1,0.328216552734375,34.2131004333496,1,1,3,200.129806518555,0,200.132423400879,,,,,,,,,,,,,,,,,,,,,,,,,,,,,,,,,
,3881349818.91487,200.261833190918,-1350.32958984375,2.41785562652997E-5,8.48473245073869E-9,1,4,14.0008964538574,4.99397685611032,33.0899991095066,0.0299903370153682,0.0045690226464126,1,1.06428828642083E-8,,,,,,,,,,,,,,,,,,,,,200.232971191406,200.29069519043,-1350.32958984375,-1350.32958984375,53.5341280963807,5.88232944602973,5.32795476913452,56,1,0,0,1,0.329971313476562,34.2131004333496,1,1,3,200.29069519043,0,200.261833190918,,,,,,,,,,,,,,,,,,,,,,,,,,,,,,,,,
,3881349857.90533,200.331871032715,-770.464172363281,1.35155788344671E-5,9.21253508044998E-9,1,4,14.0008964538574,4.99401966057228,33.0899991095066,0.0167638315888168,0.00255853155160556,1,9.54587174707143E-9,,,,,,,,,,,,,,,,,,,,,200.323547363281,200.340194702148,-770.464172363281,-770.464172363281,53.5861063929095,5.88165120233306,5.31724452972412,56,1,0,0,1,0.327072143554687,33.7243423461914,1,1,3,200.340194702148,0,200.331871032715,,,,,,,,,,,,,,,,,,,,,,,,,,,,,,,,,
,3881349896.88116,200.251152038574,-190.447708129883,2.84174717417334E-6,1.13100195840664E-8,1,4,14.0008964538574,4.99401690400303,33.0899991095066,0.00352525313373844,0.000534392213393541,1,-8.60333937242785E-10,,,,,,,,,,,,,,,,,,,,,200.250991821289,200.251312255859,-190.447708129883,-190.447708129883,53.475896771698,5.88145097330791,5.32065629959106,56,1,0,0,1,0.327911376953125,33.7243423461914,1,1,3,200.250991821289,0,200.251152038574,,,,,,,,,,,,,,,,,,,,,,,,,,,,,,,,,
,3881349935.30586,200.230690002441,389.707183837891,-7.81141414695652E-6,1.99489310668948E-8,1,4,14.0008964538574,4.99402253880606,33.0899991095066,-0.00969781221251846,-0.00141919412351233,1,4.24700633018536E-8,,,,,,,,,,,,,,,,,,,,,200.22639465332,200.234985351562,389.707183837891,389.707183837891,53.5743819651211,5.88122432819473,5.33076095581055,56,1,0,0,1,0.327224731445313,34.2131004333496,1,1,3,200.234985351562,0,200.230690002441,,,,,,,,,,,,,,,,,,,,,,,,,,,,,,,,,
,3881349974.83079,200.264419555664,969.534790039063,-1.84857203198646E-5,5.61300067602464E-8,1,4,14.0008964538574,4.99398815536479,33.0899991095066,-0.0229387592053964,-0.00343026922283513,1,4.26419511128162E-8,,,,,,,,,,,,,,,,,,,,,200.246276855469,200.282562255859,969.534790039063,969.534790039063,53.5255301826691,5.88155919586253,5.33118343353271,56,1,0,0,1,0.32958984375,33.7243423461914,1,1,3,200.282562255859,0,200.264419555664,,,,,,,,,,,,,,,,,,,,,,,,,,,,,,,,,
,3881350013.51241,200.428337097168,1549.65197753906,-2.91665338761275E-5,3.62283946075299E-8,1,4,14.0008964538574,4.99404061425134,33.100001513958,-0.0361932490017334,-0.00541077042260396,1,6.85248295777809E-8,,,,,,,,,,,,,,,,,,,,,200.417663574219,200.439010620117,1549.65197753906,1549.65197753906,53.5259209969287,5.88142226394908,5.32345914840698,56,1,0,0,1,0.327377319335937,33.7243423461914,1,1,3,200.439010620117,0,200.428337097168,,,,,,,,,,,,,,,,,,,,,,,,,,,,,,,,,
,3881350052.71706,200.438888549805,2129.74389648438,-3.97451538405566E-5,9.83405672555836E-9,1,4,14.0008964538574,4.99396520960694,33.100001513958,-0.0493133979222937,-0.00741257059561126,1,6.15474519499981E-8,,,,,,,,,,,,,,,,,,,,,200.438339233398,200.439437866211,2129.74389648438,2129.74389648438,53.4477581450057,5.88231365174521,5.32692241668701,56,1,0,0,1,0.327529907226562,34.2131004333496,1,1,3,200.438339233398,0,200.438888549805,,,,,,,,,,,,,,,,,,,,,,,,,,,,,,,,,
,3881350091.5995,200.352760314941,2709.4833984375,-5.03474862275441E-5,9.60520205093151E-9,1,4,14.0008964538574,4.99394071322508,33.0899991095066,-0.0624685066417422,-0.00938459299444105,1,8.22179106092217E-8,,,,,,,,,,,,,,,,,,,,,200.349075317383,200.3564453125,2709.4833984375,2709.4833984375,53.4669080437268,5.88214805431942,5.32324934005737,56,1,0,0,1,0.329360961914063,33.7243423461914,1,1,3,200.349075317383,0,200.352760314941,,,,,,,,,,,,,,,,,,,,,,,,,,,,,,,,,
,3881350148.44026,200.382415771484,3499.69848632812,-6.47228598601254E-5,9.63356878368201E-9,1,4,14.0008964538574,4.99393602654345,33.0899991095066,-0.0803044626775474,-0.0120650447499672,1,1.04928041877945E-7,,,,,,,,,,,,,,,,,,,,,200.381744384766,200.383087158203,3499.69848632812,3499.69848632812,53.6838099578134,5.88189304374933,5.33410835266113,56,1,0,0,1,0.326309204101562,33.7243423461914,1,1,3,200.383087158203,0,200.382415771484,,,,,,,,,,,,,,,,,,,,,,,,,,,,,,,,,
,3881350188.66712,200.374641418457,4499.5205078125,-8.29665112520553E-5,1.97834745774768E-8,1,4,14.0008964538574,4.99389000863141,33.0899991095066,-0.102937303118171,-0.0154756749039181,1,1.26430738222375E-7,,,,,,,,,,,,,,,,,,,,,200.352355957031,200.396926879883,4499.5205078125,4499.5205078125,53.5497606667653,5.88189312523543,5.32519578933716,56,1,0,0,1,0.3289794921875,33.7243423461914,1,1,3,200.396926879883,0,200.374641418457,,,,,,,,,,,,,,,,,,,,,,,,,,,,,,,,,
,3881350305.67985,200.146041870117,5499.58203125,-0.000101296476757149,2.70705808729286E-8,1,4,14.0008964538574,4.99393947279659,33.0899991095066,-0.125678608026835,-0.0189120835309395,1,1.40599581280998E-7,,,,,,,,,,,,,,,,,,,,,200.132598876953,200.159484863281,5499.58203125,5499.58203125,53.5603126517749,5.88275724209799,5.32673788070679,54,1,68,0,0,0.327911376953125,33.7243423461914,1,1,3,200.159484863281,0,200.146041870117,,,,,,,,,,,,,,,,,,,,,,,,,,,,,,,,,
,3881350346.26084,200.164749145508,6499.517578125,-0.000119678500588396,2.98476694286817E-8,1,4,14.0008964538574,4.99398257065362,33.0899991095066,-0.148483984884815,-0.0223640841226372,1,1.50151191275037E-7,,,,,,,,,,,,,,,,,,,,,200.159072875977,200.170425415039,6499.517578125,6499.517578125,53.4172746327557,5.88243199764375,5.32789945602417,56,1,0,0,1,0.33172607421875,33.7243423461914,1,1,3,200.170425415039,0,200.164749145508,,,,,,,,,,,,,,,,,,,,,,,,,,,,,,,,,
,3881350387.5876,200.2890625,7499.75537109375,-0.000138014113999456,1.8400638301516E-8,1,4,14.0008964538574,4.9940077527076,33.100001513958,-0.171231918243358,-0.0258044209084551,1,1.62018560629747E-7,,,,,,,,,,,,,,,,,,,,,200.288421630859,200.289703369141,7499.75537109375,7499.75537109375,53.5392086817557,5.88240704330083,5.33399486541748,55,1,68,0,0,0.327224731445313,33.7243423461914,1,1,3,200.289703369141,0,200.2890625,,,,,,,,,,,,,,,,,,,,,,,,,,,,,,,,,
,3881350507.20445,200.167213439941,8499.65234375,-0.000156372630086149,1.73799295195699E-8,1,4,14.0008964538574,4.99403540139626,33.0899991095066,-0.194012659922638,-0.0292231865254843,1,1.94809800829192E-7,,,,,,,,,,,,,,,,,,,,,200.15803527832,200.176391601562,8499.65234375,8499.65234375,53.5446800813903,5.88201619767237,5.33063364028931,56,1,0,0,1,0.327301025390625,33.7243423461914,1,1,3,200.15803527832,0,200.167213439941,,,,,,,,,,,,,,,,,,,,,,,,,,,,,,,,,
,3881350547.66095,200.323501586914,9499.9658203125,-0.000174736365229277,2.29518260696479E-8,1,4,14.0008964538574,4.99401069283583,33.0899991095066,-0.216793735614816,-0.032664296959997,1,2.10036833716524E-7,,,,,,,,,,,,,,,,,,,,,200.316131591797,200.330871582031,9499.9658203125,9499.9658203125,53.4594825727941,5.88262767927369,5.33219194412231,54,1,68,0,0,0.330352783203125,33.7243423461914,1,1,3,200.330871582031,0,200.323501586914,,,,,,,,,,,,,,,,,,,,,,,,,,,,,,,,,
,3881350587.48266,200.238357543945,10499.837890625,-0.000193065191331756,2.09657206190336E-8,1,4,14.0008964538574,4.99406590091314,33.0899991095066,-0.239532907352942,-0.0361236500804273,1,2.05869090434811E-7,,,,,,,,,,,,,,,,,,,,,200.235580444336,200.241134643555,10499.837890625,10499.837890625,53.5446800813903,5.88204958101785,5.33241605758667,56,1,0,0,1,0.325927734375,33.7243423461914,1,1,3,200.235580444336,0,200.238357543945,,,,,,,,,,,,,,,,,,,,,,,,,,,,,,,,,
,3881350627.88152,200.182418823242,11499.634765625,-0.000211362915453461,2.58884378746568E-8,1,4,14.0008964538574,4.99408476761249,33.0899991095066,-0.262237170946378,-0.0395396977938898,1,2.31647994322877E-7,,,,,,,,,,,,,,,,,,,,,200.163269042969,200.201568603516,11499.634765625,11499.634765625,53.5431168243518,5.88164162354911,5.33309888839722,54,1,68,0,0,0.32989501953125,33.7243423461914,1,1,3,200.201568603516,0,200.182418823242,,,,,,,,,,,,,,,,,,,,,,,,,,,,,,,,,
,3881350667.67885,200.351097106934,12499.62109375,-0.000229771108421765,1.68124751953022E-8,1,4,14.0008964538574,4.99405304287343,33.0899991095066,-0.285072072352252,-0.0429930599171051,1,2.43664156334579E-7,,,,,,,,,,,,,,,,,,,,,200.345489501953,200.356704711914,12499.62109375,12499.62109375,53.353962722698,5.88184548172557,5.33680725097656,56,1,0,0,1,0.330429077148438,33.7243423461914,1,1,3,200.345489501953,0,200.351097106934,,,,,,,,,,,,,,,,,,,,,,,,,,,,,,,,,
,3881350720.65377,200.24072265625,13500.0341796875,-0.000247988457590978,2.90499570345286E-8,1,4,14.0008964538574,4.99404821459433,33.0899991095066,-0.307668016798185,-0.0464379801552338,1,2.33729530017256E-7,,,,,,,,,,,,,,,,,,,,,200.212387084961,200.269058227539,13500.0341796875,13500.0341796875,53.5016905128326,5.88216191684465,5.34558916091919,54,1,68,0,0,0.330657958984375,33.7243423461914,1,1,3,200.269058227539,0,200.24072265625,,,,,,,,,,,,,,,,,,,,,,,,,,,,,,,,,
,3881350786.60914,200.178344726562,14499.806640625,-0.000266388420368834,3.45778998879157E-8,1,4,14.0008964538574,4.99403592273246,33.0899991095066,-0.330494745754673,-0.0498842141459102,1,2.50383030589496E-7,,,,,,,,,,,,,,,,,,,,,200.171310424805,200.18537902832,14499.806640625,14499.806640625,53.3910900773614,5.88212763648993,5.3362250328064,55,1,68,0,0,0.328598022460937,33.7243423461914,1,1,3,200.171310424805,0,200.178344726562,,,,,,,,,,,,,,,,,,,,,,,,,,,,,,,,,
,3881350870.92261,200.275695800781,19999.841796875,-0.000367528332758536,3.28911037397476E-8,1,4,14.0008964538574,4.99389132588552,33.100001513958,-0.456010928517655,-0.0684558769039194,10,6.39802947782802E-7,,,,,,,,,,,,,,,,,,,,,200.272552490234,200.278839111328,19999.841796875,19999.841796875,53.4340796459191,5.88289390595121,5.34651470184326,56,1,0,0,1,0.326995849609375,33.7243423461914,1,1,3,200.278839111328,0,200.275695800781,,,,,,,,,,,,,,,,,,,,,,,,,,,,,,,,,
,3881350959.65548,200.284065246582,30000.35546875,-0.000550565446307977,8.82137280900454E-8,1,4,14.0008964538574,4.99389956396291,33.100001513958,-0.682954922545936,-0.103608264638645,1,1.04188765103992E-7,,,,,,,,,,,,,,,,,,,,,200.274719238281,200.293411254883,30000.35546875,30000.35546875,53.491138527823,5.88269029951804,5.34821033477783,56,1,0,0,1,0.328292846679687,33.7243423461914,1,1,3,200.274719238281,0,200.284065246582,,,,,,,,,,,,,,,,,,,,,,,,,,,,,,,,,
,3881351045.64121,200.231307983398,40000.515625,-0.000734313352520517,1.23644968288664E-7,1,4,14.0008964538574,4.9938336248015,33.100001513958,-0.910854021460818,-0.138290666563206,1,5.32447832052967E-8,,,,,,,,,,,,,,,,,,,,,200.211624145508,200.250991821289,40000.515625,40000.515625,53.3899176345826,5.88287412171252,5.35019111633301,55,1,68,0,0,0.32684326171875,33.7243423461914,1,1,3,200.250991821289,0,200.231307983398,,,,,,,,,,,,,,,,,,,,,,,,,,,,,,,,,
,3881351145.17471,200.291427612305,50000.33203125,-0.000918176533549546,1.60279712111465E-7,1,4,14.0008964538574,4.99393872891612,33.0899991095066,-1.13891851446254,-0.173158515452294,1,-1.24033817539832E-7,,,,,,,,,,,,,,,,,,,,,200.26383972168,200.31901550293,50000.33203125,50000.33203125,53.3504453943614,5.88315479083137,5.3427562713623,56,1,0,0,1,0.32989501953125,33.2355842590332,1,1,3,200.31901550293,0,200.291427612305,,,,,,,,,,,,,,,,,,,,,,,,,,,,,,,,,
,3881351245.14348,200.133308410645,60000.5234375,-0.00110087619156163,2.95096965866143E-7,1,4,14.0008964538574,4.99395548734609,33.100001513958,-1.36550707677185,-0.207884449227345,1,-3.66142907593914E-7,,,,,,,,,,,,,,,,,,,,,200.12776184082,200.138854980469,60000.5234375,60000.5234375,53.1503484934383,5.88251213451478,5.3531322479248,54,1,68,0,0,0.327911376953125,33.7243423461914,1,1,3,200.12776184082,0,200.133308410645,,,,,,,,,,,,,,,,,,,,,,,,,,,,,,,,,
,3881351344.67246,200.221900939941,70000.40625,-0.00128398429347281,4.96397852713608E-7,1,4,14.0008964538574,4.99433993131471,33.100001513958,-1.59277503036448,-0.242670876764123,1,-5.74539572050877E-7,,,,,,,,,,,,,,,,,,,,,200.200241088867,200.243560791016,70000.40625,70000.40625,53.1820044484672,5.88037631730359,5.34472990036011,56,1,0,0,1,0.325546264648438,33.7243423461914,1,1,3,200.243560791016,0,200.221900939941,,,,,,,,,,,,,,,,,,,,,,,,,,,,,,,,,
,3881351348.50877,200.263725280762,70000.40625,-0.00128430342814246,3.81250764573017E-7,1,4,14.0008964538574,4.99429060101945,33.0899991095066,-1.59315824908855,-0.242666107240333,1,-5.24924949150392E-7,,,,,,,,,,,,,,,,,,,,,200.243560791016,200.283889770508,70000.40625,70000.40625,53.1550382645537,5.88075494098903,5.35018062591553,56,2,0,0,1,0.327987670898438,33.7243423461914,1,1,3,200.283889770508,0,200.263725280762,,,,,,,,,,,,,,,,,,,,,,,,,,,,,,,,,